package com.NovaCraft.world.village;

import java.util.Random;

import com.NovaCraft.config.Configs;
import com.NovaCraft.entity.illager.EntityIllagerTrader;
import com.NovaCraft.entity.illager.EntityVindicator;
import com.NovaCraftBlocks.NovaCraftBlocks;

import cpw.mods.fml.common.Loader;
import net.minecraft.block.Block;
import net.minecraft.init.Blocks;
import net.minecraft.init.Items;
import net.minecraft.item.ItemStack;
import net.minecraft.tileentity.TileEntityChest;
import net.minecraft.world.World;
import net.minecraft.world.gen.feature.WorldGenerator;

public class VindicatorRandomHouseWorshipRoom extends WorldGenerator
{	

	public VindicatorRandomHouseWorshipRoom() { 
		
	}

	public boolean generate(World world, Random rand, int i, int j, int k) {
		
		int random = rand.nextInt(24);
		if (random > 12) {
		world.setBlock(i + 0, j + 0, k + 0, NovaCraftBlocks.cobbled_grimstone, 0, 2);
		world.setBlock(i + 1, j + 0, k + 0, NovaCraftBlocks.cobbled_grimstone, 0, 2);
		world.setBlock(i + 2, j + 0, k + 0, NovaCraftBlocks.cobbled_grimstone, 0, 2);
		world.setBlock(i + 3, j + 0, k + 0, NovaCraftBlocks.cobbled_grimstone, 0, 2);
		world.setBlock(i + 4, j + 0, k + 0, NovaCraftBlocks.cobbled_grimstone, 0, 2);
		world.setBlock(i + 5, j + 0, k + 0, NovaCraftBlocks.cobbled_grimstone, 0, 2);
		world.setBlock(i + 6, j + 0, k + 0, NovaCraftBlocks.cobbled_grimstone, 0, 2);
		world.setBlock(i + 7, j + 0, k + 0, NovaCraftBlocks.cobbled_grimstone, 0, 2);
		world.setBlock(i + 8, j + 0, k + 0, NovaCraftBlocks.cobbled_grimstone, 0, 2);
		world.setBlock(i + 9, j + 0, k + 0, NovaCraftBlocks.cobbled_grimstone, 0, 2);
		world.setBlock(i + 0, j + 0, k + 1, NovaCraftBlocks.cobbled_grimstone, 0, 2);
		world.setBlock(i + 1, j + 0, k + 1, NovaCraftBlocks.cobbled_grimstone, 0, 2);
		world.setBlock(i + 2, j + 0, k + 1, NovaCraftBlocks.cobbled_grimstone, 0, 2);
		world.setBlock(i + 3, j + 0, k + 1, NovaCraftBlocks.cobbled_grimstone, 0, 2);
		world.setBlock(i + 4, j + 0, k + 1, NovaCraftBlocks.cobbled_grimstone, 0, 2);
		world.setBlock(i + 5, j + 0, k + 1, NovaCraftBlocks.cobbled_grimstone, 0, 2);
		world.setBlock(i + 6, j + 0, k + 1, NovaCraftBlocks.cobbled_grimstone, 0, 2);
		world.setBlock(i + 7, j + 0, k + 1, NovaCraftBlocks.cobbled_grimstone, 0, 2);
		world.setBlock(i + 8, j + 0, k + 1, NovaCraftBlocks.cobbled_grimstone, 0, 2);
		world.setBlock(i + 9, j + 0, k + 1, NovaCraftBlocks.cobbled_grimstone, 0, 2);
		world.setBlock(i + 0, j + 0, k + 2, NovaCraftBlocks.cobbled_grimstone, 0, 2);
		world.setBlock(i + 1, j + 0, k + 2, NovaCraftBlocks.cobbled_grimstone, 0, 2);
		world.setBlock(i + 2, j + 0, k + 2, NovaCraftBlocks.cobbled_grimstone, 0, 2);
		world.setBlock(i + 3, j + 0, k + 2, NovaCraftBlocks.cobbled_grimstone, 0, 2);
		world.setBlock(i + 4, j + 0, k + 2, NovaCraftBlocks.cobbled_grimstone, 0, 2);
		world.setBlock(i + 5, j + 0, k + 2, NovaCraftBlocks.cobbled_grimstone, 0, 2);
		world.setBlock(i + 6, j + 0, k + 2, Blocks.wool, 14, 2);
		world.setBlock(i + 7, j + 0, k + 2, NovaCraftBlocks.cobbled_grimstone, 0, 2);
		world.setBlock(i + 8, j + 0, k + 2, NovaCraftBlocks.cobbled_grimstone, 0, 2);
		world.setBlock(i + 9, j + 0, k + 2, NovaCraftBlocks.cobbled_grimstone, 0, 2);
		world.setBlock(i + 0, j + 0, k + 3, NovaCraftBlocks.cobbled_grimstone, 0, 2);
		world.setBlock(i + 1, j + 0, k + 3, NovaCraftBlocks.cobbled_grimstone, 0, 2);
		world.setBlock(i + 2, j + 0, k + 3, NovaCraftBlocks.cobbled_grimstone, 0, 2);
		world.setBlock(i + 3, j + 0, k + 3, NovaCraftBlocks.cobbled_grimstone, 0, 2);
		world.setBlock(i + 4, j + 0, k + 3, NovaCraftBlocks.cobbled_grimstone, 0, 2);
		world.setBlock(i + 5, j + 0, k + 3, NovaCraftBlocks.cobbled_grimstone, 0, 2);
		world.setBlock(i + 6, j + 0, k + 3, NovaCraftBlocks.cobbled_grimstone, 0, 2);
		world.setBlock(i + 7, j + 0, k + 3, NovaCraftBlocks.cobbled_grimstone, 0, 2);
		world.setBlock(i + 8, j + 0, k + 3, NovaCraftBlocks.cobbled_grimstone, 0, 2);
		world.setBlock(i + 9, j + 0, k + 3, NovaCraftBlocks.cobbled_grimstone, 0, 2);
		world.setBlock(i + 0, j + 0, k + 4, NovaCraftBlocks.cobbled_grimstone, 0, 2);
		world.setBlock(i + 1, j + 0, k + 4, NovaCraftBlocks.cobbled_grimstone, 0, 2);
		world.setBlock(i + 2, j + 0, k + 4, NovaCraftBlocks.cobbled_grimstone, 0, 2);
		world.setBlock(i + 3, j + 0, k + 4, NovaCraftBlocks.cobbled_grimstone, 0, 2);
		world.setBlock(i + 4, j + 0, k + 4, NovaCraftBlocks.cobbled_grimstone, 0, 2);
		world.setBlock(i + 5, j + 0, k + 4, NovaCraftBlocks.cobbled_grimstone, 0, 2);
		world.setBlock(i + 6, j + 0, k + 4, NovaCraftBlocks.cobbled_grimstone, 0, 2);
		world.setBlock(i + 7, j + 0, k + 4, NovaCraftBlocks.cobbled_grimstone, 0, 2);
		world.setBlock(i + 8, j + 0, k + 4, NovaCraftBlocks.cobbled_grimstone, 0, 2);
		world.setBlock(i + 9, j + 0, k + 4, NovaCraftBlocks.cobbled_grimstone, 0, 2);
		world.setBlock(i + 0, j + 1, k + 0, NovaCraftBlocks.cobbled_grimstone, 0, 2);
		world.setBlock(i + 1, j + 1, k + 0, NovaCraftBlocks.cobbled_grimstone, 0, 2);
		world.setBlock(i + 2, j + 1, k + 0, NovaCraftBlocks.cobbled_grimstone, 0, 2);
		world.setBlock(i + 3, j + 1, k + 0, NovaCraftBlocks.cobbled_grimstone, 0, 2);
		world.setBlock(i + 4, j + 1, k + 0, NovaCraftBlocks.cobbled_grimstone, 0, 2);
		world.setBlock(i + 5, j + 1, k + 0, NovaCraftBlocks.cobbled_grimstone, 0, 2);
		world.setBlock(i + 6, j + 1, k + 0, NovaCraftBlocks.cobbled_grimstone, 0, 2);
		world.setBlock(i + 7, j + 1, k + 0, NovaCraftBlocks.cobbled_grimstone, 0, 2);
		world.setBlock(i + 8, j + 1, k + 0, NovaCraftBlocks.cobbled_grimstone, 0, 2);
		world.setBlock(i + 9, j + 1, k + 0, NovaCraftBlocks.cobbled_grimstone, 0, 2);
		world.setBlock(i + 0, j + 1, k + 1, NovaCraftBlocks.cobbled_grimstone, 0, 2);
		world.setBlock(i + 1, j + 1, k + 1, NovaCraftBlocks.cobbled_grimstone, 0, 2);
		world.setBlock(i + 2, j + 1, k + 1, Blocks.ladder, 3, 2);
		world.setBlock(i + 3, j + 1, k + 1, NovaCraftBlocks.cobbled_grimstone_stairs, 1, 2);
		world.setBlock(i + 4, j + 1, k + 1, Blocks.air, 0, 2);
		world.setBlock(i + 5, j + 1, k + 1, NovaCraftBlocks.cobbled_grimstone_stairs, 1, 2);
		world.setBlock(i + 6, j + 1, k + 1, Blocks.carpet, 14, 2);
		world.setBlock(i + 7, j + 1, k + 1, Blocks.carpet, 14, 2);
		world.setBlock(i + 8, j + 1, k + 1, Blocks.air, 0, 2);
		world.setBlock(i + 9, j + 1, k + 1, NovaCraftBlocks.cobbled_grimstone, 0, 2);
		world.setBlock(i + 0, j + 1, k + 2, NovaCraftBlocks.cobbled_grimstone, 0, 2);
		world.setBlock(i + 1, j + 1, k + 2, NovaCraftBlocks.cobbled_grimstone_stairs, 1, 2);
		world.setBlock(i + 2, j + 1, k + 2, Blocks.air, 0, 2);
		world.setBlock(i + 3, j + 1, k + 2, Blocks.carpet, 14, 2);
		world.setBlock(i + 4, j + 1, k + 2, Blocks.carpet, 14, 2);
		world.setBlock(i + 5, j + 1, k + 2, Blocks.carpet, 14, 2);
		world.setBlock(i + 6, j + 1, k + 2, NovaCraftBlocks.cobbled_grimstone_wall, 0, 2);
		world.setBlock(i + 7, j + 1, k + 2, Blocks.carpet, 14, 2);
		world.setBlock(i + 8, j + 1, k + 2, NovaCraftBlocks.cobbled_nullstone, 0, 2);
		world.setBlock(i + 9, j + 1, k + 2, NovaCraftBlocks.cobbled_grimstone, 0, 2);
		world.setBlock(i + 0, j + 1, k + 3, NovaCraftBlocks.cobbled_grimstone, 0, 2);
		world.setBlock(i + 1, j + 1, k + 3, NovaCraftBlocks.cobbled_grimstone_stairs, 1, 2);
		world.setBlock(i + 2, j + 1, k + 3, Blocks.air, 0, 2);
		world.setBlock(i + 3, j + 1, k + 3, NovaCraftBlocks.cobbled_grimstone_stairs, 1, 2);
		world.setBlock(i + 4, j + 1, k + 3, Blocks.air, 0, 2);
		world.setBlock(i + 5, j + 1, k + 3, NovaCraftBlocks.cobbled_grimstone_stairs, 1, 2);
		world.setBlock(i + 6, j + 1, k + 3, Blocks.carpet, 14, 2);
		world.setBlock(i + 7, j + 1, k + 3, Blocks.carpet, 14, 2);
		world.setBlock(i + 8, j + 1, k + 3, Blocks.air, 0, 2);
		world.setBlock(i + 9, j + 1, k + 3, NovaCraftBlocks.cobbled_grimstone, 0, 2);
		world.setBlock(i + 0, j + 1, k + 4, NovaCraftBlocks.cobbled_grimstone, 0, 2);
		world.setBlock(i + 1, j + 1, k + 4, NovaCraftBlocks.cobbled_grimstone, 0, 2);
		world.setBlock(i + 2, j + 1, k + 4, NovaCraftBlocks.cobbled_grimstone, 0, 2);
		world.setBlock(i + 3, j + 1, k + 4, NovaCraftBlocks.cobbled_grimstone, 0, 2);
		world.setBlock(i + 4, j + 1, k + 4, NovaCraftBlocks.cobbled_grimstone, 0, 2);
		world.setBlock(i + 5, j + 1, k + 4, NovaCraftBlocks.cobbled_grimstone, 0, 2);
		world.setBlock(i + 6, j + 1, k + 4, NovaCraftBlocks.cobbled_grimstone, 0, 2);
		world.setBlock(i + 7, j + 1, k + 4, NovaCraftBlocks.cobbled_grimstone, 0, 2);
		world.setBlock(i + 8, j + 1, k + 4, NovaCraftBlocks.cobbled_grimstone, 0, 2);
		world.setBlock(i + 9, j + 1, k + 4, NovaCraftBlocks.cobbled_grimstone, 0, 2);
		world.setBlock(i + 0, j + 2, k + 0, NovaCraftBlocks.cobbled_grimstone, 0, 2);
		world.setBlock(i + 1, j + 2, k + 0, NovaCraftBlocks.cobbled_grimstone, 0, 2);
		world.setBlock(i + 2, j + 2, k + 0, NovaCraftBlocks.cobbled_grimstone, 0, 2);
		world.setBlock(i + 3, j + 2, k + 0, NovaCraftBlocks.cobbled_grimstone, 0, 2);
		world.setBlock(i + 4, j + 2, k + 0, NovaCraftBlocks.cobbled_grimstone, 0, 2);
		world.setBlock(i + 5, j + 2, k + 0, NovaCraftBlocks.cobbled_grimstone, 0, 2);
		world.setBlock(i + 6, j + 2, k + 0, NovaCraftBlocks.cobbled_grimstone, 0, 2);
		world.setBlock(i + 7, j + 2, k + 0, NovaCraftBlocks.cobbled_grimstone, 0, 2);
		world.setBlock(i + 8, j + 2, k + 0, NovaCraftBlocks.cobbled_grimstone, 0, 2);
		world.setBlock(i + 9, j + 2, k + 0, NovaCraftBlocks.cobbled_grimstone, 0, 2);
		world.setBlock(i + 0, j + 2, k + 1, NovaCraftBlocks.cobbled_grimstone, 0, 2);
		world.setBlock(i + 1, j + 2, k + 1, NovaCraftBlocks.cobbled_grimstone, 0, 2);
		world.setBlock(i + 2, j + 2, k + 1, Blocks.ladder, 3, 2);
		world.setBlock(i + 3, j + 2, k + 1, Blocks.redstone_torch, 3, 2);
		world.setBlock(i + 4, j + 2, k + 1, Blocks.air, 0, 2);
		world.setBlock(i + 5, j + 2, k + 1, Blocks.redstone_torch, 3, 2);
		world.setBlock(i + 6, j + 2, k + 1, Blocks.air, 0, 2);
		world.setBlock(i + 7, j + 2, k + 1, Blocks.redstone_torch, 3, 2);
		world.setBlock(i + 8, j + 2, k + 1, Blocks.air, 0, 2);
		world.setBlock(i + 9, j + 2, k + 1, NovaCraftBlocks.cobbled_grimstone, 0, 2);
		world.setBlock(i + 0, j + 2, k + 2, NovaCraftBlocks.cobbled_grimstone, 0, 2);
		world.setBlock(i + 1, j + 2, k + 2, Blocks.air, 0, 2);
		world.setBlock(i + 2, j + 2, k + 2, Blocks.air, 0, 2);
		world.setBlock(i + 6, j + 2, k + 2, Blocks.carpet, 14, 2);
		world.setBlock(i + 7, j + 2, k + 2, Blocks.air, 0, 2);
		world.setBlock(i + 8, j + 2, k + 2, Blocks.pumpkin, 1, 2);
		world.setBlock(i + 9, j + 2, k + 2, NovaCraftBlocks.cobbled_grimstone, 0, 2);
		world.setBlock(i + 0, j + 2, k + 3, NovaCraftBlocks.cobbled_grimstone, 0, 2);
		world.setBlock(i + 1, j + 2, k + 3, Blocks.air, 0, 2);
		world.setBlock(i + 2, j + 2, k + 3, Blocks.air, 0, 2);
		world.setBlock(i + 3, j + 2, k + 3, Blocks.redstone_torch, 4, 2);
		world.setBlock(i + 4, j + 2, k + 3, Blocks.air, 0, 2);
		world.setBlock(i + 5, j + 2, k + 3, Blocks.redstone_torch, 4, 2);
		world.setBlock(i + 6, j + 2, k + 3, Blocks.air, 0, 2);
		world.setBlock(i + 7, j + 2, k + 3, Blocks.redstone_torch, 4, 2);
		world.setBlock(i + 8, j + 2, k + 3, Blocks.air, 0, 2);
		world.setBlock(i + 9, j + 2, k + 3, NovaCraftBlocks.cobbled_grimstone, 0, 2);
		world.setBlock(i + 0, j + 2, k + 4, NovaCraftBlocks.cobbled_grimstone, 0, 2);
		world.setBlock(i + 1, j + 2, k + 4, NovaCraftBlocks.cobbled_grimstone, 0, 2);
		world.setBlock(i + 2, j + 2, k + 4, NovaCraftBlocks.cobbled_grimstone, 0, 2);
		world.setBlock(i + 3, j + 2, k + 4, NovaCraftBlocks.cobbled_grimstone, 0, 2);
		world.setBlock(i + 4, j + 2, k + 4, NovaCraftBlocks.cobbled_grimstone, 0, 2);
		world.setBlock(i + 5, j + 2, k + 4, NovaCraftBlocks.cobbled_grimstone, 0, 2);
		world.setBlock(i + 6, j + 2, k + 4, NovaCraftBlocks.cobbled_grimstone, 0, 2);
		world.setBlock(i + 7, j + 2, k + 4, NovaCraftBlocks.cobbled_grimstone, 0, 2);
		world.setBlock(i + 8, j + 2, k + 4, NovaCraftBlocks.cobbled_grimstone, 0, 2);
		world.setBlock(i + 9, j + 2, k + 4, NovaCraftBlocks.cobbled_grimstone, 0, 2);
		world.setBlock(i + 0, j + 3, k + 0, NovaCraftBlocks.cobbled_grimstone, 0, 2);
		world.setBlock(i + 1, j + 3, k + 0, NovaCraftBlocks.cobbled_grimstone, 0, 2);
		world.setBlock(i + 2, j + 3, k + 0, NovaCraftBlocks.cobbled_grimstone, 0, 2);
		world.setBlock(i + 3, j + 3, k + 0, NovaCraftBlocks.cobbled_grimstone, 0, 2);
		world.setBlock(i + 4, j + 3, k + 0, NovaCraftBlocks.cobbled_grimstone, 0, 2);
		world.setBlock(i + 5, j + 3, k + 0, NovaCraftBlocks.cobbled_grimstone, 0, 2);
		world.setBlock(i + 6, j + 3, k + 0, NovaCraftBlocks.cobbled_grimstone, 0, 2);
		world.setBlock(i + 7, j + 3, k + 0, NovaCraftBlocks.cobbled_grimstone, 0, 2);
		world.setBlock(i + 8, j + 3, k + 0, NovaCraftBlocks.cobbled_grimstone, 0, 2);
		world.setBlock(i + 9, j + 3, k + 0, NovaCraftBlocks.cobbled_grimstone, 0, 2);
		world.setBlock(i + 0, j + 3, k + 1, NovaCraftBlocks.cobbled_grimstone, 0, 2);
		world.setBlock(i + 1, j + 3, k + 1, NovaCraftBlocks.cobbled_grimstone, 0, 2);
		world.setBlock(i + 2, j + 3, k + 1, Blocks.ladder, 3, 2);
		world.setBlock(i + 3, j + 3, k + 1, Blocks.air, 0, 2);
		world.setBlock(i + 4, j + 3, k + 1, Blocks.air, 0, 2);
		world.setBlock(i + 5, j + 3, k + 1, Blocks.air, 0, 2);
		world.setBlock(i + 6, j + 3, k + 1, Blocks.air, 0, 2);
		world.setBlock(i + 7, j + 3, k + 1, Blocks.air, 0, 2);
		world.setBlock(i + 8, j + 3, k + 1, Blocks.air, 0, 2);
		world.setBlock(i + 9, j + 3, k + 1, NovaCraftBlocks.cobbled_grimstone, 0, 2);
		world.setBlock(i + 0, j + 3, k + 2, NovaCraftBlocks.cobbled_grimstone, 0, 2);
		world.setBlock(i + 1, j + 3, k + 2, Blocks.air, 0, 2);
		world.setBlock(i + 2, j + 3, k + 2, Blocks.air, 0, 2);
		world.setBlock(i + 3, j + 3, k + 2, Blocks.air, 0, 2);
		world.setBlock(i + 4, j + 3, k + 2, Blocks.air, 0, 2);
		world.setBlock(i + 5, j + 3, k + 2, Blocks.air, 0, 2);
		world.setBlock(i + 6, j + 3, k + 2, Blocks.air, 0, 2);
		world.setBlock(i + 7, j + 3, k + 2, Blocks.air, 0, 2);
		world.setBlock(i + 8, j + 3, k + 2, Blocks.air, 0, 2);
		world.setBlock(i + 9, j + 3, k + 2, NovaCraftBlocks.cobbled_grimstone, 0, 2);
		world.setBlock(i + 0, j + 3, k + 3, NovaCraftBlocks.cobbled_grimstone, 0, 2);
		world.setBlock(i + 1, j + 3, k + 3, Blocks.air, 0, 2);
		world.setBlock(i + 2, j + 3, k + 3, Blocks.air, 0, 2);
		world.setBlock(i + 3, j + 3, k + 3, Blocks.air, 0, 2);
		world.setBlock(i + 4, j + 3, k + 3, Blocks.air, 0, 2);
		world.setBlock(i + 5, j + 3, k + 3, Blocks.air, 0, 2);
		world.setBlock(i + 6, j + 3, k + 3, Blocks.air, 0, 2);
		world.setBlock(i + 7, j + 3, k + 3, Blocks.air, 0, 2);
		world.setBlock(i + 8, j + 3, k + 3, Blocks.air, 0, 2);
		world.setBlock(i + 9, j + 3, k + 3, NovaCraftBlocks.cobbled_grimstone, 0, 2);
		world.setBlock(i + 0, j + 3, k + 4, NovaCraftBlocks.cobbled_grimstone, 0, 2);
		world.setBlock(i + 1, j + 3, k + 4, NovaCraftBlocks.cobbled_grimstone, 0, 2);
		world.setBlock(i + 2, j + 3, k + 4, NovaCraftBlocks.cobbled_grimstone, 0, 2);
		world.setBlock(i + 3, j + 3, k + 4, NovaCraftBlocks.cobbled_grimstone, 0, 2);
		world.setBlock(i + 4, j + 3, k + 4, NovaCraftBlocks.cobbled_grimstone, 0, 2);
		world.setBlock(i + 5, j + 3, k + 4, NovaCraftBlocks.cobbled_grimstone, 0, 2);
		world.setBlock(i + 6, j + 3, k + 4, NovaCraftBlocks.cobbled_grimstone, 0, 2);
		world.setBlock(i + 7, j + 3, k + 4, NovaCraftBlocks.cobbled_grimstone, 0, 2);
		world.setBlock(i + 8, j + 3, k + 4, NovaCraftBlocks.cobbled_grimstone, 0, 2);
		world.setBlock(i + 9, j + 3, k + 4, NovaCraftBlocks.cobbled_grimstone, 0, 2);
		world.setBlock(i + 0, j + 4, k + 0, NovaCraftBlocks.cobbled_grimstone, 0, 2);
		world.setBlock(i + 1, j + 4, k + 0, NovaCraftBlocks.cobbled_grimstone, 0, 2);
		world.setBlock(i + 2, j + 4, k + 0, NovaCraftBlocks.cobbled_grimstone, 0, 2);
		world.setBlock(i + 3, j + 4, k + 0, NovaCraftBlocks.cobbled_grimstone, 0, 2);
		world.setBlock(i + 4, j + 4, k + 0, NovaCraftBlocks.cobbled_grimstone, 0, 2);
		world.setBlock(i + 5, j + 4, k + 0, NovaCraftBlocks.cobbled_grimstone, 0, 2);
		world.setBlock(i + 6, j + 4, k + 0, NovaCraftBlocks.cobbled_grimstone, 0, 2);
		world.setBlock(i + 7, j + 4, k + 0, NovaCraftBlocks.cobbled_grimstone, 0, 2);
		world.setBlock(i + 8, j + 4, k + 0, NovaCraftBlocks.cobbled_grimstone, 0, 2);
		world.setBlock(i + 9, j + 4, k + 0, NovaCraftBlocks.cobbled_grimstone, 0, 2);
		world.setBlock(i + 0, j + 4, k + 1, NovaCraftBlocks.cobbled_grimstone, 0, 2);
		world.setBlock(i + 1, j + 4, k + 1, NovaCraftBlocks.cobbled_grimstone, 0, 2);
		world.setBlock(i + 2, j + 4, k + 1, Blocks.ladder, 3, 2);
		world.setBlock(i + 3, j + 4, k + 1, NovaCraftBlocks.cobbled_grimstone, 0, 2);
		world.setBlock(i + 4, j + 4, k + 1, NovaCraftBlocks.cobbled_grimstone, 0, 2);
		world.setBlock(i + 5, j + 4, k + 1, NovaCraftBlocks.cobbled_grimstone, 0, 2);
		world.setBlock(i + 6, j + 4, k + 1, NovaCraftBlocks.cobbled_grimstone, 0, 2);
		world.setBlock(i + 7, j + 4, k + 1, NovaCraftBlocks.cobbled_grimstone, 0, 2);
		world.setBlock(i + 8, j + 4, k + 1, NovaCraftBlocks.cobbled_grimstone, 0, 2);
		world.setBlock(i + 9, j + 4, k + 1, NovaCraftBlocks.cobbled_grimstone, 0, 2);
		world.setBlock(i + 0, j + 4, k + 2, NovaCraftBlocks.cobbled_grimstone, 0, 2);
		world.setBlock(i + 1, j + 4, k + 2, NovaCraftBlocks.cobbled_grimstone, 0, 2);
		world.setBlock(i + 2, j + 4, k + 2, NovaCraftBlocks.cobbled_grimstone, 0, 2);
		world.setBlock(i + 3, j + 4, k + 2, NovaCraftBlocks.cobbled_grimstone, 0, 2);
		world.setBlock(i + 4, j + 4, k + 2, NovaCraftBlocks.cobbled_grimstone, 0, 2);
		world.setBlock(i + 5, j + 4, k + 2, NovaCraftBlocks.cobbled_grimstone, 0, 2);
		world.setBlock(i + 6, j + 4, k + 2, NovaCraftBlocks.cobbled_grimstone, 0, 2);
		world.setBlock(i + 7, j + 4, k + 2, NovaCraftBlocks.cobbled_grimstone, 0, 2);
		world.setBlock(i + 8, j + 4, k + 2, NovaCraftBlocks.cobbled_grimstone, 0, 2);
		world.setBlock(i + 9, j + 4, k + 2, NovaCraftBlocks.cobbled_grimstone, 0, 2);
		world.setBlock(i + 0, j + 4, k + 3, NovaCraftBlocks.cobbled_grimstone, 0, 2);
		world.setBlock(i + 1, j + 4, k + 3, NovaCraftBlocks.cobbled_grimstone, 0, 2);
		world.setBlock(i + 2, j + 4, k + 3, NovaCraftBlocks.cobbled_grimstone, 0, 2);
		world.setBlock(i + 3, j + 4, k + 3, NovaCraftBlocks.cobbled_grimstone, 0, 2);
		world.setBlock(i + 4, j + 4, k + 3, NovaCraftBlocks.cobbled_grimstone, 0, 2);
		world.setBlock(i + 5, j + 4, k + 3, NovaCraftBlocks.cobbled_grimstone, 0, 2);
		world.setBlock(i + 6, j + 4, k + 3, NovaCraftBlocks.cobbled_grimstone, 0, 2);
		world.setBlock(i + 7, j + 4, k + 3, NovaCraftBlocks.cobbled_grimstone, 0, 2);
		world.setBlock(i + 8, j + 4, k + 3, NovaCraftBlocks.cobbled_grimstone, 0, 2);
		world.setBlock(i + 9, j + 4, k + 3, NovaCraftBlocks.cobbled_grimstone, 0, 2);
		world.setBlock(i + 0, j + 4, k + 4, NovaCraftBlocks.cobbled_grimstone, 0, 2);
		world.setBlock(i + 1, j + 4, k + 4, NovaCraftBlocks.cobbled_grimstone, 0, 2);
		world.setBlock(i + 2, j + 4, k + 4, NovaCraftBlocks.cobbled_grimstone, 0, 2);
		world.setBlock(i + 3, j + 4, k + 4, NovaCraftBlocks.cobbled_grimstone, 0, 2);
		world.setBlock(i + 4, j + 4, k + 4, NovaCraftBlocks.cobbled_grimstone, 0, 2);
		world.setBlock(i + 5, j + 4, k + 4, NovaCraftBlocks.cobbled_grimstone, 0, 2);
		world.setBlock(i + 6, j + 4, k + 4, NovaCraftBlocks.cobbled_grimstone, 0, 2);
		world.setBlock(i + 7, j + 4, k + 4, NovaCraftBlocks.cobbled_grimstone, 0, 2);
		world.setBlock(i + 8, j + 4, k + 4, NovaCraftBlocks.cobbled_grimstone, 0, 2);
		world.setBlock(i + 9, j + 4, k + 4, NovaCraftBlocks.cobbled_grimstone, 0, 2);		
		world.setBlock(i + 3, j + 2, k + 2, Blocks.air, 0, 2);
		world.setBlock(i + 4, j + 2, k + 2, Blocks.air, 0, 2);
		world.setBlock(i + 5, j + 2, k + 2, Blocks.air, 0, 2);
		
		int random2 = rand.nextInt(24);
		if (random2 >= 20) {
			EntityVindicator entity = new EntityVindicator(world);
			entity.setPosition(i + 3, j + 2, k + 2);
			world.spawnEntityInWorld(entity);
		
			EntityVindicator entity2 = new EntityVindicator(world);
			entity2.setPosition(i + 4, j + 2, k + 2);
			world.spawnEntityInWorld(entity2);
		
			EntityVindicator entity3 = new EntityVindicator(world);
			entity3.setPosition(i + 5, j + 2, k + 2);
			world.spawnEntityInWorld(entity3);
		}
		else if (random2 > 10 && random2 < 20) {
			EntityVindicator entity = new EntityVindicator(world);
			entity.setPosition(i + 3, j + 2, k + 2);
			world.spawnEntityInWorld(entity);
		
			EntityVindicator entity2 = new EntityVindicator(world);
			entity2.setPosition(i + 4, j + 2, k + 2);
			world.spawnEntityInWorld(entity2);
		}
		else {
			EntityVindicator entity = new EntityVindicator(world);
			entity.setPosition(i + 3, j + 2, k + 2);
			world.spawnEntityInWorld(entity);
		}
		}
		else {
		
		world.setBlock(i + 0, j + 0, k + 0, NovaCraftBlocks.cobbled_grimstone, 0, 2);
		world.setBlock(i + 1, j + 0, k + 0, NovaCraftBlocks.cobbled_grimstone, 0, 2);
		world.setBlock(i + 2, j + 0, k + 0, NovaCraftBlocks.cobbled_grimstone, 0, 2);
		world.setBlock(i + 3, j + 0, k + 0, NovaCraftBlocks.cobbled_grimstone, 0, 2);
		world.setBlock(i + 4, j + 0, k + 0, NovaCraftBlocks.cobbled_grimstone, 0, 2);
		world.setBlock(i + 5, j + 0, k + 0, NovaCraftBlocks.cobbled_grimstone, 0, 2);
		world.setBlock(i + 6, j + 0, k + 0, NovaCraftBlocks.cobbled_grimstone, 0, 2);
		world.setBlock(i + 7, j + 0, k + 0, NovaCraftBlocks.cobbled_grimstone, 0, 2);
		world.setBlock(i + 8, j + 0, k + 0, NovaCraftBlocks.cobbled_grimstone, 0, 2);
		world.setBlock(i + 9, j + 0, k + 0, NovaCraftBlocks.cobbled_grimstone, 0, 2);
		world.setBlock(i + 10, j + 0, k + 0, NovaCraftBlocks.cobbled_grimstone, 0, 2);
		world.setBlock(i + 11, j + 0, k + 0, NovaCraftBlocks.cobbled_grimstone, 0, 2);
		world.setBlock(i + 12, j + 0, k + 0, NovaCraftBlocks.cobbled_grimstone, 0, 2);
		world.setBlock(i + 0, j + 0, k + 1, NovaCraftBlocks.cobbled_grimstone, 0, 2);
		world.setBlock(i + 1, j + 0, k + 1, NovaCraftBlocks.cobbled_grimstone, 0, 2);
		world.setBlock(i + 2, j + 0, k + 1, NovaCraftBlocks.cobbled_grimstone, 0, 2);
		world.setBlock(i + 3, j + 0, k + 1, NovaCraftBlocks.cobbled_grimstone, 0, 2);
		world.setBlock(i + 4, j + 0, k + 1, NovaCraftBlocks.cobbled_grimstone, 0, 2);
		world.setBlock(i + 5, j + 0, k + 1, NovaCraftBlocks.cobbled_grimstone, 0, 2);
		world.setBlock(i + 6, j + 0, k + 1, NovaCraftBlocks.cobbled_grimstone, 0, 2);
		world.setBlock(i + 7, j + 0, k + 1, NovaCraftBlocks.cobbled_grimstone, 0, 2);
		world.setBlock(i + 8, j + 0, k + 1, NovaCraftBlocks.cobbled_grimstone, 0, 2);
		world.setBlock(i + 9, j + 0, k + 1, NovaCraftBlocks.cobbled_grimstone, 0, 2);
		world.setBlock(i + 10, j + 0, k + 1, NovaCraftBlocks.cobbled_grimstone, 0, 2);
		world.setBlock(i + 11, j + 0, k + 1, NovaCraftBlocks.cobbled_grimstone, 0, 2);
		world.setBlock(i + 12, j + 0, k + 1, NovaCraftBlocks.cobbled_grimstone, 0, 2);
		world.setBlock(i + 0, j + 0, k + 2, NovaCraftBlocks.cobbled_grimstone, 0, 2);
		world.setBlock(i + 1, j + 0, k + 2, NovaCraftBlocks.cobbled_grimstone, 0, 2);
		world.setBlock(i + 2, j + 0, k + 2, NovaCraftBlocks.cobbled_grimstone, 0, 2);
		world.setBlock(i + 3, j + 0, k + 2, NovaCraftBlocks.cobbled_grimstone, 0, 2);
		world.setBlock(i + 4, j + 0, k + 2, NovaCraftBlocks.cobbled_grimstone, 0, 2);
		world.setBlock(i + 5, j + 0, k + 2, NovaCraftBlocks.cobbled_grimstone, 0, 2);
		world.setBlock(i + 6, j + 0, k + 2, NovaCraftBlocks.sculk_block, 0, 2);
		world.setBlock(i + 7, j + 0, k + 2, NovaCraftBlocks.sculk_block, 0, 2);
		world.setBlock(i + 8, j + 0, k + 2, NovaCraftBlocks.sculk_block, 0, 2);
		world.setBlock(i + 9, j + 0, k + 2, NovaCraftBlocks.sculk_block, 0, 2);
		world.setBlock(i + 10, j + 0, k + 2, NovaCraftBlocks.sculk_block, 0, 2);
		world.setBlock(i + 11, j + 0, k + 2, NovaCraftBlocks.cobbled_grimstone, 0, 2);
		world.setBlock(i + 12, j + 0, k + 2, NovaCraftBlocks.cobbled_grimstone, 0, 2);
		world.setBlock(i + 0, j + 0, k + 3, NovaCraftBlocks.cobbled_grimstone, 0, 2);
		world.setBlock(i + 1, j + 0, k + 3, NovaCraftBlocks.cobbled_grimstone, 0, 2);
		world.setBlock(i + 2, j + 0, k + 3, NovaCraftBlocks.cobbled_grimstone, 0, 2);
		world.setBlock(i + 3, j + 0, k + 3, NovaCraftBlocks.cobbled_grimstone, 0, 2);
		world.setBlock(i + 4, j + 0, k + 3, NovaCraftBlocks.cobbled_grimstone, 0, 2);
		world.setBlock(i + 5, j + 0, k + 3, NovaCraftBlocks.cobbled_grimstone, 0, 2);
		world.setBlock(i + 6, j + 0, k + 3, NovaCraftBlocks.cobbled_grimstone, 0, 2);
		world.setBlock(i + 7, j + 0, k + 3, NovaCraftBlocks.sculk_block, 0, 2);
		world.setBlock(i + 8, j + 0, k + 3, NovaCraftBlocks.sculk_block, 0, 2);
		world.setBlock(i + 9, j + 0, k + 3, NovaCraftBlocks.sculk_block, 0, 2);
		world.setBlock(i + 10, j + 0, k + 3, NovaCraftBlocks.sculk_block, 0, 2);
		world.setBlock(i + 11, j + 0, k + 3, NovaCraftBlocks.cobbled_grimstone, 0, 2);
		world.setBlock(i + 12, j + 0, k + 3, NovaCraftBlocks.cobbled_grimstone, 0, 2);
		world.setBlock(i + 0, j + 0, k + 4, NovaCraftBlocks.cobbled_grimstone, 0, 2);
		world.setBlock(i + 1, j + 0, k + 4, NovaCraftBlocks.cobbled_grimstone, 0, 2);
		world.setBlock(i + 2, j + 0, k + 4, NovaCraftBlocks.sculk_block, 0, 2);
		world.setBlock(i + 3, j + 0, k + 4, NovaCraftBlocks.cobbled_grimstone, 0, 2);
		world.setBlock(i + 4, j + 0, k + 4, NovaCraftBlocks.cobbled_grimstone, 0, 2);
		world.setBlock(i + 5, j + 0, k + 4, NovaCraftBlocks.cobbled_grimstone, 0, 2);
		world.setBlock(i + 6, j + 0, k + 4, NovaCraftBlocks.cobbled_grimstone, 0, 2);
		world.setBlock(i + 7, j + 0, k + 4, NovaCraftBlocks.cobbled_grimstone, 0, 2);
		world.setBlock(i + 8, j + 0, k + 4, NovaCraftBlocks.sculk_block, 0, 2);
		world.setBlock(i + 9, j + 0, k + 4, NovaCraftBlocks.cobbled_grimstone, 0, 2);
		world.setBlock(i + 10, j + 0, k + 4, NovaCraftBlocks.cobbled_grimstone, 0, 2);
		world.setBlock(i + 11, j + 0, k + 4, NovaCraftBlocks.cobbled_grimstone, 0, 2);
		world.setBlock(i + 12, j + 0, k + 4, NovaCraftBlocks.cobbled_grimstone, 0, 2);
		world.setBlock(i + 0, j + 0, k + 5, NovaCraftBlocks.cobbled_grimstone, 0, 2);
		world.setBlock(i + 1, j + 0, k + 5, NovaCraftBlocks.cobbled_grimstone, 0, 2);
		world.setBlock(i + 2, j + 0, k + 5, NovaCraftBlocks.sculk_block, 0, 2);
		world.setBlock(i + 3, j + 0, k + 5, NovaCraftBlocks.sculk_block, 0, 2);
		world.setBlock(i + 4, j + 0, k + 5, NovaCraftBlocks.cobbled_grimstone, 0, 2);
		world.setBlock(i + 5, j + 0, k + 5, NovaCraftBlocks.cobbled_grimstone, 0, 2);
		world.setBlock(i + 6, j + 0, k + 5, NovaCraftBlocks.sculk_block, 0, 2);
		world.setBlock(i + 7, j + 0, k + 5, NovaCraftBlocks.cobbled_grimstone, 0, 2);
		world.setBlock(i + 8, j + 0, k + 5, NovaCraftBlocks.cobbled_grimstone, 0, 2);
		world.setBlock(i + 9, j + 0, k + 5, NovaCraftBlocks.cobbled_grimstone, 0, 2);
		world.setBlock(i + 10, j + 0, k + 5, NovaCraftBlocks.cobbled_grimstone, 0, 2);
		world.setBlock(i + 11, j + 0, k + 5, NovaCraftBlocks.cobbled_grimstone, 0, 2);
		world.setBlock(i + 12, j + 0, k + 5, NovaCraftBlocks.cobbled_grimstone, 0, 2);
		world.setBlock(i + 0, j + 0, k + 6, NovaCraftBlocks.cobbled_grimstone, 0, 2);
		world.setBlock(i + 1, j + 0, k + 6, NovaCraftBlocks.cobbled_grimstone, 0, 2);
		world.setBlock(i + 2, j + 0, k + 6, NovaCraftBlocks.sculk_block, 0, 2);
		world.setBlock(i + 3, j + 0, k + 6, NovaCraftBlocks.cobbled_grimstone, 0, 2);
		world.setBlock(i + 4, j + 0, k + 6, NovaCraftBlocks.cobbled_grimstone, 0, 2);
		world.setBlock(i + 5, j + 0, k + 6, NovaCraftBlocks.cobbled_grimstone, 0, 2);
		world.setBlock(i + 6, j + 0, k + 6, NovaCraftBlocks.cobbled_grimstone, 0, 2);
		world.setBlock(i + 7, j + 0, k + 6, NovaCraftBlocks.sculk_block, 0, 2);
		world.setBlock(i + 8, j + 0, k + 6, NovaCraftBlocks.sculk_block, 0, 2);
		world.setBlock(i + 9, j + 0, k + 6, NovaCraftBlocks.sculk_block, 0, 2);
		world.setBlock(i + 10, j + 0, k + 6, NovaCraftBlocks.cobbled_grimstone, 0, 2);
		world.setBlock(i + 11, j + 0, k + 6, NovaCraftBlocks.cobbled_grimstone, 0, 2);
		world.setBlock(i + 12, j + 0, k + 6, NovaCraftBlocks.cobbled_grimstone, 0, 2);
		world.setBlock(i + 0, j + 0, k + 7, NovaCraftBlocks.cobbled_grimstone, 0, 2);
		world.setBlock(i + 1, j + 0, k + 7, NovaCraftBlocks.cobbled_grimstone, 0, 2);
		world.setBlock(i + 2, j + 0, k + 7, NovaCraftBlocks.cobbled_grimstone, 0, 2);
		world.setBlock(i + 3, j + 0, k + 7, NovaCraftBlocks.cobbled_grimstone, 0, 2);
		world.setBlock(i + 4, j + 0, k + 7, NovaCraftBlocks.cobbled_grimstone, 0, 2);
		world.setBlock(i + 5, j + 0, k + 7, NovaCraftBlocks.sculk_block, 0, 2);
		world.setBlock(i + 6, j + 0, k + 7, NovaCraftBlocks.cobbled_grimstone, 0, 2);
		world.setBlock(i + 7, j + 0, k + 7, NovaCraftBlocks.cobbled_grimstone, 0, 2);
		world.setBlock(i + 8, j + 0, k + 7, NovaCraftBlocks.cobbled_grimstone, 0, 2);
		world.setBlock(i + 9, j + 0, k + 7, NovaCraftBlocks.cobbled_grimstone, 0, 2);
		world.setBlock(i + 10, j + 0, k + 7, NovaCraftBlocks.cobbled_grimstone, 0, 2);
		world.setBlock(i + 11, j + 0, k + 7, NovaCraftBlocks.cobbled_grimstone, 0, 2);
		world.setBlock(i + 12, j + 0, k + 7, NovaCraftBlocks.cobbled_grimstone, 0, 2);
		world.setBlock(i + 0, j + 0, k + 8, NovaCraftBlocks.cobbled_grimstone, 0, 2);
		world.setBlock(i + 1, j + 0, k + 8, NovaCraftBlocks.cobbled_grimstone, 0, 2);
		world.setBlock(i + 2, j + 0, k + 8, NovaCraftBlocks.cobbled_grimstone, 0, 2);
		world.setBlock(i + 3, j + 0, k + 8, NovaCraftBlocks.cobbled_grimstone, 0, 2);
		world.setBlock(i + 4, j + 0, k + 8, NovaCraftBlocks.cobbled_grimstone, 0, 2);
		world.setBlock(i + 5, j + 0, k + 8, NovaCraftBlocks.cobbled_grimstone, 0, 2);
		world.setBlock(i + 6, j + 0, k + 8, NovaCraftBlocks.cobbled_grimstone, 0, 2);
		world.setBlock(i + 7, j + 0, k + 8, NovaCraftBlocks.cobbled_grimstone, 0, 2);
		world.setBlock(i + 8, j + 0, k + 8, NovaCraftBlocks.cobbled_grimstone, 0, 2);
		world.setBlock(i + 9, j + 0, k + 8, NovaCraftBlocks.cobbled_grimstone, 0, 2);
		world.setBlock(i + 10, j + 0, k + 8, NovaCraftBlocks.cobbled_grimstone, 0, 2);
		world.setBlock(i + 11, j + 0, k + 8, NovaCraftBlocks.cobbled_grimstone, 0, 2);
		world.setBlock(i + 12, j + 0, k + 8, NovaCraftBlocks.cobbled_grimstone, 0, 2);
		world.setBlock(i + 0, j + 1, k + 0, NovaCraftBlocks.cobbled_grimstone, 0, 2);
		world.setBlock(i + 1, j + 1, k + 0, NovaCraftBlocks.cobbled_grimstone, 0, 2);
		world.setBlock(i + 2, j + 1, k + 0, NovaCraftBlocks.cobbled_grimstone, 0, 2);
		world.setBlock(i + 3, j + 1, k + 0, NovaCraftBlocks.cobbled_grimstone, 0, 2);
		world.setBlock(i + 4, j + 1, k + 0, NovaCraftBlocks.cobbled_grimstone, 0, 2);
		world.setBlock(i + 5, j + 1, k + 0, NovaCraftBlocks.cobbled_grimstone, 0, 2);
		world.setBlock(i + 6, j + 1, k + 0, NovaCraftBlocks.cobbled_grimstone, 0, 2);
		world.setBlock(i + 7, j + 1, k + 0, NovaCraftBlocks.cobbled_grimstone, 0, 2);
		world.setBlock(i + 8, j + 1, k + 0, NovaCraftBlocks.cobbled_grimstone, 0, 2);
		world.setBlock(i + 9, j + 1, k + 0, NovaCraftBlocks.cobbled_grimstone, 0, 2);
		world.setBlock(i + 10, j + 1, k + 0, NovaCraftBlocks.cobbled_grimstone, 0, 2);
		world.setBlock(i + 11, j + 1, k + 0, NovaCraftBlocks.cobbled_grimstone, 0, 2);
		world.setBlock(i + 12, j + 1, k + 0, NovaCraftBlocks.cobbled_grimstone, 0, 2);
		world.setBlock(i + 0, j + 1, k + 1, NovaCraftBlocks.cobbled_grimstone, 0, 2);
		world.setBlock(i + 1, j + 1, k + 1, Blocks.air, 0, 2);
		world.setBlock(i + 2, j + 1, k + 1, Blocks.ladder, 3, 2);
		world.setBlock(i + 3, j + 1, k + 1, Blocks.air, 0, 2);
		world.setBlock(i + 4, j + 1, k + 1, Blocks.air, 0, 2);
		world.setBlock(i + 5, j + 1, k + 1, Blocks.air, 0, 2);
		world.setBlock(i + 6, j + 1, k + 1, NovaCraftBlocks.sculk_block, 0, 2);
		world.setBlock(i + 7, j + 1, k + 1, NovaCraftBlocks.sculk_block, 0, 2);
		world.setBlock(i + 8, j + 1, k + 1, NovaCraftBlocks.sculk_block, 0, 2);
		world.setBlock(i + 9, j + 1, k + 1, Blocks.air, 0, 2);
		world.setBlock(i + 10, j + 1, k + 1, NovaCraftBlocks.sculk_block, 0, 2);
		world.setBlock(i + 11, j + 1, k + 1, NovaCraftBlocks.sculk_block, 0, 2);
		world.setBlock(i + 12, j + 1, k + 1, NovaCraftBlocks.cobbled_grimstone, 0, 2);
		world.setBlock(i + 0, j + 1, k + 2, NovaCraftBlocks.cobbled_grimstone, 0, 2);
		world.setBlock(i + 1, j + 1, k + 2, NovaCraftBlocks.cobbled_grimstone_stairs, 1, 2);
		world.setBlock(i + 2, j + 1, k + 2, Blocks.air, 0, 2);
		world.setBlock(i + 3, j + 1, k + 2, Blocks.air, 0, 2);
		world.setBlock(i + 4, j + 1, k + 2, NovaCraftBlocks.cobbled_grimstone_stairs, 1, 2);
		world.setBlock(i + 5, j + 1, k + 2, Blocks.air, 0, 2);
		world.setBlock(i + 6, j + 1, k + 2, Blocks.air, 0, 2);
		world.setBlock(i + 7, j + 1, k + 2, NovaCraftBlocks.sculk_block, 0, 2);
		world.setBlock(i + 8, j + 1, k + 2, Blocks.air, 0, 2);
		world.setBlock(i + 9, j + 1, k + 2, Blocks.air, 0, 2);
		world.setBlock(i + 10, j + 1, k + 2, Blocks.air, 0, 2);
		world.setBlock(i + 11, j + 1, k + 2, Blocks.bookshelf, 0, 2);
		world.setBlock(i + 12, j + 1, k + 2, NovaCraftBlocks.cobbled_grimstone, 0, 2);
		world.setBlock(i + 0, j + 1, k + 3, NovaCraftBlocks.cobbled_grimstone, 0, 2);
		world.setBlock(i + 1, j + 1, k + 3, NovaCraftBlocks.sculk_block, 0, 2);
		world.setBlock(i + 2, j + 1, k + 3, Blocks.air, 0, 2);
		world.setBlock(i + 3, j + 1, k + 3, Blocks.air, 0, 2);
		world.setBlock(i + 4, j + 1, k + 3, Blocks.air, 0, 2);
		world.setBlock(i + 5, j + 1, k + 3, Blocks.air, 0, 2);
		world.setBlock(i + 6, j + 1, k + 3, Blocks.air, 0, 2);
		world.setBlock(i + 7, j + 1, k + 3, Blocks.air, 0, 2);
		world.setBlock(i + 8, j + 1, k + 3, Blocks.air, 0, 2);
		world.setBlock(i + 9, j + 1, k + 3, Blocks.air, 0, 2);
		world.setBlock(i + 10, j + 1, k + 3, Blocks.air, 0, 2);
		world.setBlock(i + 11, j + 1, k + 3, Blocks.air, 0, 2);
		world.setBlock(i + 12, j + 1, k + 3, NovaCraftBlocks.cobbled_grimstone, 0, 2);
		world.setBlock(i + 0, j + 1, k + 4, NovaCraftBlocks.cobbled_grimstone, 0, 2);
		world.setBlock(i + 1, j + 1, k + 4, NovaCraftBlocks.sculk_block, 0, 2);
		world.setBlock(i + 2, j + 1, k + 4, NovaCraftBlocks.sculk_block, 0, 2);
		world.setBlock(i + 3, j + 1, k + 4, Blocks.air, 0, 2);
		world.setBlock(i + 5, j + 1, k + 4, Blocks.air, 0, 2);
		world.setBlock(i + 7, j + 1, k + 4, Blocks.air, 0, 2);
		world.setBlock(i + 9, j + 1, k + 4, Blocks.air, 0, 2);
		world.setBlock(i + 10, j + 1, k + 4, NovaCraftBlocks.cobbled_nullstone, 0, 2);
		world.setBlock(i + 11, j + 1, k + 4, Blocks.air, 0, 2);
		world.setBlock(i + 12, j + 1, k + 4, NovaCraftBlocks.cobbled_grimstone, 0, 2);
		world.setBlock(i + 0, j + 1, k + 5, NovaCraftBlocks.cobbled_grimstone, 0, 2);
		world.setBlock(i + 1, j + 1, k + 5, NovaCraftBlocks.sculk_block, 0, 2);
		world.setBlock(i + 2, j + 1, k + 5, NovaCraftBlocks.sculk_block, 0, 2);
		world.setBlock(i + 3, j + 1, k + 5, Blocks.air, 0, 2);
		world.setBlock(i + 4, j + 1, k + 5, Blocks.air, 0, 2);
		world.setBlock(i + 5, j + 1, k + 5, Blocks.air, 0, 2);
		world.setBlock(i + 6, j + 1, k + 5, Blocks.air, 0, 2);
		world.setBlock(i + 7, j + 1, k + 5, Blocks.air, 0, 2);
		world.setBlock(i + 8, j + 1, k + 5, Blocks.air, 0, 2);
		world.setBlock(i + 9, j + 1, k + 5, Blocks.air, 0, 2);
		world.setBlock(i + 10, j + 1, k + 5, Blocks.air, 0, 2);
		world.setBlock(i + 11, j + 1, k + 5, Blocks.bookshelf, 0, 2);
		world.setBlock(i + 12, j + 1, k + 5, NovaCraftBlocks.cobbled_grimstone, 0, 2);
		world.setBlock(i + 0, j + 1, k + 6, NovaCraftBlocks.cobbled_grimstone, 0, 2);
		world.setBlock(i + 1, j + 1, k + 6, NovaCraftBlocks.sculk_block, 0, 2);
		world.setBlock(i + 2, j + 1, k + 6, Blocks.air, 0, 2);
		world.setBlock(i + 3, j + 1, k + 6, Blocks.air, 0, 2);
		world.setBlock(i + 4, j + 1, k + 6, NovaCraftBlocks.cobbled_grimstone_stairs, 1, 2);
		world.setBlock(i + 5, j + 1, k + 6, Blocks.air, 0, 2);
		world.setBlock(i + 6, j + 1, k + 6, NovaCraftBlocks.sculk_block, 0, 2);
		world.setBlock(i + 7, j + 1, k + 6, NovaCraftBlocks.cobbled_grimstone_stairs, 1, 2);
		world.setBlock(i + 8, j + 1, k + 6, Blocks.air, 0, 2);
		world.setBlock(i + 9, j + 1, k + 6, Blocks.air, 0, 2);
		world.setBlock(i + 10, j + 1, k + 6, Blocks.air, 0, 2);
		world.setBlock(i + 11, j + 1, k + 6, Blocks.bookshelf, 0, 2);
		world.setBlock(i + 12, j + 1, k + 6, NovaCraftBlocks.cobbled_grimstone, 0, 2);
		world.setBlock(i + 0, j + 1, k + 7, NovaCraftBlocks.cobbled_grimstone, 0, 2);
		world.setBlock(i + 1, j + 1, k + 7, NovaCraftBlocks.cobbled_grimstone_stairs, 1, 2);
		world.setBlock(i + 2, j + 1, k + 7, Blocks.air, 0, 2);
		world.setBlock(i + 3, j + 1, k + 7, Blocks.air, 0, 2);
		world.setBlock(i + 4, j + 1, k + 7, NovaCraftBlocks.cobbled_grimstone_stairs, 1, 2);
		world.setBlock(i + 5, j + 1, k + 7, Blocks.air, 0, 2);
		world.setBlock(i + 6, j + 1, k + 7, NovaCraftBlocks.sculk_block, 0, 2);
		world.setBlock(i + 7, j + 1, k + 7, NovaCraftBlocks.sculk_block, 0, 2);
		world.setBlock(i + 8, j + 1, k + 7, Blocks.air, 0, 2);
		world.setBlock(i + 9, j + 1, k + 7, Blocks.air, 0, 2);
		world.setBlock(i + 10, j + 1, k + 7, Blocks.air, 0, 2);
		world.setBlock(i + 11, j + 1, k + 7, NovaCraftBlocks.sculk_block, 0, 2);
		world.setBlock(i + 12, j + 1, k + 7, NovaCraftBlocks.cobbled_grimstone, 0, 2);
		world.setBlock(i + 0, j + 1, k + 8, NovaCraftBlocks.cobbled_grimstone, 0, 2);
		world.setBlock(i + 1, j + 1, k + 8, NovaCraftBlocks.cobbled_grimstone, 0, 2);
		world.setBlock(i + 2, j + 1, k + 8, NovaCraftBlocks.cobbled_grimstone, 0, 2);
		world.setBlock(i + 3, j + 1, k + 8, NovaCraftBlocks.cobbled_grimstone, 0, 2);
		world.setBlock(i + 4, j + 1, k + 8, NovaCraftBlocks.cobbled_grimstone, 0, 2);
		world.setBlock(i + 5, j + 1, k + 8, NovaCraftBlocks.cobbled_grimstone, 0, 2);
		world.setBlock(i + 6, j + 1, k + 8, NovaCraftBlocks.cobbled_grimstone, 0, 2);
		world.setBlock(i + 7, j + 1, k + 8, NovaCraftBlocks.cobbled_grimstone, 0, 2);
		world.setBlock(i + 8, j + 1, k + 8, NovaCraftBlocks.cobbled_grimstone, 0, 2);
		world.setBlock(i + 9, j + 1, k + 8, NovaCraftBlocks.cobbled_grimstone, 0, 2);
		world.setBlock(i + 10, j + 1, k + 8, NovaCraftBlocks.cobbled_grimstone, 0, 2);
		world.setBlock(i + 11, j + 1, k + 8, NovaCraftBlocks.cobbled_grimstone, 0, 2);
		world.setBlock(i + 12, j + 1, k + 8, NovaCraftBlocks.cobbled_grimstone, 0, 2);
		world.setBlock(i + 0, j + 2, k + 0, NovaCraftBlocks.cobbled_grimstone, 0, 2);
		world.setBlock(i + 1, j + 2, k + 0, NovaCraftBlocks.cobbled_grimstone, 0, 2);
		world.setBlock(i + 2, j + 2, k + 0, NovaCraftBlocks.cobbled_grimstone, 0, 2);
		world.setBlock(i + 3, j + 2, k + 0, NovaCraftBlocks.cobbled_grimstone, 0, 2);
		world.setBlock(i + 4, j + 2, k + 0, NovaCraftBlocks.cobbled_grimstone, 0, 2);
		world.setBlock(i + 5, j + 2, k + 0, NovaCraftBlocks.cobbled_grimstone, 0, 2);
		world.setBlock(i + 6, j + 2, k + 0, NovaCraftBlocks.cobbled_grimstone, 0, 2);
		world.setBlock(i + 7, j + 2, k + 0, NovaCraftBlocks.cobbled_grimstone, 0, 2);
		world.setBlock(i + 8, j + 2, k + 0, NovaCraftBlocks.cobbled_grimstone, 0, 2);
		world.setBlock(i + 9, j + 2, k + 0, NovaCraftBlocks.cobbled_grimstone, 0, 2);
		world.setBlock(i + 10, j + 2, k + 0, NovaCraftBlocks.cobbled_grimstone, 0, 2);
		world.setBlock(i + 11, j + 2, k + 0, NovaCraftBlocks.cobbled_grimstone, 0, 2);
		world.setBlock(i + 12, j + 2, k + 0, NovaCraftBlocks.cobbled_grimstone, 0, 2);
		world.setBlock(i + 0, j + 2, k + 1, NovaCraftBlocks.cobbled_grimstone, 0, 2);
		world.setBlock(i + 1, j + 2, k + 1, Blocks.air, 0, 2);
		world.setBlock(i + 2, j + 2, k + 1, Blocks.ladder, 3, 2);
		world.setBlock(i + 3, j + 2, k + 1, Blocks.redstone_torch, 3, 2);
		world.setBlock(i + 4, j + 2, k + 1, Blocks.air, 0, 2);
		world.setBlock(i + 5, j + 2, k + 1, Blocks.air, 0, 2);
		world.setBlock(i + 6, j + 2, k + 1, Blocks.redstone_torch, 3, 2);
		world.setBlock(i + 7, j + 2, k + 1, NovaCraftBlocks.sculk_block, 0, 2);
		world.setBlock(i + 8, j + 2, k + 1, Blocks.air, 0, 2);
		world.setBlock(i + 9, j + 2, k + 1, Blocks.redstone_torch, 3, 2);
		world.setBlock(i + 10, j + 2, k + 1, Blocks.air, 0, 2);
		world.setBlock(i + 11, j + 2, k + 1, Blocks.air, 0, 2);
		world.setBlock(i + 12, j + 2, k + 1, NovaCraftBlocks.cobbled_grimstone, 0, 2);
		world.setBlock(i + 0, j + 2, k + 2, NovaCraftBlocks.cobbled_grimstone, 0, 2);
		world.setBlock(i + 1, j + 2, k + 2, Blocks.air, 0, 2);
		world.setBlock(i + 2, j + 2, k + 2, Blocks.air, 0, 2);
		world.setBlock(i + 3, j + 2, k + 2, Blocks.air, 0, 2);
		world.setBlock(i + 4, j + 2, k + 2, Blocks.air, 0, 2);
		world.setBlock(i + 5, j + 2, k + 2, Blocks.air, 0, 2);
		world.setBlock(i + 6, j + 2, k + 2, Blocks.air, 0, 2);
		world.setBlock(i + 7, j + 2, k + 2, Blocks.air, 0, 2);
		world.setBlock(i + 8, j + 2, k + 2, Blocks.air, 0, 2);
		world.setBlock(i + 9, j + 2, k + 2, Blocks.air, 0, 2);
		world.setBlock(i + 10, j + 2, k + 2, Blocks.air, 0, 2);
		world.setBlock(i + 11, j + 2, k + 2, Blocks.air, 0, 2);
		world.setBlock(i + 12, j + 2, k + 2, NovaCraftBlocks.cobbled_grimstone, 0, 2);
		world.setBlock(i + 0, j + 2, k + 3, NovaCraftBlocks.cobbled_grimstone, 0, 2);
		world.setBlock(i + 1, j + 2, k + 3, Blocks.air, 0, 2);
		world.setBlock(i + 2, j + 2, k + 3, Blocks.air, 0, 2);
		world.setBlock(i + 3, j + 2, k + 3, Blocks.air, 0, 2);
		world.setBlock(i + 4, j + 2, k + 3, Blocks.air, 0, 2);
		world.setBlock(i + 5, j + 2, k + 3, Blocks.air, 0, 2);
		world.setBlock(i + 6, j + 2, k + 3, Blocks.air, 0, 2);
		world.setBlock(i + 7, j + 2, k + 3, Blocks.air, 0, 2);
		world.setBlock(i + 8, j + 2, k + 3, Blocks.air, 0, 2);
		world.setBlock(i + 9, j + 2, k + 3, Blocks.air, 0, 2);
		world.setBlock(i + 10, j + 2, k + 3, Blocks.air, 0, 2);
		world.setBlock(i + 11, j + 2, k + 3, Blocks.air, 0, 2);
		world.setBlock(i + 12, j + 2, k + 3, NovaCraftBlocks.cobbled_grimstone, 0, 2);
		world.setBlock(i + 0, j + 2, k + 4, NovaCraftBlocks.cobbled_grimstone, 0, 2);
		world.setBlock(i + 1, j + 2, k + 4, NovaCraftBlocks.sculk_block, 0, 2);
		world.setBlock(i + 2, j + 2, k + 4, Blocks.air, 0, 2);
		world.setBlock(i + 3, j + 2, k + 4, Blocks.air, 0, 2);
		world.setBlock(i + 4, j + 2, k + 4, Blocks.air, 0, 2);
		world.setBlock(i + 5, j + 2, k + 4, Blocks.air, 0, 2);
		world.setBlock(i + 6, j + 2, k + 4, Blocks.air, 0, 2);
		world.setBlock(i + 7, j + 2, k + 4, Blocks.air, 0, 2);
		world.setBlock(i + 8, j + 2, k + 4, Blocks.air, 0, 2);
		world.setBlock(i + 9, j + 2, k + 4, Blocks.air, 0, 2);
		world.setBlock(i + 10, j + 2, k + 4, Block.getBlockById(86), 1, 2);
		world.setBlock(i + 11, j + 2, k + 4, Blocks.air, 0, 2);
		world.setBlock(i + 12, j + 2, k + 4, NovaCraftBlocks.cobbled_grimstone, 0, 2);
		world.setBlock(i + 0, j + 2, k + 5, NovaCraftBlocks.cobbled_grimstone, 0, 2);
		world.setBlock(i + 1, j + 2, k + 5, NovaCraftBlocks.sculk_block, 0, 2);
		world.setBlock(i + 2, j + 2, k + 5, Blocks.air, 0, 2);
		world.setBlock(i + 3, j + 2, k + 5, Blocks.air, 0, 2);
		world.setBlock(i + 4, j + 2, k + 5, Blocks.air, 0, 2);
		world.setBlock(i + 5, j + 2, k + 5, Blocks.air, 0, 2);
		world.setBlock(i + 6, j + 2, k + 5, Blocks.air, 0, 2);
		world.setBlock(i + 7, j + 2, k + 5, Blocks.air, 0, 2);
		world.setBlock(i + 8, j + 2, k + 5, Blocks.air, 0, 2);
		world.setBlock(i + 9, j + 2, k + 5, Blocks.air, 0, 2);
		world.setBlock(i + 10, j + 2, k + 5, Blocks.air, 0, 2);
		world.setBlock(i + 11, j + 2, k + 5, Blocks.air, 0, 2);
		world.setBlock(i + 12, j + 2, k + 5, NovaCraftBlocks.cobbled_grimstone, 0, 2);
		world.setBlock(i + 0, j + 2, k + 6, NovaCraftBlocks.cobbled_grimstone, 0, 2);
		world.setBlock(i + 1, j + 2, k + 6, Blocks.air, 0, 2);
		world.setBlock(i + 2, j + 2, k + 6, Blocks.air, 0, 2);
		world.setBlock(i + 3, j + 2, k + 6, Blocks.air, 0, 2);
		world.setBlock(i + 4, j + 2, k + 6, Blocks.air, 0, 2);
		world.setBlock(i + 5, j + 2, k + 6, Blocks.air, 0, 2);
		world.setBlock(i + 6, j + 2, k + 6, Blocks.air, 0, 2);
		world.setBlock(i + 7, j + 2, k + 6, Blocks.air, 0, 2);
		world.setBlock(i + 8, j + 2, k + 6, Blocks.air, 0, 2);
		world.setBlock(i + 9, j + 2, k + 6, Blocks.air, 0, 2);
		world.setBlock(i + 10, j + 2, k + 6, Blocks.air, 0, 2);
		world.setBlock(i + 11, j + 2, k + 6, Blocks.bookshelf, 0, 2);
		world.setBlock(i + 12, j + 2, k + 6, NovaCraftBlocks.cobbled_grimstone, 0, 2);
		world.setBlock(i + 0, j + 2, k + 7, NovaCraftBlocks.cobbled_grimstone, 0, 2);
		world.setBlock(i + 1, j + 2, k + 7, Blocks.air, 0, 2);
		world.setBlock(i + 2, j + 2, k + 7, Blocks.air, 0, 2);
		world.setBlock(i + 3, j + 2, k + 7, Blocks.redstone_torch, 4, 2);
		world.setBlock(i + 4, j + 2, k + 7, Blocks.air, 0, 2);
		world.setBlock(i + 5, j + 2, k + 7, Blocks.air, 0, 2);
		world.setBlock(i + 6, j + 2, k + 7, Blocks.redstone_torch, 4, 2);
		world.setBlock(i + 7, j + 2, k + 7, Blocks.air, 0, 2);
		world.setBlock(i + 8, j + 2, k + 7, Blocks.air, 0, 2);
		world.setBlock(i + 9, j + 2, k + 7, Blocks.redstone_torch, 4, 2);
		world.setBlock(i + 10, j + 2, k + 7, Blocks.air, 0, 2);
		world.setBlock(i + 11, j + 2, k + 7, Blocks.air, 0, 2);
		world.setBlock(i + 12, j + 2, k + 7, NovaCraftBlocks.cobbled_grimstone, 0, 2);
		world.setBlock(i + 0, j + 2, k + 8, NovaCraftBlocks.cobbled_grimstone, 0, 2);
		world.setBlock(i + 1, j + 2, k + 8, NovaCraftBlocks.cobbled_grimstone, 0, 2);
		world.setBlock(i + 2, j + 2, k + 8, NovaCraftBlocks.cobbled_grimstone, 0, 2);
		world.setBlock(i + 3, j + 2, k + 8, NovaCraftBlocks.cobbled_grimstone, 0, 2);
		world.setBlock(i + 4, j + 2, k + 8, NovaCraftBlocks.cobbled_grimstone, 0, 2);
		world.setBlock(i + 5, j + 2, k + 8, NovaCraftBlocks.cobbled_grimstone, 0, 2);
		world.setBlock(i + 6, j + 2, k + 8, NovaCraftBlocks.cobbled_grimstone, 0, 2);
		world.setBlock(i + 7, j + 2, k + 8, NovaCraftBlocks.cobbled_grimstone, 0, 2);
		world.setBlock(i + 8, j + 2, k + 8, NovaCraftBlocks.cobbled_grimstone, 0, 2);
		world.setBlock(i + 9, j + 2, k + 8, NovaCraftBlocks.cobbled_grimstone, 0, 2);
		world.setBlock(i + 10, j + 2, k + 8, NovaCraftBlocks.cobbled_grimstone, 0, 2);
		world.setBlock(i + 11, j + 2, k + 8, NovaCraftBlocks.cobbled_grimstone, 0, 2);
		world.setBlock(i + 12, j + 2, k + 8, NovaCraftBlocks.cobbled_grimstone, 0, 2);
		world.setBlock(i + 0, j + 3, k + 0, NovaCraftBlocks.cobbled_grimstone, 0, 2);
		world.setBlock(i + 1, j + 3, k + 0, NovaCraftBlocks.cobbled_grimstone, 0, 2);
		world.setBlock(i + 2, j + 3, k + 0, NovaCraftBlocks.cobbled_grimstone, 0, 2);
		world.setBlock(i + 3, j + 3, k + 0, NovaCraftBlocks.cobbled_grimstone, 0, 2);
		world.setBlock(i + 4, j + 3, k + 0, NovaCraftBlocks.cobbled_grimstone, 0, 2);
		world.setBlock(i + 5, j + 3, k + 0, NovaCraftBlocks.cobbled_grimstone, 0, 2);
		world.setBlock(i + 6, j + 3, k + 0, NovaCraftBlocks.cobbled_grimstone, 0, 2);
		world.setBlock(i + 7, j + 3, k + 0, NovaCraftBlocks.cobbled_grimstone, 0, 2);
		world.setBlock(i + 8, j + 3, k + 0, NovaCraftBlocks.cobbled_grimstone, 0, 2);
		world.setBlock(i + 9, j + 3, k + 0, NovaCraftBlocks.cobbled_grimstone, 0, 2);
		world.setBlock(i + 10, j + 3, k + 0, NovaCraftBlocks.cobbled_grimstone, 0, 2);
		world.setBlock(i + 11, j + 3, k + 0, NovaCraftBlocks.cobbled_grimstone, 0, 2);
		world.setBlock(i + 12, j + 3, k + 0, NovaCraftBlocks.cobbled_grimstone, 0, 2);
		world.setBlock(i + 0, j + 3, k + 1, NovaCraftBlocks.cobbled_grimstone, 0, 2);
		world.setBlock(i + 1, j + 3, k + 1, Blocks.air, 0, 2);
		world.setBlock(i + 2, j + 3, k + 1, Blocks.ladder, 3, 2);
		world.setBlock(i + 3, j + 3, k + 1, Blocks.air, 0, 2);
		world.setBlock(i + 4, j + 3, k + 1, Blocks.air, 0, 2);
		world.setBlock(i + 5, j + 3, k + 1, Blocks.air, 0, 2);
		world.setBlock(i + 6, j + 3, k + 1, Blocks.air, 0, 2);
		world.setBlock(i + 7, j + 3, k + 1, Blocks.air, 0, 2);
		world.setBlock(i + 8, j + 3, k + 1, Blocks.air, 0, 2);
		world.setBlock(i + 9, j + 3, k + 1, Blocks.air, 0, 2);
		world.setBlock(i + 10, j + 3, k + 1, Blocks.air, 0, 2);
		world.setBlock(i + 11, j + 3, k + 1, Blocks.air, 0, 2);
		world.setBlock(i + 12, j + 3, k + 1, NovaCraftBlocks.cobbled_grimstone, 0, 2);
		world.setBlock(i + 0, j + 3, k + 2, NovaCraftBlocks.cobbled_grimstone, 0, 2);
		world.setBlock(i + 1, j + 3, k + 2, Blocks.air, 0, 2);
		world.setBlock(i + 2, j + 3, k + 2, Blocks.air, 0, 2);
		world.setBlock(i + 3, j + 3, k + 2, Blocks.air, 0, 2);
		world.setBlock(i + 4, j + 3, k + 2, Blocks.air, 0, 2);
		world.setBlock(i + 5, j + 3, k + 2, Blocks.air, 0, 2);
		world.setBlock(i + 6, j + 3, k + 2, Blocks.air, 0, 2);
		world.setBlock(i + 7, j + 3, k + 2, Blocks.air, 0, 2);
		world.setBlock(i + 8, j + 3, k + 2, Blocks.air, 0, 2);
		world.setBlock(i + 9, j + 3, k + 2, Blocks.air, 0, 2);
		world.setBlock(i + 10, j + 3, k + 2, Blocks.air, 0, 2);
		world.setBlock(i + 11, j + 3, k + 2, Blocks.air, 0, 2);
		world.setBlock(i + 12, j + 3, k + 2, NovaCraftBlocks.cobbled_grimstone, 0, 2);
		world.setBlock(i + 0, j + 3, k + 3, NovaCraftBlocks.cobbled_grimstone, 0, 2);
		world.setBlock(i + 1, j + 3, k + 3, Blocks.air, 0, 2);
		world.setBlock(i + 2, j + 3, k + 3, Blocks.air, 0, 2);
		world.setBlock(i + 3, j + 3, k + 3, Blocks.air, 0, 2);
		world.setBlock(i + 4, j + 3, k + 3, Blocks.air, 0, 2);
		world.setBlock(i + 5, j + 3, k + 3, Blocks.air, 0, 2);
		world.setBlock(i + 6, j + 3, k + 3, Blocks.air, 0, 2);
		world.setBlock(i + 7, j + 3, k + 3, Blocks.air, 0, 2);
		world.setBlock(i + 8, j + 3, k + 3, Blocks.air, 0, 2);
		world.setBlock(i + 9, j + 3, k + 3, Blocks.air, 0, 2);
		world.setBlock(i + 10, j + 3, k + 3, Blocks.air, 0, 2);
		world.setBlock(i + 11, j + 3, k + 3, Blocks.air, 0, 2);
		world.setBlock(i + 12, j + 3, k + 3, NovaCraftBlocks.cobbled_grimstone, 0, 2);
		world.setBlock(i + 0, j + 3, k + 4, NovaCraftBlocks.cobbled_grimstone, 0, 2);
		world.setBlock(i + 1, j + 3, k + 4, Blocks.air, 0, 2);
		world.setBlock(i + 2, j + 3, k + 4, Blocks.air, 0, 2);
		world.setBlock(i + 3, j + 3, k + 4, Blocks.air, 0, 2);
		world.setBlock(i + 4, j + 3, k + 4, Blocks.air, 0, 2);
		world.setBlock(i + 5, j + 3, k + 4, Blocks.air, 0, 2);
		world.setBlock(i + 6, j + 3, k + 4, Blocks.air, 0, 2);
		world.setBlock(i + 7, j + 3, k + 4, Blocks.air, 0, 2);
		world.setBlock(i + 8, j + 3, k + 4, Blocks.air, 0, 2);
		world.setBlock(i + 9, j + 3, k + 4, Blocks.air, 0, 2);
		world.setBlock(i + 10, j + 3, k + 4, Blocks.air, 0, 2);
		world.setBlock(i + 11, j + 3, k + 4, Blocks.air, 0, 2);
		world.setBlock(i + 12, j + 3, k + 4, NovaCraftBlocks.cobbled_grimstone, 0, 2);
		world.setBlock(i + 0, j + 3, k + 5, NovaCraftBlocks.cobbled_grimstone, 0, 2);
		world.setBlock(i + 1, j + 3, k + 5, Blocks.air, 0, 2);
		world.setBlock(i + 2, j + 3, k + 5, Blocks.air, 0, 2);
		world.setBlock(i + 3, j + 3, k + 5, Blocks.air, 0, 2);
		world.setBlock(i + 4, j + 3, k + 5, Blocks.air, 0, 2);
		world.setBlock(i + 5, j + 3, k + 5, Blocks.air, 0, 2);
		world.setBlock(i + 6, j + 3, k + 5, Blocks.air, 0, 2);
		world.setBlock(i + 7, j + 3, k + 5, Blocks.air, 0, 2);
		world.setBlock(i + 8, j + 3, k + 5, Blocks.air, 0, 2);
		world.setBlock(i + 9, j + 3, k + 5, Blocks.air, 0, 2);
		world.setBlock(i + 10, j + 3, k + 5, Blocks.air, 0, 2);
		world.setBlock(i + 11, j + 3, k + 5, Blocks.air, 0, 2);
		world.setBlock(i + 12, j + 3, k + 5, NovaCraftBlocks.cobbled_grimstone, 0, 2);
		world.setBlock(i + 0, j + 3, k + 6, NovaCraftBlocks.cobbled_grimstone, 0, 2);
		world.setBlock(i + 1, j + 3, k + 6, Blocks.air, 0, 2);
		world.setBlock(i + 2, j + 3, k + 6, Blocks.air, 0, 2);
		world.setBlock(i + 3, j + 3, k + 6, Blocks.air, 0, 2);
		world.setBlock(i + 4, j + 3, k + 6, Blocks.air, 0, 2);
		world.setBlock(i + 5, j + 3, k + 6, Blocks.air, 0, 2);
		world.setBlock(i + 6, j + 3, k + 6, Blocks.air, 0, 2);
		world.setBlock(i + 7, j + 3, k + 6, Blocks.air, 0, 2);
		world.setBlock(i + 8, j + 3, k + 6, Blocks.air, 0, 2);
		world.setBlock(i + 9, j + 3, k + 6, Blocks.air, 0, 2);
		world.setBlock(i + 10, j + 3, k + 6, Blocks.air, 0, 2);
		world.setBlock(i + 11, j + 3, k + 6, Blocks.air, 0, 2);
		world.setBlock(i + 12, j + 3, k + 6, NovaCraftBlocks.cobbled_grimstone, 0, 2);
		world.setBlock(i + 0, j + 3, k + 7, NovaCraftBlocks.cobbled_grimstone, 0, 2);
		world.setBlock(i + 1, j + 3, k + 7, Blocks.air, 0, 2);
		world.setBlock(i + 2, j + 3, k + 7, Blocks.air, 0, 2);
		world.setBlock(i + 3, j + 3, k + 7, Blocks.air, 0, 2);
		world.setBlock(i + 4, j + 3, k + 7, Blocks.air, 0, 2);
		world.setBlock(i + 5, j + 3, k + 7, Blocks.air, 0, 2);
		world.setBlock(i + 6, j + 3, k + 7, Blocks.air, 0, 2);
		world.setBlock(i + 7, j + 3, k + 7, Blocks.air, 0, 2);
		world.setBlock(i + 8, j + 3, k + 7, Blocks.air, 0, 2);
		world.setBlock(i + 9, j + 3, k + 7, Blocks.air, 0, 2);
		world.setBlock(i + 10, j + 3, k + 7, Blocks.air, 0, 2);
		world.setBlock(i + 11, j + 3, k + 7, Blocks.air, 0, 2);
		world.setBlock(i + 12, j + 3, k + 7, NovaCraftBlocks.cobbled_grimstone, 0, 2);
		world.setBlock(i + 0, j + 3, k + 8, NovaCraftBlocks.cobbled_grimstone, 0, 2);
		world.setBlock(i + 1, j + 3, k + 8, NovaCraftBlocks.cobbled_grimstone, 0, 2);
		world.setBlock(i + 2, j + 3, k + 8, NovaCraftBlocks.cobbled_grimstone, 0, 2);
		world.setBlock(i + 3, j + 3, k + 8, NovaCraftBlocks.cobbled_grimstone, 0, 2);
		world.setBlock(i + 4, j + 3, k + 8, NovaCraftBlocks.cobbled_grimstone, 0, 2);
		world.setBlock(i + 5, j + 3, k + 8, NovaCraftBlocks.cobbled_grimstone, 0, 2);
		world.setBlock(i + 6, j + 3, k + 8, NovaCraftBlocks.cobbled_grimstone, 0, 2);
		world.setBlock(i + 7, j + 3, k + 8, NovaCraftBlocks.cobbled_grimstone, 0, 2);
		world.setBlock(i + 8, j + 3, k + 8, NovaCraftBlocks.cobbled_grimstone, 0, 2);
		world.setBlock(i + 9, j + 3, k + 8, NovaCraftBlocks.cobbled_grimstone, 0, 2);
		world.setBlock(i + 10, j + 3, k + 8, NovaCraftBlocks.cobbled_grimstone, 0, 2);
		world.setBlock(i + 11, j + 3, k + 8, NovaCraftBlocks.cobbled_grimstone, 0, 2);
		world.setBlock(i + 12, j + 3, k + 8, NovaCraftBlocks.cobbled_grimstone, 0, 2);
		world.setBlock(i + 0, j + 4, k + 0, NovaCraftBlocks.cobbled_grimstone, 0, 2);
		world.setBlock(i + 1, j + 4, k + 0, NovaCraftBlocks.cobbled_grimstone, 0, 2);
		world.setBlock(i + 2, j + 4, k + 0, NovaCraftBlocks.cobbled_grimstone, 0, 2);
		world.setBlock(i + 3, j + 4, k + 0, NovaCraftBlocks.cobbled_grimstone, 0, 2);
		world.setBlock(i + 4, j + 4, k + 0, NovaCraftBlocks.cobbled_grimstone, 0, 2);
		world.setBlock(i + 5, j + 4, k + 0, NovaCraftBlocks.cobbled_grimstone, 0, 2);
		world.setBlock(i + 6, j + 4, k + 0, NovaCraftBlocks.cobbled_grimstone, 0, 2);
		world.setBlock(i + 7, j + 4, k + 0, NovaCraftBlocks.cobbled_grimstone, 0, 2);
		world.setBlock(i + 8, j + 4, k + 0, NovaCraftBlocks.cobbled_grimstone, 0, 2);
		world.setBlock(i + 9, j + 4, k + 0, NovaCraftBlocks.cobbled_grimstone, 0, 2);
		world.setBlock(i + 10, j + 4, k + 0, NovaCraftBlocks.cobbled_grimstone, 0, 2);
		world.setBlock(i + 11, j + 4, k + 0, NovaCraftBlocks.cobbled_grimstone, 0, 2);
		world.setBlock(i + 12, j + 4, k + 0, NovaCraftBlocks.cobbled_grimstone, 0, 2);
		world.setBlock(i + 0, j + 4, k + 1, NovaCraftBlocks.cobbled_grimstone, 0, 2);
		world.setBlock(i + 1, j + 4, k + 1, NovaCraftBlocks.cobbled_grimstone, 0, 2);
		world.setBlock(i + 2, j + 4, k + 1, Blocks.ladder, 3, 2);
		world.setBlock(i + 3, j + 4, k + 1, NovaCraftBlocks.cobbled_grimstone, 0, 2);
		world.setBlock(i + 4, j + 4, k + 1, NovaCraftBlocks.cobbled_grimstone, 0, 2);
		world.setBlock(i + 5, j + 4, k + 1, NovaCraftBlocks.cobbled_grimstone, 0, 2);
		world.setBlock(i + 6, j + 4, k + 1, NovaCraftBlocks.cobbled_grimstone, 0, 2);
		world.setBlock(i + 7, j + 4, k + 1, NovaCraftBlocks.cobbled_grimstone, 0, 2);
		world.setBlock(i + 8, j + 4, k + 1, NovaCraftBlocks.cobbled_grimstone, 0, 2);
		world.setBlock(i + 9, j + 4, k + 1, NovaCraftBlocks.cobbled_grimstone, 0, 2);
		world.setBlock(i + 10, j + 4, k + 1, NovaCraftBlocks.cobbled_grimstone, 0, 2);
		world.setBlock(i + 11, j + 4, k + 1, NovaCraftBlocks.cobbled_grimstone, 0, 2);
		world.setBlock(i + 12, j + 4, k + 1, NovaCraftBlocks.cobbled_grimstone, 0, 2);
		world.setBlock(i + 0, j + 4, k + 2, NovaCraftBlocks.cobbled_grimstone, 0, 2);
		world.setBlock(i + 1, j + 4, k + 2, NovaCraftBlocks.cobbled_grimstone, 0, 2);
		world.setBlock(i + 2, j + 4, k + 2, NovaCraftBlocks.cobbled_grimstone, 0, 2);
		world.setBlock(i + 3, j + 4, k + 2, NovaCraftBlocks.cobbled_grimstone, 0, 2);
		world.setBlock(i + 4, j + 4, k + 2, NovaCraftBlocks.cobbled_grimstone, 0, 2);
		world.setBlock(i + 5, j + 4, k + 2, NovaCraftBlocks.cobbled_grimstone, 0, 2);
		world.setBlock(i + 6, j + 4, k + 2, NovaCraftBlocks.cobbled_grimstone, 0, 2);
		world.setBlock(i + 7, j + 4, k + 2, NovaCraftBlocks.cobbled_grimstone, 0, 2);
		world.setBlock(i + 8, j + 4, k + 2, NovaCraftBlocks.cobbled_grimstone, 0, 2);
		world.setBlock(i + 9, j + 4, k + 2, NovaCraftBlocks.cobbled_grimstone, 0, 2);
		world.setBlock(i + 10, j + 4, k + 2, NovaCraftBlocks.cobbled_grimstone, 0, 2);
		world.setBlock(i + 11, j + 4, k + 2, NovaCraftBlocks.cobbled_grimstone, 0, 2);
		world.setBlock(i + 12, j + 4, k + 2, NovaCraftBlocks.cobbled_grimstone, 0, 2);
		world.setBlock(i + 0, j + 4, k + 3, NovaCraftBlocks.cobbled_grimstone, 0, 2);
		world.setBlock(i + 1, j + 4, k + 3, NovaCraftBlocks.cobbled_grimstone, 0, 2);
		world.setBlock(i + 2, j + 4, k + 3, NovaCraftBlocks.cobbled_grimstone, 0, 2);
		world.setBlock(i + 3, j + 4, k + 3, NovaCraftBlocks.cobbled_grimstone, 0, 2);
		world.setBlock(i + 4, j + 4, k + 3, NovaCraftBlocks.cobbled_grimstone, 0, 2);
		world.setBlock(i + 5, j + 4, k + 3, NovaCraftBlocks.cobbled_grimstone, 0, 2);
		world.setBlock(i + 6, j + 4, k + 3, NovaCraftBlocks.cobbled_grimstone, 0, 2);
		world.setBlock(i + 7, j + 4, k + 3, NovaCraftBlocks.cobbled_grimstone, 0, 2);
		world.setBlock(i + 8, j + 4, k + 3, NovaCraftBlocks.cobbled_grimstone, 0, 2);
		world.setBlock(i + 9, j + 4, k + 3, NovaCraftBlocks.cobbled_grimstone, 0, 2);
		world.setBlock(i + 10, j + 4, k + 3, NovaCraftBlocks.cobbled_grimstone, 0, 2);
		world.setBlock(i + 11, j + 4, k + 3, NovaCraftBlocks.cobbled_grimstone, 0, 2);
		world.setBlock(i + 12, j + 4, k + 3, NovaCraftBlocks.cobbled_grimstone, 0, 2);
		world.setBlock(i + 0, j + 4, k + 4, NovaCraftBlocks.cobbled_grimstone, 0, 2);
		world.setBlock(i + 1, j + 4, k + 4, NovaCraftBlocks.cobbled_grimstone, 0, 2);
		world.setBlock(i + 2, j + 4, k + 4, NovaCraftBlocks.cobbled_grimstone, 0, 2);
		world.setBlock(i + 3, j + 4, k + 4, NovaCraftBlocks.cobbled_grimstone, 0, 2);
		world.setBlock(i + 4, j + 4, k + 4, NovaCraftBlocks.cobbled_grimstone, 0, 2);
		world.setBlock(i + 5, j + 4, k + 4, NovaCraftBlocks.cobbled_grimstone, 0, 2);
		world.setBlock(i + 6, j + 4, k + 4, NovaCraftBlocks.cobbled_grimstone, 0, 2);
		world.setBlock(i + 7, j + 4, k + 4, NovaCraftBlocks.cobbled_grimstone, 0, 2);
		world.setBlock(i + 8, j + 4, k + 4, NovaCraftBlocks.cobbled_grimstone, 0, 2);
		world.setBlock(i + 9, j + 4, k + 4, NovaCraftBlocks.cobbled_grimstone, 0, 2);
		world.setBlock(i + 10, j + 4, k + 4, NovaCraftBlocks.cobbled_grimstone, 0, 2);
		world.setBlock(i + 11, j + 4, k + 4, NovaCraftBlocks.cobbled_grimstone, 0, 2);
		world.setBlock(i + 12, j + 4, k + 4, NovaCraftBlocks.cobbled_grimstone, 0, 2);
		world.setBlock(i + 0, j + 4, k + 5, NovaCraftBlocks.cobbled_grimstone, 0, 2);
		world.setBlock(i + 1, j + 4, k + 5, NovaCraftBlocks.cobbled_grimstone, 0, 2);
		world.setBlock(i + 2, j + 4, k + 5, NovaCraftBlocks.cobbled_grimstone, 0, 2);
		world.setBlock(i + 3, j + 4, k + 5, NovaCraftBlocks.cobbled_grimstone, 0, 2);
		world.setBlock(i + 4, j + 4, k + 5, NovaCraftBlocks.cobbled_grimstone, 0, 2);
		world.setBlock(i + 5, j + 4, k + 5, NovaCraftBlocks.cobbled_grimstone, 0, 2);
		world.setBlock(i + 6, j + 4, k + 5, NovaCraftBlocks.cobbled_grimstone, 0, 2);
		world.setBlock(i + 7, j + 4, k + 5, NovaCraftBlocks.cobbled_grimstone, 0, 2);
		world.setBlock(i + 8, j + 4, k + 5, NovaCraftBlocks.cobbled_grimstone, 0, 2);
		world.setBlock(i + 9, j + 4, k + 5, NovaCraftBlocks.cobbled_grimstone, 0, 2);
		world.setBlock(i + 10, j + 4, k + 5, NovaCraftBlocks.cobbled_grimstone, 0, 2);
		world.setBlock(i + 11, j + 4, k + 5, NovaCraftBlocks.cobbled_grimstone, 0, 2);
		world.setBlock(i + 12, j + 4, k + 5, NovaCraftBlocks.cobbled_grimstone, 0, 2);
		world.setBlock(i + 0, j + 4, k + 6, NovaCraftBlocks.cobbled_grimstone, 0, 2);
		world.setBlock(i + 1, j + 4, k + 6, NovaCraftBlocks.cobbled_grimstone, 0, 2);
		world.setBlock(i + 2, j + 4, k + 6, NovaCraftBlocks.cobbled_grimstone, 0, 2);
		world.setBlock(i + 3, j + 4, k + 6, NovaCraftBlocks.cobbled_grimstone, 0, 2);
		world.setBlock(i + 4, j + 4, k + 6, NovaCraftBlocks.cobbled_grimstone, 0, 2);
		world.setBlock(i + 5, j + 4, k + 6, NovaCraftBlocks.cobbled_grimstone, 0, 2);
		world.setBlock(i + 6, j + 4, k + 6, NovaCraftBlocks.cobbled_grimstone, 0, 2);
		world.setBlock(i + 7, j + 4, k + 6, NovaCraftBlocks.cobbled_grimstone, 0, 2);
		world.setBlock(i + 8, j + 4, k + 6, NovaCraftBlocks.cobbled_grimstone, 0, 2);
		world.setBlock(i + 9, j + 4, k + 6, NovaCraftBlocks.cobbled_grimstone, 0, 2);
		world.setBlock(i + 10, j + 4, k + 6, NovaCraftBlocks.cobbled_grimstone, 0, 2);
		world.setBlock(i + 11, j + 4, k + 6, NovaCraftBlocks.cobbled_grimstone, 0, 2);
		world.setBlock(i + 12, j + 4, k + 6, NovaCraftBlocks.cobbled_grimstone, 0, 2);
		world.setBlock(i + 0, j + 4, k + 7, NovaCraftBlocks.cobbled_grimstone, 0, 2);
		world.setBlock(i + 1, j + 4, k + 7, NovaCraftBlocks.cobbled_grimstone, 0, 2);
		world.setBlock(i + 2, j + 4, k + 7, NovaCraftBlocks.cobbled_grimstone, 0, 2);
		world.setBlock(i + 3, j + 4, k + 7, NovaCraftBlocks.cobbled_grimstone, 0, 2);
		world.setBlock(i + 4, j + 4, k + 7, NovaCraftBlocks.cobbled_grimstone, 0, 2);
		world.setBlock(i + 5, j + 4, k + 7, NovaCraftBlocks.cobbled_grimstone, 0, 2);
		world.setBlock(i + 6, j + 4, k + 7, NovaCraftBlocks.cobbled_grimstone, 0, 2);
		world.setBlock(i + 7, j + 4, k + 7, NovaCraftBlocks.cobbled_grimstone, 0, 2);
		world.setBlock(i + 8, j + 4, k + 7, NovaCraftBlocks.cobbled_grimstone, 0, 2);
		world.setBlock(i + 9, j + 4, k + 7, NovaCraftBlocks.cobbled_grimstone, 0, 2);
		world.setBlock(i + 10, j + 4, k + 7, NovaCraftBlocks.cobbled_grimstone, 0, 2);
		world.setBlock(i + 11, j + 4, k + 7, NovaCraftBlocks.cobbled_grimstone, 0, 2);
		world.setBlock(i + 12, j + 4, k + 7, NovaCraftBlocks.cobbled_grimstone, 0, 2);
		world.setBlock(i + 0, j + 4, k + 8, NovaCraftBlocks.cobbled_grimstone, 0, 2);
		world.setBlock(i + 1, j + 4, k + 8, NovaCraftBlocks.cobbled_grimstone, 0, 2);
		world.setBlock(i + 2, j + 4, k + 8, NovaCraftBlocks.cobbled_grimstone, 0, 2);
		world.setBlock(i + 3, j + 4, k + 8, NovaCraftBlocks.cobbled_grimstone, 0, 2);
		world.setBlock(i + 4, j + 4, k + 8, NovaCraftBlocks.cobbled_grimstone, 0, 2);
		world.setBlock(i + 5, j + 4, k + 8, NovaCraftBlocks.cobbled_grimstone, 0, 2);
		world.setBlock(i + 6, j + 4, k + 8, NovaCraftBlocks.cobbled_grimstone, 0, 2);
		world.setBlock(i + 7, j + 4, k + 8, NovaCraftBlocks.cobbled_grimstone, 0, 2);
		world.setBlock(i + 8, j + 4, k + 8, NovaCraftBlocks.cobbled_grimstone, 0, 2);
		world.setBlock(i + 9, j + 4, k + 8, NovaCraftBlocks.cobbled_grimstone, 0, 2);
		world.setBlock(i + 10, j + 4, k + 8, NovaCraftBlocks.cobbled_grimstone, 0, 2);
		world.setBlock(i + 11, j + 4, k + 8, NovaCraftBlocks.cobbled_grimstone, 0, 2);
		world.setBlock(i + 12, j + 4, k + 8, NovaCraftBlocks.cobbled_grimstone, 0, 2);		
		world.setBlock(i + 4, j + 1, k + 4, Blocks.air, 0, 2);
		world.setBlock(i + 6, j + 1, k + 4, Blocks.air, 0, 2);
		world.setBlock(i + 8, j + 1, k + 4, Blocks.air, 0, 2);
		
		EntityIllagerTrader entity = new EntityIllagerTrader(world);
		entity.setPosition(i + 4, j + 1, k + 4);
		world.spawnEntityInWorld(entity);
		
		EntityIllagerTrader entity2 = new EntityIllagerTrader(world);
		entity2.setPosition(i + 6, j + 1, k + 4);
		world.spawnEntityInWorld(entity2);
		
		EntityIllagerTrader entity3 = new EntityIllagerTrader(world);
		entity3.setPosition(i + 8, j + 1, k + 4);
		world.spawnEntityInWorld(entity3);
		}
		return true;
	}

}
