package com.NovaCraft.world.village;

import java.util.Random;
import com.NovaCraft.entity.illager.EntityIllagerTrader;
import com.NovaCraftBlocks.NovaCraftBlocks;
import net.minecraft.block.Block;
import net.minecraft.init.Blocks;
import net.minecraft.world.World;
import net.minecraft.world.gen.feature.WorldGenerator;

public class VindicatorHouseMedium extends WorldGenerator
{
	private static final Block planks = NovaCraftBlocks.sculk_bricks;
	private static final Block wood = NovaCraftBlocks.luminant_log;
	private static final Block thinGlass = NovaCraftBlocks.vanite_glass;
	private static final Block sculkBlock = NovaCraftBlocks.sculk_block;
	private static final Block cobbledGrimstone = NovaCraftBlocks.grimstone_bricks;
	private static final Block cobbledGrimstone2 = NovaCraftBlocks.cobbled_grimstone;
	private static final Block Nullstone = NovaCraftBlocks.nullstone;
	private static final Block fence = NovaCraftBlocks.vanite_glass;
	private static final Block doorWood = Blocks.wooden_door;
	private static final Block stairsWoodOak = NovaCraftBlocks.sculk_brick_stairs;
	private static final Block sculkVein = NovaCraftBlocks.sculk_vein;
	private static final Block air = Blocks.air;
	
	protected Block[] GetValidSpawnBlocks() {
		return new Block[] {
				Blocks.snow,
				Blocks.sand,
				Blocks.stone,
				Blocks.grass
		};
	}

	public boolean LocationIsValidSpawn(World world, int i, int j, int k){
		int distanceToAir = 0;
		Block checkID = world.getBlock(i, j, k);

		while (checkID != air){
			distanceToAir++;
			checkID = world.getBlock(i, j + distanceToAir, k);
		}

		if (distanceToAir > 2){
			return false;
		}
		j += distanceToAir - 1;

		Block blockID = world.getBlock(i, j, k);
		Block blockIDAbove = world.getBlock(i, j+1, k);
		Block blockIDBelow = world.getBlock(i, j-1, k);
		for (Block x : GetValidSpawnBlocks()){
			if (blockIDAbove != air){
				return false;
			}
			if ((blockID == Blocks.snow && blockIDBelow == x) || (blockID == Blocks.tallgrass && blockIDBelow == x) || (blockID == Blocks.red_flower && blockIDBelow == x) || (blockID == Blocks.yellow_flower && blockIDBelow == x) || (blockID == Blocks.deadbush && blockIDBelow == x) || (blockID == Blocks.cactus && blockIDBelow == x) || (blockID == Blocks.brown_mushroom && blockIDBelow == x) || (blockID == Blocks.red_mushroom && blockIDBelow == x)){
				return true;
			}
			else if (blockID == x){
				return true;
			}
		}
		return false;
	}

	public VindicatorHouseMedium() { }
	
	public boolean checkAllLocations(World world, int i, int j, int k){
		if(!LocationIsValidSpawn(world, i, j, k) || !LocationIsValidSpawn(world, i + 8, j, k) || !LocationIsValidSpawn(world, i + 8, j, k + 11) || !LocationIsValidSpawn(world, i, j, k + 11) || !AirLocationIsValidSpawn(world, i, j + 5, k) || !AirLocationIsValidSpawn(world, i + 8, j + 5, k) || !AirLocationIsValidSpawn(world, i + 8, j + 5, k + 11) || !AirLocationIsValidSpawn(world, i, j + 5, k + 11))
		{
			return false;
		}
		
		return true;
	}
	
	public boolean AirLocationIsValidSpawn(World world, int i, int j, int k){
		Block blockID = world.getBlock(i, j, k);
		Block blockIDAbove = world.getBlock(i, j+1, k);
		
		if (blockID != air || blockIDAbove != air){
			return false;
		}

		return true;
	}

	public boolean generate(World world, Random rand, int i, int j, int k) {
		//check that each corner is one of the valid spawn blocks
		if(!LocationIsValidSpawn(world, i, j, k) || !LocationIsValidSpawn(world, i + 8, j, k) || !LocationIsValidSpawn(world, i + 8, j, k + 11) || !LocationIsValidSpawn(world, i, j, k + 11) || !AirLocationIsValidSpawn(world, i, j + 5, k) || !AirLocationIsValidSpawn(world, i + 8, j + 5, k) || !AirLocationIsValidSpawn(world, i + 8, j + 5, k + 11) || !AirLocationIsValidSpawn(world, i, j + 5, k + 11))
		{
			return false;
		}

		world.setBlock(i, j + 1, k, air);
		world.setBlock(i, j + 1, k + 1, air);
		world.setBlock(i, j + 1, k + 2, air);
		world.setBlock(i, j + 1, k + 3, air);
		world.setBlock(i, j + 1, k + 4, air);
		world.setBlock(i, j + 1, k + 5, cobbledGrimstone, 0, 2);
		world.setBlock(i, j + 1, k + 6, cobbledGrimstone, 0, 2);
		world.setBlock(i, j + 1, k + 7, cobbledGrimstone, 0, 2);
		world.setBlock(i, j + 1, k + 8, cobbledGrimstone, 0, 2);
		world.setBlock(i, j + 1, k + 9, cobbledGrimstone, 0, 2);
		world.setBlock(i, j + 1, k + 10, cobbledGrimstone, 0, 2);
		world.setBlock(i, j + 1, k + 11, air);
		world.setBlock(i, j + 2, k, air);
		world.setBlock(i, j + 2, k + 1, air);
		world.setBlock(i, j + 2, k + 2, air);
		world.setBlock(i, j + 2, k + 3, air);
		world.setBlock(i, j + 2, k + 4, air);
		world.setBlock(i, j + 2, k + 5, cobbledGrimstone, 0, 2);
		world.setBlock(i, j + 2, k + 6, cobbledGrimstone, 0, 2);
		world.setBlock(i, j + 2, k + 7, cobbledGrimstone, 0, 2);
		world.setBlock(i, j + 2, k + 8, cobbledGrimstone, 0, 2);
		world.setBlock(i, j + 2, k + 9, cobbledGrimstone, 0, 2);
		world.setBlock(i, j + 2, k + 10, cobbledGrimstone, 0, 2);
		world.setBlock(i, j + 2, k + 11, air);
		world.setBlock(i, j + 3, k, air);
		world.setBlock(i, j + 3, k + 1, air);
		world.setBlock(i, j + 3, k + 2, air);
		world.setBlock(i, j + 3, k + 3, air);
		world.setBlock(i, j + 3, k + 4, air);
		world.setBlock(i, j + 3, k + 5, cobbledGrimstone, 0, 2);
		world.setBlock(i, j + 3, k + 6, wood, 1, 2);
		world.setBlock(i, j + 3, k + 7, thinGlass, 0, 2);
		world.setBlock(i, j + 3, k + 8, thinGlass, 0, 2);
		world.setBlock(i, j + 3, k + 9, wood, 1, 2);
		world.setBlock(i, j + 3, k + 10, cobbledGrimstone, 0, 2);
		world.setBlock(i, j + 3, k + 11, air);
		world.setBlock(i, j + 4, k, air);
		world.setBlock(i, j + 4, k + 1, air);
		world.setBlock(i, j + 4, k + 2, air);
		world.setBlock(i, j + 4, k + 3, air);
		world.setBlock(i, j + 4, k + 4, stairsWoodOak, 2, 2);
		world.setBlock(i, j + 4, k + 5, cobbledGrimstone, 0, 2);
		world.setBlock(i, j + 4, k + 6, cobbledGrimstone, 0, 2);
		world.setBlock(i, j + 4, k + 7, cobbledGrimstone, 0, 2);
		world.setBlock(i, j + 4, k + 8, cobbledGrimstone, 0, 2);
		world.setBlock(i, j + 4, k + 9, cobbledGrimstone, 0, 2);
		world.setBlock(i, j + 4, k + 10, cobbledGrimstone, 0, 2);
		world.setBlock(i, j + 4, k + 11, stairsWoodOak, 3, 2);
		world.setBlock(i, j + 5, k, air);
		world.setBlock(i, j + 5, k + 1, air);
		world.setBlock(i, j + 5, k + 2, air);
		world.setBlock(i, j + 5, k + 3, air);
		world.setBlock(i, j + 5, k + 4, air);
		world.setBlock(i, j + 5, k + 5, stairsWoodOak, 2, 2);
		world.setBlock(i, j + 5, k + 6, planks, 5, 2);
		world.setBlock(i, j + 5, k + 7, planks, 5, 2);
		world.setBlock(i, j + 5, k + 8, planks, 5, 2);
		world.setBlock(i, j + 5, k + 9, planks, 5, 2);
		world.setBlock(i, j + 5, k + 10, stairsWoodOak, 3, 2);
		world.setBlock(i, j + 5, k + 11, air);
		world.setBlock(i, j + 6, k, air);
		world.setBlock(i, j + 6, k + 1, air);
		world.setBlock(i, j + 6, k + 2, air);
		world.setBlock(i, j + 6, k + 3, air);
		world.setBlock(i, j + 6, k + 4, air);
		world.setBlock(i, j + 6, k + 5, air);
		world.setBlock(i, j + 6, k + 6, stairsWoodOak, 2, 2);
		world.setBlock(i, j + 6, k + 7, planks, 5, 2);
		world.setBlock(i, j + 6, k + 8, planks, 5, 2);
		world.setBlock(i, j + 6, k + 9, stairsWoodOak, 3, 2);
		world.setBlock(i, j + 6, k + 10, air);
		world.setBlock(i, j + 6, k + 11, air);
		world.setBlock(i, j + 7, k, air);
		world.setBlock(i, j + 7, k + 1, air);
		world.setBlock(i, j + 7, k + 2, air);
		world.setBlock(i, j + 7, k + 3, air);
		world.setBlock(i, j + 7, k + 4, air);
		world.setBlock(i, j + 7, k + 5, air);
		world.setBlock(i, j + 7, k + 6, air);
		world.setBlock(i, j + 7, k + 7, stairsWoodOak, 2, 2);
		world.setBlock(i, j + 7, k + 8, stairsWoodOak, 3, 2);
		world.setBlock(i, j + 7, k + 9, air);
		world.setBlock(i, j + 7, k + 10, air);
		world.setBlock(i, j + 7, k + 11, air);
		world.setBlock(i + 1, j + 1, k, air);
		world.setBlock(i + 1, j + 1, k + 1, air);
		world.setBlock(i + 1, j + 1, k + 2, air);
		world.setBlock(i + 1, j + 1, k + 3, air);
		world.setBlock(i + 1, j + 1, k + 4, air);
		world.setBlock(i + 1, j + 1, k + 5, cobbledGrimstone, 0, 2);
		world.setBlock(i + 1, j + 1, k + 6, planks, 5, 2);
		world.setBlock(i + 1, j + 1, k + 7, planks, 5, 2);
		world.setBlock(i + 1, j + 1, k + 8, planks, 5, 2);
		world.setBlock(i + 1, j + 1, k + 9, planks, 5, 2);
		world.setBlock(i + 1, j + 1, k + 10, cobbledGrimstone, 0, 2);
		world.setBlock(i + 1, j + 1, k + 11, air);
		world.setBlock(i + 1, j + 2, k, air);
		world.setBlock(i + 1, j + 2, k + 1, air);
		world.setBlock(i + 1, j + 2, k + 2, air);
		world.setBlock(i + 1, j + 2, k + 3, air);
		world.setBlock(i + 1, j + 2, k + 4, air);
		world.setBlock(i + 1, j + 2, k + 5, cobbledGrimstone, 0, 2);
		world.setBlock(i + 1, j + 2, k + 6, planks, 5, 2);
		world.setBlock(i + 1, j + 2, k + 7, stairsWoodOak, 1, 2);
		world.setBlock(i + 1, j + 2, k + 8, air);
		world.setBlock(i + 1, j + 2, k + 9, air);
		world.setBlock(i + 1, j + 2, k + 10, cobbledGrimstone, 0, 2);
		world.setBlock(i + 1, j + 2, k + 11, air);
		world.setBlock(i + 1, j + 3, k, air);
		world.setBlock(i + 1, j + 3, k + 1, air);
		world.setBlock(i + 1, j + 3, k + 2, air);
		world.setBlock(i + 1, j + 3, k + 3, air);
		world.setBlock(i + 1, j + 3, k + 4, air);
		world.setBlock(i + 1, j + 3, k + 5, planks, 5, 2);
		world.setBlock(i + 1, j + 3, k + 6, air);
		world.setBlock(i + 1, j + 3, k + 7, air);
		world.setBlock(i + 1, j + 3, k + 8, air);
		world.setBlock(i + 1, j + 3, k + 9, air);
		world.setBlock(i + 1, j + 3, k + 10, planks, 5, 2);
		world.setBlock(i + 1, j + 3, k + 11, air);
		world.setBlock(i + 1, j + 4, k, air);
		world.setBlock(i + 1, j + 4, k + 1, air);
		world.setBlock(i + 1, j + 4, k + 2, air);
		world.setBlock(i + 1, j + 4, k + 3, air);
		world.setBlock(i + 1, j + 4, k + 4, stairsWoodOak, 2, 2);
		world.setBlock(i + 1, j + 4, k + 5, planks, 5, 2);
		world.setBlock(i + 1, j + 4, k + 6, air);
		world.setBlock(i + 1, j + 4, k + 7, air);
		world.setBlock(i + 1, j + 4, k + 8, air);
		world.setBlock(i + 1, j + 4, k + 9, air);
		world.setBlock(i + 1, j + 4, k + 10, planks, 5, 2);
		world.setBlock(i + 1, j + 4, k + 11, stairsWoodOak, 3, 2);
		world.setBlock(i + 1, j + 5, k, air);
		world.setBlock(i + 1, j + 5, k + 1, air);
		world.setBlock(i + 1, j + 5, k + 2, air);
		world.setBlock(i + 1, j + 5, k + 3, air);
		world.setBlock(i + 1, j + 5, k + 4, air);
		world.setBlock(i + 1, j + 5, k + 5, stairsWoodOak, 2, 2);
		world.setBlock(i + 1, j + 5, k + 6, planks, 5, 2);
		world.setBlock(i + 1, j + 5, k + 7, air);
		world.setBlock(i + 1, j + 5, k + 8, air);
		world.setBlock(i + 1, j + 5, k + 9, planks, 5, 2);
		world.setBlock(i + 1, j + 5, k + 10, stairsWoodOak, 3, 2);
		world.setBlock(i + 1, j + 5, k + 11, air);
		world.setBlock(i + 1, j + 6, k, air);
		world.setBlock(i + 1, j + 6, k + 1, air);
		world.setBlock(i + 1, j + 6, k + 2, air);
		world.setBlock(i + 1, j + 6, k + 3, air);
		world.setBlock(i + 1, j + 6, k + 4, air);
		world.setBlock(i + 1, j + 6, k + 5, air);
		world.setBlock(i + 1, j + 6, k + 6, stairsWoodOak, 2, 2);
		world.setBlock(i + 1, j + 6, k + 7, planks, 5, 2);
		world.setBlock(i + 1, j + 6, k + 8, planks, 5, 2);
		world.setBlock(i + 1, j + 6, k + 9, stairsWoodOak, 3, 2);
		world.setBlock(i + 1, j + 6, k + 10, air);
		world.setBlock(i + 1, j + 6, k + 11, air);
		world.setBlock(i + 1, j + 7, k, air);
		world.setBlock(i + 1, j + 7, k + 1, air);
		world.setBlock(i + 1, j + 7, k + 2, air);
		world.setBlock(i + 1, j + 7, k + 3, air);
		world.setBlock(i + 1, j + 7, k + 4, air);
		world.setBlock(i + 1, j + 7, k + 5, air);
		world.setBlock(i + 1, j + 7, k + 6, air);
		world.setBlock(i + 1, j + 7, k + 7, stairsWoodOak, 2, 2);
		world.setBlock(i + 1, j + 7, k + 8, stairsWoodOak, 3, 2);
		world.setBlock(i + 1, j + 7, k + 9, air);
		world.setBlock(i + 1, j + 7, k + 10, air);
		world.setBlock(i + 1, j + 7, k + 11, air);
		
		world.setBlock(i + 2, j + 4, k, NovaCraftBlocks.sculk_brick_slab, 5, 2);
		world.setBlock(i + 2, j + 4, k + 1, NovaCraftBlocks.sculk_brick_slab, 5, 2);
		world.setBlock(i + 2, j + 4, k + 2, NovaCraftBlocks.sculk_brick_slab, 5, 2);
		world.setBlock(i + 2, j + 4, k + 3, NovaCraftBlocks.sculk_brick_slab, 5, 2);
		world.setBlock(i + 2, j + 4, k + 4, NovaCraftBlocks.sculk_brick_slab, 5, 2);
		
		world.setBlock(i + 2, j + 1, k + 5, cobbledGrimstone, 0, 2);
		world.setBlock(i + 2, j + 1, k + 6, planks, 5, 2);
		world.setBlock(i + 2, j + 1, k + 7, planks, 5, 2);
		world.setBlock(i + 2, j + 1, k + 8, planks, 5, 2);
		world.setBlock(i + 2, j + 1, k + 9, planks, 5, 2);
		world.setBlock(i + 2, j + 1, k + 10, cobbledGrimstone, 0, 2);
		world.setBlock(i + 2, j + 1, k + 11, NovaCraftBlocks.cobbled_grimstone_stairs, 3, 2);
		world.setBlock(i + 2, j + 2, k, fence, 0, 2);
		world.setBlock(i + 2, j + 2, k + 1, fence, 0, 2);
		world.setBlock(i + 2, j + 2, k + 2, fence, 0, 2);
		world.setBlock(i + 2, j + 2, k + 3, fence, 0, 2);
		world.setBlock(i + 2, j + 2, k + 4, fence, 0, 2);
		
		world.setBlock(i + 2, j + 3, k, fence, 0, 2);
		world.setBlock(i + 2, j + 3, k + 1, fence, 0, 2);
		world.setBlock(i + 2, j + 3, k + 2, fence, 0, 2);
		world.setBlock(i + 2, j + 3, k + 3, fence, 0, 2);
		world.setBlock(i + 2, j + 3, k + 4, fence, 0, 2);
		
		world.setBlock(i + 2, j + 1, k, cobbledGrimstone2, 0, 2);
		world.setBlock(i + 2, j + 1, k + 1, cobbledGrimstone2, 0, 2);
		world.setBlock(i + 2, j + 1, k + 2, cobbledGrimstone2, 0, 2);
		world.setBlock(i + 2, j + 1, k + 3, cobbledGrimstone2, 0, 2);
		world.setBlock(i + 2, j + 1, k + 4, cobbledGrimstone2, 0, 2);
		
		world.setBlock(i + 2, j + 2, k + 5, cobbledGrimstone, 0, 2);
		world.setBlock(i + 2, j + 2, k + 6, stairsWoodOak, 3, 2);
		world.setBlock(i + 2, j + 2, k + 7, fence, 0, 2);
		world.setBlock(i + 2, j + 2, k + 8, air);
		world.setBlock(i + 2, j + 2, k + 9, air);
		world.setBlock(i + 2, j + 2, k + 11, air);
		world.setBlock(i + 2, j + 3, k + 5, thinGlass, 0, 2);
		world.setBlock(i + 2, j + 3, k + 6, air);
		world.setBlock(i + 2, j + 3, k + 8, air);
		world.setBlock(i + 2, j + 3, k + 9, air);
		world.setBlock(i + 2, j + 3, k + 11, air);
		world.setBlock(i + 2, j + 4, k + 4, stairsWoodOak, 2, 2);
		world.setBlock(i + 2, j + 4, k + 5, planks, 5, 2);
		world.setBlock(i + 2, j + 4, k + 6, air);
		world.setBlock(i + 2, j + 4, k + 7, air);
		world.setBlock(i + 2, j + 4, k + 8, air);
		world.setBlock(i + 2, j + 4, k + 10, planks, 5, 2);
		world.setBlock(i + 2, j + 4, k + 11, stairsWoodOak, 3, 2);
		world.setBlock(i + 2, j + 5, k, air);
		world.setBlock(i + 2, j + 5, k + 1, air);
		world.setBlock(i + 2, j + 5, k + 2, air);
		world.setBlock(i + 2, j + 5, k + 3, air);
		world.setBlock(i + 2, j + 5, k + 4, air);
		world.setBlock(i + 2, j + 5, k + 5, stairsWoodOak, 2, 2);
		world.setBlock(i + 2, j + 5, k + 6, planks, 5, 2);
		world.setBlock(i + 2, j + 5, k + 7, air);
		world.setBlock(i + 2, j + 5, k + 8, air);
		world.setBlock(i + 2, j + 5, k + 9, planks, 5, 2);
		world.setBlock(i + 2, j + 5, k + 10, stairsWoodOak, 3, 2);
		world.setBlock(i + 2, j + 5, k + 11, air);
		world.setBlock(i + 2, j + 6, k, air);
		world.setBlock(i + 2, j + 6, k + 1, air);
		world.setBlock(i + 2, j + 6, k + 2, air);
		world.setBlock(i + 2, j + 6, k + 3, air);
		world.setBlock(i + 2, j + 6, k + 4, air);
		world.setBlock(i + 2, j + 6, k + 5, air);
		world.setBlock(i + 2, j + 6, k + 6, stairsWoodOak, 2, 2);
		world.setBlock(i + 2, j + 6, k + 7, planks, 5, 2);
		world.setBlock(i + 2, j + 6, k + 8, planks, 5, 2);
		world.setBlock(i + 2, j + 6, k + 9, stairsWoodOak, 3, 2);
		world.setBlock(i + 2, j + 6, k + 10, air);
		world.setBlock(i + 2, j + 6, k + 11, air);
		world.setBlock(i + 2, j + 7, k, air);
		world.setBlock(i + 2, j + 7, k + 1, air);
		world.setBlock(i + 2, j + 7, k + 2, air);
		world.setBlock(i + 2, j + 7, k + 3, air);
		world.setBlock(i + 2, j + 7, k + 4, air);
		world.setBlock(i + 2, j + 7, k + 5, air);
		world.setBlock(i + 2, j + 7, k + 6, air);
		world.setBlock(i + 2, j + 7, k + 7, stairsWoodOak, 2, 2);
		world.setBlock(i + 2, j + 7, k + 8, stairsWoodOak, 3, 2);
		world.setBlock(i + 2, j + 7, k + 9, air);
		world.setBlock(i + 2, j + 7, k + 10, air);
		world.setBlock(i + 2, j + 7, k + 11, air);
		world.setBlock(i + 3, j + 1, k + 1, Nullstone, 0, 2);
		world.setBlock(i + 3, j + 1, k + 2, Nullstone, 0, 2);
		world.setBlock(i + 3, j + 1, k + 3, Nullstone, 0, 2);
		world.setBlock(i + 3, j + 1, k + 4, Nullstone, 0, 2);
		
		world.setBlock(i + 3, j + 2, k + 2, NovaCraftBlocks.null_wart, 0, 2);
		world.setBlock(i + 3, j + 2, k + 3, NovaCraftBlocks.null_wart, 0, 2);
		
		world.setBlock(i + 3, j + 4, k, NovaCraftBlocks.sculk_brick_slab, 5, 2);
		world.setBlock(i + 3, j + 4, k + 1, NovaCraftBlocks.sculk_brick_slab, 5, 2);
		world.setBlock(i + 3, j + 4, k + 2, NovaCraftBlocks.sculk_brick_slab, 5, 2);
		world.setBlock(i + 3, j + 4, k + 3, NovaCraftBlocks.sculk_brick_slab, 5, 2);
		world.setBlock(i + 3, j + 4, k + 4, NovaCraftBlocks.sculk_brick_slab, 5, 2);
		
		world.setBlock(i + 3, j + 1, k + 5, cobbledGrimstone, 0, 2);
		world.setBlock(i + 3, j + 1, k + 6, planks, 5, 2);
		world.setBlock(i + 3, j + 1, k + 7, planks, 5, 2);
		world.setBlock(i + 3, j + 1, k + 8, planks, 5, 2);
		world.setBlock(i + 3, j + 1, k + 9, planks, 5, 2);
		world.setBlock(i + 3, j + 1, k + 10, cobbledGrimstone, 0, 2);
		world.setBlock(i + 3, j + 1, k + 11, air);
		world.setBlock(i + 3, j + 2, k, fence, 0, 2);
		world.setBlock(i + 3, j + 3, k, fence, 0, 2);
		world.setBlock(i + 3, j + 1, k, cobbledGrimstone2, 0, 2);
		world.setBlock(i + 3, j + 2, k + 1, air);
		world.setBlock(i + 3, j + 2, k + 4, air);
		world.setBlock(i + 3, j + 2, k + 5, cobbledGrimstone, 0, 2);
		world.setBlock(i + 3, j + 2, k + 6, air);
		world.setBlock(i + 3, j + 2, k + 7, air);
		world.setBlock(i + 3, j + 2, k + 8, air);
		world.setBlock(i + 3, j + 2, k + 9, air);
		world.setBlock(i + 3, j + 2, k + 10, cobbledGrimstone, 0, 2);
		world.setBlock(i + 3, j + 2, k + 11, air);
		world.setBlock(i + 3, j + 3, k + 1, air);
		world.setBlock(i + 3, j + 3, k + 2, air);
		world.setBlock(i + 3, j + 3, k + 3, air);
		world.setBlock(i + 3, j + 3, k + 4, air);
		world.setBlock(i + 3, j + 3, k + 5, thinGlass, 0, 2);
		world.setBlock(i + 3, j + 3, k + 6, air);
		world.setBlock(i + 3, j + 3, k + 7, air);
		world.setBlock(i + 3, j + 3, k + 8, air);
		world.setBlock(i + 3, j + 3, k + 9, air);
		world.setBlock(i + 3, j + 3, k + 10, planks, 5, 2);
		world.setBlock(i + 3, j + 3, k + 11, air);
		world.setBlock(i + 3, j + 4, k + 4, stairsWoodOak, 2, 2);
		world.setBlock(i + 3, j + 4, k + 5, planks, 5, 2);
		world.setBlock(i + 3, j + 4, k + 6, air);
		world.setBlock(i + 3, j + 4, k + 7, air);
		world.setBlock(i + 3, j + 4, k + 8, air);
		world.setBlock(i + 3, j + 4, k + 9, air);
		world.setBlock(i + 3, j + 4, k + 10, planks, 5, 2);
		world.setBlock(i + 3, j + 4, k + 11, stairsWoodOak, 3, 2);
		world.setBlock(i + 3, j + 5, k, air);
		world.setBlock(i + 3, j + 5, k + 1, air);
		world.setBlock(i + 3, j + 5, k + 2, air);
		world.setBlock(i + 3, j + 5, k + 3, air);
		world.setBlock(i + 3, j + 5, k + 4, air);
		world.setBlock(i + 3, j + 5, k + 5, stairsWoodOak, 2, 2);
		world.setBlock(i + 3, j + 5, k + 6, planks, 5, 2);
		world.setBlock(i + 3, j + 5, k + 7, air);
		world.setBlock(i + 3, j + 5, k + 8, air);
		world.setBlock(i + 3, j + 5, k + 9, planks, 5, 2);
		world.setBlock(i + 3, j + 5, k + 10, stairsWoodOak, 3, 2);
		world.setBlock(i + 3, j + 5, k + 11, air);
		world.setBlock(i + 3, j + 6, k, air);
		world.setBlock(i + 3, j + 6, k + 1, air);
		world.setBlock(i + 3, j + 6, k + 2, air);
		world.setBlock(i + 3, j + 6, k + 3, air);
		world.setBlock(i + 3, j + 6, k + 4, air);
		world.setBlock(i + 3, j + 6, k + 5, air);
		world.setBlock(i + 3, j + 6, k + 6, stairsWoodOak, 2, 2);
		world.setBlock(i + 3, j + 6, k + 7, planks, 5, 2);
		world.setBlock(i + 3, j + 6, k + 8, planks, 5, 2);
		world.setBlock(i + 3, j + 6, k + 9, stairsWoodOak, 3, 2);
		world.setBlock(i + 3, j + 6, k + 10, air);
		world.setBlock(i + 3, j + 6, k + 11, air);
		world.setBlock(i + 3, j + 7, k, air);
		world.setBlock(i + 3, j + 7, k + 1, air);
		world.setBlock(i + 3, j + 7, k + 2, air);
		world.setBlock(i + 3, j + 7, k + 3, air);
		world.setBlock(i + 3, j + 7, k + 4, air);
		world.setBlock(i + 3, j + 7, k + 5, air);
		world.setBlock(i + 3, j + 7, k + 6, air);
		world.setBlock(i + 3, j + 7, k + 7, stairsWoodOak, 2, 2);
		world.setBlock(i + 3, j + 7, k + 8, stairsWoodOak, 3, 2);
		world.setBlock(i + 3, j + 7, k + 9, air);
		world.setBlock(i + 3, j + 7, k + 10, air);
		world.setBlock(i + 3, j + 7, k + 11, air);
		world.setBlock(i + 4, j + 1, k + 1, Nullstone, 0, 2);
		world.setBlock(i + 4, j + 1, k + 2, Nullstone, 0, 2);
		world.setBlock(i + 4, j + 1, k + 3, Nullstone, 0, 2);
		world.setBlock(i + 4, j + 1, k + 4, Nullstone, 0, 2);
		
		world.setBlock(i + 4, j + 4, k, NovaCraftBlocks.sculk_brick_slab, 5, 2);
		world.setBlock(i + 4, j + 4, k + 1, NovaCraftBlocks.sculk_brick_slab, 5, 2);
		world.setBlock(i + 4, j + 4, k + 2, NovaCraftBlocks.sculk_brick_slab, 5, 2);
		world.setBlock(i + 4, j + 4, k + 3, NovaCraftBlocks.sculk_brick_slab, 5, 2);
		world.setBlock(i + 4, j + 4, k + 4, NovaCraftBlocks.sculk_brick_slab, 5, 2);
		
		world.setBlock(i + 4, j + 1, k + 5, cobbledGrimstone, 0, 2);
		world.setBlock(i + 4, j + 1, k + 6, planks, 5, 2);
		world.setBlock(i + 4, j + 1, k + 7, planks, 5, 2);
		world.setBlock(i + 4, j + 1, k + 8, planks, 5, 2);
		world.setBlock(i + 4, j + 1, k + 9, planks, 5, 2);
		world.setBlock(i + 4, j + 1, k + 10, cobbledGrimstone, 0, 2);
		world.setBlock(i + 4, j + 1, k + 11, air);
		world.setBlock(i + 4, j + 2, k, fence, 0, 2);
		world.setBlock(i + 4, j + 3, k, fence, 0, 2);
		world.setBlock(i + 4, j + 1, k, cobbledGrimstone2, 0, 2);
		world.setBlock(i + 4, j + 2, k + 1, air);
		world.setBlock(i + 4, j + 2, k + 2, air);
		world.setBlock(i + 4, j + 2, k + 3, air);
		world.setBlock(i + 4, j + 2, k + 4, air);
		world.setBlock(i + 4, j + 2, k + 5, cobbledGrimstone, 0, 2);
		world.setBlock(i + 4, j + 2, k + 6, air);
		world.setBlock(i + 4, j + 2, k + 7, air);
		world.setBlock(i + 4, j + 2, k + 8, air);
		world.setBlock(i + 4, j + 2, k + 9, air);
		world.setBlock(i + 4, j + 2, k + 10, cobbledGrimstone, 0, 2);
		world.setBlock(i + 4, j + 2, k + 11, air);
		world.setBlock(i + 4, j + 3, k + 1, air);
		world.setBlock(i + 4, j + 3, k + 2, air);
		world.setBlock(i + 4, j + 3, k + 3, air);
		world.setBlock(i + 4, j + 3, k + 4, air);
		world.setBlock(i + 4, j + 3, k + 5, planks, 5, 2);
		world.setBlock(i + 4, j + 3, k + 6, air);
		world.setBlock(i + 4, j + 3, k + 7, air);
		world.setBlock(i + 4, j + 3, k + 8, air);
		world.setBlock(i + 4, j + 3, k + 9, air);
		world.setBlock(i + 4, j + 3, k + 10, planks, 5, 2);
		world.setBlock(i + 4, j + 3, k + 11, air);
		world.setBlock(i + 4, j + 4, k + 4, stairsWoodOak, 2, 2);
		world.setBlock(i + 4, j + 4, k + 5, planks, 5, 2);
		world.setBlock(i + 4, j + 4, k + 6, air);
		world.setBlock(i + 4, j + 4, k + 7, air);
		world.setBlock(i + 4, j + 4, k + 8, air);
		world.setBlock(i + 4, j + 4, k + 9, air);
		world.setBlock(i + 4, j + 4, k + 10, planks, 5, 2);
		world.setBlock(i + 4, j + 4, k + 11, stairsWoodOak, 3, 2);
		world.setBlock(i + 4, j + 5, k, air);
		world.setBlock(i + 4, j + 5, k + 1, air);
		world.setBlock(i + 4, j + 5, k + 2, air);
		world.setBlock(i + 4, j + 5, k + 3, air);
		world.setBlock(i + 4, j + 5, k + 4, air);
		world.setBlock(i + 4, j + 5, k + 5, stairsWoodOak, 2, 2);
		world.setBlock(i + 4, j + 5, k + 6, planks, 5, 2);
		world.setBlock(i + 4, j + 5, k + 7, air);
		world.setBlock(i + 4, j + 5, k + 8, air);
		world.setBlock(i + 4, j + 5, k + 9, planks, 5, 2);
		world.setBlock(i + 4, j + 5, k + 10, stairsWoodOak, 3, 2);
		world.setBlock(i + 4, j + 5, k + 11, air);
		world.setBlock(i + 4, j + 6, k, air);
		world.setBlock(i + 4, j + 6, k + 1, air);
		world.setBlock(i + 4, j + 6, k + 2, air);
		world.setBlock(i + 4, j + 6, k + 3, air);
		world.setBlock(i + 4, j + 6, k + 4, air);
		world.setBlock(i + 4, j + 6, k + 5, air);
		world.setBlock(i + 4, j + 6, k + 6, stairsWoodOak, 2, 2);
		world.setBlock(i + 4, j + 6, k + 7, planks, 5, 2);
		world.setBlock(i + 4, j + 6, k + 8, planks, 5, 2);
		world.setBlock(i + 4, j + 6, k + 9, stairsWoodOak, 3, 2);
		world.setBlock(i + 4, j + 6, k + 10, air);
		world.setBlock(i + 4, j + 6, k + 11, air);
		world.setBlock(i + 4, j + 7, k, air);
		world.setBlock(i + 4, j + 7, k + 1, air);
		world.setBlock(i + 4, j + 7, k + 2, air);
		world.setBlock(i + 4, j + 7, k + 3, air);
		world.setBlock(i + 4, j + 7, k + 4, air);
		world.setBlock(i + 4, j + 7, k + 5, air);
		world.setBlock(i + 4, j + 7, k + 6, air);
		world.setBlock(i + 4, j + 7, k + 7, stairsWoodOak, 2, 2);
		world.setBlock(i + 4, j + 7, k + 8, stairsWoodOak, 3, 2);
		world.setBlock(i + 4, j + 7, k + 9, air);
		world.setBlock(i + 4, j + 7, k + 10, air);
		world.setBlock(i + 4, j + 7, k + 11, air);
		world.setBlock(i + 5, j + 1, k + 1, Nullstone, 0, 2);
		world.setBlock(i + 5, j + 1, k + 2, Nullstone, 0, 2);
		world.setBlock(i + 5, j + 1, k + 3, Nullstone, 0, 2);
		world.setBlock(i + 5, j + 1, k + 4, Nullstone, 0, 2);
		
		world.setBlock(i + 5, j + 4, k, NovaCraftBlocks.sculk_brick_slab, 5, 2);
		world.setBlock(i + 5, j + 4, k + 1, NovaCraftBlocks.sculk_brick_slab, 5, 2);
		world.setBlock(i + 5, j + 4, k + 2, NovaCraftBlocks.sculk_brick_slab, 5, 2);
		world.setBlock(i + 5, j + 4, k + 3, NovaCraftBlocks.sculk_brick_slab, 5, 2);
		world.setBlock(i + 5, j + 4, k + 4, NovaCraftBlocks.sculk_brick_slab, 5, 2);
		
		world.setBlock(i + 5, j + 1, k + 5, cobbledGrimstone, 0, 2);
		world.setBlock(i + 5, j + 1, k + 6, planks, 5, 2);
		world.setBlock(i + 5, j + 1, k + 7, sculkBlock, 0, 2);
		world.setBlock(i + 5, j + 1, k + 8, sculkBlock, 0, 2);
		world.setBlock(i + 5, j + 1, k + 9, sculkBlock, 0, 2);
		world.setBlock(i + 5, j + 1, k + 10, cobbledGrimstone, 0, 2);
		world.setBlock(i + 5, j + 1, k + 11, air);
		world.setBlock(i + 5, j + 2, k, fence, 0, 2);
		world.setBlock(i + 5, j + 3, k, fence, 0, 2);
		world.setBlock(i + 5, j + 1, k, cobbledGrimstone2, 0, 2);
		world.setBlock(i + 5, j + 2, k + 1, air);
		world.setBlock(i + 5, j + 2, k + 2, air);
		world.setBlock(i + 5, j + 2, k + 3, air);
		world.setBlock(i + 5, j + 2, k + 4, air);
		world.setBlock(i + 5, j + 2, k + 5, cobbledGrimstone, 0, 2);
		world.setBlock(i + 5, j + 2, k + 6, air);
		world.setBlock(i + 5, j + 2, k + 7, air);
		world.setBlock(i + 5, j + 2, k + 8, air);
		world.setBlock(i + 5, j + 2, k + 9, air);
		world.setBlock(i + 5, j + 2, k + 10, cobbledGrimstone, 0, 2);
		world.setBlock(i + 5, j + 2, k + 11, air);
		world.setBlock(i + 5, j + 3, k + 1, air);
		world.setBlock(i + 5, j + 3, k + 2, air);
		world.setBlock(i + 5, j + 3, k + 3, air);
		world.setBlock(i + 5, j + 3, k + 4, air);
		world.setBlock(i + 5, j + 3, k + 5, planks, 5, 2);
		world.setBlock(i + 5, j + 3, k + 6, air);
		world.setBlock(i + 5, j + 3, k + 7, air);
		world.setBlock(i + 5, j + 3, k + 8, air);
		world.setBlock(i + 5, j + 3, k + 9, air);
		world.setBlock(i + 5, j + 3, k + 10, thinGlass, 0, 2);
		world.setBlock(i + 5, j + 3, k + 11, air);
		world.setBlock(i + 5, j + 4, k + 4, stairsWoodOak, 2, 2);
		world.setBlock(i + 5, j + 4, k + 5, planks, 5, 2);
		world.setBlock(i + 5, j + 4, k + 6, air);
		world.setBlock(i + 5, j + 4, k + 7, air);
		world.setBlock(i + 5, j + 4, k + 8, air);
		world.setBlock(i + 5, j + 4, k + 9, air);
		world.setBlock(i + 5, j + 4, k + 10, planks, 5, 2);
		world.setBlock(i + 5, j + 4, k + 11, stairsWoodOak, 3, 2);
		world.setBlock(i + 5, j + 5, k, air);
		world.setBlock(i + 5, j + 5, k + 1, air);
		world.setBlock(i + 5, j + 5, k + 2, air);
		world.setBlock(i + 5, j + 5, k + 3, air);
		world.setBlock(i + 5, j + 5, k + 4, air);
		world.setBlock(i + 5, j + 5, k + 5, stairsWoodOak, 2, 2);
		world.setBlock(i + 5, j + 5, k + 6, planks, 5, 2);
		world.setBlock(i + 5, j + 5, k + 7, air);
		world.setBlock(i + 5, j + 5, k + 8, air);
		world.setBlock(i + 5, j + 5, k + 9, planks, 5, 2);
		world.setBlock(i + 5, j + 5, k + 10, stairsWoodOak, 3, 2);
		world.setBlock(i + 5, j + 5, k + 11, air);
		world.setBlock(i + 5, j + 6, k, air);
		world.setBlock(i + 5, j + 6, k + 1, air);
		world.setBlock(i + 5, j + 6, k + 2, air);
		world.setBlock(i + 5, j + 6, k + 3, air);
		world.setBlock(i + 5, j + 6, k + 4, air);
		world.setBlock(i + 5, j + 6, k + 5, air);
		world.setBlock(i + 5, j + 6, k + 6, stairsWoodOak, 2, 2);
		world.setBlock(i + 5, j + 6, k + 7, planks, 5, 2);
		world.setBlock(i + 5, j + 6, k + 8, planks, 5, 2);
		world.setBlock(i + 5, j + 6, k + 9, stairsWoodOak, 3, 2);
		world.setBlock(i + 5, j + 6, k + 10, air);
		world.setBlock(i + 5, j + 6, k + 11, air);
		world.setBlock(i + 5, j + 7, k, air);
		world.setBlock(i + 5, j + 7, k + 1, air);
		world.setBlock(i + 5, j + 7, k + 2, air);
		world.setBlock(i + 5, j + 7, k + 3, air);
		world.setBlock(i + 5, j + 7, k + 4, air);
		world.setBlock(i + 5, j + 7, k + 5, air);
		world.setBlock(i + 5, j + 7, k + 6, air);
		world.setBlock(i + 5, j + 7, k + 7, stairsWoodOak, 2, 2);
		world.setBlock(i + 5, j + 7, k + 8, stairsWoodOak, 3, 2);
		world.setBlock(i + 5, j + 7, k + 9, air);
		world.setBlock(i + 5, j + 7, k + 10, air);
		world.setBlock(i + 5, j + 7, k + 11, air);
		world.setBlock(i + 6, j + 1, k + 1, Nullstone, 0, 2);
		world.setBlock(i + 6, j + 1, k + 2, Nullstone, 0, 2);
		world.setBlock(i + 6, j + 1, k + 3, Nullstone, 0, 2);
		world.setBlock(i + 6, j + 1, k + 4, Nullstone, 0, 2);
		
		world.setBlock(i + 6, j + 4, k, NovaCraftBlocks.sculk_brick_slab, 5, 2);
		world.setBlock(i + 6, j + 4, k + 1, NovaCraftBlocks.sculk_brick_slab, 5, 2);
		world.setBlock(i + 6, j + 4, k + 2, NovaCraftBlocks.sculk_brick_slab, 5, 2);
		world.setBlock(i + 6, j + 4, k + 3, NovaCraftBlocks.sculk_brick_slab, 5, 2);
		world.setBlock(i + 6, j + 4, k + 4, NovaCraftBlocks.sculk_brick_slab, 5, 2);
		
		world.setBlock(i + 6, j + 1, k + 5, cobbledGrimstone, 0, 2);
		world.setBlock(i + 6, j + 1, k + 6, planks, 5, 2);
		world.setBlock(i + 6, j + 1, k + 7, sculkBlock, 0, 2);
		world.setBlock(i + 6, j + 1, k + 8, sculkBlock, 0, 2);
		world.setBlock(i + 6, j + 1, k + 9, sculkBlock, 0, 2);
		world.setBlock(i + 6, j + 1, k + 10, cobbledGrimstone, 0, 2);
		world.setBlock(i + 6, j + 1, k + 11, air);
		world.setBlock(i + 6, j + 2, k, fence, 0, 2);
		world.setBlock(i + 6, j + 3, k, fence, 0, 2);
		world.setBlock(i + 6, j + 1, k, cobbledGrimstone2, 0, 2);
		world.setBlock(i + 6, j + 2, k + 1, air);
		world.setBlock(i + 6, j + 2, k + 2, air);
		world.setBlock(i + 6, j + 2, k + 3, air);
		world.setBlock(i + 6, j + 2, k + 4, air);
		world.setBlock(i + 6, j + 2, k + 6, air);
		world.setBlock(i + 6, j + 2, k + 7, air);
		world.setBlock(i + 6, j + 2, k + 8, sculkBlock, 0, 2);
		world.setBlock(i + 6, j + 2, k + 9, sculkBlock, 0, 2);
		world.setBlock(i + 6, j + 2, k + 10, cobbledGrimstone, 0, 2);
		world.setBlock(i + 6, j + 2, k + 11, air);
		world.setBlock(i + 6, j + 3, k + 1, air);
		world.setBlock(i + 6, j + 3, k + 2, air);
		world.setBlock(i + 6, j + 3, k + 3, air);
		world.setBlock(i + 6, j + 3, k + 4, air);
		world.setBlock(i + 6, j + 3, k + 6, air);
		world.setBlock(i + 6, j + 3, k + 7, air);
		world.setBlock(i + 6, j + 3, k + 8, air);
		world.setBlock(i + 6, j + 3, k + 9, air);
		world.setBlock(i + 6, j + 3, k + 10, planks, 5, 2);
		world.setBlock(i + 6, j + 3, k + 11, air);
		world.setBlock(i + 6, j + 4, k + 4, stairsWoodOak, 2, 2);
		world.setBlock(i + 6, j + 4, k + 5, planks, 5, 2);
		world.setBlock(i + 6, j + 4, k + 7, air);
		world.setBlock(i + 6, j + 4, k + 8, air);
		world.setBlock(i + 6, j + 4, k + 9, air);
		world.setBlock(i + 6, j + 4, k + 10, planks, 5, 2);
		world.setBlock(i + 6, j + 4, k + 11, stairsWoodOak, 3, 2);
		world.setBlock(i + 6, j + 5, k, air);
		world.setBlock(i + 6, j + 5, k + 1, air);
		world.setBlock(i + 6, j + 5, k + 2, air);
		world.setBlock(i + 6, j + 5, k + 3, air);
		world.setBlock(i + 6, j + 5, k + 4, air);
		world.setBlock(i + 6, j + 5, k + 5, stairsWoodOak, 2, 2);
		world.setBlock(i + 6, j + 5, k + 6, planks, 5, 2);
		world.setBlock(i + 6, j + 5, k + 7, air);
		world.setBlock(i + 6, j + 5, k + 8, air);
		world.setBlock(i + 6, j + 5, k + 9, planks, 5, 2);
		world.setBlock(i + 6, j + 5, k + 10, stairsWoodOak, 3, 2);
		world.setBlock(i + 6, j + 5, k + 11, air);
		world.setBlock(i + 6, j + 6, k, air);
		world.setBlock(i + 6, j + 6, k + 1, air);
		world.setBlock(i + 6, j + 6, k + 2, air);
		world.setBlock(i + 6, j + 6, k + 3, air);
		world.setBlock(i + 6, j + 6, k + 4, air);
		world.setBlock(i + 6, j + 6, k + 5, air);
		world.setBlock(i + 6, j + 6, k + 6, stairsWoodOak, 2, 2);
		world.setBlock(i + 6, j + 6, k + 7, planks, 5, 2);
		world.setBlock(i + 6, j + 6, k + 8, planks, 5, 2);
		world.setBlock(i + 6, j + 6, k + 9, stairsWoodOak, 3, 2);
		world.setBlock(i + 6, j + 6, k + 10, air);
		world.setBlock(i + 6, j + 6, k + 11, air);
		world.setBlock(i + 6, j + 7, k, air);
		world.setBlock(i + 6, j + 7, k + 1, air);
		world.setBlock(i + 6, j + 7, k + 2, air);
		world.setBlock(i + 6, j + 7, k + 3, air);
		world.setBlock(i + 6, j + 7, k + 4, air);
		world.setBlock(i + 6, j + 7, k + 5, air);
		world.setBlock(i + 6, j + 7, k + 6, air);
		world.setBlock(i + 6, j + 7, k + 7, stairsWoodOak, 2, 2);
		world.setBlock(i + 6, j + 7, k + 8, stairsWoodOak, 3, 2);
		world.setBlock(i + 6, j + 7, k + 9, air);
		world.setBlock(i + 6, j + 7, k + 10, air);
		world.setBlock(i + 6, j + 7, k + 11, air);;
		world.setBlock(i + 7, j + 1, k + 1, Nullstone, 0, 2);
		world.setBlock(i + 7, j + 1, k + 2, Nullstone, 0, 2);
		world.setBlock(i + 7, j + 1, k + 3, Nullstone, 0, 2);
		world.setBlock(i + 7, j + 1, k + 4, Nullstone, 0, 2);
		world.setBlock(i + 7, j + 4, k, NovaCraftBlocks.sculk_brick_slab, 5, 2);
		world.setBlock(i + 7, j + 4, k + 1, NovaCraftBlocks.sculk_brick_slab, 5, 2);
		world.setBlock(i + 7, j + 4, k + 2, NovaCraftBlocks.sculk_brick_slab, 5, 2);
		world.setBlock(i + 7, j + 4, k + 3, NovaCraftBlocks.sculk_brick_slab, 5, 2);
		world.setBlock(i + 7, j + 4, k + 4, NovaCraftBlocks.sculk_brick_slab, 5, 2);
		if(rand.nextInt(2) == 0) {
			world.setBlock(i + 5, j + 2, k + 4, Blocks.brown_mushroom, 0, 2);
		}
		if(rand.nextInt(2) == 0) {
			world.setBlock(i + 4, j + 2, k + 4, Blocks.red_mushroom, 0, 2);
		}
		world.setBlock(i + 7, j + 1, k + 5, cobbledGrimstone, 0, 2);
		world.setBlock(i + 7, j + 1, k + 6, planks, 5, 2);
		world.setBlock(i + 7, j + 1, k + 7, sculkBlock, 0, 2);
		world.setBlock(i + 7, j + 1, k + 8, sculkBlock, 0, 2);
		world.setBlock(i + 7, j + 1, k + 9, sculkBlock, 0, 2);
		world.setBlock(i + 7, j + 1, k + 10, cobbledGrimstone, 0, 2);
		world.setBlock(i + 7, j + 1, k + 11, air);
		world.setBlock(i + 7, j + 2, k, fence, 0, 2);
		world.setBlock(i + 7, j + 3, k, fence, 0, 2);
		world.setBlock(i + 7, j + 1, k, cobbledGrimstone2, 0, 2);
		world.setBlock(i + 7, j + 2, k + 1, air);
		world.setBlock(i + 7, j + 2, k + 2, air);
		world.setBlock(i + 7, j + 2, k + 3, air);
		world.setBlock(i + 7, j + 2, k + 4, air);
		world.setBlock(i + 7, j + 2, k + 5, cobbledGrimstone, 0, 2);
		world.setBlock(i + 7, j + 2, k + 6, air);
		world.setBlock(i + 7, j + 2, k + 7, air);
		world.setBlock(i + 7, j + 2, k + 8, air);
		world.setBlock(i + 7, j + 2, k + 9, air);
		world.setBlock(i + 7, j + 2, k + 10, cobbledGrimstone, 0, 2);
		world.setBlock(i + 7, j + 2, k + 11, air);
		world.setBlock(i + 7, j + 3, k + 1, air);
		world.setBlock(i + 7, j + 3, k + 2, air);
		world.setBlock(i + 7, j + 3, k + 3, air);
		world.setBlock(i + 7, j + 3, k + 4, air);
		world.setBlock(i + 7, j + 3, k + 5, planks, 5, 2);
		world.setBlock(i + 7, j + 3, k + 6, air);
		world.setBlock(i + 7, j + 3, k + 7, air);
		world.setBlock(i + 7, j + 3, k + 8, air);
		world.setBlock(i + 7, j + 3, k + 9, air);
		world.setBlock(i + 7, j + 3, k + 10, planks, 5, 2);
		world.setBlock(i + 7, j + 3, k + 11, air);
		world.setBlock(i + 7, j + 4, k + 4, stairsWoodOak, 2, 2);
		world.setBlock(i + 7, j + 4, k + 5, planks, 5, 2);
		world.setBlock(i + 7, j + 4, k + 6, air);
		world.setBlock(i + 7, j + 4, k + 7, air);
		world.setBlock(i + 7, j + 4, k + 8, air);
		world.setBlock(i + 7, j + 4, k + 9, air);
		world.setBlock(i + 7, j + 4, k + 10, planks, 5, 2);
		world.setBlock(i + 7, j + 4, k + 11, stairsWoodOak, 3, 2);
		world.setBlock(i + 7, j + 5, k, air);
		world.setBlock(i + 7, j + 5, k + 1, air);
		world.setBlock(i + 7, j + 5, k + 2, air);
		world.setBlock(i + 7, j + 5, k + 3, air);
		world.setBlock(i + 7, j + 5, k + 4, air);
		world.setBlock(i + 7, j + 5, k + 5, stairsWoodOak, 2, 2);
		world.setBlock(i + 7, j + 5, k + 6, planks, 5, 2);
		world.setBlock(i + 7, j + 5, k + 7, air);
		world.setBlock(i + 7, j + 5, k + 8, air);
		world.setBlock(i + 7, j + 5, k + 9, planks, 5, 2);
		world.setBlock(i + 7, j + 5, k + 10, stairsWoodOak, 3, 2);
		world.setBlock(i + 7, j + 5, k + 11, air);
		world.setBlock(i + 7, j + 6, k, air);
		world.setBlock(i + 7, j + 6, k + 1, air);
		world.setBlock(i + 7, j + 6, k + 2, air);
		world.setBlock(i + 7, j + 6, k + 3, air);
		world.setBlock(i + 7, j + 6, k + 4, air);
		world.setBlock(i + 7, j + 6, k + 5, air);
		world.setBlock(i + 7, j + 6, k + 6, stairsWoodOak, 2, 2);
		world.setBlock(i + 7, j + 6, k + 7, planks, 5, 2);
		world.setBlock(i + 7, j + 6, k + 8, planks, 5, 2);
		world.setBlock(i + 7, j + 6, k + 9, stairsWoodOak, 3, 2);
		world.setBlock(i + 7, j + 6, k + 10, air);
		world.setBlock(i + 7, j + 6, k + 11, air);
		world.setBlock(i + 7, j + 7, k, air);
		world.setBlock(i + 7, j + 7, k + 1, air);
		world.setBlock(i + 7, j + 7, k + 2, air);
		world.setBlock(i + 7, j + 7, k + 3, air);
		world.setBlock(i + 7, j + 7, k + 4, air);
		world.setBlock(i + 7, j + 7, k + 5, air);
		world.setBlock(i + 7, j + 7, k + 6, air);
		world.setBlock(i + 7, j + 7, k + 7, stairsWoodOak, 2, 2);
		world.setBlock(i + 7, j + 7, k + 8, stairsWoodOak, 3, 2);
		world.setBlock(i + 7, j + 7, k + 9, air);
		world.setBlock(i + 7, j + 7, k + 10, air);
		world.setBlock(i + 7, j + 7, k + 11, air);
		
		world.setBlock(i + 8, j + 4, k, NovaCraftBlocks.sculk_brick_slab, 5, 2);
		world.setBlock(i + 8, j + 4, k + 1, NovaCraftBlocks.sculk_brick_slab, 5, 2);
		world.setBlock(i + 8, j + 4, k + 2, NovaCraftBlocks.sculk_brick_slab, 5, 2);
		world.setBlock(i + 8, j + 4, k + 3, NovaCraftBlocks.sculk_brick_slab, 5, 2);
		world.setBlock(i + 8, j + 4, k + 4, NovaCraftBlocks.sculk_brick_slab, 5, 2);
		
		world.setBlock(i + 8, j + 1, k + 5, cobbledGrimstone, 0, 2);
		world.setBlock(i + 8, j + 1, k + 6, cobbledGrimstone, 0, 2);
		world.setBlock(i + 8, j + 1, k + 7, cobbledGrimstone, 0, 2);
		world.setBlock(i + 8, j + 1, k + 8, cobbledGrimstone, 0, 2);
		world.setBlock(i + 8, j + 1, k + 9, cobbledGrimstone, 0, 2);
		world.setBlock(i + 8, j + 1, k + 10, cobbledGrimstone, 0, 2);
		world.setBlock(i + 8, j + 1, k + 11, air);
		world.setBlock(i + 8, j + 2, k, fence, 0, 2);
		world.setBlock(i + 8, j + 2, k + 1, fence, 0, 2);
		world.setBlock(i + 8, j + 2, k + 2, fence, 0, 2);
		world.setBlock(i + 8, j + 2, k + 3, fence, 0, 2);
		world.setBlock(i + 8, j + 2, k + 4, fence, 0, 2);
		
		world.setBlock(i + 8, j + 3, k, fence, 0, 2);
		world.setBlock(i + 8, j + 3, k + 1, fence, 0, 2);
		world.setBlock(i + 8, j + 3, k + 2, fence, 0, 2);
		world.setBlock(i + 8, j + 3, k + 3, fence, 0, 2);
		world.setBlock(i + 8, j + 3, k + 4, fence, 0, 2);
		
		world.setBlock(i + 8, j + 1, k, cobbledGrimstone2, 0, 2);
		world.setBlock(i + 8, j + 1, k + 1, cobbledGrimstone2, 0, 2);
		world.setBlock(i + 8, j + 1, k + 2, cobbledGrimstone2, 0, 2);
		world.setBlock(i + 8, j + 1, k + 3, cobbledGrimstone2, 0, 2);
		world.setBlock(i + 8, j + 1, k + 4, cobbledGrimstone2, 0, 2);
		
		world.setBlock(i + 8, j + 2, k + 5, cobbledGrimstone, 0, 2);
		world.setBlock(i + 8, j + 2, k + 6, cobbledGrimstone, 0, 2);
		world.setBlock(i + 8, j + 2, k + 7, cobbledGrimstone, 0, 2);
		world.setBlock(i + 8, j + 2, k + 8, cobbledGrimstone, 0, 2);
		world.setBlock(i + 8, j + 2, k + 9, cobbledGrimstone, 0, 2);
		world.setBlock(i + 8, j + 2, k + 10, cobbledGrimstone, 0, 2);
		world.setBlock(i + 8, j + 2, k + 11, air);
		world.setBlock(i + 8, j + 3, k + 5, cobbledGrimstone, 0, 2);
		world.setBlock(i + 8, j + 3, k + 6, wood, 1, 2);
		world.setBlock(i + 8, j + 3, k + 7, thinGlass, 0, 2);
		world.setBlock(i + 8, j + 3, k + 8, thinGlass, 0, 2);
		world.setBlock(i + 8, j + 3, k + 9, wood, 1, 2);
		world.setBlock(i + 8, j + 3, k + 10, cobbledGrimstone, 0, 2);
		world.setBlock(i + 8, j + 3, k + 11, air);
		world.setBlock(i + 8, j + 4, k + 4, stairsWoodOak, 2, 2);
		world.setBlock(i + 8, j + 4, k + 5, cobbledGrimstone, 0, 2);
		world.setBlock(i + 8, j + 4, k + 6, cobbledGrimstone, 0, 2);
		world.setBlock(i + 8, j + 4, k + 7, cobbledGrimstone, 0, 2);
		world.setBlock(i + 8, j + 4, k + 8, cobbledGrimstone, 0, 2);
		world.setBlock(i + 8, j + 4, k + 9, cobbledGrimstone, 0, 2);
		world.setBlock(i + 8, j + 4, k + 10, cobbledGrimstone, 0, 2);
		world.setBlock(i + 8, j + 4, k + 11, stairsWoodOak, 3, 2);
		world.setBlock(i + 8, j + 5, k, air);
		world.setBlock(i + 8, j + 5, k + 1, air);
		world.setBlock(i + 8, j + 5, k + 2, air);
		world.setBlock(i + 8, j + 5, k + 3, air);
		world.setBlock(i + 8, j + 5, k + 4, air);
		world.setBlock(i + 8, j + 5, k + 5, stairsWoodOak, 2, 2);
		world.setBlock(i + 8, j + 5, k + 6, planks, 5, 2);
		world.setBlock(i + 8, j + 5, k + 7, planks, 5, 2);
		world.setBlock(i + 8, j + 5, k + 8, planks, 5, 2);
		world.setBlock(i + 8, j + 5, k + 9, planks, 5, 2);
		world.setBlock(i + 8, j + 5, k + 10, stairsWoodOak, 3, 2);
		world.setBlock(i + 8, j + 5, k + 11, air);
		world.setBlock(i + 8, j + 6, k, air);
		world.setBlock(i + 8, j + 6, k + 1, air);
		world.setBlock(i + 8, j + 6, k + 2, air);
		world.setBlock(i + 8, j + 6, k + 3, air);
		world.setBlock(i + 8, j + 6, k + 4, air);
		world.setBlock(i + 8, j + 6, k + 5, air);
		world.setBlock(i + 8, j + 6, k + 6, stairsWoodOak, 2, 2);
		world.setBlock(i + 8, j + 6, k + 7, planks, 5, 2);
		world.setBlock(i + 8, j + 6, k + 8, planks, 5, 2);
		world.setBlock(i + 8, j + 6, k + 9, stairsWoodOak, 3, 2);
		world.setBlock(i + 8, j + 6, k + 10, air);
		world.setBlock(i + 8, j + 6, k + 11, air);
		world.setBlock(i + 8, j + 7, k, air);
		world.setBlock(i + 8, j + 7, k + 1, air);
		world.setBlock(i + 8, j + 7, k + 2, air);
		world.setBlock(i + 8, j + 7, k + 3, air);
		world.setBlock(i + 8, j + 7, k + 4, air);
		world.setBlock(i + 8, j + 7, k + 5, air);
		world.setBlock(i + 8, j + 7, k + 6, air);
		world.setBlock(i + 8, j + 7, k + 7, stairsWoodOak, 2, 2);
		world.setBlock(i + 8, j + 7, k + 8, stairsWoodOak, 3, 2);
		world.setBlock(i + 8, j + 7, k + 9, air);
		world.setBlock(i + 8, j + 7, k + 10, air);
		world.setBlock(i + 8, j + 7, k + 11, air);
		world.setBlock(i + 2, j + 2, k + 10, doorWood, 3, 2);
		world.setBlock(i + 2, j + 3, k + 7, Blocks.stone_slab, 0, 2);
		world.setBlock(i + 2, j + 3, k + 10, doorWood, 8, 2);
		world.setBlock(i + 2, j + 4, k + 9, sculkVein, 2, 2);
		world.setBlock(i + 6, j + 2, k + 5, doorWood, 1, 2);
		world.setBlock(i + 6, j + 3, k + 5, doorWood, 8, 2);
		world.setBlock(i + 6, j + 4, k + 6, sculkVein, 3, 2);

		for(int posX = i; posX <= i + 8; posX++)
			for(int posZ = k; posZ <= k + 11; posZ++){
				int posY = j;				
				boolean isFloorFinished = false;
				while(isFloorFinished == false){					
					if(world.getBlock(posX, posY, posZ) == air || world.getBlock(posX, posY, posZ) == Blocks.tallgrass || world.getBlock(posX, posY, posZ) == Blocks.cactus || world.getBlock(posX, posY, posZ) == Blocks.red_flower || world.getBlock(posX, posY, posZ) == Blocks.yellow_flower || world.getBlock(posX, posY, posZ) == Blocks.deadbush || world.getBlock(posX, posY, posZ) == Blocks.snow || world.getBlock(posX, posY, posZ) == Blocks.water || world.getBlock(posX, posY, posZ) == Blocks.lava || world.getBlock(posX, posY, posZ) == Blocks.brown_mushroom || world.getBlock(posX, posY, posZ) == Blocks.red_mushroom || world.getBlock(posX, posY, posZ) == Blocks.waterlily){
						world.setBlock(posX, posY, posZ, cobbledGrimstone, 0, 2);
						posY--;
					}
					else
						isFloorFinished = true;
				}
			}
			EntityIllagerTrader mob = new EntityIllagerTrader(world);
			mob.setPosition(i + 2, j + 2, k + 12);
			world.spawnEntityInWorld(mob);

			EntityIllagerTrader mob2 = new EntityIllagerTrader(world);
			mob2.setPosition(i + 1, j + 2, k + 12);
			world.spawnEntityInWorld(mob2);

		return true;
	}
}
