package com.NovaCraft.world.village;

import java.util.Random;
import com.NovaCraft.entity.illager.EntityVindicator;
import net.minecraft.init.Blocks;
import net.minecraft.world.World;
import net.minecraft.world.gen.feature.WorldGenerator;

public class VindicatorRandomHouse extends WorldGenerator
{	

	public VindicatorRandomHouse() { 
		
	}

	public boolean generate(World world, Random rand, int i, int j, int k) {

		if (world.getBlock(i, j - 1, k) != Blocks.air && world.getBlock(i, j - 1, k) != Blocks.leaves 
		&& world.getBlock(i + 5, j - 1, k) != Blocks.air && world.getBlock(i + 5, j - 1, k) != Blocks.leaves
		&& world.getBlock(i, j - 1, k + 4) != Blocks.air && world.getBlock(i, j - 1, k + 4) != Blocks.leaves
		&& world.getBlock(i + 5, j - 1, k + 4) != Blocks.air && world.getBlock(i + 5, j - 1, k + 4) != Blocks.leaves
		&& world.getBlock(i + 5, j - 1, k + 3) != Blocks.air && world.getBlock(i + 5, j - 1, k + 3) != Blocks.leaves
		&& world.getBlock(i, j + 7, k) == Blocks.air
		&& world.getBlock(i + 5, j + 7, k) == Blocks.air
		&& world.getBlock(i, j + 7, k + 4) == Blocks.air
		&& world.getBlock(i + 5, j + 7, k + 4) == Blocks.air
		&& world.getBlock(i + 5, j + 7, k + 3) == Blocks.air) {
	
	int random2 = rand.nextInt(24);
	if (random2 > 12) {
		world.setBlock(i, j, k, Blocks.cobblestone, 0, 2);
		world.setBlock(i + 1, j, k, Blocks.cobblestone, 0, 2);
		world.setBlock(i + 2, j, k, Blocks.cobblestone, 0, 2);
		world.setBlock(i + 3, j, k, Blocks.cobblestone, 0, 2);
		world.setBlock(i + 4, j, k, Blocks.cobblestone, 0, 2);
		world.setBlock(i + 5, j, k, Blocks.cobblestone, 0, 2);
		world.setBlock(i + 6, j, k, Blocks.air, 0, 2);
		world.setBlock(i, j, k + 1, Blocks.cobblestone, 0, 2);
		world.setBlock(i + 1, j, k + 1, Blocks.cobblestone, 0, 2);
		world.setBlock(i + 2, j, k + 1, Blocks.cobblestone, 0, 2);
		world.setBlock(i + 3, j, k + 1, Blocks.cobblestone, 0, 2);
		world.setBlock(i + 4, j, k + 1, Blocks.cobblestone, 0, 2);
		world.setBlock(i + 5, j, k + 1, Blocks.cobblestone, 0, 2);
		world.setBlock(i + 6, j, k + 1, Blocks.air, 0, 2);
		world.setBlock(i, j, k + 2, Blocks.cobblestone, 0, 2);
		world.setBlock(i + 1, j, k + 2, Blocks.cobblestone, 0, 2);
		world.setBlock(i + 3, j, k + 2, Blocks.cobblestone, 0, 2);
		world.setBlock(i + 4, j, k + 2, Blocks.cobblestone, 0, 2);
		world.setBlock(i + 5, j, k + 2, Blocks.cobblestone, 0, 2);
		world.setBlock(i + 6, j, k + 2, Blocks.stone_stairs, 1, 2);
		world.setBlock(i, j, k + 3, Blocks.cobblestone, 0, 2);
		world.setBlock(i + 1, j, k + 3, Blocks.cobblestone, 0, 2);
		world.setBlock(i + 2, j, k + 3, Blocks.cobblestone, 0, 2);
		world.setBlock(i + 3, j, k + 3, Blocks.cobblestone, 0, 2);
		world.setBlock(i + 4, j, k + 3, Blocks.cobblestone, 0, 2);
		world.setBlock(i + 5, j, k + 3, Blocks.cobblestone, 0, 2);
		world.setBlock(i + 6, j, k + 3, Blocks.air, 0, 2);
		world.setBlock(i, j, k + 4, Blocks.cobblestone, 0, 2);
		world.setBlock(i + 1, j, k + 4, Blocks.cobblestone, 0, 2);
		world.setBlock(i + 2, j, k + 4, Blocks.cobblestone, 0, 2);
		world.setBlock(i + 3, j, k + 4, Blocks.cobblestone, 0, 2);
		world.setBlock(i + 4, j, k + 4, Blocks.cobblestone, 0, 2);
		world.setBlock(i + 5, j, k + 4, Blocks.cobblestone, 0, 2);
		world.setBlock(i + 6, j, k + 4, Blocks.air, 0, 2);
		world.setBlock(i, j + 1, k, Blocks.log, 0, 2);
		world.setBlock(i + 1, j + 1, k, Blocks.planks, 0, 2);
		world.setBlock(i + 2, j + 1, k, Blocks.planks, 0, 2);
		world.setBlock(i + 3, j + 1, k, Blocks.planks, 0, 2);
		world.setBlock(i + 4, j + 1, k, Blocks.planks, 0, 2);
		world.setBlock(i + 5, j + 1, k, Blocks.log, 0, 2);
		world.setBlock(i + 6, j + 1, k, Blocks.air, 0, 2);
		world.setBlock(i, j + 1, k + 1, Blocks.planks, 0, 2);
		world.setBlock(i + 1, j + 1, k + 1, Blocks.fence, 0, 2);
		world.setBlock(i + 2, j + 1, k + 1, Blocks.stone_stairs, 0, 2);
		world.setBlock(i + 3, j + 1, k + 1, Blocks.cobblestone, 0, 2);
		world.setBlock(i + 4, j + 1, k + 1, Blocks.air, 0, 2);
		world.setBlock(i + 5, j + 1, k + 1, Blocks.planks, 0, 2);
		world.setBlock(i + 6, j + 1, k + 1, Blocks.air, 0, 2);
		world.setBlock(i, j + 1, k + 2, Blocks.planks, 0, 2);
		world.setBlock(i + 1, j + 1, k + 2, Blocks.ladder, 5, 2);
		world.setBlock(i + 2, j + 1, k + 2, Blocks.carpet, 14, 2);
		world.setBlock(i + 3, j + 1, k + 2, Blocks.carpet, 14, 2);
		world.setBlock(i + 4, j + 1, k + 2, Blocks.air, 0, 2);
		world.setBlock(i + 5, j + 1, k + 2, Blocks.wooden_door, 2, 2);
		world.setBlock(i + 6, j + 1, k + 2, Blocks.air, 0, 2);
		world.setBlock(i, j + 1, k + 3, Blocks.planks, 0, 2);
		world.setBlock(i + 1, j + 1, k + 3, Blocks.air, 0, 2);
		world.setBlock(i + 2, j + 1, k + 3, Blocks.air, 0, 2);
		world.setBlock(i + 3, j + 1, k + 3, Blocks.air, 0, 2);
		world.setBlock(i + 4, j + 1, k + 3, Blocks.air, 0, 2);
		world.setBlock(i + 5, j + 1, k + 3, Blocks.planks, 0, 2);
		world.setBlock(i + 6, j + 1, k + 3, Blocks.air, 0, 2);
		world.setBlock(i, j + 1, k + 4, Blocks.log, 0, 2);
		world.setBlock(i + 1, j + 1, k + 4, Blocks.planks, 0, 2);
		world.setBlock(i + 2, j + 1, k + 4, Blocks.planks, 0, 2);
		world.setBlock(i + 3, j + 1, k + 4, Blocks.planks, 0, 2);
		world.setBlock(i + 4, j + 1, k + 4, Blocks.planks, 0, 2);
		world.setBlock(i + 5, j + 1, k + 4, Blocks.log, 0, 2);
		world.setBlock(i + 6, j + 1, k + 4, Blocks.air, 0, 2);
		world.setBlock(i, j + 2, k, Blocks.log, 0, 2);
		world.setBlock(i + 1, j + 2, k, Blocks.planks, 0, 2);
		world.setBlock(i + 2, j + 2, k, Blocks.glass_pane, 0, 2);
		world.setBlock(i + 3, j + 2, k, Blocks.glass_pane, 0, 2);
		world.setBlock(i + 4, j + 2, k, Blocks.planks, 0, 2);
		world.setBlock(i + 5, j + 2, k, Blocks.log, 0, 2);
		world.setBlock(i + 6, j + 2, k, Blocks.air, 0, 2);
		world.setBlock(i, j + 2, k + 1, Blocks.planks, 0, 2);
		world.setBlock(i + 1, j + 2, k + 1, Blocks.wooden_pressure_plate, 0, 2);
		world.setBlock(i + 2, j + 2, k + 1, Blocks.air, 0, 2);
		world.setBlock(i + 3, j + 2, k + 1, Blocks.flower_pot, 5, 2);
		world.setBlock(i + 4, j + 2, k + 1, Blocks.torch, 3, 2);
		world.setBlock(i + 5, j + 2, k + 1, Blocks.planks, 0, 2);
		world.setBlock(i + 6, j + 2, k + 1, Blocks.torch, 1, 2);
		world.setBlock(i, j + 2, k + 2, Blocks.planks, 0, 2);
		world.setBlock(i + 1, j + 2, k + 2, Blocks.ladder, 5, 2);
		world.setBlock(i + 2, j + 2, k + 2, Blocks.air, 0, 2);
		world.setBlock(i + 3, j + 2, k + 2, Blocks.air, 0, 2);
		world.setBlock(i + 4, j + 2, k + 2, Blocks.air, 0, 2);
		world.setBlock(i + 5, j + 2, k + 2, Blocks.wooden_door, 8, 2);
		world.setBlock(i + 6, j + 2, k + 2, Blocks.air, 0, 2);
		world.setBlock(i, j + 2, k + 3, Blocks.planks, 0, 2);
		world.setBlock(i + 1, j + 2, k + 3, Blocks.torch, 1, 2);
		world.setBlock(i + 2, j + 2, k + 3, Blocks.air, 0, 2);
		world.setBlock(i + 3, j + 2, k + 3, Blocks.air, 0, 2);
		world.setBlock(i + 4, j + 2, k + 3, Blocks.torch, 4, 2);
		world.setBlock(i + 5, j + 2, k + 3, Blocks.planks, 0, 2);
		world.setBlock(i + 6, j + 2, k + 3, Blocks.torch, 1, 2);
		world.setBlock(i, j + 2, k + 4, Blocks.log, 0, 2);
		world.setBlock(i + 1, j + 2, k + 4, Blocks.planks, 0, 2);
		world.setBlock(i + 2, j + 2, k + 4, Blocks.glass_pane, 0, 2);
		world.setBlock(i + 3, j + 2, k + 4, Blocks.glass_pane, 0, 2);
		world.setBlock(i + 4, j + 2, k + 4, Blocks.planks, 0, 2);
		world.setBlock(i + 5, j + 2, k + 4, Blocks.log, 0, 2);
		world.setBlock(i + 6, j + 2, k + 4, Blocks.air, 0, 2);
		world.setBlock(i, j + 3, k, Blocks.log, 0, 2);
		world.setBlock(i + 1, j + 3, k, Blocks.planks, 0, 2);
		world.setBlock(i + 2, j + 3, k, Blocks.planks, 0, 2);
		world.setBlock(i + 3, j + 3, k, Blocks.planks, 0, 2);
		world.setBlock(i + 4, j + 3, k, Blocks.planks, 0, 2);
		world.setBlock(i + 5, j + 3, k, Blocks.log, 0, 2);
		world.setBlock(i + 6, j + 3, k, Blocks.air, 0, 2);
		world.setBlock(i, j + 3, k + 1, Blocks.planks, 0, 2);
		world.setBlock(i + 1, j + 3, k + 1, Blocks.air, 0, 2);
		world.setBlock(i + 2, j + 3, k + 1, Blocks.air, 0, 2);
		world.setBlock(i + 3, j + 3, k + 1, Blocks.air, 0, 2);
		world.setBlock(i + 4, j + 3, k + 1, Blocks.air, 0, 2);
		world.setBlock(i + 5, j + 3, k + 1, Blocks.planks, 0, 2);
		world.setBlock(i + 6, j + 3, k + 1, Blocks.air, 0, 2);
		world.setBlock(i, j + 3, k + 2, Blocks.planks, 0, 2);
		world.setBlock(i + 1, j + 3, k + 2, Blocks.ladder, 5, 2);
		world.setBlock(i + 2, j + 3, k + 2, Blocks.air, 0, 2);
		world.setBlock(i + 3, j + 3, k + 2, Blocks.air, 0, 2);
		world.setBlock(i + 4, j + 3, k + 2, Blocks.air, 0, 2);
		world.setBlock(i + 5, j + 3, k + 2, Blocks.planks, 0, 2);
		world.setBlock(i + 6, j + 3, k + 2, Blocks.air, 0, 2);
		world.setBlock(i, j + 3, k + 3, Blocks.planks, 0, 2);
		world.setBlock(i + 1, j + 3, k + 3, Blocks.air, 0, 2);
		world.setBlock(i + 2, j + 3, k + 3, Blocks.air, 0, 2);
		world.setBlock(i + 3, j + 3, k + 3, Blocks.air, 0, 2);
		world.setBlock(i + 4, j + 3, k + 3, Blocks.air, 0, 2);
		world.setBlock(i + 5, j + 3, k + 3, Blocks.planks, 0, 2);
		world.setBlock(i + 6, j + 3, k + 3, Blocks.air, 0, 2);
		world.setBlock(i, j + 3, k + 4, Blocks.log, 0, 2);
		world.setBlock(i + 1, j + 3, k + 4, Blocks.planks, 0, 2);
		world.setBlock(i + 2, j + 3, k + 4, Blocks.planks, 0, 2);
		world.setBlock(i + 3, j + 3, k + 4, Blocks.planks, 0, 2);
		world.setBlock(i + 4, j + 3, k + 4, Blocks.planks, 0, 2);
		world.setBlock(i + 5, j + 3, k + 4, Blocks.log, 0, 2);
		world.setBlock(i + 6, j + 3, k + 4, Blocks.air, 0, 2);
		world.setBlock(i, j + 4, k, Blocks.air, 0, 2);
		world.setBlock(i + 1, j + 4, k, Blocks.log, 0, 2);
		world.setBlock(i + 2, j + 4, k, Blocks.log, 0, 2);
		world.setBlock(i + 3, j + 4, k, Blocks.log, 0, 2);
		world.setBlock(i + 4, j + 4, k, Blocks.log, 0, 2);
		world.setBlock(i + 5, j + 4, k, Blocks.air, 0, 2);
		world.setBlock(i + 6, j + 4, k, Blocks.air, 0, 2);
		world.setBlock(i, j + 4, k + 1, Blocks.log, 0, 2);
		world.setBlock(i + 1, j + 4, k + 1, Blocks.cobblestone, 0, 2);
		world.setBlock(i + 2, j + 4, k + 1, Blocks.planks, 0, 2);
		world.setBlock(i + 3, j + 4, k + 1, Blocks.planks, 0, 2);
		world.setBlock(i + 4, j + 4, k + 1, Blocks.cobblestone, 0, 2);
		world.setBlock(i + 5, j + 4, k + 1, Blocks.log, 0, 2);
		world.setBlock(i + 6, j + 4, k + 1, Blocks.air, 0, 2);
		world.setBlock(i, j + 4, k + 2, Blocks.log, 0, 2);
		world.setBlock(i + 1, j + 4, k + 2, Blocks.trapdoor, 10, 2);
		world.setBlock(i + 2, j + 4, k + 2, Blocks.planks, 0, 2);
		world.setBlock(i + 3, j + 4, k + 2, Blocks.planks, 0, 2);
		world.setBlock(i + 4, j + 4, k + 2, Blocks.planks, 0, 2);
		world.setBlock(i + 5, j + 4, k + 2, Blocks.log, 0, 2);
		world.setBlock(i + 6, j + 4, k + 2, Blocks.air, 0, 2);
		world.setBlock(i, j + 4, k + 3, Blocks.log, 0, 2);
		world.setBlock(i + 1, j + 4, k + 3, Blocks.cobblestone, 0, 2);
		world.setBlock(i + 2, j + 4, k + 3, Blocks.planks, 0, 2);
		world.setBlock(i + 3, j + 4, k + 3, Blocks.planks, 0, 2);
		world.setBlock(i + 4, j + 4, k + 3, Blocks.cobblestone, 0, 2);
		world.setBlock(i + 5, j + 4, k + 3, Blocks.log, 0, 2);
		world.setBlock(i + 6, j + 4, k + 3, Blocks.air, 0, 2);
		world.setBlock(i, j + 4, k + 4, Blocks.air, 0, 2);
		world.setBlock(i + 1, j + 4, k + 4, Blocks.log, 0, 2);
		world.setBlock(i + 2, j + 4, k + 4, Blocks.log, 0, 2);
		world.setBlock(i + 3, j + 4, k + 4, Blocks.log, 0, 2);
		world.setBlock(i + 4, j + 4, k + 4, Blocks.log, 0, 2);
		world.setBlock(i + 5, j + 4, k + 4, Blocks.air, 0, 2);
		world.setBlock(i + 6, j + 4, k + 4, Blocks.air, 0, 2);
		world.setBlock(i, j + 5, k, Blocks.air, 0, 2);
		world.setBlock(i + 1, j + 5, k, Blocks.cobblestone_wall, 0, 2);
		world.setBlock(i + 2, j + 5, k, Blocks.cobblestone_wall, 0, 2);
		world.setBlock(i + 3, j + 5, k, Blocks.cobblestone_wall, 0, 2);
		world.setBlock(i + 4, j + 5, k, Blocks.cobblestone_wall, 0, 2);
		world.setBlock(i + 5, j + 5, k, Blocks.air, 0, 2);
		world.setBlock(i + 6, j + 5, k, Blocks.air, 0, 2);
		world.setBlock(i, j + 5, k + 1, Blocks.cobblestone_wall, 0, 2);
		world.setBlock(i + 1, j + 5, k + 1, Blocks.cobblestone_wall, 0, 2);
		world.setBlock(i + 2, j + 5, k + 1, Blocks.air, 0, 2);
		world.setBlock(i + 3, j + 5, k + 1, Blocks.air, 0, 2);
		world.setBlock(i + 4, j + 5, k + 1, Blocks.cobblestone_wall, 0, 2);
		world.setBlock(i + 5, j + 5, k + 1, Blocks.cobblestone_wall, 0, 2);
		world.setBlock(i + 6, j + 5, k + 1, Blocks.air, 0, 2);
		world.setBlock(i, j + 5, k + 2, Blocks.cobblestone_wall, 0, 2);
		world.setBlock(i + 1, j + 5, k + 2, Blocks.air, 0, 2);
		world.setBlock(i + 2, j + 5, k + 2, Blocks.air, 0, 2);
		world.setBlock(i + 3, j + 5, k + 2, Blocks.air, 0, 2);
		world.setBlock(i + 4, j + 5, k + 2, Blocks.air, 0, 2);
		world.setBlock(i + 5, j + 5, k + 2, Blocks.cobblestone_wall, 0, 2);
		world.setBlock(i + 6, j + 5, k + 2, Blocks.air, 0, 2);
		world.setBlock(i, j + 5, k + 3, Blocks.cobblestone_wall, 0, 2);
		world.setBlock(i + 1, j + 5, k + 3, Blocks.cobblestone_wall, 0, 2);
		world.setBlock(i + 2, j + 5, k + 3, Blocks.air, 0, 2);
		world.setBlock(i + 3, j + 5, k + 3, Blocks.air, 0, 2);
		world.setBlock(i + 4, j + 5, k + 3, Blocks.cobblestone_wall, 0, 2);
		world.setBlock(i + 5, j + 5, k + 3, Blocks.cobblestone_wall, 0, 2);
		world.setBlock(i + 6, j + 5, k + 3, Blocks.air, 0, 2);
		world.setBlock(i, j + 5, k + 4, Blocks.air, 0, 2);
		world.setBlock(i + 1, j + 5, k + 4, Blocks.cobblestone_wall, 0, 2);
		world.setBlock(i + 2, j + 5, k + 4, Blocks.cobblestone_wall, 0, 2);
		world.setBlock(i + 3, j + 5, k + 4, Blocks.cobblestone_wall, 0, 2);
		world.setBlock(i + 4, j + 5, k + 4, Blocks.cobblestone_wall, 0, 2);
		world.setBlock(i + 5, j + 5, k + 4, Blocks.air, 0, 2);
		world.setBlock(i + 6, j + 5, k + 4, Blocks.air, 0, 2);
		world.setBlock(i, j + 6, k, Blocks.air, 0, 2);
		world.setBlock(i + 1, j + 6, k, Blocks.air, 0, 2);
		world.setBlock(i + 2, j + 6, k, Blocks.air, 0, 2);
		world.setBlock(i + 3, j + 6, k, Blocks.air, 0, 2);
		world.setBlock(i + 4, j + 6, k, Blocks.air, 0, 2);
		world.setBlock(i + 5, j + 6, k, Blocks.air, 0, 2);
		world.setBlock(i + 6, j + 6, k, Blocks.air, 0, 2);
		world.setBlock(i, j + 6, k + 1, Blocks.air, 0, 2);
		world.setBlock(i + 1, j + 6, k + 1, Blocks.torch, 5, 2);
		world.setBlock(i + 2, j + 6, k + 1, Blocks.air, 0, 2);
		world.setBlock(i + 3, j + 6, k + 1, Blocks.air, 0, 2);
		world.setBlock(i + 4, j + 6, k + 1, Blocks.torch, 5, 2);
		world.setBlock(i + 5, j + 6, k + 1, Blocks.air, 0, 2);
		world.setBlock(i + 6, j + 6, k + 1, Blocks.air, 0, 2);
		world.setBlock(i, j + 6, k + 2, Blocks.air, 0, 2);
		world.setBlock(i + 1, j + 6, k + 2, Blocks.air, 0, 2);
		world.setBlock(i + 2, j + 6, k + 2, Blocks.air, 0, 2);
		world.setBlock(i + 3, j + 6, k + 2, Blocks.air, 0, 2);
		world.setBlock(i + 4, j + 6, k + 2, Blocks.air, 0, 2);
		world.setBlock(i + 5, j + 6, k + 2, Blocks.air, 0, 2);
		world.setBlock(i + 6, j + 6, k + 2, Blocks.air, 0, 2);
		world.setBlock(i, j + 6, k + 3, Blocks.air, 0, 2);
		world.setBlock(i + 1, j + 6, k + 3, Blocks.torch, 5, 2);
		world.setBlock(i + 2, j + 6, k + 3, Blocks.air, 0, 2);
		world.setBlock(i + 3, j + 6, k + 3, Blocks.air, 0, 2);
		world.setBlock(i + 4, j + 6, k + 3, Blocks.torch, 5, 2);
		world.setBlock(i + 5, j + 6, k + 3, Blocks.air, 0, 2);
		world.setBlock(i + 6, j + 6, k + 3, Blocks.air, 0, 2);
		world.setBlock(i, j + 6, k + 4, Blocks.air, 0, 2);
		world.setBlock(i + 1, j + 6, k + 4, Blocks.air, 0, 2);
		world.setBlock(i + 2, j + 6, k + 4, Blocks.air, 0, 2);
		world.setBlock(i + 3, j + 6, k + 4, Blocks.air, 0, 2);
		world.setBlock(i + 4, j + 6, k + 4, Blocks.air, 0, 2);
		world.setBlock(i + 5, j + 6, k + 4, Blocks.air, 0, 2);
		world.setBlock(i + 6, j + 6, k + 4, Blocks.air, 0, 2);
		world.setBlock(i + 2, j, k + 2, Blocks.cobblestone, 8, 2);
		
		EntityVindicator entity = new EntityVindicator(world);
		entity.setPosition(i + 2, j + 2, k + 2);
		world.spawnEntityInWorld(entity);
		
		int random = rand.nextInt(24);
		if (random > 12) {
			world.setBlock(i + 2, j, k + 2, Blocks.trapdoor, 8, 2);
			new VindicatorRandomHouseLadder().generate(world, rand, i + 1, j - 5, k + 1);
			new VindicatorRandomHouseWorshipRoom().generate(world, rand, i, j - 10, k + 1);
		}
		
		return true;
	}
	else {

		world.setBlock(i, j, k, Blocks.cobblestone, 0, 2);
		world.setBlock(i + 1, j, k, Blocks.cobblestone, 0, 2);
		world.setBlock(i + 2, j, k, Blocks.cobblestone, 0, 2);
		world.setBlock(i + 3, j, k, Blocks.cobblestone, 0, 2);
		world.setBlock(i + 4, j, k, Blocks.cobblestone, 0, 2);
		world.setBlock(i + 5, j, k, Blocks.cobblestone, 0, 2);
		world.setBlock(i + 6, j, k, Blocks.air, 0, 2);
		world.setBlock(i, j, k + 1, Blocks.cobblestone, 0, 2);
		world.setBlock(i + 1, j, k + 1, Blocks.cobblestone, 0, 2);
		world.setBlock(i + 2, j, k + 1, Blocks.cobblestone, 0, 2);
		world.setBlock(i + 3, j, k + 1, Blocks.cobblestone, 0, 2);
		world.setBlock(i + 4, j, k + 1, Blocks.cobblestone, 0, 2);
		world.setBlock(i + 5, j, k + 1, Blocks.cobblestone, 0, 2);
		world.setBlock(i + 6, j, k + 1, Blocks.air, 0, 2);
		world.setBlock(i, j, k + 2, Blocks.cobblestone, 0, 2);
		world.setBlock(i + 1, j, k + 2, Blocks.air, 0, 2);
		world.setBlock(i + 2, j, k + 2, Blocks.cobblestone, 8, 2);
		world.setBlock(i + 3, j, k + 2, Blocks.cobblestone, 0, 2);
		world.setBlock(i + 4, j, k + 2, Blocks.cobblestone, 0, 2);
		world.setBlock(i + 5, j, k + 2, Blocks.cobblestone, 0, 2);
		world.setBlock(i + 6, j, k + 2, Blocks.stone_stairs, 1, 2);
		world.setBlock(i, j, k + 3, Blocks.cobblestone, 0, 2);
		world.setBlock(i + 1, j, k + 3, Blocks.cobblestone, 0, 2);
		world.setBlock(i + 2, j, k + 3, Blocks.cobblestone, 0, 2);
		world.setBlock(i + 3, j, k + 3, Blocks.cobblestone, 0, 2);
		world.setBlock(i + 4, j, k + 3, Blocks.air, 0, 2);
		world.setBlock(i + 5, j, k + 3, Blocks.cobblestone, 0, 2);
		world.setBlock(i + 6, j, k + 3, Blocks.air, 0, 2);
		world.setBlock(i, j, k + 4, Blocks.cobblestone, 0, 2);
		world.setBlock(i + 1, j, k + 4, Blocks.cobblestone, 0, 2);
		world.setBlock(i + 2, j, k + 4, Blocks.cobblestone, 0, 2);
		world.setBlock(i + 3, j, k + 4, Blocks.cobblestone, 0, 2);
		world.setBlock(i + 4, j, k + 4, Blocks.cobblestone, 0, 2);
		world.setBlock(i + 5, j, k + 4, Blocks.cobblestone, 0, 2);
		world.setBlock(i + 6, j, k + 4, Blocks.air, 0, 2);
		world.setBlock(i, j + 1, k, Blocks.log, 0, 2);
		world.setBlock(i + 1, j + 1, k, Blocks.planks, 0, 2);
		world.setBlock(i + 2, j + 1, k, Blocks.planks, 0, 2);
		world.setBlock(i + 3, j + 1, k, Blocks.air, 0, 2);
		world.setBlock(i + 4, j + 1, k, Blocks.planks, 0, 2);
		world.setBlock(i + 5, j + 1, k, Blocks.log, 0, 2);
		world.setBlock(i + 6, j + 1, k, Blocks.air, 0, 2);
		world.setBlock(i, j + 1, k + 1, Blocks.planks, 0, 2);
		world.setBlock(i + 1, j + 1, k + 1, Blocks.fence, 0, 2);
		world.setBlock(i + 2, j + 1, k + 1, Blocks.stone_stairs, 0, 2);
		world.setBlock(i + 3, j + 1, k + 1, Blocks.air, 0, 2);
		world.setBlock(i + 4, j + 1, k + 1, Blocks.air, 0, 2);
		world.setBlock(i + 5, j + 1, k + 1, Blocks.planks, 0, 2);
		world.setBlock(i + 6, j + 1, k + 1, Blocks.air, 0, 2);
		world.setBlock(i, j + 1, k + 2, Blocks.planks, 0, 2);
		world.setBlock(i + 1, j + 1, k + 2, Blocks.ladder, 5, 2);
		world.setBlock(i + 1, j, k + 2, Blocks.cobblestone, 0, 2);
		world.setBlock(i + 2, j + 1, k + 2, Blocks.carpet, 14, 2);
		world.setBlock(i + 3, j + 1, k + 2, Blocks.carpet, 14, 2);
		world.setBlock(i + 4, j + 1, k + 2, Blocks.air, 0, 2);
		world.setBlock(i + 5, j + 1, k + 2, Blocks.air, 0, 2);
		world.setBlock(i + 6, j + 1, k + 2, Blocks.air, 0, 2);
		world.setBlock(i, j + 1, k + 3, Blocks.planks, 0, 2);
		world.setBlock(i + 1, j + 1, k + 3, Blocks.air, 0, 2);
		world.setBlock(i + 2, j + 1, k + 3, Blocks.air, 0, 2);
		world.setBlock(i + 3, j + 1, k + 3, Blocks.air, 0, 2);
		world.setBlock(i + 4, j + 1, k + 3, Blocks.air, 0, 2);
		world.setBlock(i + 5, j + 1, k + 3, Blocks.planks, 0, 2);
		world.setBlock(i + 6, j + 1, k + 3, Blocks.air, 0, 2);
		world.setBlock(i, j + 1, k + 4, Blocks.log, 0, 2);
		world.setBlock(i + 1, j + 1, k + 4, Blocks.planks, 0, 2);
		world.setBlock(i + 2, j + 1, k + 4, Blocks.planks, 0, 2);
		world.setBlock(i + 3, j + 1, k + 4, Blocks.planks, 0, 2);
		world.setBlock(i + 4, j + 1, k + 4, Blocks.planks, 0, 2);
		world.setBlock(i + 5, j + 1, k + 4, Blocks.log, 0, 2);
		world.setBlock(i + 6, j + 1, k + 4, Blocks.air, 0, 2);
		world.setBlock(i, j + 2, k, Blocks.log, 0, 2);
		world.setBlock(i + 1, j + 2, k, Blocks.planks, 0, 2);
		world.setBlock(i + 2, j + 2, k, Blocks.glass_pane, 0, 2);
		world.setBlock(i + 3, j + 2, k, Blocks.glass_pane, 0, 2);
		world.setBlock(i + 4, j + 2, k, Blocks.planks, 0, 2);
		world.setBlock(i + 5, j + 2, k, Blocks.log, 0, 2);
		world.setBlock(i + 6, j + 2, k, Blocks.air, 0, 2);
		world.setBlock(i, j + 2, k + 1, Blocks.planks, 0, 2);
		world.setBlock(i + 1, j + 2, k + 1, Blocks.air, 0, 2);
		world.setBlock(i + 2, j + 2, k + 1, Blocks.air, 0, 2);
		world.setBlock(i + 3, j + 2, k + 1, Blocks.air, 0, 2);
		world.setBlock(i + 4, j + 2, k + 1, Blocks.air, 0, 2);
		world.setBlock(i + 5, j + 2, k + 1, Blocks.planks, 0, 2);
		world.setBlock(i + 6, j + 2, k + 1, Blocks.air, 0, 2);
		world.setBlock(i, j + 2, k + 2, Blocks.planks, 0, 2);
		world.setBlock(i + 1, j + 2, k + 2, Blocks.air, 0, 2);
		world.setBlock(i + 2, j + 2, k + 2, Blocks.air, 0, 2);
		world.setBlock(i + 3, j + 2, k + 2, Blocks.air, 0, 2);
		world.setBlock(i + 4, j + 2, k + 2, Blocks.air, 0, 2);
		world.setBlock(i + 5, j + 2, k + 2, Blocks.air, 0, 2);
		world.setBlock(i + 6, j + 2, k + 2, Blocks.air, 0, 2);
		world.setBlock(i, j + 2, k + 3, Blocks.planks, 0, 2);
		world.setBlock(i + 1, j + 2, k + 3, Blocks.air, 0, 2);
		world.setBlock(i + 2, j + 2, k + 3, Blocks.air, 0, 2);
		world.setBlock(i + 3, j + 2, k + 3, Blocks.air, 0, 2);
		world.setBlock(i + 4, j + 2, k + 3, Blocks.air, 0, 2);
		world.setBlock(i + 5, j + 2, k + 3, Blocks.air, 0, 2);
		world.setBlock(i + 6, j + 2, k + 3, Blocks.air, 0, 2);
		world.setBlock(i, j + 2, k + 4, Blocks.log, 0, 2);
		world.setBlock(i + 1, j + 2, k + 4, Blocks.planks, 0, 2);
		world.setBlock(i + 2, j + 2, k + 4, Blocks.air, 0, 2);
		world.setBlock(i + 3, j + 2, k + 4, Blocks.glass_pane, 0, 2);
		world.setBlock(i + 4, j + 2, k + 4, Blocks.planks, 0, 2);
		world.setBlock(i + 5, j + 2, k + 4, Blocks.log, 0, 2);
		world.setBlock(i + 6, j + 2, k + 4, Blocks.air, 0, 2);
		world.setBlock(i, j + 3, k, Blocks.log, 0, 2);
		world.setBlock(i + 1, j + 3, k, Blocks.planks, 0, 2);
		world.setBlock(i + 2, j + 3, k, Blocks.planks, 0, 2);
		world.setBlock(i + 3, j + 3, k, Blocks.planks, 0, 2);
		world.setBlock(i + 4, j + 3, k, Blocks.planks, 0, 2);
		world.setBlock(i + 5, j + 3, k, Blocks.log, 0, 2);
		world.setBlock(i + 6, j + 3, k, Blocks.air, 0, 2);
		world.setBlock(i, j + 3, k + 1, Blocks.air, 0, 2);
		world.setBlock(i + 1, j + 3, k + 1, Blocks.air, 0, 2);
		world.setBlock(i + 2, j + 3, k + 1, Blocks.air, 0, 2);
		world.setBlock(i + 3, j + 3, k + 1, Blocks.air, 0, 2);
		world.setBlock(i + 4, j + 3, k + 1, Blocks.air, 0, 2);
		world.setBlock(i + 5, j + 3, k + 1, Blocks.planks, 0, 2);
		world.setBlock(i + 6, j + 3, k + 1, Blocks.air, 0, 2);
		world.setBlock(i, j + 3, k + 2, Blocks.planks, 0, 2);
		world.setBlock(i + 1, j + 3, k + 2, Blocks.ladder, 5, 2);
		world.setBlock(i + 2, j + 3, k + 2, Blocks.air, 0, 2);
		world.setBlock(i + 3, j + 3, k + 2, Blocks.air, 0, 2);
		world.setBlock(i + 4, j + 3, k + 2, Blocks.air, 0, 2);
		world.setBlock(i + 5, j + 3, k + 2, Blocks.planks, 0, 2);
		world.setBlock(i + 6, j + 3, k + 2, Blocks.air, 0, 2);
		world.setBlock(i, j + 3, k + 3, Blocks.planks, 0, 2);
		world.setBlock(i + 1, j + 3, k + 3, Blocks.air, 0, 2);
		world.setBlock(i + 2, j + 3, k + 3, Blocks.air, 0, 2);
		world.setBlock(i + 3, j + 3, k + 3, Blocks.air, 0, 2);
		world.setBlock(i + 4, j + 3, k + 3, Blocks.air, 0, 2);
		world.setBlock(i + 5, j + 3, k + 3, Blocks.planks, 0, 2);
		world.setBlock(i + 6, j + 3, k + 3, Blocks.air, 0, 2);
		world.setBlock(i, j + 3, k + 4, Blocks.log, 0, 2);
		world.setBlock(i + 1, j + 3, k + 4, Blocks.air, 0, 2);
		world.setBlock(i + 2, j + 3, k + 4, Blocks.planks, 0, 2);
		world.setBlock(i + 3, j + 3, k + 4, Blocks.planks, 0, 2);
		world.setBlock(i + 4, j + 3, k + 4, Blocks.planks, 0, 2);
		world.setBlock(i + 5, j + 3, k + 4, Blocks.log, 0, 2);
		world.setBlock(i + 6, j + 3, k + 4, Blocks.air, 0, 2);
		world.setBlock(i, j + 4, k, Blocks.air, 0, 2);
		world.setBlock(i + 1, j + 4, k, Blocks.log, 0, 2);
		world.setBlock(i + 2, j + 4, k, Blocks.log, 0, 2);
		world.setBlock(i + 3, j + 4, k, Blocks.air, 0, 2);
		world.setBlock(i + 4, j + 4, k, Blocks.log, 0, 2);
		world.setBlock(i + 5, j + 4, k, Blocks.air, 0, 2);
		world.setBlock(i + 6, j + 4, k, Blocks.air, 0, 2);
		world.setBlock(i, j + 4, k + 1, Blocks.log, 0, 2);
		world.setBlock(i + 1, j + 4, k + 1, Blocks.cobblestone, 0, 2);
		world.setBlock(i + 2, j + 4, k + 1, Blocks.planks, 0, 2);
		world.setBlock(i + 3, j + 4, k + 1, Blocks.planks, 0, 2);
		world.setBlock(i + 4, j + 4, k + 1, Blocks.air, 0, 2);
		world.setBlock(i + 5, j + 4, k + 1, Blocks.air, 0, 2);
		world.setBlock(i + 6, j + 4, k + 1, Blocks.air, 0, 2);
		world.setBlock(i, j + 4, k + 2, Blocks.log, 0, 2);
		world.setBlock(i + 1, j + 4, k + 2, Blocks.air, 0, 2);
		world.setBlock(i + 2, j + 4, k + 2, Blocks.planks, 0, 2);
		world.setBlock(i + 3, j + 4, k + 2, Blocks.air, 0, 2);
		world.setBlock(i + 4, j + 4, k + 2, Blocks.air, 0, 2);
		world.setBlock(i + 5, j + 4, k + 2, Blocks.log, 0, 2);
		world.setBlock(i + 6, j + 4, k + 2, Blocks.air, 0, 2);
		world.setBlock(i, j + 4, k + 3, Blocks.log, 0, 2);
		world.setBlock(i + 1, j + 4, k + 3, Blocks.cobblestone, 0, 2);
		world.setBlock(i + 2, j + 4, k + 3, Blocks.planks, 0, 2);
		world.setBlock(i + 3, j + 4, k + 3, Blocks.planks, 0, 2);
		world.setBlock(i + 4, j + 4, k + 3, Blocks.cobblestone, 0, 2);
		world.setBlock(i + 5, j + 4, k + 3, Blocks.air, 0, 2);
		world.setBlock(i + 6, j + 4, k + 3, Blocks.air, 0, 2);
		world.setBlock(i, j + 4, k + 4, Blocks.air, 0, 2);
		world.setBlock(i + 1, j + 4, k + 4, Blocks.log, 0, 2);
		world.setBlock(i + 2, j + 4, k + 4, Blocks.air, 0, 2);
		world.setBlock(i + 3, j + 4, k + 4, Blocks.air, 0, 2);
		world.setBlock(i + 4, j + 4, k + 4, Blocks.air, 0, 2);
		world.setBlock(i + 5, j + 4, k + 4, Blocks.air, 0, 2);
		world.setBlock(i + 6, j + 4, k + 4, Blocks.air, 0, 2);
		
		EntityVindicator entity = new EntityVindicator(world);
		entity.setPosition(i + 2, j + 2, k + 2);
		world.spawnEntityInWorld(entity);
		
		int random = rand.nextInt(24);
		if (random > 12) {
			world.setBlock(i + 2, j, k + 2, Blocks.trapdoor, 8, 2);
			new VindicatorRandomHouseLadder().generate(world, rand, i + 1, j - 5, k + 1);
			new VindicatorRandomHouseWorshipRoom().generate(world, rand, i, j - 10, k + 1);
		}
		
		return true;
		
	}
	  }
		return false;
	}
}
