package com.NovaCraft.world.structure;

import net.minecraft.world.gen.feature.*;
import net.minecraft.block.*;
import net.minecraft.enchantment.Enchantment;
import net.minecraft.enchantment.EnchantmentData;
import net.minecraft.entity.Entity;
import net.minecraft.entity.item.EntityItem;
import net.minecraft.entity.monster.EntitySkeleton;
import net.minecraft.world.*;
import java.util.*;

import com.NovaCraft.Items.NovaCraftItems;
import com.NovaCraft.config.Configs;
import com.NovaCraft.entity.EntityCreaking;
import com.NovaCraft.entity.EntityCrystalGolem;
import com.NovaCraft.registry.OtherModBlocks;
import com.NovaCraft.registry.OtherModItems;
import com.NovaCraftBlocks.NovaCraftBlocks;

import cpw.mods.fml.common.Loader;
import net.minecraft.init.*;
import net.minecraft.item.ItemStack;
import net.minecraft.tileentity.TileEntityChest;
import net.minecraft.tileentity.TileEntityMobSpawner;
import net.minecraft.util.MathHelper;

public class LargeLuminantTreeStructure extends WorldGenerator
{
	public LargeLuminantTreeStructure() {

	}

	public boolean generate(final World world, final Random random, final int i, final int j, final int k) {
		//if (!world.isAirBlock(i, j + 1, k) || !world.isAirBlock(i, j + 2, k) || !world.isAirBlock(i, j + 3, k) || !world.isAirBlock(i, j + 4, k) || !world.isAirBlock(i, j + 5, k) || (world.getBlock(i, j - 1, k) == Blocks.air) || !(world.getBlock(i, j, k) == Blocks.water || world.getBlock(i, j, k) == Blocks.grass)) return false;
			
		int topY = world.getHeightValue(i, k);
		if (!(world.canBlockSeeTheSky(i, topY, k)) || !world.isAirBlock(i, j - 1, k)) return false;
		
		world.setBlock(i + 10, j + 0, k + 0, NovaCraftBlocks.luminant_log, 8, 2);
		world.setBlock(i + 10, j + 0, k + 1, NovaCraftBlocks.luminant_log, 8, 2);
		world.setBlock(i + 10, j + 0, k + 2, NovaCraftBlocks.luminant_log, 0, 2);
		world.setBlock(i + 11, j + 0, k + 2, NovaCraftBlocks.luminant_log, 0, 2);
		world.setBlock(i + 12, j + 0, k + 2, NovaCraftBlocks.luminant_log, 0, 2);
		world.setBlock(i + 9, j + 0, k + 3, NovaCraftBlocks.luminant_log, 0, 2);
		world.setBlock(i + 10, j + 0, k + 3, NovaCraftBlocks.luminant_log, 0, 2);
		world.setBlock(i + 11, j + 0, k + 3, NovaCraftBlocks.luminant_log, 0, 2);
		world.setBlock(i + 12, j + 0, k + 3, NovaCraftBlocks.luminant_log, 0, 2);
		world.setBlock(i + 13, j + 0, k + 3, NovaCraftBlocks.luminant_log, 0, 2);
		world.setBlock(i + 14, j + 0, k + 3, NovaCraftBlocks.luminant_log, 4, 2);
		world.setBlock(i + 15, j + 0, k + 3, NovaCraftBlocks.luminant_log, 4, 2);
		world.setBlock(i + 16, j + 0, k + 3, NovaCraftBlocks.luminant_log, 4, 2);
		world.setBlock(i + 8, j + 0, k + 4, NovaCraftBlocks.luminant_log, 0, 2);
		world.setBlock(i + 9, j + 0, k + 4, NovaCraftBlocks.luminant_log, 0, 2);
		world.setBlock(i + 10, j + 0, k + 4, NovaCraftBlocks.luminant_log, 0, 2);
		world.setBlock(i + 11, j + 0, k + 4, NovaCraftBlocks.luminant_log, 0, 2);
		world.setBlock(i + 12, j + 0, k + 4, NovaCraftBlocks.luminant_log, 0, 2);
		world.setBlock(i + 13, j + 0, k + 4, NovaCraftBlocks.luminant_log, 0, 2);
		world.setBlock(i + 14, j + 0, k + 4, NovaCraftBlocks.luminant_log, 0, 2);
		world.setBlock(i + 15, j + 0, k + 4, NovaCraftBlocks.luminant_log, 4, 2);
		world.setBlock(i + 8, j + 0, k + 5, NovaCraftBlocks.luminant_log, 0, 2);
		world.setBlock(i + 9, j + 0, k + 5, NovaCraftBlocks.luminant_log, 0, 2);
		world.setBlock(i + 10, j + 0, k + 5, NovaCraftBlocks.luminant_log, 0, 2);
		world.setBlock(i + 11, j + 0, k + 5, NovaCraftBlocks.luminant_log, 0, 2);
		world.setBlock(i + 12, j + 0, k + 5, NovaCraftBlocks.luminant_log, 0, 2);
		world.setBlock(i + 13, j + 0, k + 5, NovaCraftBlocks.luminant_log, 0, 2);
		world.setBlock(i + 14, j + 0, k + 5, NovaCraftBlocks.luminant_log, 0, 2);
		world.setBlock(i + 6, j + 0, k + 6, NovaCraftBlocks.luminant_log, 4, 2);
		world.setBlock(i + 7, j + 0, k + 6, NovaCraftBlocks.luminant_log, 4, 2);
		world.setBlock(i + 8, j + 0, k + 6, NovaCraftBlocks.luminant_log, 0, 2);
		world.setBlock(i + 9, j + 0, k + 6, NovaCraftBlocks.luminant_log, 0, 2);
		world.setBlock(i + 10, j + 0, k + 6, NovaCraftBlocks.luminant_log, 0, 2);
		world.setBlock(i + 11, j + 0, k + 6, NovaCraftBlocks.luminant_log, 0, 2);
		world.setBlock(i + 12, j + 0, k + 6, NovaCraftBlocks.luminant_log, 0, 2);
		world.setBlock(i + 13, j + 0, k + 6, NovaCraftBlocks.luminant_log, 0, 2);
		world.setBlock(i + 14, j + 0, k + 6, NovaCraftBlocks.luminant_log, 0, 2);
		world.setBlock(i + 6, j + 0, k + 7, NovaCraftBlocks.luminant_log, 8, 2);
		world.setBlock(i + 9, j + 0, k + 7, NovaCraftBlocks.luminant_log, 0, 2);
		world.setBlock(i + 10, j + 0, k + 7, NovaCraftBlocks.luminant_log, 0, 2);
		world.setBlock(i + 11, j + 0, k + 7, NovaCraftBlocks.luminant_log, 0, 2);
		world.setBlock(i + 12, j + 0, k + 7, NovaCraftBlocks.luminant_log, 0, 2);
		world.setBlock(i + 13, j + 0, k + 7, NovaCraftBlocks.luminant_log, 0, 2);
		world.setBlock(i + 10, j + 0, k + 8, NovaCraftBlocks.luminant_log, 0, 2);
		world.setBlock(i + 11, j + 0, k + 8, NovaCraftBlocks.luminant_log, 0, 2);
		world.setBlock(i + 12, j + 0, k + 8, NovaCraftBlocks.luminant_log, 0, 2);
		world.setBlock(i + 13, j + 0, k + 8, NovaCraftBlocks.luminant_log, 4, 2);
		world.setBlock(i + 14, j + 0, k + 8, NovaCraftBlocks.luminant_log, 4, 2);
		world.setBlock(i + 13, j + 0, k + 9, NovaCraftBlocks.luminant_log, 8, 2);
		world.setBlock(i + 10, j + 1, k + 2, NovaCraftBlocks.luminant_log, 0, 2);
		world.setBlock(i + 11, j + 1, k + 2, NovaCraftBlocks.luminant_log, 0, 2);
		world.setBlock(i + 12, j + 1, k + 2, NovaCraftBlocks.luminant_log, 0, 2);
		world.setBlock(i + 9, j + 1, k + 3, NovaCraftBlocks.luminant_log, 0, 2);
		world.setBlock(i + 13, j + 1, k + 3, NovaCraftBlocks.luminant_log, 0, 2);
		world.setBlock(i + 8, j + 1, k + 4, NovaCraftBlocks.luminant_log, 0, 2);
		world.setBlock(i + 13, j + 1, k + 4, NovaCraftBlocks.luminant_log, 0, 2);
		world.setBlock(i + 14, j + 1, k + 4, NovaCraftBlocks.luminant_log, 0, 2);
		world.setBlock(i + 8, j + 1, k + 5, NovaCraftBlocks.luminant_log, 0, 2);
		world.setBlock(i + 14, j + 1, k + 5, NovaCraftBlocks.luminant_log, 0, 2);
		world.setBlock(i + 8, j + 1, k + 6, NovaCraftBlocks.luminant_log, 0, 2);
		world.setBlock(i + 9, j + 1, k + 6, NovaCraftBlocks.luminant_log, 0, 2);
		world.setBlock(i + 13, j + 1, k + 6, NovaCraftBlocks.luminant_log, 8, 2);
		world.setBlock(i + 14, j + 1, k + 6, NovaCraftBlocks.luminant_log, 0, 2);
		world.setBlock(i + 9, j + 1, k + 7, NovaCraftBlocks.luminant_log, 0, 2);
		world.setBlock(i + 10, j + 1, k + 7, NovaCraftBlocks.luminant_log, 4, 2);
		world.setBlock(i + 13, j + 1, k + 7, NovaCraftBlocks.luminant_log, 0, 2);
		world.setBlock(i + 10, j + 1, k + 8, NovaCraftBlocks.luminant_log, 0, 2);
		world.setBlock(i + 11, j + 1, k + 8, NovaCraftBlocks.luminant_log, 0, 2);
		world.setBlock(i + 12, j + 1, k + 8, NovaCraftBlocks.luminant_log, 0, 2);
		world.setBlock(i + 10, j + 2, k + 2, NovaCraftBlocks.luminant_log, 0, 2);
		world.setBlock(i + 11, j + 2, k + 2, NovaCraftBlocks.luminant_log, 0, 2);
		world.setBlock(i + 12, j + 2, k + 2, NovaCraftBlocks.luminant_log, 0, 2);
		world.setBlock(i + 9, j + 2, k + 3, NovaCraftBlocks.luminant_log, 0, 2);
		world.setBlock(i + 10, j + 2, k + 3, NovaCraftBlocks.luminant_log, 8, 2);
		world.setBlock(i + 13, j + 2, k + 3, NovaCraftBlocks.luminant_log, 0, 2);
		world.setBlock(i + 8, j + 2, k + 4, NovaCraftBlocks.luminant_log, 0, 2);
		world.setBlock(i + 9, j + 2, k + 4, NovaCraftBlocks.luminant_log, 4, 2);
		world.setBlock(i + 13, j + 2, k + 4, NovaCraftBlocks.luminant_log, 0, 2);
		world.setBlock(i + 14, j + 2, k + 4, NovaCraftBlocks.luminant_log, 0, 2);
		world.setBlock(i + 8, j + 2, k + 5, NovaCraftBlocks.luminant_log, 0, 2);
		world.setBlock(i + 14, j + 2, k + 5, NovaCraftBlocks.luminant_log, 0, 2);
		world.setBlock(i + 8, j + 2, k + 6, NovaCraftBlocks.luminant_log, 0, 2);
		world.setBlock(i + 9, j + 2, k + 6, NovaCraftBlocks.luminant_log, 0, 2);
		world.setBlock(i + 14, j + 2, k + 6, NovaCraftBlocks.luminant_log, 0, 2);
		world.setBlock(i + 9, j + 2, k + 7, NovaCraftBlocks.luminant_log, 0, 2);
		world.setBlock(i + 13, j + 2, k + 7, NovaCraftBlocks.luminant_log, 0, 2);
		world.setBlock(i + 10, j + 2, k + 8, NovaCraftBlocks.luminant_log, 0, 2);
		world.setBlock(i + 11, j + 2, k + 8, NovaCraftBlocks.luminant_log, 0, 2);
		world.setBlock(i + 12, j + 2, k + 8, NovaCraftBlocks.luminant_log, 0, 2);
		world.setBlock(i + 10, j + 3, k + 2, NovaCraftBlocks.luminant_log, 0, 2);
		world.setBlock(i + 11, j + 3, k + 2, NovaCraftBlocks.luminant_log, 0, 2);
		world.setBlock(i + 12, j + 3, k + 2, NovaCraftBlocks.luminant_log, 0, 2);
		world.setBlock(i + 9, j + 3, k + 3, NovaCraftBlocks.luminant_log, 0, 2);
		world.setBlock(i + 13, j + 3, k + 3, NovaCraftBlocks.luminant_log, 0, 2);
		world.setBlock(i + 8, j + 3, k + 4, NovaCraftBlocks.luminant_log, 0, 2);
		world.setBlock(i + 13, j + 3, k + 4, NovaCraftBlocks.luminant_log, 0, 2);
		world.setBlock(i + 14, j + 3, k + 4, NovaCraftBlocks.luminant_log, 0, 2);
		world.setBlock(i + 8, j + 3, k + 5, NovaCraftBlocks.luminant_log, 0, 2);
		world.setBlock(i + 14, j + 3, k + 5, NovaCraftBlocks.luminant_log, 0, 2);
		world.setBlock(i + 8, j + 3, k + 6, NovaCraftBlocks.luminant_log, 0, 2);
		world.setBlock(i + 9, j + 3, k + 6, NovaCraftBlocks.luminant_log, 0, 2);
		world.setBlock(i + 14, j + 3, k + 6, NovaCraftBlocks.luminant_log, 0, 2);
		world.setBlock(i + 9, j + 3, k + 7, NovaCraftBlocks.luminant_log, 0, 2);
		world.setBlock(i + 13, j + 3, k + 7, NovaCraftBlocks.luminant_log, 0, 2);
		world.setBlock(i + 10, j + 3, k + 8, NovaCraftBlocks.luminant_log, 0, 2);
		world.setBlock(i + 11, j + 3, k + 8, NovaCraftBlocks.luminant_log, 0, 2);
		world.setBlock(i + 12, j + 3, k + 8, NovaCraftBlocks.luminant_log, 0, 2);
		world.setBlock(i + 10, j + 4, k + 3, NovaCraftBlocks.luminant_log, 0, 2);
		world.setBlock(i + 11, j + 4, k + 3, NovaCraftBlocks.luminant_log, 0, 2);
		world.setBlock(i + 12, j + 4, k + 3, NovaCraftBlocks.luminant_log, 0, 2);
		world.setBlock(i + 9, j + 4, k + 4, NovaCraftBlocks.luminant_log, 0, 2);
		world.setBlock(i + 13, j + 4, k + 4, NovaCraftBlocks.luminant_log, 0, 2);
		world.setBlock(i + 9, j + 4, k + 5, NovaCraftBlocks.luminant_log, 0, 2);
		world.setBlock(i + 13, j + 4, k + 5, NovaCraftBlocks.luminant_log, 0, 2);
		world.setBlock(i + 9, j + 4, k + 6, NovaCraftBlocks.luminant_log, 0, 2);
		world.setBlock(i + 13, j + 4, k + 6, NovaCraftBlocks.luminant_log, 0, 2);
		world.setBlock(i + 10, j + 4, k + 7, NovaCraftBlocks.luminant_log, 0, 2);
		world.setBlock(i + 11, j + 4, k + 7, NovaCraftBlocks.luminant_log, 0, 2);
		world.setBlock(i + 12, j + 4, k + 7, NovaCraftBlocks.luminant_log, 0, 2);
		world.setBlock(i + 10, j + 5, k + 3, NovaCraftBlocks.luminant_log, 0, 2);
		world.setBlock(i + 11, j + 5, k + 3, NovaCraftBlocks.luminant_log, 0, 2);
		world.setBlock(i + 12, j + 5, k + 3, NovaCraftBlocks.luminant_log, 0, 2);
		world.setBlock(i + 3, j + 5, k + 4, NovaCraftBlocks.luminant_leaves, 0, 2);
		world.setBlock(i + 4, j + 5, k + 4, NovaCraftBlocks.luminant_leaves, 0, 2);
		world.setBlock(i + 5, j + 5, k + 4, NovaCraftBlocks.luminant_leaves, 0, 2);
		world.setBlock(i + 6, j + 5, k + 4, NovaCraftBlocks.luminant_leaves, 0, 2);
		world.setBlock(i + 7, j + 5, k + 4, NovaCraftBlocks.luminant_leaves, 0, 2);
		world.setBlock(i + 8, j + 5, k + 4, NovaCraftBlocks.luminant_leaves, 0, 2);
		world.setBlock(i + 9, j + 5, k + 4, NovaCraftBlocks.luminant_log, 0, 2);
		world.setBlock(i + 13, j + 5, k + 4, NovaCraftBlocks.luminant_log, 0, 2);
		world.setBlock(i + 3, j + 5, k + 5, NovaCraftBlocks.luminant_leaves, 0, 2);
		world.setBlock(i + 4, j + 5, k + 5, NovaCraftBlocks.luminant_leaves, 0, 2);
		world.setBlock(i + 5, j + 5, k + 5, NovaCraftBlocks.luminant_leaves, 0, 2);
		world.setBlock(i + 6, j + 5, k + 5, NovaCraftBlocks.luminant_leaves, 0, 2);
		world.setBlock(i + 7, j + 5, k + 5, NovaCraftBlocks.luminant_leaves, 0, 2);
		world.setBlock(i + 8, j + 5, k + 5, NovaCraftBlocks.luminant_leaves, 0, 2);
		world.setBlock(i + 9, j + 5, k + 5, NovaCraftBlocks.luminant_log, 0, 2);
		world.setBlock(i + 11, j + 5, k + 5, NovaCraftBlocks.luminant_log, 0, 2);
		world.setBlock(i + 13, j + 5, k + 5, NovaCraftBlocks.luminant_log, 0, 2);
		world.setBlock(i + 3, j + 5, k + 6, NovaCraftBlocks.luminant_leaves, 0, 2);
		world.setBlock(i + 4, j + 5, k + 6, NovaCraftBlocks.luminant_leaves, 0, 2);
		world.setBlock(i + 5, j + 5, k + 6, NovaCraftBlocks.luminant_leaves, 0, 2);
		world.setBlock(i + 6, j + 5, k + 6, NovaCraftBlocks.luminant_leaves, 0, 2);
		world.setBlock(i + 7, j + 5, k + 6, NovaCraftBlocks.luminant_leaves, 0, 2);
		world.setBlock(i + 8, j + 5, k + 6, NovaCraftBlocks.luminant_leaves, 0, 2);
		world.setBlock(i + 9, j + 5, k + 6, NovaCraftBlocks.luminant_log, 0, 2);
		world.setBlock(i + 13, j + 5, k + 6, NovaCraftBlocks.luminant_log, 0, 2);
		world.setBlock(i + 10, j + 5, k + 7, NovaCraftBlocks.luminant_log, 0, 2);
		world.setBlock(i + 11, j + 5, k + 7, NovaCraftBlocks.luminant_log, 0, 2);
		world.setBlock(i + 12, j + 5, k + 7, NovaCraftBlocks.luminant_log, 0, 2);
		world.setBlock(i + 9, j + 6, k + 2, NovaCraftBlocks.luminant_leaves, 0, 2);
		world.setBlock(i + 10, j + 6, k + 2, NovaCraftBlocks.luminant_leaves, 0, 2);
		world.setBlock(i + 11, j + 6, k + 2, NovaCraftBlocks.luminant_leaves, 0, 2);
		world.setBlock(i + 12, j + 6, k + 2, NovaCraftBlocks.luminant_leaves, 0, 2);
		world.setBlock(i + 2, j + 6, k + 3, NovaCraftBlocks.luminant_leaves, 0, 2);
		world.setBlock(i + 3, j + 6, k + 3, NovaCraftBlocks.luminant_leaves, 0, 2);
		world.setBlock(i + 4, j + 6, k + 3, NovaCraftBlocks.luminant_leaves, 0, 2);
		world.setBlock(i + 5, j + 6, k + 3, NovaCraftBlocks.luminant_leaves, 0, 2);
		world.setBlock(i + 6, j + 6, k + 3, NovaCraftBlocks.luminant_leaves, 0, 2);
		world.setBlock(i + 7, j + 6, k + 3, NovaCraftBlocks.luminant_leaves, 0, 2);
		world.setBlock(i + 8, j + 6, k + 3, NovaCraftBlocks.luminant_leaves, 0, 2);
		world.setBlock(i + 9, j + 6, k + 3, NovaCraftBlocks.luminant_leaves, 0, 2);
		world.setBlock(i + 10, j + 6, k + 3, NovaCraftBlocks.luminant_log, 0, 2);
		world.setBlock(i + 11, j + 6, k + 3, NovaCraftBlocks.luminant_log, 0, 2);
		world.setBlock(i + 12, j + 6, k + 3, NovaCraftBlocks.luminant_log, 0, 2);
		world.setBlock(i + 13, j + 6, k + 3, NovaCraftBlocks.luminant_leaves, 0, 2);
		world.setBlock(i + 2, j + 6, k + 4, NovaCraftBlocks.luminant_leaves, 0, 2);
		world.setBlock(i + 3, j + 6, k + 4, NovaCraftBlocks.luminant_leaves, 0, 2);
		world.setBlock(i + 4, j + 6, k + 4, NovaCraftBlocks.luminant_leaves, 0, 2);
		world.setBlock(i + 5, j + 6, k + 4, NovaCraftBlocks.luminant_leaves, 0, 2);
		world.setBlock(i + 6, j + 6, k + 4, NovaCraftBlocks.luminant_leaves, 0, 2);
		world.setBlock(i + 7, j + 6, k + 4, NovaCraftBlocks.luminant_leaves, 0, 2);
		world.setBlock(i + 8, j + 6, k + 4, NovaCraftBlocks.luminant_leaves, 0, 2);
		world.setBlock(i + 9, j + 6, k + 4, NovaCraftBlocks.luminant_log, 0, 2);
		world.setBlock(i + 13, j + 6, k + 4, NovaCraftBlocks.luminant_log, 0, 2);
		world.setBlock(i + 14, j + 6, k + 4, NovaCraftBlocks.luminant_leaves, 0, 2);
		world.setBlock(i + 2, j + 6, k + 5, NovaCraftBlocks.luminant_leaves, 0, 2);
		world.setBlock(i + 3, j + 6, k + 5, NovaCraftBlocks.luminant_leaves, 0, 2);
		world.setBlock(i + 4, j + 6, k + 5, NovaCraftBlocks.luminant_leaves, 0, 2);
		world.setBlock(i + 5, j + 6, k + 5, NovaCraftBlocks.luminant_leaves, 0, 2);
		world.setBlock(i + 6, j + 6, k + 5, NovaCraftBlocks.luminant_leaves, 0, 2);
		world.setBlock(i + 7, j + 6, k + 5, NovaCraftBlocks.luminant_log, 4, 2);
		world.setBlock(i + 8, j + 6, k + 5, NovaCraftBlocks.luminant_log, 4, 2);
		world.setBlock(i + 9, j + 6, k + 5, NovaCraftBlocks.luminant_log, 4, 2);
		world.setBlock(i + 10, j + 6, k + 5, NovaCraftBlocks.luminant_log, 8, 2);
		world.setBlock(i + 11, j + 6, k + 5, NovaCraftBlocks.luminant_log, 4, 2);
		world.setBlock(i + 13, j + 6, k + 5, NovaCraftBlocks.luminant_log, 0, 2);
		world.setBlock(i + 14, j + 6, k + 5, NovaCraftBlocks.luminant_leaves, 0, 2);
		world.setBlock(i + 2, j + 6, k + 6, NovaCraftBlocks.luminant_leaves, 0, 2);
		world.setBlock(i + 3, j + 6, k + 6, NovaCraftBlocks.luminant_leaves, 0, 2);
		world.setBlock(i + 4, j + 6, k + 6, NovaCraftBlocks.luminant_leaves, 0, 2);
		world.setBlock(i + 5, j + 6, k + 6, NovaCraftBlocks.luminant_leaves, 0, 2);
		world.setBlock(i + 6, j + 6, k + 6, NovaCraftBlocks.luminant_leaves, 0, 2);
		world.setBlock(i + 7, j + 6, k + 6, NovaCraftBlocks.luminant_leaves, 0, 2);
		world.setBlock(i + 8, j + 6, k + 6, NovaCraftBlocks.luminant_leaves, 0, 2);
		world.setBlock(i + 9, j + 6, k + 6, NovaCraftBlocks.luminant_log, 0, 2);
		world.setBlock(i + 10, j + 6, k + 6, NovaCraftBlocks.luminant_log, 8, 2);
		world.setBlock(i + 13, j + 6, k + 6, NovaCraftBlocks.luminant_log, 0, 2);
		world.setBlock(i + 14, j + 6, k + 6, NovaCraftBlocks.luminant_leaves, 0, 2);
		world.setBlock(i + 2, j + 6, k + 7, NovaCraftBlocks.luminant_leaves, 0, 2);
		world.setBlock(i + 3, j + 6, k + 7, NovaCraftBlocks.luminant_leaves, 0, 2);
		world.setBlock(i + 4, j + 6, k + 7, NovaCraftBlocks.luminant_leaves, 0, 2);
		world.setBlock(i + 5, j + 6, k + 7, NovaCraftBlocks.luminant_leaves, 0, 2);
		world.setBlock(i + 6, j + 6, k + 7, NovaCraftBlocks.luminant_leaves, 0, 2);
		world.setBlock(i + 7, j + 6, k + 7, NovaCraftBlocks.luminant_leaves, 0, 2);
		world.setBlock(i + 8, j + 6, k + 7, NovaCraftBlocks.luminant_leaves, 0, 2);
		world.setBlock(i + 9, j + 6, k + 7, NovaCraftBlocks.luminant_leaves, 0, 2);
		world.setBlock(i + 10, j + 6, k + 7, NovaCraftBlocks.luminant_log, 0, 2);
		world.setBlock(i + 11, j + 6, k + 7, NovaCraftBlocks.luminant_log, 0, 2);
		world.setBlock(i + 12, j + 6, k + 7, NovaCraftBlocks.luminant_log, 0, 2);
		world.setBlock(i + 13, j + 6, k + 7, NovaCraftBlocks.luminant_leaves, 0, 2);
		world.setBlock(i + 10, j + 6, k + 8, NovaCraftBlocks.luminant_leaves, 0, 2);
		world.setBlock(i + 11, j + 6, k + 8, NovaCraftBlocks.luminant_leaves, 0, 2);
		world.setBlock(i + 12, j + 6, k + 8, NovaCraftBlocks.luminant_leaves, 0, 2);
		world.setBlock(i + 11, j + 7, k + 1, NovaCraftBlocks.luminant_leaves, 0, 2);
		world.setBlock(i + 7, j + 7, k + 2, NovaCraftBlocks.luminant_leaves, 0, 2);
		world.setBlock(i + 9, j + 7, k + 2, NovaCraftBlocks.luminant_leaves, 0, 2);
		world.setBlock(i + 10, j + 7, k + 2, NovaCraftBlocks.luminant_leaves, 0, 2);
		world.setBlock(i + 11, j + 7, k + 2, NovaCraftBlocks.luminant_leaves, 0, 2);
		world.setBlock(i + 12, j + 7, k + 2, NovaCraftBlocks.luminant_leaves, 0, 2);
		world.setBlock(i + 13, j + 7, k + 2, NovaCraftBlocks.luminant_leaves, 0, 2);
		world.setBlock(i + 1, j + 7, k + 3, NovaCraftBlocks.luminant_leaves, 0, 2);
		world.setBlock(i + 2, j + 7, k + 3, NovaCraftBlocks.luminant_leaves, 0, 2);
		world.setBlock(i + 3, j + 7, k + 3, NovaCraftBlocks.luminant_leaves, 0, 2);
		world.setBlock(i + 4, j + 7, k + 3, NovaCraftBlocks.luminant_leaves, 0, 2);
		world.setBlock(i + 5, j + 7, k + 3, NovaCraftBlocks.luminant_leaves, 0, 2);
		world.setBlock(i + 6, j + 7, k + 3, NovaCraftBlocks.luminant_leaves, 0, 2);
		world.setBlock(i + 7, j + 7, k + 3, NovaCraftBlocks.luminant_leaves, 0, 2);
		world.setBlock(i + 8, j + 7, k + 3, NovaCraftBlocks.luminant_leaves, 0, 2);
		world.setBlock(i + 9, j + 7, k + 3, NovaCraftBlocks.luminant_leaves, 0, 2);
		world.setBlock(i + 10, j + 7, k + 3, NovaCraftBlocks.luminant_log, 0, 2);
		world.setBlock(i + 11, j + 7, k + 3, NovaCraftBlocks.luminant_log, 0, 2);
		world.setBlock(i + 12, j + 7, k + 3, NovaCraftBlocks.luminant_log, 0, 2);
		world.setBlock(i + 13, j + 7, k + 3, NovaCraftBlocks.luminant_leaves, 0, 2);
		world.setBlock(i + 14, j + 7, k + 3, NovaCraftBlocks.luminant_leaves, 0, 2);
		world.setBlock(i + 1, j + 7, k + 4, NovaCraftBlocks.luminant_leaves, 0, 2);
		world.setBlock(i + 2, j + 7, k + 4, NovaCraftBlocks.luminant_log, 4, 2);
		world.setBlock(i + 3, j + 7, k + 4, NovaCraftBlocks.luminant_log, 4, 2);
		world.setBlock(i + 4, j + 7, k + 4, NovaCraftBlocks.luminant_log, 4, 2);
		world.setBlock(i + 5, j + 7, k + 4, NovaCraftBlocks.luminant_log, 4, 2);
		world.setBlock(i + 6, j + 7, k + 4, NovaCraftBlocks.luminant_log, 4, 2);
		world.setBlock(i + 7, j + 7, k + 4, NovaCraftBlocks.luminant_log, 4, 2);
		world.setBlock(i + 8, j + 7, k + 4, NovaCraftBlocks.luminant_log, 4, 2);
		world.setBlock(i + 9, j + 7, k + 4, NovaCraftBlocks.luminant_log, 0, 2);
		world.setBlock(i + 13, j + 7, k + 4, NovaCraftBlocks.luminant_log, 0, 2);
		world.setBlock(i + 14, j + 7, k + 4, NovaCraftBlocks.luminant_leaves, 0, 2);
		world.setBlock(i + 15, j + 7, k + 4, NovaCraftBlocks.luminant_leaves, 0, 2);
		world.setBlock(i + 1, j + 7, k + 5, NovaCraftBlocks.luminant_leaves, 0, 2);
		world.setBlock(i + 2, j + 7, k + 5, NovaCraftBlocks.luminant_log, 4, 2);
		world.setBlock(i + 3, j + 7, k + 5, NovaCraftBlocks.luminant_log, 4, 2);
		world.setBlock(i + 4, j + 7, k + 5, NovaCraftBlocks.luminant_log, 4, 2);
		world.setBlock(i + 5, j + 7, k + 5, NovaCraftBlocks.luminant_log, 4, 2);
		world.setBlock(i + 6, j + 7, k + 5, NovaCraftBlocks.luminant_log, 4, 2);
		world.setBlock(i + 13, j + 7, k + 5, NovaCraftBlocks.luminant_log, 0, 2);
		world.setBlock(i + 14, j + 7, k + 5, NovaCraftBlocks.luminant_leaves, 0, 2);
		world.setBlock(i + 15, j + 7, k + 5, NovaCraftBlocks.luminant_leaves, 0, 2);
		world.setBlock(i + 1, j + 7, k + 6, NovaCraftBlocks.luminant_leaves, 0, 2);
		world.setBlock(i + 2, j + 7, k + 6, NovaCraftBlocks.luminant_log, 4, 2);
		world.setBlock(i + 3, j + 7, k + 6, NovaCraftBlocks.luminant_log, 4, 2);
		world.setBlock(i + 4, j + 7, k + 6, NovaCraftBlocks.luminant_log, 4, 2);
		world.setBlock(i + 5, j + 7, k + 6, NovaCraftBlocks.luminant_log, 4, 2);
		world.setBlock(i + 6, j + 7, k + 6, NovaCraftBlocks.luminant_log, 4, 2);
		world.setBlock(i + 7, j + 7, k + 6, NovaCraftBlocks.luminant_log, 4, 2);
		world.setBlock(i + 8, j + 7, k + 6, NovaCraftBlocks.luminant_log, 4, 2);
		world.setBlock(i + 9, j + 7, k + 6, NovaCraftBlocks.luminant_log, 0, 2);
		world.setBlock(i + 13, j + 7, k + 6, NovaCraftBlocks.luminant_log, 0, 2);
		world.setBlock(i + 14, j + 7, k + 6, NovaCraftBlocks.luminant_leaves, 0, 2);
		world.setBlock(i + 1, j + 7, k + 7, NovaCraftBlocks.luminant_leaves, 0, 2);
		world.setBlock(i + 2, j + 7, k + 7, NovaCraftBlocks.luminant_leaves, 0, 2);
		world.setBlock(i + 3, j + 7, k + 7, NovaCraftBlocks.luminant_leaves, 0, 2);
		world.setBlock(i + 4, j + 7, k + 7, NovaCraftBlocks.luminant_leaves, 0, 2);
		world.setBlock(i + 5, j + 7, k + 7, NovaCraftBlocks.luminant_leaves, 0, 2);
		world.setBlock(i + 6, j + 7, k + 7, NovaCraftBlocks.luminant_leaves, 0, 2);
		world.setBlock(i + 7, j + 7, k + 7, NovaCraftBlocks.luminant_leaves, 0, 2);
		world.setBlock(i + 8, j + 7, k + 7, NovaCraftBlocks.luminant_leaves, 0, 2);
		world.setBlock(i + 9, j + 7, k + 7, NovaCraftBlocks.luminant_leaves, 0, 2);
		world.setBlock(i + 10, j + 7, k + 7, NovaCraftBlocks.luminant_log, 0, 2);
		world.setBlock(i + 11, j + 7, k + 7, NovaCraftBlocks.luminant_log, 0, 2);
		world.setBlock(i + 12, j + 7, k + 7, NovaCraftBlocks.luminant_log, 0, 2);
		world.setBlock(i + 13, j + 7, k + 7, NovaCraftBlocks.luminant_leaves, 0, 2);
		world.setBlock(i + 14, j + 7, k + 7, NovaCraftBlocks.luminant_leaves, 0, 2);
		world.setBlock(i + 2, j + 7, k + 8, NovaCraftBlocks.luminant_leaves, 0, 2);
		world.setBlock(i + 3, j + 7, k + 8, NovaCraftBlocks.luminant_leaves, 0, 2);
		world.setBlock(i + 4, j + 7, k + 8, NovaCraftBlocks.luminant_leaves, 0, 2);
		world.setBlock(i + 5, j + 7, k + 8, NovaCraftBlocks.luminant_leaves, 0, 2);
		world.setBlock(i + 9, j + 7, k + 8, NovaCraftBlocks.luminant_leaves, 0, 2);
		world.setBlock(i + 10, j + 7, k + 8, NovaCraftBlocks.luminant_leaves, 0, 2);
		world.setBlock(i + 11, j + 7, k + 8, NovaCraftBlocks.luminant_leaves, 0, 2);
		world.setBlock(i + 12, j + 7, k + 8, NovaCraftBlocks.luminant_leaves, 0, 2);
		world.setBlock(i + 13, j + 7, k + 8, NovaCraftBlocks.luminant_leaves, 0, 2);
		world.setBlock(i + 11, j + 8, k + 1, NovaCraftBlocks.luminant_leaves, 0, 2);
		world.setBlock(i + 1, j + 8, k + 2, NovaCraftBlocks.luminant_leaves, 0, 2);
		world.setBlock(i + 2, j + 8, k + 2, NovaCraftBlocks.luminant_leaves, 0, 2);
		world.setBlock(i + 3, j + 8, k + 2, NovaCraftBlocks.luminant_leaves, 0, 2);
		world.setBlock(i + 4, j + 8, k + 2, NovaCraftBlocks.luminant_leaves, 0, 2);
		world.setBlock(i + 5, j + 8, k + 2, NovaCraftBlocks.luminant_leaves, 0, 2);
		world.setBlock(i + 7, j + 8, k + 2, NovaCraftBlocks.luminant_leaves, 0, 2);
		world.setBlock(i + 9, j + 8, k + 2, NovaCraftBlocks.luminant_leaves, 0, 2);
		world.setBlock(i + 10, j + 8, k + 2, NovaCraftBlocks.luminant_leaves, 0, 2);
		world.setBlock(i + 11, j + 8, k + 2, NovaCraftBlocks.luminant_leaves, 0, 2);
		world.setBlock(i + 12, j + 8, k + 2, NovaCraftBlocks.luminant_leaves, 0, 2);
		world.setBlock(i + 13, j + 8, k + 2, NovaCraftBlocks.luminant_leaves, 0, 2);
		world.setBlock(i + 0, j + 8, k + 3, NovaCraftBlocks.luminant_leaves, 0, 2);
		world.setBlock(i + 1, j + 8, k + 3, NovaCraftBlocks.luminant_leaves, 0, 2);
		world.setBlock(i + 2, j + 8, k + 3, NovaCraftBlocks.luminant_log, 4, 2);
		world.setBlock(i + 3, j + 8, k + 3, NovaCraftBlocks.luminant_log, 4, 2);
		world.setBlock(i + 4, j + 8, k + 3, NovaCraftBlocks.luminant_log, 4, 2);
		world.setBlock(i + 5, j + 8, k + 3, NovaCraftBlocks.luminant_log, 4, 2);
		world.setBlock(i + 6, j + 8, k + 3, NovaCraftBlocks.luminant_leaves, 0, 2);
		world.setBlock(i + 7, j + 8, k + 3, NovaCraftBlocks.luminant_leaves, 0, 2);
		world.setBlock(i + 8, j + 8, k + 3, NovaCraftBlocks.luminant_leaves, 0, 2);
		world.setBlock(i + 9, j + 8, k + 3, NovaCraftBlocks.luminant_leaves, 0, 2);
		world.setBlock(i + 10, j + 8, k + 3, NovaCraftBlocks.luminant_log, 0, 2);
		world.setBlock(i + 11, j + 8, k + 3, NovaCraftBlocks.luminant_log, 0, 2);
		world.setBlock(i + 12, j + 8, k + 3, NovaCraftBlocks.luminant_log, 0, 2);
		world.setBlock(i + 13, j + 8, k + 3, NovaCraftBlocks.luminant_leaves, 0, 2);
		world.setBlock(i + 14, j + 8, k + 3, NovaCraftBlocks.luminant_leaves, 0, 2);
		world.setBlock(i + 0, j + 8, k + 4, NovaCraftBlocks.luminant_leaves, 0, 2);
		world.setBlock(i + 1, j + 8, k + 4, NovaCraftBlocks.luminant_log, 4, 2);
		world.setBlock(i + 5, j + 8, k + 4, NovaCraftBlocks.luminant_log, 4, 2);
		world.setBlock(i + 6, j + 8, k + 4, NovaCraftBlocks.luminant_log, 4, 2);
		world.setBlock(i + 7, j + 8, k + 4, NovaCraftBlocks.luminant_log, 4, 2);
		world.setBlock(i + 8, j + 8, k + 4, NovaCraftBlocks.luminant_log, 4, 2);
		world.setBlock(i + 9, j + 8, k + 4, NovaCraftBlocks.luminant_log, 0, 2);
		world.setBlock(i + 13, j + 8, k + 4, NovaCraftBlocks.luminant_log, 0, 2);
		world.setBlock(i + 14, j + 8, k + 4, NovaCraftBlocks.luminant_leaves, 0, 2);
		world.setBlock(i + 15, j + 8, k + 4, NovaCraftBlocks.luminant_leaves, 0, 2);
		world.setBlock(i + 0, j + 8, k + 5, NovaCraftBlocks.luminant_leaves, 0, 2);
		world.setBlock(i + 1, j + 8, k + 5, NovaCraftBlocks.luminant_log, 4, 2);
		world.setBlock(i + 12, j + 8, k + 5, NovaCraftBlocks.luminant_log, 4, 2);
		world.setBlock(i + 13, j + 8, k + 5, NovaCraftBlocks.luminant_log, 0, 2);
		world.setBlock(i + 14, j + 8, k + 5, NovaCraftBlocks.luminant_leaves, 0, 2);
		world.setBlock(i + 15, j + 8, k + 5, NovaCraftBlocks.luminant_leaves, 0, 2);
		world.setBlock(i + 16, j + 8, k + 5, NovaCraftBlocks.luminant_leaves, 0, 2);
		world.setBlock(i + 0, j + 8, k + 6, NovaCraftBlocks.luminant_leaves, 0, 2);
		world.setBlock(i + 1, j + 8, k + 6, NovaCraftBlocks.luminant_log, 4, 2);
		world.setBlock(i + 5, j + 8, k + 6, NovaCraftBlocks.luminant_log, 4, 2);
		world.setBlock(i + 6, j + 8, k + 6, NovaCraftBlocks.luminant_log, 4, 2);
		world.setBlock(i + 7, j + 8, k + 6, NovaCraftBlocks.luminant_log, 4, 2);
		world.setBlock(i + 8, j + 8, k + 6, NovaCraftBlocks.luminant_log, 4, 2);
		world.setBlock(i + 9, j + 8, k + 6, NovaCraftBlocks.luminant_log, 0, 2);
		world.setBlock(i + 13, j + 8, k + 6, NovaCraftBlocks.luminant_log, 0, 2);
		world.setBlock(i + 14, j + 8, k + 6, NovaCraftBlocks.luminant_leaves, 0, 2);
		world.setBlock(i + 15, j + 8, k + 6, NovaCraftBlocks.luminant_leaves, 0, 2);
		world.setBlock(i + 0, j + 8, k + 7, NovaCraftBlocks.luminant_leaves, 0, 2);
		world.setBlock(i + 1, j + 8, k + 7, NovaCraftBlocks.luminant_leaves, 0, 2);
		world.setBlock(i + 2, j + 8, k + 7, NovaCraftBlocks.luminant_log, 4, 2);
		world.setBlock(i + 3, j + 8, k + 7, NovaCraftBlocks.luminant_log, 4, 2);
		world.setBlock(i + 4, j + 8, k + 7, NovaCraftBlocks.luminant_log, 4, 2);
		world.setBlock(i + 5, j + 8, k + 7, NovaCraftBlocks.luminant_log, 4, 2);
		world.setBlock(i + 6, j + 8, k + 7, NovaCraftBlocks.luminant_leaves, 0, 2);
		world.setBlock(i + 7, j + 8, k + 7, NovaCraftBlocks.luminant_leaves, 0, 2);
		world.setBlock(i + 8, j + 8, k + 7, NovaCraftBlocks.luminant_leaves, 0, 2);
		world.setBlock(i + 9, j + 8, k + 7, NovaCraftBlocks.luminant_leaves, 0, 2);
		world.setBlock(i + 10, j + 8, k + 7, NovaCraftBlocks.luminant_log, 0, 2);
		world.setBlock(i + 11, j + 8, k + 7, NovaCraftBlocks.luminant_log, 0, 2);
		world.setBlock(i + 12, j + 8, k + 7, NovaCraftBlocks.luminant_log, 0, 2);
		world.setBlock(i + 13, j + 8, k + 7, NovaCraftBlocks.luminant_leaves, 0, 2);
		world.setBlock(i + 14, j + 8, k + 7, NovaCraftBlocks.luminant_leaves, 0, 2);
		world.setBlock(i + 1, j + 8, k + 8, NovaCraftBlocks.luminant_leaves, 0, 2);
		world.setBlock(i + 2, j + 8, k + 8, NovaCraftBlocks.luminant_leaves, 0, 2);
		world.setBlock(i + 3, j + 8, k + 8, NovaCraftBlocks.luminant_leaves, 0, 2);
		world.setBlock(i + 4, j + 8, k + 8, NovaCraftBlocks.luminant_leaves, 0, 2);
		world.setBlock(i + 5, j + 8, k + 8, NovaCraftBlocks.luminant_leaves, 0, 2);
		world.setBlock(i + 6, j + 8, k + 8, NovaCraftBlocks.luminant_leaves, 0, 2);
		world.setBlock(i + 9, j + 8, k + 8, NovaCraftBlocks.luminant_leaves, 0, 2);
		world.setBlock(i + 10, j + 8, k + 8, NovaCraftBlocks.luminant_leaves, 0, 2);
		world.setBlock(i + 11, j + 8, k + 8, NovaCraftBlocks.luminant_leaves, 0, 2);
		world.setBlock(i + 12, j + 8, k + 8, NovaCraftBlocks.luminant_leaves, 0, 2);
		world.setBlock(i + 13, j + 8, k + 8, NovaCraftBlocks.luminant_leaves, 0, 2);
		world.setBlock(i + 10, j + 8, k + 9, NovaCraftBlocks.luminant_leaves, 0, 2);
		world.setBlock(i + 11, j + 8, k + 9, NovaCraftBlocks.luminant_leaves, 0, 2);
		world.setBlock(i + 12, j + 8, k + 9, NovaCraftBlocks.luminant_leaves, 0, 2);
		world.setBlock(i + 3, j + 9, k + 1, NovaCraftBlocks.luminant_leaves, 0, 2);
		world.setBlock(i + 4, j + 9, k + 1, NovaCraftBlocks.luminant_leaves, 0, 2);
		world.setBlock(i + 11, j + 9, k + 1, NovaCraftBlocks.luminant_leaves, 0, 2);
		world.setBlock(i + 1, j + 9, k + 2, NovaCraftBlocks.luminant_leaves, 0, 2);
		world.setBlock(i + 2, j + 9, k + 2, NovaCraftBlocks.luminant_leaves, 0, 2);
		world.setBlock(i + 3, j + 9, k + 2, NovaCraftBlocks.luminant_leaves, 0, 2);
		world.setBlock(i + 4, j + 9, k + 2, NovaCraftBlocks.luminant_leaves, 0, 2);
		world.setBlock(i + 5, j + 9, k + 2, NovaCraftBlocks.luminant_leaves, 0, 2);
		world.setBlock(i + 6, j + 9, k + 2, NovaCraftBlocks.luminant_leaves, 0, 2);
		world.setBlock(i + 7, j + 9, k + 2, NovaCraftBlocks.luminant_leaves, 0, 2);
		world.setBlock(i + 9, j + 9, k + 2, NovaCraftBlocks.luminant_leaves, 0, 2);
		world.setBlock(i + 10, j + 9, k + 2, NovaCraftBlocks.luminant_leaves, 0, 2);
		world.setBlock(i + 11, j + 9, k + 2, NovaCraftBlocks.luminant_leaves, 0, 2);
		world.setBlock(i + 12, j + 9, k + 2, NovaCraftBlocks.luminant_leaves, 0, 2);
		world.setBlock(i + 13, j + 9, k + 2, NovaCraftBlocks.luminant_leaves, 0, 2);
		world.setBlock(i + 0, j + 9, k + 3, NovaCraftBlocks.luminant_leaves, 0, 2);
		world.setBlock(i + 1, j + 9, k + 3, NovaCraftBlocks.luminant_leaves, 0, 2);
		world.setBlock(i + 2, j + 9, k + 3, NovaCraftBlocks.luminant_log, 4, 2);
		world.setBlock(i + 3, j + 9, k + 3, NovaCraftBlocks.luminant_log, 4, 2);
		world.setBlock(i + 4, j + 9, k + 3, NovaCraftBlocks.luminant_log, 4, 2);
		world.setBlock(i + 5, j + 9, k + 3, NovaCraftBlocks.luminant_log, 4, 2);
		world.setBlock(i + 6, j + 9, k + 3, NovaCraftBlocks.luminant_leaves, 0, 2);
		world.setBlock(i + 7, j + 9, k + 3, NovaCraftBlocks.luminant_leaves, 0, 2);
		world.setBlock(i + 8, j + 9, k + 3, NovaCraftBlocks.luminant_leaves, 0, 2);
		world.setBlock(i + 9, j + 9, k + 3, NovaCraftBlocks.luminant_leaves, 0, 2);
		world.setBlock(i + 10, j + 9, k + 3, NovaCraftBlocks.luminant_log, 0, 2);
		world.setBlock(i + 11, j + 9, k + 3, NovaCraftBlocks.luminant_log, 0, 2);
		world.setBlock(i + 12, j + 9, k + 3, NovaCraftBlocks.luminant_log, 0, 2);
		world.setBlock(i + 13, j + 9, k + 3, NovaCraftBlocks.luminant_leaves, 0, 2);
		world.setBlock(i + 14, j + 9, k + 3, NovaCraftBlocks.luminant_leaves, 0, 2);
		world.setBlock(i + 0, j + 9, k + 4, NovaCraftBlocks.luminant_leaves, 0, 2);
		world.setBlock(i + 1, j + 9, k + 4, NovaCraftBlocks.luminant_log, 4, 2);
		world.setBlock(i + 5, j + 9, k + 4, NovaCraftBlocks.luminant_log, 4, 2);
		world.setBlock(i + 6, j + 9, k + 4, NovaCraftBlocks.luminant_log, 4, 2);
		world.setBlock(i + 7, j + 9, k + 4, NovaCraftBlocks.luminant_log, 4, 2);
		world.setBlock(i + 8, j + 9, k + 4, NovaCraftBlocks.luminant_leaves, 0, 2);
		world.setBlock(i + 9, j + 9, k + 4, NovaCraftBlocks.luminant_log, 0, 2);
		world.setBlock(i + 13, j + 9, k + 4, NovaCraftBlocks.luminant_log, 0, 2);
		world.setBlock(i + 14, j + 9, k + 4, NovaCraftBlocks.luminant_leaves, 0, 2);
		world.setBlock(i + 15, j + 9, k + 4, NovaCraftBlocks.luminant_leaves, 0, 2);
		world.setBlock(i + 0, j + 9, k + 5, NovaCraftBlocks.luminant_leaves, 0, 2);
		world.setBlock(i + 1, j + 9, k + 5, NovaCraftBlocks.luminant_log, 4, 2);
		world.setBlock(i + 8, j + 9, k + 5, NovaCraftBlocks.luminant_log, 4, 2);
		world.setBlock(i + 9, j + 9, k + 5, NovaCraftBlocks.luminant_log, 0, 2);
		world.setBlock(i + 12, j + 9, k + 5, NovaCraftBlocks.luminant_log, 0, 2);
		world.setBlock(i + 13, j + 9, k + 5, NovaCraftBlocks.luminant_log, 0, 2);
		world.setBlock(i + 14, j + 9, k + 5, NovaCraftBlocks.luminant_leaves, 0, 2);
		world.setBlock(i + 15, j + 9, k + 5, NovaCraftBlocks.luminant_leaves, 0, 2);
		world.setBlock(i + 16, j + 9, k + 5, NovaCraftBlocks.luminant_leaves, 0, 2);
		world.setBlock(i + 0, j + 9, k + 6, NovaCraftBlocks.luminant_leaves, 0, 2);
		world.setBlock(i + 1, j + 9, k + 6, NovaCraftBlocks.luminant_log, 4, 2);
		world.setBlock(i + 5, j + 9, k + 6, NovaCraftBlocks.luminant_log, 4, 2);
		world.setBlock(i + 6, j + 9, k + 6, NovaCraftBlocks.luminant_log, 4, 2);
		world.setBlock(i + 7, j + 9, k + 6, NovaCraftBlocks.luminant_log, 4, 2);
		world.setBlock(i + 8, j + 9, k + 6, NovaCraftBlocks.luminant_leaves, 0, 2);
		world.setBlock(i + 9, j + 9, k + 6, NovaCraftBlocks.luminant_log, 0, 2);
		world.setBlock(i + 12, j + 9, k + 6, NovaCraftBlocks.luminant_log, 4, 2);
		world.setBlock(i + 13, j + 9, k + 6, NovaCraftBlocks.luminant_log, 0, 2);
		world.setBlock(i + 14, j + 9, k + 6, NovaCraftBlocks.luminant_leaves, 0, 2);
		world.setBlock(i + 15, j + 9, k + 6, NovaCraftBlocks.luminant_leaves, 0, 2);
		world.setBlock(i + 0, j + 9, k + 7, NovaCraftBlocks.luminant_leaves, 0, 2);
		world.setBlock(i + 1, j + 9, k + 7, NovaCraftBlocks.luminant_leaves, 0, 2);
		world.setBlock(i + 2, j + 9, k + 7, NovaCraftBlocks.luminant_log, 4, 2);
		world.setBlock(i + 3, j + 9, k + 7, NovaCraftBlocks.luminant_log, 4, 2);
		world.setBlock(i + 4, j + 9, k + 7, NovaCraftBlocks.luminant_log, 4, 2);
		world.setBlock(i + 5, j + 9, k + 7, NovaCraftBlocks.luminant_log, 4, 2);
		world.setBlock(i + 6, j + 9, k + 7, NovaCraftBlocks.luminant_leaves, 0, 2);
		world.setBlock(i + 7, j + 9, k + 7, NovaCraftBlocks.luminant_leaves, 0, 2);
		world.setBlock(i + 8, j + 9, k + 7, NovaCraftBlocks.luminant_leaves, 0, 2);
		world.setBlock(i + 9, j + 9, k + 7, NovaCraftBlocks.luminant_leaves, 0, 2);
		world.setBlock(i + 10, j + 9, k + 7, NovaCraftBlocks.luminant_log, 0, 2);
		world.setBlock(i + 11, j + 9, k + 7, NovaCraftBlocks.luminant_log, 0, 2);
		world.setBlock(i + 12, j + 9, k + 7, NovaCraftBlocks.luminant_log, 0, 2);
		world.setBlock(i + 13, j + 9, k + 7, NovaCraftBlocks.luminant_leaves, 0, 2);
		world.setBlock(i + 14, j + 9, k + 7, NovaCraftBlocks.luminant_leaves, 0, 2);
		world.setBlock(i + 1, j + 9, k + 8, NovaCraftBlocks.luminant_leaves, 0, 2);
		world.setBlock(i + 2, j + 9, k + 8, NovaCraftBlocks.luminant_leaves, 0, 2);
		world.setBlock(i + 3, j + 9, k + 8, NovaCraftBlocks.luminant_leaves, 0, 2);
		world.setBlock(i + 4, j + 9, k + 8, NovaCraftBlocks.luminant_leaves, 0, 2);
		world.setBlock(i + 5, j + 9, k + 8, NovaCraftBlocks.luminant_leaves, 0, 2);
		world.setBlock(i + 6, j + 9, k + 8, NovaCraftBlocks.luminant_leaves, 0, 2);
		world.setBlock(i + 9, j + 9, k + 8, NovaCraftBlocks.luminant_leaves, 0, 2);
		world.setBlock(i + 10, j + 9, k + 8, NovaCraftBlocks.luminant_leaves, 0, 2);
		world.setBlock(i + 11, j + 9, k + 8, NovaCraftBlocks.luminant_leaves, 0, 2);
		world.setBlock(i + 12, j + 9, k + 8, NovaCraftBlocks.luminant_leaves, 0, 2);
		world.setBlock(i + 13, j + 9, k + 8, NovaCraftBlocks.luminant_leaves, 0, 2);
		world.setBlock(i + 10, j + 9, k + 9, NovaCraftBlocks.luminant_leaves, 0, 2);
		world.setBlock(i + 11, j + 9, k + 9, NovaCraftBlocks.luminant_leaves, 0, 2);
		world.setBlock(i + 12, j + 9, k + 9, NovaCraftBlocks.luminant_leaves, 0, 2);
		world.setBlock(i + 11, j + 9, k + 10, NovaCraftBlocks.luminant_leaves, 0, 2);
		world.setBlock(i + 11, j + 10, k + 1, NovaCraftBlocks.luminant_leaves, 0, 2);
		world.setBlock(i + 2, j + 10, k + 2, NovaCraftBlocks.luminant_leaves, 0, 2);
		world.setBlock(i + 3, j + 10, k + 2, NovaCraftBlocks.luminant_leaves, 0, 2);
		world.setBlock(i + 4, j + 10, k + 2, NovaCraftBlocks.luminant_leaves, 0, 2);
		world.setBlock(i + 5, j + 10, k + 2, NovaCraftBlocks.luminant_leaves, 0, 2);
		world.setBlock(i + 6, j + 10, k + 2, NovaCraftBlocks.luminant_leaves, 0, 2);
		world.setBlock(i + 9, j + 10, k + 2, NovaCraftBlocks.luminant_leaves, 0, 2);
		world.setBlock(i + 10, j + 10, k + 2, NovaCraftBlocks.luminant_leaves, 0, 2);
		world.setBlock(i + 11, j + 10, k + 2, NovaCraftBlocks.luminant_leaves, 0, 2);
		world.setBlock(i + 12, j + 10, k + 2, NovaCraftBlocks.luminant_leaves, 0, 2);
		world.setBlock(i + 13, j + 10, k + 2, NovaCraftBlocks.luminant_leaves, 0, 2);
		world.setBlock(i + 0, j + 10, k + 3, NovaCraftBlocks.luminant_leaves, 0, 2);
		world.setBlock(i + 1, j + 10, k + 3, NovaCraftBlocks.luminant_leaves, 0, 2);
		world.setBlock(i + 2, j + 10, k + 3, NovaCraftBlocks.luminant_log, 4, 2);
		world.setBlock(i + 3, j + 10, k + 3, NovaCraftBlocks.luminant_log, 4, 2);
		world.setBlock(i + 4, j + 10, k + 3, NovaCraftBlocks.luminant_log, 4, 2);
		world.setBlock(i + 5, j + 10, k + 3, NovaCraftBlocks.luminant_log, 4, 2);
		world.setBlock(i + 6, j + 10, k + 3, NovaCraftBlocks.luminant_log, 4, 2);
		world.setBlock(i + 7, j + 10, k + 3, NovaCraftBlocks.luminant_leaves, 0, 2);
		world.setBlock(i + 8, j + 10, k + 3, NovaCraftBlocks.luminant_leaves, 0, 2);
		world.setBlock(i + 9, j + 10, k + 3, NovaCraftBlocks.luminant_leaves, 0, 2);
		world.setBlock(i + 10, j + 10, k + 3, NovaCraftBlocks.luminant_log, 0, 2);
		world.setBlock(i + 11, j + 10, k + 3, NovaCraftBlocks.luminant_log, 0, 2);
		world.setBlock(i + 12, j + 10, k + 3, NovaCraftBlocks.luminant_log, 0, 2);
		world.setBlock(i + 13, j + 10, k + 3, NovaCraftBlocks.luminant_leaves, 0, 2);
		world.setBlock(i + 14, j + 10, k + 3, NovaCraftBlocks.luminant_leaves, 0, 2);
		world.setBlock(i + 0, j + 10, k + 4, NovaCraftBlocks.luminant_leaves, 0, 2);
		world.setBlock(i + 1, j + 10, k + 4, NovaCraftBlocks.luminant_log, 4, 2);
		world.setBlock(i + 5, j + 10, k + 4, NovaCraftBlocks.luminant_log, 4, 2);
		world.setBlock(i + 6, j + 10, k + 4, NovaCraftBlocks.luminant_log, 4, 2);
		world.setBlock(i + 7, j + 10, k + 4, NovaCraftBlocks.luminant_log, 4, 2);
		world.setBlock(i + 8, j + 10, k + 4, NovaCraftBlocks.luminant_leaves, 0, 2);
		world.setBlock(i + 9, j + 10, k + 4, NovaCraftBlocks.luminant_log, 0, 2);
		world.setBlock(i + 13, j + 10, k + 4, NovaCraftBlocks.luminant_log, 0, 2);
		world.setBlock(i + 14, j + 10, k + 4, NovaCraftBlocks.luminant_leaves, 0, 2);
		world.setBlock(i + 15, j + 10, k + 4, NovaCraftBlocks.luminant_leaves, 0, 2);
		world.setBlock(i + 0, j + 10, k + 5, NovaCraftBlocks.luminant_leaves, 0, 2);
		world.setBlock(i + 1, j + 10, k + 5, NovaCraftBlocks.luminant_log, 4, 2);
		world.setBlock(i + 5, j + 10, k + 5, NovaCraftBlocks.luminant_log, 4, 2);
		world.setBlock(i + 6, j + 10, k + 5, NovaCraftBlocks.luminant_log, 4, 2);
		world.setBlock(i + 7, j + 10, k + 5, NovaCraftBlocks.luminant_log, 4, 2);
		world.setBlock(i + 8, j + 10, k + 5, NovaCraftBlocks.luminant_log, 4, 2);
		world.setBlock(i + 9, j + 10, k + 5, NovaCraftBlocks.luminant_log, 0, 2);
		world.setBlock(i + 12, j + 10, k + 5, NovaCraftBlocks.luminant_log, 0, 2);
		world.setBlock(i + 13, j + 10, k + 5, NovaCraftBlocks.luminant_log, 0, 2);
		world.setBlock(i + 14, j + 10, k + 5, NovaCraftBlocks.luminant_leaves, 0, 2);
		world.setBlock(i + 15, j + 10, k + 5, NovaCraftBlocks.luminant_leaves, 0, 2);
		world.setBlock(i + 16, j + 10, k + 5, NovaCraftBlocks.luminant_leaves, 0, 2);
		world.setBlock(i + 0, j + 10, k + 6, NovaCraftBlocks.luminant_leaves, 0, 2);
		world.setBlock(i + 1, j + 10, k + 6, NovaCraftBlocks.luminant_log, 4, 2);
		world.setBlock(i + 5, j + 10, k + 6, NovaCraftBlocks.luminant_log, 4, 2);
		world.setBlock(i + 6, j + 10, k + 6, NovaCraftBlocks.luminant_log, 4, 2);
		world.setBlock(i + 7, j + 10, k + 6, NovaCraftBlocks.luminant_log, 4, 2);
		world.setBlock(i + 8, j + 10, k + 6, NovaCraftBlocks.luminant_leaves, 0, 2);
		world.setBlock(i + 9, j + 10, k + 6, NovaCraftBlocks.luminant_log, 0, 2);
		world.setBlock(i + 13, j + 10, k + 6, NovaCraftBlocks.luminant_log, 0, 2);
		world.setBlock(i + 14, j + 10, k + 6, NovaCraftBlocks.luminant_leaves, 0, 2);
		world.setBlock(i + 15, j + 10, k + 6, NovaCraftBlocks.luminant_leaves, 0, 2);
		world.setBlock(i + 1, j + 10, k + 7, NovaCraftBlocks.luminant_leaves, 0, 2);
		world.setBlock(i + 2, j + 10, k + 7, NovaCraftBlocks.luminant_log, 4, 2);
		world.setBlock(i + 3, j + 10, k + 7, NovaCraftBlocks.luminant_log, 4, 2);
		world.setBlock(i + 4, j + 10, k + 7, NovaCraftBlocks.luminant_log, 4, 2);
		world.setBlock(i + 5, j + 10, k + 7, NovaCraftBlocks.luminant_log, 4, 2);
		world.setBlock(i + 6, j + 10, k + 7, NovaCraftBlocks.luminant_leaves, 0, 2);
		world.setBlock(i + 7, j + 10, k + 7, NovaCraftBlocks.luminant_leaves, 0, 2);
		world.setBlock(i + 8, j + 10, k + 7, NovaCraftBlocks.luminant_leaves, 0, 2);
		world.setBlock(i + 9, j + 10, k + 7, NovaCraftBlocks.luminant_leaves, 0, 2);
		world.setBlock(i + 10, j + 10, k + 7, NovaCraftBlocks.luminant_log, 0, 2);
		world.setBlock(i + 11, j + 10, k + 7, NovaCraftBlocks.luminant_log, 0, 2);
		world.setBlock(i + 12, j + 10, k + 7, NovaCraftBlocks.luminant_log, 0, 2);
		world.setBlock(i + 13, j + 10, k + 7, NovaCraftBlocks.luminant_leaves, 0, 2);
		world.setBlock(i + 14, j + 10, k + 7, NovaCraftBlocks.luminant_leaves, 0, 2);
		world.setBlock(i + 2, j + 10, k + 8, NovaCraftBlocks.luminant_leaves, 0, 2);
		world.setBlock(i + 3, j + 10, k + 8, NovaCraftBlocks.luminant_leaves, 0, 2);
		world.setBlock(i + 4, j + 10, k + 8, NovaCraftBlocks.luminant_leaves, 0, 2);
		world.setBlock(i + 5, j + 10, k + 8, NovaCraftBlocks.luminant_leaves, 0, 2);
		world.setBlock(i + 6, j + 10, k + 8, NovaCraftBlocks.luminant_leaves, 0, 2);
		world.setBlock(i + 9, j + 10, k + 8, NovaCraftBlocks.luminant_leaves, 0, 2);
		world.setBlock(i + 10, j + 10, k + 8, NovaCraftBlocks.luminant_leaves, 0, 2);
		world.setBlock(i + 11, j + 10, k + 8, NovaCraftBlocks.luminant_leaves, 0, 2);
		world.setBlock(i + 12, j + 10, k + 8, NovaCraftBlocks.luminant_leaves, 0, 2);
		world.setBlock(i + 13, j + 10, k + 8, NovaCraftBlocks.luminant_leaves, 0, 2);
		world.setBlock(i + 10, j + 10, k + 9, NovaCraftBlocks.luminant_leaves, 0, 2);
		world.setBlock(i + 11, j + 10, k + 9, NovaCraftBlocks.luminant_leaves, 0, 2);
		world.setBlock(i + 12, j + 10, k + 9, NovaCraftBlocks.luminant_leaves, 0, 2);
		world.setBlock(i + 11, j + 10, k + 10, NovaCraftBlocks.luminant_leaves, 0, 2);
		world.setBlock(i + 2, j + 11, k + 2, NovaCraftBlocks.luminant_leaves, 0, 2);
		world.setBlock(i + 3, j + 11, k + 2, NovaCraftBlocks.luminant_leaves, 0, 2);
		world.setBlock(i + 4, j + 11, k + 2, NovaCraftBlocks.luminant_leaves, 0, 2);
		world.setBlock(i + 5, j + 11, k + 2, NovaCraftBlocks.luminant_leaves, 0, 2);
		world.setBlock(i + 6, j + 11, k + 2, NovaCraftBlocks.luminant_leaves, 0, 2);
		world.setBlock(i + 10, j + 11, k + 2, NovaCraftBlocks.luminant_leaves, 0, 2);
		world.setBlock(i + 11, j + 11, k + 2, NovaCraftBlocks.luminant_leaves, 0, 2);
		world.setBlock(i + 12, j + 11, k + 2, NovaCraftBlocks.luminant_leaves, 0, 2);
		world.setBlock(i + 1, j + 11, k + 3, NovaCraftBlocks.luminant_leaves, 0, 2);
		world.setBlock(i + 2, j + 11, k + 3, NovaCraftBlocks.luminant_leaves, 0, 2);
		world.setBlock(i + 3, j + 11, k + 3, NovaCraftBlocks.luminant_leaves, 0, 2);
		world.setBlock(i + 4, j + 11, k + 3, NovaCraftBlocks.luminant_leaves, 0, 2);
		world.setBlock(i + 5, j + 11, k + 3, NovaCraftBlocks.luminant_leaves, 0, 2);
		world.setBlock(i + 6, j + 11, k + 3, NovaCraftBlocks.luminant_leaves, 0, 2);
		world.setBlock(i + 9, j + 11, k + 3, NovaCraftBlocks.luminant_leaves, 0, 2);
		world.setBlock(i + 10, j + 11, k + 3, NovaCraftBlocks.luminant_log, 0, 2);
		world.setBlock(i + 11, j + 11, k + 3, NovaCraftBlocks.luminant_log, 0, 2);
		world.setBlock(i + 12, j + 11, k + 3, NovaCraftBlocks.luminant_log, 0, 2);
		world.setBlock(i + 13, j + 11, k + 3, NovaCraftBlocks.luminant_leaves, 0, 2);
		world.setBlock(i + 0, j + 11, k + 4, NovaCraftBlocks.luminant_leaves, 0, 2);
		world.setBlock(i + 1, j + 11, k + 4, NovaCraftBlocks.luminant_leaves, 0, 2);
		world.setBlock(i + 2, j + 11, k + 4, NovaCraftBlocks.luminant_log, 4, 2);
		world.setBlock(i + 3, j + 11, k + 4, NovaCraftBlocks.luminant_log, 4, 2);
		world.setBlock(i + 4, j + 11, k + 4, NovaCraftBlocks.luminant_log, 4, 2);
		world.setBlock(i + 5, j + 11, k + 4, NovaCraftBlocks.luminant_leaves, 0, 2);
		world.setBlock(i + 6, j + 11, k + 4, NovaCraftBlocks.luminant_leaves, 0, 2);
		world.setBlock(i + 7, j + 11, k + 4, NovaCraftBlocks.luminant_leaves, 0, 2);
		world.setBlock(i + 8, j + 11, k + 4, NovaCraftBlocks.luminant_leaves, 0, 2);
		world.setBlock(i + 9, j + 11, k + 4, NovaCraftBlocks.luminant_log, 0, 2);
		world.setBlock(i + 13, j + 11, k + 4, NovaCraftBlocks.luminant_log, 0, 2);
		world.setBlock(i + 14, j + 11, k + 4, NovaCraftBlocks.luminant_leaves, 0, 2);
		world.setBlock(i + 15, j + 11, k + 4, NovaCraftBlocks.luminant_leaves, 0, 2);
		world.setBlock(i + 0, j + 11, k + 5, NovaCraftBlocks.luminant_leaves, 0, 2);
		world.setBlock(i + 1, j + 11, k + 5, NovaCraftBlocks.luminant_leaves, 0, 2);
		world.setBlock(i + 2, j + 11, k + 5, NovaCraftBlocks.luminant_log, 4, 2);
		world.setBlock(i + 3, j + 11, k + 5, NovaCraftBlocks.luminant_leaves, 0, 2);
		world.setBlock(i + 4, j + 11, k + 5, NovaCraftBlocks.luminant_log, 4, 2);
		world.setBlock(i + 5, j + 11, k + 5, NovaCraftBlocks.luminant_leaves, 0, 2);
		world.setBlock(i + 6, j + 11, k + 5, NovaCraftBlocks.luminant_leaves, 0, 2);
		world.setBlock(i + 7, j + 11, k + 5, NovaCraftBlocks.luminant_leaves, 0, 2);
		world.setBlock(i + 8, j + 11, k + 5, NovaCraftBlocks.luminant_leaves, 0, 2);
		world.setBlock(i + 9, j + 11, k + 5, NovaCraftBlocks.luminant_log, 0, 2);
		world.setBlock(i + 12, j + 11, k + 5, NovaCraftBlocks.luminant_log, 0, 2);
		world.setBlock(i + 13, j + 11, k + 5, NovaCraftBlocks.luminant_log, 0, 2);
		world.setBlock(i + 14, j + 11, k + 5, NovaCraftBlocks.luminant_leaves, 0, 2);
		world.setBlock(i + 15, j + 11, k + 5, NovaCraftBlocks.luminant_leaves, 0, 2);
		world.setBlock(i + 0, j + 11, k + 6, NovaCraftBlocks.luminant_leaves, 0, 2);
		world.setBlock(i + 1, j + 11, k + 6, NovaCraftBlocks.luminant_leaves, 0, 2);
		world.setBlock(i + 2, j + 11, k + 6, NovaCraftBlocks.luminant_log, 4, 2);
		world.setBlock(i + 3, j + 11, k + 6, NovaCraftBlocks.luminant_log, 4, 2);
		world.setBlock(i + 4, j + 11, k + 6, NovaCraftBlocks.luminant_log, 4, 2);
		world.setBlock(i + 5, j + 11, k + 6, NovaCraftBlocks.luminant_log, 4, 2);
		world.setBlock(i + 6, j + 11, k + 6, NovaCraftBlocks.luminant_log, 4, 2);
		world.setBlock(i + 7, j + 11, k + 6, NovaCraftBlocks.luminant_leaves, 0, 2);
		world.setBlock(i + 8, j + 11, k + 6, NovaCraftBlocks.luminant_leaves, 0, 2);
		world.setBlock(i + 9, j + 11, k + 6, NovaCraftBlocks.luminant_log, 0, 2);
		world.setBlock(i + 13, j + 11, k + 6, NovaCraftBlocks.luminant_log, 0, 2);
		world.setBlock(i + 14, j + 11, k + 6, NovaCraftBlocks.luminant_leaves, 0, 2);
		world.setBlock(i + 15, j + 11, k + 6, NovaCraftBlocks.luminant_leaves, 0, 2);
		world.setBlock(i + 1, j + 11, k + 7, NovaCraftBlocks.luminant_leaves, 0, 2);
		world.setBlock(i + 2, j + 11, k + 7, NovaCraftBlocks.luminant_leaves, 0, 2);
		world.setBlock(i + 3, j + 11, k + 7, NovaCraftBlocks.luminant_leaves, 0, 2);
		world.setBlock(i + 4, j + 11, k + 7, NovaCraftBlocks.luminant_leaves, 0, 2);
		world.setBlock(i + 5, j + 11, k + 7, NovaCraftBlocks.luminant_leaves, 0, 2);
		world.setBlock(i + 6, j + 11, k + 7, NovaCraftBlocks.luminant_leaves, 0, 2);
		world.setBlock(i + 7, j + 11, k + 7, NovaCraftBlocks.luminant_leaves, 0, 2);
		world.setBlock(i + 9, j + 11, k + 7, NovaCraftBlocks.luminant_leaves, 0, 2);
		world.setBlock(i + 10, j + 11, k + 7, NovaCraftBlocks.luminant_log, 0, 2);
		world.setBlock(i + 11, j + 11, k + 7, NovaCraftBlocks.luminant_log, 0, 2);
		world.setBlock(i + 12, j + 11, k + 7, NovaCraftBlocks.luminant_log, 0, 2);
		world.setBlock(i + 13, j + 11, k + 7, NovaCraftBlocks.luminant_leaves, 0, 2);
		world.setBlock(i + 14, j + 11, k + 7, NovaCraftBlocks.luminant_leaves, 0, 2);
		world.setBlock(i + 2, j + 11, k + 8, NovaCraftBlocks.luminant_leaves, 0, 2);
		world.setBlock(i + 3, j + 11, k + 8, NovaCraftBlocks.luminant_leaves, 0, 2);
		world.setBlock(i + 4, j + 11, k + 8, NovaCraftBlocks.luminant_leaves, 0, 2);
		world.setBlock(i + 5, j + 11, k + 8, NovaCraftBlocks.luminant_leaves, 0, 2);
		world.setBlock(i + 6, j + 11, k + 8, NovaCraftBlocks.luminant_leaves, 0, 2);
		world.setBlock(i + 9, j + 11, k + 8, NovaCraftBlocks.luminant_leaves, 0, 2);
		world.setBlock(i + 10, j + 11, k + 8, NovaCraftBlocks.luminant_leaves, 0, 2);
		world.setBlock(i + 11, j + 11, k + 8, NovaCraftBlocks.luminant_leaves, 0, 2);
		world.setBlock(i + 12, j + 11, k + 8, NovaCraftBlocks.luminant_leaves, 0, 2);
		world.setBlock(i + 13, j + 11, k + 8, NovaCraftBlocks.luminant_leaves, 0, 2);
		world.setBlock(i + 10, j + 11, k + 9, NovaCraftBlocks.luminant_leaves, 0, 2);
		world.setBlock(i + 11, j + 11, k + 9, NovaCraftBlocks.luminant_leaves, 0, 2);
		world.setBlock(i + 12, j + 11, k + 9, NovaCraftBlocks.luminant_leaves, 0, 2);
		world.setBlock(i + 11, j + 12, k + 1, NovaCraftBlocks.luminant_leaves, 0, 2);
		world.setBlock(i + 2, j + 12, k + 2, NovaCraftBlocks.luminant_leaves, 0, 2);
		world.setBlock(i + 3, j + 12, k + 2, NovaCraftBlocks.luminant_leaves, 0, 2);
		world.setBlock(i + 4, j + 12, k + 2, NovaCraftBlocks.luminant_leaves, 0, 2);
		world.setBlock(i + 5, j + 12, k + 2, NovaCraftBlocks.luminant_leaves, 0, 2);
		world.setBlock(i + 6, j + 12, k + 2, NovaCraftBlocks.luminant_leaves, 0, 2);
		world.setBlock(i + 10, j + 12, k + 2, NovaCraftBlocks.luminant_leaves, 0, 2);
		world.setBlock(i + 11, j + 12, k + 2, NovaCraftBlocks.luminant_leaves, 0, 2);
		world.setBlock(i + 12, j + 12, k + 2, NovaCraftBlocks.luminant_leaves, 0, 2);
		world.setBlock(i + 1, j + 12, k + 3, NovaCraftBlocks.luminant_leaves, 0, 2);
		world.setBlock(i + 2, j + 12, k + 3, NovaCraftBlocks.luminant_leaves, 0, 2);
		world.setBlock(i + 3, j + 12, k + 3, NovaCraftBlocks.luminant_leaves, 0, 2);
		world.setBlock(i + 4, j + 12, k + 3, NovaCraftBlocks.luminant_leaves, 0, 2);
		world.setBlock(i + 5, j + 12, k + 3, NovaCraftBlocks.luminant_leaves, 0, 2);
		world.setBlock(i + 6, j + 12, k + 3, NovaCraftBlocks.luminant_leaves, 0, 2);
		world.setBlock(i + 9, j + 12, k + 3, NovaCraftBlocks.luminant_leaves, 0, 2);
		world.setBlock(i + 10, j + 12, k + 3, NovaCraftBlocks.luminant_leaves, 0, 2);
		world.setBlock(i + 11, j + 12, k + 3, NovaCraftBlocks.luminant_leaves, 0, 2);
		world.setBlock(i + 12, j + 12, k + 3, NovaCraftBlocks.luminant_leaves, 0, 2);
		world.setBlock(i + 13, j + 12, k + 3, NovaCraftBlocks.luminant_leaves, 0, 2);
		world.setBlock(i + 1, j + 12, k + 4, NovaCraftBlocks.luminant_leaves, 0, 2);
		world.setBlock(i + 2, j + 12, k + 4, NovaCraftBlocks.luminant_leaves, 0, 2);
		world.setBlock(i + 3, j + 12, k + 4, NovaCraftBlocks.luminant_leaves, 0, 2);
		world.setBlock(i + 4, j + 12, k + 4, NovaCraftBlocks.luminant_leaves, 0, 2);
		world.setBlock(i + 5, j + 12, k + 4, NovaCraftBlocks.luminant_leaves, 0, 2);
		world.setBlock(i + 6, j + 12, k + 4, NovaCraftBlocks.luminant_leaves, 0, 2);
		world.setBlock(i + 8, j + 12, k + 4, NovaCraftBlocks.luminant_leaves, 0, 2);
		world.setBlock(i + 9, j + 12, k + 4, NovaCraftBlocks.luminant_leaves, 0, 2);
		world.setBlock(i + 10, j + 12, k + 4, NovaCraftBlocks.luminant_log, 0, 2);
		world.setBlock(i + 11, j + 12, k + 4, NovaCraftBlocks.luminant_log, 0, 2);
		world.setBlock(i + 12, j + 12, k + 4, NovaCraftBlocks.luminant_log, 0, 2);
		world.setBlock(i + 13, j + 12, k + 4, NovaCraftBlocks.luminant_leaves, 0, 2);
		world.setBlock(i + 14, j + 12, k + 4, NovaCraftBlocks.luminant_leaves, 0, 2);
		world.setBlock(i + 15, j + 12, k + 4, NovaCraftBlocks.luminant_leaves, 0, 2);
		world.setBlock(i + 16, j + 12, k + 4, NovaCraftBlocks.luminant_leaves, 0, 2);
		world.setBlock(i + 17, j + 12, k + 4, NovaCraftBlocks.luminant_leaves, 0, 2);
		world.setBlock(i + 1, j + 12, k + 5, NovaCraftBlocks.luminant_leaves, 0, 2);
		world.setBlock(i + 2, j + 12, k + 5, NovaCraftBlocks.luminant_leaves, 0, 2);
		world.setBlock(i + 3, j + 12, k + 5, NovaCraftBlocks.luminant_leaves, 0, 2);
		world.setBlock(i + 4, j + 12, k + 5, NovaCraftBlocks.luminant_leaves, 0, 2);
		world.setBlock(i + 5, j + 12, k + 5, NovaCraftBlocks.luminant_leaves, 0, 2);
		world.setBlock(i + 6, j + 12, k + 5, NovaCraftBlocks.luminant_leaves, 0, 2);
		world.setBlock(i + 7, j + 12, k + 5, NovaCraftBlocks.luminant_leaves, 0, 2);
		world.setBlock(i + 8, j + 12, k + 5, NovaCraftBlocks.luminant_leaves, 0, 2);
		world.setBlock(i + 9, j + 12, k + 5, NovaCraftBlocks.luminant_leaves, 0, 2);
		world.setBlock(i + 10, j + 12, k + 5, NovaCraftBlocks.luminant_log, 0, 2);
		world.setBlock(i + 12, j + 12, k + 5, NovaCraftBlocks.luminant_log, 0, 2);
		world.setBlock(i + 13, j + 12, k + 5, NovaCraftBlocks.luminant_leaves, 0, 2);
		world.setBlock(i + 14, j + 12, k + 5, NovaCraftBlocks.luminant_leaves, 0, 2);
		world.setBlock(i + 15, j + 12, k + 5, NovaCraftBlocks.luminant_leaves, 0, 2);
		world.setBlock(i + 16, j + 12, k + 5, NovaCraftBlocks.luminant_leaves, 0, 2);
		world.setBlock(i + 17, j + 12, k + 5, NovaCraftBlocks.luminant_leaves, 0, 2);
		world.setBlock(i + 1, j + 12, k + 6, NovaCraftBlocks.luminant_leaves, 0, 2);
		world.setBlock(i + 2, j + 12, k + 6, NovaCraftBlocks.luminant_leaves, 0, 2);
		world.setBlock(i + 3, j + 12, k + 6, NovaCraftBlocks.luminant_leaves, 0, 2);
		world.setBlock(i + 4, j + 12, k + 6, NovaCraftBlocks.luminant_leaves, 0, 2);
		world.setBlock(i + 5, j + 12, k + 6, NovaCraftBlocks.luminant_leaves, 0, 2);
		world.setBlock(i + 6, j + 12, k + 6, NovaCraftBlocks.luminant_leaves, 0, 2);
		world.setBlock(i + 7, j + 12, k + 6, NovaCraftBlocks.luminant_leaves, 0, 2);
		world.setBlock(i + 8, j + 12, k + 6, NovaCraftBlocks.luminant_leaves, 0, 2);
		world.setBlock(i + 9, j + 12, k + 6, NovaCraftBlocks.luminant_leaves, 0, 2);
		world.setBlock(i + 10, j + 12, k + 6, NovaCraftBlocks.luminant_log, 0, 2);
		world.setBlock(i + 11, j + 12, k + 6, NovaCraftBlocks.luminant_log, 0, 2);
		world.setBlock(i + 12, j + 12, k + 6, NovaCraftBlocks.luminant_log, 0, 2);
		world.setBlock(i + 13, j + 12, k + 6, NovaCraftBlocks.luminant_leaves, 0, 2);
		world.setBlock(i + 14, j + 12, k + 6, NovaCraftBlocks.luminant_leaves, 0, 2);
		world.setBlock(i + 16, j + 12, k + 6, NovaCraftBlocks.luminant_leaves, 0, 2);
		world.setBlock(i + 17, j + 12, k + 6, NovaCraftBlocks.luminant_leaves, 0, 2);
		world.setBlock(i + 2, j + 12, k + 7, NovaCraftBlocks.luminant_leaves, 0, 2);
		world.setBlock(i + 3, j + 12, k + 7, NovaCraftBlocks.luminant_leaves, 0, 2);
		world.setBlock(i + 4, j + 12, k + 7, NovaCraftBlocks.luminant_leaves, 0, 2);
		world.setBlock(i + 5, j + 12, k + 7, NovaCraftBlocks.luminant_leaves, 0, 2);
		world.setBlock(i + 6, j + 12, k + 7, NovaCraftBlocks.luminant_leaves, 0, 2);
		world.setBlock(i + 7, j + 12, k + 7, NovaCraftBlocks.luminant_leaves, 0, 2);
		world.setBlock(i + 9, j + 12, k + 7, NovaCraftBlocks.luminant_leaves, 0, 2);
		world.setBlock(i + 10, j + 12, k + 7, NovaCraftBlocks.luminant_leaves, 0, 2);
		world.setBlock(i + 11, j + 12, k + 7, NovaCraftBlocks.luminant_leaves, 0, 2);
		world.setBlock(i + 12, j + 12, k + 7, NovaCraftBlocks.luminant_leaves, 0, 2);
		world.setBlock(i + 13, j + 12, k + 7, NovaCraftBlocks.luminant_leaves, 0, 2);
		world.setBlock(i + 10, j + 12, k + 8, NovaCraftBlocks.luminant_leaves, 0, 2);
		world.setBlock(i + 11, j + 12, k + 8, NovaCraftBlocks.luminant_leaves, 0, 2);
		world.setBlock(i + 12, j + 12, k + 8, NovaCraftBlocks.luminant_leaves, 0, 2);
		world.setBlock(i + 10, j + 13, k + 2, NovaCraftBlocks.luminant_leaves, 0, 2);
		world.setBlock(i + 11, j + 13, k + 2, NovaCraftBlocks.luminant_leaves, 0, 2);
		world.setBlock(i + 12, j + 13, k + 2, NovaCraftBlocks.luminant_leaves, 0, 2);
		world.setBlock(i + 9, j + 13, k + 3, NovaCraftBlocks.luminant_leaves, 0, 2);
		world.setBlock(i + 10, j + 13, k + 3, NovaCraftBlocks.luminant_leaves, 0, 2);
		world.setBlock(i + 11, j + 13, k + 3, NovaCraftBlocks.luminant_leaves, 0, 2);
		world.setBlock(i + 12, j + 13, k + 3, NovaCraftBlocks.luminant_leaves, 0, 2);
		world.setBlock(i + 13, j + 13, k + 3, NovaCraftBlocks.luminant_leaves, 0, 2);
		world.setBlock(i + 14, j + 13, k + 3, NovaCraftBlocks.luminant_leaves, 0, 2);
		world.setBlock(i + 15, j + 13, k + 3, NovaCraftBlocks.luminant_leaves, 0, 2);
		world.setBlock(i + 16, j + 13, k + 3, NovaCraftBlocks.luminant_leaves, 0, 2);
		world.setBlock(i + 17, j + 13, k + 3, NovaCraftBlocks.luminant_leaves, 0, 2);
		world.setBlock(i + 18, j + 13, k + 3, NovaCraftBlocks.luminant_leaves, 0, 2);
		world.setBlock(i + 8, j + 13, k + 4, NovaCraftBlocks.luminant_leaves, 0, 2);
		world.setBlock(i + 9, j + 13, k + 4, NovaCraftBlocks.luminant_leaves, 0, 2);
		world.setBlock(i + 10, j + 13, k + 4, NovaCraftBlocks.luminant_log, 0, 2);
		world.setBlock(i + 11, j + 13, k + 4, NovaCraftBlocks.luminant_log, 0, 2);
		world.setBlock(i + 12, j + 13, k + 4, NovaCraftBlocks.luminant_log, 0, 2);
		world.setBlock(i + 13, j + 13, k + 4, NovaCraftBlocks.luminant_leaves, 0, 2);
		world.setBlock(i + 14, j + 13, k + 4, NovaCraftBlocks.luminant_leaves, 0, 2);
		world.setBlock(i + 15, j + 13, k + 4, NovaCraftBlocks.luminant_leaves, 0, 2);
		world.setBlock(i + 16, j + 13, k + 4, NovaCraftBlocks.luminant_log, 4, 2);
		world.setBlock(i + 17, j + 13, k + 4, NovaCraftBlocks.luminant_log, 4, 2);
		world.setBlock(i + 18, j + 13, k + 4, NovaCraftBlocks.luminant_leaves, 0, 2);
		world.setBlock(i + 19, j + 13, k + 4, NovaCraftBlocks.luminant_leaves, 0, 2);
		world.setBlock(i + 8, j + 13, k + 5, NovaCraftBlocks.luminant_leaves, 0, 2);
		world.setBlock(i + 9, j + 13, k + 5, NovaCraftBlocks.luminant_leaves, 0, 2);
		world.setBlock(i + 10, j + 13, k + 5, NovaCraftBlocks.luminant_log, 0, 2);
		world.setBlock(i + 12, j + 13, k + 5, NovaCraftBlocks.luminant_log, 0, 2);
		world.setBlock(i + 13, j + 13, k + 5, NovaCraftBlocks.luminant_log, 4, 2);
		world.setBlock(i + 14, j + 13, k + 5, NovaCraftBlocks.luminant_log, 4, 2);
		world.setBlock(i + 15, j + 13, k + 5, NovaCraftBlocks.luminant_log, 4, 2);
		world.setBlock(i + 16, j + 13, k + 5, NovaCraftBlocks.luminant_log, 4, 2);
		world.setBlock(i + 17, j + 13, k + 5, NovaCraftBlocks.luminant_log, 4, 2);
		world.setBlock(i + 18, j + 13, k + 5, NovaCraftBlocks.luminant_leaves, 0, 2);
		world.setBlock(i + 19, j + 13, k + 5, NovaCraftBlocks.luminant_leaves, 0, 2);
		world.setBlock(i + 8, j + 13, k + 6, NovaCraftBlocks.luminant_leaves, 0, 2);
		world.setBlock(i + 9, j + 13, k + 6, NovaCraftBlocks.luminant_leaves, 0, 2);
		world.setBlock(i + 10, j + 13, k + 6, NovaCraftBlocks.luminant_log, 0, 2);
		world.setBlock(i + 11, j + 13, k + 6, NovaCraftBlocks.luminant_log, 0, 2);
		world.setBlock(i + 12, j + 13, k + 6, NovaCraftBlocks.luminant_log, 0, 2);
		world.setBlock(i + 13, j + 13, k + 6, NovaCraftBlocks.luminant_leaves, 0, 2);
		world.setBlock(i + 14, j + 13, k + 6, NovaCraftBlocks.luminant_leaves, 0, 2);
		world.setBlock(i + 15, j + 13, k + 6, NovaCraftBlocks.luminant_leaves, 0, 2);
		world.setBlock(i + 16, j + 13, k + 6, NovaCraftBlocks.luminant_log, 4, 2);
		world.setBlock(i + 17, j + 13, k + 6, NovaCraftBlocks.luminant_log, 4, 2);
		world.setBlock(i + 18, j + 13, k + 6, NovaCraftBlocks.luminant_leaves, 0, 2);
		world.setBlock(i + 19, j + 13, k + 6, NovaCraftBlocks.luminant_leaves, 0, 2);
		world.setBlock(i + 9, j + 13, k + 7, NovaCraftBlocks.luminant_leaves, 0, 2);
		world.setBlock(i + 10, j + 13, k + 7, NovaCraftBlocks.luminant_leaves, 0, 2);
		world.setBlock(i + 11, j + 13, k + 7, NovaCraftBlocks.luminant_leaves, 0, 2);
		world.setBlock(i + 12, j + 13, k + 7, NovaCraftBlocks.luminant_leaves, 0, 2);
		world.setBlock(i + 13, j + 13, k + 7, NovaCraftBlocks.luminant_leaves, 0, 2);
		world.setBlock(i + 15, j + 13, k + 7, NovaCraftBlocks.luminant_leaves, 0, 2);
		world.setBlock(i + 16, j + 13, k + 7, NovaCraftBlocks.luminant_leaves, 0, 2);
		world.setBlock(i + 17, j + 13, k + 7, NovaCraftBlocks.luminant_leaves, 0, 2);
		world.setBlock(i + 18, j + 13, k + 7, NovaCraftBlocks.luminant_leaves, 0, 2);
		world.setBlock(i + 10, j + 13, k + 8, NovaCraftBlocks.luminant_leaves, 0, 2);
		world.setBlock(i + 11, j + 13, k + 8, NovaCraftBlocks.luminant_leaves, 0, 2);
		world.setBlock(i + 12, j + 13, k + 8, NovaCraftBlocks.luminant_leaves, 0, 2);
		world.setBlock(i + 14, j + 14, k + 2, NovaCraftBlocks.luminant_leaves, 0, 2);
		world.setBlock(i + 15, j + 14, k + 2, NovaCraftBlocks.luminant_leaves, 0, 2);
		world.setBlock(i + 16, j + 14, k + 2, NovaCraftBlocks.luminant_leaves, 0, 2);
		world.setBlock(i + 17, j + 14, k + 2, NovaCraftBlocks.luminant_leaves, 0, 2);
		world.setBlock(i + 18, j + 14, k + 2, NovaCraftBlocks.luminant_leaves, 0, 2);
		world.setBlock(i + 10, j + 14, k + 3, NovaCraftBlocks.luminant_leaves, 0, 2);
		world.setBlock(i + 11, j + 14, k + 3, NovaCraftBlocks.luminant_leaves, 0, 2);
		world.setBlock(i + 12, j + 14, k + 3, NovaCraftBlocks.luminant_leaves, 0, 2);
		world.setBlock(i + 13, j + 14, k + 3, NovaCraftBlocks.luminant_leaves, 0, 2);
		world.setBlock(i + 14, j + 14, k + 3, NovaCraftBlocks.luminant_leaves, 0, 2);
		world.setBlock(i + 15, j + 14, k + 3, NovaCraftBlocks.luminant_log, 4, 2);
		world.setBlock(i + 16, j + 14, k + 3, NovaCraftBlocks.luminant_log, 4, 2);
		world.setBlock(i + 17, j + 14, k + 3, NovaCraftBlocks.luminant_log, 4, 2);
		world.setBlock(i + 18, j + 14, k + 3, NovaCraftBlocks.luminant_leaves, 0, 2);
		world.setBlock(i + 19, j + 14, k + 3, NovaCraftBlocks.luminant_leaves, 0, 2);
		world.setBlock(i + 9, j + 14, k + 4, NovaCraftBlocks.luminant_leaves, 0, 2);
		world.setBlock(i + 10, j + 14, k + 4, NovaCraftBlocks.luminant_log, 0, 2);
		world.setBlock(i + 11, j + 14, k + 4, NovaCraftBlocks.luminant_log, 0, 2);
		world.setBlock(i + 12, j + 14, k + 4, NovaCraftBlocks.luminant_log, 0, 2);
		world.setBlock(i + 13, j + 14, k + 4, NovaCraftBlocks.luminant_log, 4, 2);
		world.setBlock(i + 14, j + 14, k + 4, NovaCraftBlocks.luminant_log, 4, 2);
		world.setBlock(i + 15, j + 14, k + 4, NovaCraftBlocks.luminant_log, 4, 2);
		world.setBlock(i + 18, j + 14, k + 4, NovaCraftBlocks.luminant_log, 4, 2);
		world.setBlock(i + 19, j + 14, k + 4, NovaCraftBlocks.luminant_leaves, 0, 2);
		world.setBlock(i + 20, j + 14, k + 4, NovaCraftBlocks.luminant_leaves, 0, 2);
		world.setBlock(i + 9, j + 14, k + 5, NovaCraftBlocks.luminant_leaves, 0, 2);
		world.setBlock(i + 10, j + 14, k + 5, NovaCraftBlocks.luminant_log, 0, 2);
		world.setBlock(i + 18, j + 14, k + 5, NovaCraftBlocks.luminant_log, 4, 2);
		world.setBlock(i + 19, j + 14, k + 5, NovaCraftBlocks.luminant_leaves, 0, 2);
		world.setBlock(i + 20, j + 14, k + 5, NovaCraftBlocks.luminant_leaves, 0, 2);
		world.setBlock(i + 9, j + 14, k + 6, NovaCraftBlocks.luminant_leaves, 0, 2);
		world.setBlock(i + 10, j + 14, k + 6, NovaCraftBlocks.luminant_log, 0, 2);
		world.setBlock(i + 11, j + 14, k + 6, NovaCraftBlocks.luminant_log, 0, 2);
		world.setBlock(i + 12, j + 14, k + 6, NovaCraftBlocks.luminant_log, 0, 2);
		world.setBlock(i + 13, j + 14, k + 6, NovaCraftBlocks.luminant_log, 4, 2);
		world.setBlock(i + 14, j + 14, k + 6, NovaCraftBlocks.luminant_log, 4, 2);
		world.setBlock(i + 15, j + 14, k + 6, NovaCraftBlocks.luminant_log, 4, 2);
		world.setBlock(i + 18, j + 14, k + 6, NovaCraftBlocks.luminant_log, 4, 2);
		world.setBlock(i + 19, j + 14, k + 6, NovaCraftBlocks.luminant_leaves, 0, 2);
		world.setBlock(i + 20, j + 14, k + 6, NovaCraftBlocks.luminant_leaves, 0, 2);
		world.setBlock(i + 10, j + 14, k + 7, NovaCraftBlocks.luminant_leaves, 0, 2);
		world.setBlock(i + 11, j + 14, k + 7, NovaCraftBlocks.luminant_leaves, 0, 2);
		world.setBlock(i + 12, j + 14, k + 7, NovaCraftBlocks.luminant_leaves, 0, 2);
		world.setBlock(i + 13, j + 14, k + 7, NovaCraftBlocks.luminant_leaves, 0, 2);
		world.setBlock(i + 14, j + 14, k + 7, NovaCraftBlocks.luminant_leaves, 0, 2);
		world.setBlock(i + 15, j + 14, k + 7, NovaCraftBlocks.luminant_log, 4, 2);
		world.setBlock(i + 16, j + 14, k + 7, NovaCraftBlocks.luminant_log, 4, 2);
		world.setBlock(i + 17, j + 14, k + 7, NovaCraftBlocks.luminant_log, 4, 2);
		world.setBlock(i + 18, j + 14, k + 7, NovaCraftBlocks.luminant_leaves, 0, 2);
		world.setBlock(i + 19, j + 14, k + 7, NovaCraftBlocks.luminant_leaves, 0, 2);
		world.setBlock(i + 14, j + 14, k + 8, NovaCraftBlocks.luminant_leaves, 0, 2);
		world.setBlock(i + 15, j + 14, k + 8, NovaCraftBlocks.luminant_leaves, 0, 2);
		world.setBlock(i + 16, j + 14, k + 8, NovaCraftBlocks.luminant_leaves, 0, 2);
		world.setBlock(i + 17, j + 14, k + 8, NovaCraftBlocks.luminant_leaves, 0, 2);
		world.setBlock(i + 18, j + 14, k + 8, NovaCraftBlocks.luminant_leaves, 0, 2);
		world.setBlock(i + 11, j + 15, k + 2, NovaCraftBlocks.luminant_leaves, 0, 2);
		world.setBlock(i + 14, j + 15, k + 2, NovaCraftBlocks.luminant_leaves, 0, 2);
		world.setBlock(i + 15, j + 15, k + 2, NovaCraftBlocks.luminant_leaves, 0, 2);
		world.setBlock(i + 16, j + 15, k + 2, NovaCraftBlocks.luminant_leaves, 0, 2);
		world.setBlock(i + 17, j + 15, k + 2, NovaCraftBlocks.luminant_leaves, 0, 2);
		world.setBlock(i + 18, j + 15, k + 2, NovaCraftBlocks.luminant_leaves, 0, 2);
		world.setBlock(i + 10, j + 15, k + 3, NovaCraftBlocks.luminant_leaves, 0, 2);
		world.setBlock(i + 11, j + 15, k + 3, NovaCraftBlocks.luminant_leaves, 0, 2);
		world.setBlock(i + 12, j + 15, k + 3, NovaCraftBlocks.luminant_leaves, 0, 2);
		world.setBlock(i + 13, j + 15, k + 3, NovaCraftBlocks.luminant_leaves, 0, 2);
		world.setBlock(i + 14, j + 15, k + 3, NovaCraftBlocks.luminant_leaves, 0, 2);
		world.setBlock(i + 15, j + 15, k + 3, NovaCraftBlocks.luminant_log, 4, 2);
		world.setBlock(i + 16, j + 15, k + 3, NovaCraftBlocks.luminant_log, 4, 2);
		world.setBlock(i + 17, j + 15, k + 3, NovaCraftBlocks.luminant_log, 4, 2);
		world.setBlock(i + 18, j + 15, k + 3, NovaCraftBlocks.luminant_leaves, 0, 2);
		world.setBlock(i + 19, j + 15, k + 3, NovaCraftBlocks.luminant_leaves, 0, 2);
		world.setBlock(i + 9, j + 15, k + 4, NovaCraftBlocks.luminant_leaves, 0, 2);
		world.setBlock(i + 10, j + 15, k + 4, NovaCraftBlocks.luminant_leaves, 0, 2);
		world.setBlock(i + 11, j + 15, k + 4, NovaCraftBlocks.luminant_log, 0, 2);
		world.setBlock(i + 12, j + 15, k + 4, NovaCraftBlocks.luminant_leaves, 0, 2);
		world.setBlock(i + 13, j + 15, k + 4, NovaCraftBlocks.luminant_log, 4, 2);
		world.setBlock(i + 14, j + 15, k + 4, NovaCraftBlocks.luminant_log, 4, 2);
		world.setBlock(i + 15, j + 15, k + 4, NovaCraftBlocks.luminant_log, 4, 2);
		world.setBlock(i + 18, j + 15, k + 4, NovaCraftBlocks.luminant_log, 4, 2);
		world.setBlock(i + 19, j + 15, k + 4, NovaCraftBlocks.luminant_leaves, 0, 2);
		world.setBlock(i + 20, j + 15, k + 4, NovaCraftBlocks.luminant_leaves, 0, 2);
		world.setBlock(i + 8, j + 15, k + 5, NovaCraftBlocks.luminant_leaves, 0, 2);
		world.setBlock(i + 9, j + 15, k + 5, NovaCraftBlocks.luminant_leaves, 0, 2);
		world.setBlock(i + 10, j + 15, k + 5, NovaCraftBlocks.luminant_log, 0, 2);
		world.setBlock(i + 18, j + 15, k + 5, NovaCraftBlocks.luminant_log, 4, 2);
		world.setBlock(i + 19, j + 15, k + 5, NovaCraftBlocks.luminant_leaves, 0, 2);
		world.setBlock(i + 20, j + 15, k + 5, NovaCraftBlocks.luminant_leaves, 0, 2);
		world.setBlock(i + 9, j + 15, k + 6, NovaCraftBlocks.luminant_leaves, 0, 2);
		world.setBlock(i + 10, j + 15, k + 6, NovaCraftBlocks.luminant_leaves, 0, 2);
		world.setBlock(i + 11, j + 15, k + 6, NovaCraftBlocks.luminant_log, 0, 2);
		world.setBlock(i + 12, j + 15, k + 6, NovaCraftBlocks.luminant_log, 4, 2);
		world.setBlock(i + 13, j + 15, k + 6, NovaCraftBlocks.luminant_log, 4, 2);
		world.setBlock(i + 14, j + 15, k + 6, NovaCraftBlocks.luminant_log, 4, 2);
		world.setBlock(i + 15, j + 15, k + 6, NovaCraftBlocks.luminant_log, 4, 2);
		world.setBlock(i + 18, j + 15, k + 6, NovaCraftBlocks.luminant_log, 4, 2);
		world.setBlock(i + 19, j + 15, k + 6, NovaCraftBlocks.luminant_leaves, 0, 2);
		world.setBlock(i + 20, j + 15, k + 6, NovaCraftBlocks.luminant_leaves, 0, 2);
		world.setBlock(i + 10, j + 15, k + 7, NovaCraftBlocks.luminant_leaves, 0, 2);
		world.setBlock(i + 11, j + 15, k + 7, NovaCraftBlocks.luminant_leaves, 0, 2);
		world.setBlock(i + 12, j + 15, k + 7, NovaCraftBlocks.luminant_leaves, 0, 2);
		world.setBlock(i + 13, j + 15, k + 7, NovaCraftBlocks.luminant_leaves, 0, 2);
		world.setBlock(i + 14, j + 15, k + 7, NovaCraftBlocks.luminant_leaves, 0, 2);
		world.setBlock(i + 15, j + 15, k + 7, NovaCraftBlocks.luminant_log, 4, 2);
		world.setBlock(i + 16, j + 15, k + 7, NovaCraftBlocks.luminant_log, 4, 2);
		world.setBlock(i + 17, j + 15, k + 7, NovaCraftBlocks.luminant_log, 4, 2);
		world.setBlock(i + 18, j + 15, k + 7, NovaCraftBlocks.luminant_leaves, 0, 2);
		world.setBlock(i + 19, j + 15, k + 7, NovaCraftBlocks.luminant_leaves, 0, 2);
		world.setBlock(i + 11, j + 15, k + 8, NovaCraftBlocks.luminant_leaves, 0, 2);
		world.setBlock(i + 14, j + 15, k + 8, NovaCraftBlocks.luminant_leaves, 0, 2);
		world.setBlock(i + 15, j + 15, k + 8, NovaCraftBlocks.luminant_leaves, 0, 2);
		world.setBlock(i + 16, j + 15, k + 8, NovaCraftBlocks.luminant_leaves, 0, 2);
		world.setBlock(i + 17, j + 15, k + 8, NovaCraftBlocks.luminant_leaves, 0, 2);
		world.setBlock(i + 18, j + 15, k + 8, NovaCraftBlocks.luminant_leaves, 0, 2);
		world.setBlock(i + 14, j + 16, k + 2, NovaCraftBlocks.luminant_leaves, 0, 2);
		world.setBlock(i + 15, j + 16, k + 2, NovaCraftBlocks.luminant_leaves, 0, 2);
		world.setBlock(i + 16, j + 16, k + 2, NovaCraftBlocks.luminant_leaves, 0, 2);
		world.setBlock(i + 17, j + 16, k + 2, NovaCraftBlocks.luminant_leaves, 0, 2);
		world.setBlock(i + 18, j + 16, k + 2, NovaCraftBlocks.luminant_leaves, 0, 2);
		world.setBlock(i + 10, j + 16, k + 3, NovaCraftBlocks.luminant_leaves, 0, 2);
		world.setBlock(i + 11, j + 16, k + 3, NovaCraftBlocks.luminant_leaves, 0, 2);
		world.setBlock(i + 12, j + 16, k + 3, NovaCraftBlocks.luminant_leaves, 0, 2);
		world.setBlock(i + 13, j + 16, k + 3, NovaCraftBlocks.luminant_leaves, 0, 2);
		world.setBlock(i + 14, j + 16, k + 3, NovaCraftBlocks.luminant_leaves, 0, 2);
		world.setBlock(i + 15, j + 16, k + 3, NovaCraftBlocks.luminant_leaves, 0, 2);
		world.setBlock(i + 16, j + 16, k + 3, NovaCraftBlocks.luminant_log, 4, 2);
		world.setBlock(i + 17, j + 16, k + 3, NovaCraftBlocks.luminant_log, 4, 2);
		world.setBlock(i + 18, j + 16, k + 3, NovaCraftBlocks.luminant_leaves, 0, 2);
		world.setBlock(i + 19, j + 16, k + 3, NovaCraftBlocks.luminant_leaves, 0, 2);
		world.setBlock(i + 9, j + 16, k + 4, NovaCraftBlocks.luminant_leaves, 0, 2);
		world.setBlock(i + 10, j + 16, k + 4, NovaCraftBlocks.luminant_leaves, 0, 2);
		world.setBlock(i + 11, j + 16, k + 4, NovaCraftBlocks.luminant_log, 0, 2);
		world.setBlock(i + 12, j + 16, k + 4, NovaCraftBlocks.luminant_leaves, 0, 2);
		world.setBlock(i + 13, j + 16, k + 4, NovaCraftBlocks.luminant_leaves, 0, 2);
		world.setBlock(i + 14, j + 16, k + 4, NovaCraftBlocks.luminant_log, 4, 2);
		world.setBlock(i + 15, j + 16, k + 4, NovaCraftBlocks.luminant_log, 4, 2);
		world.setBlock(i + 18, j + 16, k + 4, NovaCraftBlocks.luminant_log, 4, 2);
		world.setBlock(i + 19, j + 16, k + 4, NovaCraftBlocks.luminant_leaves, 0, 2);
		world.setBlock(i + 20, j + 16, k + 4, NovaCraftBlocks.luminant_leaves, 0, 2);
		world.setBlock(i + 9, j + 16, k + 5, NovaCraftBlocks.luminant_leaves, 0, 2);
		world.setBlock(i + 10, j + 16, k + 5, NovaCraftBlocks.luminant_log, 0, 2);
		world.setBlock(i + 11, j + 16, k + 5, NovaCraftBlocks.luminant_log, 0, 2);
		world.setBlock(i + 12, j + 16, k + 5, NovaCraftBlocks.luminant_log, 0, 2);
		world.setBlock(i + 13, j + 16, k + 5, NovaCraftBlocks.luminant_log, 4, 2);
		world.setBlock(i + 14, j + 16, k + 5, NovaCraftBlocks.luminant_log, 4, 2);
		world.setBlock(i + 15, j + 16, k + 5, NovaCraftBlocks.luminant_log, 4, 2);
		world.setBlock(i + 18, j + 16, k + 5, NovaCraftBlocks.luminant_log, 4, 2);
		world.setBlock(i + 19, j + 16, k + 5, NovaCraftBlocks.luminant_leaves, 0, 2);
		world.setBlock(i + 20, j + 16, k + 5, NovaCraftBlocks.luminant_leaves, 0, 2);
		world.setBlock(i + 9, j + 16, k + 6, NovaCraftBlocks.luminant_leaves, 0, 2);
		world.setBlock(i + 10, j + 16, k + 6, NovaCraftBlocks.luminant_leaves, 0, 2);
		world.setBlock(i + 11, j + 16, k + 6, NovaCraftBlocks.luminant_log, 0, 2);
		world.setBlock(i + 12, j + 16, k + 6, NovaCraftBlocks.luminant_leaves, 0, 2);
		world.setBlock(i + 13, j + 16, k + 6, NovaCraftBlocks.luminant_leaves, 0, 2);
		world.setBlock(i + 14, j + 16, k + 6, NovaCraftBlocks.luminant_log, 4, 2);
		world.setBlock(i + 15, j + 16, k + 6, NovaCraftBlocks.luminant_log, 4, 2);
		world.setBlock(i + 18, j + 16, k + 6, NovaCraftBlocks.luminant_log, 4, 2);
		world.setBlock(i + 19, j + 16, k + 6, NovaCraftBlocks.luminant_leaves, 0, 2);
		world.setBlock(i + 20, j + 16, k + 6, NovaCraftBlocks.luminant_leaves, 0, 2);
		world.setBlock(i + 10, j + 16, k + 7, NovaCraftBlocks.luminant_leaves, 0, 2);
		world.setBlock(i + 11, j + 16, k + 7, NovaCraftBlocks.luminant_leaves, 0, 2);
		world.setBlock(i + 12, j + 16, k + 7, NovaCraftBlocks.luminant_leaves, 0, 2);
		world.setBlock(i + 13, j + 16, k + 7, NovaCraftBlocks.luminant_leaves, 0, 2);
		world.setBlock(i + 14, j + 16, k + 7, NovaCraftBlocks.luminant_leaves, 0, 2);
		world.setBlock(i + 15, j + 16, k + 7, NovaCraftBlocks.luminant_leaves, 0, 2);
		world.setBlock(i + 16, j + 16, k + 7, NovaCraftBlocks.luminant_log, 4, 2);
		world.setBlock(i + 17, j + 16, k + 7, NovaCraftBlocks.luminant_log, 4, 2);
		world.setBlock(i + 18, j + 16, k + 7, NovaCraftBlocks.luminant_leaves, 0, 2);
		world.setBlock(i + 19, j + 16, k + 7, NovaCraftBlocks.luminant_leaves, 0, 2);
		world.setBlock(i + 14, j + 16, k + 8, NovaCraftBlocks.luminant_leaves, 0, 2);
		world.setBlock(i + 15, j + 16, k + 8, NovaCraftBlocks.luminant_leaves, 0, 2);
		world.setBlock(i + 16, j + 16, k + 8, NovaCraftBlocks.luminant_leaves, 0, 2);
		world.setBlock(i + 17, j + 16, k + 8, NovaCraftBlocks.luminant_leaves, 0, 2);
		world.setBlock(i + 18, j + 16, k + 8, NovaCraftBlocks.luminant_leaves, 0, 2);
		world.setBlock(i + 11, j + 17, k + 2, NovaCraftBlocks.luminant_leaves, 0, 2);
		world.setBlock(i + 15, j + 17, k + 2, NovaCraftBlocks.luminant_leaves, 0, 2);
		world.setBlock(i + 16, j + 17, k + 2, NovaCraftBlocks.luminant_leaves, 0, 2);
		world.setBlock(i + 17, j + 17, k + 2, NovaCraftBlocks.luminant_leaves, 0, 2);
		world.setBlock(i + 10, j + 17, k + 3, NovaCraftBlocks.luminant_leaves, 0, 2);
		world.setBlock(i + 11, j + 17, k + 3, NovaCraftBlocks.luminant_leaves, 0, 2);
		world.setBlock(i + 14, j + 17, k + 3, NovaCraftBlocks.luminant_leaves, 0, 2);
		world.setBlock(i + 15, j + 17, k + 3, NovaCraftBlocks.luminant_leaves, 0, 2);
		world.setBlock(i + 16, j + 17, k + 3, NovaCraftBlocks.luminant_leaves, 0, 2);
		world.setBlock(i + 17, j + 17, k + 3, NovaCraftBlocks.luminant_leaves, 0, 2);
		world.setBlock(i + 18, j + 17, k + 3, NovaCraftBlocks.luminant_leaves, 0, 2);
		world.setBlock(i + 9, j + 17, k + 4, NovaCraftBlocks.luminant_leaves, 0, 2);
		world.setBlock(i + 10, j + 17, k + 4, NovaCraftBlocks.luminant_leaves, 0, 2);
		world.setBlock(i + 11, j + 17, k + 4, NovaCraftBlocks.luminant_log, 0, 2);
		world.setBlock(i + 12, j + 17, k + 4, NovaCraftBlocks.luminant_leaves, 0, 2);
		world.setBlock(i + 13, j + 17, k + 4, NovaCraftBlocks.luminant_leaves, 0, 2);
		world.setBlock(i + 14, j + 17, k + 4, NovaCraftBlocks.luminant_leaves, 0, 2);
		world.setBlock(i + 15, j + 17, k + 4, NovaCraftBlocks.luminant_leaves, 0, 2);
		world.setBlock(i + 16, j + 17, k + 4, NovaCraftBlocks.luminant_log, 4, 2);
		world.setBlock(i + 17, j + 17, k + 4, NovaCraftBlocks.luminant_log, 4, 2);
		world.setBlock(i + 18, j + 17, k + 4, NovaCraftBlocks.luminant_leaves, 0, 2);
		world.setBlock(i + 19, j + 17, k + 4, NovaCraftBlocks.luminant_leaves, 0, 2);
		world.setBlock(i + 20, j + 17, k + 4, NovaCraftBlocks.luminant_leaves, 0, 2);
		world.setBlock(i + 8, j + 17, k + 5, NovaCraftBlocks.luminant_leaves, 0, 2);
		world.setBlock(i + 9, j + 17, k + 5, NovaCraftBlocks.luminant_leaves, 0, 2);
		world.setBlock(i + 10, j + 17, k + 5, NovaCraftBlocks.luminant_log, 0, 2);
		world.setBlock(i + 11, j + 17, k + 5, NovaCraftBlocks.luminant_log, 0, 2);
		world.setBlock(i + 12, j + 17, k + 5, NovaCraftBlocks.luminant_log, 0, 2);
		world.setBlock(i + 13, j + 17, k + 5, NovaCraftBlocks.luminant_leaves, 0, 2);
		world.setBlock(i + 14, j + 17, k + 5, NovaCraftBlocks.luminant_leaves, 0, 2);
		world.setBlock(i + 15, j + 17, k + 5, NovaCraftBlocks.luminant_leaves, 0, 2);
		world.setBlock(i + 16, j + 17, k + 5, NovaCraftBlocks.luminant_leaves, 0, 2);
		world.setBlock(i + 17, j + 17, k + 5, NovaCraftBlocks.luminant_log, 4, 2);
		world.setBlock(i + 18, j + 17, k + 5, NovaCraftBlocks.luminant_leaves, 0, 2);
		world.setBlock(i + 19, j + 17, k + 5, NovaCraftBlocks.luminant_leaves, 0, 2);
		world.setBlock(i + 20, j + 17, k + 5, NovaCraftBlocks.luminant_leaves, 0, 2);
		world.setBlock(i + 9, j + 17, k + 6, NovaCraftBlocks.luminant_leaves, 0, 2);
		world.setBlock(i + 10, j + 17, k + 6, NovaCraftBlocks.luminant_leaves, 0, 2);
		world.setBlock(i + 11, j + 17, k + 6, NovaCraftBlocks.luminant_log, 0, 2);
		world.setBlock(i + 12, j + 17, k + 6, NovaCraftBlocks.luminant_leaves, 0, 2);
		world.setBlock(i + 13, j + 17, k + 6, NovaCraftBlocks.luminant_leaves, 0, 2);
		world.setBlock(i + 14, j + 17, k + 6, NovaCraftBlocks.luminant_leaves, 0, 2);
		world.setBlock(i + 15, j + 17, k + 6, NovaCraftBlocks.luminant_leaves, 0, 2);
		world.setBlock(i + 16, j + 17, k + 6, NovaCraftBlocks.luminant_log, 4, 2);
		world.setBlock(i + 17, j + 17, k + 6, NovaCraftBlocks.luminant_log, 4, 2);
		world.setBlock(i + 18, j + 17, k + 6, NovaCraftBlocks.luminant_leaves, 0, 2);
		world.setBlock(i + 19, j + 17, k + 6, NovaCraftBlocks.luminant_leaves, 0, 2);
		world.setBlock(i + 20, j + 17, k + 6, NovaCraftBlocks.luminant_leaves, 0, 2);
		world.setBlock(i + 10, j + 17, k + 7, NovaCraftBlocks.luminant_leaves, 0, 2);
		world.setBlock(i + 11, j + 17, k + 7, NovaCraftBlocks.luminant_leaves, 0, 2);
		world.setBlock(i + 12, j + 17, k + 7, NovaCraftBlocks.luminant_leaves, 0, 2);
		world.setBlock(i + 14, j + 17, k + 7, NovaCraftBlocks.luminant_leaves, 0, 2);
		world.setBlock(i + 15, j + 17, k + 7, NovaCraftBlocks.luminant_leaves, 0, 2);
		world.setBlock(i + 16, j + 17, k + 7, NovaCraftBlocks.luminant_leaves, 0, 2);
		world.setBlock(i + 17, j + 17, k + 7, NovaCraftBlocks.luminant_leaves, 0, 2);
		world.setBlock(i + 18, j + 17, k + 7, NovaCraftBlocks.luminant_leaves, 0, 2);
		world.setBlock(i + 19, j + 17, k + 7, NovaCraftBlocks.luminant_leaves, 0, 2);
		world.setBlock(i + 15, j + 17, k + 8, NovaCraftBlocks.luminant_leaves, 0, 2);
		world.setBlock(i + 16, j + 17, k + 8, NovaCraftBlocks.luminant_leaves, 0, 2);
		world.setBlock(i + 17, j + 17, k + 8, NovaCraftBlocks.luminant_leaves, 0, 2);
		world.setBlock(i + 18, j + 17, k + 8, NovaCraftBlocks.luminant_leaves, 0, 2);
		world.setBlock(i + 10, j + 18, k + 3, NovaCraftBlocks.luminant_leaves, 0, 2);
		world.setBlock(i + 11, j + 18, k + 3, NovaCraftBlocks.luminant_leaves, 0, 2);
		world.setBlock(i + 15, j + 18, k + 3, NovaCraftBlocks.luminant_leaves, 0, 2);
		world.setBlock(i + 16, j + 18, k + 3, NovaCraftBlocks.luminant_leaves, 0, 2);
		world.setBlock(i + 17, j + 18, k + 3, NovaCraftBlocks.luminant_leaves, 0, 2);
		world.setBlock(i + 9, j + 18, k + 4, NovaCraftBlocks.luminant_leaves, 0, 2);
		world.setBlock(i + 10, j + 18, k + 4, NovaCraftBlocks.luminant_leaves, 0, 2);
		world.setBlock(i + 11, j + 18, k + 4, NovaCraftBlocks.luminant_log, 0, 2);
		world.setBlock(i + 12, j + 18, k + 4, NovaCraftBlocks.luminant_leaves, 0, 2);
		world.setBlock(i + 14, j + 18, k + 4, NovaCraftBlocks.luminant_leaves, 0, 2);
		world.setBlock(i + 15, j + 18, k + 4, NovaCraftBlocks.luminant_leaves, 0, 2);
		world.setBlock(i + 16, j + 18, k + 4, NovaCraftBlocks.luminant_leaves, 0, 2);
		world.setBlock(i + 17, j + 18, k + 4, NovaCraftBlocks.luminant_leaves, 0, 2);
		world.setBlock(i + 18, j + 18, k + 4, NovaCraftBlocks.luminant_leaves, 0, 2);
		world.setBlock(i + 19, j + 18, k + 4, NovaCraftBlocks.luminant_leaves, 0, 2);
		world.setBlock(i + 9, j + 18, k + 5, NovaCraftBlocks.luminant_leaves, 0, 2);
		world.setBlock(i + 10, j + 18, k + 5, NovaCraftBlocks.luminant_log, 0, 2);
		world.setBlock(i + 11, j + 18, k + 5, NovaCraftBlocks.luminant_log, 0, 2);
		world.setBlock(i + 12, j + 18, k + 5, NovaCraftBlocks.luminant_log, 0, 2);
		world.setBlock(i + 13, j + 18, k + 5, NovaCraftBlocks.luminant_leaves, 0, 2);
		world.setBlock(i + 14, j + 18, k + 5, NovaCraftBlocks.luminant_leaves, 0, 2);
		world.setBlock(i + 15, j + 18, k + 5, NovaCraftBlocks.luminant_leaves, 0, 2);
		world.setBlock(i + 16, j + 18, k + 5, NovaCraftBlocks.luminant_leaves, 0, 2);
		world.setBlock(i + 17, j + 18, k + 5, NovaCraftBlocks.luminant_leaves, 0, 2);
		world.setBlock(i + 18, j + 18, k + 5, NovaCraftBlocks.luminant_leaves, 0, 2);
		world.setBlock(i + 19, j + 18, k + 5, NovaCraftBlocks.luminant_leaves, 0, 2);
		world.setBlock(i + 9, j + 18, k + 6, NovaCraftBlocks.luminant_leaves, 0, 2);
		world.setBlock(i + 10, j + 18, k + 6, NovaCraftBlocks.luminant_leaves, 0, 2);
		world.setBlock(i + 11, j + 18, k + 6, NovaCraftBlocks.luminant_log, 0, 2);
		world.setBlock(i + 12, j + 18, k + 6, NovaCraftBlocks.luminant_leaves, 0, 2);
		world.setBlock(i + 14, j + 18, k + 6, NovaCraftBlocks.luminant_leaves, 0, 2);
		world.setBlock(i + 15, j + 18, k + 6, NovaCraftBlocks.luminant_leaves, 0, 2);
		world.setBlock(i + 16, j + 18, k + 6, NovaCraftBlocks.luminant_leaves, 0, 2);
		world.setBlock(i + 17, j + 18, k + 6, NovaCraftBlocks.luminant_leaves, 0, 2);
		world.setBlock(i + 18, j + 18, k + 6, NovaCraftBlocks.luminant_leaves, 0, 2);
		world.setBlock(i + 19, j + 18, k + 6, NovaCraftBlocks.luminant_leaves, 0, 2);
		world.setBlock(i + 10, j + 18, k + 7, NovaCraftBlocks.luminant_leaves, 0, 2);
		world.setBlock(i + 11, j + 18, k + 7, NovaCraftBlocks.luminant_leaves, 0, 2);
		world.setBlock(i + 12, j + 18, k + 7, NovaCraftBlocks.luminant_leaves, 0, 2);
		world.setBlock(i + 15, j + 18, k + 7, NovaCraftBlocks.luminant_leaves, 0, 2);
		world.setBlock(i + 16, j + 18, k + 7, NovaCraftBlocks.luminant_leaves, 0, 2);
		world.setBlock(i + 17, j + 18, k + 7, NovaCraftBlocks.luminant_leaves, 0, 2);
		world.setBlock(i + 11, j + 18, k + 8, NovaCraftBlocks.luminant_leaves, 0, 2);
		world.setBlock(i + 11, j + 19, k + 2, NovaCraftBlocks.luminant_leaves, 0, 2);
		world.setBlock(i + 10, j + 19, k + 3, NovaCraftBlocks.luminant_leaves, 0, 2);
		world.setBlock(i + 11, j + 19, k + 3, NovaCraftBlocks.luminant_leaves, 0, 2);
		world.setBlock(i + 9, j + 19, k + 4, NovaCraftBlocks.luminant_leaves, 0, 2);
		world.setBlock(i + 10, j + 19, k + 4, NovaCraftBlocks.luminant_leaves, 0, 2);
		world.setBlock(i + 11, j + 19, k + 4, NovaCraftBlocks.luminant_leaves, 0, 2);
		world.setBlock(i + 12, j + 19, k + 4, NovaCraftBlocks.luminant_leaves, 0, 2);
		world.setBlock(i + 9, j + 19, k + 5, NovaCraftBlocks.luminant_leaves, 0, 2);
		world.setBlock(i + 10, j + 19, k + 5, NovaCraftBlocks.luminant_leaves, 0, 2);
		world.setBlock(i + 11, j + 19, k + 5, NovaCraftBlocks.luminant_log, 0, 2);
		world.setBlock(i + 12, j + 19, k + 5, NovaCraftBlocks.luminant_leaves, 0, 2);
		world.setBlock(i + 13, j + 19, k + 5, NovaCraftBlocks.luminant_leaves, 0, 2);
		world.setBlock(i + 9, j + 19, k + 6, NovaCraftBlocks.luminant_leaves, 0, 2);
		world.setBlock(i + 10, j + 19, k + 6, NovaCraftBlocks.luminant_leaves, 0, 2);
		world.setBlock(i + 11, j + 19, k + 6, NovaCraftBlocks.luminant_leaves, 0, 2);
		world.setBlock(i + 12, j + 19, k + 6, NovaCraftBlocks.luminant_leaves, 0, 2);
		world.setBlock(i + 10, j + 19, k + 7, NovaCraftBlocks.luminant_leaves, 0, 2);
		world.setBlock(i + 11, j + 19, k + 7, NovaCraftBlocks.luminant_leaves, 0, 2);
		world.setBlock(i + 12, j + 19, k + 7, NovaCraftBlocks.luminant_leaves, 0, 2);
		world.setBlock(i + 10, j + 20, k + 3, NovaCraftBlocks.luminant_leaves, 0, 2);
		world.setBlock(i + 11, j + 20, k + 3, NovaCraftBlocks.luminant_leaves, 0, 2);
		world.setBlock(i + 9, j + 20, k + 4, NovaCraftBlocks.luminant_leaves, 0, 2);
		world.setBlock(i + 10, j + 20, k + 4, NovaCraftBlocks.luminant_leaves, 0, 2);
		world.setBlock(i + 11, j + 20, k + 4, NovaCraftBlocks.luminant_leaves, 0, 2);
		world.setBlock(i + 12, j + 20, k + 4, NovaCraftBlocks.luminant_leaves, 0, 2);
		world.setBlock(i + 8, j + 20, k + 5, NovaCraftBlocks.luminant_leaves, 0, 2);
		world.setBlock(i + 9, j + 20, k + 5, NovaCraftBlocks.luminant_leaves, 0, 2);
		world.setBlock(i + 10, j + 20, k + 5, NovaCraftBlocks.luminant_leaves, 0, 2);
		world.setBlock(i + 11, j + 20, k + 5, NovaCraftBlocks.luminant_log, 0, 2);
		world.setBlock(i + 12, j + 20, k + 5, NovaCraftBlocks.luminant_leaves, 0, 2);
		world.setBlock(i + 13, j + 20, k + 5, NovaCraftBlocks.luminant_leaves, 0, 2);
		world.setBlock(i + 14, j + 20, k + 5, NovaCraftBlocks.luminant_leaves, 0, 2);
		world.setBlock(i + 9, j + 20, k + 6, NovaCraftBlocks.luminant_leaves, 0, 2);
		world.setBlock(i + 10, j + 20, k + 6, NovaCraftBlocks.luminant_leaves, 0, 2);
		world.setBlock(i + 11, j + 20, k + 6, NovaCraftBlocks.luminant_leaves, 0, 2);
		world.setBlock(i + 12, j + 20, k + 6, NovaCraftBlocks.luminant_leaves, 0, 2);
		world.setBlock(i + 10, j + 20, k + 7, NovaCraftBlocks.luminant_leaves, 0, 2);
		world.setBlock(i + 11, j + 20, k + 7, NovaCraftBlocks.luminant_leaves, 0, 2);
		world.setBlock(i + 12, j + 20, k + 7, NovaCraftBlocks.luminant_leaves, 0, 2);
		world.setBlock(i + 11, j + 21, k + 2, NovaCraftBlocks.luminant_leaves, 0, 2);
		world.setBlock(i + 10, j + 21, k + 3, NovaCraftBlocks.luminant_leaves, 0, 2);
		world.setBlock(i + 11, j + 21, k + 3, NovaCraftBlocks.luminant_leaves, 0, 2);
		world.setBlock(i + 9, j + 21, k + 4, NovaCraftBlocks.luminant_leaves, 0, 2);
		world.setBlock(i + 10, j + 21, k + 4, NovaCraftBlocks.luminant_leaves, 0, 2);
		world.setBlock(i + 11, j + 21, k + 4, NovaCraftBlocks.luminant_leaves, 0, 2);
		world.setBlock(i + 12, j + 21, k + 4, NovaCraftBlocks.luminant_leaves, 0, 2);
		world.setBlock(i + 9, j + 21, k + 5, NovaCraftBlocks.luminant_leaves, 0, 2);
		world.setBlock(i + 10, j + 21, k + 5, NovaCraftBlocks.luminant_leaves, 0, 2);
		world.setBlock(i + 11, j + 21, k + 5, NovaCraftBlocks.luminant_log, 0, 2);
		world.setBlock(i + 12, j + 21, k + 5, NovaCraftBlocks.luminant_leaves, 0, 2);
		world.setBlock(i + 13, j + 21, k + 5, NovaCraftBlocks.luminant_leaves, 0, 2);
		world.setBlock(i + 9, j + 21, k + 6, NovaCraftBlocks.luminant_leaves, 0, 2);
		world.setBlock(i + 10, j + 21, k + 6, NovaCraftBlocks.luminant_leaves, 0, 2);
		world.setBlock(i + 11, j + 21, k + 6, NovaCraftBlocks.luminant_leaves, 0, 2);
		world.setBlock(i + 12, j + 21, k + 6, NovaCraftBlocks.luminant_leaves, 0, 2);
		world.setBlock(i + 11, j + 21, k + 7, NovaCraftBlocks.luminant_leaves, 0, 2);
		world.setBlock(i + 11, j + 21, k + 8, NovaCraftBlocks.luminant_leaves, 0, 2);
		world.setBlock(i + 11, j + 22, k + 3, NovaCraftBlocks.luminant_leaves, 0, 2);
		world.setBlock(i + 10, j + 22, k + 4, NovaCraftBlocks.luminant_leaves, 0, 2);
		world.setBlock(i + 11, j + 22, k + 4, NovaCraftBlocks.luminant_leaves, 0, 2);
		world.setBlock(i + 12, j + 22, k + 4, NovaCraftBlocks.luminant_leaves, 0, 2);
		world.setBlock(i + 9, j + 22, k + 5, NovaCraftBlocks.luminant_leaves, 0, 2);
		world.setBlock(i + 10, j + 22, k + 5, NovaCraftBlocks.luminant_leaves, 0, 2);
		world.setBlock(i + 11, j + 22, k + 5, NovaCraftBlocks.luminant_leaves, 0, 2);
		world.setBlock(i + 12, j + 22, k + 5, NovaCraftBlocks.luminant_leaves, 0, 2);
		world.setBlock(i + 13, j + 22, k + 5, NovaCraftBlocks.luminant_leaves, 0, 2);
		world.setBlock(i + 10, j + 22, k + 6, NovaCraftBlocks.luminant_leaves, 0, 2);
		world.setBlock(i + 11, j + 22, k + 6, NovaCraftBlocks.luminant_leaves, 0, 2);
		world.setBlock(i + 12, j + 22, k + 6, NovaCraftBlocks.luminant_leaves, 0, 2);
		world.setBlock(i + 11, j + 22, k + 7, NovaCraftBlocks.luminant_leaves, 0, 2);
		world.setBlock(i + 11, j + 23, k + 4, NovaCraftBlocks.luminant_leaves, 0, 2);
		world.setBlock(i + 10, j + 23, k + 5, NovaCraftBlocks.luminant_leaves, 0, 2);
		world.setBlock(i + 11, j + 23, k + 5, NovaCraftBlocks.luminant_leaves, 0, 2);
		world.setBlock(i + 12, j + 23, k + 5, NovaCraftBlocks.luminant_leaves, 0, 2);
		world.setBlock(i + 11, j + 23, k + 6, NovaCraftBlocks.luminant_leaves, 0, 2);
		world.setBlock(i + 11, j + 24, k + 5, NovaCraftBlocks.luminant_leaves, 0, 2);

		world.setBlock(i + 17, j + 14, k + 5, Blocks.chest, 4, 2);
		TileEntityChest chest = (TileEntityChest) world.getTileEntity(i + 17, j + 14, k + 5);

		for (int slot = 0; slot < 3 + random.nextInt(25); slot++) {
			chest.setInventorySlotContents(random.nextInt(chest.getSizeInventory()), this.getTreeLoot(random));
		}
		
		if (!world.isRemote) {
            final EntityCreaking creaking = new EntityCreaking(world);
            creaking.setLocationAndAngles((double)(i + 11), (double)(j + 1), (double)(k + 3), 0.0f, 0.0f);
            world.spawnEntityInWorld((Entity)creaking);
            creaking.setType(5);
        }
		
		if (!world.isRemote) {
            final EntityCreaking creaking2 = new EntityCreaking(world);
            creaking2.setLocationAndAngles((double)(i + 10), (double)(j + 7), (double)(k + 6), 0.0f, 0.0f);
            world.spawnEntityInWorld((Entity)creaking2);
            creaking2.setType(5);
        }
		
		if (!world.isRemote) {
            final EntityCreaking creaking3 = new EntityCreaking(world);
            creaking3.setLocationAndAngles((double)(i + 3), (double)(j + 8), (double)(k + 5), 0.0f, 0.0f);
            world.spawnEntityInWorld((Entity)creaking3);
            creaking3.setType(5);
        }
		
		if (!world.isRemote) {
            final EntityCreaking creaking4 = new EntityCreaking(world);
            creaking4.setLocationAndAngles((double)(i + 16), (double)(j + 14), (double)(k + 5), 0.0f, 0.0f);
            world.spawnEntityInWorld((Entity)creaking4);
            creaking4.setType(5);
        	}
		
		return true;
	}
	
	private ItemStack getTreeLoot(Random random) {
		int item = random.nextInt(10);
		switch (item) {
			case 0:
				return new ItemStack(Items.stick, random.nextInt(8) + 7);
			case 1:
				return new ItemStack(NovaCraftItems.luminant_ingot, random.nextInt(2) + 1);
			case 2:
				return new ItemStack(NovaCraftItems.luminant_gel, random.nextInt(5) + 7);
			case 3:
				return new ItemStack(NovaCraftItems.luminant_apple, random.nextInt(1) + 1);
			case 4:
				return new ItemStack(NovaCraftItems.luminant_tree_sap, random.nextInt(7) + 6);
			case 5:
				return new ItemStack(NovaCraftBlocks.luminant_sapling, random.nextInt(3) + 1);
			case 6:
				return new ItemStack(NovaCraftBlocks.luminant_log, random.nextInt(3) + 2);
			default:
				return new ItemStack(NovaCraftBlocks.luminant_log, random.nextInt(3) + 2);
		}
	}
}
