package com.NovaCraft.world.structure;

import java.util.Random;

import com.NovaCraft.Items.NovaCraftItems;
import com.NovaCraft.config.Configs;
import com.NovaCraftBlocks.NovaCraftBlocks;
import net.minecraft.block.Block;
import net.minecraft.init.Blocks;
import net.minecraft.init.Items;
import net.minecraft.item.ItemStack;
import net.minecraft.tileentity.TileEntityChest;
import net.minecraft.tileentity.TileEntityMobSpawner;
import net.minecraft.world.World;
import net.minecraft.world.gen.feature.WorldGenerator;

public class SlimeStructureGen extends WorldGenerator {

    public SlimeStructureGen() {

    }

    public boolean generate(final World world, final Random random, final int i, final int j, final int k) {

        if (world.getBlock(i, j - 1, k) != Blocks.water && world.getBlock(i, j - 1, k) != Blocks.air) {

            world.setBlock(i + 2, j + 0, k + 2, Blocks.cobblestone, 0, 2);
            world.setBlock(i + 3, j + 0, k + 2, Blocks.cobblestone, 0, 2);
            world.setBlock(i + 4, j + 0, k + 2, Blocks.cobblestone, 0, 2);
            world.setBlock(i + 5, j + 0, k + 2, Blocks.cobblestone, 0, 2);
            world.setBlock(i + 6, j + 0, k + 2, Blocks.cobblestone, 0, 2);
            world.setBlock(i + 7, j + 0, k + 2, Blocks.cobblestone, 0, 2);
            world.setBlock(i + 8, j + 0, k + 2, Blocks.cobblestone, 0, 2);
            world.setBlock(i + 9, j + 0, k + 2, Blocks.cobblestone, 0, 2);
            world.setBlock(i + 10, j + 0, k + 2, Blocks.cobblestone, 0, 2);
            world.setBlock(i + 11, j + 0, k + 2, Blocks.cobblestone, 0, 2);
            world.setBlock(i + 2, j + 0, k + 3, Blocks.cobblestone, 0, 2);
            world.setBlock(i + 3, j + 0, k + 3, Blocks.stonebrick, 1, 2);
            world.setBlock(i + 4, j + 0, k + 3, Blocks.stonebrick, 1, 2);
            world.setBlock(i + 5, j + 0, k + 3, Blocks.stonebrick, 0, 2);
            world.setBlock(i + 6, j + 0, k + 3, Blocks.stonebrick, 0, 2);
            world.setBlock(i + 7, j + 0, k + 3, Blocks.stonebrick, 0, 2);
            world.setBlock(i + 8, j + 0, k + 3, Blocks.stonebrick, 0, 2);
            world.setBlock(i + 9, j + 0, k + 3, Blocks.stonebrick, 1, 2);
            world.setBlock(i + 10, j + 0, k + 3, Blocks.stonebrick, 0, 2);
            world.setBlock(i + 11, j + 0, k + 3, Blocks.cobblestone, 0, 2);
            world.setBlock(i + 2, j + 0, k + 4, Blocks.cobblestone, 0, 2);
            world.setBlock(i + 3, j + 0, k + 4, Blocks.stonebrick, 2, 2);
            world.setBlock(i + 4, j + 0, k + 4, Blocks.stonebrick, 0, 2);
            world.setBlock(i + 5, j + 0, k + 4, Blocks.stonebrick, 0, 2);
            world.setBlock(i + 6, j + 0, k + 4, Blocks.stonebrick, 0, 2);
            world.setBlock(i + 7, j + 0, k + 4, Blocks.stonebrick, 1, 2);
            world.setBlock(i + 8, j + 0, k + 4, Blocks.stonebrick, 0, 2);
            world.setBlock(i + 9, j + 0, k + 4, Blocks.stonebrick, 0, 2);
            world.setBlock(i + 10, j + 0, k + 4, Blocks.stonebrick, 2, 2);
            world.setBlock(i + 11, j + 0, k + 4, Blocks.cobblestone, 0, 2);
            world.setBlock(i + 2, j + 0, k + 5, Blocks.cobblestone, 0, 2);
            world.setBlock(i + 3, j + 0, k + 5, Blocks.stonebrick, 0, 2);
            world.setBlock(i + 4, j + 0, k + 5, Blocks.stonebrick, 0, 2);
            world.setBlock(i + 5, j + 0, k + 5, Blocks.stonebrick, 0, 2);
            world.setBlock(i + 6, j + 0, k + 5, Blocks.stonebrick, 1, 2);
            world.setBlock(i + 7, j + 0, k + 5, Blocks.stonebrick, 0, 2);
            world.setBlock(i + 8, j + 0, k + 5, Blocks.stonebrick, 2, 2);
            world.setBlock(i + 9, j + 0, k + 5, Blocks.stonebrick, 0, 2);
            world.setBlock(i + 10, j + 0, k + 5, Blocks.stonebrick, 0, 2);
            world.setBlock(i + 11, j + 0, k + 5, Blocks.cobblestone, 0, 2);
            world.setBlock(i + 2, j + 0, k + 6, Blocks.cobblestone, 0, 2);
            world.setBlock(i + 3, j + 0, k + 6, Blocks.stonebrick, 0, 2);
            world.setBlock(i + 4, j + 0, k + 6, Blocks.stonebrick, 0, 2);
            world.setBlock(i + 5, j + 0, k + 6, Blocks.stonebrick, 2, 2);
            world.setBlock(i + 6, j + 0, k + 6, Blocks.stonebrick, 0, 2);
            world.setBlock(i + 7, j + 0, k + 6, Blocks.stonebrick, 1, 2);
            world.setBlock(i + 8, j + 0, k + 6, Blocks.stonebrick, 0, 2);
            world.setBlock(i + 9, j + 0, k + 6, Blocks.stonebrick, 1, 2);
            world.setBlock(i + 10, j + 0, k + 6, Blocks.stonebrick, 0, 2);
            world.setBlock(i + 11, j + 0, k + 6, Blocks.cobblestone, 0, 2);
            world.setBlock(i + 2, j + 0, k + 7, Blocks.cobblestone, 0, 2);
            world.setBlock(i + 3, j + 0, k + 7, Blocks.stonebrick, 0, 2);
            world.setBlock(i + 4, j + 0, k + 7, Blocks.stonebrick, 2, 2);
            world.setBlock(i + 5, j + 0, k + 7, Blocks.stonebrick, 1, 2);
            world.setBlock(i + 6, j + 0, k + 7, Blocks.stonebrick, 0, 2);
            world.setBlock(i + 7, j + 0, k + 7, Blocks.stonebrick, 0, 2);
            world.setBlock(i + 8, j + 0, k + 7, Blocks.stonebrick, 0, 2);
            world.setBlock(i + 9, j + 0, k + 7, Blocks.stonebrick, 2, 2);
            world.setBlock(i + 10, j + 0, k + 7, Blocks.stonebrick, 0, 2);
            world.setBlock(i + 11, j + 0, k + 7, Blocks.cobblestone, 0, 2);
            world.setBlock(i + 2, j + 0, k + 8, Blocks.cobblestone, 0, 2);
            world.setBlock(i + 3, j + 0, k + 8, Blocks.stonebrick, 0, 2);
            world.setBlock(i + 4, j + 0, k + 8, Blocks.stonebrick, 0, 2);
            world.setBlock(i + 5, j + 0, k + 8, Blocks.stonebrick, 0, 2);
            world.setBlock(i + 6, j + 0, k + 8, Blocks.stonebrick, 2, 2);
            world.setBlock(i + 7, j + 0, k + 8, Blocks.stonebrick, 0, 2);
            world.setBlock(i + 8, j + 0, k + 8, Blocks.stonebrick, 2, 2);
            world.setBlock(i + 9, j + 0, k + 8, Blocks.stonebrick, 0, 2);
            world.setBlock(i + 10, j + 0, k + 8, Blocks.stonebrick, 0, 2);
            world.setBlock(i + 11, j + 0, k + 8, Blocks.cobblestone, 0, 2);
            world.setBlock(i + 2, j + 0, k + 9, Blocks.cobblestone, 0, 2);
            world.setBlock(i + 3, j + 0, k + 9, Blocks.stonebrick, 1, 2);
            world.setBlock(i + 4, j + 0, k + 9, Blocks.stonebrick, 0, 2);
            world.setBlock(i + 5, j + 0, k + 9, Blocks.stonebrick, 0, 2);
            world.setBlock(i + 6, j + 0, k + 9, Blocks.stonebrick, 0, 2);
            world.setBlock(i + 7, j + 0, k + 9, Blocks.stonebrick, 0, 2);
            world.setBlock(i + 8, j + 0, k + 9, Blocks.stonebrick, 1, 2);
            world.setBlock(i + 9, j + 0, k + 9, Blocks.stonebrick, 0, 2);
            world.setBlock(i + 10, j + 0, k + 9, Blocks.stonebrick, 2, 2);
            world.setBlock(i + 11, j + 0, k + 9, Blocks.cobblestone, 0, 2);
            world.setBlock(i + 2, j + 0, k + 10, Blocks.cobblestone, 0, 2);
            world.setBlock(i + 3, j + 0, k + 10, Blocks.stonebrick, 0, 2);
            world.setBlock(i + 4, j + 0, k + 10, Blocks.stonebrick, 1, 2);
            world.setBlock(i + 5, j + 0, k + 10, Blocks.stonebrick, 0, 2);
            world.setBlock(i + 6, j + 0, k + 10, Blocks.stonebrick, 2, 2);
            world.setBlock(i + 7, j + 0, k + 10, Blocks.stonebrick, 0, 2);
            world.setBlock(i + 8, j + 0, k + 10, Blocks.stonebrick, 1, 2);
            world.setBlock(i + 9, j + 0, k + 10, Blocks.stonebrick, 0, 2);
            world.setBlock(i + 10, j + 0, k + 10, Blocks.stonebrick, 0, 2);
            world.setBlock(i + 11, j + 0, k + 10, Blocks.cobblestone, 0, 2);
            world.setBlock(i + 2, j + 0, k + 11, Blocks.cobblestone, 0, 2);
            world.setBlock(i + 3, j + 0, k + 11, Blocks.cobblestone, 0, 2);
            world.setBlock(i + 4, j + 0, k + 11, Blocks.cobblestone, 0, 2);
            world.setBlock(i + 5, j + 0, k + 11, Blocks.cobblestone, 0, 2);
            world.setBlock(i + 6, j + 0, k + 11, Blocks.cobblestone, 0, 2);
            world.setBlock(i + 7, j + 0, k + 11, Blocks.cobblestone, 0, 2);
            world.setBlock(i + 8, j + 0, k + 11, Blocks.cobblestone, 0, 2);
            world.setBlock(i + 9, j + 0, k + 11, Blocks.cobblestone, 0, 2);
            world.setBlock(i + 10, j + 0, k + 11, Blocks.cobblestone, 0, 2);
            world.setBlock(i + 11, j + 0, k + 11, Blocks.cobblestone, 0, 2);
            world.setBlock(i + 2, j + 1, k + 2, Blocks.cobblestone, 0, 2);
            world.setBlock(i + 3, j + 1, k + 2, Blocks.stonebrick, 2, 2);
            world.setBlock(i + 4, j + 1, k + 2, Blocks.stonebrick, 0, 2);
            world.setBlock(i + 5, j + 1, k + 2, Blocks.stonebrick, 0, 2);
            world.setBlock(i + 6, j + 1, k + 2, Blocks.stonebrick, 1, 2);
            world.setBlock(i + 7, j + 1, k + 2, Blocks.stonebrick, 1, 2);
            world.setBlock(i + 8, j + 1, k + 2, Blocks.stonebrick, 0, 2);
            world.setBlock(i + 9, j + 1, k + 2, Blocks.stonebrick, 0, 2);
            world.setBlock(i + 10, j + 1, k + 2, Blocks.stonebrick, 2, 2);
            world.setBlock(i + 11, j + 1, k + 2, Blocks.cobblestone, 0, 2);
            world.setBlock(i + 2, j + 1, k + 3, Blocks.stonebrick, 2, 2);
            world.setBlock(i + 3, j + 1, k + 3, Blocks.water, 0, 2);
            world.setBlock(i + 4, j + 1, k + 3, Blocks.water, 0, 2);
            world.setBlock(i + 5, j + 1, k + 3, Blocks.water, 0, 2);
            world.setBlock(i + 6, j + 1, k + 3, Blocks.water, 0, 2);
            world.setBlock(i + 7, j + 1, k + 3, Blocks.water, 0, 2);
            world.setBlock(i + 8, j + 1, k + 3, Blocks.water, 0, 2);
            world.setBlock(i + 9, j + 1, k + 3, Blocks.water, 0, 2);
            world.setBlock(i + 10, j + 1, k + 3, Blocks.water, 0, 2);
            world.setBlock(i + 11, j + 1, k + 3, Blocks.stonebrick, 0, 2);
            world.setBlock(i + 2, j + 1, k + 4, Blocks.stonebrick, 0, 2);
            world.setBlock(i + 3, j + 1, k + 4, Blocks.water, 0, 2);
            world.setBlock(i + 4, j + 1, k + 4, Blocks.water, 0, 2);
            world.setBlock(i + 5, j + 1, k + 4, Blocks.water, 0, 2);
            world.setBlock(i + 6, j + 1, k + 4, Blocks.water, 0, 2);
            world.setBlock(i + 7, j + 1, k + 4, Blocks.water, 0, 2);
            world.setBlock(i + 8, j + 1, k + 4, Blocks.water, 0, 2);
            world.setBlock(i + 9, j + 1, k + 4, Blocks.water, 0, 2);
            world.setBlock(i + 10, j + 1, k + 4, Blocks.water, 0, 2);
            world.setBlock(i + 11, j + 1, k + 4, Blocks.stonebrick, 0, 2);
            world.setBlock(i + 2, j + 1, k + 5, Blocks.stonebrick, 0, 2);
            world.setBlock(i + 3, j + 1, k + 5, Blocks.water, 0, 2);
            world.setBlock(i + 4, j + 1, k + 5, Blocks.water, 0, 2);
            world.setBlock(i + 5, j + 1, k + 5, Blocks.water, 0, 2);
            world.setBlock(i + 6, j + 1, k + 5, Blocks.water, 0, 2);
            world.setBlock(i + 7, j + 1, k + 5, Blocks.water, 0, 2);
            world.setBlock(i + 8, j + 1, k + 5, Blocks.water, 0, 2);
            world.setBlock(i + 9, j + 1, k + 5, Blocks.water, 0, 2);
            world.setBlock(i + 10, j + 1, k + 5, NovaCraftBlocks.flooded_chest, 0, 2);
            world.setBlock(i + 11, j + 1, k + 5, Blocks.stonebrick, 0, 2);
            world.setBlock(i + 2, j + 1, k + 6, Blocks.stonebrick, 2, 2);
            world.setBlock(i + 3, j + 1, k + 6, Blocks.water, 0, 2);
            world.setBlock(i + 4, j + 1, k + 6, Blocks.water, 0, 2);
            world.setBlock(i + 5, j + 1, k + 6, Blocks.water, 0, 2);
            world.setBlock(i + 6, j + 1, k + 6, Blocks.water, 0, 2);
            world.setBlock(i + 7, j + 1, k + 6, Blocks.water, 0, 2);
            world.setBlock(i + 8, j + 1, k + 6, Blocks.water, 0, 2);
            world.setBlock(i + 9, j + 1, k + 6, Blocks.water, 0, 2);
            world.setBlock(i + 10, j + 1, k + 6, Blocks.water, 0, 2);
            world.setBlock(i + 11, j + 1, k + 6, Blocks.stonebrick, 1, 2);
            world.setBlock(i + 2, j + 1, k + 7, Blocks.stonebrick, 0, 2);
            world.setBlock(i + 3, j + 1, k + 7, Blocks.water, 0, 2);
            world.setBlock(i + 4, j + 1, k + 7, Blocks.water, 0, 2);
            world.setBlock(i + 5, j + 1, k + 7, Blocks.water, 0, 2);
            world.setBlock(i + 6, j + 1, k + 7, Blocks.water, 0, 2);
            world.setBlock(i + 7, j + 1, k + 7, Blocks.water, 0, 2);
            world.setBlock(i + 8, j + 1, k + 7, Blocks.water, 0, 2);
            world.setBlock(i + 9, j + 1, k + 7, Blocks.water, 0, 2);
            world.setBlock(i + 10, j + 1, k + 7, Blocks.water, 0, 2);
            world.setBlock(i + 11, j + 1, k + 7, Blocks.stonebrick, 1, 2);
            world.setBlock(i + 2, j + 1, k + 8, Blocks.stonebrick, 0, 2);
            world.setBlock(i + 3, j + 1, k + 8, Blocks.water, 0, 2);
            world.setBlock(i + 4, j + 1, k + 8, Blocks.water, 0, 2);
            world.setBlock(i + 6, j + 1, k + 8, Blocks.water, 0, 2);
            world.setBlock(i + 7, j + 1, k + 8, Blocks.water, 0, 2);
            world.setBlock(i + 8, j + 1, k + 8, Blocks.water, 0, 2);
            world.setBlock(i + 9, j + 1, k + 8, Blocks.water, 0, 2);
            world.setBlock(i + 10, j + 1, k + 8, Blocks.water, 0, 2);
            world.setBlock(i + 11, j + 1, k + 8, Blocks.stonebrick, 0, 2);
            world.setBlock(i + 2, j + 1, k + 9, Blocks.stonebrick, 0, 2);
            world.setBlock(i + 3, j + 1, k + 9, Blocks.water, 0, 2);
            world.setBlock(i + 4, j + 1, k + 9, Blocks.water, 0, 2);
            world.setBlock(i + 5, j + 1, k + 9, Blocks.water, 0, 2);
            world.setBlock(i + 6, j + 1, k + 9, Blocks.water, 0, 2);
            world.setBlock(i + 7, j + 1, k + 9, Blocks.water, 0, 2);
            world.setBlock(i + 8, j + 1, k + 9, Blocks.water, 0, 2);
            world.setBlock(i + 9, j + 1, k + 9, Blocks.water, 0, 2);
            world.setBlock(i + 10, j + 1, k + 9, Blocks.water, 0, 2);
            world.setBlock(i + 11, j + 1, k + 9, Blocks.stonebrick, 0, 2);
            world.setBlock(i + 2, j + 1, k + 10, Blocks.stonebrick, 0, 2);
            world.setBlock(i + 3, j + 1, k + 10, Blocks.water, 0, 2);
            world.setBlock(i + 4, j + 1, k + 10, Blocks.water, 0, 2);
            world.setBlock(i + 5, j + 1, k + 10, Blocks.water, 0, 2);
            world.setBlock(i + 6, j + 1, k + 10, Blocks.water, 0, 2);
            world.setBlock(i + 7, j + 1, k + 10, Blocks.water, 0, 2);
            world.setBlock(i + 8, j + 1, k + 10, NovaCraftBlocks.flooded_chest, 0, 2);
            world.setBlock(i + 9, j + 1, k + 10, Blocks.water, 0, 2);
            world.setBlock(i + 10, j + 1, k + 10, Blocks.water, 0, 2);
            world.setBlock(i + 11, j + 1, k + 10, Blocks.stonebrick, 2, 2);
            world.setBlock(i + 2, j + 1, k + 11, Blocks.cobblestone, 0, 2);
            world.setBlock(i + 3, j + 1, k + 11, Blocks.stonebrick, 0, 2);
            world.setBlock(i + 4, j + 1, k + 11, Blocks.stonebrick, 2, 2);
            world.setBlock(i + 5, j + 1, k + 11, Blocks.stonebrick, 0, 2);
            world.setBlock(i + 6, j + 1, k + 11, Blocks.stonebrick, 0, 2);
            world.setBlock(i + 7, j + 1, k + 11, Blocks.stonebrick, 0, 2);
            world.setBlock(i + 8, j + 1, k + 11, Blocks.stonebrick, 1, 2);
            world.setBlock(i + 9, j + 1, k + 11, Blocks.stonebrick, 0, 2);
            world.setBlock(i + 10, j + 1, k + 11, Blocks.stonebrick, 0, 2);
            world.setBlock(i + 11, j + 1, k + 11, Blocks.cobblestone, 0, 2);
            world.setBlock(i + 4, j + 2, k + 1, Blocks.vine, 1, 2);
            world.setBlock(i + 5, j + 2, k + 1, Blocks.vine, 1, 2);
            world.setBlock(i + 6, j + 2, k + 1, Blocks.vine, 1, 2);
            world.setBlock(i + 2, j + 2, k + 2, Blocks.cobblestone, 0, 2);
            world.setBlock(i + 3, j + 2, k + 2, Blocks.stonebrick, 0, 2);
            world.setBlock(i + 4, j + 2, k + 2, Blocks.stonebrick, 1, 2);
            world.setBlock(i + 5, j + 2, k + 2, Blocks.stonebrick, 0, 2);
            world.setBlock(i + 6, j + 2, k + 2, Blocks.stonebrick, 0, 2);
            world.setBlock(i + 7, j + 2, k + 2, Blocks.stonebrick, 2, 2);
            world.setBlock(i + 8, j + 2, k + 2, Blocks.stonebrick, 0, 2);
            world.setBlock(i + 9, j + 2, k + 2, Blocks.stonebrick, 1, 2);
            world.setBlock(i + 10, j + 2, k + 2, Blocks.stonebrick, 0, 2);
            world.setBlock(i + 11, j + 2, k + 2, Blocks.cobblestone, 0, 2);
            world.setBlock(i + 2, j + 2, k + 3, Blocks.stonebrick, 0, 2);
            world.setBlock(i + 3, j + 2, k + 3, Blocks.water, 0, 2);
            world.setBlock(i + 4, j + 2, k + 3, Blocks.water, 0, 2);
            world.setBlock(i + 5, j + 2, k + 3, Blocks.water, 0, 2);
            world.setBlock(i + 6, j + 2, k + 3, Blocks.water, 0, 2);
            world.setBlock(i + 7, j + 2, k + 3, Blocks.water, 0, 2);
            world.setBlock(i + 8, j + 2, k + 3, Blocks.water, 0, 2);
            world.setBlock(i + 9, j + 2, k + 3, Blocks.water, 0, 2);
            world.setBlock(i + 10, j + 2, k + 3, Blocks.water, 0, 2);
            world.setBlock(i + 11, j + 2, k + 3, Blocks.stonebrick, 1, 2);
            world.setBlock(i + 2, j + 2, k + 4, Blocks.stonebrick, 1, 2);
            world.setBlock(i + 3, j + 2, k + 4, Blocks.water, 0, 2);
            world.setBlock(i + 4, j + 2, k + 4, Blocks.water, 0, 2);
            world.setBlock(i + 5, j + 2, k + 4, Blocks.water, 0, 2);
            world.setBlock(i + 6, j + 2, k + 4, Blocks.water, 0, 2);
            world.setBlock(i + 7, j + 2, k + 4, Blocks.water, 0, 2);
            world.setBlock(i + 8, j + 2, k + 4, Blocks.water, 0, 2);
            world.setBlock(i + 9, j + 2, k + 4, Blocks.water, 0, 2);
            world.setBlock(i + 10, j + 2, k + 4, Blocks.water, 0, 2);
            world.setBlock(i + 11, j + 2, k + 4, Blocks.stonebrick, 0, 2);
            world.setBlock(i + 2, j + 2, k + 5, Blocks.stonebrick, 0, 2);
            world.setBlock(i + 3, j + 2, k + 5, Blocks.water, 0, 2);
            world.setBlock(i + 4, j + 2, k + 5, Blocks.water, 0, 2);
            world.setBlock(i + 5, j + 2, k + 5, Blocks.water, 0, 2);
            world.setBlock(i + 6, j + 2, k + 5, Blocks.water, 0, 2);
            world.setBlock(i + 7, j + 2, k + 5, Blocks.water, 0, 2);
            world.setBlock(i + 8, j + 2, k + 5, Blocks.water, 0, 2);
            world.setBlock(i + 9, j + 2, k + 5, Blocks.water, 0, 2);
            world.setBlock(i + 10, j + 2, k + 5, Blocks.water, 0, 2);
            world.setBlock(i + 11, j + 2, k + 5, Blocks.stonebrick, 2, 2);
            world.setBlock(i + 2, j + 2, k + 6, Blocks.stonebrick, 1, 2);
            world.setBlock(i + 3, j + 2, k + 6, Blocks.water, 0, 2);
            world.setBlock(i + 4, j + 2, k + 6, Blocks.water, 0, 2);
            world.setBlock(i + 5, j + 2, k + 6, Blocks.water, 0, 2);
            world.setBlock(i + 6, j + 2, k + 6, Blocks.water, 0, 2);
            world.setBlock(i + 7, j + 2, k + 6, Blocks.water, 0, 2);
            world.setBlock(i + 8, j + 2, k + 6, Blocks.water, 0, 2);
            world.setBlock(i + 9, j + 2, k + 6, Blocks.water, 0, 2);
            world.setBlock(i + 10, j + 2, k + 6, Blocks.water, 0, 2);
            world.setBlock(i + 11, j + 2, k + 6, Blocks.stonebrick, 0, 2);
            world.setBlock(i + 2, j + 2, k + 7, Blocks.stonebrick, 0, 2);
            world.setBlock(i + 3, j + 2, k + 7, Blocks.water, 0, 2);
            world.setBlock(i + 4, j + 2, k + 7, Blocks.water, 0, 2);
            world.setBlock(i + 5, j + 2, k + 7, Blocks.water, 0, 2);
            world.setBlock(i + 6, j + 2, k + 7, Blocks.water, 0, 2);
            world.setBlock(i + 7, j + 2, k + 7, Blocks.water, 0, 2);
            world.setBlock(i + 8, j + 2, k + 7, Blocks.water, 0, 2);
            world.setBlock(i + 9, j + 2, k + 7, Blocks.water, 0, 2);
            world.setBlock(i + 10, j + 2, k + 7, Blocks.water, 0, 2);
            world.setBlock(i + 11, j + 2, k + 7, Blocks.stonebrick, 0, 2);
            world.setBlock(i + 2, j + 2, k + 8, Blocks.stonebrick, 0, 2);
            world.setBlock(i + 3, j + 2, k + 8, Blocks.water, 0, 2);
            world.setBlock(i + 4, j + 2, k + 8, Blocks.water, 0, 2);
            world.setBlock(i + 5, j + 2, k + 8, Blocks.water, 0, 2);
            world.setBlock(i + 6, j + 2, k + 8, Blocks.water, 0, 2);
            world.setBlock(i + 7, j + 2, k + 8, Blocks.water, 0, 2);
            world.setBlock(i + 8, j + 2, k + 8, Blocks.water, 0, 2);
            world.setBlock(i + 9, j + 2, k + 8, Blocks.water, 0, 2);
            world.setBlock(i + 10, j + 2, k + 8, Blocks.water, 0, 2);
            world.setBlock(i + 11, j + 2, k + 8, Blocks.stonebrick, 2, 2);
            world.setBlock(i + 2, j + 2, k + 9, Blocks.stonebrick, 2, 2);
            world.setBlock(i + 3, j + 2, k + 9, Blocks.water, 0, 2);
            world.setBlock(i + 4, j + 2, k + 9, Blocks.water, 0, 2);
            world.setBlock(i + 5, j + 2, k + 9, Blocks.water, 0, 2);
            world.setBlock(i + 6, j + 2, k + 9, Blocks.water, 0, 2);
            world.setBlock(i + 7, j + 2, k + 9, Blocks.water, 0, 2);
            world.setBlock(i + 8, j + 2, k + 9, Blocks.water, 0, 2);
            world.setBlock(i + 9, j + 2, k + 9, Blocks.water, 0, 2);
            world.setBlock(i + 10, j + 2, k + 9, Blocks.water, 0, 2);
            world.setBlock(i + 11, j + 2, k + 9, Blocks.stonebrick, 0, 2);
            world.setBlock(i + 2, j + 2, k + 10, Blocks.stonebrick, 0, 2);
            world.setBlock(i + 3, j + 2, k + 10, Blocks.water, 0, 2);
            world.setBlock(i + 4, j + 2, k + 10, Blocks.water, 0, 2);
            world.setBlock(i + 5, j + 2, k + 10, Blocks.water, 0, 2);
            world.setBlock(i + 6, j + 2, k + 10, Blocks.water, 0, 2);
            world.setBlock(i + 7, j + 2, k + 10, Blocks.water, 0, 2);
            world.setBlock(i + 8, j + 2, k + 10, Blocks.water, 0, 2);
            world.setBlock(i + 9, j + 2, k + 10, Blocks.water, 0, 2);
            world.setBlock(i + 10, j + 2, k + 10, Blocks.water, 0, 2);
            world.setBlock(i + 11, j + 2, k + 10, Blocks.stonebrick, 0, 2);
            world.setBlock(i + 2, j + 2, k + 11, Blocks.cobblestone, 0, 2);
            world.setBlock(i + 3, j + 2, k + 11, Blocks.stonebrick, 2, 2);
            world.setBlock(i + 4, j + 2, k + 11, Blocks.stonebrick, 0, 2);
            world.setBlock(i + 5, j + 2, k + 11, Blocks.stonebrick, 1, 2);
            world.setBlock(i + 6, j + 2, k + 11, Blocks.stonebrick, 0, 2);
            world.setBlock(i + 7, j + 2, k + 11, Blocks.stonebrick, 1, 2);
            world.setBlock(i + 8, j + 2, k + 11, Blocks.stonebrick, 0, 2);
            world.setBlock(i + 9, j + 2, k + 11, Blocks.stonebrick, 2, 2);
            world.setBlock(i + 10, j + 2, k + 11, Blocks.stonebrick, 0, 2);
            world.setBlock(i + 11, j + 2, k + 11, Blocks.cobblestone, 0, 2);
            world.setBlock(i + 6, j + 3, k + 1, Blocks.vine, 1, 2);
            world.setBlock(i + 8, j + 3, k + 1, Blocks.vine, 1, 2);
            world.setBlock(i + 2, j + 3, k + 2, Blocks.cobblestone, 0, 2);
            world.setBlock(i + 3, j + 3, k + 2, Blocks.stonebrick, 0, 2);
            world.setBlock(i + 4, j + 3, k + 2, Blocks.stonebrick, 0, 2);
            world.setBlock(i + 5, j + 3, k + 2, Blocks.stonebrick, 0, 2);
            world.setBlock(i + 6, j + 3, k + 2, Blocks.stonebrick, 0, 2);
            world.setBlock(i + 7, j + 3, k + 2, Blocks.stonebrick, 0, 2);
            world.setBlock(i + 8, j + 3, k + 2, Blocks.stonebrick, 0, 2);
            world.setBlock(i + 9, j + 3, k + 2, Blocks.stonebrick, 2, 2);
            world.setBlock(i + 10, j + 3, k + 2, Blocks.stonebrick, 1, 2);
            world.setBlock(i + 11, j + 3, k + 2, Blocks.cobblestone, 0, 2);
            world.setBlock(i + 2, j + 3, k + 3, Blocks.stonebrick, 0, 2);
            world.setBlock(i + 3, j + 3, k + 3, Blocks.water, 0, 2);
            world.setBlock(i + 4, j + 3, k + 3, Blocks.water, 0, 2);
            world.setBlock(i + 5, j + 3, k + 3, Blocks.water, 0, 2);
            world.setBlock(i + 6, j + 3, k + 3, Blocks.water, 0, 2);
            world.setBlock(i + 7, j + 3, k + 3, Blocks.water, 0, 2);
            world.setBlock(i + 8, j + 3, k + 3, Blocks.water, 0, 2);
            world.setBlock(i + 9, j + 3, k + 3, Blocks.water, 0, 2);
            world.setBlock(i + 10, j + 3, k + 3, Blocks.water, 0, 2);
            world.setBlock(i + 11, j + 3, k + 3, Blocks.stonebrick, 0, 2);
            world.setBlock(i + 1, j + 3, k + 4, Blocks.vine, 8, 2);
            world.setBlock(i + 2, j + 3, k + 4, Blocks.stonebrick, 2, 2);
            world.setBlock(i + 3, j + 3, k + 4, Blocks.water, 0, 2);
            world.setBlock(i + 4, j + 3, k + 4, Blocks.water, 0, 2);
            world.setBlock(i + 5, j + 3, k + 4, Blocks.water, 0, 2);
            world.setBlock(i + 6, j + 3, k + 4, Blocks.water, 0, 2);
            world.setBlock(i + 7, j + 3, k + 4, Blocks.water, 0, 2);
            world.setBlock(i + 8, j + 3, k + 4, Blocks.water, 0, 2);
            world.setBlock(i + 9, j + 3, k + 4, Blocks.water, 0, 2);
            world.setBlock(i + 10, j + 3, k + 4, Blocks.water, 0, 2);
            world.setBlock(i + 11, j + 3, k + 4, Blocks.stonebrick, 1, 2);
            world.setBlock(i + 2, j + 3, k + 5, Blocks.stonebrick, 0, 2);
            world.setBlock(i + 3, j + 3, k + 5, Blocks.water, 0, 2);
            world.setBlock(i + 4, j + 3, k + 5, Blocks.water, 0, 2);
            world.setBlock(i + 5, j + 3, k + 5, Blocks.water, 0, 2);
            world.setBlock(i + 6, j + 3, k + 5, Blocks.water, 0, 2);
            world.setBlock(i + 7, j + 3, k + 5, Blocks.water, 0, 2);
            world.setBlock(i + 8, j + 3, k + 5, Blocks.water, 0, 2);
            world.setBlock(i + 9, j + 3, k + 5, Blocks.water, 0, 2);
            world.setBlock(i + 10, j + 3, k + 5, Blocks.water, 0, 2);
            world.setBlock(i + 11, j + 3, k + 5, Blocks.stonebrick, 2, 2);
            world.setBlock(i + 2, j + 3, k + 6, Blocks.stonebrick, 0, 2);
            world.setBlock(i + 3, j + 3, k + 6, Blocks.water, 0, 2);
            world.setBlock(i + 4, j + 3, k + 6, Blocks.water, 0, 2);
            world.setBlock(i + 5, j + 3, k + 6, Blocks.water, 0, 2);
            world.setBlock(i + 6, j + 3, k + 6, Blocks.water, 0, 2);
            world.setBlock(i + 7, j + 3, k + 6, Blocks.water, 0, 2);
            world.setBlock(i + 8, j + 3, k + 6, Blocks.water, 0, 2);
            world.setBlock(i + 9, j + 3, k + 6, Blocks.water, 0, 2);
            world.setBlock(i + 10, j + 3, k + 6, Blocks.water, 0, 2);
            world.setBlock(i + 11, j + 3, k + 6, Blocks.stonebrick, 0, 2);
            world.setBlock(i + 2, j + 3, k + 7, NovaCraftBlocks.cobbled_nullstone, 0, 2);
            world.setBlock(i + 3, j + 3, k + 7, Blocks.water, 0, 2);
            world.setBlock(i + 4, j + 3, k + 7, Blocks.water, 0, 2);
            world.setBlock(i + 5, j + 3, k + 7, Blocks.water, 0, 2);
            world.setBlock(i + 6, j + 3, k + 7, Blocks.water, 0, 2);
            world.setBlock(i + 7, j + 3, k + 7, Blocks.water, 0, 2);
            world.setBlock(i + 8, j + 3, k + 7, Blocks.water, 0, 2);
            world.setBlock(i + 9, j + 3, k + 7, Blocks.water, 0, 2);
            world.setBlock(i + 10, j + 3, k + 7, Blocks.water, 0, 2);
            world.setBlock(i + 11, j + 3, k + 7, Blocks.stonebrick, 0, 2);
            world.setBlock(i + 2, j + 3, k + 8, Blocks.stonebrick, 0, 2);
            world.setBlock(i + 3, j + 3, k + 8, Blocks.water, 0, 2);
            world.setBlock(i + 4, j + 3, k + 8, Blocks.water, 0, 2);
            world.setBlock(i + 5, j + 3, k + 8, Blocks.water, 0, 2);
            world.setBlock(i + 6, j + 3, k + 8, Blocks.water, 0, 2);
            world.setBlock(i + 7, j + 3, k + 8, Blocks.water, 0, 2);
            world.setBlock(i + 8, j + 3, k + 8, Blocks.water, 0, 2);
            world.setBlock(i + 9, j + 3, k + 8, Blocks.water, 0, 2);
            world.setBlock(i + 10, j + 3, k + 8, Blocks.water, 0, 2);
            world.setBlock(i + 11, j + 3, k + 8, Blocks.stonebrick, 0, 2);
            world.setBlock(i + 2, j + 3, k + 9, Blocks.stonebrick, 1, 2);
            world.setBlock(i + 3, j + 3, k + 9, Blocks.water, 0, 2);
            world.setBlock(i + 4, j + 3, k + 9, Blocks.water, 0, 2);
            world.setBlock(i + 5, j + 3, k + 9, Blocks.water, 0, 2);
            world.setBlock(i + 6, j + 3, k + 9, Blocks.water, 0, 2);
            world.setBlock(i + 7, j + 3, k + 9, Blocks.water, 0, 2);
            world.setBlock(i + 8, j + 3, k + 9, Blocks.water, 0, 2);
            world.setBlock(i + 9, j + 3, k + 9, Blocks.water, 0, 2);
            world.setBlock(i + 10, j + 3, k + 9, Blocks.water, 0, 2);
            world.setBlock(i + 11, j + 3, k + 9, Blocks.stonebrick, 1, 2);
            world.setBlock(i + 2, j + 3, k + 10, Blocks.stonebrick, 2, 2);
            world.setBlock(i + 3, j + 3, k + 10, Blocks.water, 0, 2);
            world.setBlock(i + 4, j + 3, k + 10, Blocks.water, 0, 2);
            world.setBlock(i + 5, j + 3, k + 10, Blocks.water, 0, 2);
            world.setBlock(i + 6, j + 3, k + 10, Blocks.water, 0, 2);
            world.setBlock(i + 7, j + 3, k + 10, Blocks.water, 0, 2);
            world.setBlock(i + 8, j + 3, k + 10, Blocks.water, 0, 2);
            world.setBlock(i + 9, j + 3, k + 10, Blocks.water, 0, 2);
            world.setBlock(i + 10, j + 3, k + 10, Blocks.water, 0, 2);
            world.setBlock(i + 11, j + 3, k + 10, Blocks.stonebrick, 0, 2);
            world.setBlock(i + 2, j + 3, k + 11, Blocks.cobblestone, 0, 2);
            world.setBlock(i + 3, j + 3, k + 11, Blocks.stonebrick, 0, 2);
            world.setBlock(i + 4, j + 3, k + 11, Blocks.stonebrick, 2, 2);
            world.setBlock(i + 5, j + 3, k + 11, Blocks.stonebrick, 0, 2);
            world.setBlock(i + 6, j + 3, k + 11, Blocks.stonebrick, 0, 2);
            world.setBlock(i + 7, j + 3, k + 11, Blocks.stonebrick, 2, 2);
            world.setBlock(i + 8, j + 3, k + 11, Blocks.stonebrick, 0, 2);
            world.setBlock(i + 9, j + 3, k + 11, Blocks.stonebrick, 0, 2);
            world.setBlock(i + 10, j + 3, k + 11, Blocks.stonebrick, 1, 2);
            world.setBlock(i + 11, j + 3, k + 11, Blocks.cobblestone, 0, 2);
            world.setBlock(i + 3, j + 4, k + 1, Blocks.vine, 1, 2);
            world.setBlock(i + 8, j + 4, k + 1, Blocks.vine, 1, 2);
            world.setBlock(i + 10, j + 4, k + 1, Blocks.vine, 1, 2);
            world.setBlock(i + 2, j + 4, k + 2, Blocks.cobblestone, 0, 2);
            world.setBlock(i + 3, j + 4, k + 2, Blocks.stonebrick, 0, 2);
            world.setBlock(i + 4, j + 4, k + 2, Blocks.stonebrick, 2, 2);
            world.setBlock(i + 5, j + 4, k + 2, Blocks.stonebrick, 0, 2);
            world.setBlock(i + 6, j + 4, k + 2, Blocks.stonebrick, 0, 2);
            world.setBlock(i + 7, j + 4, k + 2, Blocks.stonebrick, 1, 2);
            world.setBlock(i + 8, j + 4, k + 2, Blocks.stonebrick, 0, 2);
            world.setBlock(i + 9, j + 4, k + 2, Blocks.stonebrick, 0, 2);
            world.setBlock(i + 10, j + 4, k + 2, Blocks.stonebrick, 0, 2);
            world.setBlock(i + 11, j + 4, k + 2, Blocks.cobblestone, 0, 2);
            world.setBlock(i + 2, j + 4, k + 3, Blocks.stonebrick, 0, 2);
            world.setBlock(i + 3, j + 4, k + 3, Blocks.water, 0, 2);
            world.setBlock(i + 4, j + 4, k + 3, Blocks.water, 0, 2);
            world.setBlock(i + 5, j + 4, k + 3, Blocks.water, 0, 2);
            world.setBlock(i + 6, j + 4, k + 3, Blocks.water, 0, 2);
            world.setBlock(i + 7, j + 4, k + 3, Blocks.water, 0, 2);
            world.setBlock(i + 8, j + 4, k + 3, Blocks.water, 0, 2);
            world.setBlock(i + 9, j + 4, k + 3, Blocks.water, 0, 2);
            world.setBlock(i + 10, j + 4, k + 3, Blocks.water, 0, 2);
            world.setBlock(i + 11, j + 4, k + 3, Blocks.stonebrick, 0, 2);
            world.setBlock(i + 1, j + 4, k + 4, Blocks.vine, 8, 2);
            world.setBlock(i + 2, j + 4, k + 4, Blocks.stonebrick, 0, 2);
            world.setBlock(i + 3, j + 4, k + 4, Blocks.water, 0, 2);
            world.setBlock(i + 4, j + 4, k + 4, Blocks.water, 0, 2);
            world.setBlock(i + 5, j + 4, k + 4, Blocks.water, 0, 2);
            world.setBlock(i + 6, j + 4, k + 4, Blocks.water, 0, 2);
            world.setBlock(i + 7, j + 4, k + 4, Blocks.water, 0, 2);
            world.setBlock(i + 8, j + 4, k + 4, Blocks.water, 0, 2);
            world.setBlock(i + 9, j + 4, k + 4, Blocks.water, 0, 2);
            world.setBlock(i + 10, j + 4, k + 4, Blocks.water, 0, 2);
            world.setBlock(i + 11, j + 4, k + 4, Blocks.stonebrick, 2, 2);
            world.setBlock(i + 2, j + 4, k + 5, Blocks.stonebrick, 1, 2);
            world.setBlock(i + 3, j + 4, k + 5, Blocks.water, 0, 2);
            world.setBlock(i + 4, j + 4, k + 5, Blocks.water, 0, 2);
            world.setBlock(i + 5, j + 4, k + 5, Blocks.water, 0, 2);
            world.setBlock(i + 6, j + 4, k + 5, Blocks.water, 0, 2);
            world.setBlock(i + 7, j + 4, k + 5, Blocks.water, 0, 2);
            world.setBlock(i + 8, j + 4, k + 5, Blocks.water, 0, 2);
            world.setBlock(i + 9, j + 4, k + 5, Blocks.water, 0, 2);
            world.setBlock(i + 10, j + 4, k + 5, Blocks.water, 0, 2);
            world.setBlock(i + 11, j + 4, k + 5, Blocks.stonebrick, 0, 2);
            world.setBlock(i + 12, j + 4, k + 5, Blocks.vine, 2, 2);
            world.setBlock(i + 1, j + 4, k + 6, Blocks.vine, 8, 2);
            world.setBlock(i + 2, j + 4, k + 6, Blocks.stonebrick, 0, 2);
            world.setBlock(i + 3, j + 4, k + 6, Blocks.water, 0, 2);
            world.setBlock(i + 4, j + 4, k + 6, Blocks.water, 0, 2);
            world.setBlock(i + 5, j + 4, k + 6, Blocks.water, 0, 2);
            world.setBlock(i + 6, j + 4, k + 6, Blocks.water, 0, 2);
            world.setBlock(i + 7, j + 4, k + 6, Blocks.water, 0, 2);
            world.setBlock(i + 8, j + 4, k + 6, Blocks.water, 0, 2);
            world.setBlock(i + 9, j + 4, k + 6, Blocks.water, 0, 2);
            world.setBlock(i + 10, j + 4, k + 6, Blocks.water, 0, 2);
            world.setBlock(i + 11, j + 4, k + 6, Blocks.stonebrick, 0, 2);
            world.setBlock(i + 12, j + 4, k + 6, Blocks.vine, 2, 2);
            world.setBlock(i + 2, j + 4, k + 7, Blocks.stonebrick, 2, 2);
            world.setBlock(i + 3, j + 4, k + 7, Blocks.water, 0, 2);
            world.setBlock(i + 4, j + 4, k + 7, Blocks.water, 0, 2);
            world.setBlock(i + 5, j + 4, k + 7, Blocks.water, 0, 2);
            world.setBlock(i + 6, j + 4, k + 7, Blocks.water, 0, 2);
            world.setBlock(i + 7, j + 4, k + 7, Blocks.water, 0, 2);
            world.setBlock(i + 8, j + 4, k + 7, Blocks.water, 0, 2);
            world.setBlock(i + 9, j + 4, k + 7, Blocks.water, 0, 2);
            world.setBlock(i + 10, j + 4, k + 7, Blocks.water, 0, 2);
            world.setBlock(i + 11, j + 4, k + 7, Blocks.stonebrick, 0, 2);
            world.setBlock(i + 2, j + 4, k + 8, Blocks.stonebrick, 1, 2);
            world.setBlock(i + 3, j + 4, k + 8, Blocks.water, 0, 2);
            world.setBlock(i + 4, j + 4, k + 8, Blocks.water, 0, 2);
            world.setBlock(i + 5, j + 4, k + 8, Blocks.water, 0, 2);
            world.setBlock(i + 6, j + 4, k + 8, Blocks.water, 0, 2);
            world.setBlock(i + 7, j + 4, k + 8, Blocks.water, 0, 2);
            world.setBlock(i + 8, j + 4, k + 8, Blocks.water, 0, 2);
            world.setBlock(i + 9, j + 4, k + 8, Blocks.water, 0, 2);
            world.setBlock(i + 10, j + 4, k + 8, Blocks.water, 0, 2);
            world.setBlock(i + 11, j + 4, k + 8, Blocks.stonebrick, 1, 2);
            world.setBlock(i + 2, j + 4, k + 9, Blocks.stonebrick, 0, 2);
            world.setBlock(i + 3, j + 4, k + 9, Blocks.water, 0, 2);
            world.setBlock(i + 4, j + 4, k + 9, Blocks.water, 0, 2);
            world.setBlock(i + 5, j + 4, k + 9, Blocks.water, 0, 2);
            world.setBlock(i + 6, j + 4, k + 9, Blocks.water, 0, 2);
            world.setBlock(i + 7, j + 4, k + 9, Blocks.water, 0, 2);
            world.setBlock(i + 8, j + 4, k + 9, Blocks.water, 0, 2);
            world.setBlock(i + 9, j + 4, k + 9, Blocks.water, 0, 2);
            world.setBlock(i + 10, j + 4, k + 9, Blocks.water, 0, 2);
            world.setBlock(i + 11, j + 4, k + 9, Blocks.stonebrick, 0, 2);
            world.setBlock(i + 1, j + 4, k + 10, Blocks.vine, 8, 2);
            world.setBlock(i + 2, j + 4, k + 10, Blocks.stonebrick, 0, 2);
            world.setBlock(i + 3, j + 4, k + 10, Blocks.water, 0, 2);
            world.setBlock(i + 4, j + 4, k + 10, Blocks.water, 0, 2);
            world.setBlock(i + 5, j + 4, k + 10, Blocks.water, 0, 2);
            world.setBlock(i + 6, j + 4, k + 10, Blocks.water, 0, 2);
            world.setBlock(i + 7, j + 4, k + 10, Blocks.water, 0, 2);
            world.setBlock(i + 8, j + 4, k + 10, Blocks.water, 0, 2);
            world.setBlock(i + 9, j + 4, k + 10, Blocks.water, 0, 2);
            world.setBlock(i + 10, j + 4, k + 10, Blocks.water, 0, 2);
            world.setBlock(i + 11, j + 4, k + 10, Blocks.stonebrick, 0, 2);
            world.setBlock(i + 2, j + 4, k + 11, Blocks.cobblestone, 0, 2);
            world.setBlock(i + 3, j + 4, k + 11, Blocks.stonebrick, 2, 2);
            world.setBlock(i + 4, j + 4, k + 11, Blocks.stonebrick, 1, 2);
            world.setBlock(i + 5, j + 4, k + 11, Blocks.stonebrick, 0, 2);
            world.setBlock(i + 6, j + 4, k + 11, Blocks.stonebrick, 0, 2);
            world.setBlock(i + 7, j + 4, k + 11, Blocks.stonebrick, 0, 2);
            world.setBlock(i + 8, j + 4, k + 11, Blocks.stonebrick, 2, 2);
            world.setBlock(i + 9, j + 4, k + 11, Blocks.stonebrick, 0, 2);
            world.setBlock(i + 10, j + 4, k + 11, Blocks.stonebrick, 0, 2);
            world.setBlock(i + 11, j + 4, k + 11, Blocks.cobblestone, 0, 2);
            world.setBlock(i + 3, j + 5, k + 1, Blocks.vine, 1, 2);
            world.setBlock(i + 10, j + 5, k + 1, Blocks.vine, 1, 2);
            world.setBlock(i + 2, j + 5, k + 2, Blocks.cobblestone, 0, 2);
            world.setBlock(i + 3, j + 5, k + 2, placeStoneBricks(random), 0, 2);
            world.setBlock(i + 4, j + 5, k + 2, placeStoneBricks(random), 0, 2);
            world.setBlock(i + 5, j + 5, k + 2, Blocks.stonebrick, 1, 2);
            world.setBlock(i + 6, j + 5, k + 2, Blocks.stonebrick, 1, 2);
            world.setBlock(i + 7, j + 5, k + 2, Blocks.stonebrick, 1, 2);
            world.setBlock(i + 8, j + 5, k + 2, placeStoneBricks(random), 0, 2);
            world.setBlock(i + 9, j + 5, k + 2, Blocks.stonebrick, 2, 2);
            world.setBlock(i + 10, j + 5, k + 2, placeStoneBricks(random), 0, 2);
            world.setBlock(i + 11, j + 5, k + 2, Blocks.cobblestone, 0, 2);
            world.setBlock(i + 2, j + 5, k + 3, Blocks.stonebrick, 1, 2);
            world.setBlock(i + 3, j + 5, k + 3, Blocks.air, 0, 2);
            world.setBlock(i + 4, j + 5, k + 3, Blocks.air, 0, 2);
            world.setBlock(i + 5, j + 5, k + 3, Blocks.air, 0, 2);
            world.setBlock(i + 6, j + 5, k + 3, Blocks.waterlily, 0, 2);
            world.setBlock(i + 7, j + 5, k + 3, Blocks.air, 0, 2);
            world.setBlock(i + 8, j + 5, k + 3, Blocks.air, 0, 2);
            world.setBlock(i + 9, j + 5, k + 3, Blocks.air, 0, 2);
            world.setBlock(i + 10, j + 5, k + 3, Blocks.air, 0, 2);
            world.setBlock(i + 11, j + 5, k + 3, placeStoneBricks(random), 0, 2);
            world.setBlock(i + 12, j + 5, k + 3, Blocks.vine, 2, 2);
            world.setBlock(i + 1, j + 5, k + 4, Blocks.vine, 8, 2);
            world.setBlock(i + 2, j + 5, k + 4, placeStoneBricks(random), 0, 2);
            world.setBlock(i + 3, j + 5, k + 4, Blocks.air, 0, 2);
            world.setBlock(i + 4, j + 5, k + 4, Blocks.air, 0, 2);
            world.setBlock(i + 5, j + 5, k + 4, Blocks.waterlily, 0, 2);
            world.setBlock(i + 6, j + 5, k + 4, Blocks.air, 0, 2);
            world.setBlock(i + 7, j + 5, k + 4, Blocks.waterlily, 0, 2);
            world.setBlock(i + 8, j + 5, k + 4, Blocks.air, 0, 2);
            world.setBlock(i + 9, j + 5, k + 4, Blocks.waterlily, 0, 2);
            world.setBlock(i + 10, j + 5, k + 4, Blocks.air, 0, 2);
            world.setBlock(i + 11, j + 5, k + 4, placeStoneBricks(random), 0, 2);
            world.setBlock(i + 2, j + 5, k + 5, placeStoneBricks(random), 0, 2);
            world.setBlock(i + 3, j + 5, k + 5, Blocks.air, 0, 2);
            world.setBlock(i + 4, j + 5, k + 5, Blocks.waterlily, 0, 2);
            world.setBlock(i + 5, j + 5, k + 5, Blocks.air, 0, 2);
            world.setBlock(i + 6, j + 5, k + 5, Blocks.waterlily, 0, 2);
            world.setBlock(i + 7, j + 5, k + 5, Blocks.air, 0, 2);
            world.setBlock(i + 8, j + 5, k + 5, Blocks.air, 0, 2);
            world.setBlock(i + 9, j + 5, k + 5, Blocks.air, 0, 2);
            world.setBlock(i + 10, j + 5, k + 5, Blocks.air, 0, 2);
            world.setBlock(i + 11, j + 5, k + 5, Blocks.stonebrick, 1, 2);
            world.setBlock(i + 1, j + 5, k + 6, Blocks.vine, 8, 2);
            world.setBlock(i + 2, j + 5, k + 6, placeStoneBricks(random), 0, 2);
            world.setBlock(i + 3, j + 5, k + 6, Blocks.air, 0, 2);
            world.setBlock(i + 4, j + 5, k + 6, Blocks.air, 0, 2);
            world.setBlock(i + 5, j + 5, k + 6, Blocks.air, 0, 2);
            world.setBlock(i + 6, j + 5, k + 6, Blocks.air, 0, 2);
            world.setBlock(i + 7, j + 5, k + 6, Blocks.air, 0, 2);
            world.setBlock(i + 8, j + 5, k + 6, Blocks.waterlily, 0, 2);
            world.setBlock(i + 9, j + 5, k + 6, Blocks.air, 0, 2);
            world.setBlock(i + 10, j + 5, k + 6, Blocks.waterlily, 0, 2);
            world.setBlock(i + 11, j + 5, k + 6, placeStoneBricks(random), 0, 2);
            world.setBlock(i + 12, j + 5, k + 6, Blocks.vine, 2, 2);
            world.setBlock(i + 2, j + 5, k + 7, placeStoneBricks(random), 0, 2);
            world.setBlock(i + 3, j + 5, k + 7, Blocks.air, 0, 2);
            world.setBlock(i + 4, j + 5, k + 7, Blocks.waterlily, 0, 2);
            world.setBlock(i + 5, j + 5, k + 7, Blocks.waterlily, 0, 2);
            world.setBlock(i + 6, j + 5, k + 7, Blocks.air, 0, 2);
            world.setBlock(i + 7, j + 5, k + 7, Blocks.waterlily, 0, 2);
            world.setBlock(i + 8, j + 5, k + 7, Blocks.air, 0, 2);
            world.setBlock(i + 9, j + 5, k + 7, Blocks.air, 0, 2);
            world.setBlock(i + 10, j + 5, k + 7, Blocks.air, 0, 2);
            world.setBlock(i + 11, j + 5, k + 7, Blocks.stonebrick, 2, 2);
            world.setBlock(i + 2, j + 5, k + 8, Blocks.stonebrick, 2, 2);
            world.setBlock(i + 3, j + 5, k + 8, Blocks.air, 0, 2);
            world.setBlock(i + 4, j + 5, k + 8, Blocks.air, 0, 2);
            world.setBlock(i + 5, j + 5, k + 8, Blocks.air, 0, 2);
            world.setBlock(i + 6, j + 5, k + 8, Blocks.air, 0, 2);
            world.setBlock(i + 7, j + 5, k + 8, Blocks.air, 0, 2);
            world.setBlock(i + 8, j + 5, k + 8, Blocks.air, 0, 2);
            world.setBlock(i + 9, j + 5, k + 8, Blocks.air, 0, 2);
            world.setBlock(i + 10, j + 5, k + 8, Blocks.waterlily, 0, 2);
            world.setBlock(i + 11, j + 5, k + 8, placeStoneBricks(random), 0, 2);
            world.setBlock(i + 12, j + 5, k + 8, Blocks.vine, 2, 2);
            world.setBlock(i + 2, j + 5, k + 9, placeStoneBricks(random), 0, 2);
            world.setBlock(i + 3, j + 5, k + 9, Blocks.waterlily, 0, 2);
            world.setBlock(i + 4, j + 5, k + 9, Blocks.air, 0, 2);
            world.setBlock(i + 5, j + 5, k + 9, Blocks.air, 0, 2);
            world.setBlock(i + 6, j + 5, k + 9, Blocks.waterlily, 0, 2);
            world.setBlock(i + 7, j + 5, k + 9, Blocks.air, 0, 2);
            world.setBlock(i + 8, j + 5, k + 9, Blocks.air, 0, 2);
            world.setBlock(i + 9, j + 5, k + 9, Blocks.air, 0, 2);
            world.setBlock(i + 10, j + 5, k + 9, Blocks.air, 0, 2);
            world.setBlock(i + 11, j + 5, k + 9, Blocks.stonebrick, 2, 2);
            world.setBlock(i + 12, j + 5, k + 9, Blocks.vine, 2, 2);
            world.setBlock(i + 1, j + 5, k + 10, Blocks.vine, 8, 2);
            world.setBlock(i + 2, j + 5, k + 10, placeStoneBricks(random), 0, 2);
            world.setBlock(i + 3, j + 5, k + 10, Blocks.air, 0, 2);
            world.setBlock(i + 4, j + 5, k + 10, Blocks.air, 0, 2);
            world.setBlock(i + 5, j + 5, k + 10, Blocks.air, 0, 2);
            world.setBlock(i + 6, j + 5, k + 10, Blocks.air, 0, 2);
            world.setBlock(i + 7, j + 5, k + 10, Blocks.air, 0, 2);
            world.setBlock(i + 8, j + 5, k + 10, Blocks.air, 0, 2);
            world.setBlock(i + 9, j + 5, k + 10, Blocks.waterlily, 0, 2);
            world.setBlock(i + 10, j + 5, k + 10, Blocks.air, 0, 2);
            world.setBlock(i + 11, j + 5, k + 10, placeStoneBricks(random), 0, 2);
            world.setBlock(i + 2, j + 5, k + 11, Blocks.cobblestone, 0, 2);
            world.setBlock(i + 3, j + 5, k + 11, placeStoneBricks(random), 0, 2);
            world.setBlock(i + 4, j + 5, k + 11, placeStoneBricks(random), 0, 2);
            world.setBlock(i + 5, j + 5, k + 11, placeStoneBricks(random), 0, 2);
            world.setBlock(i + 6, j + 5, k + 11, placeStoneBricks(random), 0, 2);
            world.setBlock(i + 7, j + 5, k + 11, placeStoneBricks(random), 0, 2);
            world.setBlock(i + 8, j + 5, k + 11, placeStoneBricks(random), 0, 2);
            world.setBlock(i + 9, j + 5, k + 11, Blocks.stonebrick, 2, 2);
            world.setBlock(i + 10, j + 5, k + 11, placeStoneBricks(random), 0, 2);
            world.setBlock(i + 11, j + 5, k + 11, Blocks.cobblestone, 0, 2);
            world.setBlock(i + 5, j + 5, k + 12, Blocks.vine, 4, 2);
            world.setBlock(i + 6, j + 5, k + 12, Blocks.vine, 4, 2);
            world.setBlock(i + 2, j + 6, k + 1, Blocks.vine, 1, 2);
            world.setBlock(i + 7, j + 6, k + 1, Blocks.vine, 1, 2);
            world.setBlock(i + 10, j + 6, k + 1, Blocks.vine, 1, 2);
            world.setBlock(i + 11, j + 6, k + 1, Blocks.vine, 1, 2);
            world.setBlock(i + 2, j + 6, k + 2, Blocks.cobblestone, 0, 2);
            world.setBlock(i + 3, j + 6, k + 2, placeStoneBricks(random), 0, 2);
            world.setBlock(i + 4, j + 6, k + 2, placeStoneBricks(random), 0, 2);
            world.setBlock(i + 5, j + 6, k + 2, placeStoneBricks(random), 0, 2);
            world.setBlock(i + 6, j + 6, k + 2, placeStoneBricks(random), 0, 2);
            world.setBlock(i + 7, j + 6, k + 2, placeStoneBricks(random), 0, 2);
            world.setBlock(i + 8, j + 6, k + 2, placeStoneBricks(random), 0, 2);
            world.setBlock(i + 9, j + 6, k + 2, placeStoneBricks(random), 0, 2);
            world.setBlock(i + 10, j + 6, k + 2, Blocks.stonebrick, 1, 2);
            world.setBlock(i + 11, j + 6, k + 2, Blocks.cobblestone, 0, 2);
            world.setBlock(i + 1, j + 6, k + 3, Blocks.vine, 8, 2);
            world.setBlock(i + 2, j + 6, k + 3, placeStoneBricks(random), 0, 2);
            world.setBlock(i + 3, j + 6, k + 3, Blocks.air, 0, 2);
            world.setBlock(i + 4, j + 6, k + 3, Blocks.air, 0, 2);
            world.setBlock(i + 5, j + 6, k + 3, Blocks.air, 0, 2);
            world.setBlock(i + 6, j + 6, k + 3, Blocks.vine, 4, 2);
            world.setBlock(i + 7, j + 6, k + 3, Blocks.air, 0, 2);
            world.setBlock(i + 8, j + 6, k + 3, Blocks.air, 0, 2);
            world.setBlock(i + 9, j + 6, k + 3, Blocks.air, 0, 2);
            world.setBlock(i + 10, j + 6, k + 3, Blocks.air, 0, 2);
            world.setBlock(i + 11, j + 6, k + 3, placeStoneBricks(random), 0, 2);
            world.setBlock(i + 12, j + 6, k + 3, Blocks.vine, 2, 2);
            world.setBlock(i + 2, j + 6, k + 4, NovaCraftBlocks.cobbled_nullstone, 0, 2);
            world.setBlock(i + 3, j + 6, k + 4, Blocks.air, 0, 2);
            world.setBlock(i + 4, j + 6, k + 4, Blocks.air, 0, 2);
            world.setBlock(i + 5, j + 6, k + 4, Blocks.air, 0, 2);
            world.setBlock(i + 6, j + 6, k + 4, Blocks.air, 0, 2);
            world.setBlock(i + 7, j + 6, k + 4, Blocks.air, 0, 2);
            world.setBlock(i + 8, j + 6, k + 4, Blocks.air, 0, 2);
            world.setBlock(i + 9, j + 6, k + 4, Blocks.air, 0, 2);
            world.setBlock(i + 10, j + 6, k + 4, Blocks.air, 0, 2);
            world.setBlock(i + 11, j + 6, k + 4, placeStoneBricks(random), 0, 2);
            world.setBlock(i + 2, j + 6, k + 5, NovaCraftBlocks.cobbled_nullstone, 0, 2);
            world.setBlock(i + 3, j + 6, k + 5, Blocks.air, 0, 2);
            world.setBlock(i + 4, j + 6, k + 5, Blocks.air, 0, 2);
            world.setBlock(i + 5, j + 6, k + 5, Blocks.air, 0, 2);
            world.setBlock(i + 6, j + 6, k + 5, Blocks.air, 0, 2);
            world.setBlock(i + 7, j + 6, k + 5, Blocks.air, 0, 2);
            world.setBlock(i + 8, j + 6, k + 5, Blocks.air, 0, 2);
            world.setBlock(i + 9, j + 6, k + 5, Blocks.air, 0, 2);
            world.setBlock(i + 10, j + 6, k + 5, Blocks.air, 0, 2);
            world.setBlock(i + 11, j + 6, k + 5, placeStoneBricks(random), 0, 2);
            world.setBlock(i + 1, j + 6, k + 6, Blocks.vine, 8, 2);
            world.setBlock(i + 2, j + 6, k + 6, placeStoneBricks(random), 0, 2);
            world.setBlock(i + 3, j + 6, k + 6, Blocks.air, 0, 2);
            world.setBlock(i + 4, j + 6, k + 6, Blocks.air, 0, 2);
            world.setBlock(i + 5, j + 6, k + 6, Blocks.air, 0, 2);
            world.setBlock(i + 6, j + 6, k + 6, Blocks.air, 0, 2);
            world.setBlock(i + 7, j + 6, k + 6, Blocks.air, 0, 2);
            world.setBlock(i + 8, j + 6, k + 6, Blocks.air, 0, 2);
            world.setBlock(i + 9, j + 6, k + 6, Blocks.air, 0, 2);
            world.setBlock(i + 10, j + 6, k + 6, Blocks.air, 0, 2);
            world.setBlock(i + 11, j + 6, k + 6, placeStoneBricks(random), 0, 2);
            world.setBlock(i + 12, j + 6, k + 6, Blocks.vine, 2, 2);
            world.setBlock(i + 1, j + 6, k + 7, Blocks.vine, 8, 2);
            world.setBlock(i + 2, j + 6, k + 7, placeStoneBricks(random), 0, 2);
            world.setBlock(i + 3, j + 6, k + 7, Blocks.air, 0, 2);
            world.setBlock(i + 4, j + 6, k + 7, Blocks.air, 0, 2);
            world.setBlock(i + 5, j + 6, k + 7, Blocks.air, 0, 2);
            world.setBlock(i + 6, j + 6, k + 7, Blocks.air, 0, 2);
            world.setBlock(i + 7, j + 6, k + 7, Blocks.air, 0, 2);
            world.setBlock(i + 8, j + 6, k + 7, Blocks.air, 0, 2);
            world.setBlock(i + 9, j + 6, k + 7, Blocks.air, 0, 2);
            world.setBlock(i + 10, j + 6, k + 7, Blocks.air, 0, 2);
            world.setBlock(i + 11, j + 6, k + 7, Blocks.stonebrick, 2, 2);
            world.setBlock(i + 2, j + 6, k + 8, NovaCraftBlocks.cobbled_nullstone, 0, 2);
            world.setBlock(i + 3, j + 6, k + 8, Blocks.air, 0, 2);
            world.setBlock(i + 4, j + 6, k + 8, Blocks.air, 0, 2);
            world.setBlock(i + 5, j + 6, k + 8, Blocks.air, 0, 2);
            world.setBlock(i + 6, j + 6, k + 8, Blocks.air, 0, 2);
            world.setBlock(i + 7, j + 6, k + 8, Blocks.air, 0, 2);
            world.setBlock(i + 8, j + 6, k + 8, Blocks.air, 0, 2);
            world.setBlock(i + 9, j + 6, k + 8, Blocks.air, 0, 2);
            world.setBlock(i + 10, j + 6, k + 8, Blocks.air, 0, 2);
            world.setBlock(i + 11, j + 6, k + 8, placeStoneBricks(random), 0, 2);
            world.setBlock(i + 12, j + 6, k + 8, Blocks.vine, 2, 2);
            world.setBlock(i + 2, j + 6, k + 9, NovaCraftBlocks.cobbled_nullstone, 0, 2);
            world.setBlock(i + 3, j + 6, k + 9, Blocks.air, 0, 2);
            world.setBlock(i + 4, j + 6, k + 9, Blocks.air, 0, 2);
            world.setBlock(i + 5, j + 6, k + 9, Blocks.air, 0, 2);
            world.setBlock(i + 6, j + 6, k + 9, Blocks.air, 0, 2);
            world.setBlock(i + 7, j + 6, k + 9, Blocks.air, 0, 2);
            world.setBlock(i + 8, j + 6, k + 9, Blocks.air, 0, 2);
            world.setBlock(i + 9, j + 6, k + 9, Blocks.air, 0, 2);
            world.setBlock(i + 10, j + 6, k + 9, Blocks.air, 0, 2);
            world.setBlock(i + 11, j + 6, k + 9, placeStoneBricks(random), 0, 2);
            world.setBlock(i + 2, j + 6, k + 10, placeStoneBricks(random), 0, 2);
            world.setBlock(i + 3, j + 6, k + 10, Blocks.air, 0, 2);
            world.setBlock(i + 4, j + 6, k + 10, Blocks.air, 0, 2);
            world.setBlock(i + 5, j + 6, k + 10, Blocks.air, 0, 2);
            world.setBlock(i + 6, j + 6, k + 10, Blocks.air, 0, 2);
            world.setBlock(i + 7, j + 6, k + 10, Blocks.air, 0, 2);
            world.setBlock(i + 8, j + 6, k + 10, Blocks.air, 0, 2);
            world.setBlock(i + 9, j + 6, k + 10, Blocks.air, 0, 2);
            world.setBlock(i + 10, j + 6, k + 10, Blocks.air, 0, 2);
            world.setBlock(i + 11, j + 6, k + 10, Blocks.stonebrick, 1, 2);
            world.setBlock(i + 1, j + 6, k + 11, Blocks.vine, 8, 2);
            world.setBlock(i + 2, j + 6, k + 11, Blocks.cobblestone, 0, 2);
            world.setBlock(i + 3, j + 6, k + 11, Blocks.stonebrick, 2, 2);
            world.setBlock(i + 4, j + 6, k + 11, placeStoneBricks(random), 0, 2);
            world.setBlock(i + 5, j + 6, k + 11, placeStoneBricks(random), 0, 2);
            world.setBlock(i + 6, j + 6, k + 11, placeStoneBricks(random), 0, 2);
            world.setBlock(i + 7, j + 6, k + 11, Blocks.stonebrick, 1, 2);
            world.setBlock(i + 8, j + 6, k + 11, placeStoneBricks(random), 0, 2);
            world.setBlock(i + 9, j + 6, k + 11, placeStoneBricks(random), 0, 2);
            world.setBlock(i + 10, j + 6, k + 11, placeStoneBricks(random), 0, 2);
            world.setBlock(i + 11, j + 6, k + 11, Blocks.cobblestone, 0, 2);
            world.setBlock(i + 2, j + 6, k + 12, Blocks.vine, 4, 2);
            world.setBlock(i + 5, j + 6, k + 12, Blocks.vine, 4, 2);
            world.setBlock(i + 4, j + 7, k + 1, Blocks.vine, 1, 2);
            world.setBlock(i + 5, j + 7, k + 1, Blocks.vine, 1, 2);
            world.setBlock(i + 10, j + 7, k + 1, Blocks.vine, 1, 2);
            world.setBlock(i + 2, j + 7, k + 2, Blocks.cobblestone, 0, 2);
            world.setBlock(i + 3, j + 7, k + 2, Blocks.stonebrick, 1, 2);
            world.setBlock(i + 4, j + 7, k + 2, placeStoneBricks(random), 0, 2);
            world.setBlock(i + 5, j + 7, k + 2, placeStoneBricks(random), 0, 2);
            world.setBlock(i + 6, j + 7, k + 2, Blocks.stonebrick, 2, 2);
            world.setBlock(i + 7, j + 7, k + 2, placeStoneBricks(random), 0, 2);
            world.setBlock(i + 8, j + 7, k + 2, Blocks.stonebrick, 1, 2);
            world.setBlock(i + 9, j + 7, k + 2, placeStoneBricks(random), 0, 2);
            world.setBlock(i + 10, j + 7, k + 2, placeStoneBricks(random), 0, 2);
            world.setBlock(i + 11, j + 7, k + 2, Blocks.cobblestone, 0, 2);
            world.setBlock(i + 1, j + 7, k + 3, Blocks.vine, 8, 2);
            world.setBlock(i + 2, j + 7, k + 3, placeStoneBricks(random), 0, 2);
            world.setBlock(i + 3, j + 7, k + 3, Blocks.air, 0, 2);
            world.setBlock(i + 4, j + 7, k + 3, Blocks.air, 0, 2);
            world.setBlock(i + 5, j + 7, k + 3, Blocks.air, 0, 2);
            world.setBlock(i + 6, j + 7, k + 3, Blocks.air, 0, 2);
            world.setBlock(i + 7, j + 7, k + 3, Blocks.air, 0, 2);
            world.setBlock(i + 8, j + 7, k + 3, Blocks.air, 0, 2);
            world.setBlock(i + 9, j + 7, k + 3, Blocks.air, 0, 2);
            world.setBlock(i + 10, j + 7, k + 3, Blocks.air, 0, 2);
            world.setBlock(i + 11, j + 7, k + 3, placeStoneBricks(random), 0, 2);
            world.setBlock(i + 2, j + 7, k + 4, NovaCraftBlocks.cobbled_nullstone, 0, 2);
            world.setBlock(i + 3, j + 7, k + 4, Blocks.air, 0, 2);
            world.setBlock(i + 4, j + 7, k + 4, Blocks.air, 0, 2);
            world.setBlock(i + 5, j + 7, k + 4, Blocks.air, 0, 2);
            world.setBlock(i + 6, j + 7, k + 4, Blocks.air, 0, 2);
            world.setBlock(i + 7, j + 7, k + 4, Blocks.air, 0, 2);
            world.setBlock(i + 8, j + 7, k + 4, Blocks.air, 0, 2);
            world.setBlock(i + 9, j + 7, k + 4, Blocks.air, 0, 2);
            world.setBlock(i + 10, j + 7, k + 4, Blocks.air, 0, 2);
            world.setBlock(i + 11, j + 7, k + 4, Blocks.stonebrick, 2, 2);
            world.setBlock(i + 2, j + 7, k + 5, NovaCraftBlocks.cobbled_nullstone, 0, 2);
            world.setBlock(i + 3, j + 7, k + 5, Blocks.air, 0, 2);
            world.setBlock(i + 4, j + 7, k + 5, Blocks.air, 0, 2);
            world.setBlock(i + 5, j + 7, k + 5, Blocks.air, 0, 2);
            world.setBlock(i + 6, j + 7, k + 5, Blocks.air, 0, 2);
            world.setBlock(i + 7, j + 7, k + 5, Blocks.air, 0, 2);
            world.setBlock(i + 8, j + 7, k + 5, Blocks.air, 0, 2);
            world.setBlock(i + 9, j + 7, k + 5, Blocks.air, 0, 2);
            world.setBlock(i + 10, j + 7, k + 5, Blocks.air, 0, 2);
            world.setBlock(i + 11, j + 7, k + 5, placeStoneBricks(random), 0, 2);
            world.setBlock(i + 2, j + 7, k + 6, placeStoneBricks(random), 0, 2);
            world.setBlock(i + 3, j + 7, k + 6, Blocks.vine, 2, 2);
            world.setBlock(i + 4, j + 7, k + 6, Blocks.air, 0, 2);
            world.setBlock(i + 5, j + 7, k + 6, Blocks.air, 0, 2);
            world.setBlock(i + 6, j + 7, k + 6, Blocks.air, 0, 2);
            world.setBlock(i + 7, j + 7, k + 6, Blocks.air, 0, 2);
            world.setBlock(i + 8, j + 7, k + 6, Blocks.air, 0, 2);
            world.setBlock(i + 9, j + 7, k + 6, Blocks.air, 0, 2);
            world.setBlock(i + 10, j + 7, k + 6, Blocks.vine, 8, 2);
            world.setBlock(i + 11, j + 7, k + 6, placeStoneBricks(random), 0, 2);
            world.setBlock(i + 12, j + 7, k + 6, Blocks.vine, 2, 2);
            world.setBlock(i + 2, j + 7, k + 7, placeStoneBricks(random), 0, 2);
            world.setBlock(i + 3, j + 7, k + 7, Blocks.air, 0, 2);
            world.setBlock(i + 4, j + 7, k + 7, Blocks.air, 0, 2);
            world.setBlock(i + 5, j + 7, k + 7, Blocks.air, 0, 2);
            world.setBlock(i + 6, j + 7, k + 7, Blocks.air, 0, 2);
            world.setBlock(i + 7, j + 7, k + 7, Blocks.air, 0, 2);
            world.setBlock(i + 8, j + 7, k + 7, Blocks.air, 0, 2);
            world.setBlock(i + 9, j + 7, k + 7, Blocks.air, 0, 2);
            world.setBlock(i + 10, j + 7, k + 7, Blocks.air, 0, 2);
            world.setBlock(i + 11, j + 7, k + 7, placeStoneBricks(random), 0, 2);
            world.setBlock(i + 2, j + 7, k + 8, NovaCraftBlocks.cobbled_nullstone, 0, 2);
            world.setBlock(i + 3, j + 7, k + 8, Blocks.air, 0, 2);
            world.setBlock(i + 4, j + 7, k + 8, Blocks.air, 0, 2);
            world.setBlock(i + 5, j + 7, k + 8, Blocks.air, 0, 2);
            world.setBlock(i + 6, j + 7, k + 8, Blocks.air, 0, 2);
            world.setBlock(i + 7, j + 7, k + 8, Blocks.air, 0, 2);
            world.setBlock(i + 8, j + 7, k + 8, Blocks.air, 0, 2);
            world.setBlock(i + 9, j + 7, k + 8, Blocks.air, 0, 2);
            world.setBlock(i + 10, j + 7, k + 8, Blocks.air, 0, 2);
            world.setBlock(i + 11, j + 7, k + 8, Blocks.stonebrick, 1, 2);
            world.setBlock(i + 2, j + 7, k + 9, NovaCraftBlocks.cobbled_nullstone, 0, 2);
            world.setBlock(i + 3, j + 7, k + 9, Blocks.air, 0, 2);
            world.setBlock(i + 4, j + 7, k + 9, Blocks.air, 0, 2);
            world.setBlock(i + 5, j + 7, k + 9, Blocks.air, 0, 2);
            world.setBlock(i + 6, j + 7, k + 9, Blocks.air, 0, 2);
            world.setBlock(i + 7, j + 7, k + 9, Blocks.air, 0, 2);
            world.setBlock(i + 8, j + 7, k + 9, Blocks.air, 0, 2);
            world.setBlock(i + 9, j + 7, k + 9, Blocks.air, 0, 2);
            world.setBlock(i + 10, j + 7, k + 9, Blocks.air, 0, 2);
            world.setBlock(i + 11, j + 7, k + 9, placeStoneBricks(random), 0, 2);
            world.setBlock(i + 2, j + 7, k + 10, placeStoneBricks(random), 0, 2);
            world.setBlock(i + 3, j + 7, k + 10, Blocks.air, 0, 2);
            world.setBlock(i + 4, j + 7, k + 10, Blocks.air, 0, 2);
            world.setBlock(i + 5, j + 7, k + 10, Blocks.air, 0, 2);
            world.setBlock(i + 6, j + 7, k + 10, Blocks.air, 0, 2);
            world.setBlock(i + 7, j + 7, k + 10, Blocks.air, 0, 2);
            world.setBlock(i + 8, j + 7, k + 10, Blocks.air, 0, 2);
            world.setBlock(i + 9, j + 7, k + 10, Blocks.air, 0, 2);
            world.setBlock(i + 10, j + 7, k + 10, Blocks.air, 0, 2);
            world.setBlock(i + 11, j + 7, k + 10, Blocks.stonebrick, 2, 2);
            world.setBlock(i + 2, j + 7, k + 11, Blocks.cobblestone, 0, 2);
            world.setBlock(i + 3, j + 7, k + 11, placeStoneBricks(random), 0, 2);
            world.setBlock(i + 4, j + 7, k + 11, Blocks.stonebrick, 1, 2);
            world.setBlock(i + 5, j + 7, k + 11, placeStoneBricks(random), 0, 2);
            world.setBlock(i + 6, j + 7, k + 11, placeStoneBricks(random), 0, 2);
            world.setBlock(i + 7, j + 7, k + 11, placeStoneBricks(random), 0, 2);
            world.setBlock(i + 8, j + 7, k + 11, placeStoneBricks(random), 0, 2);
            world.setBlock(i + 9, j + 7, k + 11, placeStoneBricks(random), 0, 2);
            world.setBlock(i + 10, j + 7, k + 11, Blocks.stonebrick, 2, 2);
            world.setBlock(i + 11, j + 7, k + 11, Blocks.cobblestone, 0, 2);
            world.setBlock(i + 5, j + 7, k + 12, Blocks.vine, 4, 2);
            world.setBlock(i + 8, j + 7, k + 12, Blocks.vine, 4, 2);
            world.setBlock(i + 3, j + 8, k + 1, Blocks.vine, 1, 2);
            world.setBlock(i + 5, j + 8, k + 1, Blocks.vine, 1, 2);
            world.setBlock(i + 2, j + 8, k + 2, Blocks.cobblestone, 0, 2);
            world.setBlock(i + 3, j + 8, k + 2, placeStoneBricks(random), 0, 2);
            world.setBlock(i + 4, j + 8, k + 2, placeStoneBricks(random), 0, 2);
            world.setBlock(i + 5, j + 8, k + 2, placeStoneBricks(random), 0, 2);
            world.setBlock(i + 6, j + 8, k + 2, placeStoneBricks(random), 0, 2);
            world.setBlock(i + 7, j + 8, k + 2, Blocks.stonebrick, 1, 2);
            world.setBlock(i + 8, j + 8, k + 2, placeStoneBricks(random), 0, 2);
            world.setBlock(i + 9, j + 8, k + 2, Blocks.stonebrick, 2, 2);
            world.setBlock(i + 10, j + 8, k + 2, placeStoneBricks(random), 0, 2);
            world.setBlock(i + 11, j + 8, k + 2, Blocks.cobblestone, 0, 2);
            world.setBlock(i + 1, j + 8, k + 3, Blocks.vine, 8, 2);
            world.setBlock(i + 2, j + 8, k + 3, placeStoneBricks(random), 0, 2);
            world.setBlock(i + 3, j + 8, k + 3, Blocks.air, 0, 2);
            world.setBlock(i + 4, j + 8, k + 3, Blocks.air, 0, 2);
            world.setBlock(i + 5, j + 8, k + 3, Blocks.air, 0, 2);
            world.setBlock(i + 6, j + 8, k + 3, Blocks.air, 0, 2);
            world.setBlock(i + 7, j + 8, k + 3, Blocks.air, 0, 2);
            world.setBlock(i + 8, j + 8, k + 3, Blocks.air, 0, 2);
            world.setBlock(i + 9, j + 8, k + 3, Blocks.air, 0, 2);
            world.setBlock(i + 10, j + 8, k + 3, Blocks.air, 0, 2);
            world.setBlock(i + 11, j + 8, k + 3, placeStoneBricks(random), 0, 2);
            world.setBlock(i + 2, j + 8, k + 4, placeStoneBricks(random), 0, 2);
            world.setBlock(i + 3, j + 8, k + 4, Blocks.air, 0, 2);
            world.setBlock(i + 4, j + 8, k + 4, Blocks.air, 0, 2);
            world.setBlock(i + 5, j + 8, k + 4, Blocks.air, 0, 2);
            world.setBlock(i + 6, j + 8, k + 4, Blocks.air, 0, 2);
            world.setBlock(i + 7, j + 8, k + 4, Blocks.air, 0, 2);
            world.setBlock(i + 8, j + 8, k + 4, Blocks.air, 0, 2);
            world.setBlock(i + 9, j + 8, k + 4, Blocks.air, 0, 2);
            world.setBlock(i + 10, j + 8, k + 4, Blocks.air, 0, 2);
            world.setBlock(i + 11, j + 8, k + 4, Blocks.stonebrick, 1, 2);
            world.setBlock(i + 2, j + 8, k + 5, Blocks.stonebrick, 2, 2);
            world.setBlock(i + 3, j + 8, k + 5, Blocks.air, 0, 2);
            world.setBlock(i + 4, j + 8, k + 5, Blocks.air, 0, 2);
            world.setBlock(i + 5, j + 8, k + 5, Blocks.air, 0, 2);
            world.setBlock(i + 6, j + 8, k + 5, Blocks.air, 0, 2);
            world.setBlock(i + 7, j + 8, k + 5, Blocks.air, 0, 2);
            world.setBlock(i + 8, j + 8, k + 5, Blocks.air, 0, 2);
            world.setBlock(i + 9, j + 8, k + 5, Blocks.air, 0, 2);
            world.setBlock(i + 10, j + 8, k + 5, Blocks.air, 0, 2);
            world.setBlock(i + 11, j + 8, k + 5, Blocks.stonebrick, 2, 2);
            world.setBlock(i + 1, j + 8, k + 6, Blocks.vine, 8, 2);
            world.setBlock(i + 2, j + 8, k + 6, Blocks.stonebrick, 1, 2);
            world.setBlock(i + 3, j + 8, k + 6, Blocks.air, 0, 2);
            world.setBlock(i + 4, j + 8, k + 6, Blocks.air, 0, 2);
            world.setBlock(i + 5, j + 8, k + 6, Blocks.air, 0, 2);
            world.setBlock(i + 6, j + 8, k + 6, Blocks.air, 0, 2);
            world.setBlock(i + 7, j + 8, k + 6, Blocks.air, 0, 2);
            world.setBlock(i + 8, j + 8, k + 6, Blocks.air, 0, 2);
            world.setBlock(i + 9, j + 8, k + 6, Blocks.air, 0, 2);
            world.setBlock(i + 10, j + 8, k + 6, Blocks.air, 0, 2);
            world.setBlock(i + 11, j + 8, k + 6, placeStoneBricks(random), 0, 2);
            world.setBlock(i + 2, j + 8, k + 7, placeStoneBricks(random), 0, 2);
            world.setBlock(i + 3, j + 8, k + 7, Blocks.air, 0, 2);
            world.setBlock(i + 4, j + 8, k + 7, Blocks.air, 0, 2);
            world.setBlock(i + 5, j + 8, k + 7, Blocks.air, 0, 2);
            world.setBlock(i + 6, j + 8, k + 7, Blocks.air, 0, 2);
            world.setBlock(i + 7, j + 8, k + 7, Blocks.air, 0, 2);
            world.setBlock(i + 8, j + 8, k + 7, Blocks.air, 0, 2);
            world.setBlock(i + 9, j + 8, k + 7, Blocks.air, 0, 2);
            world.setBlock(i + 10, j + 8, k + 7, Blocks.air, 0, 2);
            world.setBlock(i + 11, j + 8, k + 7, Blocks.stonebrick, 2, 2);
            world.setBlock(i + 2, j + 8, k + 8, Blocks.stonebrick, 2, 2);
            world.setBlock(i + 3, j + 8, k + 8, Blocks.air, 0, 2);
            world.setBlock(i + 4, j + 8, k + 8, Blocks.air, 0, 2);
            world.setBlock(i + 5, j + 8, k + 8, Blocks.air, 0, 2);
            world.setBlock(i + 6, j + 8, k + 8, Blocks.air, 0, 2);
            world.setBlock(i + 7, j + 8, k + 8, Blocks.air, 0, 2);
            world.setBlock(i + 8, j + 8, k + 8, Blocks.air, 0, 2);
            world.setBlock(i + 9, j + 8, k + 8, Blocks.air, 0, 2);
            world.setBlock(i + 10, j + 8, k + 8, Blocks.air, 0, 2);
            world.setBlock(i + 11, j + 8, k + 8, placeStoneBricks(random), 0, 2);
            world.setBlock(i + 12, j + 8, k + 8, Blocks.vine, 2, 2);
            world.setBlock(i + 2, j + 8, k + 9, placeStoneBricks(random), 0, 2);
            world.setBlock(i + 3, j + 8, k + 9, Blocks.air, 0, 2);
            world.setBlock(i + 4, j + 8, k + 9, Blocks.air, 0, 2);
            world.setBlock(i + 5, j + 8, k + 9, Blocks.air, 0, 2);
            world.setBlock(i + 6, j + 8, k + 9, Blocks.air, 0, 2);
            world.setBlock(i + 7, j + 8, k + 9, Blocks.air, 0, 2);
            world.setBlock(i + 8, j + 8, k + 9, Blocks.air, 0, 2);
            world.setBlock(i + 9, j + 8, k + 9, Blocks.air, 0, 2);
            world.setBlock(i + 10, j + 8, k + 9, Blocks.air, 0, 2);
            world.setBlock(i + 11, j + 8, k + 9, Blocks.stonebrick, 1, 2);
            world.setBlock(i + 2, j + 8, k + 10, placeStoneBricks(random), 0, 2);
            world.setBlock(i + 3, j + 8, k + 10, Blocks.air, 0, 2);
            world.setBlock(i + 4, j + 8, k + 10, Blocks.air, 0, 2);
            world.setBlock(i + 5, j + 8, k + 10, Blocks.air, 0, 2);
            world.setBlock(i + 6, j + 8, k + 10, Blocks.vine, 1, 2);
            world.setBlock(i + 7, j + 8, k + 10, Blocks.air, 0, 2);
            world.setBlock(i + 8, j + 8, k + 10, Blocks.air, 0, 2);
            world.setBlock(i + 9, j + 8, k + 10, Blocks.air, 0, 2);
            world.setBlock(i + 10, j + 8, k + 10, Blocks.air, 0, 2);
            world.setBlock(i + 11, j + 8, k + 10, placeStoneBricks(random), 0, 2);
            world.setBlock(i + 2, j + 8, k + 11, Blocks.cobblestone, 0, 2);
            world.setBlock(i + 3, j + 8, k + 11, placeStoneBricks(random), 0, 2);
            world.setBlock(i + 4, j + 8, k + 11, Blocks.stonebrick, 2, 2);
            world.setBlock(i + 5, j + 8, k + 11, placeStoneBricks(random), 0, 2);
            world.setBlock(i + 6, j + 8, k + 11, placeStoneBricks(random), 0, 2);
            world.setBlock(i + 7, j + 8, k + 11, placeStoneBricks(random), 0, 2);
            world.setBlock(i + 8, j + 8, k + 11, placeStoneBricks(random), 0, 2);
            world.setBlock(i + 9, j + 8, k + 11, placeStoneBricks(random), 0, 2);
            world.setBlock(i + 10, j + 8, k + 11, placeStoneBricks(random), 0, 2);
            world.setBlock(i + 11, j + 8, k + 11, Blocks.cobblestone, 0, 2);
            world.setBlock(i + 8, j + 8, k + 12, Blocks.vine, 4, 2);
            world.setBlock(i + 9, j + 8, k + 12, Blocks.vine, 4, 2);
            world.setBlock(i + 7, j + 9, k + 1, Blocks.vine, 1, 2);
            world.setBlock(i + 8, j + 9, k + 1, Blocks.vine, 1, 2);
            world.setBlock(i + 9, j + 9, k + 1, Blocks.vine, 1, 2);
            world.setBlock(i + 2, j + 9, k + 2, Blocks.cobblestone, 0, 2);
            world.setBlock(i + 3, j + 9, k + 2, Blocks.cobblestone, 0, 2);
            world.setBlock(i + 4, j + 9, k + 2, Blocks.cobblestone, 0, 2);
            world.setBlock(i + 5, j + 9, k + 2, Blocks.cobblestone, 0, 2);
            world.setBlock(i + 6, j + 9, k + 2, Blocks.cobblestone, 0, 2);
            world.setBlock(i + 7, j + 9, k + 2, Blocks.cobblestone, 0, 2);
            world.setBlock(i + 8, j + 9, k + 2, Blocks.cobblestone, 0, 2);
            world.setBlock(i + 9, j + 9, k + 2, Blocks.cobblestone, 0, 2);
            world.setBlock(i + 10, j + 9, k + 2, Blocks.cobblestone, 0, 2);
            world.setBlock(i + 11, j + 9, k + 2, Blocks.cobblestone, 0, 2);
            world.setBlock(i + 2, j + 9, k + 3, Blocks.cobblestone, 0, 2);
            world.setBlock(i + 3, j + 9, k + 3, placeStoneBricks(random), 0, 2);
            world.setBlock(i + 4, j + 9, k + 3, Blocks.stonebrick, 2, 2);
            world.setBlock(i + 5, j + 9, k + 3, placeStoneBricks(random), 0, 2);
            world.setBlock(i + 6, j + 9, k + 3, placeStoneBricks(random), 0, 2);
            world.setBlock(i + 7, j + 9, k + 3, Blocks.stonebrick, 1, 2);
            world.setBlock(i + 8, j + 9, k + 3, placeStoneBricks(random), 0, 2);
            world.setBlock(i + 9, j + 9, k + 3, Blocks.stonebrick, 1, 2);
            world.setBlock(i + 10, j + 9, k + 3, placeStoneBricks(random), 0, 2);
            world.setBlock(i + 11, j + 9, k + 3, Blocks.cobblestone, 0, 2);
            world.setBlock(i + 2, j + 9, k + 4, Blocks.cobblestone, 0, 2);
            world.setBlock(i + 3, j + 9, k + 4, placeStoneBricks(random), 0, 2);
            world.setBlock(i + 4, j + 9, k + 4, Blocks.stonebrick, 1, 2);
            world.setBlock(i + 5, j + 9, k + 4, placeStoneBricks(random), 0, 2);
            world.setBlock(i + 6, j + 9, k + 4, placeStoneBricks(random), 0, 2);
            world.setBlock(i + 7, j + 9, k + 4, placeStoneBricks(random), 0, 2);
            world.setBlock(i + 8, j + 9, k + 4, Blocks.stonebrick, 2, 2);
            world.setBlock(i + 9, j + 9, k + 4, placeStoneBricks(random), 0, 2);
            world.setBlock(i + 10, j + 9, k + 4, placeStoneBricks(random), 0, 2);
            world.setBlock(i + 11, j + 9, k + 4, Blocks.cobblestone, 0, 2);
            world.setBlock(i + 1, j + 9, k + 5, Blocks.vine, 8, 2);
            world.setBlock(i + 2, j + 9, k + 5, Blocks.cobblestone, 0, 2);
            world.setBlock(i + 3, j + 9, k + 5, placeStoneBricks(random), 0, 2);
            world.setBlock(i + 4, j + 9, k + 5, placeStoneBricks(random), 0, 2);
            world.setBlock(i + 5, j + 9, k + 5, Blocks.stonebrick, 2, 2);
            world.setBlock(i + 6, j + 9, k + 5, Blocks.stonebrick, 2, 2);
            world.setBlock(i + 7, j + 9, k + 5, placeStoneBricks(random), 0, 2);
            world.setBlock(i + 8, j + 9, k + 5, Blocks.stonebrick, 1, 2);
            world.setBlock(i + 9, j + 9, k + 5, Blocks.stonebrick, 1, 2);
            world.setBlock(i + 10, j + 9, k + 5, placeStoneBricks(random), 0, 2);
            world.setBlock(i + 11, j + 9, k + 5, Blocks.cobblestone, 0, 2);
            world.setBlock(i + 1, j + 9, k + 6, Blocks.vine, 8, 2);
            world.setBlock(i + 2, j + 9, k + 6, Blocks.cobblestone, 0, 2);
            world.setBlock(i + 3, j + 9, k + 6, placeStoneBricks(random), 0, 2);
            world.setBlock(i + 4, j + 9, k + 6, placeStoneBricks(random), 0, 2);
            world.setBlock(i + 5, j + 9, k + 6, placeStoneBricks(random), 0, 2);
            world.setBlock(i + 6, j + 9, k + 6, Blocks.stonebrick, 1, 2);
            world.setBlock(i + 7, j + 9, k + 6, Blocks.stonebrick, 1, 2);
            world.setBlock(i + 8, j + 9, k + 6, Blocks.stonebrick, 2, 2);
            world.setBlock(i + 9, j + 9, k + 6, placeStoneBricks(random), 0, 2);
            world.setBlock(i + 10, j + 9, k + 6, Blocks.stonebrick, 1, 2);
            world.setBlock(i + 11, j + 9, k + 6, Blocks.cobblestone, 0, 2);
            world.setBlock(i + 2, j + 9, k + 7, Blocks.cobblestone, 0, 2);
            world.setBlock(i + 3, j + 9, k + 7, Blocks.stonebrick, 1, 2);
            world.setBlock(i + 4, j + 9, k + 7, placeStoneBricks(random), 0, 2);
            world.setBlock(i + 5, j + 9, k + 7, placeStoneBricks(random), 0, 2);
            world.setBlock(i + 6, j + 9, k + 7, placeStoneBricks(random), 0, 2);
            world.setBlock(i + 7, j + 9, k + 7, placeStoneBricks(random), 0, 2);
            world.setBlock(i + 8, j + 9, k + 7, placeStoneBricks(random), 0, 2);
            world.setBlock(i + 9, j + 9, k + 7, placeStoneBricks(random), 0, 2);
            world.setBlock(i + 10, j + 9, k + 7, placeStoneBricks(random), 0, 2);
            world.setBlock(i + 11, j + 9, k + 7, Blocks.cobblestone, 0, 2);
            world.setBlock(i + 2, j + 9, k + 8, Blocks.cobblestone, 0, 2);
            world.setBlock(i + 3, j + 9, k + 8, placeStoneBricks(random), 0, 2);
            world.setBlock(i + 4, j + 9, k + 8, placeStoneBricks(random), 0, 2);
            world.setBlock(i + 5, j + 9, k + 8, Blocks.stonebrick, 2, 2);
            world.setBlock(i + 6, j + 9, k + 8, placeStoneBricks(random), 0, 2);
            world.setBlock(i + 7, j + 9, k + 8, placeStoneBricks(random), 0, 2);
            world.setBlock(i + 8, j + 9, k + 8, Blocks.stonebrick, 2, 2);
            world.setBlock(i + 9, j + 9, k + 8, Blocks.stonebrick, 2, 2);
            world.setBlock(i + 10, j + 9, k + 8, placeStoneBricks(random), 0, 2);
            world.setBlock(i + 11, j + 9, k + 8, Blocks.cobblestone, 0, 2);
            world.setBlock(i + 1, j + 9, k + 9, Blocks.vine, 8, 2);
            world.setBlock(i + 2, j + 9, k + 9, Blocks.cobblestone, 0, 2);
            world.setBlock(i + 3, j + 9, k + 9, placeStoneBricks(random), 0, 2);
            world.setBlock(i + 4, j + 9, k + 9, Blocks.stonebrick, 2, 2);
            world.setBlock(i + 5, j + 9, k + 9, placeStoneBricks(random), 0, 2);
            world.setBlock(i + 6, j + 9, k + 9, placeStoneBricks(random), 0, 2);
            world.setBlock(i + 7, j + 9, k + 9, Blocks.stonebrick, 1, 2);
            world.setBlock(i + 8, j + 9, k + 9, placeStoneBricks(random), 0, 2);
            world.setBlock(i + 9, j + 9, k + 9, placeStoneBricks(random), 0, 2);
            world.setBlock(i + 10, j + 9, k + 9, Blocks.stonebrick, 1, 2);
            world.setBlock(i + 11, j + 9, k + 9, Blocks.cobblestone, 0, 2);
            world.setBlock(i + 1, j + 9, k + 10, Blocks.vine, 8, 2);
            world.setBlock(i + 2, j + 9, k + 10, Blocks.cobblestone, 0, 2);
            world.setBlock(i + 3, j + 9, k + 10, placeStoneBricks(random), 0, 2);
            world.setBlock(i + 4, j + 9, k + 10, placeStoneBricks(random), 0, 2);
            world.setBlock(i + 5, j + 9, k + 10, Blocks.stonebrick, 1, 2);
            world.setBlock(i + 6, j + 9, k + 10, placeStoneBricks(random), 0, 2);
            world.setBlock(i + 7, j + 9, k + 10, Blocks.stonebrick, 2, 2);
            world.setBlock(i + 8, j + 9, k + 10, Blocks.stonebrick, 2, 2);
            world.setBlock(i + 9, j + 9, k + 10, placeStoneBricks(random), 0, 2);
            world.setBlock(i + 10, j + 9, k + 10, placeStoneBricks(random), 0, 2);
            world.setBlock(i + 11, j + 9, k + 10, Blocks.cobblestone, 0, 2);
            world.setBlock(i + 1, j + 9, k + 11, Blocks.vine, 8, 2);
            world.setBlock(i + 2, j + 9, k + 11, Blocks.cobblestone, 0, 2);
            world.setBlock(i + 3, j + 9, k + 11, Blocks.cobblestone, 0, 2);
            world.setBlock(i + 4, j + 9, k + 11, Blocks.cobblestone, 0, 2);
            world.setBlock(i + 5, j + 9, k + 11, Blocks.cobblestone, 0, 2);
            world.setBlock(i + 6, j + 9, k + 11, Blocks.cobblestone, 0, 2);
            world.setBlock(i + 7, j + 9, k + 11, Blocks.cobblestone, 0, 2);
            world.setBlock(i + 8, j + 9, k + 11, Blocks.cobblestone, 0, 2);
            world.setBlock(i + 9, j + 9, k + 11, Blocks.cobblestone, 0, 2);
            world.setBlock(i + 10, j + 9, k + 11, Blocks.cobblestone, 0, 2);
            world.setBlock(i + 11, j + 9, k + 11, Blocks.cobblestone, 0, 2);

            world.setBlock(i + 5, j + 1, k + 8, Blocks.mob_spawner, 0, 2);
            TileEntityMobSpawner tileentitymobspawner = (TileEntityMobSpawner) world.getTileEntity(i + 5, j + 1, k + 8);

            if (tileentitymobspawner != null) {
                tileentitymobspawner.func_145881_a().setEntityName("nova_craft.sea_serpent");
            }

        }

        return true;
    }

    private Block placeStoneBricks(Random random) {
        if (random.nextDouble() < 0.12) {
            return Blocks.air;
        } else {
            return Blocks.stonebrick;
        }
    }
}