package com.NovaCraft.world.structure;

import com.NovaCraft.Items.NovaCraftItems;
import com.NovaCraft.config.Configs;
import com.NovaCraft.entity.EntityCrystalGolem;
import com.NovaCraft.registry.OtherModBlocks;
import com.NovaCraftBlocks.NovaCraftBlocks;
import cpw.mods.fml.common.Loader;
import cpw.mods.fml.common.registry.GameRegistry;
import net.minecraft.block.Block;
import net.minecraft.enchantment.Enchantment;
import net.minecraft.entity.Entity;
import net.minecraft.init.Blocks;
import net.minecraft.init.Items;
import net.minecraft.item.ItemStack;
import net.minecraft.tileentity.TileEntityChest;
import net.minecraft.world.World;
import net.minecraft.world.gen.feature.WorldGenerator;

import java.util.Random;

public class VoidTempleGen extends WorldGenerator
{
    public VoidTempleGen() {

    }
    private Block PlaceBasalt;

    private Block determineIfBasaltExists(World world, int x, int y, int z) {
        Block existingBlock = world.getBlock(x, y, z);

        if (!(Configs.disableNetherliciousBasaltInAncientCity) && Loader.isModLoaded("netherlicious")) {
            try {
                Block nether_Basalt = GameRegistry.findBlock("netherlicious", "Basalt");
                if (nether_Basalt != null && (existingBlock == null || existingBlock != nether_Basalt)) {
                    return nether_Basalt;
                }
            } catch (Exception ex) {
                if (Configs.enableDebugMode) {
                    System.out.println("Failed to Find Netherlicious basalt, trying Et Futurum Requiem...");
                }
            }
        }

        if (Loader.isModLoaded("etfuturum")) {
            try {
                Block et_basalt = GameRegistry.findBlock("etfuturum", "basalt");
                if (et_basalt != null && (existingBlock == null || existingBlock != et_basalt)) {
                    return et_basalt;
                }
            } catch (Exception ex) {
                if (Configs.enableDebugMode) {
                    System.out.println("Failed to Find Et Futurum Requiem basalt, placing Polished Vanite Bricks...");
                }
            }
        }

        return NovaCraftBlocks.polished_vanite_bricks;
    }

    public boolean generate(final World world, final Random random, final int i, final int j, final int k) {
        PlaceBasalt = determineIfBasaltExists(world, i + 18, j + 1, k + 6);

        if (world.isAirBlock(i + 12, j + 20, k + 16) && ((!(world.isAirBlock(i + 14, j + 19, k + 16)) || !(world.isAirBlock(i + 10, j + 19, k + 16)))
                && (!(world.isAirBlock(i + 14, j + 19, k + 14)) || !(world.isAirBlock(i + 14, j + 19, k + 18))))) {
            world.setBlock(i + 6, j + 0, k + 1, placeBuildingBlock(random), 0, 2);
            world.setBlock(i + 7, j + 0, k + 1, Blocks.bedrock, 0, 2);
            world.setBlock(i + 8, j + 0, k + 1, Blocks.bedrock, 0, 2);
            world.setBlock(i + 9, j + 0, k + 1, placeBuildingBlock(random), 0, 2);
            world.setBlock(i + 10, j + 0, k + 1, Blocks.bedrock, 0, 2);
            world.setBlock(i + 11, j + 0, k + 1, placeBuildingBlock(random), 0, 2);
            world.setBlock(i + 12, j + 0, k + 1, placeBuildingBlock(random), 0, 2);
            world.setBlock(i + 13, j + 0, k + 1, placeBuildingBlock(random), 0, 2);
            world.setBlock(i + 14, j + 0, k + 1, Blocks.bedrock, 0, 2);
            world.setBlock(i + 15, j + 0, k + 1, placeBuildingBlock(random), 0, 2);
            world.setBlock(i + 5, j + 0, k + 2, placeBuildingBlock(random), 0, 2);
            world.setBlock(i + 6, j + 0, k + 2, placeBuildingBlock(random), 0, 2);
            world.setBlock(i + 7, j + 0, k + 2, placeBuildingBlock(random), 0, 2);
            world.setBlock(i + 8, j + 0, k + 2, NovaCraftBlocks.sculk_block, 0, 2);
            world.setBlock(i + 9, j + 0, k + 2, NovaCraftBlocks.sculk_block, 0, 2);
            world.setBlock(i + 10, j + 0, k + 2, NovaCraftBlocks.sculk_block, 0, 2);
            world.setBlock(i + 11, j + 0, k + 2, NovaCraftBlocks.sculk_block, 0, 2);
            world.setBlock(i + 12, j + 0, k + 2, placeBuildingBlock(random), 0, 2);
            world.setBlock(i + 13, j + 0, k + 2, placeBuildingBlock(random), 0, 2);
            world.setBlock(i + 14, j + 0, k + 2, placeBuildingBlock(random), 0, 2);
            world.setBlock(i + 15, j + 0, k + 2, placeBuildingBlock(random), 0, 2);
            world.setBlock(i + 16, j + 0, k + 2, Blocks.bedrock, 0, 2);
            world.setBlock(i + 4, j + 0, k + 3, Blocks.bedrock, 0, 2);
            world.setBlock(i + 5, j + 0, k + 3, placeBuildingBlock(random), 0, 2);
            world.setBlock(i + 6, j + 0, k + 3, placeBuildingBlock(random), 0, 2);
            world.setBlock(i + 7, j + 0, k + 3, placeBuildingBlock(random), 0, 2);
            world.setBlock(i + 8, j + 0, k + 3, NovaCraftBlocks.sculk_block, 0, 2);
            world.setBlock(i + 9, j + 0, k + 3, NovaCraftBlocks.sculk_block, 0, 2);
            world.setBlock(i + 10, j + 0, k + 3, placeBuildingBlock(random), 0, 2);
            world.setBlock(i + 11, j + 0, k + 3, placeBuildingBlock(random), 0, 2);
            world.setBlock(i + 12, j + 0, k + 3, Blocks.bedrock, 0, 2);
            world.setBlock(i + 13, j + 0, k + 3, placeBuildingBlock(random), 0, 2);
            world.setBlock(i + 14, j + 0, k + 3, placeBuildingBlock(random), 0, 2);
            world.setBlock(i + 15, j + 0, k + 3, placeBuildingBlock(random), 0, 2);
            world.setBlock(i + 16, j + 0, k + 3, placeBuildingBlock(random), 0, 2);
            world.setBlock(i + 17, j + 0, k + 3, placeBuildingBlock(random), 0, 2);
            world.setBlock(i + 3, j + 0, k + 4, Blocks.bedrock, 0, 2);
            world.setBlock(i + 4, j + 0, k + 4, placeBuildingBlock(random), 0, 2);
            world.setBlock(i + 5, j + 0, k + 4, placeBuildingBlock(random), 0, 2);
            world.setBlock(i + 6, j + 0, k + 4, placeBuildingBlock(random), 0, 2);
            world.setBlock(i + 7, j + 0, k + 4, placeBuildingBlock(random), 0, 2);
            world.setBlock(i + 8, j + 0, k + 4, placeBuildingBlock(random), 0, 2);
            world.setBlock(i + 9, j + 0, k + 4, placeBuildingBlock(random), 0, 2);
            world.setBlock(i + 10, j + 0, k + 4, placeBuildingBlock(random), 0, 2);
            world.setBlock(i + 11, j + 0, k + 4, Blocks.bedrock, 0, 2);
            world.setBlock(i + 12, j + 0, k + 4, placeBuildingBlock(random), 0, 2);
            world.setBlock(i + 13, j + 0, k + 4, placeBuildingBlock(random), 0, 2);
            world.setBlock(i + 14, j + 0, k + 4, placeBuildingBlock(random), 0, 2);
            world.setBlock(i + 15, j + 0, k + 4, placeBuildingBlock(random), 0, 2);
            world.setBlock(i + 16, j + 0, k + 4, placeBuildingBlock(random), 0, 2);
            world.setBlock(i + 17, j + 0, k + 4, placeBuildingBlock(random), 0, 2);
            world.setBlock(i + 18, j + 0, k + 4, Blocks.bedrock, 0, 2);
            world.setBlock(i + 19, j + 0, k + 4, placeBuildingBlock(random), 0, 2);
            world.setBlock(i + 2, j + 0, k + 5, placeBuildingBlock(random), 0, 2);
            world.setBlock(i + 3, j + 0, k + 5, placeBuildingBlock(random), 0, 2);
            world.setBlock(i + 4, j + 0, k + 5, placeBuildingBlock(random), 0, 2);
            world.setBlock(i + 5, j + 0, k + 5, placeBuildingBlock(random), 0, 2);
            world.setBlock(i + 6, j + 0, k + 5, Blocks.bedrock, 0, 2);
            world.setBlock(i + 7, j + 0, k + 5, placeBuildingBlock(random), 0, 2);
            world.setBlock(i + 8, j + 0, k + 5, placeBuildingBlock(random), 0, 2);
            world.setBlock(i + 9, j + 0, k + 5, Blocks.air, 0, 2);
            world.setBlock(i + 10, j + 0, k + 5, placeBuildingBlock(random), 0, 2);
            world.setBlock(i + 11, j + 0, k + 5, placeBuildingBlock(random), 0, 2);
            world.setBlock(i + 12, j + 0, k + 5, placeBuildingBlock(random), 0, 2);
            world.setBlock(i + 13, j + 0, k + 5, placeBuildingBlock(random), 0, 2);
            world.setBlock(i + 14, j + 0, k + 5, Blocks.bedrock, 0, 2);
            world.setBlock(i + 15, j + 0, k + 5, placeBuildingBlock(random), 0, 2);
            world.setBlock(i + 16, j + 0, k + 5, Blocks.bedrock, 0, 2);
            world.setBlock(i + 17, j + 0, k + 5, placeBuildingBlock(random), 0, 2);
            world.setBlock(i + 18, j + 0, k + 5, placeBuildingBlock(random), 0, 2);
            world.setBlock(i + 19, j + 0, k + 5, placeBuildingBlock(random), 0, 2);
            world.setBlock(i + 20, j + 0, k + 5, placeBuildingBlock(random), 0, 2);
            world.setBlock(i + 1, j + 0, k + 6, placeBuildingBlock(random), 0, 2);
            world.setBlock(i + 2, j + 0, k + 6, placeBuildingBlock(random), 0, 2);
            world.setBlock(i + 3, j + 0, k + 6, placeBuildingBlock(random), 0, 2);
            world.setBlock(i + 4, j + 0, k + 6, placeBuildingBlock(random), 0, 2);
            world.setBlock(i + 5, j + 0, k + 6, placeBuildingBlock(random), 0, 2);
            world.setBlock(i + 6, j + 0, k + 6, placeBuildingBlock(random), 0, 2);
            world.setBlock(i + 7, j + 0, k + 6, placeBuildingBlock(random), 0, 2);
            world.setBlock(i + 8, j + 0, k + 6, placeBuildingBlock(random), 0, 2);
            world.setBlock(i + 9, j + 0, k + 6, placeBuildingBlock(random), 0, 2);
            world.setBlock(i + 10, j + 0, k + 6, placeBuildingBlock(random), 0, 2);
            world.setBlock(i + 11, j + 0, k + 6, placeBuildingBlock(random), 0, 2);
            world.setBlock(i + 12, j + 0, k + 6, placeBuildingBlock(random), 0, 2);
            world.setBlock(i + 13, j + 0, k + 6, placeBuildingBlock(random), 0, 2);
            world.setBlock(i + 14, j + 0, k + 6, placeBuildingBlock(random), 0, 2);
            world.setBlock(i + 15, j + 0, k + 6, placeBuildingBlock(random), 0, 2);
            world.setBlock(i + 16, j + 0, k + 6, placeBuildingBlock(random), 0, 2);
            world.setBlock(i + 17, j + 0, k + 6, placeBuildingBlock(random), 0, 2);
            world.setBlock(i + 18, j + 0, k + 6, placeBuildingBlock(random), 0, 2);
            world.setBlock(i + 19, j + 0, k + 6, Blocks.bedrock, 0, 2);
            world.setBlock(i + 20, j + 0, k + 6, placeBuildingBlock(random), 0, 2);
            world.setBlock(i + 2, j + 0, k + 7, Blocks.bedrock, 0, 2);
            world.setBlock(i + 3, j + 0, k + 7, placeBuildingBlock(random), 0, 2);
            world.setBlock(i + 4, j + 0, k + 7, NovaCraftBlocks.sculk_block, 0, 2);
            world.setBlock(i + 5, j + 0, k + 7, placeBuildingBlock(random), 0, 2);
            world.setBlock(i + 6, j + 0, k + 7, placeBuildingBlock(random), 0, 2);
            world.setBlock(i + 7, j + 0, k + 7, Blocks.bedrock, 0, 2);
            world.setBlock(i + 8, j + 0, k + 7, placeBuildingBlock(random), 0, 2);
            world.setBlock(i + 9, j + 0, k + 7, Blocks.bedrock, 0, 2);
            world.setBlock(i + 10, j + 0, k + 7, placeBuildingBlock(random), 0, 2);
            world.setBlock(i + 11, j + 0, k + 7, placeBuildingBlock(random), 0, 2);
            world.setBlock(i + 12, j + 0, k + 7, placeBuildingBlock(random), 0, 2);
            world.setBlock(i + 13, j + 0, k + 7, placeBuildingBlock(random), 0, 2);
            world.setBlock(i + 14, j + 0, k + 7, Blocks.bedrock, 0, 2);
            world.setBlock(i + 15, j + 0, k + 7, placeBuildingBlock(random), 0, 2);
            world.setBlock(i + 16, j + 0, k + 7, placeBuildingBlock(random), 0, 2);
            world.setBlock(i + 17, j + 0, k + 7, placeBuildingBlock(random), 0, 2);
            world.setBlock(i + 18, j + 0, k + 7, placeBuildingBlock(random), 0, 2);
            world.setBlock(i + 19, j + 0, k + 7, placeBuildingBlock(random), 0, 2);
            world.setBlock(i + 20, j + 0, k + 7, placeBuildingBlock(random), 0, 2);
            world.setBlock(i + 3, j + 0, k + 8, Blocks.bedrock, 0, 2);
            world.setBlock(i + 4, j + 0, k + 8, NovaCraftBlocks.sculk_block, 0, 2);
            world.setBlock(i + 5, j + 0, k + 8, NovaCraftBlocks.sculk_block, 0, 2);
            world.setBlock(i + 6, j + 0, k + 8, placeBuildingBlock(random), 0, 2);
            world.setBlock(i + 7, j + 0, k + 8, placeBuildingBlock(random), 0, 2);
            world.setBlock(i + 8, j + 0, k + 8, placeBuildingBlock(random), 0, 2);
            world.setBlock(i + 9, j + 0, k + 8, placeBuildingBlock(random), 0, 2);
            world.setBlock(i + 10, j + 0, k + 8, placeBuildingBlock(random), 0, 2);
            world.setBlock(i + 11, j + 0, k + 8, placeBuildingBlock(random), 0, 2);
            world.setBlock(i + 12, j + 0, k + 8, Blocks.bedrock, 0, 2);
            world.setBlock(i + 13, j + 0, k + 8, placeBuildingBlock(random), 0, 2);
            world.setBlock(i + 14, j + 0, k + 8, placeBuildingBlock(random), 0, 2);
            world.setBlock(i + 15, j + 0, k + 8, placeBuildingBlock(random), 0, 2);
            world.setBlock(i + 16, j + 0, k + 8, Blocks.bedrock, 0, 2);
            world.setBlock(i + 17, j + 0, k + 8, placeBuildingBlock(random), 0, 2);
            world.setBlock(i + 18, j + 0, k + 8, Blocks.bedrock, 0, 2);
            world.setBlock(i + 19, j + 0, k + 8, placeBuildingBlock(random), 0, 2);
            world.setBlock(i + 4, j + 0, k + 9, placeBuildingBlock(random), 0, 2);
            world.setBlock(i + 5, j + 0, k + 9, NovaCraftBlocks.sculk_block, 0, 2);
            world.setBlock(i + 6, j + 0, k + 9, Blocks.bedrock, 0, 2);
            world.setBlock(i + 7, j + 0, k + 9, placeBuildingBlock(random), 0, 2);
            world.setBlock(i + 8, j + 0, k + 9, NovaCraftBlocks.sculk_block, 0, 2);
            world.setBlock(i + 9, j + 0, k + 9, placeBuildingBlock(random), 0, 2);
            world.setBlock(i + 10, j + 0, k + 9, placeBuildingBlock(random), 0, 2);
            world.setBlock(i + 11, j + 0, k + 9, placeBuildingBlock(random), 0, 2);
            world.setBlock(i + 12, j + 0, k + 9, placeBuildingBlock(random), 0, 2);
            world.setBlock(i + 13, j + 0, k + 9, placeBuildingBlock(random), 0, 2);
            world.setBlock(i + 14, j + 0, k + 9, Blocks.bedrock, 0, 2);
            world.setBlock(i + 15, j + 0, k + 9, placeBuildingBlock(random), 0, 2);
            world.setBlock(i + 16, j + 0, k + 9, placeBuildingBlock(random), 0, 2);
            world.setBlock(i + 17, j + 0, k + 9, placeBuildingBlock(random), 0, 2);
            world.setBlock(i + 5, j + 0, k + 10, placeBuildingBlock(random), 0, 2);
            world.setBlock(i + 6, j + 0, k + 10, placeBuildingBlock(random), 0, 2);
            world.setBlock(i + 7, j + 0, k + 10, NovaCraftBlocks.sculk_block, 0, 2);
            world.setBlock(i + 8, j + 0, k + 10, NovaCraftBlocks.sculk_block, 0, 2);
            world.setBlock(i + 9, j + 0, k + 10, NovaCraftBlocks.sculk_block, 0, 2);
            world.setBlock(i + 10, j + 0, k + 10, placeBuildingBlock(random), 0, 2);
            world.setBlock(i + 11, j + 0, k + 10, placeBuildingBlock(random), 0, 2);
            world.setBlock(i + 12, j + 0, k + 10, placeBuildingBlock(random), 0, 2);
            world.setBlock(i + 13, j + 0, k + 10, placeBuildingBlock(random), 0, 2);
            world.setBlock(i + 14, j + 0, k + 10, placeBuildingBlock(random), 0, 2);
            world.setBlock(i + 15, j + 0, k + 10, placeBuildingBlock(random), 0, 2);
            world.setBlock(i + 16, j + 0, k + 10, placeBuildingBlock(random), 0, 2);
            world.setBlock(i + 6, j + 0, k + 11, placeBuildingBlock(random), 0, 2);
            world.setBlock(i + 7, j + 0, k + 11, Blocks.bedrock, 0, 2);
            world.setBlock(i + 8, j + 0, k + 11, placeBuildingBlock(random), 0, 2);
            world.setBlock(i + 9, j + 0, k + 11, placeBuildingBlock(random), 0, 2);
            world.setBlock(i + 10, j + 0, k + 11, placeBuildingBlock(random), 0, 2);
            world.setBlock(i + 11, j + 0, k + 11, Blocks.bedrock, 0, 2);
            world.setBlock(i + 12, j + 0, k + 11, placeBuildingBlock(random), 0, 2);
            world.setBlock(i + 13, j + 0, k + 11, placeBuildingBlock(random), 0, 2);
            world.setBlock(i + 14, j + 0, k + 11, Blocks.bedrock, 0, 2);
            world.setBlock(i + 15, j + 0, k + 11, placeBuildingBlock(random), 0, 2);
            world.setBlock(i + 6, j + 1, k + 1, placeBuildingBlock(random), 0, 2);
            world.setBlock(i + 7, j + 1, k + 1, placeBuildingBlock(random), 0, 2);
            world.setBlock(i + 8, j + 1, k + 1, NovaCraftBlocks.sculk_block, 0, 2);
            world.setBlock(i + 9, j + 1, k + 1, NovaCraftBlocks.sculk_block, 0, 2);
            world.setBlock(i + 10, j + 1, k + 1, NovaCraftBlocks.sculk_block, 0, 2);
            world.setBlock(i + 11, j + 1, k + 1, placeBuildingBlock(random), 0, 2);
            world.setBlock(i + 12, j + 1, k + 1, placeBuildingBlock(random), 0, 2);
            world.setBlock(i + 13, j + 1, k + 1, placeBuildingBlock(random), 0, 2);
            world.setBlock(i + 14, j + 1, k + 1, placeBuildingBlock(random), 0, 2);
            world.setBlock(i + 15, j + 1, k + 1, placeBuildingBlock(random), 0, 2);
            world.setBlock(i + 5, j + 1, k + 2, placeBuildingBlock(random), 0, 2);
            world.setBlock(i + 6, j + 1, k + 2, Blocks.air, 0, 2);
            world.setBlock(i + 7, j + 1, k + 2, Blocks.air, 0, 2);
            world.setBlock(i + 8, j + 1, k + 2, Blocks.air, 0, 2);
            world.setBlock(i + 10, j + 1, k + 2, Blocks.air, 0, 2);
            world.setBlock(i + 11, j + 1, k + 2, Blocks.air, 0, 2);
            world.setBlock(i + 12, j + 1, k + 2, Blocks.air, 0, 2);
            world.setBlock(i + 13, j + 1, k + 2, Blocks.air, 0, 2);
            world.setBlock(i + 14, j + 1, k + 2, Blocks.air, 0, 2);
            world.setBlock(i + 15, j + 1, k + 2, Blocks.air, 0, 2);
            world.setBlock(i + 16, j + 1, k + 2, placeBuildingBlock(random), 0, 2);
            world.setBlock(i + 4, j + 1, k + 3, placeBuildingBlock(random), 0, 2);
            world.setBlock(i + 5, j + 1, k + 3, Blocks.air, 0, 2);
            world.setBlock(i + 6, j + 1, k + 3, Blocks.air, 0, 2);
            world.setBlock(i + 7, j + 1, k + 3, Blocks.air, 0, 2);
            world.setBlock(i + 8, j + 1, k + 3, Blocks.air, 0, 2);
            world.setBlock(i + 9, j + 1, k + 3, Blocks.air, 0, 2);
            world.setBlock(i + 10, j + 1, k + 3, Blocks.air, 0, 2);
            world.setBlock(i + 11, j + 1, k + 3, Blocks.air, 0, 2);
            world.setBlock(i + 12, j + 1, k + 3, Blocks.air, 0, 2);
            world.setBlock(i + 13, j + 1, k + 3, Blocks.air, 0, 2);
            world.setBlock(i + 14, j + 1, k + 3, Blocks.air, 0, 2);
            world.setBlock(i + 15, j + 1, k + 3, Blocks.air, 0, 2);
            world.setBlock(i + 16, j + 1, k + 3, Blocks.air, 0, 2);
            world.setBlock(i + 17, j + 1, k + 3, placeBuildingBlock(random), 0, 2);
            world.setBlock(i + 3, j + 1, k + 4, placeBuildingBlock(random), 0, 2);
            world.setBlock(i + 4, j + 1, k + 4, Blocks.air, 0, 2);
            world.setBlock(i + 5, j + 1, k + 4, Blocks.air, 0, 2);
            world.setBlock(i + 6, j + 1, k + 4, placeBuildingBlockSlab(random), 5, 2);
            world.setBlock(i + 7, j + 1, k + 4, Blocks.air, 0, 2);
            world.setBlock(i + 8, j + 1, k + 4, Blocks.air, 0, 2);
            world.setBlock(i + 9, j + 1, k + 4, Blocks.air, 0, 2);
            world.setBlock(i + 10, j + 1, k + 4, Blocks.air, 0, 2);
            world.setBlock(i + 11, j + 1, k + 4, placeBuildingBlock(random), 0, 2);
            world.setBlock(i + 12, j + 1, k + 4, placeBuildingBlock(random), 0, 2);
            world.setBlock(i + 13, j + 1, k + 4, Blocks.air, 0, 2);
            world.setBlock(i + 14, j + 1, k + 4, Blocks.air, 0, 2);
            world.setBlock(i + 15, j + 1, k + 4, Blocks.air, 0, 2);
            world.setBlock(i + 16, j + 1, k + 4, Blocks.air, 0, 2);
            world.setBlock(i + 17, j + 1, k + 4, placeBuildingBlock(random), 0, 2);
            world.setBlock(i + 18, j + 1, k + 4, placeBuildingBlock(random), 0, 2);
            world.setBlock(i + 19, j + 1, k + 4, placeBuildingBlock(random), 0, 2);
            world.setBlock(i + 2, j + 1, k + 5, placeBuildingBlock(random), 0, 2);
            world.setBlock(i + 3, j + 1, k + 5, Blocks.air, 0, 2);
            world.setBlock(i + 4, j + 1, k + 5, Blocks.air, 0, 2);
            world.setBlock(i + 5, j + 1, k + 5, placeBuildingBlockSlab(random), 5, 2);
            world.setBlock(i + 6, j + 1, k + 5, placeBuildingBlock(random), 0, 2);
            world.setBlock(i + 7, j + 1, k + 5, placeBuildingBlockSlab(random), 5, 2);
            world.setBlock(i + 8, j + 1, k + 5, Blocks.air, 0, 2);
            world.setBlock(i + 9, j + 1, k + 5, Blocks.air, 0, 2);
            world.setBlock(i + 10, j + 1, k + 5, placeBuildingBlock(random), 0, 2);
            world.setBlock(i + 11, j + 1, k + 5, placeBuildingBlock(random), 0, 2);
            world.setBlock(i + 12, j + 1, k + 5, placeBuildingBlock(random), 0, 2);
            world.setBlock(i + 13, j + 1, k + 5, placeBuildingBlock(random), 0, 2);
            world.setBlock(i + 14, j + 1, k + 5, Blocks.air, 0, 2);
            world.setBlock(i + 15, j + 1, k + 5, Blocks.air, 0, 2);
            world.setBlock(i + 16, j + 1, k + 5, Blocks.air, 0, 2);
            world.setBlock(i + 17, j + 1, k + 5, Blocks.air, 0, 2);
            world.setBlock(i + 18, j + 1, k + 5, placeBuildingBlock(random), 0, 2);
            world.setBlock(i + 19, j + 1, k + 5, placeBuildingBlock(random), 0, 2);
            world.setBlock(i + 20, j + 1, k + 5, placeBuildingBlock(random), 0, 2);
            world.setBlock(i + 1, j + 1, k + 6, placeBuildingBlock(random), 0, 2);
            world.setBlock(i + 2, j + 1, k + 6, placeBuildingBlock(random), 0, 2);
            world.setBlock(i + 3, j + 1, k + 6, Blocks.air, 0, 2);
            world.setBlock(i + 4, j + 1, k + 6, placeBuildingBlockSlab(random), 5, 2);
            world.setBlock(i + 5, j + 1, k + 6, NovaCraftBlocks.sculk_block, 0, 2);
            world.setBlock(i + 6, j + 1, k + 6, placeBuildingBlock(random), 0, 2);
            world.setBlock(i + 7, j + 1, k + 6, placeBuildingBlock(random), 0, 2);
            world.setBlock(i + 8, j + 1, k + 6, placeBuildingBlockSlab(random), 5, 2);
            world.setBlock(i + 9, j + 1, k + 6, Blocks.air, 0, 2);
            world.setBlock(i + 10, j + 1, k + 6, placeBuildingBlock(random), 0, 2);
            world.setBlock(i + 11, j + 1, k + 6, Blocks.lava, 0, 2);
            world.setBlock(i + 12, j + 1, k + 6, Blocks.lava, 8, 2);
            world.setBlock(i + 13, j + 1, k + 6, Blocks.lava, 0, 2);
            world.setBlock(i + 14, j + 1, k + 6, placeBuildingBlock(random), 0, 2);
            world.setBlock(i + 15, j + 1, k + 6, Blocks.air, 0, 2);
            world.setBlock(i + 16, j + 1, k + 6, Blocks.air, 0, 2);
            world.setBlock(i + 17, j + 1, k + 6, placeBuildingBlockStairs(random), 2, 2);
            world.setBlock(i + 18, j + 1, k + 6, PlaceBasalt, 1, 2);
            world.setBlock(i + 19, j + 1, k + 6, placeBuildingBlock(random), 0, 2);
            world.setBlock(i + 20, j + 1, k + 6, placeBuildingBlock(random), 0, 2);
            world.setBlock(i + 2, j + 1, k + 7, placeBuildingBlock(random), 0, 2);
            world.setBlock(i + 3, j + 1, k + 7, Blocks.air, 0, 2);
            world.setBlock(i + 4, j + 1, k + 7, Blocks.air, 0, 2);
            world.setBlock(i + 5, j + 1, k + 7, placeBuildingBlockSlab(random), 5, 2);
            world.setBlock(i + 6, j + 1, k + 7, placeBuildingBlock(random), 0, 2);
            world.setBlock(i + 7, j + 1, k + 7, placeBuildingBlockSlab(random), 5, 2);
            world.setBlock(i + 8, j + 1, k + 7, Blocks.air, 0, 2);
            world.setBlock(i + 9, j + 1, k + 7, Blocks.air, 0, 2);
            world.setBlock(i + 10, j + 1, k + 7, placeBuildingBlock(random), 0, 2);
            world.setBlock(i + 11, j + 1, k + 7, placeBuildingBlock(random), 0, 2);
            world.setBlock(i + 12, j + 1, k + 7, Blocks.lava, 0, 2);
            world.setBlock(i + 13, j + 1, k + 7, placeBuildingBlock(random), 0, 2);
            world.setBlock(i + 14, j + 1, k + 7, placeBuildingBlock(random), 0, 2);
            world.setBlock(i + 15, j + 1, k + 7, Blocks.air, 0, 2);
            world.setBlock(i + 16, j + 1, k + 7, Blocks.air, 0, 2);
            world.setBlock(i + 17, j + 1, k + 7, placeBuildingBlockStairs(random), 0, 2);
            world.setBlock(i + 18, j + 1, k + 7, placeBuildingBlock(random), 0, 2);
            world.setBlock(i + 19, j + 1, k + 7, placeBuildingBlock(random), 0, 2);
            world.setBlock(i + 20, j + 1, k + 7, placeBuildingBlock(random), 0, 2);
            world.setBlock(i + 3, j + 1, k + 8, NovaCraftBlocks.sculk_block, 0, 2);
            world.setBlock(i + 4, j + 1, k + 8, Blocks.air, 0, 2);
            world.setBlock(i + 5, j + 1, k + 8, Blocks.air, 0, 2);
            world.setBlock(i + 6, j + 1, k + 8, placeBuildingBlockSlab(random), 5, 2);
            world.setBlock(i + 7, j + 1, k + 8, Blocks.air, 0, 2);
            world.setBlock(i + 8, j + 1, k + 8, Blocks.air, 0, 2);
            world.setBlock(i + 9, j + 1, k + 8, Blocks.air, 0, 2);
            world.setBlock(i + 10, j + 1, k + 8, Blocks.air, 0, 2);
            world.setBlock(i + 11, j + 1, k + 8, placeBuildingBlock(random), 0, 2);
            world.setBlock(i + 12, j + 1, k + 8, placeBuildingBlock(random), 0, 2);
            world.setBlock(i + 13, j + 1, k + 8, placeBuildingBlock(random), 0, 2);
            world.setBlock(i + 14, j + 1, k + 8, Blocks.air, 0, 2);
            world.setBlock(i + 15, j + 1, k + 8, Blocks.air, 0, 2);
            world.setBlock(i + 16, j + 1, k + 8, Blocks.air, 0, 2);
            world.setBlock(i + 17, j + 1, k + 8, placeBuildingBlock(random), 0, 2);
            world.setBlock(i + 18, j + 1, k + 8, placeBuildingBlock(random), 0, 2);
            world.setBlock(i + 19, j + 1, k + 8, placeBuildingBlock(random), 0, 2);
            world.setBlock(i + 4, j + 1, k + 9, NovaCraftBlocks.sculk_block, 0, 2);
            world.setBlock(i + 5, j + 1, k + 9, Blocks.air, 0, 2);
            world.setBlock(i + 6, j + 1, k + 9, Blocks.air, 0, 2);
            world.setBlock(i + 7, j + 1, k + 9, Blocks.air, 0, 2);
            world.setBlock(i + 8, j + 1, k + 9, Blocks.air, 0, 2);
            world.setBlock(i + 9, j + 1, k + 9, Blocks.air, 0, 2);
            world.setBlock(i + 10, j + 1, k + 9, Blocks.air, 0, 2);
            world.setBlock(i + 11, j + 1, k + 9, Blocks.air, 0, 2);
            world.setBlock(i + 12, j + 1, k + 9, Blocks.air, 0, 2);
            world.setBlock(i + 13, j + 1, k + 9, Blocks.air, 0, 2);
            world.setBlock(i + 14, j + 1, k + 9, Blocks.air, 0, 2);
            world.setBlock(i + 15, j + 1, k + 9, Blocks.air, 0, 2);
            world.setBlock(i + 16, j + 1, k + 9, Blocks.air, 0, 2);
            world.setBlock(i + 17, j + 1, k + 9, placeBuildingBlock(random), 0, 2);
            world.setBlock(i + 5, j + 1, k + 10, placeBuildingBlock(random), 0, 2);
            world.setBlock(i + 6, j + 1, k + 10, Blocks.air, 0, 2);
            world.setBlock(i + 7, j + 1, k + 10, Blocks.air, 0, 2);
            world.setBlock(i + 8, j + 1, k + 10, Blocks.air, 0, 2);
            world.setBlock(i + 9, j + 1, k + 10, Blocks.air, 0, 2);
            world.setBlock(i + 10, j + 1, k + 10, Blocks.air, 0, 2);
            world.setBlock(i + 11, j + 1, k + 10, Blocks.air, 0, 2);
            world.setBlock(i + 12, j + 1, k + 10, Blocks.air, 0, 2);
            world.setBlock(i + 13, j + 1, k + 10, Blocks.air, 0, 2);
            world.setBlock(i + 14, j + 1, k + 10, Blocks.air, 0, 2);
            world.setBlock(i + 15, j + 1, k + 10, Blocks.air, 0, 2);
            world.setBlock(i + 16, j + 1, k + 10, placeBuildingBlock(random), 0, 2);
            world.setBlock(i + 6, j + 1, k + 11, placeBuildingBlock(random), 0, 2);
            world.setBlock(i + 7, j + 1, k + 11, NovaCraftBlocks.sculk_block, 0, 2);
            world.setBlock(i + 8, j + 1, k + 11, NovaCraftBlocks.sculk_block, 0, 2);
            world.setBlock(i + 9, j + 1, k + 11, NovaCraftBlocks.sculk_block, 0, 2);
            world.setBlock(i + 10, j + 1, k + 11, NovaCraftBlocks.sculk_block, 0, 2);
            world.setBlock(i + 11, j + 1, k + 11, placeBuildingBlock(random), 0, 2);
            world.setBlock(i + 12, j + 1, k + 11, placeBuildingBlock(random), 0, 2);
            world.setBlock(i + 13, j + 1, k + 11, placeBuildingBlock(random), 0, 2);
            world.setBlock(i + 14, j + 1, k + 11, placeBuildingBlock(random), 0, 2);
            world.setBlock(i + 15, j + 1, k + 11, placeBuildingBlock(random), 0, 2);
            world.setBlock(i + 6, j + 2, k + 1, placeBuildingBlock(random), 0, 2);
            world.setBlock(i + 7, j + 2, k + 1, placeBuildingBlock(random), 0, 2);
            world.setBlock(i + 8, j + 2, k + 1, placeBuildingBlock(random), 0, 2);
            world.setBlock(i + 9, j + 2, k + 1, NovaCraftBlocks.sculk_block, 0, 2);
            world.setBlock(i + 10, j + 2, k + 1, placeBuildingBlock(random), 0, 2);
            world.setBlock(i + 11, j + 2, k + 1, placeBuildingBlock(random), 0, 2);
            world.setBlock(i + 12, j + 2, k + 1, placeBuildingBlock(random), 0, 2);
            world.setBlock(i + 13, j + 2, k + 1, placeBuildingBlock(random), 0, 2);
            world.setBlock(i + 14, j + 2, k + 1, placeBuildingBlock(random), 0, 2);
            world.setBlock(i + 15, j + 2, k + 1, placeBuildingBlock(random), 0, 2);
            world.setBlock(i + 5, j + 2, k + 2, placeBuildingBlock(random), 0, 2);
            world.setBlock(i + 6, j + 2, k + 2, Blocks.air, 0, 2);
            world.setBlock(i + 7, j + 2, k + 2, NovaCraftBlocks.dim_vanite_torch, 3, 2);
            world.setBlock(i + 8, j + 2, k + 2, Blocks.air, 0, 2);
            world.setBlock(i + 9, j + 2, k + 2, Blocks.air, 0, 2);
            world.setBlock(i + 10, j + 2, k + 2, Blocks.air, 0, 2);
            world.setBlock(i + 11, j + 2, k + 2, Blocks.air, 0, 2);
            world.setBlock(i + 12, j + 2, k + 2, Blocks.air, 0, 2);
            world.setBlock(i + 13, j + 2, k + 2, Blocks.air, 0, 2);
            world.setBlock(i + 14, j + 2, k + 2, NovaCraftBlocks.dim_vanite_torch, 3, 2);
            world.setBlock(i + 15, j + 2, k + 2, Blocks.air, 0, 2);
            world.setBlock(i + 16, j + 2, k + 2, placeBuildingBlock(random), 0, 2);
            world.setBlock(i + 4, j + 2, k + 3, placeBuildingBlock(random), 0, 2);
            world.setBlock(i + 5, j + 2, k + 3, Blocks.air, 0, 2);
            world.setBlock(i + 6, j + 2, k + 3, Blocks.air, 0, 2);
            world.setBlock(i + 7, j + 2, k + 3, Blocks.air, 0, 2);
            world.setBlock(i + 8, j + 2, k + 3, Blocks.air, 0, 2);
            world.setBlock(i + 9, j + 2, k + 3, Blocks.air, 0, 2);
            world.setBlock(i + 10, j + 2, k + 3, Blocks.air, 0, 2);
            world.setBlock(i + 11, j + 2, k + 3, Blocks.air, 0, 2);
            world.setBlock(i + 12, j + 2, k + 3, Blocks.air, 0, 2);
            world.setBlock(i + 13, j + 2, k + 3, Blocks.air, 0, 2);
            world.setBlock(i + 14, j + 2, k + 3, Blocks.air, 0, 2);
            world.setBlock(i + 15, j + 2, k + 3, Blocks.air, 0, 2);
            world.setBlock(i + 16, j + 2, k + 3, Blocks.air, 0, 2);
            world.setBlock(i + 17, j + 2, k + 3, placeBuildingBlock(random), 0, 2);
            world.setBlock(i + 3, j + 2, k + 4, placeBuildingBlock(random), 0, 2);
            world.setBlock(i + 4, j + 2, k + 4, Blocks.air, 0, 2);
            world.setBlock(i + 5, j + 2, k + 4, Blocks.air, 0, 2);
            world.setBlock(i + 6, j + 2, k + 4, Blocks.air, 0, 2);
            world.setBlock(i + 7, j + 2, k + 4, Blocks.air, 0, 2);
            world.setBlock(i + 8, j + 2, k + 4, Blocks.air, 0, 2);
            world.setBlock(i + 9, j + 2, k + 4, Blocks.air, 0, 2);
            world.setBlock(i + 10, j + 2, k + 4, Blocks.air, 0, 2);
            world.setBlock(i + 11, j + 2, k + 4, placeBuildingBlock(random), 0, 2);
            world.setBlock(i + 12, j + 2, k + 4, placeBuildingBlock(random), 0, 2);
            world.setBlock(i + 13, j + 2, k + 4, Blocks.air, 0, 2);
            world.setBlock(i + 14, j + 2, k + 4, Blocks.air, 0, 2);
            world.setBlock(i + 15, j + 2, k + 4, Blocks.air, 0, 2);
            world.setBlock(i + 16, j + 2, k + 4, Blocks.air, 0, 2);
            world.setBlock(i + 17, j + 2, k + 4, placeBuildingBlock(random), 0, 2);
            world.setBlock(i + 18, j + 2, k + 4, placeBuildingBlock(random), 0, 2);
            world.setBlock(i + 19, j + 2, k + 4, placeBuildingBlock(random), 0, 2);
            world.setBlock(i + 2, j + 2, k + 5, placeBuildingBlock(random), 0, 2);
            world.setBlock(i + 3, j + 2, k + 5, Blocks.air, 0, 2);
            world.setBlock(i + 4, j + 2, k + 5, Blocks.air, 0, 2);
            world.setBlock(i + 5, j + 2, k + 5, Blocks.air, 0, 2);
            world.setBlock(i + 6, j + 2, k + 5, Blocks.air, 0, 2);
            world.setBlock(i + 7, j + 2, k + 5, Blocks.air, 0, 2);
            world.setBlock(i + 8, j + 2, k + 5, Blocks.air, 0, 2);
            world.setBlock(i + 9, j + 2, k + 5, Blocks.air, 0, 2);
            world.setBlock(i + 10, j + 2, k + 5, placeBuildingBlock(random), 0, 2);
            world.setBlock(i + 11, j + 2, k + 5, placeBuildingBlock(random), 0, 2);
            world.setBlock(i + 12, j + 2, k + 5, Blocks.lava, 0, 2);
            world.setBlock(i + 13, j + 2, k + 5, placeBuildingBlock(random), 0, 2);
            world.setBlock(i + 14, j + 2, k + 5, Blocks.air, 0, 2);
            world.setBlock(i + 15, j + 2, k + 5, Blocks.air, 0, 2);
            world.setBlock(i + 16, j + 2, k + 5, Blocks.air, 0, 2);
            world.setBlock(i + 17, j + 2, k + 5, Blocks.air, 0, 2);
            world.setBlock(i + 18, j + 2, k + 5, placeBuildingBlock(random), 0, 2);
            world.setBlock(i + 19, j + 2, k + 5, placeBuildingBlock(random), 0, 2);
            world.setBlock(i + 20, j + 2, k + 5, placeBuildingBlock(random), 0, 2);
            world.setBlock(i + 1, j + 2, k + 6, placeBuildingBlock(random), 0, 2);
            world.setBlock(i + 2, j + 2, k + 6, placeBuildingBlock(random), 0, 2);
            world.setBlock(i + 3, j + 2, k + 6, NovaCraftBlocks.dim_vanite_torch, 1, 2);
            world.setBlock(i + 4, j + 2, k + 6, Blocks.air, 0, 2);
            world.setBlock(i + 5, j + 2, k + 6, Blocks.air, 0, 2);
            world.setBlock(i + 7, j + 2, k + 6, Blocks.air, 0, 2);
            world.setBlock(i + 8, j + 2, k + 6, Blocks.air, 0, 2);
            world.setBlock(i + 9, j + 2, k + 6, NovaCraftBlocks.dim_vanite_torch, 2, 2);
            world.setBlock(i + 10, j + 2, k + 6, placeBuildingBlock(random), 0, 2);
            world.setBlock(i + 11, j + 2, k + 6, Blocks.lava, 0, 2);
            world.setBlock(i + 12, j + 2, k + 6, Blocks.lava, 0, 2);
            world.setBlock(i + 13, j + 2, k + 6, Blocks.lava, 0, 2);
            world.setBlock(i + 14, j + 2, k + 6, placeBuildingBlock(random), 0, 2);
            world.setBlock(i + 15, j + 2, k + 6, NovaCraftBlocks.dim_vanite_torch, 1, 2);
            world.setBlock(i + 16, j + 2, k + 6, Blocks.air, 0, 2);
            world.setBlock(i + 17, j + 2, k + 6, Blocks.air, 0, 2);
            world.setBlock(i + 18, j + 2, k + 6, PlaceBasalt, 1, 2);
            world.setBlock(i + 19, j + 2, k + 6, placeBuildingBlock(random), 0, 2);
            world.setBlock(i + 20, j + 2, k + 6, placeBuildingBlock(random), 0, 2);
            world.setBlock(i + 2, j + 2, k + 7, placeBuildingBlock(random), 0, 2);
            world.setBlock(i + 3, j + 2, k + 7, Blocks.air, 0, 2);
            world.setBlock(i + 4, j + 2, k + 7, Blocks.air, 0, 2);
            world.setBlock(i + 5, j + 2, k + 7, Blocks.air, 0, 2);
            world.setBlock(i + 6, j + 2, k + 7, Blocks.air, 0, 2);
            world.setBlock(i + 7, j + 2, k + 7, Blocks.air, 0, 2);
            world.setBlock(i + 8, j + 2, k + 7, Blocks.air, 0, 2);
            world.setBlock(i + 9, j + 2, k + 7, Blocks.air, 0, 2);
            world.setBlock(i + 10, j + 2, k + 7, placeBuildingBlock(random), 0, 2);
            world.setBlock(i + 11, j + 2, k + 7, placeBuildingBlock(random), 0, 2);
            world.setBlock(i + 12, j + 2, k + 7, Blocks.lava, 0, 2);
            world.setBlock(i + 13, j + 2, k + 7, placeBuildingBlock(random), 0, 2);
            world.setBlock(i + 14, j + 2, k + 7, placeBuildingBlock(random), 0, 2);
            world.setBlock(i + 15, j + 2, k + 7, Blocks.air, 0, 2);
            world.setBlock(i + 16, j + 2, k + 7, Blocks.air, 0, 2);
            world.setBlock(i + 17, j + 2, k + 7, Blocks.air, 0, 2);
            world.setBlock(i + 18, j + 2, k + 7, Blocks.air, 0, 2);
            world.setBlock(i + 19, j + 2, k + 7, placeBuildingBlockStairs(random), 0, 2);
            world.setBlock(i + 20, j + 2, k + 7, placeBuildingBlock(random), 0, 2);
            world.setBlock(i + 3, j + 2, k + 8, placeBuildingBlock(random), 0, 2);
            world.setBlock(i + 4, j + 2, k + 8, Blocks.air, 0, 2);
            world.setBlock(i + 5, j + 2, k + 8, Blocks.air, 0, 2);
            world.setBlock(i + 6, j + 2, k + 8, Blocks.air, 0, 2);
            world.setBlock(i + 7, j + 2, k + 8, Blocks.air, 0, 2);
            world.setBlock(i + 9, j + 2, k + 8, Blocks.air, 0, 2);
            world.setBlock(i + 10, j + 2, k + 8, Blocks.air, 0, 2);
            world.setBlock(i + 11, j + 2, k + 8, placeBuildingBlock(random), 0, 2);
            world.setBlock(i + 12, j + 2, k + 8, placeBuildingBlock(random), 0, 2);
            world.setBlock(i + 13, j + 2, k + 8, placeBuildingBlock(random), 0, 2);
            world.setBlock(i + 14, j + 2, k + 8, Blocks.air, 0, 2);
            world.setBlock(i + 15, j + 2, k + 8, Blocks.air, 0, 2);
            world.setBlock(i + 16, j + 2, k + 8, Blocks.air, 0, 2);
            world.setBlock(i + 17, j + 2, k + 8, placeBuildingBlock(random), 0, 2);
            world.setBlock(i + 18, j + 2, k + 8, placeBuildingBlock(random), 0, 2);
            world.setBlock(i + 19, j + 2, k + 8, placeBuildingBlock(random), 0, 2);
            world.setBlock(i + 4, j + 2, k + 9, placeBuildingBlock(random), 0, 2);
            world.setBlock(i + 5, j + 2, k + 9, Blocks.air, 0, 2);
            world.setBlock(i + 6, j + 2, k + 9, Blocks.air, 0, 2);
            world.setBlock(i + 7, j + 2, k + 9, Blocks.air, 0, 2);
            world.setBlock(i + 8, j + 2, k + 9, Blocks.air, 0, 2);
            world.setBlock(i + 9, j + 2, k + 9, Blocks.air, 0, 2);
            world.setBlock(i + 10, j + 2, k + 9, Blocks.air, 0, 2);
            world.setBlock(i + 11, j + 2, k + 9, Blocks.air, 0, 2);
            world.setBlock(i + 12, j + 2, k + 9, Blocks.air, 0, 2);
            world.setBlock(i + 13, j + 2, k + 9, Blocks.air, 0, 2);
            world.setBlock(i + 14, j + 2, k + 9, Blocks.air, 0, 2);
            world.setBlock(i + 15, j + 2, k + 9, Blocks.air, 0, 2);
            world.setBlock(i + 16, j + 2, k + 9, Blocks.air, 0, 2);
            world.setBlock(i + 17, j + 2, k + 9, placeBuildingBlock(random), 0, 2);
            world.setBlock(i + 5, j + 2, k + 10, placeBuildingBlock(random), 0, 2);
            world.setBlock(i + 6, j + 2, k + 10, Blocks.air, 0, 2);
            world.setBlock(i + 7, j + 2, k + 10, NovaCraftBlocks.dim_vanite_torch, 4, 2);
            world.setBlock(i + 8, j + 2, k + 10, Blocks.air, 0, 2);
            world.setBlock(i + 9, j + 2, k + 10, Blocks.air, 0, 2);
            world.setBlock(i + 10, j + 2, k + 10, Blocks.air, 0, 2);
            world.setBlock(i + 11, j + 2, k + 10, Blocks.air, 0, 2);
            world.setBlock(i + 12, j + 2, k + 10, Blocks.air, 0, 2);
            world.setBlock(i + 13, j + 2, k + 10, Blocks.air, 0, 2);
            world.setBlock(i + 14, j + 2, k + 10, NovaCraftBlocks.dim_vanite_torch, 4, 2);
            world.setBlock(i + 15, j + 2, k + 10, Blocks.air, 0, 2);
            world.setBlock(i + 16, j + 2, k + 10, placeBuildingBlock(random), 0, 2);
            world.setBlock(i + 6, j + 2, k + 11, placeBuildingBlock(random), 0, 2);
            world.setBlock(i + 7, j + 2, k + 11, placeBuildingBlock(random), 0, 2);
            world.setBlock(i + 8, j + 2, k + 11, NovaCraftBlocks.sculk_block, 0, 2);
            world.setBlock(i + 9, j + 2, k + 11, NovaCraftBlocks.sculk_block, 0, 2);
            world.setBlock(i + 10, j + 2, k + 11, NovaCraftBlocks.sculk_block, 0, 2);
            world.setBlock(i + 11, j + 2, k + 11, placeBuildingBlock(random), 0, 2);
            world.setBlock(i + 12, j + 2, k + 11, placeBuildingBlock(random), 0, 2);
            world.setBlock(i + 13, j + 2, k + 11, placeBuildingBlock(random), 0, 2);
            world.setBlock(i + 14, j + 2, k + 11, placeBuildingBlock(random), 0, 2);
            world.setBlock(i + 15, j + 2, k + 11, placeBuildingBlock(random), 0, 2);
            world.setBlock(i + 6, j + 3, k + 1, placeBuildingBlock(random), 0, 2);
            world.setBlock(i + 7, j + 3, k + 1, placeBuildingBlock(random), 0, 2);
            world.setBlock(i + 8, j + 3, k + 1, placeBuildingBlock(random), 0, 2);
            world.setBlock(i + 9, j + 3, k + 1, placeBuildingBlock(random), 0, 2);
            world.setBlock(i + 10, j + 3, k + 1, placeBuildingBlock(random), 0, 2);
            world.setBlock(i + 11, j + 3, k + 1, placeBuildingBlock(random), 0, 2);
            world.setBlock(i + 12, j + 3, k + 1, placeBuildingBlock(random), 0, 2);
            world.setBlock(i + 13, j + 3, k + 1, placeBuildingBlock(random), 0, 2);
            world.setBlock(i + 14, j + 3, k + 1, placeBuildingBlock(random), 0, 2);
            world.setBlock(i + 15, j + 3, k + 1, placeBuildingBlock(random), 0, 2);
            world.setBlock(i + 5, j + 3, k + 2, placeBuildingBlock(random), 0, 2);
            world.setBlock(i + 6, j + 3, k + 2, Blocks.air, 0, 2);
            world.setBlock(i + 7, j + 3, k + 2, Blocks.air, 0, 2);
            world.setBlock(i + 8, j + 3, k + 2, Blocks.air, 0, 2);
            world.setBlock(i + 9, j + 3, k + 2, Blocks.air, 0, 2);
            world.setBlock(i + 10, j + 3, k + 2, Blocks.air, 0, 2);
            world.setBlock(i + 11, j + 3, k + 2, Blocks.air, 0, 2);
            world.setBlock(i + 12, j + 3, k + 2, Blocks.air, 0, 2);
            world.setBlock(i + 13, j + 3, k + 2, Blocks.air, 0, 2);
            world.setBlock(i + 14, j + 3, k + 2, Blocks.air, 0, 2);
            world.setBlock(i + 15, j + 3, k + 2, Blocks.air, 0, 2);
            world.setBlock(i + 16, j + 3, k + 2, placeBuildingBlock(random), 0, 2);
            world.setBlock(i + 4, j + 3, k + 3, placeBuildingBlock(random), 0, 2);
            world.setBlock(i + 5, j + 3, k + 3, Blocks.air, 0, 2);
            world.setBlock(i + 6, j + 3, k + 3, Blocks.air, 0, 2);
            world.setBlock(i + 7, j + 3, k + 3, Blocks.air, 0, 2);
            world.setBlock(i + 8, j + 3, k + 3, Blocks.air, 0, 2);
            world.setBlock(i + 9, j + 3, k + 3, Blocks.air, 0, 2);
            world.setBlock(i + 10, j + 3, k + 3, Blocks.air, 0, 2);
            world.setBlock(i + 11, j + 3, k + 3, Blocks.air, 0, 2);
            world.setBlock(i + 12, j + 3, k + 3, Blocks.air, 0, 2);
            world.setBlock(i + 13, j + 3, k + 3, Blocks.air, 0, 2);
            world.setBlock(i + 14, j + 3, k + 3, Blocks.air, 0, 2);
            world.setBlock(i + 15, j + 3, k + 3, Blocks.air, 0, 2);
            world.setBlock(i + 16, j + 3, k + 3, Blocks.air, 0, 2);
            world.setBlock(i + 17, j + 3, k + 3, placeBuildingBlock(random), 0, 2);
            world.setBlock(i + 3, j + 3, k + 4, placeBuildingBlock(random), 0, 2);
            world.setBlock(i + 4, j + 3, k + 4, Blocks.air, 0, 2);
            world.setBlock(i + 5, j + 3, k + 4, Blocks.air, 0, 2);
            world.setBlock(i + 6, j + 3, k + 4, Blocks.air, 0, 2);
            world.setBlock(i + 7, j + 3, k + 4, Blocks.air, 0, 2);
            world.setBlock(i + 8, j + 3, k + 4, Blocks.air, 0, 2);
            world.setBlock(i + 9, j + 3, k + 4, Blocks.air, 0, 2);
            world.setBlock(i + 10, j + 3, k + 4, Blocks.air, 0, 2);
            world.setBlock(i + 11, j + 3, k + 4, placeBuildingBlock(random), 0, 2);
            world.setBlock(i + 12, j + 3, k + 4, placeBuildingBlock(random), 0, 2);
            world.setBlock(i + 13, j + 3, k + 4, Blocks.air, 0, 2);
            world.setBlock(i + 14, j + 3, k + 4, Blocks.air, 0, 2);
            world.setBlock(i + 15, j + 3, k + 4, Blocks.air, 0, 2);
            world.setBlock(i + 16, j + 3, k + 4, Blocks.air, 0, 2);
            world.setBlock(i + 17, j + 3, k + 4, placeBuildingBlock(random), 0, 2);
            world.setBlock(i + 18, j + 3, k + 4, placeBuildingBlock(random), 0, 2);
            world.setBlock(i + 19, j + 3, k + 4, placeBuildingBlock(random), 0, 2);
            world.setBlock(i + 2, j + 3, k + 5, placeBuildingBlock(random), 0, 2);
            world.setBlock(i + 3, j + 3, k + 5, Blocks.air, 0, 2);
            world.setBlock(i + 4, j + 3, k + 5, Blocks.air, 0, 2);
            world.setBlock(i + 5, j + 3, k + 5, Blocks.air, 0, 2);
            world.setBlock(i + 6, j + 3, k + 5, Blocks.air, 0, 2);
            world.setBlock(i + 7, j + 3, k + 5, Blocks.air, 0, 2);
            world.setBlock(i + 8, j + 3, k + 5, Blocks.air, 0, 2);
            world.setBlock(i + 9, j + 3, k + 5, Blocks.air, 0, 2);
            world.setBlock(i + 10, j + 3, k + 5, placeBuildingBlock(random), 0, 2);
            world.setBlock(i + 11, j + 3, k + 5, placeBuildingBlock(random), 0, 2);
            world.setBlock(i + 12, j + 3, k + 5, Blocks.lava, 0, 2);
            world.setBlock(i + 13, j + 3, k + 5, placeBuildingBlock(random), 0, 2);
            world.setBlock(i + 14, j + 3, k + 5, Blocks.air, 0, 2);
            world.setBlock(i + 15, j + 3, k + 5, Blocks.air, 0, 2);
            world.setBlock(i + 16, j + 3, k + 5, Blocks.air, 0, 2);
            world.setBlock(i + 17, j + 3, k + 5, placeBuildingBlock(random), 0, 2);
            world.setBlock(i + 18, j + 3, k + 5, placeBuildingBlock(random), 0, 2);
            world.setBlock(i + 19, j + 3, k + 5, placeBuildingBlockStairs(random), 3, 2);
            world.setBlock(i + 20, j + 3, k + 5, placeBuildingBlock(random), 0, 2);
            world.setBlock(i + 1, j + 3, k + 6, placeBuildingBlock(random), 0, 2);
            world.setBlock(i + 2, j + 3, k + 6, placeBuildingBlock(random), 0, 2);
            world.setBlock(i + 3, j + 3, k + 6, Blocks.air, 0, 2);
            world.setBlock(i + 4, j + 3, k + 6, Blocks.air, 0, 2);
            world.setBlock(i + 5, j + 3, k + 6, Blocks.air, 0, 2);
            world.setBlock(i + 6, j + 3, k + 6, Blocks.air, 0, 2);
            world.setBlock(i + 7, j + 3, k + 6, Blocks.air, 0, 2);
            world.setBlock(i + 8, j + 3, k + 6, Blocks.air, 0, 2);
            world.setBlock(i + 9, j + 3, k + 6, Blocks.air, 0, 2);
            world.setBlock(i + 10, j + 3, k + 6, placeBuildingBlock(random), 0, 2);
            world.setBlock(i + 11, j + 3, k + 6, Blocks.lava, 0, 2);
            world.setBlock(i + 12, j + 3, k + 6, Blocks.lava, 0, 2);
            world.setBlock(i + 13, j + 3, k + 6, Blocks.lava, 0, 2);
            world.setBlock(i + 14, j + 3, k + 6, placeBuildingBlock(random), 0, 2);
            world.setBlock(i + 15, j + 3, k + 6, Blocks.air, 0, 2);
            world.setBlock(i + 16, j + 3, k + 6, Blocks.air, 0, 2);
            world.setBlock(i + 17, j + 3, k + 6, Blocks.air, 0, 2);
            world.setBlock(i + 18, j + 3, k + 6, PlaceBasalt, 1, 2);
            world.setBlock(i + 19, j + 3, k + 6, Blocks.air, 0, 2);
            world.setBlock(i + 20, j + 3, k + 6, placeBuildingBlock(random), 0, 2);
            world.setBlock(i + 2, j + 3, k + 7, placeBuildingBlock(random), 0, 2);
            world.setBlock(i + 3, j + 3, k + 7, Blocks.air, 0, 2);
            world.setBlock(i + 4, j + 3, k + 7, Blocks.air, 0, 2);
            world.setBlock(i + 5, j + 3, k + 7, Blocks.air, 0, 2);
            world.setBlock(i + 6, j + 3, k + 7, Blocks.air, 0, 2);
            world.setBlock(i + 7, j + 3, k + 7, Blocks.air, 0, 2);
            world.setBlock(i + 8, j + 3, k + 7, Blocks.air, 0, 2);
            world.setBlock(i + 9, j + 3, k + 7, Blocks.air, 0, 2);
            world.setBlock(i + 10, j + 3, k + 7, placeBuildingBlock(random), 0, 2);
            world.setBlock(i + 11, j + 3, k + 7, placeBuildingBlock(random), 0, 2);
            world.setBlock(i + 12, j + 3, k + 7, Blocks.lava, 0, 2);
            world.setBlock(i + 13, j + 3, k + 7, placeBuildingBlock(random), 0, 2);
            world.setBlock(i + 14, j + 3, k + 7, placeBuildingBlock(random), 0, 2);
            world.setBlock(i + 15, j + 3, k + 7, Blocks.air, 0, 2);
            world.setBlock(i + 16, j + 3, k + 7, Blocks.air, 0, 2);
            world.setBlock(i + 17, j + 3, k + 7, Blocks.air, 0, 2);
            world.setBlock(i + 18, j + 3, k + 7, Blocks.air, 0, 2);
            world.setBlock(i + 19, j + 3, k + 7, Blocks.air, 0, 2);
            world.setBlock(i + 20, j + 3, k + 7, placeBuildingBlock(random), 0, 2);
            world.setBlock(i + 3, j + 3, k + 8, placeBuildingBlock(random), 0, 2);
            world.setBlock(i + 4, j + 3, k + 8, Blocks.air, 0, 2);
            world.setBlock(i + 5, j + 3, k + 8, Blocks.air, 0, 2);
            world.setBlock(i + 6, j + 3, k + 8, Blocks.air, 0, 2);
            world.setBlock(i + 7, j + 3, k + 8, Blocks.air, 0, 2);
            world.setBlock(i + 8, j + 3, k + 8, Blocks.air, 0, 2);
            world.setBlock(i + 9, j + 3, k + 8, Blocks.air, 0, 2);
            world.setBlock(i + 10, j + 3, k + 8, Blocks.air, 0, 2);
            world.setBlock(i + 11, j + 3, k + 8, placeBuildingBlock(random), 0, 2);
            world.setBlock(i + 12, j + 3, k + 8, placeBuildingBlock(random), 0, 2);
            world.setBlock(i + 13, j + 3, k + 8, placeBuildingBlock(random), 0, 2);
            world.setBlock(i + 14, j + 3, k + 8, Blocks.air, 0, 2);
            world.setBlock(i + 15, j + 3, k + 8, Blocks.air, 0, 2);
            world.setBlock(i + 16, j + 3, k + 8, Blocks.air, 0, 2);
            world.setBlock(i + 17, j + 3, k + 8, placeBuildingBlock(random), 0, 2);
            world.setBlock(i + 18, j + 3, k + 8, placeBuildingBlock(random), 0, 2);
            world.setBlock(i + 19, j + 3, k + 8, placeBuildingBlock(random), 0, 2);
            world.setBlock(i + 4, j + 3, k + 9, placeBuildingBlock(random), 0, 2);
            world.setBlock(i + 5, j + 3, k + 9, Blocks.air, 0, 2);
            world.setBlock(i + 6, j + 3, k + 9, Blocks.air, 0, 2);
            world.setBlock(i + 7, j + 3, k + 9, Blocks.air, 0, 2);
            world.setBlock(i + 8, j + 3, k + 9, Blocks.air, 0, 2);
            world.setBlock(i + 9, j + 3, k + 9, Blocks.air, 0, 2);
            world.setBlock(i + 10, j + 3, k + 9, Blocks.air, 0, 2);
            world.setBlock(i + 11, j + 3, k + 9, Blocks.air, 0, 2);
            world.setBlock(i + 12, j + 3, k + 9, Blocks.air, 0, 2);
            world.setBlock(i + 13, j + 3, k + 9, Blocks.air, 0, 2);
            world.setBlock(i + 14, j + 3, k + 9, Blocks.air, 0, 2);
            world.setBlock(i + 15, j + 3, k + 9, Blocks.air, 0, 2);
            world.setBlock(i + 16, j + 3, k + 9, Blocks.air, 0, 2);
            world.setBlock(i + 17, j + 3, k + 9, placeBuildingBlock(random), 0, 2);
            world.setBlock(i + 5, j + 3, k + 10, placeBuildingBlock(random), 0, 2);
            world.setBlock(i + 6, j + 3, k + 10, Blocks.air, 0, 2);
            world.setBlock(i + 7, j + 3, k + 10, Blocks.air, 0, 2);
            world.setBlock(i + 8, j + 3, k + 10, Blocks.air, 0, 2);
            world.setBlock(i + 9, j + 3, k + 10, Blocks.air, 0, 2);
            world.setBlock(i + 10, j + 3, k + 10, Blocks.air, 0, 2);
            world.setBlock(i + 11, j + 3, k + 10, Blocks.air, 0, 2);
            world.setBlock(i + 12, j + 3, k + 10, Blocks.air, 0, 2);
            world.setBlock(i + 13, j + 3, k + 10, Blocks.air, 0, 2);
            world.setBlock(i + 14, j + 3, k + 10, Blocks.air, 0, 2);
            world.setBlock(i + 15, j + 3, k + 10, Blocks.air, 0, 2);
            world.setBlock(i + 16, j + 3, k + 10, placeBuildingBlock(random), 0, 2);
            world.setBlock(i + 6, j + 3, k + 11, placeBuildingBlock(random), 0, 2);
            world.setBlock(i + 7, j + 3, k + 11, placeBuildingBlock(random), 0, 2);
            world.setBlock(i + 8, j + 3, k + 11, placeBuildingBlock(random), 0, 2);
            world.setBlock(i + 9, j + 3, k + 11, NovaCraftBlocks.sculk_block, 0, 2);
            world.setBlock(i + 10, j + 3, k + 11, placeBuildingBlock(random), 0, 2);
            world.setBlock(i + 11, j + 3, k + 11, placeBuildingBlock(random), 0, 2);
            world.setBlock(i + 12, j + 3, k + 11, placeBuildingBlock(random), 0, 2);
            world.setBlock(i + 13, j + 3, k + 11, placeBuildingBlock(random), 0, 2);
            world.setBlock(i + 14, j + 3, k + 11, placeBuildingBlock(random), 0, 2);
            world.setBlock(i + 15, j + 3, k + 11, placeBuildingBlock(random), 0, 2);
            world.setBlock(i + 6, j + 4, k + 1, placeBuildingBlock(random), 0, 2);
            world.setBlock(i + 7, j + 4, k + 1, placeBuildingBlock(random), 0, 2);
            world.setBlock(i + 8, j + 4, k + 1, placeBuildingBlock(random), 0, 2);
            world.setBlock(i + 9, j + 4, k + 1, placeBuildingBlock(random), 0, 2);
            world.setBlock(i + 10, j + 4, k + 1, placeBuildingBlock(random), 0, 2);
            world.setBlock(i + 11, j + 4, k + 1, placeBuildingBlock(random), 0, 2);
            world.setBlock(i + 12, j + 4, k + 1, placeBuildingBlock(random), 0, 2);
            world.setBlock(i + 13, j + 4, k + 1, placeBuildingBlock(random), 0, 2);
            world.setBlock(i + 14, j + 4, k + 1, placeBuildingBlock(random), 0, 2);
            world.setBlock(i + 15, j + 4, k + 1, placeBuildingBlock(random), 0, 2);
            world.setBlock(i + 5, j + 4, k + 2, placeBuildingBlock(random), 0, 2);
            world.setBlock(i + 6, j + 4, k + 2, placeBuildingBlock(random), 0, 2);
            world.setBlock(i + 7, j + 4, k + 2, placeBuildingBlock(random), 0, 2);
            world.setBlock(i + 8, j + 4, k + 2, placeBuildingBlock(random), 0, 2);
            world.setBlock(i + 9, j + 4, k + 2, placeBuildingBlock(random), 0, 2);
            world.setBlock(i + 10, j + 4, k + 2, placeBuildingBlock(random), 0, 2);
            world.setBlock(i + 11, j + 4, k + 2, placeBuildingBlock(random), 0, 2);
            world.setBlock(i + 12, j + 4, k + 2, placeBuildingBlock(random), 0, 2);
            world.setBlock(i + 13, j + 4, k + 2, placeBuildingBlock(random), 0, 2);
            world.setBlock(i + 14, j + 4, k + 2, placeBuildingBlock(random), 0, 2);
            world.setBlock(i + 15, j + 4, k + 2, placeBuildingBlock(random), 0, 2);
            world.setBlock(i + 16, j + 4, k + 2, placeBuildingBlock(random), 0, 2);
            world.setBlock(i + 4, j + 4, k + 3, placeBuildingBlock(random), 0, 2);
            world.setBlock(i + 5, j + 4, k + 3, placeBuildingBlock(random), 0, 2);
            world.setBlock(i + 6, j + 4, k + 3, placeBuildingBlock(random), 0, 2);
            world.setBlock(i + 7, j + 4, k + 3, placeBuildingBlock(random), 0, 2);
            world.setBlock(i + 8, j + 4, k + 3, placeBuildingBlock(random), 0, 2);
            world.setBlock(i + 9, j + 4, k + 3, placeBuildingBlock(random), 0, 2);
            world.setBlock(i + 10, j + 4, k + 3, placeBuildingBlock(random), 0, 2);
            world.setBlock(i + 11, j + 4, k + 3, placeBuildingBlock(random), 0, 2);
            world.setBlock(i + 12, j + 4, k + 3, placeBuildingBlock(random), 0, 2);
            world.setBlock(i + 13, j + 4, k + 3, placeBuildingBlock(random), 0, 2);
            world.setBlock(i + 14, j + 4, k + 3, placeBuildingBlock(random), 0, 2);
            world.setBlock(i + 15, j + 4, k + 3, placeBuildingBlock(random), 0, 2);
            world.setBlock(i + 16, j + 4, k + 3, placeBuildingBlock(random), 0, 2);
            world.setBlock(i + 17, j + 4, k + 3, placeBuildingBlock(random), 0, 2);
            world.setBlock(i + 3, j + 4, k + 4, placeBuildingBlock(random), 0, 2);
            world.setBlock(i + 4, j + 4, k + 4, placeBuildingBlock(random), 0, 2);
            world.setBlock(i + 5, j + 4, k + 4, placeBuildingBlock(random), 0, 2);
            world.setBlock(i + 6, j + 4, k + 4, placeBuildingBlock(random), 0, 2);
            world.setBlock(i + 7, j + 4, k + 4, placeBuildingBlock(random), 0, 2);
            world.setBlock(i + 8, j + 4, k + 4, placeBuildingBlock(random), 0, 2);
            world.setBlock(i + 9, j + 4, k + 4, placeBuildingBlock(random), 0, 2);
            world.setBlock(i + 10, j + 4, k + 4, placeBuildingBlock(random), 0, 2);
            world.setBlock(i + 11, j + 4, k + 4, placeBuildingBlock(random), 0, 2);
            world.setBlock(i + 12, j + 4, k + 4, Blocks.lava, 0, 2);
            world.setBlock(i + 13, j + 4, k + 4, placeBuildingBlock(random), 0, 2);
            world.setBlock(i + 14, j + 4, k + 4, placeBuildingBlock(random), 0, 2);
            world.setBlock(i + 15, j + 4, k + 4, placeBuildingBlock(random), 0, 2);
            world.setBlock(i + 16, j + 4, k + 4, placeBuildingBlock(random), 0, 2);
            world.setBlock(i + 17, j + 4, k + 4, placeBuildingBlock(random), 0, 2);
            world.setBlock(i + 18, j + 4, k + 4, placeBuildingBlock(random), 0, 2);
            world.setBlock(i + 19, j + 4, k + 4, placeBuildingBlock(random), 0, 2);
            world.setBlock(i + 2, j + 4, k + 5, placeBuildingBlock(random), 0, 2);
            world.setBlock(i + 3, j + 4, k + 5, placeBuildingBlock(random), 0, 2);
            world.setBlock(i + 4, j + 4, k + 5, placeBuildingBlock(random), 0, 2);
            world.setBlock(i + 5, j + 4, k + 5, placeBuildingBlock(random), 0, 2);
            world.setBlock(i + 6, j + 4, k + 5, placeBuildingBlock(random), 0, 2);
            world.setBlock(i + 7, j + 4, k + 5, placeBuildingBlock(random), 0, 2);
            world.setBlock(i + 8, j + 4, k + 5, placeBuildingBlock(random), 0, 2);
            world.setBlock(i + 9, j + 4, k + 5, placeBuildingBlock(random), 0, 2);
            world.setBlock(i + 10, j + 4, k + 5, placeBuildingBlock(random), 0, 2);
            world.setBlock(i + 11, j + 4, k + 5, Blocks.lava, 0, 2);
            world.setBlock(i + 12, j + 4, k + 5, Blocks.lava, 0, 2);
            world.setBlock(i + 13, j + 4, k + 5, Blocks.lava, 0, 2);
            world.setBlock(i + 14, j + 4, k + 5, placeBuildingBlock(random), 0, 2);
            world.setBlock(i + 15, j + 4, k + 5, placeBuildingBlock(random), 0, 2);
            world.setBlock(i + 16, j + 4, k + 5, placeBuildingBlock(random), 0, 2);
            world.setBlock(i + 17, j + 4, k + 5, placeBuildingBlockStairs(random), 1, 2);
            world.setBlock(i + 18, j + 4, k + 5, Blocks.air, 0, 2);
            world.setBlock(i + 19, j + 4, k + 5, Blocks.air, 0, 2);
            world.setBlock(i + 20, j + 4, k + 5, placeBuildingBlock(random), 0, 2);
            world.setBlock(i + 1, j + 4, k + 6, placeBuildingBlock(random), 0, 2);
            world.setBlock(i + 2, j + 4, k + 6, placeBuildingBlock(random), 0, 2);
            world.setBlock(i + 3, j + 4, k + 6, placeBuildingBlock(random), 0, 2);
            world.setBlock(i + 4, j + 4, k + 6, placeBuildingBlock(random), 0, 2);
            world.setBlock(i + 5, j + 4, k + 6, placeBuildingBlock(random), 0, 2);
            world.setBlock(i + 6, j + 4, k + 6, placeBuildingBlock(random), 0, 2);
            world.setBlock(i + 7, j + 4, k + 6, placeBuildingBlock(random), 0, 2);
            world.setBlock(i + 8, j + 4, k + 6, placeBuildingBlock(random), 0, 2);
            world.setBlock(i + 9, j + 4, k + 6, placeBuildingBlock(random), 0, 2);
            world.setBlock(i + 10, j + 4, k + 6, Blocks.lava, 0, 2);
            world.setBlock(i + 11, j + 4, k + 6, Blocks.lava, 0, 2);
            world.setBlock(i + 12, j + 4, k + 6, Blocks.lava, 0, 2);
            world.setBlock(i + 13, j + 4, k + 6, Blocks.lava, 0, 2);
            world.setBlock(i + 14, j + 4, k + 6, Blocks.lava, 0, 2);
            world.setBlock(i + 15, j + 4, k + 6, placeBuildingBlock(random), 0, 2);
            world.setBlock(i + 16, j + 4, k + 6, placeBuildingBlock(random), 0, 2);
            world.setBlock(i + 17, j + 4, k + 6, placeBuildingBlock(random), 0, 2);
            world.setBlock(i + 18, j + 4, k + 6, PlaceBasalt, 1, 2);
            world.setBlock(i + 19, j + 4, k + 6, Blocks.air, 0, 2);
            world.setBlock(i + 20, j + 4, k + 6, placeBuildingBlock(random), 0, 2);
            world.setBlock(i + 2, j + 4, k + 7, placeBuildingBlock(random), 0, 2);
            world.setBlock(i + 3, j + 4, k + 7, placeBuildingBlock(random), 0, 2);
            world.setBlock(i + 4, j + 4, k + 7, placeBuildingBlock(random), 0, 2);
            world.setBlock(i + 5, j + 4, k + 7, placeBuildingBlock(random), 0, 2);
            world.setBlock(i + 6, j + 4, k + 7, placeBuildingBlock(random), 0, 2);
            world.setBlock(i + 7, j + 4, k + 7, placeBuildingBlock(random), 0, 2);
            world.setBlock(i + 8, j + 4, k + 7, placeBuildingBlock(random), 0, 2);
            world.setBlock(i + 9, j + 4, k + 7, placeBuildingBlock(random), 0, 2);
            world.setBlock(i + 10, j + 4, k + 7, placeBuildingBlock(random), 0, 2);
            world.setBlock(i + 11, j + 4, k + 7, Blocks.lava, 0, 2);
            world.setBlock(i + 12, j + 4, k + 7, Blocks.lava, 0, 2);
            world.setBlock(i + 13, j + 4, k + 7, Blocks.lava, 0, 2);
            world.setBlock(i + 14, j + 4, k + 7, placeBuildingBlock(random), 0, 2);
            world.setBlock(i + 15, j + 4, k + 7, placeBuildingBlock(random), 0, 2);
            world.setBlock(i + 16, j + 4, k + 7, placeBuildingBlock(random), 0, 2);
            world.setBlock(i + 17, j + 4, k + 7, placeBuildingBlock(random), 0, 2);
            world.setBlock(i + 18, j + 4, k + 7, Blocks.air, 0, 2);
            world.setBlock(i + 19, j + 4, k + 7, Blocks.air, 0, 2);
            world.setBlock(i + 20, j + 4, k + 7, placeBuildingBlock(random), 0, 2);
            world.setBlock(i + 3, j + 4, k + 8, placeBuildingBlock(random), 0, 2);
            world.setBlock(i + 4, j + 4, k + 8, placeBuildingBlock(random), 0, 2);
            world.setBlock(i + 5, j + 4, k + 8, placeBuildingBlock(random), 0, 2);
            world.setBlock(i + 6, j + 4, k + 8, placeBuildingBlock(random), 0, 2);
            world.setBlock(i + 7, j + 4, k + 8, placeBuildingBlock(random), 0, 2);
            world.setBlock(i + 8, j + 4, k + 8, placeBuildingBlock(random), 0, 2);
            world.setBlock(i + 9, j + 4, k + 8, placeBuildingBlock(random), 0, 2);
            world.setBlock(i + 10, j + 4, k + 8, placeBuildingBlock(random), 0, 2);
            world.setBlock(i + 11, j + 4, k + 8, placeBuildingBlock(random), 0, 2);
            world.setBlock(i + 12, j + 4, k + 8, Blocks.lava, 0, 2);
            world.setBlock(i + 13, j + 4, k + 8, placeBuildingBlock(random), 0, 2);
            world.setBlock(i + 14, j + 4, k + 8, placeBuildingBlock(random), 0, 2);
            world.setBlock(i + 15, j + 4, k + 8, placeBuildingBlock(random), 0, 2);
            world.setBlock(i + 16, j + 4, k + 8, placeBuildingBlock(random), 0, 2);
            world.setBlock(i + 17, j + 4, k + 8, placeBuildingBlock(random), 0, 2);
            world.setBlock(i + 18, j + 4, k + 8, placeBuildingBlock(random), 0, 2);
            world.setBlock(i + 19, j + 4, k + 8, placeBuildingBlock(random), 0, 2);
            world.setBlock(i + 4, j + 4, k + 9, placeBuildingBlock(random), 0, 2);
            world.setBlock(i + 5, j + 4, k + 9, placeBuildingBlock(random), 0, 2);
            world.setBlock(i + 6, j + 4, k + 9, placeBuildingBlock(random), 0, 2);
            world.setBlock(i + 7, j + 4, k + 9, placeBuildingBlock(random), 0, 2);
            world.setBlock(i + 8, j + 4, k + 9, placeBuildingBlock(random), 0, 2);
            world.setBlock(i + 9, j + 4, k + 9, placeBuildingBlock(random), 0, 2);
            world.setBlock(i + 10, j + 4, k + 9, placeBuildingBlock(random), 0, 2);
            world.setBlock(i + 11, j + 4, k + 9, placeBuildingBlock(random), 0, 2);
            world.setBlock(i + 12, j + 4, k + 9, placeBuildingBlock(random), 0, 2);
            world.setBlock(i + 13, j + 4, k + 9, placeBuildingBlock(random), 0, 2);
            world.setBlock(i + 14, j + 4, k + 9, placeBuildingBlock(random), 0, 2);
            world.setBlock(i + 15, j + 4, k + 9, placeBuildingBlock(random), 0, 2);
            world.setBlock(i + 16, j + 4, k + 9, placeBuildingBlock(random), 0, 2);
            world.setBlock(i + 5, j + 4, k + 10, placeBuildingBlock(random), 0, 2);
            world.setBlock(i + 6, j + 4, k + 10, placeBuildingBlock(random), 0, 2);
            world.setBlock(i + 7, j + 4, k + 10, placeBuildingBlock(random), 0, 2);
            world.setBlock(i + 8, j + 4, k + 10, placeBuildingBlock(random), 0, 2);
            world.setBlock(i + 9, j + 4, k + 10, placeBuildingBlock(random), 0, 2);
            world.setBlock(i + 10, j + 4, k + 10, placeBuildingBlock(random), 0, 2);
            world.setBlock(i + 11, j + 4, k + 10, placeBuildingBlock(random), 0, 2);
            world.setBlock(i + 12, j + 4, k + 10, placeBuildingBlock(random), 0, 2);
            world.setBlock(i + 13, j + 4, k + 10, placeBuildingBlock(random), 0, 2);
            world.setBlock(i + 14, j + 4, k + 10, placeBuildingBlock(random), 0, 2);
            world.setBlock(i + 15, j + 4, k + 10, placeBuildingBlock(random), 0, 2);
            world.setBlock(i + 6, j + 4, k + 11, placeBuildingBlock(random), 0, 2);
            world.setBlock(i + 7, j + 4, k + 11, placeBuildingBlock(random), 0, 2);
            world.setBlock(i + 8, j + 4, k + 11, placeBuildingBlock(random), 0, 2);
            world.setBlock(i + 9, j + 4, k + 11, placeBuildingBlock(random), 0, 2);
            world.setBlock(i + 12, j + 4, k + 11, placeBuildingBlock(random), 0, 2);
            world.setBlock(i + 12, j + 4, k + 12, placeBuildingBlock(random), 0, 2);
            world.setBlock(i + 6, j + 5, k + 1, placeBuildingBlock(random), 0, 2);
            world.setBlock(i + 7, j + 5, k + 1, placeBuildingBlock(random), 0, 2);
            world.setBlock(i + 8, j + 5, k + 1, placeBuildingBlock(random), 0, 2);
            world.setBlock(i + 5, j + 5, k + 2, placeBuildingBlock(random), 0, 2);
            world.setBlock(i + 6, j + 5, k + 2, Blocks.air, 0, 2);
            world.setBlock(i + 7, j + 5, k + 2, Blocks.air, 0, 2);
            world.setBlock(i + 9, j + 5, k + 2, placeBuildingBlock(random), 0, 2);
            world.setBlock(i + 10, j + 5, k + 2, placeBuildingBlock(random), 0, 2);
            world.setBlock(i + 11, j + 5, k + 2, placeBuildingBlock(random), 0, 2);
            world.setBlock(i + 12, j + 5, k + 2, placeBuildingBlock(random), 0, 2);
            world.setBlock(i + 13, j + 5, k + 2, placeBuildingBlock(random), 0, 2);
            world.setBlock(i + 14, j + 5, k + 2, placeBuildingBlock(random), 0, 2);
            world.setBlock(i + 4, j + 5, k + 3, placeBuildingBlock(random), 0, 2);
            world.setBlock(i + 5, j + 5, k + 3, Blocks.air, 0, 2);
            world.setBlock(i + 6, j + 5, k + 3, Blocks.air, 0, 2);
            world.setBlock(i + 7, j + 5, k + 3, Blocks.air, 0, 2);
            world.setBlock(i + 8, j + 5, k + 3, Blocks.air, 0, 2);
            world.setBlock(i + 9, j + 5, k + 3, placeBuildingBlock(random), 0, 2);
            world.setBlock(i + 10, j + 5, k + 3, Blocks.air, 0, 2);
            world.setBlock(i + 11, j + 5, k + 3, Blocks.air, 0, 2);
            world.setBlock(i + 12, j + 5, k + 3, Blocks.air, 0, 2);
            world.setBlock(i + 13, j + 5, k + 3, Blocks.air, 0, 2);
            world.setBlock(i + 14, j + 5, k + 3, Blocks.air, 0, 2);
            world.setBlock(i + 15, j + 5, k + 3, placeBuildingBlock(random), 0, 2);
            world.setBlock(i + 3, j + 5, k + 4, placeBuildingBlock(random), 0, 2);
            world.setBlock(i + 4, j + 5, k + 4, Blocks.air, 0, 2);
            world.setBlock(i + 5, j + 5, k + 4, Blocks.air, 0, 2);
            world.setBlock(i + 6, j + 5, k + 4, Blocks.air, 0, 2);
            world.setBlock(i + 7, j + 5, k + 4, Blocks.air, 0, 2);
            world.setBlock(i + 8, j + 5, k + 4, PlaceBasalt, 1, 2);
            world.setBlock(i + 9, j + 5, k + 4, Blocks.air, 0, 2);
            world.setBlock(i + 10, j + 5, k + 4, Blocks.air, 0, 2);
            world.setBlock(i + 11, j + 5, k + 4, Blocks.air, 0, 2);
            world.setBlock(i + 12, j + 5, k + 4, Blocks.air, 0, 2);
            world.setBlock(i + 13, j + 5, k + 4, Blocks.air, 0, 2);
            world.setBlock(i + 14, j + 5, k + 4, Blocks.air, 0, 2);
            world.setBlock(i + 15, j + 5, k + 4, Blocks.air, 0, 2);
            world.setBlock(i + 16, j + 5, k + 4, placeBuildingBlock(random), 0, 2);
            world.setBlock(i + 17, j + 5, k + 4, placeBuildingBlock(random), 0, 2);
            world.setBlock(i + 18, j + 5, k + 4, placeBuildingBlock(random), 0, 2);
            world.setBlock(i + 19, j + 5, k + 4, placeBuildingBlock(random), 0, 2);
            world.setBlock(i + 2, j + 5, k + 5, placeBuildingBlock(random), 0, 2);
            world.setBlock(i + 3, j + 5, k + 5, placeBuildingBlock(random), 0, 2);
            world.setBlock(i + 4, j + 5, k + 5, Blocks.air, 0, 2);
            world.setBlock(i + 5, j + 5, k + 5, Blocks.air, 0, 2);
            world.setBlock(i + 6, j + 5, k + 5, Blocks.air, 0, 2);
            world.setBlock(i + 7, j + 5, k + 5, Blocks.air, 0, 2);
            world.setBlock(i + 8, j + 5, k + 5, Blocks.air, 0, 2);
            world.setBlock(i + 9, j + 5, k + 5, Blocks.air, 0, 2);
            world.setBlock(i + 10, j + 5, k + 5, Blocks.air, 0, 2);
            world.setBlock(i + 11, j + 5, k + 5, Blocks.air, 0, 2);
            world.setBlock(i + 12, j + 5, k + 5, Blocks.air, 0, 2);
            world.setBlock(i + 13, j + 5, k + 5, Blocks.air, 0, 2);
            world.setBlock(i + 14, j + 5, k + 5, Blocks.air, 0, 2);
            world.setBlock(i + 15, j + 5, k + 5, Blocks.air, 0, 2);
            world.setBlock(i + 16, j + 5, k + 5, Blocks.air, 0, 2);
            world.setBlock(i + 17, j + 5, k + 5, Blocks.air, 0, 2);
            world.setBlock(i + 18, j + 5, k + 5, Blocks.air, 0, 2);
            world.setBlock(i + 19, j + 5, k + 5, Blocks.air, 0, 2);
            world.setBlock(i + 20, j + 5, k + 5, placeBuildingBlock(random), 0, 2);
            world.setBlock(i + 1, j + 5, k + 6, placeBuildingBlock(random), 0, 2);
            world.setBlock(i + 2, j + 5, k + 6, placeBuildingBlock(random), 0, 2);
            world.setBlock(i + 3, j + 5, k + 6, placeBuildingBlock(random), 0, 2);
            world.setBlock(i + 4, j + 5, k + 6, placeBuildingBlock(random), 0, 2);
            world.setBlock(i + 5, j + 5, k + 6, Blocks.air, 0, 2);
            world.setBlock(i + 6, j + 5, k + 6, Blocks.air, 0, 2);
            world.setBlock(i + 7, j + 5, k + 6, Blocks.air, 0, 2);
            world.setBlock(i + 8, j + 5, k + 6, Blocks.air, 0, 2);
            world.setBlock(i + 9, j + 5, k + 6, Blocks.air, 0, 2);
            world.setBlock(i + 10, j + 5, k + 6, Blocks.air, 0, 2);
            world.setBlock(i + 11, j + 5, k + 6, Blocks.air, 0, 2);
            world.setBlock(i + 12, j + 5, k + 6, Blocks.air, 0, 2);
            world.setBlock(i + 13, j + 5, k + 6, Blocks.air, 0, 2);
            world.setBlock(i + 14, j + 5, k + 6, Blocks.air, 0, 2);
            world.setBlock(i + 15, j + 5, k + 6, Blocks.air, 0, 2);
            world.setBlock(i + 16, j + 5, k + 6, Blocks.air, 0, 2);
            world.setBlock(i + 17, j + 5, k + 6, Blocks.air, 0, 2);
            world.setBlock(i + 18, j + 5, k + 6, PlaceBasalt, 1, 2);
            world.setBlock(i + 19, j + 5, k + 6, Blocks.air, 0, 2);
            world.setBlock(i + 20, j + 5, k + 6, placeBuildingBlock(random), 0, 2);
            world.setBlock(i + 2, j + 5, k + 7, placeBuildingBlock(random), 0, 2);
            world.setBlock(i + 3, j + 5, k + 7, placeBuildingBlock(random), 0, 2);
            world.setBlock(i + 4, j + 5, k + 7, Blocks.air, 0, 2);
            world.setBlock(i + 5, j + 5, k + 7, Blocks.air, 0, 2);
            world.setBlock(i + 6, j + 5, k + 7, Blocks.air, 0, 2);
            world.setBlock(i + 7, j + 5, k + 7, Blocks.air, 0, 2);
            world.setBlock(i + 8, j + 5, k + 7, Blocks.air, 0, 2);
            world.setBlock(i + 9, j + 5, k + 7, Blocks.air, 0, 2);
            world.setBlock(i + 10, j + 5, k + 7, Blocks.air, 0, 2);
            world.setBlock(i + 11, j + 5, k + 7, Blocks.air, 0, 2);
            world.setBlock(i + 12, j + 5, k + 7, Blocks.air, 0, 2);
            world.setBlock(i + 13, j + 5, k + 7, Blocks.air, 0, 2);
            world.setBlock(i + 14, j + 5, k + 7, Blocks.air, 0, 2);
            world.setBlock(i + 15, j + 5, k + 7, Blocks.air, 0, 2);
            world.setBlock(i + 16, j + 5, k + 7, Blocks.air, 0, 2);
            world.setBlock(i + 17, j + 5, k + 7, Blocks.air, 0, 2);
            world.setBlock(i + 18, j + 5, k + 7, Blocks.air, 0, 2);
            world.setBlock(i + 19, j + 5, k + 7, Blocks.air, 0, 2);
            world.setBlock(i + 20, j + 5, k + 7, placeBuildingBlock(random), 0, 2);
            world.setBlock(i + 3, j + 5, k + 8, placeBuildingBlock(random), 0, 2);
            world.setBlock(i + 4, j + 5, k + 8, Blocks.air, 0, 2);
            world.setBlock(i + 5, j + 5, k + 8, Blocks.air, 0, 2);
            world.setBlock(i + 6, j + 5, k + 8, Blocks.air, 0, 2);
            world.setBlock(i + 7, j + 5, k + 8, Blocks.air, 0, 2);
            world.setBlock(i + 8, j + 5, k + 8, PlaceBasalt, 1, 2);
            world.setBlock(i + 9, j + 5, k + 8, Blocks.air, 0, 2);
            world.setBlock(i + 10, j + 5, k + 8, Blocks.air, 0, 2);
            world.setBlock(i + 11, j + 5, k + 8, Blocks.air, 0, 2);
            world.setBlock(i + 12, j + 5, k + 8, Blocks.air, 0, 2);
            world.setBlock(i + 13, j + 5, k + 8, Blocks.air, 0, 2);
            world.setBlock(i + 14, j + 5, k + 8, Blocks.air, 0, 2);
            world.setBlock(i + 15, j + 5, k + 8, Blocks.air, 0, 2);
            world.setBlock(i + 16, j + 5, k + 8, placeBuildingBlock(random), 0, 2);
            world.setBlock(i + 17, j + 5, k + 8, placeBuildingBlock(random), 0, 2);
            world.setBlock(i + 18, j + 5, k + 8, placeBuildingBlock(random), 0, 2);
            world.setBlock(i + 19, j + 5, k + 8, placeBuildingBlock(random), 0, 2);
            world.setBlock(i + 4, j + 5, k + 9, placeBuildingBlock(random), 0, 2);
            world.setBlock(i + 5, j + 5, k + 9, Blocks.air, 0, 2);
            world.setBlock(i + 6, j + 5, k + 9, Blocks.air, 0, 2);
            world.setBlock(i + 7, j + 5, k + 9, Blocks.air, 0, 2);
            world.setBlock(i + 8, j + 5, k + 9, Blocks.air, 0, 2);
            world.setBlock(i + 9, j + 5, k + 9, placeBuildingBlock(random), 0, 2);
            world.setBlock(i + 10, j + 5, k + 9, Blocks.air, 0, 2);
            world.setBlock(i + 11, j + 5, k + 9, Blocks.air, 0, 2);
            world.setBlock(i + 12, j + 5, k + 9, Blocks.air, 0, 2);
            world.setBlock(i + 13, j + 5, k + 9, Blocks.air, 0, 2);
            world.setBlock(i + 14, j + 5, k + 9, Blocks.air, 0, 2);
            world.setBlock(i + 15, j + 5, k + 9, placeBuildingBlock(random), 0, 2);
            world.setBlock(i + 5, j + 5, k + 10, placeBuildingBlock(random), 0, 2);
            world.setBlock(i + 6, j + 5, k + 10, Blocks.air, 0, 2);
            world.setBlock(i + 7, j + 5, k + 10, Blocks.air, 0, 2);
            world.setBlock(i + 9, j + 5, k + 10, placeBuildingBlock(random), 0, 2);
            world.setBlock(i + 10, j + 5, k + 10, placeBuildingBlock(random), 0, 2);
            world.setBlock(i + 11, j + 5, k + 10, placeBuildingBlockStairs(random), 2, 2);
            world.setBlock(i + 12, j + 5, k + 10, placeBuildingBlockStairs(random), 2, 2);
            world.setBlock(i + 13, j + 5, k + 10, placeBuildingBlockStairs(random), 2, 2);
            world.setBlock(i + 14, j + 5, k + 10, placeBuildingBlock(random), 0, 2);
            world.setBlock(i + 6, j + 5, k + 11, placeBuildingBlock(random), 0, 2);
            world.setBlock(i + 7, j + 5, k + 11, placeBuildingBlock(random), 0, 2);
            world.setBlock(i + 8, j + 5, k + 11, placeBuildingBlock(random), 0, 2);
            world.setBlock(i + 9, j + 5, k + 11, placeBuildingBlock(random), 0, 2);
            world.setBlock(i + 12, j + 5, k + 11, placeBuildingBlock(random), 0, 2);
            world.setBlock(i + 12, j + 5, k + 12, placeBuildingBlock(random), 0, 2);
            world.setBlock(i + 6, j + 6, k + 1, placeBuildingBlock(random), 0, 2);
            world.setBlock(i + 7, j + 6, k + 1, placeBuildingBlock(random), 0, 2);
            world.setBlock(i + 8, j + 6, k + 1, placeBuildingBlock(random), 0, 2);
            world.setBlock(i + 5, j + 6, k + 2, placeBuildingBlock(random), 0, 2);
            world.setBlock(i + 6, j + 6, k + 2, Blocks.air, 0, 2);
            world.setBlock(i + 7, j + 6, k + 2, Blocks.air, 0, 2);
            world.setBlock(i + 8, j + 6, k + 2, Blocks.air, 0, 2);
            world.setBlock(i + 9, j + 6, k + 2, placeBuildingBlock(random), 0, 2);
            world.setBlock(i + 10, j + 6, k + 2, placeBuildingBlock(random), 0, 2);
            world.setBlock(i + 11, j + 6, k + 2, placeBuildingBlock(random), 0, 2);
            world.setBlock(i + 12, j + 6, k + 2, placeBuildingBlock(random), 0, 2);
            world.setBlock(i + 13, j + 6, k + 2, placeBuildingBlock(random), 0, 2);
            world.setBlock(i + 14, j + 6, k + 2, placeBuildingBlock(random), 0, 2);
            world.setBlock(i + 4, j + 6, k + 3, placeBuildingBlock(random), 0, 2);
            world.setBlock(i + 5, j + 6, k + 3, NovaCraftBlocks.dim_vanite_torch, 3, 2);
            world.setBlock(i + 6, j + 6, k + 3, Blocks.air, 0, 2);
            world.setBlock(i + 7, j + 6, k + 3, Blocks.air, 0, 2);
            world.setBlock(i + 8, j + 6, k + 3, Blocks.air, 0, 2);
            world.setBlock(i + 9, j + 6, k + 3, placeBuildingBlock(random), 0, 2);
            world.setBlock(i + 10, j + 6, k + 3, Blocks.air, 0, 2);
            world.setBlock(i + 11, j + 6, k + 3, Blocks.air, 0, 2);
            world.setBlock(i + 12, j + 6, k + 3, Blocks.air, 0, 2);
            world.setBlock(i + 13, j + 6, k + 3, Blocks.air, 0, 2);
            world.setBlock(i + 14, j + 6, k + 3, Blocks.air, 0, 2);
            world.setBlock(i + 15, j + 6, k + 3, placeBuildingBlock(random), 0, 2);
            world.setBlock(i + 3, j + 6, k + 4, placeBuildingBlock(random), 0, 2);
            world.setBlock(i + 4, j + 6, k + 4, Blocks.air, 0, 2);
            world.setBlock(i + 5, j + 6, k + 4, Blocks.air, 0, 2);
            world.setBlock(i + 6, j + 6, k + 4, Blocks.air, 0, 2);
            world.setBlock(i + 7, j + 6, k + 4, Blocks.air, 0, 2);
            world.setBlock(i + 8, j + 6, k + 4, PlaceBasalt, 1, 2);
            world.setBlock(i + 9, j + 6, k + 4, Blocks.air, 0, 2);
            world.setBlock(i + 10, j + 6, k + 4, Blocks.air, 0, 2);
            world.setBlock(i + 11, j + 6, k + 4, Blocks.air, 0, 2);
            world.setBlock(i + 12, j + 6, k + 4, Blocks.air, 0, 2);
            world.setBlock(i + 13, j + 6, k + 4, Blocks.air, 0, 2);
            world.setBlock(i + 14, j + 6, k + 4, Blocks.air, 0, 2);
            world.setBlock(i + 15, j + 6, k + 4, Blocks.air, 0, 2);
            world.setBlock(i + 16, j + 6, k + 4, placeBuildingBlock(random), 0, 2);
            world.setBlock(i + 17, j + 6, k + 4, placeBuildingBlock(random), 0, 2);
            world.setBlock(i + 18, j + 6, k + 4, placeBuildingBlock(random), 0, 2);
            world.setBlock(i + 19, j + 6, k + 4, placeBuildingBlock(random), 0, 2);
            world.setBlock(i + 2, j + 6, k + 5, placeBuildingBlock(random), 0, 2);
            world.setBlock(i + 4, j + 6, k + 5, Blocks.air, 0, 2);
            world.setBlock(i + 5, j + 6, k + 5, Blocks.air, 0, 2);
            world.setBlock(i + 6, j + 6, k + 5, Blocks.air, 0, 2);
            world.setBlock(i + 7, j + 6, k + 5, Blocks.air, 0, 2);
            world.setBlock(i + 8, j + 6, k + 5, Blocks.air, 0, 2);
            world.setBlock(i + 9, j + 6, k + 5, Blocks.air, 0, 2);
            world.setBlock(i + 10, j + 6, k + 5, Blocks.air, 0, 2);
            world.setBlock(i + 11, j + 6, k + 5, Blocks.air, 0, 2);
            world.setBlock(i + 12, j + 6, k + 5, Blocks.air, 0, 2);
            world.setBlock(i + 13, j + 6, k + 5, Blocks.air, 0, 2);
            world.setBlock(i + 14, j + 6, k + 5, Blocks.air, 0, 2);
            world.setBlock(i + 15, j + 6, k + 5, Blocks.air, 0, 2);
            world.setBlock(i + 16, j + 6, k + 5, Blocks.air, 0, 2);
            world.setBlock(i + 17, j + 6, k + 5, Blocks.air, 0, 2);
            world.setBlock(i + 18, j + 6, k + 5, Blocks.air, 0, 2);
            world.setBlock(i + 19, j + 6, k + 5, Blocks.air, 0, 2);
            world.setBlock(i + 20, j + 6, k + 5, placeBuildingBlock(random), 0, 2);
            world.setBlock(i + 1, j + 6, k + 6, placeBuildingBlock(random), 0, 2);
            world.setBlock(i + 3, j + 6, k + 6, NovaCraftBlocks.block_of_vanite, 0, 2);
            world.setBlock(i + 5, j + 6, k + 6, Blocks.air, 0, 2);
            world.setBlock(i + 6, j + 6, k + 6, Blocks.air, 0, 2);
            world.setBlock(i + 7, j + 6, k + 6, Blocks.air, 0, 2);
            world.setBlock(i + 8, j + 6, k + 6, Blocks.air, 0, 2);
            world.setBlock(i + 9, j + 6, k + 6, Blocks.air, 0, 2);
            world.setBlock(i + 10, j + 6, k + 6, Blocks.air, 0, 2);
            world.setBlock(i + 11, j + 6, k + 6, Blocks.air, 0, 2);
            world.setBlock(i + 12, j + 6, k + 6, Blocks.air, 0, 2);
            world.setBlock(i + 13, j + 6, k + 6, Blocks.air, 0, 2);
            world.setBlock(i + 14, j + 6, k + 6, Blocks.air, 0, 2);
            world.setBlock(i + 15, j + 6, k + 6, Blocks.air, 0, 2);
            world.setBlock(i + 16, j + 6, k + 6, Blocks.air, 0, 2);
            world.setBlock(i + 17, j + 6, k + 6, Blocks.air, 0, 2);
            world.setBlock(i + 18, j + 6, k + 6, PlaceBasalt, 1, 2);
            world.setBlock(i + 19, j + 6, k + 6, Blocks.air, 0, 2);
            world.setBlock(i + 20, j + 6, k + 6, placeBuildingBlock(random), 0, 2);
            world.setBlock(i + 2, j + 6, k + 7, placeBuildingBlock(random), 0, 2);
            world.setBlock(i + 4, j + 6, k + 7, Blocks.air, 0, 2);
            world.setBlock(i + 5, j + 6, k + 7, Blocks.air, 0, 2);
            world.setBlock(i + 6, j + 6, k + 7, Blocks.air, 0, 2);
            world.setBlock(i + 8, j + 6, k + 7, Blocks.air, 0, 2);
            world.setBlock(i + 9, j + 6, k + 7, Blocks.air, 0, 2);
            world.setBlock(i + 10, j + 6, k + 7, Blocks.air, 0, 2);
            world.setBlock(i + 11, j + 6, k + 7, Blocks.air, 0, 2);
            world.setBlock(i + 12, j + 6, k + 7, Blocks.air, 0, 2);
            world.setBlock(i + 13, j + 6, k + 7, Blocks.air, 0, 2);
            world.setBlock(i + 14, j + 6, k + 7, Blocks.air, 0, 2);
            world.setBlock(i + 15, j + 6, k + 7, Blocks.air, 0, 2);
            world.setBlock(i + 16, j + 6, k + 7, Blocks.air, 0, 2);
            world.setBlock(i + 17, j + 6, k + 7, Blocks.air, 0, 2);
            world.setBlock(i + 18, j + 6, k + 7, Blocks.air, 0, 2);
            world.setBlock(i + 19, j + 6, k + 7, Blocks.air, 0, 2);
            world.setBlock(i + 20, j + 6, k + 7, placeBuildingBlock(random), 0, 2);
            world.setBlock(i + 3, j + 6, k + 8, placeBuildingBlock(random), 0, 2);
            world.setBlock(i + 4, j + 6, k + 8, Blocks.air, 0, 2);
            world.setBlock(i + 5, j + 6, k + 8, Blocks.air, 0, 2);
            world.setBlock(i + 6, j + 6, k + 8, Blocks.air, 0, 2);
            world.setBlock(i + 7, j + 6, k + 8, Blocks.air, 0, 2);
            world.setBlock(i + 8, j + 6, k + 8, PlaceBasalt, 1, 2);
            world.setBlock(i + 9, j + 6, k + 8, Blocks.air, 0, 2);
            world.setBlock(i + 10, j + 6, k + 8, Blocks.air, 0, 2);
            world.setBlock(i + 11, j + 6, k + 8, Blocks.air, 0, 2);
            world.setBlock(i + 12, j + 6, k + 8, Blocks.air, 0, 2);
            world.setBlock(i + 13, j + 6, k + 8, Blocks.air, 0, 2);
            world.setBlock(i + 14, j + 6, k + 8, Blocks.air, 0, 2);
            world.setBlock(i + 15, j + 6, k + 8, Blocks.air, 0, 2);
            world.setBlock(i + 16, j + 6, k + 8, placeBuildingBlock(random), 0, 2);
            world.setBlock(i + 17, j + 6, k + 8, placeBuildingBlock(random), 0, 2);
            world.setBlock(i + 18, j + 6, k + 8, placeBuildingBlock(random), 0, 2);
            world.setBlock(i + 19, j + 6, k + 8, placeBuildingBlock(random), 0, 2);
            world.setBlock(i + 4, j + 6, k + 9, placeBuildingBlock(random), 0, 2);
            world.setBlock(i + 5, j + 6, k + 9, NovaCraftBlocks.dim_vanite_torch, 4, 2);
            world.setBlock(i + 6, j + 6, k + 9, Blocks.air, 0, 2);
            world.setBlock(i + 7, j + 6, k + 9, Blocks.air, 0, 2);
            world.setBlock(i + 8, j + 6, k + 9, Blocks.air, 0, 2);
            world.setBlock(i + 9, j + 6, k + 9, placeBuildingBlock(random), 0, 2);
            world.setBlock(i + 10, j + 6, k + 9, Blocks.air, 0, 2);
            world.setBlock(i + 11, j + 6, k + 9, Blocks.air, 0, 2);
            world.setBlock(i + 12, j + 6, k + 9, Blocks.air, 0, 2);
            world.setBlock(i + 13, j + 6, k + 9, Blocks.air, 0, 2);
            world.setBlock(i + 14, j + 6, k + 9, Blocks.air, 0, 2);
            world.setBlock(i + 15, j + 6, k + 9, placeBuildingBlock(random), 0, 2);
            world.setBlock(i + 5, j + 6, k + 10, placeBuildingBlock(random), 0, 2);
            world.setBlock(i + 6, j + 6, k + 10, Blocks.air, 0, 2);
            world.setBlock(i + 7, j + 6, k + 10, Blocks.air, 0, 2);
            world.setBlock(i + 8, j + 6, k + 10, Blocks.air, 0, 2);
            world.setBlock(i + 9, j + 6, k + 10, placeBuildingBlock(random), 0, 2);
            world.setBlock(i + 10, j + 6, k + 10, placeBuildingBlock(random), 0, 2);
            world.setBlock(i + 11, j + 6, k + 10, Blocks.air, 0, 2);
            world.setBlock(i + 12, j + 6, k + 10, Blocks.air, 0, 2);
            world.setBlock(i + 13, j + 6, k + 10, Blocks.air, 0, 2);
            world.setBlock(i + 14, j + 6, k + 10, placeBuildingBlock(random), 0, 2);
            world.setBlock(i + 6, j + 6, k + 11, placeBuildingBlock(random), 0, 2);
            world.setBlock(i + 7, j + 6, k + 11, placeBuildingBlock(random), 0, 2);
            world.setBlock(i + 8, j + 6, k + 11, placeBuildingBlock(random), 0, 2);
            world.setBlock(i + 9, j + 6, k + 11, placeBuildingBlock(random), 0, 2);
            world.setBlock(i + 11, j + 6, k + 11, PlaceBasalt, 1, 2);
            world.setBlock(i + 12, j + 6, k + 11, Blocks.air, 0, 2);
            world.setBlock(i + 13, j + 6, k + 11, PlaceBasalt, 1, 2);
            world.setBlock(i + 11, j + 6, k + 12, placeBuildingBlock(random), 0, 2);
            world.setBlock(i + 12, j + 6, k + 12, placeBuildingBlockStairs(random), 2, 2);
            world.setBlock(i + 13, j + 6, k + 12, placeBuildingBlock(random), 0, 2);
            world.setBlock(i + 12, j + 6, k + 13, placeBuildingBlock(random), 0, 2);
            world.setBlock(i + 6, j + 7, k + 1, placeBuildingBlock(random), 0, 2);
            world.setBlock(i + 7, j + 7, k + 1, placeBuildingBlock(random), 0, 2);
            world.setBlock(i + 8, j + 7, k + 1, placeBuildingBlock(random), 0, 2);
            world.setBlock(i + 5, j + 7, k + 2, placeBuildingBlock(random), 0, 2);
            world.setBlock(i + 6, j + 7, k + 2, Blocks.air, 0, 2);
            world.setBlock(i + 7, j + 7, k + 2, Blocks.air, 0, 2);
            world.setBlock(i + 8, j + 7, k + 2, Blocks.air, 0, 2);
            world.setBlock(i + 9, j + 7, k + 2, placeBuildingBlock(random), 0, 2);
            world.setBlock(i + 10, j + 7, k + 2, placeBuildingBlock(random), 0, 2);
            world.setBlock(i + 11, j + 7, k + 2, placeBuildingBlock(random), 0, 2);
            world.setBlock(i + 12, j + 7, k + 2, placeBuildingBlock(random), 0, 2);
            world.setBlock(i + 13, j + 7, k + 2, placeBuildingBlock(random), 0, 2);
            world.setBlock(i + 14, j + 7, k + 2, placeBuildingBlock(random), 0, 2);
            world.setBlock(i + 4, j + 7, k + 3, placeBuildingBlock(random), 0, 2);
            world.setBlock(i + 5, j + 7, k + 3, Blocks.air, 0, 2);
            world.setBlock(i + 6, j + 7, k + 3, Blocks.air, 0, 2);
            world.setBlock(i + 7, j + 7, k + 3, Blocks.air, 0, 2);
            world.setBlock(i + 8, j + 7, k + 3, Blocks.air, 0, 2);
            world.setBlock(i + 9, j + 7, k + 3, placeBuildingBlock(random), 0, 2);
            world.setBlock(i + 10, j + 7, k + 3, Blocks.air, 0, 2);
            world.setBlock(i + 11, j + 7, k + 3, Blocks.air, 0, 2);
            world.setBlock(i + 12, j + 7, k + 3, Blocks.air, 0, 2);
            world.setBlock(i + 13, j + 7, k + 3, Blocks.air, 0, 2);
            world.setBlock(i + 14, j + 7, k + 3, Blocks.air, 0, 2);
            world.setBlock(i + 15, j + 7, k + 3, placeBuildingBlock(random), 0, 2);
            world.setBlock(i + 3, j + 7, k + 4, placeBuildingBlock(random), 0, 2);
            world.setBlock(i + 4, j + 7, k + 4, Blocks.air, 0, 2);
            world.setBlock(i + 5, j + 7, k + 4, Blocks.air, 0, 2);
            world.setBlock(i + 6, j + 7, k + 4, Blocks.air, 0, 2);
            world.setBlock(i + 7, j + 7, k + 4, Blocks.air, 0, 2);
            world.setBlock(i + 8, j + 7, k + 4, PlaceBasalt, 1, 2);
            world.setBlock(i + 9, j + 7, k + 4, Blocks.air, 0, 2);
            world.setBlock(i + 10, j + 7, k + 4, Blocks.air, 0, 2);
            world.setBlock(i + 11, j + 7, k + 4, Blocks.air, 0, 2);
            world.setBlock(i + 12, j + 7, k + 4, Blocks.air, 0, 2);
            world.setBlock(i + 13, j + 7, k + 4, Blocks.air, 0, 2);
            world.setBlock(i + 14, j + 7, k + 4, Blocks.air, 0, 2);
            world.setBlock(i + 15, j + 7, k + 4, Blocks.air, 0, 2);
            world.setBlock(i + 16, j + 7, k + 4, placeBuildingBlock(random), 0, 2);
            world.setBlock(i + 17, j + 7, k + 4, placeBuildingBlock(random), 0, 2);
            world.setBlock(i + 18, j + 7, k + 4, placeBuildingBlock(random), 0, 2);
            world.setBlock(i + 19, j + 7, k + 4, placeBuildingBlock(random), 0, 2);
            world.setBlock(i + 2, j + 7, k + 5, placeBuildingBlock(random), 0, 2);
            world.setBlock(i + 3, j + 7, k + 5, Blocks.air, 0, 2);
            world.setBlock(i + 4, j + 7, k + 5, Blocks.air, 0, 2);
            world.setBlock(i + 5, j + 7, k + 5, Blocks.air, 0, 2);
            world.setBlock(i + 6, j + 7, k + 5, Blocks.air, 0, 2);
            world.setBlock(i + 7, j + 7, k + 5, Blocks.air, 0, 2);
            world.setBlock(i + 8, j + 7, k + 5, Blocks.air, 0, 2);
            world.setBlock(i + 9, j + 7, k + 5, Blocks.air, 0, 2);
            world.setBlock(i + 10, j + 7, k + 5, Blocks.air, 0, 2);
            world.setBlock(i + 11, j + 7, k + 5, Blocks.air, 0, 2);
            world.setBlock(i + 12, j + 7, k + 5, Blocks.air, 0, 2);
            world.setBlock(i + 13, j + 7, k + 5, Blocks.air, 0, 2);
            world.setBlock(i + 14, j + 7, k + 5, Blocks.air, 0, 2);
            world.setBlock(i + 15, j + 7, k + 5, Blocks.air, 0, 2);
            world.setBlock(i + 16, j + 7, k + 5, Blocks.air, 0, 2);
            world.setBlock(i + 17, j + 7, k + 5, Blocks.air, 0, 2);
            world.setBlock(i + 18, j + 7, k + 5, Blocks.air, 0, 2);
            world.setBlock(i + 19, j + 7, k + 5, Blocks.air, 0, 2);
            world.setBlock(i + 20, j + 7, k + 5, placeBuildingBlock(random), 0, 2);
            world.setBlock(i + 1, j + 7, k + 6, placeBuildingBlock(random), 0, 2);
            world.setBlock(i + 4, j + 7, k + 6, Blocks.air, 0, 2);
            world.setBlock(i + 5, j + 7, k + 6, Blocks.air, 0, 2);
            world.setBlock(i + 6, j + 7, k + 6, Blocks.air, 0, 2);
            world.setBlock(i + 7, j + 7, k + 6, Blocks.air, 0, 2);
            world.setBlock(i + 8, j + 7, k + 6, Blocks.air, 0, 2);
            world.setBlock(i + 9, j + 7, k + 6, Blocks.air, 0, 2);
            world.setBlock(i + 10, j + 7, k + 6, Blocks.air, 0, 2);
            world.setBlock(i + 11, j + 7, k + 6, Blocks.air, 0, 2);
            world.setBlock(i + 12, j + 7, k + 6, Blocks.air, 0, 2);
            world.setBlock(i + 13, j + 7, k + 6, Blocks.air, 0, 2);
            world.setBlock(i + 14, j + 7, k + 6, Blocks.air, 0, 2);
            world.setBlock(i + 15, j + 7, k + 6, Blocks.air, 0, 2);
            world.setBlock(i + 16, j + 7, k + 6, Blocks.air, 0, 2);
            world.setBlock(i + 17, j + 7, k + 6, Blocks.air, 0, 2);
            world.setBlock(i + 18, j + 7, k + 6, PlaceBasalt, 1, 2);
            world.setBlock(i + 19, j + 7, k + 6, Blocks.air, 0, 2);
            world.setBlock(i + 20, j + 7, k + 6, placeBuildingBlock(random), 0, 2);
            world.setBlock(i + 2, j + 7, k + 7, placeBuildingBlock(random), 0, 2);
            world.setBlock(i + 3, j + 7, k + 7, Blocks.air, 0, 2);
            world.setBlock(i + 4, j + 7, k + 7, Blocks.air, 0, 2);
            world.setBlock(i + 5, j + 7, k + 7, Blocks.air, 0, 2);
            world.setBlock(i + 6, j + 7, k + 7, Blocks.air, 0, 2);
            world.setBlock(i + 7, j + 7, k + 7, Blocks.air, 0, 2);
            world.setBlock(i + 8, j + 7, k + 7, Blocks.air, 0, 2);
            world.setBlock(i + 9, j + 7, k + 7, Blocks.air, 0, 2);
            world.setBlock(i + 10, j + 7, k + 7, Blocks.air, 0, 2);
            world.setBlock(i + 11, j + 7, k + 7, Blocks.air, 0, 2);
            world.setBlock(i + 12, j + 7, k + 7, Blocks.air, 0, 2);
            world.setBlock(i + 13, j + 7, k + 7, Blocks.air, 0, 2);
            world.setBlock(i + 14, j + 7, k + 7, Blocks.air, 0, 2);
            world.setBlock(i + 15, j + 7, k + 7, Blocks.air, 0, 2);
            world.setBlock(i + 16, j + 7, k + 7, Blocks.air, 0, 2);
            world.setBlock(i + 17, j + 7, k + 7, Blocks.air, 0, 2);
            world.setBlock(i + 18, j + 7, k + 7, Blocks.air, 0, 2);
            world.setBlock(i + 19, j + 7, k + 7, Blocks.air, 0, 2);
            world.setBlock(i + 20, j + 7, k + 7, placeBuildingBlock(random), 0, 2);
            world.setBlock(i + 3, j + 7, k + 8, placeBuildingBlock(random), 0, 2);
            world.setBlock(i + 4, j + 7, k + 8, Blocks.air, 0, 2);
            world.setBlock(i + 5, j + 7, k + 8, Blocks.air, 0, 2);
            world.setBlock(i + 6, j + 7, k + 8, Blocks.air, 0, 2);
            world.setBlock(i + 7, j + 7, k + 8, Blocks.air, 0, 2);
            world.setBlock(i + 8, j + 7, k + 8, PlaceBasalt, 1, 2);
            world.setBlock(i + 9, j + 7, k + 8, Blocks.air, 0, 2);
            world.setBlock(i + 10, j + 7, k + 8, Blocks.air, 0, 2);
            world.setBlock(i + 11, j + 7, k + 8, Blocks.air, 0, 2);
            world.setBlock(i + 12, j + 7, k + 8, Blocks.air, 0, 2);
            world.setBlock(i + 13, j + 7, k + 8, Blocks.air, 0, 2);
            world.setBlock(i + 14, j + 7, k + 8, Blocks.air, 0, 2);
            world.setBlock(i + 15, j + 7, k + 8, Blocks.air, 0, 2);
            world.setBlock(i + 16, j + 7, k + 8, placeBuildingBlock(random), 0, 2);
            world.setBlock(i + 17, j + 7, k + 8, placeBuildingBlock(random), 0, 2);
            world.setBlock(i + 18, j + 7, k + 8, placeBuildingBlock(random), 0, 2);
            world.setBlock(i + 19, j + 7, k + 8, placeBuildingBlock(random), 0, 2);
            world.setBlock(i + 4, j + 7, k + 9, placeBuildingBlock(random), 0, 2);
            world.setBlock(i + 5, j + 7, k + 9, Blocks.air, 0, 2);
            world.setBlock(i + 6, j + 7, k + 9, Blocks.air, 0, 2);
            world.setBlock(i + 7, j + 7, k + 9, Blocks.air, 0, 2);
            world.setBlock(i + 8, j + 7, k + 9, Blocks.air, 0, 2);
            world.setBlock(i + 9, j + 7, k + 9, placeBuildingBlock(random), 0, 2);
            world.setBlock(i + 10, j + 7, k + 9, Blocks.air, 0, 2);
            world.setBlock(i + 11, j + 7, k + 9, Blocks.air, 0, 2);
            world.setBlock(i + 12, j + 7, k + 9, Blocks.air, 0, 2);
            world.setBlock(i + 13, j + 7, k + 9, Blocks.air, 0, 2);
            world.setBlock(i + 14, j + 7, k + 9, Blocks.air, 0, 2);
            world.setBlock(i + 15, j + 7, k + 9, placeBuildingBlock(random), 0, 2);
            world.setBlock(i + 5, j + 7, k + 10, placeBuildingBlock(random), 0, 2);
            world.setBlock(i + 6, j + 7, k + 10, Blocks.air, 0, 2);
            world.setBlock(i + 7, j + 7, k + 10, Blocks.air, 0, 2);
            world.setBlock(i + 8, j + 7, k + 10, Blocks.air, 0, 2);
            world.setBlock(i + 9, j + 7, k + 10, placeBuildingBlock(random), 0, 2);
            world.setBlock(i + 10, j + 7, k + 10, placeBuildingBlock(random), 0, 2);
            world.setBlock(i + 11, j + 7, k + 10, Blocks.air, 0, 2);
            world.setBlock(i + 12, j + 7, k + 10, Blocks.air, 0, 2);
            world.setBlock(i + 13, j + 7, k + 10, Blocks.air, 0, 2);
            world.setBlock(i + 14, j + 7, k + 10, placeBuildingBlock(random), 0, 2);
            world.setBlock(i + 6, j + 7, k + 11, placeBuildingBlock(random), 0, 2);
            world.setBlock(i + 7, j + 7, k + 11, placeBuildingBlock(random), 0, 2);
            world.setBlock(i + 8, j + 7, k + 11, placeBuildingBlock(random), 0, 2);
            world.setBlock(i + 9, j + 7, k + 11, placeBuildingBlock(random), 0, 2);
            world.setBlock(i + 11, j + 7, k + 11, PlaceBasalt, 1, 2);
            world.setBlock(i + 12, j + 7, k + 11, Blocks.air, 0, 2);
            world.setBlock(i + 13, j + 7, k + 11, PlaceBasalt, 1, 2);
            world.setBlock(i + 11, j + 7, k + 12, placeBuildingBlock(random), 0, 2);
            world.setBlock(i + 12, j + 7, k + 12, Blocks.air, 0, 2);
            world.setBlock(i + 13, j + 7, k + 12, placeBuildingBlock(random), 0, 2);
            world.setBlock(i + 11, j + 7, k + 13, placeBuildingBlock(random), 0, 2);
            world.setBlock(i + 12, j + 7, k + 13, placeBuildingBlockStairs(random), 2, 2);
            world.setBlock(i + 13, j + 7, k + 13, placeBuildingBlock(random), 0, 2);
            world.setBlock(i + 12, j + 7, k + 14, placeBuildingBlock(random), 0, 2);
            world.setBlock(i + 12, j + 7, k + 15, placeBuildingBlock(random), 0, 2);
            world.setBlock(i + 12, j + 7, k + 16, placeBuildingBlock(random), 0, 2);
            world.setBlock(i + 12, j + 7, k + 17, placeBuildingBlock(random), 0, 2);
            world.setBlock(i + 6, j + 8, k + 1, placeBuildingBlock(random), 0, 2);
            world.setBlock(i + 7, j + 8, k + 1, placeBuildingBlock(random), 0, 2);
            world.setBlock(i + 8, j + 8, k + 1, placeBuildingBlock(random), 0, 2);
            world.setBlock(i + 5, j + 8, k + 2, placeBuildingBlock(random), 0, 2);
            world.setBlock(i + 6, j + 8, k + 2, placeBuildingBlock(random), 0, 2);
            world.setBlock(i + 7, j + 8, k + 2, placeBuildingBlock(random), 0, 2);
            world.setBlock(i + 8, j + 8, k + 2, placeBuildingBlock(random), 0, 2);
            world.setBlock(i + 9, j + 8, k + 2, placeBuildingBlock(random), 0, 2);
            world.setBlock(i + 10, j + 8, k + 2, placeBuildingBlock(random), 0, 2);
            world.setBlock(i + 11, j + 8, k + 2, placeBuildingBlock(random), 0, 2);
            world.setBlock(i + 12, j + 8, k + 2, placeBuildingBlock(random), 0, 2);
            world.setBlock(i + 13, j + 8, k + 2, placeBuildingBlock(random), 0, 2);
            world.setBlock(i + 14, j + 8, k + 2, placeBuildingBlock(random), 0, 2);
            world.setBlock(i + 4, j + 8, k + 3, placeBuildingBlock(random), 0, 2);
            world.setBlock(i + 5, j + 8, k + 3, placeBuildingBlock(random), 0, 2);
            world.setBlock(i + 6, j + 8, k + 3, placeBuildingBlock(random), 0, 2);
            world.setBlock(i + 7, j + 8, k + 3, placeBuildingBlock(random), 0, 2);
            world.setBlock(i + 8, j + 8, k + 3, placeBuildingBlock(random), 0, 2);
            world.setBlock(i + 9, j + 8, k + 3, placeBuildingBlock(random), 0, 2);
            world.setBlock(i + 10, j + 8, k + 3, placeBuildingBlock(random), 0, 2);
            world.setBlock(i + 11, j + 8, k + 3, placeBuildingBlock(random), 0, 2);
            world.setBlock(i + 12, j + 8, k + 3, placeBuildingBlock(random), 0, 2);
            world.setBlock(i + 13, j + 8, k + 3, placeBuildingBlock(random), 0, 2);
            world.setBlock(i + 14, j + 8, k + 3, placeBuildingBlock(random), 0, 2);
            world.setBlock(i + 15, j + 8, k + 3, placeBuildingBlock(random), 0, 2);
