package com.NovaCraft.world.ancient_city;

import java.util.Random;

import com.NovaCraft.Items.NovaCraftItems;
import com.NovaCraft.registry.OtherModBlocks;
import com.NovaCraft.registry.OtherModItems;
import com.NovaCraftBlocks.NovaCraftBlocks;

import cpw.mods.fml.common.Loader;
import net.minecraft.block.Block;
import net.minecraft.enchantment.Enchantment;
import net.minecraft.enchantment.EnchantmentData;
import net.minecraft.init.Blocks;
import net.minecraft.init.Items;
import net.minecraft.item.ItemStack;
import net.minecraft.tileentity.TileEntityChest;
import net.minecraft.tileentity.TileEntityMobSpawner;
import net.minecraft.util.MathHelper;
import net.minecraft.world.World;
import net.minecraft.world.gen.feature.WorldGenerator;

public class AncientCitySculkPortalGen extends WorldGenerator
{
	public AncientCitySculkPortalGen() {

	}
	
	private static final Block grimstone = NovaCraftBlocks.grimstone;
	private static final Block sculk_grimstone = NovaCraftBlocks.sculk_grimstone;
	private static final Block sculk_block = NovaCraftBlocks.sculk_block;
	private static final Block sculk_tulip = NovaCraftBlocks.sculk_tulip;
	private static final Block sculk_tendrils = NovaCraftBlocks.sculk_tendrils;
	private static final Block sculk_bush = NovaCraftBlocks.sculk_bush;
	private static final Block sculk_bloom = NovaCraftBlocks.sculk_bloom;	
	private static final Block sculk_tiles = NovaCraftBlocks.sculk_tiles;
	private static final Block sculk_bricks = NovaCraftBlocks.sculk_bricks;
	private static final Block nullstone_bricks = NovaCraftBlocks.nullstone_bricks;
	private static final Block nullstone_tiles = NovaCraftBlocks.nullstone_tiles;
    
    public boolean generate(final World world, final Random random, final int i, final int j, final int k) {
    	
		world.setBlock(i + 0, j + 0, k + 8, sculk_block, 0, 2);
		world.setBlock(i + 0, j + 0, k + 10, sculk_block, 0, 2);
		world.setBlock(i + 0, j + 0, k + 28, sculk_block, 0, 2);
		world.setBlock(i + 0, j + 0, k + 29, sculk_block, 0, 2);
		world.setBlock(i + 0, j + 0, k + 31, sculk_block, 0, 2);
		world.setBlock(i + 0, j + 0, k + 35, sculk_block, 0, 2);
		world.setBlock(i + 0, j + 0, k + 36, sculk_block, 0, 2);
		world.setBlock(i + 3, j + 0, k + 40, sculk_block, 0, 2);
		world.setBlock(i + 2, j + 1, k + 1, sculk_block, 0, 2);
		world.setBlock(i + 6, j + 1, k + 1, sculk_block, 0, 2);
		world.setBlock(i + 7, j + 1, k + 1, sculk_block, 0, 2);
		world.setBlock(i + 8, j + 1, k + 1, sculk_block, 0, 2);
		world.setBlock(i + 10, j + 1, k + 2, sculk_block, 0, 2);
		world.setBlock(i + 11, j + 1, k + 3, sculk_block, 0, 2);
		world.setBlock(i + 12, j + 1, k + 3, sculk_block, 0, 2);
		world.setBlock(i + 12, j + 1, k + 4, sculk_block, 0, 2);
		world.setBlock(i + 13, j + 1, k + 5, sculk_block, 0, 2);
		world.setBlock(i + 13, j + 1, k + 6, sculk_block, 0, 2);
		world.setBlock(i + 0, j + 1, k + 7, sculk_block, 0, 2);
		world.setBlock(i + 0, j + 1, k + 8, sculk_block, 0, 2);
		world.setBlock(i + 11, j + 1, k + 8, sculk_block, 0, 2);
		world.setBlock(i + 12, j + 1, k + 8, sculk_block, 0, 2);
		world.setBlock(i + 0, j + 1, k + 9, sculk_block, 0, 2);
		world.setBlock(i + 12, j + 1, k + 9, sculk_block, 0, 2);
		world.setBlock(i + 0, j + 1, k + 10, sculk_block, 0, 2);
		world.setBlock(i + 0, j + 1, k + 11, sculk_block, 0, 2);
		world.setBlock(i + 0, j + 1, k + 16, sculk_block, 0, 2);
		world.setBlock(i + 0, j + 1, k + 17, sculk_block, 0, 2);
		world.setBlock(i + 0, j + 1, k + 18, sculk_block, 0, 2);
		world.setBlock(i + 0, j + 1, k + 19, sculk_block, 0, 2);
		world.setBlock(i + 0, j + 1, k + 23, sculk_block, 0, 2);
		world.setBlock(i + 0, j + 1, k + 28, sculk_block, 0, 2);
		world.setBlock(i + 0, j + 1, k + 29, sculk_block, 0, 2);
		world.setBlock(i + 0, j + 1, k + 31, sculk_block, 0, 2);
		world.setBlock(i + 12, j + 1, k + 31, sculk_block, 0, 2);
		world.setBlock(i + 11, j + 1, k + 32, sculk_block, 0, 2);
		world.setBlock(i + 12, j + 1, k + 32, sculk_block, 0, 2);
		world.setBlock(i + 9, j + 1, k + 33, sculk_block, 0, 2);
		world.setBlock(i + 11, j + 1, k + 33, sculk_block, 0, 2);
		world.setBlock(i + 12, j + 1, k + 33, sculk_block, 0, 2);
		world.setBlock(i + 0, j + 1, k + 35, sculk_block, 0, 2);
		world.setBlock(i + 10, j + 1, k + 35, sculk_block, 0, 2);
		world.setBlock(i + 13, j + 1, k + 35, sculk_block, 0, 2);
		world.setBlock(i + 0, j + 1, k + 36, sculk_block, 0, 2);
		world.setBlock(i + 10, j + 1, k + 36, sculk_block, 0, 2);
		world.setBlock(i + 11, j + 1, k + 36, sculk_block, 0, 2);
		world.setBlock(i + 10, j + 1, k + 37, sculk_block, 0, 2);
		world.setBlock(i + 11, j + 1, k + 37, sculk_block, 0, 2);
		world.setBlock(i + 6, j + 1, k + 39, sculk_block, 0, 2);
		world.setBlock(i + 8, j + 1, k + 39, sculk_block, 0, 2);
		world.setBlock(i + 0, j + 1, k + 40, sculk_block, 0, 2);
		world.setBlock(i + 2, j + 1, k + 40, sculk_block, 0, 2);
		world.setBlock(i + 0, j + 2, k + 0, sculk_block, 0, 2);
		world.setBlock(i + 0, j + 2, k + 1, sculk_block, 0, 2);
		world.setBlock(i + 7, j + 2, k + 1, sculk_tendrils, 0, 2);
		world.setBlock(i + 1, j + 2, k + 2, sculk_block, 0, 2);
		world.setBlock(i + 2, j + 2, k + 2, sculk_block, 0, 2);
		world.setBlock(i + 3, j + 2, k + 2, sculk_block, 0, 2);
		world.setBlock(i + 5, j + 2, k + 2, sculk_block, 0, 2);
		world.setBlock(i + 10, j + 2, k + 2, sculk_tendrils, 0, 2);
		world.setBlock(i + 9, j + 2, k + 3, NovaCraftBlocks.nullstone_brick_wall, 0, 2);
		world.setBlock(i + 11, j + 2, k + 3, nullstone_bricks, 0, 2);
		world.setBlock(i + 13, j + 2, k + 3, NovaCraftBlocks.nullstone_brick_wall, 0, 2);
		world.setBlock(i + 0, j + 2, k + 4, sculk_block, 0, 2);
		world.setBlock(i + 8, j + 2, k + 4, sculk_block, 0, 2);
		world.setBlock(i + 0, j + 2, k + 5, sculk_block, 0, 2);
		world.setBlock(i + 8, j + 2, k + 5, sculk_block, 0, 2);
		world.setBlock(i + 10, j + 2, k + 5, NovaCraftBlocks.nullstone_brick_wall, 0, 2);
		world.setBlock(i + 12, j + 2, k + 5, NovaCraftBlocks.nullstone_brick_wall, 0, 2);
		world.setBlock(i + 0, j + 2, k + 6, sculk_block, 0, 2);
		world.setBlock(i + 0, j + 2, k + 8, sculk_block, 0, 2);
		world.setBlock(i + 0, j + 2, k + 9, sculk_block, 0, 2);
		world.setBlock(i + 8, j + 2, k + 9, sculk_block, 0, 2);
		world.setBlock(i + 0, j + 2, k + 10, sculk_block, 0, 2);
		world.setBlock(i + 7, j + 2, k + 10, sculk_block, 0, 2);
		world.setBlock(i + 7, j + 2, k + 11, sculk_block, 0, 2);
		world.setBlock(i + 0, j + 2, k + 12, sculk_block, 0, 2);
		world.setBlock(i + 8, j + 2, k + 12, sculk_block, 0, 2);
		world.setBlock(i + 1, j + 2, k + 14, sculk_block, 0, 2);
		world.setBlock(i + 0, j + 2, k + 15, sculk_block, 0, 2);
		world.setBlock(i + 1, j + 2, k + 15, sculk_block, 0, 2);
		world.setBlock(i + 0, j + 2, k + 16, sculk_block, 0, 2);
		world.setBlock(i + 1, j + 2, k + 16, sculk_block, 0, 2);
		world.setBlock(i + 7, j + 2, k + 16, sculk_block, 0, 2);
		world.setBlock(i + 8, j + 2, k + 16, sculk_block, 0, 2);
		world.setBlock(i + 0, j + 2, k + 17, sculk_block, 0, 2);
		world.setBlock(i + 7, j + 2, k + 17, sculk_block, 0, 2);
		world.setBlock(i + 10, j + 2, k + 17, sculk_block, 0, 2);
		world.setBlock(i + 0, j + 2, k + 18, sculk_block, 0, 2);
		world.setBlock(i + 10, j + 2, k + 18, sculk_block, 0, 2);
		world.setBlock(i + 0, j + 2, k + 19, sculk_block, 0, 2);
		world.setBlock(i + 8, j + 2, k + 19, sculk_block, 0, 2);
		world.setBlock(i + 9, j + 2, k + 19, sculk_block, 0, 2);
		world.setBlock(i + 7, j + 2, k + 20, sculk_block, 0, 2);
		world.setBlock(i + 0, j + 2, k + 21, sculk_block, 0, 2);
		world.setBlock(i + 8, j + 2, k + 21, sculk_block, 0, 2);
		world.setBlock(i + 9, j + 2, k + 21, sculk_block, 0, 2);
		world.setBlock(i + 0, j + 2, k + 22, sculk_block, 0, 2);
		world.setBlock(i + 1, j + 2, k + 22, sculk_block, 0, 2);
		world.setBlock(i + 8, j + 2, k + 22, sculk_block, 0, 2);
		world.setBlock(i + 9, j + 2, k + 22, sculk_block, 0, 2);
		world.setBlock(i + 0, j + 2, k + 23, sculk_block, 0, 2);
		world.setBlock(i + 1, j + 2, k + 23, sculk_block, 0, 2);
		world.setBlock(i + 7, j + 2, k + 23, sculk_block, 0, 2);
		world.setBlock(i + 9, j + 2, k + 23, sculk_block, 0, 2);
		world.setBlock(i + 10, j + 2, k + 23, sculk_block, 0, 2);
		world.setBlock(i + 0, j + 2, k + 24, sculk_block, 0, 2);
		world.setBlock(i + 8, j + 2, k + 24, sculk_block, 0, 2);
		world.setBlock(i + 8, j + 2, k + 25, sculk_block, 0, 2);
		world.setBlock(i + 0, j + 2, k + 26, sculk_block, 0, 2);
		world.setBlock(i + 1, j + 2, k + 26, sculk_block, 0, 2);
		world.setBlock(i + 0, j + 2, k + 27, sculk_block, 0, 2);
		world.setBlock(i + 1, j + 2, k + 27, sculk_block, 0, 2);
		world.setBlock(i + 7, j + 2, k + 27, sculk_block, 0, 2);
		world.setBlock(i + 8, j + 2, k + 27, sculk_block, 0, 2);
		world.setBlock(i + 0, j + 2, k + 28, sculk_block, 0, 2);
		world.setBlock(i + 1, j + 2, k + 28, sculk_block, 0, 2);
		world.setBlock(i + 7, j + 2, k + 28, sculk_block, 0, 2);
		world.setBlock(i + 0, j + 2, k + 29, sculk_block, 0, 2);
		world.setBlock(i + 7, j + 2, k + 29, sculk_block, 0, 2);
		world.setBlock(i + 1, j + 2, k + 30, sculk_block, 0, 2);
		world.setBlock(i + 8, j + 2, k + 30, sculk_block, 0, 2);
		world.setBlock(i + 12, j + 2, k + 31, sculk_tendrils, 0, 2);
		world.setBlock(i + 0, j + 2, k + 32, sculk_block, 0, 2);
		world.setBlock(i + 8, j + 2, k + 32, sculk_block, 0, 2);
		world.setBlock(i + 0, j + 2, k + 33, sculk_block, 0, 2);
		world.setBlock(i + 0, j + 2, k + 34, sculk_block, 0, 2);
		world.setBlock(i + 8, j + 2, k + 34, sculk_block, 0, 2);
		world.setBlock(i + 10, j + 2, k + 35, NovaCraftBlocks.nullstone_brick_wall, 0, 2);
		world.setBlock(i + 12, j + 2, k + 35, NovaCraftBlocks.nullstone_brick_wall, 0, 2);
		world.setBlock(i + 1, j + 2, k + 36, sculk_block, 0, 2);
		world.setBlock(i + 8, j + 2, k + 36, sculk_block, 0, 2);
		world.setBlock(i + 11, j + 2, k + 36, Blocks.ladder, 2, 2);
		world.setBlock(i + 0, j + 2, k + 37, sculk_block, 0, 2);
		world.setBlock(i + 2, j + 2, k + 37, sculk_block, 0, 2);
		world.setBlock(i + 3, j + 2, k + 37, sculk_block, 0, 2);
		world.setBlock(i + 5, j + 2, k + 37, sculk_block, 0, 2);
		world.setBlock(i + 6, j + 2, k + 37, sculk_block, 0, 2);
		world.setBlock(i + 9, j + 2, k + 37, NovaCraftBlocks.nullstone_brick_wall, 0, 2);
		world.setBlock(i + 11, j + 2, k + 37, nullstone_bricks, 0, 2);
		world.setBlock(i + 13, j + 2, k + 37, NovaCraftBlocks.nullstone_brick_wall, 0, 2);
		world.setBlock(i + 0, j + 3, k + 0, NovaCraftBlocks.sculk_tentacle_2, 1, 2);
		world.setBlock(i + 2, j + 3, k + 3, sculk_block, 0, 2);
		world.setBlock(i + 3, j + 3, k + 3, sculk_block, 0, 2);
		world.setBlock(i + 4, j + 3, k + 3, sculk_block, 0, 2);
		world.setBlock(i + 7, j + 3, k + 3, sculk_block, 0, 2);
		world.setBlock(i + 9, j + 3, k + 3, NovaCraftBlocks.nullstone_brick_wall, 0, 2);
		world.setBlock(i + 11, j + 3, k + 3, nullstone_bricks, 0, 2);
		world.setBlock(i + 13, j + 3, k + 3, NovaCraftBlocks.nullstone_brick_wall, 0, 2);
		world.setBlock(i + 1, j + 3, k + 5, sculk_block, 0, 2);
		world.setBlock(i + 7, j + 3, k + 5, sculk_block, 0, 2);
		world.setBlock(i + 10, j + 3, k + 5, NovaCraftBlocks.nullstone_brick_wall, 0, 2);
		world.setBlock(i + 12, j + 3, k + 5, NovaCraftBlocks.nullstone_brick_wall, 0, 2);
		world.setBlock(i + 0, j + 3, k + 6, sculk_tendrils, 0, 2);
		world.setBlock(i + 1, j + 3, k + 6, sculk_block, 0, 2);
		world.setBlock(i + 2, j + 3, k + 6, sculk_block, 0, 2);
		world.setBlock(i + 7, j + 3, k + 6, sculk_block, 0, 2);
		world.setBlock(i + 6, j + 3, k + 8, sculk_block, 0, 2);
		world.setBlock(i + 7, j + 3, k + 8, sculk_block, 0, 2);
		world.setBlock(i + 0, j + 3, k + 9, NovaCraftBlocks.sculk_tentacle_2, 1, 2);
		world.setBlock(i + 1, j + 3, k + 9, sculk_block, 0, 2);
		world.setBlock(i + 7, j + 3, k + 9, sculk_block, 0, 2);
		world.setBlock(i + 1, j + 3, k + 15, NovaCraftBlocks.sculk_tentacle_2, 1, 2);
		world.setBlock(i + 10, j + 3, k + 17, NovaCraftBlocks.sculk_tentacle_2, 1, 2);
		world.setBlock(i + 0, j + 3, k + 19, sculk_tendrils, 0, 2);
		world.setBlock(i + 0, j + 3, k + 22, NovaCraftBlocks.sculk_tentacle_2, 1, 2);
		world.setBlock(i + 9, j + 3, k + 22, NovaCraftBlocks.sculk_tentacle_2, 1, 2);
		world.setBlock(i + 1, j + 3, k + 23, sculk_tendrils, 0, 2);
		world.setBlock(i + 10, j + 3, k + 25, sculk_block, 0, 2);
		world.setBlock(i + 1, j + 3, k + 27, NovaCraftBlocks.sculk_tentacle_2, 1, 2);
		world.setBlock(i + 7, j + 3, k + 31, sculk_block, 0, 2);
		world.setBlock(i + 1, j + 3, k + 32, sculk_block, 0, 2);
		world.setBlock(i + 7, j + 3, k + 32, sculk_block, 0, 2);
		world.setBlock(i + 1, j + 3, k + 33, sculk_block, 0, 2);
		world.setBlock(i + 1, j + 3, k + 35, sculk_block, 0, 2);
		world.setBlock(i + 6, j + 3, k + 35, sculk_block, 0, 2);
		world.setBlock(i + 7, j + 3, k + 35, sculk_block, 0, 2);
		world.setBlock(i + 10, j + 3, k + 35, NovaCraftBlocks.nullstone_brick_wall, 0, 2);
		world.setBlock(i + 12, j + 3, k + 35, NovaCraftBlocks.nullstone_brick_wall, 0, 2);
		world.setBlock(i + 3, j + 3, k + 36, sculk_block, 0, 2);
		world.setBlock(i + 5, j + 3, k + 36, sculk_block, 0, 2);
		world.setBlock(i + 7, j + 3, k + 36, sculk_block, 0, 2);
		world.setBlock(i + 9, j + 3, k + 37, NovaCraftBlocks.nullstone_brick_wall, 0, 2);
		world.setBlock(i + 11, j + 3, k + 37, nullstone_bricks, 0, 2);
		world.setBlock(i + 13, j + 3, k + 37, NovaCraftBlocks.nullstone_brick_wall, 0, 2);
		world.setBlock(i + 7, j + 4, k + 3, NovaCraftBlocks.sculk_tentacle_2, 1, 2);
		world.setBlock(i + 9, j + 4, k + 3, NovaCraftBlocks.nullstone_brick_wall, 0, 2);
		world.setBlock(i + 11, j + 4, k + 3, nullstone_bricks, 0, 2);
		world.setBlock(i + 13, j + 4, k + 3, NovaCraftBlocks.nullstone_brick_wall, 0, 2);
		world.setBlock(i + 6, j + 4, k + 4, sculk_block, 0, 2);
		world.setBlock(i + 11, j + 4, k + 4, Blocks.ladder, 3, 2);
		world.setBlock(i + 10, j + 4, k + 5, NovaCraftBlocks.nullstone_brick_wall, 0, 2);
		world.setBlock(i + 12, j + 4, k + 5, NovaCraftBlocks.nullstone_brick_wall, 0, 2);
		world.setBlock(i + 2, j + 4, k + 6, sculk_block, 0, 2);
		world.setBlock(i + 6, j + 4, k + 7, sculk_block, 0, 2);
		world.setBlock(i + 2, j + 4, k + 9, sculk_block, 0, 2);
		world.setBlock(i + 6, j + 4, k + 18, sculk_block, 0, 2);
		world.setBlock(i + 1, j + 4, k + 23, sculk_tendrils, 0, 2);
		world.setBlock(i + 2, j + 4, k + 23, sculk_block, 0, 2);
		world.setBlock(i + 2, j + 4, k + 24, sculk_block, 0, 2);
		world.setBlock(i + 2, j + 4, k + 29, sculk_block, 0, 2);
		world.setBlock(i + 7, j + 4, k + 31, NovaCraftBlocks.sculk_tentacle_2, 1, 2);
		world.setBlock(i + 2, j + 4, k + 33, sculk_block, 0, 2);
		world.setBlock(i + 1, j + 4, k + 35, NovaCraftBlocks.sculk_tentacle_2, 1, 2);
		world.setBlock(i + 2, j + 4, k + 35, sculk_block, 0, 2);
		world.setBlock(i + 3, j + 4, k + 35, sculk_block, 0, 2);
		world.setBlock(i + 4, j + 4, k + 35, sculk_block, 0, 2);
		world.setBlock(i + 6, j + 4, k + 35, sculk_block, 0, 2);
		world.setBlock(i + 7, j + 4, k + 35, sculk_tendrils, 0, 2);
		world.setBlock(i + 10, j + 4, k + 35, NovaCraftBlocks.nullstone_brick_wall, 0, 2);
		world.setBlock(i + 12, j + 4, k + 35, NovaCraftBlocks.nullstone_brick_wall, 0, 2);
		world.setBlock(i + 7, j + 4, k + 36, NovaCraftBlocks.sculk_tentacle_2, 1, 2);
		world.setBlock(i + 9, j + 4, k + 37, NovaCraftBlocks.nullstone_brick_wall, 0, 2);
		world.setBlock(i + 11, j + 4, k + 37, nullstone_bricks, 0, 2);
		world.setBlock(i + 13, j + 4, k + 37, NovaCraftBlocks.nullstone_brick_wall, 0, 2);
		world.setBlock(i + 9, j + 5, k + 3, NovaCraftBlocks.nullstone_brick_wall, 0, 2);
		world.setBlock(i + 11, j + 5, k + 3, nullstone_bricks, 0, 2);
		world.setBlock(i + 13, j + 5, k + 3, NovaCraftBlocks.nullstone_brick_wall, 0, 2);
		world.setBlock(i + 2, j + 5, k + 5, sculk_block, 0, 2);
		world.setBlock(i + 10, j + 5, k + 5, NovaCraftBlocks.nullstone_brick_wall, 0, 2);
		world.setBlock(i + 12, j + 5, k + 5, NovaCraftBlocks.nullstone_brick_wall, 0, 2);
		world.setBlock(i + 2, j + 5, k + 6, sculk_block, 0, 2);
		world.setBlock(i + 6, j + 5, k + 7, sculk_block, 0, 2);
		world.setBlock(i + 2, j + 5, k + 8, sculk_block, 0, 2);
		world.setBlock(i + 2, j + 5, k + 15, sculk_block, 0, 2);
		world.setBlock(i + 2, j + 5, k + 16, sculk_block, 0, 2);
		world.setBlock(i + 2, j + 5, k + 22, sculk_block, 0, 2);
		world.setBlock(i + 6, j + 5, k + 22, sculk_block, 0, 2);
		world.setBlock(i + 2, j + 5, k + 23, sculk_block, 0, 2);
		world.setBlock(i + 2, j + 5, k + 28, sculk_block, 0, 2);
		world.setBlock(i + 2, j + 5, k + 29, sculk_block, 0, 2);
		world.setBlock(i + 2, j + 5, k + 32, sculk_block, 0, 2);
		world.setBlock(i + 2, j + 5, k + 35, sculk_block, 0, 2);
		world.setBlock(i + 3, j + 5, k + 35, sculk_block, 0, 2);
		world.setBlock(i + 10, j + 5, k + 35, NovaCraftBlocks.nullstone_brick_wall, 0, 2);
		world.setBlock(i + 12, j + 5, k + 35, NovaCraftBlocks.nullstone_brick_wall, 0, 2);
		world.setBlock(i + 9, j + 5, k + 37, NovaCraftBlocks.nullstone_brick_wall, 0, 2);
		world.setBlock(i + 11, j + 5, k + 37, nullstone_bricks, 0, 2);
		world.setBlock(i + 13, j + 5, k + 37, NovaCraftBlocks.nullstone_brick_wall, 0, 2);
		world.setBlock(i + 9, j + 6, k + 3, NovaCraftBlocks.nullstone_brick_wall, 0, 2);
		world.setBlock(i + 11, j + 6, k + 3, nullstone_bricks, 0, 2);
		world.setBlock(i + 13, j + 6, k + 3, NovaCraftBlocks.nullstone_brick_wall, 0, 2);
		world.setBlock(i + 4, j + 6, k + 4, sculk_block, 0, 2);
		world.setBlock(i + 11, j + 6, k + 4, Blocks.ladder, 3, 2);
		world.setBlock(i + 2, j + 6, k + 5, sculk_block, 0, 2);
		world.setBlock(i + 10, j + 6, k + 5, NovaCraftBlocks.nullstone_brick_wall, 0, 2);
		world.setBlock(i + 12, j + 6, k + 5, NovaCraftBlocks.nullstone_brick_wall, 0, 2);
		world.setBlock(i + 2, j + 6, k + 6, sculk_block, 0, 2);
		world.setBlock(i + 2, j + 6, k + 7, sculk_block, 0, 2);
		world.setBlock(i + 2, j + 6, k + 8, sculk_block, 0, 2);
		world.setBlock(i + 2, j + 6, k + 12, sculk_block, 0, 2);
		world.setBlock(i + 2, j + 6, k + 14, sculk_block, 0, 2);
		world.setBlock(i + 2, j + 6, k + 15, sculk_block, 0, 2);
		world.setBlock(i + 2, j + 6, k + 17, sculk_block, 0, 2);
		world.setBlock(i + 2, j + 6, k + 21, sculk_block, 0, 2);
		world.setBlock(i + 2, j + 6, k + 22, sculk_block, 0, 2);
		world.setBlock(i + 6, j + 6, k + 23, sculk_block, 0, 2);
		world.setBlock(i + 2, j + 6, k + 24, sculk_block, 0, 2);
		world.setBlock(i + 2, j + 6, k + 26, sculk_block, 0, 2);
		world.setBlock(i + 2, j + 6, k + 28, sculk_block, 0, 2);
		world.setBlock(i + 2, j + 6, k + 32, sculk_block, 0, 2);
		world.setBlock(i + 2, j + 6, k + 33, sculk_block, 0, 2);
		world.setBlock(i + 10, j + 6, k + 35, NovaCraftBlocks.nullstone_brick_wall, 0, 2);
		world.setBlock(i + 12, j + 6, k + 35, NovaCraftBlocks.nullstone_brick_wall, 0, 2);
		world.setBlock(i + 9, j + 6, k + 37, NovaCraftBlocks.nullstone_brick_wall, 0, 2);
		world.setBlock(i + 11, j + 6, k + 37, nullstone_bricks, 0, 2);
		world.setBlock(i + 13, j + 6, k + 37, NovaCraftBlocks.nullstone_brick_wall, 0, 2);
		world.setBlock(i + 9, j + 7, k + 3, NovaCraftBlocks.nullstone_brick_wall, 0, 2);
		world.setBlock(i + 11, j + 7, k + 3, nullstone_bricks, 0, 2);
		world.setBlock(i + 13, j + 7, k + 3, NovaCraftBlocks.nullstone_brick_wall, 0, 2);
		world.setBlock(i + 11, j + 7, k + 4, Blocks.ladder, 3, 2);
		world.setBlock(i + 4, j + 7, k + 5, sculk_block, 0, 2);
		world.setBlock(i + 10, j + 7, k + 5, NovaCraftBlocks.nullstone_brick_wall, 0, 2);
		world.setBlock(i + 12, j + 7, k + 5, NovaCraftBlocks.nullstone_brick_wall, 0, 2);
		world.setBlock(i + 2, j + 7, k + 7, sculk_block, 0, 2);
		world.setBlock(i + 2, j + 7, k + 8, sculk_block, 0, 2);
		world.setBlock(i + 2, j + 7, k + 9, sculk_block, 0, 2);
		world.setBlock(i + 2, j + 7, k + 11, sculk_block, 0, 2);
		world.setBlock(i + 2, j + 7, k + 12, sculk_block, 0, 2);
		world.setBlock(i + 2, j + 7, k + 15, sculk_block, 0, 2);
		world.setBlock(i + 2, j + 7, k + 17, sculk_block, 0, 2);
		world.setBlock(i + 2, j + 7, k + 18, sculk_block, 0, 2);
		world.setBlock(i + 2, j + 7, k + 19, sculk_block, 0, 2);
		world.setBlock(i + 2, j + 7, k + 22, sculk_block, 0, 2);
		world.setBlock(i + 6, j + 7, k + 23, sculk_block, 0, 2);
		world.setBlock(i + 6, j + 7, k + 26, sculk_block, 0, 2);
		world.setBlock(i + 2, j + 7, k + 27, sculk_block, 0, 2);
		world.setBlock(i + 10, j + 7, k + 35, NovaCraftBlocks.nullstone_brick_wall, 0, 2);
		world.setBlock(i + 12, j + 7, k + 35, NovaCraftBlocks.nullstone_brick_wall, 0, 2);
		world.setBlock(i + 9, j + 7, k + 37, NovaCraftBlocks.nullstone_brick_wall, 0, 2);
		world.setBlock(i + 11, j + 7, k + 37, nullstone_bricks, 0, 2);
		world.setBlock(i + 13, j + 7, k + 37, NovaCraftBlocks.nullstone_brick_wall, 0, 2);
		world.setBlock(i + 9, j + 8, k + 3, NovaCraftBlocks.nullstone_brick_wall, 0, 2);
		world.setBlock(i + 11, j + 8, k + 3, nullstone_bricks, 0, 2);
		world.setBlock(i + 13, j + 8, k + 3, NovaCraftBlocks.nullstone_brick_wall, 0, 2);
		world.setBlock(i + 3, j + 8, k + 4, sculk_block, 0, 2);
		world.setBlock(i + 4, j + 8, k + 4, sculk_block, 0, 2);
		world.setBlock(i + 4, j + 8, k + 5, sculk_block, 0, 2);
		world.setBlock(i + 10, j + 8, k + 5, NovaCraftBlocks.nullstone_brick_wall, 0, 2);
		world.setBlock(i + 12, j + 8, k + 5, NovaCraftBlocks.nullstone_brick_wall, 0, 2);
		world.setBlock(i + 2, j + 8, k + 10, sculk_block, 0, 2);
		world.setBlock(i + 2, j + 8, k + 11, sculk_block, 0, 2);
		world.setBlock(i + 2, j + 8, k + 12, sculk_block, 0, 2);
		world.setBlock(i + 2, j + 8, k + 13, sculk_block, 0, 2);
		world.setBlock(i + 6, j + 8, k + 13, sculk_block, 0, 2);
		world.setBlock(i + 6, j + 8, k + 14, sculk_block, 0, 2);
		world.setBlock(i + 2, j + 8, k + 15, sculk_block, 0, 2);
		world.setBlock(i + 6, j + 8, k + 16, sculk_block, 0, 2);
		world.setBlock(i + 2, j + 8, k + 17, sculk_block, 0, 2);
		world.setBlock(i + 5, j + 8, k + 17, sculk_block, 0, 2);
		world.setBlock(i + 6, j + 8, k + 17, sculk_block, 0, 2);
		world.setBlock(i + 5, j + 8, k + 18, sculk_block, 0, 2);
		world.setBlock(i + 6, j + 8, k + 18, sculk_block, 0, 2);
		world.setBlock(i + 2, j + 8, k + 19, sculk_block, 0, 2);
		world.setBlock(i + 2, j + 8, k + 20, sculk_block, 0, 2);
		world.setBlock(i + 6, j + 8, k + 21, sculk_block, 0, 2);
		world.setBlock(i + 2, j + 8, k + 22, sculk_block, 0, 2);
		world.setBlock(i + 6, j + 8, k + 22, sculk_block, 0, 2);
		world.setBlock(i + 2, j + 8, k + 23, sculk_block, 0, 2);
		world.setBlock(i + 2, j + 8, k + 24, sculk_block, 0, 2);
		world.setBlock(i + 6, j + 8, k + 24, sculk_block, 0, 2);
		world.setBlock(i + 5, j + 8, k + 25, sculk_block, 0, 2);
		world.setBlock(i + 6, j + 8, k + 25, sculk_block, 0, 2);
		world.setBlock(i + 2, j + 8, k + 26, sculk_block, 0, 2);
		world.setBlock(i + 3, j + 8, k + 26, sculk_block, 0, 2);
		world.setBlock(i + 6, j + 8, k + 26, sculk_block, 0, 2);
		world.setBlock(i + 2, j + 8, k + 27, sculk_block, 0, 2);
		world.setBlock(i + 6, j + 8, k + 27, sculk_block, 0, 2);
		world.setBlock(i + 2, j + 8, k + 28, sculk_block, 0, 2);
		world.setBlock(i + 6, j + 8, k + 28, sculk_block, 0, 2);
		world.setBlock(i + 2, j + 8, k + 29, sculk_block, 0, 2);
		world.setBlock(i + 3, j + 8, k + 32, sculk_block, 0, 2);
		world.setBlock(i + 10, j + 8, k + 35, NovaCraftBlocks.nullstone_brick_wall, 0, 2);
		world.setBlock(i + 12, j + 8, k + 35, NovaCraftBlocks.nullstone_brick_wall, 0, 2);
		world.setBlock(i + 11, j + 8, k + 36, Blocks.ladder, 2, 2);
		world.setBlock(i + 9, j + 8, k + 37, NovaCraftBlocks.nullstone_brick_wall, 0, 2);
		world.setBlock(i + 11, j + 8, k + 37, nullstone_bricks, 0, 2);
		world.setBlock(i + 13, j + 8, k + 37, NovaCraftBlocks.nullstone_brick_wall, 0, 2);
		world.setBlock(i + 9, j + 9, k + 3, NovaCraftBlocks.nullstone_brick_wall, 0, 2);
		world.setBlock(i + 11, j + 9, k + 3, nullstone_bricks, 0, 2);
		world.setBlock(i + 13, j + 9, k + 3, NovaCraftBlocks.nullstone_brick_wall, 0, 2);
		world.setBlock(i + 2, j + 9, k + 4, sculk_block, 0, 2);
		world.setBlock(i + 4, j + 9, k + 4, sculk_block, 0, 2);
		world.setBlock(i + 5, j + 9, k + 4, sculk_block, 0, 2);
		world.setBlock(i + 2, j + 9, k + 5, sculk_block, 0, 2);
		world.setBlock(i + 6, j + 9, k + 5, sculk_block, 0, 2);
		world.setBlock(i + 10, j + 9, k + 5, NovaCraftBlocks.nullstone_brick_wall, 0, 2);
		world.setBlock(i + 12, j + 9, k + 5, NovaCraftBlocks.nullstone_brick_wall, 0, 2);
		world.setBlock(i + 2, j + 9, k + 6, sculk_block, 0, 2);
		world.setBlock(i + 6, j + 9, k + 6, sculk_block, 0, 2);
		world.setBlock(i + 2, j + 9, k + 9, sculk_block, 0, 2);
		world.setBlock(i + 5, j + 9, k + 10, sculk_block, 0, 2);
		world.setBlock(i + 2, j + 9, k + 11, sculk_block, 0, 2);
		world.setBlock(i + 3, j + 9, k + 11, sculk_block, 0, 2);
		world.setBlock(i + 5, j + 9, k + 11, sculk_block, 0, 2);
		world.setBlock(i + 6, j + 9, k + 11, sculk_block, 0, 2);
		world.setBlock(i + 2, j + 9, k + 12, sculk_block, 0, 2);
		world.setBlock(i + 6, j + 9, k + 12, sculk_block, 0, 2);
		world.setBlock(i + 3, j + 9, k + 14, sculk_block, 0, 2);
		world.setBlock(i + 3, j + 9, k + 15, sculk_block, 0, 2);
		world.setBlock(i + 6, j + 9, k + 15, sculk_block, 0, 2);
		world.setBlock(i + 2, j + 9, k + 16, sculk_block, 0, 2);
		world.setBlock(i + 6, j + 9, k + 16, sculk_block, 0, 2);
		world.setBlock(i + 5, j + 9, k + 17, sculk_block, 0, 2);
		world.setBlock(i + 3, j + 9, k + 18, sculk_block, 0, 2);
		world.setBlock(i + 5, j + 9, k + 18, sculk_block, 0, 2);
		world.setBlock(i + 6, j + 9, k + 18, sculk_block, 0, 2);
		world.setBlock(i + 2, j + 9, k + 19, sculk_block, 0, 2);
		world.setBlock(i + 3, j + 9, k + 19, sculk_block, 0, 2);
		world.setBlock(i + 6, j + 9, k + 20, sculk_block, 0, 2);
		world.setBlock(i + 3, j + 9, k + 21, sculk_block, 0, 2);
		world.setBlock(i + 6, j + 9, k + 21, NovaCraftBlocks.sculk_tentacle_2, 1, 2);
		world.setBlock(i + 3, j + 9, k + 22, sculk_block, 0, 2);
		world.setBlock(i + 5, j + 9, k + 22, sculk_block, 0, 2);
		world.setBlock(i + 2, j + 9, k + 24, sculk_block, 0, 2);
		world.setBlock(i + 3, j + 9, k + 25, sculk_block, 0, 2);
		world.setBlock(i + 4, j + 9, k + 25, sculk_block, 0, 2);
		world.setBlock(i + 3, j + 9, k + 26, sculk_block, 0, 2);
		world.setBlock(i + 5, j + 9, k + 26, sculk_block, 0, 2);
		world.setBlock(i + 2, j + 9, k + 27, sculk_block, 0, 2);
		world.setBlock(i + 3, j + 9, k + 27, sculk_block, 0, 2);
		world.setBlock(i + 6, j + 9, k + 27, sculk_block, 0, 2);
		world.setBlock(i + 2, j + 9, k + 28, sculk_block, 0, 2);
		world.setBlock(i + 5, j + 9, k + 28, sculk_block, 0, 2);
		world.setBlock(i + 6, j + 9, k + 28, sculk_block, 0, 2);
		world.setBlock(i + 5, j + 9, k + 29, sculk_block, 0, 2);
		world.setBlock(i + 2, j + 9, k + 31, sculk_block, 0, 2);
		world.setBlock(i + 3, j + 9, k + 32, sculk_block, 0, 2);
		world.setBlock(i + 5, j + 9, k + 35, sculk_block, 0, 2);
		world.setBlock(i + 10, j + 9, k + 35, NovaCraftBlocks.nullstone_brick_wall, 0, 2);
		world.setBlock(i + 12, j + 9, k + 35, NovaCraftBlocks.nullstone_brick_wall, 0, 2);
		world.setBlock(i + 11, j + 9, k + 36, Blocks.ladder, 2, 2);
		world.setBlock(i + 9, j + 9, k + 37, NovaCraftBlocks.nullstone_brick_wall, 0, 2);
		world.setBlock(i + 11, j + 9, k + 37, nullstone_bricks, 0, 2);
		world.setBlock(i + 13, j + 9, k + 37, NovaCraftBlocks.nullstone_brick_wall, 0, 2);
		world.setBlock(i + 10, j + 10, k + 2, nullstone_tiles, 0, 2);
		world.setBlock(i + 11, j + 10, k + 2, nullstone_tiles, 0, 2);
		world.setBlock(i + 12, j + 10, k + 2, nullstone_tiles, 0, 2);
		world.setBlock(i + 9, j + 10, k + 3, nullstone_tiles, 0, 2);
		world.setBlock(i + 10, j + 10, k + 3, nullstone_tiles, 0, 2);
		world.setBlock(i + 11, j + 10, k + 3, nullstone_tiles, 0, 2);
		world.setBlock(i + 12, j + 10, k + 3, nullstone_tiles, 0, 2);
		world.setBlock(i + 13, j + 10, k + 3, nullstone_tiles, 0, 2);
		world.setBlock(i + 3, j + 10, k + 4, sculk_block, 0, 2);
		world.setBlock(i + 4, j + 10, k + 4, sculk_block, 0, 2);
		world.setBlock(i + 5, j + 10, k + 4, sculk_block, 0, 2);
		world.setBlock(i + 9, j + 10, k + 4, nullstone_tiles, 0, 2);
		world.setBlock(i + 10, j + 10, k + 4, nullstone_tiles, 0, 2);
		world.setBlock(i + 12, j + 10, k + 4, nullstone_tiles, 0, 2);
		world.setBlock(i + 13, j + 10, k + 4, nullstone_tiles, 0, 2);
		world.setBlock(i + 6, j + 10, k + 5, sculk_block, 0, 2);
		world.setBlock(i + 9, j + 10, k + 5, nullstone_tiles, 0, 2);
		world.setBlock(i + 10, j + 10, k + 5, nullstone_tiles, 0, 2);
		world.setBlock(i + 11, j + 10, k + 5, nullstone_tiles, 0, 2);
		world.setBlock(i + 12, j + 10, k + 5, nullstone_tiles, 0, 2);
		world.setBlock(i + 13, j + 10, k + 5, nullstone_tiles, 0, 2);
		world.setBlock(i + 2, j + 10, k + 6, sculk_block, 0, 2);
		world.setBlock(i + 10, j + 10, k + 6, nullstone_tiles, 0, 2);
		world.setBlock(i + 11, j + 10, k + 6, nullstone_tiles, 0, 2);
		world.setBlock(i + 12, j + 10, k + 6, nullstone_tiles, 0, 2);
		world.setBlock(i + 2, j + 10, k + 7, sculk_block, 0, 2);
		world.setBlock(i + 2, j + 10, k + 8, sculk_block, 0, 2);
		world.setBlock(i + 3, j + 10, k + 8, sculk_block, 0, 2);
		world.setBlock(i + 5, j + 10, k + 8, sculk_block, 0, 2);
		world.setBlock(i + 6, j + 10, k + 9, sculk_block, 0, 2);
		world.setBlock(i + 2, j + 10, k + 11, sculk_tendrils, 0, 2);
		world.setBlock(i + 5, j + 10, k + 11, sculk_tendrils, 0, 2);
		world.setBlock(i + 3, j + 10, k + 15, sculk_tendrils, 0, 2);
		world.setBlock(i + 6, j + 10, k + 15, sculk_tendrils, 0, 2);
		world.setBlock(i + 5, j + 10, k + 17, NovaCraftBlocks.sculk_tentacle_2, 1, 2);
		world.setBlock(i + 3, j + 10, k + 18, sculk_tendrils, 0, 2);
		world.setBlock(i + 1, j + 10, k + 20, sculk_tendrils, 0, 2);
		world.setBlock(i + 6, j + 10, k + 20, NovaCraftBlocks.sculk_tentacle_2, 1, 2);
		world.setBlock(i + 3, j + 10, k + 21, sculk_tendrils, 0, 2);
		world.setBlock(i + 5, j + 10, k + 22, sculk_tendrils, 0, 2);
		world.setBlock(i + 2, j + 10, k + 24, sculk_tendrils, 0, 2);
		world.setBlock(i + 6, j + 10, k + 27, sculk_tendrils, 0, 2);
		world.setBlock(i + 2, j + 10, k + 28, sculk_tendrils, 0, 2);
		world.setBlock(i + 6, j + 10, k + 28, NovaCraftBlocks.sculk_tentacle_2, 1, 2);
		world.setBlock(i + 5, j + 10, k + 29, NovaCraftBlocks.sculk_tentacle_2, 1, 2);
		world.setBlock(i + 2, j + 10, k + 30, sculk_block, 0, 2);
		world.setBlock(i + 6, j + 10, k + 30, sculk_block, 0, 2);
		world.setBlock(i + 2, j + 10, k + 31, sculk_block, 0, 2);
		world.setBlock(i + 2, j + 10, k + 32, sculk_block, 0, 2);
		world.setBlock(i + 2, j + 10, k + 33, sculk_block, 0, 2);
		world.setBlock(i + 2, j + 10, k + 34, sculk_block, 0, 2);
		world.setBlock(i + 10, j + 10, k + 34, nullstone_tiles, 0, 2);
		world.setBlock(i + 11, j + 10, k + 34, nullstone_tiles, 0, 2);
		world.setBlock(i + 12, j + 10, k + 34, nullstone_tiles, 0, 2);
		world.setBlock(i + 4, j + 10, k + 35, sculk_block, 0, 2);
		world.setBlock(i + 9, j + 10, k + 35, nullstone_tiles, 0, 2);
		world.setBlock(i + 10, j + 10, k + 35, nullstone_tiles, 0, 2);
		world.setBlock(i + 11, j + 10, k + 35, nullstone_tiles, 0, 2);
		world.setBlock(i + 12, j + 10, k + 35, nullstone_tiles, 0, 2);
		world.setBlock(i + 13, j + 10, k + 35, nullstone_tiles, 0, 2);
		world.setBlock(i + 9, j + 10, k + 36, nullstone_tiles, 0, 2);
		world.setBlock(i + 10, j + 10, k + 36, nullstone_tiles, 0, 2);
		world.setBlock(i + 12, j + 10, k + 36, nullstone_tiles, 0, 2);
		world.setBlock(i + 13, j + 10, k + 36, nullstone_tiles, 0, 2);
		world.setBlock(i + 9, j + 10, k + 37, nullstone_tiles, 0, 2);
		world.setBlock(i + 10, j + 10, k + 37, nullstone_tiles, 0, 2);
		world.setBlock(i + 11, j + 10, k + 37, nullstone_tiles, 0, 2);
		world.setBlock(i + 12, j + 10, k + 37, nullstone_tiles, 0, 2);
		world.setBlock(i + 13, j + 10, k + 37, nullstone_tiles, 0, 2);
		world.setBlock(i + 10, j + 10, k + 38, nullstone_tiles, 0, 2);
		world.setBlock(i + 11, j + 10, k + 38, nullstone_tiles, 0, 2);
		world.setBlock(i + 12, j + 10, k + 38, nullstone_tiles, 0, 2);
		world.setBlock(i + 9, j + 11, k + 2, nullstone_tiles, 0, 2);
		world.setBlock(i + 10, j + 11, k + 2, nullstone_bricks, 0, 2);
		world.setBlock(i + 11, j + 11, k + 2, nullstone_bricks, 0, 2);
		world.setBlock(i + 12, j + 11, k + 2, nullstone_bricks, 0, 2);
		world.setBlock(i + 13, j + 11, k + 2, nullstone_tiles, 0, 2);
		world.setBlock(i + 9, j + 11, k + 3, nullstone_bricks, 0, 2);
		world.setBlock(i + 13, j + 11, k + 3, nullstone_bricks, 0, 2);
		world.setBlock(i + 4, j + 11, k + 4, sculk_block, 0, 2);
		world.setBlock(i + 6, j + 11, k + 4, sculk_block, 0, 2);
		world.setBlock(i + 9, j + 11, k + 4, nullstone_bricks, 0, 2);
		world.setBlock(i + 13, j + 11, k + 4, nullstone_bricks, 0, 2);
		world.setBlock(i + 2, j + 11, k + 5, sculk_block, 0, 2);
		world.setBlock(i + 3, j + 11, k + 5, sculk_block, 0, 2);
		world.setBlock(i + 4, j + 11, k + 5, sculk_block, 0, 2);
		world.setBlock(i + 9, j + 11, k + 5, nullstone_bricks, 0, 2);
		world.setBlock(i + 13, j + 11, k + 5, nullstone_bricks, 0, 2);
		world.setBlock(i + 2, j + 11, k + 6, sculk_block, 0, 2);
		world.setBlock(i + 9, j + 11, k + 6, nullstone_tiles, 0, 2);
		world.setBlock(i + 10, j + 11, k + 6, nullstone_bricks, 0, 2);
		world.setBlock(i + 11, j + 11, k + 6, nullstone_bricks, 0, 2);
		world.setBlock(i + 12, j + 11, k + 6, nullstone_bricks, 0, 2);
		world.setBlock(i + 13, j + 11, k + 6, nullstone_tiles, 0, 2);
		world.setBlock(i + 2, j + 11, k + 8, sculk_block, 0, 2);
		world.setBlock(i + 3, j + 11, k + 8, sculk_block, 0, 2);
		world.setBlock(i + 5, j + 11, k + 8, sculk_block, 0, 2);
		world.setBlock(i + 6, j + 11, k + 8, sculk_block, 0, 2);
		world.setBlock(i + 6, j + 11, k + 9, NovaCraftBlocks.sculk_tentacle_2, 1, 2);
		world.setBlock(i + 3, j + 11, k + 31, sculk_block, 0, 2);
		world.setBlock(i + 5, j + 11, k + 31, sculk_block, 0, 2);
		world.setBlock(i + 6, j + 11, k + 31, sculk_block, 0, 2);
		world.setBlock(i + 2, j + 11, k + 33, sculk_block, 0, 2);
		world.setBlock(i + 2, j + 11, k + 34, sculk_block, 0, 2);
		world.setBlock(i + 9, j + 11, k + 34, nullstone_tiles, 0, 2);
		world.setBlock(i + 10, j + 11, k + 34, nullstone_bricks, 0, 2);
		world.setBlock(i + 11, j + 11, k + 34, nullstone_bricks, 0, 2);
		world.setBlock(i + 12, j + 11, k + 34, nullstone_bricks, 0, 2);
		world.setBlock(i + 13, j + 11, k + 34, nullstone_tiles, 0, 2);
		world.setBlock(i + 3, j + 11, k + 35, sculk_block, 0, 2);
		world.setBlock(i + 4, j + 11, k + 35, sculk_block, 0, 2);
		world.setBlock(i + 6, j + 11, k + 35, sculk_block, 0, 2);
		world.setBlock(i + 9, j + 11, k + 35, nullstone_bricks, 0, 2);
		world.setBlock(i + 13, j + 11, k + 35, nullstone_bricks, 0, 2);
		world.setBlock(i + 9, j + 11, k + 36, nullstone_bricks, 0, 2);
		world.setBlock(i + 13, j + 11, k + 36, nullstone_bricks, 0, 2);
		world.setBlock(i + 9, j + 11, k + 37, nullstone_bricks, 0, 2);
		world.setBlock(i + 13, j + 11, k + 37, nullstone_bricks, 0, 2);
		world.setBlock(i + 9, j + 11, k + 38, nullstone_tiles, 0, 2);
		world.setBlock(i + 10, j + 11, k + 38, nullstone_bricks, 0, 2);
		world.setBlock(i + 11, j + 11, k + 38, nullstone_bricks, 0, 2);
		world.setBlock(i + 12, j + 11, k + 38, nullstone_bricks, 0, 2);
		world.setBlock(i + 13, j + 11, k + 38, nullstone_tiles, 0, 2);
		world.setBlock(i + 9, j + 12, k + 2, NovaCraftBlocks.nullstone_tiled_wall, 0, 2);
		world.setBlock(i + 10, j + 12, k + 2, NovaCraftBlocks.nullstone_tiled_wall, 0, 2);
		world.setBlock(i + 12, j + 12, k + 2, NovaCraftBlocks.nullstone_tiled_wall, 0, 2);
		world.setBlock(i + 13, j + 12, k + 2, NovaCraftBlocks.nullstone_tiled_wall, 0, 2);
		world.setBlock(i + 9, j + 12, k + 3, NovaCraftBlocks.nullstone_tiled_wall, 0, 2);
		world.setBlock(i + 13, j + 12, k + 3, NovaCraftBlocks.nullstone_tiled_wall, 0, 2);
		world.setBlock(i + 2, j + 12, k + 4, sculk_block, 0, 2);
		world.setBlock(i + 3, j + 12, k + 4, sculk_block, 0, 2);
		world.setBlock(i + 9, j + 12, k + 4, NovaCraftBlocks.nullstone_tiled_wall, 0, 2);
		world.setBlock(i + 6, j + 12, k + 5, sculk_block, 0, 2);
		world.setBlock(i + 9, j + 12, k + 5, NovaCraftBlocks.nullstone_tiled_wall, 0, 2);
		world.setBlock(i + 13, j + 12, k + 5, NovaCraftBlocks.nullstone_tiled_wall, 0, 2);
		world.setBlock(i + 6, j + 12, k + 6, sculk_block, 0, 2);
		world.setBlock(i + 9, j + 12, k + 6, NovaCraftBlocks.nullstone_tiled_wall, 0, 2);
		world.setBlock(i + 10, j + 12, k + 6, NovaCraftBlocks.nullstone_tiled_wall, 0, 2);
		world.setBlock(i + 12, j + 12, k + 6, NovaCraftBlocks.nullstone_tiled_wall, 0, 2);
		world.setBlock(i + 13, j + 12, k + 6, NovaCraftBlocks.nullstone_tiled_wall, 0, 2);
		world.setBlock(i + 2, j + 12, k + 7, sculk_block, 0, 2);
		world.setBlock(i + 6, j + 12, k + 7, sculk_block, 0, 2);
		world.setBlock(i + 2, j + 12, k + 8, sculk_block, 0, 2);
		world.setBlock(i + 3, j + 12, k + 8, sculk_block, 0, 2);
		world.setBlock(i + 6, j + 12, k + 8, sculk_block, 0, 2);
		world.setBlock(i + 3, j + 12, k + 31, sculk_block, 0, 2);
		world.setBlock(i + 6, j + 12, k + 31, sculk_block, 0, 2);
		world.setBlock(i + 2, j + 12, k + 32, sculk_block, 0, 2);
		world.setBlock(i + 2, j + 12, k + 33, sculk_block, 0, 2);
		world.setBlock(i + 2, j + 12, k + 34, sculk_block, 0, 2);
		world.setBlock(i + 6, j + 12, k + 34, sculk_block, 0, 2);
		world.setBlock(i + 9, j + 12, k + 34, NovaCraftBlocks.nullstone_tiled_wall, 0, 2);
		world.setBlock(i + 10, j + 12, k + 34, NovaCraftBlocks.nullstone_tiled_wall, 0, 2);
		world.setBlock(i + 12, j + 12, k + 34, NovaCraftBlocks.nullstone_tiled_wall, 0, 2);
		world.setBlock(i + 13, j + 12, k + 34, NovaCraftBlocks.nullstone_tiled_wall, 0, 2);
		world.setBlock(i + 2, j + 12, k + 35, sculk_block, 0, 2);
		world.setBlock(i + 4, j + 12, k + 35, sculk_block, 0, 2);
		world.setBlock(i + 6, j + 12, k + 35, sculk_block, 0, 2);
		world.setBlock(i + 9, j + 12, k + 35, NovaCraftBlocks.nullstone_tiled_wall, 0, 2);
		world.setBlock(i + 13, j + 12, k + 35, NovaCraftBlocks.nullstone_tiled_wall, 0, 2);
		world.setBlock(i + 9, j + 12, k + 36, NovaCraftBlocks.nullstone_tiled_wall, 0, 2);
		world.setBlock(i + 9, j + 12, k + 37, NovaCraftBlocks.nullstone_tiled_wall, 0, 2);
		world.setBlock(i + 13, j + 12, k + 37, NovaCraftBlocks.nullstone_tiled_wall, 0, 2);
		world.setBlock(i + 9, j + 12, k + 38, NovaCraftBlocks.nullstone_tiled_wall, 0, 2);
		world.setBlock(i + 10, j + 12, k + 38, NovaCraftBlocks.nullstone_tiled_wall, 0, 2);
		world.setBlock(i + 12, j + 12, k + 38, NovaCraftBlocks.nullstone_tiled_wall, 0, 2);
		world.setBlock(i + 13, j + 12, k + 38, NovaCraftBlocks.nullstone_tiled_wall, 0, 2);
		world.setBlock(i + 5, j + 13, k + 2, sculk_block, 0, 2);
		world.setBlock(i + 10, j + 13, k + 2, nullstone_tiles, 0, 2);
		world.setBlock(i + 11, j + 13, k + 2, nullstone_tiles, 0, 2);
		world.setBlock(i + 12, j + 13, k + 2, nullstone_tiles, 0, 2);
		world.setBlock(i + 3, j + 13, k + 3, sculk_block, 0, 2);
		world.setBlock(i + 5, j + 13, k + 3, sculk_block, 0, 2);
		world.setBlock(i + 9, j + 13, k + 3, nullstone_tiles, 0, 2);
		world.setBlock(i + 13, j + 13, k + 3, nullstone_tiles, 0, 2);
		world.setBlock(i + 6, j + 13, k + 4, sculk_block, 0, 2);
		world.setBlock(i + 9, j + 13, k + 4, nullstone_tiles, 0, 2);
		world.setBlock(i + 13, j + 13, k + 4, nullstone_tiles, 0, 2);
		world.setBlock(i + 9, j + 13, k + 5, nullstone_tiles, 0, 2);
		world.setBlock(i + 13, j + 13, k + 5, nullstone_tiles, 0, 2);
		world.setBlock(i + 6, j + 13, k + 6, sculk_block, 0, 2);
		world.setBlock(i + 10, j + 13, k + 6, nullstone_tiles, 0, 2);
		world.setBlock(i + 11, j + 13, k + 6, nullstone_tiles, 0, 2);
		world.setBlock(i + 12, j + 13, k + 6, nullstone_tiles, 0, 2);
		world.setBlock(i + 2, j + 13, k + 7, sculk_block, 0, 2);
		world.setBlock(i + 5, j + 13, k + 8, sculk_block, 0, 2);
		world.setBlock(i + 5, j + 13, k + 31, sculk_block, 0, 2);
		world.setBlock(i + 6, j + 13, k + 31, sculk_block, 0, 2);
		world.setBlock(i + 2, j + 13, k + 32, sculk_block, 0, 2);
		world.setBlock(i + 5, j + 13, k + 32, sculk_block, 0, 2);
		world.setBlock(i + 2, j + 13, k + 33, sculk_block, 0, 2);
		world.setBlock(i + 6, j + 13, k + 33, sculk_block, 0, 2);
		world.setBlock(i + 10, j + 13, k + 34, nullstone_tiles, 0, 2);
		world.setBlock(i + 11, j + 13, k + 34, nullstone_tiles, 0, 2);
		world.setBlock(i + 12, j + 13, k + 34, nullstone_tiles, 0, 2);
		world.setBlock(i + 2, j + 13, k + 35, sculk_block, 0, 2);
		world.setBlock(i + 6, j + 13, k + 35, sculk_block, 0, 2);
		world.setBlock(i + 9, j + 13, k + 35, nullstone_tiles, 0, 2);
		world.setBlock(i + 13, j + 13, k + 35, nullstone_tiles, 0, 2);
		world.setBlock(i + 3, j + 13, k + 36, sculk_block, 0, 2);
		world.setBlock(i + 9, j + 13, k + 36, nullstone_tiles, 0, 2);
		world.setBlock(i + 13, j + 13, k + 36, nullstone_tiles, 0, 2);
		world.setBlock(i + 3, j + 13, k + 37, sculk_block, 0, 2);
		world.setBlock(i + 9, j + 13, k + 37, nullstone_tiles, 0, 2);
		world.setBlock(i + 13, j + 13, k + 37, nullstone_tiles, 0, 2);
		world.setBlock(i + 10, j + 13, k + 38, nullstone_tiles, 0, 2);
		world.setBlock(i + 11, j + 13, k + 38, nullstone_tiles, 0, 2);
		world.setBlock(i + 12, j + 13, k + 38, nullstone_tiles, 0, 2);
		world.setBlock(i + 5, j + 14, k + 0, sculk_block, 0, 2);
		world.setBlock(i + 3, j + 14, k + 1, sculk_block, 0, 2);
		world.setBlock(i + 5, j + 14, k + 1, sculk_block, 0, 2);
		world.setBlock(i + 5, j + 14, k + 2, sculk_block, 0, 2);
		world.setBlock(i + 3, j + 14, k + 3, sculk_block, 0, 2);
		world.setBlock(i + 10, j + 14, k + 3, nullstone_tiles, 0, 2);
		world.setBlock(i + 11, j + 14, k + 3, nullstone_tiles, 0, 2);
		world.setBlock(i + 12, j + 14, k + 3, nullstone_tiles, 0, 2);
		world.setBlock(i + 6, j + 14, k + 4, sculk_block, 0, 2);
		world.setBlock(i + 10, j + 14, k + 4, nullstone_tiles, 0, 2);
		world.setBlock(i + 11, j + 14, k + 4, Blocks.glowstone, 0, 2);
		world.setBlock(i + 12, j + 14, k + 4, nullstone_tiles, 0, 2);
		world.setBlock(i + 10, j + 14, k + 5, nullstone_tiles, 0, 2);
		world.setBlock(i + 11, j + 14, k + 5, nullstone_tiles, 0, 2);
		world.setBlock(i + 12, j + 14, k + 5, nullstone_tiles, 0, 2);
		world.setBlock(i + 2, j + 14, k + 6, sculk_block, 0, 2);
		world.setBlock(i + 2, j + 14, k + 7, sculk_block, 0, 2);
		world.setBlock(i + 3, j + 14, k + 8, sculk_block, 0, 2);
		world.setBlock(i + 5, j + 14, k + 8, sculk_block, 0, 2);
		world.setBlock(i + 3, j + 14, k + 31, sculk_block, 0, 2);
		world.setBlock(i + 5, j + 14, k + 31, sculk_block, 0, 2);
		world.setBlock(i + 6, j + 14, k + 31, sculk_tendrils, 0, 2);
		world.setBlock(i + 2, j + 14, k + 32, sculk_block, 0, 2);
		world.setBlock(i + 6, j + 14, k + 32, sculk_block, 0, 2);
		world.setBlock(i + 2, j + 14, k + 33, sculk_block, 0, 2);
		world.setBlock(i + 10, j + 14, k + 35, nullstone_tiles, 0, 2);
		world.setBlock(i + 11, j + 14, k + 35, nullstone_tiles, 0, 2);
		world.setBlock(i + 12, j + 14, k + 35, nullstone_tiles, 0, 2);
		world.setBlock(i + 3, j + 14, k + 36, sculk_block, 0, 2);
		world.setBlock(i + 4, j + 14, k + 36, sculk_block, 0, 2);
		world.setBlock(i + 10, j + 14, k + 36, nullstone_tiles, 0, 2);
		world.setBlock(i + 11, j + 14, k + 36, Blocks.glowstone, 0, 2);
		world.setBlock(i + 12, j + 14, k + 36, nullstone_tiles, 0, 2);
		world.setBlock(i + 3, j + 14, k + 37, sculk_block, 0, 2);
		world.setBlock(i + 5, j + 14, k + 37, sculk_block, 0, 2);
		world.setBlock(i + 10, j + 14, k + 37, nullstone_tiles, 0, 2);
		world.setBlock(i + 11, j + 14, k + 37, nullstone_tiles, 0, 2);
		world.setBlock(i + 12, j + 14, k + 37, nullstone_tiles, 0, 2);
		world.setBlock(i + 3, j + 14, k + 38, sculk_block, 0, 2);
		world.setBlock(i + 5, j + 14, k + 38, sculk_block, 0, 2);
		world.setBlock(i + 3, j + 14, k + 39, sculk_block, 0, 2);
		world.setBlock(i + 4, j + 14, k + 39, sculk_block, 0, 2);
		world.setBlock(i + 3, j + 15, k + 0, sculk_block, 0, 2);
		world.setBlock(i + 5, j + 15, k + 1, sculk_block, 0, 2);
		world.setBlock(i + 3, j + 15, k + 3, NovaCraftBlocks.sculk_tentacle_2, 1, 2);
		world.setBlock(i + 3, j + 15, k + 4, sculk_block, 0, 2);
		world.setBlock(i + 4, j + 15, k + 4, sculk_block, 0, 2);
		world.setBlock(i + 6, j + 15, k + 5, sculk_block, 0, 2);
		world.setBlock(i + 2, j + 15, k + 6, sculk_block, 0, 2);
		world.setBlock(i + 6, j + 15, k + 6, sculk_block, 0, 2);
		world.setBlock(i + 2, j + 15, k + 7, sculk_block, 0, 2);
		world.setBlock(i + 2, j + 15, k + 8, sculk_block, 0, 2);
		world.setBlock(i + 5, j + 15, k + 8, sculk_block, 0, 2);
		world.setBlock(i + 3, j + 15, k + 31, sculk_block, 0, 2);
		world.setBlock(i + 6, j + 15, k + 31, sculk_block, 0, 2);
		world.setBlock(i + 2, j + 15, k + 32, sculk_block, 0, 2);
		world.setBlock(i + 2, j + 15, k + 33, sculk_block, 0, 2);
		world.setBlock(i + 6, j + 15, k + 33, sculk_block, 0, 2);
		world.setBlock(i + 4, j + 15, k + 35, sculk_block, 0, 2);
		world.setBlock(i + 3, j + 15, k + 36, sculk_tendrils, 0, 2);
		world.setBlock(i + 5, j + 15, k + 37, sculk_tendrils, 0, 2);
		world.setBlock(i + 3, j + 15, k + 38, sculk_block, 0, 2);
		world.setBlock(i + 5, j + 15, k + 38, sculk_block, 0, 2);
		world.setBlock(i + 3, j + 15, k + 39, sculk_block, 0, 2);
		world.setBlock(i + 3, j + 16, k + 0, sculk_block, 0, 2);
		world.setBlock(i + 4, j + 16, k + 4, sculk_block, 0, 2);
		world.setBlock(i + 2, j + 16, k + 5, sculk_block, 0, 2);
		world.setBlock(i + 6, j + 16, k + 5, sculk_block, 0, 2);
		world.setBlock(i + 2, j + 16, k + 6, sculk_block, 0, 2);
		world.setBlock(i + 6, j + 16, k + 6, sculk_block, 0, 2);
		world.setBlock(i + 2, j + 16, k + 7, sculk_block, 0, 2);
		world.setBlock(i + 6, j + 16, k + 7, sculk_block, 0, 2);
		world.setBlock(i + 6, j + 16, k + 8, sculk_block, 0, 2);
		world.setBlock(i + 2, j + 16, k + 31, sculk_block, 0, 2);
		world.setBlock(i + 3, j + 16, k + 31, sculk_block, 0, 2);
		world.setBlock(i + 5, j + 16, k + 31, sculk_block, 0, 2);
		world.setBlock(i + 6, j + 16, k + 31, sculk_block, 0, 2);
		world.setBlock(i + 2, j + 16, k + 32, sculk_block, 0, 2);
		world.setBlock(i + 6, j + 16, k + 33, sculk_block, 0, 2);
		world.setBlock(i + 2, j + 16, k + 34, sculk_block, 0, 2);
		world.setBlock(i + 6, j + 16, k + 34, sculk_block, 0, 2);
		world.setBlock(i + 2, j + 16, k + 35, sculk_block, 0, 2);
		world.setBlock(i + 6, j + 16, k + 35, sculk_block, 0, 2);
		world.setBlock(i + 3, j + 16, k + 38, sculk_block, 0, 2);
		world.setBlock(i + 3, j + 16, k + 39, sculk_block, 0, 2);
		world.setBlock(i + 4, j + 16, k + 39, sculk_block, 0, 2);
		world.setBlock(i + 5, j + 16, k + 39, sculk_block, 0, 2);
		world.setBlock(i + 3, j + 17, k + 0, sculk_block, 0, 2);
		world.setBlock(i + 4, j + 17, k + 0, sculk_block, 0, 2);
		world.setBlock(i + 3, j + 17, k + 1, sculk_block, 0, 2);
		world.setBlock(i + 4, j + 17, k + 1, sculk_block, 0, 2);
		world.setBlock(i + 3, j + 17, k + 2, sculk_block, 0, 2);
		world.setBlock(i + 4, j + 17, k + 2, sculk_block, 0, 2);
		world.setBlock(i + 3, j + 17, k + 3, sculk_block, 0, 2);
		world.setBlock(i + 4, j + 17, k + 3, sculk_block, 0, 2);
		world.setBlock(i + 2, j + 17, k + 5, sculk_block, 0, 2);
		world.setBlock(i + 3, j + 17, k + 5, sculk_block, 0, 2);
		world.setBlock(i + 6, j + 17, k + 5, sculk_block, 0, 2);
		world.setBlock(i + 2, j + 17, k + 6, sculk_block, 0, 2);
		world.setBlock(i + 6, j + 17, k + 6, sculk_block, 0, 2);
		world.setBlock(i + 2, j + 17, k + 7, sculk_block, 0, 2);
		world.setBlock(i + 6, j + 17, k + 7, sculk_block, 0, 2);
		world.setBlock(i + 2, j + 17, k + 8, sculk_block, 0, 2);
		world.setBlock(i + 6, j + 17, k + 8, sculk_block, 0, 2);
		world.setBlock(i + 2, j + 17, k + 9, sculk_block, 0, 2);
		world.setBlock(i + 3, j + 17, k + 9, sculk_block, 0, 2);
		world.setBlock(i + 6, j + 17, k + 9, sculk_block, 0, 2);
		world.setBlock(i + 2, j + 17, k + 30, sculk_block, 0, 2);
		world.setBlock(i + 6, j + 17, k + 30, sculk_block, 0, 2);
		world.setBlock(i + 2, j + 17, k + 31, sculk_block, 0, 2);
		world.setBlock(i + 3, j + 17, k + 31, sculk_block, 0, 2);
		world.setBlock(i + 5, j + 17, k + 31, sculk_block, 0, 2);
		world.setBlock(i + 2, j + 17, k + 32, sculk_block, 0, 2);
		world.setBlock(i + 6, j + 17, k + 33, sculk_block, 0, 2);
		world.setBlock(i + 6, j + 17, k + 34, sculk_block, 0, 2);
		world.setBlock(i + 2, j + 17, k + 35, sculk_block, 0, 2);
		world.setBlock(i + 6, j + 17, k + 35, sculk_block, 0, 2);
		world.setBlock(i + 3, j + 17, k + 36, sculk_block, 0, 2);
		world.setBlock(i + 5, j + 17, k + 36, sculk_block, 0, 2);
		world.setBlock(i + 5, j + 17, k + 37, sculk_block, 0, 2);
		world.setBlock(i + 5, j + 17, k + 38, sculk_block, 0, 2);
		world.setBlock(i + 3, j + 17, k + 39, sculk_block, 0, 2);
		world.setBlock(i + 4, j + 17, k + 39, sculk_block, 0, 2);
		world.setBlock(i + 5, j + 17, k + 39, sculk_block, 0, 2);
		world.setBlock(i + 3, j + 18, k + 0, sculk_block, 0, 2);
		world.setBlock(i + 4, j + 18, k + 0, sculk_block, 0, 2);
		world.setBlock(i + 3, j + 18, k + 1, sculk_block, 0, 2);
		world.setBlock(i + 4, j + 18, k + 1, sculk_block, 0, 2);
		world.setBlock(i + 5, j + 18, k + 1, sculk_block, 0, 2);
		world.setBlock(i + 3, j + 18, k + 2, sculk_block, 0, 2);
		world.setBlock(i + 4, j + 18, k + 2, sculk_block, 0, 2);
		world.setBlock(i + 5, j + 18, k + 2, sculk_block, 0, 2);
		world.setBlock(i + 3, j + 18, k + 3, sculk_block, 0, 2);
		world.setBlock(i + 4, j + 18, k + 3, sculk_block, 0, 2);
		world.setBlock(i + 5, j + 18, k + 3, sculk_block, 0, 2);
		world.setBlock(i + 2, j + 18, k + 4, sculk_block, 0, 2);
		world.setBlock(i + 6, j + 18, k + 4, sculk_block, 0, 2);
		world.setBlock(i + 2, j + 18, k + 5, sculk_block, 0, 2);
		world.setBlock(i + 6, j + 18, k + 5, sculk_block, 0, 2);
		world.setBlock(i + 2, j + 18, k + 6, sculk_block, 0, 2);
		world.setBlock(i + 6, j + 18, k + 6, sculk_block, 0, 2);
		world.setBlock(i + 2, j + 18, k + 7, sculk_block, 0, 2);
		world.setBlock(i + 6, j + 18, k + 7, sculk_block, 0, 2);
		world.setBlock(i + 2, j + 18, k + 8, sculk_block, 0, 2);
		world.setBlock(i + 3, j + 18, k + 8, sculk_block, 0, 2);
		world.setBlock(i + 6, j + 18, k + 8, sculk_block, 0, 2);
		world.setBlock(i + 2, j + 18, k + 9, sculk_block, 0, 2);
		world.setBlock(i + 3, j + 18, k + 9, sculk_block, 0, 2);
		world.setBlock(i + 2, j + 18, k + 10, sculk_block, 0, 2);
		world.setBlock(i + 5, j + 18, k + 10, sculk_block, 0, 2);
		world.setBlock(i + 3, j + 18, k + 11, sculk_block, 0, 2);
		world.setBlock(i + 5, j + 18, k + 11, sculk_block, 0, 2);
		world.setBlock(i + 6, j + 18, k + 11, sculk_block, 0, 2);
		world.setBlock(i + 2, j + 18, k + 12, sculk_block, 0, 2);
		world.setBlock(i + 3, j + 18, k + 12, sculk_block, 0, 2);
		world.setBlock(i + 5, j + 18, k + 12, sculk_block, 0, 2);
		world.setBlock(i + 6, j + 18, k + 12, sculk_block, 0, 2);
		world.setBlock(i + 3, j + 18, k + 13, sculk_block, 0, 2);
		world.setBlock(i + 5, j + 18, k + 13, sculk_block, 0, 2);
		world.setBlock(i + 5, j + 18, k + 14, sculk_block, 0, 2);
		world.setBlock(i + 3, j + 18, k + 15, sculk_block, 0, 2);
		world.setBlock(i + 2, j + 18, k + 16, sculk_block, 0, 2);
		world.setBlock(i + 2, j + 18, k + 17, sculk_block, 0, 2);
		world.setBlock(i + 3, j + 18, k + 17, sculk_block, 0, 2);
		world.setBlock(i + 2, j + 18, k + 20, sculk_block, 0, 2);
		world.setBlock(i + 3, j + 18, k + 21, sculk_block, 0, 2);
		world.setBlock(i + 5, j + 18, k + 21, sculk_block, 0, 2);
		world.setBlock(i + 3, j + 18, k + 22, sculk_block, 0, 2);
		world.setBlock(i + 5, j + 18, k + 22, sculk_block, 0, 2);
		world.setBlock(i + 2, j + 18, k + 23, sculk_block, 0, 2);
		world.setBlock(i + 5, j + 18, k + 23, sculk_block, 0, 2);
		world.setBlock(i + 2, j + 18, k + 24, sculk_block, 0, 2);
		world.setBlock(i + 5, j + 18, k + 24, sculk_block, 0, 2);
		world.setBlock(i + 6, j + 18, k + 24, sculk_block, 0, 2);
		world.setBlock(i + 3, j + 18, k + 25, sculk_block, 0, 2);
		world.setBlock(i + 5, j + 18, k + 25, sculk_block, 0, 2);
		world.setBlock(i + 5, j + 18, k + 26, sculk_block, 0, 2);
		world.setBlock(i + 2, j + 18, k + 27, sculk_block, 0, 2);
		world.setBlock(i + 3, j + 18, k + 27, sculk_block, 0, 2);
		world.setBlock(i + 5, j + 18, k + 27, sculk_block, 0, 2);
		world.setBlock(i + 6, j + 18, k + 27, sculk_block, 0, 2);
		world.setBlock(i + 3, j + 18, k + 28, sculk_block, 0, 2);
		world.setBlock(i + 5, j + 18, k + 28, sculk_block, 0, 2);
		world.setBlock(i + 6, j + 18, k + 28, sculk_block, 0, 2);
		world.setBlock(i + 2, j + 18, k + 29, sculk_block, 0, 2);
		world.setBlock(i + 3, j + 18, k + 29, sculk_block, 0, 2);
		world.setBlock(i + 5, j + 18, k + 29, sculk_block, 0, 2);
		world.setBlock(i + 2, j + 18, k + 30, sculk_block, 0, 2);
		world.setBlock(i + 3, j + 18, k + 30, sculk_block, 0, 2);
		world.setBlock(i + 2, j + 18, k + 31, sculk_block, 0, 2);
		world.setBlock(i + 6, j + 18, k + 32, sculk_block, 0, 2);
		world.setBlock(i + 6, j + 18, k + 33, sculk_block, 0, 2);
		world.setBlock(i + 6, j + 18, k + 34, sculk_block, 0, 2);
		world.setBlock(i + 3, j + 18, k + 36, sculk_block, 0, 2);
		world.setBlock(i + 4, j + 18, k + 36, sculk_block, 0, 2);
		world.setBlock(i + 3, j + 18, k + 37, sculk_block, 0, 2);
		world.setBlock(i + 4, j + 18, k + 37, sculk_block, 0, 2);
		world.setBlock(i + 3, j + 18, k + 38, sculk_block, 0, 2);
		world.setBlock(i + 5, j + 18, k + 38, sculk_block, 0, 2);
		world.setBlock(i + 3, j + 18, k + 39, sculk_block, 0, 2);
		world.setBlock(i + 5, j + 18, k + 39, sculk_tendrils, 0, 2);
		world.setBlock(i + 3, j + 19, k + 1, NovaCraftBlocks.sculk_tentacle_2, 1, 2);
		world.setBlock(i + 4, j + 19, k + 1, sculk_tendrils, 0, 2);
		world.setBlock(i + 5, j + 19, k + 2, sculk_tendrils, 0, 2);
		world.setBlock(i + 2, j + 19, k + 4, sculk_block, 0, 2);
		world.setBlock(i + 3, j + 19, k + 4, sculk_block, 0, 2);
		world.setBlock(i + 4, j + 19, k + 4, sculk_block, 0, 2);
		world.setBlock(i + 5, j + 19, k + 4, sculk_block, 0, 2);
		world.setBlock(i + 6, j + 19, k + 4, sculk_block, 0, 2);
		world.setBlock(i + 2, j + 19, k + 5, sculk_block, 0, 2);
		world.setBlock(i + 2, j + 19, k + 6, sculk_block, 0, 2);
		world.setBlock(i + 6, j + 19, k + 6, sculk_block, 0, 2);
		world.setBlock(i + 2, j + 19, k + 7, sculk_block, 0, 2);
		world.setBlock(i + 3, j + 19, k + 7, sculk_block, 0, 2);
		world.setBlock(i + 5, j + 19, k + 7, sculk_block, 0, 2);
		world.setBlock(i + 2, j + 19, k + 8, sculk_block, 0, 2);
		world.setBlock(i + 3, j + 19, k + 8, sculk_block, 0, 2);
		world.setBlock(i + 6, j + 19, k + 8, sculk_block, 0, 2);
		world.setBlock(i + 2, j + 19, k + 9, sculk_block, 0, 2);
		world.setBlock(i + 6, j + 19, k + 9, sculk_block, 0, 2);
		world.setBlock(i + 2, j + 19, k + 10, sculk_block, 0, 2);
		world.setBlock(i + 6, j + 19, k + 10, sculk_block, 0, 2);
		world.setBlock(i + 6, j + 19, k + 11, sculk_block, 0, 2);
		world.setBlock(i + 6, j + 19, k + 12, sculk_block, 0, 2);
		world.setBlock(i + 3, j + 19, k + 13, sculk_block, 0, 2);
		world.setBlock(i + 6, j + 19, k + 13, sculk_block, 0, 2);
		world.setBlock(i + 2, j + 19, k + 17, sculk_block, 0, 2);
		world.setBlock(i + 2, j + 19, k + 19, sculk_block, 0, 2);
		world.setBlock(i + 2, j + 19, k + 20, sculk_block, 0, 2);
		world.setBlock(i + 2, j + 19, k + 21, sculk_block, 0, 2);
		world.setBlock(i + 6, j + 19, k + 22, sculk_block, 0, 2);
		world.setBlock(i + 6, j + 19, k + 23, sculk_block, 0, 2);
		world.setBlock(i + 2, j + 19, k + 24, sculk_block, 0, 2);
		world.setBlock(i + 6, j + 19, k + 24, sculk_block, 0, 2);
		world.setBlock(i + 6, j + 19, k + 25, sculk_block, 0, 2);
		world.setBlock(i + 6, j + 19, k + 26, sculk_block, 0, 2);
		world.setBlock(i + 6, j + 19, k + 27, sculk_block, 0, 2);
		world.setBlock(i + 2, j + 19, k + 28, sculk_block, 0, 2);
		world.setBlock(i + 6, j + 19, k + 28, sculk_block, 0, 2);
		world.setBlock(i + 2, j + 19, k + 29, sculk_block, 0, 2);
		world.setBlock(i + 6, j + 19, k + 29, sculk_block, 0, 2);
		world.setBlock(i + 5, j + 19, k + 30, sculk_block, 0, 2);
		world.setBlock(i + 6, j + 19, k + 30, sculk_block, 0, 2);
		world.setBlock(i + 5, j + 19, k + 31, sculk_block, 0, 2);
		world.setBlock(i + 6, j + 19, k + 31, sculk_block, 0, 2);
		world.setBlock(i + 5, j + 19, k + 32, sculk_block, 0, 2);
		world.setBlock(i + 6, j + 19, k + 32, sculk_block, 0, 2);
		world.setBlock(i + 2, j + 19, k + 33, sculk_block, 0, 2);
		world.setBlock(i + 2, j + 19, k + 34, sculk_block, 0, 2);
		world.setBlock(i + 6, j + 19, k + 34, sculk_block, 0, 2);
		world.setBlock(i + 2, j + 19, k + 35, sculk_block, 0, 2);
		world.setBlock(i + 3, j + 19, k + 35, sculk_block, 0, 2);
		world.setBlock(i + 4, j + 19, k + 35, sculk_block, 0, 2);
		world.setBlock(i + 3, j + 19, k + 36, NovaCraftBlocks.sculk_tentacle_2, 1, 2);
		world.setBlock(i + 4, j + 19, k + 37, sculk_tendrils, 0, 2);
		world.setBlock(i + 4, j + 20, k + 1, sculk_tendrils, 0, 2);
		world.setBlock(i + 2, j + 20, k + 4, sculk_block, 0, 2);
		world.setBlock(i + 3, j + 20, k + 4, sculk_block, 0, 2);
		world.setBlock(i + 4, j + 20, k + 4, sculk_block, 0, 2);
		world.setBlock(i + 5, j + 20, k + 4, sculk_block, 0, 2);
		world.setBlock(i + 2, j + 20, k + 5, sculk_block, 0, 2);
		world.setBlock(i + 2, j + 20, k + 6, sculk_block, 0, 2);
		world.setBlock(i + 2, j + 20, k + 7, sculk_block, 0, 2);
		world.setBlock(i + 5, j + 20, k + 7, sculk_block, 0, 2);
		world.setBlock(i + 2, j + 20, k + 8, sculk_block, 0, 2);
		world.setBlock(i + 5, j + 20, k + 8, sculk_block, 0, 2);
		world.setBlock(i + 6, j + 20, k + 9, sculk_block, 0, 2);
		world.setBlock(i + 2, j + 20, k + 10, sculk_block, 0, 2);
		world.setBlock(i + 6, j + 20, k + 10, sculk_block, 0, 2);
		world.setBlock(i + 2, j + 20, k + 11, sculk_block, 0, 2);
		world.setBlock(i + 6, j + 20, k + 11, sculk_block, 0, 2);
		world.setBlock(i + 6, j + 20, k + 12, sculk_block, 0, 2);
		world.setBlock(i + 2, j + 20, k + 13, sculk_block, 0, 2);
		world.setBlock(i + 6, j + 20, k + 13, sculk_block, 0, 2);
		world.setBlock(i + 2, j + 20, k + 14, sculk_block, 0, 2);
		world.setBlock(i + 6, j + 20, k + 14, sculk_block, 0, 2);
		world.setBlock(i + 2, j + 20, k + 15, sculk_block, 0, 2);
		world.setBlock(i + 2, j + 20, k + 16, sculk_block, 0, 2);
		world.setBlock(i + 2, j + 20, k + 17, sculk_block, 0, 2);
		world.setBlock(i + 6, j + 20, k + 17, sculk_block, 0, 2);
		world.setBlock(i + 2, j + 20, k + 18, sculk_block, 0, 2);
		world.setBlock(i + 2, j + 20, k + 19, sculk_block, 0, 2);
		world.setBlock(i + 6, j + 20, k + 19, sculk_block, 0, 2);
		world.setBlock(i + 2, j + 20, k + 22, sculk_block, 0, 2);
		world.setBlock(i + 6, j + 20, k + 23, sculk_block, 0, 2);
		world.setBlock(i + 6, j + 20, k + 24, sculk_block, 0, 2);
		world.setBlock(i + 2, j + 20, k + 25, sculk_block, 0, 2);
		world.setBlock(i + 6, j + 20, k + 25, sculk_block, 0, 2);
		world.setBlock(i + 2, j + 20, k + 26, sculk_block, 0, 2);
		world.setBlock(i + 6, j + 20, k + 26, sculk_block, 0, 2);
		world.setBlock(i + 2, j + 20, k + 27, sculk_block, 0, 2);
		world.setBlock(i + 6, j + 20, k + 27, sculk_block, 0, 2);
		world.setBlock(i + 6, j + 20, k + 28, sculk_block, 0, 2);
		world.setBlock(i + 2, j + 20, k + 29, sculk_block, 0, 2);
		world.setBlock(i + 6, j + 20, k + 29, sculk_block, 0, 2);
		world.setBlock(i + 2, j + 20, k + 30, sculk_block, 0, 2);
		world.setBlock(i + 6, j + 20, k + 30, sculk_block, 0, 2);
		world.setBlock(i + 5, j + 20, k + 31, sculk_block, 0, 2);
		world.setBlock(i + 6, j + 20, k + 31, sculk_block, 0, 2);
		world.setBlock(i + 2, j + 20, k + 32, sculk_block, 0, 2);
		world.setBlock(i + 6, j + 20, k + 32, sculk_block, 0, 2);
		world.setBlock(i + 2, j + 20, k + 33, sculk_block, 0, 2);
		world.setBlock(i + 6, j + 20, k + 33, sculk_block, 0, 2);
		world.setBlock(i + 2, j + 20, k + 35, sculk_block, 0, 2);
		world.setBlock(i + 3, j + 20, k + 35, sculk_block, 0, 2);
		world.setBlock(i + 4, j + 20, k + 35, sculk_block, 0, 2);
		world.setBlock(i + 2, j + 21, k + 4, sculk_block, 0, 2);
		world.setBlock(i + 3, j + 21, k + 4, sculk_block, 0, 2);
		world.setBlock(i + 2, j + 21, k + 5, sculk_block, 0, 2);
		world.setBlock(i + 3, j + 21, k + 5, sculk_block, 0, 2);
		world.setBlock(i + 4, j + 21, k + 5, sculk_block, 0, 2);
		world.setBlock(i + 2, j + 21, k + 6, sculk_block, 0, 2);
		world.setBlock(i + 2, j + 21, k + 7, sculk_block, 0, 2);
		world.setBlock(i + 2, j + 21, k + 8, sculk_block, 0, 2);
		world.setBlock(i + 5, j + 21, k + 8, sculk_block, 0, 2);
		world.setBlock(i + 6, j + 21, k + 9, sculk_block, 0, 2);
		world.setBlock(i + 2, j + 21, k + 10, sculk_block, 0, 2);
		world.setBlock(i + 6, j + 21, k + 10, sculk_block, 0, 2);
		world.setBlock(i + 2, j + 21, k + 11, sculk_block, 0, 2);
		world.setBlock(i + 4, j + 21, k + 11, sculk_block, 0, 2);
		world.setBlock(i + 6, j + 21, k + 11, sculk_block, 0, 2);
		world.setBlock(i + 2, j + 21, k + 12, sculk_block, 0, 2);
		world.setBlock(i + 2, j + 21, k + 13, sculk_block, 0, 2);
		world.setBlock(i + 2, j + 21, k + 14, sculk_block, 0, 2);
		world.setBlock(i + 6, j + 21, k + 14, sculk_block, 0, 2);
		world.setBlock(i + 2, j + 21, k + 15, sculk_block, 0, 2);
		world.setBlock(i + 2, j + 21, k + 16, sculk_block, 0, 2);
		world.setBlock(i + 6, j + 21, k + 17, sculk_block, 0, 2);
		world.setBlock(i + 2, j + 21, k + 18, sculk_block, 0, 2);
		world.setBlock(i + 6, j + 21, k + 18, sculk_block, 0, 2);
		world.setBlock(i + 2, j + 21, k + 19, sculk_block, 0, 2);
		world.setBlock(i + 4, j + 21, k + 19, sculk_block, 0, 2);
		world.setBlock(i + 5, j + 21, k + 19, sculk_block, 0, 2);
		world.setBlock(i + 6, j + 21, k + 19, sculk_block, 0, 2);
		world.setBlock(i + 2, j + 21, k + 20, sculk_block, 0, 2);
		world.setBlock(i + 6, j + 21, k + 20, sculk_block, 0, 2);
		world.setBlock(i + 2, j + 21, k + 21, sculk_block, 0, 2);
		world.setBlock(i + 2, j + 21, k + 22, sculk_block, 0, 2);
		world.setBlock(i + 6, j + 21, k + 22, sculk_block, 0, 2);
		world.setBlock(i + 6, j + 21, k + 23, sculk_block, 0, 2);
		world.setBlock(i + 2, j + 21, k + 24, sculk_block, 0, 2);
		world.setBlock(i + 6, j + 21, k + 24, sculk_block, 0, 2);
		world.setBlock(i + 2, j + 21, k + 25, sculk_block, 0, 2);
		world.setBlock(i + 6, j + 21, k + 25, sculk_block, 0, 2);
		world.setBlock(i + 2, j + 21, k + 26, sculk_block, 0, 2);
		world.setBlock(i + 6, j + 21, k + 26, sculk_block, 0, 2);
		world.setBlock(i + 2, j + 21, k + 27, sculk_block, 0, 2);
		world.setBlock(i + 6, j + 21, k + 27, sculk_block, 0, 2);
		world.setBlock(i + 4, j + 21, k + 28, sculk_block, 0, 2);
		world.setBlock(i + 6, j + 21, k + 28, sculk_block, 0, 2);
		world.setBlock(i + 2, j + 21, k + 29, sculk_block, 0, 2);
		world.setBlock(i + 6, j + 21, k + 29, sculk_block, 0, 2);
		world.setBlock(i + 3, j + 21, k + 30, sculk_block, 0, 2);
		world.setBlock(i + 6, j + 21, k + 30, sculk_block, 0, 2);
		world.setBlock(i + 2, j + 21, k + 31, sculk_block, 0, 2);
		world.setBlock(i + 6, j + 21, k + 31, sculk_block, 0, 2);
		world.setBlock(i + 2, j + 21, k + 32, sculk_block, 0, 2);
		world.setBlock(i + 3, j + 21, k + 32, sculk_block, 0, 2);
		world.setBlock(i + 4, j + 21, k + 32, sculk_block, 0, 2);
		world.setBlock(i + 4, j + 21, k + 33, sculk_block, 0, 2);
		world.setBlock(i + 2, j + 21, k + 35, sculk_block, 0, 2);
		world.setBlock(i + 3, j + 21, k + 35, sculk_block, 0, 2);
		world.setBlock(i + 4, j + 21, k + 35, sculk_block, 0, 2);
		world.setBlock(i + 6, j + 21, k + 35, sculk_block, 0, 2);
		world.setBlock(i + 3, j + 22, k + 4, sculk_tendrils, 0, 2);
		world.setBlock(i + 2, j + 22, k + 5, NovaCraftBlocks.sculk_tentacle_2, 1, 2);
		world.setBlock(i + 2, j + 22, k + 6, sculk_block, 0, 2);
		world.setBlock(i + 3, j + 22, k + 6, sculk_block, 0, 2);
		world.setBlock(i + 4, j + 22, k + 6, sculk_block, 0, 2);
		world.setBlock(i + 5, j + 22, k + 6, sculk_block, 0, 2);
		world.setBlock(i + 2, j + 22, k + 7, sculk_block, 0, 2);
		world.setBlock(i + 3, j + 22, k + 7, sculk_block, 0, 2);
		world.setBlock(i + 2, j + 22, k + 8, sculk_block, 0, 2);
		world.setBlock(i + 2, j + 22, k + 9, sculk_block, 0, 2);
		world.setBlock(i + 6, j + 22, k + 9, sculk_block, 0, 2);
		world.setBlock(i + 2, j + 22, k + 10, sculk_block, 0, 2);
		world.setBlock(i + 6, j + 22, k + 10, sculk_block, 0, 2);
		world.setBlock(i + 2, j + 22, k + 11, sculk_block, 0, 2);
		world.setBlock(i + 3, j + 22, k + 11, sculk_block, 0, 2);
		world.setBlock(i + 4, j + 22, k + 11, sculk_block, 0, 2);
		world.setBlock(i + 6, j + 22, k + 11, sculk_block, 0, 2);
		world.setBlock(i + 3, j + 22, k + 12, sculk_block, 0, 2);
		world.setBlock(i + 4, j + 22, k + 12, sculk_block, 0, 2);
		world.setBlock(i + 3, j + 22, k + 13, sculk_block, 0, 2);
		world.setBlock(i + 4, j + 22, k + 13, sculk_block, 0, 2);
		world.setBlock(i + 2, j + 22, k + 14, sculk_block, 0, 2);
		world.setBlock(i + 2, j + 22, k + 15, sculk_block, 0, 2);
		world.setBlock(i + 3, j + 22, k + 15, sculk_block, 0, 2);
		world.setBlock(i + 4, j + 22, k + 15, sculk_block, 0, 2);
		world.setBlock(i + 6, j + 22, k + 15, sculk_block, 0, 2);
		world.setBlock(i + 2, j + 22, k + 16, sculk_block, 0, 2);
		world.setBlock(i + 4, j + 22, k + 16, sculk_block, 0, 2);
		world.setBlock(i + 6, j + 22, k + 16, sculk_block, 0, 2);
		world.setBlock(i + 2, j + 22, k + 17, sculk_block, 0, 2);
		world.setBlock(i + 3, j + 22, k + 17, sculk_block, 0, 2);
		world.setBlock(i + 6, j + 22, k + 17, sculk_block, 0, 2);
		world.setBlock(i + 2, j + 22, k + 18, sculk_block, 0, 2);
		world.setBlock(i + 6, j + 22, k + 18, sculk_block, 0, 2);
		world.setBlock(i + 2, j + 22, k + 19, sculk_block, 0, 2);
		world.setBlock(i + 5, j + 22, k + 19, sculk_block, 0, 2);
		world.setBlock(i + 6, j + 22, k + 19, sculk_block, 0, 2);
		world.setBlock(i + 2, j + 22, k + 20, sculk_block, 0, 2);
		world.setBlock(i + 6, j + 22, k + 20, sculk_block, 0, 2);
		world.setBlock(i + 2, j + 22, k + 21, sculk_block, 0, 2);
		world.setBlock(i + 6, j + 22, k + 21, sculk_block, 0, 2);
		world.setBlock(i + 4, j + 22, k + 22, sculk_block, 0, 2);
		world.setBlock(i + 2, j + 22, k + 23, sculk_block, 0, 2);
		world.setBlock(i + 4, j + 22, k + 23, sculk_block, 0, 2);
		world.setBlock(i + 5, j + 22, k + 23, sculk_block, 0, 2);
		world.setBlock(i + 6, j + 22, k + 23, sculk_block, 0, 2);
		world.setBlock(i + 2, j + 22, k + 24, sculk_block, 0, 2);
		world.setBlock(i + 6, j + 22, k + 24, sculk_block, 0, 2);
		world.setBlock(i + 2, j + 22, k + 25, sculk_block, 0, 2);
		world.setBlock(i + 5, j + 22, k + 25, sculk_block, 0, 2);
		world.setBlock(i + 6, j + 22, k + 25, sculk_block, 0, 2);
		world.setBlock(i + 2, j + 22, k + 26, sculk_block, 0, 2);
		world.setBlock(i + 4, j + 22, k + 26, sculk_block, 0, 2);
		world.setBlock(i + 5, j + 22, k + 26, sculk_block, 0, 2);
		world.setBlock(i + 6, j + 22, k + 26, sculk_block, 0, 2);
		world.setBlock(i + 2, j + 22, k + 27, sculk_block, 0, 2);
		world.setBlock(i + 3, j + 22, k + 27, sculk_block, 0, 2);
		world.setBlock(i + 4, j + 22, k + 27, sculk_block, 0, 2);
		world.setBlock(i + 2, j + 22, k + 28, sculk_block, 0, 2);
		world.setBlock(i + 4, j + 22, k + 28, sculk_block, 0, 2);
		world.setBlock(i + 2, j + 22, k + 30, sculk_block, 0, 2);
		world.setBlock(i + 4, j + 22, k + 30, sculk_block, 0, 2);
		world.setBlock(i + 5, j + 22, k + 30, sculk_block, 0, 2);
		world.setBlock(i + 6, j + 22, k + 30, sculk_block, 0, 2);
		world.setBlock(i + 2, j + 22, k + 31, sculk_block, 0, 2);
		world.setBlock(i + 5, j + 22, k + 31, sculk_block, 0, 2);
		world.setBlock(i + 5, j + 22, k + 32, sculk_block, 0, 2);
		world.setBlock(i + 2, j + 22, k + 33, sculk_block, 0, 2);
		world.setBlock(i + 4, j + 22, k + 33, sculk_block, 0, 2);
		world.setBlock(i + 5, j + 22, k + 33, sculk_block, 0, 2);
		world.setBlock(i + 6, j + 22, k + 33, sculk_block, 0, 2);
		world.setBlock(i + 2, j + 22, k + 34, sculk_block, 0, 2);
		world.setBlock(i + 3, j + 22, k + 34, sculk_block, 0, 2);
		world.setBlock(i + 4, j + 22, k + 34, sculk_block, 0, 2);
		world.setBlock(i + 3, j + 22, k + 35, sculk_block, 0, 2);
		world.setBlock(i + 4, j + 22, k + 35, sculk_block, 0, 2);
		world.setBlock(i + 5, j + 22, k + 35, sculk_block, 0, 2);
		world.setBlock(i + 5, j + 23, k + 7, sculk_block, 0, 2);
		world.setBlock(i + 3, j + 23, k + 8, sculk_block, 0, 2);
		world.setBlock(i + 4, j + 23, k + 8, sculk_block, 0, 2);
		world.setBlock(i + 5, j + 23, k + 8, sculk_block, 0, 2);
		world.setBlock(i + 6, j + 23, k + 8, sculk_block, 0, 2);
		world.setBlock(i + 3, j + 23, k + 9, sculk_block, 0, 2);
		world.setBlock(i + 5, j + 23, k + 9, sculk_block, 0, 2);
		world.setBlock(i + 6, j + 23, k + 9, sculk_block, 0, 2);
		world.setBlock(i + 3, j + 23, k + 10, sculk_block, 0, 2);
		world.setBlock(i + 4, j + 23, k + 10, sculk_block, 0, 2);
		world.setBlock(i + 6, j + 23, k + 11, sculk_block, 0, 2);
		world.setBlock(i + 5, j + 23, k + 12, sculk_block, 0, 2);
		world.setBlock(i + 5, j + 23, k + 13, sculk_block, 0, 2);
		world.setBlock(i + 4, j + 23, k + 14, sculk_block, 0, 2);
		world.setBlock(i + 4, j + 23, k + 15, NovaCraftBlocks.sculk_tentacle_2, 1, 2);
		world.setBlock(i + 5, j + 23, k + 15, sculk_block, 0, 2);
		world.setBlock(i + 2, j + 23, k + 16, sculk_block, 0, 2);
		world.setBlock(i + 3, j + 23, k + 16, sculk_block, 0, 2);
		world.setBlock(i + 4, j + 23, k + 16, NovaCraftBlocks.sculk_tentacle_2, 1, 2);
		world.setBlock(i + 5, j + 23, k + 16, sculk_block, 0, 2);
		world.setBlock(i + 6, j + 23, k + 16, sculk_block, 0, 2);
		world.setBlock(i + 3, j + 23, k + 17, NovaCraftBlocks.sculk_tentacle_2, 1, 2);
		world.setBlock(i + 6, j + 23, k + 17, sculk_block, 0, 2);
		world.setBlock(i + 2, j + 23, k + 19, sculk_block, 0, 2);
		world.setBlock(i + 6, j + 23, k + 19, sculk_block, 0, 2);
		world.setBlock(i + 2, j + 23, k + 20, sculk_block, 0, 2);
		world.setBlock(i + 6, j + 23, k + 20, sculk_block, 0, 2);
		world.setBlock(i + 3, j + 23, k + 22, sculk_block, 0, 2);
		world.setBlock(i + 4, j + 23, k + 22, sculk_block, 0, 2);
		world.setBlock(i + 5, j + 23, k + 22, sculk_block, 0, 2);
		world.setBlock(i + 2, j + 23, k + 23, sculk_block, 0, 2);
		world.setBlock(i + 6, j + 23, k + 24, sculk_block, 0, 2);
		world.setBlock(i + 2, j + 23, k + 25, NovaCraftBlocks.sculk_tentacle_2, 1, 2);
		world.setBlock(i + 6, j + 23, k + 25, sculk_block, 0, 2);
		world.setBlock(i + 2, j + 23, k + 26, sculk_block, 0, 2);
		world.setBlock(i + 6, j + 23, k + 27, sculk_block, 0, 2);
		world.setBlock(i + 2, j + 23, k + 28, sculk_block, 0, 2);
		world.setBlock(i + 6, j + 23, k + 28, sculk_block, 0, 2);
		world.setBlock(i + 3, j + 23, k + 29, sculk_block, 0, 2);
		world.setBlock(i + 4, j + 23, k + 29, sculk_block, 0, 2);
		world.setBlock(i + 2, j + 23, k + 32, sculk_block, 0, 2);
		world.setBlock(i + 5, j + 23, k + 32, NovaCraftBlocks.sculk_tentacle_2, 1, 2);
		world.setBlock(i + 2, j + 23, k + 33, sculk_block, 0, 2);
		world.setBlock(i + 3, j + 23, k + 33, sculk_block, 0, 2);
		world.setBlock(i + 4, j + 23, k + 33, sculk_tendrils, 0, 2);
		world.setBlock(i + 2, j + 23, k + 35, sculk_block, 0, 2);
		world.setBlock(i + 3, j + 23, k + 35, NovaCraftBlocks.sculk_tentacle_2, 1, 2);
		world.setBlock(i + 3, j + 24, k + 8, sculk_tendrils, 0, 2);
		world.setBlock(i + 4, j + 24, k + 10, NovaCraftBlocks.sculk_tentacle_2, 1, 2);
		world.setBlock(i + 6, j + 24, k + 11, sculk_tendrils, 0, 2);
		world.setBlock(i + 4, j + 24, k + 14, NovaCraftBlocks.sculk_tentacle_2, 1, 2);
		world.setBlock(i + 5, j + 24, k + 16, sculk_tendrils, 0, 2);
		world.setBlock(i + 3, j + 24, k + 22, sculk_tendrils, 0, 2);
		world.setBlock(i + 5, j + 24, k + 22, NovaCraftBlocks.sculk_tentacle_2, 1, 2);
		world.setBlock(i + 6, j + 24, k + 25, NovaCraftBlocks.sculk_tentacle_2, 1, 2);
		world.setBlock(i + 6, j + 24, k + 27, sculk_tendrils, 0, 2);
		world.setBlock(i + 2, j + 24, k + 33, sculk_tendrils, 0, 2);
		world.setBlock(i + 3, j + 25, k + 8, sculk_tendrils, 0, 2);	
		world.setBlock(i + 11, j + 10, k + 36, Blocks.trapdoor, 9, 2);
		world.setBlock(i + 11, j + 10, k + 4, Blocks.trapdoor, 8, 2);
		
		world.setBlock(i + 10, j + 11, k + 37, Blocks.chest, 2, 2);
		TileEntityChest chest = (TileEntityChest) world.getTileEntity(i + 10, j + 11, k + 37);

		for (int slot = 0; slot < 3 + random.nextInt(25); slot++) {
			chest.setInventorySlotContents(random.nextInt(chest.getSizeInventory()), this.getBasicLoot(random));
		}
		
		world.setBlock(i + 10, j + 11, k + 3, Blocks.chest, 3, 2);
		TileEntityChest chest2 = (TileEntityChest) world.getTileEntity(i + 10, j + 11, k + 3);
		
		for (int slot = 0; slot < 3 + random.nextInt(25); slot++) {
			chest2.setInventorySlotContents(random.nextInt(chest.getSizeInventory()), this.getBasicLoot(random));
		}
		
		world.setBlock(i + 3, j + 22, k + 30, Blocks.mob_spawner, 0, 2);
		TileEntityMobSpawner tileentitymobspawner = (TileEntityMobSpawner)world.getTileEntity(i + 3, j + 22, k + 30);
        
        if (tileentitymobspawner != null)
        {
        	tileentitymobspawner.func_145881_a().setEntityName("nova_craft.sculked_monitor");
        }
        
		world.setBlock(i + 5, j + 24, k + 8, Blocks.mob_spawner, 0, 2);
		TileEntityMobSpawner tileentitymobspawner2 = (TileEntityMobSpawner)world.getTileEntity(i + 5, j + 24, k + 8);
        
        if (tileentitymobspawner2 != null)
        {
        	tileentitymobspawner2.func_145881_a().setEntityName("nova_craft.sculk_incinerator");
        }
    	
    	return true;
    }
    
    private ItemStack getBasicLoot(Random random) {
		int item = random.nextInt(21);
		switch (item) {
			case 0:
				return new ItemStack(Items.coal, random.nextInt(9) + 6);
			case 1:
				return new ItemStack(Items.bone, random.nextInt(14) + 1);
			case 2:
				return new ItemStack(NovaCraftItems.larimar_shard, random.nextInt(2) + 1);
			case 3:
				return new ItemStack(NovaCraftItems.copartz_shard, random.nextInt(3) + 1);
			case 4:
				return new ItemStack(NovaCraftItems.tsavorokite_shard, random.nextInt(1) + 1);
			case 5:
				return new ItemStack(NovaCraftItems.yttrlinsite_shard, 1);
			case 6:
				if (Loader.isModLoaded("netherlicious")) {
					return new ItemStack(OtherModBlocks.SoulTorch, random.nextInt(14) + 1);
				}
				if (Loader.isModLoaded("etfuturum")) {
					return new ItemStack(OtherModBlocks.soul_torch, random.nextInt(14) + 1);
				}
				else {
					return new ItemStack(NovaCraftBlocks.dim_vanite_torch, random.nextInt(14) + 1);
				}		
			case 7: 
				if (Loader.isModLoaded("etfuturum")) {
					return new ItemStack(OtherModItems.amethyst_shard, random.nextInt(14) + 1);
				}
				else {
					return new ItemStack(NovaCraftItems.copartz_shard, random.nextInt(14) + 1);
				}
			case 8: 
				return new ItemStack(NovaCraftBlocks.sculk_block, random.nextInt(6) + 4);
			case 9: 
				return new ItemStack(Items.experience_bottle, random.nextInt(3) + 3);
			case 10: 
				return new ItemStack(Items.gunpowder, random.nextInt(6) + 5);
			case 11: 
				return new ItemStack(NovaCraftItems.diamond_bow, 1);
			case 12: 
				return new ItemStack(NovaCraftItems.ancient_city_totem, 1);
			case 13: 
				return new ItemStack(Blocks.sand, random.nextInt(6) + 4);
			case 14: 
				return new ItemStack(Blocks.tnt, random.nextInt(1) + 1);
			case 15: 
				return new ItemStack(Items.bow, 1);
			case 16: 
				return new ItemStack(Blocks.gravel, random.nextInt(9) + 8);
			case 17: 
				return new ItemStack(Items.flint, random.nextInt(4) + 2);
			case 18: 
				return new ItemStack(Items.feather, random.nextInt(2) + 3);
			default: {
				return new ItemStack(Items.arrow, random.nextInt(23) + 18);
			}
		}
	}

}
