package com.NovaCraft.world.ancient_city;

import cpw.mods.fml.common.registry.GameRegistry;
import net.minecraft.world.gen.feature.*;
import net.minecraft.block.*;
import net.minecraft.world.*;
import java.util.*;

import com.NovaCraft.config.Configs;
import com.NovaCraft.registry.OtherModBlocks;
import com.NovaCraftBlocks.NovaCraftBlocks;

import cpw.mods.fml.common.Loader;
import net.minecraft.init.*;

public class AncientCityColumnGen2 extends WorldGenerator
{
	public AncientCityColumnGen2() {

	}

	private static final Block sculk_block = NovaCraftBlocks.sculk_block;

	private Block PlaceDeepslate;

	private Block determineIfDeepslateExists(World world, int x, int y, int z) {
		Block existingBlock = world.getBlock(x, y, z);
		if (Configs.enableDeepslateInAncientCity && Loader.isModLoaded("etfuturum")) {
			try {
				Block deepslate = GameRegistry.findBlock("etfuturum", "deepslate");
				if (deepslate != null && (existingBlock == null || existingBlock != deepslate)) {
					return deepslate;
				}
			} catch (Exception ex) {
				if (Configs.enableDebugMode) {
					System.out.println("Missing Deepslate from Et Futurum Requiem, using Grimstone instead...");
				}
				return NovaCraftBlocks.grimstone;
			}
		}

		return NovaCraftBlocks.grimstone;
	}
    
    public boolean generate(final World world, final Random random, final int i, final int j, final int k) {
    	PlaceDeepslate = determineIfDeepslateExists(world, i + 18, j + 19, k + 11);
	
    	world.setBlock(i + 18, j + 19, k + 11, PlaceDeepslate, 0, 2);
		world.setBlock(i + 19, j + 19, k + 11, PlaceDeepslate, 0, 2);
		world.setBlock(i + 20, j + 19, k + 11, PlaceDeepslate, 0, 2);
		world.setBlock(i + 21, j + 19, k + 11, PlaceDeepslate, 0, 2);
		world.setBlock(i + 10, j + 19, k + 12, sculk_block, 0, 2);
		world.setBlock(i + 11, j + 19, k + 12, PlaceDeepslate, 0, 2);
		world.setBlock(i + 12, j + 19, k + 12, PlaceDeepslate, 0, 2);
		world.setBlock(i + 13, j + 19, k + 12, PlaceDeepslate, 0, 2);
		world.setBlock(i + 14, j + 19, k + 12, PlaceDeepslate, 0, 2);
		world.setBlock(i + 15, j + 19, k + 12, PlaceDeepslate, 0, 2);
		world.setBlock(i + 16, j + 19, k + 12, PlaceDeepslate, 0, 2);
		world.setBlock(i + 17, j + 19, k + 12, PlaceDeepslate, 0, 2);
		world.setBlock(i + 18, j + 19, k + 12, PlaceDeepslate, 0, 2);
		world.setBlock(i + 19, j + 19, k + 12, PlaceDeepslate, 0, 2);
		world.setBlock(i + 20, j + 19, k + 12, PlaceDeepslate, 0, 2);
		world.setBlock(i + 21, j + 19, k + 12, PlaceDeepslate, 0, 2);
		world.setBlock(i + 11, j + 19, k + 13, sculk_block, 0, 2);
		world.setBlock(i + 12, j + 19, k + 13, PlaceDeepslate, 0, 2);
		world.setBlock(i + 13, j + 19, k + 13, PlaceDeepslate, 0, 2);
		world.setBlock(i + 14, j + 19, k + 13, PlaceDeepslate, 0, 2);
		world.setBlock(i + 15, j + 19, k + 13, PlaceDeepslate, 0, 2);
		world.setBlock(i + 16, j + 19, k + 13, PlaceDeepslate, 0, 2);
		world.setBlock(i + 17, j + 19, k + 13, PlaceDeepslate, 0, 2);
		world.setBlock(i + 18, j + 19, k + 13, PlaceDeepslate, 0, 2);
		world.setBlock(i + 19, j + 19, k + 13, PlaceDeepslate, 0, 2);
		world.setBlock(i + 20, j + 19, k + 13, PlaceDeepslate, 0, 2);
		world.setBlock(i + 21, j + 19, k + 13, PlaceDeepslate, 0, 2);
		world.setBlock(i + 11, j + 19, k + 14, sculk_block, 0, 2);
		world.setBlock(i + 12, j + 19, k + 14, PlaceDeepslate, 0, 2);
		world.setBlock(i + 13, j + 19, k + 14, PlaceDeepslate, 0, 2);
		world.setBlock(i + 14, j + 19, k + 14, PlaceDeepslate, 0, 2);
		world.setBlock(i + 15, j + 19, k + 14, PlaceDeepslate, 0, 2);
		world.setBlock(i + 16, j + 19, k + 14, PlaceDeepslate, 0, 2);
		world.setBlock(i + 17, j + 19, k + 14, PlaceDeepslate, 0, 2);
		world.setBlock(i + 18, j + 19, k + 14, PlaceDeepslate, 0, 2);
		world.setBlock(i + 19, j + 19, k + 14, PlaceDeepslate, 0, 2);
		world.setBlock(i + 20, j + 19, k + 14, PlaceDeepslate, 0, 2);
		world.setBlock(i + 21, j + 19, k + 14, PlaceDeepslate, 0, 2);
		world.setBlock(i + 11, j + 19, k + 15, sculk_block, 0, 2);
		world.setBlock(i + 12, j + 19, k + 15, PlaceDeepslate, 0, 2);
		world.setBlock(i + 13, j + 19, k + 15, PlaceDeepslate, 0, 2);
		world.setBlock(i + 14, j + 19, k + 15, PlaceDeepslate, 0, 2);
		world.setBlock(i + 15, j + 19, k + 15, PlaceDeepslate, 0, 2);
		world.setBlock(i + 16, j + 19, k + 15, PlaceDeepslate, 0, 2);
		world.setBlock(i + 17, j + 19, k + 15, PlaceDeepslate, 0, 2);
		world.setBlock(i + 18, j + 19, k + 15, PlaceDeepslate, 0, 2);
		world.setBlock(i + 19, j + 19, k + 15, PlaceDeepslate, 0, 2);
		world.setBlock(i + 20, j + 19, k + 15, PlaceDeepslate, 0, 2);
		world.setBlock(i + 21, j + 19, k + 15, PlaceDeepslate, 0, 2);
		world.setBlock(i + 11, j + 19, k + 16, sculk_block, 0, 2);
		world.setBlock(i + 12, j + 19, k + 16, sculk_block, 0, 2);
		world.setBlock(i + 13, j + 19, k + 16, sculk_block, 0, 2);
		world.setBlock(i + 14, j + 19, k + 16, sculk_block, 0, 2);
		world.setBlock(i + 15, j + 19, k + 16, PlaceDeepslate, 0, 2);
		world.setBlock(i + 16, j + 19, k + 16, PlaceDeepslate, 0, 2);
		world.setBlock(i + 17, j + 19, k + 16, PlaceDeepslate, 0, 2);
		world.setBlock(i + 18, j + 19, k + 16, PlaceDeepslate, 0, 2);
		world.setBlock(i + 19, j + 19, k + 16, PlaceDeepslate, 0, 2);
		world.setBlock(i + 20, j + 19, k + 16, PlaceDeepslate, 0, 2);
		world.setBlock(i + 15, j + 19, k + 17, sculk_block, 0, 2);
		world.setBlock(i + 20, j + 19, k + 17, sculk_block, 0, 2);
		world.setBlock(i + 11, j + 20, k + 4, PlaceDeepslate, 0, 2);
		world.setBlock(i + 12, j + 20, k + 4, PlaceDeepslate, 0, 2);
		world.setBlock(i + 13, j + 20, k + 4, PlaceDeepslate, 0, 2);
		world.setBlock(i + 14, j + 20, k + 4, PlaceDeepslate, 0, 2);
		world.setBlock(i + 15, j + 20, k + 4, sculk_block, 0, 2);
		world.setBlock(i + 16, j + 20, k + 4, PlaceDeepslate, 0, 2);
		world.setBlock(i + 11, j + 20, k + 5, PlaceDeepslate, 0, 2);
		world.setBlock(i + 12, j + 20, k + 5, PlaceDeepslate, 0, 2);
		world.setBlock(i + 13, j + 20, k + 5, PlaceDeepslate, 0, 2);
		world.setBlock(i + 14, j + 20, k + 5, sculk_block, 0, 2);
		world.setBlock(i + 15, j + 20, k + 5, sculk_block, 0, 2);
		world.setBlock(i + 16, j + 20, k + 5, sculk_block, 0, 2);
		world.setBlock(i + 17, j + 20, k + 5, sculk_block, 0, 2);
		world.setBlock(i + 11, j + 20, k + 6, PlaceDeepslate, 0, 2);
		world.setBlock(i + 12, j + 20, k + 6, PlaceDeepslate, 0, 2);
		world.setBlock(i + 13, j + 20, k + 6, PlaceDeepslate, 0, 2);
		world.setBlock(i + 14, j + 20, k + 6, sculk_block, 0, 2);
		world.setBlock(i + 15, j + 20, k + 6, sculk_block, 0, 2);
		world.setBlock(i + 16, j + 20, k + 6, sculk_block, 0, 2);
		world.setBlock(i + 17, j + 20, k + 6, sculk_block, 0, 2);
		world.setBlock(i + 11, j + 20, k + 7, PlaceDeepslate, 0, 2);
		world.setBlock(i + 12, j + 20, k + 7, PlaceDeepslate, 0, 2);
		world.setBlock(i + 13, j + 20, k + 7, PlaceDeepslate, 0, 2);
		world.setBlock(i + 14, j + 20, k + 7, PlaceDeepslate, 0, 2);
		world.setBlock(i + 15, j + 20, k + 7, sculk_block, 0, 2);
		world.setBlock(i + 16, j + 20, k + 7, sculk_block, 0, 2);
		world.setBlock(i + 17, j + 20, k + 7, sculk_block, 0, 2);
		world.setBlock(i + 18, j + 20, k + 7, sculk_block, 0, 2);
		world.setBlock(i + 10, j + 20, k + 8, sculk_block, 0, 2);
		world.setBlock(i + 11, j + 20, k + 8, PlaceDeepslate, 0, 2);
		world.setBlock(i + 12, j + 20, k + 8, PlaceDeepslate, 0, 2);
		world.setBlock(i + 13, j + 20, k + 8, PlaceDeepslate, 0, 2);
		world.setBlock(i + 14, j + 20, k + 8, PlaceDeepslate, 0, 2);
		world.setBlock(i + 15, j + 20, k + 8, PlaceDeepslate, 0, 2);
		world.setBlock(i + 16, j + 20, k + 8, PlaceDeepslate, 0, 2);
		world.setBlock(i + 17, j + 20, k + 8, sculk_block, 0, 2);
		world.setBlock(i + 18, j + 20, k + 8, sculk_block, 0, 2);
		world.setBlock(i + 19, j + 20, k + 8, sculk_block, 0, 2);
		world.setBlock(i + 11, j + 20, k + 9, PlaceDeepslate, 0, 2);
		world.setBlock(i + 12, j + 20, k + 9, PlaceDeepslate, 0, 2);
		world.setBlock(i + 13, j + 20, k + 9, PlaceDeepslate, 0, 2);
		world.setBlock(i + 14, j + 20, k + 9, PlaceDeepslate, 0, 2);
		world.setBlock(i + 15, j + 20, k + 9, PlaceDeepslate, 0, 2);
		world.setBlock(i + 16, j + 20, k + 9, PlaceDeepslate, 0, 2);
		world.setBlock(i + 17, j + 20, k + 9, PlaceDeepslate, 0, 2);
		world.setBlock(i + 18, j + 20, k + 9, PlaceDeepslate, 0, 2);
		world.setBlock(i + 19, j + 20, k + 9, PlaceDeepslate, 0, 2);
		world.setBlock(i + 20, j + 20, k + 9, PlaceDeepslate, 0, 2);
		world.setBlock(i + 10, j + 20, k + 10, sculk_block, 0, 2);
		world.setBlock(i + 11, j + 20, k + 10, PlaceDeepslate, 0, 2);
		world.setBlock(i + 12, j + 20, k + 10, PlaceDeepslate, 0, 2);
		world.setBlock(i + 13, j + 20, k + 10, PlaceDeepslate, 0, 2);
		world.setBlock(i + 14, j + 20, k + 10, PlaceDeepslate, 0, 2);
		world.setBlock(i + 15, j + 20, k + 10, PlaceDeepslate, 0, 2);
		world.setBlock(i + 16, j + 20, k + 10, PlaceDeepslate, 0, 2);
		world.setBlock(i + 17, j + 20, k + 10, PlaceDeepslate, 0, 2);
		world.setBlock(i + 18, j + 20, k + 10, PlaceDeepslate, 0, 2);
		world.setBlock(i + 19, j + 20, k + 10, PlaceDeepslate, 0, 2);
		world.setBlock(i + 0, j + 30, k + 15, PlaceDeepslate, 0, 2);
		world.setBlock(i + 1, j + 30, k + 15, PlaceDeepslate, 0, 2);
		world.setBlock(i + 2, j + 30, k + 15, PlaceDeepslate, 0, 2);
		world.setBlock(i + 3, j + 30, k + 15, PlaceDeepslate, 0, 2);
		world.setBlock(i + 4, j + 30, k + 15, PlaceDeepslate, 0, 2);
		world.setBlock(i + 5, j + 30, k + 15, PlaceDeepslate, 0, 2);
		world.setBlock(i + 6, j + 30, k + 15, PlaceDeepslate, 0, 2);
		world.setBlock(i + 7, j + 30, k + 15, PlaceDeepslate, 0, 2);
		world.setBlock(i + 8, j + 30, k + 15, PlaceDeepslate, 0, 2);
		world.setBlock(i + 9, j + 30, k + 15, PlaceDeepslate, 0, 2);
		world.setBlock(i + 10, j + 30, k + 15, PlaceDeepslate, 0, 2);
		world.setBlock(i + 11, j + 30, k + 15, PlaceDeepslate, 0, 2);
		world.setBlock(i + 12, j + 30, k + 15, PlaceDeepslate, 0, 2);
		world.setBlock(i + 13, j + 30, k + 15, PlaceDeepslate, 0, 2);
		world.setBlock(i + 14, j + 30, k + 15, PlaceDeepslate, 0, 2);
		world.setBlock(i + 15, j + 30, k + 15, PlaceDeepslate, 0, 2);
		world.setBlock(i + 16, j + 30, k + 15, PlaceDeepslate, 0, 2);
		world.setBlock(i + 17, j + 30, k + 15, PlaceDeepslate, 0, 2);
		world.setBlock(i + 18, j + 30, k + 15, PlaceDeepslate, 0, 2);
		world.setBlock(i + 19, j + 30, k + 15, PlaceDeepslate, 0, 2);
		world.setBlock(i + 20, j + 30, k + 15, PlaceDeepslate, 0, 2);
		world.setBlock(i + 21, j + 30, k + 15, PlaceDeepslate, 0, 2);
		world.setBlock(i + 0, j + 30, k + 16, PlaceDeepslate, 0, 2);
		world.setBlock(i + 1, j + 30, k + 16, PlaceDeepslate, 0, 2);
		world.setBlock(i + 2, j + 30, k + 16, PlaceDeepslate, 0, 2);
		world.setBlock(i + 3, j + 30, k + 16, PlaceDeepslate, 0, 2);
		world.setBlock(i + 4, j + 30, k + 16, PlaceDeepslate, 0, 2);
		world.setBlock(i + 5, j + 30, k + 16, PlaceDeepslate, 0, 2);
		world.setBlock(i + 6, j + 30, k + 16, PlaceDeepslate, 0, 2);
		world.setBlock(i + 7, j + 30, k + 16, PlaceDeepslate, 0, 2);
		world.setBlock(i + 8, j + 30, k + 16, PlaceDeepslate, 0, 2);
		world.setBlock(i + 9, j + 30, k + 16, PlaceDeepslate, 0, 2);
		world.setBlock(i + 10, j + 30, k + 16, PlaceDeepslate, 0, 2);
		world.setBlock(i + 11, j + 30, k + 16, PlaceDeepslate, 0, 2);
		world.setBlock(i + 12, j + 30, k + 16, PlaceDeepslate, 0, 2);
		world.setBlock(i + 13, j + 30, k + 16, PlaceDeepslate, 0, 2);
		world.setBlock(i + 14, j + 30, k + 16, PlaceDeepslate, 0, 2);
		world.setBlock(i + 15, j + 30, k + 16, PlaceDeepslate, 0, 2);
		world.setBlock(i + 16, j + 30, k + 16, PlaceDeepslate, 0, 2);
		world.setBlock(i + 17, j + 30, k + 16, PlaceDeepslate, 0, 2);
		world.setBlock(i + 18, j + 30, k + 16, PlaceDeepslate, 0, 2);
		world.setBlock(i + 19, j + 30, k + 16, PlaceDeepslate, 0, 2);
		world.setBlock(i + 20, j + 30, k + 16, PlaceDeepslate, 0, 2);
		world.setBlock(i + 21, j + 30, k + 16, PlaceDeepslate, 0, 2);
		world.setBlock(i + 0, j + 30, k + 17, PlaceDeepslate, 0, 2);
		world.setBlock(i + 1, j + 30, k + 17, PlaceDeepslate, 0, 2);
		world.setBlock(i + 2, j + 30, k + 17, PlaceDeepslate, 0, 2);
		world.setBlock(i + 3, j + 30, k + 17, PlaceDeepslate, 0, 2);
		world.setBlock(i + 4, j + 30, k + 17, PlaceDeepslate, 0, 2);
		world.setBlock(i + 5, j + 30, k + 17, PlaceDeepslate, 0, 2);
		world.setBlock(i + 6, j + 30, k + 17, PlaceDeepslate, 0, 2);
		world.setBlock(i + 7, j + 30, k + 17, PlaceDeepslate, 0, 2);
		world.setBlock(i + 8, j + 30, k + 17, PlaceDeepslate, 0, 2);
		world.setBlock(i + 9, j + 30, k + 17, PlaceDeepslate, 0, 2);
		world.setBlock(i + 10, j + 30, k + 17, PlaceDeepslate, 0, 2);
		world.setBlock(i + 11, j + 30, k + 17, PlaceDeepslate, 0, 2);
		world.setBlock(i + 12, j + 30, k + 17, PlaceDeepslate, 0, 2);
		world.setBlock(i + 13, j + 30, k + 17, PlaceDeepslate, 0, 2);
		world.setBlock(i + 14, j + 30, k + 17, PlaceDeepslate, 0, 2);
		world.setBlock(i + 15, j + 30, k + 17, PlaceDeepslate, 0, 2);
		world.setBlock(i + 16, j + 30, k + 17, PlaceDeepslate, 0, 2);
		world.setBlock(i + 17, j + 30, k + 17, PlaceDeepslate, 0, 2);
		world.setBlock(i + 18, j + 30, k + 17, PlaceDeepslate, 0, 2);
		world.setBlock(i + 19, j + 30, k + 17, PlaceDeepslate, 0, 2);
		world.setBlock(i + 20, j + 30, k + 17, PlaceDeepslate, 0, 2);
		world.setBlock(i + 21, j + 30, k + 17, PlaceDeepslate, 0, 2);
		world.setBlock(i + 1, j + 30, k + 18, PlaceDeepslate, 0, 2);
		world.setBlock(i + 2, j + 30, k + 18, PlaceDeepslate, 0, 2);
		world.setBlock(i + 3, j + 30, k + 18, PlaceDeepslate, 0, 2);
		world.setBlock(i + 4, j + 30, k + 18, PlaceDeepslate, 0, 2);
		world.setBlock(i + 5, j + 30, k + 18, PlaceDeepslate, 0, 2);
		world.setBlock(i + 6, j + 30, k + 18, PlaceDeepslate, 0, 2);
		world.setBlock(i + 7, j + 30, k + 18, PlaceDeepslate, 0, 2);
		world.setBlock(i + 8, j + 30, k + 18, PlaceDeepslate, 0, 2);
		world.setBlock(i + 9, j + 30, k + 18, PlaceDeepslate, 0, 2);
		world.setBlock(i + 10, j + 30, k + 18, PlaceDeepslate, 0, 2);
		world.setBlock(i + 11, j + 30, k + 18, PlaceDeepslate, 0, 2);
		world.setBlock(i + 12, j + 30, k + 18, PlaceDeepslate, 0, 2);
		world.setBlock(i + 13, j + 30, k + 18, PlaceDeepslate, 0, 2);
		world.setBlock(i + 14, j + 30, k + 18, PlaceDeepslate, 0, 2);
		world.setBlock(i + 15, j + 30, k + 18, PlaceDeepslate, 0, 2);
		world.setBlock(i + 16, j + 30, k + 18, PlaceDeepslate, 0, 2);
		world.setBlock(i + 17, j + 30, k + 18, PlaceDeepslate, 0, 2);
		world.setBlock(i + 18, j + 30, k + 18, PlaceDeepslate, 0, 2);
		world.setBlock(i + 19, j + 30, k + 18, PlaceDeepslate, 0, 2);
		world.setBlock(i + 20, j + 30, k + 18, PlaceDeepslate, 0, 2);
		world.setBlock(i + 21, j + 30, k + 18, sculk_block, 0, 2);
		world.setBlock(i + 2, j + 30, k + 19, PlaceDeepslate, 0, 2);
		world.setBlock(i + 3, j + 30, k + 19, PlaceDeepslate, 0, 2);
		world.setBlock(i + 4, j + 30, k + 19, PlaceDeepslate, 0, 2);
		world.setBlock(i + 5, j + 30, k + 19, PlaceDeepslate, 0, 2);
		world.setBlock(i + 6, j + 30, k + 19, PlaceDeepslate, 0, 2);
		world.setBlock(i + 7, j + 30, k + 19, PlaceDeepslate, 0, 2);
		world.setBlock(i + 8, j + 30, k + 19, PlaceDeepslate, 0, 2);
		world.setBlock(i + 9, j + 30, k + 19, PlaceDeepslate, 0, 2);
		world.setBlock(i + 10, j + 30, k + 19, PlaceDeepslate, 0, 2);
		world.setBlock(i + 11, j + 30, k + 19, PlaceDeepslate, 0, 2);
		world.setBlock(i + 12, j + 30, k + 19, PlaceDeepslate, 0, 2);
		world.setBlock(i + 13, j + 30, k + 19, PlaceDeepslate, 0, 2);
		world.setBlock(i + 14, j + 30, k + 19, PlaceDeepslate, 0, 2);
		world.setBlock(i + 15, j + 30, k + 19, PlaceDeepslate, 0, 2);
		world.setBlock(i + 16, j + 30, k + 19, PlaceDeepslate, 0, 2);
		world.setBlock(i + 17, j + 30, k + 19, PlaceDeepslate, 0, 2);
		world.setBlock(i + 18, j + 30, k + 19, PlaceDeepslate, 0, 2);
		world.setBlock(i + 19, j + 30, k + 19, sculk_block, 0, 2);
		world.setBlock(i + 20, j + 30, k + 19, sculk_block, 0, 2);
    	world.setBlock(i + 20, j + 20, k + 10, PlaceDeepslate, 0, 2);
		world.setBlock(i + 10, j + 20, k + 11, sculk_block, 0, 2);
		world.setBlock(i + 11, j + 20, k + 11, PlaceDeepslate, 0, 2);
		world.setBlock(i + 12, j + 20, k + 11, PlaceDeepslate, 0, 2);
		world.setBlock(i + 13, j + 20, k + 11, PlaceDeepslate, 0, 2);
		world.setBlock(i + 14, j + 20, k + 11, PlaceDeepslate, 0, 2);
		world.setBlock(i + 15, j + 20, k + 11, PlaceDeepslate, 0, 2);
		world.setBlock(i + 16, j + 20, k + 11, PlaceDeepslate, 0, 2);
		world.setBlock(i + 17, j + 20, k + 11, PlaceDeepslate, 0, 2);
		world.setBlock(i + 18, j + 20, k + 11, PlaceDeepslate, 0, 2);
		world.setBlock(i + 19, j + 20, k + 11, PlaceDeepslate, 0, 2);
		world.setBlock(i + 20, j + 20, k + 11, PlaceDeepslate, 0, 2);
		world.setBlock(i + 21, j + 20, k + 11, PlaceDeepslate, 0, 2);
		world.setBlock(i + 10, j + 20, k + 12, sculk_block, 0, 2);
		world.setBlock(i + 11, j + 20, k + 12, PlaceDeepslate, 0, 2);
		world.setBlock(i + 12, j + 20, k + 12, PlaceDeepslate, 0, 2);
		world.setBlock(i + 13, j + 20, k + 12, PlaceDeepslate, 0, 2);
		world.setBlock(i + 14, j + 20, k + 12, PlaceDeepslate, 0, 2);
		world.setBlock(i + 15, j + 20, k + 12, PlaceDeepslate, 0, 2);
		world.setBlock(i + 16, j + 20, k + 12, PlaceDeepslate, 0, 2);
		world.setBlock(i + 17, j + 20, k + 12, PlaceDeepslate, 0, 2);
		world.setBlock(i + 18, j + 20, k + 12, PlaceDeepslate, 0, 2);
		world.setBlock(i + 19, j + 20, k + 12, PlaceDeepslate, 0, 2);
		world.setBlock(i + 20, j + 20, k + 12, PlaceDeepslate, 0, 2);
		world.setBlock(i + 21, j + 20, k + 12, PlaceDeepslate, 0, 2);
		world.setBlock(i + 11, j + 20, k + 13, sculk_block, 0, 2);
		world.setBlock(i + 12, j + 20, k + 13, PlaceDeepslate, 0, 2);
		world.setBlock(i + 13, j + 20, k + 13, PlaceDeepslate, 0, 2);
		world.setBlock(i + 14, j + 20, k + 13, PlaceDeepslate, 0, 2);
		world.setBlock(i + 15, j + 20, k + 13, PlaceDeepslate, 0, 2);
		world.setBlock(i + 16, j + 20, k + 13, PlaceDeepslate, 0, 2);
		world.setBlock(i + 17, j + 20, k + 13, PlaceDeepslate, 0, 2);
		world.setBlock(i + 18, j + 20, k + 13, PlaceDeepslate, 0, 2);
		world.setBlock(i + 19, j + 20, k + 13, PlaceDeepslate, 0, 2);
		world.setBlock(i + 20, j + 20, k + 13, PlaceDeepslate, 0, 2);
		world.setBlock(i + 21, j + 20, k + 13, PlaceDeepslate, 0, 2);
		world.setBlock(i + 11, j + 20, k + 14, sculk_block, 0, 2);
		world.setBlock(i + 12, j + 20, k + 14, PlaceDeepslate, 0, 2);
		world.setBlock(i + 13, j + 20, k + 14, PlaceDeepslate, 0, 2);
		world.setBlock(i + 14, j + 20, k + 14, PlaceDeepslate, 0, 2);
		world.setBlock(i + 15, j + 20, k + 14, PlaceDeepslate, 0, 2);
		world.setBlock(i + 16, j + 20, k + 14, PlaceDeepslate, 0, 2);
		world.setBlock(i + 17, j + 20, k + 14, PlaceDeepslate, 0, 2);
		world.setBlock(i + 18, j + 20, k + 14, PlaceDeepslate, 0, 2);
		world.setBlock(i + 19, j + 20, k + 14, PlaceDeepslate, 0, 2);
		world.setBlock(i + 20, j + 20, k + 14, PlaceDeepslate, 0, 2);
		world.setBlock(i + 21, j + 20, k + 14, PlaceDeepslate, 0, 2);
		world.setBlock(i + 11, j + 20, k + 15, sculk_block, 0, 2);
		world.setBlock(i + 12, j + 20, k + 15, PlaceDeepslate, 0, 2);
		world.setBlock(i + 13, j + 20, k + 15, PlaceDeepslate, 0, 2);
		world.setBlock(i + 14, j + 20, k + 15, PlaceDeepslate, 0, 2);
		world.setBlock(i + 15, j + 20, k + 15, PlaceDeepslate, 0, 2);
		world.setBlock(i + 16, j + 20, k + 15, PlaceDeepslate, 0, 2);
		world.setBlock(i + 17, j + 20, k + 15, PlaceDeepslate, 0, 2);
		world.setBlock(i + 18, j + 20, k + 15, PlaceDeepslate, 0, 2);
		world.setBlock(i + 19, j + 20, k + 15, PlaceDeepslate, 0, 2);
		world.setBlock(i + 20, j + 20, k + 15, PlaceDeepslate, 0, 2);
		world.setBlock(i + 21, j + 20, k + 15, PlaceDeepslate, 0, 2);
		world.setBlock(i + 22, j + 20, k + 15, sculk_block, 0, 2);
		world.setBlock(i + 11, j + 20, k + 16, sculk_block, 0, 2);
		world.setBlock(i + 12, j + 20, k + 16, sculk_block, 0, 2);
		world.setBlock(i + 13, j + 20, k + 16, sculk_block, 0, 2);
		world.setBlock(i + 14, j + 20, k + 16, sculk_block, 0, 2);
		world.setBlock(i + 15, j + 20, k + 16, PlaceDeepslate, 0, 2);
		world.setBlock(i + 16, j + 20, k + 16, PlaceDeepslate, 0, 2);
		world.setBlock(i + 17, j + 20, k + 16, PlaceDeepslate, 0, 2);
		world.setBlock(i + 18, j + 20, k + 16, PlaceDeepslate, 0, 2);
		world.setBlock(i + 19, j + 20, k + 16, PlaceDeepslate, 0, 2);
		world.setBlock(i + 20, j + 20, k + 16, PlaceDeepslate, 0, 2);
		world.setBlock(i + 21, j + 20, k + 16, sculk_block, 0, 2);
		world.setBlock(i + 15, j + 20, k + 17, sculk_block, 0, 2);
		world.setBlock(i + 19, j + 20, k + 17, sculk_block, 0, 2);
		world.setBlock(i + 20, j + 20, k + 17, sculk_block, 0, 2);
		world.setBlock(i + 11, j + 21, k + 4, PlaceDeepslate, 0, 2);
		world.setBlock(i + 12, j + 21, k + 4, PlaceDeepslate, 0, 2);
		world.setBlock(i + 13, j + 21, k + 4, PlaceDeepslate, 0, 2);
		world.setBlock(i + 14, j + 21, k + 4, PlaceDeepslate, 0, 2);
		world.setBlock(i + 15, j + 21, k + 4, PlaceDeepslate, 0, 2);
		world.setBlock(i + 16, j + 21, k + 4, PlaceDeepslate, 0, 2);
		world.setBlock(i + 17, j + 21, k + 4, PlaceDeepslate, 0, 2);
		world.setBlock(i + 11, j + 21, k + 5, PlaceDeepslate, 0, 2);
		world.setBlock(i + 12, j + 21, k + 5, PlaceDeepslate, 0, 2);
		world.setBlock(i + 13, j + 21, k + 5, PlaceDeepslate, 0, 2);
		world.setBlock(i + 14, j + 21, k + 5, PlaceDeepslate, 0, 2);
		world.setBlock(i + 15, j + 21, k + 5, PlaceDeepslate, 0, 2);
		world.setBlock(i + 16, j + 21, k + 5, PlaceDeepslate, 0, 2);
		world.setBlock(i + 17, j + 21, k + 5, PlaceDeepslate, 0, 2);
		world.setBlock(i + 10, j + 21, k + 6, PlaceDeepslate, 0, 2);
		world.setBlock(i + 11, j + 21, k + 6, PlaceDeepslate, 0, 2);
		world.setBlock(i + 12, j + 21, k + 6, PlaceDeepslate, 0, 2);
		world.setBlock(i + 13, j + 21, k + 6, PlaceDeepslate, 0, 2);
		world.setBlock(i + 14, j + 21, k + 6, PlaceDeepslate, 0, 2);
		world.setBlock(i + 15, j + 21, k + 6, PlaceDeepslate, 0, 2);
		world.setBlock(i + 16, j + 21, k + 6, PlaceDeepslate, 0, 2);
		world.setBlock(i + 17, j + 21, k + 6, PlaceDeepslate, 0, 2);
		world.setBlock(i + 18, j + 21, k + 6, PlaceDeepslate, 0, 2);
		world.setBlock(i + 10, j + 21, k + 7, PlaceDeepslate, 0, 2);
		world.setBlock(i + 11, j + 21, k + 7, PlaceDeepslate, 0, 2);
		world.setBlock(i + 12, j + 21, k + 7, PlaceDeepslate, 0, 2);
		world.setBlock(i + 13, j + 21, k + 7, PlaceDeepslate, 0, 2);
		world.setBlock(i + 14, j + 21, k + 7, PlaceDeepslate, 0, 2);
		world.setBlock(i + 15, j + 21, k + 7, PlaceDeepslate, 0, 2);
		world.setBlock(i + 16, j + 21, k + 7, PlaceDeepslate, 0, 2);
		world.setBlock(i + 17, j + 21, k + 7, PlaceDeepslate, 0, 2);
		world.setBlock(i + 18, j + 21, k + 7, PlaceDeepslate, 0, 2);
		world.setBlock(i + 9, j + 21, k + 8, sculk_block, 0, 2);
		world.setBlock(i + 10, j + 21, k + 8, PlaceDeepslate, 0, 2);
		world.setBlock(i + 11, j + 21, k + 8, PlaceDeepslate, 0, 2);
		world.setBlock(i + 12, j + 21, k + 8, PlaceDeepslate, 0, 2);
		world.setBlock(i + 13, j + 21, k + 8, PlaceDeepslate, 0, 2);
		world.setBlock(i + 14, j + 21, k + 8, PlaceDeepslate, 0, 2);
		world.setBlock(i + 15, j + 21, k + 8, PlaceDeepslate, 0, 2);
		world.setBlock(i + 16, j + 21, k + 8, PlaceDeepslate, 0, 2);
		world.setBlock(i + 17, j + 21, k + 8, PlaceDeepslate, 0, 2);
		world.setBlock(i + 18, j + 21, k + 8, PlaceDeepslate, 0, 2);
		world.setBlock(i + 19, j + 21, k + 8, PlaceDeepslate, 0, 2);
		world.setBlock(i + 10, j + 21, k + 9, sculk_block, 0, 2);
		world.setBlock(i + 11, j + 21, k + 9, PlaceDeepslate, 0, 2);
		world.setBlock(i + 12, j + 21, k + 9, PlaceDeepslate, 0, 2);
		world.setBlock(i + 13, j + 21, k + 9, PlaceDeepslate, 0, 2);
		world.setBlock(i + 14, j + 21, k + 9, PlaceDeepslate, 0, 2);
		world.setBlock(i + 15, j + 21, k + 9, PlaceDeepslate, 0, 2);
		world.setBlock(i + 16, j + 21, k + 9, PlaceDeepslate, 0, 2);
		world.setBlock(i + 17, j + 21, k + 9, PlaceDeepslate, 0, 2);
		world.setBlock(i + 18, j + 21, k + 9, PlaceDeepslate, 0, 2);
		world.setBlock(i + 19, j + 21, k + 9, PlaceDeepslate, 0, 2);
		world.setBlock(i + 20, j + 21, k + 9, PlaceDeepslate, 0, 2);
		world.setBlock(i + 10, j + 21, k + 10, sculk_block, 0, 2);
		world.setBlock(i + 11, j + 21, k + 10, PlaceDeepslate, 0, 2);
		world.setBlock(i + 12, j + 21, k + 10, PlaceDeepslate, 0, 2);
		world.setBlock(i + 13, j + 21, k + 10, PlaceDeepslate, 0, 2);
		world.setBlock(i + 14, j + 21, k + 10, PlaceDeepslate, 0, 2);
		world.setBlock(i + 15, j + 21, k + 10, PlaceDeepslate, 0, 2);
		world.setBlock(i + 16, j + 21, k + 10, PlaceDeepslate, 0, 2);
		world.setBlock(i + 17, j + 21, k + 10, PlaceDeepslate, 0, 2);
		world.setBlock(i + 18, j + 21, k + 10, PlaceDeepslate, 0, 2);
		world.setBlock(i + 19, j + 21, k + 10, PlaceDeepslate, 0, 2);
		world.setBlock(i + 20, j + 21, k + 10, PlaceDeepslate, 0, 2);
		world.setBlock(i + 10, j + 21, k + 11, sculk_block, 0, 2);
		world.setBlock(i + 11, j + 21, k + 11, PlaceDeepslate, 0, 2);
		world.setBlock(i + 12, j + 21, k + 11, PlaceDeepslate, 0, 2);
		world.setBlock(i + 13, j + 21, k + 11, PlaceDeepslate, 0, 2);
		world.setBlock(i + 14, j + 21, k + 11, PlaceDeepslate, 0, 2);
		world.setBlock(i + 15, j + 21, k + 11, PlaceDeepslate, 0, 2);
		world.setBlock(i + 16, j + 21, k + 11, PlaceDeepslate, 0, 2);
		world.setBlock(i + 17, j + 21, k + 11, PlaceDeepslate, 0, 2);
		world.setBlock(i + 18, j + 21, k + 11, PlaceDeepslate, 0, 2);
		world.setBlock(i + 19, j + 21, k + 11, PlaceDeepslate, 0, 2);
		world.setBlock(i + 20, j + 21, k + 11, PlaceDeepslate, 0, 2);
		world.setBlock(i + 21, j + 21, k + 11, PlaceDeepslate, 0, 2);
		world.setBlock(i + 10, j + 21, k + 12, sculk_block, 0, 2);
		world.setBlock(i + 11, j + 21, k + 12, PlaceDeepslate, 0, 2);
		world.setBlock(i + 12, j + 21, k + 12, PlaceDeepslate, 0, 2);
		world.setBlock(i + 13, j + 21, k + 12, PlaceDeepslate, 0, 2);
		world.setBlock(i + 14, j + 21, k + 12, PlaceDeepslate, 0, 2);
		world.setBlock(i + 15, j + 21, k + 12, PlaceDeepslate, 0, 2);
		world.setBlock(i + 16, j + 21, k + 12, PlaceDeepslate, 0, 2);
		world.setBlock(i + 17, j + 21, k + 12, PlaceDeepslate, 0, 2);
		world.setBlock(i + 18, j + 21, k + 12, PlaceDeepslate, 0, 2);
		world.setBlock(i + 19, j + 21, k + 12, PlaceDeepslate, 0, 2);
		world.setBlock(i + 20, j + 21, k + 12, PlaceDeepslate, 0, 2);
		world.setBlock(i + 21, j + 21, k + 12, PlaceDeepslate, 0, 2);
		world.setBlock(i + 10, j + 21, k + 13, sculk_block, 0, 2);
		world.setBlock(i + 11, j + 21, k + 13, PlaceDeepslate, 0, 2);
		world.setBlock(i + 12, j + 21, k + 13, PlaceDeepslate, 0, 2);
		world.setBlock(i + 13, j + 21, k + 13, PlaceDeepslate, 0, 2);
		world.setBlock(i + 14, j + 21, k + 13, PlaceDeepslate, 0, 2);
		world.setBlock(i + 15, j + 21, k + 13, PlaceDeepslate, 0, 2);
		world.setBlock(i + 16, j + 21, k + 13, PlaceDeepslate, 0, 2);
		world.setBlock(i + 17, j + 21, k + 13, PlaceDeepslate, 0, 2);
		world.setBlock(i + 18, j + 21, k + 13, PlaceDeepslate, 0, 2);
		world.setBlock(i + 19, j + 21, k + 13, PlaceDeepslate, 0, 2);
		world.setBlock(i + 20, j + 21, k + 13, PlaceDeepslate, 0, 2);
		world.setBlock(i + 21, j + 21, k + 13, PlaceDeepslate, 0, 2);
		world.setBlock(i + 10, j + 21, k + 14, sculk_block, 0, 2);
		world.setBlock(i + 11, j + 21, k + 14, PlaceDeepslate, 0, 2);
		world.setBlock(i + 12, j + 21, k + 14, PlaceDeepslate, 0, 2);
		world.setBlock(i + 13, j + 21, k + 14, PlaceDeepslate, 0, 2);
		world.setBlock(i + 14, j + 21, k + 14, PlaceDeepslate, 0, 2);
		world.setBlock(i + 15, j + 21, k + 14, PlaceDeepslate, 0, 2);
		world.setBlock(i + 16, j + 21, k + 14, PlaceDeepslate, 0, 2);
		world.setBlock(i + 17, j + 21, k + 14, PlaceDeepslate, 0, 2);
		world.setBlock(i + 18, j + 21, k + 14, PlaceDeepslate, 0, 2);
		world.setBlock(i + 19, j + 21, k + 14, PlaceDeepslate, 0, 2);
		world.setBlock(i + 20, j + 21, k + 14, PlaceDeepslate, 0, 2);
		world.setBlock(i + 21, j + 21, k + 14, PlaceDeepslate, 0, 2);
		world.setBlock(i + 22, j + 21, k + 14, sculk_block, 0, 2);
		world.setBlock(i + 11, j + 21, k + 15, sculk_block, 0, 2);
		world.setBlock(i + 12, j + 21, k + 15, PlaceDeepslate, 0, 2);
		world.setBlock(i + 13, j + 21, k + 15, PlaceDeepslate, 0, 2);
		world.setBlock(i + 14, j + 21, k + 15, PlaceDeepslate, 0, 2);
		world.setBlock(i + 15, j + 21, k + 15, PlaceDeepslate, 0, 2);
		world.setBlock(i + 16, j + 21, k + 15, PlaceDeepslate, 0, 2);
		world.setBlock(i + 17, j + 21, k + 15, PlaceDeepslate, 0, 2);
		world.setBlock(i + 18, j + 21, k + 15, PlaceDeepslate, 0, 2);
		world.setBlock(i + 19, j + 21, k + 15, PlaceDeepslate, 0, 2);
		world.setBlock(i + 20, j + 21, k + 15, PlaceDeepslate, 0, 2);
		world.setBlock(i + 21, j + 21, k + 15, sculk_block, 0, 2);
		world.setBlock(i + 11, j + 21, k + 16, sculk_block, 0, 2);
		world.setBlock(i + 12, j + 21, k + 16, sculk_block, 0, 2);
		world.setBlock(i + 13, j + 21, k + 16, sculk_block, 0, 2);
		world.setBlock(i + 14, j + 21, k + 16, sculk_block, 0, 2);
		world.setBlock(i + 15, j + 21, k + 16, sculk_block, 0, 2);
		world.setBlock(i + 16, j + 21, k + 16, PlaceDeepslate, 0, 2);
		world.setBlock(i + 17, j + 21, k + 16, PlaceDeepslate, 0, 2);
		world.setBlock(i + 18, j + 21, k + 16, PlaceDeepslate, 0, 2);
		world.setBlock(i + 19, j + 21, k + 16, sculk_block, 0, 2);
		world.setBlock(i + 20, j + 21, k + 16, sculk_block, 0, 2);
		world.setBlock(i + 16, j + 21, k + 17, sculk_block, 0, 2);
		world.setBlock(i + 18, j + 21, k + 17, sculk_block, 0, 2);
		world.setBlock(i + 11, j + 22, k + 3, PlaceDeepslate, 0, 2);
		world.setBlock(i + 12, j + 22, k + 3, PlaceDeepslate, 0, 2);
		world.setBlock(i + 13, j + 22, k + 3, PlaceDeepslate, 0, 2);
		world.setBlock(i + 14, j + 22, k + 3, PlaceDeepslate, 0, 2);
		world.setBlock(i + 15, j + 22, k + 3, PlaceDeepslate, 0, 2);
		world.setBlock(i + 16, j + 22, k + 3, PlaceDeepslate, 0, 2);
		world.setBlock(i + 10, j + 22, k + 4, PlaceDeepslate, 0, 2);
		world.setBlock(i + 11, j + 22, k + 4, PlaceDeepslate, 0, 2);
		world.setBlock(i + 12, j + 22, k + 4, PlaceDeepslate, 0, 2);
		world.setBlock(i + 13, j + 22, k + 4, PlaceDeepslate, 0, 2);
		world.setBlock(i + 14, j + 22, k + 4, PlaceDeepslate, 0, 2);
		world.setBlock(i + 15, j + 22, k + 4, PlaceDeepslate, 0, 2);
		world.setBlock(i + 16, j + 22, k + 4, PlaceDeepslate, 0, 2);
		world.setBlock(i + 17, j + 22, k + 4, PlaceDeepslate, 0, 2);
		world.setBlock(i + 10, j + 22, k + 5, PlaceDeepslate, 0, 2);
		world.setBlock(i + 11, j + 22, k + 5, PlaceDeepslate, 0, 2);
		world.setBlock(i + 12, j + 22, k + 5, PlaceDeepslate, 0, 2);
		world.setBlock(i + 13, j + 22, k + 5, PlaceDeepslate, 0, 2);
		world.setBlock(i + 14, j + 22, k + 5, PlaceDeepslate, 0, 2);
		world.setBlock(i + 15, j + 22, k + 5, PlaceDeepslate, 0, 2);
		world.setBlock(i + 16, j + 22, k + 5, PlaceDeepslate, 0, 2);
		world.setBlock(i + 17, j + 22, k + 5, PlaceDeepslate, 0, 2);
		world.setBlock(i + 10, j + 22, k + 6, PlaceDeepslate, 0, 2);
		world.setBlock(i + 11, j + 22, k + 6, PlaceDeepslate, 0, 2);
		world.setBlock(i + 12, j + 22, k + 6, PlaceDeepslate, 0, 2);
		world.setBlock(i + 13, j + 22, k + 6, PlaceDeepslate, 0, 2);
		world.setBlock(i + 14, j + 22, k + 6, PlaceDeepslate, 0, 2);
		world.setBlock(i + 15, j + 22, k + 6, PlaceDeepslate, 0, 2);
		world.setBlock(i + 16, j + 22, k + 6, PlaceDeepslate, 0, 2);
		world.setBlock(i + 17, j + 22, k + 6, PlaceDeepslate, 0, 2);
		world.setBlock(i + 18, j + 22, k + 6, PlaceDeepslate, 0, 2);
		world.setBlock(i + 10, j + 22, k + 7, PlaceDeepslate, 0, 2);
		world.setBlock(i + 11, j + 22, k + 7, PlaceDeepslate, 0, 2);
		world.setBlock(i + 12, j + 22, k + 7, PlaceDeepslate, 0, 2);
		world.setBlock(i + 13, j + 22, k + 7, PlaceDeepslate, 0, 2);
		world.setBlock(i + 14, j + 22, k + 7, PlaceDeepslate, 0, 2);
		world.setBlock(i + 15, j + 22, k + 7, PlaceDeepslate, 0, 2);
		world.setBlock(i + 16, j + 22, k + 7, PlaceDeepslate, 0, 2);
		world.setBlock(i + 17, j + 22, k + 7, PlaceDeepslate, 0, 2);
		world.setBlock(i + 18, j + 22, k + 7, PlaceDeepslate, 0, 2);
		world.setBlock(i + 9, j + 22, k + 8, sculk_block, 0, 2);
		world.setBlock(i + 10, j + 22, k + 8, PlaceDeepslate, 0, 2);
		world.setBlock(i + 11, j + 22, k + 8, PlaceDeepslate, 0, 2);
		world.setBlock(i + 12, j + 22, k + 8, PlaceDeepslate, 0, 2);
		world.setBlock(i + 13, j + 22, k + 8, PlaceDeepslate, 0, 2);
		world.setBlock(i + 14, j + 22, k + 8, PlaceDeepslate, 0, 2);
		world.setBlock(i + 15, j + 22, k + 8, PlaceDeepslate, 0, 2);
		world.setBlock(i + 16, j + 22, k + 8, PlaceDeepslate, 0, 2);
		world.setBlock(i + 17, j + 22, k + 8, PlaceDeepslate, 0, 2);
		world.setBlock(i + 18, j + 22, k + 8, PlaceDeepslate, 0, 2);
		world.setBlock(i + 19, j + 22, k + 8, PlaceDeepslate, 0, 2);
		world.setBlock(i + 10, j + 22, k + 9, sculk_block, 0, 2);
		world.setBlock(i + 11, j + 22, k + 9, PlaceDeepslate, 0, 2);
		world.setBlock(i + 12, j + 22, k + 9, PlaceDeepslate, 0, 2);
		world.setBlock(i + 13, j + 22, k + 9, PlaceDeepslate, 0, 2);
		world.setBlock(i + 14, j + 22, k + 9, PlaceDeepslate, 0, 2);
		world.setBlock(i + 15, j + 22, k + 9, PlaceDeepslate, 0, 2);
		world.setBlock(i + 16, j + 22, k + 9, PlaceDeepslate, 0, 2);
		world.setBlock(i + 17, j + 22, k + 9, PlaceDeepslate, 0, 2);
		world.setBlock(i + 18, j + 22, k + 9, PlaceDeepslate, 0, 2);
		world.setBlock(i + 19, j + 22, k + 9, PlaceDeepslate, 0, 2);
		world.setBlock(i + 20, j + 22, k + 9, PlaceDeepslate, 0, 2);
		world.setBlock(i + 10, j + 22, k + 10, sculk_block, 0, 2);
		world.setBlock(i + 11, j + 22, k + 10, PlaceDeepslate, 0, 2);
		world.setBlock(i + 12, j + 22, k + 10, PlaceDeepslate, 0, 2);
		world.setBlock(i + 13, j + 22, k + 10, PlaceDeepslate, 0, 2);
		world.setBlock(i + 14, j + 22, k + 10, PlaceDeepslate, 0, 2);
		world.setBlock(i + 15, j + 22, k + 10, PlaceDeepslate, 0, 2);
		world.setBlock(i + 16, j + 22, k + 10, PlaceDeepslate, 0, 2);
		world.setBlock(i + 17, j + 22, k + 10, PlaceDeepslate, 0, 2);
		world.setBlock(i + 18, j + 22, k + 10, PlaceDeepslate, 0, 2);
		world.setBlock(i + 19, j + 22, k + 10, PlaceDeepslate, 0, 2);
		world.setBlock(i + 20, j + 22, k + 10, PlaceDeepslate, 0, 2);
		world.setBlock(i + 10, j + 22, k + 11, sculk_block, 0, 2);
		world.setBlock(i + 11, j + 22, k + 11, PlaceDeepslate, 0, 2);
		world.setBlock(i + 12, j + 22, k + 11, PlaceDeepslate, 0, 2);
		world.setBlock(i + 13, j + 22, k + 11, PlaceDeepslate, 0, 2);
		world.setBlock(i + 14, j + 22, k + 11, PlaceDeepslate, 0, 2);
		world.setBlock(i + 15, j + 22, k + 11, PlaceDeepslate, 0, 2);
		world.setBlock(i + 16, j + 22, k + 11, PlaceDeepslate, 0, 2);
		world.setBlock(i + 17, j + 22, k + 11, PlaceDeepslate, 0, 2);
		world.setBlock(i + 18, j + 22, k + 11, PlaceDeepslate, 0, 2);
		world.setBlock(i + 19, j + 22, k + 11, PlaceDeepslate, 0, 2);
		world.setBlock(i + 20, j + 22, k + 11, PlaceDeepslate, 0, 2);
		world.setBlock(i + 21, j + 22, k + 11, PlaceDeepslate, 0, 2);
		world.setBlock(i + 10, j + 22, k + 12, sculk_block, 0, 2);
		world.setBlock(i + 11, j + 22, k + 12, PlaceDeepslate, 0, 2);
		world.setBlock(i + 12, j + 22, k + 12, PlaceDeepslate, 0, 2);
		world.setBlock(i + 13, j + 22, k + 12, PlaceDeepslate, 0, 2);
		world.setBlock(i + 14, j + 22, k + 12, PlaceDeepslate, 0, 2);
		world.setBlock(i + 15, j + 22, k + 12, PlaceDeepslate, 0, 2);
		world.setBlock(i + 16, j + 22, k + 12, PlaceDeepslate, 0, 2);
		world.setBlock(i + 17, j + 22, k + 12, PlaceDeepslate, 0, 2);
		world.setBlock(i + 18, j + 22, k + 12, PlaceDeepslate, 0, 2);
		world.setBlock(i + 19, j + 22, k + 12, PlaceDeepslate, 0, 2);
		world.setBlock(i + 20, j + 22, k + 12, PlaceDeepslate, 0, 2);
		world.setBlock(i + 21, j + 22, k + 12, PlaceDeepslate, 0, 2);
		world.setBlock(i + 9, j + 22, k + 13, sculk_block, 0, 2);
		world.setBlock(i + 10, j + 22, k + 13, PlaceDeepslate, 0, 2);
		world.setBlock(i + 11, j + 22, k + 13, PlaceDeepslate, 0, 2);
		world.setBlock(i + 12, j + 22, k + 13, PlaceDeepslate, 0, 2);
		world.setBlock(i + 13, j + 22, k + 13, PlaceDeepslate, 0, 2);
		world.setBlock(i + 14, j + 22, k + 13, PlaceDeepslate, 0, 2);
		world.setBlock(i + 15, j + 22, k + 13, PlaceDeepslate, 0, 2);
		world.setBlock(i + 16, j + 22, k + 13, PlaceDeepslate, 0, 2);
		world.setBlock(i + 17, j + 22, k + 13, PlaceDeepslate, 0, 2);
		world.setBlock(i + 18, j + 22, k + 13, PlaceDeepslate, 0, 2);
		world.setBlock(i + 19, j + 22, k + 13, PlaceDeepslate, 0, 2);
		world.setBlock(i + 20, j + 22, k + 13, PlaceDeepslate, 0, 2);
		world.setBlock(i + 21, j + 22, k + 13, PlaceDeepslate, 0, 2);
		world.setBlock(i + 10, j + 22, k + 14, sculk_block, 0, 2);
		world.setBlock(i + 11, j + 22, k + 14, PlaceDeepslate, 0, 2);
		world.setBlock(i + 12, j + 22, k + 14, PlaceDeepslate, 0, 2);
		world.setBlock(i + 13, j + 22, k + 14, PlaceDeepslate, 0, 2);
		world.setBlock(i + 14, j + 22, k + 14, PlaceDeepslate, 0, 2);
		world.setBlock(i + 15, j + 22, k + 14, PlaceDeepslate, 0, 2);
		world.setBlock(i + 16, j + 22, k + 14, PlaceDeepslate, 0, 2);
		world.setBlock(i + 17, j + 22, k + 14, PlaceDeepslate, 0, 2);
		world.setBlock(i + 18, j + 22, k + 14, PlaceDeepslate, 0, 2);
		world.setBlock(i + 19, j + 22, k + 14, PlaceDeepslate, 0, 2);
		world.setBlock(i + 20, j + 22, k + 14, PlaceDeepslate, 0, 2);
		world.setBlock(i + 21, j + 22, k + 14, PlaceDeepslate, 0, 2);
		world.setBlock(i + 22, j + 22, k + 14, sculk_block, 0, 2);
		world.setBlock(i + 10, j + 22, k + 15, sculk_block, 0, 2);
		world.setBlock(i + 11, j + 22, k + 15, PlaceDeepslate, 0, 2);
		world.setBlock(i + 12, j + 22, k + 15, PlaceDeepslate, 0, 2);
		world.setBlock(i + 13, j + 22, k + 15, PlaceDeepslate, 0, 2);
		world.setBlock(i + 14, j + 22, k + 15, PlaceDeepslate, 0, 2);
		world.setBlock(i + 15, j + 22, k + 15, PlaceDeepslate, 0, 2);
		world.setBlock(i + 16, j + 22, k + 15, PlaceDeepslate, 0, 2);
		world.setBlock(i + 17, j + 22, k + 15, PlaceDeepslate, 0, 2);
		world.setBlock(i + 18, j + 22, k + 15, PlaceDeepslate, 0, 2);
		world.setBlock(i + 19, j + 22, k + 15, PlaceDeepslate, 0, 2);
		world.setBlock(i + 20, j + 22, k + 15, PlaceDeepslate, 0, 2);
		world.setBlock(i + 21, j + 22, k + 15, sculk_block, 0, 2);
		world.setBlock(i + 11, j + 22, k + 16, sculk_block, 0, 2);
		world.setBlock(i + 12, j + 22, k + 16, sculk_block, 0, 2);
		world.setBlock(i + 13, j + 22, k + 16, PlaceDeepslate, 0, 2);
		world.setBlock(i + 14, j + 22, k + 16, sculk_block, 0, 2);
		world.setBlock(i + 15, j + 22, k + 16, sculk_block, 0, 2);
		world.setBlock(i + 16, j + 22, k + 16, sculk_block, 0, 2);
		world.setBlock(i + 17, j + 22, k + 16, PlaceDeepslate, 0, 2);
		world.setBlock(i + 18, j + 22, k + 16, sculk_block, 0, 2);
		world.setBlock(i + 19, j + 22, k + 16, sculk_block, 0, 2);
		world.setBlock(i + 20, j + 22, k + 16, sculk_block, 0, 2);
		world.setBlock(i + 13, j + 22, k + 17, sculk_block, 0, 2);
		world.setBlock(i + 17, j + 22, k + 17, sculk_block, 0, 2);
		world.setBlock(i + 12, j + 23, k + 2, PlaceDeepslate, 0, 2);
		world.setBlock(i + 13, j + 23, k + 2, PlaceDeepslate, 0, 2);
		world.setBlock(i + 14, j + 23, k + 2, PlaceDeepslate, 0, 2);
		world.setBlock(i + 10, j + 23, k + 3, PlaceDeepslate, 0, 2);
		world.setBlock(i + 11, j + 23, k + 3, PlaceDeepslate, 0, 2);
		world.setBlock(i + 12, j + 23, k + 3, PlaceDeepslate, 0, 2);
		world.setBlock(i + 13, j + 23, k + 3, PlaceDeepslate, 0, 2);
		world.setBlock(i + 14, j + 23, k + 3, PlaceDeepslate, 0, 2);
		world.setBlock(i + 15, j + 23, k + 3, PlaceDeepslate, 0, 2);
		world.setBlock(i + 16, j + 23, k + 3, PlaceDeepslate, 0, 2);
		world.setBlock(i + 17, j + 23, k + 3, PlaceDeepslate, 0, 2);
		world.setBlock(i + 9, j + 23, k + 4, PlaceDeepslate, 0, 2);
		world.setBlock(i + 10, j + 23, k + 4, PlaceDeepslate, 0, 2);
		world.setBlock(i + 11, j + 23, k + 4, PlaceDeepslate, 0, 2);
		world.setBlock(i + 12, j + 23, k + 4, PlaceDeepslate, 0, 2);
		world.setBlock(i + 13, j + 23, k + 4, PlaceDeepslate, 0, 2);
		world.setBlock(i + 14, j + 23, k + 4, PlaceDeepslate, 0, 2);
		world.setBlock(i + 15, j + 23, k + 4, PlaceDeepslate, 0, 2);
		world.setBlock(i + 16, j + 23, k + 4, PlaceDeepslate, 0, 2);
		world.setBlock(i + 17, j + 23, k + 4, PlaceDeepslate, 0, 2);
		world.setBlock(i + 9, j + 23, k + 5, PlaceDeepslate, 0, 2);
		world.setBlock(i + 10, j + 23, k + 5, PlaceDeepslate, 0, 2);
		world.setBlock(i + 11, j + 23, k + 5, PlaceDeepslate, 0, 2);
		world.setBlock(i + 12, j + 23, k + 5, PlaceDeepslate, 0, 2);
		world.setBlock(i + 13, j + 23, k + 5, PlaceDeepslate, 0, 2);
		world.setBlock(i + 14, j + 23, k + 5, PlaceDeepslate, 0, 2);
		world.setBlock(i + 15, j + 23, k + 5, PlaceDeepslate, 0, 2);
		world.setBlock(i + 16, j + 23, k + 5, PlaceDeepslate, 0, 2);
		world.setBlock(i + 17, j + 23, k + 5, PlaceDeepslate, 0, 2);
		world.setBlock(i + 9, j + 23, k + 6, PlaceDeepslate, 0, 2);
		world.setBlock(i + 10, j + 23, k + 6, PlaceDeepslate, 0, 2);
		world.setBlock(i + 11, j + 23, k + 6, PlaceDeepslate, 0, 2);
		world.setBlock(i + 12, j + 23, k + 6, PlaceDeepslate, 0, 2);
		world.setBlock(i + 13, j + 23, k + 6, PlaceDeepslate, 0, 2);
		world.setBlock(i + 14, j + 23, k + 6, PlaceDeepslate, 0, 2);
		world.setBlock(i + 15, j + 23, k + 6, PlaceDeepslate, 0, 2);
		world.setBlock(i + 16, j + 23, k + 6, PlaceDeepslate, 0, 2);
		world.setBlock(i + 17, j + 23, k + 6, PlaceDeepslate, 0, 2);
		world.setBlock(i + 18, j + 23, k + 6, PlaceDeepslate, 0, 2);
		world.setBlock(i + 9, j + 23, k + 7, PlaceDeepslate, 0, 2);
		world.setBlock(i + 10, j + 23, k + 7, PlaceDeepslate, 0, 2);
		world.setBlock(i + 11, j + 23, k + 7, PlaceDeepslate, 0, 2);
		world.setBlock(i + 12, j + 23, k + 7, PlaceDeepslate, 0, 2);
		world.setBlock(i + 13, j + 23, k + 7, PlaceDeepslate, 0, 2);
		world.setBlock(i + 14, j + 23, k + 7, PlaceDeepslate, 0, 2);
		world.setBlock(i + 15, j + 23, k + 7, PlaceDeepslate, 0, 2);
		world.setBlock(i + 16, j + 23, k + 7, PlaceDeepslate, 0, 2);
		world.setBlock(i + 17, j + 23, k + 7, PlaceDeepslate, 0, 2);
		world.setBlock(i + 18, j + 23, k + 7, PlaceDeepslate, 0, 2);
		world.setBlock(i + 8, j + 23, k + 8, sculk_block, 0, 2);
		world.setBlock(i + 9, j + 23, k + 8, PlaceDeepslate, 0, 2);
		world.setBlock(i + 10, j + 23, k + 8, PlaceDeepslate, 0, 2);
		world.setBlock(i + 11, j + 23, k + 8, PlaceDeepslate, 0, 2);
		world.setBlock(i + 12, j + 23, k + 8, PlaceDeepslate, 0, 2);
		world.setBlock(i + 13, j + 23, k + 8, PlaceDeepslate, 0, 2);
		world.setBlock(i + 14, j + 23, k + 8, PlaceDeepslate, 0, 2);
		world.setBlock(i + 15, j + 23, k + 8, PlaceDeepslate, 0, 2);
		world.setBlock(i + 16, j + 23, k + 8, PlaceDeepslate, 0, 2);
		world.setBlock(i + 17, j + 23, k + 8, PlaceDeepslate, 0, 2);
		world.setBlock(i + 18, j + 23, k + 8, PlaceDeepslate, 0, 2);
		world.setBlock(i + 19, j + 23, k + 8, PlaceDeepslate, 0, 2);
		world.setBlock(i + 8, j + 23, k + 9, sculk_block, 0, 2);
		world.setBlock(i + 9, j + 23, k + 9, sculk_block, 0, 2);
		world.setBlock(i + 10, j + 23, k + 9, PlaceDeepslate, 0, 2);
		world.setBlock(i + 11, j + 23, k + 9, PlaceDeepslate, 0, 2);
		world.setBlock(i + 12, j + 23, k + 9, PlaceDeepslate, 0, 2);
		world.setBlock(i + 13, j + 23, k + 9, PlaceDeepslate, 0, 2);
		world.setBlock(i + 14, j + 23, k + 9, PlaceDeepslate, 0, 2);
		world.setBlock(i + 15, j + 23, k + 9, PlaceDeepslate, 0, 2);
		world.setBlock(i + 16, j + 23, k + 9, PlaceDeepslate, 0, 2);
		world.setBlock(i + 17, j + 23, k + 9, PlaceDeepslate, 0, 2);
		world.setBlock(i + 18, j + 23, k + 9, PlaceDeepslate, 0, 2);
		world.setBlock(i + 19, j + 23, k + 9, PlaceDeepslate, 0, 2);
		world.setBlock(i + 20, j + 23, k + 9, PlaceDeepslate, 0, 2);
		world.setBlock(i + 9, j + 23, k + 10, sculk_block, 0, 2);
		world.setBlock(i + 10, j + 23, k + 10, PlaceDeepslate, 0, 2);
		world.setBlock(i + 11, j + 23, k + 10, PlaceDeepslate, 0, 2);
		world.setBlock(i + 12, j + 23, k + 10, PlaceDeepslate, 0, 2);
		world.setBlock(i + 13, j + 23, k + 10, PlaceDeepslate, 0, 2);
		world.setBlock(i + 14, j + 23, k + 10, PlaceDeepslate, 0, 2);
		world.setBlock(i + 15, j + 23, k + 10, PlaceDeepslate, 0, 2);
		world.setBlock(i + 16, j + 23, k + 10, PlaceDeepslate, 0, 2);
		world.setBlock(i + 17, j + 23, k + 10, PlaceDeepslate, 0, 2);
		world.setBlock(i + 18, j + 23, k + 10, PlaceDeepslate, 0, 2);
		world.setBlock(i + 19, j + 23, k + 10, PlaceDeepslate, 0, 2);
		world.setBlock(i + 20, j + 23, k + 10, PlaceDeepslate, 0, 2);
		world.setBlock(i + 9, j + 23, k + 11, sculk_block, 0, 2);
		world.setBlock(i + 10, j + 23, k + 11, PlaceDeepslate, 0, 2);
		world.setBlock(i + 11, j + 23, k + 11, PlaceDeepslate, 0, 2);
		world.setBlock(i + 12, j + 23, k + 11, PlaceDeepslate, 0, 2);
		world.setBlock(i + 13, j + 23, k + 11, PlaceDeepslate, 0, 2);
		world.setBlock(i + 14, j + 23, k + 11, PlaceDeepslate, 0, 2);
		world.setBlock(i + 15, j + 23, k + 11, PlaceDeepslate, 0, 2);
		world.setBlock(i + 16, j + 23, k + 11, PlaceDeepslate, 0, 2);
		world.setBlock(i + 17, j + 23, k + 11, PlaceDeepslate, 0, 2);
		world.setBlock(i + 18, j + 23, k + 11, PlaceDeepslate, 0, 2);
		world.setBlock(i + 19, j + 23, k + 11, PlaceDeepslate, 0, 2);
		world.setBlock(i + 20, j + 23, k + 11, PlaceDeepslate, 0, 2);
		world.setBlock(i + 21, j + 23, k + 11, PlaceDeepslate, 0, 2);
		world.setBlock(i + 9, j + 23, k + 12, sculk_block, 0, 2);
		world.setBlock(i + 10, j + 23, k + 12, PlaceDeepslate, 0, 2);
		world.setBlock(i + 11, j + 23, k + 12, PlaceDeepslate, 0, 2);
		world.setBlock(i + 12, j + 23, k + 12, PlaceDeepslate, 0, 2);
		world.setBlock(i + 13, j + 23, k + 12, PlaceDeepslate, 0, 2);
		world.setBlock(i + 14, j + 23, k + 12, PlaceDeepslate, 0, 2);
		world.setBlock(i + 15, j + 23, k + 12, PlaceDeepslate, 0, 2);
		world.setBlock(i + 16, j + 23, k + 12, PlaceDeepslate, 0, 2);
		world.setBlock(i + 17, j + 23, k + 12, PlaceDeepslate, 0, 2);
		world.setBlock(i + 18, j + 23, k + 12, PlaceDeepslate, 0, 2);
		world.setBlock(i + 19, j + 23, k + 12, PlaceDeepslate, 0, 2);
		world.setBlock(i + 20, j + 23, k + 12, PlaceDeepslate, 0, 2);
		world.setBlock(i + 21, j + 23, k + 12, PlaceDeepslate, 0, 2);
		world.setBlock(i + 8, j + 23, k + 13, sculk_block, 0, 2);
		world.setBlock(i + 9, j + 23, k + 13, PlaceDeepslate, 0, 2);
		world.setBlock(i + 10, j + 23, k + 13, PlaceDeepslate, 0, 2);
		world.setBlock(i + 11, j + 23, k + 13, PlaceDeepslate, 0, 2);
		world.setBlock(i + 12, j + 23, k + 13, PlaceDeepslate, 0, 2);
		world.setBlock(i + 13, j + 23, k + 13, PlaceDeepslate, 0, 2);
		world.setBlock(i + 14, j + 23, k + 13, PlaceDeepslate, 0, 2);
		world.setBlock(i + 15, j + 23, k + 13, PlaceDeepslate, 0, 2);
		world.setBlock(i + 16, j + 23, k + 13, PlaceDeepslate, 0, 2);
		world.setBlock(i + 17, j + 23, k + 13, PlaceDeepslate, 0, 2);
		world.setBlock(i + 18, j + 23, k + 13, PlaceDeepslate, 0, 2);
		world.setBlock(i + 19, j + 23, k + 13, PlaceDeepslate, 0, 2);
		world.setBlock(i + 20, j + 23, k + 13, PlaceDeepslate, 0, 2);
		world.setBlock(i + 21, j + 23, k + 13, PlaceDeepslate, 0, 2);
		world.setBlock(i + 9, j + 23, k + 14, sculk_block, 0, 2);
		world.setBlock(i + 10, j + 23, k + 14, PlaceDeepslate, 0, 2);
		world.setBlock(i + 11, j + 23, k + 14, PlaceDeepslate, 0, 2);
		world.setBlock(i + 12, j + 23, k + 14, PlaceDeepslate, 0, 2);
		world.setBlock(i + 13, j + 23, k + 14, PlaceDeepslate, 0, 2);
		world.setBlock(i + 14, j + 23, k + 14, PlaceDeepslate, 0, 2);
		world.setBlock(i + 15, j + 23, k + 14, PlaceDeepslate, 0, 2);
		world.setBlock(i + 16, j + 23, k + 14, PlaceDeepslate, 0, 2);
		world.setBlock(i + 17, j + 23, k + 14, PlaceDeepslate, 0, 2);
		world.setBlock(i + 18, j + 23, k + 14, PlaceDeepslate, 0, 2);
		world.setBlock(i + 19, j + 23, k + 14, PlaceDeepslate, 0, 2);
		world.setBlock(i + 20, j + 23, k + 14, PlaceDeepslate, 0, 2);
		world.setBlock(i + 21, j + 23, k + 14, PlaceDeepslate, 0, 2);
		world.setBlock(i + 22, j + 23, k + 14, sculk_block, 0, 2);
		world.setBlock(i + 10, j + 23, k + 15, sculk_block, 0, 2);
		world.setBlock(i + 11, j + 23, k + 15, PlaceDeepslate, 0, 2);
		world.setBlock(i + 12, j + 23, k + 15, PlaceDeepslate, 0, 2);
		world.setBlock(i + 13, j + 23, k + 15, PlaceDeepslate, 0, 2);
		world.setBlock(i + 14, j + 23, k + 15, PlaceDeepslate, 0, 2);
		world.setBlock(i + 15, j + 23, k + 15, PlaceDeepslate, 0, 2);
		world.setBlock(i + 16, j + 23, k + 15, PlaceDeepslate, 0, 2);
		world.setBlock(i + 17, j + 23, k + 15, PlaceDeepslate, 0, 2);
		world.setBlock(i + 18, j + 23, k + 15, PlaceDeepslate, 0, 2);
		world.setBlock(i + 19, j + 23, k + 15, PlaceDeepslate, 0, 2);
		world.setBlock(i + 20, j + 23, k + 15, PlaceDeepslate, 0, 2);
		world.setBlock(i + 21, j + 23, k + 15, sculk_block, 0, 2);
		world.setBlock(i + 10, j + 23, k + 16, sculk_block, 0, 2);
		world.setBlock(i + 11, j + 23, k + 16, sculk_block, 0, 2);
		world.setBlock(i + 12, j + 23, k + 16, sculk_block, 0, 2);
		world.setBlock(i + 13, j + 23, k + 16, sculk_block, 0, 2);
		world.setBlock(i + 14, j + 23, k + 16, PlaceDeepslate, 0, 2);
		world.setBlock(i + 15, j + 23, k + 16, sculk_block, 0, 2);
		world.setBlock(i + 16, j + 23, k + 16, PlaceDeepslate, 0, 2);
		world.setBlock(i + 17, j + 23, k + 16, PlaceDeepslate, 0, 2);
		world.setBlock(i + 18, j + 23, k + 16, PlaceDeepslate, 0, 2);
		world.setBlock(i + 19, j + 23, k + 16, sculk_block, 0, 2);
		world.setBlock(i + 20, j + 23, k + 16, sculk_block, 0, 2);
		world.setBlock(i + 14, j + 23, k + 17, sculk_block, 0, 2);
		world.setBlock(i + 16, j + 23, k + 17, sculk_block, 0, 2);
		world.setBlock(i + 17, j + 23, k + 17, sculk_block, 0, 2);
		world.setBlock(i + 18, j + 23, k + 17, sculk_block, 0, 2);
		world.setBlock(i + 10, j + 24, k + 1, PlaceDeepslate, 0, 2);
		world.setBlock(i + 11, j + 24, k + 1, PlaceDeepslate, 0, 2);
		world.setBlock(i + 12, j + 24, k + 1, PlaceDeepslate, 0, 2);
		world.setBlock(i + 13, j + 24, k + 1, PlaceDeepslate, 0, 2);
		world.setBlock(i + 14, j + 24, k + 1, PlaceDeepslate, 0, 2);
		world.setBlock(i + 8, j + 24, k + 2, PlaceDeepslate, 0, 2);
		world.setBlock(i + 9, j + 24, k + 2, PlaceDeepslate, 0, 2);
		world.setBlock(i + 10, j + 24, k + 2, PlaceDeepslate, 0, 2);
		world.setBlock(i + 11, j + 24, k + 2, PlaceDeepslate, 0, 2);
		world.setBlock(i + 12, j + 24, k + 2, PlaceDeepslate, 0, 2);
		world.setBlock(i + 13, j + 24, k + 2, PlaceDeepslate, 0, 2);
		world.setBlock(i + 14, j + 24, k + 2, PlaceDeepslate, 0, 2);
		world.setBlock(i + 15, j + 24, k + 2, PlaceDeepslate, 0, 2);
		world.setBlock(i + 16, j + 24, k + 2, PlaceDeepslate, 0, 2);
		world.setBlock(i + 7, j + 24, k + 3, PlaceDeepslate, 0, 2);
		world.setBlock(i + 8, j + 24, k + 3, PlaceDeepslate, 0, 2);
		world.setBlock(i + 9, j + 24, k + 3, PlaceDeepslate, 0, 2);
		world.setBlock(i + 10, j + 24, k + 3, PlaceDeepslate, 0, 2);
		world.setBlock(i + 11, j + 24, k + 3, PlaceDeepslate, 0, 2);
		world.setBlock(i + 12, j + 24, k + 3, PlaceDeepslate, 0, 2);
		world.setBlock(i + 13, j + 24, k + 3, PlaceDeepslate, 0, 2);
		world.setBlock(i + 14, j + 24, k + 3, PlaceDeepslate, 0, 2);
		world.setBlock(i + 15, j + 24, k + 3, PlaceDeepslate, 0, 2);
		world.setBlock(i + 16, j + 24, k + 3, PlaceDeepslate, 0, 2);
		world.setBlock(i + 17, j + 24, k + 3, PlaceDeepslate, 0, 2);
		world.setBlock(i + 8, j + 24, k + 4, PlaceDeepslate, 0, 2);
		world.setBlock(i + 9, j + 24, k + 4, PlaceDeepslate, 0, 2);
		world.setBlock(i + 10, j + 24, k + 4, PlaceDeepslate, 0, 2);
		world.setBlock(i + 11, j + 24, k + 4, PlaceDeepslate, 0, 2);
		world.setBlock(i + 12, j + 24, k + 4, PlaceDeepslate, 0, 2);
		world.setBlock(i + 13, j + 24, k + 4, PlaceDeepslate, 0, 2);
		world.setBlock(i + 14, j + 24, k + 4, PlaceDeepslate, 0, 2);
		world.setBlock(i + 15, j + 24, k + 4, PlaceDeepslate, 0, 2);
		world.setBlock(i + 16, j + 24, k + 4, PlaceDeepslate, 0, 2);
		world.setBlock(i + 17, j + 24, k + 4, PlaceDeepslate, 0, 2);
		world.setBlock(i + 8, j + 24, k + 5, PlaceDeepslate, 0, 2);
		world.setBlock(i + 9, j + 24, k + 5, PlaceDeepslate, 0, 2);
		world.setBlock(i + 10, j + 24, k + 5, PlaceDeepslate, 0, 2);
		world.setBlock(i + 11, j + 24, k + 5, PlaceDeepslate, 0, 2);
		world.setBlock(i + 12, j + 24, k + 5, PlaceDeepslate, 0, 2);
		world.setBlock(i + 13, j + 24, k + 5, PlaceDeepslate, 0, 2);
		world.setBlock(i + 14, j + 24, k + 5, PlaceDeepslate, 0, 2);
		world.setBlock(i + 15, j + 24, k + 5, PlaceDeepslate, 0, 2);
		world.setBlock(i + 16, j + 24, k + 5, PlaceDeepslate, 0, 2);
		world.setBlock(i + 17, j + 24, k + 5, PlaceDeepslate, 0, 2);
		world.setBlock(i + 18, j + 24, k + 5, PlaceDeepslate, 0, 2);
		world.setBlock(i + 5, j + 24, k + 6, sculk_block, 0, 2);
		world.setBlock(i + 6, j + 24, k + 6, sculk_block, 0, 2);
		world.setBlock(i + 8, j + 24, k + 6, PlaceDeepslate, 0, 2);
		world.setBlock(i + 9, j + 24, k + 6, PlaceDeepslate, 0, 2);
		world.setBlock(i + 10, j + 24, k + 6, PlaceDeepslate, 0, 2);
		world.setBlock(i + 11, j + 24, k + 6, PlaceDeepslate, 0, 2);
		world.setBlock(i + 12, j + 24, k + 6, PlaceDeepslate, 0, 2);
		world.setBlock(i + 13, j + 24, k + 6, PlaceDeepslate, 0, 2);
		world.setBlock(i + 14, j + 24, k + 6, PlaceDeepslate, 0, 2);
		world.setBlock(i + 15, j + 24, k + 6, PlaceDeepslate, 0, 2);
		world.setBlock(i + 16, j + 24, k + 6, PlaceDeepslate, 0, 2);
		world.setBlock(i + 17, j + 24, k + 6, PlaceDeepslate, 0, 2);
		world.setBlock(i + 18, j + 24, k + 6, PlaceDeepslate, 0, 2);
		world.setBlock(i + 4, j + 24, k + 7, sculk_block, 0, 2);
		world.setBlock(i + 7, j + 24, k + 7, sculk_block, 0, 2);
		world.setBlock(i + 8, j + 24, k + 7, PlaceDeepslate, 0, 2);
		world.setBlock(i + 9, j + 24, k + 7, PlaceDeepslate, 0, 2);
		world.setBlock(i + 10, j + 24, k + 7, PlaceDeepslate, 0, 2);
		world.setBlock(i + 11, j + 24, k + 7, PlaceDeepslate, 0, 2);
		world.setBlock(i + 12, j + 24, k + 7, PlaceDeepslate, 0, 2);
		world.setBlock(i + 13, j + 24, k + 7, PlaceDeepslate, 0, 2);
		world.setBlock(i + 14, j + 24, k + 7, PlaceDeepslate, 0, 2);
		world.setBlock(i + 15, j + 24, k + 7, PlaceDeepslate, 0, 2);
		world.setBlock(i + 16, j + 24, k + 7, PlaceDeepslate, 0, 2);
		world.setBlock(i + 17, j + 24, k + 7, PlaceDeepslate, 0, 2);
		world.setBlock(i + 18, j + 24, k + 7, PlaceDeepslate, 0, 2);
		world.setBlock(i + 2, j + 24, k + 8, sculk_block, 0, 2);
		world.setBlock(i + 3, j + 24, k + 8, sculk_block, 0, 2);
		world.setBlock(i + 4, j + 24, k + 8, sculk_block, 0, 2);
		world.setBlock(i + 7, j + 24, k + 8, sculk_block, 0, 2);
		world.setBlock(i + 8, j + 24, k + 8, PlaceDeepslate, 0, 2);
		world.setBlock(i + 9, j + 24, k + 8, PlaceDeepslate, 0, 2);
		world.setBlock(i + 10, j + 24, k + 8, PlaceDeepslate, 0, 2);
		world.setBlock(i + 11, j + 24, k + 8, PlaceDeepslate, 0, 2);
		world.setBlock(i + 12, j + 24, k + 8, PlaceDeepslate, 0, 2);
		world.setBlock(i + 13, j + 24, k + 8, PlaceDeepslate, 0, 2);
		world.setBlock(i + 14, j + 24, k + 8, PlaceDeepslate, 0, 2);
		world.setBlock(i + 15, j + 24, k + 8, PlaceDeepslate, 0, 2);
		world.setBlock(i + 16, j + 24, k + 8, PlaceDeepslate, 0, 2);
		world.setBlock(i + 17, j + 24, k + 8, PlaceDeepslate, 0, 2);
		world.setBlock(i + 18, j + 24, k + 8, PlaceDeepslate, 0, 2);
		world.setBlock(i + 19, j + 24, k + 8, PlaceDeepslate, 0, 2);
		world.setBlock(i + 7, j + 24, k + 9, sculk_block, 0, 2);
		world.setBlock(i + 8, j + 24, k + 9, PlaceDeepslate, 0, 2);
		world.setBlock(i + 9, j + 24, k + 9, PlaceDeepslate, 0, 2);
		world.setBlock(i + 10, j + 24, k + 9, PlaceDeepslate, 0, 2);
		world.setBlock(i + 11, j + 24, k + 9, PlaceDeepslate, 0, 2);
		world.setBlock(i + 12, j + 24, k + 9, PlaceDeepslate, 0, 2);
		world.setBlock(i + 13, j + 24, k + 9, PlaceDeepslate, 0, 2);
		world.setBlock(i + 14, j + 24, k + 9, PlaceDeepslate, 0, 2);
		world.setBlock(i + 15, j + 24, k + 9, PlaceDeepslate, 0, 2);
		world.setBlock(i + 16, j + 24, k + 9, PlaceDeepslate, 0, 2);
		world.setBlock(i + 17, j + 24, k + 9, PlaceDeepslate, 0, 2);
		world.setBlock(i + 18, j + 24, k + 9, PlaceDeepslate, 0, 2);
		world.setBlock(i + 19, j + 24, k + 9, PlaceDeepslate, 0, 2);
		world.setBlock(i + 20, j + 24, k + 9, PlaceDeepslate, 0, 2);
		world.setBlock(i + 4, j + 24, k + 10, sculk_block, 0, 2);
		world.setBlock(i + 7, j + 24, k + 10, sculk_block, 0, 2);
		world.setBlock(i + 8, j + 24, k + 10, sculk_block, 0, 2);
		world.setBlock(i + 9, j + 24, k + 10, PlaceDeepslate, 0, 2);
		world.setBlock(i + 10, j + 24, k + 10, PlaceDeepslate, 0, 2);
		world.setBlock(i + 11, j + 24, k + 10, PlaceDeepslate, 0, 2);
		world.setBlock(i + 12, j + 24, k + 10, PlaceDeepslate, 0, 2);
		world.setBlock(i + 13, j + 24, k + 10, PlaceDeepslate, 0, 2);
		world.setBlock(i + 14, j + 24, k + 10, PlaceDeepslate, 0, 2);
		world.setBlock(i + 15, j + 24, k + 10, PlaceDeepslate, 0, 2);
		world.setBlock(i + 16, j + 24, k + 10, PlaceDeepslate, 0, 2);
		world.setBlock(i + 17, j + 24, k + 10, PlaceDeepslate, 0, 2);
		world.setBlock(i + 18, j + 24, k + 10, PlaceDeepslate, 0, 2);
		world.setBlock(i + 19, j + 24, k + 10, PlaceDeepslate, 0, 2);
		world.setBlock(i + 20, j + 24, k + 10, PlaceDeepslate, 0, 2);
		world.setBlock(i + 21, j + 24, k + 10, PlaceDeepslate, 0, 2);
		world.setBlock(i + 3, j + 24, k + 11, sculk_block, 0, 2);
		world.setBlock(i + 4, j + 24, k + 11, sculk_block, 0, 2);
		world.setBlock(i + 8, j + 24, k + 11, sculk_block, 0, 2);
		world.setBlock(i + 9, j + 24, k + 11, PlaceDeepslate, 0, 2);
		world.setBlock(i + 10, j + 24, k + 11, PlaceDeepslate, 0, 2);
		world.setBlock(i + 11, j + 24, k + 11, PlaceDeepslate, 0, 2);
		world.setBlock(i + 12, j + 24, k + 11, PlaceDeepslate, 0, 2);
		world.setBlock(i + 13, j + 24, k + 11, PlaceDeepslate, 0, 2);
		world.setBlock(i + 14, j + 24, k + 11, PlaceDeepslate, 0, 2);
		world.setBlock(i + 15, j + 24, k + 11, PlaceDeepslate, 0, 2);
		world.setBlock(i + 16, j + 24, k + 11, PlaceDeepslate, 0, 2);
		world.setBlock(i + 17, j + 24, k + 11, PlaceDeepslate, 0, 2);
		world.setBlock(i + 18, j + 24, k + 11, PlaceDeepslate, 0, 2);
		world.setBlock(i + 19, j + 24, k + 11, PlaceDeepslate, 0, 2);
		world.setBlock(i + 20, j + 24, k + 11, PlaceDeepslate, 0, 2);
		world.setBlock(i + 21, j + 24, k + 11, PlaceDeepslate, 0, 2);
		world.setBlock(i + 2, j + 24, k + 12, sculk_block, 0, 2);
		world.setBlock(i + 4, j + 24, k + 12, sculk_block, 0, 2);
		world.setBlock(i + 8, j + 24, k + 12, sculk_block, 0, 2);
		world.setBlock(i + 9, j + 24, k + 12, PlaceDeepslate, 0, 2);
		world.setBlock(i + 10, j + 24, k + 12, PlaceDeepslate, 0, 2);
		world.setBlock(i + 11, j + 24, k + 12, PlaceDeepslate, 0, 2);
		world.setBlock(i + 12, j + 24, k + 12, PlaceDeepslate, 0, 2);
		world.setBlock(i + 13, j + 24, k + 12, PlaceDeepslate, 0, 2);
		world.setBlock(i + 14, j + 24, k + 12, PlaceDeepslate, 0, 2);
		world.setBlock(i + 15, j + 24, k + 12, PlaceDeepslate, 0, 2);
		world.setBlock(i + 16, j + 24, k + 12, PlaceDeepslate, 0, 2);
		world.setBlock(i + 17, j + 24, k + 12, PlaceDeepslate, 0, 2);
		world.setBlock(i + 18, j + 24, k + 12, PlaceDeepslate, 0, 2);
		world.setBlock(i + 19, j + 24, k + 12, PlaceDeepslate, 0, 2);
		world.setBlock(i + 20, j + 24, k + 12, PlaceDeepslate, 0, 2);
		world.setBlock(i + 21, j + 24, k + 12, PlaceDeepslate, 0, 2);
		world.setBlock(i + 4, j + 24, k + 13, sculk_block, 0, 2);
		world.setBlock(i + 8, j + 24, k + 13, sculk_block, 0, 2);
		world.setBlock(i + 9, j + 24, k + 13, PlaceDeepslate, 0, 2);
		world.setBlock(i + 10, j + 24, k + 13, PlaceDeepslate, 0, 2);
		world.setBlock(i + 11, j + 24, k + 13, PlaceDeepslate, 0, 2);
		world.setBlock(i + 12, j + 24, k + 13, PlaceDeepslate, 0, 2);
		world.setBlock(i + 13, j + 24, k + 13, PlaceDeepslate, 0, 2);
		world.setBlock(i + 14, j + 24, k + 13, PlaceDeepslate, 0, 2);
		world.setBlock(i + 15, j + 24, k + 13, PlaceDeepslate, 0, 2);
		world.setBlock(i + 16, j + 24, k + 13, PlaceDeepslate, 0, 2);
		world.setBlock(i + 17, j + 24, k + 13, PlaceDeepslate, 0, 2);
		world.setBlock(i + 18, j + 24, k + 13, PlaceDeepslate, 0, 2);
		world.setBlock(i + 19, j + 24, k + 13, PlaceDeepslate, 0, 2);
		world.setBlock(i + 20, j + 24, k + 13, PlaceDeepslate, 0, 2);
		world.setBlock(i + 21, j + 24, k + 13, PlaceDeepslate, 0, 2);
		world.setBlock(i + 5, j + 24, k + 14, sculk_block, 0, 2);
		world.setBlock(i + 6, j + 24, k + 14, sculk_block, 0, 2);
		world.setBlock(i + 8, j + 24, k + 14, sculk_block, 0, 2);
		world.setBlock(i + 9, j + 24, k + 14, PlaceDeepslate, 0, 2);
		world.setBlock(i + 10, j + 24, k + 14, PlaceDeepslate, 0, 2);
		world.setBlock(i + 11, j + 24, k + 14, PlaceDeepslate, 0, 2);
		world.setBlock(i + 12, j + 24, k + 14, PlaceDeepslate, 0, 2);
		world.setBlock(i + 13, j + 24, k + 14, PlaceDeepslate, 0, 2);
		world.setBlock(i + 14, j + 24, k + 14, PlaceDeepslate, 0, 2);
		world.setBlock(i + 15, j + 24, k + 14, PlaceDeepslate, 0, 2);
		world.setBlock(i + 16, j + 24, k + 14, PlaceDeepslate, 0, 2);
		world.setBlock(i + 17, j + 24, k + 14, PlaceDeepslate, 0, 2);
		world.setBlock(i + 18, j + 24, k + 14, PlaceDeepslate, 0, 2);
		world.setBlock(i + 19, j + 24, k + 14, PlaceDeepslate, 0, 2);
		world.setBlock(i + 20, j + 24, k + 14, PlaceDeepslate, 0, 2);
		world.setBlock(i + 21, j + 24, k + 14, PlaceDeepslate, 0, 2);
		world.setBlock(i + 4, j + 24, k + 15, sculk_block, 0, 2);
		world.setBlock(i + 8, j + 24, k + 15, sculk_block, 0, 2);
		world.setBlock(i + 9, j + 24, k + 15, sculk_block, 0, 2);
		world.setBlock(i + 10, j + 24, k + 15, PlaceDeepslate, 0, 2);
		world.setBlock(i + 11, j + 24, k + 15, PlaceDeepslate, 0, 2);
		world.setBlock(i + 12, j + 24, k + 15, PlaceDeepslate, 0, 2);
		world.setBlock(i + 13, j + 24, k + 15, PlaceDeepslate, 0, 2);
		world.setBlock(i + 14, j + 24, k + 15, PlaceDeepslate, 0, 2);
		world.setBlock(i + 15, j + 24, k + 15, PlaceDeepslate, 0, 2);
		world.setBlock(i + 16, j + 24, k + 15, PlaceDeepslate, 0, 2);
		world.setBlock(i + 17, j + 24, k + 15, PlaceDeepslate, 0, 2);
		world.setBlock(i + 18, j + 24, k + 15, PlaceDeepslate, 0, 2);
		world.setBlock(i + 19, j + 24, k + 15, PlaceDeepslate, 0, 2);
		world.setBlock(i + 20, j + 24, k + 15, PlaceDeepslate, 0, 2);
		world.setBlock(i + 21, j + 24, k + 15, PlaceDeepslate, 0, 2);
		world.setBlock(i + 22, j + 24, k + 15, sculk_block, 0, 2);
		world.setBlock(i + 9, j + 24, k + 16, sculk_block, 0, 2);
		world.setBlock(i + 10, j + 24, k + 16, sculk_block, 0, 2);
		world.setBlock(i + 11, j + 24, k + 16, sculk_block, 0, 2);
		world.setBlock(i + 12, j + 24, k + 16, sculk_block, 0, 2);
		world.setBlock(i + 13, j + 24, k + 16, sculk_block, 0, 2);
		world.setBlock(i + 14, j + 24, k + 16, sculk_block, 0, 2);
		world.setBlock(i + 15, j + 24, k + 16, sculk_block, 0, 2);
		world.setBlock(i + 16, j + 24, k + 16, sculk_block, 0, 2);
		world.setBlock(i + 17, j + 24, k + 16, sculk_block, 0, 2);
		world.setBlock(i + 18, j + 24, k + 16, sculk_block, 0, 2);
		world.setBlock(i + 19, j + 24, k + 16, sculk_block, 0, 2);
		world.setBlock(i + 20, j + 24, k + 16, sculk_block, 0, 2);
		world.setBlock(i + 21, j + 24, k + 16, sculk_block, 0, 2);
		world.setBlock(i + 8, j + 25, k + 0, PlaceDeepslate, 0, 2);
		world.setBlock(i + 9, j + 25, k + 0, PlaceDeepslate, 0, 2);
		world.setBlock(i + 10, j + 25, k + 0, PlaceDeepslate, 0, 2);
		world.setBlock(i + 11, j + 25, k + 0, PlaceDeepslate, 0, 2);
		world.setBlock(i + 12, j + 25, k + 0, PlaceDeepslate, 0, 2);
		world.setBlock(i + 13, j + 25, k + 0, PlaceDeepslate, 0, 2);
		world.setBlock(i + 14, j + 25, k + 0, PlaceDeepslate, 0, 2);
		world.setBlock(i + 15, j + 25, k + 0, PlaceDeepslate, 0, 2);
		world.setBlock(i + 16, j + 25, k + 0, PlaceDeepslate, 0, 2);
		world.setBlock(i + 7, j + 25, k + 1, PlaceDeepslate, 0, 2);
		world.setBlock(i + 8, j + 25, k + 1, PlaceDeepslate, 0, 2);
		world.setBlock(i + 9, j + 25, k + 1, PlaceDeepslate, 0, 2);
		world.setBlock(i + 10, j + 25, k + 1, PlaceDeepslate, 0, 2);
		world.setBlock(i + 11, j + 25, k + 1, PlaceDeepslate, 0, 2);
		world.setBlock(i + 12, j + 25, k + 1, PlaceDeepslate, 0, 2);
		world.setBlock(i + 13, j + 25, k + 1, PlaceDeepslate, 0, 2);
		world.setBlock(i + 14, j + 25, k + 1, PlaceDeepslate, 0, 2);
		world.setBlock(i + 15, j + 25, k + 1, PlaceDeepslate, 0, 2);
		world.setBlock(i + 16, j + 25, k + 1, PlaceDeepslate, 0, 2);
		world.setBlock(i + 17, j + 25, k + 1, PlaceDeepslate, 0, 2);
		world.setBlock(i + 6, j + 25, k + 2, PlaceDeepslate, 0, 2);
		world.setBlock(i + 7, j + 25, k + 2, PlaceDeepslate, 0, 2);
		world.setBlock(i + 8, j + 25, k + 2, PlaceDeepslate, 0, 2);
		world.setBlock(i + 9, j + 25, k + 2, PlaceDeepslate, 0, 2);
		world.setBlock(i + 10, j + 25, k + 2, PlaceDeepslate, 0, 2);
		world.setBlock(i + 11, j + 25, k + 2, PlaceDeepslate, 0, 2);
		world.setBlock(i + 12, j + 25, k + 2, PlaceDeepslate, 0, 2);
		world.setBlock(i + 13, j + 25, k + 2, PlaceDeepslate, 0, 2);
		world.setBlock(i + 14, j + 25, k + 2, PlaceDeepslate, 0, 2);
		world.setBlock(i + 15, j + 25, k + 2, PlaceDeepslate, 0, 2);
		world.setBlock(i + 16, j + 25, k + 2, PlaceDeepslate, 0, 2);
		world.setBlock(i + 17, j + 25, k + 2, PlaceDeepslate, 0, 2);
		world.setBlock(i + 6, j + 25, k + 3, PlaceDeepslate, 0, 2);
		world.setBlock(i + 7, j + 25, k + 3, PlaceDeepslate, 0, 2);
		world.setBlock(i + 8, j + 25, k + 3, PlaceDeepslate, 0, 2);
		world.setBlock(i + 9, j + 25, k + 3, PlaceDeepslate, 0, 2);
		world.setBlock(i + 10, j + 25, k + 3, PlaceDeepslate, 0, 2);
		world.setBlock(i + 11, j + 25, k + 3, PlaceDeepslate, 0, 2);
		world.setBlock(i + 12, j + 25, k + 3, PlaceDeepslate, 0, 2);
		world.setBlock(i + 13, j + 25, k + 3, PlaceDeepslate, 0, 2);
		world.setBlock(i + 14, j + 25, k + 3, PlaceDeepslate, 0, 2);
		world.setBlock(i + 15, j + 25, k + 3, PlaceDeepslate, 0, 2);
		world.setBlock(i + 16, j + 25, k + 3, PlaceDeepslate, 0, 2);
		world.setBlock(i + 17, j + 25, k + 3, PlaceDeepslate, 0, 2);
		world.setBlock(i + 18, j + 25, k + 3, PlaceDeepslate, 0, 2);
		world.setBlock(i + 5, j + 25, k + 4, PlaceDeepslate, 0, 2);
		world.setBlock(i + 6, j + 25, k + 4, PlaceDeepslate, 0, 2);
		world.setBlock(i + 7, j + 25, k + 4, PlaceDeepslate, 0, 2);
		world.setBlock(i + 8, j + 25, k + 4, PlaceDeepslate, 0, 2);
		world.setBlock(i + 9, j + 25, k + 4, PlaceDeepslate, 0, 2);
		world.setBlock(i + 10, j + 25, k + 4, PlaceDeepslate, 0, 2);
		world.setBlock(i + 11, j + 25, k + 4, PlaceDeepslate, 0, 2);
		world.setBlock(i + 12, j + 25, k + 4, PlaceDeepslate, 0, 2);
		world.setBlock(i + 13, j + 25, k + 4, PlaceDeepslate, 0, 2);
		world.setBlock(i + 14, j + 25, k + 4, PlaceDeepslate, 0, 2);
		world.setBlock(i + 15, j + 25, k + 4, PlaceDeepslate, 0, 2);
		world.setBlock(i + 16, j + 25, k + 4, PlaceDeepslate, 0, 2);
		world.setBlock(i + 17, j + 25, k + 4, PlaceDeepslate, 0, 2);
		world.setBlock(i + 18, j + 25, k + 4, PlaceDeepslate, 0, 2);
		world.setBlock(i + 5, j + 25, k + 5, PlaceDeepslate, 0, 2);
		world.setBlock(i + 6, j + 25, k + 5, PlaceDeepslate, 0, 2);
		world.setBlock(i + 7, j + 25, k + 5, PlaceDeepslate, 0, 2);
		world.setBlock(i + 8, j + 25, k + 5, PlaceDeepslate, 0, 2);
		world.setBlock(i + 9, j + 25, k + 5, PlaceDeepslate, 0, 2);
		world.setBlock(i + 10, j + 25, k + 5, PlaceDeepslate, 0, 2);
		world.setBlock(i + 11, j + 25, k + 5, PlaceDeepslate, 0, 2);
		world.setBlock(i + 12, j + 25, k + 5, PlaceDeepslate, 0, 2);
		world.setBlock(i + 13, j + 25, k + 5, PlaceDeepslate, 0, 2);
		world.setBlock(i + 14, j + 25, k + 5, PlaceDeepslate, 0, 2);
		world.setBlock(i + 15, j + 25, k + 5, PlaceDeepslate, 0, 2);
		world.setBlock(i + 16, j + 25, k + 5, PlaceDeepslate, 0, 2);
		world.setBlock(i + 17, j + 25, k + 5, PlaceDeepslate, 0, 2);
		world.setBlock(i + 18, j + 25, k + 5, PlaceDeepslate, 0, 2);
		world.setBlock(i + 4, j + 25, k + 6, PlaceDeepslate, 0, 2);
		world.setBlock(i + 5, j + 25, k + 6, PlaceDeepslate, 0, 2);
		world.setBlock(i + 6, j + 25, k + 6, PlaceDeepslate, 0, 2);
		world.setBlock(i + 7, j + 25, k + 6, PlaceDeepslate, 0, 2);
		world.setBlock(i + 8, j + 25, k + 6, PlaceDeepslate, 0, 2);
		world.setBlock(i + 9, j + 25, k + 6, PlaceDeepslate, 0, 2);
		world.setBlock(i + 10, j + 25, k + 6, PlaceDeepslate, 0, 2);
		world.setBlock(i + 11, j + 25, k + 6, PlaceDeepslate, 0, 2);
		world.setBlock(i + 12, j + 25, k + 6, PlaceDeepslate, 0, 2);
		world.setBlock(i + 13, j + 25, k + 6, PlaceDeepslate, 0, 2);
		world.setBlock(i + 14, j + 25, k + 6, PlaceDeepslate, 0, 2);
		world.setBlock(i + 15, j + 25, k + 6, PlaceDeepslate, 0, 2);
		world.setBlock(i + 16, j + 25, k + 6, PlaceDeepslate, 0, 2);
		world.setBlock(i + 17, j + 25, k + 6, PlaceDeepslate, 0, 2);
		world.setBlock(i + 18, j + 25, k + 6, PlaceDeepslate, 0, 2);
		world.setBlock(i + 3, j + 25, k + 7, PlaceDeepslate, 0, 2);
		world.setBlock(i + 4, j + 25, k + 7, PlaceDeepslate, 0, 2);
		world.setBlock(i + 5, j + 25, k + 7, sculk_block, 0, 2);
		world.setBlock(i + 6, j + 25, k + 7, sculk_block, 0, 2);
		world.setBlock(i + 7, j + 25, k + 7, PlaceDeepslate, 0, 2);
		world.setBlock(i + 8, j + 25, k + 7, PlaceDeepslate, 0, 2);
		world.setBlock(i + 9, j + 25, k + 7, PlaceDeepslate, 0, 2);
		world.setBlock(i + 10, j + 25, k + 7, PlaceDeepslate, 0, 2);
		world.setBlock(i + 11, j + 25, k + 7, PlaceDeepslate, 0, 2);
		world.setBlock(i + 12, j + 25, k + 7, PlaceDeepslate, 0, 2);
		world.setBlock(i + 13, j + 25, k + 7, PlaceDeepslate, 0, 2);
		world.setBlock(i + 14, j + 25, k + 7, PlaceDeepslate, 0, 2);
		world.setBlock(i + 15, j + 25, k + 7, PlaceDeepslate, 0, 2);
		world.setBlock(i + 16, j + 25, k + 7, PlaceDeepslate, 0, 2);
		world.setBlock(i + 17, j + 25, k + 7, PlaceDeepslate, 0, 2);
		world.setBlock(i + 18, j + 25, k + 7, PlaceDeepslate, 0, 2);
		world.setBlock(i + 2, j + 25, k + 8, PlaceDeepslate, 0, 2);
		world.setBlock(i + 3, j + 25, k + 8, PlaceDeepslate, 0, 2);
		world.setBlock(i + 4, j + 25, k + 8, PlaceDeepslate, 0, 2);
		world.setBlock(i + 5, j + 25, k + 8, sculk_block, 0, 2);
		world.setBlock(i + 6, j + 25, k + 8, sculk_block, 0, 2);
		world.setBlock(i + 7, j + 25, k + 8, PlaceDeepslate, 0, 2);
		world.setBlock(i + 8, j + 25, k + 8, PlaceDeepslate, 0, 2);
		world.setBlock(i + 9, j + 25, k + 8, PlaceDeepslate, 0, 2);
		world.setBlock(i + 10, j + 25, k + 8, PlaceDeepslate, 0, 2);
		world.setBlock(i + 11, j + 25, k + 8, PlaceDeepslate, 0, 2);
		world.setBlock(i + 12, j + 25, k + 8, PlaceDeepslate, 0, 2);
		world.setBlock(i + 13, j + 25, k + 8, PlaceDeepslate, 0, 2);
		world.setBlock(i + 14, j + 25, k + 8, PlaceDeepslate, 0, 2);
		world.setBlock(i + 15, j + 25, k + 8, PlaceDeepslate, 0, 2);
		world.setBlock(i + 16, j + 25, k + 8, PlaceDeepslate, 0, 2);
		world.setBlock(i + 17, j + 25, k + 8, PlaceDeepslate, 0, 2);
		world.setBlock(i + 18, j + 25, k + 8, PlaceDeepslate, 0, 2);
		world.setBlock(i + 19, j + 25, k + 8, PlaceDeepslate, 0, 2);
		world.setBlock(i + 2, j + 25, k + 9, sculk_block, 0, 2);
		world.setBlock(i + 3, j + 25, k + 9, sculk_block, 0, 2);
		world.setBlock(i + 4, j + 25, k + 9, sculk_block, 0, 2);
		world.setBlock(i + 5, j + 25, k + 9, sculk_block, 0, 2);
		world.setBlock(i + 6, j + 25, k + 9, sculk_block, 0, 2);
		world.setBlock(i + 7, j + 25, k + 9, PlaceDeepslate, 0, 2);
		world.setBlock(i + 8, j + 25, k + 9, PlaceDeepslate, 0, 2);
		world.setBlock(i + 9, j + 25, k + 9, PlaceDeepslate, 0, 2);
		world.setBlock(i + 10, j + 25, k + 9, PlaceDeepslate, 0, 2);
		world.setBlock(i + 11, j + 25, k + 9, PlaceDeepslate, 0, 2);
		world.setBlock(i + 12, j + 25, k + 9, PlaceDeepslate, 0, 2);
		world.setBlock(i + 13, j + 25, k + 9, PlaceDeepslate, 0, 2);
		world.setBlock(i + 14, j + 25, k + 9, PlaceDeepslate, 0, 2);
		world.setBlock(i + 15, j + 25, k + 9, PlaceDeepslate, 0, 2);
		world.setBlock(i + 16, j + 25, k + 9, PlaceDeepslate, 0, 2);
		world.setBlock(i + 17, j + 25, k + 9, PlaceDeepslate, 0, 2);
		world.setBlock(i + 18, j + 25, k + 9, PlaceDeepslate, 0, 2);
		world.setBlock(i + 19, j + 25, k + 9, PlaceDeepslate, 0, 2);
		world.setBlock(i + 20, j + 25, k + 9, PlaceDeepslate, 0, 2);
		world.setBlock(i + 2, j + 25, k + 10, sculk_block, 0, 2);
		world.setBlock(i + 3, j + 25, k + 10, sculk_block, 0, 2);
		world.setBlock(i + 4, j + 25, k + 10, PlaceDeepslate, 0, 2);
		world.setBlock(i + 5, j + 25, k + 10, sculk_block, 0, 2);
		world.setBlock(i + 6, j + 25, k + 10, sculk_block, 0, 2);
		world.setBlock(i + 7, j + 25, k + 10, PlaceDeepslate, 0, 2);
		world.setBlock(i + 8, j + 25, k + 10, PlaceDeepslate, 0, 2);
		world.setBlock(i + 9, j + 25, k + 10, PlaceDeepslate, 0, 2);
		world.setBlock(i + 10, j + 25, k + 10, PlaceDeepslate, 0, 2);
		world.setBlock(i + 11, j + 25, k + 10, PlaceDeepslate, 0, 2);
		world.setBlock(i + 12, j + 25, k + 10, PlaceDeepslate, 0, 2);
		world.setBlock(i + 13, j + 25, k + 10, PlaceDeepslate, 0, 2);
		world.setBlock(i + 14, j + 25, k + 10, PlaceDeepslate, 0, 2);
		world.setBlock(i + 15, j + 25, k + 10, PlaceDeepslate, 0, 2);
		world.setBlock(i + 16, j + 25, k + 10, PlaceDeepslate, 0, 2);
		world.setBlock(i + 17, j + 25, k + 10, PlaceDeepslate, 0, 2);
		world.setBlock(i + 18, j + 25, k + 10, PlaceDeepslate, 0, 2);
		world.setBlock(i + 19, j + 25, k + 10, PlaceDeepslate, 0, 2);
		world.setBlock(i + 20, j + 25, k + 10, PlaceDeepslate, 0, 2);
		world.setBlock(i + 21, j + 25, k + 10, PlaceDeepslate, 0, 2);
		world.setBlock(i + 2, j + 25, k + 11, sculk_block, 0, 2);
		world.setBlock(i + 3, j + 25, k + 11, PlaceDeepslate, 0, 2);
		world.setBlock(i + 4, j + 25, k + 11, PlaceDeepslate, 0, 2);
		world.setBlock(i + 5, j + 25, k + 11, sculk_block, 0, 2);
		world.setBlock(i + 6, j + 25, k + 11, sculk_block, 0, 2);
		world.setBlock(i + 7, j + 25, k + 11, sculk_block, 0, 2);
		world.setBlock(i + 8, j + 25, k + 11, PlaceDeepslate, 0, 2);
		world.setBlock(i + 9, j + 25, k + 11, PlaceDeepslate, 0, 2);
		world.setBlock(i + 10, j + 25, k + 11, PlaceDeepslate, 0, 2);
		world.setBlock(i + 11, j + 25, k + 11, PlaceDeepslate, 0, 2);
		world.setBlock(i + 12, j + 25, k + 11, PlaceDeepslate, 0, 2);
		world.setBlock(i + 13, j + 25, k + 11, PlaceDeepslate, 0, 2);
		world.setBlock(i + 14, j + 25, k + 11, PlaceDeepslate, 0, 2);
		world.setBlock(i + 15, j + 25, k + 11, PlaceDeepslate, 0, 2);
		world.setBlock(i + 16, j + 25, k + 11, PlaceDeepslate, 0, 2);
		world.setBlock(i + 17, j + 25, k + 11, PlaceDeepslate, 0, 2);
		world.setBlock(i + 18, j + 25, k + 11, PlaceDeepslate, 0, 2);
		world.setBlock(i + 19, j + 25, k + 11, PlaceDeepslate, 0, 2);
		world.setBlock(i + 20, j + 25, k + 11, PlaceDeepslate, 0, 2);
		world.setBlock(i + 21, j + 25, k + 11, PlaceDeepslate, 0, 2);
		world.setBlock(i + 2, j + 25, k + 12, PlaceDeepslate, 0, 2);
		world.setBlock(i + 3, j + 25, k + 12, PlaceDeepslate, 0, 2);
		world.setBlock(i + 4, j + 25, k + 12, PlaceDeepslate, 0, 2);
		world.setBlock(i + 5, j + 25, k + 12, sculk_block, 0, 2);
		world.setBlock(i + 6, j + 25, k + 12, sculk_block, 0, 2);
		world.setBlock(i + 7, j + 25, k + 12, sculk_block, 0, 2);
		world.setBlock(i + 8, j + 25, k + 12, PlaceDeepslate, 0, 2);
		world.setBlock(i + 9, j + 25, k + 12, PlaceDeepslate, 0, 2);
		world.setBlock(i + 10, j + 25, k + 12, PlaceDeepslate, 0, 2);
		world.setBlock(i + 11, j + 25, k + 12, PlaceDeepslate, 0, 2);
		world.setBlock(i + 12, j + 25, k + 12, PlaceDeepslate, 0, 2);
		world.setBlock(i + 13, j + 25, k + 12, PlaceDeepslate, 0, 2);
		world.setBlock(i + 14, j + 25, k + 12, PlaceDeepslate, 0, 2);
		world.setBlock(i + 15, j + 25, k + 12, PlaceDeepslate, 0, 2);
		world.setBlock(i + 16, j + 25, k + 12, PlaceDeepslate, 0, 2);
		world.setBlock(i + 17, j + 25, k + 12, PlaceDeepslate, 0, 2);
		world.setBlock(i + 18, j + 25, k + 12, PlaceDeepslate, 0, 2);
		world.setBlock(i + 19, j + 25, k + 12, PlaceDeepslate, 0, 2);
		world.setBlock(i + 20, j + 25, k + 12, PlaceDeepslate, 0, 2);
		world.setBlock(i + 21, j + 25, k + 12, PlaceDeepslate, 0, 2);
		world.setBlock(i + 2, j + 25, k + 13, PlaceDeepslate, 0, 2);
		world.setBlock(i + 3, j + 25, k + 13, PlaceDeepslate, 0, 2);
		world.setBlock(i + 4, j + 25, k + 13, PlaceDeepslate, 0, 2);
		world.setBlock(i + 5, j + 25, k + 13, sculk_block, 0, 2);
		world.setBlock(i + 6, j + 25, k + 13, sculk_block, 0, 2);
		world.setBlock(i + 7, j + 25, k + 13, sculk_block, 0, 2);
		world.setBlock(i + 8, j + 25, k + 13, PlaceDeepslate, 0, 2);
		world.setBlock(i + 9, j + 25, k + 13, PlaceDeepslate, 0, 2);
		world.setBlock(i + 10, j + 25, k + 13, PlaceDeepslate, 0, 2);
		world.setBlock(i + 11, j + 25, k + 13, PlaceDeepslate, 0, 2);
		world.setBlock(i + 12, j + 25, k + 13, PlaceDeepslate, 0, 2);
		world.setBlock(i + 13, j + 25, k + 13, PlaceDeepslate, 0, 2);
		world.setBlock(i + 14, j + 25, k + 13, PlaceDeepslate, 0, 2);
		world.setBlock(i + 15, j + 25, k + 13, PlaceDeepslate, 0, 2);
		world.setBlock(i + 16, j + 25, k + 13, PlaceDeepslate, 0, 2);
		world.setBlock(i + 17, j + 25, k + 13, PlaceDeepslate, 0, 2);
		world.setBlock(i + 18, j + 25, k + 13, PlaceDeepslate, 0, 2);
		world.setBlock(i + 19, j + 25, k + 13, PlaceDeepslate, 0, 2);
		world.setBlock(i + 20, j + 25, k + 13, PlaceDeepslate, 0, 2);
		world.setBlock(i + 21, j + 25, k + 13, PlaceDeepslate, 0, 2);
		world.setBlock(i + 2, j + 25, k + 14, PlaceDeepslate, 0, 2);
		world.setBlock(i + 3, j + 25, k + 14, PlaceDeepslate, 0, 2);
		world.setBlock(i + 4, j + 25, k + 14, PlaceDeepslate, 0, 2);
		world.setBlock(i + 5, j + 25, k + 14, PlaceDeepslate, 0, 2);
		world.setBlock(i + 6, j + 25, k + 14, PlaceDeepslate, 0, 2);
		world.setBlock(i + 7, j + 25, k + 14, sculk_block, 0, 2);
		world.setBlock(i + 8, j + 25, k + 14, PlaceDeepslate, 0, 2);
		world.setBlock(i + 9, j + 25, k + 14, PlaceDeepslate, 0, 2);
		world.setBlock(i + 10, j + 25, k + 14, PlaceDeepslate, 0, 2);
		world.setBlock(i + 11, j + 25, k + 14, PlaceDeepslate, 0, 2);
		world.setBlock(i + 12, j + 25, k + 14, PlaceDeepslate, 0, 2);
		world.setBlock(i + 13, j + 25, k + 14, PlaceDeepslate, 0, 2);
		world.setBlock(i + 14, j + 25, k + 14, PlaceDeepslate, 0, 2);
		world.setBlock(i + 15, j + 25, k + 14, PlaceDeepslate, 0, 2);
		world.setBlock(i + 16, j + 25, k + 14, PlaceDeepslate, 0, 2);
		world.setBlock(i + 17, j + 25, k + 14, PlaceDeepslate, 0, 2);
		world.setBlock(i + 18, j + 25, k + 14, PlaceDeepslate, 0, 2);
		world.setBlock(i + 19, j + 25, k + 14, PlaceDeepslate, 0, 2);
		world.setBlock(i + 20, j + 25, k + 14, PlaceDeepslate, 0, 2);
		world.setBlock(i + 21, j + 25, k + 14, PlaceDeepslate, 0, 2);
		world.setBlock(i + 2, j + 25, k + 15, PlaceDeepslate, 0, 2);
		world.setBlock(i + 3, j + 25, k + 15, PlaceDeepslate, 0, 2);
		world.setBlock(i + 4, j + 25, k + 15, PlaceDeepslate, 0, 2);
		world.setBlock(i + 5, j + 25, k + 15, sculk_block, 0, 2);
		world.setBlock(i + 6, j + 25, k + 15, sculk_block, 0, 2);
		world.setBlock(i + 7, j + 25, k + 15, sculk_block, 0, 2);
		world.setBlock(i + 8, j + 25, k + 15, PlaceDeepslate, 0, 2);
		world.setBlock(i + 9, j + 25, k + 15, PlaceDeepslate, 0, 2);
		world.setBlock(i + 10, j + 25, k + 15, PlaceDeepslate, 0, 2);
		world.setBlock(i + 11, j + 25, k + 15, PlaceDeepslate, 0, 2);
		world.setBlock(i + 12, j + 25, k + 15, PlaceDeepslate, 0, 2);
		world.setBlock(i + 13, j + 25, k + 15, PlaceDeepslate, 0, 2);
		world.setBlock(i + 14, j + 25, k + 15, PlaceDeepslate, 0, 2);
		world.setBlock(i + 15, j + 25, k + 15, PlaceDeepslate, 0, 2);
		world.setBlock(i + 16, j + 25, k + 15, PlaceDeepslate, 0, 2);
		world.setBlock(i + 17, j + 25, k + 15, PlaceDeepslate, 0, 2);
		world.setBlock(i + 18, j + 25, k + 15, PlaceDeepslate, 0, 2);
		world.setBlock(i + 19, j + 25, k + 15, PlaceDeepslate, 0, 2);
		world.setBlock(i + 20, j + 25, k + 15, PlaceDeepslate, 0, 2);
		world.setBlock(i + 21, j + 25, k + 15, PlaceDeepslate, 0, 2);
		world.setBlock(i + 4, j + 25, k + 16, sculk_block, 0, 2);
		world.setBlock(i + 8, j + 25, k + 16, sculk_block, 0, 2);
		world.setBlock(i + 9, j + 25, k + 16, sculk_block, 0, 2);
		world.setBlock(i + 10, j + 25, k + 16, sculk_block, 0, 2);
		world.setBlock(i + 11, j + 25, k + 16, sculk_block, 0, 2);
		world.setBlock(i + 12, j + 25, k + 16, sculk_block, 0, 2);
		world.setBlock(i + 13, j + 25, k + 16, sculk_block, 0, 2);
		world.setBlock(i + 14, j + 25, k + 16, sculk_block, 0, 2);
		world.setBlock(i + 15, j + 25, k + 16, sculk_block, 0, 2);
		world.setBlock(i + 16, j + 25, k + 16, sculk_block, 0, 2);
		world.setBlock(i + 17, j + 25, k + 16, sculk_block, 0, 2);
		world.setBlock(i + 18, j + 25, k + 16, sculk_block, 0, 2);
		world.setBlock(i + 19, j + 25, k + 16, sculk_block, 0, 2);
		world.setBlock(i + 20, j + 25, k + 16, sculk_block, 0, 2);
		world.setBlock(i + 21, j + 25, k + 16, sculk_block, 0, 2);
		world.setBlock(i + 6, j + 26, k + 0, PlaceDeepslate, 0, 2);
		world.setBlock(i + 7, j + 26, k + 0, PlaceDeepslate, 0, 2);
		world.setBlock(i + 8, j + 26, k + 0, PlaceDeepslate, 0, 2);
		world.setBlock(i + 9, j + 26, k + 0, PlaceDeepslate, 0, 2);
		world.setBlock(i + 10, j + 26, k + 0, PlaceDeepslate, 0, 2);
		world.setBlock(i + 11, j + 26, k + 0, PlaceDeepslate, 0, 2);
		world.setBlock(i + 12, j + 26, k + 0, PlaceDeepslate, 0, 2);
		world.setBlock(i + 13, j + 26, k + 0, PlaceDeepslate, 0, 2);
		world.setBlock(i + 14, j + 26, k + 0, PlaceDeepslate, 0, 2);
		world.setBlock(i + 15, j + 26, k + 0, PlaceDeepslate, 0, 2);
		world.setBlock(i + 16, j + 26, k + 0, PlaceDeepslate, 0, 2);
		world.setBlock(i + 17, j + 26, k + 0, PlaceDeepslate, 0, 2);
		world.setBlock(i + 6, j + 26, k + 1, PlaceDeepslate, 0, 2);
		world.setBlock(i + 7, j + 26, k + 1, PlaceDeepslate, 0, 2);
		world.setBlock(i + 8, j + 26, k + 1, PlaceDeepslate, 0, 2);
		world.setBlock(i + 9, j + 26, k + 1, PlaceDeepslate, 0, 2);
		world.setBlock(i + 10, j + 26, k + 1, PlaceDeepslate, 0, 2);
		world.setBlock(i + 11, j + 26, k + 1, PlaceDeepslate, 0, 2);
		world.setBlock(i + 12, j + 26, k + 1, PlaceDeepslate, 0, 2);
		world.setBlock(i + 13, j + 26, k + 1, PlaceDeepslate, 0, 2);
		world.setBlock(i + 14, j + 26, k + 1, PlaceDeepslate, 0, 2);
		world.setBlock(i + 15, j + 26, k + 1, PlaceDeepslate, 0, 2);
		world.setBlock(i + 16, j + 26, k + 1, PlaceDeepslate, 0, 2);
		world.setBlock(i + 17, j + 26, k + 1, PlaceDeepslate, 0, 2);
		world.setBlock(i + 5, j + 26, k + 2, PlaceDeepslate, 0, 2);
		world.setBlock(i + 6, j + 26, k + 2, PlaceDeepslate, 0, 2);
		world.setBlock(i + 7, j + 26, k + 2, PlaceDeepslate, 0, 2);
		world.setBlock(i + 8, j + 26, k + 2, PlaceDeepslate, 0, 2);
		world.setBlock(i + 9, j + 26, k + 2, PlaceDeepslate, 0, 2);
		world.setBlock(i + 10, j + 26, k + 2, PlaceDeepslate, 0, 2);
		world.setBlock(i + 11, j + 26, k + 2, PlaceDeepslate, 0, 2);
		world.setBlock(i + 12, j + 26, k + 2, PlaceDeepslate, 0, 2);
		world.setBlock(i + 13, j + 26, k + 2, PlaceDeepslate, 0, 2);
		world.setBlock(i + 14, j + 26, k + 2, PlaceDeepslate, 0, 2);
		world.setBlock(i + 15, j + 26, k + 2, PlaceDeepslate, 0, 2);
		world.setBlock(i + 16, j + 26, k + 2, PlaceDeepslate, 0, 2);
		world.setBlock(i + 17, j + 26, k + 2, PlaceDeepslate, 0, 2);
		world.setBlock(i + 18, j + 26, k + 2, PlaceDeepslate, 0, 2);
		world.setBlock(i + 4, j + 26, k + 3, PlaceDeepslate, 0, 2);
		world.setBlock(i + 5, j + 26, k + 3, PlaceDeepslate, 0, 2);
		world.setBlock(i + 6, j + 26, k + 3, PlaceDeepslate, 0, 2);
		world.setBlock(i + 7, j + 26, k + 3, PlaceDeepslate, 0, 2);
		world.setBlock(i + 8, j + 26, k + 3, PlaceDeepslate, 0, 2);
		world.setBlock(i + 9, j + 26, k + 3, PlaceDeepslate, 0, 2);
		world.setBlock(i + 10, j + 26, k + 3, PlaceDeepslate, 0, 2);
		world.setBlock(i + 11, j + 26, k + 3, PlaceDeepslate, 0, 2);
		world.setBlock(i + 12, j + 26, k + 3, PlaceDeepslate, 0, 2);
		world.setBlock(i + 13, j + 26, k + 3, PlaceDeepslate, 0, 2);
		world.setBlock(i + 14, j + 26, k + 3, PlaceDeepslate, 0, 2);
		world.setBlock(i + 15, j + 26, k + 3, PlaceDeepslate, 0, 2);
		world.setBlock(i + 16, j + 26, k + 3, PlaceDeepslate, 0, 2);
		world.setBlock(i + 17, j + 26, k + 3, PlaceDeepslate, 0, 2);
		world.setBlock(i + 18, j + 26, k + 3, PlaceDeepslate, 0, 2);
		world.setBlock(i + 4, j + 26, k + 4, PlaceDeepslate, 0, 2);
		world.setBlock(i + 5, j + 26, k + 4, PlaceDeepslate, 0, 2);
		world.setBlock(i + 6, j + 26, k + 4, PlaceDeepslate, 0, 2);
		world.setBlock(i + 7, j + 26, k + 4, PlaceDeepslate, 0, 2);
		world.setBlock(i + 8, j + 26, k + 4, PlaceDeepslate, 0, 2);
		world.setBlock(i + 9, j + 26, k + 4, PlaceDeepslate, 0, 2);
		world.setBlock(i + 10, j + 26, k + 4, PlaceDeepslate, 0, 2);
		world.setBlock(i + 11, j + 26, k + 4, PlaceDeepslate, 0, 2);
		world.setBlock(i + 12, j + 26, k + 4, PlaceDeepslate, 0, 2);
		world.setBlock(i + 13, j + 26, k + 4, PlaceDeepslate, 0, 2);
		world.setBlock(i + 14, j + 26, k + 4, PlaceDeepslate, 0, 2);
		world.setBlock(i + 15, j + 26, k + 4, PlaceDeepslate, 0, 2);
		world.setBlock(i + 16, j + 26, k + 4, PlaceDeepslate, 0, 2);
		world.setBlock(i + 17, j + 26, k + 4, PlaceDeepslate, 0, 2);
		world.setBlock(i + 18, j + 26, k + 4, PlaceDeepslate, 0, 2);
		world.setBlock(i + 3, j + 26, k + 5, PlaceDeepslate, 0, 2);
		world.setBlock(i + 4, j + 26, k + 5, PlaceDeepslate, 0, 2);
		world.setBlock(i + 5, j + 26, k + 5, PlaceDeepslate, 0, 2);
		world.setBlock(i + 6, j + 26, k + 5, PlaceDeepslate, 0, 2);
		world.setBlock(i + 7, j + 26, k + 5, PlaceDeepslate, 0, 2);
		world.setBlock(i + 8, j + 26, k + 5, PlaceDeepslate, 0, 2);
		world.setBlock(i + 9, j + 26, k + 5, PlaceDeepslate, 0, 2);
		world.setBlock(i + 10, j + 26, k + 5, PlaceDeepslate, 0, 2);
		world.setBlock(i + 11, j + 26, k + 5, PlaceDeepslate, 0, 2);
		world.setBlock(i + 12, j + 26, k + 5, PlaceDeepslate, 0, 2);
		world.setBlock(i + 13, j + 26, k + 5, PlaceDeepslate, 0, 2);
		world.setBlock(i + 14, j + 26, k + 5, PlaceDeepslate, 0, 2);
		world.setBlock(i + 15, j + 26, k + 5, PlaceDeepslate, 0, 2);
		world.setBlock(i + 16, j + 26, k + 5, PlaceDeepslate, 0, 2);
		world.setBlock(i + 17, j + 26, k + 5, PlaceDeepslate, 0, 2);
		world.setBlock(i + 18, j + 26, k + 5, PlaceDeepslate, 0, 2);
		world.setBlock(i + 2, j + 26, k + 6, PlaceDeepslate, 0, 2);
		world.setBlock(i + 3, j + 26, k + 6, PlaceDeepslate, 0, 2);
		world.setBlock(i + 4, j + 26, k + 6, PlaceDeepslate, 0, 2);
		world.setBlock(i + 5, j + 26, k + 6, PlaceDeepslate, 0, 2);
		world.setBlock(i + 6, j + 26, k + 6, PlaceDeepslate, 0, 2);
		world.setBlock(i + 7, j + 26, k + 6, PlaceDeepslate, 0, 2);
		world.setBlock(i + 8, j + 26, k + 6, PlaceDeepslate, 0, 2);
		world.setBlock(i + 9, j + 26, k + 6, PlaceDeepslate, 0, 2);
		world.setBlock(i + 10, j + 26, k + 6, PlaceDeepslate, 0, 2);
		world.setBlock(i + 11, j + 26, k + 6, PlaceDeepslate, 0, 2);
		world.setBlock(i + 12, j + 26, k + 6, PlaceDeepslate, 0, 2);
		world.setBlock(i + 13, j + 26, k + 6, PlaceDeepslate, 0, 2);
		world.setBlock(i + 14, j + 26, k + 6, PlaceDeepslate, 0, 2);
		world.setBlock(i + 15, j + 26, k + 6, PlaceDeepslate, 0, 2);
		world.setBlock(i + 16, j + 26, k + 6, PlaceDeepslate, 0, 2);
		world.setBlock(i + 17, j + 26, k + 6, PlaceDeepslate, 0, 2);
		world.setBlock(i + 18, j + 26, k + 6, PlaceDeepslate, 0, 2);
		world.setBlock(i + 2, j + 26, k + 7, PlaceDeepslate, 0, 2);
		world.setBlock(i + 3, j + 26, k + 7, PlaceDeepslate, 0, 2);
		world.setBlock(i + 4, j + 26, k + 7, PlaceDeepslate, 0, 2);
		world.setBlock(i + 5, j + 26, k + 7, PlaceDeepslate, 0, 2);
		world.setBlock(i + 6, j + 26, k + 7, PlaceDeepslate, 0, 2);
		world.setBlock(i + 7, j + 26, k + 7, PlaceDeepslate, 0, 2);
		world.setBlock(i + 8, j + 26, k + 7, PlaceDeepslate, 0, 2);
		world.setBlock(i + 9, j + 26, k + 7, PlaceDeepslate, 0, 2);
		world.setBlock(i + 10, j + 26, k + 7, PlaceDeepslate, 0, 2);
		world.setBlock(i + 11, j + 26, k + 7, PlaceDeepslate, 0, 2);
		world.setBlock(i + 12, j + 26, k + 7, PlaceDeepslate, 0, 2);
		world.setBlock(i + 13, j + 26, k + 7, PlaceDeepslate, 0, 2);
		world.setBlock(i + 14, j + 26, k + 7, PlaceDeepslate, 0, 2);
		world.setBlock(i + 15, j + 26, k + 7, PlaceDeepslate, 0, 2);
		world.setBlock(i + 16, j + 26, k + 7, PlaceDeepslate, 0, 2);
		world.setBlock(i + 17, j + 26, k + 7, PlaceDeepslate, 0, 2);
		world.setBlock(i + 18, j + 26, k + 7, PlaceDeepslate, 0, 2);
		world.setBlock(i + 1, j + 26, k + 8, PlaceDeepslate, 0, 2);
		world.setBlock(i + 2, j + 26, k + 8, PlaceDeepslate, 0, 2);
		world.setBlock(i + 3, j + 26, k + 8, PlaceDeepslate, 0, 2);
		world.setBlock(i + 4, j + 26, k + 8, PlaceDeepslate, 0, 2);
		world.setBlock(i + 5, j + 26, k + 8, PlaceDeepslate, 0, 2);
		world.setBlock(i + 6, j + 26, k + 8, PlaceDeepslate, 0, 2);
		world.setBlock(i + 7, j + 26, k + 8, PlaceDeepslate, 0, 2);
		world.setBlock(i + 8, j + 26, k + 8, PlaceDeepslate, 0, 2);
		world.setBlock(i + 9, j + 26, k + 8, PlaceDeepslate, 0, 2);
		world.setBlock(i + 10, j + 26, k + 8, PlaceDeepslate, 0, 2);
		world.setBlock(i + 11, j + 26, k + 8, PlaceDeepslate, 0, 2);
		world.setBlock(i + 12, j + 26, k + 8, PlaceDeepslate, 0, 2);
		world.setBlock(i + 13, j + 26, k + 8, PlaceDeepslate, 0, 2);
		world.setBlock(i + 14, j + 26, k + 8, PlaceDeepslate, 0, 2);
		world.setBlock(i + 15, j + 26, k + 8, PlaceDeepslate, 0, 2);
		world.setBlock(i + 16, j + 26, k + 8, PlaceDeepslate, 0, 2);
		world.setBlock(i + 17, j + 26, k + 8, PlaceDeepslate, 0, 2);
		world.setBlock(i + 18, j + 26, k + 8, PlaceDeepslate, 0, 2);
		world.setBlock(i + 19, j + 26, k + 8, PlaceDeepslate, 0, 2);
		world.setBlock(i + 1, j + 26, k + 9, PlaceDeepslate, 0, 2);
		world.setBlock(i + 2, j + 26, k + 9, PlaceDeepslate, 0, 2);
		world.setBlock(i + 3, j + 26, k + 9, PlaceDeepslate, 0, 2);
		world.setBlock(i + 4, j + 26, k + 9, PlaceDeepslate, 0, 2);
		world.setBlock(i + 5, j + 26, k + 9, PlaceDeepslate, 0, 2);
		world.setBlock(i + 6, j + 26, k + 9, PlaceDeepslate, 0, 2);
		world.setBlock(i + 7, j + 26, k + 9, PlaceDeepslate, 0, 2);
		world.setBlock(i + 8, j + 26, k + 9, PlaceDeepslate, 0, 2);
		world.setBlock(i + 9, j + 26, k + 9, PlaceDeepslate, 0, 2);
		world.setBlock(i + 10, j + 26, k + 9, PlaceDeepslate, 0, 2);
		world.setBlock(i + 11, j + 26, k + 9, PlaceDeepslate, 0, 2);
		world.setBlock(i + 12, j + 26, k + 9, PlaceDeepslate, 0, 2);
		world.setBlock(i + 13, j + 26, k + 9, PlaceDeepslate, 0, 2);
		world.setBlock(i + 14, j + 26, k + 9, PlaceDeepslate, 0, 2);
		world.setBlock(i + 15, j + 26, k + 9, PlaceDeepslate, 0, 2);
		world.setBlock(i + 16, j + 26, k + 9, PlaceDeepslate, 0, 2);
		world.setBlock(i + 17, j + 26, k + 9, PlaceDeepslate, 0, 2);
		world.setBlock(i + 18, j + 26, k + 9, PlaceDeepslate, 0, 2);
		world.setBlock(i + 19, j + 26, k + 9, PlaceDeepslate, 0, 2);
		world.setBlock(i + 20, j + 26, k + 9, PlaceDeepslate, 0, 2);
		world.setBlock(i + 1, j + 26, k + 10, PlaceDeepslate, 0, 2);
		world.setBlock(i + 2, j + 26, k + 10, PlaceDeepslate, 0, 2);
		world.setBlock(i + 3, j + 26, k + 10, PlaceDeepslate, 0, 2);
		world.setBlock(i + 4, j + 26, k + 10, PlaceDeepslate, 0, 2);
		world.setBlock(i + 5, j + 26, k + 10, PlaceDeepslate, 0, 2);
		world.setBlock(i + 6, j + 26, k + 10, PlaceDeepslate, 0, 2);
		world.setBlock(i + 7, j + 26, k + 10, PlaceDeepslate, 0, 2);
		world.setBlock(i + 8, j + 26, k + 10, PlaceDeepslate, 0, 2);
		world.setBlock(i + 9, j + 26, k + 10, PlaceDeepslate, 0, 2);
		world.setBlock(i + 10, j + 26, k + 10, PlaceDeepslate, 0, 2);
		world.setBlock(i + 11, j + 26, k + 10, PlaceDeepslate, 0, 2);
		world.setBlock(i + 12, j + 26, k + 10, PlaceDeepslate, 0, 2);
		world.setBlock(i + 13, j + 26, k + 10, PlaceDeepslate, 0, 2);
		world.setBlock(i + 14, j + 26, k + 10, PlaceDeepslate, 0, 2);
		world.setBlock(i + 15, j + 26, k + 10, PlaceDeepslate, 0, 2);
		world.setBlock(i + 16, j + 26, k + 10, PlaceDeepslate, 0, 2);
		world.setBlock(i + 17, j + 26, k + 10, PlaceDeepslate, 0, 2);
		world.setBlock(i + 18, j + 26, k + 10, PlaceDeepslate, 0, 2);
		world.setBlock(i + 19, j + 26, k + 10, PlaceDeepslate, 0, 2);
		world.setBlock(i + 20, j + 26, k + 10, PlaceDeepslate, 0, 2);
		world.setBlock(i + 21, j + 26, k + 10, PlaceDeepslate, 0, 2);
		world.setBlock(i + 1, j + 26, k + 11, PlaceDeepslate, 0, 2);
		world.setBlock(i + 2, j + 26, k + 11, PlaceDeepslate, 0, 2);
		world.setBlock(i + 3, j + 26, k + 11, PlaceDeepslate, 0, 2);
		world.setBlock(i + 4, j + 26, k + 11, PlaceDeepslate, 0, 2);
		world.setBlock(i + 5, j + 26, k + 11, PlaceDeepslate, 0, 2);
		world.setBlock(i + 6, j + 26, k + 11, PlaceDeepslate, 0, 2);
		world.setBlock(i + 7, j + 26, k + 11, PlaceDeepslate, 0, 2);
		world.setBlock(i + 8, j + 26, k + 11, PlaceDeepslate, 0, 2);
		world.setBlock(i + 9, j + 26, k + 11, PlaceDeepslate, 0, 2);
		world.setBlock(i + 10, j + 26, k + 11, PlaceDeepslate, 0, 2);
		world.setBlock(i + 11, j + 26, k + 11, PlaceDeepslate, 0, 2);
		world.setBlock(i + 12, j + 26, k + 11, PlaceDeepslate, 0, 2);
		world.setBlock(i + 13, j + 26, k + 11, PlaceDeepslate, 0, 2);
		world.setBlock(i + 14, j + 26, k + 11, PlaceDeepslate, 0, 2);
		world.setBlock(i + 15, j + 26, k + 11, PlaceDeepslate, 0, 2);
		world.setBlock(i + 16, j + 26, k + 11, PlaceDeepslate, 0, 2);
		world.setBlock(i + 17, j + 26, k + 11, PlaceDeepslate, 0, 2);
		world.setBlock(i + 18, j + 26, k + 11, PlaceDeepslate, 0, 2);
		world.setBlock(i + 19, j + 26, k + 11, PlaceDeepslate, 0, 2);
		world.setBlock(i + 20, j + 26, k + 11, PlaceDeepslate, 0, 2);
		world.setBlock(i + 21, j + 26, k + 11, PlaceDeepslate, 0, 2);
		world.setBlock(i + 1, j + 26, k + 12, PlaceDeepslate, 0, 2);
		world.setBlock(i + 2, j + 26, k + 12, PlaceDeepslate, 0, 2);
		world.setBlock(i + 3, j + 26, k + 12, PlaceDeepslate, 0, 2);
		world.setBlock(i + 4, j + 26, k + 12, PlaceDeepslate, 0, 2);
		world.setBlock(i + 5, j + 26, k + 12, PlaceDeepslate, 0, 2);
		world.setBlock(i + 6, j + 26, k + 12, PlaceDeepslate, 0, 2);
		world.setBlock(i + 7, j + 26, k + 12, PlaceDeepslate, 0, 2);
		world.setBlock(i + 8, j + 26, k + 12, PlaceDeepslate, 0, 2);
		world.setBlock(i + 9, j + 26, k + 12, PlaceDeepslate, 0, 2);
		world.setBlock(i + 10, j + 26, k + 12, PlaceDeepslate, 0, 2);
		world.setBlock(i + 11, j + 26, k + 12, PlaceDeepslate, 0, 2);
		world.setBlock(i + 12, j + 26, k + 12, PlaceDeepslate, 0, 2);
		world.setBlock(i + 13, j + 26, k + 12, PlaceDeepslate, 0, 2);
		world.setBlock(i + 14, j + 26, k + 12, PlaceDeepslate, 0, 2);
		world.setBlock(i + 15, j + 26, k + 12, PlaceDeepslate, 0, 2);
		world.setBlock(i + 16, j + 26, k + 12, PlaceDeepslate, 0, 2);
		world.setBlock(i + 17, j + 26, k + 12, PlaceDeepslate, 0, 2);
		world.setBlock(i + 18, j + 26, k + 12, PlaceDeepslate, 0, 2);
		world.setBlock(i + 19, j + 26, k + 12, PlaceDeepslate, 0, 2);
		world.setBlock(i + 20, j + 26, k + 12, PlaceDeepslate, 0, 2);
		world.setBlock(i + 21, j + 26, k + 12, PlaceDeepslate, 0, 2);
		world.setBlock(i + 1, j + 26, k + 13, PlaceDeepslate, 0, 2);
		world.setBlock(i + 2, j + 26, k + 13, PlaceDeepslate, 0, 2);
		world.setBlock(i + 3, j + 26, k + 13, PlaceDeepslate, 0, 2);
		world.setBlock(i + 4, j + 26, k + 13, PlaceDeepslate, 0, 2);
		world.setBlock(i + 5, j + 26, k + 13, PlaceDeepslate, 0, 2);
		world.setBlock(i + 6, j + 26, k + 13, PlaceDeepslate, 0, 2);
		world.setBlock(i + 7, j + 26, k + 13, PlaceDeepslate, 0, 2);
		world.setBlock(i + 8, j + 26, k + 13, PlaceDeepslate, 0, 2);
		world.setBlock(i + 9, j + 26, k + 13, PlaceDeepslate, 0, 2);
		world.setBlock(i + 10, j + 26, k + 13, PlaceDeepslate, 0, 2);
		world.setBlock(i + 11, j + 26, k + 13, PlaceDeepslate, 0, 2);
		world.setBlock(i + 12, j + 26, k + 13, PlaceDeepslate, 0, 2);
		world.setBlock(i + 13, j + 26, k + 13, PlaceDeepslate, 0, 2);
		world.setBlock(i + 14, j + 26, k + 13, PlaceDeepslate, 0, 2);
		world.setBlock(i + 15, j + 26, k + 13, PlaceDeepslate, 0, 2);
		world.setBlock(i + 16, j + 26, k + 13, PlaceDeepslate, 0, 2);
		world.setBlock(i + 17, j + 26, k + 13, PlaceDeepslate, 0, 2);
		world.setBlock(i + 18, j + 26, k + 13, PlaceDeepslate, 0, 2);
		world.setBlock(i + 19, j + 26, k + 13, PlaceDeepslate, 0, 2);
		world.setBlock(i + 20, j + 26, k + 13, PlaceDeepslate, 0, 2);
		world.setBlock(i + 21, j + 26, k + 13, PlaceDeepslate, 0, 2);
		world.setBlock(i + 1, j + 26, k + 14, PlaceDeepslate, 0, 2);
		world.setBlock(i + 2, j + 26, k + 14, PlaceDeepslate, 0, 2);
		world.setBlock(i + 3, j + 26, k + 14, PlaceDeepslate, 0, 2);
		world.setBlock(i + 4, j + 26, k + 14, PlaceDeepslate, 0, 2);
		world.setBlock(i + 5, j + 26, k + 14, PlaceDeepslate, 0, 2);
		world.setBlock(i + 6, j + 26, k + 14, PlaceDeepslate, 0, 2);
		world.setBlock(i + 7, j + 26, k + 14, PlaceDeepslate, 0, 2);
		world.setBlock(i + 8, j + 26, k + 14, PlaceDeepslate, 0, 2);
		world.setBlock(i + 9, j + 26, k + 14, PlaceDeepslate, 0, 2);
		world.setBlock(i + 10, j + 26, k + 14, PlaceDeepslate, 0, 2);
		world.setBlock(i + 11, j + 26, k + 14, PlaceDeepslate, 0, 2);
		world.setBlock(i + 12, j + 26, k + 14, PlaceDeepslate, 0, 2);
		world.setBlock(i + 13, j + 26, k + 14, PlaceDeepslate, 0, 2);
		world.setBlock(i + 14, j + 26, k + 14, PlaceDeepslate, 0, 2);
		world.setBlock(i + 15, j + 26, k + 14, PlaceDeepslate, 0, 2);
		world.setBlock(i + 16, j + 26, k + 14, PlaceDeepslate, 0, 2);
		world.setBlock(i + 17, j + 26, k + 14, PlaceDeepslate, 0, 2);
		world.setBlock(i + 18, j + 26, k + 14, PlaceDeepslate, 0, 2);
		world.setBlock(i + 19, j + 26, k + 14, PlaceDeepslate, 0, 2);
		world.setBlock(i + 20, j + 26, k + 14, PlaceDeepslate, 0, 2);
		world.setBlock(i + 21, j + 26, k + 14, PlaceDeepslate, 0, 2);
		world.setBlock(i + 1, j + 26, k + 15, PlaceDeepslate, 0, 2);
		world.setBlock(i + 2, j + 26, k + 15, PlaceDeepslate, 0, 2);
		world.setBlock(i + 3, j + 26, k + 15, PlaceDeepslate, 0, 2);
		world.setBlock(i + 4, j + 26, k + 15, PlaceDeepslate, 0, 2);
		world.setBlock(i + 5, j + 26, k + 15, PlaceDeepslate, 0, 2);
		world.setBlock(i + 6, j + 26, k + 15, PlaceDeepslate, 0, 2);
		world.setBlock(i + 7, j + 26, k + 15, PlaceDeepslate, 0, 2);
		world.setBlock(i + 8, j + 26, k + 15, PlaceDeepslate, 0, 2);
		world.setBlock(i + 9, j + 26, k + 15, PlaceDeepslate, 0, 2);
		world.setBlock(i + 10, j + 26, k + 15, PlaceDeepslate, 0, 2);
		world.setBlock(i + 11, j + 26, k + 15, PlaceDeepslate, 0, 2);
		world.setBlock(i + 12, j + 26, k + 15, PlaceDeepslate, 0, 2);
		world.setBlock(i + 13, j + 26, k + 15, PlaceDeepslate, 0, 2);
		world.setBlock(i + 14, j + 26, k + 15, PlaceDeepslate, 0, 2);
		world.setBlock(i + 15, j + 26, k + 15, PlaceDeepslate, 0, 2);
		world.setBlock(i + 16, j + 26, k + 15, PlaceDeepslate, 0, 2);
		world.setBlock(i + 17, j + 26, k + 15, PlaceDeepslate, 0, 2);
		world.setBlock(i + 18, j + 26, k + 15, PlaceDeepslate, 0, 2);
		world.setBlock(i + 19, j + 26, k + 15, PlaceDeepslate, 0, 2);
		world.setBlock(i + 20, j + 26, k + 15, PlaceDeepslate, 0, 2);
		world.setBlock(i + 21, j + 26, k + 15, PlaceDeepslate, 0, 2);
		world.setBlock(i + 2, j + 26, k + 16, PlaceDeepslate, 0, 2);
		world.setBlock(i + 3, j + 26, k + 16, PlaceDeepslate, 0, 2);
		world.setBlock(i + 4, j + 26, k + 16, PlaceDeepslate, 0, 2);
		world.setBlock(i + 5, j + 26, k + 16, sculk_block, 0, 2);
		world.setBlock(i + 6, j + 26, k + 16, sculk_block, 0, 2);
		world.setBlock(i + 7, j + 26, k + 16, sculk_block, 0, 2);
		world.setBlock(i + 8, j + 26, k + 16, sculk_block, 0, 2);
		world.setBlock(i + 9, j + 26, k + 16, PlaceDeepslate, 0, 2);
		world.setBlock(i + 10, j + 26, k + 16, PlaceDeepslate, 0, 2);
		world.setBlock(i + 11, j + 26, k + 16, PlaceDeepslate, 0, 2);
		world.setBlock(i + 12, j + 26, k + 16, PlaceDeepslate, 0, 2);
		world.setBlock(i + 13, j + 26, k + 16, PlaceDeepslate, 0, 2);
		world.setBlock(i + 14, j + 26, k + 16, PlaceDeepslate, 0, 2);
		world.setBlock(i + 15, j + 26, k + 16, PlaceDeepslate, 0, 2);
		world.setBlock(i + 16, j + 26, k + 16, PlaceDeepslate, 0, 2);
		world.setBlock(i + 17, j + 26, k + 16, PlaceDeepslate, 0, 2);
		world.setBlock(i + 18, j + 26, k + 16, PlaceDeepslate, 0, 2);
		world.setBlock(i + 19, j + 26, k + 16, PlaceDeepslate, 0, 2);
		world.setBlock(i + 20, j + 26, k + 16, sculk_block, 0, 2);
		world.setBlock(i + 21, j + 26, k + 16, sculk_block, 0, 2);
		world.setBlock(i + 4, j + 26, k + 17, sculk_block, 0, 2);
		world.setBlock(i + 9, j + 26, k + 17, sculk_block, 0, 2);
		world.setBlock(i + 10, j + 26, k + 17, sculk_block, 0, 2);
		world.setBlock(i + 11, j + 26, k + 17, sculk_block, 0, 2);
		world.setBlock(i + 12, j + 26, k + 17, sculk_block, 0, 2);
		world.setBlock(i + 13, j + 26, k + 17, sculk_block, 0, 2);
		world.setBlock(i + 14, j + 26, k + 17, sculk_block, 0, 2);
		world.setBlock(i + 15, j + 26, k + 17, sculk_block, 0, 2);
		world.setBlock(i + 16, j + 26, k + 17, sculk_block, 0, 2);
		world.setBlock(i + 17, j + 26, k + 17, sculk_block, 0, 2);
		world.setBlock(i + 18, j + 26, k + 17, sculk_block, 0, 2);
		world.setBlock(i + 19, j + 26, k + 17, sculk_block, 0, 2);
		world.setBlock(i + 5, j + 27, k + 0, PlaceDeepslate, 0, 2);
		world.setBlock(i + 6, j + 27, k + 0, PlaceDeepslate, 0, 2);
		world.setBlock(i + 7, j + 27, k + 0, PlaceDeepslate, 0, 2);
		world.setBlock(i + 8, j + 27, k + 0, PlaceDeepslate, 0, 2);
		world.setBlock(i + 9, j + 27, k + 0, PlaceDeepslate, 0, 2);
		world.setBlock(i + 10, j + 27, k + 0, PlaceDeepslate, 0, 2);
		world.setBlock(i + 11, j + 27, k + 0, PlaceDeepslate, 0, 2);
		world.setBlock(i + 12, j + 27, k + 0, PlaceDeepslate, 0, 2);
		world.setBlock(i + 13, j + 27, k + 0, PlaceDeepslate, 0, 2);
		world.setBlock(i + 14, j + 27, k + 0, PlaceDeepslate, 0, 2);
		world.setBlock(i + 15, j + 27, k + 0, PlaceDeepslate, 0, 2);
		world.setBlock(i + 16, j + 27, k + 0, PlaceDeepslate, 0, 2);
		world.setBlock(i + 17, j + 27, k + 0, PlaceDeepslate, 0, 2);
		world.setBlock(i + 5, j + 27, k + 1, PlaceDeepslate, 0, 2);
