package com.NovaCraft.world.ancient_city;

import net.minecraft.world.gen.feature.*;
import net.minecraft.block.*;
import net.minecraft.world.*;
import java.util.*;

import com.NovaCraft.config.Configs;
import com.NovaCraft.registry.OtherModBlocks;
import com.NovaCraftBlocks.NovaCraftBlocks;

import cpw.mods.fml.common.Loader;
import net.minecraft.init.*;

public class AncientCitySupportTopGen extends WorldGenerator
{
	public AncientCitySupportTopGen() {

	}
    
    public boolean generate(final World world, final Random random, final int i, final int j, final int k) {

		world.setBlock(i + 7, j + 0, k + 2, Blocks.stone, 0, 2);
		world.setBlock(i + 8, j + 0, k + 2, Blocks.stone, 0, 2);
		world.setBlock(i + 9, j + 0, k + 2, Blocks.stone, 0, 2);
		world.setBlock(i + 10, j + 0, k + 2, Blocks.stone, 0, 2);
		world.setBlock(i + 5, j + 0, k + 3, Blocks.stone, 0, 2);
		world.setBlock(i + 6, j + 0, k + 3, Blocks.stone, 0, 2);
		world.setBlock(i + 7, j + 0, k + 3, Blocks.stone, 0, 2);
		world.setBlock(i + 8, j + 0, k + 3, Blocks.stone, 0, 2);
		world.setBlock(i + 9, j + 0, k + 3, Blocks.stone, 0, 2);
		world.setBlock(i + 10, j + 0, k + 3, Blocks.stone, 0, 2);
		world.setBlock(i + 11, j + 0, k + 3, Blocks.stone, 0, 2);
		world.setBlock(i + 4, j + 0, k + 4, Blocks.stone, 0, 2);
		world.setBlock(i + 5, j + 0, k + 4, Blocks.stone, 0, 2);
		world.setBlock(i + 6, j + 0, k + 4, Blocks.stone, 0, 2);
		world.setBlock(i + 7, j + 0, k + 4, Blocks.stone, 0, 2);
		world.setBlock(i + 8, j + 0, k + 4, Blocks.stone, 0, 2);
		world.setBlock(i + 9, j + 0, k + 4, Blocks.stone, 0, 2);
		world.setBlock(i + 10, j + 0, k + 4, Blocks.stone, 0, 2);
		world.setBlock(i + 11, j + 0, k + 4, Blocks.stone, 0, 2);
		world.setBlock(i + 12, j + 0, k + 4, Blocks.stone, 0, 2);
		world.setBlock(i + 3, j + 0, k + 5, Blocks.stone, 0, 2);
		world.setBlock(i + 4, j + 0, k + 5, Blocks.stone, 0, 2);
		world.setBlock(i + 5, j + 0, k + 5, Blocks.stone, 0, 2);
		world.setBlock(i + 6, j + 0, k + 5, Blocks.stone, 0, 2);
		world.setBlock(i + 7, j + 0, k + 5, Blocks.stone, 0, 2);
		world.setBlock(i + 8, j + 0, k + 5, Blocks.stone, 0, 2);
		world.setBlock(i + 9, j + 0, k + 5, Blocks.stone, 0, 2);
		world.setBlock(i + 10, j + 0, k + 5, Blocks.stone, 0, 2);
		world.setBlock(i + 11, j + 0, k + 5, Blocks.stone, 0, 2);
		world.setBlock(i + 12, j + 0, k + 5, Blocks.stone, 0, 2);
		world.setBlock(i + 13, j + 0, k + 5, Blocks.stone, 0, 2);
		world.setBlock(i + 2, j + 0, k + 6, Blocks.stone, 0, 2);
		world.setBlock(i + 3, j + 0, k + 6, Blocks.stone, 0, 2);
		world.setBlock(i + 4, j + 0, k + 6, Blocks.stone, 0, 2);
		world.setBlock(i + 5, j + 0, k + 6, Blocks.stone, 0, 2);
		world.setBlock(i + 6, j + 0, k + 6, Blocks.stone, 0, 2);
		world.setBlock(i + 7, j + 0, k + 6, Blocks.stone, 0, 2);
		world.setBlock(i + 8, j + 0, k + 6, Blocks.stone, 0, 2);
		world.setBlock(i + 9, j + 0, k + 6, Blocks.stone, 0, 2);
		world.setBlock(i + 10, j + 0, k + 6, Blocks.stone, 0, 2);
		world.setBlock(i + 11, j + 0, k + 6, Blocks.stone, 0, 2);
		world.setBlock(i + 12, j + 0, k + 6, Blocks.stone, 0, 2);
		world.setBlock(i + 13, j + 0, k + 6, Blocks.stone, 0, 2);
		world.setBlock(i + 14, j + 0, k + 6, Blocks.stone, 0, 2);
		world.setBlock(i + 2, j + 0, k + 7, Blocks.stone, 0, 2);
		world.setBlock(i + 3, j + 0, k + 7, Blocks.stone, 0, 2);
		world.setBlock(i + 4, j + 0, k + 7, Blocks.stone, 0, 2);
		world.setBlock(i + 5, j + 0, k + 7, Blocks.stone, 0, 2);
		world.setBlock(i + 6, j + 0, k + 7, Blocks.stone, 0, 2);
		world.setBlock(i + 7, j + 0, k + 7, Blocks.stone, 0, 2);
		world.setBlock(i + 8, j + 0, k + 7, Blocks.stone, 0, 2);
		world.setBlock(i + 9, j + 0, k + 7, Blocks.stone, 0, 2);
		world.setBlock(i + 10, j + 0, k + 7, Blocks.stone, 0, 2);
		world.setBlock(i + 11, j + 0, k + 7, Blocks.stone, 0, 2);
		world.setBlock(i + 12, j + 0, k + 7, Blocks.stone, 0, 2);
		world.setBlock(i + 13, j + 0, k + 7, Blocks.stone, 0, 2);
		world.setBlock(i + 14, j + 0, k + 7, Blocks.stone, 0, 2);
		world.setBlock(i + 2, j + 0, k + 8, Blocks.stone, 0, 2);
		world.setBlock(i + 3, j + 0, k + 8, Blocks.stone, 0, 2);
		world.setBlock(i + 4, j + 0, k + 8, Blocks.stone, 0, 2);
		world.setBlock(i + 5, j + 0, k + 8, Blocks.stone, 0, 2);
		world.setBlock(i + 6, j + 0, k + 8, Blocks.stone, 0, 2);
		world.setBlock(i + 7, j + 0, k + 8, Blocks.stone, 0, 2);
		world.setBlock(i + 8, j + 0, k + 8, Blocks.stone, 0, 2);
		world.setBlock(i + 9, j + 0, k + 8, Blocks.stone, 0, 2);
		world.setBlock(i + 10, j + 0, k + 8, Blocks.stone, 0, 2);
		world.setBlock(i + 11, j + 0, k + 8, Blocks.stone, 0, 2);
		world.setBlock(i + 12, j + 0, k + 8, Blocks.stone, 0, 2);
		world.setBlock(i + 13, j + 0, k + 8, Blocks.stone, 0, 2);
		world.setBlock(i + 14, j + 0, k + 8, Blocks.stone, 0, 2);
		world.setBlock(i + 2, j + 0, k + 9, Blocks.stone, 0, 2);
		world.setBlock(i + 3, j + 0, k + 9, Blocks.stone, 0, 2);
		world.setBlock(i + 4, j + 0, k + 9, Blocks.stone, 0, 2);
		world.setBlock(i + 5, j + 0, k + 9, Blocks.stone, 0, 2);
		world.setBlock(i + 6, j + 0, k + 9, Blocks.stone, 0, 2);
		world.setBlock(i + 7, j + 0, k + 9, Blocks.stone, 0, 2);
		world.setBlock(i + 8, j + 0, k + 9, Blocks.stone, 0, 2);
		world.setBlock(i + 9, j + 0, k + 9, Blocks.stone, 0, 2);
		world.setBlock(i + 10, j + 0, k + 9, Blocks.stone, 0, 2);
		world.setBlock(i + 11, j + 0, k + 9, Blocks.stone, 0, 2);
		world.setBlock(i + 12, j + 0, k + 9, Blocks.stone, 0, 2);
		world.setBlock(i + 13, j + 0, k + 9, Blocks.stone, 0, 2);
		world.setBlock(i + 14, j + 0, k + 9, Blocks.stone, 0, 2);
		world.setBlock(i + 2, j + 0, k + 10, Blocks.stone, 0, 2);
		world.setBlock(i + 3, j + 0, k + 10, Blocks.stone, 0, 2);
		world.setBlock(i + 4, j + 0, k + 10, Blocks.stone, 0, 2);
		world.setBlock(i + 5, j + 0, k + 10, Blocks.stone, 0, 2);
		world.setBlock(i + 6, j + 0, k + 10, Blocks.stone, 0, 2);
		world.setBlock(i + 7, j + 0, k + 10, Blocks.stone, 0, 2);
		world.setBlock(i + 8, j + 0, k + 10, Blocks.stone, 0, 2);
		world.setBlock(i + 9, j + 0, k + 10, Blocks.stone, 0, 2);
		world.setBlock(i + 10, j + 0, k + 10, Blocks.stone, 0, 2);
		world.setBlock(i + 11, j + 0, k + 10, Blocks.stone, 0, 2);
		world.setBlock(i + 12, j + 0, k + 10, Blocks.stone, 0, 2);
		world.setBlock(i + 13, j + 0, k + 10, Blocks.stone, 0, 2);
		world.setBlock(i + 14, j + 0, k + 10, Blocks.stone, 0, 2);
		world.setBlock(i + 3, j + 0, k + 11, Blocks.stone, 0, 2);
		world.setBlock(i + 4, j + 0, k + 11, Blocks.stone, 0, 2);
		world.setBlock(i + 5, j + 0, k + 11, Blocks.stone, 0, 2);
		world.setBlock(i + 6, j + 0, k + 11, Blocks.stone, 0, 2);
		world.setBlock(i + 7, j + 0, k + 11, Blocks.stone, 0, 2);
		world.setBlock(i + 8, j + 0, k + 11, Blocks.stone, 0, 2);
		world.setBlock(i + 9, j + 0, k + 11, Blocks.stone, 0, 2);
		world.setBlock(i + 10, j + 0, k + 11, Blocks.stone, 0, 2);
		world.setBlock(i + 11, j + 0, k + 11, Blocks.stone, 0, 2);
		world.setBlock(i + 12, j + 0, k + 11, Blocks.stone, 0, 2);
		world.setBlock(i + 13, j + 0, k + 11, Blocks.stone, 0, 2);
		world.setBlock(i + 4, j + 0, k + 12, Blocks.stone, 0, 2);
		world.setBlock(i + 5, j + 0, k + 12, Blocks.stone, 0, 2);
		world.setBlock(i + 6, j + 0, k + 12, Blocks.stone, 0, 2);
		world.setBlock(i + 7, j + 0, k + 12, Blocks.stone, 0, 2);
		world.setBlock(i + 8, j + 0, k + 12, Blocks.stone, 0, 2);
		world.setBlock(i + 9, j + 0, k + 12, Blocks.stone, 0, 2);
		world.setBlock(i + 10, j + 0, k + 12, Blocks.stone, 0, 2);
		world.setBlock(i + 11, j + 0, k + 12, Blocks.stone, 0, 2);
		world.setBlock(i + 12, j + 0, k + 12, Blocks.stone, 0, 2);
		world.setBlock(i + 5, j + 0, k + 13, Blocks.stone, 0, 2);
		world.setBlock(i + 6, j + 0, k + 13, Blocks.stone, 0, 2);
		world.setBlock(i + 7, j + 0, k + 13, Blocks.stone, 0, 2);
		world.setBlock(i + 8, j + 0, k + 13, Blocks.stone, 0, 2);
		world.setBlock(i + 9, j + 0, k + 13, Blocks.stone, 0, 2);
		world.setBlock(i + 10, j + 0, k + 13, Blocks.stone, 0, 2);
		world.setBlock(i + 11, j + 0, k + 13, Blocks.stone, 0, 2);
		world.setBlock(i + 6, j + 0, k + 14, Blocks.stone, 0, 2);
		world.setBlock(i + 7, j + 0, k + 14, Blocks.stone, 0, 2);
		world.setBlock(i + 8, j + 0, k + 14, Blocks.stone, 0, 2);
		world.setBlock(i + 9, j + 0, k + 14, Blocks.stone, 0, 2);
		world.setBlock(i + 10, j + 0, k + 14, Blocks.stone, 0, 2);
		world.setBlock(i + 11, j + 0, k + 14, Blocks.stone, 0, 2);
		world.setBlock(i + 7, j + 1, k + 1, Blocks.stone, 0, 2);
		world.setBlock(i + 8, j + 1, k + 1, Blocks.stone, 0, 2);
		world.setBlock(i + 9, j + 1, k + 1, Blocks.stone, 0, 2);
		world.setBlock(i + 10, j + 1, k + 1, Blocks.stone, 0, 2);
		world.setBlock(i + 5, j + 1, k + 2, Blocks.stone, 0, 2);
		world.setBlock(i + 6, j + 1, k + 2, Blocks.stone, 0, 2);
		world.setBlock(i + 7, j + 1, k + 2, Blocks.stone, 0, 2);
		world.setBlock(i + 8, j + 1, k + 2, Blocks.stone, 0, 2);
		world.setBlock(i + 9, j + 1, k + 2, Blocks.stone, 0, 2);
		world.setBlock(i + 10, j + 1, k + 2, Blocks.stone, 0, 2);
		world.setBlock(i + 11, j + 1, k + 2, Blocks.stone, 0, 2);
		world.setBlock(i + 4, j + 1, k + 3, Blocks.stone, 0, 2);
		world.setBlock(i + 5, j + 1, k + 3, Blocks.stone, 0, 2);
		world.setBlock(i + 6, j + 1, k + 3, Blocks.stone, 0, 2);
		world.setBlock(i + 7, j + 1, k + 3, Blocks.stone, 0, 2);
		world.setBlock(i + 8, j + 1, k + 3, Blocks.stone, 0, 2);
		world.setBlock(i + 9, j + 1, k + 3, Blocks.stone, 0, 2);
		world.setBlock(i + 10, j + 1, k + 3, Blocks.stone, 0, 2);
		world.setBlock(i + 11, j + 1, k + 3, Blocks.stone, 0, 2);
		world.setBlock(i + 12, j + 1, k + 3, Blocks.stone, 0, 2);
		world.setBlock(i + 3, j + 1, k + 4, Blocks.stone, 0, 2);
		world.setBlock(i + 4, j + 1, k + 4, Blocks.stone, 0, 2);
		world.setBlock(i + 5, j + 1, k + 4, Blocks.stone, 0, 2);
		world.setBlock(i + 6, j + 1, k + 4, Blocks.stone, 0, 2);
		world.setBlock(i + 7, j + 1, k + 4, Blocks.stone, 0, 2);
		world.setBlock(i + 8, j + 1, k + 4, Blocks.stone, 0, 2);
		world.setBlock(i + 9, j + 1, k + 4, Blocks.stone, 0, 2);
		world.setBlock(i + 10, j + 1, k + 4, Blocks.stone, 0, 2);
		world.setBlock(i + 11, j + 1, k + 4, Blocks.stone, 0, 2);
		world.setBlock(i + 12, j + 1, k + 4, Blocks.stone, 0, 2);
		world.setBlock(i + 13, j + 1, k + 4, Blocks.stone, 0, 2);
		world.setBlock(i + 2, j + 1, k + 5, Blocks.stone, 0, 2);
		world.setBlock(i + 3, j + 1, k + 5, Blocks.stone, 0, 2);
		world.setBlock(i + 4, j + 1, k + 5, Blocks.stone, 0, 2);
		world.setBlock(i + 5, j + 1, k + 5, Blocks.stone, 0, 2);
		world.setBlock(i + 6, j + 1, k + 5, Blocks.stone, 0, 2);
		world.setBlock(i + 7, j + 1, k + 5, Blocks.stone, 0, 2);
		world.setBlock(i + 8, j + 1, k + 5, Blocks.stone, 0, 2);
		world.setBlock(i + 9, j + 1, k + 5, Blocks.stone, 0, 2);
		world.setBlock(i + 10, j + 1, k + 5, Blocks.stone, 0, 2);
		world.setBlock(i + 11, j + 1, k + 5, Blocks.stone, 0, 2);
		world.setBlock(i + 12, j + 1, k + 5, Blocks.stone, 0, 2);
		world.setBlock(i + 13, j + 1, k + 5, Blocks.stone, 0, 2);
		world.setBlock(i + 14, j + 1, k + 5, Blocks.stone, 0, 2);
		world.setBlock(i + 1, j + 1, k + 6, Blocks.stone, 0, 2);
		world.setBlock(i + 2, j + 1, k + 6, Blocks.stone, 0, 2);
		world.setBlock(i + 3, j + 1, k + 6, Blocks.stone, 0, 2);
		world.setBlock(i + 4, j + 1, k + 6, Blocks.stone, 0, 2);
		world.setBlock(i + 5, j + 1, k + 6, Blocks.stone, 0, 2);
		world.setBlock(i + 6, j + 1, k + 6, Blocks.stone, 0, 2);
		world.setBlock(i + 7, j + 1, k + 6, Blocks.stone, 0, 2);
		world.setBlock(i + 8, j + 1, k + 6, Blocks.stone, 0, 2);
		world.setBlock(i + 9, j + 1, k + 6, Blocks.stone, 0, 2);
		world.setBlock(i + 10, j + 1, k + 6, Blocks.stone, 0, 2);
		world.setBlock(i + 11, j + 1, k + 6, Blocks.stone, 0, 2);
		world.setBlock(i + 12, j + 1, k + 6, Blocks.stone, 0, 2);
		world.setBlock(i + 13, j + 1, k + 6, Blocks.stone, 0, 2);
		world.setBlock(i + 14, j + 1, k + 6, Blocks.stone, 0, 2);
		world.setBlock(i + 15, j + 1, k + 6, Blocks.stone, 0, 2);
		world.setBlock(i + 1, j + 1, k + 7, Blocks.stone, 0, 2);
		world.setBlock(i + 2, j + 1, k + 7, Blocks.stone, 0, 2);
		world.setBlock(i + 3, j + 1, k + 7, Blocks.stone, 0, 2);
		world.setBlock(i + 4, j + 1, k + 7, Blocks.stone, 0, 2);
		world.setBlock(i + 5, j + 1, k + 7, Blocks.stone, 0, 2);
		world.setBlock(i + 6, j + 1, k + 7, Blocks.stone, 0, 2);
		world.setBlock(i + 7, j + 1, k + 7, Blocks.stone, 0, 2);
		world.setBlock(i + 8, j + 1, k + 7, Blocks.stone, 0, 2);
		world.setBlock(i + 9, j + 1, k + 7, Blocks.stone, 0, 2);
		world.setBlock(i + 10, j + 1, k + 7, Blocks.stone, 0, 2);
		world.setBlock(i + 11, j + 1, k + 7, Blocks.stone, 0, 2);
		world.setBlock(i + 12, j + 1, k + 7, Blocks.stone, 0, 2);
		world.setBlock(i + 13, j + 1, k + 7, Blocks.stone, 0, 2);
		world.setBlock(i + 14, j + 1, k + 7, Blocks.stone, 0, 2);
		world.setBlock(i + 15, j + 1, k + 7, Blocks.stone, 0, 2);
		world.setBlock(i + 1, j + 1, k + 8, Blocks.stone, 0, 2);
		world.setBlock(i + 2, j + 1, k + 8, Blocks.stone, 0, 2);
		world.setBlock(i + 3, j + 1, k + 8, Blocks.stone, 0, 2);
		world.setBlock(i + 4, j + 1, k + 8, Blocks.stone, 0, 2);
		world.setBlock(i + 5, j + 1, k + 8, Blocks.stone, 0, 2);
		world.setBlock(i + 6, j + 1, k + 8, Blocks.stone, 0, 2);
		world.setBlock(i + 7, j + 1, k + 8, Blocks.stone, 0, 2);
		world.setBlock(i + 8, j + 1, k + 8, Blocks.stone, 0, 2);
		world.setBlock(i + 9, j + 1, k + 8, Blocks.stone, 0, 2);
		world.setBlock(i + 10, j + 1, k + 8, Blocks.stone, 0, 2);
		world.setBlock(i + 11, j + 1, k + 8, Blocks.stone, 0, 2);
		world.setBlock(i + 12, j + 1, k + 8, Blocks.stone, 0, 2);
		world.setBlock(i + 13, j + 1, k + 8, Blocks.stone, 0, 2);
		world.setBlock(i + 14, j + 1, k + 8, Blocks.stone, 0, 2);
		world.setBlock(i + 15, j + 1, k + 8, Blocks.stone, 0, 2);
		world.setBlock(i + 1, j + 1, k + 9, Blocks.stone, 0, 2);
		world.setBlock(i + 2, j + 1, k + 9, Blocks.stone, 0, 2);
		world.setBlock(i + 3, j + 1, k + 9, Blocks.stone, 0, 2);
		world.setBlock(i + 4, j + 1, k + 9, Blocks.stone, 0, 2);
		world.setBlock(i + 5, j + 1, k + 9, Blocks.stone, 0, 2);
		world.setBlock(i + 6, j + 1, k + 9, Blocks.stone, 0, 2);
		world.setBlock(i + 7, j + 1, k + 9, Blocks.stone, 0, 2);
		world.setBlock(i + 8, j + 1, k + 9, Blocks.stone, 0, 2);
		world.setBlock(i + 9, j + 1, k + 9, Blocks.stone, 0, 2);
		world.setBlock(i + 10, j + 1, k + 9, Blocks.stone, 0, 2);
		world.setBlock(i + 11, j + 1, k + 9, Blocks.stone, 0, 2);
		world.setBlock(i + 12, j + 1, k + 9, Blocks.stone, 0, 2);
		world.setBlock(i + 13, j + 1, k + 9, Blocks.stone, 0, 2);
		world.setBlock(i + 14, j + 1, k + 9, Blocks.stone, 0, 2);
		world.setBlock(i + 15, j + 1, k + 9, Blocks.stone, 0, 2);
		world.setBlock(i + 1, j + 1, k + 10, Blocks.stone, 0, 2);
		world.setBlock(i + 2, j + 1, k + 10, Blocks.stone, 0, 2);
		world.setBlock(i + 3, j + 1, k + 10, Blocks.stone, 0, 2);
		world.setBlock(i + 4, j + 1, k + 10, Blocks.stone, 0, 2);
		world.setBlock(i + 5, j + 1, k + 10, Blocks.stone, 0, 2);
		world.setBlock(i + 6, j + 1, k + 10, Blocks.stone, 0, 2);
		world.setBlock(i + 7, j + 1, k + 10, Blocks.stone, 0, 2);
		world.setBlock(i + 8, j + 1, k + 10, Blocks.stone, 0, 2);
		world.setBlock(i + 9, j + 1, k + 10, Blocks.stone, 0, 2);
		world.setBlock(i + 10, j + 1, k + 10, Blocks.stone, 0, 2);
		world.setBlock(i + 11, j + 1, k + 10, Blocks.stone, 0, 2);
		world.setBlock(i + 12, j + 1, k + 10, Blocks.stone, 0, 2);
		world.setBlock(i + 13, j + 1, k + 10, Blocks.stone, 0, 2);
		world.setBlock(i + 14, j + 1, k + 10, Blocks.stone, 0, 2);
		world.setBlock(i + 15, j + 1, k + 10, Blocks.stone, 0, 2);
		world.setBlock(i + 2, j + 1, k + 11, Blocks.stone, 0, 2);
		world.setBlock(i + 3, j + 1, k + 11, Blocks.stone, 0, 2);
		world.setBlock(i + 4, j + 1, k + 11, Blocks.stone, 0, 2);
		world.setBlock(i + 5, j + 1, k + 11, Blocks.stone, 0, 2);
		world.setBlock(i + 6, j + 1, k + 11, Blocks.stone, 0, 2);
		world.setBlock(i + 7, j + 1, k + 11, Blocks.stone, 0, 2);
		world.setBlock(i + 8, j + 1, k + 11, Blocks.stone, 0, 2);
		world.setBlock(i + 9, j + 1, k + 11, Blocks.stone, 0, 2);
		world.setBlock(i + 10, j + 1, k + 11, Blocks.stone, 0, 2);
		world.setBlock(i + 11, j + 1, k + 11, Blocks.stone, 0, 2);
		world.setBlock(i + 12, j + 1, k + 11, Blocks.stone, 0, 2);
		world.setBlock(i + 13, j + 1, k + 11, Blocks.stone, 0, 2);
		world.setBlock(i + 14, j + 1, k + 11, Blocks.stone, 0, 2);
		world.setBlock(i + 3, j + 1, k + 12, Blocks.stone, 0, 2);
		world.setBlock(i + 4, j + 1, k + 12, Blocks.stone, 0, 2);
		world.setBlock(i + 5, j + 1, k + 12, Blocks.stone, 0, 2);
		world.setBlock(i + 6, j + 1, k + 12, Blocks.stone, 0, 2);
		world.setBlock(i + 7, j + 1, k + 12, Blocks.stone, 0, 2);
		world.setBlock(i + 8, j + 1, k + 12, Blocks.stone, 0, 2);
		world.setBlock(i + 9, j + 1, k + 12, Blocks.stone, 0, 2);
		world.setBlock(i + 10, j + 1, k + 12, Blocks.stone, 0, 2);
		world.setBlock(i + 11, j + 1, k + 12, Blocks.stone, 0, 2);
		world.setBlock(i + 12, j + 1, k + 12, Blocks.stone, 0, 2);
		world.setBlock(i + 13, j + 1, k + 12, Blocks.stone, 0, 2);
		world.setBlock(i + 4, j + 1, k + 13, Blocks.stone, 0, 2);
		world.setBlock(i + 5, j + 1, k + 13, Blocks.stone, 0, 2);
		world.setBlock(i + 6, j + 1, k + 13, Blocks.stone, 0, 2);
		world.setBlock(i + 7, j + 1, k + 13, Blocks.stone, 0, 2);
		world.setBlock(i + 8, j + 1, k + 13, Blocks.stone, 0, 2);
		world.setBlock(i + 9, j + 1, k + 13, Blocks.stone, 0, 2);
		world.setBlock(i + 10, j + 1, k + 13, Blocks.stone, 0, 2);
		world.setBlock(i + 11, j + 1, k + 13, Blocks.stone, 0, 2);
		world.setBlock(i + 12, j + 1, k + 13, Blocks.stone, 0, 2);
		world.setBlock(i + 5, j + 1, k + 14, Blocks.stone, 0, 2);
		world.setBlock(i + 6, j + 1, k + 14, Blocks.stone, 0, 2);
		world.setBlock(i + 7, j + 1, k + 14, Blocks.stone, 0, 2);
		world.setBlock(i + 8, j + 1, k + 14, Blocks.stone, 0, 2);
		world.setBlock(i + 9, j + 1, k + 14, Blocks.stone, 0, 2);
		world.setBlock(i + 10, j + 1, k + 14, Blocks.stone, 0, 2);
		world.setBlock(i + 11, j + 1, k + 14, Blocks.stone, 0, 2);
		world.setBlock(i + 6, j + 1, k + 15, Blocks.stone, 0, 2);
		world.setBlock(i + 7, j + 1, k + 15, Blocks.stone, 0, 2);
		world.setBlock(i + 8, j + 1, k + 15, Blocks.stone, 0, 2);
		world.setBlock(i + 9, j + 1, k + 15, Blocks.stone, 0, 2);
		world.setBlock(i + 10, j + 1, k + 15, Blocks.stone, 0, 2);
		world.setBlock(i + 7, j + 2, k + 0, Blocks.stone, 0, 2);
		world.setBlock(i + 8, j + 2, k + 0, Blocks.stone, 0, 2);
		world.setBlock(i + 9, j + 2, k + 0, Blocks.stone, 0, 2);
		world.setBlock(i + 10, j + 2, k + 0, Blocks.stone, 0, 2);
		world.setBlock(i + 5, j + 2, k + 1, Blocks.stone, 0, 2);
		world.setBlock(i + 6, j + 2, k + 1, Blocks.stone, 0, 2);
		world.setBlock(i + 7, j + 2, k + 1, Blocks.stone, 0, 2);
		world.setBlock(i + 8, j + 2, k + 1, Blocks.stone, 0, 2);
		world.setBlock(i + 9, j + 2, k + 1, Blocks.stone, 0, 2);
		world.setBlock(i + 10, j + 2, k + 1, Blocks.stone, 0, 2);
		world.setBlock(i + 11, j + 2, k + 1, Blocks.stone, 0, 2);
		world.setBlock(i + 4, j + 2, k + 2, Blocks.stone, 0, 2);
		world.setBlock(i + 5, j + 2, k + 2, Blocks.stone, 0, 2);
		world.setBlock(i + 6, j + 2, k + 2, Blocks.stone, 0, 2);
		world.setBlock(i + 7, j + 2, k + 2, Blocks.stone, 0, 2);
		world.setBlock(i + 8, j + 2, k + 2, Blocks.stone, 0, 2);
		world.setBlock(i + 9, j + 2, k + 2, Blocks.stone, 0, 2);
		world.setBlock(i + 10, j + 2, k + 2, Blocks.stone, 0, 2);
		world.setBlock(i + 11, j + 2, k + 2, Blocks.stone, 0, 2);
		world.setBlock(i + 12, j + 2, k + 2, Blocks.stone, 0, 2);
		world.setBlock(i + 3, j + 2, k + 3, Blocks.stone, 0, 2);
		world.setBlock(i + 4, j + 2, k + 3, Blocks.stone, 0, 2);
		world.setBlock(i + 5, j + 2, k + 3, Blocks.stone, 0, 2);
		world.setBlock(i + 6, j + 2, k + 3, Blocks.stone, 0, 2);
		world.setBlock(i + 7, j + 2, k + 3, Blocks.stone, 0, 2);
		world.setBlock(i + 8, j + 2, k + 3, Blocks.stone, 0, 2);
		world.setBlock(i + 9, j + 2, k + 3, Blocks.stone, 0, 2);
		world.setBlock(i + 10, j + 2, k + 3, Blocks.stone, 0, 2);
		world.setBlock(i + 11, j + 2, k + 3, Blocks.stone, 0, 2);
		world.setBlock(i + 12, j + 2, k + 3, Blocks.stone, 0, 2);
		world.setBlock(i + 13, j + 2, k + 3, Blocks.stone, 0, 2);
		world.setBlock(i + 2, j + 2, k + 4, Blocks.stone, 0, 2);
		world.setBlock(i + 3, j + 2, k + 4, Blocks.stone, 0, 2);
		world.setBlock(i + 4, j + 2, k + 4, Blocks.stone, 0, 2);
		world.setBlock(i + 5, j + 2, k + 4, Blocks.stone, 0, 2);
		world.setBlock(i + 6, j + 2, k + 4, Blocks.stone, 0, 2);
		world.setBlock(i + 7, j + 2, k + 4, Blocks.stone, 0, 2);
		world.setBlock(i + 8, j + 2, k + 4, Blocks.stone, 0, 2);
		world.setBlock(i + 9, j + 2, k + 4, Blocks.stone, 0, 2);
		world.setBlock(i + 10, j + 2, k + 4, Blocks.stone, 0, 2);
		world.setBlock(i + 11, j + 2, k + 4, Blocks.stone, 0, 2);
		world.setBlock(i + 12, j + 2, k + 4, Blocks.stone, 0, 2);
		world.setBlock(i + 13, j + 2, k + 4, Blocks.stone, 0, 2);
		world.setBlock(i + 14, j + 2, k + 4, Blocks.stone, 0, 2);
		world.setBlock(i + 1, j + 2, k + 5, Blocks.stone, 0, 2);
		world.setBlock(i + 2, j + 2, k + 5, Blocks.stone, 0, 2);
		world.setBlock(i + 3, j + 2, k + 5, Blocks.stone, 0, 2);
		world.setBlock(i + 4, j + 2, k + 5, Blocks.stone, 0, 2);
		world.setBlock(i + 5, j + 2, k + 5, Blocks.stone, 0, 2);
		world.setBlock(i + 6, j + 2, k + 5, Blocks.stone, 0, 2);
		world.setBlock(i + 7, j + 2, k + 5, Blocks.stone, 0, 2);
		world.setBlock(i + 8, j + 2, k + 5, Blocks.stone, 0, 2);
		world.setBlock(i + 9, j + 2, k + 5, Blocks.stone, 0, 2);
		world.setBlock(i + 10, j + 2, k + 5, Blocks.stone, 0, 2);
		world.setBlock(i + 11, j + 2, k + 5, Blocks.stone, 0, 2);
		world.setBlock(i + 12, j + 2, k + 5, Blocks.stone, 0, 2);
		world.setBlock(i + 13, j + 2, k + 5, Blocks.stone, 0, 2);
		world.setBlock(i + 14, j + 2, k + 5, Blocks.stone, 0, 2);
		world.setBlock(i + 15, j + 2, k + 5, Blocks.stone, 0, 2);
		world.setBlock(i + 0, j + 2, k + 6, Blocks.stone, 0, 2);
		world.setBlock(i + 1, j + 2, k + 6, Blocks.stone, 0, 2);
		world.setBlock(i + 2, j + 2, k + 6, Blocks.stone, 0, 2);
		world.setBlock(i + 3, j + 2, k + 6, Blocks.stone, 0, 2);
		world.setBlock(i + 4, j + 2, k + 6, Blocks.stone, 0, 2);
		world.setBlock(i + 5, j + 2, k + 6, Blocks.stone, 0, 2);
		world.setBlock(i + 6, j + 2, k + 6, Blocks.stone, 0, 2);
		world.setBlock(i + 7, j + 2, k + 6, Blocks.stone, 0, 2);
		world.setBlock(i + 8, j + 2, k + 6, Blocks.stone, 0, 2);
		world.setBlock(i + 9, j + 2, k + 6, Blocks.stone, 0, 2);
		world.setBlock(i + 10, j + 2, k + 6, Blocks.stone, 0, 2);
		world.setBlock(i + 11, j + 2, k + 6, Blocks.stone, 0, 2);
		world.setBlock(i + 12, j + 2, k + 6, Blocks.stone, 0, 2);
		world.setBlock(i + 13, j + 2, k + 6, Blocks.stone, 0, 2);
		world.setBlock(i + 14, j + 2, k + 6, Blocks.stone, 0, 2);
		world.setBlock(i + 15, j + 2, k + 6, Blocks.stone, 0, 2);
		world.setBlock(i + 16, j + 2, k + 6, Blocks.stone, 0, 2);
		world.setBlock(i + 0, j + 2, k + 7, Blocks.stone, 0, 2);
		world.setBlock(i + 1, j + 2, k + 7, Blocks.stone, 0, 2);
		world.setBlock(i + 2, j + 2, k + 7, Blocks.stone, 0, 2);
		world.setBlock(i + 3, j + 2, k + 7, Blocks.stone, 0, 2);
		world.setBlock(i + 4, j + 2, k + 7, Blocks.stone, 0, 2);
		world.setBlock(i + 5, j + 2, k + 7, Blocks.stone, 0, 2);
		world.setBlock(i + 6, j + 2, k + 7, Blocks.stone, 0, 2);
		world.setBlock(i + 7, j + 2, k + 7, Blocks.stone, 0, 2);
		world.setBlock(i + 8, j + 2, k + 7, Blocks.stone, 0, 2);
		world.setBlock(i + 9, j + 2, k + 7, Blocks.stone, 0, 2);
		world.setBlock(i + 10, j + 2, k + 7, Blocks.stone, 0, 2);
		world.setBlock(i + 11, j + 2, k + 7, Blocks.stone, 0, 2);
		world.setBlock(i + 12, j + 2, k + 7, Blocks.stone, 0, 2);
		world.setBlock(i + 13, j + 2, k + 7, Blocks.stone, 0, 2);
		world.setBlock(i + 14, j + 2, k + 7, Blocks.stone, 0, 2);
		world.setBlock(i + 15, j + 2, k + 7, Blocks.stone, 0, 2);
		world.setBlock(i + 16, j + 2, k + 7, Blocks.stone, 0, 2);
		world.setBlock(i + 0, j + 2, k + 8, Blocks.stone, 0, 2);
		world.setBlock(i + 1, j + 2, k + 8, Blocks.stone, 0, 2);
		world.setBlock(i + 2, j + 2, k + 8, Blocks.stone, 0, 2);
		world.setBlock(i + 3, j + 2, k + 8, Blocks.stone, 0, 2);
		world.setBlock(i + 4, j + 2, k + 8, Blocks.stone, 0, 2);
		world.setBlock(i + 5, j + 2, k + 8, Blocks.stone, 0, 2);
		world.setBlock(i + 6, j + 2, k + 8, Blocks.stone, 0, 2);
		world.setBlock(i + 7, j + 2, k + 8, Blocks.stone, 0, 2);
		world.setBlock(i + 8, j + 2, k + 8, Blocks.stone, 0, 2);
		world.setBlock(i + 9, j + 2, k + 8, Blocks.stone, 0, 2);
		world.setBlock(i + 10, j + 2, k + 8, Blocks.stone, 0, 2);
		world.setBlock(i + 11, j + 2, k + 8, Blocks.stone, 0, 2);
		world.setBlock(i + 12, j + 2, k + 8, Blocks.stone, 0, 2);
		world.setBlock(i + 13, j + 2, k + 8, Blocks.stone, 0, 2);
		world.setBlock(i + 14, j + 2, k + 8, Blocks.stone, 0, 2);
		world.setBlock(i + 15, j + 2, k + 8, Blocks.stone, 0, 2);
		world.setBlock(i + 16, j + 2, k + 8, Blocks.stone, 0, 2);
		world.setBlock(i + 0, j + 2, k + 9, Blocks.stone, 0, 2);
		world.setBlock(i + 1, j + 2, k + 9, Blocks.stone, 0, 2);
		world.setBlock(i + 2, j + 2, k + 9, Blocks.stone, 0, 2);
		world.setBlock(i + 3, j + 2, k + 9, Blocks.stone, 0, 2);
		world.setBlock(i + 4, j + 2, k + 9, Blocks.stone, 0, 2);
		world.setBlock(i + 5, j + 2, k + 9, Blocks.stone, 0, 2);
		world.setBlock(i + 6, j + 2, k + 9, Blocks.stone, 0, 2);
		world.setBlock(i + 7, j + 2, k + 9, Blocks.stone, 0, 2);
		world.setBlock(i + 8, j + 2, k + 9, Blocks.stone, 0, 2);
		world.setBlock(i + 9, j + 2, k + 9, Blocks.stone, 0, 2);
		world.setBlock(i + 10, j + 2, k + 9, Blocks.stone, 0, 2);
		world.setBlock(i + 11, j + 2, k + 9, Blocks.stone, 0, 2);
		world.setBlock(i + 12, j + 2, k + 9, Blocks.stone, 0, 2);
		world.setBlock(i + 13, j + 2, k + 9, Blocks.stone, 0, 2);
		world.setBlock(i + 14, j + 2, k + 9, Blocks.stone, 0, 2);
		world.setBlock(i + 15, j + 2, k + 9, Blocks.stone, 0, 2);
		world.setBlock(i + 16, j + 2, k + 9, Blocks.stone, 0, 2);
		world.setBlock(i + 0, j + 2, k + 10, Blocks.stone, 0, 2);
		world.setBlock(i + 1, j + 2, k + 10, Blocks.stone, 0, 2);
		world.setBlock(i + 2, j + 2, k + 10, Blocks.stone, 0, 2);
		world.setBlock(i + 3, j + 2, k + 10, Blocks.stone, 0, 2);
		world.setBlock(i + 4, j + 2, k + 10, Blocks.stone, 0, 2);
		world.setBlock(i + 5, j + 2, k + 10, Blocks.stone, 0, 2);
		world.setBlock(i + 6, j + 2, k + 10, Blocks.stone, 0, 2);
		world.setBlock(i + 7, j + 2, k + 10, Blocks.stone, 0, 2);
		world.setBlock(i + 8, j + 2, k + 10, Blocks.stone, 0, 2);
		world.setBlock(i + 9, j + 2, k + 10, Blocks.stone, 0, 2);
		world.setBlock(i + 10, j + 2, k + 10, Blocks.stone, 0, 2);
		world.setBlock(i + 11, j + 2, k + 10, Blocks.stone, 0, 2);
		world.setBlock(i + 12, j + 2, k + 10, Blocks.stone, 0, 2);
		world.setBlock(i + 13, j + 2, k + 10, Blocks.stone, 0, 2);
		world.setBlock(i + 14, j + 2, k + 10, Blocks.stone, 0, 2);
		world.setBlock(i + 15, j + 2, k + 10, Blocks.stone, 0, 2);
		world.setBlock(i + 16, j + 2, k + 10, Blocks.stone, 0, 2);
		world.setBlock(i + 1, j + 2, k + 11, Blocks.stone, 0, 2);
		world.setBlock(i + 2, j + 2, k + 11, Blocks.stone, 0, 2);
		world.setBlock(i + 3, j + 2, k + 11, Blocks.stone, 0, 2);
		world.setBlock(i + 4, j + 2, k + 11, Blocks.stone, 0, 2);
		world.setBlock(i + 5, j + 2, k + 11, Blocks.stone, 0, 2);
		world.setBlock(i + 6, j + 2, k + 11, Blocks.stone, 0, 2);
		world.setBlock(i + 7, j + 2, k + 11, Blocks.stone, 0, 2);
		world.setBlock(i + 8, j + 2, k + 11, Blocks.stone, 0, 2);
		world.setBlock(i + 9, j + 2, k + 11, Blocks.stone, 0, 2);
		world.setBlock(i + 10, j + 2, k + 11, Blocks.stone, 0, 2);
		world.setBlock(i + 11, j + 2, k + 11, Blocks.stone, 0, 2);
		world.setBlock(i + 12, j + 2, k + 11, Blocks.stone, 0, 2);
		world.setBlock(i + 13, j + 2, k + 11, Blocks.stone, 0, 2);
		world.setBlock(i + 14, j + 2, k + 11, Blocks.stone, 0, 2);
		world.setBlock(i + 15, j + 2, k + 11, Blocks.stone, 0, 2);
		world.setBlock(i + 2, j + 2, k + 12, Blocks.stone, 0, 2);
		world.setBlock(i + 3, j + 2, k + 12, Blocks.stone, 0, 2);
		world.setBlock(i + 4, j + 2, k + 12, Blocks.stone, 0, 2);
		world.setBlock(i + 5, j + 2, k + 12, Blocks.stone, 0, 2);
		world.setBlock(i + 6, j + 2, k + 12, Blocks.stone, 0, 2);
		world.setBlock(i + 7, j + 2, k + 12, Blocks.stone, 0, 2);
		world.setBlock(i + 8, j + 2, k + 12, Blocks.stone, 0, 2);
		world.setBlock(i + 9, j + 2, k + 12, Blocks.stone, 0, 2);
		world.setBlock(i + 10, j + 2, k + 12, Blocks.stone, 0, 2);
		world.setBlock(i + 11, j + 2, k + 12, Blocks.stone, 0, 2);
		world.setBlock(i + 12, j + 2, k + 12, Blocks.stone, 0, 2);
		world.setBlock(i + 13, j + 2, k + 12, Blocks.stone, 0, 2);
		world.setBlock(i + 14, j + 2, k + 12, Blocks.stone, 0, 2);
		world.setBlock(i + 3, j + 2, k + 13, Blocks.stone, 0, 2);
		world.setBlock(i + 4, j + 2, k + 13, Blocks.stone, 0, 2);
		world.setBlock(i + 5, j + 2, k + 13, Blocks.stone, 0, 2);
		world.setBlock(i + 6, j + 2, k + 13, Blocks.stone, 0, 2);
		world.setBlock(i + 7, j + 2, k + 13, Blocks.stone, 0, 2);
		world.setBlock(i + 8, j + 2, k + 13, Blocks.stone, 0, 2);
		world.setBlock(i + 9, j + 2, k + 13, Blocks.stone, 0, 2);
		world.setBlock(i + 10, j + 2, k + 13, Blocks.stone, 0, 2);
		world.setBlock(i + 11, j + 2, k + 13, Blocks.stone, 0, 2);
		world.setBlock(i + 12, j + 2, k + 13, Blocks.stone, 0, 2);
		world.setBlock(i + 13, j + 2, k + 13, Blocks.stone, 0, 2);
		world.setBlock(i + 4, j + 2, k + 14, Blocks.stone, 0, 2);
		world.setBlock(i + 5, j + 2, k + 14, Blocks.stone, 0, 2);
		world.setBlock(i + 6, j + 2, k + 14, Blocks.stone, 0, 2);
		world.setBlock(i + 7, j + 2, k + 14, Blocks.stone, 0, 2);
		world.setBlock(i + 8, j + 2, k + 14, Blocks.stone, 0, 2);
		world.setBlock(i + 9, j + 2, k + 14, Blocks.stone, 0, 2);
		world.setBlock(i + 10, j + 2, k + 14, Blocks.stone, 0, 2);
		world.setBlock(i + 11, j + 2, k + 14, Blocks.stone, 0, 2);
		world.setBlock(i + 12, j + 2, k + 14, Blocks.stone, 0, 2);
		world.setBlock(i + 5, j + 2, k + 15, Blocks.stone, 0, 2);
		world.setBlock(i + 6, j + 2, k + 15, Blocks.stone, 0, 2);
		world.setBlock(i + 7, j + 2, k + 15, Blocks.stone, 0, 2);
		world.setBlock(i + 8, j + 2, k + 15, Blocks.stone, 0, 2);
		world.setBlock(i + 9, j + 2, k + 15, Blocks.stone, 0, 2);
		world.setBlock(i + 10, j + 2, k + 15, Blocks.stone, 0, 2);
		world.setBlock(i + 11, j + 2, k + 15, Blocks.stone, 0, 2);
		world.setBlock(i + 6, j + 2, k + 16, Blocks.stone, 0, 2);
		world.setBlock(i + 7, j + 2, k + 16, Blocks.stone, 0, 2);
		world.setBlock(i + 8, j + 2, k + 16, Blocks.stone, 0, 2);
		world.setBlock(i + 9, j + 2, k + 16, Blocks.stone, 0, 2);
		world.setBlock(i + 10, j + 2, k + 16, Blocks.stone, 0, 2);
		world.setBlock(i + 7, j + 3, k + 0, Blocks.stone, 0, 2);
		world.setBlock(i + 8, j + 3, k + 0, Blocks.stone, 0, 2);
		world.setBlock(i + 9, j + 3, k + 0, Blocks.stone, 0, 2);
		world.setBlock(i + 10, j + 3, k + 0, Blocks.stone, 0, 2);
		world.setBlock(i + 5, j + 3, k + 1, Blocks.stone, 0, 2);
		world.setBlock(i + 6, j + 3, k + 1, Blocks.stone, 0, 2);
		world.setBlock(i + 7, j + 3, k + 1, Blocks.stone, 0, 2);
		world.setBlock(i + 8, j + 3, k + 1, Blocks.stone, 0, 2);
		world.setBlock(i + 9, j + 3, k + 1, Blocks.stone, 0, 2);
		world.setBlock(i + 10, j + 3, k + 1, Blocks.stone, 0, 2);
		world.setBlock(i + 11, j + 3, k + 1, Blocks.stone, 0, 2);
		world.setBlock(i + 4, j + 3, k + 2, Blocks.stone, 0, 2);
		world.setBlock(i + 5, j + 3, k + 2, Blocks.stone, 0, 2);
		world.setBlock(i + 6, j + 3, k + 2, Blocks.stone, 0, 2);
		world.setBlock(i + 7, j + 3, k + 2, Blocks.stone, 0, 2);
		world.setBlock(i + 8, j + 3, k + 2, Blocks.stone, 0, 2);
		world.setBlock(i + 9, j + 3, k + 2, Blocks.stone, 0, 2);
		world.setBlock(i + 10, j + 3, k + 2, Blocks.stone, 0, 2);
		world.setBlock(i + 11, j + 3, k + 2, Blocks.stone, 0, 2);
		world.setBlock(i + 12, j + 3, k + 2, Blocks.stone, 0, 2);
		world.setBlock(i + 3, j + 3, k + 3, Blocks.stone, 0, 2);
		world.setBlock(i + 4, j + 3, k + 3, Blocks.stone, 0, 2);
		world.setBlock(i + 5, j + 3, k + 3, Blocks.stone, 0, 2);
		world.setBlock(i + 6, j + 3, k + 3, Blocks.stone, 0, 2);
		world.setBlock(i + 7, j + 3, k + 3, Blocks.stone, 0, 2);
		world.setBlock(i + 8, j + 3, k + 3, Blocks.stone, 0, 2);
		world.setBlock(i + 9, j + 3, k + 3, Blocks.stone, 0, 2);
		world.setBlock(i + 10, j + 3, k + 3, Blocks.stone, 0, 2);
		world.setBlock(i + 11, j + 3, k + 3, Blocks.stone, 0, 2);
		world.setBlock(i + 12, j + 3, k + 3, Blocks.stone, 0, 2);
		world.setBlock(i + 13, j + 3, k + 3, Blocks.stone, 0, 2);
		world.setBlock(i + 2, j + 3, k + 4, Blocks.stone, 0, 2);
		world.setBlock(i + 3, j + 3, k + 4, Blocks.stone, 0, 2);
		world.setBlock(i + 4, j + 3, k + 4, Blocks.stone, 0, 2);
		world.setBlock(i + 5, j + 3, k + 4, Blocks.stone, 0, 2);
		world.setBlock(i + 6, j + 3, k + 4, Blocks.stone, 0, 2);
		world.setBlock(i + 7, j + 3, k + 4, Blocks.stone, 0, 2);
		world.setBlock(i + 8, j + 3, k + 4, Blocks.stone, 0, 2);
		world.setBlock(i + 9, j + 3, k + 4, Blocks.stone, 0, 2);
		world.setBlock(i + 10, j + 3, k + 4, Blocks.stone, 0, 2);
		world.setBlock(i + 11, j + 3, k + 4, Blocks.stone, 0, 2);
		world.setBlock(i + 12, j + 3, k + 4, Blocks.stone, 0, 2);
		world.setBlock(i + 13, j + 3, k + 4, Blocks.stone, 0, 2);
		world.setBlock(i + 14, j + 3, k + 4, Blocks.stone, 0, 2);
		world.setBlock(i + 1, j + 3, k + 5, Blocks.stone, 0, 2);
		world.setBlock(i + 2, j + 3, k + 5, Blocks.stone, 0, 2);
		world.setBlock(i + 3, j + 3, k + 5, Blocks.stone, 0, 2);
		world.setBlock(i + 4, j + 3, k + 5, Blocks.stone, 0, 2);
		world.setBlock(i + 5, j + 3, k + 5, Blocks.stone, 0, 2);
		world.setBlock(i + 6, j + 3, k + 5, Blocks.stone, 0, 2);
		world.setBlock(i + 7, j + 3, k + 5, Blocks.stone, 0, 2);
		world.setBlock(i + 8, j + 3, k + 5, Blocks.stone, 0, 2);
		world.setBlock(i + 9, j + 3, k + 5, Blocks.stone, 0, 2);
		world.setBlock(i + 10, j + 3, k + 5, Blocks.stone, 0, 2);
		world.setBlock(i + 11, j + 3, k + 5, Blocks.stone, 0, 2);
		world.setBlock(i + 12, j + 3, k + 5, Blocks.stone, 0, 2);
		world.setBlock(i + 13, j + 3, k + 5, Blocks.stone, 0, 2);
		world.setBlock(i + 14, j + 3, k + 5, Blocks.stone, 0, 2);
		world.setBlock(i + 15, j + 3, k + 5, Blocks.stone, 0, 2);
		world.setBlock(i + 0, j + 3, k + 6, Blocks.stone, 0, 2);
		world.setBlock(i + 1, j + 3, k + 6, Blocks.stone, 0, 2);
		world.setBlock(i + 2, j + 3, k + 6, Blocks.stone, 0, 2);
		world.setBlock(i + 3, j + 3, k + 6, Blocks.stone, 0, 2);
		world.setBlock(i + 4, j + 3, k + 6, Blocks.stone, 0, 2);
		world.setBlock(i + 5, j + 3, k + 6, Blocks.stone, 0, 2);
		world.setBlock(i + 6, j + 3, k + 6, Blocks.stone, 0, 2);
		world.setBlock(i + 7, j + 3, k + 6, Blocks.stone, 0, 2);
		world.setBlock(i + 8, j + 3, k + 6, Blocks.stone, 0, 2);
		world.setBlock(i + 9, j + 3, k + 6, Blocks.stone, 0, 2);
		world.setBlock(i + 10, j + 3, k + 6, Blocks.stone, 0, 2);
		world.setBlock(i + 11, j + 3, k + 6, Blocks.stone, 0, 2);
		world.setBlock(i + 12, j + 3, k + 6, Blocks.stone, 0, 2);
		world.setBlock(i + 13, j + 3, k + 6, Blocks.stone, 0, 2);
		world.setBlock(i + 14, j + 3, k + 6, Blocks.stone, 0, 2);
		world.setBlock(i + 15, j + 3, k + 6, Blocks.stone, 0, 2);
		world.setBlock(i + 16, j + 3, k + 6, Blocks.stone, 0, 2);
		world.setBlock(i + 0, j + 3, k + 7, Blocks.stone, 0, 2);
		world.setBlock(i + 1, j + 3, k + 7, Blocks.stone, 0, 2);
		world.setBlock(i + 2, j + 3, k + 7, Blocks.stone, 0, 2);
		world.setBlock(i + 3, j + 3, k + 7, Blocks.stone, 0, 2);
		world.setBlock(i + 4, j + 3, k + 7, Blocks.stone, 0, 2);
		world.setBlock(i + 5, j + 3, k + 7, Blocks.stone, 0, 2);
		world.setBlock(i + 6, j + 3, k + 7, Blocks.stone, 0, 2);
		world.setBlock(i + 7, j + 3, k + 7, Blocks.stone, 0, 2);
		world.setBlock(i + 8, j + 3, k + 7, Blocks.stone, 0, 2);
		world.setBlock(i + 9, j + 3, k + 7, Blocks.stone, 0, 2);
		world.setBlock(i + 10, j + 3, k + 7, Blocks.stone, 0, 2);
		world.setBlock(i + 11, j + 3, k + 7, Blocks.stone, 0, 2);
		world.setBlock(i + 12, j + 3, k + 7, Blocks.stone, 0, 2);
		world.setBlock(i + 13, j + 3, k + 7, Blocks.stone, 0, 2);
		world.setBlock(i + 14, j + 3, k + 7, Blocks.stone, 0, 2);
		world.setBlock(i + 15, j + 3, k + 7, Blocks.stone, 0, 2);
		world.setBlock(i + 16, j + 3, k + 7, Blocks.stone, 0, 2);
		world.setBlock(i + 0, j + 3, k + 8, Blocks.stone, 0, 2);
		world.setBlock(i + 1, j + 3, k + 8, Blocks.stone, 0, 2);
		world.setBlock(i + 2, j + 3, k + 8, Blocks.stone, 0, 2);
		world.setBlock(i + 3, j + 3, k + 8, Blocks.stone, 0, 2);
		world.setBlock(i + 4, j + 3, k + 8, Blocks.stone, 0, 2);
		world.setBlock(i + 5, j + 3, k + 8, Blocks.stone, 0, 2);
		world.setBlock(i + 6, j + 3, k + 8, Blocks.stone, 0, 2);
		world.setBlock(i + 7, j + 3, k + 8, Blocks.stone, 0, 2);
		world.setBlock(i + 8, j + 3, k + 8, Blocks.stone, 0, 2);
		world.setBlock(i + 9, j + 3, k + 8, Blocks.stone, 0, 2);
		world.setBlock(i + 10, j + 3, k + 8, Blocks.stone, 0, 2);
		world.setBlock(i + 11, j + 3, k + 8, Blocks.stone, 0, 2);
		world.setBlock(i + 12, j + 3, k + 8, Blocks.stone, 0, 2);
		world.setBlock(i + 13, j + 3, k + 8, Blocks.stone, 0, 2);
		world.setBlock(i + 14, j + 3, k + 8, Blocks.stone, 0, 2);
		world.setBlock(i + 15, j + 3, k + 8, Blocks.stone, 0, 2);
		world.setBlock(i + 16, j + 3, k + 8, Blocks.stone, 0, 2);
		world.setBlock(i + 0, j + 3, k + 9, Blocks.stone, 0, 2);
		world.setBlock(i + 1, j + 3, k + 9, Blocks.stone, 0, 2);
		world.setBlock(i + 2, j + 3, k + 9, Blocks.stone, 0, 2);
		world.setBlock(i + 3, j + 3, k + 9, Blocks.stone, 0, 2);
		world.setBlock(i + 4, j + 3, k + 9, Blocks.stone, 0, 2);
		world.setBlock(i + 5, j + 3, k + 9, Blocks.stone, 0, 2);
		world.setBlock(i + 6, j + 3, k + 9, Blocks.stone, 0, 2);
		world.setBlock(i + 7, j + 3, k + 9, Blocks.stone, 0, 2);
		world.setBlock(i + 8, j + 3, k + 9, Blocks.stone, 0, 2);
		world.setBlock(i + 9, j + 3, k + 9, Blocks.stone, 0, 2);
		world.setBlock(i + 10, j + 3, k + 9, Blocks.stone, 0, 2);
		world.setBlock(i + 11, j + 3, k + 9, Blocks.stone, 0, 2);
		world.setBlock(i + 12, j + 3, k + 9, Blocks.stone, 0, 2);
		world.setBlock(i + 13, j + 3, k + 9, Blocks.stone, 0, 2);
		world.setBlock(i + 14, j + 3, k + 9, Blocks.stone, 0, 2);
		world.setBlock(i + 15, j + 3, k + 9, Blocks.stone, 0, 2);
		world.setBlock(i + 16, j + 3, k + 9, Blocks.stone, 0, 2);
		world.setBlock(i + 0, j + 3, k + 10, Blocks.stone, 0, 2);
		world.setBlock(i + 1, j + 3, k + 10, Blocks.stone, 0, 2);
		world.setBlock(i + 2, j + 3, k + 10, Blocks.stone, 0, 2);
		world.setBlock(i + 3, j + 3, k + 10, Blocks.stone, 0, 2);
		world.setBlock(i + 4, j + 3, k + 10, Blocks.stone, 0, 2);
		world.setBlock(i + 5, j + 3, k + 10, Blocks.stone, 0, 2);
		world.setBlock(i + 6, j + 3, k + 10, Blocks.stone, 0, 2);
		world.setBlock(i + 7, j + 3, k + 10, Blocks.stone, 0, 2);
		world.setBlock(i + 8, j + 3, k + 10, Blocks.stone, 0, 2);
		world.setBlock(i + 9, j + 3, k + 10, Blocks.stone, 0, 2);
		world.setBlock(i + 10, j + 3, k + 10, Blocks.stone, 0, 2);
		world.setBlock(i + 11, j + 3, k + 10, Blocks.stone, 0, 2);
		world.setBlock(i + 12, j + 3, k + 10, Blocks.stone, 0, 2);
		world.setBlock(i + 13, j + 3, k + 10, Blocks.stone, 0, 2);
		world.setBlock(i + 14, j + 3, k + 10, Blocks.stone, 0, 2);
		world.setBlock(i + 15, j + 3, k + 10, Blocks.stone, 0, 2);
		world.setBlock(i + 16, j + 3, k + 10, Blocks.stone, 0, 2);
		world.setBlock(i + 1, j + 3, k + 11, Blocks.stone, 0, 2);
		world.setBlock(i + 2, j + 3, k + 11, Blocks.stone, 0, 2);
		world.setBlock(i + 3, j + 3, k + 11, Blocks.stone, 0, 2);
		world.setBlock(i + 4, j + 3, k + 11, Blocks.stone, 0, 2);
		world.setBlock(i + 5, j + 3, k + 11, Blocks.stone, 0, 2);
		world.setBlock(i + 6, j + 3, k + 11, Blocks.stone, 0, 2);
		world.setBlock(i + 7, j + 3, k + 11, Blocks.stone, 0, 2);
		world.setBlock(i + 8, j + 3, k + 11, Blocks.stone, 0, 2);
		world.setBlock(i + 9, j + 3, k + 11, Blocks.stone, 0, 2);
		world.setBlock(i + 10, j + 3, k + 11, Blocks.stone, 0, 2);
		world.setBlock(i + 11, j + 3, k + 11, Blocks.stone, 0, 2);
		world.setBlock(i + 12, j + 3, k + 11, Blocks.stone, 0, 2);
		world.setBlock(i + 13, j + 3, k + 11, Blocks.stone, 0, 2);
		world.setBlock(i + 14, j + 3, k + 11, Blocks.stone, 0, 2);
		world.setBlock(i + 15, j + 3, k + 11, Blocks.stone, 0, 2);
		world.setBlock(i + 2, j + 3, k + 12, Blocks.stone, 0, 2);
		world.setBlock(i + 3, j + 3, k + 12, Blocks.stone, 0, 2);
		world.setBlock(i + 4, j + 3, k + 12, Blocks.stone, 0, 2);
		world.setBlock(i + 5, j + 3, k + 12, Blocks.stone, 0, 2);
		world.setBlock(i + 6, j + 3, k + 12, Blocks.stone, 0, 2);
		world.setBlock(i + 7, j + 3, k + 12, Blocks.stone, 0, 2);
		world.setBlock(i + 8, j + 3, k + 12, Blocks.stone, 0, 2);
		world.setBlock(i + 9, j + 3, k + 12, Blocks.stone, 0, 2);
		world.setBlock(i + 10, j + 3, k + 12, Blocks.stone, 0, 2);
		world.setBlock(i + 11, j + 3, k + 12, Blocks.stone, 0, 2);
		world.setBlock(i + 12, j + 3, k + 12, Blocks.stone, 0, 2);
		world.setBlock(i + 13, j + 3, k + 12, Blocks.stone, 0, 2);
		world.setBlock(i + 14, j + 3, k + 12, Blocks.stone, 0, 2);
		world.setBlock(i + 3, j + 3, k + 13, Blocks.stone, 0, 2);
		world.setBlock(i + 4, j + 3, k + 13, Blocks.stone, 0, 2);
		world.setBlock(i + 5, j + 3, k + 13, Blocks.stone, 0, 2);
		world.setBlock(i + 6, j + 3, k + 13, Blocks.stone, 0, 2);
		world.setBlock(i + 7, j + 3, k + 13, Blocks.stone, 0, 2);
		world.setBlock(i + 8, j + 3, k + 13, Blocks.stone, 0, 2);
		world.setBlock(i + 9, j + 3, k + 13, Blocks.stone, 0, 2);
		world.setBlock(i + 10, j + 3, k + 13, Blocks.stone, 0, 2);
		world.setBlock(i + 11, j + 3, k + 13, Blocks.stone, 0, 2);
		world.setBlock(i + 12, j + 3, k + 13, Blocks.stone, 0, 2);
		world.setBlock(i + 13, j + 3, k + 13, Blocks.stone, 0, 2);
		world.setBlock(i + 4, j + 3, k + 14, Blocks.stone, 0, 2);
		world.setBlock(i + 5, j + 3, k + 14, Blocks.stone, 0, 2);
		world.setBlock(i + 6, j + 3, k + 14, Blocks.stone, 0, 2);
		world.setBlock(i + 7, j + 3, k + 14, Blocks.stone, 0, 2);
		world.setBlock(i + 8, j + 3, k + 14, Blocks.stone, 0, 2);
		world.setBlock(i + 9, j + 3, k + 14, Blocks.stone, 0, 2);
		world.setBlock(i + 10, j + 3, k + 14, Blocks.stone, 0, 2);
		world.setBlock(i + 11, j + 3, k + 14, Blocks.stone, 0, 2);
		world.setBlock(i + 12, j + 3, k + 14, Blocks.stone, 0, 2);
		world.setBlock(i + 5, j + 3, k + 15, Blocks.stone, 0, 2);
		world.setBlock(i + 6, j + 3, k + 15, Blocks.stone, 0, 2);
		world.setBlock(i + 7, j + 3, k + 15, Blocks.stone, 0, 2);
		world.setBlock(i + 8, j + 3, k + 15, Blocks.stone, 0, 2);
		world.setBlock(i + 9, j + 3, k + 15, Blocks.stone, 0, 2);
		world.setBlock(i + 10, j + 3, k + 15, Blocks.stone, 0, 2);
		world.setBlock(i + 11, j + 3, k + 15, Blocks.stone, 0, 2);
		world.setBlock(i + 6, j + 3, k + 16, Blocks.stone, 0, 2);
		world.setBlock(i + 7, j + 3, k + 16, Blocks.stone, 0, 2);
		world.setBlock(i + 8, j + 3, k + 16, Blocks.stone, 0, 2);
		world.setBlock(i + 9, j + 3, k + 16, Blocks.stone, 0, 2);
		world.setBlock(i + 10, j + 3, k + 16, Blocks.stone, 0, 2);
   	
    	return true;
    }

}
