package com.NovaCraft.world.ancient_city;

import java.util.Random;

import com.NovaCraft.Items.NovaCraftItems;
import com.NovaCraft.registry.OtherModBlocks;
import com.NovaCraft.registry.OtherModItems;
import com.NovaCraftBlocks.NovaCraftBlocks;

import cpw.mods.fml.common.Loader;
import net.minecraft.block.Block;
import net.minecraft.enchantment.Enchantment;
import net.minecraft.enchantment.EnchantmentData;
import net.minecraft.init.Blocks;
import net.minecraft.init.Items;
import net.minecraft.item.ItemStack;
import net.minecraft.tileentity.TileEntityChest;
import net.minecraft.util.MathHelper;
import net.minecraft.world.World;
import net.minecraft.world.gen.feature.WorldGenerator;

public class AncientCitySculkWallPosXGen extends WorldGenerator
{
	public AncientCitySculkWallPosXGen() {

	}
	
	private static final Block grimstone = NovaCraftBlocks.grimstone;
	private static final Block sculk_grimstone = NovaCraftBlocks.sculk_grimstone;
	private static final Block sculk_block = NovaCraftBlocks.sculk_block;
	private static final Block sculk_tulip = NovaCraftBlocks.sculk_tulip;
	private static final Block sculk_tendrils = NovaCraftBlocks.sculk_tendrils;
	private static final Block sculk_bush = NovaCraftBlocks.sculk_bush;
	private static final Block sculk_bloom = NovaCraftBlocks.sculk_bloom;	
	private static final Block sculk_tiles = NovaCraftBlocks.sculk_tiles;
	private static final Block sculk_bricks = NovaCraftBlocks.sculk_bricks;
    
    public boolean generate(final World world, final Random random, final int i, final int j, final int k) {
    	
		world.setBlock(i + 33, j + 0, k + 4, NovaCraftBlocks.sculk_vein, 0, 2);
		world.setBlock(i + 34, j + 0, k + 4, NovaCraftBlocks.sculk_vein, 0, 2);
		world.setBlock(i + 15, j + 0, k + 11, NovaCraftBlocks.sculk_vein, 0, 2);
		world.setBlock(i + 8, j + 0, k + 22, NovaCraftBlocks.sculk_vein, 0, 2);
		world.setBlock(i + 8, j + 0, k + 23, NovaCraftBlocks.sculk_vein, 0, 2);
		world.setBlock(i + 7, j + 0, k + 27, NovaCraftBlocks.sculk_vein, 0, 2);
		world.setBlock(i + 10, j + 0, k + 27, NovaCraftBlocks.sculk_vein, 0, 2);
		world.setBlock(i + 11, j + 0, k + 27, NovaCraftBlocks.sculk_vein, 0, 2);
		world.setBlock(i + 8, j + 0, k + 28, NovaCraftBlocks.sculk_vein, 0, 2);
		world.setBlock(i + 11, j + 0, k + 28, NovaCraftBlocks.sculk_vein, 0, 2);
		world.setBlock(i + 11, j + 0, k + 29, NovaCraftBlocks.sculk_vein, 0, 2);
		world.setBlock(i + 12, j + 0, k + 29, NovaCraftBlocks.sculk_vein, 0, 2);
		world.setBlock(i + 11, j + 0, k + 30, NovaCraftBlocks.sculk_vein, 0, 2);
		world.setBlock(i + 12, j + 0, k + 30, NovaCraftBlocks.sculk_vein, 0, 2);
		world.setBlock(i + 28, j + 0, k + 31, NovaCraftBlocks.sculk_vein, 0, 2);
		world.setBlock(i + 24, j + 0, k + 32, NovaCraftBlocks.sculk_vein, 0, 2);
		world.setBlock(i + 23, j + 0, k + 33, NovaCraftBlocks.sculk_vein, 0, 2);
		world.setBlock(i + 22, j + 0, k + 38, NovaCraftBlocks.sculk_vein, 0, 2);
		world.setBlock(i + 23, j + 0, k + 38, NovaCraftBlocks.sculk_vein, 0, 2);
		world.setBlock(i + 22, j + 0, k + 39, NovaCraftBlocks.sculk_vein, 0, 2);
		world.setBlock(i + 23, j + 0, k + 39, NovaCraftBlocks.sculk_vein, 0, 2);
		world.setBlock(i + 28, j + 0, k + 41, NovaCraftBlocks.sculk_vein, 0, 2);
		world.setBlock(i + 31, j + 1, k + 4, sculk_block, 0, 2);
		world.setBlock(i + 32, j + 1, k + 4, sculk_block, 0, 2);
		world.setBlock(i + 33, j + 1, k + 4, sculk_block, 0, 2);
		world.setBlock(i + 34, j + 1, k + 4, sculk_block, 0, 2);
		world.setBlock(i + 35, j + 1, k + 4, sculk_block, 0, 2);
		world.setBlock(i + 36, j + 1, k + 4, sculk_block, 0, 2);
		world.setBlock(i + 37, j + 1, k + 4, sculk_block, 0, 2);
		world.setBlock(i + 26, j + 1, k + 5, sculk_block, 0, 2);
		world.setBlock(i + 27, j + 1, k + 5, sculk_block, 0, 2);
		world.setBlock(i + 28, j + 1, k + 5, sculk_block, 0, 2);
		world.setBlock(i + 29, j + 1, k + 5, sculk_block, 0, 2);
		world.setBlock(i + 30, j + 1, k + 5, sculk_block, 0, 2);
		world.setBlock(i + 31, j + 1, k + 5, sculk_block, 0, 2);
		world.setBlock(i + 32, j + 1, k + 5, sculk_block, 0, 2);
		world.setBlock(i + 33, j + 1, k + 5, sculk_block, 0, 2);
		world.setBlock(i + 34, j + 1, k + 5, sculk_block, 0, 2);
		world.setBlock(i + 35, j + 1, k + 5, sculk_block, 0, 2);
		world.setBlock(i + 36, j + 1, k + 5, sculk_block, 0, 2);
		world.setBlock(i + 37, j + 1, k + 5, sculk_block, 0, 2);
		world.setBlock(i + 0, j + 1, k + 6, NovaCraftBlocks.sculk_vein, 0, 2);
		world.setBlock(i + 6, j + 1, k + 6, sculk_block, 0, 2);
		world.setBlock(i + 7, j + 1, k + 6, sculk_block, 0, 2);
		world.setBlock(i + 8, j + 1, k + 6, sculk_block, 0, 2);
		world.setBlock(i + 9, j + 1, k + 6, sculk_block, 0, 2);
		world.setBlock(i + 10, j + 1, k + 6, sculk_block, 0, 2);
		world.setBlock(i + 23, j + 1, k + 6, sculk_block, 0, 2);
		world.setBlock(i + 24, j + 1, k + 6, sculk_block, 0, 2);
		world.setBlock(i + 25, j + 1, k + 6, sculk_block, 0, 2);
		world.setBlock(i + 26, j + 1, k + 6, sculk_block, 0, 2);
		world.setBlock(i + 27, j + 1, k + 6, sculk_block, 0, 2);
		world.setBlock(i + 28, j + 1, k + 6, sculk_block, 0, 2);
		world.setBlock(i + 29, j + 1, k + 6, sculk_block, 0, 2);
		world.setBlock(i + 30, j + 1, k + 6, sculk_block, 0, 2);
		world.setBlock(i + 31, j + 1, k + 6, sculk_block, 0, 2);
		world.setBlock(i + 33, j + 1, k + 6, sculk_block, 0, 2);
		world.setBlock(i + 34, j + 1, k + 6, sculk_block, 0, 2);
		world.setBlock(i + 35, j + 1, k + 6, sculk_block, 0, 2);
		world.setBlock(i + 36, j + 1, k + 6, sculk_block, 0, 2);
		world.setBlock(i + 37, j + 1, k + 6, sculk_block, 0, 2);
		world.setBlock(i + 0, j + 1, k + 7, NovaCraftBlocks.sculk_vein, 0, 2);
		world.setBlock(i + 4, j + 1, k + 7, sculk_block, 0, 2);
		world.setBlock(i + 5, j + 1, k + 7, sculk_block, 0, 2);
		world.setBlock(i + 6, j + 1, k + 7, sculk_block, 0, 2);
		world.setBlock(i + 7, j + 1, k + 7, sculk_block, 0, 2);
		world.setBlock(i + 8, j + 1, k + 7, sculk_block, 0, 2);
		world.setBlock(i + 9, j + 1, k + 7, sculk_block, 0, 2);
		world.setBlock(i + 10, j + 1, k + 7, sculk_block, 0, 2);
		world.setBlock(i + 11, j + 1, k + 7, sculk_block, 0, 2);
		world.setBlock(i + 12, j + 1, k + 7, sculk_block, 0, 2);
		world.setBlock(i + 13, j + 1, k + 7, sculk_block, 0, 2);
		world.setBlock(i + 14, j + 1, k + 7, sculk_block, 0, 2);
		world.setBlock(i + 15, j + 1, k + 7, sculk_block, 0, 2);
		world.setBlock(i + 16, j + 1, k + 7, sculk_block, 0, 2);
		world.setBlock(i + 17, j + 1, k + 7, sculk_block, 0, 2);
		world.setBlock(i + 18, j + 1, k + 7, sculk_block, 0, 2);
		world.setBlock(i + 19, j + 1, k + 7, sculk_block, 0, 2);
		world.setBlock(i + 20, j + 1, k + 7, sculk_block, 0, 2);
		world.setBlock(i + 21, j + 1, k + 7, sculk_block, 0, 2);
		world.setBlock(i + 22, j + 1, k + 7, sculk_block, 0, 2);
		world.setBlock(i + 33, j + 1, k + 7, sculk_block, 0, 2);
		world.setBlock(i + 34, j + 1, k + 7, sculk_block, 0, 2);
		world.setBlock(i + 35, j + 1, k + 7, sculk_block, 0, 2);
		world.setBlock(i + 36, j + 1, k + 7, sculk_block, 0, 2);
		world.setBlock(i + 37, j + 1, k + 7, sculk_block, 0, 2);
		world.setBlock(i + 3, j + 1, k + 8, sculk_block, 0, 2);
		world.setBlock(i + 4, j + 1, k + 8, sculk_block, 0, 2);
		world.setBlock(i + 5, j + 1, k + 8, sculk_block, 0, 2);
		world.setBlock(i + 6, j + 1, k + 8, sculk_block, 0, 2);
		world.setBlock(i + 7, j + 1, k + 8, sculk_block, 0, 2);
		world.setBlock(i + 8, j + 1, k + 8, sculk_block, 0, 2);
		world.setBlock(i + 9, j + 1, k + 8, sculk_block, 0, 2);
		world.setBlock(i + 10, j + 1, k + 8, sculk_block, 0, 2);
		world.setBlock(i + 11, j + 1, k + 8, sculk_block, 0, 2);
		world.setBlock(i + 12, j + 1, k + 8, sculk_block, 0, 2);
		world.setBlock(i + 13, j + 1, k + 8, sculk_block, 0, 2);
		world.setBlock(i + 14, j + 1, k + 8, sculk_block, 0, 2);
		world.setBlock(i + 15, j + 1, k + 8, sculk_block, 0, 2);
		world.setBlock(i + 16, j + 1, k + 8, sculk_block, 0, 2);
		world.setBlock(i + 17, j + 1, k + 8, sculk_block, 0, 2);
		world.setBlock(i + 18, j + 1, k + 8, sculk_block, 0, 2);
		world.setBlock(i + 19, j + 1, k + 8, sculk_block, 0, 2);
		world.setBlock(i + 34, j + 1, k + 8, sculk_block, 0, 2);
		world.setBlock(i + 35, j + 1, k + 8, sculk_block, 0, 2);
		world.setBlock(i + 36, j + 1, k + 8, sculk_block, 0, 2);
		world.setBlock(i + 3, j + 1, k + 9, sculk_block, 0, 2);
		world.setBlock(i + 4, j + 1, k + 9, sculk_block, 0, 2);
		world.setBlock(i + 5, j + 1, k + 9, sculk_block, 0, 2);
		world.setBlock(i + 6, j + 1, k + 9, sculk_block, 0, 2);
		world.setBlock(i + 7, j + 1, k + 9, sculk_block, 0, 2);
		world.setBlock(i + 8, j + 1, k + 9, sculk_block, 0, 2);
		world.setBlock(i + 9, j + 1, k + 9, sculk_block, 0, 2);
		world.setBlock(i + 10, j + 1, k + 9, sculk_block, 0, 2);
		world.setBlock(i + 11, j + 1, k + 9, sculk_block, 0, 2);
		world.setBlock(i + 12, j + 1, k + 9, sculk_block, 0, 2);
		world.setBlock(i + 13, j + 1, k + 9, sculk_block, 0, 2);
		world.setBlock(i + 14, j + 1, k + 9, sculk_block, 0, 2);
		world.setBlock(i + 15, j + 1, k + 9, sculk_block, 0, 2);
		world.setBlock(i + 16, j + 1, k + 9, sculk_block, 0, 2);
		world.setBlock(i + 17, j + 1, k + 9, sculk_block, 0, 2);
		world.setBlock(i + 18, j + 1, k + 9, sculk_block, 0, 2);
		world.setBlock(i + 19, j + 1, k + 9, sculk_block, 0, 2);
		world.setBlock(i + 5, j + 1, k + 10, sculk_block, 0, 2);
		world.setBlock(i + 6, j + 1, k + 10, sculk_block, 0, 2);
		world.setBlock(i + 7, j + 1, k + 10, sculk_block, 0, 2);
		world.setBlock(i + 8, j + 1, k + 10, sculk_block, 0, 2);
		world.setBlock(i + 9, j + 1, k + 10, sculk_block, 0, 2);
		world.setBlock(i + 10, j + 1, k + 10, sculk_block, 0, 2);
		world.setBlock(i + 11, j + 1, k + 10, sculk_block, 0, 2);
		world.setBlock(i + 12, j + 1, k + 10, sculk_block, 0, 2);
		world.setBlock(i + 13, j + 1, k + 10, sculk_block, 0, 2);
		world.setBlock(i + 14, j + 1, k + 10, sculk_block, 0, 2);
		world.setBlock(i + 15, j + 1, k + 10, sculk_block, 0, 2);
		world.setBlock(i + 16, j + 1, k + 10, sculk_block, 0, 2);
		world.setBlock(i + 17, j + 1, k + 10, sculk_block, 0, 2);
		world.setBlock(i + 18, j + 1, k + 10, sculk_block, 0, 2);
		world.setBlock(i + 19, j + 1, k + 10, sculk_block, 0, 2);
		world.setBlock(i + 8, j + 1, k + 11, sculk_block, 0, 2);
		world.setBlock(i + 9, j + 1, k + 11, sculk_block, 0, 2);
		world.setBlock(i + 10, j + 1, k + 11, sculk_block, 0, 2);
		world.setBlock(i + 11, j + 1, k + 11, sculk_block, 0, 2);
		world.setBlock(i + 12, j + 1, k + 11, sculk_block, 0, 2);
		world.setBlock(i + 13, j + 1, k + 11, sculk_block, 0, 2);
		world.setBlock(i + 14, j + 1, k + 11, sculk_block, 0, 2);
		world.setBlock(i + 15, j + 1, k + 11, sculk_block, 0, 2);
		world.setBlock(i + 16, j + 1, k + 11, sculk_block, 0, 2);
		world.setBlock(i + 17, j + 1, k + 11, sculk_block, 0, 2);
		world.setBlock(i + 18, j + 1, k + 11, sculk_block, 0, 2);
		world.setBlock(i + 19, j + 1, k + 11, sculk_block, 0, 2);
		world.setBlock(i + 13, j + 1, k + 12, sculk_block, 0, 2);
		world.setBlock(i + 14, j + 1, k + 12, sculk_block, 0, 2);
		world.setBlock(i + 15, j + 1, k + 12, sculk_block, 0, 2);
		world.setBlock(i + 16, j + 1, k + 12, sculk_block, 0, 2);
		world.setBlock(i + 17, j + 1, k + 12, sculk_block, 0, 2);
		world.setBlock(i + 18, j + 1, k + 12, sculk_block, 0, 2);
		world.setBlock(i + 19, j + 1, k + 12, sculk_block, 0, 2);
		world.setBlock(i + 34, j + 1, k + 19, NovaCraftBlocks.sculk_vein, 0, 2);
		world.setBlock(i + 1, j + 1, k + 20, NovaCraftBlocks.sculk_vein, 0, 2);
		world.setBlock(i + 34, j + 1, k + 20, NovaCraftBlocks.sculk_vein, 0, 2);
		world.setBlock(i + 35, j + 1, k + 20, NovaCraftBlocks.sculk_vein, 0, 2);
		world.setBlock(i + 2, j + 1, k + 21, NovaCraftBlocks.sculk_vein, 0, 2);
		world.setBlock(i + 8, j + 1, k + 22, NovaCraftBlocks.sculk_vein, 0, 2);
		world.setBlock(i + 8, j + 1, k + 23, NovaCraftBlocks.sculk_vein, 0, 2);
		world.setBlock(i + 7, j + 1, k + 27, NovaCraftBlocks.sculk_vein, 0, 2);
		world.setBlock(i + 8, j + 1, k + 28, NovaCraftBlocks.sculk_vein, 0, 2);
		world.setBlock(i + 11, j + 1, k + 29, NovaCraftBlocks.sculk_vein, 0, 2);
		world.setBlock(i + 20, j + 1, k + 32, NovaCraftBlocks.sculk_vein, 0, 2);
		world.setBlock(i + 24, j + 1, k + 32, NovaCraftBlocks.sculk_vein, 0, 2);
		world.setBlock(i + 20, j + 1, k + 33, NovaCraftBlocks.sculk_vein, 0, 2);
		world.setBlock(i + 21, j + 1, k + 33, NovaCraftBlocks.sculk_vein, 0, 2);
		world.setBlock(i + 23, j + 1, k + 33, NovaCraftBlocks.sculk_vein, 0, 2);
		world.setBlock(i + 15, j + 1, k + 39, NovaCraftBlocks.sculk_vein, 0, 2);
		world.setBlock(i + 16, j + 1, k + 39, NovaCraftBlocks.sculk_vein, 0, 2);
		world.setBlock(i + 22, j + 1, k + 39, NovaCraftBlocks.sculk_vein, 0, 2);
		world.setBlock(i + 15, j + 1, k + 40, NovaCraftBlocks.sculk_vein, 0, 2);
		world.setBlock(i + 16, j + 1, k + 40, NovaCraftBlocks.sculk_vein, 0, 2);
		world.setBlock(i + 19, j + 1, k + 40, NovaCraftBlocks.sculk_vein, 0, 2);
		world.setBlock(i + 18, j + 1, k + 41, NovaCraftBlocks.sculk_vein, 0, 2);
		world.setBlock(i + 19, j + 1, k + 41, NovaCraftBlocks.sculk_vein, 0, 2);
		world.setBlock(i + 28, j + 1, k + 41, NovaCraftBlocks.sculk_vein, 0, 2);
		world.setBlock(i + 31, j + 2, k + 4, sculk_block, 0, 2);
		world.setBlock(i + 32, j + 2, k + 4, sculk_block, 0, 2);
		world.setBlock(i + 33, j + 2, k + 4, sculk_block, 0, 2);
		world.setBlock(i + 34, j + 2, k + 4, sculk_block, 0, 2);
		world.setBlock(i + 35, j + 2, k + 4, sculk_block, 0, 2);
		world.setBlock(i + 36, j + 2, k + 4, sculk_block, 0, 2);
		world.setBlock(i + 37, j + 2, k + 4, sculk_block, 0, 2);
		world.setBlock(i + 38, j + 2, k + 4, sculk_block, 0, 2);
		world.setBlock(i + 39, j + 2, k + 4, sculk_block, 0, 2);
		world.setBlock(i + 40, j + 2, k + 4, sculk_block, 0, 2);
		world.setBlock(i + 32, j + 2, k + 5, sculk_block, 0, 2);
		world.setBlock(i + 33, j + 2, k + 5, sculk_block, 0, 2);
		world.setBlock(i + 34, j + 2, k + 5, sculk_block, 0, 2);
		world.setBlock(i + 35, j + 2, k + 5, sculk_block, 0, 2);
		world.setBlock(i + 36, j + 2, k + 5, sculk_block, 0, 2);
		world.setBlock(i + 37, j + 2, k + 5, sculk_block, 0, 2);
		world.setBlock(i + 38, j + 2, k + 5, sculk_block, 0, 2);
		world.setBlock(i + 39, j + 2, k + 5, sculk_block, 0, 2);
		world.setBlock(i + 40, j + 2, k + 5, sculk_block, 0, 2);
		world.setBlock(i + 41, j + 2, k + 5, sculk_block, 0, 2);
		world.setBlock(i + 42, j + 2, k + 5, sculk_block, 0, 2);
		world.setBlock(i + 32, j + 2, k + 6, sculk_block, 0, 2);
		world.setBlock(i + 33, j + 2, k + 6, sculk_block, 0, 2);
		world.setBlock(i + 34, j + 2, k + 6, sculk_block, 0, 2);
		world.setBlock(i + 35, j + 2, k + 6, sculk_block, 0, 2);
		world.setBlock(i + 36, j + 2, k + 6, sculk_block, 0, 2);
		world.setBlock(i + 37, j + 2, k + 6, sculk_block, 0, 2);
		world.setBlock(i + 38, j + 2, k + 6, sculk_block, 0, 2);
		world.setBlock(i + 39, j + 2, k + 6, sculk_block, 0, 2);
		world.setBlock(i + 40, j + 2, k + 6, sculk_block, 0, 2);
		world.setBlock(i + 41, j + 2, k + 6, sculk_block, 0, 2);
		world.setBlock(i + 15, j + 2, k + 7, NovaCraftBlocks.sculk_tentacle_2, 1, 2);
		world.setBlock(i + 23, j + 2, k + 7, sculk_block, 0, 2);
		world.setBlock(i + 24, j + 2, k + 7, sculk_block, 0, 2);
		world.setBlock(i + 25, j + 2, k + 7, sculk_block, 0, 2);
		world.setBlock(i + 26, j + 2, k + 7, sculk_block, 0, 2);
		world.setBlock(i + 27, j + 2, k + 7, sculk_block, 0, 2);
		world.setBlock(i + 28, j + 2, k + 7, sculk_block, 0, 2);
		world.setBlock(i + 29, j + 2, k + 7, sculk_block, 0, 2);
		world.setBlock(i + 30, j + 2, k + 7, sculk_block, 0, 2);
		world.setBlock(i + 31, j + 2, k + 7, sculk_block, 0, 2);
		world.setBlock(i + 32, j + 2, k + 7, sculk_block, 0, 2);
		world.setBlock(i + 33, j + 2, k + 7, sculk_block, 0, 2);
		world.setBlock(i + 34, j + 2, k + 7, sculk_block, 0, 2);
		world.setBlock(i + 35, j + 2, k + 7, sculk_block, 0, 2);
		world.setBlock(i + 36, j + 2, k + 7, sculk_block, 0, 2);
		world.setBlock(i + 37, j + 2, k + 7, sculk_block, 0, 2);
		world.setBlock(i + 38, j + 2, k + 7, sculk_block, 0, 2);
		world.setBlock(i + 39, j + 2, k + 7, sculk_block, 0, 2);
		world.setBlock(i + 40, j + 2, k + 7, sculk_block, 0, 2);
		world.setBlock(i + 20, j + 2, k + 8, sculk_block, 0, 2);
		world.setBlock(i + 21, j + 2, k + 8, sculk_block, 0, 2);
		world.setBlock(i + 22, j + 2, k + 8, sculk_block, 0, 2);
		world.setBlock(i + 23, j + 2, k + 8, sculk_block, 0, 2);
		world.setBlock(i + 24, j + 2, k + 8, sculk_block, 0, 2);
		world.setBlock(i + 25, j + 2, k + 8, sculk_block, 0, 2);
		world.setBlock(i + 26, j + 2, k + 8, sculk_block, 0, 2);
		world.setBlock(i + 27, j + 2, k + 8, sculk_block, 0, 2);
		world.setBlock(i + 28, j + 2, k + 8, sculk_block, 0, 2);
		world.setBlock(i + 29, j + 2, k + 8, sculk_block, 0, 2);
		world.setBlock(i + 30, j + 2, k + 8, sculk_block, 0, 2);
		world.setBlock(i + 31, j + 2, k + 8, sculk_block, 0, 2);
		world.setBlock(i + 32, j + 2, k + 8, sculk_block, 0, 2);
		world.setBlock(i + 33, j + 2, k + 8, sculk_block, 0, 2);
		world.setBlock(i + 34, j + 2, k + 8, sculk_block, 0, 2);
		world.setBlock(i + 35, j + 2, k + 8, sculk_block, 0, 2);
		world.setBlock(i + 36, j + 2, k + 8, sculk_block, 0, 2);
		world.setBlock(i + 37, j + 2, k + 8, sculk_block, 0, 2);
		world.setBlock(i + 38, j + 2, k + 8, sculk_block, 0, 2);
		world.setBlock(i + 39, j + 2, k + 8, sculk_block, 0, 2);
		world.setBlock(i + 2, j + 2, k + 9, sculk_block, 0, 2);
		world.setBlock(i + 7, j + 2, k + 9, NovaCraftBlocks.sculk_vein, 1, 2);
		world.setBlock(i + 20, j + 2, k + 9, sculk_block, 0, 2);
		world.setBlock(i + 21, j + 2, k + 9, sculk_block, 0, 2);
		world.setBlock(i + 22, j + 2, k + 9, sculk_block, 0, 2);
		world.setBlock(i + 23, j + 2, k + 9, sculk_block, 0, 2);
		world.setBlock(i + 24, j + 2, k + 9, sculk_block, 0, 2);
		world.setBlock(i + 25, j + 2, k + 9, sculk_block, 0, 2);
		world.setBlock(i + 26, j + 2, k + 9, sculk_block, 0, 2);
		world.setBlock(i + 27, j + 2, k + 9, sculk_block, 0, 2);
		world.setBlock(i + 28, j + 2, k + 9, sculk_block, 0, 2);
		world.setBlock(i + 29, j + 2, k + 9, sculk_block, 0, 2);
		world.setBlock(i + 30, j + 2, k + 9, sculk_block, 0, 2);
		world.setBlock(i + 31, j + 2, k + 9, sculk_block, 0, 2);
		world.setBlock(i + 32, j + 2, k + 9, sculk_block, 0, 2);
		world.setBlock(i + 33, j + 2, k + 9, sculk_block, 0, 2);
		world.setBlock(i + 34, j + 2, k + 9, sculk_block, 0, 2);
		world.setBlock(i + 35, j + 2, k + 9, sculk_block, 0, 2);
		world.setBlock(i + 36, j + 2, k + 9, sculk_block, 0, 2);
		world.setBlock(i + 37, j + 2, k + 9, sculk_block, 0, 2);
		world.setBlock(i + 38, j + 2, k + 9, sculk_block, 0, 2);
		world.setBlock(i + 39, j + 2, k + 9, sculk_block, 0, 2);
		world.setBlock(i + 40, j + 2, k + 9, sculk_block, 0, 2);
		world.setBlock(i + 2, j + 2, k + 10, sculk_block, 0, 2);
		world.setBlock(i + 3, j + 2, k + 10, sculk_block, 0, 2);
		world.setBlock(i + 4, j + 2, k + 10, sculk_block, 0, 2);
		world.setBlock(i + 14, j + 2, k + 10, NovaCraftBlocks.sculk_vein, 1, 2);
		world.setBlock(i + 20, j + 2, k + 10, sculk_block, 0, 2);
		world.setBlock(i + 21, j + 2, k + 10, sculk_block, 0, 2);
		world.setBlock(i + 22, j + 2, k + 10, sculk_block, 0, 2);
		world.setBlock(i + 23, j + 2, k + 10, sculk_block, 0, 2);
		world.setBlock(i + 24, j + 2, k + 10, sculk_block, 0, 2);
		world.setBlock(i + 25, j + 2, k + 10, sculk_block, 0, 2);
		world.setBlock(i + 26, j + 2, k + 10, sculk_block, 0, 2);
		world.setBlock(i + 27, j + 2, k + 10, sculk_block, 0, 2);
		world.setBlock(i + 28, j + 2, k + 10, sculk_block, 0, 2);
		world.setBlock(i + 29, j + 2, k + 10, sculk_block, 0, 2);
		world.setBlock(i + 30, j + 2, k + 10, sculk_block, 0, 2);
		world.setBlock(i + 31, j + 2, k + 10, sculk_block, 0, 2);
		world.setBlock(i + 32, j + 2, k + 10, sculk_block, 0, 2);
		world.setBlock(i + 33, j + 2, k + 10, sculk_block, 0, 2);
		world.setBlock(i + 34, j + 2, k + 10, sculk_block, 0, 2);
		world.setBlock(i + 35, j + 2, k + 10, sculk_block, 0, 2);
		world.setBlock(i + 36, j + 2, k + 10, sculk_block, 0, 2);
		world.setBlock(i + 37, j + 2, k + 10, sculk_block, 0, 2);
		world.setBlock(i + 38, j + 2, k + 10, sculk_block, 0, 2);
		world.setBlock(i + 39, j + 2, k + 10, sculk_block, 0, 2);
		world.setBlock(i + 40, j + 2, k + 10, sculk_block, 0, 2);
		world.setBlock(i + 1, j + 2, k + 11, sculk_block, 0, 2);
		world.setBlock(i + 2, j + 2, k + 11, sculk_block, 0, 2);
		world.setBlock(i + 3, j + 2, k + 11, sculk_block, 0, 2);
		world.setBlock(i + 4, j + 2, k + 11, sculk_block, 0, 2);
		world.setBlock(i + 5, j + 2, k + 11, sculk_block, 0, 2);
		world.setBlock(i + 6, j + 2, k + 11, sculk_block, 0, 2);
		world.setBlock(i + 7, j + 2, k + 11, sculk_block, 0, 2);
		world.setBlock(i + 20, j + 2, k + 11, sculk_block, 0, 2);
		world.setBlock(i + 21, j + 2, k + 11, sculk_block, 0, 2);
		world.setBlock(i + 22, j + 2, k + 11, sculk_block, 0, 2);
		world.setBlock(i + 23, j + 2, k + 11, sculk_block, 0, 2);
		world.setBlock(i + 24, j + 2, k + 11, sculk_block, 0, 2);
		world.setBlock(i + 25, j + 2, k + 11, sculk_block, 0, 2);
		world.setBlock(i + 26, j + 2, k + 11, sculk_block, 0, 2);
		world.setBlock(i + 27, j + 2, k + 11, sculk_block, 0, 2);
		world.setBlock(i + 28, j + 2, k + 11, sculk_block, 0, 2);
		world.setBlock(i + 29, j + 2, k + 11, sculk_block, 0, 2);
		world.setBlock(i + 30, j + 2, k + 11, sculk_block, 0, 2);
		world.setBlock(i + 31, j + 2, k + 11, sculk_block, 0, 2);
		world.setBlock(i + 32, j + 2, k + 11, sculk_block, 0, 2);
		world.setBlock(i + 33, j + 2, k + 11, sculk_block, 0, 2);
		world.setBlock(i + 34, j + 2, k + 11, sculk_block, 0, 2);
		world.setBlock(i + 35, j + 2, k + 11, sculk_block, 0, 2);
		world.setBlock(i + 36, j + 2, k + 11, sculk_block, 0, 2);
		world.setBlock(i + 37, j + 2, k + 11, sculk_block, 0, 2);
		world.setBlock(i + 38, j + 2, k + 11, sculk_block, 0, 2);
		world.setBlock(i + 39, j + 2, k + 11, sculk_block, 0, 2);
		world.setBlock(i + 0, j + 2, k + 12, sculk_block, 0, 2);
		world.setBlock(i + 1, j + 2, k + 12, sculk_block, 0, 2);
		world.setBlock(i + 2, j + 2, k + 12, sculk_block, 0, 2);
		world.setBlock(i + 3, j + 2, k + 12, sculk_block, 0, 2);
		world.setBlock(i + 4, j + 2, k + 12, sculk_block, 0, 2);
		world.setBlock(i + 5, j + 2, k + 12, sculk_block, 0, 2);
		world.setBlock(i + 6, j + 2, k + 12, sculk_block, 0, 2);
		world.setBlock(i + 7, j + 2, k + 12, sculk_block, 0, 2);
		world.setBlock(i + 8, j + 2, k + 12, sculk_block, 0, 2);
		world.setBlock(i + 9, j + 2, k + 12, sculk_block, 0, 2);
		world.setBlock(i + 10, j + 2, k + 12, sculk_block, 0, 2);
		world.setBlock(i + 11, j + 2, k + 12, sculk_block, 0, 2);
		world.setBlock(i + 12, j + 2, k + 12, sculk_block, 0, 2);
		world.setBlock(i + 19, j + 2, k + 12, sculk_block, 0, 2);
		world.setBlock(i + 20, j + 2, k + 12, sculk_block, 0, 2);
		world.setBlock(i + 1, j + 2, k + 13, sculk_block, 0, 2);
		world.setBlock(i + 2, j + 2, k + 13, sculk_block, 0, 2);
		world.setBlock(i + 3, j + 2, k + 13, sculk_block, 0, 2);
		world.setBlock(i + 4, j + 2, k + 13, sculk_block, 0, 2);
		world.setBlock(i + 5, j + 2, k + 13, sculk_block, 0, 2);
		world.setBlock(i + 6, j + 2, k + 13, sculk_block, 0, 2);
		world.setBlock(i + 7, j + 2, k + 13, sculk_block, 0, 2);
		world.setBlock(i + 8, j + 2, k + 13, sculk_block, 0, 2);
		world.setBlock(i + 9, j + 2, k + 13, sculk_block, 0, 2);
		world.setBlock(i + 10, j + 2, k + 13, sculk_block, 0, 2);
		world.setBlock(i + 11, j + 2, k + 13, sculk_block, 0, 2);
		world.setBlock(i + 12, j + 2, k + 13, sculk_block, 0, 2);
		world.setBlock(i + 13, j + 2, k + 13, sculk_block, 0, 2);
		world.setBlock(i + 14, j + 2, k + 13, sculk_block, 0, 2);
		world.setBlock(i + 15, j + 2, k + 13, sculk_block, 0, 2);
		world.setBlock(i + 16, j + 2, k + 13, sculk_block, 0, 2);
		world.setBlock(i + 17, j + 2, k + 13, sculk_block, 0, 2);
		world.setBlock(i + 18, j + 2, k + 13, sculk_block, 0, 2);
		world.setBlock(i + 19, j + 2, k + 13, sculk_block, 0, 2);
		world.setBlock(i + 4, j + 2, k + 14, sculk_block, 0, 2);
		world.setBlock(i + 5, j + 2, k + 14, sculk_block, 0, 2);
		world.setBlock(i + 6, j + 2, k + 14, sculk_block, 0, 2);
		world.setBlock(i + 7, j + 2, k + 14, sculk_block, 0, 2);
		world.setBlock(i + 8, j + 2, k + 14, sculk_block, 0, 2);
		world.setBlock(i + 9, j + 2, k + 14, sculk_block, 0, 2);
		world.setBlock(i + 10, j + 2, k + 14, sculk_block, 0, 2);
		world.setBlock(i + 11, j + 2, k + 14, sculk_block, 0, 2);
		world.setBlock(i + 12, j + 2, k + 14, sculk_block, 0, 2);
		world.setBlock(i + 13, j + 2, k + 14, sculk_block, 0, 2);
		world.setBlock(i + 14, j + 2, k + 14, sculk_block, 0, 2);
		world.setBlock(i + 15, j + 2, k + 14, sculk_block, 0, 2);
		world.setBlock(i + 16, j + 2, k + 14, sculk_block, 0, 2);
		world.setBlock(i + 17, j + 2, k + 14, sculk_block, 0, 2);
		world.setBlock(i + 18, j + 2, k + 14, sculk_block, 0, 2);
		world.setBlock(i + 19, j + 2, k + 14, sculk_block, 0, 2);
		world.setBlock(i + 6, j + 2, k + 15, sculk_block, 0, 2);
		world.setBlock(i + 7, j + 2, k + 15, sculk_block, 0, 2);
		world.setBlock(i + 8, j + 2, k + 15, sculk_block, 0, 2);
		world.setBlock(i + 9, j + 2, k + 15, sculk_block, 0, 2);
		world.setBlock(i + 10, j + 2, k + 15, sculk_block, 0, 2);
		world.setBlock(i + 11, j + 2, k + 15, sculk_block, 0, 2);
		world.setBlock(i + 12, j + 2, k + 15, sculk_block, 0, 2);
		world.setBlock(i + 13, j + 2, k + 15, sculk_block, 0, 2);
		world.setBlock(i + 14, j + 2, k + 15, sculk_block, 0, 2);
		world.setBlock(i + 15, j + 2, k + 15, sculk_block, 0, 2);
		world.setBlock(i + 16, j + 2, k + 15, sculk_block, 0, 2);
		world.setBlock(i + 17, j + 2, k + 15, sculk_block, 0, 2);
		world.setBlock(i + 18, j + 2, k + 15, sculk_block, 0, 2);
		world.setBlock(i + 19, j + 2, k + 15, sculk_block, 0, 2);
		world.setBlock(i + 44, j + 2, k + 15, NovaCraftBlocks.sculk_vein, 0, 2);
		world.setBlock(i + 11, j + 2, k + 16, sculk_block, 0, 2);
		world.setBlock(i + 12, j + 2, k + 16, sculk_block, 0, 2);
		world.setBlock(i + 13, j + 2, k + 16, sculk_block, 0, 2);
		world.setBlock(i + 14, j + 2, k + 16, sculk_block, 0, 2);
		world.setBlock(i + 15, j + 2, k + 16, sculk_block, 0, 2);
		world.setBlock(i + 16, j + 2, k + 16, sculk_block, 0, 2);
		world.setBlock(i + 17, j + 2, k + 16, sculk_block, 0, 2);
		world.setBlock(i + 18, j + 2, k + 16, sculk_block, 0, 2);
		world.setBlock(i + 19, j + 2, k + 16, sculk_block, 0, 2);
		world.setBlock(i + 44, j + 2, k + 16, NovaCraftBlocks.sculk_vein, 0, 2);
		world.setBlock(i + 34, j + 2, k + 19, NovaCraftBlocks.sculk_vein, 0, 2);
		world.setBlock(i + 1, j + 2, k + 20, NovaCraftBlocks.sculk_vein, 0, 2);
		world.setBlock(i + 2, j + 2, k + 21, NovaCraftBlocks.sculk_vein, 0, 2);
		world.setBlock(i + 18, j + 2, k + 22, NovaCraftBlocks.sculk_vein, 0, 2);
		world.setBlock(i + 2, j + 2, k + 28, NovaCraftBlocks.sculk_vein, 0, 2);
		world.setBlock(i + 19, j + 2, k + 40, NovaCraftBlocks.sculk_vein, 0, 2);
		world.setBlock(i + 18, j + 2, k + 41, NovaCraftBlocks.sculk_vein, 0, 2);
		world.setBlock(i + 19, j + 2, k + 41, NovaCraftBlocks.sculk_vein, 0, 2);
		world.setBlock(i + 35, j + 3, k + 4, NovaCraftBlocks.sculk_tentacle_2, 1, 2);
		world.setBlock(i + 38, j + 3, k + 6, NovaCraftBlocks.sculk_vein, 1, 2);
		world.setBlock(i + 42, j + 3, k + 6, sculk_block, 0, 2);
		world.setBlock(i + 43, j + 3, k + 6, sculk_block, 0, 2);
		world.setBlock(i + 41, j + 3, k + 7, sculk_block, 0, 2);
		world.setBlock(i + 42, j + 3, k + 7, sculk_block, 0, 2);
		world.setBlock(i + 43, j + 3, k + 7, sculk_block, 0, 2);
		world.setBlock(i + 44, j + 3, k + 7, sculk_block, 0, 2);
		world.setBlock(i + 28, j + 3, k + 8, NovaCraftBlocks.sculk_tentacle_2, 1, 2);
		world.setBlock(i + 40, j + 3, k + 8, sculk_block, 0, 2);
		world.setBlock(i + 41, j + 3, k + 8, sculk_block, 0, 2);
		world.setBlock(i + 42, j + 3, k + 8, sculk_block, 0, 2);
		world.setBlock(i + 43, j + 3, k + 8, sculk_block, 0, 2);
		world.setBlock(i + 44, j + 3, k + 8, sculk_block, 0, 2);
		world.setBlock(i + 22, j + 3, k + 9, NovaCraftBlocks.sculk_tentacle_2, 1, 2);
		world.setBlock(i + 31, j + 3, k + 9, sculk_tulip, 0, 2);
		world.setBlock(i + 33, j + 3, k + 9, NovaCraftBlocks.sculk_vein, 1, 2);
		world.setBlock(i + 41, j + 3, k + 9, sculk_block, 0, 2);
		world.setBlock(i + 42, j + 3, k + 9, sculk_block, 0, 2);
		world.setBlock(i + 43, j + 3, k + 9, sculk_block, 0, 2);
		world.setBlock(i + 41, j + 3, k + 10, sculk_block, 0, 2);
		world.setBlock(i + 42, j + 3, k + 10, sculk_block, 0, 2);
		world.setBlock(i + 39, j + 3, k + 11, NovaCraftBlocks.sculk_tentacle_2, 1, 2);
		world.setBlock(i + 40, j + 3, k + 11, sculk_block, 0, 2);
		world.setBlock(i + 41, j + 3, k + 11, sculk_block, 0, 2);
		world.setBlock(i + 5, j + 3, k + 12, sculk_tulip, 0, 2);
		world.setBlock(i + 9, j + 3, k + 12, NovaCraftBlocks.sculk_tentacle_2, 1, 2);
		world.setBlock(i + 20, j + 3, k + 12, sculk_block, 0, 2);
		world.setBlock(i + 21, j + 3, k + 12, sculk_block, 0, 2);
		world.setBlock(i + 22, j + 3, k + 12, sculk_block, 0, 2);
		world.setBlock(i + 23, j + 3, k + 12, sculk_block, 0, 2);
		world.setBlock(i + 24, j + 3, k + 12, sculk_block, 0, 2);
		world.setBlock(i + 25, j + 3, k + 12, sculk_block, 0, 2);
		world.setBlock(i + 26, j + 3, k + 12, sculk_block, 0, 2);
		world.setBlock(i + 27, j + 3, k + 12, sculk_block, 0, 2);
		world.setBlock(i + 28, j + 3, k + 12, sculk_block, 0, 2);
		world.setBlock(i + 29, j + 3, k + 12, sculk_block, 0, 2);
		world.setBlock(i + 30, j + 3, k + 12, sculk_block, 0, 2);
		world.setBlock(i + 31, j + 3, k + 12, sculk_block, 0, 2);
		world.setBlock(i + 32, j + 3, k + 12, sculk_block, 0, 2);
		world.setBlock(i + 33, j + 3, k + 12, sculk_block, 0, 2);
		world.setBlock(i + 34, j + 3, k + 12, sculk_block, 0, 2);
		world.setBlock(i + 35, j + 3, k + 12, sculk_block, 0, 2);
		world.setBlock(i + 36, j + 3, k + 12, sculk_block, 0, 2);
		world.setBlock(i + 37, j + 3, k + 12, sculk_block, 0, 2);
		world.setBlock(i + 38, j + 3, k + 12, sculk_block, 0, 2);
		world.setBlock(i + 39, j + 3, k + 12, sculk_block, 0, 2);
		world.setBlock(i + 40, j + 3, k + 12, sculk_block, 0, 2);
		world.setBlock(i + 41, j + 3, k + 12, sculk_block, 0, 2);
		world.setBlock(i + 0, j + 3, k + 13, sculk_block, 0, 2);
		world.setBlock(i + 20, j + 3, k + 13, sculk_block, 0, 2);
		world.setBlock(i + 21, j + 3, k + 13, sculk_block, 0, 2);
		world.setBlock(i + 22, j + 3, k + 13, sculk_block, 0, 2);
		world.setBlock(i + 23, j + 3, k + 13, sculk_block, 0, 2);
		world.setBlock(i + 24, j + 3, k + 13, sculk_block, 0, 2);
		world.setBlock(i + 25, j + 3, k + 13, sculk_block, 0, 2);
		world.setBlock(i + 26, j + 3, k + 13, sculk_block, 0, 2);
		world.setBlock(i + 32, j + 3, k + 13, sculk_block, 0, 2);
		world.setBlock(i + 33, j + 3, k + 13, sculk_block, 0, 2);
		world.setBlock(i + 34, j + 3, k + 13, sculk_block, 0, 2);
		world.setBlock(i + 44, j + 3, k + 13, NovaCraftBlocks.sculk_vein, 0, 2);
		world.setBlock(i + 1, j + 3, k + 14, sculk_block, 0, 2);
		world.setBlock(i + 2, j + 3, k + 14, sculk_block, 0, 2);
		world.setBlock(i + 3, j + 3, k + 14, sculk_block, 0, 2);
		world.setBlock(i + 4, j + 3, k + 14, NovaCraftBlocks.sculk_vein, 1, 2);
		world.setBlock(i + 20, j + 3, k + 14, sculk_block, 0, 2);
		world.setBlock(i + 21, j + 3, k + 14, sculk_block, 0, 2);
		world.setBlock(i + 22, j + 3, k + 14, sculk_block, 0, 2);
		world.setBlock(i + 23, j + 3, k + 14, sculk_block, 0, 2);
		world.setBlock(i + 24, j + 3, k + 14, sculk_block, 0, 2);
		world.setBlock(i + 25, j + 3, k + 14, sculk_block, 0, 2);
		world.setBlock(i + 26, j + 3, k + 14, sculk_block, 0, 2);
		world.setBlock(i + 44, j + 3, k + 14, NovaCraftBlocks.sculk_vein, 0, 2);
		world.setBlock(i + 3, j + 3, k + 15, sculk_block, 0, 2);
		world.setBlock(i + 4, j + 3, k + 15, sculk_block, 0, 2);
		world.setBlock(i + 5, j + 3, k + 15, sculk_block, 0, 2);
		world.setBlock(i + 20, j + 3, k + 15, sculk_block, 0, 2);
		world.setBlock(i + 21, j + 3, k + 15, sculk_block, 0, 2);
		world.setBlock(i + 22, j + 3, k + 15, sculk_block, 0, 2);
		world.setBlock(i + 23, j + 3, k + 15, sculk_block, 0, 2);
		world.setBlock(i + 24, j + 3, k + 15, sculk_block, 0, 2);
		world.setBlock(i + 25, j + 3, k + 15, sculk_block, 0, 2);
		world.setBlock(i + 26, j + 3, k + 15, sculk_block, 0, 2);
		world.setBlock(i + 27, j + 3, k + 15, sculk_block, 0, 2);
		world.setBlock(i + 28, j + 3, k + 15, sculk_block, 0, 2);
		world.setBlock(i + 3, j + 3, k + 16, sculk_block, 0, 2);
		world.setBlock(i + 4, j + 3, k + 16, sculk_block, 0, 2);
		world.setBlock(i + 5, j + 3, k + 16, sculk_block, 0, 2);
		world.setBlock(i + 6, j + 3, k + 16, sculk_block, 0, 2);
		world.setBlock(i + 7, j + 3, k + 16, sculk_block, 0, 2);
		world.setBlock(i + 8, j + 3, k + 16, sculk_block, 0, 2);
		world.setBlock(i + 9, j + 3, k + 16, sculk_block, 0, 2);
		world.setBlock(i + 10, j + 3, k + 16, sculk_block, 0, 2);
		world.setBlock(i + 19, j + 3, k + 16, NovaCraftBlocks.sculk_tentacle_2, 1, 2);
		world.setBlock(i + 20, j + 3, k + 16, sculk_block, 0, 2);
		world.setBlock(i + 21, j + 3, k + 16, sculk_block, 0, 2);
		world.setBlock(i + 22, j + 3, k + 16, sculk_block, 0, 2);
		world.setBlock(i + 23, j + 3, k + 16, sculk_block, 0, 2);
		world.setBlock(i + 24, j + 3, k + 16, sculk_block, 0, 2);
		world.setBlock(i + 25, j + 3, k + 16, sculk_block, 0, 2);
		world.setBlock(i + 26, j + 3, k + 16, sculk_block, 0, 2);
		world.setBlock(i + 27, j + 3, k + 16, sculk_block, 0, 2);
		world.setBlock(i + 28, j + 3, k + 16, sculk_block, 0, 2);
		world.setBlock(i + 29, j + 3, k + 16, sculk_block, 0, 2);
		world.setBlock(i + 30, j + 3, k + 16, sculk_block, 0, 2);
		world.setBlock(i + 3, j + 3, k + 17, sculk_block, 0, 2);
		world.setBlock(i + 4, j + 3, k + 17, sculk_block, 0, 2);
		world.setBlock(i + 5, j + 3, k + 17, sculk_block, 0, 2);
		world.setBlock(i + 6, j + 3, k + 17, sculk_block, 0, 2);
		world.setBlock(i + 7, j + 3, k + 17, sculk_block, 0, 2);
		world.setBlock(i + 8, j + 3, k + 17, sculk_block, 0, 2);
		world.setBlock(i + 9, j + 3, k + 17, sculk_block, 0, 2);
		world.setBlock(i + 10, j + 3, k + 17, sculk_block, 0, 2);
		world.setBlock(i + 11, j + 3, k + 17, sculk_block, 0, 2);
		world.setBlock(i + 12, j + 3, k + 17, sculk_block, 0, 2);
		world.setBlock(i + 13, j + 3, k + 17, sculk_block, 0, 2);
		world.setBlock(i + 14, j + 3, k + 17, sculk_block, 0, 2);
		world.setBlock(i + 15, j + 3, k + 17, sculk_block, 0, 2);
		world.setBlock(i + 16, j + 3, k + 17, sculk_block, 0, 2);
		world.setBlock(i + 17, j + 3, k + 17, sculk_block, 0, 2);
		world.setBlock(i + 18, j + 3, k + 17, sculk_block, 0, 2);
		world.setBlock(i + 19, j + 3, k + 17, sculk_block, 0, 2);
		world.setBlock(i + 20, j + 3, k + 17, sculk_block, 0, 2);
		world.setBlock(i + 21, j + 3, k + 17, sculk_block, 0, 2);
		world.setBlock(i + 22, j + 3, k + 17, sculk_block, 0, 2);
		world.setBlock(i + 23, j + 3, k + 17, sculk_block, 0, 2);
		world.setBlock(i + 24, j + 3, k + 17, sculk_block, 0, 2);
		world.setBlock(i + 25, j + 3, k + 17, sculk_block, 0, 2);
		world.setBlock(i + 26, j + 3, k + 17, sculk_block, 0, 2);
		world.setBlock(i + 27, j + 3, k + 17, sculk_block, 0, 2);
		world.setBlock(i + 28, j + 3, k + 17, sculk_block, 0, 2);
		world.setBlock(i + 29, j + 3, k + 17, sculk_block, 0, 2);
		world.setBlock(i + 30, j + 3, k + 17, sculk_block, 0, 2);
		world.setBlock(i + 4, j + 3, k + 18, sculk_block, 0, 2);
		world.setBlock(i + 5, j + 3, k + 18, sculk_block, 0, 2);
		world.setBlock(i + 6, j + 3, k + 18, sculk_block, 0, 2);
		world.setBlock(i + 7, j + 3, k + 18, sculk_block, 0, 2);
		world.setBlock(i + 8, j + 3, k + 18, sculk_block, 0, 2);
		world.setBlock(i + 9, j + 3, k + 18, sculk_block, 0, 2);
		world.setBlock(i + 10, j + 3, k + 18, sculk_block, 0, 2);
		world.setBlock(i + 11, j + 3, k + 18, sculk_block, 0, 2);
		world.setBlock(i + 12, j + 3, k + 18, sculk_block, 0, 2);
		world.setBlock(i + 13, j + 3, k + 18, sculk_block, 0, 2);
		world.setBlock(i + 14, j + 3, k + 18, sculk_block, 0, 2);
		world.setBlock(i + 15, j + 3, k + 18, sculk_block, 0, 2);
		world.setBlock(i + 16, j + 3, k + 18, sculk_block, 0, 2);
		world.setBlock(i + 17, j + 3, k + 18, sculk_block, 0, 2);
		world.setBlock(i + 18, j + 3, k + 18, sculk_block, 0, 2);
		world.setBlock(i + 19, j + 3, k + 18, sculk_block, 0, 2);
		world.setBlock(i + 20, j + 3, k + 18, sculk_block, 0, 2);
		world.setBlock(i + 21, j + 3, k + 18, sculk_block, 0, 2);
		world.setBlock(i + 22, j + 3, k + 18, sculk_block, 0, 2);
		world.setBlock(i + 23, j + 3, k + 18, sculk_block, 0, 2);
		world.setBlock(i + 24, j + 3, k + 18, sculk_block, 0, 2);
		world.setBlock(i + 25, j + 3, k + 18, sculk_block, 0, 2);
		world.setBlock(i + 26, j + 3, k + 18, sculk_block, 0, 2);
		world.setBlock(i + 27, j + 3, k + 18, sculk_block, 0, 2);
		world.setBlock(i + 28, j + 3, k + 18, sculk_block, 0, 2);
		world.setBlock(i + 8, j + 3, k + 19, sculk_block, 0, 2);
		world.setBlock(i + 9, j + 3, k + 19, sculk_block, 0, 2);
		world.setBlock(i + 10, j + 3, k + 19, sculk_block, 0, 2);
		world.setBlock(i + 11, j + 3, k + 19, sculk_block, 0, 2);
		world.setBlock(i + 12, j + 3, k + 19, sculk_block, 0, 2);
		world.setBlock(i + 13, j + 3, k + 19, sculk_block, 0, 2);
		world.setBlock(i + 14, j + 3, k + 19, sculk_block, 0, 2);
		world.setBlock(i + 15, j + 3, k + 19, sculk_block, 0, 2);
		world.setBlock(i + 16, j + 3, k + 19, sculk_block, 0, 2);
		world.setBlock(i + 17, j + 3, k + 19, sculk_block, 0, 2);
		world.setBlock(i + 18, j + 3, k + 19, sculk_block, 0, 2);
		world.setBlock(i + 19, j + 3, k + 19, sculk_block, 0, 2);
		world.setBlock(i + 20, j + 3, k + 19, sculk_block, 0, 2);
		world.setBlock(i + 21, j + 3, k + 19, sculk_block, 0, 2);
		world.setBlock(i + 22, j + 3, k + 19, sculk_block, 0, 2);
		world.setBlock(i + 23, j + 3, k + 19, sculk_block, 0, 2);
		world.setBlock(i + 24, j + 3, k + 19, sculk_block, 0, 2);
		world.setBlock(i + 42, j + 3, k + 21, NovaCraftBlocks.sculk_vein, 0, 2);
		world.setBlock(i + 18, j + 3, k + 22, NovaCraftBlocks.sculk_vein, 0, 2);
		world.setBlock(i + 17, j + 3, k + 23, NovaCraftBlocks.sculk_vein, 0, 2);
		world.setBlock(i + 40, j + 3, k + 25, NovaCraftBlocks.sculk_vein, 0, 2);
		world.setBlock(i + 1, j + 3, k + 27, NovaCraftBlocks.sculk_vein, 0, 2);
		world.setBlock(i + 2, j + 3, k + 27, NovaCraftBlocks.sculk_vein, 0, 2);
		world.setBlock(i + 1, j + 3, k + 28, NovaCraftBlocks.sculk_vein, 0, 2);
		world.setBlock(i + 2, j + 3, k + 28, NovaCraftBlocks.sculk_vein, 0, 2);
		world.setBlock(i + 25, j + 3, k + 32, NovaCraftBlocks.sculk_vein, 0, 2);
		world.setBlock(i + 42, j + 4, k + 8, NovaCraftBlocks.sculk_vein, 1, 2);
		world.setBlock(i + 44, j + 4, k + 9, sculk_block, 0, 2);
		world.setBlock(i + 43, j + 4, k + 10, sculk_block, 0, 2);
		world.setBlock(i + 42, j + 4, k + 11, sculk_block, 0, 2);
		world.setBlock(i + 23, j + 4, k + 12, NovaCraftBlocks.sculk_vein, 1, 2);
		world.setBlock(i + 42, j + 4, k + 12, sculk_block, 0, 2);
		world.setBlock(i + 27, j + 4, k + 13, sculk_block, 0, 2);
		world.setBlock(i + 28, j + 4, k + 13, sculk_block, 0, 2);
		world.setBlock(i + 29, j + 4, k + 13, sculk_block, 0, 2);
		world.setBlock(i + 30, j + 4, k + 13, sculk_block, 0, 2);
		world.setBlock(i + 31, j + 4, k + 13, sculk_block, 0, 2);
		world.setBlock(i + 32, j + 4, k + 13, sculk_block, 0, 2);
		world.setBlock(i + 33, j + 4, k + 13, sculk_block, 0, 2);
		world.setBlock(i + 34, j + 4, k + 13, sculk_block, 0, 2);
		world.setBlock(i + 35, j + 4, k + 13, sculk_block, 0, 2);
		world.setBlock(i + 36, j + 4, k + 13, sculk_block, 0, 2);
		world.setBlock(i + 37, j + 4, k + 13, sculk_block, 0, 2);
		world.setBlock(i + 38, j + 4, k + 13, sculk_block, 0, 2);
		world.setBlock(i + 39, j + 4, k + 13, sculk_block, 0, 2);
		world.setBlock(i + 40, j + 4, k + 13, sculk_block, 0, 2);
		world.setBlock(i + 41, j + 4, k + 13, sculk_block, 0, 2);
		world.setBlock(i + 42, j + 4, k + 13, sculk_block, 0, 2);
		world.setBlock(i + 27, j + 4, k + 14, sculk_block, 0, 2);
		world.setBlock(i + 28, j + 4, k + 14, sculk_block, 0, 2);
		world.setBlock(i + 29, j + 4, k + 14, sculk_block, 0, 2);
		world.setBlock(i + 30, j + 4, k + 14, sculk_block, 0, 2);
		world.setBlock(i + 31, j + 4, k + 14, sculk_block, 0, 2);
		world.setBlock(i + 32, j + 4, k + 14, sculk_block, 0, 2);
		world.setBlock(i + 33, j + 4, k + 14, sculk_block, 0, 2);
		world.setBlock(i + 34, j + 4, k + 14, sculk_block, 0, 2);
		world.setBlock(i + 35, j + 4, k + 14, sculk_block, 0, 2);
		world.setBlock(i + 36, j + 4, k + 14, sculk_block, 0, 2);
		world.setBlock(i + 37, j + 4, k + 14, sculk_block, 0, 2);
		world.setBlock(i + 38, j + 4, k + 14, sculk_block, 0, 2);
		world.setBlock(i + 39, j + 4, k + 14, sculk_block, 0, 2);
		world.setBlock(i + 40, j + 4, k + 14, sculk_block, 0, 2);
		world.setBlock(i + 41, j + 4, k + 14, sculk_block, 0, 2);
		world.setBlock(i + 42, j + 4, k + 14, sculk_block, 0, 2);
		world.setBlock(i + 44, j + 4, k + 14, NovaCraftBlocks.sculk_vein, 0, 2);
		world.setBlock(i + 29, j + 4, k + 15, sculk_block, 0, 2);
		world.setBlock(i + 30, j + 4, k + 15, sculk_block, 0, 2);
		world.setBlock(i + 31, j + 4, k + 15, sculk_block, 0, 2);
		world.setBlock(i + 32, j + 4, k + 15, sculk_block, 0, 2);
		world.setBlock(i + 33, j + 4, k + 15, sculk_block, 0, 2);
		world.setBlock(i + 34, j + 4, k + 15, sculk_block, 0, 2);
		world.setBlock(i + 35, j + 4, k + 15, sculk_block, 0, 2);
		world.setBlock(i + 36, j + 4, k + 15, sculk_block, 0, 2);
		world.setBlock(i + 37, j + 4, k + 15, sculk_block, 0, 2);
		world.setBlock(i + 38, j + 4, k + 15, sculk_block, 0, 2);
		world.setBlock(i + 39, j + 4, k + 15, sculk_block, 0, 2);
		world.setBlock(i + 40, j + 4, k + 15, sculk_block, 0, 2);
		world.setBlock(i + 31, j + 4, k + 16, sculk_block, 0, 2);
		world.setBlock(i + 32, j + 4, k + 16, sculk_block, 0, 2);
		world.setBlock(i + 33, j + 4, k + 16, sculk_block, 0, 2);
		world.setBlock(i + 34, j + 4, k + 16, sculk_block, 0, 2);
		world.setBlock(i + 35, j + 4, k + 16, sculk_block, 0, 2);
		world.setBlock(i + 36, j + 4, k + 16, sculk_block, 0, 2);
		world.setBlock(i + 37, j + 4, k + 16, sculk_block, 0, 2);
		world.setBlock(i + 38, j + 4, k + 16, sculk_block, 0, 2);
		world.setBlock(i + 39, j + 4, k + 16, sculk_block, 0, 2);
		world.setBlock(i + 8, j + 4, k + 17, NovaCraftBlocks.sculk_vein, 1, 2);
		world.setBlock(i + 22, j + 4, k + 17, sculk_tulip, 0, 2);
		world.setBlock(i + 31, j + 4, k + 17, sculk_block, 0, 2);
		world.setBlock(i + 32, j + 4, k + 17, sculk_block, 0, 2);
		world.setBlock(i + 33, j + 4, k + 17, sculk_block, 0, 2);
		world.setBlock(i + 34, j + 4, k + 17, sculk_block, 0, 2);
		world.setBlock(i + 35, j + 4, k + 17, sculk_block, 0, 2);
		world.setBlock(i + 36, j + 4, k + 17, sculk_block, 0, 2);
		world.setBlock(i + 37, j + 4, k + 17, sculk_block, 0, 2);
		world.setBlock(i + 3, j + 4, k + 18, sculk_block, 0, 2);
		world.setBlock(i + 29, j + 4, k + 18, sculk_block, 0, 2);
		world.setBlock(i + 30, j + 4, k + 18, sculk_block, 0, 2);
		world.setBlock(i + 31, j + 4, k + 18, sculk_block, 0, 2);
		world.setBlock(i + 32, j + 4, k + 18, sculk_block, 0, 2);
		world.setBlock(i + 33, j + 4, k + 18, sculk_block, 0, 2);
		world.setBlock(i + 34, j + 4, k + 18, sculk_block, 0, 2);
		world.setBlock(i + 35, j + 4, k + 18, sculk_block, 0, 2);
		world.setBlock(i + 3, j + 4, k + 19, sculk_block, 0, 2);
		world.setBlock(i + 4, j + 4, k + 19, sculk_block, 0, 2);
		world.setBlock(i + 5, j + 4, k + 19, sculk_block, 0, 2);
		world.setBlock(i + 6, j + 4, k + 19, sculk_block, 0, 2);
		world.setBlock(i + 7, j + 4, k + 19, sculk_block, 0, 2);
		world.setBlock(i + 20, j + 4, k + 19, NovaCraftBlocks.sculk_vein, 1, 2);
		world.setBlock(i + 25, j + 4, k + 19, sculk_block, 0, 2);
		world.setBlock(i + 26, j + 4, k + 19, sculk_block, 0, 2);
		world.setBlock(i + 27, j + 4, k + 19, sculk_block, 0, 2);
		world.setBlock(i + 28, j + 4, k + 19, sculk_block, 0, 2);
		world.setBlock(i + 29, j + 4, k + 19, sculk_block, 0, 2);
		world.setBlock(i + 30, j + 4, k + 19, sculk_block, 0, 2);
		world.setBlock(i + 31, j + 4, k + 19, sculk_block, 0, 2);
		world.setBlock(i + 32, j + 4, k + 19, sculk_block, 0, 2);
		world.setBlock(i + 33, j + 4, k + 19, sculk_block, 0, 2);
		world.setBlock(i + 3, j + 4, k + 20, sculk_block, 0, 2);
		world.setBlock(i + 4, j + 4, k + 20, sculk_block, 0, 2);
		world.setBlock(i + 5, j + 4, k + 20, sculk_block, 0, 2);
		world.setBlock(i + 6, j + 4, k + 20, sculk_block, 0, 2);
		world.setBlock(i + 7, j + 4, k + 20, sculk_block, 0, 2);
		world.setBlock(i + 8, j + 4, k + 20, sculk_block, 0, 2);
		world.setBlock(i + 9, j + 4, k + 20, sculk_block, 0, 2);
		world.setBlock(i + 10, j + 4, k + 20, sculk_block, 0, 2);
		world.setBlock(i + 11, j + 4, k + 20, sculk_block, 0, 2);
		world.setBlock(i + 12, j + 4, k + 20, sculk_block, 0, 2);
		world.setBlock(i + 13, j + 4, k + 20, sculk_block, 0, 2);
		world.setBlock(i + 14, j + 4, k + 20, sculk_block, 0, 2);
		world.setBlock(i + 15, j + 4, k + 20, sculk_block, 0, 2);
		world.setBlock(i + 16, j + 4, k + 20, sculk_block, 0, 2);
		world.setBlock(i + 17, j + 4, k + 20, sculk_block, 0, 2);
		world.setBlock(i + 18, j + 4, k + 20, sculk_block, 0, 2);
		world.setBlock(i + 19, j + 4, k + 20, sculk_block, 0, 2);
		world.setBlock(i + 20, j + 4, k + 20, sculk_block, 0, 2);
		world.setBlock(i + 21, j + 4, k + 20, sculk_block, 0, 2);
		world.setBlock(i + 22, j + 4, k + 20, sculk_block, 0, 2);
		world.setBlock(i + 23, j + 4, k + 20, sculk_block, 0, 2);
		world.setBlock(i + 24, j + 4, k + 20, sculk_block, 0, 2);
		world.setBlock(i + 25, j + 4, k + 20, sculk_block, 0, 2);
		world.setBlock(i + 26, j + 4, k + 20, sculk_block, 0, 2);
		world.setBlock(i + 27, j + 4, k + 20, sculk_block, 0, 2);
		world.setBlock(i + 28, j + 4, k + 20, sculk_block, 0, 2);
		world.setBlock(i + 29, j + 4, k + 20, sculk_block, 0, 2);
		world.setBlock(i + 30, j + 4, k + 20, sculk_block, 0, 2);
		world.setBlock(i + 31, j + 4, k + 20, sculk_block, 0, 2);
		world.setBlock(i + 4, j + 4, k + 21, sculk_block, 0, 2);
		world.setBlock(i + 5, j + 4, k + 21, sculk_block, 0, 2);
		world.setBlock(i + 6, j + 4, k + 21, sculk_block, 0, 2);
		world.setBlock(i + 7, j + 4, k + 21, sculk_block, 0, 2);
		world.setBlock(i + 8, j + 4, k + 21, sculk_block, 0, 2);
		world.setBlock(i + 9, j + 4, k + 21, sculk_block, 0, 2);
		world.setBlock(i + 10, j + 4, k + 21, sculk_block, 0, 2);
		world.setBlock(i + 11, j + 4, k + 21, sculk_block, 0, 2);
		world.setBlock(i + 12, j + 4, k + 21, sculk_block, 0, 2);
		world.setBlock(i + 13, j + 4, k + 21, sculk_block, 0, 2);
		world.setBlock(i + 14, j + 4, k + 21, sculk_block, 0, 2);
		world.setBlock(i + 15, j + 4, k + 21, sculk_block, 0, 2);
		world.setBlock(i + 16, j + 4, k + 21, sculk_block, 0, 2);
		world.setBlock(i + 17, j + 4, k + 21, sculk_block, 0, 2);
		world.setBlock(i + 18, j + 4, k + 21, sculk_block, 0, 2);
		world.setBlock(i + 19, j + 4, k + 21, sculk_block, 0, 2);
		world.setBlock(i + 20, j + 4, k + 21, sculk_block, 0, 2);
		world.setBlock(i + 21, j + 4, k + 21, sculk_block, 0, 2);
		world.setBlock(i + 22, j + 4, k + 21, sculk_block, 0, 2);
		world.setBlock(i + 23, j + 4, k + 21, sculk_block, 0, 2);
		world.setBlock(i + 8, j + 4, k + 22, sculk_block, 0, 2);
		world.setBlock(i + 9, j + 4, k + 22, sculk_block, 0, 2);
		world.setBlock(i + 10, j + 4, k + 22, sculk_block, 0, 2);
		world.setBlock(i + 11, j + 4, k + 22, sculk_block, 0, 2);
		world.setBlock(i + 12, j + 4, k + 22, sculk_block, 0, 2);
		world.setBlock(i + 13, j + 4, k + 22, sculk_block, 0, 2);
		world.setBlock(i + 14, j + 4, k + 22, sculk_block, 0, 2);
		world.setBlock(i + 15, j + 4, k + 22, sculk_block, 0, 2);
		world.setBlock(i + 16, j + 4, k + 22, sculk_block, 0, 2);
		world.setBlock(i + 17, j + 4, k + 22, sculk_block, 0, 2);
		world.setBlock(i + 18, j + 4, k + 22, sculk_block, 0, 2);
		world.setBlock(i + 19, j + 4, k + 22, sculk_block, 0, 2);
		world.setBlock(i + 20, j + 4, k + 22, sculk_block, 0, 2);
		world.setBlock(i + 21, j + 4, k + 22, sculk_block, 0, 2);
		world.setBlock(i + 22, j + 4, k + 22, sculk_block, 0, 2);
		world.setBlock(i + 17, j + 4, k + 23, NovaCraftBlocks.sculk_vein, 0, 2);
		world.setBlock(i + 40, j + 4, k + 25, NovaCraftBlocks.sculk_vein, 0, 2);
		world.setBlock(i + 25, j + 4, k + 32, NovaCraftBlocks.sculk_vein, 0, 2);
		world.setBlock(i + 42, j + 5, k + 14, NovaCraftBlocks.sculk_tentacle_2, 1, 2);
		world.setBlock(i + 37, j + 5, k + 15, sculk_tulip, 0, 2);
		world.setBlock(i + 41, j + 5, k + 15, sculk_block, 0, 2);
		world.setBlock(i + 42, j + 5, k + 15, sculk_block, 0, 2);
		world.setBlock(i + 33, j + 5, k + 16, NovaCraftBlocks.sculk_tentacle_2, 1, 2);
		world.setBlock(i + 40, j + 5, k + 16, sculk_block, 0, 2);
		world.setBlock(i + 41, j + 5, k + 16, sculk_block, 0, 2);
		world.setBlock(i + 42, j + 5, k + 16, sculk_block, 0, 2);
		world.setBlock(i + 38, j + 5, k + 17, sculk_block, 0, 2);
		world.setBlock(i + 39, j + 5, k + 17, sculk_block, 0, 2);
		world.setBlock(i + 40, j + 5, k + 17, sculk_block, 0, 2);
		world.setBlock(i + 41, j + 5, k + 17, sculk_block, 0, 2);
		world.setBlock(i + 36, j + 5, k + 18, sculk_block, 0, 2);
		world.setBlock(i + 37, j + 5, k + 18, sculk_block, 0, 2);
		world.setBlock(i + 38, j + 5, k + 18, sculk_block, 0, 2);
		world.setBlock(i + 39, j + 5, k + 18, sculk_block, 0, 2);
		world.setBlock(i + 40, j + 5, k + 18, sculk_block, 0, 2);
		world.setBlock(i + 34, j + 5, k + 19, sculk_block, 0, 2);
		world.setBlock(i + 35, j + 5, k + 19, sculk_block, 0, 2);
		world.setBlock(i + 36, j + 5, k + 19, sculk_block, 0, 2);
		world.setBlock(i + 37, j + 5, k + 19, sculk_block, 0, 2);
		world.setBlock(i + 38, j + 5, k + 19, sculk_block, 0, 2);
		world.setBlock(i + 39, j + 5, k + 19, sculk_block, 0, 2);
		world.setBlock(i + 5, j + 5, k + 20, NovaCraftBlocks.sculk_tentacle_2, 1, 2);
		world.setBlock(i + 32, j + 5, k + 20, sculk_block, 0, 2);
		world.setBlock(i + 33, j + 5, k + 20, sculk_block, 0, 2);
		world.setBlock(i + 34, j + 5, k + 20, sculk_block, 0, 2);
		world.setBlock(i + 35, j + 5, k + 20, sculk_block, 0, 2);
		world.setBlock(i + 36, j + 5, k + 20, sculk_block, 0, 2);
		world.setBlock(i + 37, j + 5, k + 20, sculk_block, 0, 2);
		world.setBlock(i + 3, j + 5, k + 21, sculk_block, 0, 2);
		world.setBlock(i + 10, j + 5, k + 21, NovaCraftBlocks.sculk_vein, 1, 2);
		world.setBlock(i + 24, j + 5, k + 21, sculk_block, 0, 2);
		world.setBlock(i + 25, j + 5, k + 21, sculk_block, 0, 2);
		world.setBlock(i + 26, j + 5, k + 21, sculk_block, 0, 2);
		world.setBlock(i + 27, j + 5, k + 21, sculk_block, 0, 2);
		world.setBlock(i + 28, j + 5, k + 21, sculk_block, 0, 2);
		world.setBlock(i + 29, j + 5, k + 21, sculk_block, 0, 2);
		world.setBlock(i + 30, j + 5, k + 21, sculk_block, 0, 2);
		world.setBlock(i + 31, j + 5, k + 21, sculk_block, 0, 2);
		world.setBlock(i + 32, j + 5, k + 21, sculk_block, 0, 2);
		world.setBlock(i + 33, j + 5, k + 21, sculk_block, 0, 2);
		world.setBlock(i + 34, j + 5, k + 21, sculk_block, 0, 2);
		world.setBlock(i + 35, j + 5, k + 21, sculk_block, 0, 2);
		world.setBlock(i + 4, j + 5, k + 22, sculk_block, 0, 2);
		world.setBlock(i + 5, j + 5, k + 22, sculk_block, 0, 2);
		world.setBlock(i + 6, j + 5, k + 22, sculk_block, 0, 2);
		world.setBlock(i + 7, j + 5, k + 22, sculk_block, 0, 2);
		world.setBlock(i + 23, j + 5, k + 22, sculk_block, 0, 2);
		world.setBlock(i + 24, j + 5, k + 22, sculk_block, 0, 2);
		world.setBlock(i + 25, j + 5, k + 22, sculk_block, 0, 2);
		world.setBlock(i + 26, j + 5, k + 22, sculk_block, 0, 2);
		world.setBlock(i + 27, j + 5, k + 22, sculk_block, 0, 2);
		world.setBlock(i + 28, j + 5, k + 22, sculk_block, 0, 2);
		world.setBlock(i + 29, j + 5, k + 22, sculk_block, 0, 2);
		world.setBlock(i + 30, j + 5, k + 22, sculk_block, 0, 2);
		world.setBlock(i + 31, j + 5, k + 22, sculk_block, 0, 2);
		world.setBlock(i + 32, j + 5, k + 22, sculk_block, 0, 2);
		world.setBlock(i + 33, j + 5, k + 22, sculk_block, 0, 2);
		world.setBlock(i + 4, j + 5, k + 23, sculk_block, 0, 2);
		world.setBlock(i + 5, j + 5, k + 23, sculk_block, 0, 2);
		world.setBlock(i + 6, j + 5, k + 23, sculk_block, 0, 2);
		world.setBlock(i + 7, j + 5, k + 23, sculk_block, 0, 2);
		world.setBlock(i + 8, j + 5, k + 23, sculk_block, 0, 2);
		world.setBlock(i + 9, j + 5, k + 23, sculk_block, 0, 2);
		world.setBlock(i + 10, j + 5, k + 23, sculk_block, 0, 2);
		world.setBlock(i + 11, j + 5, k + 23, sculk_block, 0, 2);
		world.setBlock(i + 12, j + 5, k + 23, sculk_block, 0, 2);
		world.setBlock(i + 13, j + 5, k + 23, sculk_block, 0, 2);
		world.setBlock(i + 14, j + 5, k + 23, sculk_block, 0, 2);
		world.setBlock(i + 15, j + 5, k + 23, sculk_block, 0, 2);
		world.setBlock(i + 16, j + 5, k + 23, sculk_block, 0, 2);
		world.setBlock(i + 17, j + 5, k + 23, sculk_block, 0, 2);
		world.setBlock(i + 18, j + 5, k + 23, sculk_block, 0, 2);
		world.setBlock(i + 19, j + 5, k + 23, sculk_block, 0, 2);
		world.setBlock(i + 20, j + 5, k + 23, sculk_block, 0, 2);
		world.setBlock(i + 21, j + 5, k + 23, sculk_block, 0, 2);
		world.setBlock(i + 22, j + 5, k + 23, sculk_block, 0, 2);
		world.setBlock(i + 23, j + 5, k + 23, sculk_block, 0, 2);
		world.setBlock(i + 24, j + 5, k + 23, sculk_block, 0, 2);
		world.setBlock(i + 25, j + 5, k + 23, sculk_block, 0, 2);
		world.setBlock(i + 26, j + 5, k + 23, sculk_block, 0, 2);
		world.setBlock(i + 27, j + 5, k + 23, sculk_block, 0, 2);
		world.setBlock(i + 28, j + 5, k + 23, sculk_block, 0, 2);
		world.setBlock(i + 29, j + 5, k + 23, sculk_block, 0, 2);
		world.setBlock(i + 30, j + 5, k + 23, sculk_block, 0, 2);
		world.setBlock(i + 5, j + 5, k + 24, sculk_block, 0, 2);
		world.setBlock(i + 6, j + 5, k + 24, sculk_block, 0, 2);
		world.setBlock(i + 7, j + 5, k + 24, sculk_block, 0, 2);
		world.setBlock(i + 8, j + 5, k + 24, sculk_block, 0, 2);
		world.setBlock(i + 9, j + 5, k + 24, sculk_block, 0, 2);
		world.setBlock(i + 10, j + 5, k + 24, sculk_block, 0, 2);
		world.setBlock(i + 11, j + 5, k + 24, sculk_block, 0, 2);
		world.setBlock(i + 12, j + 5, k + 24, sculk_block, 0, 2);
		world.setBlock(i + 13, j + 5, k + 24, sculk_block, 0, 2);
		world.setBlock(i + 14, j + 5, k + 24, sculk_block, 0, 2);
		world.setBlock(i + 15, j + 5, k + 24, sculk_block, 0, 2);
		world.setBlock(i + 16, j + 5, k + 24, sculk_block, 0, 2);
		world.setBlock(i + 17, j + 5, k + 24, sculk_block, 0, 2);
		world.setBlock(i + 18, j + 5, k + 24, sculk_block, 0, 2);
		world.setBlock(i + 19, j + 5, k + 24, sculk_block, 0, 2);
		world.setBlock(i + 20, j + 5, k + 24, sculk_block, 0, 2);
		world.setBlock(i + 21, j + 5, k + 24, sculk_block, 0, 2);
		world.setBlock(i + 22, j + 5, k + 24, sculk_block, 0, 2);
		world.setBlock(i + 23, j + 5, k + 24, sculk_block, 0, 2);
		world.setBlock(i + 24, j + 5, k + 24, sculk_block, 0, 2);
		world.setBlock(i + 25, j + 5, k + 24, sculk_block, 0, 2);
		world.setBlock(i + 26, j + 5, k + 24, sculk_block, 0, 2);
		world.setBlock(i + 27, j + 5, k + 24, sculk_block, 0, 2);
		world.setBlock(i + 9, j + 5, k + 25, sculk_block, 0, 2);
		world.setBlock(i + 10, j + 5, k + 25, sculk_block, 0, 2);
		world.setBlock(i + 11, j + 5, k + 25, sculk_block, 0, 2);
		world.setBlock(i + 12, j + 5, k + 25, sculk_block, 0, 2);
		world.setBlock(i + 13, j + 5, k + 25, sculk_block, 0, 2);
		world.setBlock(i + 14, j + 5, k + 25, sculk_block, 0, 2);
		world.setBlock(i + 15, j + 5, k + 25, sculk_block, 0, 2);
		world.setBlock(i + 16, j + 5, k + 25, sculk_block, 0, 2);
		world.setBlock(i + 17, j + 5, k + 25, sculk_block, 0, 2);
		world.setBlock(i + 18, j + 5, k + 25, sculk_block, 0, 2);
		world.setBlock(i + 19, j + 5, k + 25, sculk_block, 0, 2);
		world.setBlock(i + 20, j + 5, k + 25, sculk_block, 0, 2);
		world.setBlock(i + 21, j + 5, k + 25, sculk_block, 0, 2);
		world.setBlock(i + 22, j + 5, k + 25, sculk_block, 0, 2);
		world.setBlock(i + 41, j + 5, k + 25, NovaCraftBlocks.sculk_vein, 0, 2);
		world.setBlock(i + 41, j + 5, k + 26, NovaCraftBlocks.sculk_vein, 0, 2);
		world.setBlock(i + 38, j + 5, k + 27, NovaCraftBlocks.sculk_vein, 0, 2);
		world.setBlock(i + 26, j + 5, k + 33, NovaCraftBlocks.sculk_vein, 0, 2);
		world.setBlock(i + 39, j + 6, k + 17, NovaCraftBlocks.sculk_vein, 1, 2);
		world.setBlock(i + 41, j + 6, k + 18, sculk_block, 0, 2);
		world.setBlock(i + 40, j + 6, k + 19, sculk_block, 0, 2);
		world.setBlock(i + 38, j + 6, k + 20, sculk_block, 0, 2);
		world.setBlock(i + 39, j + 6, k + 20, sculk_block, 0, 2);
		world.setBlock(i + 40, j + 6, k + 20, sculk_block, 0, 2);
		world.setBlock(i + 25, j + 6, k + 21, NovaCraftBlocks.sculk_tentacle_2, 1, 2);
		world.setBlock(i + 34, j + 6, k + 21, NovaCraftBlocks.sculk_vein, 1, 2);
		world.setBlock(i + 36, j + 6, k + 21, sculk_block, 0, 2);
		world.setBlock(i + 37, j + 6, k + 21, sculk_block, 0, 2);
		world.setBlock(i + 38, j + 6, k + 21, sculk_block, 0, 2);
		world.setBlock(i + 39, j + 6, k + 21, sculk_block, 0, 2);
		world.setBlock(i + 40, j + 6, k + 21, sculk_block, 0, 2);
		world.setBlock(i + 34, j + 6, k + 22, sculk_block, 0, 2);
		world.setBlock(i + 35, j + 6, k + 22, sculk_block, 0, 2);
		world.setBlock(i + 36, j + 6, k + 22, sculk_block, 0, 2);
		world.setBlock(i + 37, j + 6, k + 22, sculk_block, 0, 2);
		world.setBlock(i + 38, j + 6, k + 22, sculk_block, 0, 2);
		world.setBlock(i + 42, j + 6, k + 22, NovaCraftBlocks.sculk_vein, 0, 2);
		world.setBlock(i + 15, j + 6, k + 23, NovaCraftBlocks.sculk_tentacle_2, 1, 2);
		world.setBlock(i + 31, j + 6, k + 23, sculk_block, 0, 2);
		world.setBlock(i + 32, j + 6, k + 23, sculk_block, 0, 2);
		world.setBlock(i + 33, j + 6, k + 23, sculk_block, 0, 2);
		world.setBlock(i + 34, j + 6, k + 23, sculk_block, 0, 2);
		world.setBlock(i + 35, j + 6, k + 23, sculk_block, 0, 2);
		world.setBlock(i + 36, j + 6, k + 23, sculk_block, 0, 2);
		world.setBlock(i + 4, j + 6, k + 24, sculk_block, 0, 2);
		world.setBlock(i + 8, j + 6, k + 24, NovaCraftBlocks.sculk_tentacle_2, 1, 2);
		world.setBlock(i + 28, j + 6, k + 24, sculk_block, 0, 2);
		world.setBlock(i + 29, j + 6, k + 24, sculk_block, 0, 2);
		world.setBlock(i + 30, j + 6, k + 24, sculk_block, 0, 2);
		world.setBlock(i + 31, j + 6, k + 24, sculk_block, 0, 2);
		world.setBlock(i + 32, j + 6, k + 24, sculk_block, 0, 2);
		world.setBlock(i + 33, j + 6, k + 24, sculk_block, 0, 2);
		world.setBlock(i + 34, j + 6, k + 24, sculk_block, 0, 2);
		world.setBlock(i + 5, j + 6, k + 25, sculk_block, 0, 2);
		world.setBlock(i + 6, j + 6, k + 25, sculk_block, 0, 2);
		world.setBlock(i + 7, j + 6, k + 25, sculk_block, 0, 2);
		world.setBlock(i + 8, j + 6, k + 25, sculk_block, 0, 2);
		world.setBlock(i + 9, j + 6, k + 25, sculk_block, 0, 2);
		world.setBlock(i + 23, j + 6, k + 25, sculk_block, 0, 2);
		world.setBlock(i + 24, j + 6, k + 25, sculk_block, 0, 2);
		world.setBlock(i + 25, j + 6, k + 25, sculk_block, 0, 2);
		world.setBlock(i + 26, j + 6, k + 25, sculk_block, 0, 2);
		world.setBlock(i + 27, j + 6, k + 25, sculk_block, 0, 2);
		world.setBlock(i + 28, j + 6, k + 25, sculk_block, 0, 2);
		world.setBlock(i + 29, j + 6, k + 25, sculk_block, 0, 2);
		world.setBlock(i + 30, j + 6, k + 25, sculk_block, 0, 2);
		world.setBlock(i + 31, j + 6, k + 25, sculk_block, 0, 2);
		world.setBlock(i + 5, j + 6, k + 26, sculk_block, 0, 2);
		world.setBlock(i + 6, j + 6, k + 26, sculk_block, 0, 2);
		world.setBlock(i + 7, j + 6, k + 26, sculk_block, 0, 2);
		world.setBlock(i + 8, j + 6, k + 26, sculk_block, 0, 2);
		world.setBlock(i + 9, j + 6, k + 26, sculk_block, 0, 2);
		world.setBlock(i + 10, j + 6, k + 26, sculk_block, 0, 2);
		world.setBlock(i + 11, j + 6, k + 26, sculk_block, 0, 2);
		world.setBlock(i + 12, j + 6, k + 26, sculk_block, 0, 2);
		world.setBlock(i + 13, j + 6, k + 26, sculk_block, 0, 2);
		world.setBlock(i + 14, j + 6, k + 26, sculk_block, 0, 2);
		world.setBlock(i + 15, j + 6, k + 26, sculk_block, 0, 2);
		world.setBlock(i + 16, j + 6, k + 26, sculk_block, 0, 2);
		world.setBlock(i + 17, j + 6, k + 26, sculk_block, 0, 2);
		world.setBlock(i + 18, j + 6, k + 26, sculk_block, 0, 2);
		world.setBlock(i + 19, j + 6, k + 26, sculk_block, 0, 2);
		world.setBlock(i + 20, j + 6, k + 26, sculk_block, 0, 2);
		world.setBlock(i + 21, j + 6, k + 26, sculk_block, 0, 2);
		world.setBlock(i + 22, j + 6, k + 26, sculk_block, 0, 2);
		world.setBlock(i + 23, j + 6, k + 26, sculk_block, 0, 2);
		world.setBlock(i + 24, j + 6, k + 26, sculk_block, 0, 2);
		world.setBlock(i + 25, j + 6, k + 26, sculk_block, 0, 2);
		world.setBlock(i + 26, j + 6, k + 26, sculk_block, 0, 2);
		world.setBlock(i + 27, j + 6, k + 26, sculk_block, 0, 2);
		world.setBlock(i + 28, j + 6, k + 26, sculk_block, 0, 2);
		world.setBlock(i + 41, j + 6, k + 26, NovaCraftBlocks.sculk_vein, 0, 2);
		world.setBlock(i + 9, j + 6, k + 27, sculk_block, 0, 2);
		world.setBlock(i + 10, j + 6, k + 27, sculk_block, 0, 2);
		world.setBlock(i + 11, j + 6, k + 27, sculk_block, 0, 2);
		world.setBlock(i + 12, j + 6, k + 27, sculk_block, 0, 2);
		world.setBlock(i + 13, j + 6, k + 27, sculk_block, 0, 2);
		world.setBlock(i + 14, j + 6, k + 27, sculk_block, 0, 2);
		world.setBlock(i + 15, j + 6, k + 27, sculk_block, 0, 2);
		world.setBlock(i + 16, j + 6, k + 27, sculk_block, 0, 2);
		world.setBlock(i + 17, j + 6, k + 27, sculk_block, 0, 2);
		world.setBlock(i + 18, j + 6, k + 27, sculk_block, 0, 2);
		world.setBlock(i + 19, j + 6, k + 27, sculk_block, 0, 2);
		world.setBlock(i + 20, j + 6, k + 27, sculk_block, 0, 2);
		world.setBlock(i + 21, j + 6, k + 27, sculk_block, 0, 2);
		world.setBlock(i + 22, j + 6, k + 27, sculk_block, 0, 2);
		world.setBlock(i + 23, j + 6, k + 27, sculk_block, 0, 2);
		world.setBlock(i + 38, j + 6, k + 27, NovaCraftBlocks.sculk_vein, 0, 2);
		world.setBlock(i + 37, j + 6, k + 28, NovaCraftBlocks.sculk_vein, 0, 2);
		world.setBlock(i + 1, j + 6, k + 31, NovaCraftBlocks.sculk_vein, 0, 2);
		world.setBlock(i + 2, j + 6, k + 31, NovaCraftBlocks.sculk_vein, 0, 2);
		world.setBlock(i + 26, j + 6, k + 33, NovaCraftBlocks.sculk_vein, 0, 2);
		world.setBlock(i + 39, j + 7, k + 22, sculk_block, 0, 2);
		world.setBlock(i + 40, j + 7, k + 22, sculk_block, 0, 2);
		world.setBlock(i + 35, j + 7, k + 23, NovaCraftBlocks.sculk_vein, 1, 2);
		world.setBlock(i + 37, j + 7, k + 23, sculk_block, 0, 2);
		world.setBlock(i + 38, j + 7, k + 23, sculk_block, 0, 2);
		world.setBlock(i + 39, j + 7, k + 23, sculk_block, 0, 2);
		world.setBlock(i + 40, j + 7, k + 23, sculk_block, 0, 2);
		world.setBlock(i + 29, j + 7, k + 24, NovaCraftBlocks.sculk_tentacle_2, 1, 2);
		world.setBlock(i + 35, j + 7, k + 24, sculk_block, 0, 2);
		world.setBlock(i + 36, j + 7, k + 24, sculk_block, 0, 2);
		world.setBlock(i + 37, j + 7, k + 24, sculk_block, 0, 2);
		world.setBlock(i + 38, j + 7, k + 24, sculk_block, 0, 2);
		world.setBlock(i + 32, j + 7, k + 25, sculk_block, 0, 2);
		world.setBlock(i + 33, j + 7, k + 25, sculk_block, 0, 2);
		world.setBlock(i + 34, j + 7, k + 25, sculk_block, 0, 2);
		world.setBlock(i + 35, j + 7, k + 25, sculk_block, 0, 2);
		world.setBlock(i + 36, j + 7, k + 25, sculk_block, 0, 2);
		world.setBlock(i + 8, j + 7, k + 26, NovaCraftBlocks.sculk_vein, 1, 2);
		world.setBlock(i + 29, j + 7, k + 26, sculk_block, 0, 2);
		world.setBlock(i + 30, j + 7, k + 26, sculk_block, 0, 2);
		world.setBlock(i + 31, j + 7, k + 26, sculk_block, 0, 2);
		world.setBlock(i + 32, j + 7, k + 26, sculk_block, 0, 2);
		world.setBlock(i + 33, j + 7, k + 26, sculk_block, 0, 2);
		world.setBlock(i + 34, j + 7, k + 26, sculk_block, 0, 2);
		world.setBlock(i + 6, j + 7, k + 27, sculk_block, 0, 2);
		world.setBlock(i + 7, j + 7, k + 27, sculk_block, 0, 2);
		world.setBlock(i + 8, j + 7, k + 27, sculk_block, 0, 2);
		world.setBlock(i + 11, j + 7, k + 27, NovaCraftBlocks.sculk_tentacle_2, 1, 2);
		world.setBlock(i + 21, j + 7, k + 27, NovaCraftBlocks.sculk_vein, 1, 2);
		world.setBlock(i + 24, j + 7, k + 27, sculk_block, 0, 2);
		world.setBlock(i + 25, j + 7, k + 27, sculk_block, 0, 2);
		world.setBlock(i + 26, j + 7, k + 27, sculk_block, 0, 2);
		world.setBlock(i + 27, j + 7, k + 27, sculk_block, 0, 2);
		world.setBlock(i + 28, j + 7, k + 27, sculk_block, 0, 2);
		world.setBlock(i + 29, j + 7, k + 27, sculk_block, 0, 2);
		world.setBlock(i + 30, j + 7, k + 27, sculk_block, 0, 2);
		world.setBlock(i + 31, j + 7, k + 27, sculk_block, 0, 2);
		world.setBlock(i + 6, j + 7, k + 28, sculk_block, 0, 2);
		world.setBlock(i + 7, j + 7, k + 28, sculk_block, 0, 2);
		world.setBlock(i + 8, j + 7, k + 28, sculk_block, 0, 2);
		world.setBlock(i + 9, j + 7, k + 28, sculk_block, 0, 2);
		world.setBlock(i + 10, j + 7, k + 28, sculk_block, 0, 2);
		world.setBlock(i + 11, j + 7, k + 28, sculk_block, 0, 2);
		world.setBlock(i + 12, j + 7, k + 28, sculk_block, 0, 2);
		world.setBlock(i + 13, j + 7, k + 28, sculk_block, 0, 2);
		world.setBlock(i + 14, j + 7, k + 28, sculk_block, 0, 2);
		world.setBlock(i + 15, j + 7, k + 28, sculk_block, 0, 2);
		world.setBlock(i + 16, j + 7, k + 28, sculk_block, 0, 2);
		world.setBlock(i + 17, j + 7, k + 28, sculk_block, 0, 2);
		world.setBlock(i + 18, j + 7, k + 28, sculk_block, 0, 2);
		world.setBlock(i + 19, j + 7, k + 28, sculk_block, 0, 2);
		world.setBlock(i + 20, j + 7, k + 28, sculk_block, 0, 2);
		world.setBlock(i + 21, j + 7, k + 28, sculk_block, 0, 2);
		world.setBlock(i + 22, j + 7, k + 28, sculk_block, 0, 2);
		world.setBlock(i + 23, j + 7, k + 28, sculk_block, 0, 2);
		world.setBlock(i + 24, j + 7, k + 28, sculk_block, 0, 2);
		world.setBlock(i + 25, j + 7, k + 28, sculk_block, 0, 2);
		world.setBlock(i + 26, j + 7, k + 28, sculk_block, 0, 2);
		world.setBlock(i + 27, j + 7, k + 28, sculk_block, 0, 2);
		world.setBlock(i + 28, j + 7, k + 28, sculk_block, 0, 2);
		world.setBlock(i + 9, j + 7, k + 29, sculk_block, 0, 2);
		world.setBlock(i + 10, j + 7, k + 29, sculk_block, 0, 2);
		world.setBlock(i + 11, j + 7, k + 29, sculk_block, 0, 2);
		world.setBlock(i + 12, j + 7, k + 29, sculk_block, 0, 2);
		world.setBlock(i + 13, j + 7, k + 29, sculk_block, 0, 2);
		world.setBlock(i + 14, j + 7, k + 29, sculk_block, 0, 2);
		world.setBlock(i + 15, j + 7, k + 29, sculk_block, 0, 2);
		world.setBlock(i + 16, j + 7, k + 29, sculk_block, 0, 2);
		world.setBlock(i + 17, j + 7, k + 29, sculk_block, 0, 2);
		world.setBlock(i + 18, j + 7, k + 29, sculk_block, 0, 2);
		world.setBlock(i + 19, j + 7, k + 29, sculk_block, 0, 2);
		world.setBlock(i + 20, j + 7, k + 29, sculk_block, 0, 2);
		world.setBlock(i + 21, j + 7, k + 29, sculk_block, 0, 2);
		world.setBlock(i + 22, j + 7, k + 29, sculk_block, 0, 2);
		world.setBlock(i + 23, j + 7, k + 29, sculk_block, 0, 2);
		world.setBlock(i + 23, j + 7, k + 36, NovaCraftBlocks.sculk_vein, 0, 2);
		world.setBlock(i + 35, j + 8, k + 24, NovaCraftBlocks.sculk_tentacle_2, 1, 2);
		world.setBlock(i + 39, j + 8, k + 24, sculk_block, 0, 2);
		world.setBlock(i + 37, j + 8, k + 25, sculk_block, 0, 2);
		world.setBlock(i + 38, j + 8, k + 25, sculk_block, 0, 2);
		world.setBlock(i + 39, j + 8, k + 25, sculk_block, 0, 2);
		world.setBlock(i + 35, j + 8, k + 26, sculk_block, 0, 2);
		world.setBlock(i + 36, j + 8, k + 26, sculk_block, 0, 2);
		world.setBlock(i + 37, j + 8, k + 26, sculk_block, 0, 2);
		world.setBlock(i + 38, j + 8, k + 26, sculk_block, 0, 2);
		world.setBlock(i + 28, j + 8, k + 27, NovaCraftBlocks.sculk_vein, 1, 2);
		world.setBlock(i + 32, j + 8, k + 27, sculk_block, 0, 2);
		world.setBlock(i + 33, j + 8, k + 27, sculk_block, 0, 2);
		world.setBlock(i + 34, j + 8, k + 27, sculk_block, 0, 2);
		world.setBlock(i + 35, j + 8, k + 27, sculk_block, 0, 2);
		world.setBlock(i + 25, j + 8, k + 28, NovaCraftBlocks.sculk_tentacle_2, 1, 2);
		world.setBlock(i + 29, j + 8, k + 28, sculk_block, 0, 2);
		world.setBlock(i + 30, j + 8, k + 28, sculk_block, 0, 2);
		world.setBlock(i + 31, j + 8, k + 28, sculk_block, 0, 2);
		world.setBlock(i + 32, j + 8, k + 28, sculk_block, 0, 2);
		world.setBlock(i + 33, j + 8, k + 28, sculk_block, 0, 2);
		world.setBlock(i + 6, j + 8, k + 29, sculk_block, 0, 2);
		world.setBlock(i + 7, j + 8, k + 29, sculk_block, 0, 2);
		world.setBlock(i + 8, j + 8, k + 29, sculk_block, 0, 2);
		world.setBlock(i + 13, j + 8, k + 29, NovaCraftBlocks.sculk_vein, 1, 2);
		world.setBlock(i + 18, j + 8, k + 29, NovaCraftBlocks.sculk_tentacle_2, 1, 2);
		world.setBlock(i + 24, j + 8, k + 29, sculk_block, 0, 2);
		world.setBlock(i + 25, j + 8, k + 29, sculk_block, 0, 2);
		world.setBlock(i + 26, j + 8, k + 29, sculk_block, 0, 2);
		world.setBlock(i + 27, j + 8, k + 29, sculk_block, 0, 2);
		world.setBlock(i + 28, j + 8, k + 29, sculk_block, 0, 2);
		world.setBlock(i + 29, j + 8, k + 29, sculk_block, 0, 2);
		world.setBlock(i + 30, j + 8, k + 29, sculk_block, 0, 2);
		world.setBlock(i + 7, j + 8, k + 30, sculk_block, 0, 2);
		world.setBlock(i + 8, j + 8, k + 30, sculk_block, 0, 2);
		world.setBlock(i + 9, j + 8, k + 30, sculk_block, 0, 2);
		world.setBlock(i + 10, j + 8, k + 30, sculk_block, 0, 2);
		world.setBlock(i + 11, j + 8, k + 30, sculk_block, 0, 2);
		world.setBlock(i + 12, j + 8, k + 30, sculk_block, 0, 2);
		world.setBlock(i + 13, j + 8, k + 30, sculk_block, 0, 2);
		world.setBlock(i + 14, j + 8, k + 30, sculk_block, 0, 2);
		world.setBlock(i + 15, j + 8, k + 30, sculk_block, 0, 2);
		world.setBlock(i + 16, j + 8, k + 30, sculk_block, 0, 2);
		world.setBlock(i + 17, j + 8, k + 30, sculk_block, 0, 2);
		world.setBlock(i + 18, j + 8, k + 30, sculk_block, 0, 2);
		world.setBlock(i + 19, j + 8, k + 30, sculk_block, 0, 2);
		world.setBlock(i + 20, j + 8, k + 30, sculk_block, 0, 2);
		world.setBlock(i + 21, j + 8, k + 30, sculk_block, 0, 2);
		world.setBlock(i + 22, j + 8, k + 30, sculk_block, 0, 2);
		world.setBlock(i + 23, j + 8, k + 30, sculk_block, 0, 2);
		world.setBlock(i + 24, j + 8, k + 30, sculk_block, 0, 2);
		world.setBlock(i + 25, j + 8, k + 30, sculk_block, 0, 2);
		world.setBlock(i + 26, j + 8, k + 30, sculk_block, 0, 2);
		world.setBlock(i + 9, j + 8, k + 31, sculk_block, 0, 2);
		world.setBlock(i + 13, j + 8, k + 31, sculk_block, 0, 2);
		world.setBlock(i + 14, j + 8, k + 31, sculk_block, 0, 2);
		world.setBlock(i + 15, j + 8, k + 31, sculk_block, 0, 2);
		world.setBlock(i + 16, j + 8, k + 31, sculk_block, 0, 2);
		world.setBlock(i + 17, j + 8, k + 31, sculk_block, 0, 2);
		world.setBlock(i + 18, j + 8, k + 31, sculk_block, 0, 2);
		world.setBlock(i + 19, j + 8, k + 31, sculk_block, 0, 2);
		world.setBlock(i + 39, j + 9, k + 26, sculk_block, 0, 2);
		world.setBlock(i + 33, j + 9, k + 27, NovaCraftBlocks.sculk_vein, 1, 2);
		world.setBlock(i + 36, j + 9, k + 27, sculk_block, 0, 2);
		world.setBlock(i + 37, j + 9, k + 27, sculk_block, 0, 2);
		world.setBlock(i + 38, j + 9, k + 27, sculk_block, 0, 2);
		world.setBlock(i + 39, j + 9, k + 27, sculk_block, 0, 2);
		world.setBlock(i + 34, j + 9, k + 28, sculk_block, 0, 2);
		world.setBlock(i + 35, j + 9, k + 28, sculk_block, 0, 2);
		world.setBlock(i + 36, j + 9, k + 28, sculk_block, 0, 2);
		world.setBlock(i + 31, j + 9, k + 29, sculk_block, 0, 2);
		world.setBlock(i + 32, j + 9, k + 29, sculk_block, 0, 2);
		world.setBlock(i + 33, j + 9, k + 29, sculk_block, 0, 2);
		world.setBlock(i + 34, j + 9, k + 29, sculk_block, 0, 2);
		world.setBlock(i + 6, j + 9, k + 30, sculk_block, 0, 2);
		world.setBlock(i + 27, j + 9, k + 30, sculk_block, 0, 2);
		world.setBlock(i + 28, j + 9, k + 30, sculk_block, 0, 2);
		world.setBlock(i + 29, j + 9, k + 30, sculk_block, 0, 2);
		world.setBlock(i + 30, j + 9, k + 30, sculk_block, 0, 2);
		world.setBlock(i + 31, j + 9, k + 30, sculk_block, 0, 2);
		world.setBlock(i + 6, j + 9, k + 31, sculk_block, 0, 2);
		world.setBlock(i + 7, j + 9, k + 31, sculk_block, 0, 2);
		world.setBlock(i + 8, j + 9, k + 31, sculk_block, 0, 2);
		world.setBlock(i + 9, j + 9, k + 31, sculk_block, 0, 2);
		world.setBlock(i + 10, j + 9, k + 31, sculk_block, 0, 2);
		world.setBlock(i + 11, j + 9, k + 31, sculk_block, 0, 2);
		world.setBlock(i + 12, j + 9, k + 31, sculk_block, 0, 2);
		world.setBlock(i + 13, j + 9, k + 31, sculk_tulip, 0, 2);
		world.setBlock(i + 20, j + 9, k + 31, sculk_block, 0, 2);
		world.setBlock(i + 21, j + 9, k + 31, sculk_block, 0, 2);
		world.setBlock(i + 22, j + 9, k + 31, sculk_block, 0, 2);
		world.setBlock(i + 23, j + 9, k + 31, sculk_block, 0, 2);
		world.setBlock(i + 24, j + 9, k + 31, sculk_block, 0, 2);
		world.setBlock(i + 25, j + 9, k + 31, sculk_block, 0, 2);
		world.setBlock(i + 26, j + 9, k + 31, sculk_block, 0, 2);
		world.setBlock(i + 27, j + 9, k + 31, sculk_block, 0, 2);
		world.setBlock(i + 28, j + 9, k + 31, sculk_block, 0, 2);
		world.setBlock(i + 10, j + 9, k + 32, sculk_block, 0, 2);
		world.setBlock(i + 11, j + 9, k + 32, sculk_block, 0, 2);
		world.setBlock(i + 12, j + 9, k + 32, sculk_block, 0, 2);
		world.setBlock(i + 13, j + 9, k + 32, sculk_block, 0, 2);
		world.setBlock(i + 14, j + 9, k + 32, sculk_block, 0, 2);
		world.setBlock(i + 15, j + 9, k + 32, sculk_block, 0, 2);
		world.setBlock(i + 16, j + 9, k + 32, sculk_block, 0, 2);
		world.setBlock(i + 17, j + 9, k + 32, sculk_block, 0, 2);
		world.setBlock(i + 18, j + 9, k + 32, sculk_block, 0, 2);
		world.setBlock(i + 19, j + 9, k + 32, sculk_block, 0, 2);
		world.setBlock(i + 20, j + 9, k + 32, sculk_block, 0, 2);
		world.setBlock(i + 21, j + 9, k + 32, sculk_block, 0, 2);
		world.setBlock(i + 22, j + 9, k + 32, sculk_block, 0, 2);
		world.setBlock(i + 36, j + 10, k + 27, sculk_tulip, 0, 2);
		world.setBlock(i + 40, j + 10, k + 27, sculk_block, 0, 2);
		world.setBlock(i + 37, j + 10, k + 28, sculk_block, 0, 2);
		world.setBlock(i + 38, j + 10, k + 28, sculk_block, 0, 2);
		world.setBlock(i + 39, j + 10, k + 28, sculk_block, 0, 2);
		world.setBlock(i + 35, j + 10, k + 29, sculk_block, 0, 2);
		world.setBlock(i + 36, j + 10, k + 29, sculk_block, 0, 2);
		world.setBlock(i + 37, j + 10, k + 29, sculk_block, 0, 2);
		world.setBlock(i + 32, j + 10, k + 30, sculk_block, 0, 2);
		world.setBlock(i + 33, j + 10, k + 30, sculk_block, 0, 2);
		world.setBlock(i + 34, j + 10, k + 30, sculk_block, 0, 2);
		world.setBlock(i + 35, j + 10, k + 30, sculk_block, 0, 2);
		world.setBlock(i + 29, j + 10, k + 31, sculk_block, 0, 2);
		world.setBlock(i + 30, j + 10, k + 31, sculk_block, 0, 2);
		world.setBlock(i + 31, j + 10, k + 31, sculk_block, 0, 2);
		world.setBlock(i + 32, j + 10, k + 31, sculk_block, 0, 2);
		world.setBlock(i + 5, j + 10, k + 32, sculk_block, 0, 2);
		world.setBlock(i + 6, j + 10, k + 32, sculk_block, 0, 2);
		world.setBlock(i + 7, j + 10, k + 32, sculk_block, 0, 2);
		world.setBlock(i + 8, j + 10, k + 32, sculk_block, 0, 2);
		world.setBlock(i + 9, j + 10, k + 32, sculk_block, 0, 2);
		world.setBlock(i + 19, j + 10, k + 32, NovaCraftBlocks.sculk_vein, 1, 2);
		world.setBlock(i + 23, j + 10, k + 32, sculk_block, 0, 2);
		world.setBlock(i + 24, j + 10, k + 32, sculk_block, 0, 2);
		world.setBlock(i + 25, j + 10, k + 32, sculk_block, 0, 2);
		world.setBlock(i + 26, j + 10, k + 32, sculk_block, 0, 2);
		world.setBlock(i + 27, j + 10, k + 32, sculk_block, 0, 2);
		world.setBlock(i + 28, j + 10, k + 32, sculk_block, 0, 2);
		world.setBlock(i + 9, j + 10, k + 33, sculk_block, 0, 2);
		world.setBlock(i + 10, j + 10, k + 33, sculk_block, 0, 2);
		world.setBlock(i + 11, j + 10, k + 33, sculk_block, 0, 2);
		world.setBlock(i + 12, j + 10, k + 33, sculk_block, 0, 2);
		world.setBlock(i + 13, j + 10, k + 33, sculk_block, 0, 2);
		world.setBlock(i + 14, j + 10, k + 33, sculk_block, 0, 2);
		world.setBlock(i + 15, j + 10, k + 33, sculk_block, 0, 2);
		world.setBlock(i + 16, j + 10, k + 33, sculk_block, 0, 2);
		world.setBlock(i + 17, j + 10, k + 33, sculk_block, 0, 2);
		world.setBlock(i + 18, j + 10, k + 33, sculk_block, 0, 2);
		world.setBlock(i + 19, j + 10, k + 33, sculk_block, 0, 2);
		world.setBlock(i + 20, j + 10, k + 33, sculk_block, 0, 2);
		world.setBlock(i + 21, j + 10, k + 33, sculk_block, 0, 2);
		world.setBlock(i + 22, j + 10, k + 33, sculk_block, 0, 2);
		world.setBlock(i + 23, j + 10, k + 33, sculk_block, 0, 2);
		world.setBlock(i + 38, j + 11, k + 29, sculk_block, 0, 2);
		world.setBlock(i + 39, j + 11, k + 29, sculk_block, 0, 2);
		world.setBlock(i + 36, j + 11, k + 30, sculk_block, 0, 2);
		world.setBlock(i + 37, j + 11, k + 30, sculk_block, 0, 2);
		world.setBlock(i + 33, j + 11, k + 31, sculk_block, 0, 2);
		world.setBlock(i + 34, j + 11, k + 31, sculk_block, 0, 2);
		world.setBlock(i + 35, j + 11, k + 31, sculk_block, 0, 2);
		world.setBlock(i + 27, j + 11, k + 32, NovaCraftBlocks.sculk_vein, 1, 2);
		world.setBlock(i + 29, j + 11, k + 32, sculk_block, 0, 2);
		world.setBlock(i + 30, j + 11, k + 32, sculk_block, 0, 2);
		world.setBlock(i + 31, j + 11, k + 32, sculk_block, 0, 2);
		world.setBlock(i + 32, j + 11, k + 32, sculk_block, 0, 2);
		world.setBlock(i + 5, j + 11, k + 33, sculk_block, 0, 2);
		world.setBlock(i + 6, j + 11, k + 33, sculk_block, 0, 2);
		world.setBlock(i + 7, j + 11, k + 33, sculk_block, 0, 2);
		world.setBlock(i + 8, j + 11, k + 33, sculk_block, 0, 2);
		world.setBlock(i + 24, j + 11, k + 33, sculk_block, 0, 2);
		world.setBlock(i + 25, j + 11, k + 33, sculk_block, 0, 2);
		world.setBlock(i + 26, j + 11, k + 33, sculk_block, 0, 2);
		world.setBlock(i + 27, j + 11, k + 33, sculk_block, 0, 2);
		world.setBlock(i + 28, j + 11, k + 33, sculk_block, 0, 2);
		world.setBlock(i + 9, j + 11, k + 34, sculk_block, 0, 2);
		world.setBlock(i + 10, j + 11, k + 34, sculk_block, 0, 2);
		world.setBlock(i + 11, j + 11, k + 34, sculk_block, 0, 2);
		world.setBlock(i + 12, j + 11, k + 34, sculk_block, 0, 2);
		world.setBlock(i + 13, j + 11, k + 34, sculk_block, 0, 2);
		world.setBlock(i + 14, j + 11, k + 34, sculk_block, 0, 2);
		world.setBlock(i + 15, j + 11, k + 34, sculk_block, 0, 2);
		world.setBlock(i + 16, j + 11, k + 34, sculk_block, 0, 2);
		world.setBlock(i + 17, j + 11, k + 34, sculk_block, 0, 2);
		world.setBlock(i + 18, j + 11, k + 34, sculk_block, 0, 2);
		world.setBlock(i + 19, j + 11, k + 34, sculk_block, 0, 2);
		world.setBlock(i + 20, j + 11, k + 34, sculk_block, 0, 2);
		world.setBlock(i + 21, j + 11, k + 34, sculk_block, 0, 2);
		world.setBlock(i + 22, j + 11, k + 34, sculk_block, 0, 2);
		world.setBlock(i + 23, j + 11, k + 34, sculk_block, 0, 2);
		world.setBlock(i + 37, j + 12, k + 30, NovaCraftBlocks.sculk_vein, 1, 2);
		world.setBlock(i + 38, j + 12, k + 30, sculk_block, 0, 2);
		world.setBlock(i + 35, j + 12, k + 31, sculk_block, 0, 2);
		world.setBlock(i + 36, j + 12, k + 31, sculk_block, 0, 2);
		world.setBlock(i + 37, j + 12, k + 31, sculk_block, 0, 2);
		world.setBlock(i + 30, j + 12, k + 32, NovaCraftBlocks.sculk_tentacle_2, 1, 2);
		world.setBlock(i + 33, j + 12, k + 32, sculk_block, 0, 2);
		world.setBlock(i + 34, j + 12, k + 32, sculk_block, 0, 2);
		world.setBlock(i + 8, j + 12, k + 33, NovaCraftBlocks.sculk_tentacle_2, 1, 2);
		world.setBlock(i + 29, j + 12, k + 33, sculk_block, 0, 2);
		world.setBlock(i + 30, j + 12, k + 33, sculk_block, 0, 2);
		world.setBlock(i + 31, j + 12, k + 33, sculk_block, 0, 2);
		world.setBlock(i + 32, j + 12, k + 33, sculk_block, 0, 2);
		world.setBlock(i + 5, j + 12, k + 34, sculk_block, 0, 2);
		world.setBlock(i + 6, j + 12, k + 34, sculk_block, 0, 2);
		world.setBlock(i + 7, j + 12, k + 34, sculk_block, 0, 2);
		world.setBlock(i + 8, j + 12, k + 34, sculk_block, 0, 2);
		world.setBlock(i + 9, j + 12, k + 34, sculk_block, 0, 2);
		world.setBlock(i + 21, j + 12, k + 34, NovaCraftBlocks.sculk_tentacle_2, 1, 2);
		world.setBlock(i + 23, j + 12, k + 34, sculk_block, 0, 2);
		world.setBlock(i + 24, j + 12, k + 34, sculk_block, 0, 2);
		world.setBlock(i + 25, j + 12, k + 34, sculk_block, 0, 2);
		world.setBlock(i + 26, j + 12, k + 34, sculk_block, 0, 2);
		world.setBlock(i + 27, j + 12, k + 34, sculk_block, 0, 2);
		world.setBlock(i + 28, j + 12, k + 34, sculk_block, 0, 2);
		world.setBlock(i + 10, j + 12, k + 35, sculk_block, 0, 2);
		world.setBlock(i + 11, j + 12, k + 35, sculk_block, 0, 2);
		world.setBlock(i + 12, j + 12, k + 35, sculk_block, 0, 2);
		world.setBlock(i + 13, j + 12, k + 35, sculk_block, 0, 2);
		world.setBlock(i + 14, j + 12, k + 35, sculk_block, 0, 2);
		world.setBlock(i + 15, j + 12, k + 35, sculk_block, 0, 2);
		world.setBlock(i + 16, j + 12, k + 35, sculk_block, 0, 2);
		world.setBlock(i + 17, j + 12, k + 35, sculk_block, 0, 2);
		world.setBlock(i + 18, j + 12, k + 35, sculk_block, 0, 2);
		world.setBlock(i + 19, j + 12, k + 35, sculk_block, 0, 2);
		world.setBlock(i + 20, j + 12, k + 35, sculk_block, 0, 2);
		world.setBlock(i + 21, j + 12, k + 35, sculk_block, 0, 2);
		world.setBlock(i + 22, j + 12, k + 35, sculk_block, 0, 2);
		world.setBlock(i + 36, j + 13, k + 31, NovaCraftBlocks.sculk_tentacle_2, 1, 2);
		world.setBlock(i + 37, j + 13, k + 31, sculk_block, 0, 2);
		world.setBlock(i + 38, j + 13, k + 31, sculk_block, 0, 2);
		world.setBlock(i + 35, j + 13, k + 32, sculk_block, 0, 2);
		world.setBlock(i + 36, j + 13, k + 32, sculk_block, 0, 2);
		world.setBlock(i + 32, j + 13, k + 33, sculk_block, 0, 2);
		world.setBlock(i + 33, j + 13, k + 33, sculk_block, 0, 2);
		world.setBlock(i + 34, j + 13, k + 33, sculk_block, 0, 2);
		world.setBlock(i + 5, j + 13, k + 34, NovaCraftBlocks.sculk_vein, 1, 2);
		world.setBlock(i + 26, j + 13, k + 34, NovaCraftBlocks.sculk_vein, 1, 2);
		world.setBlock(i + 28, j + 13, k + 34, sculk_block, 0, 2);
		world.setBlock(i + 29, j + 13, k + 34, sculk_block, 0, 2);
		world.setBlock(i + 30, j + 13, k + 34, sculk_block, 0, 2);
		world.setBlock(i + 31, j + 13, k + 34, sculk_block, 0, 2);
		world.setBlock(i + 5, j + 13, k + 35, sculk_block, 0, 2);
		world.setBlock(i + 6, j + 13, k + 35, sculk_block, 0, 2);
		world.setBlock(i + 7, j + 13, k + 35, sculk_block, 0, 2);
		world.setBlock(i + 8, j + 13, k + 35, sculk_block, 0, 2);
		world.setBlock(i + 9, j + 13, k + 35, sculk_block, 0, 2);
		world.setBlock(i + 10, j + 13, k + 35, sculk_block, 0, 2);
		world.setBlock(i + 11, j + 13, k + 35, sculk_block, 0, 2);
		world.setBlock(i + 12, j + 13, k + 35, sculk_block, 0, 2);
		world.setBlock(i + 14, j + 13, k + 35, sculk_tulip, 0, 2);
		world.setBlock(i + 17, j + 13, k + 35, NovaCraftBlocks.sculk_vein, 1, 2);
		world.setBlock(i + 20, j + 13, k + 35, sculk_block, 0, 2);
		world.setBlock(i + 21, j + 13, k + 35, sculk_block, 0, 2);
		world.setBlock(i + 22, j + 13, k + 35, sculk_block, 0, 2);
		world.setBlock(i + 23, j + 13, k + 35, sculk_block, 0, 2);
		world.setBlock(i + 24, j + 13, k + 35, sculk_block, 0, 2);
		world.setBlock(i + 25, j + 13, k + 35, sculk_block, 0, 2);
		world.setBlock(i + 26, j + 13, k + 35, sculk_block, 0, 2);
		world.setBlock(i + 27, j + 13, k + 35, sculk_block, 0, 2);
		world.setBlock(i + 13, j + 13, k + 36, sculk_block, 0, 2);
		world.setBlock(i + 14, j + 13, k + 36, sculk_block, 0, 2);
		world.setBlock(i + 15, j + 13, k + 36, sculk_block, 0, 2);
		world.setBlock(i + 16, j + 13, k + 36, sculk_block, 0, 2);
		world.setBlock(i + 17, j + 13, k + 36, sculk_block, 0, 2);
		world.setBlock(i + 18, j + 13, k + 36, sculk_block, 0, 2);
		world.setBlock(i + 19, j + 13, k + 36, sculk_block, 0, 2);
		world.setBlock(i + 38, j + 14, k + 31, sculk_block, 0, 2);
		world.setBlock(i + 36, j + 14, k + 32, sculk_block, 0, 2);
		world.setBlock(i + 37, j + 14, k + 32, sculk_block, 0, 2);
		world.setBlock(i + 33, j + 14, k + 33, sculk_block, 0, 2);
		world.setBlock(i + 34, j + 14, k + 33, sculk_block, 0, 2);
		world.setBlock(i + 35, j + 14, k + 33, sculk_block, 0, 2);
		world.setBlock(i + 30, j + 14, k + 34, sculk_block, 0, 2);
		world.setBlock(i + 31, j + 14, k + 34, sculk_block, 0, 2);
		world.setBlock(i + 32, j + 14, k + 34, sculk_block, 0, 2);
		world.setBlock(i + 5, j + 14, k + 35, sculk_block, 0, 2);
		world.setBlock(i + 6, j + 14, k + 35, sculk_block, 0, 2);
		world.setBlock(i + 7, j + 14, k + 35, sculk_block, 0, 2);
		world.setBlock(i + 11, j + 14, k + 35, NovaCraftBlocks.sculk_vein, 1, 2);
		world.setBlock(i + 23, j + 14, k + 35, sculk_tulip, 0, 2);
		world.setBlock(i + 25, j + 14, k + 35, sculk_block, 0, 2);
		world.setBlock(i + 26, j + 14, k + 35, sculk_block, 0, 2);
		world.setBlock(i + 27, j + 14, k + 35, sculk_block, 0, 2);
		world.setBlock(i + 28, j + 14, k + 35, sculk_block, 0, 2);
		world.setBlock(i + 29, j + 14, k + 35, sculk_block, 0, 2);
		world.setBlock(i + 8, j + 14, k + 36, sculk_block, 0, 2);
		world.setBlock(i + 9, j + 14, k + 36, sculk_block, 0, 2);
		world.setBlock(i + 10, j + 14, k + 36, sculk_block, 0, 2);
		world.setBlock(i + 11, j + 14, k + 36, sculk_block, 0, 2);
		world.setBlock(i + 12, j + 14, k + 36, sculk_block, 0, 2);
		world.setBlock(i + 13, j + 14, k + 36, sculk_block, 0, 2);
		world.setBlock(i + 14, j + 14, k + 36, sculk_block, 0, 2);
		world.setBlock(i + 15, j + 14, k + 36, sculk_block, 0, 2);
		world.setBlock(i + 16, j + 14, k + 36, sculk_block, 0, 2);
		world.setBlock(i + 17, j + 14, k + 36, sculk_block, 0, 2);
		world.setBlock(i + 18, j + 14, k + 36, sculk_block, 0, 2);
		world.setBlock(i + 19, j + 14, k + 36, sculk_block, 0, 2);
		world.setBlock(i + 20, j + 14, k + 36, sculk_block, 0, 2);
		world.setBlock(i + 21, j + 14, k + 36, sculk_block, 0, 2);
		world.setBlock(i + 22, j + 14, k + 36, sculk_block, 0, 2);
		world.setBlock(i + 23, j + 14, k + 36, sculk_block, 0, 2);
		world.setBlock(i + 24, j + 14, k + 36, sculk_block, 0, 2);
		world.setBlock(i + 37, j + 15, k + 32, sculk_block, 0, 2);
		world.setBlock(i + 33, j + 15, k + 33, NovaCraftBlocks.sculk_vein, 1, 2);
		world.setBlock(i + 34, j + 15, k + 33, sculk_block, 0, 2);
		world.setBlock(i + 35, j + 15, k + 33, sculk_block, 0, 2);
		world.setBlock(i + 36, j + 15, k + 33, sculk_block, 0, 2);
		world.setBlock(i + 31, j + 15, k + 34, sculk_block, 0, 2);
		world.setBlock(i + 32, j + 15, k + 34, sculk_block, 0, 2);
		world.setBlock(i + 33, j + 15, k + 34, sculk_block, 0, 2);
		world.setBlock(i + 5, j + 15, k + 35, sculk_block, 0, 2);
		world.setBlock(i + 6, j + 15, k + 35, sculk_block, 0, 2);
		world.setBlock(i + 26, j + 15, k + 35, sculk_block, 0, 2);
		world.setBlock(i + 27, j + 15, k + 35, sculk_block, 0, 2);
		world.setBlock(i + 28, j + 15, k + 35, sculk_block, 0, 2);
		world.setBlock(i + 29, j + 15, k + 35, sculk_block, 0, 2);
		world.setBlock(i + 30, j + 15, k + 35, sculk_block, 0, 2);
		world.setBlock(i + 7, j + 15, k + 36, sculk_block, 0, 2);
		world.setBlock(i + 8, j + 15, k + 36, sculk_block, 0, 2);
		world.setBlock(i + 9, j + 15, k + 36, sculk_block, 0, 2);
		world.setBlock(i + 10, j + 15, k + 36, sculk_block, 0, 2);
		world.setBlock(i + 11, j + 15, k + 36, sculk_block, 0, 2);
		world.setBlock(i + 12, j + 15, k + 36, sculk_block, 0, 2);
		world.setBlock(i + 13, j + 15, k + 36, sculk_block, 0, 2);
		world.setBlock(i + 14, j + 15, k + 36, sculk_block, 0, 2);
		world.setBlock(i + 15, j + 15, k + 36, sculk_block, 0, 2);
		world.setBlock(i + 16, j + 15, k + 36, sculk_block, 0, 2);
		world.setBlock(i + 17, j + 15, k + 36, sculk_block, 0, 2);
		world.setBlock(i + 18, j + 15, k + 36, sculk_block, 0, 2);
		world.setBlock(i + 19, j + 15, k + 36, sculk_block, 0, 2);
		world.setBlock(i + 20, j + 15, k + 36, sculk_block, 0, 2);
		world.setBlock(i + 21, j + 15, k + 36, sculk_block, 0, 2);
		world.setBlock(i + 22, j + 15, k + 36, sculk_block, 0, 2);
		world.setBlock(i + 23, j + 15, k + 36, sculk_block, 0, 2);
		world.setBlock(i + 24, j + 15, k + 36, sculk_block, 0, 2);
		world.setBlock(i + 25, j + 15, k + 36, sculk_block, 0, 2);
		world.setBlock(i + 12, j + 15, k + 37, sculk_block, 0, 2);
		world.setBlock(i + 15, j + 15, k + 37, sculk_block, 0, 2);
		world.setBlock(i + 16, j + 15, k + 37, sculk_block, 0, 2);
		world.setBlock(i + 17, j + 15, k + 37, sculk_block, 0, 2);
		world.setBlock(i + 37, j + 16, k + 32, sculk_block, 0, 2);
		world.setBlock(i + 34, j + 16, k + 33, sculk_block, 0, 2);
		world.setBlock(i + 35, j + 16, k + 33, sculk_block, 0, 2);
		world.setBlock(i + 36, j + 16, k + 33, sculk_block, 0, 2);
		world.setBlock(i + 31, j + 16, k + 34, sculk_block, 0, 2);
		world.setBlock(i + 32, j + 16, k + 34, sculk_block, 0, 2);
		world.setBlock(i + 33, j + 16, k + 34, sculk_block, 0, 2);
		world.setBlock(i + 5, j + 16, k + 35, sculk_block, 0, 2);
		world.setBlock(i + 26, j + 16, k + 35, sculk_block, 0, 2);
		world.setBlock(i + 27, j + 16, k + 35, sculk_block, 0, 2);
		world.setBlock(i + 28, j + 16, k + 35, sculk_block, 0, 2);
		world.setBlock(i + 29, j + 16, k + 35, sculk_block, 0, 2);
		world.setBlock(i + 30, j + 16, k + 35, sculk_block, 0, 2);
		world.setBlock(i + 6, j + 16, k + 36, sculk_block, 0, 2);
		world.setBlock(i + 7, j + 16, k + 36, sculk_block, 0, 2);
		world.setBlock(i + 8, j + 16, k + 36, sculk_block, 0, 2);
		world.setBlock(i + 9, j + 16, k + 36, sculk_block, 0, 2);
		world.setBlock(i + 10, j + 16, k + 36, sculk_block, 0, 2);
		world.setBlock(i + 11, j + 16, k + 36, sculk_block, 0, 2);
		world.setBlock(i + 12, j + 16, k + 36, sculk_block, 0, 2);
		world.setBlock(i + 13, j + 16, k + 36, sculk_block, 0, 2);
		world.setBlock(i + 14, j + 16, k + 36, sculk_block, 0, 2);
		world.setBlock(i + 15, j + 16, k + 36, sculk_block, 0, 2);
		world.setBlock(i + 17, j + 16, k + 36, sculk_block, 0, 2);
		world.setBlock(i + 18, j + 16, k + 36, sculk_block, 0, 2);
		world.setBlock(i + 19, j + 16, k + 36, sculk_block, 0, 2);
		world.setBlock(i + 20, j + 16, k + 36, sculk_block, 0, 2);
		world.setBlock(i + 21, j + 16, k + 36, sculk_block, 0, 2);
		world.setBlock(i + 22, j + 16, k + 36, sculk_block, 0, 2);
		world.setBlock(i + 23, j + 16, k + 36, sculk_block, 0, 2);
		world.setBlock(i + 24, j + 16, k + 36, sculk_block, 0, 2);
		world.setBlock(i + 25, j + 16, k + 36, sculk_block, 0, 2);
		world.setBlock(i + 15, j + 16, k + 37, sculk_block, 0, 2);
		world.setBlock(i + 16, j + 16, k + 37, sculk_block, 0, 2);
		world.setBlock(i + 17, j + 16, k + 37, sculk_block, 0, 2);
		world.setBlock(i + 37, j + 17, k + 32, sculk_block, 0, 2);
		world.setBlock(i + 34, j + 17, k + 33, sculk_block, 0, 2);
		world.setBlock(i + 35, j + 17, k + 33, sculk_block, 0, 2);
		world.setBlock(i + 36, j + 17, k + 33, sculk_block, 0, 2);
		world.setBlock(i + 31, j + 17, k + 34, sculk_block, 0, 2);
		world.setBlock(i + 32, j + 17, k + 34, sculk_block, 0, 2);
		world.setBlock(i + 33, j + 17, k + 34, sculk_block, 0, 2);
		world.setBlock(i + 6, j + 17, k + 35, sculk_block, 0, 2);
		world.setBlock(i + 26, j + 17, k + 35, sculk_block, 0, 2);
		world.setBlock(i + 27, j + 17, k + 35, sculk_block, 0, 2);
		world.setBlock(i + 28, j + 17, k + 35, sculk_block, 0, 2);
		world.setBlock(i + 29, j + 17, k + 35, sculk_block, 0, 2);
		world.setBlock(i + 30, j + 17, k + 35, sculk_block, 0, 2);
		world.setBlock(i + 7, j + 17, k + 36, sculk_block, 0, 2);
		world.setBlock(i + 8, j + 17, k + 36, sculk_block, 0, 2);
		world.setBlock(i + 9, j + 17, k + 36, sculk_block, 0, 2);
		world.setBlock(i + 10, j + 17, k + 36, sculk_block, 0, 2);
		world.setBlock(i + 11, j + 17, k + 36, sculk_block, 0, 2);
		world.setBlock(i + 12, j + 17, k + 36, sculk_block, 0, 2);
		world.setBlock(i + 13, j + 17, k + 36, sculk_block, 0, 2);
		world.setBlock(i + 14, j + 17, k + 36, sculk_block, 0, 2);
		world.setBlock(i + 15, j + 17, k + 36, sculk_block, 0, 2);
		world.setBlock(i + 16, j + 17, k + 36, sculk_block, 0, 2);
		world.setBlock(i + 17, j + 17, k + 36, sculk_block, 0, 2);
		world.setBlock(i + 18, j + 17, k + 36, sculk_block, 0, 2);
		world.setBlock(i + 19, j + 17, k + 36, sculk_block, 0, 2);
		world.setBlock(i + 20, j + 17, k + 36, sculk_block, 0, 2);
		world.setBlock(i + 21, j + 17, k + 36, sculk_block, 0, 2);
		world.setBlock(i + 22, j + 17, k + 36, sculk_block, 0, 2);
		world.setBlock(i + 23, j + 17, k + 36, sculk_block, 0, 2);
		world.setBlock(i + 24, j + 17, k + 36, sculk_block, 0, 2);
		world.setBlock(i + 25, j + 17, k + 36, sculk_block, 0, 2);
		world.setBlock(i + 15, j + 17, k + 37, sculk_block, 0, 2);
		world.setBlock(i + 16, j + 17, k + 37, sculk_block, 0, 2);
		world.setBlock(i + 17, j + 17, k + 37, sculk_block, 0, 2);
		world.setBlock(i + 36, j + 18, k + 32, sculk_block, 0, 2);
		world.setBlock(i + 33, j + 18, k + 33, sculk_block, 0, 2);
		world.setBlock(i + 34, j + 18, k + 33, sculk_block, 0, 2);
		world.setBlock(i + 35, j + 18, k + 33, sculk_block, 0, 2);
		world.setBlock(i + 29, j + 18, k + 34, NovaCraftBlocks.sculk_tentacle_2, 0, 2);
		world.setBlock(i + 30, j + 18, k + 34, sculk_block, 0, 2);
		world.setBlock(i + 31, j + 18, k + 34, sculk_block, 0, 2);
		world.setBlock(i + 32, j + 18, k + 34, sculk_block, 0, 2);
		world.setBlock(i + 7, j + 18, k + 35, sculk_block, 0, 2);
		world.setBlock(i + 22, j + 18, k + 35, NovaCraftBlocks.sculk_tentacle_2, 0, 2);
		world.setBlock(i + 25, j + 18, k + 35, sculk_block, 0, 2);
		world.setBlock(i + 26, j + 18, k + 35, sculk_block, 0, 2);
		world.setBlock(i + 27, j + 18, k + 35, sculk_block, 0, 2);
		world.setBlock(i + 28, j + 18, k + 35, sculk_block, 0, 2);
		world.setBlock(i + 29, j + 18, k + 35, sculk_block, 0, 2);
		world.setBlock(i + 8, j + 18, k + 36, sculk_block, 0, 2);
		world.setBlock(i + 9, j + 18, k + 36, sculk_block, 0, 2);
		world.setBlock(i + 10, j + 18, k + 36, sculk_block, 0, 2);
		world.setBlock(i + 11, j + 18, k + 36, sculk_block, 0, 2);
		world.setBlock(i + 12, j + 18, k + 36, sculk_block, 0, 2);
		world.setBlock(i + 13, j + 18, k + 36, sculk_block, 0, 2);
		world.setBlock(i + 14, j + 18, k + 36, sculk_block, 0, 2);
		world.setBlock(i + 15, j + 18, k + 36, sculk_block, 0, 2);
		world.setBlock(i + 16, j + 18, k + 36, sculk_block, 0, 2);
		world.setBlock(i + 17, j + 18, k + 36, sculk_block, 0, 2);
		world.setBlock(i + 18, j + 18, k + 36, sculk_block, 0, 2);
		world.setBlock(i + 19, j + 18, k + 36, sculk_block, 0, 2);
		world.setBlock(i + 20, j + 18, k + 36, sculk_block, 0, 2);
		world.setBlock(i + 21, j + 18, k + 36, sculk_block, 0, 2);
		world.setBlock(i + 22, j + 18, k + 36, sculk_block, 0, 2);
		world.setBlock(i + 23, j + 18, k + 36, sculk_block, 0, 2);
		world.setBlock(i + 24, j + 18, k + 36, sculk_block, 0, 2);
		world.setBlock(i + 28, j + 18, k + 36, sculk_block, 0, 2);
		world.setBlock(i + 35, j + 19, k + 32, sculk_block, 0, 2);
		world.setBlock(i + 31, j + 19, k + 33, NovaCraftBlocks.sculk_tentacle_2, 0, 2);
		world.setBlock(i + 32, j + 19, k + 33, sculk_block, 0, 2);
		world.setBlock(i + 33, j + 19, k + 33, sculk_block, 0, 2);
		world.setBlock(i + 34, j + 19, k + 33, sculk_block, 0, 2);
		world.setBlock(i + 24, j + 19, k + 34, NovaCraftBlocks.sculk_vein, 0, 2);
		world.setBlock(i + 28, j + 19, k + 34, sculk_block, 0, 2);
		world.setBlock(i + 29, j + 19, k + 34, sculk_block, 0, 2);
		world.setBlock(i + 30, j + 19, k + 34, sculk_block, 0, 2);
		world.setBlock(i + 31, j + 19, k + 34, sculk_block, 0, 2);
		world.setBlock(i + 7, j + 19, k + 35, sculk_block, 0, 2);
		world.setBlock(i + 8, j + 19, k + 35, sculk_block, 0, 2);
		world.setBlock(i + 9, j + 19, k + 35, sculk_block, 0, 2);
		world.setBlock(i + 10, j + 19, k + 35, sculk_block, 0, 2);
		world.setBlock(i + 20, j + 19, k + 35, sculk_block, 0, 2);
		world.setBlock(i + 21, j + 19, k + 35, sculk_block, 0, 2);
		world.setBlock(i + 22, j + 19, k + 35, sculk_block, 0, 2);
		world.setBlock(i + 23, j + 19, k + 35, sculk_block, 0, 2);
		world.setBlock(i + 24, j + 19, k + 35, sculk_block, 0, 2);
		world.setBlock(i + 25, j + 19, k + 35, sculk_block, 0, 2);
		world.setBlock(i + 26, j + 19, k + 35, sculk_block, 0, 2);
		world.setBlock(i + 27, j + 19, k + 35, sculk_block, 0, 2);
		world.setBlock(i + 10, j + 19, k + 36, sculk_block, 0, 2);
		world.setBlock(i + 11, j + 19, k + 36, sculk_block, 0, 2);
		world.setBlock(i + 12, j + 19, k + 36, sculk_block, 0, 2);
		world.setBlock(i + 13, j + 19, k + 36, sculk_block, 0, 2);
		world.setBlock(i + 14, j + 19, k + 36, sculk_block, 0, 2);
		world.setBlock(i + 15, j + 19, k + 36, sculk_block, 0, 2);
		world.setBlock(i + 16, j + 19, k + 36, sculk_block, 0, 2);
		world.setBlock(i + 17, j + 19, k + 36, sculk_block, 0, 2);
		world.setBlock(i + 18, j + 19, k + 36, sculk_block, 0, 2);
		world.setBlock(i + 19, j + 19, k + 36, sculk_block, 0, 2);
		world.setBlock(i + 33, j + 20, k + 32, sculk_block, 0, 2);
		world.setBlock(i + 34, j + 20, k + 32, sculk_block, 0, 2);
		world.setBlock(i + 29, j + 20, k + 33, sculk_block, 0, 2);
		world.setBlock(i + 30, j + 20, k + 33, sculk_block, 0, 2);
		world.setBlock(i + 31, j + 20, k + 33, sculk_block, 0, 2);
		world.setBlock(i + 32, j + 20, k + 33, sculk_block, 0, 2);
		world.setBlock(i + 7, j + 20, k + 34, sculk_block, 0, 2);
		world.setBlock(i + 8, j + 20, k + 34, sculk_block, 0, 2);
		world.setBlock(i + 9, j + 20, k + 34, sculk_block, 0, 2);
		world.setBlock(i + 21, j + 20, k + 34, NovaCraftBlocks.sculk_tentacle_2, 0, 2);
		world.setBlock(i + 22, j + 20, k + 34, sculk_block, 0, 2);
		world.setBlock(i + 23, j + 20, k + 34, sculk_block, 0, 2);
		world.setBlock(i + 24, j + 20, k + 34, sculk_block, 0, 2);
		world.setBlock(i + 25, j + 20, k + 34, sculk_block, 0, 2);
		world.setBlock(i + 26, j + 20, k + 34, sculk_block, 0, 2);
		world.setBlock(i + 27, j + 20, k + 34, sculk_block, 0, 2);
		world.setBlock(i + 28, j + 20, k + 34, sculk_block, 0, 2);
		world.setBlock(i + 10, j + 20, k + 35, sculk_block, 0, 2);
		world.setBlock(i + 11, j + 20, k + 35, sculk_block, 0, 2);
		world.setBlock(i + 12, j + 20, k + 35, sculk_block, 0, 2);
		world.setBlock(i + 13, j + 20, k + 35, sculk_block, 0, 2);
		world.setBlock(i + 14, j + 20, k + 35, sculk_block, 0, 2);
		world.setBlock(i + 15, j + 20, k + 35, sculk_block, 0, 2);
		world.setBlock(i + 16, j + 20, k + 35, sculk_block, 0, 2);
		world.setBlock(i + 17, j + 20, k + 35, sculk_block, 0, 2);
		world.setBlock(i + 18, j + 20, k + 35, sculk_block, 0, 2);
		world.setBlock(i + 19, j + 20, k + 35, sculk_block, 0, 2);
		world.setBlock(i + 20, j + 20, k + 35, sculk_block, 0, 2);
		world.setBlock(i + 21, j + 20, k + 35, sculk_block, 0, 2);
		world.setBlock(i + 22, j + 20, k + 35, sculk_block, 0, 2);
		world.setBlock(i + 15, j + 20, k + 36, sculk_block, 0, 2);
		world.setBlock(i + 29, j + 21, k + 32, sculk_block, 0, 2);
		world.setBlock(i + 30, j + 21, k + 32, sculk_block, 0, 2);
		world.setBlock(i + 31, j + 21, k + 32, sculk_block, 0, 2);
		world.setBlock(i + 32, j + 21, k + 32, sculk_block, 0, 2);
		world.setBlock(i + 7, j + 21, k + 33, sculk_block, 0, 2);
		world.setBlock(i + 8, j + 21, k + 33, sculk_block, 0, 2);
		world.setBlock(i + 11, j + 21, k + 33, NovaCraftBlocks.sculk_tentacle_2, 0, 2);
		world.setBlock(i + 17, j + 21, k + 33, NovaCraftBlocks.sculk_vein, 0, 2);
		world.setBlock(i + 22, j + 21, k + 33, sculk_block, 0, 2);
		world.setBlock(i + 23, j + 21, k + 33, sculk_block, 0, 2);
		world.setBlock(i + 24, j + 21, k + 33, sculk_block, 0, 2);
		world.setBlock(i + 25, j + 21, k + 33, sculk_block, 0, 2);
		world.setBlock(i + 26, j + 21, k + 33, sculk_block, 0, 2);
		world.setBlock(i + 27, j + 21, k + 33, sculk_block, 0, 2);
		world.setBlock(i + 28, j + 21, k + 33, sculk_block, 0, 2);
		world.setBlock(i + 9, j + 21, k + 34, sculk_block, 0, 2);
		world.setBlock(i + 10, j + 21, k + 34, sculk_block, 0, 2);
		world.setBlock(i + 11, j + 21, k + 34, sculk_block, 0, 2);
		world.setBlock(i + 12, j + 21, k + 34, sculk_block, 0, 2);
		world.setBlock(i + 13, j + 21, k + 34, sculk_block, 0, 2);
		world.setBlock(i + 14, j + 21, k + 34, sculk_block, 0, 2);
		world.setBlock(i + 15, j + 21, k + 34, sculk_block, 0, 2);
		world.setBlock(i + 16, j + 21, k + 34, sculk_block, 0, 2);
		world.setBlock(i + 17, j + 21, k + 34, sculk_block, 0, 2);
		world.setBlock(i + 18, j + 21, k + 34, sculk_block, 0, 2);
		world.setBlock(i + 19, j + 21, k + 34, sculk_block, 0, 2);
		world.setBlock(i + 20, j + 21, k + 34, sculk_block, 0, 2);
		world.setBlock(i + 21, j + 21, k + 34, sculk_block, 0, 2);
		world.setBlock(i + 9, j + 22, k + 31, NovaCraftBlocks.sculk_spike, 0, 2);
		world.setBlock(i + 24, j + 22, k + 31, NovaCraftBlocks.sculk_spike, 0, 2);
		world.setBlock(i + 29, j + 22, k + 31, sculk_block, 0, 2);
		world.setBlock(i + 30, j + 22, k + 31, sculk_block, 0, 2);
		world.setBlock(i + 31, j + 22, k + 31, sculk_block, 0, 2);
		world.setBlock(i + 7, j + 22, k + 32, sculk_block, 0, 2);
		world.setBlock(i + 8, j + 22, k + 32, sculk_block, 0, 2);
		world.setBlock(i + 9, j + 22, k + 32, sculk_block, 0, 2);
		world.setBlock(i + 20, j + 22, k + 32, sculk_block, 0, 2);
		world.setBlock(i + 21, j + 22, k + 32, sculk_block, 0, 2);
		world.setBlock(i + 22, j + 22, k + 32, sculk_block, 0, 2);
		world.setBlock(i + 23, j + 22, k + 32, sculk_block, 0, 2);
		world.setBlock(i + 24, j + 22, k + 32, sculk_block, 0, 2);
		world.setBlock(i + 25, j + 22, k + 32, sculk_block, 0, 2);
		world.setBlock(i + 26, j + 22, k + 32, sculk_block, 0, 2);
		world.setBlock(i + 27, j + 22, k + 32, sculk_block, 0, 2);
		world.setBlock(i + 28, j + 22, k + 32, sculk_block, 0, 2);
		world.setBlock(i + 9, j + 22, k + 33, sculk_block, 0, 2);
		world.setBlock(i + 10, j + 22, k + 33, sculk_block, 0, 2);
		world.setBlock(i + 11, j + 22, k + 33, sculk_block, 0, 2);
