package com.NovaCraft.world.ancient_city;

import java.util.Random;

import com.NovaCraft.Items.NovaCraftItems;
import com.NovaCraft.registry.OtherModBlocks;
import com.NovaCraft.registry.OtherModItems;
import com.NovaCraftBlocks.NovaCraftBlocks;

import cpw.mods.fml.common.Loader;
import net.minecraft.block.Block;
import net.minecraft.enchantment.Enchantment;
import net.minecraft.enchantment.EnchantmentData;
import net.minecraft.init.Blocks;
import net.minecraft.init.Items;
import net.minecraft.item.ItemStack;
import net.minecraft.tileentity.TileEntityChest;
import net.minecraft.util.MathHelper;
import net.minecraft.world.World;
import net.minecraft.world.gen.feature.WorldGenerator;

public class AncientCitySculkWallPosX2Gen extends WorldGenerator
{
	public AncientCitySculkWallPosX2Gen() {

	}
	
	private static final Block grimstone = NovaCraftBlocks.grimstone;
	private static final Block sculk_grimstone = NovaCraftBlocks.sculk_grimstone;
	private static final Block sculk_block = NovaCraftBlocks.sculk_block;
	private static final Block sculk_tulip = NovaCraftBlocks.sculk_tulip;
	private static final Block sculk_tendrils = NovaCraftBlocks.sculk_tendrils;
	private static final Block sculk_bush = NovaCraftBlocks.sculk_bush;
	private static final Block sculk_bloom = NovaCraftBlocks.sculk_bloom;	
	private static final Block sculk_tiles = NovaCraftBlocks.sculk_tiles;
	private static final Block sculk_bricks = NovaCraftBlocks.sculk_bricks;
    
    public boolean generate(final World world, final Random random, final int i, final int j, final int k) {
    	
		world.setBlock(i + 21, j + 0, k + 3, NovaCraftBlocks.sculk_vein, 0, 2);
		world.setBlock(i + 22, j + 0, k + 3, NovaCraftBlocks.sculk_vein, 0, 2);
		world.setBlock(i + 21, j + 0, k + 4, NovaCraftBlocks.sculk_vein, 0, 2);
		world.setBlock(i + 22, j + 0, k + 4, NovaCraftBlocks.sculk_vein, 0, 2);
		world.setBlock(i + 24, j + 0, k + 5, NovaCraftBlocks.sculk_vein, 0, 2);
		world.setBlock(i + 25, j + 0, k + 5, NovaCraftBlocks.sculk_vein, 0, 2);
		world.setBlock(i + 24, j + 0, k + 6, NovaCraftBlocks.sculk_vein, 0, 2);
		world.setBlock(i + 25, j + 0, k + 6, NovaCraftBlocks.sculk_vein, 0, 2);
		world.setBlock(i + 24, j + 0, k + 20, NovaCraftBlocks.sculk_vein, 0, 2);
		world.setBlock(i + 36, j + 0, k + 22, NovaCraftBlocks.sculk_vein, 0, 2);
		world.setBlock(i + 26, j + 0, k + 36, NovaCraftBlocks.sculk_vein, 0, 2);
		world.setBlock(i + 26, j + 0, k + 37, NovaCraftBlocks.sculk_vein, 0, 2);
		world.setBlock(i + 13, j + 0, k + 41, NovaCraftBlocks.sculk_vein, 0, 2);
		world.setBlock(i + 31, j + 1, k + 9, NovaCraftBlocks.sculk_vein, 0, 2);
		world.setBlock(i + 22, j + 1, k + 10, sculk_block, 0, 2);
		world.setBlock(i + 23, j + 1, k + 10, sculk_block, 0, 2);
		world.setBlock(i + 20, j + 1, k + 11, sculk_block, 0, 2);
		world.setBlock(i + 21, j + 1, k + 11, sculk_block, 0, 2);
		world.setBlock(i + 22, j + 1, k + 11, sculk_block, 0, 2);
		world.setBlock(i + 23, j + 1, k + 11, sculk_block, 0, 2);
		world.setBlock(i + 19, j + 1, k + 12, sculk_block, 0, 2);
		world.setBlock(i + 20, j + 1, k + 12, sculk_block, 0, 2);
		world.setBlock(i + 21, j + 1, k + 12, sculk_block, 0, 2);
		world.setBlock(i + 22, j + 1, k + 12, sculk_block, 0, 2);
		world.setBlock(i + 23, j + 1, k + 12, sculk_block, 0, 2);
		world.setBlock(i + 19, j + 1, k + 13, sculk_block, 0, 2);
		world.setBlock(i + 20, j + 1, k + 13, sculk_block, 0, 2);
		world.setBlock(i + 21, j + 1, k + 13, sculk_block, 0, 2);
		world.setBlock(i + 22, j + 1, k + 13, sculk_block, 0, 2);
		world.setBlock(i + 23, j + 1, k + 13, sculk_block, 0, 2);
		world.setBlock(i + 19, j + 1, k + 14, sculk_block, 0, 2);
		world.setBlock(i + 20, j + 1, k + 14, sculk_block, 0, 2);
		world.setBlock(i + 21, j + 1, k + 14, sculk_block, 0, 2);
		world.setBlock(i + 22, j + 1, k + 14, sculk_block, 0, 2);
		world.setBlock(i + 23, j + 1, k + 14, sculk_block, 0, 2);
		world.setBlock(i + 26, j + 1, k + 14, NovaCraftBlocks.sculk_vein, 0, 2);
		world.setBlock(i + 27, j + 1, k + 14, NovaCraftBlocks.sculk_vein, 0, 2);
		world.setBlock(i + 19, j + 1, k + 15, sculk_block, 0, 2);
		world.setBlock(i + 20, j + 1, k + 15, sculk_block, 0, 2);
		world.setBlock(i + 21, j + 1, k + 15, sculk_block, 0, 2);
		world.setBlock(i + 22, j + 1, k + 15, sculk_block, 0, 2);
		world.setBlock(i + 23, j + 1, k + 15, sculk_block, 0, 2);
		world.setBlock(i + 26, j + 1, k + 15, NovaCraftBlocks.sculk_vein, 0, 2);
		world.setBlock(i + 27, j + 1, k + 15, NovaCraftBlocks.sculk_vein, 0, 2);
		world.setBlock(i + 19, j + 1, k + 16, sculk_block, 0, 2);
		world.setBlock(i + 20, j + 1, k + 16, sculk_block, 0, 2);
		world.setBlock(i + 21, j + 1, k + 16, sculk_block, 0, 2);
		world.setBlock(i + 22, j + 1, k + 16, sculk_block, 0, 2);
		world.setBlock(i + 23, j + 1, k + 16, sculk_block, 0, 2);
		world.setBlock(i + 19, j + 1, k + 17, sculk_block, 0, 2);
		world.setBlock(i + 20, j + 1, k + 17, sculk_block, 0, 2);
		world.setBlock(i + 21, j + 1, k + 17, sculk_block, 0, 2);
		world.setBlock(i + 22, j + 1, k + 17, sculk_block, 0, 2);
		world.setBlock(i + 23, j + 1, k + 17, sculk_block, 0, 2);
		world.setBlock(i + 19, j + 1, k + 18, sculk_block, 0, 2);
		world.setBlock(i + 20, j + 1, k + 18, sculk_block, 0, 2);
		world.setBlock(i + 21, j + 1, k + 18, sculk_block, 0, 2);
		world.setBlock(i + 22, j + 1, k + 18, sculk_block, 0, 2);
		world.setBlock(i + 23, j + 1, k + 18, sculk_block, 0, 2);
		world.setBlock(i + 19, j + 1, k + 19, sculk_block, 0, 2);
		world.setBlock(i + 20, j + 1, k + 19, sculk_block, 0, 2);
		world.setBlock(i + 21, j + 1, k + 19, sculk_block, 0, 2);
		world.setBlock(i + 22, j + 1, k + 19, sculk_block, 0, 2);
		world.setBlock(i + 23, j + 1, k + 19, sculk_block, 0, 2);
		world.setBlock(i + 19, j + 1, k + 20, sculk_block, 0, 2);
		world.setBlock(i + 20, j + 1, k + 20, sculk_block, 0, 2);
		world.setBlock(i + 21, j + 1, k + 20, sculk_block, 0, 2);
		world.setBlock(i + 22, j + 1, k + 20, sculk_block, 0, 2);
		world.setBlock(i + 23, j + 1, k + 20, sculk_block, 0, 2);
		world.setBlock(i + 19, j + 1, k + 21, sculk_block, 0, 2);
		world.setBlock(i + 20, j + 1, k + 21, sculk_block, 0, 2);
		world.setBlock(i + 21, j + 1, k + 21, sculk_block, 0, 2);
		world.setBlock(i + 22, j + 1, k + 21, sculk_block, 0, 2);
		world.setBlock(i + 19, j + 1, k + 22, sculk_block, 0, 2);
		world.setBlock(i + 20, j + 1, k + 22, sculk_block, 0, 2);
		world.setBlock(i + 21, j + 1, k + 22, sculk_block, 0, 2);
		world.setBlock(i + 22, j + 1, k + 22, sculk_block, 0, 2);
		world.setBlock(i + 19, j + 1, k + 23, sculk_block, 0, 2);
		world.setBlock(i + 20, j + 1, k + 23, sculk_block, 0, 2);
		world.setBlock(i + 21, j + 1, k + 23, sculk_block, 0, 2);
		world.setBlock(i + 22, j + 1, k + 23, sculk_block, 0, 2);
		world.setBlock(i + 18, j + 1, k + 24, sculk_block, 0, 2);
		world.setBlock(i + 19, j + 1, k + 24, sculk_block, 0, 2);
		world.setBlock(i + 20, j + 1, k + 24, sculk_block, 0, 2);
		world.setBlock(i + 21, j + 1, k + 24, sculk_block, 0, 2);
		world.setBlock(i + 22, j + 1, k + 24, sculk_block, 0, 2);
		world.setBlock(i + 18, j + 1, k + 25, sculk_block, 0, 2);
		world.setBlock(i + 19, j + 1, k + 25, sculk_block, 0, 2);
		world.setBlock(i + 20, j + 1, k + 25, sculk_block, 0, 2);
		world.setBlock(i + 21, j + 1, k + 25, sculk_block, 0, 2);
		world.setBlock(i + 22, j + 1, k + 25, sculk_block, 0, 2);
		world.setBlock(i + 18, j + 1, k + 26, sculk_block, 0, 2);
		world.setBlock(i + 19, j + 1, k + 26, sculk_block, 0, 2);
		world.setBlock(i + 20, j + 1, k + 26, sculk_block, 0, 2);
		world.setBlock(i + 21, j + 1, k + 26, sculk_block, 0, 2);
		world.setBlock(i + 17, j + 1, k + 27, sculk_block, 0, 2);
		world.setBlock(i + 18, j + 1, k + 27, sculk_block, 0, 2);
		world.setBlock(i + 19, j + 1, k + 27, sculk_block, 0, 2);
		world.setBlock(i + 20, j + 1, k + 27, sculk_block, 0, 2);
		world.setBlock(i + 21, j + 1, k + 27, sculk_block, 0, 2);
		world.setBlock(i + 17, j + 1, k + 28, sculk_block, 0, 2);
		world.setBlock(i + 18, j + 1, k + 28, sculk_block, 0, 2);
		world.setBlock(i + 19, j + 1, k + 28, sculk_block, 0, 2);
		world.setBlock(i + 20, j + 1, k + 28, sculk_block, 0, 2);
		world.setBlock(i + 16, j + 1, k + 29, sculk_block, 0, 2);
		world.setBlock(i + 17, j + 1, k + 29, sculk_block, 0, 2);
		world.setBlock(i + 18, j + 1, k + 29, sculk_block, 0, 2);
		world.setBlock(i + 19, j + 1, k + 29, sculk_block, 0, 2);
		world.setBlock(i + 20, j + 1, k + 29, sculk_block, 0, 2);
		world.setBlock(i + 45, j + 1, k + 29, NovaCraftBlocks.sculk_vein, 0, 2);
		world.setBlock(i + 46, j + 1, k + 29, NovaCraftBlocks.sculk_vein, 0, 2);
		world.setBlock(i + 16, j + 1, k + 30, sculk_block, 0, 2);
		world.setBlock(i + 17, j + 1, k + 30, sculk_block, 0, 2);
		world.setBlock(i + 18, j + 1, k + 30, sculk_block, 0, 2);
		world.setBlock(i + 19, j + 1, k + 30, sculk_block, 0, 2);
		world.setBlock(i + 20, j + 1, k + 30, sculk_block, 0, 2);
		world.setBlock(i + 45, j + 1, k + 30, NovaCraftBlocks.sculk_vein, 0, 2);
		world.setBlock(i + 46, j + 1, k + 30, NovaCraftBlocks.sculk_vein, 0, 2);
		world.setBlock(i + 15, j + 1, k + 31, sculk_block, 0, 2);
		world.setBlock(i + 16, j + 1, k + 31, sculk_block, 0, 2);
		world.setBlock(i + 17, j + 1, k + 31, sculk_block, 0, 2);
		world.setBlock(i + 18, j + 1, k + 31, sculk_block, 0, 2);
		world.setBlock(i + 19, j + 1, k + 31, sculk_block, 0, 2);
		world.setBlock(i + 15, j + 1, k + 32, sculk_block, 0, 2);
		world.setBlock(i + 16, j + 1, k + 32, sculk_block, 0, 2);
		world.setBlock(i + 17, j + 1, k + 32, sculk_block, 0, 2);
		world.setBlock(i + 18, j + 1, k + 32, sculk_block, 0, 2);
		world.setBlock(i + 19, j + 1, k + 32, sculk_block, 0, 2);
		world.setBlock(i + 14, j + 1, k + 33, sculk_block, 0, 2);
		world.setBlock(i + 15, j + 1, k + 33, sculk_block, 0, 2);
		world.setBlock(i + 16, j + 1, k + 33, sculk_block, 0, 2);
		world.setBlock(i + 17, j + 1, k + 33, sculk_block, 0, 2);
		world.setBlock(i + 18, j + 1, k + 33, sculk_block, 0, 2);
		world.setBlock(i + 13, j + 1, k + 34, sculk_block, 0, 2);
		world.setBlock(i + 14, j + 1, k + 34, sculk_block, 0, 2);
		world.setBlock(i + 15, j + 1, k + 34, sculk_block, 0, 2);
		world.setBlock(i + 16, j + 1, k + 34, sculk_block, 0, 2);
		world.setBlock(i + 17, j + 1, k + 34, sculk_block, 0, 2);
		world.setBlock(i + 14, j + 1, k + 35, sculk_block, 0, 2);
		world.setBlock(i + 15, j + 1, k + 35, sculk_block, 0, 2);
		world.setBlock(i + 16, j + 1, k + 35, sculk_block, 0, 2);
		world.setBlock(i + 17, j + 1, k + 35, sculk_block, 0, 2);
		world.setBlock(i + 15, j + 1, k + 36, sculk_block, 0, 2);
		world.setBlock(i + 16, j + 1, k + 36, sculk_block, 0, 2);
		world.setBlock(i + 26, j + 1, k + 37, NovaCraftBlocks.sculk_vein, 0, 2);
		world.setBlock(i + 30, j + 2, k + 9, NovaCraftBlocks.sculk_vein, 0, 2);
		world.setBlock(i + 31, j + 2, k + 9, NovaCraftBlocks.sculk_vein, 0, 2);
		world.setBlock(i + 24, j + 2, k + 10, sculk_block, 0, 2);
		world.setBlock(i + 25, j + 2, k + 10, sculk_block, 0, 2);
		world.setBlock(i + 26, j + 2, k + 10, sculk_block, 0, 2);
		world.setBlock(i + 24, j + 2, k + 11, sculk_block, 0, 2);
		world.setBlock(i + 25, j + 2, k + 11, sculk_block, 0, 2);
		world.setBlock(i + 26, j + 2, k + 11, sculk_block, 0, 2);
		world.setBlock(i + 22, j + 2, k + 12, NovaCraftBlocks.sculk_tentacle_2, 1, 2);
		world.setBlock(i + 24, j + 2, k + 12, sculk_block, 0, 2);
		world.setBlock(i + 25, j + 2, k + 12, sculk_block, 0, 2);
		world.setBlock(i + 26, j + 2, k + 12, sculk_block, 0, 2);
		world.setBlock(i + 24, j + 2, k + 13, sculk_block, 0, 2);
		world.setBlock(i + 25, j + 2, k + 13, sculk_block, 0, 2);
		world.setBlock(i + 26, j + 2, k + 13, sculk_block, 0, 2);
		world.setBlock(i + 24, j + 2, k + 14, sculk_block, 0, 2);
		world.setBlock(i + 25, j + 2, k + 14, sculk_block, 0, 2);
		world.setBlock(i + 26, j + 2, k + 14, sculk_block, 0, 2);
		world.setBlock(i + 37, j + 2, k + 14, NovaCraftBlocks.sculk_vein, 0, 2);
		world.setBlock(i + 24, j + 2, k + 15, sculk_block, 0, 2);
		world.setBlock(i + 25, j + 2, k + 15, sculk_block, 0, 2);
		world.setBlock(i + 26, j + 2, k + 15, sculk_block, 0, 2);
		world.setBlock(i + 20, j + 2, k + 16, NovaCraftBlocks.sculk_tentacle_2, 1, 2);
		world.setBlock(i + 24, j + 2, k + 16, sculk_block, 0, 2);
		world.setBlock(i + 25, j + 2, k + 16, sculk_block, 0, 2);
		world.setBlock(i + 26, j + 2, k + 16, sculk_block, 0, 2);
		world.setBlock(i + 24, j + 2, k + 17, sculk_block, 0, 2);
		world.setBlock(i + 25, j + 2, k + 17, sculk_block, 0, 2);
		world.setBlock(i + 26, j + 2, k + 17, sculk_block, 0, 2);
		world.setBlock(i + 22, j + 2, k + 18, NovaCraftBlocks.sculk_vein, 1, 2);
		world.setBlock(i + 24, j + 2, k + 18, sculk_block, 0, 2);
		world.setBlock(i + 25, j + 2, k + 18, sculk_block, 0, 2);
		world.setBlock(i + 26, j + 2, k + 18, sculk_block, 0, 2);
		world.setBlock(i + 24, j + 2, k + 19, sculk_block, 0, 2);
		world.setBlock(i + 25, j + 2, k + 19, sculk_block, 0, 2);
		world.setBlock(i + 26, j + 2, k + 19, sculk_block, 0, 2);
		world.setBlock(i + 22, j + 2, k + 20, NovaCraftBlocks.sculk_tentacle_2, 1, 2);
		world.setBlock(i + 24, j + 2, k + 20, sculk_block, 0, 2);
		world.setBlock(i + 25, j + 2, k + 20, sculk_block, 0, 2);
		world.setBlock(i + 26, j + 2, k + 20, sculk_block, 0, 2);
		world.setBlock(i + 23, j + 2, k + 21, sculk_block, 0, 2);
		world.setBlock(i + 24, j + 2, k + 21, sculk_block, 0, 2);
		world.setBlock(i + 25, j + 2, k + 21, sculk_block, 0, 2);
		world.setBlock(i + 26, j + 2, k + 21, sculk_block, 0, 2);
		world.setBlock(i + 23, j + 2, k + 22, sculk_block, 0, 2);
		world.setBlock(i + 24, j + 2, k + 22, sculk_block, 0, 2);
		world.setBlock(i + 25, j + 2, k + 22, sculk_block, 0, 2);
		world.setBlock(i + 26, j + 2, k + 22, sculk_block, 0, 2);
		world.setBlock(i + 38, j + 2, k + 22, NovaCraftBlocks.sculk_vein, 0, 2);
		world.setBlock(i + 23, j + 2, k + 23, sculk_block, 0, 2);
		world.setBlock(i + 24, j + 2, k + 23, sculk_block, 0, 2);
		world.setBlock(i + 25, j + 2, k + 23, sculk_block, 0, 2);
		world.setBlock(i + 26, j + 2, k + 23, sculk_block, 0, 2);
		world.setBlock(i + 19, j + 2, k + 24, NovaCraftBlocks.sculk_vein, 1, 2);
		world.setBlock(i + 23, j + 2, k + 24, sculk_block, 0, 2);
		world.setBlock(i + 24, j + 2, k + 24, sculk_block, 0, 2);
		world.setBlock(i + 25, j + 2, k + 24, sculk_block, 0, 2);
		world.setBlock(i + 22, j + 2, k + 25, NovaCraftBlocks.sculk_tentacle_2, 1, 2);
		world.setBlock(i + 23, j + 2, k + 25, sculk_block, 0, 2);
		world.setBlock(i + 24, j + 2, k + 25, sculk_block, 0, 2);
		world.setBlock(i + 25, j + 2, k + 25, sculk_block, 0, 2);
		world.setBlock(i + 22, j + 2, k + 26, sculk_block, 0, 2);
		world.setBlock(i + 23, j + 2, k + 26, sculk_block, 0, 2);
		world.setBlock(i + 24, j + 2, k + 26, sculk_block, 0, 2);
		world.setBlock(i + 25, j + 2, k + 26, sculk_block, 0, 2);
		world.setBlock(i + 19, j + 2, k + 27, sculk_tendrils, 0, 2);
		world.setBlock(i + 22, j + 2, k + 27, sculk_block, 0, 2);
		world.setBlock(i + 23, j + 2, k + 27, sculk_block, 0, 2);
		world.setBlock(i + 24, j + 2, k + 27, sculk_block, 0, 2);
		world.setBlock(i + 25, j + 2, k + 27, sculk_block, 0, 2);
		world.setBlock(i + 21, j + 2, k + 28, sculk_block, 0, 2);
		world.setBlock(i + 22, j + 2, k + 28, sculk_block, 0, 2);
		world.setBlock(i + 23, j + 2, k + 28, sculk_block, 0, 2);
		world.setBlock(i + 24, j + 2, k + 28, sculk_block, 0, 2);
		world.setBlock(i + 18, j + 2, k + 29, NovaCraftBlocks.sculk_tentacle_2, 1, 2);
		world.setBlock(i + 21, j + 2, k + 29, sculk_block, 0, 2);
		world.setBlock(i + 22, j + 2, k + 29, sculk_block, 0, 2);
		world.setBlock(i + 23, j + 2, k + 29, sculk_block, 0, 2);
		world.setBlock(i + 24, j + 2, k + 29, sculk_block, 0, 2);
		world.setBlock(i + 29, j + 2, k + 29, NovaCraftBlocks.sculk_vein, 0, 2);
		world.setBlock(i + 30, j + 2, k + 29, NovaCraftBlocks.sculk_vein, 0, 2);
		world.setBlock(i + 21, j + 2, k + 30, sculk_block, 0, 2);
		world.setBlock(i + 22, j + 2, k + 30, sculk_block, 0, 2);
		world.setBlock(i + 23, j + 2, k + 30, sculk_block, 0, 2);
		world.setBlock(i + 45, j + 2, k + 30, NovaCraftBlocks.sculk_vein, 0, 2);
		world.setBlock(i + 20, j + 2, k + 31, sculk_block, 0, 2);
		world.setBlock(i + 21, j + 2, k + 31, sculk_block, 0, 2);
		world.setBlock(i + 22, j + 2, k + 31, sculk_block, 0, 2);
		world.setBlock(i + 23, j + 2, k + 31, sculk_block, 0, 2);
		world.setBlock(i + 20, j + 2, k + 32, sculk_block, 0, 2);
		world.setBlock(i + 21, j + 2, k + 32, sculk_block, 0, 2);
		world.setBlock(i + 22, j + 2, k + 32, sculk_block, 0, 2);
		world.setBlock(i + 23, j + 2, k + 32, sculk_block, 0, 2);
		world.setBlock(i + 16, j + 2, k + 33, NovaCraftBlocks.sculk_tentacle_2, 1, 2);
		world.setBlock(i + 19, j + 2, k + 33, sculk_block, 0, 2);
		world.setBlock(i + 20, j + 2, k + 33, sculk_block, 0, 2);
		world.setBlock(i + 21, j + 2, k + 33, sculk_block, 0, 2);
		world.setBlock(i + 22, j + 2, k + 33, sculk_block, 0, 2);
		world.setBlock(i + 18, j + 2, k + 34, sculk_block, 0, 2);
		world.setBlock(i + 19, j + 2, k + 34, sculk_block, 0, 2);
		world.setBlock(i + 20, j + 2, k + 34, sculk_block, 0, 2);
		world.setBlock(i + 21, j + 2, k + 34, sculk_block, 0, 2);
		world.setBlock(i + 22, j + 2, k + 34, sculk_block, 0, 2);
		world.setBlock(i + 18, j + 2, k + 35, sculk_block, 0, 2);
		world.setBlock(i + 19, j + 2, k + 35, sculk_block, 0, 2);
		world.setBlock(i + 20, j + 2, k + 35, sculk_block, 0, 2);
		world.setBlock(i + 21, j + 2, k + 35, sculk_block, 0, 2);
		world.setBlock(i + 17, j + 2, k + 36, sculk_block, 0, 2);
		world.setBlock(i + 18, j + 2, k + 36, sculk_block, 0, 2);
		world.setBlock(i + 19, j + 2, k + 36, sculk_block, 0, 2);
		world.setBlock(i + 20, j + 2, k + 36, sculk_block, 0, 2);
		world.setBlock(i + 16, j + 2, k + 37, sculk_block, 0, 2);
		world.setBlock(i + 17, j + 2, k + 37, sculk_block, 0, 2);
		world.setBlock(i + 18, j + 2, k + 37, sculk_block, 0, 2);
		world.setBlock(i + 19, j + 2, k + 37, sculk_block, 0, 2);
		world.setBlock(i + 20, j + 2, k + 37, sculk_block, 0, 2);
		world.setBlock(i + 43, j + 2, k + 37, NovaCraftBlocks.sculk_vein, 0, 2);
		world.setBlock(i + 43, j + 2, k + 38, NovaCraftBlocks.sculk_vein, 0, 2);
		world.setBlock(i + 30, j + 3, k + 8, NovaCraftBlocks.sculk_vein, 0, 2);
		world.setBlock(i + 31, j + 3, k + 8, NovaCraftBlocks.sculk_vein, 0, 2);
		world.setBlock(i + 47, j + 3, k + 8, NovaCraftBlocks.sculk_vein, 0, 2);
		world.setBlock(i + 30, j + 3, k + 9, NovaCraftBlocks.sculk_vein, 0, 2);
		world.setBlock(i + 48, j + 3, k + 9, NovaCraftBlocks.sculk_vein, 0, 2);
		world.setBlock(i + 27, j + 3, k + 10, sculk_block, 0, 2);
		world.setBlock(i + 28, j + 3, k + 10, sculk_block, 0, 2);
		world.setBlock(i + 29, j + 3, k + 10, sculk_block, 0, 2);
		world.setBlock(i + 24, j + 3, k + 11, NovaCraftBlocks.sculk_tentacle_2, 1, 2);
		world.setBlock(i + 27, j + 3, k + 11, sculk_block, 0, 2);
		world.setBlock(i + 28, j + 3, k + 11, sculk_block, 0, 2);
		world.setBlock(i + 29, j + 3, k + 11, sculk_block, 0, 2);
		world.setBlock(i + 27, j + 3, k + 12, sculk_block, 0, 2);
		world.setBlock(i + 28, j + 3, k + 12, sculk_block, 0, 2);
		world.setBlock(i + 29, j + 3, k + 12, sculk_block, 0, 2);
		world.setBlock(i + 27, j + 3, k + 13, sculk_block, 0, 2);
		world.setBlock(i + 28, j + 3, k + 13, sculk_block, 0, 2);
		world.setBlock(i + 29, j + 3, k + 13, sculk_block, 0, 2);
		world.setBlock(i + 36, j + 3, k + 13, NovaCraftBlocks.sculk_vein, 0, 2);
		world.setBlock(i + 37, j + 3, k + 13, NovaCraftBlocks.sculk_vein, 0, 2);
		world.setBlock(i + 27, j + 3, k + 14, sculk_block, 0, 2);
		world.setBlock(i + 28, j + 3, k + 14, sculk_block, 0, 2);
		world.setBlock(i + 29, j + 3, k + 14, sculk_block, 0, 2);
		world.setBlock(i + 30, j + 3, k + 14, sculk_block, 0, 2);
		world.setBlock(i + 36, j + 3, k + 14, NovaCraftBlocks.sculk_vein, 0, 2);
		world.setBlock(i + 37, j + 3, k + 14, NovaCraftBlocks.sculk_vein, 0, 2);
		world.setBlock(i + 27, j + 3, k + 15, sculk_block, 0, 2);
		world.setBlock(i + 28, j + 3, k + 15, sculk_block, 0, 2);
		world.setBlock(i + 29, j + 3, k + 15, sculk_block, 0, 2);
		world.setBlock(i + 30, j + 3, k + 15, sculk_block, 0, 2);
		world.setBlock(i + 31, j + 3, k + 15, sculk_block, 0, 2);
		world.setBlock(i + 25, j + 3, k + 16, sculk_tendrils, 0, 2);
		world.setBlock(i + 27, j + 3, k + 16, sculk_block, 0, 2);
		world.setBlock(i + 28, j + 3, k + 16, sculk_block, 0, 2);
		world.setBlock(i + 29, j + 3, k + 16, sculk_block, 0, 2);
		world.setBlock(i + 30, j + 3, k + 16, sculk_block, 0, 2);
		world.setBlock(i + 31, j + 3, k + 16, sculk_block, 0, 2);
		world.setBlock(i + 27, j + 3, k + 17, sculk_block, 0, 2);
		world.setBlock(i + 28, j + 3, k + 17, sculk_block, 0, 2);
		world.setBlock(i + 29, j + 3, k + 17, sculk_block, 0, 2);
		world.setBlock(i + 30, j + 3, k + 17, sculk_block, 0, 2);
		world.setBlock(i + 27, j + 3, k + 18, sculk_block, 0, 2);
		world.setBlock(i + 28, j + 3, k + 18, sculk_block, 0, 2);
		world.setBlock(i + 29, j + 3, k + 18, sculk_block, 0, 2);
		world.setBlock(i + 27, j + 3, k + 19, sculk_block, 0, 2);
		world.setBlock(i + 28, j + 3, k + 19, sculk_block, 0, 2);
		world.setBlock(i + 29, j + 3, k + 19, sculk_block, 0, 2);
		world.setBlock(i + 26, j + 3, k + 20, NovaCraftBlocks.sculk_tentacle_2, 1, 2);
		world.setBlock(i + 27, j + 3, k + 20, sculk_block, 0, 2);
		world.setBlock(i + 28, j + 3, k + 20, sculk_block, 0, 2);
		world.setBlock(i + 29, j + 3, k + 20, sculk_block, 0, 2);
		world.setBlock(i + 27, j + 3, k + 21, sculk_block, 0, 2);
		world.setBlock(i + 28, j + 3, k + 21, sculk_block, 0, 2);
		world.setBlock(i + 29, j + 3, k + 21, sculk_block, 0, 2);
		world.setBlock(i + 27, j + 3, k + 22, sculk_block, 0, 2);
		world.setBlock(i + 28, j + 3, k + 22, sculk_block, 0, 2);
		world.setBlock(i + 29, j + 3, k + 22, sculk_block, 0, 2);
		world.setBlock(i + 38, j + 3, k + 22, NovaCraftBlocks.sculk_vein, 0, 2);
		world.setBlock(i + 27, j + 3, k + 23, sculk_block, 0, 2);
		world.setBlock(i + 28, j + 3, k + 23, sculk_block, 0, 2);
		world.setBlock(i + 29, j + 3, k + 23, sculk_block, 0, 2);
		world.setBlock(i + 37, j + 3, k + 23, NovaCraftBlocks.sculk_vein, 0, 2);
		world.setBlock(i + 26, j + 3, k + 24, sculk_block, 0, 2);
		world.setBlock(i + 27, j + 3, k + 24, sculk_block, 0, 2);
		world.setBlock(i + 28, j + 3, k + 24, sculk_block, 0, 2);
		world.setBlock(i + 26, j + 3, k + 25, sculk_block, 0, 2);
		world.setBlock(i + 27, j + 3, k + 25, sculk_block, 0, 2);
		world.setBlock(i + 28, j + 3, k + 25, sculk_block, 0, 2);
		world.setBlock(i + 24, j + 3, k + 26, NovaCraftBlocks.sculk_vein, 1, 2);
		world.setBlock(i + 26, j + 3, k + 26, sculk_block, 0, 2);
		world.setBlock(i + 27, j + 3, k + 26, sculk_block, 0, 2);
		world.setBlock(i + 28, j + 3, k + 26, sculk_block, 0, 2);
		world.setBlock(i + 26, j + 3, k + 27, sculk_block, 0, 2);
		world.setBlock(i + 27, j + 3, k + 27, sculk_block, 0, 2);
		world.setBlock(i + 28, j + 3, k + 27, sculk_block, 0, 2);
		world.setBlock(i + 25, j + 3, k + 28, sculk_block, 0, 2);
		world.setBlock(i + 26, j + 3, k + 28, sculk_block, 0, 2);
		world.setBlock(i + 27, j + 3, k + 28, sculk_block, 0, 2);
		world.setBlock(i + 29, j + 3, k + 28, NovaCraftBlocks.sculk_vein, 0, 2);
		world.setBlock(i + 30, j + 3, k + 28, NovaCraftBlocks.sculk_vein, 0, 2);
		world.setBlock(i + 24, j + 3, k + 29, NovaCraftBlocks.sculk_tentacle_2, 1, 2);
		world.setBlock(i + 25, j + 3, k + 29, sculk_block, 0, 2);
		world.setBlock(i + 26, j + 3, k + 29, sculk_block, 0, 2);
		world.setBlock(i + 27, j + 3, k + 29, sculk_block, 0, 2);
		world.setBlock(i + 24, j + 3, k + 30, sculk_block, 0, 2);
		world.setBlock(i + 25, j + 3, k + 30, sculk_block, 0, 2);
		world.setBlock(i + 26, j + 3, k + 30, sculk_block, 0, 2);
		world.setBlock(i + 27, j + 3, k + 30, sculk_block, 0, 2);
		world.setBlock(i + 32, j + 3, k + 30, NovaCraftBlocks.sculk_vein, 0, 2);
		world.setBlock(i + 24, j + 3, k + 31, sculk_block, 0, 2);
		world.setBlock(i + 25, j + 3, k + 31, sculk_block, 0, 2);
		world.setBlock(i + 26, j + 3, k + 31, sculk_block, 0, 2);
		world.setBlock(i + 31, j + 3, k + 31, NovaCraftBlocks.sculk_vein, 0, 2);
		world.setBlock(i + 24, j + 3, k + 32, sculk_block, 0, 2);
		world.setBlock(i + 25, j + 3, k + 32, sculk_block, 0, 2);
		world.setBlock(i + 26, j + 3, k + 32, sculk_block, 0, 2);
		world.setBlock(i + 23, j + 3, k + 33, sculk_block, 0, 2);
		world.setBlock(i + 24, j + 3, k + 33, sculk_block, 0, 2);
		world.setBlock(i + 25, j + 3, k + 33, sculk_block, 0, 2);
		world.setBlock(i + 22, j + 3, k + 34, sculk_block, 0, 2);
		world.setBlock(i + 23, j + 3, k + 34, sculk_block, 0, 2);
		world.setBlock(i + 24, j + 3, k + 34, sculk_block, 0, 2);
		world.setBlock(i + 25, j + 3, k + 34, sculk_block, 0, 2);
		world.setBlock(i + 19, j + 3, k + 35, NovaCraftBlocks.sculk_tentacle_2, 1, 2);
		world.setBlock(i + 22, j + 3, k + 35, sculk_block, 0, 2);
		world.setBlock(i + 23, j + 3, k + 35, sculk_block, 0, 2);
		world.setBlock(i + 24, j + 3, k + 35, sculk_block, 0, 2);
		world.setBlock(i + 21, j + 3, k + 36, sculk_block, 0, 2);
		world.setBlock(i + 22, j + 3, k + 36, sculk_block, 0, 2);
		world.setBlock(i + 23, j + 3, k + 36, sculk_block, 0, 2);
		world.setBlock(i + 24, j + 3, k + 36, sculk_block, 0, 2);
		world.setBlock(i + 21, j + 3, k + 37, sculk_block, 0, 2);
		world.setBlock(i + 22, j + 3, k + 37, sculk_block, 0, 2);
		world.setBlock(i + 23, j + 3, k + 37, sculk_block, 0, 2);
		world.setBlock(i + 42, j + 3, k + 37, NovaCraftBlocks.sculk_vein, 0, 2);
		world.setBlock(i + 20, j + 3, k + 38, sculk_block, 0, 2);
		world.setBlock(i + 21, j + 3, k + 38, sculk_block, 0, 2);
		world.setBlock(i + 22, j + 3, k + 38, sculk_block, 0, 2);
		world.setBlock(i + 23, j + 3, k + 38, sculk_block, 0, 2);
		world.setBlock(i + 42, j + 3, k + 38, NovaCraftBlocks.sculk_vein, 0, 2);
		world.setBlock(i + 47, j + 3, k + 40, NovaCraftBlocks.sculk_vein, 0, 2);
		world.setBlock(i + 48, j + 3, k + 40, NovaCraftBlocks.sculk_vein, 0, 2);
		world.setBlock(i + 47, j + 3, k + 41, NovaCraftBlocks.sculk_vein, 0, 2);
		world.setBlock(i + 48, j + 3, k + 41, NovaCraftBlocks.sculk_vein, 0, 2);
		world.setBlock(i + 38, j + 3, k + 43, NovaCraftBlocks.sculk_vein, 0, 2);
		world.setBlock(i + 30, j + 4, k + 8, NovaCraftBlocks.sculk_vein, 0, 2);
		world.setBlock(i + 47, j + 4, k + 8, NovaCraftBlocks.sculk_vein, 0, 2);
		world.setBlock(i + 48, j + 4, k + 9, NovaCraftBlocks.sculk_vein, 0, 2);
		world.setBlock(i + 30, j + 4, k + 10, sculk_block, 0, 2);
		world.setBlock(i + 31, j + 4, k + 10, sculk_block, 0, 2);
		world.setBlock(i + 32, j + 4, k + 10, sculk_block, 0, 2);
		world.setBlock(i + 28, j + 4, k + 11, NovaCraftBlocks.sculk_tentacle_2, 1, 2);
		world.setBlock(i + 30, j + 4, k + 11, sculk_block, 0, 2);
		world.setBlock(i + 31, j + 4, k + 11, sculk_block, 0, 2);
		world.setBlock(i + 32, j + 4, k + 11, sculk_block, 0, 2);
		world.setBlock(i + 30, j + 4, k + 12, sculk_block, 0, 2);
		world.setBlock(i + 31, j + 4, k + 12, sculk_block, 0, 2);
		world.setBlock(i + 32, j + 4, k + 12, sculk_block, 0, 2);
		world.setBlock(i + 30, j + 4, k + 13, sculk_block, 0, 2);
		world.setBlock(i + 31, j + 4, k + 13, sculk_block, 0, 2);
		world.setBlock(i + 32, j + 4, k + 13, sculk_block, 0, 2);
		world.setBlock(i + 30, j + 4, k + 14, sculk_block, 0, 2);
		world.setBlock(i + 31, j + 4, k + 14, sculk_block, 0, 2);
		world.setBlock(i + 32, j + 4, k + 14, sculk_block, 0, 2);
		world.setBlock(i + 33, j + 4, k + 14, sculk_block, 0, 2);
		world.setBlock(i + 29, j + 4, k + 15, NovaCraftBlocks.sculk_vein, 1, 2);
		world.setBlock(i + 30, j + 4, k + 15, sculk_block, 0, 2);
		world.setBlock(i + 31, j + 4, k + 15, sculk_block, 0, 2);
		world.setBlock(i + 32, j + 4, k + 15, sculk_block, 0, 2);
		world.setBlock(i + 33, j + 4, k + 15, sculk_block, 0, 2);
		world.setBlock(i + 30, j + 4, k + 16, sculk_block, 0, 2);
		world.setBlock(i + 31, j + 4, k + 16, sculk_block, 0, 2);
		world.setBlock(i + 32, j + 4, k + 16, sculk_block, 0, 2);
		world.setBlock(i + 28, j + 4, k + 17, NovaCraftBlocks.sculk_tentacle_2, 1, 2);
		world.setBlock(i + 30, j + 4, k + 17, sculk_block, 0, 2);
		world.setBlock(i + 31, j + 4, k + 17, sculk_block, 0, 2);
		world.setBlock(i + 32, j + 4, k + 17, sculk_block, 0, 2);
		world.setBlock(i + 30, j + 4, k + 18, sculk_block, 0, 2);
		world.setBlock(i + 31, j + 4, k + 18, sculk_block, 0, 2);
		world.setBlock(i + 32, j + 4, k + 18, sculk_block, 0, 2);
		world.setBlock(i + 30, j + 4, k + 19, sculk_block, 0, 2);
		world.setBlock(i + 31, j + 4, k + 19, sculk_block, 0, 2);
		world.setBlock(i + 32, j + 4, k + 19, sculk_block, 0, 2);
		world.setBlock(i + 30, j + 4, k + 20, sculk_block, 0, 2);
		world.setBlock(i + 31, j + 4, k + 20, sculk_block, 0, 2);
		world.setBlock(i + 32, j + 4, k + 20, sculk_block, 0, 2);
		world.setBlock(i + 30, j + 4, k + 21, sculk_block, 0, 2);
		world.setBlock(i + 31, j + 4, k + 21, sculk_block, 0, 2);
		world.setBlock(i + 32, j + 4, k + 21, sculk_block, 0, 2);
		world.setBlock(i + 30, j + 4, k + 22, sculk_block, 0, 2);
		world.setBlock(i + 31, j + 4, k + 22, sculk_block, 0, 2);
		world.setBlock(i + 30, j + 4, k + 23, sculk_block, 0, 2);
		world.setBlock(i + 31, j + 4, k + 23, sculk_block, 0, 2);
		world.setBlock(i + 37, j + 4, k + 23, NovaCraftBlocks.sculk_vein, 0, 2);
		world.setBlock(i + 29, j + 4, k + 24, sculk_block, 0, 2);
		world.setBlock(i + 30, j + 4, k + 24, sculk_block, 0, 2);
		world.setBlock(i + 31, j + 4, k + 24, sculk_block, 0, 2);
		world.setBlock(i + 29, j + 4, k + 25, sculk_block, 0, 2);
		world.setBlock(i + 30, j + 4, k + 25, sculk_block, 0, 2);
		world.setBlock(i + 31, j + 4, k + 25, sculk_block, 0, 2);
		world.setBlock(i + 29, j + 4, k + 26, sculk_block, 0, 2);
		world.setBlock(i + 30, j + 4, k + 26, sculk_block, 0, 2);
		world.setBlock(i + 31, j + 4, k + 26, sculk_block, 0, 2);
		world.setBlock(i + 29, j + 4, k + 27, sculk_block, 0, 2);
		world.setBlock(i + 30, j + 4, k + 27, sculk_block, 0, 2);
		world.setBlock(i + 26, j + 4, k + 28, NovaCraftBlocks.sculk_tentacle_2, 1, 2);
		world.setBlock(i + 28, j + 4, k + 28, sculk_block, 0, 2);
		world.setBlock(i + 29, j + 4, k + 28, sculk_block, 0, 2);
		world.setBlock(i + 30, j + 4, k + 28, sculk_block, 0, 2);
		world.setBlock(i + 28, j + 4, k + 29, sculk_block, 0, 2);
		world.setBlock(i + 29, j + 4, k + 29, sculk_block, 0, 2);
		world.setBlock(i + 30, j + 4, k + 29, sculk_block, 0, 2);
		world.setBlock(i + 28, j + 4, k + 30, sculk_block, 0, 2);
		world.setBlock(i + 29, j + 4, k + 30, sculk_block, 0, 2);
		world.setBlock(i + 27, j + 4, k + 31, sculk_block, 0, 2);
		world.setBlock(i + 28, j + 4, k + 31, sculk_block, 0, 2);
		world.setBlock(i + 29, j + 4, k + 31, sculk_block, 0, 2);
		world.setBlock(i + 27, j + 4, k + 32, sculk_block, 0, 2);
		world.setBlock(i + 28, j + 4, k + 32, sculk_block, 0, 2);
		world.setBlock(i + 29, j + 4, k + 32, sculk_block, 0, 2);
		world.setBlock(i + 26, j + 4, k + 33, sculk_block, 0, 2);
		world.setBlock(i + 27, j + 4, k + 33, sculk_block, 0, 2);
		world.setBlock(i + 28, j + 4, k + 33, sculk_block, 0, 2);
		world.setBlock(i + 22, j + 4, k + 34, NovaCraftBlocks.sculk_vein, 1, 2);
		world.setBlock(i + 25, j + 4, k + 34, sculk_block, 0, 2);
		world.setBlock(i + 26, j + 4, k + 34, sculk_block, 0, 2);
		world.setBlock(i + 27, j + 4, k + 34, sculk_block, 0, 2);
		world.setBlock(i + 28, j + 4, k + 34, sculk_block, 0, 2);
		world.setBlock(i + 25, j + 4, k + 35, sculk_block, 0, 2);
		world.setBlock(i + 26, j + 4, k + 35, sculk_block, 0, 2);
		world.setBlock(i + 27, j + 4, k + 35, sculk_block, 0, 2);
		world.setBlock(i + 25, j + 4, k + 36, sculk_block, 0, 2);
		world.setBlock(i + 26, j + 4, k + 36, sculk_block, 0, 2);
		world.setBlock(i + 27, j + 4, k + 36, sculk_block, 0, 2);
		world.setBlock(i + 24, j + 4, k + 37, sculk_block, 0, 2);
		world.setBlock(i + 25, j + 4, k + 37, sculk_block, 0, 2);
		world.setBlock(i + 26, j + 4, k + 37, sculk_block, 0, 2);
		world.setBlock(i + 42, j + 4, k + 37, NovaCraftBlocks.sculk_vein, 0, 2);
		world.setBlock(i + 24, j + 4, k + 38, sculk_block, 0, 2);
		world.setBlock(i + 25, j + 4, k + 38, sculk_block, 0, 2);
		world.setBlock(i + 26, j + 4, k + 38, sculk_block, 0, 2);
		world.setBlock(i + 23, j + 4, k + 39, sculk_block, 0, 2);
		world.setBlock(i + 24, j + 4, k + 39, sculk_block, 0, 2);
		world.setBlock(i + 25, j + 4, k + 39, sculk_block, 0, 2);
		world.setBlock(i + 39, j + 4, k + 42, NovaCraftBlocks.sculk_vein, 0, 2);
		world.setBlock(i + 38, j + 4, k + 43, NovaCraftBlocks.sculk_vein, 0, 2);
		world.setBlock(i + 34, j + 5, k + 9, sculk_block, 0, 2);
		world.setBlock(i + 33, j + 5, k + 10, sculk_block, 0, 2);
		world.setBlock(i + 34, j + 5, k + 10, sculk_block, 0, 2);
		world.setBlock(i + 32, j + 5, k + 11, NovaCraftBlocks.sculk_tentacle_2, 1, 2);
		world.setBlock(i + 33, j + 5, k + 11, sculk_block, 0, 2);
		world.setBlock(i + 34, j + 5, k + 11, sculk_block, 0, 2);
		world.setBlock(i + 33, j + 5, k + 12, sculk_block, 0, 2);
		world.setBlock(i + 34, j + 5, k + 12, sculk_block, 0, 2);
		world.setBlock(i + 33, j + 5, k + 13, sculk_block, 0, 2);
		world.setBlock(i + 34, j + 5, k + 13, sculk_block, 0, 2);
		world.setBlock(i + 32, j + 5, k + 14, NovaCraftBlocks.sculk_tentacle_2, 1, 2);
		world.setBlock(i + 33, j + 5, k + 14, sculk_block, 0, 2);
		world.setBlock(i + 34, j + 5, k + 14, sculk_block, 0, 2);
		world.setBlock(i + 33, j + 5, k + 15, sculk_block, 0, 2);
		world.setBlock(i + 34, j + 5, k + 15, sculk_block, 0, 2);
		world.setBlock(i + 30, j + 5, k + 16, NovaCraftBlocks.sculk_tentacle_2, 1, 2);
		world.setBlock(i + 33, j + 5, k + 16, sculk_block, 0, 2);
		world.setBlock(i + 34, j + 5, k + 16, sculk_block, 0, 2);
		world.setBlock(i + 33, j + 5, k + 17, sculk_block, 0, 2);
		world.setBlock(i + 34, j + 5, k + 17, sculk_block, 0, 2);
		world.setBlock(i + 33, j + 5, k + 18, sculk_block, 0, 2);
		world.setBlock(i + 34, j + 5, k + 18, sculk_block, 0, 2);
		world.setBlock(i + 33, j + 5, k + 19, sculk_block, 0, 2);
		world.setBlock(i + 34, j + 5, k + 19, sculk_block, 0, 2);
		world.setBlock(i + 33, j + 5, k + 20, sculk_block, 0, 2);
		world.setBlock(i + 34, j + 5, k + 20, sculk_block, 0, 2);
		world.setBlock(i + 33, j + 5, k + 21, sculk_block, 0, 2);
		world.setBlock(i + 34, j + 5, k + 21, sculk_block, 0, 2);
		world.setBlock(i + 32, j + 5, k + 22, sculk_block, 0, 2);
		world.setBlock(i + 33, j + 5, k + 22, sculk_block, 0, 2);
		world.setBlock(i + 34, j + 5, k + 22, sculk_block, 0, 2);
		world.setBlock(i + 32, j + 5, k + 23, sculk_block, 0, 2);
		world.setBlock(i + 33, j + 5, k + 23, sculk_block, 0, 2);
		world.setBlock(i + 32, j + 5, k + 24, sculk_block, 0, 2);
		world.setBlock(i + 33, j + 5, k + 24, sculk_block, 0, 2);
		world.setBlock(i + 32, j + 5, k + 25, sculk_block, 0, 2);
		world.setBlock(i + 33, j + 5, k + 25, sculk_block, 0, 2);
		world.setBlock(i + 32, j + 5, k + 26, sculk_block, 0, 2);
		world.setBlock(i + 33, j + 5, k + 26, sculk_block, 0, 2);
		world.setBlock(i + 31, j + 5, k + 27, sculk_block, 0, 2);
		world.setBlock(i + 32, j + 5, k + 27, sculk_block, 0, 2);
		world.setBlock(i + 33, j + 5, k + 27, sculk_block, 0, 2);
		world.setBlock(i + 31, j + 5, k + 28, sculk_block, 0, 2);
		world.setBlock(i + 32, j + 5, k + 28, sculk_block, 0, 2);
		world.setBlock(i + 31, j + 5, k + 29, sculk_block, 0, 2);
		world.setBlock(i + 32, j + 5, k + 29, sculk_block, 0, 2);
		world.setBlock(i + 30, j + 5, k + 30, sculk_block, 0, 2);
		world.setBlock(i + 31, j + 5, k + 30, sculk_block, 0, 2);
		world.setBlock(i + 32, j + 5, k + 30, sculk_block, 0, 2);
		world.setBlock(i + 30, j + 5, k + 31, sculk_block, 0, 2);
		world.setBlock(i + 31, j + 5, k + 31, sculk_block, 0, 2);
		world.setBlock(i + 30, j + 5, k + 32, sculk_block, 0, 2);
		world.setBlock(i + 31, j + 5, k + 32, sculk_block, 0, 2);
		world.setBlock(i + 29, j + 5, k + 33, sculk_block, 0, 2);
		world.setBlock(i + 30, j + 5, k + 33, sculk_block, 0, 2);
		world.setBlock(i + 31, j + 5, k + 33, sculk_block, 0, 2);
		world.setBlock(i + 28, j + 5, k + 34, sculk_block, 0, 2);
		world.setBlock(i + 29, j + 5, k + 34, sculk_block, 0, 2);
		world.setBlock(i + 30, j + 5, k + 34, sculk_block, 0, 2);
		world.setBlock(i + 28, j + 5, k + 35, sculk_block, 0, 2);
		world.setBlock(i + 29, j + 5, k + 35, sculk_block, 0, 2);
		world.setBlock(i + 30, j + 5, k + 35, sculk_block, 0, 2);
		world.setBlock(i + 28, j + 5, k + 36, sculk_block, 0, 2);
		world.setBlock(i + 29, j + 5, k + 36, sculk_block, 0, 2);
		world.setBlock(i + 24, j + 5, k + 37, NovaCraftBlocks.sculk_tentacle_2, 1, 2);
		world.setBlock(i + 27, j + 5, k + 37, sculk_block, 0, 2);
		world.setBlock(i + 28, j + 5, k + 37, sculk_block, 0, 2);
		world.setBlock(i + 29, j + 5, k + 37, sculk_block, 0, 2);
		world.setBlock(i + 27, j + 5, k + 38, sculk_block, 0, 2);
		world.setBlock(i + 28, j + 5, k + 38, sculk_block, 0, 2);
		world.setBlock(i + 26, j + 5, k + 39, sculk_block, 0, 2);
		world.setBlock(i + 27, j + 5, k + 39, sculk_block, 0, 2);
		world.setBlock(i + 28, j + 5, k + 39, sculk_block, 0, 2);
		world.setBlock(i + 25, j + 5, k + 40, sculk_block, 0, 2);
		world.setBlock(i + 26, j + 5, k + 40, sculk_block, 0, 2);
		world.setBlock(i + 27, j + 5, k + 40, sculk_block, 0, 2);
		world.setBlock(i + 39, j + 5, k + 42, NovaCraftBlocks.sculk_vein, 0, 2);
		world.setBlock(i + 35, j + 6, k + 9, sculk_block, 0, 2);
		world.setBlock(i + 36, j + 6, k + 9, sculk_block, 0, 2);
		world.setBlock(i + 35, j + 6, k + 10, sculk_block, 0, 2);
		world.setBlock(i + 36, j + 6, k + 10, sculk_block, 0, 2);
		world.setBlock(i + 35, j + 6, k + 11, sculk_block, 0, 2);
		world.setBlock(i + 36, j + 6, k + 11, sculk_block, 0, 2);
		world.setBlock(i + 35, j + 6, k + 12, sculk_block, 0, 2);
		world.setBlock(i + 36, j + 6, k + 12, sculk_block, 0, 2);
		world.setBlock(i + 35, j + 6, k + 13, sculk_block, 0, 2);
		world.setBlock(i + 36, j + 6, k + 13, sculk_block, 0, 2);
		world.setBlock(i + 35, j + 6, k + 14, sculk_block, 0, 2);
		world.setBlock(i + 36, j + 6, k + 14, sculk_block, 0, 2);
		world.setBlock(i + 35, j + 6, k + 15, sculk_block, 0, 2);
		world.setBlock(i + 36, j + 6, k + 15, sculk_block, 0, 2);
		world.setBlock(i + 35, j + 6, k + 16, sculk_block, 0, 2);
		world.setBlock(i + 36, j + 6, k + 16, sculk_block, 0, 2);
		world.setBlock(i + 33, j + 6, k + 17, NovaCraftBlocks.sculk_tentacle_2, 1, 2);
		world.setBlock(i + 35, j + 6, k + 17, sculk_block, 0, 2);
		world.setBlock(i + 36, j + 6, k + 17, sculk_block, 0, 2);
		world.setBlock(i + 35, j + 6, k + 18, sculk_block, 0, 2);
		world.setBlock(i + 36, j + 6, k + 18, sculk_block, 0, 2);
		world.setBlock(i + 34, j + 6, k + 19, NovaCraftBlocks.sculk_vein, 1, 2);
		world.setBlock(i + 35, j + 6, k + 19, sculk_block, 0, 2);
		world.setBlock(i + 36, j + 6, k + 19, sculk_block, 0, 2);
		world.setBlock(i + 35, j + 6, k + 20, sculk_block, 0, 2);
		world.setBlock(i + 36, j + 6, k + 20, sculk_block, 0, 2);
		world.setBlock(i + 35, j + 6, k + 21, sculk_block, 0, 2);
		world.setBlock(i + 36, j + 6, k + 21, sculk_block, 0, 2);
		world.setBlock(i + 35, j + 6, k + 22, sculk_block, 0, 2);
		world.setBlock(i + 36, j + 6, k + 22, sculk_block, 0, 2);
		world.setBlock(i + 34, j + 6, k + 23, sculk_block, 0, 2);
		world.setBlock(i + 35, j + 6, k + 23, sculk_block, 0, 2);
		world.setBlock(i + 33, j + 6, k + 24, NovaCraftBlocks.sculk_vein, 1, 2);
		world.setBlock(i + 34, j + 6, k + 24, sculk_block, 0, 2);
		world.setBlock(i + 35, j + 6, k + 24, sculk_block, 0, 2);
		world.setBlock(i + 34, j + 6, k + 25, sculk_block, 0, 2);
		world.setBlock(i + 35, j + 6, k + 25, sculk_block, 0, 2);
		world.setBlock(i + 34, j + 6, k + 26, sculk_block, 0, 2);
		world.setBlock(i + 35, j + 6, k + 26, sculk_block, 0, 2);
		world.setBlock(i + 34, j + 6, k + 27, sculk_block, 0, 2);
		world.setBlock(i + 35, j + 6, k + 27, sculk_block, 0, 2);
		world.setBlock(i + 33, j + 6, k + 28, sculk_block, 0, 2);
		world.setBlock(i + 34, j + 6, k + 28, sculk_block, 0, 2);
		world.setBlock(i + 33, j + 6, k + 29, sculk_block, 0, 2);
		world.setBlock(i + 34, j + 6, k + 29, sculk_block, 0, 2);
		world.setBlock(i + 33, j + 6, k + 30, sculk_block, 0, 2);
		world.setBlock(i + 34, j + 6, k + 30, sculk_block, 0, 2);
		world.setBlock(i + 32, j + 6, k + 31, sculk_block, 0, 2);
		world.setBlock(i + 33, j + 6, k + 31, sculk_block, 0, 2);
		world.setBlock(i + 32, j + 6, k + 32, sculk_block, 0, 2);
		world.setBlock(i + 33, j + 6, k + 32, sculk_block, 0, 2);
		world.setBlock(i + 29, j + 6, k + 33, NovaCraftBlocks.sculk_tentacle_2, 1, 2);
		world.setBlock(i + 32, j + 6, k + 33, sculk_block, 0, 2);
		world.setBlock(i + 33, j + 6, k + 33, sculk_block, 0, 2);
		world.setBlock(i + 31, j + 6, k + 34, sculk_block, 0, 2);
		world.setBlock(i + 32, j + 6, k + 34, sculk_block, 0, 2);
		world.setBlock(i + 31, j + 6, k + 35, sculk_block, 0, 2);
		world.setBlock(i + 32, j + 6, k + 35, sculk_block, 0, 2);
		world.setBlock(i + 28, j + 6, k + 36, NovaCraftBlocks.sculk_vein, 1, 2);
		world.setBlock(i + 30, j + 6, k + 36, sculk_block, 0, 2);
		world.setBlock(i + 31, j + 6, k + 36, sculk_block, 0, 2);
		world.setBlock(i + 30, j + 6, k + 37, sculk_block, 0, 2);
		world.setBlock(i + 31, j + 6, k + 37, sculk_block, 0, 2);
		world.setBlock(i + 29, j + 6, k + 38, sculk_block, 0, 2);
		world.setBlock(i + 30, j + 6, k + 38, sculk_block, 0, 2);
		world.setBlock(i + 31, j + 6, k + 38, sculk_block, 0, 2);
		world.setBlock(i + 29, j + 6, k + 39, sculk_block, 0, 2);
		world.setBlock(i + 30, j + 6, k + 39, sculk_block, 0, 2);
		world.setBlock(i + 37, j + 6, k + 39, NovaCraftBlocks.sculk_vein, 0, 2);
		world.setBlock(i + 28, j + 6, k + 40, sculk_block, 0, 2);
		world.setBlock(i + 29, j + 6, k + 40, sculk_block, 0, 2);
		world.setBlock(i + 28, j + 6, k + 41, sculk_block, 0, 2);
		world.setBlock(i + 37, j + 7, k + 8, sculk_block, 0, 2);
		world.setBlock(i + 37, j + 7, k + 9, sculk_block, 0, 2);
		world.setBlock(i + 36, j + 7, k + 10, NovaCraftBlocks.sculk_tentacle_2, 1, 2);
		world.setBlock(i + 37, j + 7, k + 10, sculk_block, 0, 2);
		world.setBlock(i + 37, j + 7, k + 11, sculk_block, 0, 2);
		world.setBlock(i + 37, j + 7, k + 12, sculk_block, 0, 2);
		world.setBlock(i + 38, j + 7, k + 12, sculk_block, 0, 2);
		world.setBlock(i + 37, j + 7, k + 13, sculk_block, 0, 2);
		world.setBlock(i + 38, j + 7, k + 13, sculk_block, 0, 2);
		world.setBlock(i + 39, j + 7, k + 13, sculk_tendrils, 0, 2);
		world.setBlock(i + 40, j + 7, k + 13, sculk_tendrils, 0, 2);
		world.setBlock(i + 36, j + 7, k + 14, NovaCraftBlocks.sculk_tentacle_2, 1, 2);
		world.setBlock(i + 37, j + 7, k + 14, sculk_block, 0, 2);
		world.setBlock(i + 38, j + 7, k + 14, sculk_block, 0, 2);
		world.setBlock(i + 37, j + 7, k + 15, sculk_block, 0, 2);
		world.setBlock(i + 38, j + 7, k + 15, sculk_block, 0, 2);
		world.setBlock(i + 36, j + 7, k + 16, NovaCraftBlocks.sculk_vein, 1, 2);
		world.setBlock(i + 37, j + 7, k + 16, sculk_block, 0, 2);
		world.setBlock(i + 38, j + 7, k + 16, sculk_block, 0, 2);
		world.setBlock(i + 37, j + 7, k + 17, sculk_block, 0, 2);
		world.setBlock(i + 38, j + 7, k + 17, sculk_block, 0, 2);
		world.setBlock(i + 37, j + 7, k + 18, sculk_block, 0, 2);
		world.setBlock(i + 38, j + 7, k + 18, sculk_block, 0, 2);
		world.setBlock(i + 37, j + 7, k + 19, sculk_block, 0, 2);
		world.setBlock(i + 36, j + 7, k + 20, NovaCraftBlocks.sculk_tentacle_2, 1, 2);
		world.setBlock(i + 37, j + 7, k + 20, sculk_block, 0, 2);
		world.setBlock(i + 37, j + 7, k + 21, sculk_block, 0, 2);
		world.setBlock(i + 36, j + 7, k + 22, sculk_block, 0, 2);
		world.setBlock(i + 37, j + 7, k + 22, sculk_block, 0, 2);
		world.setBlock(i + 36, j + 7, k + 23, sculk_block, 0, 2);
		world.setBlock(i + 37, j + 7, k + 23, sculk_block, 0, 2);
		world.setBlock(i + 36, j + 7, k + 24, sculk_block, 0, 2);
		world.setBlock(i + 37, j + 7, k + 24, sculk_block, 0, 2);
		world.setBlock(i + 36, j + 7, k + 25, sculk_block, 0, 2);
		world.setBlock(i + 37, j + 7, k + 25, sculk_block, 0, 2);
		world.setBlock(i + 36, j + 7, k + 26, sculk_block, 0, 2);
		world.setBlock(i + 36, j + 7, k + 27, sculk_block, 0, 2);
		world.setBlock(i + 35, j + 7, k + 28, sculk_block, 0, 2);
		world.setBlock(i + 36, j + 7, k + 28, sculk_block, 0, 2);
		world.setBlock(i + 35, j + 7, k + 29, sculk_block, 0, 2);
		world.setBlock(i + 36, j + 7, k + 29, sculk_block, 0, 2);
		world.setBlock(i + 33, j + 7, k + 30, NovaCraftBlocks.sculk_tentacle_2, 1, 2);
		world.setBlock(i + 35, j + 7, k + 30, sculk_block, 0, 2);
		world.setBlock(i + 34, j + 7, k + 31, sculk_block, 0, 2);
		world.setBlock(i + 35, j + 7, k + 31, sculk_block, 0, 2);
		world.setBlock(i + 34, j + 7, k + 32, sculk_block, 0, 2);
		world.setBlock(i + 35, j + 7, k + 32, sculk_block, 0, 2);
		world.setBlock(i + 34, j + 7, k + 33, sculk_block, 0, 2);
		world.setBlock(i + 33, j + 7, k + 34, sculk_block, 0, 2);
		world.setBlock(i + 34, j + 7, k + 34, sculk_block, 0, 2);
		world.setBlock(i + 33, j + 7, k + 35, sculk_block, 0, 2);
		world.setBlock(i + 32, j + 7, k + 36, sculk_block, 0, 2);
		world.setBlock(i + 33, j + 7, k + 36, sculk_block, 0, 2);
		world.setBlock(i + 32, j + 7, k + 37, sculk_block, 0, 2);
		world.setBlock(i + 33, j + 7, k + 37, sculk_block, 0, 2);
		world.setBlock(i + 31, j + 7, k + 38, sculk_block, 0, 2);
		world.setBlock(i + 32, j + 7, k + 38, sculk_block, 0, 2);
		world.setBlock(i + 29, j + 7, k + 39, NovaCraftBlocks.sculk_tentacle_2, 1, 2);
		world.setBlock(i + 31, j + 7, k + 39, sculk_block, 0, 2);
		world.setBlock(i + 32, j + 7, k + 39, sculk_block, 0, 2);
		world.setBlock(i + 37, j + 7, k + 39, NovaCraftBlocks.sculk_vein, 0, 2);
		world.setBlock(i + 30, j + 7, k + 40, sculk_block, 0, 2);
		world.setBlock(i + 31, j + 7, k + 40, sculk_block, 0, 2);
		world.setBlock(i + 29, j + 7, k + 41, sculk_block, 0, 2);
		world.setBlock(i + 30, j + 7, k + 41, sculk_block, 0, 2);
		world.setBlock(i + 38, j + 8, k + 7, sculk_block, 0, 2);
		world.setBlock(i + 38, j + 8, k + 8, sculk_block, 0, 2);
		world.setBlock(i + 38, j + 8, k + 9, sculk_block, 0, 2);
		world.setBlock(i + 39, j + 8, k + 9, sculk_block, 0, 2);
		world.setBlock(i + 43, j + 8, k + 9, sculk_tendrils, 0, 2);
		world.setBlock(i + 38, j + 8, k + 10, sculk_block, 0, 2);
		world.setBlock(i + 39, j + 8, k + 10, sculk_block, 0, 2);
		world.setBlock(i + 38, j + 8, k + 11, sculk_block, 0, 2);
		world.setBlock(i + 39, j + 8, k + 11, sculk_block, 0, 2);
		world.setBlock(i + 40, j + 8, k + 11, sculk_tendrils, 0, 2);
		world.setBlock(i + 42, j + 8, k + 11, sculk_tendrils, 0, 2);
		world.setBlock(i + 45, j + 8, k + 11, sculk_tendrils, 0, 2);
		world.setBlock(i + 39, j + 8, k + 12, sculk_block, 0, 2);
		world.setBlock(i + 42, j + 8, k + 12, sculk_tendrils, 0, 2);
		world.setBlock(i + 39, j + 8, k + 13, sculk_block, 0, 2);
		world.setBlock(i + 37, j + 8, k + 14, sculk_tendrils, 0, 2);
		world.setBlock(i + 39, j + 8, k + 14, sculk_block, 0, 2);
		world.setBlock(i + 39, j + 8, k + 15, sculk_block, 0, 2);
		world.setBlock(i + 39, j + 8, k + 16, sculk_block, 0, 2);
		world.setBlock(i + 37, j + 8, k + 17, NovaCraftBlocks.sculk_tentacle_2, 1, 2);
		world.setBlock(i + 39, j + 8, k + 17, sculk_block, 0, 2);
		world.setBlock(i + 39, j + 8, k + 18, sculk_block, 0, 2);
		world.setBlock(i + 38, j + 8, k + 19, sculk_block, 0, 2);
		world.setBlock(i + 39, j + 8, k + 19, sculk_block, 0, 2);
		world.setBlock(i + 38, j + 8, k + 20, sculk_block, 0, 2);
		world.setBlock(i + 39, j + 8, k + 20, sculk_block, 0, 2);
		world.setBlock(i + 38, j + 8, k + 21, sculk_block, 0, 2);
		world.setBlock(i + 39, j + 8, k + 21, sculk_block, 0, 2);
		world.setBlock(i + 38, j + 8, k + 22, sculk_block, 0, 2);
		world.setBlock(i + 38, j + 8, k + 23, sculk_block, 0, 2);
		world.setBlock(i + 38, j + 8, k + 24, sculk_block, 0, 2);
		world.setBlock(i + 38, j + 8, k + 25, sculk_block, 0, 2);
		world.setBlock(i + 37, j + 8, k + 26, sculk_block, 0, 2);
		world.setBlock(i + 38, j + 8, k + 26, sculk_block, 0, 2);
		world.setBlock(i + 37, j + 8, k + 27, sculk_block, 0, 2);
		world.setBlock(i + 38, j + 8, k + 27, sculk_block, 0, 2);
		world.setBlock(i + 37, j + 8, k + 28, sculk_block, 0, 2);
		world.setBlock(i + 37, j + 8, k + 29, sculk_block, 0, 2);
		world.setBlock(i + 36, j + 8, k + 30, sculk_block, 0, 2);
		world.setBlock(i + 37, j + 8, k + 30, sculk_block, 0, 2);
		world.setBlock(i + 36, j + 8, k + 31, sculk_block, 0, 2);
		world.setBlock(i + 36, j + 8, k + 32, sculk_block, 0, 2);
		world.setBlock(i + 35, j + 8, k + 33, sculk_block, 0, 2);
		world.setBlock(i + 36, j + 8, k + 33, sculk_block, 0, 2);
		world.setBlock(i + 35, j + 8, k + 34, sculk_block, 0, 2);
		world.setBlock(i + 34, j + 8, k + 35, sculk_block, 0, 2);
		world.setBlock(i + 35, j + 8, k + 35, sculk_block, 0, 2);
		world.setBlock(i + 34, j + 8, k + 36, sculk_block, 0, 2);
		world.setBlock(i + 34, j + 8, k + 37, sculk_block, 0, 2);
		world.setBlock(i + 33, j + 8, k + 38, sculk_block, 0, 2);
		world.setBlock(i + 34, j + 8, k + 38, sculk_block, 0, 2);
		world.setBlock(i + 31, j + 8, k + 39, NovaCraftBlocks.sculk_tentacle_2, 1, 2);
		world.setBlock(i + 33, j + 8, k + 39, sculk_block, 0, 2);
		world.setBlock(i + 32, j + 8, k + 40, sculk_block, 0, 2);
		world.setBlock(i + 31, j + 8, k + 41, sculk_block, 0, 2);
		world.setBlock(i + 32, j + 8, k + 41, sculk_block, 0, 2);
		world.setBlock(i + 39, j + 9, k + 7, sculk_block, 0, 2);
		world.setBlock(i + 39, j + 9, k + 8, sculk_block, 0, 2);
		world.setBlock(i + 40, j + 9, k + 8, sculk_block, 0, 2);
		world.setBlock(i + 40, j + 9, k + 9, sculk_block, 0, 2);
		world.setBlock(i + 39, j + 9, k + 10, NovaCraftBlocks.sculk_tentacle_2, 1, 2);
		world.setBlock(i + 40, j + 9, k + 10, sculk_block, 0, 2);
		world.setBlock(i + 40, j + 9, k + 11, sculk_block, 0, 2);
		world.setBlock(i + 40, j + 9, k + 12, sculk_block, 0, 2);
		world.setBlock(i + 40, j + 9, k + 13, sculk_block, 0, 2);
		world.setBlock(i + 40, j + 9, k + 14, sculk_block, 0, 2);
		world.setBlock(i + 39, j + 9, k + 15, NovaCraftBlocks.sculk_tentacle_2, 1, 2);
		world.setBlock(i + 40, j + 9, k + 15, sculk_block, 0, 2);
		world.setBlock(i + 40, j + 9, k + 16, sculk_block, 0, 2);
		world.setBlock(i + 40, j + 9, k + 17, sculk_block, 0, 2);
		world.setBlock(i + 40, j + 9, k + 18, sculk_block, 0, 2);
		world.setBlock(i + 40, j + 9, k + 19, sculk_block, 0, 2);
		world.setBlock(i + 40, j + 9, k + 20, sculk_block, 0, 2);
		world.setBlock(i + 40, j + 9, k + 21, sculk_block, 0, 2);
		world.setBlock(i + 39, j + 9, k + 22, sculk_block, 0, 2);
		world.setBlock(i + 40, j + 9, k + 22, sculk_block, 0, 2);
		world.setBlock(i + 39, j + 9, k + 23, sculk_block, 0, 2);
		world.setBlock(i + 38, j + 9, k + 24, NovaCraftBlocks.sculk_tentacle_2, 1, 2);
		world.setBlock(i + 39, j + 9, k + 24, sculk_block, 0, 2);
		world.setBlock(i + 39, j + 9, k + 25, sculk_block, 0, 2);
		world.setBlock(i + 39, j + 9, k + 26, sculk_block, 0, 2);
		world.setBlock(i + 37, j + 9, k + 27, NovaCraftBlocks.sculk_tentacle_2, 1, 2);
		world.setBlock(i + 39, j + 9, k + 27, sculk_block, 0, 2);
		world.setBlock(i + 38, j + 9, k + 28, sculk_block, 0, 2);
		world.setBlock(i + 38, j + 9, k + 29, sculk_block, 0, 2);
		world.setBlock(i + 37, j + 9, k + 30, NovaCraftBlocks.sculk_vein, 1, 2);
		world.setBlock(i + 38, j + 9, k + 30, sculk_block, 0, 2);
		world.setBlock(i + 37, j + 9, k + 31, sculk_block, 0, 2);
		world.setBlock(i + 38, j + 9, k + 31, sculk_block, 0, 2);
		world.setBlock(i + 37, j + 9, k + 32, sculk_block, 0, 2);
		world.setBlock(i + 35, j + 9, k + 33, NovaCraftBlocks.sculk_vein, 1, 2);
		world.setBlock(i + 37, j + 9, k + 33, sculk_block, 0, 2);
		world.setBlock(i + 36, j + 9, k + 34, sculk_block, 0, 2);
		world.setBlock(i + 37, j + 9, k + 34, sculk_block, 0, 2);
		world.setBlock(i + 36, j + 9, k + 35, sculk_block, 0, 2);
		world.setBlock(i + 35, j + 9, k + 36, sculk_block, 0, 2);
		world.setBlock(i + 36, j + 9, k + 36, sculk_block, 0, 2);
		world.setBlock(i + 34, j + 9, k + 37, NovaCraftBlocks.sculk_vein, 1, 2);
		world.setBlock(i + 35, j + 9, k + 37, sculk_block, 0, 2);
		world.setBlock(i + 35, j + 9, k + 38, sculk_block, 0, 2);
		world.setBlock(i + 33, j + 9, k + 39, NovaCraftBlocks.sculk_tentacle_2, 1, 2);
		world.setBlock(i + 34, j + 9, k + 39, sculk_block, 0, 2);
		world.setBlock(i + 33, j + 9, k + 40, sculk_block, 0, 2);
		world.setBlock(i + 34, j + 9, k + 40, sculk_block, 0, 2);
		world.setBlock(i + 33, j + 9, k + 41, sculk_block, 0, 2);
		world.setBlock(i + 32, j + 9, k + 42, sculk_block, 0, 2);
		world.setBlock(i + 33, j + 9, k + 42, sculk_block, 0, 2);
		world.setBlock(i + 40, j + 10, k + 6, sculk_block, 0, 2);
		world.setBlock(i + 40, j + 10, k + 7, sculk_block, 0, 2);
		world.setBlock(i + 40, j + 10, k + 8, NovaCraftBlocks.sculk_tentacle_2, 1, 2);
		world.setBlock(i + 41, j + 10, k + 8, sculk_block, 0, 2);
		world.setBlock(i + 41, j + 10, k + 9, sculk_block, 0, 2);
		world.setBlock(i + 41, j + 10, k + 10, sculk_block, 0, 2);
		world.setBlock(i + 41, j + 10, k + 11, sculk_block, 0, 2);
		world.setBlock(i + 41, j + 10, k + 12, sculk_block, 0, 2);
		world.setBlock(i + 41, j + 10, k + 13, sculk_block, 0, 2);
		world.setBlock(i + 41, j + 10, k + 14, sculk_block, 0, 2);
		world.setBlock(i + 41, j + 10, k + 15, sculk_block, 0, 2);
		world.setBlock(i + 41, j + 10, k + 16, sculk_block, 0, 2);
		world.setBlock(i + 41, j + 10, k + 17, sculk_block, 0, 2);
		world.setBlock(i + 41, j + 10, k + 18, sculk_block, 0, 2);
		world.setBlock(i + 41, j + 10, k + 19, sculk_block, 0, 2);
		world.setBlock(i + 40, j + 10, k + 20, NovaCraftBlocks.sculk_vein, 1, 2);
		world.setBlock(i + 41, j + 10, k + 20, sculk_block, 0, 2);
		world.setBlock(i + 41, j + 10, k + 21, sculk_block, 0, 2);
		world.setBlock(i + 41, j + 10, k + 22, sculk_block, 0, 2);
		world.setBlock(i + 40, j + 10, k + 23, sculk_block, 0, 2);
		world.setBlock(i + 40, j + 10, k + 24, sculk_block, 0, 2);
		world.setBlock(i + 40, j + 10, k + 25, sculk_block, 0, 2);
		world.setBlock(i + 40, j + 10, k + 26, sculk_block, 0, 2);
		world.setBlock(i + 39, j + 10, k + 27, sculk_tendrils, 0, 2);
		world.setBlock(i + 40, j + 10, k + 27, sculk_block, 0, 2);
		world.setBlock(i + 39, j + 10, k + 28, sculk_block, 0, 2);
		world.setBlock(i + 39, j + 10, k + 29, sculk_block, 0, 2);
		world.setBlock(i + 39, j + 10, k + 30, sculk_block, 0, 2);
		world.setBlock(i + 39, j + 10, k + 31, sculk_block, 0, 2);
		world.setBlock(i + 38, j + 10, k + 32, sculk_block, 0, 2);
		world.setBlock(i + 38, j + 10, k + 33, sculk_block, 0, 2);
		world.setBlock(i + 38, j + 10, k + 34, sculk_block, 0, 2);
		world.setBlock(i + 37, j + 10, k + 35, sculk_block, 0, 2);
		world.setBlock(i + 37, j + 10, k + 36, sculk_block, 0, 2);
		world.setBlock(i + 36, j + 10, k + 37, sculk_block, 0, 2);
		world.setBlock(i + 36, j + 10, k + 38, sculk_block, 0, 2);
		world.setBlock(i + 35, j + 10, k + 39, sculk_block, 0, 2);
		world.setBlock(i + 35, j + 10, k + 40, sculk_block, 0, 2);
		world.setBlock(i + 34, j + 10, k + 41, sculk_block, 0, 2);
		world.setBlock(i + 33, j + 10, k + 42, NovaCraftBlocks.sculk_tentacle_2, 1, 2);
		world.setBlock(i + 34, j + 10, k + 42, sculk_block, 0, 2);
		world.setBlock(i + 41, j + 11, k + 6, sculk_block, 0, 2);
		world.setBlock(i + 40, j + 11, k + 7, NovaCraftBlocks.sculk_vein, 1, 2);
		world.setBlock(i + 41, j + 11, k + 7, sculk_block, 0, 2);
		world.setBlock(i + 41, j + 11, k + 8, sculk_block, 0, 2);
		world.setBlock(i + 42, j + 11, k + 9, sculk_block, 0, 2);
		world.setBlock(i + 41, j + 11, k + 10, NovaCraftBlocks.sculk_tentacle_2, 1, 2);
		world.setBlock(i + 42, j + 11, k + 10, sculk_block, 0, 2);
		world.setBlock(i + 42, j + 11, k + 11, sculk_block, 0, 2);
		world.setBlock(i + 42, j + 11, k + 12, sculk_block, 0, 2);
		world.setBlock(i + 42, j + 11, k + 13, sculk_block, 0, 2);
		world.setBlock(i + 42, j + 11, k + 14, sculk_block, 0, 2);
		world.setBlock(i + 42, j + 11, k + 15, sculk_block, 0, 2);
		world.setBlock(i + 42, j + 11, k + 16, sculk_block, 0, 2);
		world.setBlock(i + 42, j + 11, k + 17, sculk_block, 0, 2);
		world.setBlock(i + 41, j + 11, k + 18, NovaCraftBlocks.sculk_tentacle_2, 1, 2);
		world.setBlock(i + 42, j + 11, k + 18, sculk_block, 0, 2);
		world.setBlock(i + 42, j + 11, k + 19, sculk_block, 0, 2);
		world.setBlock(i + 42, j + 11, k + 20, sculk_block, 0, 2);
		world.setBlock(i + 42, j + 11, k + 21, sculk_block, 0, 2);
		world.setBlock(i + 41, j + 11, k + 22, sculk_block, 0, 2);
		world.setBlock(i + 41, j + 11, k + 23, sculk_block, 0, 2);
		world.setBlock(i + 41, j + 11, k + 24, sculk_block, 0, 2);
		world.setBlock(i + 41, j + 11, k + 25, sculk_block, 0, 2);
		world.setBlock(i + 41, j + 11, k + 26, sculk_block, 0, 2);
		world.setBlock(i + 41, j + 11, k + 27, sculk_block, 0, 2);
		world.setBlock(i + 39, j + 11, k + 28, NovaCraftBlocks.sculk_tentacle_2, 1, 2);
		world.setBlock(i + 40, j + 11, k + 28, sculk_block, 0, 2);
		world.setBlock(i + 40, j + 11, k + 29, sculk_block, 0, 2);
		world.setBlock(i + 40, j + 11, k + 30, sculk_block, 0, 2);
		world.setBlock(i + 40, j + 11, k + 31, sculk_block, 0, 2);
		world.setBlock(i + 39, j + 11, k + 32, sculk_block, 0, 2);
		world.setBlock(i + 39, j + 11, k + 33, sculk_block, 0, 2);
		world.setBlock(i + 38, j + 11, k + 34, sculk_block, 0, 2);
		world.setBlock(i + 38, j + 11, k + 35, sculk_block, 0, 2);
		world.setBlock(i + 38, j + 11, k + 36, sculk_block, 0, 2);
		world.setBlock(i + 37, j + 11, k + 37, sculk_block, 0, 2);
		world.setBlock(i + 36, j + 11, k + 38, sculk_tendrils, 0, 2);
		world.setBlock(i + 37, j + 11, k + 38, sculk_block, 0, 2);
		world.setBlock(i + 36, j + 11, k + 39, sculk_block, 0, 2);
		world.setBlock(i + 36, j + 11, k + 40, sculk_block, 0, 2);
		world.setBlock(i + 35, j + 11, k + 41, sculk_block, 0, 2);
		world.setBlock(i + 35, j + 11, k + 42, sculk_block, 0, 2);
		world.setBlock(i + 42, j + 12, k + 6, sculk_block, 0, 2);
		world.setBlock(i + 42, j + 12, k + 7, sculk_block, 0, 2);
		world.setBlock(i + 42, j + 12, k + 8, sculk_block, 0, 2);
		world.setBlock(i + 42, j + 12, k + 9, sculk_block, 0, 2);
		world.setBlock(i + 42, j + 12, k + 10, sculk_block, 0, 2);
		world.setBlock(i + 42, j + 12, k + 11, sculk_block, 0, 2);
		world.setBlock(i + 43, j + 12, k + 12, sculk_block, 0, 2);
		world.setBlock(i + 42, j + 12, k + 13, NovaCraftBlocks.sculk_tentacle_2, 1, 2);
		world.setBlock(i + 43, j + 12, k + 13, sculk_block, 0, 2);
		world.setBlock(i + 43, j + 12, k + 14, sculk_block, 0, 2);
		world.setBlock(i + 42, j + 12, k + 15, NovaCraftBlocks.sculk_vein, 1, 2);
		world.setBlock(i + 43, j + 12, k + 15, sculk_block, 0, 2);
		world.setBlock(i + 43, j + 12, k + 16, sculk_block, 0, 2);
		world.setBlock(i + 43, j + 12, k + 17, sculk_block, 0, 2);
		world.setBlock(i + 43, j + 12, k + 18, sculk_block, 0, 2);
		world.setBlock(i + 42, j + 12, k + 19, sculk_block, 0, 2);
		world.setBlock(i + 42, j + 12, k + 20, sculk_block, 0, 2);
		world.setBlock(i + 42, j + 12, k + 21, sculk_block, 0, 2);
		world.setBlock(i + 42, j + 12, k + 22, sculk_block, 0, 2);
		world.setBlock(i + 41, j + 12, k + 23, NovaCraftBlocks.sculk_tentacle_2, 1, 2);
		world.setBlock(i + 42, j + 12, k + 23, sculk_block, 0, 2);
		world.setBlock(i + 42, j + 12, k + 24, sculk_block, 0, 2);
		world.setBlock(i + 42, j + 12, k + 25, sculk_block, 0, 2);
		world.setBlock(i + 42, j + 12, k + 26, sculk_block, 0, 2);
		world.setBlock(i + 41, j + 12, k + 27, sculk_block, 0, 2);
		world.setBlock(i + 41, j + 12, k + 28, sculk_block, 0, 2);
		world.setBlock(i + 41, j + 12, k + 29, sculk_block, 0, 2);
		world.setBlock(i + 41, j + 12, k + 30, sculk_block, 0, 2);
		world.setBlock(i + 40, j + 12, k + 31, sculk_block, 0, 2);
		world.setBlock(i + 40, j + 12, k + 32, sculk_block, 0, 2);
		world.setBlock(i + 39, j + 12, k + 33, NovaCraftBlocks.sculk_tentacle_2, 1, 2);
		world.setBlock(i + 40, j + 12, k + 33, sculk_block, 0, 2);
		world.setBlock(i + 39, j + 12, k + 34, sculk_block, 0, 2);
		world.setBlock(i + 39, j + 12, k + 35, sculk_block, 0, 2);
		world.setBlock(i + 38, j + 12, k + 36, sculk_block, 0, 2);
		world.setBlock(i + 38, j + 12, k + 37, sculk_block, 0, 2);
		world.setBlock(i + 38, j + 12, k + 38, sculk_block, 0, 2);
		world.setBlock(i + 37, j + 12, k + 39, sculk_block, 0, 2);
		world.setBlock(i + 37, j + 12, k + 40, sculk_block, 0, 2);
		world.setBlock(i + 35, j + 12, k + 41, NovaCraftBlocks.sculk_tentacle_2, 1, 2);
		world.setBlock(i + 36, j + 12, k + 41, sculk_block, 0, 2);
		world.setBlock(i + 35, j + 12, k + 42, sculk_block, 0, 2);
		world.setBlock(i + 42, j + 13, k + 5, sculk_block, 0, 2);
		world.setBlock(i + 42, j + 13, k + 6, sculk_block, 0, 2);
		world.setBlock(i + 43, j + 13, k + 7, sculk_block, 0, 2);
		world.setBlock(i + 42, j + 13, k + 8, NovaCraftBlocks.sculk_tentacle_2, 1, 2);
		world.setBlock(i + 43, j + 13, k + 8, sculk_block, 0, 2);
		world.setBlock(i + 43, j + 13, k + 9, sculk_block, 0, 2);
		world.setBlock(i + 43, j + 13, k + 10, sculk_block, 0, 2);
		world.setBlock(i + 43, j + 13, k + 11, sculk_block, 0, 2);
		world.setBlock(i + 43, j + 13, k + 12, sculk_block, 0, 2);
		world.setBlock(i + 43, j + 13, k + 13, sculk_block, 0, 2);
		world.setBlock(i + 43, j + 13, k + 14, sculk_block, 0, 2);
		world.setBlock(i + 43, j + 13, k + 15, sculk_block, 0, 2);
		world.setBlock(i + 43, j + 13, k + 16, sculk_block, 0, 2);
		world.setBlock(i + 43, j + 13, k + 17, sculk_block, 0, 2);
		world.setBlock(i + 43, j + 13, k + 18, sculk_block, 0, 2);
		world.setBlock(i + 43, j + 13, k + 19, sculk_block, 0, 2);
		world.setBlock(i + 42, j + 13, k + 20, NovaCraftBlocks.sculk_tentacle_2, 1, 2);
		world.setBlock(i + 43, j + 13, k + 20, sculk_block, 0, 2);
		world.setBlock(i + 43, j + 13, k + 21, sculk_block, 0, 2);
		world.setBlock(i + 43, j + 13, k + 22, sculk_block, 0, 2);
		world.setBlock(i + 43, j + 13, k + 23, sculk_block, 0, 2);
		world.setBlock(i + 42, j + 13, k + 24, sculk_block, 0, 2);
		world.setBlock(i + 42, j + 13, k + 25, sculk_block, 0, 2);
		world.setBlock(i + 42, j + 13, k + 26, sculk_block, 0, 2);
		world.setBlock(i + 41, j + 13, k + 27, NovaCraftBlocks.sculk_vein, 1, 2);
		world.setBlock(i + 42, j + 13, k + 27, sculk_block, 0, 2);
		world.setBlock(i + 42, j + 13, k + 28, sculk_block, 0, 2);
		world.setBlock(i + 41, j + 13, k + 29, sculk_block, 0, 2);
		world.setBlock(i + 41, j + 13, k + 30, sculk_block, 0, 2);
		world.setBlock(i + 41, j + 13, k + 31, sculk_block, 0, 2);
		world.setBlock(i + 40, j + 13, k + 32, sculk_block, 0, 2);
		world.setBlock(i + 40, j + 13, k + 33, sculk_block, 0, 2);
		world.setBlock(i + 40, j + 13, k + 34, sculk_block, 0, 2);
		world.setBlock(i + 39, j + 13, k + 35, sculk_block, 0, 2);
		world.setBlock(i + 38, j + 13, k + 36, NovaCraftBlocks.sculk_tentacle_2, 1, 2);
		world.setBlock(i + 39, j + 13, k + 36, sculk_block, 0, 2);
		world.setBlock(i + 38, j + 13, k + 37, sculk_block, 0, 2);
		world.setBlock(i + 38, j + 13, k + 38, sculk_block, 0, 2);
		world.setBlock(i + 37, j + 13, k + 39, NovaCraftBlocks.sculk_tentacle_2, 1, 2);
		world.setBlock(i + 38, j + 13, k + 39, sculk_block, 0, 2);
		world.setBlock(i + 37, j + 13, k + 40, sculk_block, 0, 2);
		world.setBlock(i + 37, j + 13, k + 41, sculk_block, 0, 2);
		world.setBlock(i + 36, j + 13, k + 42, sculk_block, 0, 2);
		world.setBlock(i + 42, j + 14, k + 5, sculk_block, 0, 2);
		world.setBlock(i + 43, j + 14, k + 6, sculk_block, 0, 2);
		world.setBlock(i + 43, j + 14, k + 7, sculk_block, 0, 2);
		world.setBlock(i + 43, j + 14, k + 8, sculk_block, 0, 2);
		world.setBlock(i + 43, j + 14, k + 9, sculk_block, 0, 2);
		world.setBlock(i + 43, j + 14, k + 10, sculk_block, 0, 2);
		world.setBlock(i + 43, j + 14, k + 11, sculk_block, 0, 2);
		world.setBlock(i + 43, j + 14, k + 12, sculk_block, 0, 2);
		world.setBlock(i + 43, j + 14, k + 13, sculk_block, 0, 2);
		world.setBlock(i + 43, j + 14, k + 14, sculk_block, 0, 2);
		world.setBlock(i + 44, j + 14, k + 14, sculk_block, 0, 2);
		world.setBlock(i + 43, j + 14, k + 15, sculk_block, 0, 2);
		world.setBlock(i + 44, j + 14, k + 15, sculk_block, 0, 2);
		world.setBlock(i + 43, j + 14, k + 16, sculk_block, 0, 2);
		world.setBlock(i + 44, j + 14, k + 16, sculk_block, 0, 2);
		world.setBlock(i + 43, j + 14, k + 17, sculk_block, 0, 2);
		world.setBlock(i + 43, j + 14, k + 18, sculk_block, 0, 2);
		world.setBlock(i + 43, j + 14, k + 19, sculk_block, 0, 2);
		world.setBlock(i + 43, j + 14, k + 20, sculk_block, 0, 2);
		world.setBlock(i + 43, j + 14, k + 21, sculk_block, 0, 2);
		world.setBlock(i + 43, j + 14, k + 22, sculk_block, 0, 2);
		world.setBlock(i + 43, j + 14, k + 23, sculk_block, 0, 2);
		world.setBlock(i + 42, j + 14, k + 24, NovaCraftBlocks.sculk_vein, 1, 2);
		world.setBlock(i + 43, j + 14, k + 24, sculk_block, 0, 2);
		world.setBlock(i + 42, j + 14, k + 25, sculk_block, 0, 2);
		world.setBlock(i + 42, j + 14, k + 26, sculk_block, 0, 2);
		world.setBlock(i + 42, j + 14, k + 27, sculk_block, 0, 2);
		world.setBlock(i + 42, j + 14, k + 28, sculk_block, 0, 2);
		world.setBlock(i + 42, j + 14, k + 29, sculk_block, 0, 2);
		world.setBlock(i + 41, j + 14, k + 30, sculk_block, 0, 2);
		world.setBlock(i + 41, j + 14, k + 31, sculk_block, 0, 2);
		world.setBlock(i + 41, j + 14, k + 32, sculk_block, 0, 2);
		world.setBlock(i + 40, j + 14, k + 33, sculk_block, 0, 2);
		world.setBlock(i + 40, j + 14, k + 34, sculk_block, 0, 2);
		world.setBlock(i + 40, j + 14, k + 35, sculk_block, 0, 2);
		world.setBlock(i + 39, j + 14, k + 36, sculk_block, 0, 2);
		world.setBlock(i + 39, j + 14, k + 37, sculk_block, 0, 2);
		world.setBlock(i + 38, j + 14, k + 38, sculk_block, 0, 2);
		world.setBlock(i + 38, j + 14, k + 39, sculk_block, 0, 2);
		world.setBlock(i + 37, j + 14, k + 40, sculk_block, 0, 2);
		world.setBlock(i + 37, j + 14, k + 41, sculk_block, 0, 2);
		world.setBlock(i + 36, j + 14, k + 42, sculk_block, 0, 2);
		world.setBlock(i + 42, j + 15, k + 4, sculk_block, 0, 2);
		world.setBlock(i + 43, j + 15, k + 5, sculk_block, 0, 2);
		world.setBlock(i + 43, j + 15, k + 6, sculk_block, 0, 2);
		world.setBlock(i + 43, j + 15, k + 7, sculk_block, 0, 2);
		world.setBlock(i + 43, j + 15, k + 8, sculk_block, 0, 2);
		world.setBlock(i + 43, j + 15, k + 9, sculk_block, 0, 2);
		world.setBlock(i + 43, j + 15, k + 10, sculk_block, 0, 2);
		world.setBlock(i + 43, j + 15, k + 11, sculk_block, 0, 2);
		world.setBlock(i + 43, j + 15, k + 12, sculk_block, 0, 2);
		world.setBlock(i + 43, j + 15, k + 13, sculk_block, 0, 2);
		world.setBlock(i + 43, j + 15, k + 14, sculk_block, 0, 2);
		world.setBlock(i + 44, j + 15, k + 14, sculk_block, 0, 2);
		world.setBlock(i + 44, j + 15, k + 15, sculk_block, 0, 2);
		world.setBlock(i + 43, j + 15, k + 16, sculk_block, 0, 2);
		world.setBlock(i + 44, j + 15, k + 16, sculk_block, 0, 2);
		world.setBlock(i + 45, j + 15, k + 16, sculk_block, 0, 2);
		world.setBlock(i + 43, j + 15, k + 17, sculk_block, 0, 2);
		world.setBlock(i + 43, j + 15, k + 18, sculk_block, 0, 2);
		world.setBlock(i + 43, j + 15, k + 19, sculk_block, 0, 2);
		world.setBlock(i + 43, j + 15, k + 20, sculk_block, 0, 2);
		world.setBlock(i + 43, j + 15, k + 21, sculk_block, 0, 2);
		world.setBlock(i + 43, j + 15, k + 22, sculk_block, 0, 2);
		world.setBlock(i + 43, j + 15, k + 23, sculk_block, 0, 2);
		world.setBlock(i + 43, j + 15, k + 24, sculk_block, 0, 2);
		world.setBlock(i + 43, j + 15, k + 25, sculk_block, 0, 2);
		world.setBlock(i + 42, j + 15, k + 26, sculk_block, 0, 2);
		world.setBlock(i + 42, j + 15, k + 27, sculk_block, 0, 2);
		world.setBlock(i + 42, j + 15, k + 28, sculk_block, 0, 2);
		world.setBlock(i + 42, j + 15, k + 29, sculk_block, 0, 2);
		world.setBlock(i + 41, j + 15, k + 30, sculk_block, 0, 2);
		world.setBlock(i + 41, j + 15, k + 31, sculk_block, 0, 2);
		world.setBlock(i + 41, j + 15, k + 32, sculk_block, 0, 2);
		world.setBlock(i + 40, j + 15, k + 33, sculk_block, 0, 2);
		world.setBlock(i + 40, j + 15, k + 34, sculk_block, 0, 2);
		world.setBlock(i + 40, j + 15, k + 35, sculk_block, 0, 2);
		world.setBlock(i + 39, j + 15, k + 36, sculk_block, 0, 2);
		world.setBlock(i + 39, j + 15, k + 37, sculk_block, 0, 2);
		world.setBlock(i + 38, j + 15, k + 38, sculk_block, 0, 2);
		world.setBlock(i + 38, j + 15, k + 39, sculk_block, 0, 2);
		world.setBlock(i + 37, j + 15, k + 40, sculk_block, 0, 2);
		world.setBlock(i + 37, j + 15, k + 41, sculk_block, 0, 2);
		world.setBlock(i + 36, j + 15, k + 42, sculk_block, 0, 2);
		world.setBlock(i + 42, j + 16, k + 4, sculk_block, 0, 2);
		world.setBlock(i + 42, j + 16, k + 5, sculk_block, 0, 2);
		world.setBlock(i + 43, j + 16, k + 6, sculk_block, 0, 2);
		world.setBlock(i + 43, j + 16, k + 7, sculk_block, 0, 2);
		world.setBlock(i + 43, j + 16, k + 8, sculk_block, 0, 2);
		world.setBlock(i + 43, j + 16, k + 9, sculk_block, 0, 2);
		world.setBlock(i + 43, j + 16, k + 10, sculk_block, 0, 2);
		world.setBlock(i + 43, j + 16, k + 11, sculk_block, 0, 2);
		world.setBlock(i + 43, j + 16, k + 12, sculk_block, 0, 2);
		world.setBlock(i + 43, j + 16, k + 13, sculk_block, 0, 2);
		world.setBlock(i + 43, j + 16, k + 14, sculk_block, 0, 2);
		world.setBlock(i + 44, j + 16, k + 14, sculk_block, 0, 2);
		world.setBlock(i + 43, j + 16, k + 15, sculk_block, 0, 2);
		world.setBlock(i + 44, j + 16, k + 15, sculk_block, 0, 2);
		world.setBlock(i + 43, j + 16, k + 16, sculk_block, 0, 2);
		world.setBlock(i + 44, j + 16, k + 16, sculk_block, 0, 2);
		world.setBlock(i + 43, j + 16, k + 17, sculk_block, 0, 2);
		world.setBlock(i + 43, j + 16, k + 18, sculk_block, 0, 2);
		world.setBlock(i + 43, j + 16, k + 19, sculk_block, 0, 2);
		world.setBlock(i + 43, j + 16, k + 20, sculk_block, 0, 2);
		world.setBlock(i + 43, j + 16, k + 21, sculk_block, 0, 2);
		world.setBlock(i + 43, j + 16, k + 22, sculk_block, 0, 2);
		world.setBlock(i + 43, j + 16, k + 23, sculk_block, 0, 2);
		world.setBlock(i + 43, j + 16, k + 24, sculk_block, 0, 2);
		world.setBlock(i + 42, j + 16, k + 25, sculk_block, 0, 2);
		world.setBlock(i + 42, j + 16, k + 26, sculk_block, 0, 2);
		world.setBlock(i + 42, j + 16, k + 27, sculk_block, 0, 2);
		world.setBlock(i + 42, j + 16, k + 28, sculk_block, 0, 2);
		world.setBlock(i + 42, j + 16, k + 29, sculk_block, 0, 2);
		world.setBlock(i + 41, j + 16, k + 30, sculk_block, 0, 2);
		world.setBlock(i + 41, j + 16, k + 31, sculk_block, 0, 2);
		world.setBlock(i + 41, j + 16, k + 32, sculk_block, 0, 2);
		world.setBlock(i + 40, j + 16, k + 33, sculk_block, 0, 2);
		world.setBlock(i + 40, j + 16, k + 34, sculk_block, 0, 2);
		world.setBlock(i + 40, j + 16, k + 35, sculk_block, 0, 2);
		world.setBlock(i + 39, j + 16, k + 36, sculk_block, 0, 2);
		world.setBlock(i + 39, j + 16, k + 37, sculk_block, 0, 2);
		world.setBlock(i + 38, j + 16, k + 38, sculk_block, 0, 2);
		world.setBlock(i + 38, j + 16, k + 39, sculk_block, 0, 2);
		world.setBlock(i + 37, j + 16, k + 40, sculk_block, 0, 2);
		world.setBlock(i + 37, j + 16, k + 41, sculk_block, 0, 2);
		world.setBlock(i + 36, j + 16, k + 42, sculk_block, 0, 2);
		world.setBlock(i + 36, j + 16, k + 43, sculk_block, 0, 2);
		world.setBlock(i + 42, j + 17, k + 4, sculk_block, 0, 2);
		world.setBlock(i + 42, j + 17, k + 5, sculk_block, 0, 2);
		world.setBlock(i + 42, j + 17, k + 6, sculk_block, 0, 2);
		world.setBlock(i + 43, j + 17, k + 7, sculk_block, 0, 2);
		world.setBlock(i + 43, j + 17, k + 8, sculk_block, 0, 2);
		world.setBlock(i + 43, j + 17, k + 9, sculk_block, 0, 2);
		world.setBlock(i + 43, j + 17, k + 10, sculk_block, 0, 2);
		world.setBlock(i + 43, j + 17, k + 11, sculk_block, 0, 2);
		world.setBlock(i + 43, j + 17, k + 12, sculk_block, 0, 2);
		world.setBlock(i + 43, j + 17, k + 13, sculk_block, 0, 2);
		world.setBlock(i + 43, j + 17, k + 14, sculk_block, 0, 2);
		world.setBlock(i + 43, j + 17, k + 15, sculk_block, 0, 2);
		world.setBlock(i + 43, j + 17, k + 16, sculk_block, 0, 2);
		world.setBlock(i + 43, j + 17, k + 17, sculk_block, 0, 2);
		world.setBlock(i + 43, j + 17, k + 18, sculk_block, 0, 2);
		world.setBlock(i + 43, j + 17, k + 19, sculk_block, 0, 2);
		world.setBlock(i + 43, j + 17, k + 20, sculk_block, 0, 2);
		world.setBlock(i + 43, j + 17, k + 21, sculk_block, 0, 2);
		world.setBlock(i + 43, j + 17, k + 22, sculk_block, 0, 2);
		world.setBlock(i + 43, j + 17, k + 23, sculk_block, 0, 2);
		world.setBlock(i + 42, j + 17, k + 24, sculk_block, 0, 2);
		world.setBlock(i + 42, j + 17, k + 25, sculk_block, 0, 2);
		world.setBlock(i + 42, j + 17, k + 26, sculk_block, 0, 2);
		world.setBlock(i + 42, j + 17, k + 27, sculk_block, 0, 2);
		world.setBlock(i + 42, j + 17, k + 28, sculk_block, 0, 2);
		world.setBlock(i + 41, j + 17, k + 29, sculk_block, 0, 2);
		world.setBlock(i + 41, j + 17, k + 30, sculk_block, 0, 2);
		world.setBlock(i + 41, j + 17, k + 31, sculk_block, 0, 2);
		world.setBlock(i + 40, j + 17, k + 32, sculk_block, 0, 2);
		world.setBlock(i + 40, j + 17, k + 33, sculk_block, 0, 2);
		world.setBlock(i + 40, j + 17, k + 34, sculk_block, 0, 2);
		world.setBlock(i + 39, j + 17, k + 35, sculk_block, 0, 2);
		world.setBlock(i + 39, j + 17, k + 36, sculk_block, 0, 2);
		world.setBlock(i + 38, j + 17, k + 37, sculk_block, 0, 2);
		world.setBlock(i + 38, j + 17, k + 38, sculk_block, 0, 2);
		world.setBlock(i + 38, j + 17, k + 39, sculk_block, 0, 2);
		world.setBlock(i + 37, j + 17, k + 40, sculk_block, 0, 2);
		world.setBlock(i + 37, j + 17, k + 41, sculk_block, 0, 2);
		world.setBlock(i + 36, j + 17, k + 42, sculk_block, 0, 2);
		world.setBlock(i + 35, j + 17, k + 43, sculk_block, 0, 2);
		world.setBlock(i + 41, j + 18, k + 3, sculk_block, 0, 2);
		world.setBlock(i + 41, j + 18, k + 4, sculk_block, 0, 2);
		world.setBlock(i + 42, j + 18, k + 5, sculk_block, 0, 2);
		world.setBlock(i + 42, j + 18, k + 6, sculk_block, 0, 2);
		world.setBlock(i + 42, j + 18, k + 7, sculk_block, 0, 2);
		world.setBlock(i + 42, j + 18, k + 8, sculk_block, 0, 2);
		world.setBlock(i + 42, j + 18, k + 9, sculk_block, 0, 2);
		world.setBlock(i + 42, j + 18, k + 10, sculk_block, 0, 2);
		world.setBlock(i + 42, j + 18, k + 11, sculk_block, 0, 2);
		world.setBlock(i + 42, j + 18, k + 12, sculk_block, 0, 2);
		world.setBlock(i + 42, j + 18, k + 13, sculk_block, 0, 2);
		world.setBlock(i + 43, j + 18, k + 14, sculk_block, 0, 2);
		world.setBlock(i + 42, j + 18, k + 15, NovaCraftBlocks.sculk_vein, 0, 2);
		world.setBlock(i + 43, j + 18, k + 15, sculk_block, 0, 2);
		world.setBlock(i + 43, j + 18, k + 16, sculk_block, 0, 2);
		world.setBlock(i + 43, j + 18, k + 17, sculk_block, 0, 2);
		world.setBlock(i + 42, j + 18, k + 18, NovaCraftBlocks.sculk_vein, 0, 2);
		world.setBlock(i + 43, j + 18, k + 18, sculk_block, 0, 2);
		world.setBlock(i + 42, j + 18, k + 19, sculk_block, 0, 2);
		world.setBlock(i + 42, j + 18, k + 20, sculk_block, 0, 2);
		world.setBlock(i + 42, j + 18, k + 21, sculk_block, 0, 2);
		world.setBlock(i + 42, j + 18, k + 22, sculk_block, 0, 2);
		world.setBlock(i + 42, j + 18, k + 23, sculk_block, 0, 2);
		world.setBlock(i + 42, j + 18, k + 24, sculk_block, 0, 2);
		world.setBlock(i + 42, j + 18, k + 25, sculk_block, 0, 2);
		world.setBlock(i + 42, j + 18, k + 26, sculk_block, 0, 2);
		world.setBlock(i + 41, j + 18, k + 27, sculk_block, 0, 2);
		world.setBlock(i + 40, j + 18, k + 28, NovaCraftBlocks.sculk_vein, 0, 2);
		world.setBlock(i + 41, j + 18, k + 28, sculk_block, 0, 2);
		world.setBlock(i + 41, j + 18, k + 29, sculk_block, 0, 2);
		world.setBlock(i + 41, j + 18, k + 30, sculk_block, 0, 2);
		world.setBlock(i + 40, j + 18, k + 31, sculk_block, 0, 2);
		world.setBlock(i + 40, j + 18, k + 32, sculk_block, 0, 2);
		world.setBlock(i + 40, j + 18, k + 33, sculk_block, 0, 2);
		world.setBlock(i + 39, j + 18, k + 34, sculk_block, 0, 2);
		world.setBlock(i + 39, j + 18, k + 35, sculk_block, 0, 2);
		world.setBlock(i + 38, j + 18, k + 36, sculk_block, 0, 2);
		world.setBlock(i + 38, j + 18, k + 37, sculk_block, 0, 2);
		world.setBlock(i + 38, j + 18, k + 38, sculk_block, 0, 2);
		world.setBlock(i + 37, j + 18, k + 39, sculk_block, 0, 2);
		world.setBlock(i + 37, j + 18, k + 40, sculk_block, 0, 2);
		world.setBlock(i + 36, j + 18, k + 41, sculk_block, 0, 2);
		world.setBlock(i + 35, j + 18, k + 42, sculk_block, 0, 2);
		world.setBlock(i + 41, j + 19, k + 3, sculk_block, 0, 2);
		world.setBlock(i + 41, j + 19, k + 4, sculk_block, 0, 2);
		world.setBlock(i + 40, j + 19, k + 5, NovaCraftBlocks.sculk_vein, 0, 2);
		world.setBlock(i + 41, j + 19, k + 5, sculk_block, 0, 2);
		world.setBlock(i + 41, j + 19, k + 6, sculk_block, 0, 2);
		world.setBlock(i + 40, j + 19, k + 7, NovaCraftBlocks.sculk_tentacle_2, 0, 2);
		world.setBlock(i + 41, j + 19, k + 7, sculk_block, 0, 2);
		world.setBlock(i + 41, j + 19, k + 8, sculk_block, 0, 2);
		world.setBlock(i + 42, j + 19, k + 9, sculk_block, 0, 2);
		world.setBlock(i + 41, j + 19, k + 10, NovaCraftBlocks.sculk_spike, 0, 2);
		world.setBlock(i + 42, j + 19, k + 10, sculk_block, 0, 2);
		world.setBlock(i + 42, j + 19, k + 11, sculk_block, 0, 2);
		world.setBlock(i + 42, j + 19, k + 12, sculk_block, 0, 2);
		world.setBlock(i + 41, j + 19, k + 13, NovaCraftBlocks.sculk_tentacle_2, 0, 2);
		world.setBlock(i + 42, j + 19, k + 13, sculk_block, 0, 2);
		world.setBlock(i + 42, j + 19, k + 14, sculk_block, 0, 2);
		world.setBlock(i + 42, j + 19, k + 15, sculk_block, 0, 2);
		world.setBlock(i + 42, j + 19, k + 16, sculk_block, 0, 2);
		world.setBlock(i + 42, j + 19, k + 17, sculk_block, 0, 2);
		world.setBlock(i + 42, j + 19, k + 18, sculk_block, 0, 2);
		world.setBlock(i + 42, j + 19, k + 19, sculk_block, 0, 2);
		world.setBlock(i + 42, j + 19, k + 20, sculk_block, 0, 2);
		world.setBlock(i + 42, j + 19, k + 21, sculk_block, 0, 2);
		world.setBlock(i + 41, j + 19, k + 22, sculk_block, 0, 2);
		world.setBlock(i + 41, j + 19, k + 23, sculk_block, 0, 2);
		world.setBlock(i + 41, j + 19, k + 24, sculk_block, 0, 2);
		world.setBlock(i + 41, j + 19, k + 25, sculk_block, 0, 2);
		world.setBlock(i + 41, j + 19, k + 26, sculk_block, 0, 2);
		world.setBlock(i + 40, j + 19, k + 27, NovaCraftBlocks.sculk_tentacle_2, 0, 2);
		world.setBlock(i + 41, j + 19, k + 27, sculk_block, 0, 2);
		world.setBlock(i + 40, j + 19, k + 28, sculk_block, 0, 2);
		world.setBlock(i + 40, j + 19, k + 29, sculk_block, 0, 2);
		world.setBlock(i + 40, j + 19, k + 30, sculk_block, 0, 2);
		world.setBlock(i + 40, j + 19, k + 31, sculk_block, 0, 2);
		world.setBlock(i + 39, j + 19, k + 32, sculk_block, 0, 2);
		world.setBlock(i + 38, j + 19, k + 33, NovaCraftBlocks.sculk_tentacle_2, 0, 2);
		world.setBlock(i + 39, j + 19, k + 33, sculk_block, 0, 2);
		world.setBlock(i + 38, j + 19, k + 34, sculk_block, 0, 2);
		world.setBlock(i + 38, j + 19, k + 35, sculk_block, 0, 2);
		world.setBlock(i + 39, j + 19, k + 35, sculk_block, 0, 2);
		world.setBlock(i + 38, j + 19, k + 36, sculk_block, 0, 2);
		world.setBlock(i + 36, j + 19, k + 37, NovaCraftBlocks.sculk_spike, 0, 2);
		world.setBlock(i + 37, j + 19, k + 37, sculk_block, 0, 2);
		world.setBlock(i + 37, j + 19, k + 38, sculk_block, 0, 2);
		world.setBlock(i + 36, j + 19, k + 39, sculk_block, 0, 2);
		world.setBlock(i + 36, j + 19, k + 40, sculk_block, 0, 2);
		world.setBlock(i + 35, j + 19, k + 41, sculk_block, 0, 2);
		world.setBlock(i + 35, j + 19, k + 42, sculk_block, 0, 2);
		world.setBlock(i + 39, j + 20, k + 3, NovaCraftBlocks.sculk_tentacle_2, 0, 2);
		world.setBlock(i + 40, j + 20, k + 3, sculk_block, 0, 2);
		world.setBlock(i + 40, j + 20, k + 4, sculk_block, 0, 2);
		world.setBlock(i + 40, j + 20, k + 5, sculk_block, 0, 2);
		world.setBlock(i + 40, j + 20, k + 6, sculk_block, 0, 2);
		world.setBlock(i + 40, j + 20, k + 7, sculk_block, 0, 2);
		world.setBlock(i + 40, j + 20, k + 8, sculk_block, 0, 2);
		world.setBlock(i + 41, j + 20, k + 9, sculk_block, 0, 2);
		world.setBlock(i + 41, j + 20, k + 10, sculk_block, 0, 2);
		world.setBlock(i + 41, j + 20, k + 11, sculk_block, 0, 2);
		world.setBlock(i + 41, j + 20, k + 12, sculk_block, 0, 2);
		world.setBlock(i + 41, j + 20, k + 13, sculk_block, 0, 2);
		world.setBlock(i + 41, j + 20, k + 14, sculk_block, 0, 2);
		world.setBlock(i + 41, j + 20, k + 15, sculk_block, 0, 2);
		world.setBlock(i + 40, j + 20, k + 16, NovaCraftBlocks.sculk_vein, 0, 2);
		world.setBlock(i + 41, j + 20, k + 16, sculk_block, 0, 2);
		world.setBlock(i + 41, j + 20, k + 17, sculk_block, 0, 2);
		world.setBlock(i + 41, j + 20, k + 18, sculk_block, 0, 2);
		world.setBlock(i + 41, j + 20, k + 19, sculk_block, 0, 2);
		world.setBlock(i + 41, j + 20, k + 20, sculk_block, 0, 2);
		world.setBlock(i + 41, j + 20, k + 21, sculk_block, 0, 2);
		world.setBlock(i + 40, j + 20, k + 22, NovaCraftBlocks.sculk_spike, 0, 2);
		world.setBlock(i + 41, j + 20, k + 22, sculk_block, 0, 2);
		world.setBlock(i + 40, j + 20, k + 23, sculk_block, 0, 2);
		world.setBlock(i + 40, j + 20, k + 24, sculk_block, 0, 2);
		world.setBlock(i + 40, j + 20, k + 25, sculk_block, 0, 2);
		world.setBlock(i + 39, j + 20, k + 26, NovaCraftBlocks.sculk_spike, 0, 2);
		world.setBlock(i + 40, j + 20, k + 26, sculk_block, 0, 2);
		world.setBlock(i + 40, j + 20, k + 27, sculk_block, 0, 2);
		world.setBlock(i + 39, j + 20, k + 28, sculk_block, 0, 2);
		world.setBlock(i + 39, j + 20, k + 29, sculk_block, 0, 2);
		world.setBlock(i + 38, j + 20, k + 30, NovaCraftBlocks.sculk_vein, 0, 2);
		world.setBlock(i + 39, j + 20, k + 30, sculk_block, 0, 2);
		world.setBlock(i + 39, j + 20, k + 31, sculk_block, 0, 2);
		world.setBlock(i + 38, j + 20, k + 32, sculk_block, 0, 2);
		world.setBlock(i + 38, j + 20, k + 33, sculk_block, 0, 2);
		world.setBlock(i + 36, j + 20, k + 34, NovaCraftBlocks.sculk_vein, 0, 2);
		world.setBlock(i + 37, j + 20, k + 34, sculk_block, 0, 2);
		world.setBlock(i + 38, j + 20, k + 34, sculk_block, 0, 2);
		world.setBlock(i + 37, j + 20, k + 35, sculk_block, 0, 2);
		world.setBlock(i + 36, j + 20, k + 36, sculk_block, 0, 2);
		world.setBlock(i + 37, j + 20, k + 36, sculk_block, 0, 2);
		world.setBlock(i + 36, j + 20, k + 37, sculk_block, 0, 2);
		world.setBlock(i + 36, j + 20, k + 38, sculk_block, 0, 2);
		world.setBlock(i + 34, j + 20, k + 39, NovaCraftBlocks.sculk_vein, 0, 2);
		world.setBlock(i + 35, j + 20, k + 39, sculk_block, 0, 2);
		world.setBlock(i + 34, j + 20, k + 40, sculk_block, 0, 2);
		world.setBlock(i + 35, j + 20, k + 40, sculk_block, 0, 2);
		world.setBlock(i + 34, j + 20, k + 41, sculk_block, 0, 2);
		world.setBlock(i + 34, j + 20, k + 42, sculk_block, 0, 2);
		world.setBlock(i + 38, j + 21, k + 2, sculk_block, 0, 2);
		world.setBlock(i + 39, j + 21, k + 3, sculk_block, 0, 2);
		world.setBlock(i + 39, j + 21, k + 4, sculk_block, 0, 2);
		world.setBlock(i + 39, j + 21, k + 5, sculk_block, 0, 2);
		world.setBlock(i + 39, j + 21, k + 6, sculk_block, 0, 2);
		world.setBlock(i + 38, j + 21, k + 7, NovaCraftBlocks.sculk_spike, 0, 2);
		world.setBlock(i + 39, j + 21, k + 7, sculk_block, 0, 2);
		world.setBlock(i + 39, j + 21, k + 8, sculk_block, 0, 2);
		world.setBlock(i + 40, j + 21, k + 8, sculk_block, 0, 2);
		world.setBlock(i + 40, j + 21, k + 9, sculk_block, 0, 2);
		world.setBlock(i + 39, j + 21, k + 10, NovaCraftBlocks.sculk_tentacle_2, 0, 2);
		world.setBlock(i + 40, j + 21, k + 10, sculk_block, 0, 2);
		world.setBlock(i + 40, j + 21, k + 11, sculk_block, 0, 2);
		world.setBlock(i + 40, j + 21, k + 12, sculk_block, 0, 2);
		world.setBlock(i + 40, j + 21, k + 13, sculk_block, 0, 2);
		world.setBlock(i + 40, j + 21, k + 14, sculk_block, 0, 2);
		world.setBlock(i + 40, j + 21, k + 15, sculk_block, 0, 2);
		world.setBlock(i + 39, j + 21, k + 16, NovaCraftBlocks.sculk_tentacle_2, 0, 2);
		world.setBlock(i + 40, j + 21, k + 16, sculk_block, 0, 2);
		world.setBlock(i + 40, j + 21, k + 17, sculk_block, 0, 2);
		world.setBlock(i + 40, j + 21, k + 18, sculk_block, 0, 2);
		world.setBlock(i + 39, j + 21, k + 19, NovaCraftBlocks.sculk_spike, 0, 2);
		world.setBlock(i + 40, j + 21, k + 19, sculk_block, 0, 2);
		world.setBlock(i + 40, j + 21, k + 20, sculk_block, 0, 2);
		world.setBlock(i + 40, j + 21, k + 21, sculk_block, 0, 2);
		world.setBlock(i + 39, j + 21, k + 22, sculk_block, 0, 2);
		world.setBlock(i + 40, j + 21, k + 22, sculk_block, 0, 2);
		world.setBlock(i + 39, j + 21, k + 23, sculk_block, 0, 2);
		world.setBlock(i + 39, j + 21, k + 24, sculk_block, 0, 2);
		world.setBlock(i + 39, j + 21, k + 25, sculk_block, 0, 2);
		world.setBlock(i + 39, j + 21, k + 26, sculk_block, 0, 2);
		world.setBlock(i + 39, j + 21, k + 27, sculk_block, 0, 2);
		world.setBlock(i + 38, j + 21, k + 28, sculk_block, 0, 2);
		world.setBlock(i + 37, j + 21, k + 29, NovaCraftBlocks.sculk_spike, 0, 2);
		world.setBlock(i + 38, j + 21, k + 29, sculk_block, 0, 2);
		world.setBlock(i + 38, j + 21, k + 30, sculk_block, 0, 2);
		world.setBlock(i + 37, j + 21, k + 31, sculk_block, 0, 2);
		world.setBlock(i + 38, j + 21, k + 31, sculk_block, 0, 2);
		world.setBlock(i + 37, j + 21, k + 32, sculk_block, 0, 2);
		world.setBlock(i + 37, j + 21, k + 33, sculk_block, 0, 2);
		world.setBlock(i + 36, j + 21, k + 34, sculk_block, 0, 2);
		world.setBlock(i + 36, j + 21, k + 35, sculk_block, 0, 2);
		world.setBlock(i + 35, j + 21, k + 36, sculk_block, 0, 2);
		world.setBlock(i + 35, j + 21, k + 37, sculk_block, 0, 2);
		world.setBlock(i + 34, j + 21, k + 38, NovaCraftBlocks.sculk_spike, 0, 2);
		world.setBlock(i + 35, j + 21, k + 38, sculk_block, 0, 2);
		world.setBlock(i + 34, j + 21, k + 39, sculk_block, 0, 2);
		world.setBlock(i + 33, j + 21, k + 40, sculk_block, 0, 2);
		world.setBlock(i + 34, j + 21, k + 40, sculk_block, 0, 2);
		world.setBlock(i + 32, j + 21, k + 41, sculk_block, 0, 2);
		world.setBlock(i + 33, j + 21, k + 41, sculk_block, 0, 2);
		world.setBlock(i + 37, j + 22, k + 2, sculk_block, 0, 2);
		world.setBlock(i + 37, j + 22, k + 3, sculk_block, 0, 2);
		world.setBlock(i + 38, j + 22, k + 3, sculk_block, 0, 2);
		world.setBlock(i + 37, j + 22, k + 4, sculk_block, 0, 2);
		world.setBlock(i + 38, j + 22, k + 4, sculk_block, 0, 2);
		world.setBlock(i + 38, j + 22, k + 5, sculk_block, 0, 2);
		world.setBlock(i + 38, j + 22, k + 6, sculk_block, 0, 2);
		world.setBlock(i + 38, j + 22, k + 7, sculk_block, 0, 2);
		world.setBlock(i + 38, j + 22, k + 8, sculk_block, 0, 2);
		world.setBlock(i + 38, j + 22, k + 9, sculk_block, 0, 2);
		world.setBlock(i + 39, j + 22, k + 9, sculk_block, 0, 2);
		world.setBlock(i + 38, j + 22, k + 10, sculk_block, 0, 2);
		world.setBlock(i + 39, j + 22, k + 10, sculk_block, 0, 2);
		world.setBlock(i + 38, j + 22, k + 11, sculk_block, 0, 2);
		world.setBlock(i + 39, j + 22, k + 11, sculk_block, 0, 2);
		world.setBlock(i + 39, j + 22, k + 12, sculk_block, 0, 2);
		world.setBlock(i + 38, j + 22, k + 13, NovaCraftBlocks.sculk_vein, 0, 2);
		world.setBlock(i + 39, j + 22, k + 13, sculk_block, 0, 2);
		world.setBlock(i + 39, j + 22, k + 14, sculk_block, 0, 2);
		world.setBlock(i + 39, j + 22, k + 15, sculk_block, 0, 2);
		world.setBlock(i + 39, j + 22, k + 16, sculk_block, 0, 2);
		world.setBlock(i + 39, j + 22, k + 17, sculk_block, 0, 2);
		world.setBlock(i + 39, j + 22, k + 18, sculk_block, 0, 2);
		world.setBlock(i + 38, j + 22, k + 19, sculk_block, 0, 2);
		world.setBlock(i + 39, j + 22, k + 19, sculk_block, 0, 2);
		world.setBlock(i + 38, j + 22, k + 20, sculk_block, 0, 2);
		world.setBlock(i + 39, j + 22, k + 20, sculk_block, 0, 2);
		world.setBlock(i + 38, j + 22, k + 21, sculk_block, 0, 2);
		world.setBlock(i + 39, j + 22, k + 21, sculk_block, 0, 2);
		world.setBlock(i + 38, j + 22, k + 22, sculk_block, 0, 2);
		world.setBlock(i + 37, j + 22, k + 23, NovaCraftBlocks.sculk_tentacle_2, 0, 2);
		world.setBlock(i + 38, j + 22, k + 23, sculk_block, 0, 2);
		world.setBlock(i + 38, j + 22, k + 24, sculk_block, 0, 2);
		world.setBlock(i + 38, j + 22, k + 25, sculk_block, 0, 2);
		world.setBlock(i + 37, j + 22, k + 26, sculk_block, 0, 2);
		world.setBlock(i + 38, j + 22, k + 26, sculk_block, 0, 2);
		world.setBlock(i + 36, j + 22, k + 27, NovaCraftBlocks.sculk_tentacle_2, 0, 2);
		world.setBlock(i + 37, j + 22, k + 27, sculk_block, 0, 2);
		world.setBlock(i + 38, j + 22, k + 27, sculk_block, 0, 2);
		world.setBlock(i + 37, j + 22, k + 28, sculk_block, 0, 2);
		world.setBlock(i + 37, j + 22, k + 29, sculk_block, 0, 2);
		world.setBlock(i + 36, j + 22, k + 30, sculk_block, 0, 2);
		world.setBlock(i + 37, j + 22, k + 30, sculk_block, 0, 2);
		world.setBlock(i + 36, j + 22, k + 31, sculk_block, 0, 2);
		world.setBlock(i + 36, j + 22, k + 32, sculk_block, 0, 2);
		world.setBlock(i + 35, j + 22, k + 33, sculk_block, 0, 2);
		world.setBlock(i + 36, j + 22, k + 33, sculk_block, 0, 2);
		world.setBlock(i + 35, j + 22, k + 34, sculk_block, 0, 2);
		world.setBlock(i + 34, j + 22, k + 35, sculk_block, 0, 2);
		world.setBlock(i + 35, j + 22, k + 35, sculk_block, 0, 2);
		world.setBlock(i + 34, j + 22, k + 36, sculk_block, 0, 2);
		world.setBlock(i + 34, j + 22, k + 37, sculk_block, 0, 2);
		world.setBlock(i + 33, j + 22, k + 38, sculk_block, 0, 2);
		world.setBlock(i + 34, j + 22, k + 38, sculk_block, 0, 2);
		world.setBlock(i + 32, j + 22, k + 39, sculk_block, 0, 2);
		world.setBlock(i + 33, j + 22, k + 39, sculk_block, 0, 2);
		world.setBlock(i + 32, j + 22, k + 40, sculk_block, 0, 2);
		world.setBlock(i + 33, j + 22, k + 40, sculk_block, 0, 2);
		world.setBlock(i + 31, j + 22, k + 41, sculk_block, 0, 2);
		world.setBlock(i + 32, j + 22, k + 41, sculk_block, 0, 2);
		world.setBlock(i + 33, j + 22, k + 41, sculk_block, 0, 2);
		world.setBlock(i + 36, j + 23, k + 3, sculk_block, 0, 2);
		world.setBlock(i + 36, j + 23, k + 4, sculk_block, 0, 2);
		world.setBlock(i + 35, j + 23, k + 5, NovaCraftBlocks.sculk_spike, 0, 2);
		world.setBlock(i + 36, j + 23, k + 5, sculk_block, 0, 2);
		world.setBlock(i + 37, j + 23, k + 5, sculk_block, 0, 2);
		world.setBlock(i + 36, j + 23, k + 6, sculk_block, 0, 2);
		world.setBlock(i + 37, j + 23, k + 6, sculk_block, 0, 2);
		world.setBlock(i + 36, j + 23, k + 7, sculk_block, 0, 2);
		world.setBlock(i + 37, j + 23, k + 7, sculk_block, 0, 2);
		world.setBlock(i + 37, j + 23, k + 8, sculk_block, 0, 2);
		world.setBlock(i + 37, j + 23, k + 9, sculk_block, 0, 2);
		world.setBlock(i + 36, j + 23, k + 10, NovaCraftBlocks.sculk_vein, 0, 2);
		world.setBlock(i + 37, j + 23, k + 10, sculk_block, 0, 2);
		world.setBlock(i + 37, j + 23, k + 11, sculk_block, 0, 2);
		world.setBlock(i + 37, j + 23, k + 12, sculk_block, 0, 2);
		world.setBlock(i + 38, j + 23, k + 12, sculk_block, 0, 2);
		world.setBlock(i + 36, j + 23, k + 13, NovaCraftBlocks.sculk_spike, 0, 2);
		world.setBlock(i + 37, j + 23, k + 13, sculk_block, 0, 2);
		world.setBlock(i + 38, j + 23, k + 13, sculk_block, 0, 2);
		world.setBlock(i + 37, j + 23, k + 14, sculk_block, 0, 2);
		world.setBlock(i + 38, j + 23, k + 14, sculk_block, 0, 2);
		world.setBlock(i + 37, j + 23, k + 15, sculk_block, 0, 2);
		world.setBlock(i + 38, j + 23, k + 15, sculk_block, 0, 2);
		world.setBlock(i + 37, j + 23, k + 16, sculk_block, 0, 2);
		world.setBlock(i + 38, j + 23, k + 16, sculk_block, 0, 2);
		world.setBlock(i + 37, j + 23, k + 17, sculk_block, 0, 2);
		world.setBlock(i + 38, j + 23, k + 17, sculk_block, 0, 2);
		world.setBlock(i + 36, j + 23, k + 18, NovaCraftBlocks.sculk_vein, 0, 2);
		world.setBlock(i + 37, j + 23, k + 18, sculk_block, 0, 2);
		world.setBlock(i + 38, j + 23, k + 18, sculk_block, 0, 2);
		world.setBlock(i + 37, j + 23, k + 19, sculk_block, 0, 2);
		world.setBlock(i + 37, j + 23, k + 20, sculk_block, 0, 2);
		world.setBlock(i + 35, j + 23, k + 21, NovaCraftBlocks.sculk_tentacle_2, 0, 2);
		world.setBlock(i + 37, j + 23, k + 21, sculk_block, 0, 2);
		world.setBlock(i + 37, j + 23, k + 22, sculk_block, 0, 2);
		world.setBlock(i + 36, j + 23, k + 23, sculk_block, 0, 2);
		world.setBlock(i + 37, j + 23, k + 23, sculk_block, 0, 2);
		world.setBlock(i + 35, j + 23, k + 24, NovaCraftBlocks.sculk_vein, 0, 2);
		world.setBlock(i + 36, j + 23, k + 24, sculk_block, 0, 2);
		world.setBlock(i + 37, j + 23, k + 24, sculk_block, 0, 2);
		world.setBlock(i + 36, j + 23, k + 25, sculk_block, 0, 2);
		world.setBlock(i + 37, j + 23, k + 25, sculk_block, 0, 2);
		world.setBlock(i + 36, j + 23, k + 26, sculk_block, 0, 2);
		world.setBlock(i + 36, j + 23, k + 27, sculk_block, 0, 2);
		world.setBlock(i + 35, j + 23, k + 28, sculk_block, 0, 2);
		world.setBlock(i + 36, j + 23, k + 28, sculk_block, 0, 2);
		world.setBlock(i + 35, j + 23, k + 29, sculk_block, 0, 2);
		world.setBlock(i + 36, j + 23, k + 29, sculk_block, 0, 2);
		world.setBlock(i + 33, j + 23, k + 30, NovaCraftBlocks.sculk_tentacle_2, 0, 2);
		world.setBlock(i + 35, j + 23, k + 30, sculk_block, 0, 2);
		world.setBlock(i + 34, j + 23, k + 31, sculk_block, 0, 2);
		world.setBlock(i + 35, j + 23, k + 31, sculk_block, 0, 2);
		world.setBlock(i + 34, j + 23, k + 32, sculk_block, 0, 2);
		world.setBlock(i + 35, j + 23, k + 32, sculk_block, 0, 2);
		world.setBlock(i + 32, j + 23, k + 33, NovaCraftBlocks.sculk_vein, 0, 2);
		world.setBlock(i + 33, j + 23, k + 33, NovaCraftBlocks.sculk_spike, 0, 2);
		world.setBlock(i + 34, j + 23, k + 33, sculk_block, 0, 2);
		world.setBlock(i + 33, j + 23, k + 34, sculk_block, 0, 2);
		world.setBlock(i + 34, j + 23, k + 34, sculk_block, 0, 2);
		world.setBlock(i + 33, j + 23, k + 35, sculk_block, 0, 2);
		world.setBlock(i + 31, j + 23, k + 36, NovaCraftBlocks.sculk_tentacle_2, 0, 2);
		world.setBlock(i + 32, j + 23, k + 36, sculk_block, 0, 2);
		world.setBlock(i + 33, j + 23, k + 36, sculk_block, 0, 2);
		world.setBlock(i + 32, j + 23, k + 37, sculk_block, 0, 2);
		world.setBlock(i + 33, j + 23, k + 37, sculk_block, 0, 2);
		world.setBlock(i + 31, j + 23, k + 38, sculk_block, 0, 2);
		world.setBlock(i + 32, j + 23, k + 38, sculk_block, 0, 2);
		world.setBlock(i + 30, j + 23, k + 39, NovaCraftBlocks.sculk_vein, 0, 2);
		world.setBlock(i + 31, j + 23, k + 39, sculk_block, 0, 2);
		world.setBlock(i + 32, j + 23, k + 39, sculk_block, 0, 2);
		world.setBlock(i + 30, j + 23, k + 40, sculk_block, 0, 2);
		world.setBlock(i + 31, j + 23, k + 40, sculk_block, 0, 2);
		world.setBlock(i + 29, j + 23, k + 41, sculk_block, 0, 2);
		world.setBlock(i + 30, j + 23, k + 41, sculk_block, 0, 2);
		world.setBlock(i + 33, j + 23, k + 41, sculk_block, 0, 2);
		world.setBlock(i + 35, j + 24, k + 4, sculk_block, 0, 2);
		world.setBlock(i + 34, j + 24, k + 5, sculk_block, 0, 2);
		world.setBlock(i + 35, j + 24, k + 5, sculk_block, 0, 2);
		world.setBlock(i + 34, j + 24, k + 6, sculk_block, 0, 2);
		world.setBlock(i + 35, j + 24, k + 6, sculk_block, 0, 2);
		world.setBlock(i + 34, j + 24, k + 7, sculk_block, 0, 2);
		world.setBlock(i + 35, j + 24, k + 7, sculk_block, 0, 2);
		world.setBlock(i + 35, j + 24, k + 8, sculk_block, 0, 2);
		world.setBlock(i + 36, j + 24, k + 8, sculk_block, 0, 2);
		world.setBlock(i + 35, j + 24, k + 9, sculk_block, 0, 2);
		world.setBlock(i + 36, j + 24, k + 9, sculk_block, 0, 2);
		world.setBlock(i + 35, j + 24, k + 10, sculk_block, 0, 2);
		world.setBlock(i + 36, j + 24, k + 10, sculk_block, 0, 2);
		world.setBlock(i + 33, j + 24, k + 11, NovaCraftBlocks.sculk_spike, 0, 2);
		world.setBlock(i + 35, j + 24, k + 11, sculk_block, 0, 2);
		world.setBlock(i + 36, j + 24, k + 11, sculk_block, 0, 2);
		world.setBlock(i + 35, j + 24, k + 12, sculk_block, 0, 2);
		world.setBlock(i + 36, j + 24, k + 12, sculk_block, 0, 2);
		world.setBlock(i + 35, j + 24, k + 13, sculk_block, 0, 2);
		world.setBlock(i + 36, j + 24, k + 13, sculk_block, 0, 2);
		world.setBlock(i + 35, j + 24, k + 14, sculk_block, 0, 2);
		world.setBlock(i + 36, j + 24, k + 14, sculk_block, 0, 2);
		world.setBlock(i + 35, j + 24, k + 15, sculk_block, 0, 2);
		world.setBlock(i + 36, j + 24, k + 15, sculk_block, 0, 2);
		world.setBlock(i + 35, j + 24, k + 16, sculk_block, 0, 2);
		world.setBlock(i + 36, j + 24, k + 16, sculk_block, 0, 2);
		world.setBlock(i + 35, j + 24, k + 17, sculk_block, 0, 2);
		world.setBlock(i + 36, j + 24, k + 17, sculk_block, 0, 2);
		world.setBlock(i + 35, j + 24, k + 18, sculk_block, 0, 2);
		world.setBlock(i + 36, j + 24, k + 18, sculk_block, 0, 2);
		world.setBlock(i + 35, j + 24, k + 19, sculk_block, 0, 2);
		world.setBlock(i + 36, j + 24, k + 19, sculk_block, 0, 2);
		world.setBlock(i + 35, j + 24, k + 20, sculk_block, 0, 2);
		world.setBlock(i + 36, j + 24, k + 20, sculk_block, 0, 2);
		world.setBlock(i + 34, j + 24, k + 21, NovaCraftBlocks.sculk_spike, 0, 2);
		world.setBlock(i + 35, j + 24, k + 21, sculk_block, 0, 2);
		world.setBlock(i + 36, j + 24, k + 21, sculk_block, 0, 2);
		world.setBlock(i + 35, j + 24, k + 22, sculk_block, 0, 2);
		world.setBlock(i + 36, j + 24, k + 22, sculk_block, 0, 2);
		world.setBlock(i + 34, j + 24, k + 23, sculk_block, 0, 2);
		world.setBlock(i + 35, j + 24, k + 23, sculk_block, 0, 2);
		world.setBlock(i + 34, j + 24, k + 24, sculk_block, 0, 2);
		world.setBlock(i + 35, j + 24, k + 24, sculk_block, 0, 2);
		world.setBlock(i + 34, j + 24, k + 25, sculk_block, 0, 2);
		world.setBlock(i + 35, j + 24, k + 25, sculk_block, 0, 2);
		world.setBlock(i + 34, j + 24, k + 26, sculk_block, 0, 2);
		world.setBlock(i + 35, j + 24, k + 26, sculk_block, 0, 2);
		world.setBlock(i + 33, j + 24, k + 27, NovaCraftBlocks.sculk_vein, 0, 2);
		world.setBlock(i + 34, j + 24, k + 27, sculk_block, 0, 2);
		world.setBlock(i + 35, j + 24, k + 27, sculk_block, 0, 2);
		world.setBlock(i + 33, j + 24, k + 28, sculk_block, 0, 2);
		world.setBlock(i + 34, j + 24, k + 28, sculk_block, 0, 2);
		world.setBlock(i + 33, j + 24, k + 29, sculk_block, 0, 2);
		world.setBlock(i + 34, j + 24, k + 29, sculk_block, 0, 2);
		world.setBlock(i + 33, j + 24, k + 30, sculk_block, 0, 2);
		world.setBlock(i + 34, j + 24, k + 30, sculk_block, 0, 2);
		world.setBlock(i + 32, j + 24, k + 31, sculk_block, 0, 2);
		world.setBlock(i + 33, j + 24, k + 31, sculk_block, 0, 2);
		world.setBlock(i + 32, j + 24, k + 32, sculk_block, 0, 2);
		world.setBlock(i + 33, j + 24, k + 32, sculk_block, 0, 2);
		world.setBlock(i + 32, j + 24, k + 33, sculk_block, 0, 2);
		world.setBlock(i + 33, j + 24, k + 33, sculk_block, 0, 2);
		world.setBlock(i + 31, j + 24, k + 34, sculk_block, 0, 2);
		world.setBlock(i + 32, j + 24, k + 34, sculk_block, 0, 2);
		world.setBlock(i + 31, j + 24, k + 35, sculk_block, 0, 2);
		world.setBlock(i + 32, j + 24, k + 35, sculk_block, 0, 2);
		world.setBlock(i + 28, j + 24, k + 36, NovaCraftBlocks.sculk_tentacle_2, 0, 2);
		world.setBlock(i + 30, j + 24, k + 36, sculk_block, 0, 2);
		world.setBlock(i + 31, j + 24, k + 36, sculk_block, 0, 2);
		world.setBlock(i + 30, j + 24, k + 37, sculk_block, 0, 2);
		world.setBlock(i + 31, j + 24, k + 37, sculk_block, 0, 2);
		world.setBlock(i + 29, j + 24, k + 38, sculk_block, 0, 2);
		world.setBlock(i + 30, j + 24, k + 38, sculk_block, 0, 2);
		world.setBlock(i + 29, j + 24, k + 39, sculk_block, 0, 2);
		world.setBlock(i + 30, j + 24, k + 39, sculk_block, 0, 2);
		world.setBlock(i + 28, j + 24, k + 40, sculk_block, 0, 2);
		world.setBlock(i + 29, j + 24, k + 40, sculk_block, 0, 2);
		world.setBlock(i + 33, j + 25, k + 6, sculk_block, 0, 2);
		world.setBlock(i + 32, j + 25, k + 7, sculk_block, 0, 2);
		world.setBlock(i + 33, j + 25, k + 7, sculk_block, 0, 2);
		world.setBlock(i + 32, j + 25, k + 8, sculk_block, 0, 2);
		world.setBlock(i + 33, j + 25, k + 8, sculk_block, 0, 2);
		world.setBlock(i + 34, j + 25, k + 8, sculk_block, 0, 2);
		world.setBlock(i + 30, j + 25, k + 9, NovaCraftBlocks.sculk_tentacle_2, 0, 2);
		world.setBlock(i + 33, j + 25, k + 9, sculk_block, 0, 2);
		world.setBlock(i + 34, j + 25, k + 9, sculk_block, 0, 2);
		world.setBlock(i + 32, j + 25, k + 10, NovaCraftBlocks.sculk_vein, 0, 2);
		world.setBlock(i + 33, j + 25, k + 10, sculk_block, 0, 2);
		world.setBlock(i + 34, j + 25, k + 10, sculk_block, 0, 2);
		world.setBlock(i + 33, j + 25, k + 11, sculk_block, 0, 2);
		world.setBlock(i + 34, j + 25, k + 11, sculk_block, 0, 2);
		world.setBlock(i + 30, j + 25, k + 12, NovaCraftBlocks.sculk_tentacle_2, 0, 2);
		world.setBlock(i + 33, j + 25, k + 12, sculk_block, 0, 2);
		world.setBlock(i + 34, j + 25, k + 12, sculk_block, 0, 2);
		world.setBlock(i + 33, j + 25, k + 13, sculk_block, 0, 2);
		world.setBlock(i + 34, j + 25, k + 13, sculk_block, 0, 2);
		world.setBlock(i + 33, j + 25, k + 14, sculk_block, 0, 2);
		world.setBlock(i + 34, j + 25, k + 14, sculk_block, 0, 2);
		world.setBlock(i + 33, j + 25, k + 15, sculk_block, 0, 2);
		world.setBlock(i + 34, j + 25, k + 15, sculk_block, 0, 2);
		world.setBlock(i + 33, j + 25, k + 16, sculk_block, 0, 2);
		world.setBlock(i + 34, j + 25, k + 16, sculk_block, 0, 2);
		world.setBlock(i + 33, j + 25, k + 17, sculk_block, 0, 2);
		world.setBlock(i + 34, j + 25, k + 17, sculk_block, 0, 2);
		world.setBlock(i + 35, j + 25, k + 17, sculk_block, 0, 2);
		world.setBlock(i + 30, j + 25, k + 18, NovaCraftBlocks.sculk_tentacle_2, 0, 2);
		world.setBlock(i + 33, j + 25, k + 18, sculk_block, 0, 2);
