package com.NovaCraft.world.ancient_city;

import cpw.mods.fml.common.registry.GameRegistry;
import net.minecraft.world.gen.feature.*;
import net.minecraft.block.*;
import net.minecraft.world.*;
import java.util.*;

import com.NovaCraft.Items.NovaCraftItems;
import com.NovaCraft.config.Configs;
import com.NovaCraft.registry.OtherModBlocks;
import com.NovaCraftBlocks.NovaCraftBlocks;

import cpw.mods.fml.common.Loader;
import net.minecraft.init.*;
import net.minecraft.item.ItemStack;
import net.minecraft.tileentity.TileEntityChest;

public class AncientCityIceRoomAlternateGen1 extends WorldGenerator
{
	public AncientCityIceRoomAlternateGen1() {

	}
	private Block PlaceDeepslateBricks;
	private Block PlaceDeepslateTiles;
	private Block PlaceCrackedDeepslateBricks;
	private Block PlaceChiseledDeepslate;
	private Block PlaceSoulLantern;
	private Block PlaceCobbledDeepslate;
	private Block PlaceBlueIce;
	private Block PlaceIronTrapdoor;
	private Block PlaceBasalt;

	
	private Block PlaceDeepslateBrickSlab;
	private Block PlaceDeepslateBrickStairs;
	private Block PlacePolishedDeepslateStairs;

	private Block determineIfCobbledDeepslateExists(World world, int x, int y, int z) {
		Block existingBlock = world.getBlock(x, y, z);
		if (Configs.enableCobbledDeepslateInAncientCity && Loader.isModLoaded("etfuturum")) {
			try {
				Block cobbled_deepslate = GameRegistry.findBlock("etfuturum", "cobbled_deepslate");
				if (cobbled_deepslate != null && (existingBlock == null || existingBlock != cobbled_deepslate)) {
					return cobbled_deepslate;
				}
			} catch (Exception ex) {
				if (Configs.enableDebugMode) {
					System.out.println("Missing Cobbled Deepslate from Et Futurum Requiem, using Cobbled Grimstone instead...");
				}
				return NovaCraftBlocks.cobbled_grimstone;
			}
		}

		return NovaCraftBlocks.cobbled_grimstone;
	}

	private Block determineIfDeepslateBricksExists(World world, int x, int y, int z) {
		Block existingBlock = world.getBlock(x, y, z);
		if (Configs.enableDeepslateBricksInAncientCity && Loader.isModLoaded("etfuturum")) {
			try {
				Block deepslate_bricks = GameRegistry.findBlock("etfuturum", "deepslate_bricks");
				if (deepslate_bricks != null && (existingBlock == null || existingBlock != deepslate_bricks)) {
					return deepslate_bricks;
				}
			} catch (Exception ex) {
				if (Configs.enableDebugMode) {
					System.out.println("Missing Deepslate Bricks from Et Futurum Requiem, using Grimstone Bricks instead...");
				}
				return NovaCraftBlocks.grimstone_bricks;
			}
		}

		return NovaCraftBlocks.grimstone_bricks;
	}

	private Block determineIfCrackedDeepslateBricksExists(World world, int x, int y, int z) {
		Block existingBlock = world.getBlock(x, y, z);
		if (Configs.enableDeepslateBricksInAncientCity && Loader.isModLoaded("etfuturum")) {
			try {
				Block deepslate_bricks = GameRegistry.findBlock("etfuturum", "deepslate_bricks");
				if (deepslate_bricks != null && (existingBlock == null || existingBlock != deepslate_bricks)) {
					return deepslate_bricks;
				}
			} catch (Exception ex) {
				if (Configs.enableDebugMode) {
					System.out.println("Missing Cracked Deepslate Bricks from Et Futurum Requiem, using Cracked Grimstone Bricks instead...");
				}
				return NovaCraftBlocks.cracked_grimstone_bricks;
			}
		}

		return NovaCraftBlocks.cracked_grimstone_bricks;
	}

	private Block determineIfDeepslateTilesExist(World world, int x, int y, int z) {
		Block existingBlock = world.getBlock(x, y, z);
		if (Configs.enableDeepslateBricksInAncientCity && Loader.isModLoaded("etfuturum")) {
			try {
				Block deepslate_bricks = GameRegistry.findBlock("etfuturum", "deepslate_bricks");
				if (deepslate_bricks != null && (existingBlock == null || existingBlock != deepslate_bricks)) {
					return deepslate_bricks;
				}
			} catch (Exception ex) {
				if (Configs.enableDebugMode) {
					System.out.println("Missing Deepslate Tiles from Et Futurum Requiem, using Grimstone Tiles instead...");
				}
				return NovaCraftBlocks.grimstone_tiles;
			}
		}

		return NovaCraftBlocks.grimstone_tiles;
	}

	private Block determineIfChiseledDeepslateExist(World world, int x, int y, int z) {
		Block existingBlock = world.getBlock(x, y, z);
		if (Configs.enableDeepslateBricksInAncientCity && Loader.isModLoaded("etfuturum")) {
			try {
				Block deepslate_bricks = GameRegistry.findBlock("etfuturum", "deepslate_bricks");
				if (deepslate_bricks != null && (existingBlock == null || existingBlock != deepslate_bricks)) {
					return deepslate_bricks;
				}
			} catch (Exception ex) {
				if (Configs.enableDebugMode) {
					System.out.println("Missing Chiseled Deepslate from Et Futurum Requiem, using Chiseled Grimstone instead...");
				}
				return NovaCraftBlocks.chiseled_grimstone;
			}
		}

		return NovaCraftBlocks.chiseled_grimstone;
	}

	private Block determineIfDeepslateBrickStairsExists(World world, int x, int y, int z) {
		Block existingBlock = world.getBlock(x, y, z);
		if (Configs.enableDeepslateBricksInAncientCity && Loader.isModLoaded("etfuturum")) {
			try {
				Block deepslate_brick_stairs = GameRegistry.findBlock("etfuturum", "deepslate_brick_stairs");
				if (deepslate_brick_stairs != null && (existingBlock == null || existingBlock != deepslate_brick_stairs)) {
					return deepslate_brick_stairs;
				}
			} catch (Exception ex) {
				if (Configs.enableDebugMode) {
					System.out.println("Missing Deepslate Tile Stairs from Et Futurum Requiem, using Grimstone Tile Stairs instead...");
				}
				return NovaCraftBlocks.grimstone_brick_stairs;
			}
		}

		return NovaCraftBlocks.grimstone_brick_stairs;
	}

	private Block determineIfPolishedDeepslateStairsExists(World world, int x, int y, int z) {
		Block existingBlock = world.getBlock(x, y, z);
		if (Configs.enableDeepslateBricksInAncientCity && Loader.isModLoaded("etfuturum")) {
			try {
				Block polished_deepslate_stairs = GameRegistry.findBlock("etfuturum", "polished_deepslate_stairs");
				if (polished_deepslate_stairs != null && (existingBlock == null || existingBlock != polished_deepslate_stairs)) {
					return polished_deepslate_stairs;
				}
			} catch (Exception ex) {
				if (Configs.enableDebugMode) {
					System.out.println("Missing Deepslate Tile Stairs from Et Futurum Requiem, using Grimstone Tile Stairs instead...");
				}
				return NovaCraftBlocks.grimstone_stairs;
			}
		}

		return NovaCraftBlocks.grimstone_stairs;
	}

	private Block determineIfDeepslateSlabExists(World world, int x, int y, int z) {
		Block existingBlock = world.getBlock(x, y, z);
		if (Configs.enableDeepslateBricksInAncientCity && Loader.isModLoaded("etfuturum")) {
			try {
				Block deepslate_brick_slab = GameRegistry.findBlock("etfuturum", "deepslate_brick_slab");
				if (deepslate_brick_slab != null && (existingBlock == null || existingBlock != deepslate_brick_slab)) {
					return deepslate_brick_slab;
				}
			} catch (Exception ex) {
				if (Configs.enableDebugMode) {
					System.out.println("Missing Deepslate Brick Slab from Et Futurum Requiem, using Grimstone Brick Slab instead...");
				}
				return NovaCraftBlocks.grimstone_brick_slab;
			}
		}

		return NovaCraftBlocks.grimstone_brick_slab;
	}

	private Block determineIfIronTrapdoorExists(World world, int x, int y, int z) {
		Block existingBlock = world.getBlock(x, y, z);
		if (Configs.enableIronTrapdoorInAncientCity && Loader.isModLoaded("etfuturum")) {
			try {
				Block iron_trapdoor = GameRegistry.findBlock("etfuturum", "iron_trapdoor");
				if (iron_trapdoor != null && (existingBlock == null || existingBlock != iron_trapdoor)) {
					return iron_trapdoor;
				}
			} catch (Exception ex) {
				if (Configs.enableDebugMode) {
					System.out.println("Missing Iron Trapdoor from Et Futurum Requiem, using regular trapdoor instead...");
				}
				return Blocks.trapdoor;
			}
		}

		return Blocks.trapdoor;
	}

	private Block determineIfBlueIceExists(World world, int x, int y, int z) {
		Block existingBlock = world.getBlock(x, y, z);
		if (Configs.enableBlueIceInAncientCity && Loader.isModLoaded("etfuturum")) {
			try {
				Block blue_ice = GameRegistry.findBlock("etfuturum", "blue_ice");
				if (blue_ice != null && (existingBlock == null || existingBlock != blue_ice)) {
					return blue_ice;
				}
			} catch (Exception ex) {
				if (Configs.enableDebugMode) {
					System.out.println("Missing Blue Ice from Et Futurum Requiem, using packed ice instead...");
				}
				return Blocks.packed_ice;
			}
		}

		return Blocks.packed_ice;
	}

	private Block determineIfSoulLanternExists(World world, int x, int y, int z) {
		Block existingBlock = world.getBlock(x, y, z);

		if (!(Configs.enableEtFuturumSoulLanternInAncientCity) && Loader.isModLoaded("netherlicious")) {
			try {
				Block SoulLantern = GameRegistry.findBlock("netherlicious", "SoulLantern");
				if (SoulLantern != null && (existingBlock == null || existingBlock != SoulLantern)) {
					return SoulLantern;
				}
			} catch (Exception ex) {
				if (Configs.enableDebugMode) {
					System.out.println("Failed to Find Netherlicious soul lantern, trying Et Futurum Requiem...");
				}
			}
		}

		if (Loader.isModLoaded("etfuturum")) {
			try {
				Block soul_lantern = GameRegistry.findBlock("etfuturum", "soul_lantern");
				if (soul_lantern != null && (existingBlock == null || existingBlock != soul_lantern)) {
					return soul_lantern;
				}
			} catch (Exception ex) {
				if (Configs.enableDebugMode) {
					System.out.println("Failed to Find Et Futurum Requiem soul lantern, placing nothing...");
				}
			}
		}

		return Blocks.air;
	}

	private Block determineIfBasaltExists(World world, int x, int y, int z) {
		Block existingBlock = world.getBlock(x, y, z);

		if (!(Configs.disableNetherliciousBasaltInAncientCity) && Loader.isModLoaded("netherlicious")) {
			try {
				Block nether_Basalt = GameRegistry.findBlock("netherlicious", "Basalt");
				if (nether_Basalt != null && (existingBlock == null || existingBlock != nether_Basalt)) {
					return nether_Basalt;
				}
			} catch (Exception ex) {
				if (Configs.enableDebugMode) {
					System.out.println("Failed to Find Netherlicious basalt, trying Et Futurum Requiem...");
				}
			}
		}

		if (Loader.isModLoaded("etfuturum")) {
			try {
				Block et_basalt = GameRegistry.findBlock("etfuturum", "basalt");
				if (et_basalt != null && (existingBlock == null || existingBlock != et_basalt)) {
					return et_basalt;
				}
			} catch (Exception ex) {
				if (Configs.enableDebugMode) {
					System.out.println("Failed to Find Et Futurum Requiem basalt, placing Polished Vanite Bricks...");
				}
			}
		}

		return NovaCraftBlocks.polished_vanite_bricks;
	}
    
    public boolean generate(final World world, final Random random, final int i, final int j, final int k) {
    	PlaceCobbledDeepslate = determineIfCobbledDeepslateExists(world, i + 8, j + 0, k + 3);
    	PlaceDeepslateBricks = determineIfDeepslateBricksExists(world, i + 1, j + 0, k + 1);
    	PlaceCrackedDeepslateBricks = determineIfCrackedDeepslateBricksExists(world, i + 11, j + 5, k + 3);
    	PlaceDeepslateTiles = determineIfDeepslateTilesExist(world, i + 0, j + 0, k + 7);
    	PlaceChiseledDeepslate = determineIfChiseledDeepslateExist(world, i + 4, j + 1, k + 6);
    	
    	PlaceSoulLantern = determineIfSoulLanternExists(world, i + 11, j + 3, k + 8);
    	PlaceBlueIce = determineIfBlueIceExists(world, i + 15, j + 1, k + 9);
    	PlaceBasalt = determineIfBasaltExists(world, i + 11, j + 1, k + 6);
    	PlaceIronTrapdoor = determineIfIronTrapdoorExists(world, i + 11, j + 4, k + 5);
    	
    	PlacePolishedDeepslateStairs = determineIfPolishedDeepslateStairsExists(world, i + 0, j + 0, k + 8);
    	PlaceDeepslateBrickSlab = determineIfDeepslateSlabExists(world, i + 5, j + 4, k + 9);
    	PlaceDeepslateBrickStairs = determineIfDeepslateBrickStairsExists(world, i + 3, j + 4, k + 12);
    	
    	world.setBlock(i + 0, j + 0, k + 0, Blocks.air, 0, 2);
		world.setBlock(i + 1, j + 0, k + 0, NovaCraftBlocks.sculk_vein, 2, 2);
		world.setBlock(i + 2, j + 0, k + 0, NovaCraftBlocks.sculk_vein, 2, 2);
		world.setBlock(i + 3, j + 0, k + 0, Blocks.air, 0, 2);
		world.setBlock(i + 4, j + 0, k + 0, Blocks.air, 0, 2);
		world.setBlock(i + 5, j + 0, k + 0, Blocks.air, 0, 2);
		world.setBlock(i + 6, j + 0, k + 0, Blocks.air, 0, 2);
		world.setBlock(i + 7, j + 0, k + 0, Blocks.air, 0, 2);
		world.setBlock(i + 8, j + 0, k + 0, Blocks.air, 0, 2);
		world.setBlock(i + 9, j + 0, k + 0, Blocks.air, 0, 2);
		world.setBlock(i + 10, j + 0, k + 0, Blocks.air, 0, 2);
		world.setBlock(i + 11, j + 0, k + 0, Blocks.air, 0, 2);
		world.setBlock(i + 12, j + 0, k + 0, Blocks.air, 0, 2);
		world.setBlock(i + 13, j + 0, k + 0, Blocks.air, 0, 2);
		world.setBlock(i + 14, j + 0, k + 0, Blocks.air, 0, 2);
		world.setBlock(i + 15, j + 0, k + 0, Blocks.air, 0, 2);
		world.setBlock(i + 16, j + 0, k + 0, Blocks.air, 0, 2);
		world.setBlock(i + 17, j + 0, k + 0, Blocks.air, 0, 2);
		world.setBlock(i + 18, j + 0, k + 0, Blocks.air, 0, 2);
		world.setBlock(i + 0, j + 0, k + 1, NovaCraftBlocks.sculk_vein, 4, 2);
		world.setBlock(i + 1, j + 0, k + 1, PlaceDeepslateBricks, 0, 2);
		world.setBlock(i + 2, j + 0, k + 1, PlaceDeepslateBricks, 0, 2);
		world.setBlock(i + 3, j + 0, k + 1, NovaCraftBlocks.sculk_block, 0, 2);
		world.setBlock(i + 4, j + 0, k + 1, Blocks.air, 0, 2);
		world.setBlock(i + 5, j + 0, k + 1, Blocks.air, 0, 2);
		world.setBlock(i + 6, j + 0, k + 1, Blocks.air, 0, 2);
		world.setBlock(i + 7, j + 0, k + 1, Blocks.air, 0, 2);
		world.setBlock(i + 8, j + 0, k + 1, Blocks.air, 0, 2);
		world.setBlock(i + 9, j + 0, k + 1, Blocks.air, 0, 2);
		world.setBlock(i + 10, j + 0, k + 1, Blocks.air, 0, 2);
		world.setBlock(i + 11, j + 0, k + 1, Blocks.air, 0, 2);
		world.setBlock(i + 12, j + 0, k + 1, Blocks.air, 0, 2);
		world.setBlock(i + 13, j + 0, k + 1, Blocks.air, 0, 2);
		world.setBlock(i + 14, j + 0, k + 1, Blocks.air, 0, 2);
		world.setBlock(i + 15, j + 0, k + 1, Blocks.air, 0, 2);
		world.setBlock(i + 16, j + 0, k + 1, Blocks.air, 0, 2);
		world.setBlock(i + 17, j + 0, k + 1, Blocks.air, 0, 2);
		world.setBlock(i + 18, j + 0, k + 1, Blocks.air, 0, 2);
		world.setBlock(i + 0, j + 0, k + 2, Blocks.air, 0, 2);
		world.setBlock(i + 1, j + 0, k + 2, NovaCraftBlocks.sculk_block, 0, 2);
		world.setBlock(i + 2, j + 0, k + 2, NovaCraftBlocks.sculk_block, 0, 2);
		world.setBlock(i + 3, j + 0, k + 2, PlaceDeepslateBricks, 0, 2);
		world.setBlock(i + 4, j + 0, k + 2, NovaCraftBlocks.sculk_block, 0, 2);
		world.setBlock(i + 5, j + 0, k + 2, NovaCraftBlocks.sculk_block, 0, 2);
		world.setBlock(i + 6, j + 0, k + 2, NovaCraftBlocks.sculk_block, 0, 2);
		world.setBlock(i + 7, j + 0, k + 2, NovaCraftBlocks.sculk_block, 0, 2);
		world.setBlock(i + 8, j + 0, k + 2, PlaceDeepslateBricks, 0, 2);
		world.setBlock(i + 9, j + 0, k + 2, PlaceDeepslateBricks, 0, 2);
		world.setBlock(i + 10, j + 0, k + 2, PlaceDeepslateBricks, 0, 2);
		world.setBlock(i + 11, j + 0, k + 2, PlaceDeepslateBricks, 0, 2);
		world.setBlock(i + 12, j + 0, k + 2, PlaceDeepslateBricks, 0, 2);
		world.setBlock(i + 13, j + 0, k + 2, PlaceDeepslateBricks, 0, 2);
		world.setBlock(i + 14, j + 0, k + 2, Blocks.air, 0, 2);
		world.setBlock(i + 15, j + 0, k + 2, PlaceDeepslateBricks, 0, 2);
		world.setBlock(i + 16, j + 0, k + 2, PlaceDeepslateBricks, 0, 2);
		world.setBlock(i + 17, j + 0, k + 2, PlaceDeepslateBricks, 0, 2);
		world.setBlock(i + 18, j + 0, k + 2, PlaceDeepslateBricks, 0, 2);
		world.setBlock(i + 0, j + 0, k + 3, Blocks.air, 0, 2);
		world.setBlock(i + 1, j + 0, k + 3, Blocks.air, 0, 2);
		world.setBlock(i + 2, j + 0, k + 3, Blocks.air, 0, 2);
		world.setBlock(i + 3, j + 0, k + 3, NovaCraftBlocks.sculk_block, 0, 2);
		world.setBlock(i + 4, j + 0, k + 3, NovaCraftBlocks.sculk_block, 0, 2);
		world.setBlock(i + 5, j + 0, k + 3, NovaCraftBlocks.sculk_block, 0, 2);
		world.setBlock(i + 6, j + 0, k + 3, NovaCraftBlocks.sculk_block, 0, 2);
		world.setBlock(i + 7, j + 0, k + 3, NovaCraftBlocks.sculk_block, 0, 2);
		world.setBlock(i + 8, j + 0, k + 3, PlaceCobbledDeepslate, 0, 2);
		world.setBlock(i + 9, j + 0, k + 3, PlaceCobbledDeepslate, 0, 2);
		world.setBlock(i + 10, j + 0, k + 3, PlaceCobbledDeepslate, 0, 2);
		world.setBlock(i + 11, j + 0, k + 3, NovaCraftBlocks.sculk_block, 0, 2);
		world.setBlock(i + 12, j + 0, k + 3, NovaCraftBlocks.sculk_block, 0, 2);
		world.setBlock(i + 13, j + 0, k + 3, NovaCraftBlocks.sculk_block, 0, 2);
		world.setBlock(i + 14, j + 0, k + 3, PlaceCobbledDeepslate, 0, 2);
		world.setBlock(i + 15, j + 0, k + 3, PlaceDeepslateBricks, 0, 2);
		world.setBlock(i + 16, j + 0, k + 3, PlaceDeepslateBricks, 0, 2);
		world.setBlock(i + 17, j + 0, k + 3, PlaceCobbledDeepslate, 0, 2);
		world.setBlock(i + 18, j + 0, k + 3, PlaceCobbledDeepslate, 0, 2);
		world.setBlock(i + 0, j + 0, k + 4, Blocks.air, 0, 2);
		world.setBlock(i + 1, j + 0, k + 4, Blocks.air, 0, 2);
		world.setBlock(i + 2, j + 0, k + 4, Blocks.air, 0, 2);
		world.setBlock(i + 3, j + 0, k + 4, NovaCraftBlocks.sculk_block, 0, 2);
		world.setBlock(i + 4, j + 0, k + 4, NovaCraftBlocks.sculk_block, 0, 2);
		world.setBlock(i + 5, j + 0, k + 4, NovaCraftBlocks.sculk_block, 0, 2);
		world.setBlock(i + 6, j + 0, k + 4, PlaceCobbledDeepslate, 0, 2);
		world.setBlock(i + 7, j + 0, k + 4, PlaceDeepslateBricks, 0, 2);
		world.setBlock(i + 8, j + 0, k + 4, PlaceDeepslateBricks, 0, 2);
		world.setBlock(i + 9, j + 0, k + 4, PlaceDeepslateBricks, 0, 2);
		world.setBlock(i + 10, j + 0, k + 4, PlaceDeepslateBricks, 0, 2);
		world.setBlock(i + 11, j + 0, k + 4, NovaCraftBlocks.sculk_block, 0, 2);
		world.setBlock(i + 12, j + 0, k + 4, NovaCraftBlocks.sculk_block, 0, 2);
		world.setBlock(i + 13, j + 0, k + 4, NovaCraftBlocks.sculk_block, 0, 2);
		world.setBlock(i + 14, j + 0, k + 4, NovaCraftBlocks.sculk_block, 0, 2);
		world.setBlock(i + 15, j + 0, k + 4, PlaceCobbledDeepslate, 0, 2);
		world.setBlock(i + 16, j + 0, k + 4, PlaceCobbledDeepslate, 0, 2);
		world.setBlock(i + 17, j + 0, k + 4, PlaceCobbledDeepslate, 0, 2);
		world.setBlock(i + 18, j + 0, k + 4, PlaceCobbledDeepslate, 0, 2);
		world.setBlock(i + 0, j + 0, k + 5, Blocks.air, 0, 2);
		world.setBlock(i + 1, j + 0, k + 5, Blocks.air, 0, 2);
		world.setBlock(i + 2, j + 0, k + 5, NovaCraftBlocks.sculk_vein, 4, 2);
		world.setBlock(i + 3, j + 0, k + 5, PlaceDeepslateBricks, 0, 2);
		world.setBlock(i + 4, j + 0, k + 5, NovaCraftBlocks.sculk_block, 0, 2);
		world.setBlock(i + 5, j + 0, k + 5, NovaCraftBlocks.sculk_block, 0, 2);
		world.setBlock(i + 6, j + 0, k + 5, PlaceCobbledDeepslate, 0, 2);
		world.setBlock(i + 7, j + 0, k + 5, PlaceDeepslateBricks, 0, 2);
		world.setBlock(i + 8, j + 0, k + 5, NovaCraftBlocks.sculk_block, 0, 2);
		world.setBlock(i + 9, j + 0, k + 5, NovaCraftBlocks.sculk_block, 0, 2);
		world.setBlock(i + 10, j + 0, k + 5, NovaCraftBlocks.sculk_block, 0, 2);
		world.setBlock(i + 11, j + 0, k + 5, PlaceDeepslateBricks, 0, 2);
		world.setBlock(i + 12, j + 0, k + 5, NovaCraftBlocks.sculk_block, 0, 2);
		world.setBlock(i + 13, j + 0, k + 5, NovaCraftBlocks.sculk_block, 0, 2);
		world.setBlock(i + 14, j + 0, k + 5, PlaceCobbledDeepslate, 0, 2);
		world.setBlock(i + 15, j + 0, k + 5, PlaceCobbledDeepslate, 0, 2);
		world.setBlock(i + 16, j + 0, k + 5, PlaceCobbledDeepslate, 0, 2);
		world.setBlock(i + 17, j + 0, k + 5, PlaceCobbledDeepslate, 0, 2);
		world.setBlock(i + 18, j + 0, k + 5, PlaceCobbledDeepslate, 0, 2);
		world.setBlock(i + 0, j + 0, k + 6, PlaceCobbledDeepslate, 0, 2);
		world.setBlock(i + 1, j + 0, k + 6, Blocks.air, 0, 2);
		world.setBlock(i + 2, j + 0, k + 6, PlaceDeepslateBricks, 0, 2);
		world.setBlock(i + 3, j + 0, k + 6, PlaceDeepslateBricks, 0, 2);
		world.setBlock(i + 4, j + 0, k + 6, PlaceCobbledDeepslate, 0, 2);
		world.setBlock(i + 5, j + 0, k + 6, Blocks.air, 0, 2);
		world.setBlock(i + 6, j + 0, k + 6, PlaceCobbledDeepslate, 0, 2);
		world.setBlock(i + 7, j + 0, k + 6, NovaCraftBlocks.sculk_block, 0, 2);
		world.setBlock(i + 8, j + 0, k + 6, NovaCraftBlocks.sculk_block, 0, 2);
		world.setBlock(i + 9, j + 0, k + 6, NovaCraftBlocks.sculk_block, 0, 2);
		world.setBlock(i + 10, j + 0, k + 6, NovaCraftBlocks.sculk_block, 0, 2);
		world.setBlock(i + 11, j + 0, k + 6, PlaceCobbledDeepslate, 0, 2);
		world.setBlock(i + 12, j + 0, k + 6, NovaCraftBlocks.sculk_block, 0, 2);
		world.setBlock(i + 13, j + 0, k + 6, NovaCraftBlocks.sculk_block, 0, 2);
		world.setBlock(i + 14, j + 0, k + 6, PlaceCobbledDeepslate, 0, 2);
		world.setBlock(i + 15, j + 0, k + 6, PlaceDeepslateBricks, 0, 2);
		world.setBlock(i + 16, j + 0, k + 6, PlaceDeepslateBricks, 0, 2);
		world.setBlock(i + 17, j + 0, k + 6, PlaceCobbledDeepslate, 0, 2);
		world.setBlock(i + 18, j + 0, k + 6, PlaceCobbledDeepslate, 0, 2);
		world.setBlock(i + 0, j + 0, k + 7, PlaceDeepslateTiles, 2, 2);
		world.setBlock(i + 1, j + 0, k + 7, PlaceDeepslateTiles, 2, 2);
		world.setBlock(i + 2, j + 0, k + 7, PlaceDeepslateTiles, 2, 2);
		world.setBlock(i + 3, j + 0, k + 7, PlaceDeepslateTiles, 2, 2);
		world.setBlock(i + 4, j + 0, k + 7, PlaceDeepslateTiles, 2, 2);
		world.setBlock(i + 5, j + 0, k + 7, Blocks.air, 0, 2);
		world.setBlock(i + 6, j + 0, k + 7, PlaceCobbledDeepslate, 0, 2);
		world.setBlock(i + 7, j + 0, k + 7, PlaceDeepslateBricks, 0, 2);
		world.setBlock(i + 8, j + 0, k + 7, NovaCraftBlocks.sculk_block, 0, 2);
		world.setBlock(i + 9, j + 0, k + 7, NovaCraftBlocks.sculk_block, 0, 2);
		world.setBlock(i + 10, j + 0, k + 7, NovaCraftBlocks.sculk_block, 0, 2);
		world.setBlock(i + 11, j + 0, k + 7, NovaCraftBlocks.sculk_block, 0, 2);
		world.setBlock(i + 12, j + 0, k + 7, NovaCraftBlocks.sculk_block, 0, 2);
		world.setBlock(i + 13, j + 0, k + 7, NovaCraftBlocks.sculk_block, 0, 2);
		world.setBlock(i + 14, j + 0, k + 7, NovaCraftBlocks.sculk_block, 0, 2);
		world.setBlock(i + 15, j + 0, k + 7, NovaCraftBlocks.sculk_block, 0, 2);
		world.setBlock(i + 16, j + 0, k + 7, PlaceDeepslateBricks, 0, 2);
		world.setBlock(i + 17, j + 0, k + 7, PlaceDeepslateBricks, 0, 2);
		world.setBlock(i + 18, j + 0, k + 7, PlaceCobbledDeepslate, 0, 2);
		world.setBlock(i + 0, j + 0, k + 8, PlacePolishedDeepslateStairs, 0, 2);
		world.setBlock(i + 1, j + 0, k + 8, PlaceDeepslateTiles, 2, 2);
		world.setBlock(i + 2, j + 0, k + 8, PlaceDeepslateTiles, 2, 2);
		world.setBlock(i + 3, j + 0, k + 8, PlaceDeepslateTiles, 2, 2);
		world.setBlock(i + 4, j + 0, k + 8, PlaceDeepslateTiles, 2, 2);
		world.setBlock(i + 5, j + 0, k + 8, Blocks.air, 0, 2);
		world.setBlock(i + 6, j + 0, k + 8, PlaceCobbledDeepslate, 0, 2);
		world.setBlock(i + 7, j + 0, k + 8, PlaceDeepslateBricks, 0, 2);
		world.setBlock(i + 8, j + 0, k + 8, PlaceDeepslateBricks, 0, 2);
		world.setBlock(i + 9, j + 0, k + 8, PlaceDeepslateBricks, 0, 2);
		world.setBlock(i + 10, j + 0, k + 8, NovaCraftBlocks.sculk_block, 0, 2);
		world.setBlock(i + 11, j + 0, k + 8, NovaCraftBlocks.sculk_block, 0, 2);
		world.setBlock(i + 12, j + 0, k + 8, NovaCraftBlocks.sculk_block, 0, 2);
		world.setBlock(i + 13, j + 0, k + 8, NovaCraftBlocks.sculk_block, 0, 2);
		world.setBlock(i + 14, j + 0, k + 8, NovaCraftBlocks.sculk_block, 0, 2);
		world.setBlock(i + 15, j + 0, k + 8, NovaCraftBlocks.sculk_block, 0, 2);
		world.setBlock(i + 16, j + 0, k + 8, Blocks.air, 0, 2);
		world.setBlock(i + 17, j + 0, k + 8, PlaceCobbledDeepslate, 0, 2);
		world.setBlock(i + 18, j + 0, k + 8, Blocks.air, 0, 2);
		world.setBlock(i + 0, j + 0, k + 9, PlacePolishedDeepslateStairs, 0, 2);
		world.setBlock(i + 1, j + 0, k + 9, PlaceDeepslateTiles, 2, 2);
		world.setBlock(i + 2, j + 0, k + 9, PlaceDeepslateTiles, 2, 2);
		world.setBlock(i + 3, j + 0, k + 9, PlaceDeepslateTiles, 2, 2);
		world.setBlock(i + 4, j + 0, k + 9, PlaceDeepslateTiles, 2, 2);
		world.setBlock(i + 5, j + 0, k + 9, Blocks.air, 0, 2);
		world.setBlock(i + 6, j + 0, k + 9, PlaceCobbledDeepslate, 0, 2);
		world.setBlock(i + 7, j + 0, k + 9, PlaceDeepslateBricks, 0, 2);
		world.setBlock(i + 8, j + 0, k + 9, PlaceDeepslateBricks, 0, 2);
		world.setBlock(i + 9, j + 0, k + 9, PlaceDeepslateBricks, 0, 2);
		world.setBlock(i + 10, j + 0, k + 9, PlaceDeepslateBricks, 0, 2);
		world.setBlock(i + 11, j + 0, k + 9, PlaceDeepslateBricks, 0, 2);
		world.setBlock(i + 12, j + 0, k + 9, PlaceDeepslateBricks, 0, 2);
		world.setBlock(i + 13, j + 0, k + 9, PlaceDeepslateBricks, 0, 2);
		world.setBlock(i + 14, j + 0, k + 9, PlaceDeepslateBricks, 0, 2);
		world.setBlock(i + 15, j + 0, k + 9, PlaceDeepslateBricks, 0, 2);
		world.setBlock(i + 16, j + 0, k + 9, PlaceDeepslateBricks, 0, 2);
		world.setBlock(i + 17, j + 0, k + 9, PlaceDeepslateBricks, 0, 2);
		world.setBlock(i + 18, j + 0, k + 9, PlaceCobbledDeepslate, 0, 2);
		world.setBlock(i + 0, j + 0, k + 10, PlaceDeepslateTiles, 2, 2);
		world.setBlock(i + 1, j + 0, k + 10, PlaceDeepslateTiles, 2, 2);
		world.setBlock(i + 2, j + 0, k + 10, PlaceDeepslateTiles, 2, 2);
		world.setBlock(i + 3, j + 0, k + 10, PlaceDeepslateTiles, 2, 2);
		world.setBlock(i + 4, j + 0, k + 10, PlaceDeepslateTiles, 2, 2);
		world.setBlock(i + 5, j + 0, k + 10, Blocks.air, 0, 2);
		world.setBlock(i + 6, j + 0, k + 10, PlaceCobbledDeepslate, 0, 2);
		world.setBlock(i + 7, j + 0, k + 10, PlaceCobbledDeepslate, 0, 2);
		world.setBlock(i + 8, j + 0, k + 10, PlaceDeepslateBricks, 0, 2);
		world.setBlock(i + 9, j + 0, k + 10, PlaceDeepslateBricks, 0, 2);
		world.setBlock(i + 10, j + 0, k + 10, PlaceCobbledDeepslate, 0, 2);
		world.setBlock(i + 11, j + 0, k + 10, PlaceDeepslateBricks, 0, 2);
		world.setBlock(i + 12, j + 0, k + 10, PlaceDeepslateBricks, 0, 2);
		world.setBlock(i + 13, j + 0, k + 10, PlaceDeepslateBricks, 0, 2);
		world.setBlock(i + 14, j + 0, k + 10, PlaceCobbledDeepslate, 0, 2);
		world.setBlock(i + 15, j + 0, k + 10, PlaceCobbledDeepslate, 0, 2);
		world.setBlock(i + 16, j + 0, k + 10, PlaceDeepslateBricks, 0, 2);
		world.setBlock(i + 17, j + 0, k + 10, PlaceCobbledDeepslate, 0, 2);
		world.setBlock(i + 18, j + 0, k + 10, PlaceCobbledDeepslate, 0, 2);
		world.setBlock(i + 0, j + 0, k + 11, PlaceCobbledDeepslate, 0, 2);
		world.setBlock(i + 1, j + 0, k + 11, Blocks.air, 0, 2);
		world.setBlock(i + 2, j + 0, k + 11, Blocks.air, 0, 2);
		world.setBlock(i + 3, j + 0, k + 11, PlaceDeepslateBricks, 0, 2);
		world.setBlock(i + 4, j + 0, k + 11, PlaceCobbledDeepslate, 0, 2);
		world.setBlock(i + 5, j + 0, k + 11, Blocks.air, 0, 2);
		world.setBlock(i + 6, j + 0, k + 11, PlaceCobbledDeepslate, 0, 2);
		world.setBlock(i + 7, j + 0, k + 11, PlaceCobbledDeepslate, 0, 2);
		world.setBlock(i + 8, j + 0, k + 11, PlaceCobbledDeepslate, 0, 2);
		world.setBlock(i + 9, j + 0, k + 11, PlaceCobbledDeepslate, 0, 2);
		world.setBlock(i + 10, j + 0, k + 11, PlaceDeepslateBricks, 0, 2);
		world.setBlock(i + 11, j + 0, k + 11, PlaceDeepslateBricks, 0, 2);
		world.setBlock(i + 12, j + 0, k + 11, PlaceDeepslateBricks, 0, 2);
		world.setBlock(i + 13, j + 0, k + 11, PlaceDeepslateBricks, 0, 2);
		world.setBlock(i + 14, j + 0, k + 11, PlaceDeepslateBricks, 0, 2);
		world.setBlock(i + 15, j + 0, k + 11, PlaceDeepslateBricks, 0, 2);
		world.setBlock(i + 16, j + 0, k + 11, PlaceDeepslateBricks, 0, 2);
		world.setBlock(i + 17, j + 0, k + 11, PlaceCobbledDeepslate, 0, 2);
		world.setBlock(i + 18, j + 0, k + 11, PlaceCobbledDeepslate, 0, 2);
		world.setBlock(i + 0, j + 0, k + 12, Blocks.air, 0, 2);
		world.setBlock(i + 1, j + 0, k + 12, Blocks.air, 0, 2);
		world.setBlock(i + 2, j + 0, k + 12, Blocks.air, 0, 2);
		world.setBlock(i + 3, j + 0, k + 12, PlaceDeepslateBricks, 0, 2);
		world.setBlock(i + 4, j + 0, k + 12, PlaceCobbledDeepslate, 0, 2);
		world.setBlock(i + 5, j + 0, k + 12, PlaceCobbledDeepslate, 0, 2);
		world.setBlock(i + 6, j + 0, k + 12, PlaceCobbledDeepslate, 0, 2);
		world.setBlock(i + 7, j + 0, k + 12, PlaceCobbledDeepslate, 0, 2);
		world.setBlock(i + 8, j + 0, k + 12, PlaceCobbledDeepslate, 0, 2);
		world.setBlock(i + 9, j + 0, k + 12, PlaceCobbledDeepslate, 0, 2);
		world.setBlock(i + 10, j + 0, k + 12, PlaceDeepslateBricks, 0, 2);
		world.setBlock(i + 11, j + 0, k + 12, PlaceDeepslateBricks, 0, 2);
		world.setBlock(i + 12, j + 0, k + 12, PlaceDeepslateBricks, 0, 2);
		world.setBlock(i + 13, j + 0, k + 12, PlaceDeepslateBricks, 0, 2);
		world.setBlock(i + 14, j + 0, k + 12, PlaceDeepslateBricks, 0, 2);
		world.setBlock(i + 15, j + 0, k + 12, PlaceDeepslateBricks, 0, 2);
		world.setBlock(i + 16, j + 0, k + 12, PlaceDeepslateBricks, 0, 2);
		world.setBlock(i + 17, j + 0, k + 12, PlaceCobbledDeepslate, 0, 2);
		world.setBlock(i + 18, j + 0, k + 12, PlaceCobbledDeepslate, 0, 2);
		world.setBlock(i + 0, j + 0, k + 13, Blocks.air, 0, 2);
		world.setBlock(i + 1, j + 0, k + 13, Blocks.air, 0, 2);
		world.setBlock(i + 2, j + 0, k + 13, Blocks.air, 0, 2);
		world.setBlock(i + 3, j + 0, k + 13, PlaceDeepslateBricks, 0, 2);
		world.setBlock(i + 4, j + 0, k + 13, PlaceCobbledDeepslate, 0, 2);
		world.setBlock(i + 5, j + 0, k + 13, PlaceCobbledDeepslate, 0, 2);
		world.setBlock(i + 6, j + 0, k + 13, PlaceCobbledDeepslate, 0, 2);
		world.setBlock(i + 7, j + 0, k + 13, PlaceCobbledDeepslate, 0, 2);
		world.setBlock(i + 8, j + 0, k + 13, PlaceCobbledDeepslate, 0, 2);
		world.setBlock(i + 9, j + 0, k + 13, PlaceCobbledDeepslate, 0, 2);
		world.setBlock(i + 10, j + 0, k + 13, PlaceCobbledDeepslate, 0, 2);
		world.setBlock(i + 11, j + 0, k + 13, PlaceCobbledDeepslate, 0, 2);
		world.setBlock(i + 12, j + 0, k + 13, PlaceCobbledDeepslate, 0, 2);
		world.setBlock(i + 13, j + 0, k + 13, PlaceCobbledDeepslate, 0, 2);
		world.setBlock(i + 14, j + 0, k + 13, PlaceCobbledDeepslate, 0, 2);
		world.setBlock(i + 15, j + 0, k + 13, PlaceCobbledDeepslate, 0, 2);
		world.setBlock(i + 16, j + 0, k + 13, PlaceCobbledDeepslate, 0, 2);
		world.setBlock(i + 17, j + 0, k + 13, PlaceCobbledDeepslate, 0, 2);
		world.setBlock(i + 18, j + 0, k + 13, PlaceCobbledDeepslate, 0, 2);
		world.setBlock(i + 0, j + 0, k + 14, Blocks.air, 0, 2);
		world.setBlock(i + 1, j + 0, k + 14, PlaceDeepslateBricks, 0, 2);
		world.setBlock(i + 2, j + 0, k + 14, PlaceDeepslateBricks, 0, 2);
		world.setBlock(i + 3, j + 0, k + 14, PlaceDeepslateBricks, 0, 2);
		world.setBlock(i + 4, j + 0, k + 14, PlaceDeepslateBricks, 0, 2);
		world.setBlock(i + 5, j + 0, k + 14, PlaceDeepslateBricks, 0, 2);
		world.setBlock(i + 6, j + 0, k + 14, PlaceDeepslateBricks, 0, 2);
		world.setBlock(i + 7, j + 0, k + 14, PlaceDeepslateBricks, 0, 2);
		world.setBlock(i + 8, j + 0, k + 14, PlaceDeepslateBricks, 0, 2);
		world.setBlock(i + 9, j + 0, k + 14, PlaceDeepslateBricks, 0, 2);
		world.setBlock(i + 10, j + 0, k + 14, PlaceDeepslateBricks, 0, 2);
		world.setBlock(i + 11, j + 0, k + 14, PlaceDeepslateBricks, 0, 2);
		world.setBlock(i + 12, j + 0, k + 14, PlaceDeepslateBricks, 0, 2);
		world.setBlock(i + 13, j + 0, k + 14, PlaceDeepslateBricks, 0, 2);
		world.setBlock(i + 14, j + 0, k + 14, PlaceDeepslateBricks, 0, 2);
		world.setBlock(i + 15, j + 0, k + 14, PlaceDeepslateBricks, 0, 2);
		world.setBlock(i + 16, j + 0, k + 14, PlaceDeepslateBricks, 0, 2);
		world.setBlock(i + 17, j + 0, k + 14, PlaceDeepslateBricks, 0, 2);
		world.setBlock(i + 18, j + 0, k + 14, PlaceDeepslateBricks, 0, 2);
		world.setBlock(i + 0, j + 0, k + 15, Blocks.air, 0, 2);
		world.setBlock(i + 1, j + 0, k + 15, PlaceDeepslateBricks, 0, 2);
		world.setBlock(i + 2, j + 0, k + 15, PlaceDeepslateBricks, 0, 2);
		world.setBlock(i + 3, j + 0, k + 15, PlaceDeepslateBricks, 0, 2);
		world.setBlock(i + 4, j + 0, k + 15, Blocks.air, 0, 2);
		world.setBlock(i + 5, j + 0, k + 15, Blocks.air, 0, 2);
		world.setBlock(i + 6, j + 0, k + 15, Blocks.air, 0, 2);
		world.setBlock(i + 7, j + 0, k + 15, Blocks.air, 0, 2);
		world.setBlock(i + 8, j + 0, k + 15, Blocks.air, 0, 2);
		world.setBlock(i + 9, j + 0, k + 15, Blocks.air, 0, 2);
		world.setBlock(i + 10, j + 0, k + 15, Blocks.air, 0, 2);
		world.setBlock(i + 11, j + 0, k + 15, Blocks.air, 0, 2);
		world.setBlock(i + 12, j + 0, k + 15, Blocks.air, 0, 2);
		world.setBlock(i + 13, j + 0, k + 15, Blocks.air, 0, 2);
		world.setBlock(i + 14, j + 0, k + 15, Blocks.air, 0, 2);
		world.setBlock(i + 15, j + 0, k + 15, Blocks.air, 0, 2);
		world.setBlock(i + 16, j + 0, k + 15, Blocks.air, 0, 2);
		world.setBlock(i + 17, j + 0, k + 15, Blocks.air, 0, 2);
		world.setBlock(i + 18, j + 0, k + 15, Blocks.air, 0, 2);
		world.setBlock(i + 0, j + 1, k + 0, Blocks.air, 0, 2);
		world.setBlock(i + 1, j + 1, k + 0, Blocks.air, 0, 2);
		world.setBlock(i + 2, j + 1, k + 0, NovaCraftBlocks.sculk_vein, 2, 2);
		world.setBlock(i + 3, j + 1, k + 0, Blocks.air, 0, 2);
		world.setBlock(i + 4, j + 1, k + 0, Blocks.air, 0, 2);
		world.setBlock(i + 5, j + 1, k + 0, Blocks.air, 0, 2);
		world.setBlock(i + 6, j + 1, k + 0, Blocks.air, 0, 2);
		world.setBlock(i + 7, j + 1, k + 0, Blocks.air, 0, 2);
		world.setBlock(i + 8, j + 1, k + 0, Blocks.air, 0, 2);
		world.setBlock(i + 9, j + 1, k + 0, Blocks.air, 0, 2);
		world.setBlock(i + 10, j + 1, k + 0, Blocks.air, 0, 2);
		world.setBlock(i + 11, j + 1, k + 0, Blocks.air, 0, 2);
		world.setBlock(i + 12, j + 1, k + 0, Blocks.air, 0, 2);
		world.setBlock(i + 13, j + 1, k + 0, Blocks.air, 0, 2);
		world.setBlock(i + 14, j + 1, k + 0, Blocks.air, 0, 2);
		world.setBlock(i + 15, j + 1, k + 0, Blocks.air, 0, 2);
		world.setBlock(i + 16, j + 1, k + 0, Blocks.air, 0, 2);
		world.setBlock(i + 17, j + 1, k + 0, Blocks.air, 0, 2);
		world.setBlock(i + 18, j + 1, k + 0, Blocks.air, 0, 2);
		world.setBlock(i + 0, j + 1, k + 1, Blocks.air, 0, 2);
		world.setBlock(i + 1, j + 1, k + 1, NovaCraftBlocks.sculk_block, 0, 2);
		world.setBlock(i + 2, j + 1, k + 1, PlaceDeepslateBricks, 0, 2);
		world.setBlock(i + 3, j + 1, k + 1, NovaCraftBlocks.sculk_block, 0, 2);
		world.setBlock(i + 4, j + 1, k + 1, Blocks.air, 0, 2);
		world.setBlock(i + 5, j + 1, k + 1, Blocks.air, 0, 2);
		world.setBlock(i + 6, j + 1, k + 1, Blocks.air, 0, 2);
		world.setBlock(i + 7, j + 1, k + 1, Blocks.air, 0, 2);
		world.setBlock(i + 8, j + 1, k + 1, Blocks.air, 0, 2);
		world.setBlock(i + 9, j + 1, k + 1, Blocks.air, 0, 2);
		world.setBlock(i + 10, j + 1, k + 1, Blocks.air, 0, 2);
		world.setBlock(i + 11, j + 1, k + 1, Blocks.air, 0, 2);
		world.setBlock(i + 12, j + 1, k + 1, Blocks.air, 0, 2);
		world.setBlock(i + 13, j + 1, k + 1, Blocks.air, 0, 2);
		world.setBlock(i + 14, j + 1, k + 1, Blocks.air, 0, 2);
		world.setBlock(i + 15, j + 1, k + 1, Blocks.air, 0, 2);
		world.setBlock(i + 16, j + 1, k + 1, Blocks.air, 0, 2);
		world.setBlock(i + 17, j + 1, k + 1, Blocks.air, 0, 2);
		world.setBlock(i + 18, j + 1, k + 1, Blocks.air, 0, 2);
		world.setBlock(i + 0, j + 1, k + 2, Blocks.air, 0, 2);
		world.setBlock(i + 1, j + 1, k + 2, NovaCraftBlocks.sculk_block, 0, 2);
		world.setBlock(i + 2, j + 1, k + 2, NovaCraftBlocks.sculk_block, 0, 2);
		world.setBlock(i + 3, j + 1, k + 2, PlaceDeepslateBricks, 0, 2);
		world.setBlock(i + 4, j + 1, k + 2, NovaCraftBlocks.sculk_block, 0, 2);
		world.setBlock(i + 5, j + 1, k + 2, NovaCraftBlocks.sculk_block, 0, 2);
		world.setBlock(i + 6, j + 1, k + 2, NovaCraftBlocks.sculk_block, 0, 2);
		world.setBlock(i + 7, j + 1, k + 2, NovaCraftBlocks.sculk_block, 0, 2);
		world.setBlock(i + 8, j + 1, k + 2, PlaceCobbledDeepslate, 0, 2);
		world.setBlock(i + 9, j + 1, k + 2, PlaceCobbledDeepslate, 0, 2);
		world.setBlock(i + 10, j + 1, k + 2, PlaceCobbledDeepslate, 0, 2);
		world.setBlock(i + 11, j + 1, k + 2, PlaceCobbledDeepslate, 0, 2);
		world.setBlock(i + 12, j + 1, k + 2, PlaceCobbledDeepslate, 0, 2);
		world.setBlock(i + 13, j + 1, k + 2, PlaceCobbledDeepslate, 0, 2);
		world.setBlock(i + 14, j + 1, k + 2, Blocks.air, 0, 2);
		world.setBlock(i + 15, j + 1, k + 2, PlaceCobbledDeepslate, 0, 2);
		world.setBlock(i + 16, j + 1, k + 2, PlaceCobbledDeepslate, 0, 2);
		world.setBlock(i + 17, j + 1, k + 2, PlaceCobbledDeepslate, 0, 2);
		world.setBlock(i + 18, j + 1, k + 2, Blocks.air, 0, 2);
		world.setBlock(i + 0, j + 1, k + 3, Blocks.air, 0, 2);
		world.setBlock(i + 1, j + 1, k + 3, Blocks.air, 0, 2);
		world.setBlock(i + 2, j + 1, k + 3, Blocks.air, 0, 2);
		world.setBlock(i + 3, j + 1, k + 3, NovaCraftBlocks.sculk_block, 0, 2);
		world.setBlock(i + 4, j + 1, k + 3, PlaceCobbledDeepslate, 0, 2);
		world.setBlock(i + 5, j + 1, k + 3, PlaceCobbledDeepslate, 0, 2);
		world.setBlock(i + 6, j + 1, k + 3, PlaceCobbledDeepslate, 0, 2);
		world.setBlock(i + 7, j + 1, k + 3, PlaceCobbledDeepslate, 0, 2);
		world.setBlock(i + 8, j + 1, k + 3, PlaceCobbledDeepslate, 0, 2);
		world.setBlock(i + 9, j + 1, k + 3, PlaceCobbledDeepslate, 0, 2);
		world.setBlock(i + 10, j + 1, k + 3, PlaceCobbledDeepslate, 0, 2);
		world.setBlock(i + 11, j + 1, k + 3, NovaCraftBlocks.sculk_block, 0, 2);
		world.setBlock(i + 12, j + 1, k + 3, PlaceCobbledDeepslate, 0, 2);
		world.setBlock(i + 13, j + 1, k + 3, PlaceCobbledDeepslate, 0, 2);
		world.setBlock(i + 14, j + 1, k + 3, PlaceCobbledDeepslate, 0, 2);
		world.setBlock(i + 15, j + 1, k + 3, Blocks.packed_ice, 0, 2);
		world.setBlock(i + 16, j + 1, k + 3, Blocks.packed_ice, 0, 2);
		world.setBlock(i + 17, j + 1, k + 3, PlaceCobbledDeepslate, 0, 2);
		world.setBlock(i + 18, j + 1, k + 3, PlaceCobbledDeepslate, 0, 2);
		world.setBlock(i + 0, j + 1, k + 4, Blocks.air, 0, 2);
		world.setBlock(i + 1, j + 1, k + 4, Blocks.air, 0, 2);
		world.setBlock(i + 2, j + 1, k + 4, Blocks.air, 0, 2);
		world.setBlock(i + 3, j + 1, k + 4, NovaCraftBlocks.sculk_block, 0, 2);
		world.setBlock(i + 4, j + 1, k + 4, PlaceCobbledDeepslate, 0, 2);
		world.setBlock(i + 5, j + 1, k + 4, PlaceCobbledDeepslate, 0, 2);
		world.setBlock(i + 6, j + 1, k + 4, PlaceCobbledDeepslate, 0, 2);
		world.setBlock(i + 7, j + 1, k + 4, Blocks.packed_ice, 0, 2);
		world.setBlock(i + 8, j + 1, k + 4, Blocks.packed_ice, 0, 2);
		world.setBlock(i + 9, j + 1, k + 4, Blocks.packed_ice, 0, 2);
		world.setBlock(i + 10, j + 1, k + 4, Blocks.packed_ice, 0, 2);
		world.setBlock(i + 11, j + 1, k + 4, NovaCraftBlocks.sculk_vein, 4, 2);
		world.setBlock(i + 12, j + 1, k + 4, Blocks.packed_ice, 0, 2);
		world.setBlock(i + 13, j + 1, k + 4, Blocks.packed_ice, 0, 2);
		world.setBlock(i + 14, j + 1, k + 4, Blocks.ice, 0, 2);
		world.setBlock(i + 15, j + 1, k + 4, Blocks.packed_ice, 0, 2);
		world.setBlock(i + 16, j + 1, k + 4, Blocks.packed_ice, 0, 2);
		world.setBlock(i + 17, j + 1, k + 4, Blocks.packed_ice, 0, 2);
		world.setBlock(i + 18, j + 1, k + 4, PlaceCobbledDeepslate, 0, 2);
		world.setBlock(i + 0, j + 1, k + 5, Blocks.air, 0, 2);
		world.setBlock(i + 1, j + 1, k + 5, Blocks.air, 0, 2);
		world.setBlock(i + 2, j + 1, k + 5, NovaCraftBlocks.sculk_vein, 4, 2);
		world.setBlock(i + 3, j + 1, k + 5, PlaceCobbledDeepslate, 0, 2);
		world.setBlock(i + 4, j + 1, k + 5, PlaceCobbledDeepslate, 0, 2);
		world.setBlock(i + 5, j + 1, k + 5, PlaceCobbledDeepslate, 0, 2);
		world.setBlock(i + 6, j + 1, k + 5, PlaceCobbledDeepslate, 0, 2);
		world.setBlock(i + 7, j + 1, k + 5, Blocks.packed_ice, 0, 2);
		world.setBlock(i + 8, j + 1, k + 5, Blocks.packed_ice, 0, 2);
		world.setBlock(i + 9, j + 1, k + 5, NovaCraftBlocks.sculk_vein, 3, 2);
		world.setBlock(i + 10, j + 1, k + 5, NovaCraftBlocks.sculk_vein, 3, 2);
		world.setBlock(i + 11, j + 1, k + 5, Blocks.ladder, 2, 2);
		world.setBlock(i + 12, j + 1, k + 5, Blocks.packed_ice, 0, 2);
		world.setBlock(i + 13, j + 1, k + 5, Blocks.packed_ice, 0, 2);
		world.setBlock(i + 14, j + 1, k + 5, Blocks.packed_ice, 0, 2);
		world.setBlock(i + 15, j + 1, k + 5, Blocks.packed_ice, 0, 2);
		world.setBlock(i + 16, j + 1, k + 5, Blocks.packed_ice, 0, 2);
		world.setBlock(i + 17, j + 1, k + 5, Blocks.air, 0, 2);
		world.setBlock(i + 18, j + 1, k + 5, PlaceCobbledDeepslate, 0, 2);
		world.setBlock(i + 0, j + 1, k + 6, PlaceCobbledDeepslate, 0, 2);
		world.setBlock(i + 1, j + 1, k + 6, Blocks.air, 0, 2);
		world.setBlock(i + 2, j + 1, k + 6, PlaceDeepslateBricks, 0, 2);
		world.setBlock(i + 3, j + 1, k + 6, PlaceDeepslateBricks, 0, 2);
		world.setBlock(i + 4, j + 1, k + 6, PlaceChiseledDeepslate, 4, 2);
		world.setBlock(i + 5, j + 1, k + 6, PlaceCobbledDeepslate, 0, 2);
		world.setBlock(i + 6, j + 1, k + 6, Blocks.packed_ice, 0, 2);
		world.setBlock(i + 7, j + 1, k + 6, NovaCraftBlocks.sculk_vein, 2, 2);
		world.setBlock(i + 8, j + 1, k + 6, NovaCraftBlocks.sculk_vein, 3, 2);
		world.setBlock(i + 9, j + 1, k + 6, Blocks.air, 0, 2);
		world.setBlock(i + 10, j + 1, k + 6, NovaCraftBlocks.sculk_vein, 4, 2);
		world.setBlock(i + 11, j + 1, k + 6, PlaceBasalt, 1, 2);
		world.setBlock(i + 12, j + 1, k + 6, NovaCraftBlocks.sculk_vein, 3, 2);
		world.setBlock(i + 13, j + 1, k + 6, Blocks.packed_ice, 0, 2);
		world.setBlock(i + 14, j + 1, k + 6, Blocks.packed_ice, 0, 2);
		world.setBlock(i + 15, j + 1, k + 6, Blocks.packed_ice, 0, 2);
		world.setBlock(i + 16, j + 1, k + 6, Blocks.packed_ice, 0, 2);
		world.setBlock(i + 17, j + 1, k + 6, PlaceCobbledDeepslate, 0, 2);
		world.setBlock(i + 18, j + 1, k + 6, PlaceCobbledDeepslate, 0, 2);
		world.setBlock(i + 0, j + 1, k + 7, PlaceDeepslateTiles, 2, 2);
		world.setBlock(i + 1, j + 1, k + 7, PlaceDeepslateTiles, 2, 2);
		world.setBlock(i + 2, j + 1, k + 7, PlaceDeepslateTiles, 2, 2);
		world.setBlock(i + 3, j + 1, k + 7, PlaceDeepslateTiles, 2, 2);
		world.setBlock(i + 4, j + 1, k + 7, Blocks.air, 0, 2);
		world.setBlock(i + 5, j + 1, k + 7, PlaceDeepslateTiles, 2, 2);
		world.setBlock(i + 6, j + 1, k + 7, Blocks.packed_ice, 0, 2);
		world.setBlock(i + 7, j + 1, k + 7, Blocks.packed_ice, 0, 2);
		world.setBlock(i + 8, j + 1, k + 7, Blocks.air, 0, 2);
		world.setBlock(i + 9, j + 1, k + 7, Blocks.air, 0, 2);
		world.setBlock(i + 10, j + 1, k + 7, Blocks.air, 0, 2);
		world.setBlock(i + 11, j + 1, k + 7, NovaCraftBlocks.sculk_vein, 3, 2);
		world.setBlock(i + 12, j + 1, k + 7, Blocks.air, 0, 2);
		world.setBlock(i + 13, j + 1, k + 7, NovaCraftBlocks.sculk_vein, 3, 2);
		world.setBlock(i + 14, j + 1, k + 7, NovaCraftBlocks.sculk_vein, 3, 2);
		world.setBlock(i + 15, j + 1, k + 7, Blocks.packed_ice, 0, 2);
		world.setBlock(i + 16, j + 1, k + 7, Blocks.ice, 0, 2);
		world.setBlock(i + 17, j + 1, k + 7, Blocks.packed_ice, 0, 2);
		world.setBlock(i + 18, j + 1, k + 7, PlaceCobbledDeepslate, 0, 2);
		world.setBlock(i + 0, j + 1, k + 8, Blocks.air, 0, 2);
		world.setBlock(i + 1, j + 1, k + 8, PlacePolishedDeepslateStairs, 0, 2);
		world.setBlock(i + 2, j + 1, k + 8, PlaceDeepslateTiles, 2, 2);
		world.setBlock(i + 3, j + 1, k + 8, PlaceDeepslateTiles, 2, 2);
		world.setBlock(i + 4, j + 1, k + 8, PlaceDeepslateTiles, 2, 2);
		world.setBlock(i + 5, j + 1, k + 8, PlaceDeepslateTiles, 2, 2);
		world.setBlock(i + 6, j + 1, k + 8, Blocks.packed_ice, 0, 2);
		world.setBlock(i + 7, j + 1, k + 8, Blocks.packed_ice, 0, 2);
		world.setBlock(i + 8, j + 1, k + 8, NovaCraftBlocks.sculk_vein, 1, 2);
		world.setBlock(i + 9, j + 1, k + 8, NovaCraftBlocks.sculk_vein, 1, 2);
		world.setBlock(i + 10, j + 1, k + 8, Blocks.air, 0, 2);
		world.setBlock(i + 11, j + 1, k + 8, Blocks.air, 0, 2);
		world.setBlock(i + 13, j + 1, k + 8, NovaCraftBlocks.sculk_block, 0, 2);
		world.setBlock(i + 14, j + 1, k + 8, NovaCraftBlocks.sculk_block, 0, 2);
		world.setBlock(i + 15, j + 1, k + 8, NovaCraftBlocks.sculk_vein, 3, 2);
		world.setBlock(i + 16, j + 1, k + 8, NovaCraftBlocks.sculk_block, 0, 2);
		world.setBlock(i + 17, j + 1, k + 8, PlaceCobbledDeepslate, 0, 2);
		world.setBlock(i + 18, j + 1, k + 8, PlaceCobbledDeepslate, 0, 2);
		world.setBlock(i + 0, j + 1, k + 9, Blocks.air, 0, 2);
		world.setBlock(i + 1, j + 1, k + 9, PlacePolishedDeepslateStairs, 0, 2);
		world.setBlock(i + 2, j + 1, k + 9, PlaceDeepslateTiles, 2, 2);
		world.setBlock(i + 3, j + 1, k + 9, PlaceDeepslateTiles, 2, 2);
		world.setBlock(i + 4, j + 1, k + 9, PlaceDeepslateTiles, 2, 2);
		world.setBlock(i + 5, j + 1, k + 9, Blocks.air, 0, 2);
		world.setBlock(i + 6, j + 1, k + 9, Blocks.packed_ice, 0, 2);
		world.setBlock(i + 7, j + 1, k + 9, Blocks.packed_ice, 0, 2);
		world.setBlock(i + 8, j + 1, k + 9, Blocks.air, 0, 2);
		world.setBlock(i + 9, j + 1, k + 9, Blocks.air, 0, 2);
		world.setBlock(i + 10, j + 1, k + 9, Blocks.air, 0, 2);
		world.setBlock(i + 11, j + 1, k + 9, Blocks.air, 0, 2);
		world.setBlock(i + 12, j + 1, k + 9, Blocks.air, 0, 2);
		world.setBlock(i + 13, j + 1, k + 9, Blocks.air, 0, 2);
		world.setBlock(i + 14, j + 1, k + 9, Blocks.air, 0, 2);
		world.setBlock(i + 15, j + 1, k + 9, PlaceBlueIce, 0, 2);
		world.setBlock(i + 16, j + 1, k + 9, PlaceBlueIce, 0, 2);
		world.setBlock(i + 17, j + 1, k + 9, PlaceBlueIce, 0, 2);
		world.setBlock(i + 18, j + 1, k + 9, PlaceCobbledDeepslate, 0, 2);
		world.setBlock(i + 0, j + 1, k + 10, Blocks.air, 0, 2);
		world.setBlock(i + 1, j + 1, k + 10, PlaceDeepslateTiles, 2, 2);
		world.setBlock(i + 2, j + 1, k + 10, PlaceDeepslateTiles, 2, 2);
		world.setBlock(i + 3, j + 1, k + 10, PlaceDeepslateTiles, 2, 2);
		world.setBlock(i + 4, j + 1, k + 10, PlaceDeepslateTiles, 2, 2);
		world.setBlock(i + 5, j + 1, k + 10, PlaceDeepslateTiles, 2, 2);
		world.setBlock(i + 6, j + 1, k + 10, Blocks.packed_ice, 0, 2);
		world.setBlock(i + 7, j + 1, k + 10, PlaceBlueIce, 0, 2);
		world.setBlock(i + 8, j + 1, k + 10, Blocks.air, 0, 2);
		world.setBlock(i + 9, j + 1, k + 10, Blocks.air, 0, 2);
		world.setBlock(i + 10, j + 1, k + 10, Blocks.air, 0, 2);
		world.setBlock(i + 11, j + 1, k + 10, Blocks.air, 0, 2);
		world.setBlock(i + 12, j + 1, k + 10, Blocks.air, 0, 2);
		world.setBlock(i + 13, j + 1, k + 10, Blocks.air, 0, 2);
		world.setBlock(i + 14, j + 1, k + 10, PlaceBlueIce, 0, 2);
		world.setBlock(i + 15, j + 1, k + 10, PlaceBlueIce, 0, 2);
		world.setBlock(i + 16, j + 1, k + 10, PlaceBlueIce, 0, 2);
		world.setBlock(i + 17, j + 1, k + 10, PlaceCobbledDeepslate, 0, 2);
		world.setBlock(i + 18, j + 1, k + 10, PlaceCobbledDeepslate, 0, 2);
		world.setBlock(i + 0, j + 1, k + 11, PlaceCobbledDeepslate, 0, 2);
		world.setBlock(i + 1, j + 1, k + 11, Blocks.air, 0, 2);
		world.setBlock(i + 2, j + 1, k + 11, Blocks.air, 0, 2);
		world.setBlock(i + 3, j + 1, k + 11, Blocks.air, 0, 2);
		world.setBlock(i + 4, j + 1, k + 11, PlaceChiseledDeepslate, 4, 2);
		world.setBlock(i + 5, j + 1, k + 11, PlaceCobbledDeepslate, 0, 2);
		world.setBlock(i + 6, j + 1, k + 11, Blocks.packed_ice, 0, 2);
		world.setBlock(i + 7, j + 1, k + 11, PlaceBlueIce, 0, 2);
		world.setBlock(i + 8, j + 1, k + 11, PlaceBlueIce, 0, 2);
		world.setBlock(i + 9, j + 1, k + 11, Blocks.air, 0, 2);
		world.setBlock(i + 10, j + 1, k + 11, Blocks.air, 0, 2);
		world.setBlock(i + 11, j + 1, k + 11, Blocks.air, 0, 2);
		world.setBlock(i + 12, j + 1, k + 11, Blocks.air, 0, 2);
		world.setBlock(i + 13, j + 1, k + 11, PlaceBlueIce, 0, 2);
		world.setBlock(i + 14, j + 1, k + 11, PlaceBlueIce, 0, 2);
		world.setBlock(i + 15, j + 1, k + 11, PlaceBlueIce, 0, 2);
		world.setBlock(i + 16, j + 1, k + 11, PlaceBlueIce, 0, 2);
		world.setBlock(i + 17, j + 1, k + 11, PlaceCobbledDeepslate, 0, 2);
		world.setBlock(i + 18, j + 1, k + 11, Blocks.air, 0, 2);
		world.setBlock(i + 0, j + 1, k + 12, Blocks.air, 0, 2);
		world.setBlock(i + 1, j + 1, k + 12, Blocks.air, 0, 2);
		world.setBlock(i + 2, j + 1, k + 12, Blocks.air, 0, 2);
		world.setBlock(i + 3, j + 1, k + 12, PlaceDeepslateBricks, 0, 2);
		world.setBlock(i + 4, j + 1, k + 12, PlaceCobbledDeepslate, 0, 2);
		world.setBlock(i + 5, j + 1, k + 12, PlaceCobbledDeepslate, 0, 2);
		world.setBlock(i + 6, j + 1, k + 12, PlaceCobbledDeepslate, 0, 2);
		world.setBlock(i + 7, j + 1, k + 12, Blocks.packed_ice, 0, 2);
		world.setBlock(i + 8, j + 1, k + 12, Blocks.packed_ice, 0, 2);
		world.setBlock(i + 9, j + 1, k + 12, Blocks.packed_ice, 0, 2);
		world.setBlock(i + 10, j + 1, k + 12, Blocks.air, 0, 2);
		world.setBlock(i + 11, j + 1, k + 12, PlaceBlueIce, 0, 2);
		world.setBlock(i + 12, j + 1, k + 12, Blocks.ice, 0, 2);
		world.setBlock(i + 13, j + 1, k + 12, PlaceBlueIce, 0, 2);
		world.setBlock(i + 14, j + 1, k + 12, PlaceBlueIce, 0, 2);
		world.setBlock(i + 15, j + 1, k + 12, PlaceBlueIce, 0, 2);
		world.setBlock(i + 16, j + 1, k + 12, PlaceBlueIce, 0, 2);
		world.setBlock(i + 17, j + 1, k + 12, PlaceCobbledDeepslate, 0, 2);
		world.setBlock(i + 18, j + 1, k + 12, PlaceCobbledDeepslate, 0, 2);
		world.setBlock(i + 0, j + 1, k + 13, Blocks.air, 0, 2);
		world.setBlock(i + 1, j + 1, k + 13, Blocks.air, 0, 2);
		world.setBlock(i + 2, j + 1, k + 13, Blocks.air, 0, 2);
		world.setBlock(i + 3, j + 1, k + 13, PlaceDeepslateTiles, 2, 2);
		world.setBlock(i + 4, j + 1, k + 13, PlaceCobbledDeepslate, 0, 2);
		world.setBlock(i + 5, j + 1, k + 13, PlaceCobbledDeepslate, 0, 2);
		world.setBlock(i + 6, j + 1, k + 13, PlaceCobbledDeepslate, 0, 2);
		world.setBlock(i + 7, j + 1, k + 13, PlaceCobbledDeepslate, 0, 2);
		world.setBlock(i + 8, j + 1, k + 13, PlaceCobbledDeepslate, 0, 2);
		world.setBlock(i + 9, j + 1, k + 13, PlaceCobbledDeepslate, 0, 2);
		world.setBlock(i + 10, j + 1, k + 13, PlaceCobbledDeepslate, 0, 2);
		world.setBlock(i + 11, j + 1, k + 13, PlaceCobbledDeepslate, 0, 2);
		world.setBlock(i + 12, j + 1, k + 13, PlaceCobbledDeepslate, 0, 2);
		world.setBlock(i + 13, j + 1, k + 13, PlaceCobbledDeepslate, 0, 2);
		world.setBlock(i + 14, j + 1, k + 13, PlaceCobbledDeepslate, 0, 2);
		world.setBlock(i + 15, j + 1, k + 13, PlaceCobbledDeepslate, 0, 2);
		world.setBlock(i + 16, j + 1, k + 13, PlaceCobbledDeepslate, 0, 2);
		world.setBlock(i + 17, j + 1, k + 13, PlaceCobbledDeepslate, 0, 2);
		world.setBlock(i + 18, j + 1, k + 13, Blocks.air, 0, 2);
		world.setBlock(i + 0, j + 1, k + 14, Blocks.air, 0, 2);
		world.setBlock(i + 1, j + 1, k + 14, PlaceDeepslateBricks, 0, 2);
		world.setBlock(i + 2, j + 1, k + 14, PlaceDeepslateBricks, 0, 2);
		world.setBlock(i + 3, j + 1, k + 14, PlaceDeepslateBricks, 0, 2);
		world.setBlock(i + 4, j + 1, k + 14, PlaceCobbledDeepslate, 0, 2);
		world.setBlock(i + 5, j + 1, k + 14, PlaceCobbledDeepslate, 0, 2);
		world.setBlock(i + 6, j + 1, k + 14, PlaceDeepslateBricks, 0, 2);
		world.setBlock(i + 7, j + 1, k + 14, Blocks.air, 0, 2);
		world.setBlock(i + 8, j + 1, k + 14, Blocks.air, 0, 2);
		world.setBlock(i + 9, j + 1, k + 14, PlaceCobbledDeepslate, 0, 2);
		world.setBlock(i + 10, j + 1, k + 14, PlaceCobbledDeepslate, 0, 2);
		world.setBlock(i + 11, j + 1, k + 14, Blocks.air, 0, 2);
		world.setBlock(i + 12, j + 1, k + 14, PlaceCobbledDeepslate, 0, 2);
		world.setBlock(i + 13, j + 1, k + 14, PlaceCobbledDeepslate, 0, 2);
		world.setBlock(i + 14, j + 1, k + 14, PlaceCobbledDeepslate, 0, 2);
		world.setBlock(i + 15, j + 1, k + 14, PlaceCobbledDeepslate, 0, 2);
		world.setBlock(i + 16, j + 1, k + 14, PlaceCobbledDeepslate, 0, 2);
		world.setBlock(i + 17, j + 1, k + 14, PlaceCobbledDeepslate, 0, 2);
		world.setBlock(i + 18, j + 1, k + 14, PlaceCobbledDeepslate, 0, 2);
		world.setBlock(i + 0, j + 1, k + 15, Blocks.air, 0, 2);
		world.setBlock(i + 1, j + 1, k + 15, PlaceDeepslateBricks, 0, 2);
		world.setBlock(i + 2, j + 1, k + 15, PlaceDeepslateBricks, 0, 2);
		world.setBlock(i + 3, j + 1, k + 15, PlaceDeepslateBricks, 0, 2);
		world.setBlock(i + 4, j + 1, k + 15, Blocks.air, 0, 2);
		world.setBlock(i + 5, j + 1, k + 15, Blocks.air, 0, 2);
		world.setBlock(i + 6, j + 1, k + 15, Blocks.air, 0, 2);
		world.setBlock(i + 7, j + 1, k + 15, Blocks.air, 0, 2);
		world.setBlock(i + 8, j + 1, k + 15, Blocks.air, 0, 2);
		world.setBlock(i + 9, j + 1, k + 15, Blocks.air, 0, 2);
		world.setBlock(i + 10, j + 1, k + 15, Blocks.air, 0, 2);
		world.setBlock(i + 11, j + 1, k + 15, Blocks.air, 0, 2);
		world.setBlock(i + 12, j + 1, k + 15, Blocks.air, 0, 2);
		world.setBlock(i + 13, j + 1, k + 15, Blocks.air, 0, 2);
		world.setBlock(i + 14, j + 1, k + 15, Blocks.air, 0, 2);
		world.setBlock(i + 15, j + 1, k + 15, Blocks.air, 0, 2);
		world.setBlock(i + 16, j + 1, k + 15, Blocks.air, 0, 2);
		world.setBlock(i + 17, j + 1, k + 15, Blocks.air, 0, 2);
		world.setBlock(i + 18, j + 1, k + 15, Blocks.air, 0, 2);
		world.setBlock(i + 0, j + 2, k + 0, Blocks.air, 0, 2);
		world.setBlock(i + 1, j + 2, k + 0, Blocks.air, 0, 2);
		world.setBlock(i + 2, j + 2, k + 0, Blocks.air, 0, 2);
		world.setBlock(i + 3, j + 2, k + 0, NovaCraftBlocks.sculk_vein, 2, 2);
		world.setBlock(i + 4, j + 2, k + 0, Blocks.air, 0, 2);
		world.setBlock(i + 5, j + 2, k + 0, Blocks.air, 0, 2);
		world.setBlock(i + 6, j + 2, k + 0, Blocks.air, 0, 2);
		world.setBlock(i + 7, j + 2, k + 0, Blocks.air, 0, 2);
		world.setBlock(i + 8, j + 2, k + 0, Blocks.air, 0, 2);
		world.setBlock(i + 9, j + 2, k + 0, Blocks.air, 0, 2);
		world.setBlock(i + 10, j + 2, k + 0, Blocks.air, 0, 2);
		world.setBlock(i + 11, j + 2, k + 0, Blocks.air, 0, 2);
		world.setBlock(i + 12, j + 2, k + 0, Blocks.air, 0, 2);
		world.setBlock(i + 13, j + 2, k + 0, Blocks.air, 0, 2);
		world.setBlock(i + 14, j + 2, k + 0, Blocks.air, 0, 2);
		world.setBlock(i + 15, j + 2, k + 0, Blocks.air, 0, 2);
		world.setBlock(i + 16, j + 2, k + 0, Blocks.air, 0, 2);
		world.setBlock(i + 17, j + 2, k + 0, Blocks.air, 0, 2);
		world.setBlock(i + 18, j + 2, k + 0, Blocks.air, 0, 2);
		world.setBlock(i + 0, j + 2, k + 1, Blocks.air, 0, 2);
		world.setBlock(i + 1, j + 2, k + 1, NovaCraftBlocks.sculk_vein, 4, 2);
		world.setBlock(i + 2, j + 2, k + 1, PlaceDeepslateBricks, 0, 2);
		world.setBlock(i + 3, j + 2, k + 1, PlaceDeepslateBricks, 0, 2);
		world.setBlock(i + 4, j + 2, k + 1, NovaCraftBlocks.sculk_vein, 0, 2);
		world.setBlock(i + 5, j + 2, k + 1, Blocks.air, 0, 2);
		world.setBlock(i + 6, j + 2, k + 1, Blocks.air, 0, 2);
		world.setBlock(i + 7, j + 2, k + 1, Blocks.air, 0, 2);
		world.setBlock(i + 8, j + 2, k + 1, Blocks.air, 0, 2);
		world.setBlock(i + 9, j + 2, k + 1, Blocks.air, 0, 2);
		world.setBlock(i + 10, j + 2, k + 1, Blocks.air, 0, 2);
		world.setBlock(i + 11, j + 2, k + 1, Blocks.air, 0, 2);
		world.setBlock(i + 12, j + 2, k + 1, Blocks.air, 0, 2);
		world.setBlock(i + 13, j + 2, k + 1, Blocks.air, 0, 2);
		world.setBlock(i + 14, j + 2, k + 1, Blocks.air, 0, 2);
		world.setBlock(i + 15, j + 2, k + 1, Blocks.air, 0, 2);
		world.setBlock(i + 16, j + 2, k + 1, Blocks.air, 0, 2);
		world.setBlock(i + 17, j + 2, k + 1, Blocks.air, 0, 2);
		world.setBlock(i + 18, j + 2, k + 1, Blocks.air, 0, 2);
		world.setBlock(i + 0, j + 2, k + 2, Blocks.air, 0, 2);
		world.setBlock(i + 1, j + 2, k + 2, Blocks.air, 0, 2);
		world.setBlock(i + 2, j + 2, k + 2, NovaCraftBlocks.sculk_block, 0, 2);
		world.setBlock(i + 3, j + 2, k + 2, PlaceDeepslateBricks, 0, 2);
		world.setBlock(i + 4, j + 2, k + 2, NovaCraftBlocks.sculk_block, 0, 2);
		world.setBlock(i + 5, j + 2, k + 2, NovaCraftBlocks.sculk_block, 0, 2);
		world.setBlock(i + 6, j + 2, k + 2, NovaCraftBlocks.sculk_block, 0, 2);
		world.setBlock(i + 7, j + 2, k + 2, NovaCraftBlocks.sculk_block, 0, 2);
		world.setBlock(i + 8, j + 2, k + 2, PlaceCobbledDeepslate, 0, 2);
		world.setBlock(i + 9, j + 2, k + 2, PlaceCobbledDeepslate, 0, 2);
		world.setBlock(i + 10, j + 2, k + 2, PlaceCobbledDeepslate, 0, 2);
		world.setBlock(i + 11, j + 2, k + 2, PlaceCobbledDeepslate, 0, 2);
		world.setBlock(i + 12, j + 2, k + 2, PlaceCobbledDeepslate, 0, 2);
		world.setBlock(i + 13, j + 2, k + 2, PlaceCobbledDeepslate, 0, 2);
		world.setBlock(i + 14, j + 2, k + 2, PlaceCobbledDeepslate, 0, 2);
		world.setBlock(i + 15, j + 2, k + 2, PlaceCobbledDeepslate, 0, 2);
		world.setBlock(i + 16, j + 2, k + 2, PlaceCobbledDeepslate, 0, 2);
		world.setBlock(i + 17, j + 2, k + 2, PlaceCobbledDeepslate, 0, 2);
		world.setBlock(i + 18, j + 2, k + 2, PlaceCobbledDeepslate, 0, 2);
		world.setBlock(i + 0, j + 2, k + 3, Blocks.air, 0, 2);
		world.setBlock(i + 1, j + 2, k + 3, Blocks.air, 0, 2);
		world.setBlock(i + 2, j + 2, k + 3, Blocks.air, 0, 2);
		world.setBlock(i + 3, j + 2, k + 3, NovaCraftBlocks.sculk_vein, 2, 2);
		world.setBlock(i + 4, j + 2, k + 3, NovaCraftBlocks.sculk_block, 0, 2);
		world.setBlock(i + 5, j + 2, k + 3, PlaceCobbledDeepslate, 0, 2);
		world.setBlock(i + 6, j + 2, k + 3, PlaceCobbledDeepslate, 0, 2);
		world.setBlock(i + 7, j + 2, k + 3, PlaceCobbledDeepslate, 0, 2);
		world.setBlock(i + 8, j + 2, k + 3, PlaceCobbledDeepslate, 0, 2);
		world.setBlock(i + 9, j + 2, k + 3, NovaCraftBlocks.sculk_block, 0, 2);
		world.setBlock(i + 10, j + 2, k + 3, NovaCraftBlocks.sculk_block, 0, 2);
		world.setBlock(i + 11, j + 2, k + 3, NovaCraftBlocks.sculk_block, 0, 2);
		world.setBlock(i + 12, j + 2, k + 3, NovaCraftBlocks.sculk_block, 0, 2);
		world.setBlock(i + 13, j + 2, k + 3, NovaCraftBlocks.sculk_block, 0, 2);
		world.setBlock(i + 14, j + 2, k + 3, NovaCraftBlocks.sculk_block, 0, 2);
		world.setBlock(i + 15, j + 2, k + 3, PlaceCobbledDeepslate, 0, 2);
		world.setBlock(i + 16, j + 2, k + 3, PlaceCobbledDeepslate, 0, 2);
		world.setBlock(i + 17, j + 2, k + 3, PlaceCobbledDeepslate, 0, 2);
		world.setBlock(i + 18, j + 2, k + 3, PlaceCobbledDeepslate, 0, 2);
		world.setBlock(i + 0, j + 2, k + 4, Blocks.air, 0, 2);
		world.setBlock(i + 1, j + 2, k + 4, Blocks.air, 0, 2);
		world.setBlock(i + 2, j + 2, k + 4, NovaCraftBlocks.sculk_vein, 4, 2);
		world.setBlock(i + 3, j + 2, k + 4, PlaceCobbledDeepslate, 0, 2);
		world.setBlock(i + 4, j + 2, k + 4, PlaceCobbledDeepslate, 0, 2);
		world.setBlock(i + 5, j + 2, k + 4, PlaceCobbledDeepslate, 0, 2);
		world.setBlock(i + 6, j + 2, k + 4, PlaceCobbledDeepslate, 0, 2);
		world.setBlock(i + 7, j + 2, k + 4, Blocks.packed_ice, 0, 2);
		world.setBlock(i + 8, j + 2, k + 4, Blocks.packed_ice, 0, 2);
		world.setBlock(i + 9, j + 2, k + 4, NovaCraftBlocks.sculk_vein, 1, 2);
		world.setBlock(i + 10, j + 2, k + 4, NovaCraftBlocks.sculk_vein, 1, 2);
		world.setBlock(i + 11, j + 2, k + 4, Blocks.air, 0, 2);
		world.setBlock(i + 12, j + 2, k + 4, NovaCraftBlocks.sculk_vein, 1, 2);
		world.setBlock(i + 13, j + 2, k + 4, NovaCraftBlocks.sculk_vein, 1, 2);
		world.setBlock(i + 14, j + 2, k + 4, NovaCraftBlocks.sculk_vein, 1, 2);
		world.setBlock(i + 15, j + 2, k + 4, PlaceBlueIce, 0, 2);
		world.setBlock(i + 16, j + 2, k + 4, Blocks.packed_ice, 0, 2);
		world.setBlock(i + 17, j + 2, k + 4, PlaceCobbledDeepslate, 0, 2);
		world.setBlock(i + 18, j + 2, k + 4, PlaceCobbledDeepslate, 0, 2);
		world.setBlock(i + 0, j + 2, k + 5, Blocks.air, 0, 2);
		world.setBlock(i + 1, j + 2, k + 5, Blocks.air, 0, 2);
		world.setBlock(i + 2, j + 2, k + 5, Blocks.air, 0, 2);
		world.setBlock(i + 3, j + 2, k + 5, PlaceCobbledDeepslate, 0, 2);
		world.setBlock(i + 4, j + 2, k + 5, PlaceCobbledDeepslate, 0, 2);
		world.setBlock(i + 5, j + 2, k + 5, PlaceCobbledDeepslate, 0, 2);
		world.setBlock(i + 6, j + 2, k + 5, PlaceCobbledDeepslate, 0, 2);
		world.setBlock(i + 7, j + 2, k + 5, Blocks.packed_ice, 0, 2);
		world.setBlock(i + 8, j + 2, k + 5, NovaCraftBlocks.sculk_vein, 1, 2);
		world.setBlock(i + 9, j + 2, k + 5, Blocks.air, 0, 2);
		world.setBlock(i + 10, j + 2, k + 5, Blocks.air, 0, 2);
		world.setBlock(i + 11, j + 2, k + 5, Blocks.ladder, 2, 2);
		world.setBlock(i + 12, j + 2, k + 5, NovaCraftBlocks.sculk_vein, 1, 2);
		world.setBlock(i + 13, j + 2, k + 5, NovaCraftBlocks.sculk_vein, 1, 2);
		world.setBlock(i + 14, j + 2, k + 5, NovaCraftBlocks.sculk_vein, 1, 2);
		world.setBlock(i + 15, j + 2, k + 5, NovaCraftBlocks.sculk_vein, 1, 2);
		world.setBlock(i + 16, j + 2, k + 5, PlaceBlueIce, 0, 2);
		world.setBlock(i + 17, j + 2, k + 5, PlaceCobbledDeepslate, 0, 2);
		world.setBlock(i + 18, j + 2, k + 5, PlaceCobbledDeepslate, 0, 2);
		world.setBlock(i + 0, j + 2, k + 6, PlaceChiseledDeepslate, 4, 2);
		world.setBlock(i + 1, j + 2, k + 6, Blocks.air, 0, 2);
		world.setBlock(i + 2, j + 2, k + 6, Blocks.air, 0, 2);
		world.setBlock(i + 3, j + 2, k + 6, PlaceDeepslateBricks, 0, 2);
		world.setBlock(i + 4, j + 2, k + 6, PlaceChiseledDeepslate, 4, 2);
		world.setBlock(i + 5, j + 2, k + 6, PlaceDeepslateBricks, 0, 2);
		world.setBlock(i + 6, j + 2, k + 6, NovaCraftBlocks.sculk_vein, 3, 2);
		world.setBlock(i + 7, j + 2, k + 6, NovaCraftBlocks.sculk_vein, 3, 2);
		world.setBlock(i + 8, j + 2, k + 6, Blocks.air, 0, 2);
		world.setBlock(i + 9, j + 2, k + 6, Blocks.air, 0, 2);
		world.setBlock(i + 10, j + 2, k + 6, NovaCraftBlocks.sculk_vein, 4, 2);
		world.setBlock(i + 11, j + 2, k + 6, PlaceBasalt, 1, 2);
		world.setBlock(i + 12, j + 2, k + 6, Blocks.air, 0, 2);
		world.setBlock(i + 13, j + 2, k + 6, NovaCraftBlocks.sculk_vein, 1, 2);
		world.setBlock(i + 14, j + 2, k + 6, NovaCraftBlocks.sculk_vein, 1, 2);
		world.setBlock(i + 15, j + 2, k + 6, NovaCraftBlocks.sculk_vein, 1, 2);
		world.setBlock(i + 16, j + 2, k + 6, NovaCraftBlocks.sculk_vein, 1, 2);
		world.setBlock(i + 17, j + 2, k + 6, PlaceCobbledDeepslate, 0, 2);
		world.setBlock(i + 18, j + 2, k + 6, PlaceCobbledDeepslate, 0, 2);
		world.setBlock(i + 0, j + 2, k + 7, Blocks.air, 0, 2);
		world.setBlock(i + 1, j + 2, k + 7, Blocks.air, 0, 2);
		world.setBlock(i + 2, j + 2, k + 7, Blocks.air, 0, 2);
		world.setBlock(i + 3, j + 2, k + 7, Blocks.air, 0, 2);
		world.setBlock(i + 4, j + 2, k + 7, PlaceDeepslateTiles, 2, 2);
		world.setBlock(i + 5, j + 2, k + 7, PlaceDeepslateTiles, 2, 2);
		world.setBlock(i + 6, j + 2, k + 7, Blocks.air, 0, 2);
		world.setBlock(i + 7, j + 2, k + 7, Blocks.air, 0, 2);
		world.setBlock(i + 8, j + 2, k + 7, Blocks.air, 0, 2);
		world.setBlock(i + 9, j + 2, k + 7, Blocks.air, 0, 2);
		world.setBlock(i + 10, j + 2, k + 7, Blocks.air, 0, 2);
		world.setBlock(i + 11, j + 2, k + 7, NovaCraftBlocks.sculk_vein, 3, 2);
		world.setBlock(i + 12, j + 2, k + 7, Blocks.air, 0, 2);
		world.setBlock(i + 13, j + 2, k + 7, Blocks.air, 0, 2);
		world.setBlock(i + 14, j + 2, k + 7, Blocks.air, 0, 2);
		world.setBlock(i + 15, j + 2, k + 7, NovaCraftBlocks.sculk_vein, 1, 2);
		world.setBlock(i + 16, j + 2, k + 7, Blocks.air, 0, 2);
		world.setBlock(i + 17, j + 2, k + 7, Blocks.air, 0, 2);
		world.setBlock(i + 18, j + 2, k + 7, PlaceCobbledDeepslate, 0, 2);
		world.setBlock(i + 0, j + 2, k + 8, Blocks.air, 0, 2);
		world.setBlock(i + 1, j + 2, k + 8, Blocks.air, 0, 2);
		world.setBlock(i + 2, j + 2, k + 8, Blocks.air, 0, 2);
		world.setBlock(i + 3, j + 2, k + 8, PlacePolishedDeepslateStairs, 0, 2);
		world.setBlock(i + 4, j + 2, k + 8, PlaceDeepslateTiles, 2, 2);
		world.setBlock(i + 5, j + 2, k + 8, PlaceDeepslateTiles, 2, 2);
		world.setBlock(i + 6, j + 2, k + 8, Blocks.packed_ice, 0, 2);
		world.setBlock(i + 7, j + 2, k + 8, Blocks.packed_ice, 0, 2);
		world.setBlock(i + 8, j + 2, k + 8, Blocks.air, 0, 2);
		world.setBlock(i + 9, j + 2, k + 8, Blocks.air, 0, 2);
		world.setBlock(i + 10, j + 2, k + 8, Blocks.air, 0, 2);
		world.setBlock(i + 11, j + 2, k + 8, Blocks.air, 0, 2);
		world.setBlock(i + 12, j + 2, k + 8, Blocks.air, 0, 2);
		world.setBlock(i + 13, j + 2, k + 8, NovaCraftBlocks.sculk_vein, 0, 2);
		world.setBlock(i + 14, j + 2, k + 8, Blocks.air, 0, 2);
		world.setBlock(i + 15, j + 2, k + 8, NovaCraftBlocks.sculk_vein, 4, 2);
		world.setBlock(i + 16, j + 2, k + 8, PlaceCobbledDeepslate, 0, 2);
		world.setBlock(i + 17, j + 2, k + 8, PlaceCobbledDeepslate, 0, 2);
		world.setBlock(i + 18, j + 2, k + 8, PlaceCobbledDeepslate, 0, 2);
		world.setBlock(i + 0, j + 2, k + 9, Blocks.air, 0, 2);
		world.setBlock(i + 1, j + 2, k + 9, Blocks.air, 0, 2);
		world.setBlock(i + 2, j + 2, k + 9, Blocks.air, 0, 2);
		world.setBlock(i + 3, j + 2, k + 9, PlacePolishedDeepslateStairs, 0, 2);
		world.setBlock(i + 4, j + 2, k + 9, PlaceDeepslateTiles, 2, 2);
		world.setBlock(i + 5, j + 2, k + 9, PlaceDeepslateTiles, 2, 2);
		world.setBlock(i + 6, j + 2, k + 9, Blocks.packed_ice, 0, 2);
		world.setBlock(i + 7, j + 2, k + 9, Blocks.packed_ice, 0, 2);
		world.setBlock(i + 8, j + 2, k + 9, Blocks.air, 0, 2);
		world.setBlock(i + 9, j + 2, k + 9, Blocks.air, 0, 2);
		world.setBlock(i + 10, j + 2, k + 9, Blocks.air, 0, 2);
		world.setBlock(i + 11, j + 2, k + 9, Blocks.air, 0, 2);
		world.setBlock(i + 12, j + 2, k + 9, Blocks.air, 0, 2);
		world.setBlock(i + 13, j + 2, k + 9, Blocks.air, 0, 2);
		world.setBlock(i + 14, j + 2, k + 9, Blocks.air, 0, 2);
		world.setBlock(i + 15, j + 2, k + 9, Blocks.air, 0, 2);
		world.setBlock(i + 16, j + 2, k + 9, NovaCraftBlocks.sculk_vein, 3, 2);
		world.setBlock(i + 17, j + 2, k + 9, PlaceCobbledDeepslate, 0, 2);
		world.setBlock(i + 18, j + 2, k + 9, PlaceCobbledDeepslate, 0, 2);
		world.setBlock(i + 0, j + 2, k + 10, Blocks.air, 0, 2);
		world.setBlock(i + 1, j + 2, k + 10, Blocks.air, 0, 2);
		world.setBlock(i + 2, j + 2, k + 10, Blocks.air, 0, 2);
		world.setBlock(i + 3, j + 2, k + 10, Blocks.air, 0, 2);
		world.setBlock(i + 4, j + 2, k + 10, PlaceDeepslateTiles, 2, 2);
		world.setBlock(i + 5, j + 2, k + 10, PlaceDeepslateTiles, 2, 2);
		world.setBlock(i + 6, j + 2, k + 10, Blocks.air, 0, 2);
		world.setBlock(i + 7, j + 2, k + 10, Blocks.air, 0, 2);
		world.setBlock(i + 8, j + 2, k + 10, Blocks.air, 0, 2);
		world.setBlock(i + 9, j + 2, k + 10, Blocks.air, 0, 2);
		world.setBlock(i + 10, j + 2, k + 10, Blocks.air, 0, 2);
		world.setBlock(i + 11, j + 2, k + 10, Blocks.air, 0, 2);
		world.setBlock(i + 12, j + 2, k + 10, Blocks.air, 0, 2);
		world.setBlock(i + 13, j + 2, k + 10, Blocks.air, 0, 2);
		world.setBlock(i + 14, j + 2, k + 10, Blocks.air, 0, 2);
		world.setBlock(i + 15, j + 2, k + 10, PlaceBlueIce, 0, 2);
		world.setBlock(i + 16, j + 2, k + 10, PlaceBlueIce, 0, 2);
		world.setBlock(i + 17, j + 2, k + 10, PlaceCobbledDeepslate, 0, 2);
		world.setBlock(i + 18, j + 2, k + 10, Blocks.air, 0, 2);
		world.setBlock(i + 0, j + 2, k + 11, PlaceChiseledDeepslate, 4, 2);
		world.setBlock(i + 1, j + 2, k + 11, Blocks.air, 0, 2);
		world.setBlock(i + 2, j + 2, k + 11, Blocks.air, 0, 2);
		world.setBlock(i + 3, j + 2, k + 11, Blocks.air, 0, 2);
		world.setBlock(i + 4, j + 2, k + 11, Blocks.air, 0, 2);
		world.setBlock(i + 5, j + 2, k + 11, PlaceDeepslateTiles, 2, 2);
		world.setBlock(i + 6, j + 2, k + 11, Blocks.air, 0, 2);
		world.setBlock(i + 7, j + 2, k + 11, Blocks.air, 0, 2);
		world.setBlock(i + 8, j + 2, k + 11, Blocks.air, 0, 2);
		world.setBlock(i + 9, j + 2, k + 11, Blocks.air, 0, 2);
		world.setBlock(i + 10, j + 2, k + 11, Blocks.air, 0, 2);
		world.setBlock(i + 11, j + 2, k + 11, Blocks.air, 0, 2);
		world.setBlock(i + 12, j + 2, k + 11, Blocks.air, 0, 2);
		world.setBlock(i + 13, j + 2, k + 11, Blocks.air, 0, 2);
		world.setBlock(i + 14, j + 2, k + 11, PlaceBlueIce, 0, 2);
		world.setBlock(i + 15, j + 2, k + 11, PlaceBlueIce, 0, 2);
		world.setBlock(i + 16, j + 2, k + 11, PlaceBlueIce, 0, 2);
		world.setBlock(i + 17, j + 2, k + 11, PlaceCobbledDeepslate, 0, 2);
		world.setBlock(i + 18, j + 2, k + 11, Blocks.air, 0, 2);
		world.setBlock(i + 0, j + 2, k + 12, Blocks.air, 0, 2);
		world.setBlock(i + 1, j + 2, k + 12, Blocks.air, 0, 2);
		world.setBlock(i + 2, j + 2, k + 12, Blocks.air, 0, 2);
		world.setBlock(i + 3, j + 2, k + 12, PlaceCobbledDeepslate, 0, 2);
		world.setBlock(i + 4, j + 2, k + 12, PlaceCobbledDeepslate, 0, 2);
		world.setBlock(i + 5, j + 2, k + 12, PlaceCobbledDeepslate, 0, 2);
		world.setBlock(i + 6, j + 2, k + 12, PlaceCobbledDeepslate, 0, 2);
		world.setBlock(i + 7, j + 2, k + 12, Blocks.air, 0, 2);
		world.setBlock(i + 8, j + 2, k + 12, Blocks.air, 0, 2);
		world.setBlock(i + 9, j + 2, k + 12, Blocks.air, 0, 2);
		world.setBlock(i + 10, j + 2, k + 12, Blocks.air, 0, 2);
		world.setBlock(i + 11, j + 2, k + 12, Blocks.air, 0, 2);
		world.setBlock(i + 12, j + 2, k + 12, Blocks.air, 0, 2);
		world.setBlock(i + 13, j + 2, k + 12, Blocks.air, 0, 2);
		world.setBlock(i + 14, j + 2, k + 12, Blocks.air, 0, 2);
		world.setBlock(i + 15, j + 2, k + 12, PlaceBlueIce, 0, 2);
		world.setBlock(i + 16, j + 2, k + 12, PlaceBlueIce, 0, 2);
		world.setBlock(i + 17, j + 2, k + 12, PlaceCobbledDeepslate, 0, 2);
		world.setBlock(i + 18, j + 2, k + 12, Blocks.air, 0, 2);
		world.setBlock(i + 0, j + 2, k + 13, Blocks.air, 0, 2);
		world.setBlock(i + 1, j + 2, k + 13, Blocks.air, 0, 2);
		world.setBlock(i + 2, j + 2, k + 13, Blocks.air, 0, 2);
		world.setBlock(i + 3, j + 2, k + 13, PlaceCobbledDeepslate, 0, 2);
		world.setBlock(i + 4, j + 2, k + 13, PlaceCobbledDeepslate, 0, 2);
		world.setBlock(i + 5, j + 2, k + 13, PlaceCobbledDeepslate, 0, 2);
		world.setBlock(i + 6, j + 2, k + 13, PlaceCobbledDeepslate, 0, 2);
		world.setBlock(i + 7, j + 2, k + 13, PlaceCobbledDeepslate, 0, 2);
		world.setBlock(i + 8, j + 2, k + 13, PlaceCobbledDeepslate, 0, 2);
		world.setBlock(i + 9, j + 2, k + 13, PlaceCobbledDeepslate, 0, 2);
		world.setBlock(i + 10, j + 2, k + 13, PlaceCobbledDeepslate, 0, 2);
		world.setBlock(i + 11, j + 2, k + 13, PlaceCobbledDeepslate, 0, 2);
		world.setBlock(i + 12, j + 2, k + 13, PlaceCobbledDeepslate, 0, 2);
		world.setBlock(i + 13, j + 2, k + 13, PlaceCobbledDeepslate, 0, 2);
		world.setBlock(i + 14, j + 2, k + 13, PlaceCobbledDeepslate, 0, 2);
		world.setBlock(i + 15, j + 2, k + 13, PlaceCobbledDeepslate, 0, 2);
		world.setBlock(i + 16, j + 2, k + 13, PlaceCobbledDeepslate, 0, 2);
		world.setBlock(i + 17, j + 2, k + 13, PlaceCobbledDeepslate, 0, 2);
		world.setBlock(i + 18, j + 2, k + 13, PlaceCobbledDeepslate, 0, 2);
		world.setBlock(i + 0, j + 2, k + 14, Blocks.air, 0, 2);
		world.setBlock(i + 1, j + 2, k + 14, Blocks.air, 0, 2);
		world.setBlock(i + 2, j + 2, k + 14, PlaceDeepslateBricks, 0, 2);
		world.setBlock(i + 3, j + 2, k + 14, PlaceDeepslateBricks, 0, 2);
		world.setBlock(i + 4, j + 2, k + 14, PlaceCobbledDeepslate, 0, 2);
		world.setBlock(i + 5, j + 2, k + 14, PlaceCobbledDeepslate, 0, 2);
		world.setBlock(i + 6, j + 2, k + 14, PlaceCobbledDeepslate, 0, 2);
		world.setBlock(i + 7, j + 2, k + 14, Blocks.air, 0, 2);
		world.setBlock(i + 8, j + 2, k + 14, Blocks.air, 0, 2);
		world.setBlock(i + 9, j + 2, k + 14, Blocks.air, 0, 2);
		world.setBlock(i + 10, j + 2, k + 14, PlaceCobbledDeepslate, 0, 2);
		world.setBlock(i + 11, j + 2, k + 14, PlaceCobbledDeepslate, 0, 2);
		world.setBlock(i + 12, j + 2, k + 14, PlaceCobbledDeepslate, 0, 2);
		world.setBlock(i + 13, j + 2, k + 14, PlaceCobbledDeepslate, 0, 2);
		world.setBlock(i + 14, j + 2, k + 14, Blocks.air, 0, 2);
		world.setBlock(i + 15, j + 2, k + 14, Blocks.air, 0, 2);
		world.setBlock(i + 16, j + 2, k + 14, PlaceCobbledDeepslate, 0, 2);
		world.setBlock(i + 17, j + 2, k + 14, PlaceCobbledDeepslate, 0, 2);
		world.setBlock(i + 18, j + 2, k + 14, PlaceCobbledDeepslate, 0, 2);
		world.setBlock(i + 0, j + 2, k + 15, Blocks.air, 0, 2);
		world.setBlock(i + 1, j + 2, k + 15, Blocks.air, 0, 2);
		world.setBlock(i + 2, j + 2, k + 15, PlaceDeepslateBricks, 0, 2);
		world.setBlock(i + 3, j + 2, k + 15, PlaceDeepslateBricks, 0, 2);
		world.setBlock(i + 4, j + 2, k + 15, Blocks.air, 0, 2);
		world.setBlock(i + 5, j + 2, k + 15, Blocks.air, 0, 2);
		world.setBlock(i + 6, j + 2, k + 15, Blocks.air, 0, 2);
		world.setBlock(i + 7, j + 2, k + 15, Blocks.air, 0, 2);
		world.setBlock(i + 8, j + 2, k + 15, Blocks.air, 0, 2);
		world.setBlock(i + 9, j + 2, k + 15, Blocks.air, 0, 2);
		world.setBlock(i + 10, j + 2, k + 15, Blocks.air, 0, 2);
		world.setBlock(i + 11, j + 2, k + 15, Blocks.air, 0, 2);
		world.setBlock(i + 12, j + 2, k + 15, Blocks.air, 0, 2);
		world.setBlock(i + 13, j + 2, k + 15, Blocks.air, 0, 2);
		world.setBlock(i + 14, j + 2, k + 15, Blocks.air, 0, 2);
		world.setBlock(i + 15, j + 2, k + 15, Blocks.air, 0, 2);
		world.setBlock(i + 16, j + 2, k + 15, Blocks.air, 0, 2);
		world.setBlock(i + 17, j + 2, k + 15, Blocks.air, 0, 2);
		world.setBlock(i + 18, j + 2, k + 15, Blocks.air, 0, 2);
		world.setBlock(i + 0, j + 3, k + 0, Blocks.air, 0, 2);
		world.setBlock(i + 1, j + 3, k + 0, Blocks.air, 0, 2);
		world.setBlock(i + 2, j + 3, k + 0, NovaCraftBlocks.sculk_vein, 2, 2);
		world.setBlock(i + 3, j + 3, k + 0, Blocks.air, 0, 2);
		world.setBlock(i + 4, j + 3, k + 0, Blocks.air, 0, 2);
		world.setBlock(i + 5, j + 3, k + 0, Blocks.air, 0, 2);
		world.setBlock(i + 6, j + 3, k + 0, Blocks.air, 0, 2);
		world.setBlock(i + 7, j + 3, k + 0, Blocks.air, 0, 2);
		world.setBlock(i + 8, j + 3, k + 0, Blocks.air, 0, 2);
		world.setBlock(i + 9, j + 3, k + 0, Blocks.air, 0, 2);
		world.setBlock(i + 10, j + 3, k + 0, Blocks.air, 0, 2);
		world.setBlock(i + 11, j + 3, k + 0, Blocks.air, 0, 2);
		world.setBlock(i + 12, j + 3, k + 0, Blocks.air, 0, 2);
		world.setBlock(i + 13, j + 3, k + 0, Blocks.air, 0, 2);
		world.setBlock(i + 14, j + 3, k + 0, Blocks.air, 0, 2);
		world.setBlock(i + 15, j + 3, k + 0, Blocks.air, 0, 2);
		world.setBlock(i + 16, j + 3, k + 0, Blocks.air, 0, 2);
		world.setBlock(i + 17, j + 3, k + 0, Blocks.air, 0, 2);
		world.setBlock(i + 18, j + 3, k + 0, Blocks.air, 0, 2);
		world.setBlock(i + 0, j + 3, k + 1, Blocks.air, 0, 2);
		world.setBlock(i + 1, j + 3, k + 1, PlaceDeepslateBricks, 0, 2);
		world.setBlock(i + 2, j + 3, k + 1, PlaceDeepslateBricks, 0, 2);
		world.setBlock(i + 3, j + 3, k + 1, NovaCraftBlocks.sculk_block, 0, 2);
		world.setBlock(i + 4, j + 3, k + 1, Blocks.air, 0, 2);
		world.setBlock(i + 5, j + 3, k + 1, Blocks.air, 0, 2);
		world.setBlock(i + 6, j + 3, k + 1, Blocks.air, 0, 2);
		world.setBlock(i + 7, j + 3, k + 1, Blocks.air, 0, 2);
		world.setBlock(i + 8, j + 3, k + 1, Blocks.air, 0, 2);
		world.setBlock(i + 9, j + 3, k + 1, Blocks.air, 0, 2);
		world.setBlock(i + 10, j + 3, k + 1, Blocks.air, 0, 2);
		world.setBlock(i + 11, j + 3, k + 1, Blocks.air, 0, 2);
		world.setBlock(i + 12, j + 3, k + 1, Blocks.air, 0, 2);
		world.setBlock(i + 13, j + 3, k + 1, Blocks.air, 0, 2);
		world.setBlock(i + 14, j + 3, k + 1, Blocks.air, 0, 2);
		world.setBlock(i + 15, j + 3, k + 1, Blocks.air, 0, 2);
		world.setBlock(i + 16, j + 3, k + 1, Blocks.air, 0, 2);
		world.setBlock(i + 17, j + 3, k + 1, Blocks.air, 0, 2);
		world.setBlock(i + 18, j + 3, k + 1, Blocks.air, 0, 2);
		world.setBlock(i + 0, j + 3, k + 2, Blocks.air, 0, 2);
		world.setBlock(i + 1, j + 3, k + 2, PlaceDeepslateBricks, 0, 2);
		world.setBlock(i + 2, j + 3, k + 2, NovaCraftBlocks.sculk_block, 0, 2);
		world.setBlock(i + 3, j + 3, k + 2, NovaCraftBlocks.sculk_block, 0, 2);
		world.setBlock(i + 4, j + 3, k + 2, Blocks.air, 0, 2);
		world.setBlock(i + 5, j + 3, k + 2, NovaCraftBlocks.sculk_block, 0, 2);
		world.setBlock(i + 6, j + 3, k + 2, NovaCraftBlocks.sculk_block, 0, 2);
		world.setBlock(i + 7, j + 3, k + 2, NovaCraftBlocks.sculk_block, 0, 2);
		world.setBlock(i + 8, j + 3, k + 2, PlaceCobbledDeepslate, 0, 2);
		world.setBlock(i + 9, j + 3, k + 2, PlaceCobbledDeepslate, 0, 2);
		world.setBlock(i + 10, j + 3, k + 2, PlaceCobbledDeepslate, 0, 2);
		world.setBlock(i + 11, j + 3, k + 2, PlaceCobbledDeepslate, 0, 2);
		world.setBlock(i + 12, j + 3, k + 2, PlaceCobbledDeepslate, 0, 2);
		world.setBlock(i + 13, j + 3, k + 2, PlaceCobbledDeepslate, 0, 2);
		world.setBlock(i + 14, j + 3, k + 2, PlaceCobbledDeepslate, 0, 2);
		world.setBlock(i + 15, j + 3, k + 2, PlaceCobbledDeepslate, 0, 2);
		world.setBlock(i + 16, j + 3, k + 2, PlaceCobbledDeepslate, 0, 2);
		world.setBlock(i + 17, j + 3, k + 2, PlaceCobbledDeepslate, 0, 2);
		world.setBlock(i + 18, j + 3, k + 2, PlaceCobbledDeepslate, 0, 2);
		world.setBlock(i + 0, j + 3, k + 3, Blocks.air, 0, 2);
		world.setBlock(i + 1, j + 3, k + 3, NovaCraftBlocks.sculk_vein, 3, 2);
		world.setBlock(i + 2, j + 3, k + 3, Blocks.air, 0, 2);
		world.setBlock(i + 3, j + 3, k + 3, NovaCraftBlocks.sculk_vein, 2, 2);
		world.setBlock(i + 4, j + 3, k + 3, NovaCraftBlocks.sculk_block, 0, 2);
		world.setBlock(i + 5, j + 3, k + 3, PlaceCobbledDeepslate, 0, 2);
		world.setBlock(i + 6, j + 3, k + 3, PlaceCobbledDeepslate, 0, 2);
		world.setBlock(i + 7, j + 3, k + 3, NovaCraftBlocks.sculk_block, 0, 2);
		world.setBlock(i + 8, j + 3, k + 3, PlaceCobbledDeepslate, 0, 2);
		world.setBlock(i + 9, j + 3, k + 3, NovaCraftBlocks.sculk_block, 0, 2);
		world.setBlock(i + 10, j + 3, k + 3, NovaCraftBlocks.sculk_block, 0, 2);
		world.setBlock(i + 11, j + 3, k + 3, PlaceCobbledDeepslate, 0, 2);
		world.setBlock(i + 12, j + 3, k + 3, NovaCraftBlocks.sculk_block, 0, 2);
		world.setBlock(i + 13, j + 3, k + 3, PlaceCobbledDeepslate, 0, 2);
		world.setBlock(i + 14, j + 3, k + 3, PlaceCobbledDeepslate, 0, 2);
		world.setBlock(i + 15, j + 3, k + 3, Blocks.air, 0, 2);
		world.setBlock(i + 16, j + 3, k + 3, PlaceCobbledDeepslate, 0, 2);
		world.setBlock(i + 17, j + 3, k + 3, PlaceCobbledDeepslate, 0, 2);
		world.setBlock(i + 18, j + 3, k + 3, PlaceCobbledDeepslate, 0, 2);
		world.setBlock(i + 0, j + 3, k + 4, Blocks.air, 0, 2);
		world.setBlock(i + 1, j + 3, k + 4, Blocks.air, 0, 2);
		world.setBlock(i + 2, j + 3, k + 4, Blocks.air, 0, 2);
		world.setBlock(i + 3, j + 3, k + 4, PlaceCobbledDeepslate, 0, 2);
		world.setBlock(i + 4, j + 3, k + 4, PlaceCobbledDeepslate, 0, 2);
		world.setBlock(i + 5, j + 3, k + 4, PlaceCobbledDeepslate, 0, 2);
		world.setBlock(i + 6, j + 3, k + 4, PlaceCobbledDeepslate, 0, 2);
		world.setBlock(i + 7, j + 3, k + 4, Blocks.packed_ice, 0, 2);
		world.setBlock(i + 8, j + 3, k + 4, NovaCraftBlocks.sculk_vein, 3, 2);
		world.setBlock(i + 9, j + 3, k + 4, Blocks.air, 0, 2);
		world.setBlock(i + 10, j + 3, k + 4, Blocks.air, 0, 2);
		world.setBlock(i + 11, j + 3, k + 4, Blocks.lever, 7, 2);
		world.setBlock(i + 12, j + 3, k + 4, NovaCraftBlocks.sculk_vein, 0, 2);
		world.setBlock(i + 13, j + 3, k + 4, NovaCraftBlocks.sculk_vein, 3, 2);
		world.setBlock(i + 14, j + 3, k + 4, NovaCraftBlocks.sculk_vein, 3, 2);
		world.setBlock(i + 15, j + 3, k + 4, NovaCraftBlocks.sculk_vein, 0, 2);
		world.setBlock(i + 16, j + 3, k + 4, Blocks.packed_ice, 0, 2);
		world.setBlock(i + 17, j + 3, k + 4, PlaceCobbledDeepslate, 0, 2);
		world.setBlock(i + 18, j + 3, k + 4, PlaceCobbledDeepslate, 0, 2);
		world.setBlock(i + 0, j + 3, k + 5, Blocks.air, 0, 2);
		world.setBlock(i + 1, j + 3, k + 5, Blocks.air, 0, 2);
		world.setBlock(i + 2, j + 3, k + 5, Blocks.air, 0, 2);
		world.setBlock(i + 3, j + 3, k + 5, NovaCraftBlocks.sculk_vein, 4, 2);
		world.setBlock(i + 4, j + 3, k + 5, PlaceCobbledDeepslate, 0, 2);
		world.setBlock(i + 5, j + 3, k + 5, PlaceCobbledDeepslate, 0, 2);
		world.setBlock(i + 6, j + 3, k + 5, NovaCraftBlocks.sculk_block, 0, 2);
		world.setBlock(i + 7, j + 3, k + 5, NovaCraftBlocks.sculk_vein, 3, 2);
		world.setBlock(i + 8, j + 3, k + 5, Blocks.air, 0, 2);
		world.setBlock(i + 9, j + 3, k + 5, Blocks.air, 0, 2);
		world.setBlock(i + 10, j + 3, k + 5, Blocks.air, 0, 2);
		world.setBlock(i + 11, j + 3, k + 5, Blocks.ladder, 2, 2);
		world.setBlock(i + 12, j + 3, k + 5, NovaCraftBlocks.sculk_vein, 0, 2);
		world.setBlock(i + 13, j + 3, k + 5, Blocks.air, 0, 2);
		world.setBlock(i + 14, j + 3, k + 5, Blocks.air, 0, 2);
		world.setBlock(i + 15, j + 3, k + 5, Blocks.air, 0, 2);
		world.setBlock(i + 16, j + 3, k + 5, NovaCraftBlocks.sculk_vein, 4, 2);
		world.setBlock(i + 17, j + 3, k + 5, PlaceCobbledDeepslate, 0, 2);
		world.setBlock(i + 18, j + 3, k + 5, PlaceCobbledDeepslate, 0, 2);
		world.setBlock(i + 0, j + 3, k + 6, PlaceDeepslateBricks, 0, 2);
		world.setBlock(i + 1, j + 3, k + 6, Blocks.air, 0, 2);
		world.setBlock(i + 2, j + 3, k + 6, Blocks.air, 0, 2);
		world.setBlock(i + 3, j + 3, k + 6, PlaceChiseledDeepslate, 4, 2);
		world.setBlock(i + 4, j + 3, k + 6, PlaceChiseledDeepslate, 4, 2);
		world.setBlock(i + 5, j + 3, k + 6, NovaCraftBlocks.sculk_block, 0, 2);
		world.setBlock(i + 6, j + 3, k + 6, Blocks.air, 0, 2);
		world.setBlock(i + 7, j + 3, k + 6, Blocks.air, 0, 2);
		world.setBlock(i + 8, j + 3, k + 6, Blocks.air, 0, 2);
		world.setBlock(i + 9, j + 3, k + 6, Blocks.air, 0, 2);
		world.setBlock(i + 10, j + 3, k + 6, NovaCraftBlocks.sculk_vein, 4, 2);
		world.setBlock(i + 11, j + 3, k + 6, PlaceBasalt, 1, 2);
		world.setBlock(i + 12, j + 3, k + 6, Blocks.air, 0, 2);
		world.setBlock(i + 13, j + 3, k + 6, NovaCraftBlocks.sculk_vein, 0, 2);
		world.setBlock(i + 14, j + 3, k + 6, Blocks.air, 0, 2);
		world.setBlock(i + 15, j + 3, k + 6, Blocks.air, 0, 2);
		world.setBlock(i + 16, j + 3, k + 6, NovaCraftBlocks.sculk_vein, 4, 2);
		world.setBlock(i + 17, j + 3, k + 6, PlaceCobbledDeepslate, 0, 2);
		world.setBlock(i + 18, j + 3, k + 6, PlaceCobbledDeepslate, 0, 2);
		world.setBlock(i + 0, j + 3, k + 7, Blocks.air, 0, 2);
		world.setBlock(i + 1, j + 3, k + 7, Blocks.air, 0, 2);
		world.setBlock(i + 2, j + 3, k + 7, Blocks.air, 0, 2);
		world.setBlock(i + 3, j + 3, k + 7, Blocks.air, 0, 2);
		world.setBlock(i + 4, j + 3, k + 7, Blocks.air, 0, 2);
		world.setBlock(i + 5, j + 3, k + 7, PlaceDeepslateTiles, 2, 2);
		world.setBlock(i + 6, j + 3, k + 7, Blocks.air, 0, 2);
		world.setBlock(i + 7, j + 3, k + 7, NovaCraftBlocks.sculk_vein, 2, 2);
		world.setBlock(i + 8, j + 3, k + 7, NovaCraftBlocks.sculk_vein, 0, 2);
		world.setBlock(i + 9, j + 3, k + 7, Blocks.air, 0, 2);
		world.setBlock(i + 10, j + 3, k + 7, NovaCraftBlocks.sculk_vein, 0, 2);
		world.setBlock(i + 11, j + 3, k + 7, NovaCraftBlocks.sculk_vein, 3, 2);
		world.setBlock(i + 12, j + 3, k + 7, NovaCraftBlocks.sculk_vein, 2, 2);
		world.setBlock(i + 13, j + 3, k + 7, NovaCraftBlocks.sculk_vein, 2, 2);
		world.setBlock(i + 14, j + 3, k + 7, Blocks.air, 0, 2);
		world.setBlock(i + 15, j + 3, k + 7, NovaCraftBlocks.sculk_vein, 2, 2);
		world.setBlock(i + 16, j + 3, k + 7, Blocks.air, 0, 2);
		world.setBlock(i + 17, j + 3, k + 7, Blocks.air, 0, 2);
		world.setBlock(i + 18, j + 3, k + 7, PlaceCobbledDeepslate, 0, 2);
		world.setBlock(i + 0, j + 3, k + 8, Blocks.air, 0, 2);
		world.setBlock(i + 1, j + 3, k + 8, Blocks.air, 0, 2);
		world.setBlock(i + 2, j + 3, k + 8, Blocks.air, 0, 2);
		world.setBlock(i + 3, j + 3, k + 8, Blocks.air, 0, 2);
		world.setBlock(i + 4, j + 3, k + 8, Blocks.air, 0, 2);
		world.setBlock(i + 5, j + 3, k + 8, PlaceDeepslateTiles, 2, 2);
		world.setBlock(i + 6, j + 3, k + 8, Blocks.packed_ice, 0, 2);
		world.setBlock(i + 7, j + 3, k + 8, Blocks.packed_ice, 0, 2);
		world.setBlock(i + 8, j + 3, k + 8, Blocks.air, 0, 2);
		world.setBlock(i + 9, j + 3, k + 8, NovaCraftBlocks.sculk_vein, 0, 2);
		world.setBlock(i + 10, j + 3, k + 8, Blocks.air, 0, 2);
		world.setBlock(i + 11, j + 3, k + 8, PlaceSoulLantern, 0, 2);
		world.setBlock(i + 12, j + 3, k + 8, PlaceChiseledDeepslate, 4, 2);
		world.setBlock(i + 13, j + 3, k + 8, PlaceCobbledDeepslate, 0, 2);
		world.setBlock(i + 14, j + 3, k + 8, NovaCraftBlocks.sculk_block, 0, 2);
		world.setBlock(i + 15, j + 3, k + 8, PlaceCobbledDeepslate, 0, 2);
		world.setBlock(i + 16, j + 3, k + 8, PlaceChiseledDeepslate, 4, 2);
		world.setBlock(i + 17, j + 3, k + 8, PlaceCobbledDeepslate, 0, 2);
		world.setBlock(i + 18, j + 3, k + 8, Blocks.air, 0, 2);
		world.setBlock(i + 0, j + 3, k + 9, Blocks.air, 0, 2);
		world.setBlock(i + 1, j + 3, k + 9, Blocks.air, 0, 2);
		world.setBlock(i + 2, j + 3, k + 9, Blocks.air, 0, 2);
		world.setBlock(i + 3, j + 3, k + 9, Blocks.air, 0, 2);
		world.setBlock(i + 4, j + 3, k + 9, PlacePolishedDeepslateStairs, 0, 2);
		world.setBlock(i + 5, j + 3, k + 9, PlaceDeepslateTiles, 2, 2);
		world.setBlock(i + 6, j + 3, k + 9, Blocks.packed_ice, 0, 2);
		world.setBlock(i + 7, j + 3, k + 9, Blocks.packed_ice, 0, 2);
		world.setBlock(i + 8, j + 3, k + 9, Blocks.air, 0, 2);
		world.setBlock(i + 9, j + 3, k + 9, Blocks.air, 0, 2);
		world.setBlock(i + 10, j + 3, k + 9, Blocks.air, 0, 2);
		world.setBlock(i + 11, j + 3, k + 9, Blocks.air, 0, 2);
		world.setBlock(i + 12, j + 3, k + 9, Blocks.air, 0, 2);
		world.setBlock(i + 13, j + 3, k + 9, NovaCraftBlocks.sculk_vein, 3, 2);
		world.setBlock(i + 14, j + 3, k + 9, Blocks.air, 0, 2);
		world.setBlock(i + 15, j + 3, k + 9, NovaCraftBlocks.sculk_vein, 3, 2);
		world.setBlock(i + 16, j + 3, k + 9, Blocks.air, 0, 2);
		world.setBlock(i + 17, j + 3, k + 9, PlaceCobbledDeepslate, 0, 2);
		world.setBlock(i + 18, j + 3, k + 9, Blocks.air, 0, 2);
		world.setBlock(i + 0, j + 3, k + 10, Blocks.air, 0, 2);
		world.setBlock(i + 1, j + 3, k + 10, Blocks.air, 0, 2);
		world.setBlock(i + 2, j + 3, k + 10, Blocks.air, 0, 2);
		world.setBlock(i + 3, j + 3, k + 10, Blocks.air, 0, 2);
		world.setBlock(i + 4, j + 3, k + 10, Blocks.air, 0, 2);
		world.setBlock(i + 5, j + 3, k + 10, PlaceDeepslateTiles, 2, 2);
		world.setBlock(i + 6, j + 3, k + 10, Blocks.air, 0, 2);
		world.setBlock(i + 7, j + 3, k + 10, Blocks.air, 0, 2);
		world.setBlock(i + 8, j + 3, k + 10, Blocks.air, 0, 2);
		world.setBlock(i + 9, j + 3, k + 10, Blocks.air, 0, 2);
		world.setBlock(i + 10, j + 3, k + 10, Blocks.air, 0, 2);
		world.setBlock(i + 11, j + 3, k + 10, Blocks.air, 0, 2);
		world.setBlock(i + 12, j + 3, k + 10, Blocks.air, 0, 2);
		world.setBlock(i + 13, j + 3, k + 10, Blocks.air, 0, 2);
		world.setBlock(i + 14, j + 3, k + 10, Blocks.air, 0, 2);
		world.setBlock(i + 15, j + 3, k + 10, Blocks.air, 0, 2);
		world.setBlock(i + 16, j + 3, k + 10, Blocks.air, 0, 2);
		world.setBlock(i + 17, j + 3, k + 10, PlaceCobbledDeepslate, 0, 2);
		world.setBlock(i + 18, j + 3, k + 10, Blocks.air, 0, 2);
		world.setBlock(i + 0, j + 3, k + 11, PlaceDeepslateBricks, 0, 2);
		world.setBlock(i + 1, j + 3, k + 11, Blocks.air, 0, 2);
		world.setBlock(i + 2, j + 3, k + 11, Blocks.air, 0, 2);
		world.setBlock(i + 3, j + 3, k + 11, Blocks.air, 0, 2);
		world.setBlock(i + 4, j + 3, k + 11, Blocks.air, 0, 2);
		world.setBlock(i + 5, j + 3, k + 11, PlaceDeepslateTiles, 2, 2);
		world.setBlock(i + 6, j + 3, k + 11, Blocks.air, 0, 2);
		world.setBlock(i + 7, j + 3, k + 11, Blocks.air, 0, 2);
		world.setBlock(i + 8, j + 3, k + 11, Blocks.air, 0, 2);
		world.setBlock(i + 9, j + 3, k + 11, Blocks.air, 0, 2);
		world.setBlock(i + 10, j + 3, k + 11, Blocks.air, 0, 2);
		world.setBlock(i + 11, j + 3, k + 11, Blocks.air, 0, 2);
		world.setBlock(i + 12, j + 3, k + 11, Blocks.air, 0, 2);
		world.setBlock(i + 13, j + 3, k + 11, Blocks.air, 0, 2);
		world.setBlock(i + 14, j + 3, k + 11, Blocks.air, 0, 2);
		world.setBlock(i + 15, j + 3, k + 11, Blocks.air, 0, 2);
		world.setBlock(i + 16, j + 3, k + 11, Blocks.packed_ice, 0, 2);
		world.setBlock(i + 17, j + 3, k + 11, PlaceCobbledDeepslate, 0, 2);
		world.setBlock(i + 18, j + 3, k + 11, Blocks.air, 0, 2);
		world.setBlock(i + 0, j + 3, k + 12, Blocks.air, 0, 2);
		world.setBlock(i + 1, j + 3, k + 12, Blocks.air, 0, 2);
		world.setBlock(i + 2, j + 3, k + 12, Blocks.air, 0, 2);
		world.setBlock(i + 3, j + 3, k + 12, PlaceCobbledDeepslate, 0, 2);
		world.setBlock(i + 4, j + 3, k + 12, PlaceCobbledDeepslate, 0, 2);
		world.setBlock(i + 5, j + 3, k + 12, PlaceCobbledDeepslate, 0, 2);
		world.setBlock(i + 6, j + 3, k + 12, PlaceCobbledDeepslate, 0, 2);
		world.setBlock(i + 7, j + 3, k + 12, Blocks.air, 0, 2);
		world.setBlock(i + 8, j + 3, k + 12, PlaceCobbledDeepslate, 0, 2);
		world.setBlock(i + 9, j + 3, k + 12, PlaceCobbledDeepslate, 0, 2);
		world.setBlock(i + 10, j + 3, k + 12, PlaceCobbledDeepslate, 0, 2);
		world.setBlock(i + 11, j + 3, k + 12, Blocks.air, 0, 2);
		world.setBlock(i + 12, j + 3, k + 12, Blocks.air, 0, 2);
		world.setBlock(i + 13, j + 3, k + 12, Blocks.air, 0, 2);
		world.setBlock(i + 14, j + 3, k + 12, Blocks.air, 0, 2);
		world.setBlock(i + 15, j + 3, k + 12, Blocks.packed_ice, 0, 2);
		world.setBlock(i + 16, j + 3, k + 12, PlaceBlueIce, 0, 2);
		world.setBlock(i + 17, j + 3, k + 12, PlaceCobbledDeepslate, 0, 2);
		world.setBlock(i + 18, j + 3, k + 12, Blocks.air, 0, 2);
		world.setBlock(i + 0, j + 3, k + 13, Blocks.air, 0, 2);
		world.setBlock(i + 1, j + 3, k + 13, Blocks.air, 0, 2);
		world.setBlock(i + 2, j + 3, k + 13, Blocks.air, 0, 2);
		world.setBlock(i + 3, j + 3, k + 13, Blocks.air, 0, 2);
		world.setBlock(i + 4, j + 3, k + 13, PlaceDeepslateBricks, 0, 2);
		world.setBlock(i + 5, j + 3, k + 13, PlaceCobbledDeepslate, 0, 2);
		world.setBlock(i + 6, j + 3, k + 13, PlaceCobbledDeepslate, 0, 2);
		world.setBlock(i + 7, j + 3, k + 13, PlaceCobbledDeepslate, 0, 2);
		world.setBlock(i + 8, j + 3, k + 13, PlaceCobbledDeepslate, 0, 2);
		world.setBlock(i + 9, j + 3, k + 13, Blocks.air, 0, 2);
		world.setBlock(i + 10, j + 3, k + 13, PlaceCobbledDeepslate, 0, 2);
		world.setBlock(i + 11, j + 3, k + 13, PlaceCobbledDeepslate, 0, 2);
		world.setBlock(i + 12, j + 3, k + 13, PlaceCobbledDeepslate, 0, 2);
		world.setBlock(i + 13, j + 3, k + 13, PlaceCobbledDeepslate, 0, 2);
		world.setBlock(i + 14, j + 3, k + 13, PlaceCobbledDeepslate, 0, 2);
		world.setBlock(i + 15, j + 3, k + 13, PlaceCobbledDeepslate, 0, 2);
		world.setBlock(i + 16, j + 3, k + 13, PlaceCobbledDeepslate, 0, 2);
		world.setBlock(i + 17, j + 3, k + 13, PlaceCobbledDeepslate, 0, 2);
		world.setBlock(i + 18, j + 3, k + 13, PlaceCobbledDeepslate, 0, 2);
		world.setBlock(i + 0, j + 3, k + 14, Blocks.air, 0, 2);
		world.setBlock(i + 1, j + 3, k + 14, PlaceDeepslateBricks, 0, 2);
		world.setBlock(i + 2, j + 3, k + 14, Blocks.air, 0, 2);
		world.setBlock(i + 3, j + 3, k + 14, PlaceDeepslateBricks, 0, 2);
		world.setBlock(i + 4, j + 3, k + 14, Blocks.air, 0, 2);
		world.setBlock(i + 5, j + 3, k + 14, PlaceCobbledDeepslate, 0, 2);
		world.setBlock(i + 6, j + 3, k + 14, PlaceCobbledDeepslate, 0, 2);
		world.setBlock(i + 7, j + 3, k + 14, Blocks.air, 0, 2);
		world.setBlock(i + 8, j + 3, k + 14, Blocks.air, 0, 2);
		world.setBlock(i + 9, j + 3, k + 14, Blocks.air, 0, 2);
		world.setBlock(i + 10, j + 3, k + 14, Blocks.air, 0, 2);
		world.setBlock(i + 11, j + 3, k + 14, PlaceCobbledDeepslate, 0, 2);
		world.setBlock(i + 12, j + 3, k + 14, PlaceCobbledDeepslate, 0, 2);
		world.setBlock(i + 13, j + 3, k + 14, PlaceCobbledDeepslate, 0, 2);
		world.setBlock(i + 14, j + 3, k + 14, PlaceCobbledDeepslate, 0, 2);
		world.setBlock(i + 15, j + 3, k + 14, PlaceCobbledDeepslate, 0, 2);
		world.setBlock(i + 16, j + 3, k + 14, PlaceCobbledDeepslate, 0, 2);
		world.setBlock(i + 17, j + 3, k + 14, PlaceCobbledDeepslate, 0, 2);
		world.setBlock(i + 18, j + 3, k + 14, Blocks.air, 0, 2);
		world.setBlock(i + 0, j + 3, k + 15, Blocks.air, 0, 2);
		world.setBlock(i + 1, j + 3, k + 15, PlaceDeepslateBricks, 0, 2);
		world.setBlock(i + 2, j + 3, k + 15, PlaceDeepslateBricks, 0, 2);
		world.setBlock(i + 3, j + 3, k + 15, PlaceDeepslateBricks, 0, 2);
		world.setBlock(i + 4, j + 3, k + 15, Blocks.air, 0, 2);
		world.setBlock(i + 5, j + 3, k + 15, Blocks.air, 0, 2);
		world.setBlock(i + 6, j + 3, k + 15, Blocks.air, 0, 2);
		world.setBlock(i + 7, j + 3, k + 15, Blocks.air, 0, 2);
		world.setBlock(i + 8, j + 3, k + 15, Blocks.air, 0, 2);
		world.setBlock(i + 9, j + 3, k + 15, Blocks.air, 0, 2);
		world.setBlock(i + 10, j + 3, k + 15, Blocks.air, 0, 2);
		world.setBlock(i + 11, j + 3, k + 15, Blocks.air, 0, 2);
		world.setBlock(i + 12, j + 3, k + 15, Blocks.air, 0, 2);
		world.setBlock(i + 13, j + 3, k + 15, Blocks.air, 0, 2);
		world.setBlock(i + 14, j + 3, k + 15, Blocks.air, 0, 2);
		world.setBlock(i + 15, j + 3, k + 15, Blocks.air, 0, 2);
		world.setBlock(i + 16, j + 3, k + 15, Blocks.air, 0, 2);
		world.setBlock(i + 17, j + 3, k + 15, Blocks.air, 0, 2);
		world.setBlock(i + 18, j + 3, k + 15, Blocks.air, 0, 2);
		world.setBlock(i + 0, j + 4, k + 0, Blocks.air, 0, 2);
		world.setBlock(i + 1, j + 4, k + 0, Blocks.air, 0, 2);
		world.setBlock(i + 2, j + 4, k + 0, NovaCraftBlocks.sculk_vein, 2, 2);
		world.setBlock(i + 3, j + 4, k + 0, Blocks.air, 0, 2);
		world.setBlock(i + 4, j + 4, k + 0, Blocks.air, 0, 2);
		world.setBlock(i + 5, j + 4, k + 0, Blocks.air, 0, 2);
		world.setBlock(i + 6, j + 4, k + 0, Blocks.air, 0, 2);
		world.setBlock(i + 7, j + 4, k + 0, Blocks.air, 0, 2);
		world.setBlock(i + 8, j + 4, k + 0, Blocks.air, 0, 2);
		world.setBlock(i + 9, j + 4, k + 0, Blocks.air, 0, 2);
		world.setBlock(i + 10, j + 4, k + 0, Blocks.air, 0, 2);
		world.setBlock(i + 11, j + 4, k + 0, Blocks.air, 0, 2);
		world.setBlock(i + 12, j + 4, k + 0, Blocks.air, 0, 2);
		world.setBlock(i + 13, j + 4, k + 0, Blocks.air, 0, 2);
		world.setBlock(i + 14, j + 4, k + 0, Blocks.air, 0, 2);
		world.setBlock(i + 15, j + 4, k + 0, Blocks.air, 0, 2);
		world.setBlock(i + 16, j + 4, k + 0, Blocks.air, 0, 2);
		world.setBlock(i + 17, j + 4, k + 0, Blocks.air, 0, 2);
		world.setBlock(i + 18, j + 4, k + 0, Blocks.air, 0, 2);
		world.setBlock(i + 0, j + 4, k + 1, Blocks.air, 0, 2);
		world.setBlock(i + 1, j + 4, k + 1, PlaceDeepslateBricks, 0, 2);
		world.setBlock(i + 2, j + 4, k + 1, PlaceDeepslateBricks, 0, 2);
		world.setBlock(i + 3, j + 4, k + 1, NovaCraftBlocks.sculk_block, 0, 2);
		world.setBlock(i + 4, j + 4, k + 1, Blocks.air, 0, 2);
		world.setBlock(i + 5, j + 4, k + 1, Blocks.air, 0, 2);
		world.setBlock(i + 6, j + 4, k + 1, Blocks.air, 0, 2);
		world.setBlock(i + 7, j + 4, k + 1, Blocks.air, 0, 2);
		world.setBlock(i + 8, j + 4, k + 1, Blocks.air, 0, 2);
		world.setBlock(i + 9, j + 4, k + 1, Blocks.air, 0, 2);
		world.setBlock(i + 10, j + 4, k + 1, Blocks.air, 0, 2);
		world.setBlock(i + 11, j + 4, k + 1, Blocks.air, 0, 2);
		world.setBlock(i + 12, j + 4, k + 1, Blocks.air, 0, 2);
		world.setBlock(i + 13, j + 4, k + 1, Blocks.air, 0, 2);
		world.setBlock(i + 14, j + 4, k + 1, Blocks.air, 0, 2);
		world.setBlock(i + 15, j + 4, k + 1, Blocks.air, 0, 2);
		world.setBlock(i + 16, j + 4, k + 1, Blocks.air, 0, 2);
		world.setBlock(i + 17, j + 4, k + 1, Blocks.air, 0, 2);
		world.setBlock(i + 18, j + 4, k + 1, Blocks.air, 0, 2);
		world.setBlock(i + 0, j + 4, k + 2, Blocks.air, 0, 2);
		world.setBlock(i + 1, j + 4, k + 2, PlaceDeepslateBricks, 0, 2);
		world.setBlock(i + 2, j + 4, k + 2, PlaceDeepslateBricks, 0, 2);
		world.setBlock(i + 3, j + 4, k + 2, NovaCraftBlocks.sculk_block, 0, 2);
		world.setBlock(i + 4, j + 4, k + 2, Blocks.air, 0, 2);
		world.setBlock(i + 5, j + 4, k + 2, NovaCraftBlocks.sculk_spike, 1, 2);
		world.setBlock(i + 6, j + 4, k + 2, NovaCraftBlocks.sculk_spike, 1, 2);
		world.setBlock(i + 7, j + 4, k + 2, Blocks.air, 0, 2);
		world.setBlock(i + 8, j + 4, k + 2, Blocks.air, 0, 2);
		world.setBlock(i + 9, j + 4, k + 2, Blocks.air, 0, 2);
		world.setBlock(i + 10, j + 4, k + 2, Blocks.air, 0, 2);
		world.setBlock(i + 11, j + 4, k + 2, PlaceCobbledDeepslate, 0, 2);
		world.setBlock(i + 12, j + 4, k + 2, PlaceCobbledDeepslate, 0, 2);
		world.setBlock(i + 13, j + 4, k + 2, PlaceCobbledDeepslate, 0, 2);
		world.setBlock(i + 14, j + 4, k + 2, Blocks.air, 0, 2);
		world.setBlock(i + 15, j + 4, k + 2, PlaceCobbledDeepslate, 0, 2);
		world.setBlock(i + 16, j + 4, k + 2, PlaceCobbledDeepslate, 0, 2);
		world.setBlock(i + 17, j + 4, k + 2, PlaceCobbledDeepslate, 0, 2);
		world.setBlock(i + 18, j + 4, k + 2, Blocks.air, 0, 2);
		world.setBlock(i + 0, j + 4, k + 3, Blocks.air, 0, 2);
		world.setBlock(i + 1, j + 4, k + 3, Blocks.air, 0, 2);
		world.setBlock(i + 2, j + 4, k + 3, NovaCraftBlocks.sculk_vein, 3, 2);
		world.setBlock(i + 3, j + 4, k + 3, Blocks.air, 0, 2);
		world.setBlock(i + 4, j + 4, k + 3, NovaCraftBlocks.sculk_spike, 1, 2);
		world.setBlock(i + 5, j + 4, k + 3, NovaCraftBlocks.sculk_block, 0, 2);
		world.setBlock(i + 6, j + 4, k + 3, NovaCraftBlocks.sculk_block, 0, 2);
		world.setBlock(i + 7, j + 4, k + 3, NovaCraftBlocks.sculk_block, 0, 2);
		world.setBlock(i + 8, j + 4, k + 3, PlaceDeepslateBricks, 0, 2);
		world.setBlock(i + 9, j + 4, k + 3, PlaceCobbledDeepslate, 0, 2);
		world.setBlock(i + 10, j + 4, k + 3, PlaceCobbledDeepslate, 0, 2);
		world.setBlock(i + 11, j + 4, k + 3, PlaceDeepslateBricks, 0, 2);
		world.setBlock(i + 12, j + 4, k + 3, PlaceCobbledDeepslate, 0, 2);
		world.setBlock(i + 13, j + 4, k + 3, PlaceCobbledDeepslate, 0, 2);
		world.setBlock(i + 14, j + 4, k + 3, PlaceCobbledDeepslate, 0, 2);
		world.setBlock(i + 15, j + 4, k + 3, PlaceCobbledDeepslate, 0, 2);
		world.setBlock(i + 16, j + 4, k + 3, PlaceCobbledDeepslate, 0, 2);
		world.setBlock(i + 17, j + 4, k + 3, PlaceCobbledDeepslate, 0, 2);
		world.setBlock(i + 18, j + 4, k + 3, PlaceCobbledDeepslate, 0, 2);
		world.setBlock(i + 0, j + 4, k + 4, Blocks.air, 0, 2);
		world.setBlock(i + 1, j + 4, k + 4, Blocks.air, 0, 2);
		world.setBlock(i + 2, j + 4, k + 4, Blocks.air, 0, 2);
		world.setBlock(i + 3, j + 4, k + 4, NovaCraftBlocks.sculk_vein, 1, 2);
		world.setBlock(i + 4, j + 4, k + 4, NovaCraftBlocks.sculk_vein, 1, 2);
		world.setBlock(i + 5, j + 4, k + 4, NovaCraftBlocks.sculk_block, 0, 2);
		world.setBlock(i + 6, j + 4, k + 4, NovaCraftBlocks.sculk_block, 0, 2);
		world.setBlock(i + 7, j + 4, k + 4, NovaCraftBlocks.sculk_block, 0, 2);
		world.setBlock(i + 8, j + 4, k + 4, NovaCraftBlocks.sculk_block, 0, 2);
		world.setBlock(i + 9, j + 4, k + 4, NovaCraftBlocks.sculk_block, 0, 2);
		world.setBlock(i + 10, j + 4, k + 4, NovaCraftBlocks.sculk_block, 0, 2);
		world.setBlock(i + 11, j + 4, k + 4, PlaceDeepslateTiles, 2, 2);
		world.setBlock(i + 12, j + 4, k + 4, PlaceDeepslateTiles, 2, 2);
		world.setBlock(i + 13, j + 4, k + 4, NovaCraftBlocks.sculk_block, 0, 2);
		world.setBlock(i + 14, j + 4, k + 4, PlaceDeepslateTiles, 2, 2);
		world.setBlock(i + 15, j + 4, k + 4, PlaceDeepslateTiles, 2, 2);
		world.setBlock(i + 16, j + 4, k + 4, PlaceDeepslateTiles, 2, 2);
		world.setBlock(i + 17, j + 4, k + 4, PlaceCobbledDeepslate, 0, 2);
		world.setBlock(i + 18, j + 4, k + 4, PlaceCobbledDeepslate, 0, 2);
		world.setBlock(i + 0, j + 4, k + 5, Blocks.air, 0, 2);
		world.setBlock(i + 1, j + 4, k + 5, Blocks.air, 0, 2);
		world.setBlock(i + 2, j + 4, k + 5, Blocks.air, 0, 2);
		world.setBlock(i + 3, j + 4, k + 5, Blocks.air, 0, 2);
		world.setBlock(i + 4, j + 4, k + 5, NovaCraftBlocks.sculk_block, 0, 2);
		world.setBlock(i + 5, j + 4, k + 5, PlaceCobbledDeepslate, 0, 2);
		world.setBlock(i + 6, j + 4, k + 5, PlaceCobbledDeepslate, 0, 2);
		world.setBlock(i + 7, j + 4, k + 5, NovaCraftBlocks.sculk_block, 0, 2);
		world.setBlock(i + 8, j + 4, k + 5, NovaCraftBlocks.sculk_block, 0, 2);
		world.setBlock(i + 9, j + 4, k + 5, NovaCraftBlocks.sculk_block, 0, 2);
		world.setBlock(i + 10, j + 4, k + 5, NovaCraftBlocks.sculk_block, 0, 2);
		world.setBlock(i + 11, j + 4, k + 5, PlaceIronTrapdoor, 9, 2);
		world.setBlock(i + 12, j + 4, k + 5, PlaceDeepslateTiles, 2, 2);
		world.setBlock(i + 13, j + 4, k + 5, NovaCraftBlocks.sculk_block, 0, 2);
		world.setBlock(i + 14, j + 4, k + 5, NovaCraftBlocks.sculk_block, 0, 2);
		world.setBlock(i + 15, j + 4, k + 5, NovaCraftBlocks.sculk_block, 0, 2);
		world.setBlock(i + 16, j + 4, k + 5, PlaceDeepslateTiles, 2, 2);
		world.setBlock(i + 17, j + 4, k + 5, PlaceCobbledDeepslate, 0, 2);
		world.setBlock(i + 18, j + 4, k + 5, PlaceCobbledDeepslate, 0, 2);
		world.setBlock(i + 0, j + 4, k + 6, Blocks.air, 0, 2);
		world.setBlock(i + 1, j + 4, k + 6, Blocks.air, 0, 2);
		world.setBlock(i + 2, j + 4, k + 6, Blocks.air, 0, 2);
		world.setBlock(i + 3, j + 4, k + 6, NovaCraftBlocks.sculk_vein, 4, 2);
		world.setBlock(i + 4, j + 4, k + 6, PlaceDeepslateTiles, 2, 2);
		world.setBlock(i + 5, j + 4, k + 6, PlaceDeepslateTiles, 2, 2);
		world.setBlock(i + 6, j + 4, k + 6, NovaCraftBlocks.sculk_block, 0, 2);
		world.setBlock(i + 7, j + 4, k + 6, NovaCraftBlocks.sculk_block, 0, 2);
		world.setBlock(i + 8, j + 4, k + 6, PlaceDeepslateTiles, 2, 2);
		world.setBlock(i + 9, j + 4, k + 6, NovaCraftBlocks.sculk_block, 0, 2);
		world.setBlock(i + 10, j + 4, k + 6, NovaCraftBlocks.sculk_block, 0, 2);
		world.setBlock(i + 11, j + 4, k + 6, PlaceBasalt, 1, 2);
		world.setBlock(i + 12, j + 4, k + 6, NovaCraftBlocks.sculk_block, 0, 2);
		world.setBlock(i + 13, j + 4, k + 6, PlaceDeepslateTiles, 2, 2);
		world.setBlock(i + 14, j + 4, k + 6, NovaCraftBlocks.sculk_block, 0, 2);
		world.setBlock(i + 15, j + 4, k + 6, NovaCraftBlocks.sculk_block, 0, 2);
		world.setBlock(i + 16, j + 4, k + 6, NovaCraftBlocks.sculk_block, 0, 2);
		world.setBlock(i + 17, j + 4, k + 6, PlaceCobbledDeepslate, 0, 2);
		world.setBlock(i + 18, j + 4, k + 6, PlaceCobbledDeepslate, 0, 2);
		world.setBlock(i + 0, j + 4, k + 7, Blocks.air, 0, 2);
		world.setBlock(i + 1, j + 4, k + 7, Blocks.air, 0, 2);
		world.setBlock(i + 2, j + 4, k + 7, Blocks.air, 0, 2);
		world.setBlock(i + 3, j + 4, k + 7, Blocks.air, 0, 2);
		world.setBlock(i + 4, j + 4, k + 7, Blocks.air, 0, 2);
		world.setBlock(i + 5, j + 4, k + 7, PlaceDeepslateTiles, 2, 2);
		world.setBlock(i + 6, j + 4, k + 7, PlaceDeepslateTiles, 2, 2);
		world.setBlock(i + 7, j + 4, k + 7, NovaCraftBlocks.sculk_block, 0, 2);
		world.setBlock(i + 8, j + 4, k + 7, PlaceDeepslateTiles, 2, 2);
		world.setBlock(i + 9, j + 4, k + 7, NovaCraftBlocks.sculk_block, 0, 2);
		world.setBlock(i + 10, j + 4, k + 7, PlaceDeepslateTiles, 2, 2);
		world.setBlock(i + 11, j + 4, k + 7, NovaCraftBlocks.sculk_block, 0, 2);
		world.setBlock(i + 12, j + 4, k + 7, NovaCraftBlocks.sculk_block, 0, 2);
		world.setBlock(i + 13, j + 4, k + 7, PlaceDeepslateTiles, 2, 2);
		world.setBlock(i + 14, j + 4, k + 7, NovaCraftBlocks.sculk_block, 0, 2);
		world.setBlock(i + 15, j + 4, k + 7, NovaCraftBlocks.sculk_block, 0, 2);
