package com.NovaCraft.world.ancient_city;

import net.minecraft.world.gen.feature.*;
import net.minecraft.block.*;
import net.minecraft.world.*;
import java.util.*;

import com.NovaCraft.registry.OtherModBlocks;
import com.NovaCraftBlocks.NovaCraftBlocks;

import cpw.mods.fml.common.Loader;
import net.minecraft.init.*;

public class AncientCitySupportGen extends WorldGenerator
{
	public AncientCitySupportGen() {

	}
	
	private static final Block cobbled_deepslate = OtherModBlocks.cobbled_deepslate;
	private static final Block deepslate = OtherModBlocks.deepslate;
	private static final Block sculk_block = NovaCraftBlocks.sculk_block;
	private static final Block soul_lantern = OtherModBlocks.soul_lantern; //1
	private static final Block soul_sand = Blocks.netherrack;
	
	private static final Block polished_deepslate = OtherModBlocks.polished_deepslate;
	private static final Block deepslate_brick_slab = OtherModBlocks.deepslate_brick_slab;
	private static final Block deepslate_tile_stairs = OtherModBlocks.deepslate_tile_stairs;
	private static final Block deepslate_brick_stairs = OtherModBlocks.deepslate_brick_stairs;
	private static final Block polished_deepslate_stairs = OtherModBlocks.polished_deepslate_stairs;
	private static final Block deepslate_wall = OtherModBlocks.deepslate_wall;
	private static final Block fence_dark_oak = OtherModBlocks.fence_dark_oak;
	private static final Block blue_ice = OtherModBlocks.blue_ice;
	private static final Block iron_trapdoor = OtherModBlocks.iron_trapdoor;
	
	private static final Block deepslate_bricks = OtherModBlocks.deepslate_bricks;
	private static final Block cobbled_deepslate_stairs = OtherModBlocks.cobbled_deepslate_stairs;
	
	private static final Block basalt = OtherModBlocks.Basalt; //netherlicious
	private static final Block basalt1 = OtherModBlocks.basalt; //et futurum requiem

	//0 -> deepslate bricks
	//1 -> cracked deepslate bricks
	//2 -> deepslate tiles
	//3 -> cracked deepslate bricks
	//4 -> chiseled deepslate bricks
    
    public boolean generate(final World world, final Random random, final int i, final int j, final int k) {
    	

		world.setBlock(i + 0, j + 0, k + 0, sculk_block, 0, 2);
		world.setBlock(i + 1, j + 0, k + 0, sculk_block, 0, 2);
		world.setBlock(i + 2, j + 0, k + 0, sculk_block, 0, 2);
		world.setBlock(i + 3, j + 0, k + 0, sculk_block, 0, 2);
		world.setBlock(i + 4, j + 0, k + 0, sculk_block, 0, 2);
		world.setBlock(i + 5, j + 0, k + 0, sculk_block, 0, 2);
		world.setBlock(i + 6, j + 0, k + 0, sculk_block, 0, 2);
		world.setBlock(i + 7, j + 0, k + 0, sculk_block, 0, 2);
		world.setBlock(i + 8, j + 0, k + 0, sculk_block, 0, 2);
		world.setBlock(i + 9, j + 0, k + 0, sculk_block, 0, 2);
		world.setBlock(i + 10, j + 0, k + 0, sculk_block, 0, 2);
		world.setBlock(i + 0, j + 0, k + 1, sculk_block, 0, 2);
		world.setBlock(i + 1, j + 0, k + 1, sculk_block, 0, 2);
		world.setBlock(i + 2, j + 0, k + 1, sculk_block, 0, 2);
		world.setBlock(i + 3, j + 0, k + 1, sculk_block, 0, 2);
		world.setBlock(i + 4, j + 0, k + 1, sculk_block, 0, 2);
		world.setBlock(i + 5, j + 0, k + 1, sculk_block, 0, 2);
		world.setBlock(i + 6, j + 0, k + 1, sculk_block, 0, 2);
		world.setBlock(i + 7, j + 0, k + 1, sculk_block, 0, 2);
		world.setBlock(i + 8, j + 0, k + 1, sculk_block, 0, 2);
		world.setBlock(i + 9, j + 0, k + 1, sculk_block, 0, 2);
		world.setBlock(i + 10, j + 0, k + 1, sculk_block, 0, 2);
		world.setBlock(i + 0, j + 0, k + 2, sculk_block, 0, 2);
		world.setBlock(i + 1, j + 0, k + 2, sculk_block, 0, 2);
		world.setBlock(i + 2, j + 0, k + 2, sculk_block, 0, 2);
		world.setBlock(i + 3, j + 0, k + 2, deepslate, 0, 2);
		world.setBlock(i + 4, j + 0, k + 2, deepslate, 0, 2);
		world.setBlock(i + 5, j + 0, k + 2, deepslate, 0, 2);
		world.setBlock(i + 6, j + 0, k + 2, sculk_block, 0, 2);
		world.setBlock(i + 7, j + 0, k + 2, sculk_block, 0, 2);
		world.setBlock(i + 8, j + 0, k + 2, sculk_block, 0, 2);
		world.setBlock(i + 9, j + 0, k + 2, sculk_block, 0, 2);
		world.setBlock(i + 10, j + 0, k + 2, sculk_block, 0, 2);
		world.setBlock(i + 0, j + 0, k + 3, deepslate, 0, 2);
		world.setBlock(i + 1, j + 0, k + 3, deepslate, 0, 2);
		world.setBlock(i + 2, j + 0, k + 3, deepslate, 0, 2);
		world.setBlock(i + 3, j + 0, k + 3, deepslate, 0, 2);
		world.setBlock(i + 4, j + 0, k + 3, deepslate, 0, 2);
		world.setBlock(i + 5, j + 0, k + 3, sculk_block, 0, 2);
		world.setBlock(i + 6, j + 0, k + 3, sculk_block, 0, 2);
		world.setBlock(i + 7, j + 0, k + 3, sculk_block, 0, 2);
		world.setBlock(i + 8, j + 0, k + 3, sculk_block, 0, 2);
		world.setBlock(i + 9, j + 0, k + 3, sculk_block, 0, 2);
		world.setBlock(i + 10, j + 0, k + 3, sculk_block, 0, 2);
		world.setBlock(i + 0, j + 0, k + 4, deepslate, 0, 2);
		world.setBlock(i + 1, j + 0, k + 4, deepslate, 0, 2);
		world.setBlock(i + 2, j + 0, k + 4, deepslate, 0, 2);
		world.setBlock(i + 3, j + 0, k + 4, sculk_block, 0, 2);
		world.setBlock(i + 4, j + 0, k + 4, sculk_block, 0, 2);
		world.setBlock(i + 5, j + 0, k + 4, sculk_block, 0, 2);
		world.setBlock(i + 6, j + 0, k + 4, sculk_block, 0, 2);
		world.setBlock(i + 7, j + 0, k + 4, sculk_block, 0, 2);
		world.setBlock(i + 8, j + 0, k + 4, sculk_block, 0, 2);
		world.setBlock(i + 9, j + 0, k + 4, sculk_block, 0, 2);
		world.setBlock(i + 10, j + 0, k + 4, sculk_block, 0, 2);
		world.setBlock(i + 0, j + 0, k + 5, sculk_block, 0, 2);
		world.setBlock(i + 1, j + 0, k + 5, sculk_block, 0, 2);
		world.setBlock(i + 2, j + 0, k + 5, sculk_block, 0, 2);
		world.setBlock(i + 3, j + 0, k + 5, sculk_block, 0, 2);
		world.setBlock(i + 4, j + 0, k + 5, sculk_block, 0, 2);
		world.setBlock(i + 5, j + 0, k + 5, sculk_block, 0, 2);
		world.setBlock(i + 6, j + 0, k + 5, sculk_block, 0, 2);
		world.setBlock(i + 7, j + 0, k + 5, sculk_block, 0, 2);
		world.setBlock(i + 8, j + 0, k + 5, sculk_block, 0, 2);
		world.setBlock(i + 9, j + 0, k + 5, sculk_block, 0, 2);
		world.setBlock(i + 10, j + 0, k + 5, sculk_block, 0, 2);
		world.setBlock(i + 0, j + 0, k + 6, sculk_block, 0, 2);
		world.setBlock(i + 1, j + 0, k + 6, sculk_block, 0, 2);
		world.setBlock(i + 2, j + 0, k + 6, sculk_block, 0, 2);
		world.setBlock(i + 3, j + 0, k + 6, sculk_block, 0, 2);
		world.setBlock(i + 4, j + 0, k + 6, sculk_block, 0, 2);
		world.setBlock(i + 5, j + 0, k + 6, sculk_block, 0, 2);
		world.setBlock(i + 6, j + 0, k + 6, sculk_block, 0, 2);
		world.setBlock(i + 7, j + 0, k + 6, sculk_block, 0, 2);
		world.setBlock(i + 8, j + 0, k + 6, sculk_block, 0, 2);
		world.setBlock(i + 9, j + 0, k + 6, sculk_block, 0, 2);
		world.setBlock(i + 10, j + 0, k + 6, sculk_block, 0, 2);
		world.setBlock(i + 0, j + 0, k + 7, sculk_block, 0, 2);
		world.setBlock(i + 1, j + 0, k + 7, sculk_block, 0, 2);
		world.setBlock(i + 2, j + 0, k + 7, sculk_block, 0, 2);
		world.setBlock(i + 3, j + 0, k + 7, sculk_block, 0, 2);
		world.setBlock(i + 4, j + 0, k + 7, deepslate, 0, 2);
		world.setBlock(i + 5, j + 0, k + 7, sculk_block, 0, 2);
		world.setBlock(i + 6, j + 0, k + 7, sculk_block, 0, 2);
		world.setBlock(i + 7, j + 0, k + 7, sculk_block, 0, 2);
		world.setBlock(i + 8, j + 0, k + 7, sculk_block, 0, 2);
		world.setBlock(i + 9, j + 0, k + 7, sculk_block, 0, 2);
		world.setBlock(i + 10, j + 0, k + 7, sculk_block, 0, 2);
		world.setBlock(i + 0, j + 0, k + 8, sculk_block, 0, 2);
		world.setBlock(i + 1, j + 0, k + 8, sculk_block, 0, 2);
		world.setBlock(i + 2, j + 0, k + 8, sculk_block, 0, 2);
		world.setBlock(i + 3, j + 0, k + 8, sculk_block, 0, 2);
		world.setBlock(i + 4, j + 0, k + 8, sculk_block, 0, 2);
		world.setBlock(i + 5, j + 0, k + 8, sculk_block, 0, 2);
		world.setBlock(i + 6, j + 0, k + 8, sculk_block, 0, 2);
		world.setBlock(i + 7, j + 0, k + 8, sculk_block, 0, 2);
		world.setBlock(i + 8, j + 0, k + 8, sculk_block, 0, 2);
		world.setBlock(i + 9, j + 0, k + 8, sculk_block, 0, 2);
		world.setBlock(i + 10, j + 0, k + 8, sculk_block, 0, 2);
		world.setBlock(i + 0, j + 0, k + 9, sculk_block, 0, 2);
		world.setBlock(i + 1, j + 0, k + 9, sculk_block, 0, 2);
		world.setBlock(i + 2, j + 0, k + 9, sculk_block, 0, 2);
		world.setBlock(i + 3, j + 0, k + 9, sculk_block, 0, 2);
		world.setBlock(i + 4, j + 0, k + 9, sculk_block, 0, 2);
		world.setBlock(i + 5, j + 0, k + 9, sculk_block, 0, 2);
		world.setBlock(i + 6, j + 0, k + 9, sculk_block, 0, 2);
		world.setBlock(i + 7, j + 0, k + 9, sculk_block, 0, 2);
		world.setBlock(i + 8, j + 0, k + 9, sculk_block, 0, 2);
		world.setBlock(i + 9, j + 0, k + 9, sculk_block, 0, 2);
		world.setBlock(i + 10, j + 0, k + 9, sculk_block, 0, 2);
		world.setBlock(i + 0, j + 0, k + 10, sculk_block, 0, 2);
		world.setBlock(i + 1, j + 0, k + 10, sculk_block, 0, 2);
		world.setBlock(i + 2, j + 0, k + 10, sculk_block, 0, 2);
		world.setBlock(i + 3, j + 0, k + 10, sculk_block, 0, 2);
		world.setBlock(i + 4, j + 0, k + 10, sculk_block, 0, 2);
		world.setBlock(i + 5, j + 0, k + 10, sculk_block, 0, 2);
		world.setBlock(i + 6, j + 0, k + 10, sculk_block, 0, 2);
		world.setBlock(i + 7, j + 0, k + 10, sculk_block, 0, 2);
		world.setBlock(i + 8, j + 0, k + 10, sculk_block, 0, 2);
		world.setBlock(i + 9, j + 0, k + 10, sculk_block, 0, 2);
		world.setBlock(i + 10, j + 0, k + 10, sculk_block, 0, 2);
		world.setBlock(i + 3, j + 1, k + 1, deepslate, 0, 2);
		world.setBlock(i + 4, j + 1, k + 1, deepslate, 0, 2);
		world.setBlock(i + 5, j + 1, k + 1, deepslate, 0, 2);
		world.setBlock(i + 6, j + 1, k + 1, deepslate, 0, 2);
		world.setBlock(i + 7, j + 1, k + 1, deepslate, 0, 2);
		world.setBlock(i + 2, j + 1, k + 2, deepslate, 0, 2);
		world.setBlock(i + 3, j + 1, k + 2, deepslate, 0, 2);
		world.setBlock(i + 4, j + 1, k + 2, deepslate, 0, 2);
		world.setBlock(i + 5, j + 1, k + 2, deepslate, 0, 2);
		world.setBlock(i + 6, j + 1, k + 2, deepslate, 0, 2);
		world.setBlock(i + 7, j + 1, k + 2, deepslate, 0, 2);
		world.setBlock(i + 8, j + 1, k + 2, deepslate, 0, 2);
		world.setBlock(i + 1, j + 1, k + 3, deepslate, 0, 2);
		world.setBlock(i + 2, j + 1, k + 3, deepslate, 0, 2);
		world.setBlock(i + 3, j + 1, k + 3, deepslate, 0, 2);
		world.setBlock(i + 4, j + 1, k + 3, deepslate, 0, 2);
		world.setBlock(i + 5, j + 1, k + 3, deepslate, 0, 2);
		world.setBlock(i + 6, j + 1, k + 3, deepslate, 0, 2);
		world.setBlock(i + 7, j + 1, k + 3, deepslate, 0, 2);
		world.setBlock(i + 8, j + 1, k + 3, deepslate, 0, 2);
		world.setBlock(i + 9, j + 1, k + 3, deepslate, 0, 2);
		world.setBlock(i + 1, j + 1, k + 4, deepslate, 0, 2);
		world.setBlock(i + 2, j + 1, k + 4, deepslate, 0, 2);
		world.setBlock(i + 3, j + 1, k + 4, deepslate, 0, 2);
		world.setBlock(i + 4, j + 1, k + 4, deepslate, 0, 2);
		world.setBlock(i + 5, j + 1, k + 4, deepslate, 0, 2);
		world.setBlock(i + 6, j + 1, k + 4, deepslate, 0, 2);
		world.setBlock(i + 7, j + 1, k + 4, deepslate, 0, 2);
		world.setBlock(i + 8, j + 1, k + 4, deepslate, 0, 2);
		world.setBlock(i + 9, j + 1, k + 4, deepslate, 0, 2);
		world.setBlock(i + 1, j + 1, k + 5, deepslate, 0, 2);
		world.setBlock(i + 2, j + 1, k + 5, deepslate, 0, 2);
		world.setBlock(i + 3, j + 1, k + 5, deepslate, 0, 2);
		world.setBlock(i + 4, j + 1, k + 5, deepslate, 0, 2);
		world.setBlock(i + 5, j + 1, k + 5, deepslate, 0, 2);
		world.setBlock(i + 6, j + 1, k + 5, deepslate, 0, 2);
		world.setBlock(i + 7, j + 1, k + 5, deepslate, 0, 2);
		world.setBlock(i + 8, j + 1, k + 5, deepslate, 0, 2);
		world.setBlock(i + 9, j + 1, k + 5, deepslate, 0, 2);
		world.setBlock(i + 1, j + 1, k + 6, deepslate, 0, 2);
		world.setBlock(i + 2, j + 1, k + 6, deepslate, 0, 2);
		world.setBlock(i + 3, j + 1, k + 6, deepslate, 0, 2);
		world.setBlock(i + 4, j + 1, k + 6, deepslate, 0, 2);
		world.setBlock(i + 5, j + 1, k + 6, deepslate, 0, 2);
		world.setBlock(i + 6, j + 1, k + 6, deepslate, 0, 2);
		world.setBlock(i + 7, j + 1, k + 6, deepslate, 0, 2);
		world.setBlock(i + 8, j + 1, k + 6, deepslate, 0, 2);
		world.setBlock(i + 9, j + 1, k + 6, deepslate, 0, 2);
		world.setBlock(i + 1, j + 1, k + 7, deepslate, 0, 2);
		world.setBlock(i + 2, j + 1, k + 7, deepslate, 0, 2);
		world.setBlock(i + 3, j + 1, k + 7, deepslate, 0, 2);
		world.setBlock(i + 4, j + 1, k + 7, deepslate, 0, 2);
		world.setBlock(i + 5, j + 1, k + 7, deepslate, 0, 2);
		world.setBlock(i + 6, j + 1, k + 7, deepslate, 0, 2);
		world.setBlock(i + 7, j + 1, k + 7, deepslate, 0, 2);
		world.setBlock(i + 8, j + 1, k + 7, deepslate, 0, 2);
		world.setBlock(i + 9, j + 1, k + 7, deepslate, 0, 2);
		world.setBlock(i + 2, j + 1, k + 8, deepslate, 0, 2);
		world.setBlock(i + 3, j + 1, k + 8, deepslate, 0, 2);
		world.setBlock(i + 4, j + 1, k + 8, deepslate, 0, 2);
		world.setBlock(i + 5, j + 1, k + 8, deepslate, 0, 2);
		world.setBlock(i + 6, j + 1, k + 8, deepslate, 0, 2);
		world.setBlock(i + 7, j + 1, k + 8, deepslate, 0, 2);
		world.setBlock(i + 8, j + 1, k + 8, deepslate, 0, 2);
		world.setBlock(i + 3, j + 1, k + 9, deepslate, 0, 2);
		world.setBlock(i + 4, j + 1, k + 9, deepslate, 0, 2);
		world.setBlock(i + 5, j + 1, k + 9, deepslate, 0, 2);
		world.setBlock(i + 6, j + 1, k + 9, deepslate, 0, 2);
		world.setBlock(i + 7, j + 1, k + 9, deepslate, 0, 2);
		world.setBlock(i + 3, j + 2, k + 2, deepslate, 0, 2);
		world.setBlock(i + 4, j + 2, k + 2, deepslate, 0, 2);
		world.setBlock(i + 5, j + 2, k + 2, deepslate, 0, 2);
		world.setBlock(i + 6, j + 2, k + 2, deepslate, 0, 2);
		world.setBlock(i + 7, j + 2, k + 2, deepslate, 0, 2);
		world.setBlock(i + 2, j + 2, k + 3, deepslate, 0, 2);
		world.setBlock(i + 3, j + 2, k + 3, deepslate, 0, 2);
		world.setBlock(i + 4, j + 2, k + 3, deepslate, 0, 2);
		world.setBlock(i + 5, j + 2, k + 3, deepslate, 0, 2);
		world.setBlock(i + 6, j + 2, k + 3, deepslate, 0, 2);
		world.setBlock(i + 7, j + 2, k + 3, deepslate, 0, 2);
		world.setBlock(i + 8, j + 2, k + 3, deepslate, 0, 2);
		world.setBlock(i + 2, j + 2, k + 4, deepslate, 0, 2);
		world.setBlock(i + 3, j + 2, k + 4, deepslate, 0, 2);
		world.setBlock(i + 4, j + 2, k + 4, deepslate, 0, 2);
		world.setBlock(i + 5, j + 2, k + 4, deepslate, 0, 2);
		world.setBlock(i + 6, j + 2, k + 4, deepslate, 0, 2);
		world.setBlock(i + 7, j + 2, k + 4, deepslate, 0, 2);
		world.setBlock(i + 8, j + 2, k + 4, deepslate, 0, 2);
		world.setBlock(i + 2, j + 2, k + 5, deepslate, 0, 2);
		world.setBlock(i + 3, j + 2, k + 5, deepslate, 0, 2);
		world.setBlock(i + 4, j + 2, k + 5, deepslate, 0, 2);
		world.setBlock(i + 5, j + 2, k + 5, deepslate, 0, 2);
		world.setBlock(i + 6, j + 2, k + 5, deepslate, 0, 2);
		world.setBlock(i + 7, j + 2, k + 5, deepslate, 0, 2);
		world.setBlock(i + 8, j + 2, k + 5, deepslate, 0, 2);
		world.setBlock(i + 2, j + 2, k + 6, deepslate, 0, 2);
		world.setBlock(i + 3, j + 2, k + 6, deepslate, 0, 2);
		world.setBlock(i + 4, j + 2, k + 6, deepslate, 0, 2);
		world.setBlock(i + 5, j + 2, k + 6, deepslate, 0, 2);
		world.setBlock(i + 6, j + 2, k + 6, deepslate, 0, 2);
		world.setBlock(i + 7, j + 2, k + 6, deepslate, 0, 2);
		world.setBlock(i + 8, j + 2, k + 6, deepslate, 0, 2);
		world.setBlock(i + 2, j + 2, k + 7, deepslate, 0, 2);
		world.setBlock(i + 3, j + 2, k + 7, deepslate, 0, 2);
		world.setBlock(i + 4, j + 2, k + 7, deepslate, 0, 2);
		world.setBlock(i + 5, j + 2, k + 7, deepslate, 0, 2);
		world.setBlock(i + 6, j + 2, k + 7, deepslate, 0, 2);
		world.setBlock(i + 7, j + 2, k + 7, deepslate, 0, 2);
		world.setBlock(i + 8, j + 2, k + 7, deepslate, 0, 2);
		world.setBlock(i + 3, j + 2, k + 8, deepslate, 0, 2);
		world.setBlock(i + 4, j + 2, k + 8, deepslate, 0, 2);
		world.setBlock(i + 5, j + 2, k + 8, deepslate, 0, 2);
		world.setBlock(i + 6, j + 2, k + 8, deepslate, 0, 2);
		world.setBlock(i + 7, j + 2, k + 8, deepslate, 0, 2);
		world.setBlock(i + 3, j + 3, k + 3, deepslate, 0, 2);
		world.setBlock(i + 4, j + 3, k + 3, deepslate, 0, 2);
		world.setBlock(i + 5, j + 3, k + 3, deepslate, 0, 2);
		world.setBlock(i + 6, j + 3, k + 3, deepslate, 0, 2);
		world.setBlock(i + 7, j + 3, k + 3, deepslate, 0, 2);
		world.setBlock(i + 3, j + 3, k + 4, deepslate, 0, 2);
		world.setBlock(i + 4, j + 3, k + 4, deepslate, 0, 2);
		world.setBlock(i + 5, j + 3, k + 4, deepslate, 0, 2);
		world.setBlock(i + 6, j + 3, k + 4, deepslate, 0, 2);
		world.setBlock(i + 7, j + 3, k + 4, deepslate, 0, 2);
		world.setBlock(i + 3, j + 3, k + 5, deepslate, 0, 2);
		world.setBlock(i + 4, j + 3, k + 5, deepslate, 0, 2);
		world.setBlock(i + 5, j + 3, k + 5, deepslate, 0, 2);
		world.setBlock(i + 6, j + 3, k + 5, deepslate, 0, 2);
		world.setBlock(i + 7, j + 3, k + 5, deepslate, 0, 2);
		world.setBlock(i + 3, j + 3, k + 6, deepslate, 0, 2);
		world.setBlock(i + 4, j + 3, k + 6, deepslate, 0, 2);
		world.setBlock(i + 5, j + 3, k + 6, deepslate, 0, 2);
		world.setBlock(i + 6, j + 3, k + 6, deepslate, 0, 2);
		world.setBlock(i + 7, j + 3, k + 6, deepslate, 0, 2);
		world.setBlock(i + 3, j + 3, k + 7, deepslate, 0, 2);
		world.setBlock(i + 4, j + 3, k + 7, deepslate, 0, 2);
		world.setBlock(i + 5, j + 3, k + 7, deepslate, 0, 2);
		world.setBlock(i + 6, j + 3, k + 7, deepslate, 0, 2);
		world.setBlock(i + 7, j + 3, k + 7, deepslate, 0, 2);
		world.setBlock(i + 3, j + 4, k + 3, deepslate, 0, 2);
		world.setBlock(i + 4, j + 4, k + 3, deepslate, 0, 2);
		world.setBlock(i + 5, j + 4, k + 3, deepslate, 0, 2);
		world.setBlock(i + 6, j + 4, k + 3, deepslate, 0, 2);
		world.setBlock(i + 7, j + 4, k + 3, deepslate, 0, 2);
		world.setBlock(i + 3, j + 4, k + 4, deepslate, 0, 2);
		world.setBlock(i + 4, j + 4, k + 4, deepslate, 0, 2);
		world.setBlock(i + 5, j + 4, k + 4, deepslate, 0, 2);
		world.setBlock(i + 6, j + 4, k + 4, deepslate, 0, 2);
		world.setBlock(i + 7, j + 4, k + 4, deepslate, 0, 2);
		world.setBlock(i + 3, j + 4, k + 5, deepslate, 0, 2);
		world.setBlock(i + 4, j + 4, k + 5, deepslate, 0, 2);
		world.setBlock(i + 5, j + 4, k + 5, deepslate, 0, 2);
		world.setBlock(i + 6, j + 4, k + 5, deepslate, 0, 2);
		world.setBlock(i + 7, j + 4, k + 5, deepslate, 0, 2);
		world.setBlock(i + 3, j + 4, k + 6, deepslate, 0, 2);
		world.setBlock(i + 4, j + 4, k + 6, deepslate, 0, 2);
		world.setBlock(i + 5, j + 4, k + 6, deepslate, 0, 2);
		world.setBlock(i + 6, j + 4, k + 6, deepslate, 0, 2);
		world.setBlock(i + 7, j + 4, k + 6, deepslate, 0, 2);
		world.setBlock(i + 3, j + 4, k + 7, deepslate, 0, 2);
		world.setBlock(i + 4, j + 4, k + 7, deepslate, 0, 2);
		world.setBlock(i + 5, j + 4, k + 7, deepslate, 0, 2);
		world.setBlock(i + 6, j + 4, k + 7, deepslate, 0, 2);
		world.setBlock(i + 7, j + 4, k + 7, deepslate, 0, 2);
		world.setBlock(i + 3, j + 5, k + 3, deepslate, 0, 2);
		world.setBlock(i + 4, j + 5, k + 3, deepslate, 0, 2);
		world.setBlock(i + 5, j + 5, k + 3, deepslate, 0, 2);
		world.setBlock(i + 6, j + 5, k + 3, deepslate, 0, 2);
		world.setBlock(i + 7, j + 5, k + 3, deepslate, 0, 2);
		world.setBlock(i + 3, j + 5, k + 4, deepslate, 0, 2);
		world.setBlock(i + 4, j + 5, k + 4, deepslate, 0, 2);
		world.setBlock(i + 5, j + 5, k + 4, deepslate, 0, 2);
		world.setBlock(i + 6, j + 5, k + 4, deepslate, 0, 2);
		world.setBlock(i + 7, j + 5, k + 4, deepslate, 0, 2);
		world.setBlock(i + 3, j + 5, k + 5, deepslate, 0, 2);
		world.setBlock(i + 4, j + 5, k + 5, deepslate, 0, 2);
		world.setBlock(i + 5, j + 5, k + 5, deepslate, 0, 2);
		world.setBlock(i + 6, j + 5, k + 5, deepslate, 0, 2);
		world.setBlock(i + 7, j + 5, k + 5, deepslate, 0, 2);
		world.setBlock(i + 3, j + 5, k + 6, deepslate, 0, 2);
		world.setBlock(i + 4, j + 5, k + 6, deepslate, 0, 2);
		world.setBlock(i + 5, j + 5, k + 6, deepslate, 0, 2);
		world.setBlock(i + 6, j + 5, k + 6, deepslate, 0, 2);
		world.setBlock(i + 7, j + 5, k + 6, deepslate, 0, 2);
		world.setBlock(i + 3, j + 5, k + 7, deepslate, 0, 2);
		world.setBlock(i + 4, j + 5, k + 7, deepslate, 0, 2);
		world.setBlock(i + 5, j + 5, k + 7, deepslate, 0, 2);
		world.setBlock(i + 6, j + 5, k + 7, deepslate, 0, 2);
		world.setBlock(i + 7, j + 5, k + 7, deepslate, 0, 2);
		world.setBlock(i + 3, j + 6, k + 3, deepslate, 0, 2);
		world.setBlock(i + 4, j + 6, k + 3, deepslate, 0, 2);
		world.setBlock(i + 5, j + 6, k + 3, deepslate, 0, 2);
		world.setBlock(i + 6, j + 6, k + 3, deepslate, 0, 2);
		world.setBlock(i + 7, j + 6, k + 3, deepslate, 0, 2);
		world.setBlock(i + 3, j + 6, k + 4, deepslate, 0, 2);
		world.setBlock(i + 4, j + 6, k + 4, deepslate, 0, 2);
		world.setBlock(i + 5, j + 6, k + 4, deepslate, 0, 2);
		world.setBlock(i + 6, j + 6, k + 4, deepslate, 0, 2);
		world.setBlock(i + 7, j + 6, k + 4, deepslate, 0, 2);
		world.setBlock(i + 3, j + 6, k + 5, deepslate, 0, 2);
		world.setBlock(i + 4, j + 6, k + 5, deepslate, 0, 2);
		world.setBlock(i + 5, j + 6, k + 5, deepslate, 0, 2);
		world.setBlock(i + 6, j + 6, k + 5, deepslate, 0, 2);
		world.setBlock(i + 7, j + 6, k + 5, deepslate, 0, 2);
		world.setBlock(i + 3, j + 6, k + 6, deepslate, 0, 2);
		world.setBlock(i + 4, j + 6, k + 6, deepslate, 0, 2);
		world.setBlock(i + 5, j + 6, k + 6, deepslate, 0, 2);
		world.setBlock(i + 6, j + 6, k + 6, deepslate, 0, 2);
		world.setBlock(i + 7, j + 6, k + 6, deepslate, 0, 2);
		world.setBlock(i + 3, j + 6, k + 7, deepslate, 0, 2);
		world.setBlock(i + 4, j + 6, k + 7, deepslate, 0, 2);
		world.setBlock(i + 5, j + 6, k + 7, deepslate, 0, 2);
		world.setBlock(i + 6, j + 6, k + 7, deepslate, 0, 2);
		world.setBlock(i + 7, j + 6, k + 7, deepslate, 0, 2);
		world.setBlock(i + 3, j + 7, k + 3, deepslate, 0, 2);
		world.setBlock(i + 4, j + 7, k + 3, deepslate, 0, 2);
		world.setBlock(i + 5, j + 7, k + 3, deepslate, 0, 2);
		world.setBlock(i + 6, j + 7, k + 3, deepslate, 0, 2);
		world.setBlock(i + 7, j + 7, k + 3, deepslate, 0, 2);
		world.setBlock(i + 3, j + 7, k + 4, deepslate, 0, 2);
		world.setBlock(i + 4, j + 7, k + 4, deepslate, 0, 2);
		world.setBlock(i + 5, j + 7, k + 4, deepslate, 0, 2);
		world.setBlock(i + 6, j + 7, k + 4, deepslate, 0, 2);
		world.setBlock(i + 7, j + 7, k + 4, deepslate, 0, 2);
		world.setBlock(i + 3, j + 7, k + 5, deepslate, 0, 2);
		world.setBlock(i + 4, j + 7, k + 5, deepslate, 0, 2);
		world.setBlock(i + 5, j + 7, k + 5, deepslate, 0, 2);
		world.setBlock(i + 6, j + 7, k + 5, deepslate, 0, 2);
		world.setBlock(i + 7, j + 7, k + 5, deepslate, 0, 2);
		world.setBlock(i + 3, j + 7, k + 6, deepslate, 0, 2);
		world.setBlock(i + 4, j + 7, k + 6, deepslate, 0, 2);
		world.setBlock(i + 5, j + 7, k + 6, deepslate, 0, 2);
		world.setBlock(i + 6, j + 7, k + 6, deepslate, 0, 2);
		world.setBlock(i + 7, j + 7, k + 6, deepslate, 0, 2);
		world.setBlock(i + 3, j + 7, k + 7, deepslate, 0, 2);
		world.setBlock(i + 4, j + 7, k + 7, deepslate, 0, 2);
		world.setBlock(i + 5, j + 7, k + 7, deepslate, 0, 2);
		world.setBlock(i + 6, j + 7, k + 7, deepslate, 0, 2);
		world.setBlock(i + 7, j + 7, k + 7, deepslate, 0, 2);
		world.setBlock(i + 3, j + 8, k + 3, deepslate, 0, 2);
		world.setBlock(i + 4, j + 8, k + 3, deepslate, 0, 2);
		world.setBlock(i + 5, j + 8, k + 3, deepslate, 0, 2);
		world.setBlock(i + 6, j + 8, k + 3, deepslate, 0, 2);
		world.setBlock(i + 7, j + 8, k + 3, deepslate, 0, 2);
		world.setBlock(i + 3, j + 8, k + 4, deepslate, 0, 2);
		world.setBlock(i + 4, j + 8, k + 4, deepslate, 0, 2);
		world.setBlock(i + 5, j + 8, k + 4, deepslate, 0, 2);
		world.setBlock(i + 6, j + 8, k + 4, deepslate, 0, 2);
		world.setBlock(i + 7, j + 8, k + 4, deepslate, 0, 2);
		world.setBlock(i + 3, j + 8, k + 5, deepslate, 0, 2);
		world.setBlock(i + 4, j + 8, k + 5, deepslate, 0, 2);
		world.setBlock(i + 5, j + 8, k + 5, deepslate, 0, 2);
		world.setBlock(i + 6, j + 8, k + 5, deepslate, 0, 2);
		world.setBlock(i + 7, j + 8, k + 5, deepslate, 0, 2);
		world.setBlock(i + 3, j + 8, k + 6, deepslate, 0, 2);
		world.setBlock(i + 4, j + 8, k + 6, deepslate, 0, 2);
		world.setBlock(i + 5, j + 8, k + 6, deepslate, 0, 2);
		world.setBlock(i + 6, j + 8, k + 6, deepslate, 0, 2);
		world.setBlock(i + 7, j + 8, k + 6, deepslate, 0, 2);
		world.setBlock(i + 3, j + 8, k + 7, deepslate, 0, 2);
		world.setBlock(i + 4, j + 8, k + 7, deepslate, 0, 2);
		world.setBlock(i + 5, j + 8, k + 7, deepslate, 0, 2);
		world.setBlock(i + 6, j + 8, k + 7, deepslate, 0, 2);
		world.setBlock(i + 7, j + 8, k + 7, deepslate, 0, 2);
		world.setBlock(i + 3, j + 9, k + 3, deepslate, 0, 2);
		world.setBlock(i + 4, j + 9, k + 3, deepslate, 0, 2);
		world.setBlock(i + 5, j + 9, k + 3, deepslate, 0, 2);
		world.setBlock(i + 6, j + 9, k + 3, deepslate, 0, 2);
		world.setBlock(i + 7, j + 9, k + 3, deepslate, 0, 2);
		world.setBlock(i + 3, j + 9, k + 4, deepslate, 0, 2);
		world.setBlock(i + 4, j + 9, k + 4, deepslate, 0, 2);
		world.setBlock(i + 5, j + 9, k + 4, deepslate, 0, 2);
		world.setBlock(i + 6, j + 9, k + 4, deepslate, 0, 2);
		world.setBlock(i + 7, j + 9, k + 4, deepslate, 0, 2);
		world.setBlock(i + 3, j + 9, k + 5, deepslate, 0, 2);
		world.setBlock(i + 4, j + 9, k + 5, deepslate, 0, 2);
		world.setBlock(i + 5, j + 9, k + 5, deepslate, 0, 2);
		world.setBlock(i + 6, j + 9, k + 5, deepslate, 0, 2);
		world.setBlock(i + 7, j + 9, k + 5, deepslate, 0, 2);
		world.setBlock(i + 3, j + 9, k + 6, deepslate, 0, 2);
		world.setBlock(i + 4, j + 9, k + 6, deepslate, 0, 2);
		world.setBlock(i + 5, j + 9, k + 6, deepslate, 0, 2);
		world.setBlock(i + 6, j + 9, k + 6, deepslate, 0, 2);
		world.setBlock(i + 7, j + 9, k + 6, deepslate, 0, 2);
		world.setBlock(i + 3, j + 9, k + 7, deepslate, 0, 2);
		world.setBlock(i + 4, j + 9, k + 7, deepslate, 0, 2);
		world.setBlock(i + 5, j + 9, k + 7, deepslate, 0, 2);
		world.setBlock(i + 6, j + 9, k + 7, deepslate, 0, 2);
		world.setBlock(i + 7, j + 9, k + 7, deepslate, 0, 2);
		world.setBlock(i + 3, j + 10, k + 3, deepslate, 0, 2);
		world.setBlock(i + 4, j + 10, k + 3, deepslate, 0, 2);
		world.setBlock(i + 5, j + 10, k + 3, deepslate, 0, 2);
		world.setBlock(i + 6, j + 10, k + 3, deepslate, 0, 2);
		world.setBlock(i + 7, j + 10, k + 3, deepslate, 0, 2);
		world.setBlock(i + 3, j + 10, k + 4, deepslate, 0, 2);
		world.setBlock(i + 4, j + 10, k + 4, deepslate, 0, 2);
		world.setBlock(i + 5, j + 10, k + 4, deepslate, 0, 2);
		world.setBlock(i + 6, j + 10, k + 4, deepslate, 0, 2);
		world.setBlock(i + 7, j + 10, k + 4, deepslate, 0, 2);
		world.setBlock(i + 3, j + 10, k + 5, deepslate, 0, 2);
		world.setBlock(i + 4, j + 10, k + 5, deepslate, 0, 2);
		world.setBlock(i + 5, j + 10, k + 5, deepslate, 0, 2);
		world.setBlock(i + 6, j + 10, k + 5, deepslate, 0, 2);
		world.setBlock(i + 7, j + 10, k + 5, deepslate, 0, 2);
		world.setBlock(i + 3, j + 10, k + 6, deepslate, 0, 2);
		world.setBlock(i + 4, j + 10, k + 6, deepslate, 0, 2);
		world.setBlock(i + 5, j + 10, k + 6, deepslate, 0, 2);
		world.setBlock(i + 6, j + 10, k + 6, deepslate, 0, 2);
		world.setBlock(i + 7, j + 10, k + 6, deepslate, 0, 2);
		world.setBlock(i + 3, j + 10, k + 7, deepslate, 0, 2);
		world.setBlock(i + 4, j + 10, k + 7, deepslate, 0, 2);
		world.setBlock(i + 5, j + 10, k + 7, deepslate, 0, 2);
		world.setBlock(i + 6, j + 10, k + 7, deepslate, 0, 2);
		world.setBlock(i + 7, j + 10, k + 7, deepslate, 0, 2);
		world.setBlock(i + 3, j + 11, k + 3, deepslate, 0, 2);
		world.setBlock(i + 4, j + 11, k + 3, deepslate, 0, 2);
		world.setBlock(i + 5, j + 11, k + 3, deepslate, 0, 2);
		world.setBlock(i + 6, j + 11, k + 3, deepslate, 0, 2);
		world.setBlock(i + 7, j + 11, k + 3, deepslate, 0, 2);
		world.setBlock(i + 3, j + 11, k + 4, deepslate, 0, 2);
		world.setBlock(i + 4, j + 11, k + 4, deepslate, 0, 2);
		world.setBlock(i + 5, j + 11, k + 4, deepslate, 0, 2);
		world.setBlock(i + 6, j + 11, k + 4, deepslate, 0, 2);
		world.setBlock(i + 7, j + 11, k + 4, deepslate, 0, 2);
		world.setBlock(i + 3, j + 11, k + 5, deepslate, 0, 2);
		world.setBlock(i + 4, j + 11, k + 5, deepslate, 0, 2);
		world.setBlock(i + 5, j + 11, k + 5, deepslate, 0, 2);
		world.setBlock(i + 6, j + 11, k + 5, deepslate, 0, 2);
		world.setBlock(i + 7, j + 11, k + 5, deepslate, 0, 2);
		world.setBlock(i + 3, j + 11, k + 6, deepslate, 0, 2);
		world.setBlock(i + 4, j + 11, k + 6, deepslate, 0, 2);
		world.setBlock(i + 5, j + 11, k + 6, deepslate, 0, 2);
		world.setBlock(i + 6, j + 11, k + 6, deepslate, 0, 2);
		world.setBlock(i + 7, j + 11, k + 6, deepslate, 0, 2);
		world.setBlock(i + 3, j + 11, k + 7, deepslate, 0, 2);
		world.setBlock(i + 4, j + 11, k + 7, deepslate, 0, 2);
		world.setBlock(i + 5, j + 11, k + 7, deepslate, 0, 2);
		world.setBlock(i + 6, j + 11, k + 7, deepslate, 0, 2);
		world.setBlock(i + 7, j + 11, k + 7, deepslate, 0, 2);
		world.setBlock(i + 3, j + 12, k + 3, deepslate, 0, 2);
		world.setBlock(i + 4, j + 12, k + 3, deepslate, 0, 2);
		world.setBlock(i + 5, j + 12, k + 3, deepslate, 0, 2);
		world.setBlock(i + 6, j + 12, k + 3, deepslate, 0, 2);
		world.setBlock(i + 7, j + 12, k + 3, deepslate, 0, 2);
		world.setBlock(i + 3, j + 12, k + 4, deepslate, 0, 2);
		world.setBlock(i + 4, j + 12, k + 4, deepslate, 0, 2);
		world.setBlock(i + 5, j + 12, k + 4, deepslate, 0, 2);
		world.setBlock(i + 6, j + 12, k + 4, deepslate, 0, 2);
		world.setBlock(i + 7, j + 12, k + 4, deepslate, 0, 2);
		world.setBlock(i + 3, j + 12, k + 5, deepslate, 0, 2);
		world.setBlock(i + 4, j + 12, k + 5, deepslate, 0, 2);
		world.setBlock(i + 5, j + 12, k + 5, deepslate, 0, 2);
		world.setBlock(i + 6, j + 12, k + 5, deepslate, 0, 2);
		world.setBlock(i + 7, j + 12, k + 5, deepslate, 0, 2);
		world.setBlock(i + 3, j + 12, k + 6, deepslate, 0, 2);
		world.setBlock(i + 4, j + 12, k + 6, deepslate, 0, 2);
		world.setBlock(i + 5, j + 12, k + 6, deepslate, 0, 2);
		world.setBlock(i + 6, j + 12, k + 6, deepslate, 0, 2);
		world.setBlock(i + 7, j + 12, k + 6, deepslate, 0, 2);
		world.setBlock(i + 3, j + 12, k + 7, deepslate, 0, 2);
		world.setBlock(i + 4, j + 12, k + 7, deepslate, 0, 2);
		world.setBlock(i + 5, j + 12, k + 7, deepslate, 0, 2);
		world.setBlock(i + 6, j + 12, k + 7, deepslate, 0, 2);
		world.setBlock(i + 7, j + 12, k + 7, deepslate, 0, 2);
		world.setBlock(i + 3, j + 13, k + 3, deepslate, 0, 2);
		world.setBlock(i + 4, j + 13, k + 3, deepslate, 0, 2);
		world.setBlock(i + 5, j + 13, k + 3, deepslate, 0, 2);
		world.setBlock(i + 6, j + 13, k + 3, deepslate, 0, 2);
		world.setBlock(i + 7, j + 13, k + 3, deepslate, 0, 2);
		world.setBlock(i + 3, j + 13, k + 4, deepslate, 0, 2);
		world.setBlock(i + 4, j + 13, k + 4, deepslate, 0, 2);
		world.setBlock(i + 5, j + 13, k + 4, deepslate, 0, 2);
		world.setBlock(i + 6, j + 13, k + 4, deepslate, 0, 2);
		world.setBlock(i + 7, j + 13, k + 4, deepslate, 0, 2);
		world.setBlock(i + 3, j + 13, k + 5, deepslate, 0, 2);
		world.setBlock(i + 4, j + 13, k + 5, deepslate, 0, 2);
		world.setBlock(i + 5, j + 13, k + 5, deepslate, 0, 2);
		world.setBlock(i + 6, j + 13, k + 5, deepslate, 0, 2);
		world.setBlock(i + 7, j + 13, k + 5, deepslate, 0, 2);
		world.setBlock(i + 3, j + 13, k + 6, deepslate, 0, 2);
		world.setBlock(i + 4, j + 13, k + 6, deepslate, 0, 2);
		world.setBlock(i + 5, j + 13, k + 6, deepslate, 0, 2);
		world.setBlock(i + 6, j + 13, k + 6, deepslate, 0, 2);
		world.setBlock(i + 7, j + 13, k + 6, deepslate, 0, 2);
		world.setBlock(i + 3, j + 13, k + 7, deepslate, 0, 2);
		world.setBlock(i + 4, j + 13, k + 7, deepslate, 0, 2);
		world.setBlock(i + 5, j + 13, k + 7, deepslate, 0, 2);
		world.setBlock(i + 6, j + 13, k + 7, deepslate, 0, 2);
		world.setBlock(i + 7, j + 13, k + 7, deepslate, 0, 2);
		world.setBlock(i + 3, j + 14, k + 3, deepslate, 0, 2);
		world.setBlock(i + 4, j + 14, k + 3, deepslate, 0, 2);
		world.setBlock(i + 5, j + 14, k + 3, deepslate, 0, 2);
		world.setBlock(i + 6, j + 14, k + 3, deepslate, 0, 2);
		world.setBlock(i + 7, j + 14, k + 3, deepslate, 0, 2);
		world.setBlock(i + 3, j + 14, k + 4, deepslate, 0, 2);
		world.setBlock(i + 4, j + 14, k + 4, deepslate, 0, 2);
		world.setBlock(i + 5, j + 14, k + 4, deepslate, 0, 2);
		world.setBlock(i + 6, j + 14, k + 4, deepslate, 0, 2);
		world.setBlock(i + 7, j + 14, k + 4, deepslate, 0, 2);
		world.setBlock(i + 3, j + 14, k + 5, deepslate, 0, 2);
		world.setBlock(i + 4, j + 14, k + 5, deepslate, 0, 2);
		world.setBlock(i + 5, j + 14, k + 5, deepslate, 0, 2);
		world.setBlock(i + 6, j + 14, k + 5, deepslate, 0, 2);
		world.setBlock(i + 7, j + 14, k + 5, deepslate, 0, 2);
		world.setBlock(i + 3, j + 14, k + 6, deepslate, 0, 2);
		world.setBlock(i + 4, j + 14, k + 6, deepslate, 0, 2);
		world.setBlock(i + 5, j + 14, k + 6, deepslate, 0, 2);
		world.setBlock(i + 6, j + 14, k + 6, deepslate, 0, 2);
		world.setBlock(i + 7, j + 14, k + 6, deepslate, 0, 2);
		world.setBlock(i + 3, j + 14, k + 7, deepslate, 0, 2);
		world.setBlock(i + 4, j + 14, k + 7, deepslate, 0, 2);
		world.setBlock(i + 5, j + 14, k + 7, deepslate, 0, 2);
		world.setBlock(i + 6, j + 14, k + 7, deepslate, 0, 2);
		world.setBlock(i + 7, j + 14, k + 7, deepslate, 0, 2);
		world.setBlock(i + 3, j + 15, k + 3, deepslate, 0, 2);
		world.setBlock(i + 4, j + 15, k + 3, deepslate, 0, 2);
		world.setBlock(i + 5, j + 15, k + 3, deepslate, 0, 2);
		world.setBlock(i + 6, j + 15, k + 3, deepslate, 0, 2);
		world.setBlock(i + 7, j + 15, k + 3, deepslate, 0, 2);
		world.setBlock(i + 3, j + 15, k + 4, deepslate, 0, 2);
		world.setBlock(i + 4, j + 15, k + 4, deepslate, 0, 2);
		world.setBlock(i + 5, j + 15, k + 4, deepslate, 0, 2);
		world.setBlock(i + 6, j + 15, k + 4, deepslate, 0, 2);
		world.setBlock(i + 7, j + 15, k + 4, deepslate, 0, 2);
		world.setBlock(i + 3, j + 15, k + 5, deepslate, 0, 2);
		world.setBlock(i + 4, j + 15, k + 5, deepslate, 0, 2);
		world.setBlock(i + 5, j + 15, k + 5, deepslate, 0, 2);
		world.setBlock(i + 6, j + 15, k + 5, deepslate, 0, 2);
		world.setBlock(i + 7, j + 15, k + 5, deepslate, 0, 2);
		world.setBlock(i + 3, j + 15, k + 6, deepslate, 0, 2);
		world.setBlock(i + 4, j + 15, k + 6, deepslate, 0, 2);
		world.setBlock(i + 5, j + 15, k + 6, deepslate, 0, 2);
		world.setBlock(i + 6, j + 15, k + 6, deepslate, 0, 2);
		world.setBlock(i + 7, j + 15, k + 6, deepslate, 0, 2);
		world.setBlock(i + 3, j + 15, k + 7, deepslate, 0, 2);
		world.setBlock(i + 4, j + 15, k + 7, deepslate, 0, 2);
		world.setBlock(i + 5, j + 15, k + 7, deepslate, 0, 2);
		world.setBlock(i + 6, j + 15, k + 7, deepslate, 0, 2);
		world.setBlock(i + 7, j + 15, k + 7, deepslate, 0, 2);
		world.setBlock(i + 3, j + 16, k + 3, deepslate, 0, 2);
		world.setBlock(i + 4, j + 16, k + 3, deepslate, 0, 2);
		world.setBlock(i + 5, j + 16, k + 3, deepslate, 0, 2);
		world.setBlock(i + 6, j + 16, k + 3, deepslate, 0, 2);
		world.setBlock(i + 7, j + 16, k + 3, deepslate, 0, 2);
		world.setBlock(i + 3, j + 16, k + 4, deepslate, 0, 2);
		world.setBlock(i + 4, j + 16, k + 4, deepslate, 0, 2);
		world.setBlock(i + 5, j + 16, k + 4, deepslate, 0, 2);
		world.setBlock(i + 6, j + 16, k + 4, deepslate, 0, 2);
		world.setBlock(i + 7, j + 16, k + 4, deepslate, 0, 2);
		world.setBlock(i + 3, j + 16, k + 5, deepslate, 0, 2);
		world.setBlock(i + 4, j + 16, k + 5, deepslate, 0, 2);
		world.setBlock(i + 5, j + 16, k + 5, deepslate, 0, 2);
		world.setBlock(i + 6, j + 16, k + 5, deepslate, 0, 2);
		world.setBlock(i + 7, j + 16, k + 5, deepslate, 0, 2);
		world.setBlock(i + 3, j + 16, k + 6, deepslate, 0, 2);
		world.setBlock(i + 4, j + 16, k + 6, deepslate, 0, 2);
		world.setBlock(i + 5, j + 16, k + 6, deepslate, 0, 2);
		world.setBlock(i + 6, j + 16, k + 6, deepslate, 0, 2);
		world.setBlock(i + 7, j + 16, k + 6, deepslate, 0, 2);
		world.setBlock(i + 3, j + 16, k + 7, deepslate, 0, 2);
		world.setBlock(i + 4, j + 16, k + 7, deepslate, 0, 2);
		world.setBlock(i + 5, j + 16, k + 7, deepslate, 0, 2);
		world.setBlock(i + 6, j + 16, k + 7, deepslate, 0, 2);
		world.setBlock(i + 7, j + 16, k + 7, deepslate, 0, 2);
		world.setBlock(i + 3, j + 17, k + 3, deepslate, 0, 2);
		world.setBlock(i + 4, j + 17, k + 3, deepslate, 0, 2);
		world.setBlock(i + 5, j + 17, k + 3, deepslate, 0, 2);
		world.setBlock(i + 6, j + 17, k + 3, deepslate, 0, 2);
		world.setBlock(i + 7, j + 17, k + 3, deepslate, 0, 2);
		world.setBlock(i + 3, j + 17, k + 4, deepslate, 0, 2);
		world.setBlock(i + 4, j + 17, k + 4, deepslate, 0, 2);
		world.setBlock(i + 5, j + 17, k + 4, deepslate, 0, 2);
		world.setBlock(i + 6, j + 17, k + 4, deepslate, 0, 2);
		world.setBlock(i + 7, j + 17, k + 4, deepslate, 0, 2);
		world.setBlock(i + 3, j + 17, k + 5, deepslate, 0, 2);
		world.setBlock(i + 4, j + 17, k + 5, deepslate, 0, 2);
		world.setBlock(i + 5, j + 17, k + 5, deepslate, 0, 2);
		world.setBlock(i + 6, j + 17, k + 5, deepslate, 0, 2);
		world.setBlock(i + 7, j + 17, k + 5, deepslate, 0, 2);
		world.setBlock(i + 3, j + 17, k + 6, deepslate, 0, 2);
		world.setBlock(i + 4, j + 17, k + 6, deepslate, 0, 2);
		world.setBlock(i + 5, j + 17, k + 6, deepslate, 0, 2);
		world.setBlock(i + 6, j + 17, k + 6, deepslate, 0, 2);
		world.setBlock(i + 7, j + 17, k + 6, deepslate, 0, 2);
		world.setBlock(i + 3, j + 17, k + 7, deepslate, 0, 2);
		world.setBlock(i + 4, j + 17, k + 7, deepslate, 0, 2);
		world.setBlock(i + 5, j + 17, k + 7, deepslate, 0, 2);
		world.setBlock(i + 6, j + 17, k + 7, deepslate, 0, 2);
		world.setBlock(i + 7, j + 17, k + 7, deepslate, 0, 2);
		world.setBlock(i + 3, j + 18, k + 3, deepslate, 0, 2);
		world.setBlock(i + 4, j + 18, k + 3, deepslate, 0, 2);
		world.setBlock(i + 5, j + 18, k + 3, deepslate, 0, 2);
		world.setBlock(i + 6, j + 18, k + 3, deepslate, 0, 2);
		world.setBlock(i + 7, j + 18, k + 3, deepslate, 0, 2);
		world.setBlock(i + 3, j + 18, k + 4, deepslate, 0, 2);
		world.setBlock(i + 4, j + 18, k + 4, deepslate, 0, 2);
		world.setBlock(i + 5, j + 18, k + 4, deepslate, 0, 2);
		world.setBlock(i + 6, j + 18, k + 4, deepslate, 0, 2);
		world.setBlock(i + 7, j + 18, k + 4, deepslate, 0, 2);
		world.setBlock(i + 3, j + 18, k + 5, deepslate, 0, 2);
		world.setBlock(i + 4, j + 18, k + 5, deepslate, 0, 2);
		world.setBlock(i + 5, j + 18, k + 5, deepslate, 0, 2);
		world.setBlock(i + 6, j + 18, k + 5, deepslate, 0, 2);
		world.setBlock(i + 7, j + 18, k + 5, deepslate, 0, 2);
		world.setBlock(i + 3, j + 18, k + 6, deepslate, 0, 2);
		world.setBlock(i + 4, j + 18, k + 6, deepslate, 0, 2);
		world.setBlock(i + 5, j + 18, k + 6, deepslate, 0, 2);
		world.setBlock(i + 6, j + 18, k + 6, deepslate, 0, 2);
		world.setBlock(i + 7, j + 18, k + 6, deepslate, 0, 2);
		world.setBlock(i + 3, j + 18, k + 7, deepslate, 0, 2);
		world.setBlock(i + 4, j + 18, k + 7, deepslate, 0, 2);
		world.setBlock(i + 5, j + 18, k + 7, deepslate, 0, 2);
		world.setBlock(i + 6, j + 18, k + 7, deepslate, 0, 2);
		world.setBlock(i + 7, j + 18, k + 7, deepslate, 0, 2);
		world.setBlock(i + 3, j + 19, k + 3, deepslate, 0, 2);
		world.setBlock(i + 4, j + 19, k + 3, deepslate, 0, 2);
		world.setBlock(i + 5, j + 19, k + 3, deepslate, 0, 2);
		world.setBlock(i + 6, j + 19, k + 3, deepslate, 0, 2);
		world.setBlock(i + 7, j + 19, k + 3, deepslate, 0, 2);
		world.setBlock(i + 3, j + 19, k + 4, deepslate, 0, 2);
		world.setBlock(i + 4, j + 19, k + 4, deepslate, 0, 2);
		world.setBlock(i + 5, j + 19, k + 4, deepslate, 0, 2);
		world.setBlock(i + 6, j + 19, k + 4, deepslate, 0, 2);
		world.setBlock(i + 7, j + 19, k + 4, deepslate, 0, 2);
		world.setBlock(i + 3, j + 19, k + 5, deepslate, 0, 2);
		world.setBlock(i + 4, j + 19, k + 5, deepslate, 0, 2);
		world.setBlock(i + 5, j + 19, k + 5, deepslate, 0, 2);
		world.setBlock(i + 6, j + 19, k + 5, deepslate, 0, 2);
		world.setBlock(i + 7, j + 19, k + 5, deepslate, 0, 2);
		world.setBlock(i + 3, j + 19, k + 6, deepslate, 0, 2);
		world.setBlock(i + 4, j + 19, k + 6, deepslate, 0, 2);
		world.setBlock(i + 5, j + 19, k + 6, deepslate, 0, 2);
		world.setBlock(i + 6, j + 19, k + 6, deepslate, 0, 2);
		world.setBlock(i + 7, j + 19, k + 6, deepslate, 0, 2);
		world.setBlock(i + 3, j + 19, k + 7, deepslate, 0, 2);
		world.setBlock(i + 4, j + 19, k + 7, deepslate, 0, 2);
		world.setBlock(i + 5, j + 19, k + 7, deepslate, 0, 2);
		world.setBlock(i + 6, j + 19, k + 7, deepslate, 0, 2);
		world.setBlock(i + 7, j + 19, k + 7, deepslate, 0, 2);
		world.setBlock(i + 3, j + 20, k + 3, deepslate, 0, 2);
		world.setBlock(i + 4, j + 20, k + 3, deepslate, 0, 2);
		world.setBlock(i + 5, j + 20, k + 3, deepslate, 0, 2);
		world.setBlock(i + 6, j + 20, k + 3, deepslate, 0, 2);
		world.setBlock(i + 7, j + 20, k + 3, deepslate, 0, 2);
		world.setBlock(i + 3, j + 20, k + 4, deepslate, 0, 2);
		world.setBlock(i + 4, j + 20, k + 4, deepslate, 0, 2);
		world.setBlock(i + 5, j + 20, k + 4, deepslate, 0, 2);
		world.setBlock(i + 6, j + 20, k + 4, deepslate, 0, 2);
		world.setBlock(i + 7, j + 20, k + 4, deepslate, 0, 2);
		world.setBlock(i + 3, j + 20, k + 5, deepslate, 0, 2);
		world.setBlock(i + 4, j + 20, k + 5, deepslate, 0, 2);
		world.setBlock(i + 5, j + 20, k + 5, deepslate, 0, 2);
		world.setBlock(i + 6, j + 20, k + 5, deepslate, 0, 2);
		world.setBlock(i + 7, j + 20, k + 5, deepslate, 0, 2);
		world.setBlock(i + 3, j + 20, k + 6, deepslate, 0, 2);
		world.setBlock(i + 4, j + 20, k + 6, deepslate, 0, 2);
		world.setBlock(i + 5, j + 20, k + 6, deepslate, 0, 2);
		world.setBlock(i + 6, j + 20, k + 6, deepslate, 0, 2);
		world.setBlock(i + 7, j + 20, k + 6, deepslate, 0, 2);
		world.setBlock(i + 3, j + 20, k + 7, deepslate, 0, 2);
		world.setBlock(i + 4, j + 20, k + 7, deepslate, 0, 2);
		world.setBlock(i + 5, j + 20, k + 7, deepslate, 0, 2);
		world.setBlock(i + 6, j + 20, k + 7, deepslate, 0, 2);
		world.setBlock(i + 7, j + 20, k + 7, deepslate, 0, 2);
		world.setBlock(i + 3, j + 21, k + 3, deepslate, 0, 2);
		world.setBlock(i + 4, j + 21, k + 3, deepslate, 0, 2);
		world.setBlock(i + 5, j + 21, k + 3, deepslate, 0, 2);
		world.setBlock(i + 6, j + 21, k + 3, deepslate, 0, 2);
		world.setBlock(i + 7, j + 21, k + 3, deepslate, 0, 2);
		world.setBlock(i + 3, j + 21, k + 4, deepslate, 0, 2);
		world.setBlock(i + 4, j + 21, k + 4, deepslate, 0, 2);
		world.setBlock(i + 5, j + 21, k + 4, deepslate, 0, 2);
		world.setBlock(i + 6, j + 21, k + 4, deepslate, 0, 2);
		world.setBlock(i + 7, j + 21, k + 4, deepslate, 0, 2);
		world.setBlock(i + 3, j + 21, k + 5, deepslate, 0, 2);
		world.setBlock(i + 4, j + 21, k + 5, deepslate, 0, 2);
		world.setBlock(i + 5, j + 21, k + 5, deepslate, 0, 2);
		world.setBlock(i + 6, j + 21, k + 5, deepslate, 0, 2);
		world.setBlock(i + 7, j + 21, k + 5, deepslate, 0, 2);
		world.setBlock(i + 3, j + 21, k + 6, deepslate, 0, 2);
		world.setBlock(i + 4, j + 21, k + 6, deepslate, 0, 2);
		world.setBlock(i + 5, j + 21, k + 6, deepslate, 0, 2);
		world.setBlock(i + 6, j + 21, k + 6, deepslate, 0, 2);
		world.setBlock(i + 7, j + 21, k + 6, deepslate, 0, 2);
		world.setBlock(i + 3, j + 21, k + 7, deepslate, 0, 2);
		world.setBlock(i + 4, j + 21, k + 7, deepslate, 0, 2);
		world.setBlock(i + 5, j + 21, k + 7, deepslate, 0, 2);
		world.setBlock(i + 6, j + 21, k + 7, deepslate, 0, 2);
		world.setBlock(i + 7, j + 21, k + 7, deepslate, 0, 2);
		world.setBlock(i + 3, j + 22, k + 3, deepslate, 0, 2);
		world.setBlock(i + 4, j + 22, k + 3, deepslate, 0, 2);
		world.setBlock(i + 5, j + 22, k + 3, deepslate, 0, 2);
		world.setBlock(i + 6, j + 22, k + 3, deepslate, 0, 2);
		world.setBlock(i + 7, j + 22, k + 3, deepslate, 0, 2);
		world.setBlock(i + 3, j + 22, k + 4, deepslate, 0, 2);
		world.setBlock(i + 4, j + 22, k + 4, deepslate, 0, 2);
		world.setBlock(i + 5, j + 22, k + 4, deepslate, 0, 2);
		world.setBlock(i + 6, j + 22, k + 4, deepslate, 0, 2);
		world.setBlock(i + 7, j + 22, k + 4, deepslate, 0, 2);
		world.setBlock(i + 3, j + 22, k + 5, deepslate, 0, 2);
		world.setBlock(i + 4, j + 22, k + 5, deepslate, 0, 2);
		world.setBlock(i + 5, j + 22, k + 5, deepslate, 0, 2);
		world.setBlock(i + 6, j + 22, k + 5, deepslate, 0, 2);
		world.setBlock(i + 7, j + 22, k + 5, deepslate, 0, 2);
		world.setBlock(i + 3, j + 22, k + 6, deepslate, 0, 2);
		world.setBlock(i + 4, j + 22, k + 6, deepslate, 0, 2);
		world.setBlock(i + 5, j + 22, k + 6, deepslate, 0, 2);
		world.setBlock(i + 6, j + 22, k + 6, deepslate, 0, 2);
		world.setBlock(i + 7, j + 22, k + 6, deepslate, 0, 2);
		world.setBlock(i + 3, j + 22, k + 7, deepslate, 0, 2);
		world.setBlock(i + 4, j + 22, k + 7, deepslate, 0, 2);
		world.setBlock(i + 5, j + 22, k + 7, deepslate, 0, 2);
		world.setBlock(i + 6, j + 22, k + 7, deepslate, 0, 2);
		world.setBlock(i + 7, j + 22, k + 7, deepslate, 0, 2);
		world.setBlock(i + 3, j + 23, k + 3, deepslate, 0, 2);
		world.setBlock(i + 4, j + 23, k + 3, deepslate, 0, 2);
		world.setBlock(i + 5, j + 23, k + 3, deepslate, 0, 2);
		world.setBlock(i + 6, j + 23, k + 3, deepslate, 0, 2);
		world.setBlock(i + 7, j + 23, k + 3, deepslate, 0, 2);
		world.setBlock(i + 3, j + 23, k + 4, deepslate, 0, 2);
		world.setBlock(i + 4, j + 23, k + 4, deepslate, 0, 2);
		world.setBlock(i + 5, j + 23, k + 4, deepslate, 0, 2);
		world.setBlock(i + 6, j + 23, k + 4, deepslate, 0, 2);
		world.setBlock(i + 7, j + 23, k + 4, deepslate, 0, 2);
		world.setBlock(i + 3, j + 23, k + 5, deepslate, 0, 2);
		world.setBlock(i + 4, j + 23, k + 5, deepslate, 0, 2);
		world.setBlock(i + 5, j + 23, k + 5, deepslate, 0, 2);
		world.setBlock(i + 6, j + 23, k + 5, deepslate, 0, 2);
		world.setBlock(i + 7, j + 23, k + 5, deepslate, 0, 2);
		world.setBlock(i + 3, j + 23, k + 6, deepslate, 0, 2);
		world.setBlock(i + 4, j + 23, k + 6, deepslate, 0, 2);
		world.setBlock(i + 5, j + 23, k + 6, deepslate, 0, 2);
		world.setBlock(i + 6, j + 23, k + 6, deepslate, 0, 2);
		world.setBlock(i + 7, j + 23, k + 6, deepslate, 0, 2);
		world.setBlock(i + 3, j + 23, k + 7, deepslate, 0, 2);
		world.setBlock(i + 4, j + 23, k + 7, deepslate, 0, 2);
		world.setBlock(i + 5, j + 23, k + 7, deepslate, 0, 2);
		world.setBlock(i + 6, j + 23, k + 7, deepslate, 0, 2);
		world.setBlock(i + 7, j + 23, k + 7, deepslate, 0, 2);
		world.setBlock(i + 3, j + 24, k + 3, deepslate, 0, 2);
		world.setBlock(i + 4, j + 24, k + 3, deepslate, 0, 2);
		world.setBlock(i + 5, j + 24, k + 3, deepslate, 0, 2);
		world.setBlock(i + 6, j + 24, k + 3, deepslate, 0, 2);
		world.setBlock(i + 7, j + 24, k + 3, deepslate, 0, 2);
		world.setBlock(i + 3, j + 24, k + 4, deepslate, 0, 2);
		world.setBlock(i + 4, j + 24, k + 4, deepslate, 0, 2);
		world.setBlock(i + 5, j + 24, k + 4, deepslate, 0, 2);
		world.setBlock(i + 6, j + 24, k + 4, deepslate, 0, 2);
		world.setBlock(i + 7, j + 24, k + 4, deepslate, 0, 2);
		world.setBlock(i + 3, j + 24, k + 5, deepslate, 0, 2);
		world.setBlock(i + 4, j + 24, k + 5, deepslate, 0, 2);
		world.setBlock(i + 5, j + 24, k + 5, deepslate, 0, 2);
		world.setBlock(i + 6, j + 24, k + 5, deepslate, 0, 2);
		world.setBlock(i + 7, j + 24, k + 5, deepslate, 0, 2);
		world.setBlock(i + 3, j + 24, k + 6, deepslate, 0, 2);
		world.setBlock(i + 4, j + 24, k + 6, deepslate, 0, 2);
		world.setBlock(i + 5, j + 24, k + 6, deepslate, 0, 2);
		world.setBlock(i + 6, j + 24, k + 6, deepslate, 0, 2);
		world.setBlock(i + 7, j + 24, k + 6, deepslate, 0, 2);
		world.setBlock(i + 3, j + 24, k + 7, deepslate, 0, 2);
		world.setBlock(i + 4, j + 24, k + 7, deepslate, 0, 2);
		world.setBlock(i + 5, j + 24, k + 7, deepslate, 0, 2);
		world.setBlock(i + 6, j + 24, k + 7, deepslate, 0, 2);
		world.setBlock(i + 7, j + 24, k + 7, deepslate, 0, 2);
		world.setBlock(i + 3, j + 25, k + 3, deepslate, 0, 2);
		world.setBlock(i + 4, j + 25, k + 3, deepslate, 0, 2);
		world.setBlock(i + 5, j + 25, k + 3, deepslate, 0, 2);
		world.setBlock(i + 6, j + 25, k + 3, deepslate, 0, 2);
		world.setBlock(i + 7, j + 25, k + 3, deepslate, 0, 2);
		world.setBlock(i + 3, j + 25, k + 4, deepslate, 0, 2);
		world.setBlock(i + 4, j + 25, k + 4, deepslate, 0, 2);
		world.setBlock(i + 5, j + 25, k + 4, deepslate, 0, 2);
		world.setBlock(i + 6, j + 25, k + 4, deepslate, 0, 2);
		world.setBlock(i + 7, j + 25, k + 4, deepslate, 0, 2);
		world.setBlock(i + 3, j + 25, k + 5, deepslate, 0, 2);
		world.setBlock(i + 4, j + 25, k + 5, deepslate, 0, 2);
		world.setBlock(i + 5, j + 25, k + 5, deepslate, 0, 2);
		world.setBlock(i + 6, j + 25, k + 5, deepslate, 0, 2);
		world.setBlock(i + 7, j + 25, k + 5, deepslate, 0, 2);
		world.setBlock(i + 3, j + 25, k + 6, deepslate, 0, 2);
		world.setBlock(i + 4, j + 25, k + 6, deepslate, 0, 2);
		world.setBlock(i + 5, j + 25, k + 6, deepslate, 0, 2);
		world.setBlock(i + 6, j + 25, k + 6, deepslate, 0, 2);
		world.setBlock(i + 7, j + 25, k + 6, deepslate, 0, 2);
		world.setBlock(i + 3, j + 25, k + 7, deepslate, 0, 2);
		world.setBlock(i + 4, j + 25, k + 7, deepslate, 0, 2);
		world.setBlock(i + 5, j + 25, k + 7, deepslate, 0, 2);
		world.setBlock(i + 6, j + 25, k + 7, deepslate, 0, 2);
		world.setBlock(i + 7, j + 25, k + 7, deepslate, 0, 2);
		world.setBlock(i + 3, j + 26, k + 3, deepslate, 0, 2);
		world.setBlock(i + 4, j + 26, k + 3, deepslate, 0, 2);
		world.setBlock(i + 5, j + 26, k + 3, deepslate, 0, 2);
		world.setBlock(i + 6, j + 26, k + 3, deepslate, 0, 2);
		world.setBlock(i + 7, j + 26, k + 3, deepslate, 0, 2);
		world.setBlock(i + 3, j + 26, k + 4, deepslate, 0, 2);
		world.setBlock(i + 4, j + 26, k + 4, deepslate, 0, 2);
		world.setBlock(i + 5, j + 26, k + 4, deepslate, 0, 2);
		world.setBlock(i + 6, j + 26, k + 4, deepslate, 0, 2);
		world.setBlock(i + 7, j + 26, k + 4, deepslate, 0, 2);
		world.setBlock(i + 3, j + 26, k + 5, deepslate, 0, 2);
		world.setBlock(i + 4, j + 26, k + 5, deepslate, 0, 2);
		world.setBlock(i + 5, j + 26, k + 5, deepslate, 0, 2);
		world.setBlock(i + 6, j + 26, k + 5, deepslate, 0, 2);
		world.setBlock(i + 7, j + 26, k + 5, deepslate, 0, 2);
		world.setBlock(i + 3, j + 26, k + 6, deepslate, 0, 2);
		world.setBlock(i + 4, j + 26, k + 6, deepslate, 0, 2);
		world.setBlock(i + 5, j + 26, k + 6, deepslate, 0, 2);
		world.setBlock(i + 6, j + 26, k + 6, deepslate, 0, 2);
		world.setBlock(i + 7, j + 26, k + 6, deepslate, 0, 2);
		world.setBlock(i + 3, j + 26, k + 7, deepslate, 0, 2);
		world.setBlock(i + 4, j + 26, k + 7, deepslate, 0, 2);
		world.setBlock(i + 5, j + 26, k + 7, deepslate, 0, 2);
		world.setBlock(i + 6, j + 26, k + 7, deepslate, 0, 2);
		world.setBlock(i + 7, j + 26, k + 7, deepslate, 0, 2);
		world.setBlock(i + 3, j + 27, k + 3, deepslate, 0, 2);
		world.setBlock(i + 4, j + 27, k + 3, deepslate, 0, 2);
		world.setBlock(i + 5, j + 27, k + 3, deepslate, 0, 2);
		world.setBlock(i + 6, j + 27, k + 3, deepslate, 0, 2);
		world.setBlock(i + 7, j + 27, k + 3, deepslate, 0, 2);
		world.setBlock(i + 3, j + 27, k + 4, deepslate, 0, 2);
		world.setBlock(i + 4, j + 27, k + 4, deepslate, 0, 2);
		world.setBlock(i + 5, j + 27, k + 4, deepslate, 0, 2);
		world.setBlock(i + 6, j + 27, k + 4, deepslate, 0, 2);
		world.setBlock(i + 7, j + 27, k + 4, deepslate, 0, 2);
		world.setBlock(i + 3, j + 27, k + 5, deepslate, 0, 2);
		world.setBlock(i + 4, j + 27, k + 5, deepslate, 0, 2);
		world.setBlock(i + 5, j + 27, k + 5, deepslate, 0, 2);
		world.setBlock(i + 6, j + 27, k + 5, deepslate, 0, 2);
		world.setBlock(i + 7, j + 27, k + 5, deepslate, 0, 2);
		world.setBlock(i + 3, j + 27, k + 6, deepslate, 0, 2);
		world.setBlock(i + 4, j + 27, k + 6, deepslate, 0, 2);
		world.setBlock(i + 5, j + 27, k + 6, deepslate, 0, 2);
		world.setBlock(i + 6, j + 27, k + 6, deepslate, 0, 2);
		world.setBlock(i + 7, j + 27, k + 6, deepslate, 0, 2);
		world.setBlock(i + 3, j + 27, k + 7, deepslate, 0, 2);
		world.setBlock(i + 4, j + 27, k + 7, deepslate, 0, 2);
		world.setBlock(i + 5, j + 27, k + 7, deepslate, 0, 2);
		world.setBlock(i + 6, j + 27, k + 7, deepslate, 0, 2);
		world.setBlock(i + 7, j + 27, k + 7, deepslate, 0, 2);
		world.setBlock(i + 3, j + 28, k + 2, deepslate, 0, 2);
		world.setBlock(i + 4, j + 28, k + 2, deepslate, 0, 2);
		world.setBlock(i + 5, j + 28, k + 2, deepslate, 0, 2);
		world.setBlock(i + 6, j + 28, k + 2, deepslate, 0, 2);
		world.setBlock(i + 7, j + 28, k + 2, deepslate, 0, 2);
		world.setBlock(i + 2, j + 28, k + 3, deepslate, 0, 2);
		world.setBlock(i + 3, j + 28, k + 3, deepslate, 0, 2);
		world.setBlock(i + 4, j + 28, k + 3, deepslate, 0, 2);
		world.setBlock(i + 5, j + 28, k + 3, deepslate, 0, 2);
		world.setBlock(i + 6, j + 28, k + 3, deepslate, 0, 2);
		world.setBlock(i + 7, j + 28, k + 3, deepslate, 0, 2);
		world.setBlock(i + 8, j + 28, k + 3, deepslate, 0, 2);
		world.setBlock(i + 2, j + 28, k + 4, deepslate, 0, 2);
		world.setBlock(i + 3, j + 28, k + 4, deepslate, 0, 2);
		world.setBlock(i + 4, j + 28, k + 4, deepslate, 0, 2);
		world.setBlock(i + 5, j + 28, k + 4, deepslate, 0, 2);
		world.setBlock(i + 6, j + 28, k + 4, deepslate, 0, 2);
		world.setBlock(i + 7, j + 28, k + 4, deepslate, 0, 2);
		world.setBlock(i + 8, j + 28, k + 4, deepslate, 0, 2);
		world.setBlock(i + 2, j + 28, k + 5, deepslate, 0, 2);
		world.setBlock(i + 3, j + 28, k + 5, deepslate, 0, 2);
		world.setBlock(i + 4, j + 28, k + 5, deepslate, 0, 2);
		world.setBlock(i + 5, j + 28, k + 5, deepslate, 0, 2);
		world.setBlock(i + 6, j + 28, k + 5, deepslate, 0, 2);
		world.setBlock(i + 7, j + 28, k + 5, deepslate, 0, 2);
		world.setBlock(i + 8, j + 28, k + 5, deepslate, 0, 2);
		world.setBlock(i + 2, j + 28, k + 6, deepslate, 0, 2);
		world.setBlock(i + 3, j + 28, k + 6, deepslate, 0, 2);
		world.setBlock(i + 4, j + 28, k + 6, deepslate, 0, 2);
		world.setBlock(i + 5, j + 28, k + 6, deepslate, 0, 2);
		world.setBlock(i + 6, j + 28, k + 6, deepslate, 0, 2);
		world.setBlock(i + 7, j + 28, k + 6, deepslate, 0, 2);
		world.setBlock(i + 8, j + 28, k + 6, deepslate, 0, 2);
		world.setBlock(i + 2, j + 28, k + 7, deepslate, 0, 2);
		world.setBlock(i + 3, j + 28, k + 7, deepslate, 0, 2);
		world.setBlock(i + 4, j + 28, k + 7, deepslate, 0, 2);
		world.setBlock(i + 5, j + 28, k + 7, deepslate, 0, 2);
		world.setBlock(i + 6, j + 28, k + 7, deepslate, 0, 2);
		world.setBlock(i + 7, j + 28, k + 7, deepslate, 0, 2);
		world.setBlock(i + 8, j + 28, k + 7, deepslate, 0, 2);
		world.setBlock(i + 3, j + 28, k + 8, deepslate, 0, 2);
		world.setBlock(i + 4, j + 28, k + 8, deepslate, 0, 2);
		world.setBlock(i + 5, j + 28, k + 8, deepslate, 0, 2);
		world.setBlock(i + 6, j + 28, k + 8, deepslate, 0, 2);
		world.setBlock(i + 7, j + 28, k + 8, deepslate, 0, 2);
		world.setBlock(i + 3, j + 29, k + 1, deepslate, 0, 2);
		world.setBlock(i + 4, j + 29, k + 1, deepslate, 0, 2);
		world.setBlock(i + 5, j + 29, k + 1, deepslate, 0, 2);
		world.setBlock(i + 6, j + 29, k + 1, deepslate, 0, 2);
		world.setBlock(i + 7, j + 29, k + 1, deepslate, 0, 2);
		world.setBlock(i + 2, j + 29, k + 2, deepslate, 0, 2);
		world.setBlock(i + 3, j + 29, k + 2, deepslate, 0, 2);
		world.setBlock(i + 4, j + 29, k + 2, deepslate, 0, 2);
		world.setBlock(i + 5, j + 29, k + 2, deepslate, 0, 2);
		world.setBlock(i + 6, j + 29, k + 2, deepslate, 0, 2);
		world.setBlock(i + 7, j + 29, k + 2, deepslate, 0, 2);
		world.setBlock(i + 8, j + 29, k + 2, deepslate, 0, 2);
		world.setBlock(i + 1, j + 29, k + 3, deepslate, 0, 2);
		world.setBlock(i + 2, j + 29, k + 3, deepslate, 0, 2);
		world.setBlock(i + 3, j + 29, k + 3, deepslate, 0, 2);
		world.setBlock(i + 4, j + 29, k + 3, deepslate, 0, 2);
		world.setBlock(i + 5, j + 29, k + 3, deepslate, 0, 2);
		world.setBlock(i + 6, j + 29, k + 3, deepslate, 0, 2);
		world.setBlock(i + 7, j + 29, k + 3, deepslate, 0, 2);
		world.setBlock(i + 8, j + 29, k + 3, deepslate, 0, 2);
		world.setBlock(i + 9, j + 29, k + 3, deepslate, 0, 2);
		world.setBlock(i + 1, j + 29, k + 4, deepslate, 0, 2);
		world.setBlock(i + 2, j + 29, k + 4, deepslate, 0, 2);
		world.setBlock(i + 3, j + 29, k + 4, deepslate, 0, 2);
		world.setBlock(i + 4, j + 29, k + 4, deepslate, 0, 2);
		world.setBlock(i + 5, j + 29, k + 4, deepslate, 0, 2);
		world.setBlock(i + 6, j + 29, k + 4, deepslate, 0, 2);
		world.setBlock(i + 7, j + 29, k + 4, deepslate, 0, 2);
		world.setBlock(i + 8, j + 29, k + 4, deepslate, 0, 2);
		world.setBlock(i + 9, j + 29, k + 4, deepslate, 0, 2);
		world.setBlock(i + 1, j + 29, k + 5, deepslate, 0, 2);
		world.setBlock(i + 2, j + 29, k + 5, deepslate, 0, 2);
		world.setBlock(i + 3, j + 29, k + 5, deepslate, 0, 2);
		world.setBlock(i + 4, j + 29, k + 5, deepslate, 0, 2);
		world.setBlock(i + 5, j + 29, k + 5, deepslate, 0, 2);
		world.setBlock(i + 6, j + 29, k + 5, deepslate, 0, 2);
		world.setBlock(i + 7, j + 29, k + 5, deepslate, 0, 2);
		world.setBlock(i + 8, j + 29, k + 5, deepslate, 0, 2);
		world.setBlock(i + 9, j + 29, k + 5, deepslate, 0, 2);
		world.setBlock(i + 1, j + 29, k + 6, deepslate, 0, 2);
		world.setBlock(i + 2, j + 29, k + 6, deepslate, 0, 2);
		world.setBlock(i + 3, j + 29, k + 6, deepslate, 0, 2);
		world.setBlock(i + 4, j + 29, k + 6, deepslate, 0, 2);
		world.setBlock(i + 5, j + 29, k + 6, deepslate, 0, 2);
		world.setBlock(i + 6, j + 29, k + 6, deepslate, 0, 2);
		world.setBlock(i + 7, j + 29, k + 6, deepslate, 0, 2);
		world.setBlock(i + 8, j + 29, k + 6, deepslate, 0, 2);
		world.setBlock(i + 9, j + 29, k + 6, deepslate, 0, 2);
		world.setBlock(i + 1, j + 29, k + 7, deepslate, 0, 2);
		world.setBlock(i + 2, j + 29, k + 7, deepslate, 0, 2);
		world.setBlock(i + 3, j + 29, k + 7, deepslate, 0, 2);
		world.setBlock(i + 4, j + 29, k + 7, deepslate, 0, 2);
		world.setBlock(i + 5, j + 29, k + 7, deepslate, 0, 2);
		world.setBlock(i + 6, j + 29, k + 7, deepslate, 0, 2);
		world.setBlock(i + 7, j + 29, k + 7, deepslate, 0, 2);
		world.setBlock(i + 8, j + 29, k + 7, deepslate, 0, 2);
		world.setBlock(i + 9, j + 29, k + 7, deepslate, 0, 2);
		world.setBlock(i + 2, j + 29, k + 8, deepslate, 0, 2);
		world.setBlock(i + 3, j + 29, k + 8, deepslate, 0, 2);
		world.setBlock(i + 4, j + 29, k + 8, deepslate, 0, 2);
		world.setBlock(i + 5, j + 29, k + 8, deepslate, 0, 2);
		world.setBlock(i + 6, j + 29, k + 8, deepslate, 0, 2);
		world.setBlock(i + 7, j + 29, k + 8, deepslate, 0, 2);
		world.setBlock(i + 8, j + 29, k + 8, deepslate, 0, 2);
		world.setBlock(i + 3, j + 29, k + 9, deepslate, 0, 2);
		world.setBlock(i + 4, j + 29, k + 9, deepslate, 0, 2);
		world.setBlock(i + 5, j + 29, k + 9, deepslate, 0, 2);
		world.setBlock(i + 6, j + 29, k + 9, deepslate, 0, 2);
		world.setBlock(i + 7, j + 29, k + 9, deepslate, 0, 2);
		world.setBlock(i + 4, j + 30, k + 0, deepslate, 0, 2);
		world.setBlock(i + 5, j + 30, k + 0, deepslate, 0, 2);
		world.setBlock(i + 6, j + 30, k + 0, deepslate, 0, 2);
		world.setBlock(i + 7, j + 30, k + 0, deepslate, 0, 2);
		world.setBlock(i + 2, j + 30, k + 1, deepslate, 0, 2);
		world.setBlock(i + 3, j + 30, k + 1, deepslate, 0, 2);
		world.setBlock(i + 4, j + 30, k + 1, deepslate, 0, 2);
		world.setBlock(i + 5, j + 30, k + 1, deepslate, 0, 2);
		world.setBlock(i + 6, j + 30, k + 1, deepslate, 0, 2);
		world.setBlock(i + 7, j + 30, k + 1, deepslate, 0, 2);
		world.setBlock(i + 8, j + 30, k + 1, deepslate, 0, 2);
		world.setBlock(i + 1, j + 30, k + 2, deepslate, 0, 2);
		world.setBlock(i + 2, j + 30, k + 2, deepslate, 0, 2);
		world.setBlock(i + 3, j + 30, k + 2, deepslate, 0, 2);
		world.setBlock(i + 4, j + 30, k + 2, deepslate, 0, 2);
		world.setBlock(i + 5, j + 30, k + 2, deepslate, 0, 2);
		world.setBlock(i + 6, j + 30, k + 2, deepslate, 0, 2);
		world.setBlock(i + 7, j + 30, k + 2, deepslate, 0, 2);
		world.setBlock(i + 8, j + 30, k + 2, deepslate, 0, 2);
		world.setBlock(i + 9, j + 30, k + 2, deepslate, 0, 2);
		world.setBlock(i + 0, j + 30, k + 3, deepslate, 0, 2);
		world.setBlock(i + 1, j + 30, k + 3, deepslate, 0, 2);
		world.setBlock(i + 2, j + 30, k + 3, deepslate, 0, 2);
		world.setBlock(i + 3, j + 30, k + 3, deepslate, 0, 2);
		world.setBlock(i + 4, j + 30, k + 3, deepslate, 0, 2);
		world.setBlock(i + 5, j + 30, k + 3, deepslate, 0, 2);
		world.setBlock(i + 6, j + 30, k + 3, deepslate, 0, 2);
		world.setBlock(i + 7, j + 30, k + 3, deepslate, 0, 2);
		world.setBlock(i + 8, j + 30, k + 3, deepslate, 0, 2);
		world.setBlock(i + 9, j + 30, k + 3, deepslate, 0, 2);
		world.setBlock(i + 10, j + 30, k + 3, deepslate, 0, 2);
		world.setBlock(i + 0, j + 30, k + 4, deepslate, 0, 2);
		world.setBlock(i + 1, j + 30, k + 4, deepslate, 0, 2);
		world.setBlock(i + 2, j + 30, k + 4, deepslate, 0, 2);
		world.setBlock(i + 3, j + 30, k + 4, deepslate, 0, 2);
		world.setBlock(i + 4, j + 30, k + 4, deepslate, 0, 2);
		world.setBlock(i + 5, j + 30, k + 4, deepslate, 0, 2);
		world.setBlock(i + 6, j + 30, k + 4, deepslate, 0, 2);
		world.setBlock(i + 7, j + 30, k + 4, deepslate, 0, 2);
		world.setBlock(i + 8, j + 30, k + 4, deepslate, 0, 2);
		world.setBlock(i + 9, j + 30, k + 4, deepslate, 0, 2);
		world.setBlock(i + 10, j + 30, k + 4, deepslate, 0, 2);
		world.setBlock(i + 0, j + 30, k + 5, deepslate, 0, 2);
		world.setBlock(i + 1, j + 30, k + 5, deepslate, 0, 2);
		world.setBlock(i + 2, j + 30, k + 5, deepslate, 0, 2);
		world.setBlock(i + 3, j + 30, k + 5, deepslate, 0, 2);
		world.setBlock(i + 4, j + 30, k + 5, deepslate, 0, 2);
		world.setBlock(i + 5, j + 30, k + 5, deepslate, 0, 2);
		world.setBlock(i + 6, j + 30, k + 5, deepslate, 0, 2);
		world.setBlock(i + 7, j + 30, k + 5, deepslate, 0, 2);
		world.setBlock(i + 8, j + 30, k + 5, deepslate, 0, 2);
		world.setBlock(i + 9, j + 30, k + 5, deepslate, 0, 2);
		world.setBlock(i + 10, j + 30, k + 5, deepslate, 0, 2);
		world.setBlock(i + 0, j + 30, k + 6, deepslate, 0, 2);
		world.setBlock(i + 1, j + 30, k + 6, deepslate, 0, 2);
		world.setBlock(i + 2, j + 30, k + 6, deepslate, 0, 2);
		world.setBlock(i + 3, j + 30, k + 6, deepslate, 0, 2);
		world.setBlock(i + 4, j + 30, k + 6, deepslate, 0, 2);
		world.setBlock(i + 5, j + 30, k + 6, deepslate, 0, 2);
		world.setBlock(i + 6, j + 30, k + 6, deepslate, 0, 2);
		world.setBlock(i + 7, j + 30, k + 6, deepslate, 0, 2);
		world.setBlock(i + 8, j + 30, k + 6, deepslate, 0, 2);
		world.setBlock(i + 9, j + 30, k + 6, deepslate, 0, 2);
		world.setBlock(i + 10, j + 30, k + 6, deepslate, 0, 2);
		world.setBlock(i + 0, j + 30, k + 7, deepslate, 0, 2);
		world.setBlock(i + 1, j + 30, k + 7, deepslate, 0, 2);
		world.setBlock(i + 2, j + 30, k + 7, deepslate, 0, 2);
		world.setBlock(i + 3, j + 30, k + 7, deepslate, 0, 2);
		world.setBlock(i + 4, j + 30, k + 7, deepslate, 0, 2);
		world.setBlock(i + 5, j + 30, k + 7, deepslate, 0, 2);
		world.setBlock(i + 6, j + 30, k + 7, deepslate, 0, 2);
		world.setBlock(i + 7, j + 30, k + 7, deepslate, 0, 2);
		world.setBlock(i + 8, j + 30, k + 7, deepslate, 0, 2);
		world.setBlock(i + 9, j + 30, k + 7, deepslate, 0, 2);
		world.setBlock(i + 10, j + 30, k + 7, deepslate, 0, 2);
		world.setBlock(i + 1, j + 30, k + 8, deepslate, 0, 2);
		world.setBlock(i + 2, j + 30, k + 8, deepslate, 0, 2);
		world.setBlock(i + 3, j + 30, k + 8, deepslate, 0, 2);
		world.setBlock(i + 4, j + 30, k + 8, deepslate, 0, 2);
		world.setBlock(i + 5, j + 30, k + 8, deepslate, 0, 2);
		world.setBlock(i + 6, j + 30, k + 8, deepslate, 0, 2);
		world.setBlock(i + 7, j + 30, k + 8, deepslate, 0, 2);
		world.setBlock(i + 8, j + 30, k + 8, deepslate, 0, 2);
		world.setBlock(i + 9, j + 30, k + 8, deepslate, 0, 2);
		world.setBlock(i + 2, j + 30, k + 9, deepslate, 0, 2);
		world.setBlock(i + 3, j + 30, k + 9, deepslate, 0, 2);
		world.setBlock(i + 4, j + 30, k + 9, deepslate, 0, 2);
		world.setBlock(i + 5, j + 30, k + 9, deepslate, 0, 2);
		world.setBlock(i + 6, j + 30, k + 9, deepslate, 0, 2);
		world.setBlock(i + 7, j + 30, k + 9, deepslate, 0, 2);
		world.setBlock(i + 8, j + 30, k + 9, deepslate, 0, 2);
		world.setBlock(i + 3, j + 30, k + 10, deepslate, 0, 2);
		world.setBlock(i + 4, j + 30, k + 10, deepslate, 0, 2);
		world.setBlock(i + 5, j + 30, k + 10, deepslate, 0, 2);
		world.setBlock(i + 6, j + 30, k + 10, deepslate, 0, 2);
		world.setBlock(i + 7, j + 30, k + 10, deepslate, 0, 2);
		world.setBlock(i + 4, j + 31, k + 0, deepslate, 0, 2);
		world.setBlock(i + 5, j + 31, k + 0, deepslate, 0, 2);
		world.setBlock(i + 6, j + 31, k + 0, deepslate, 0, 2);
		world.setBlock(i + 7, j + 31, k + 0, deepslate, 0, 2);
		world.setBlock(i + 2, j + 31, k + 1, deepslate, 0, 2);
		world.setBlock(i + 3, j + 31, k + 1, deepslate, 0, 2);
		world.setBlock(i + 4, j + 31, k + 1, deepslate, 0, 2);
		world.setBlock(i + 5, j + 31, k + 1, deepslate, 0, 2);
		world.setBlock(i + 6, j + 31, k + 1, deepslate, 0, 2);
		world.setBlock(i + 7, j + 31, k + 1, deepslate, 0, 2);
		world.setBlock(i + 8, j + 31, k + 1, deepslate, 0, 2);
		world.setBlock(i + 1, j + 31, k + 2, deepslate, 0, 2);
		world.setBlock(i + 2, j + 31, k + 2, deepslate, 0, 2);
		world.setBlock(i + 3, j + 31, k + 2, deepslate, 0, 2);
		world.setBlock(i + 4, j + 31, k + 2, deepslate, 0, 2);
		world.setBlock(i + 5, j + 31, k + 2, deepslate, 0, 2);
		world.setBlock(i + 6, j + 31, k + 2, deepslate, 0, 2);
		world.setBlock(i + 7, j + 31, k + 2, deepslate, 0, 2);
		world.setBlock(i + 8, j + 31, k + 2, deepslate, 0, 2);
		world.setBlock(i + 9, j + 31, k + 2, deepslate, 0, 2);
		world.setBlock(i + 0, j + 31, k + 3, deepslate, 0, 2);
		world.setBlock(i + 1, j + 31, k + 3, deepslate, 0, 2);
		world.setBlock(i + 2, j + 31, k + 3, deepslate, 0, 2);
		world.setBlock(i + 3, j + 31, k + 3, deepslate, 0, 2);
		world.setBlock(i + 4, j + 31, k + 3, deepslate, 0, 2);
		world.setBlock(i + 5, j + 31, k + 3, deepslate, 0, 2);
		world.setBlock(i + 6, j + 31, k + 3, deepslate, 0, 2);
		world.setBlock(i + 7, j + 31, k + 3, deepslate, 0, 2);
		world.setBlock(i + 8, j + 31, k + 3, deepslate, 0, 2);
		world.setBlock(i + 9, j + 31, k + 3, deepslate, 0, 2);
		world.setBlock(i + 10, j + 31, k + 3, deepslate, 0, 2);
		world.setBlock(i + 0, j + 31, k + 4, deepslate, 0, 2);
		world.setBlock(i + 1, j + 31, k + 4, deepslate, 0, 2);
		world.setBlock(i + 2, j + 31, k + 4, deepslate, 0, 2);
		world.setBlock(i + 3, j + 31, k + 4, deepslate, 0, 2);
		world.setBlock(i + 4, j + 31, k + 4, deepslate, 0, 2);
		world.setBlock(i + 5, j + 31, k + 4, deepslate, 0, 2);
		world.setBlock(i + 6, j + 31, k + 4, deepslate, 0, 2);
		world.setBlock(i + 7, j + 31, k + 4, deepslate, 0, 2);
		world.setBlock(i + 8, j + 31, k + 4, deepslate, 0, 2);
		world.setBlock(i + 9, j + 31, k + 4, deepslate, 0, 2);
		world.setBlock(i + 10, j + 31, k + 4, deepslate, 0, 2);
		world.setBlock(i + 0, j + 31, k + 5, deepslate, 0, 2);
		world.setBlock(i + 1, j + 31, k + 5, deepslate, 0, 2);
		world.setBlock(i + 2, j + 31, k + 5, deepslate, 0, 2);
		world.setBlock(i + 3, j + 31, k + 5, deepslate, 0, 2);
		world.setBlock(i + 4, j + 31, k + 5, deepslate, 0, 2);
		world.setBlock(i + 5, j + 31, k + 5, deepslate, 0, 2);
		world.setBlock(i + 6, j + 31, k + 5, deepslate, 0, 2);
		world.setBlock(i + 7, j + 31, k + 5, deepslate, 0, 2);
		world.setBlock(i + 8, j + 31, k + 5, deepslate, 0, 2);
		world.setBlock(i + 9, j + 31, k + 5, deepslate, 0, 2);
		world.setBlock(i + 10, j + 31, k + 5, deepslate, 0, 2);
		world.setBlock(i + 0, j + 31, k + 6, deepslate, 0, 2);
		world.setBlock(i + 1, j + 31, k + 6, deepslate, 0, 2);
		world.setBlock(i + 2, j + 31, k + 6, deepslate, 0, 2);
		world.setBlock(i + 3, j + 31, k + 6, deepslate, 0, 2);
		world.setBlock(i + 4, j + 31, k + 6, deepslate, 0, 2);
		world.setBlock(i + 5, j + 31, k + 6, deepslate, 0, 2);
		world.setBlock(i + 6, j + 31, k + 6, deepslate, 0, 2);
		world.setBlock(i + 7, j + 31, k + 6, deepslate, 0, 2);
		world.setBlock(i + 8, j + 31, k + 6, deepslate, 0, 2);
		world.setBlock(i + 9, j + 31, k + 6, deepslate, 0, 2);
		world.setBlock(i + 10, j + 31, k + 6, deepslate, 0, 2);
		world.setBlock(i + 0, j + 31, k + 7, deepslate, 0, 2);
		world.setBlock(i + 1, j + 31, k + 7, deepslate, 0, 2);
		world.setBlock(i + 2, j + 31, k + 7, deepslate, 0, 2);
		world.setBlock(i + 3, j + 31, k + 7, deepslate, 0, 2);
		world.setBlock(i + 4, j + 31, k + 7, deepslate, 0, 2);
		world.setBlock(i + 5, j + 31, k + 7, deepslate, 0, 2);
		world.setBlock(i + 6, j + 31, k + 7, deepslate, 0, 2);
		world.setBlock(i + 7, j + 31, k + 7, deepslate, 0, 2);
		world.setBlock(i + 8, j + 31, k + 7, deepslate, 0, 2);
		world.setBlock(i + 9, j + 31, k + 7, deepslate, 0, 2);
		world.setBlock(i + 10, j + 31, k + 7, deepslate, 0, 2);
		world.setBlock(i + 1, j + 31, k + 8, deepslate, 0, 2);
		world.setBlock(i + 2, j + 31, k + 8, deepslate, 0, 2);
		world.setBlock(i + 3, j + 31, k + 8, deepslate, 0, 2);
		world.setBlock(i + 4, j + 31, k + 8, deepslate, 0, 2);
		world.setBlock(i + 5, j + 31, k + 8, deepslate, 0, 2);
		world.setBlock(i + 6, j + 31, k + 8, deepslate, 0, 2);
		world.setBlock(i + 7, j + 31, k + 8, deepslate, 0, 2);
		world.setBlock(i + 8, j + 31, k + 8, deepslate, 0, 2);
		world.setBlock(i + 9, j + 31, k + 8, deepslate, 0, 2);
		world.setBlock(i + 2, j + 31, k + 9, deepslate, 0, 2);
		world.setBlock(i + 3, j + 31, k + 9, deepslate, 0, 2);
		world.setBlock(i + 4, j + 31, k + 9, deepslate, 0, 2);
		world.setBlock(i + 5, j + 31, k + 9, deepslate, 0, 2);
		world.setBlock(i + 6, j + 31, k + 9, deepslate, 0, 2);
		world.setBlock(i + 7, j + 31, k + 9, deepslate, 0, 2);
		world.setBlock(i + 8, j + 31, k + 9, deepslate, 0, 2);
		world.setBlock(i + 3, j + 31, k + 10, deepslate, 0, 2);
		world.setBlock(i + 4, j + 31, k + 10, deepslate, 0, 2);
		world.setBlock(i + 5, j + 31, k + 10, deepslate, 0, 2);
		world.setBlock(i + 6, j + 31, k + 10, deepslate, 0, 2);
		world.setBlock(i + 7, j + 31, k + 10, deepslate, 0, 2);
		world.setBlock(i + 4, j + 32, k + 0, deepslate, 0, 2);
		world.setBlock(i + 5, j + 32, k + 0, deepslate, 0, 2);
		world.setBlock(i + 6, j + 32, k + 0, deepslate, 0, 2);
		world.setBlock(i + 7, j + 32, k + 0, deepslate, 0, 2);
		world.setBlock(i + 2, j + 32, k + 1, deepslate, 0, 2);
		world.setBlock(i + 3, j + 32, k + 1, deepslate, 0, 2);
		world.setBlock(i + 4, j + 32, k + 1, deepslate, 0, 2);
		world.setBlock(i + 5, j + 32, k + 1, deepslate, 0, 2);
		world.setBlock(i + 6, j + 32, k + 1, deepslate, 0, 2);
		world.setBlock(i + 7, j + 32, k + 1, deepslate, 0, 2);
		world.setBlock(i + 8, j + 32, k + 1, deepslate, 0, 2);
		world.setBlock(i + 1, j + 32, k + 2, deepslate, 0, 2);
		world.setBlock(i + 2, j + 32, k + 2, deepslate, 0, 2);
		world.setBlock(i + 3, j + 32, k + 2, deepslate, 0, 2);
		world.setBlock(i + 4, j + 32, k + 2, deepslate, 0, 2);
		world.setBlock(i + 5, j + 32, k + 2, deepslate, 0, 2);
		world.setBlock(i + 6, j + 32, k + 2, deepslate, 0, 2);
		world.setBlock(i + 7, j + 32, k + 2, deepslate, 0, 2);
		world.setBlock(i + 8, j + 32, k + 2, deepslate, 0, 2);
		world.setBlock(i + 9, j + 32, k + 2, deepslate, 0, 2);
		world.setBlock(i + 0, j + 32, k + 3, deepslate, 0, 2);
		world.setBlock(i + 1, j + 32, k + 3, deepslate, 0, 2);
		world.setBlock(i + 2, j + 32, k + 3, deepslate, 0, 2);
		world.setBlock(i + 3, j + 32, k + 3, deepslate, 0, 2);
		world.setBlock(i + 4, j + 32, k + 3, deepslate, 0, 2);
		world.setBlock(i + 5, j + 32, k + 3, deepslate, 0, 2);
		world.setBlock(i + 6, j + 32, k + 3, deepslate, 0, 2);
		world.setBlock(i + 7, j + 32, k + 3, deepslate, 0, 2);
		world.setBlock(i + 8, j + 32, k + 3, deepslate, 0, 2);
		world.setBlock(i + 9, j + 32, k + 3, deepslate, 0, 2);
		world.setBlock(i + 10, j + 32, k + 3, deepslate, 0, 2);
		world.setBlock(i + 0, j + 32, k + 4, deepslate, 0, 2);
		world.setBlock(i + 1, j + 32, k + 4, deepslate, 0, 2);
		world.setBlock(i + 2, j + 32, k + 4, deepslate, 0, 2);
		world.setBlock(i + 3, j + 32, k + 4, deepslate, 0, 2);
		world.setBlock(i + 4, j + 32, k + 4, deepslate, 0, 2);
		world.setBlock(i + 5, j + 32, k + 4, deepslate, 0, 2);
		world.setBlock(i + 6, j + 32, k + 4, deepslate, 0, 2);
		world.setBlock(i + 7, j + 32, k + 4, deepslate, 0, 2);
		world.setBlock(i + 8, j + 32, k + 4, deepslate, 0, 2);
		world.setBlock(i + 9, j + 32, k + 4, deepslate, 0, 2);
		world.setBlock(i + 10, j + 32, k + 4, deepslate, 0, 2);
		world.setBlock(i + 0, j + 32, k + 5, deepslate, 0, 2);
		world.setBlock(i + 1, j + 32, k + 5, deepslate, 0, 2);
		world.setBlock(i + 2, j + 32, k + 5, deepslate, 0, 2);
		world.setBlock(i + 3, j + 32, k + 5, deepslate, 0, 2);
		world.setBlock(i + 4, j + 32, k + 5, deepslate, 0, 2);
		world.setBlock(i + 5, j + 32, k + 5, deepslate, 0, 2);
		world.setBlock(i + 6, j + 32, k + 5, deepslate, 0, 2);
		world.setBlock(i + 7, j + 32, k + 5, deepslate, 0, 2);
		world.setBlock(i + 8, j + 32, k + 5, deepslate, 0, 2);
		world.setBlock(i + 9, j + 32, k + 5, deepslate, 0, 2);
		world.setBlock(i + 10, j + 32, k + 5, deepslate, 0, 2);
		world.setBlock(i + 0, j + 32, k + 6, deepslate, 0, 2);
		world.setBlock(i + 1, j + 32, k + 6, deepslate, 0, 2);
		world.setBlock(i + 2, j + 32, k + 6, deepslate, 0, 2);
		world.setBlock(i + 3, j + 32, k + 6, deepslate, 0, 2);
		world.setBlock(i + 4, j + 32, k + 6, deepslate, 0, 2);
		world.setBlock(i + 5, j + 32, k + 6, deepslate, 0, 2);
		world.setBlock(i + 6, j + 32, k + 6, deepslate, 0, 2);
		world.setBlock(i + 7, j + 32, k + 6, deepslate, 0, 2);
		world.setBlock(i + 8, j + 32, k + 6, deepslate, 0, 2);
		world.setBlock(i + 9, j + 32, k + 6, deepslate, 0, 2);
		world.setBlock(i + 10, j + 32, k + 6, deepslate, 0, 2);
		world.setBlock(i + 0, j + 32, k + 7, deepslate, 0, 2);
		world.setBlock(i + 1, j + 32, k + 7, deepslate, 0, 2);
		world.setBlock(i + 2, j + 32, k + 7, deepslate, 0, 2);
		world.setBlock(i + 3, j + 32, k + 7, deepslate, 0, 2);
		world.setBlock(i + 4, j + 32, k + 7, deepslate, 0, 2);
		world.setBlock(i + 5, j + 32, k + 7, deepslate, 0, 2);
		world.setBlock(i + 6, j + 32, k + 7, deepslate, 0, 2);
		world.setBlock(i + 7, j + 32, k + 7, deepslate, 0, 2);
		world.setBlock(i + 8, j + 32, k + 7, deepslate, 0, 2);
		world.setBlock(i + 9, j + 32, k + 7, deepslate, 0, 2);
		world.setBlock(i + 10, j + 32, k + 7, deepslate, 0, 2);
		world.setBlock(i + 1, j + 32, k + 8, deepslate, 0, 2);
		world.setBlock(i + 2, j + 32, k + 8, deepslate, 0, 2);
		world.setBlock(i + 3, j + 32, k + 8, deepslate, 0, 2);
		world.setBlock(i + 4, j + 32, k + 8, deepslate, 0, 2);
		world.setBlock(i + 5, j + 32, k + 8, deepslate, 0, 2);
		world.setBlock(i + 6, j + 32, k + 8, deepslate, 0, 2);
		world.setBlock(i + 7, j + 32, k + 8, deepslate, 0, 2);
		world.setBlock(i + 8, j + 32, k + 8, deepslate, 0, 2);
		world.setBlock(i + 9, j + 32, k + 8, deepslate, 0, 2);
		world.setBlock(i + 2, j + 32, k + 9, deepslate, 0, 2);
		world.setBlock(i + 3, j + 32, k + 9, deepslate, 0, 2);
		world.setBlock(i + 4, j + 32, k + 9, deepslate, 0, 2);
		world.setBlock(i + 5, j + 32, k + 9, deepslate, 0, 2);
		world.setBlock(i + 6, j + 32, k + 9, deepslate, 0, 2);
		world.setBlock(i + 7, j + 32, k + 9, deepslate, 0, 2);
		world.setBlock(i + 8, j + 32, k + 9, deepslate, 0, 2);
		world.setBlock(i + 0, j + 32, k + 10, sculk_block, 0, 2);
		world.setBlock(i + 3, j + 32, k + 10, deepslate, 0, 2);
		world.setBlock(i + 4, j + 32, k + 10, deepslate, 0, 2);
		world.setBlock(i + 5, j + 32, k + 10, deepslate, 0, 2);
		world.setBlock(i + 6, j + 32, k + 10, deepslate, 0, 2);
		world.setBlock(i + 7, j + 32, k + 10, deepslate, 0, 2);
		world.setBlock(i + 4, j + 33, k + 0, deepslate, 0, 2);
		world.setBlock(i + 5, j + 33, k + 0, deepslate, 0, 2);
		world.setBlock(i + 6, j + 33, k + 0, deepslate, 0, 2);
		world.setBlock(i + 7, j + 33, k + 0, deepslate, 0, 2);
		world.setBlock(i + 2, j + 33, k + 1, deepslate, 0, 2);
		world.setBlock(i + 3, j + 33, k + 1, deepslate, 0, 2);
		world.setBlock(i + 4, j + 33, k + 1, deepslate, 0, 2);
		world.setBlock(i + 5, j + 33, k + 1, deepslate, 0, 2);
		world.setBlock(i + 6, j + 33, k + 1, deepslate, 0, 2);
		world.setBlock(i + 7, j + 33, k + 1, deepslate, 0, 2);
		world.setBlock(i + 8, j + 33, k + 1, deepslate, 0, 2);
		world.setBlock(i + 1, j + 33, k + 2, deepslate, 0, 2);
		world.setBlock(i + 2, j + 33, k + 2, deepslate, 0, 2);
		world.setBlock(i + 3, j + 33, k + 2, deepslate, 0, 2);
		world.setBlock(i + 4, j + 33, k + 2, deepslate, 0, 2);
		world.setBlock(i + 5, j + 33, k + 2, deepslate, 0, 2);
		world.setBlock(i + 6, j + 33, k + 2, deepslate, 0, 2);
		world.setBlock(i + 7, j + 33, k + 2, deepslate, 0, 2);
		world.setBlock(i + 8, j + 33, k + 2, deepslate, 0, 2);
		world.setBlock(i + 9, j + 33, k + 2, deepslate, 0, 2);
		world.setBlock(i + 0, j + 33, k + 3, deepslate, 0, 2);
		world.setBlock(i + 1, j + 33, k + 3, deepslate, 0, 2);
		world.setBlock(i + 2, j + 33, k + 3, deepslate, 0, 2);
		world.setBlock(i + 3, j + 33, k + 3, deepslate, 0, 2);
		world.setBlock(i + 4, j + 33, k + 3, deepslate, 0, 2);
		world.setBlock(i + 5, j + 33, k + 3, deepslate, 0, 2);
		world.setBlock(i + 6, j + 33, k + 3, deepslate, 0, 2);
		world.setBlock(i + 7, j + 33, k + 3, deepslate, 0, 2);
		world.setBlock(i + 8, j + 33, k + 3, deepslate, 0, 2);
		world.setBlock(i + 9, j + 33, k + 3, deepslate, 0, 2);
		world.setBlock(i + 10, j + 33, k + 3, deepslate, 0, 2);
		world.setBlock(i + 0, j + 33, k + 4, deepslate, 0, 2);
		world.setBlock(i + 1, j + 33, k + 4, deepslate, 0, 2);
		world.setBlock(i + 2, j + 33, k + 4, deepslate, 0, 2);
		world.setBlock(i + 3, j + 33, k + 4, deepslate, 0, 2);
		world.setBlock(i + 4, j + 33, k + 4, deepslate, 0, 2);
		world.setBlock(i + 5, j + 33, k + 4, deepslate, 0, 2);
		world.setBlock(i + 6, j + 33, k + 4, deepslate, 0, 2);
		world.setBlock(i + 7, j + 33, k + 4, deepslate, 0, 2);
		world.setBlock(i + 8, j + 33, k + 4, deepslate, 0, 2);
		world.setBlock(i + 9, j + 33, k + 4, deepslate, 0, 2);
		world.setBlock(i + 10, j + 33, k + 4, deepslate, 0, 2);
		world.setBlock(i + 0, j + 33, k + 5, deepslate, 0, 2);
		world.setBlock(i + 1, j + 33, k + 5, deepslate, 0, 2);
		world.setBlock(i + 2, j + 33, k + 5, deepslate, 0, 2);
		world.setBlock(i + 3, j + 33, k + 5, deepslate, 0, 2);
		world.setBlock(i + 4, j + 33, k + 5, deepslate, 0, 2);
		world.setBlock(i + 5, j + 33, k + 5, deepslate, 0, 2);
		world.setBlock(i + 6, j + 33, k + 5, deepslate, 0, 2);
		world.setBlock(i + 7, j + 33, k + 5, deepslate, 0, 2);
		world.setBlock(i + 8, j + 33, k + 5, deepslate, 0, 2);
		world.setBlock(i + 9, j + 33, k + 5, deepslate, 0, 2);
		world.setBlock(i + 10, j + 33, k + 5, deepslate, 0, 2);
		world.setBlock(i + 0, j + 33, k + 6, deepslate, 0, 2);
		world.setBlock(i + 1, j + 33, k + 6, deepslate, 0, 2);
		world.setBlock(i + 2, j + 33, k + 6, deepslate, 0, 2);
		world.setBlock(i + 3, j + 33, k + 6, deepslate, 0, 2);
		world.setBlock(i + 4, j + 33, k + 6, deepslate, 0, 2);
		world.setBlock(i + 5, j + 33, k + 6, deepslate, 0, 2);
		world.setBlock(i + 6, j + 33, k + 6, deepslate, 0, 2);
		world.setBlock(i + 7, j + 33, k + 6, deepslate, 0, 2);
		world.setBlock(i + 8, j + 33, k + 6, deepslate, 0, 2);
		world.setBlock(i + 9, j + 33, k + 6, deepslate, 0, 2);
		world.setBlock(i + 10, j + 33, k + 6, deepslate, 0, 2);
		world.setBlock(i + 0, j + 33, k + 7, deepslate, 0, 2);
		world.setBlock(i + 1, j + 33, k + 7, deepslate, 0, 2);
		world.setBlock(i + 2, j + 33, k + 7, deepslate, 0, 2);
		world.setBlock(i + 3, j + 33, k + 7, deepslate, 0, 2);
		world.setBlock(i + 4, j + 33, k + 7, deepslate, 0, 2);
		world.setBlock(i + 5, j + 33, k + 7, deepslate, 0, 2);
		world.setBlock(i + 6, j + 33, k + 7, deepslate, 0, 2);
		world.setBlock(i + 7, j + 33, k + 7, deepslate, 0, 2);
		world.setBlock(i + 8, j + 33, k + 7, deepslate, 0, 2);
		world.setBlock(i + 9, j + 33, k + 7, deepslate, 0, 2);
		world.setBlock(i + 10, j + 33, k + 7, deepslate, 0, 2);
		world.setBlock(i + 1, j + 33, k + 8, deepslate, 0, 2);
		world.setBlock(i + 2, j + 33, k + 8, deepslate, 0, 2);
		world.setBlock(i + 3, j + 33, k + 8, deepslate, 0, 2);
		world.setBlock(i + 4, j + 33, k + 8, deepslate, 0, 2);
		world.setBlock(i + 5, j + 33, k + 8, deepslate, 0, 2);
		world.setBlock(i + 6, j + 33, k + 8, deepslate, 0, 2);
		world.setBlock(i + 7, j + 33, k + 8, deepslate, 0, 2);
		world.setBlock(i + 8, j + 33, k + 8, deepslate, 0, 2);
		world.setBlock(i + 9, j + 33, k + 8, deepslate, 0, 2);
		world.setBlock(i + 2, j + 33, k + 9, deepslate, 0, 2);
		world.setBlock(i + 3, j + 33, k + 9, deepslate, 0, 2);
		world.setBlock(i + 4, j + 33, k + 9, deepslate, 0, 2);
		world.setBlock(i + 5, j + 33, k + 9, deepslate, 0, 2);
		world.setBlock(i + 6, j + 33, k + 9, deepslate, 0, 2);
		world.setBlock(i + 7, j + 33, k + 9, deepslate, 0, 2);
		world.setBlock(i + 8, j + 33, k + 9, deepslate, 0, 2);
		world.setBlock(i + 0, j + 33, k + 10, deepslate, 0, 2);
		world.setBlock(i + 3, j + 33, k + 10, deepslate, 0, 2);
		world.setBlock(i + 4, j + 33, k + 10, deepslate, 0, 2);
		world.setBlock(i + 5, j + 33, k + 10, deepslate, 0, 2);
		world.setBlock(i + 6, j + 33, k + 10, deepslate, 0, 2);
		world.setBlock(i + 7, j + 33, k + 10, deepslate, 0, 2);
		world.setBlock(i + 4, j + 34, k + 0, deepslate, 0, 2);
		world.setBlock(i + 5, j + 34, k + 0, deepslate, 0, 2);
		world.setBlock(i + 6, j + 34, k + 0, deepslate, 0, 2);
		world.setBlock(i + 7, j + 34, k + 0, deepslate, 0, 2);
		world.setBlock(i + 2, j + 34, k + 1, deepslate, 0, 2);
		world.setBlock(i + 3, j + 34, k + 1, deepslate, 0, 2);
		world.setBlock(i + 4, j + 34, k + 1, deepslate, 0, 2);
		world.setBlock(i + 5, j + 34, k + 1, deepslate, 0, 2);
		world.setBlock(i + 6, j + 34, k + 1, deepslate, 0, 2);
		world.setBlock(i + 7, j + 34, k + 1, deepslate, 0, 2);
		world.setBlock(i + 8, j + 34, k + 1, deepslate, 0, 2);
		world.setBlock(i + 1, j + 34, k + 2, deepslate, 0, 2);
		world.setBlock(i + 2, j + 34, k + 2, deepslate, 0, 2);
		world.setBlock(i + 3, j + 34, k + 2, deepslate, 0, 2);
		world.setBlock(i + 4, j + 34, k + 2, deepslate, 0, 2);
		world.setBlock(i + 5, j + 34, k + 2, deepslate, 0, 2);
		world.setBlock(i + 6, j + 34, k + 2, deepslate, 0, 2);
		world.setBlock(i + 7, j + 34, k + 2, deepslate, 0, 2);
		world.setBlock(i + 8, j + 34, k + 2, deepslate, 0, 2);
		world.setBlock(i + 9, j + 34, k + 2, deepslate, 0, 2);
		world.setBlock(i + 0, j + 34, k + 3, deepslate, 0, 2);
		world.setBlock(i + 1, j + 34, k + 3, deepslate, 0, 2);
		world.setBlock(i + 2, j + 34, k + 3, deepslate, 0, 2);
		world.setBlock(i + 3, j + 34, k + 3, deepslate, 0, 2);
		world.setBlock(i + 4, j + 34, k + 3, deepslate, 0, 2);
		world.setBlock(i + 5, j + 34, k + 3, deepslate, 0, 2);
		world.setBlock(i + 6, j + 34, k + 3, deepslate, 0, 2);
		world.setBlock(i + 7, j + 34, k + 3, deepslate, 0, 2);
		world.setBlock(i + 8, j + 34, k + 3, deepslate, 0, 2);
		world.setBlock(i + 9, j + 34, k + 3, deepslate, 0, 2);
		world.setBlock(i + 10, j + 34, k + 3, deepslate, 0, 2);
		world.setBlock(i + 2, j + 34, k + 4, deepslate, 0, 2);
		world.setBlock(i + 3, j + 34, k + 4, deepslate, 0, 2);
		world.setBlock(i + 4, j + 34, k + 4, deepslate, 0, 2);
		world.setBlock(i + 5, j + 34, k + 4, deepslate, 0, 2);
		world.setBlock(i + 6, j + 34, k + 4, deepslate, 0, 2);
		world.setBlock(i + 7, j + 34, k + 4, deepslate, 0, 2);
		world.setBlock(i + 8, j + 34, k + 4, deepslate, 0, 2);
		world.setBlock(i + 9, j + 34, k + 4, deepslate, 0, 2);
		world.setBlock(i + 10, j + 34, k + 4, deepslate, 0, 2);
		world.setBlock(i + 0, j + 34, k + 5, deepslate, 0, 2);
		world.setBlock(i + 1, j + 34, k + 5, deepslate, 0, 2);
		world.setBlock(i + 2, j + 34, k + 5, deepslate, 0, 2);
		world.setBlock(i + 3, j + 34, k + 5, deepslate, 0, 2);
		world.setBlock(i + 4, j + 34, k + 5, deepslate, 0, 2);
		world.setBlock(i + 5, j + 34, k + 5, deepslate, 0, 2);
		world.setBlock(i + 6, j + 34, k + 5, deepslate, 0, 2);
		world.setBlock(i + 7, j + 34, k + 5, deepslate, 0, 2);
		world.setBlock(i + 8, j + 34, k + 5, deepslate, 0, 2);
		world.setBlock(i + 9, j + 34, k + 5, deepslate, 0, 2);
		world.setBlock(i + 10, j + 34, k + 5, deepslate, 0, 2);
		world.setBlock(i + 0, j + 34, k + 6, deepslate, 0, 2);
		world.setBlock(i + 1, j + 34, k + 6, deepslate, 0, 2);
		world.setBlock(i + 2, j + 34, k + 6, deepslate, 0, 2);
		world.setBlock(i + 3, j + 34, k + 6, deepslate, 0, 2);
		world.setBlock(i + 4, j + 34, k + 6, deepslate, 0, 2);
		world.setBlock(i + 5, j + 34, k + 6, deepslate, 0, 2);
		world.setBlock(i + 6, j + 34, k + 6, deepslate, 0, 2);
		world.setBlock(i + 7, j + 34, k + 6, deepslate, 0, 2);
		world.setBlock(i + 8, j + 34, k + 6, deepslate, 0, 2);
		world.setBlock(i + 9, j + 34, k + 6, deepslate, 0, 2);
		world.setBlock(i + 10, j + 34, k + 6, deepslate, 0, 2);
		world.setBlock(i + 0, j + 34, k + 7, deepslate, 0, 2);
		world.setBlock(i + 1, j + 34, k + 7, deepslate, 0, 2);
		world.setBlock(i + 2, j + 34, k + 7, deepslate, 0, 2);
		world.setBlock(i + 3, j + 34, k + 7, deepslate, 0, 2);
		world.setBlock(i + 4, j + 34, k + 7, deepslate, 0, 2);
		world.setBlock(i + 5, j + 34, k + 7, deepslate, 0, 2);
		world.setBlock(i + 6, j + 34, k + 7, deepslate, 0, 2);
		world.setBlock(i + 7, j + 34, k + 7, deepslate, 0, 2);
		world.setBlock(i + 8, j + 34, k + 7, deepslate, 0, 2);
		world.setBlock(i + 9, j + 34, k + 7, deepslate, 0, 2);
		world.setBlock(i + 10, j + 34, k + 7, deepslate, 0, 2);
		world.setBlock(i + 1, j + 34, k + 8, deepslate, 0, 2);
		world.setBlock(i + 2, j + 34, k + 8, deepslate, 0, 2);
		world.setBlock(i + 3, j + 34, k + 8, deepslate, 0, 2);
		world.setBlock(i + 4, j + 34, k + 8, deepslate, 0, 2);
		world.setBlock(i + 5, j + 34, k + 8, deepslate, 0, 2);
		world.setBlock(i + 6, j + 34, k + 8, deepslate, 0, 2);
		world.setBlock(i + 7, j + 34, k + 8, deepslate, 0, 2);
		world.setBlock(i + 8, j + 34, k + 8, deepslate, 0, 2);
		world.setBlock(i + 9, j + 34, k + 8, deepslate, 0, 2);
		world.setBlock(i + 2, j + 34, k + 9, deepslate, 0, 2);
		world.setBlock(i + 3, j + 34, k + 9, deepslate, 0, 2);
		world.setBlock(i + 4, j + 34, k + 9, deepslate, 0, 2);
		world.setBlock(i + 5, j + 34, k + 9, deepslate, 0, 2);
		world.setBlock(i + 6, j + 34, k + 9, deepslate, 0, 2);
		world.setBlock(i + 7, j + 34, k + 9, deepslate, 0, 2);
		world.setBlock(i + 8, j + 34, k + 9, deepslate, 0, 2);
		world.setBlock(i + 0, j + 34, k + 10, deepslate, 0, 2);
		world.setBlock(i + 3, j + 34, k + 10, deepslate, 0, 2);
		world.setBlock(i + 4, j + 34, k + 10, deepslate, 0, 2);
		world.setBlock(i + 5, j + 34, k + 10, deepslate, 0, 2);
		world.setBlock(i + 6, j + 34, k + 10, deepslate, 0, 2);
		world.setBlock(i + 7, j + 34, k + 10, deepslate, 0, 2);

    	
    	return true;
    }

}
