package com.NovaCraft.world.ancient_city;

import net.minecraft.world.gen.feature.*;
import net.minecraft.block.*;
import net.minecraft.world.*;
import java.util.*;

import com.NovaCraft.registry.OtherModBlocks;
import com.NovaCraftBlocks.NovaCraftBlocks;

import net.minecraft.init.*;
import net.minecraft.tileentity.TileEntityMobSpawner;

public class AncientCityCenterPortalGen3 extends WorldGenerator
{
	public AncientCityCenterPortalGen3() {

	}
	
	private static final Block cobbled_deepslate = OtherModBlocks.cobbled_deepslate;
	private static final Block deepslate = OtherModBlocks.deepslate;
	private static final Block sculk_block = NovaCraftBlocks.sculk_block;
	private static final Block soul_lantern = Blocks.glowstone; //1
	private static final Block soul_sand = Blocks.soul_sand;
	private static final Block SoulFire = OtherModBlocks.SoulFire;
	
	private static final Block polished_deepslate = OtherModBlocks.polished_deepslate;
	private static final Block deepslate_brick_slab = OtherModBlocks.deepslate_brick_slab;
	private static final Block deepslate_tile_stairs = OtherModBlocks.deepslate_tile_stairs;
	private static final Block deepslate_brick_stairs = OtherModBlocks.deepslate_brick_stairs;
	private static final Block polished_deepslate_stairs = OtherModBlocks.polished_deepslate_stairs;
	private static final Block deepslate_wall = OtherModBlocks.deepslate_wall;
	private static final Block fence_dark_oak = OtherModBlocks.fence_dark_oak;
	
	private static final Block deepslate_bricks = OtherModBlocks.deepslate_bricks;
	
	//0 -> deepslate bricks
	//1 -> cracked deepslate bricks
	//2 -> deepslate tiles
	//3 -> cracked deepslate bricks
	//4 -> chiseled deepslate bricks

	public boolean generate(final World world, final Random random, final int i, final int j, final int k) {
		
		world.setBlock(i + 30, j + 8, k + 28, deepslate_bricks, 0, 2);
		world.setBlock(i + 31, j + 8, k + 28, deepslate_bricks, 1, 2);
		world.setBlock(i + 45, j + 8, k + 28, deepslate_tile_stairs, 1, 2);
		world.setBlock(i + 0, j + 8, k + 29, deepslate_tile_stairs, 0, 2);
		world.setBlock(i + 3, j + 8, k + 29, deepslate_tile_stairs, 2, 2);
		world.setBlock(i + 14, j + 8, k + 29, deepslate_bricks, 0, 2);
		world.setBlock(i + 15, j + 8, k + 29, deepslate_bricks, 1, 2);
		world.setBlock(i + 16, j + 8, k + 29, deepslate_bricks, 0, 2);
		world.setBlock(i + 17, j + 8, k + 29, deepslate_bricks, 0, 2);
		world.setBlock(i + 18, j + 8, k + 29, deepslate_bricks, 0, 2);
		world.setBlock(i + 19, j + 8, k + 29, deepslate_bricks, 0, 2);
		world.setBlock(i + 20, j + 8, k + 29, deepslate_bricks, 0, 2);
		world.setBlock(i + 21, j + 8, k + 29, deepslate_bricks, 0, 2);
		world.setBlock(i + 22, j + 8, k + 29, deepslate_bricks, 0, 2);
		world.setBlock(i + 23, j + 8, k + 29, deepslate_bricks, 0, 2);
		world.setBlock(i + 24, j + 8, k + 29, deepslate_bricks, 0, 2);
		world.setBlock(i + 25, j + 8, k + 29, deepslate_bricks, 0, 2);
		world.setBlock(i + 26, j + 8, k + 29, deepslate_bricks, 0, 2);
		world.setBlock(i + 27, j + 8, k + 29, deepslate_bricks, 0, 2);
		world.setBlock(i + 28, j + 8, k + 29, deepslate_bricks, 0, 2);
		world.setBlock(i + 29, j + 8, k + 29, deepslate_bricks, 0, 2);
		world.setBlock(i + 30, j + 8, k + 29, deepslate_bricks, 1, 2);
		world.setBlock(i + 31, j + 8, k + 29, deepslate_bricks, 0, 2);
		world.setBlock(i + 0, j + 8, k + 30, deepslate_tile_stairs, 0, 2);
		world.setBlock(i + 3, j + 8, k + 30, deepslate_tile_stairs, 3, 2);
		world.setBlock(i + 14, j + 8, k + 30, deepslate_bricks, 1, 2);
		world.setBlock(i + 15, j + 8, k + 30, deepslate_bricks, 0, 2);
		world.setBlock(i + 16, j + 8, k + 30, deepslate_bricks, 1, 2);
		world.setBlock(i + 17, j + 8, k + 30, deepslate_bricks, 0, 2);
		world.setBlock(i + 18, j + 8, k + 30, deepslate_bricks, 0, 2);
		world.setBlock(i + 19, j + 8, k + 30, deepslate_bricks, 0, 2);
		world.setBlock(i + 20, j + 8, k + 30, deepslate_bricks, 0, 2);
		world.setBlock(i + 21, j + 8, k + 30, deepslate_bricks, 0, 2);
		world.setBlock(i + 22, j + 8, k + 30, deepslate_bricks, 0, 2);
		world.setBlock(i + 23, j + 8, k + 30, deepslate_bricks, 0, 2);
		world.setBlock(i + 24, j + 8, k + 30, deepslate_bricks, 0, 2);
		world.setBlock(i + 25, j + 8, k + 30, deepslate_bricks, 0, 2);
		world.setBlock(i + 26, j + 8, k + 30, deepslate_bricks, 1, 2);
		world.setBlock(i + 27, j + 8, k + 30, deepslate_bricks, 0, 2);
		world.setBlock(i + 28, j + 8, k + 30, deepslate_bricks, 0, 2);
		world.setBlock(i + 29, j + 8, k + 30, deepslate_bricks, 0, 2);
		world.setBlock(i + 30, j + 8, k + 30, deepslate_bricks, 0, 2);
		world.setBlock(i + 31, j + 8, k + 30, deepslate_bricks, 0, 2);
		world.setBlock(i + 33, j + 8, k + 30, polished_deepslate, 0, 2);
		world.setBlock(i + 42, j + 8, k + 30, deepslate_tile_stairs, 2, 2);
		world.setBlock(i + 0, j + 8, k + 31, deepslate_tile_stairs, 0, 2);
		world.setBlock(i + 14, j + 8, k + 31, deepslate_bricks, 0, 2);
		world.setBlock(i + 15, j + 8, k + 31, deepslate_bricks, 1, 2);
		world.setBlock(i + 16, j + 8, k + 31, deepslate_bricks, 0, 2);
		world.setBlock(i + 17, j + 8, k + 31, deepslate_bricks, 0, 2);
		world.setBlock(i + 18, j + 8, k + 31, deepslate_bricks, 1, 2);
		world.setBlock(i + 19, j + 8, k + 31, deepslate_bricks, 0, 2);
		world.setBlock(i + 20, j + 8, k + 31, deepslate_bricks, 1, 2);
		world.setBlock(i + 21, j + 8, k + 31, deepslate_bricks, 0, 2);
		world.setBlock(i + 22, j + 8, k + 31, deepslate_bricks, 0, 2);
		world.setBlock(i + 23, j + 8, k + 31, deepslate_bricks, 0, 2);
		world.setBlock(i + 24, j + 8, k + 31, deepslate_bricks, 1, 2);
		world.setBlock(i + 25, j + 8, k + 31, deepslate_bricks, 0, 2);
		world.setBlock(i + 26, j + 8, k + 31, deepslate_bricks, 0, 2);
		world.setBlock(i + 27, j + 8, k + 31, deepslate_bricks, 1, 2);
		world.setBlock(i + 28, j + 8, k + 31, deepslate_bricks, 0, 2);
		world.setBlock(i + 42, j + 8, k + 31, deepslate_tile_stairs, 3, 2);
		world.setBlock(i + 14, j + 8, k + 32, deepslate_bricks, 0, 2);
		world.setBlock(i + 15, j + 8, k + 32, deepslate_bricks, 1, 2);
		world.setBlock(i + 16, j + 8, k + 32, deepslate_bricks, 0, 2);
		world.setBlock(i + 17, j + 8, k + 32, deepslate_bricks, 0, 2);
		world.setBlock(i + 18, j + 8, k + 32, deepslate_bricks, 1, 2);
		world.setBlock(i + 19, j + 8, k + 32, deepslate_bricks, 1, 2);
		world.setBlock(i + 20, j + 8, k + 32, deepslate_bricks, 0, 2);
		world.setBlock(i + 21, j + 8, k + 32, deepslate_bricks, 1, 2);
		world.setBlock(i + 22, j + 8, k + 32, deepslate_bricks, 0, 2);
		world.setBlock(i + 23, j + 8, k + 32, deepslate_bricks, 1, 2);
		world.setBlock(i + 24, j + 8, k + 32, deepslate_bricks, 0, 2);
		world.setBlock(i + 25, j + 8, k + 32, deepslate_bricks, 0, 2);
		world.setBlock(i + 26, j + 8, k + 32, deepslate_bricks, 0, 2);
		world.setBlock(i + 27, j + 8, k + 32, deepslate_bricks, 0, 2);
		world.setBlock(i + 28, j + 8, k + 32, deepslate_bricks, 0, 2);
		world.setBlock(i + 0, j + 8, k + 33, deepslate_tile_stairs, 0, 2);
		world.setBlock(i + 14, j + 8, k + 33, deepslate_bricks, 1, 2);
		world.setBlock(i + 15, j + 8, k + 33, deepslate_bricks, 0, 2);
		world.setBlock(i + 16, j + 8, k + 33, deepslate_bricks, 1, 2);
		world.setBlock(i + 17, j + 8, k + 33, deepslate_bricks, 0, 2);
		world.setBlock(i + 18, j + 8, k + 33, deepslate_bricks, 0, 2);
		world.setBlock(i + 19, j + 8, k + 33, deepslate_bricks, 0, 2);
		world.setBlock(i + 20, j + 8, k + 33, deepslate_bricks, 0, 2);
		world.setBlock(i + 21, j + 8, k + 33, deepslate_bricks, 0, 2);
		world.setBlock(i + 22, j + 8, k + 33, deepslate_bricks, 0, 2);
		world.setBlock(i + 23, j + 8, k + 33, deepslate_bricks, 0, 2);
		world.setBlock(i + 24, j + 8, k + 33, deepslate_bricks, 1, 2);
		world.setBlock(i + 25, j + 8, k + 33, deepslate_bricks, 0, 2);
		world.setBlock(i + 26, j + 8, k + 33, deepslate_bricks, 0, 2);
		world.setBlock(i + 27, j + 8, k + 33, deepslate_bricks, 0, 2);
		world.setBlock(i + 28, j + 8, k + 33, polished_deepslate_stairs, 1, 2);
		world.setBlock(i + 35, j + 8, k + 33, Blocks.planks, 5, 2);
		world.setBlock(i + 0, j + 8, k + 34, deepslate_tile_stairs, 0, 2);
		world.setBlock(i + 14, j + 8, k + 34, deepslate_bricks, 0, 2);
		world.setBlock(i + 15, j + 8, k + 34, deepslate_bricks, 1, 2);
		world.setBlock(i + 16, j + 8, k + 34, deepslate_bricks, 0, 2);
		world.setBlock(i + 17, j + 8, k + 34, deepslate_bricks, 0, 2);
		world.setBlock(i + 18, j + 8, k + 34, deepslate_bricks, 0, 2);
		world.setBlock(i + 19, j + 8, k + 34, deepslate_bricks, 1, 2);
		world.setBlock(i + 20, j + 8, k + 34, deepslate_bricks, 0, 2);
		world.setBlock(i + 21, j + 8, k + 34, deepslate_bricks, 0, 2);
		world.setBlock(i + 22, j + 8, k + 34, deepslate_bricks, 0, 2);
		world.setBlock(i + 23, j + 8, k + 34, deepslate_bricks, 0, 2);
		world.setBlock(i + 24, j + 8, k + 34, deepslate_bricks, 0, 2);
		world.setBlock(i + 25, j + 8, k + 34, deepslate_bricks, 0, 2);
		world.setBlock(i + 26, j + 8, k + 34, deepslate_bricks, 0, 2);
		world.setBlock(i + 27, j + 8, k + 34, deepslate_bricks, 0, 2);
		world.setBlock(i + 28, j + 8, k + 34, polished_deepslate_stairs, 1, 2);
		world.setBlock(i + 3, j + 8, k + 35, deepslate_tile_stairs, 2, 2);
		world.setBlock(i + 14, j + 8, k + 35, deepslate_bricks, 0, 2);
		world.setBlock(i + 15, j + 8, k + 35, deepslate_bricks, 0, 2);
		world.setBlock(i + 16, j + 8, k + 35, deepslate_bricks, 0, 2);
		world.setBlock(i + 17, j + 8, k + 35, deepslate_bricks, 0, 2);
		world.setBlock(i + 18, j + 8, k + 35, deepslate_bricks, 0, 2);
		world.setBlock(i + 19, j + 8, k + 35, deepslate_bricks, 0, 2);
		world.setBlock(i + 20, j + 8, k + 35, deepslate_bricks, 0, 2);
		world.setBlock(i + 21, j + 8, k + 35, deepslate_bricks, 1, 2);
		world.setBlock(i + 22, j + 8, k + 35, deepslate_bricks, 0, 2);
		world.setBlock(i + 23, j + 8, k + 35, deepslate_bricks, 1, 2);
		world.setBlock(i + 24, j + 8, k + 35, deepslate_bricks, 1, 2);
		world.setBlock(i + 25, j + 8, k + 35, deepslate_bricks, 0, 2);
		world.setBlock(i + 26, j + 8, k + 35, deepslate_bricks, 0, 2);
		world.setBlock(i + 27, j + 8, k + 35, deepslate_bricks, 0, 2);
		world.setBlock(i + 28, j + 8, k + 35, polished_deepslate_stairs, 1, 2);
		world.setBlock(i + 38, j + 8, k + 35, Blocks.planks, 5, 2);
		world.setBlock(i + 41, j + 8, k + 35, Blocks.planks, 5, 2);
		world.setBlock(i + 0, j + 8, k + 36, deepslate_tile_stairs, 0, 2);
		world.setBlock(i + 3, j + 8, k + 36, deepslate_tile_stairs, 3, 2);
		world.setBlock(i + 14, j + 8, k + 36, deepslate_bricks, 1, 2);
		world.setBlock(i + 15, j + 8, k + 36, deepslate_bricks, 0, 2);
		world.setBlock(i + 16, j + 8, k + 36, deepslate_bricks, 0, 2);
		world.setBlock(i + 17, j + 8, k + 36, deepslate_bricks, 0, 2);
		world.setBlock(i + 18, j + 8, k + 36, deepslate_bricks, 0, 2);
		world.setBlock(i + 19, j + 8, k + 36, deepslate_bricks, 0, 2);
		world.setBlock(i + 20, j + 8, k + 36, deepslate_bricks, 1, 2);
		world.setBlock(i + 21, j + 8, k + 36, deepslate_bricks, 0, 2);
		world.setBlock(i + 22, j + 8, k + 36, deepslate_bricks, 0, 2);
		world.setBlock(i + 23, j + 8, k + 36, deepslate_bricks, 0, 2);
		world.setBlock(i + 24, j + 8, k + 36, deepslate_bricks, 1, 2);
		world.setBlock(i + 25, j + 8, k + 36, deepslate_bricks, 0, 2);
		world.setBlock(i + 26, j + 8, k + 36, deepslate_bricks, 0, 2);
		world.setBlock(i + 27, j + 8, k + 36, deepslate_bricks, 0, 2);
		world.setBlock(i + 28, j + 8, k + 36, deepslate_bricks, 0, 2);
		world.setBlock(i + 0, j + 8, k + 37, deepslate_tile_stairs, 0, 2);
		world.setBlock(i + 14, j + 8, k + 37, deepslate_bricks, 0, 2);
		world.setBlock(i + 15, j + 8, k + 37, deepslate_bricks, 1, 2);
		world.setBlock(i + 16, j + 8, k + 37, deepslate_bricks, 0, 2);
		world.setBlock(i + 17, j + 8, k + 37, deepslate_bricks, 0, 2);
		world.setBlock(i + 18, j + 8, k + 37, deepslate_bricks, 0, 2);
		world.setBlock(i + 19, j + 8, k + 37, deepslate_bricks, 0, 2);
		world.setBlock(i + 20, j + 8, k + 37, deepslate_bricks, 1, 2);
		world.setBlock(i + 21, j + 8, k + 37, deepslate_bricks, 0, 2);
		world.setBlock(i + 22, j + 8, k + 37, deepslate_bricks, 0, 2);
		world.setBlock(i + 23, j + 8, k + 37, deepslate_bricks, 0, 2);
		world.setBlock(i + 24, j + 8, k + 37, deepslate_bricks, 1, 2);
		world.setBlock(i + 25, j + 8, k + 37, deepslate_bricks, 0, 2);
		world.setBlock(i + 26, j + 8, k + 37, deepslate_bricks, 0, 2);
		world.setBlock(i + 27, j + 8, k + 37, deepslate_bricks, 0, 2);
		world.setBlock(i + 28, j + 8, k + 37, deepslate_bricks, 0, 2);
		world.setBlock(i + 42, j + 8, k + 37, deepslate_tile_stairs, 2, 2);
		world.setBlock(i + 0, j + 8, k + 38, deepslate_tile_stairs, 0, 2);
		world.setBlock(i + 14, j + 8, k + 38, deepslate_bricks, 0, 2);
		world.setBlock(i + 15, j + 8, k + 38, deepslate_bricks, 0, 2);
		world.setBlock(i + 16, j + 8, k + 38, deepslate_bricks, 0, 2);
		world.setBlock(i + 17, j + 8, k + 38, deepslate_bricks, 0, 2);
		world.setBlock(i + 18, j + 8, k + 38, deepslate_bricks, 1, 2);
		world.setBlock(i + 19, j + 8, k + 38, deepslate_bricks, 0, 2);
		world.setBlock(i + 20, j + 8, k + 38, deepslate_bricks, 1, 2);
		world.setBlock(i + 21, j + 8, k + 38, deepslate_bricks, 0, 2);
		world.setBlock(i + 22, j + 8, k + 38, deepslate_bricks, 0, 2);
		world.setBlock(i + 23, j + 8, k + 38, deepslate_bricks, 1, 2);
		world.setBlock(i + 24, j + 8, k + 38, deepslate_bricks, 1, 2);
		world.setBlock(i + 25, j + 8, k + 38, deepslate_bricks, 1, 2);
		world.setBlock(i + 26, j + 8, k + 38, deepslate_bricks, 1, 2);
		world.setBlock(i + 27, j + 8, k + 38, deepslate_bricks, 0, 2);
		world.setBlock(i + 28, j + 8, k + 38, deepslate_bricks, 1, 2);
		world.setBlock(i + 29, j + 8, k + 38, deepslate_bricks, 1, 2);
		world.setBlock(i + 30, j + 8, k + 38, deepslate_bricks, 1, 2);
		world.setBlock(i + 31, j + 8, k + 38, deepslate_bricks, 1, 2);
		world.setBlock(i + 33, j + 8, k + 38, polished_deepslate, 0, 2);
		world.setBlock(i + 42, j + 8, k + 38, deepslate_tile_stairs, 3, 2);
		world.setBlock(i + 0, j + 8, k + 39, deepslate_tile_stairs, 0, 2);
		world.setBlock(i + 14, j + 8, k + 39, deepslate_bricks, 0, 2);
		world.setBlock(i + 15, j + 8, k + 39, deepslate_bricks, 0, 2);
		world.setBlock(i + 16, j + 8, k + 39, deepslate_bricks, 1, 2);
		world.setBlock(i + 17, j + 8, k + 39, deepslate_bricks, 1, 2);
		world.setBlock(i + 18, j + 8, k + 39, deepslate_bricks, 1, 2);
		world.setBlock(i + 19, j + 8, k + 39, deepslate_bricks, 0, 2);
		world.setBlock(i + 20, j + 8, k + 39, deepslate_bricks, 0, 2);
		world.setBlock(i + 21, j + 8, k + 39, deepslate_bricks, 1, 2);
		world.setBlock(i + 22, j + 8, k + 39, deepslate_bricks, 0, 2);
		world.setBlock(i + 23, j + 8, k + 39, deepslate_bricks, 0, 2);
		world.setBlock(i + 24, j + 8, k + 39, deepslate_bricks, 1, 2);
		world.setBlock(i + 25, j + 8, k + 39, deepslate_bricks, 1, 2);
		world.setBlock(i + 26, j + 8, k + 39, deepslate_bricks, 0, 2);
		world.setBlock(i + 27, j + 8, k + 39, deepslate_bricks, 1, 2);
		world.setBlock(i + 28, j + 8, k + 39, deepslate_bricks, 0, 2);
		world.setBlock(i + 29, j + 8, k + 39, deepslate_bricks, 0, 2);
		world.setBlock(i + 30, j + 8, k + 39, deepslate_bricks, 0, 2);
		world.setBlock(i + 31, j + 8, k + 39, deepslate_bricks, 0, 2);
		world.setBlock(i + 14, j + 8, k + 40, deepslate_bricks, 0, 2);
		world.setBlock(i + 15, j + 8, k + 40, deepslate_bricks, 0, 2);
		world.setBlock(i + 16, j + 8, k + 40, deepslate_bricks, 0, 2);
		world.setBlock(i + 17, j + 8, k + 40, deepslate_bricks, 1, 2);
		world.setBlock(i + 18, j + 8, k + 40, deepslate_bricks, 0, 2);
		world.setBlock(i + 19, j + 8, k + 40, deepslate_bricks, 0, 2);
		world.setBlock(i + 20, j + 8, k + 40, deepslate_bricks, 0, 2);
		world.setBlock(i + 21, j + 8, k + 40, deepslate_bricks, 0, 2);
		world.setBlock(i + 22, j + 8, k + 40, deepslate_bricks, 0, 2);
		world.setBlock(i + 23, j + 8, k + 40, deepslate_bricks, 0, 2);
		world.setBlock(i + 24, j + 8, k + 40, deepslate_bricks, 0, 2);
		world.setBlock(i + 25, j + 8, k + 40, deepslate_bricks, 0, 2);
		world.setBlock(i + 26, j + 8, k + 40, deepslate_bricks, 1, 2);
		world.setBlock(i + 27, j + 8, k + 40, deepslate_bricks, 0, 2);
		world.setBlock(i + 28, j + 8, k + 40, deepslate_bricks, 1, 2);
		world.setBlock(i + 29, j + 8, k + 40, deepslate_bricks, 0, 2);
		world.setBlock(i + 30, j + 8, k + 40, deepslate_bricks, 0, 2);
		world.setBlock(i + 31, j + 8, k + 40, deepslate_bricks, 0, 2);
		world.setBlock(i + 45, j + 8, k + 40, deepslate_tile_stairs, 1, 2);
		world.setBlock(i + 0, j + 8, k + 41, deepslate_tile_stairs, 0, 2);
		world.setBlock(i + 3, j + 8, k + 41, deepslate_tile_stairs, 2, 2);
		world.setBlock(i + 14, j + 8, k + 41, deepslate_bricks, 1, 2);
		world.setBlock(i + 15, j + 8, k + 41, deepslate_bricks, 0, 2);
		world.setBlock(i + 16, j + 8, k + 41, deepslate_bricks, 0, 2);
		world.setBlock(i + 17, j + 8, k + 41, deepslate_bricks, 1, 2);
		world.setBlock(i + 18, j + 8, k + 41, deepslate_bricks, 0, 2);
		world.setBlock(i + 19, j + 8, k + 41, deepslate_bricks, 0, 2);
		world.setBlock(i + 20, j + 8, k + 41, deepslate_bricks, 0, 2);
		world.setBlock(i + 21, j + 8, k + 41, deepslate_bricks, 0, 2);
		world.setBlock(i + 22, j + 8, k + 41, deepslate_bricks, 0, 2);
		world.setBlock(i + 23, j + 8, k + 41, deepslate_bricks, 0, 2);
		world.setBlock(i + 24, j + 8, k + 41, deepslate_bricks, 0, 2);
		world.setBlock(i + 25, j + 8, k + 41, deepslate_bricks, 0, 2);
		world.setBlock(i + 26, j + 8, k + 41, deepslate_bricks, 0, 2);
		world.setBlock(i + 27, j + 8, k + 41, deepslate_bricks, 0, 2);
		world.setBlock(i + 28, j + 8, k + 41, deepslate_bricks, 0, 2);
		world.setBlock(i + 29, j + 8, k + 41, deepslate_bricks, 1, 2);
		world.setBlock(i + 30, j + 8, k + 41, deepslate_bricks, 1, 2);
		world.setBlock(i + 31, j + 8, k + 41, deepslate_bricks, 1, 2);
		world.setBlock(i + 45, j + 8, k + 41, deepslate_tile_stairs, 1, 2);
		world.setBlock(i + 0, j + 8, k + 42, deepslate_tile_stairs, 0, 2);
		world.setBlock(i + 3, j + 8, k + 42, deepslate_tile_stairs, 3, 2);
		world.setBlock(i + 14, j + 8, k + 42, deepslate_bricks, 0, 2);
		world.setBlock(i + 15, j + 8, k + 42, deepslate_bricks, 0, 2);
		world.setBlock(i + 16, j + 8, k + 42, deepslate_bricks, 0, 2);
		world.setBlock(i + 17, j + 8, k + 42, deepslate_bricks, 1, 2);
		world.setBlock(i + 18, j + 8, k + 42, deepslate_bricks, 0, 2);
		world.setBlock(i + 19, j + 8, k + 42, deepslate_bricks, 1, 2);
		world.setBlock(i + 20, j + 8, k + 42, deepslate_bricks, 0, 2);
		world.setBlock(i + 21, j + 8, k + 42, deepslate_bricks, 1, 2);
		world.setBlock(i + 22, j + 8, k + 42, deepslate_bricks, 1, 2);
		world.setBlock(i + 23, j + 8, k + 42, deepslate_bricks, 0, 2);
		world.setBlock(i + 24, j + 8, k + 42, deepslate_bricks, 0, 2);
		world.setBlock(i + 25, j + 8, k + 42, deepslate_bricks, 0, 2);
		world.setBlock(i + 26, j + 8, k + 42, deepslate_bricks, 0, 2);
		world.setBlock(i + 27, j + 8, k + 42, deepslate_bricks, 0, 2);
		world.setBlock(i + 28, j + 8, k + 42, deepslate_bricks, 0, 2);
		world.setBlock(i + 29, j + 8, k + 42, deepslate_bricks, 1, 2);
		world.setBlock(i + 30, j + 8, k + 42, deepslate_bricks, 0, 2);
		world.setBlock(i + 31, j + 8, k + 42, deepslate_bricks, 1, 2);
		world.setBlock(i + 14, j + 8, k + 43, deepslate_bricks, 1, 2);
		world.setBlock(i + 15, j + 8, k + 43, deepslate_bricks, 1, 2);
		world.setBlock(i + 16, j + 8, k + 43, deepslate_bricks, 0, 2);
		world.setBlock(i + 17, j + 8, k + 43, deepslate_bricks, 0, 2);
		world.setBlock(i + 18, j + 8, k + 43, deepslate_bricks, 0, 2);
		world.setBlock(i + 19, j + 8, k + 43, deepslate_bricks, 1, 2);
		world.setBlock(i + 20, j + 8, k + 43, deepslate_bricks, 0, 2);
		world.setBlock(i + 21, j + 8, k + 43, deepslate_bricks, 0, 2);
		world.setBlock(i + 22, j + 8, k + 43, deepslate_bricks, 0, 2);
		world.setBlock(i + 23, j + 8, k + 43, deepslate_bricks, 0, 2);
		world.setBlock(i + 24, j + 8, k + 43, deepslate_bricks, 0, 2);
		world.setBlock(i + 25, j + 8, k + 43, deepslate_bricks, 0, 2);
		world.setBlock(i + 26, j + 8, k + 43, deepslate_bricks, 0, 2);
		world.setBlock(i + 27, j + 8, k + 43, deepslate_bricks, 1, 2);
		world.setBlock(i + 28, j + 8, k + 43, deepslate_brick_slab, 0, 2);
		world.setBlock(i + 29, j + 8, k + 43, deepslate_brick_slab, 0, 2);
		world.setBlock(i + 30, j + 8, k + 43, deepslate_brick_slab, 0, 2);
		world.setBlock(i + 31, j + 8, k + 43, deepslate_brick_slab, 0, 2);
		world.setBlock(i + 0, j + 8, k + 44, deepslate_tile_stairs, 0, 2);
		world.setBlock(i + 14, j + 8, k + 44, deepslate_bricks, 1, 2);
		world.setBlock(i + 15, j + 8, k + 44, deepslate_bricks, 1, 2);
		world.setBlock(i + 16, j + 8, k + 44, deepslate_bricks, 1, 2);
		world.setBlock(i + 17, j + 8, k + 44, deepslate_bricks, 1, 2);
		world.setBlock(i + 18, j + 8, k + 44, deepslate_bricks, 0, 2);
		world.setBlock(i + 19, j + 8, k + 44, deepslate_bricks, 0, 2);
		world.setBlock(i + 20, j + 8, k + 44, deepslate_bricks, 1, 2);
		world.setBlock(i + 21, j + 8, k + 44, deepslate_bricks, 0, 2);
		world.setBlock(i + 22, j + 8, k + 44, deepslate_bricks, 0, 2);
		world.setBlock(i + 23, j + 8, k + 44, deepslate_bricks, 0, 2);
		world.setBlock(i + 24, j + 8, k + 44, deepslate_bricks, 1, 2);
		world.setBlock(i + 25, j + 8, k + 44, deepslate_bricks, 0, 2);
		world.setBlock(i + 26, j + 8, k + 44, deepslate_bricks, 0, 2);
		world.setBlock(i + 27, j + 8, k + 44, deepslate_bricks, 0, 2);
		world.setBlock(i + 42, j + 8, k + 44, deepslate_tile_stairs, 2, 2);
		world.setBlock(i + 0, j + 8, k + 45, deepslate_tile_stairs, 0, 2);
		world.setBlock(i + 14, j + 8, k + 45, deepslate_bricks, 0, 2);
		world.setBlock(i + 15, j + 8, k + 45, deepslate_bricks, 0, 2);
		world.setBlock(i + 16, j + 8, k + 45, deepslate_bricks, 0, 2);
		world.setBlock(i + 17, j + 8, k + 45, deepslate_bricks, 0, 2);
		world.setBlock(i + 18, j + 8, k + 45, deepslate_bricks, 0, 2);
		world.setBlock(i + 19, j + 8, k + 45, deepslate_bricks, 0, 2);
		world.setBlock(i + 20, j + 8, k + 45, deepslate_bricks, 1, 2);
		world.setBlock(i + 21, j + 8, k + 45, deepslate_bricks, 0, 2);
		world.setBlock(i + 22, j + 8, k + 45, deepslate_bricks, 0, 2);
		world.setBlock(i + 23, j + 8, k + 45, deepslate_bricks, 1, 2);
		world.setBlock(i + 24, j + 8, k + 45, deepslate_bricks, 0, 2);
		world.setBlock(i + 25, j + 8, k + 45, deepslate_bricks, 0, 2);
		world.setBlock(i + 26, j + 8, k + 45, deepslate_bricks, 0, 2);
		world.setBlock(i + 27, j + 8, k + 45, deepslate_bricks, 0, 2);
		world.setBlock(i + 42, j + 8, k + 45, deepslate_tile_stairs, 3, 2);
		world.setBlock(i + 0, j + 8, k + 46, deepslate_tile_stairs, 0, 2);
		world.setBlock(i + 14, j + 8, k + 46, deepslate_bricks, 1, 2);
		world.setBlock(i + 15, j + 8, k + 46, deepslate_bricks, 0, 2);
		world.setBlock(i + 16, j + 8, k + 46, deepslate_bricks, 0, 2);
		world.setBlock(i + 17, j + 8, k + 46, deepslate_bricks, 0, 2);
		world.setBlock(i + 18, j + 8, k + 46, deepslate_bricks, 0, 2);
		world.setBlock(i + 19, j + 8, k + 46, deepslate_bricks, 0, 2);
		world.setBlock(i + 20, j + 8, k + 46, deepslate_bricks, 0, 2);
		world.setBlock(i + 21, j + 8, k + 46, deepslate_bricks, 0, 2);
		world.setBlock(i + 22, j + 8, k + 46, deepslate_bricks, 0, 2);
		world.setBlock(i + 23, j + 8, k + 46, deepslate_bricks, 1, 2);
		world.setBlock(i + 24, j + 8, k + 46, deepslate_bricks, 0, 2);
		world.setBlock(i + 25, j + 8, k + 46, deepslate_bricks, 0, 2);
		world.setBlock(i + 26, j + 8, k + 46, deepslate_bricks, 0, 2);
		world.setBlock(i + 27, j + 8, k + 46, deepslate_bricks, 0, 2);
		world.setBlock(i + 45, j + 8, k + 46, deepslate_tile_stairs, 1, 2);
		world.setBlock(i + 0, j + 8, k + 47, deepslate_tile_stairs, 0, 2);
		world.setBlock(i + 3, j + 8, k + 47, deepslate_tile_stairs, 2, 2);
		world.setBlock(i + 14, j + 8, k + 47, deepslate_bricks, 0, 2);
		world.setBlock(i + 15, j + 8, k + 47, deepslate_bricks, 0, 2);
		world.setBlock(i + 16, j + 8, k + 47, deepslate_bricks, 0, 2);
		world.setBlock(i + 17, j + 8, k + 47, deepslate_bricks, 1, 2);
		world.setBlock(i + 18, j + 8, k + 47, deepslate_bricks, 1, 2);
		world.setBlock(i + 19, j + 8, k + 47, deepslate_bricks, 1, 2);
		world.setBlock(i + 20, j + 8, k + 47, deepslate_bricks, 0, 2);
		world.setBlock(i + 21, j + 8, k + 47, deepslate_bricks, 0, 2);
		world.setBlock(i + 22, j + 8, k + 47, deepslate_bricks, 0, 2);
		world.setBlock(i + 23, j + 8, k + 47, deepslate_bricks, 0, 2);
		world.setBlock(i + 24, j + 8, k + 47, deepslate_bricks, 1, 2);
		world.setBlock(i + 25, j + 8, k + 47, deepslate_bricks, 1, 2);
		world.setBlock(i + 26, j + 8, k + 47, deepslate_bricks, 0, 2);
		world.setBlock(i + 27, j + 8, k + 47, deepslate_bricks, 0, 2);
		world.setBlock(i + 45, j + 8, k + 47, deepslate_tile_stairs, 1, 2);
		world.setBlock(i + 3, j + 8, k + 48, deepslate_tile_stairs, 3, 2);
		world.setBlock(i + 14, j + 8, k + 48, deepslate_bricks, 0, 2);
		world.setBlock(i + 15, j + 8, k + 48, deepslate_bricks, 0, 2);
		world.setBlock(i + 16, j + 8, k + 48, deepslate_bricks, 0, 2);
		world.setBlock(i + 17, j + 8, k + 48, deepslate_bricks, 1, 2);
		world.setBlock(i + 18, j + 8, k + 48, deepslate_bricks, 1, 2);
		world.setBlock(i + 19, j + 8, k + 48, deepslate_bricks, 0, 2);
		world.setBlock(i + 20, j + 8, k + 48, deepslate_bricks, 0, 2);
		world.setBlock(i + 21, j + 8, k + 48, deepslate_bricks, 0, 2);
		world.setBlock(i + 22, j + 8, k + 48, deepslate_bricks, 0, 2);
		world.setBlock(i + 23, j + 8, k + 48, deepslate_bricks, 1, 2);
		world.setBlock(i + 24, j + 8, k + 48, deepslate_bricks, 0, 2);
		world.setBlock(i + 25, j + 8, k + 48, deepslate_bricks, 0, 2);
		world.setBlock(i + 26, j + 8, k + 48, deepslate_bricks, 1, 2);
		world.setBlock(i + 27, j + 8, k + 48, deepslate_bricks, 0, 2);
		world.setBlock(i + 0, j + 8, k + 49, deepslate_tile_stairs, 0, 2);
		world.setBlock(i + 14, j + 8, k + 49, deepslate_bricks, 0, 2);
		world.setBlock(i + 15, j + 8, k + 49, deepslate_bricks, 0, 2);
		world.setBlock(i + 16, j + 8, k + 49, deepslate_bricks, 0, 2);
		world.setBlock(i + 17, j + 8, k + 49, deepslate_bricks, 1, 2);
		world.setBlock(i + 18, j + 8, k + 49, deepslate_bricks, 1, 2);
		world.setBlock(i + 19, j + 8, k + 49, deepslate_bricks, 0, 2);
		world.setBlock(i + 20, j + 8, k + 49, deepslate_bricks, 0, 2);
		world.setBlock(i + 21, j + 8, k + 49, deepslate_bricks, 1, 2);
		world.setBlock(i + 22, j + 8, k + 49, deepslate_bricks, 0, 2);
		world.setBlock(i + 23, j + 8, k + 49, deepslate_bricks, 0, 2);
		world.setBlock(i + 24, j + 8, k + 49, deepslate_bricks, 0, 2);
		world.setBlock(i + 25, j + 8, k + 49, deepslate_bricks, 0, 2);
		world.setBlock(i + 26, j + 8, k + 49, deepslate_bricks, 0, 2);
		world.setBlock(i + 27, j + 8, k + 49, deepslate_bricks, 0, 2);
		world.setBlock(i + 0, j + 8, k + 50, deepslate_tile_stairs, 0, 2);
		world.setBlock(i + 14, j + 8, k + 50, deepslate_bricks, 0, 2);
		world.setBlock(i + 15, j + 8, k + 50, deepslate_bricks, 1, 2);
		world.setBlock(i + 16, j + 8, k + 50, deepslate_bricks, 0, 2);
		world.setBlock(i + 17, j + 8, k + 50, deepslate_bricks, 0, 2);
		world.setBlock(i + 18, j + 8, k + 50, deepslate_bricks, 0, 2);
		world.setBlock(i + 19, j + 8, k + 50, deepslate_bricks, 0, 2);
		world.setBlock(i + 20, j + 8, k + 50, deepslate_bricks, 0, 2);
		world.setBlock(i + 21, j + 8, k + 50, deepslate_bricks, 0, 2);
		world.setBlock(i + 22, j + 8, k + 50, deepslate_bricks, 0, 2);
		world.setBlock(i + 23, j + 8, k + 50, deepslate_bricks, 1, 2);
		world.setBlock(i + 24, j + 8, k + 50, deepslate_bricks, 1, 2);
		world.setBlock(i + 25, j + 8, k + 50, deepslate_bricks, 1, 2);
		world.setBlock(i + 26, j + 8, k + 50, deepslate_bricks, 0, 2);
		world.setBlock(i + 27, j + 8, k + 50, deepslate_bricks, 0, 2);
		world.setBlock(i + 42, j + 8, k + 50, deepslate_tile_stairs, 2, 2);
		world.setBlock(i + 14, j + 8, k + 51, deepslate_bricks, 1, 2);
		world.setBlock(i + 15, j + 8, k + 51, deepslate_bricks, 1, 2);
		world.setBlock(i + 16, j + 8, k + 51, deepslate_bricks, 0, 2);
		world.setBlock(i + 17, j + 8, k + 51, deepslate_bricks, 0, 2);
		world.setBlock(i + 18, j + 8, k + 51, deepslate_bricks, 0, 2);
		world.setBlock(i + 19, j + 8, k + 51, deepslate_bricks, 1, 2);
		world.setBlock(i + 20, j + 8, k + 51, deepslate_bricks, 0, 2);
		world.setBlock(i + 21, j + 8, k + 51, deepslate_bricks, 0, 2);
		world.setBlock(i + 22, j + 8, k + 51, deepslate_bricks, 0, 2);
		world.setBlock(i + 23, j + 8, k + 51, deepslate_bricks, 1, 2);
		world.setBlock(i + 24, j + 8, k + 51, deepslate_bricks, 0, 2);
		world.setBlock(i + 25, j + 8, k + 51, deepslate_bricks, 0, 2);
		world.setBlock(i + 26, j + 8, k + 51, deepslate_bricks, 0, 2);
		world.setBlock(i + 27, j + 8, k + 51, deepslate_bricks, 0, 2);
		world.setBlock(i + 42, j + 8, k + 51, deepslate_tile_stairs, 3, 2);
		world.setBlock(i + 0, j + 8, k + 52, deepslate_tile_stairs, 0, 2);
		world.setBlock(i + 14, j + 8, k + 52, deepslate_bricks, 1, 2);
		world.setBlock(i + 15, j + 8, k + 52, deepslate_bricks, 1, 2);
		world.setBlock(i + 16, j + 8, k + 52, deepslate_bricks, 0, 2);
		world.setBlock(i + 17, j + 8, k + 52, deepslate_bricks, 1, 2);
		world.setBlock(i + 18, j + 8, k + 52, deepslate_bricks, 0, 2);
		world.setBlock(i + 19, j + 8, k + 52, deepslate_bricks, 0, 2);
		world.setBlock(i + 20, j + 8, k + 52, deepslate_bricks, 0, 2);
		world.setBlock(i + 21, j + 8, k + 52, deepslate_bricks, 0, 2);
		world.setBlock(i + 22, j + 8, k + 52, deepslate_bricks, 0, 2);
		world.setBlock(i + 23, j + 8, k + 52, deepslate_bricks, 0, 2);
		world.setBlock(i + 24, j + 8, k + 52, deepslate_bricks, 0, 2);
		world.setBlock(i + 25, j + 8, k + 52, deepslate_bricks, 0, 2);
		world.setBlock(i + 26, j + 8, k + 52, deepslate_bricks, 1, 2);
		world.setBlock(i + 27, j + 8, k + 52, deepslate_bricks, 0, 2);
		world.setBlock(i + 45, j + 8, k + 52, deepslate_tile_stairs, 1, 2);
		world.setBlock(i + 0, j + 8, k + 53, deepslate_tile_stairs, 0, 2);
		world.setBlock(i + 3, j + 8, k + 53, deepslate_tile_stairs, 2, 2);
		world.setBlock(i + 14, j + 8, k + 53, deepslate_bricks, 1, 2);
		world.setBlock(i + 15, j + 8, k + 53, deepslate_bricks, 0, 2);
		world.setBlock(i + 16, j + 8, k + 53, deepslate_bricks, 0, 2);
		world.setBlock(i + 17, j + 8, k + 53, deepslate_bricks, 1, 2);
		world.setBlock(i + 18, j + 8, k + 53, deepslate_bricks, 0, 2);
		world.setBlock(i + 19, j + 8, k + 53, deepslate_bricks, 1, 2);
		world.setBlock(i + 20, j + 8, k + 53, deepslate_bricks, 0, 2);
		world.setBlock(i + 21, j + 8, k + 53, deepslate_bricks, 0, 2);
		world.setBlock(i + 22, j + 8, k + 53, deepslate_bricks, 0, 2);
		world.setBlock(i + 23, j + 8, k + 53, deepslate_bricks, 0, 2);
		world.setBlock(i + 24, j + 8, k + 53, deepslate_bricks, 0, 2);
		world.setBlock(i + 25, j + 8, k + 53, deepslate_bricks, 0, 2);
		world.setBlock(i + 26, j + 8, k + 53, deepslate_bricks, 0, 2);
		world.setBlock(i + 27, j + 8, k + 53, deepslate_bricks, 0, 2);
		world.setBlock(i + 45, j + 8, k + 53, deepslate_tile_stairs, 1, 2);
		world.setBlock(i + 0, j + 8, k + 54, deepslate_tile_stairs, 0, 2);
		world.setBlock(i + 3, j + 8, k + 54, deepslate_tile_stairs, 3, 2);
		world.setBlock(i + 14, j + 8, k + 54, deepslate_bricks, 0, 2);
		world.setBlock(i + 15, j + 8, k + 54, deepslate_bricks, 1, 2);
		world.setBlock(i + 16, j + 8, k + 54, deepslate_bricks, 0, 2);
		world.setBlock(i + 17, j + 8, k + 54, deepslate_bricks, 0, 2);
		world.setBlock(i + 18, j + 8, k + 54, deepslate_bricks, 1, 2);
		world.setBlock(i + 19, j + 8, k + 54, deepslate_bricks, 1, 2);
		world.setBlock(i + 20, j + 8, k + 54, deepslate_bricks, 0, 2);
		world.setBlock(i + 21, j + 8, k + 54, deepslate_bricks, 0, 2);
		world.setBlock(i + 22, j + 8, k + 54, deepslate_bricks, 1, 2);
		world.setBlock(i + 23, j + 8, k + 54, deepslate_bricks, 0, 2);
		world.setBlock(i + 24, j + 8, k + 54, deepslate_bricks, 1, 2);
		world.setBlock(i + 25, j + 8, k + 54, deepslate_bricks, 0, 2);
		world.setBlock(i + 26, j + 8, k + 54, deepslate_bricks, 1, 2);
		world.setBlock(i + 27, j + 8, k + 54, deepslate_bricks, 1, 2);
		world.setBlock(i + 45, j + 8, k + 55, deepslate_tile_stairs, 1, 2);
		world.setBlock(i + 3, j + 8, k + 56, deepslate_tile_stairs, 2, 2);
		world.setBlock(i + 45, j + 8, k + 56, deepslate_tile_stairs, 1, 2);
		world.setBlock(i + 3, j + 8, k + 57, deepslate_tile_stairs, 3, 2);
		world.setBlock(i + 0, j + 8, k + 58, deepslate_tile_stairs, 0, 2);
		world.setBlock(i + 0, j + 8, k + 59, deepslate_tile_stairs, 0, 2);
		world.setBlock(i + 42, j + 8, k + 59, deepslate_tile_stairs, 2, 2);
		world.setBlock(i + 42, j + 8, k + 60, deepslate_tile_stairs, 3, 2);
		world.setBlock(i + 45, j + 8, k + 61, deepslate_tile_stairs, 1, 2);
		world.setBlock(i + 3, j + 8, k + 62, deepslate_tile_stairs, 2, 2);
		world.setBlock(i + 45, j + 8, k + 62, deepslate_tile_stairs, 1, 2);
		world.setBlock(i + 3, j + 8, k + 63, deepslate_tile_stairs, 3, 2);
		world.setBlock(i + 0, j + 8, k + 64, deepslate_tile_stairs, 0, 2);
		world.setBlock(i + 0, j + 8, k + 65, deepslate_tile_stairs, 0, 2);
		world.setBlock(i + 5, j + 8, k + 65, deepslate_tile_stairs, 0, 2);
		world.setBlock(i + 6, j + 8, k + 65, deepslate_tile_stairs, 1, 2);
		world.setBlock(i + 11, j + 8, k + 65, deepslate_tile_stairs, 0, 2);
		world.setBlock(i + 12, j + 8, k + 65, deepslate_tile_stairs, 1, 2);
		world.setBlock(i + 24, j + 8, k + 65, deepslate_tile_stairs, 0, 2);
		world.setBlock(i + 25, j + 8, k + 65, deepslate_tile_stairs, 1, 2);
		world.setBlock(i + 30, j + 8, k + 65, deepslate_tile_stairs, 0, 2);
		world.setBlock(i + 31, j + 8, k + 65, deepslate_tile_stairs, 1, 2);
		world.setBlock(i + 36, j + 8, k + 65, deepslate_tile_stairs, 0, 2);
		world.setBlock(i + 37, j + 8, k + 65, deepslate_tile_stairs, 1, 2);
		world.setBlock(i + 45, j + 8, k + 67, deepslate_tile_stairs, 1, 2);
		world.setBlock(i + 3, j + 8, k + 68, deepslate_tile_stairs, 3, 2);
		world.setBlock(i + 4, j + 8, k + 68, deepslate_tile_stairs, 3, 2);
		world.setBlock(i + 9, j + 8, k + 68, deepslate_tile_stairs, 3, 2);
		world.setBlock(i + 10, j + 8, k + 68, deepslate_tile_stairs, 3, 2);
		world.setBlock(i + 14, j + 8, k + 68, deepslate_tile_stairs, 3, 2);
		world.setBlock(i + 15, j + 8, k + 68, deepslate_tile_stairs, 3, 2);
		world.setBlock(i + 20, j + 8, k + 68, deepslate_tile_stairs, 3, 2);
		world.setBlock(i + 21, j + 8, k + 68, deepslate_tile_stairs, 3, 2);
		world.setBlock(i + 26, j + 8, k + 68, deepslate_tile_stairs, 3, 2);
		world.setBlock(i + 27, j + 8, k + 68, deepslate_tile_stairs, 3, 2);
		world.setBlock(i + 32, j + 8, k + 68, deepslate_tile_stairs, 3, 2);
		world.setBlock(i + 33, j + 8, k + 68, deepslate_tile_stairs, 3, 2);
		world.setBlock(i + 38, j + 8, k + 68, deepslate_tile_stairs, 3, 2);
		world.setBlock(i + 39, j + 8, k + 68, deepslate_tile_stairs, 3, 2);
		world.setBlock(i + 44, j + 8, k + 68, deepslate_tile_stairs, 3, 2);
		world.setBlock(i + 14, j + 9, k + 14, deepslate, 0, 2);
		world.setBlock(i + 14, j + 9, k + 15, deepslate, 0, 2);
		world.setBlock(i + 14, j + 9, k + 16, deepslate_bricks, 2, 2);
		world.setBlock(i + 15, j + 9, k + 16, deepslate_bricks, 2, 2);
		world.setBlock(i + 16, j + 9, k + 16, deepslate_bricks, 3, 2);
		world.setBlock(i + 17, j + 9, k + 16, deepslate_bricks, 3, 2);
		world.setBlock(i + 18, j + 9, k + 16, deepslate_bricks, 2, 2);
		world.setBlock(i + 19, j + 9, k + 16, deepslate_bricks, 3, 2);
		world.setBlock(i + 20, j + 9, k + 16, deepslate_bricks, 2, 2);
		world.setBlock(i + 21, j + 9, k + 16, deepslate_bricks, 2, 2);
		world.setBlock(i + 22, j + 9, k + 16, deepslate_bricks, 2, 2);
		world.setBlock(i + 14, j + 9, k + 17, deepslate_bricks, 2, 2);
		world.setBlock(i + 15, j + 9, k + 17, deepslate_bricks, 2, 2);
		world.setBlock(i + 16, j + 9, k + 17, deepslate_bricks, 2, 2);
		world.setBlock(i + 17, j + 9, k + 17, deepslate_bricks, 2, 2);
		world.setBlock(i + 18, j + 9, k + 17, deepslate_bricks, 2, 2);
		world.setBlock(i + 19, j + 9, k + 17, deepslate_bricks, 2, 2);
		world.setBlock(i + 20, j + 9, k + 17, deepslate_bricks, 2, 2);
		world.setBlock(i + 21, j + 9, k + 17, deepslate_bricks, 2, 2);
		world.setBlock(i + 22, j + 9, k + 17, deepslate_bricks, 2, 2);
		world.setBlock(i + 14, j + 9, k + 18, deepslate_bricks, 3, 2);
		world.setBlock(i + 15, j + 9, k + 18, deepslate_bricks, 2, 2);
		world.setBlock(i + 16, j + 9, k + 18, deepslate_bricks, 2, 2);
		world.setBlock(i + 17, j + 9, k + 18, deepslate_bricks, 3, 2);
		world.setBlock(i + 18, j + 9, k + 18, deepslate_bricks, 2, 2);
		world.setBlock(i + 19, j + 9, k + 18, deepslate_bricks, 3, 2);
		world.setBlock(i + 20, j + 9, k + 18, deepslate_bricks, 2, 2);
		world.setBlock(i + 21, j + 9, k + 18, deepslate_bricks, 2, 2);
		world.setBlock(i + 22, j + 9, k + 18, deepslate_bricks, 2, 2);
		world.setBlock(i + 14, j + 9, k + 19, deepslate_bricks, 1, 2);
		world.setBlock(i + 15, j + 9, k + 19, deepslate_bricks, 2, 2);
		world.setBlock(i + 16, j + 9, k + 19, deepslate_bricks, 2, 2);
		world.setBlock(i + 17, j + 9, k + 19, deepslate_bricks, 2, 2);
		world.setBlock(i + 18, j + 9, k + 19, deepslate_bricks, 2, 2);
		world.setBlock(i + 19, j + 9, k + 19, deepslate_bricks, 3, 2);
		world.setBlock(i + 20, j + 9, k + 19, deepslate_bricks, 2, 2);
		world.setBlock(i + 21, j + 9, k + 19, deepslate_bricks, 2, 2);
		world.setBlock(i + 22, j + 9, k + 19, deepslate_bricks, 2, 2);
		world.setBlock(i + 14, j + 9, k + 20, deepslate_bricks, 0, 2);
		world.setBlock(i + 15, j + 9, k + 20, deepslate_bricks, 0, 2);
		world.setBlock(i + 16, j + 9, k + 20, deepslate_bricks, 0, 2);
		world.setBlock(i + 17, j + 9, k + 20, deepslate_bricks, 0, 2);
		world.setBlock(i + 18, j + 9, k + 20, deepslate_bricks, 2, 2);
		world.setBlock(i + 19, j + 9, k + 20, deepslate_bricks, 3, 2);
		world.setBlock(i + 20, j + 9, k + 20, deepslate_bricks, 3, 2);
		world.setBlock(i + 21, j + 9, k + 20, deepslate_bricks, 2, 2);
		world.setBlock(i + 22, j + 9, k + 20, deepslate_bricks, 2, 2);
		world.setBlock(i + 14, j + 9, k + 21, deepslate_bricks, 0, 2);
		world.setBlock(i + 15, j + 9, k + 21, deepslate_bricks, 0, 2);
		world.setBlock(i + 16, j + 9, k + 21, deepslate_bricks, 1, 2);
		world.setBlock(i + 17, j + 9, k + 21, deepslate_bricks, 0, 2);
		world.setBlock(i + 18, j + 9, k + 21, deepslate_bricks, 0, 2);
		world.setBlock(i + 19, j + 9, k + 21, deepslate_bricks, 0, 2);
		world.setBlock(i + 20, j + 9, k + 21, deepslate_bricks, 1, 2);
		world.setBlock(i + 21, j + 9, k + 21, deepslate_bricks, 2, 2);
		world.setBlock(i + 22, j + 9, k + 21, deepslate_bricks, 3, 2);
		world.setBlock(i + 14, j + 9, k + 22, deepslate_bricks, 3, 2);
		world.setBlock(i + 15, j + 9, k + 22, deepslate_bricks, 3, 2);
		world.setBlock(i + 16, j + 9, k + 22, deepslate_bricks, 3, 2);
		world.setBlock(i + 17, j + 9, k + 22, deepslate_bricks, 2, 2);
		world.setBlock(i + 18, j + 9, k + 22, deepslate_bricks, 0, 2);
		world.setBlock(i + 19, j + 9, k + 22, deepslate_bricks, 3, 2);
		world.setBlock(i + 20, j + 9, k + 22, deepslate_bricks, 3, 2);
		world.setBlock(i + 21, j + 9, k + 22, deepslate_bricks, 3, 2);
		world.setBlock(i + 22, j + 9, k + 22, deepslate_bricks, 2, 2);
		world.setBlock(i + 23, j + 9, k + 22, NovaCraftBlocks.dim_vanite_torch, 5, 2);
		world.setBlock(i + 14, j + 9, k + 23, deepslate_bricks, 2, 2);
		world.setBlock(i + 15, j + 9, k + 23, deepslate_bricks, 2, 2);
		world.setBlock(i + 16, j + 9, k + 23, deepslate_bricks, 2, 2);
		world.setBlock(i + 17, j + 9, k + 23, deepslate_bricks, 3, 2);
		world.setBlock(i + 18, j + 9, k + 23, deepslate_bricks, 2, 2);
		world.setBlock(i + 19, j + 9, k + 23, deepslate_bricks, 2, 2);
		world.setBlock(i + 20, j + 9, k + 23, deepslate_bricks, 2, 2);
		world.setBlock(i + 21, j + 9, k + 23, deepslate_bricks, 2, 2);
		world.setBlock(i + 22, j + 9, k + 23, deepslate_bricks, 2, 2);
		world.setBlock(i + 23, j + 9, k + 23, NovaCraftBlocks.dim_vanite_torch, 5, 2);
		world.setBlock(i + 24, j + 9, k + 23, NovaCraftBlocks.dim_vanite_torch, 5, 2);
		world.setBlock(i + 14, j + 9, k + 24, deepslate_bricks, 2, 2);
		world.setBlock(i + 15, j + 9, k + 24, deepslate_bricks, 2, 2);
		world.setBlock(i + 16, j + 9, k + 24, deepslate_bricks, 3, 2);
		world.setBlock(i + 17, j + 9, k + 24, deepslate_bricks, 2, 2);
		world.setBlock(i + 18, j + 9, k + 24, deepslate_bricks, 3, 2);
		world.setBlock(i + 19, j + 9, k + 24, deepslate_bricks, 2, 2);
		world.setBlock(i + 20, j + 9, k + 24, deepslate_bricks, 3, 2);
		world.setBlock(i + 21, j + 9, k + 24, deepslate_bricks, 2, 2);
		world.setBlock(i + 22, j + 9, k + 24, deepslate_bricks, 2, 2);
		world.setBlock(i + 23, j + 9, k + 24, NovaCraftBlocks.dim_vanite_torch, 5, 2);
		world.setBlock(i + 24, j + 9, k + 24, NovaCraftBlocks.dim_vanite_torch, 5, 2);
		world.setBlock(i + 25, j + 9, k + 24, NovaCraftBlocks.dim_vanite_torch, 5, 2);
		world.setBlock(i + 33, j + 9, k + 24, polished_deepslate, 0, 2);
		world.setBlock(i + 14, j + 9, k + 25, deepslate_bricks, 2, 2);
		world.setBlock(i + 15, j + 9, k + 25, deepslate_bricks, 2, 2);
		world.setBlock(i + 16, j + 9, k + 25, deepslate_bricks, 3, 2);
		world.setBlock(i + 17, j + 9, k + 25, soul_sand, 0, 2);
		world.setBlock(i + 18, j + 9, k + 25, soul_sand, 0, 2);
		world.setBlock(i + 19, j + 9, k + 25, soul_sand, 0, 2);
		world.setBlock(i + 20, j + 9, k + 25, deepslate_bricks, 2, 2);
		world.setBlock(i + 21, j + 9, k + 25, deepslate_bricks, 2, 2);
		world.setBlock(i + 22, j + 9, k + 25, deepslate_bricks, 3, 2);
		world.setBlock(i + 23, j + 9, k + 25, NovaCraftBlocks.dim_vanite_torch, 5, 2);
		world.setBlock(i + 24, j + 9, k + 25, NovaCraftBlocks.dim_vanite_torch, 5, 2);
		world.setBlock(i + 25, j + 9, k + 25, NovaCraftBlocks.dim_vanite_torch, 5, 2);
		world.setBlock(i + 14, j + 9, k + 26, deepslate_bricks, 2, 2);
		world.setBlock(i + 15, j + 9, k + 26, deepslate_bricks, 2, 2);
		world.setBlock(i + 16, j + 9, k + 26, deepslate_bricks, 2, 2);
		world.setBlock(i + 17, j + 9, k + 26, soul_sand, 0, 2);
		world.setBlock(i + 18, j + 9, k + 26, soul_sand, 0, 2);
		world.setBlock(i + 19, j + 9, k + 26, soul_sand, 0, 2);
		world.setBlock(i + 20, j + 9, k + 26, deepslate_bricks, 2, 2);
		world.setBlock(i + 21, j + 9, k + 26, deepslate_bricks, 3, 2);
		world.setBlock(i + 22, j + 9, k + 26, deepslate_bricks, 2, 2);
		world.setBlock(i + 23, j + 9, k + 26, NovaCraftBlocks.dim_vanite_torch, 5, 2);
		world.setBlock(i + 25, j + 9, k + 26, NovaCraftBlocks.dim_vanite_torch, 5, 2);
		world.setBlock(i + 14, j + 9, k + 27, deepslate_bricks, 0, 2);
		world.setBlock(i + 15, j + 9, k + 27, deepslate_bricks, 0, 2);
		world.setBlock(i + 16, j + 9, k + 27, deepslate_bricks, 0, 2);
		world.setBlock(i + 17, j + 9, k + 27, soul_sand, 0, 2);
		world.setBlock(i + 18, j + 9, k + 27, soul_sand, 0, 2);
		world.setBlock(i + 19, j + 9, k + 27, soul_sand, 0, 2);
		world.setBlock(i + 20, j + 9, k + 27, deepslate_bricks, 0, 2);
		world.setBlock(i + 21, j + 9, k + 27, deepslate_bricks, 0, 2);
		world.setBlock(i + 22, j + 9, k + 27, deepslate_bricks, 1, 2);
		world.setBlock(i + 23, j + 9, k + 27, NovaCraftBlocks.dim_vanite_torch, 5, 2);
		world.setBlock(i + 24, j + 9, k + 27, NovaCraftBlocks.dim_vanite_torch, 5, 2);
		world.setBlock(i + 25, j + 9, k + 27, NovaCraftBlocks.dim_vanite_torch, 5, 2);
		world.setBlock(i + 26, j + 9, k + 27, NovaCraftBlocks.dim_vanite_torch, 5, 2);
		world.setBlock(i + 27, j + 9, k + 27, NovaCraftBlocks.dim_vanite_torch, 5, 2);
		world.setBlock(i + 14, j + 9, k + 28, deepslate_bricks, 0, 2);
		world.setBlock(i + 15, j + 9, k + 28, deepslate_bricks, 0, 2);
		world.setBlock(i + 16, j + 9, k + 28, deepslate_bricks, 0, 2);
		world.setBlock(i + 17, j + 9, k + 28, soul_sand, 0, 2);
		world.setBlock(i + 18, j + 9, k + 28, soul_sand, 0, 2);
		world.setBlock(i + 19, j + 9, k + 28, soul_sand, 0, 2);
		world.setBlock(i + 20, j + 9, k + 28, deepslate_bricks, 1, 2);
		world.setBlock(i + 21, j + 9, k + 28, deepslate_bricks, 1, 2);
		world.setBlock(i + 22, j + 9, k + 28, deepslate_bricks, 0, 2);
		world.setBlock(i + 23, j + 9, k + 28, cobbled_deepslate, 0, 2);
		world.setBlock(i + 24, j + 9, k + 28, cobbled_deepslate, 0, 2);
		world.setBlock(i + 25, j + 9, k + 28, cobbled_deepslate, 0, 2);
		world.setBlock(i + 26, j + 9, k + 28, cobbled_deepslate, 0, 2);
		world.setBlock(i + 27, j + 9, k + 28, cobbled_deepslate, 0, 2);
		world.setBlock(i + 28, j + 9, k + 28, deepslate_bricks, 2, 2);
		world.setBlock(i + 29, j + 9, k + 28, NovaCraftBlocks.dim_vanite_torch, 5, 2);
		world.setBlock(i + 14, j + 9, k + 29, deepslate_bricks, 0, 2);
		world.setBlock(i + 15, j + 9, k + 29, deepslate_bricks, 1, 2);
		world.setBlock(i + 16, j + 9, k + 29, deepslate_bricks, 0, 2);
		world.setBlock(i + 17, j + 9, k + 29, soul_sand, 0, 2);
		world.setBlock(i + 18, j + 9, k + 29, soul_sand, 0, 2);
		world.setBlock(i + 19, j + 9, k + 29, soul_sand, 0, 2);
		world.setBlock(i + 20, j + 9, k + 29, deepslate_bricks, 0, 2);
		world.setBlock(i + 21, j + 9, k + 29, deepslate_bricks, 0, 2);
		world.setBlock(i + 22, j + 9, k + 29, deepslate_bricks, 0, 2);
		world.setBlock(i + 23, j + 9, k + 29, deepslate_bricks, 0, 2);
		world.setBlock(i + 24, j + 9, k + 29, deepslate_bricks, 0, 2);
		world.setBlock(i + 25, j + 9, k + 29, deepslate_bricks, 0, 2);
		world.setBlock(i + 26, j + 9, k + 29, deepslate_bricks, 0, 2);
		world.setBlock(i + 27, j + 9, k + 29, cobbled_deepslate, 0, 2);
		world.setBlock(i + 28, j + 9, k + 29, deepslate_bricks, 2, 2);
		world.setBlock(i + 29, j + 9, k + 29, NovaCraftBlocks.dim_vanite_torch, 5, 2);
		world.setBlock(i + 14, j + 9, k + 30, deepslate_bricks, 0, 2);
		world.setBlock(i + 15, j + 9, k + 30, deepslate_bricks, 0, 2);
		world.setBlock(i + 16, j + 9, k + 30, deepslate_bricks, 1, 2);
		world.setBlock(i + 17, j + 9, k + 30, soul_sand, 0, 2);
		world.setBlock(i + 18, j + 9, k + 30, soul_sand, 0, 2);
		world.setBlock(i + 19, j + 9, k + 30, soul_sand, 0, 2);
		world.setBlock(i + 20, j + 9, k + 30, deepslate_bricks, 1, 2);
		world.setBlock(i + 21, j + 9, k + 30, deepslate_bricks, 0, 2);
		world.setBlock(i + 22, j + 9, k + 30, deepslate_bricks, 1, 2);
		world.setBlock(i + 23, j + 9, k + 30, deepslate_bricks, 1, 2);
		world.setBlock(i + 24, j + 9, k + 30, deepslate_bricks, 0, 2);
		world.setBlock(i + 25, j + 9, k + 30, deepslate_bricks, 0, 2);
		world.setBlock(i + 26, j + 9, k + 30, deepslate_bricks, 1, 2);
		world.setBlock(i + 27, j + 9, k + 30, NovaCraftBlocks.dim_vanite_torch, 5, 2);
		world.setBlock(i + 28, j + 9, k + 30, NovaCraftBlocks.dim_vanite_torch, 5, 2);
		world.setBlock(i + 33, j + 9, k + 30, polished_deepslate, 0, 2);
		world.setBlock(i + 14, j + 9, k + 31, deepslate_bricks, 0, 2);
		world.setBlock(i + 15, j + 9, k + 31, deepslate_bricks, 0, 2);
		world.setBlock(i + 16, j + 9, k + 31, deepslate_bricks, 0, 2);
		world.setBlock(i + 17, j + 9, k + 31, soul_sand, 0, 2);
		world.setBlock(i + 18, j + 9, k + 31, soul_sand, 0, 2);
		world.setBlock(i + 19, j + 9, k + 31, soul_sand, 0, 2);
		world.setBlock(i + 20, j + 9, k + 31, deepslate_bricks, 1, 2);
		world.setBlock(i + 21, j + 9, k + 31, deepslate_bricks, 1, 2);
		world.setBlock(i + 22, j + 9, k + 31, deepslate_bricks, 0, 2);
		world.setBlock(i + 23, j + 9, k + 31, deepslate_bricks, 3, 2);
		world.setBlock(i + 24, j + 9, k + 31, deepslate_bricks, 2, 2);
		world.setBlock(i + 25, j + 9, k + 31, deepslate_bricks, 0, 2);
		world.setBlock(i + 26, j + 9, k + 31, deepslate_bricks, 0, 2);
		world.setBlock(i + 27, j + 9, k + 31, NovaCraftBlocks.dim_vanite_torch, 5, 2);
		world.setBlock(i + 14, j + 9, k + 32, deepslate_bricks, 1, 2);
		world.setBlock(i + 15, j + 9, k + 32, deepslate_bricks, 1, 2);
		world.setBlock(i + 16, j + 9, k + 32, deepslate_bricks, 0, 2);
		world.setBlock(i + 17, j + 9, k + 32, soul_sand, 0, 2);
		world.setBlock(i + 18, j + 9, k + 32, soul_sand, 0, 2);
		world.setBlock(i + 19, j + 9, k + 32, soul_sand, 0, 2);
		world.setBlock(i + 20, j + 9, k + 32, deepslate_bricks, 1, 2);
		world.setBlock(i + 21, j + 9, k + 32, deepslate_bricks, 0, 2);
		world.setBlock(i + 22, j + 9, k + 32, deepslate_bricks, 0, 2);
		world.setBlock(i + 23, j + 9, k + 32, deepslate_bricks, 3, 2);
		world.setBlock(i + 24, j + 9, k + 32, deepslate_bricks, 2, 2);
		world.setBlock(i + 25, j + 9, k + 32, deepslate_bricks, 2, 2);
		world.setBlock(i + 26, j + 9, k + 32, deepslate_bricks, 1, 2);
		world.setBlock(i + 14, j + 9, k + 33, deepslate_bricks, 0, 2);
		world.setBlock(i + 15, j + 9, k + 33, deepslate_bricks, 1, 2);
		world.setBlock(i + 16, j + 9, k + 33, deepslate_bricks, 0, 2);
		world.setBlock(i + 17, j + 9, k + 33, soul_sand, 0, 2);
		world.setBlock(i + 18, j + 9, k + 33, soul_sand, 0, 2);
		world.setBlock(i + 19, j + 9, k + 33, soul_sand, 0, 2);
		world.setBlock(i + 20, j + 9, k + 33, deepslate_bricks, 0, 2);
		world.setBlock(i + 21, j + 9, k + 33, deepslate_bricks, 1, 2);
		world.setBlock(i + 22, j + 9, k + 33, deepslate_bricks, 1, 2);
		world.setBlock(i + 23, j + 9, k + 33, deepslate_bricks, 1, 2);
		world.setBlock(i + 24, j + 9, k + 33, deepslate_bricks, 0, 2);
		world.setBlock(i + 25, j + 9, k + 33, deepslate_bricks, 1, 2);
		world.setBlock(i + 26, j + 9, k + 33, deepslate_bricks, 0, 2);
		world.setBlock(i + 27, j + 9, k + 33, polished_deepslate_stairs, 1, 2);
		world.setBlock(i + 14, j + 9, k + 34, deepslate_bricks, 0, 2);
		world.setBlock(i + 15, j + 9, k + 34, deepslate_bricks, 1, 2);
		world.setBlock(i + 16, j + 9, k + 34, deepslate_bricks, 0, 2);
		world.setBlock(i + 17, j + 9, k + 34, soul_sand, 0, 2);
		world.setBlock(i + 18, j + 9, k + 34, soul_sand, 0, 2);
		world.setBlock(i + 19, j + 9, k + 34, soul_sand, 0, 2);
		world.setBlock(i + 20, j + 9, k + 34, deepslate_bricks, 1, 2);
		world.setBlock(i + 21, j + 9, k + 34, deepslate_bricks, 0, 2);
		world.setBlock(i + 22, j + 9, k + 34, deepslate_bricks, 1, 2);
		world.setBlock(i + 23, j + 9, k + 34, deepslate_bricks, 0, 2);
		world.setBlock(i + 24, j + 9, k + 34, deepslate_bricks, 1, 2);
		world.setBlock(i + 25, j + 9, k + 34, deepslate_bricks, 0, 2);
		world.setBlock(i + 26, j + 9, k + 34, deepslate_bricks, 1, 2);
		world.setBlock(i + 27, j + 9, k + 34, polished_deepslate_stairs, 1, 2);
		world.setBlock(i + 14, j + 9, k + 35, deepslate_bricks, 0, 2);
		world.setBlock(i + 15, j + 9, k + 35, deepslate_bricks, 0, 2);
		world.setBlock(i + 16, j + 9, k + 35, deepslate_bricks, 0, 2);
		world.setBlock(i + 17, j + 9, k + 35, soul_sand, 0, 2);
		world.setBlock(i + 18, j + 9, k + 35, soul_sand, 0, 2);
		world.setBlock(i + 19, j + 9, k + 35, soul_sand, 0, 2);
		world.setBlock(i + 20, j + 9, k + 35, deepslate_bricks, 0, 2);
		world.setBlock(i + 21, j + 9, k + 35, deepslate_bricks, 0, 2);
		world.setBlock(i + 22, j + 9, k + 35, deepslate_bricks, 0, 2);
		world.setBlock(i + 23, j + 9, k + 35, deepslate_bricks, 0, 2);
		world.setBlock(i + 24, j + 9, k + 35, deepslate_bricks, 0, 2);
		world.setBlock(i + 25, j + 9, k + 35, deepslate_bricks, 0, 2);
		world.setBlock(i + 26, j + 9, k + 35, deepslate_bricks, 1, 2);
		world.setBlock(i + 27, j + 9, k + 35, polished_deepslate_stairs, 1, 2);
		world.setBlock(i + 14, j + 9, k + 36, deepslate_bricks, 1, 2);
		world.setBlock(i + 15, j + 9, k + 36, deepslate_bricks, 1, 2);
		world.setBlock(i + 16, j + 9, k + 36, deepslate_bricks, 0, 2);
		world.setBlock(i + 17, j + 9, k + 36, soul_sand, 0, 2);
		world.setBlock(i + 18, j + 9, k + 36, soul_sand, 0, 2);
		world.setBlock(i + 19, j + 9, k + 36, soul_sand, 0, 2);
		world.setBlock(i + 20, j + 9, k + 36, deepslate_bricks, 0, 2);
		world.setBlock(i + 21, j + 9, k + 36, deepslate_bricks, 1, 2);
		world.setBlock(i + 22, j + 9, k + 36, deepslate_bricks, 1, 2);
		world.setBlock(i + 23, j + 9, k + 36, deepslate_bricks, 2, 2);
		world.setBlock(i + 24, j + 9, k + 36, deepslate_bricks, 2, 2);
		world.setBlock(i + 25, j + 9, k + 36, deepslate_bricks, 3, 2);
		world.setBlock(i + 26, j + 9, k + 36, deepslate_bricks, 1, 2);
		world.setBlock(i + 27, j + 9, k + 36, NovaCraftBlocks.dim_vanite_torch, 5, 2);
		world.setBlock(i + 14, j + 9, k + 37, deepslate_bricks, 0, 2);
		world.setBlock(i + 15, j + 9, k + 37, deepslate_bricks, 0, 2);
		world.setBlock(i + 16, j + 9, k + 37, deepslate_bricks, 0, 2);
		world.setBlock(i + 17, j + 9, k + 37, soul_sand, 0, 2);
		world.setBlock(i + 18, j + 9, k + 37, soul_sand, 0, 2);
		world.setBlock(i + 19, j + 9, k + 37, soul_sand, 0, 2);
		world.setBlock(i + 20, j + 9, k + 37, deepslate_bricks, 1, 2);
		world.setBlock(i + 21, j + 9, k + 37, deepslate_bricks, 1, 2);
		world.setBlock(i + 22, j + 9, k + 37, deepslate_bricks, 0, 2);
		world.setBlock(i + 23, j + 9, k + 37, deepslate_bricks, 0, 2);
		world.setBlock(i + 24, j + 9, k + 37, deepslate_bricks, 2, 2);
		world.setBlock(i + 25, j + 9, k + 37, deepslate_bricks, 0, 2);
		world.setBlock(i + 26, j + 9, k + 37, deepslate_bricks, 0, 2);
		world.setBlock(i + 27, j + 9, k + 37, NovaCraftBlocks.dim_vanite_torch, 5, 2);
		world.setBlock(i + 28, j + 9, k + 37, NovaCraftBlocks.dim_vanite_torch, 5, 2);
		world.setBlock(i + 14, j + 9, k + 38, deepslate_bricks, 1, 2);
		world.setBlock(i + 15, j + 9, k + 38, deepslate_bricks, 1, 2);
		world.setBlock(i + 16, j + 9, k + 38, deepslate_bricks, 0, 2);
		world.setBlock(i + 17, j + 9, k + 38, soul_sand, 0, 2);
		world.setBlock(i + 18, j + 9, k + 38, soul_sand, 0, 2);
		world.setBlock(i + 19, j + 9, k + 38, soul_sand, 0, 2);
		world.setBlock(i + 20, j + 9, k + 38, deepslate_bricks, 1, 2);
		world.setBlock(i + 21, j + 9, k + 38, deepslate_bricks, 0, 2);
		world.setBlock(i + 22, j + 9, k + 38, deepslate_bricks, 1, 2);
		world.setBlock(i + 23, j + 9, k + 38, deepslate_bricks, 0, 2);
		world.setBlock(i + 24, j + 9, k + 38, deepslate_bricks, 0, 2);
		world.setBlock(i + 25, j + 9, k + 38, deepslate_bricks, 0, 2);
		world.setBlock(i + 26, j + 9, k + 38, deepslate_bricks, 0, 2);
		world.setBlock(i + 27, j + 9, k + 38, NovaCraftBlocks.dim_vanite_torch, 5, 2);
		world.setBlock(i + 28, j + 9, k + 38, NovaCraftBlocks.dim_vanite_torch, 5, 2);
		world.setBlock(i + 29, j + 9, k + 38, NovaCraftBlocks.dim_vanite_torch, 5, 2);
		world.setBlock(i + 33, j + 9, k + 38, polished_deepslate, 0, 2);
		world.setBlock(i + 14, j + 9, k + 39, deepslate_bricks, 2, 2);
		world.setBlock(i + 15, j + 9, k + 39, deepslate_bricks, 2, 2);
		world.setBlock(i + 16, j + 9, k + 39, deepslate_bricks, 2, 2);
		world.setBlock(i + 17, j + 9, k + 39, soul_sand, 0, 2);
		world.setBlock(i + 18, j + 9, k + 39, soul_sand, 0, 2);
		world.setBlock(i + 19, j + 9, k + 39, soul_sand, 0, 2);
		world.setBlock(i + 20, j + 9, k + 39, deepslate_bricks, 1, 2);
		world.setBlock(i + 21, j + 9, k + 39, deepslate_bricks, 0, 2);
		world.setBlock(i + 22, j + 9, k + 39, deepslate_bricks, 1, 2);
		world.setBlock(i + 23, j + 9, k + 39, deepslate_bricks, 1, 2);
		world.setBlock(i + 24, j + 9, k + 39, deepslate_bricks, 0, 2);
		world.setBlock(i + 25, j + 9, k + 39, deepslate_bricks, 1, 2);
		world.setBlock(i + 26, j + 9, k + 39, deepslate_bricks, 0, 2);
		world.setBlock(i + 27, j + 9, k + 39, cobbled_deepslate, 0, 2);
		world.setBlock(i + 28, j + 9, k + 39, deepslate_bricks, 2, 2);
		world.setBlock(i + 29, j + 9, k + 39, NovaCraftBlocks.dim_vanite_torch, 5, 2);
		world.setBlock(i + 14, j + 9, k + 40, deepslate_bricks, 3, 2);
		world.setBlock(i + 15, j + 9, k + 40, deepslate_bricks, 2, 2);
		world.setBlock(i + 16, j + 9, k + 40, deepslate_bricks, 3, 2);
		world.setBlock(i + 17, j + 9, k + 40, soul_sand, 0, 2);
		world.setBlock(i + 18, j + 9, k + 40, soul_sand, 0, 2);
		world.setBlock(i + 19, j + 9, k + 40, soul_sand, 0, 2);
		world.setBlock(i + 20, j + 9, k + 40, deepslate_bricks, 2, 2);
		world.setBlock(i + 21, j + 9, k + 40, deepslate_bricks, 2, 2);
		world.setBlock(i + 22, j + 9, k + 40, deepslate_bricks, 3, 2);
		world.setBlock(i + 23, j + 9, k + 40, deepslate_bricks, 1, 2);
		world.setBlock(i + 24, j + 9, k + 40, deepslate_bricks, 0, 2);
		world.setBlock(i + 25, j + 9, k + 40, deepslate_bricks, 0, 2);
		world.setBlock(i + 26, j + 9, k + 40, deepslate_bricks, 1, 2);
		world.setBlock(i + 27, j + 9, k + 40, deepslate_bricks, 0, 2);
		world.setBlock(i + 28, j + 9, k + 40, deepslate_bricks, 3, 2);
		world.setBlock(i + 14, j + 9, k + 41, deepslate_bricks, 2, 2);
		world.setBlock(i + 15, j + 9, k + 41, deepslate_bricks, 2, 2);
		world.setBlock(i + 16, j + 9, k + 41, deepslate_bricks, 2, 2);
		world.setBlock(i + 17, j + 9, k + 41, soul_sand, 0, 2);
		world.setBlock(i + 18, j + 9, k + 41, soul_sand, 0, 2);
		world.setBlock(i + 19, j + 9, k + 41, soul_sand, 0, 2);
		world.setBlock(i + 20, j + 9, k + 41, deepslate_bricks, 2, 2);
		world.setBlock(i + 21, j + 9, k + 41, deepslate_bricks, 2, 2);
		world.setBlock(i + 22, j + 9, k + 41, deepslate_bricks, 2, 2);
		world.setBlock(i + 23, j + 9, k + 41, deepslate_bricks, 1, 2);
		world.setBlock(i + 24, j + 9, k + 41, deepslate_bricks, 0, 2);
		world.setBlock(i + 25, j + 9, k + 41, deepslate_bricks, 0, 2);
		world.setBlock(i + 26, j + 9, k + 41, deepslate_bricks, 0, 2);
		world.setBlock(i + 27, j + 9, k + 41, deepslate_bricks, 0, 2);
		world.setBlock(i + 28, j + 9, k + 41, deepslate_brick_slab, 0, 2);
		
		
		
		
		
		
		
		
		
		
		
		
		
		
		
		
		
		
		
		
		
		
		
		
		
		
		
		
		
		
		
		
		
		
		
		
		
		
		
		
		
		
		
		
		
		
		
		
		
		
		world.setBlock(i + 14, j + 9, k + 42, deepslate_bricks, 3, 2);
		world.setBlock(i + 15, j + 9, k + 42, deepslate_bricks, 2, 2);
		world.setBlock(i + 16, j + 9, k + 42, deepslate_bricks, 3, 2);
		world.setBlock(i + 17, j + 9, k + 42, soul_sand, 0, 2);
		world.setBlock(i + 18, j + 9, k + 42, soul_sand, 0, 2);
		world.setBlock(i + 19, j + 9, k + 42, soul_sand, 0, 2);
		world.setBlock(i + 20, j + 9, k + 42, deepslate_bricks, 3, 2);
		world.setBlock(i + 21, j + 9, k + 42, deepslate_bricks, 2, 2);
		world.setBlock(i + 22, j + 9, k + 42, deepslate_bricks, 2, 2);
		world.setBlock(i + 23, j + 9, k + 42, deepslate_bricks, 1, 2);
		world.setBlock(i + 24, j + 9, k + 42, deepslate_bricks, 0, 2);
		world.setBlock(i + 25, j + 9, k + 42, deepslate_brick_slab, 0, 2);
		world.setBlock(i + 26, j + 9, k + 42, deepslate_brick_slab, 0, 2);
		world.setBlock(i + 27, j + 9, k + 42, deepslate_brick_slab, 0, 2);
		world.setBlock(i + 14, j + 9, k + 43, deepslate_bricks, 2, 2);
		world.setBlock(i + 15, j + 9, k + 43, deepslate_bricks, 2, 2);
		world.setBlock(i + 16, j + 9, k + 43, deepslate_bricks, 3, 2);
		world.setBlock(i + 17, j + 9, k + 43, soul_sand, 0, 2);
		world.setBlock(i + 18, j + 9, k + 43, soul_sand, 0, 2);
		world.setBlock(i + 19, j + 9, k + 43, soul_sand, 0, 2);
		world.setBlock(i + 20, j + 9, k + 43, deepslate_bricks, 2, 2);
		world.setBlock(i + 21, j + 9, k + 43, deepslate_bricks, 2, 2);
		world.setBlock(i + 22, j + 9, k + 43, deepslate_bricks, 2, 2);
		world.setBlock(i + 23, j + 9, k + 43, deepslate_bricks, 0, 2);
		world.setBlock(i + 24, j + 9, k + 43, deepslate_brick_slab, 0, 2);
		world.setBlock(i + 25, j + 9, k + 43, NovaCraftBlocks.dim_vanite_torch, 5, 2);
		world.setBlock(i + 14, j + 9, k + 44, deepslate_bricks, 2, 2);
		world.setBlock(i + 15, j + 9, k + 44, deepslate_bricks, 2, 2);
		world.setBlock(i + 16, j + 9, k + 44, deepslate_bricks, 2, 2);
		world.setBlock(i + 17, j + 9, k + 44, deepslate_bricks, 2, 2);
		world.setBlock(i + 18, j + 9, k + 44, deepslate_bricks, 3, 2);
		world.setBlock(i + 19, j + 9, k + 44, deepslate_bricks, 3, 2);
		world.setBlock(i + 20, j + 9, k + 44, deepslate_bricks, 3, 2);
		world.setBlock(i + 21, j + 9, k + 44, deepslate_bricks, 2, 2);
		world.setBlock(i + 22, j + 9, k + 44, deepslate_bricks, 2, 2);
		world.setBlock(i + 23, j + 9, k + 44, NovaCraftBlocks.dim_vanite_torch, 5, 2);
		world.setBlock(i + 24, j + 9, k + 44, NovaCraftBlocks.dim_vanite_torch, 5, 2);
		world.setBlock(i + 25, j + 9, k + 44, NovaCraftBlocks.dim_vanite_torch, 5, 2);
		world.setBlock(i + 14, j + 9, k + 45, deepslate_bricks, 2, 2);
		world.setBlock(i + 15, j + 9, k + 45, deepslate_bricks, 2, 2);
		world.setBlock(i + 16, j + 9, k + 45, deepslate_bricks, 2, 2);
		world.setBlock(i + 17, j + 9, k + 45, deepslate_bricks, 2, 2);
		world.setBlock(i + 18, j + 9, k + 45, deepslate_bricks, 3, 2);
		world.setBlock(i + 19, j + 9, k + 45, deepslate_bricks, 2, 2);
		world.setBlock(i + 20, j + 9, k + 45, deepslate_bricks, 2, 2);
		world.setBlock(i + 21, j + 9, k + 45, deepslate_bricks, 2, 2);
		world.setBlock(i + 22, j + 9, k + 45, deepslate_bricks, 2, 2);
		world.setBlock(i + 23, j + 9, k + 45, NovaCraftBlocks.dim_vanite_torch, 5, 2);
		world.setBlock(i + 24, j + 9, k + 45, NovaCraftBlocks.dim_vanite_torch, 5, 2);
		world.setBlock(i + 14, j + 9, k + 46, deepslate_bricks, 2, 2);
		world.setBlock(i + 15, j + 9, k + 46, deepslate_bricks, 2, 2);
		world.setBlock(i + 16, j + 9, k + 46, deepslate_bricks, 2, 2);
		world.setBlock(i + 17, j + 9, k + 46, deepslate_bricks, 2, 2);
		world.setBlock(i + 18, j + 9, k + 46, deepslate_bricks, 3, 2);
		world.setBlock(i + 19, j + 9, k + 46, deepslate_bricks, 2, 2);
		world.setBlock(i + 20, j + 9, k + 46, deepslate_bricks, 2, 2);
		world.setBlock(i + 21, j + 9, k + 46, deepslate_bricks, 2, 2);
		world.setBlock(i + 22, j + 9, k + 46, deepslate_bricks, 2, 2);
		world.setBlock(i + 23, j + 9, k + 46, NovaCraftBlocks.dim_vanite_torch, 5, 2);
		world.setBlock(i + 14, j + 9, k + 47, deepslate_bricks, 3, 2);
		world.setBlock(i + 15, j + 9, k + 47, deepslate_bricks, 3, 2);
		world.setBlock(i + 16, j + 9, k + 47, deepslate_bricks, 2, 2);
		world.setBlock(i + 17, j + 9, k + 47, deepslate_bricks, 2, 2);
		world.setBlock(i + 18, j + 9, k + 47, deepslate_bricks, 3, 2);
		world.setBlock(i + 19, j + 9, k + 47, deepslate_bricks, 3, 2);
		world.setBlock(i + 20, j + 9, k + 47, deepslate_bricks, 2, 2);
		world.setBlock(i + 21, j + 9, k + 47, deepslate_bricks, 2, 2);
		world.setBlock(i + 22, j + 9, k + 47, deepslate_bricks, 3, 2);
		world.setBlock(i + 14, j + 9, k + 48, deepslate_bricks, 2, 2);
		world.setBlock(i + 15, j + 9, k + 48, deepslate_bricks, 2, 2);
		world.setBlock(i + 16, j + 9, k + 48, deepslate_bricks, 2, 2);
		world.setBlock(i + 17, j + 9, k + 48, deepslate_bricks, 3, 2);
		world.setBlock(i + 18, j + 9, k + 48, deepslate_bricks, 2, 2);
		world.setBlock(i + 19, j + 9, k + 48, deepslate_bricks, 2, 2);
		world.setBlock(i + 20, j + 9, k + 48, deepslate_bricks, 2, 2);
		world.setBlock(i + 21, j + 9, k + 48, deepslate_bricks, 2, 2);
		world.setBlock(i + 22, j + 9, k + 48, deepslate_bricks, 2, 2);
		world.setBlock(i + 14, j + 9, k + 49, deepslate_bricks, 2, 2);
		world.setBlock(i + 15, j + 9, k + 49, deepslate_bricks, 2, 2);
		world.setBlock(i + 16, j + 9, k + 49, deepslate_bricks, 2, 2);
		world.setBlock(i + 17, j + 9, k + 49, deepslate_bricks, 2, 2);
		world.setBlock(i + 18, j + 9, k + 49, deepslate_bricks, 2, 2);
		world.setBlock(i + 19, j + 9, k + 49, deepslate_bricks, 2, 2);
		world.setBlock(i + 20, j + 9, k + 49, deepslate_bricks, 2, 2);
		world.setBlock(i + 21, j + 9, k + 49, deepslate_bricks, 2, 2);
		world.setBlock(i + 22, j + 9, k + 49, deepslate_bricks, 2, 2);
		world.setBlock(i + 14, j + 9, k + 50, deepslate_bricks, 3, 2);
		world.setBlock(i + 15, j + 9, k + 50, deepslate_bricks, 2, 2);
		world.setBlock(i + 16, j + 9, k + 50, deepslate_bricks, 3, 2);
		world.setBlock(i + 17, j + 9, k + 50, deepslate_bricks, 2, 2);
		world.setBlock(i + 18, j + 9, k + 50, deepslate_bricks, 2, 2);
		world.setBlock(i + 19, j + 9, k + 50, deepslate_bricks, 2, 2);
		world.setBlock(i + 20, j + 9, k + 50, deepslate_bricks, 3, 2);
		world.setBlock(i + 21, j + 9, k + 50, deepslate_bricks, 2, 2);
		world.setBlock(i + 22, j + 9, k + 50, deepslate_bricks, 2, 2);
		world.setBlock(i + 14, j + 9, k + 51, deepslate_bricks, 2, 2);
		world.setBlock(i + 15, j + 9, k + 51, deepslate_bricks, 2, 2);
		world.setBlock(i + 16, j + 9, k + 51, deepslate_bricks, 3, 2);
		world.setBlock(i + 17, j + 9, k + 51, deepslate_bricks, 2, 2);
		world.setBlock(i + 18, j + 9, k + 51, deepslate_bricks, 2, 2);
		world.setBlock(i + 19, j + 9, k + 51, deepslate_bricks, 2, 2);
		world.setBlock(i + 20, j + 9, k + 51, deepslate_bricks, 2, 2);
		world.setBlock(i + 21, j + 9, k + 51, deepslate_bricks, 2, 2);
		world.setBlock(i + 15, j + 10, k + 17, deepslate_bricks, 3, 2);
		world.setBlock(i + 16, j + 10, k + 17, deepslate_bricks, 3, 2);
		world.setBlock(i + 17, j + 10, k + 17, deepslate_bricks, 2, 2);
		world.setBlock(i + 18, j + 10, k + 17, deepslate_bricks, 2, 2);
		world.setBlock(i + 19, j + 10, k + 17, deepslate_bricks, 2, 2);
		world.setBlock(i + 20, j + 10, k + 17, deepslate_bricks, 3, 2);
		world.setBlock(i + 21, j + 10, k + 17, deepslate_bricks, 2, 2);
		world.setBlock(i + 15, j + 10, k + 18, deepslate_bricks, 2, 2);
		world.setBlock(i + 21, j + 10, k + 18, deepslate_bricks, 2, 2);
		world.setBlock(i + 15, j + 10, k + 19, deepslate_bricks, 2, 2);
		world.setBlock(i + 21, j + 10, k + 19, deepslate_bricks, 2, 2);
		world.setBlock(i + 15, j + 10, k + 20, deepslate_bricks, 2, 2);
		world.setBlock(i + 21, j + 10, k + 20, deepslate_bricks, 2, 2);
		world.setBlock(i + 15, j + 10, k + 21, deepslate_bricks, 3, 2);
		world.setBlock(i + 21, j + 10, k + 21, deepslate_bricks, 2, 2);
		world.setBlock(i + 15, j + 10, k + 22, deepslate_bricks, 2, 2);
		world.setBlock(i + 21, j + 10, k + 22, deepslate_bricks, 3, 2);
		world.setBlock(i + 15, j + 10, k + 23, deepslate_bricks, 2, 2);
		world.setBlock(i + 16, j + 10, k + 23, deepslate_bricks, 3, 2);
		world.setBlock(i + 17, j + 10, k + 23, deepslate_bricks, 2, 2);
		world.setBlock(i + 18, j + 10, k + 23, deepslate_bricks, 2, 2);
		world.setBlock(i + 19, j + 10, k + 23, deepslate_bricks, 2, 2);
		world.setBlock(i + 20, j + 10, k + 23, deepslate_bricks, 2, 2);
		world.setBlock(i + 21, j + 10, k + 23, deepslate_bricks, 2, 2);
		world.setBlock(i + 33, j + 10, k + 24, polished_deepslate, 0, 2);
		world.setBlock(i + 17, j + 10, k + 25, SoulFire, 15, 2);
		world.setBlock(i + 18, j + 10, k + 25, SoulFire, 15, 2);
		world.setBlock(i + 19, j + 10, k + 25, SoulFire, 15, 2);
		world.setBlock(i + 17, j + 10, k + 26, SoulFire, 15, 2);
		world.setBlock(i + 18, j + 10, k + 26, SoulFire, 15, 2);
		world.setBlock(i + 19, j + 10, k + 26, SoulFire, 15, 2);
		world.setBlock(i + 17, j + 10, k + 27, SoulFire, 15, 2);
		world.setBlock(i + 18, j + 10, k + 27, SoulFire, 15, 2);
		world.setBlock(i + 19, j + 10, k + 27, SoulFire, 15, 2);
		world.setBlock(i + 17, j + 10, k + 28, SoulFire, 15, 2);
		world.setBlock(i + 18, j + 10, k + 28, SoulFire, 15, 2);
		world.setBlock(i + 19, j + 10, k + 28, SoulFire, 15, 2);
		world.setBlock(i + 23, j + 10, k + 28, deepslate_bricks, 0, 2);
		world.setBlock(i + 24, j + 10, k + 28, deepslate_bricks, 0, 2);
		world.setBlock(i + 25, j + 10, k + 28, deepslate_bricks, 0, 2);
		world.setBlock(i + 26, j + 10, k + 28, deepslate_bricks, 0, 2);
		world.setBlock(i + 27, j + 10, k + 28, deepslate_bricks, 4, 2);
		world.setBlock(i + 17, j + 10, k + 29, SoulFire, 15, 2);
		world.setBlock(i + 18, j + 10, k + 29, SoulFire, 15, 2);
		world.setBlock(i + 19, j + 10, k + 29, SoulFire, 15, 2);
		world.setBlock(i + 23, j + 10, k + 29, deepslate_bricks, 0, 2);
		world.setBlock(i + 24, j + 10, k + 29, deepslate_bricks, 1, 2);
		world.setBlock(i + 25, j + 10, k + 29, deepslate_bricks, 0, 2);
		world.setBlock(i + 26, j + 10, k + 29, deepslate_bricks, 0, 2);
		world.setBlock(i + 27, j + 10, k + 29, deepslate_bricks, 4, 2);
		world.setBlock(i + 17, j + 10, k + 30, SoulFire, 15, 2);
		world.setBlock(i + 18, j + 10, k + 30, SoulFire, 15, 2);
		world.setBlock(i + 19, j + 10, k + 30, SoulFire, 15, 2);
		world.setBlock(i + 33, j + 10, k + 30, polished_deepslate, 0, 2);
		world.setBlock(i + 17, j + 10, k + 31, SoulFire, 15, 2);
		world.setBlock(i + 18, j + 10, k + 31, SoulFire, 15, 2);
		world.setBlock(i + 19, j + 10, k + 31, SoulFire, 15, 2);
		world.setBlock(i + 17, j + 10, k + 32, SoulFire, 15, 2);
		world.setBlock(i + 18, j + 10, k + 32, SoulFire, 15, 2);
		world.setBlock(i + 19, j + 10, k + 32, SoulFire, 15, 2);
		world.setBlock(i + 17, j + 10, k + 33, SoulFire, 15, 2);
		world.setBlock(i + 18, j + 10, k + 33, SoulFire, 15, 2);
		world.setBlock(i + 19, j + 10, k + 33, SoulFire, 15, 2);
		world.setBlock(i + 17, j + 10, k + 34, SoulFire, 15, 2);
		world.setBlock(i + 18, j + 10, k + 34, SoulFire, 15, 2);
		world.setBlock(i + 19, j + 10, k + 34, SoulFire, 15, 2);
		world.setBlock(i + 24, j + 10, k + 34, Blocks.air, 0, 2); //
		world.setBlock(i + 17, j + 10, k + 35, SoulFire, 15, 2);
		world.setBlock(i + 18, j + 10, k + 35, SoulFire, 15, 2);
		world.setBlock(i + 19, j + 10, k + 35, SoulFire, 15, 2);
		world.setBlock(i + 17, j + 10, k + 36, SoulFire, 15, 2);
		world.setBlock(i + 18, j + 10, k + 36, SoulFire, 15, 2);
		world.setBlock(i + 19, j + 10, k + 36, SoulFire, 15, 2);
		world.setBlock(i + 17, j + 10, k + 37, SoulFire, 15, 2);
		world.setBlock(i + 18, j + 10, k + 37, SoulFire, 15, 2);
		world.setBlock(i + 19, j + 10, k + 37, SoulFire, 15, 2);
		world.setBlock(i + 17, j + 10, k + 38, SoulFire, 15, 2);
		world.setBlock(i + 18, j + 10, k + 38, SoulFire, 15, 2);
		world.setBlock(i + 19, j + 10, k + 38, SoulFire, 15, 2);
		world.setBlock(i + 33, j + 10, k + 38, polished_deepslate, 0, 2);
		world.setBlock(i + 17, j + 10, k + 39, SoulFire, 15, 2);
		world.setBlock(i + 18, j + 10, k + 39, SoulFire, 15, 2);
		world.setBlock(i + 19, j + 10, k + 39, SoulFire, 15, 2);
		world.setBlock(i + 23, j + 10, k + 39, cobbled_deepslate, 0, 2);
		world.setBlock(i + 24, j + 10, k + 39, deepslate_bricks, 0, 2);
		world.setBlock(i + 25, j + 10, k + 39, cobbled_deepslate, 0, 2);
		world.setBlock(i + 26, j + 10, k + 39, cobbled_deepslate, 0, 2);
		world.setBlock(i + 27, j + 10, k + 39, deepslate_bricks, 4, 2);
		world.setBlock(i + 17, j + 10, k + 40, SoulFire, 15, 2);
		world.setBlock(i + 18, j + 10, k + 40, SoulFire, 15, 2);
		world.setBlock(i + 19, j + 10, k + 40, SoulFire, 15, 2);
		world.setBlock(i + 23, j + 10, k + 40, deepslate_bricks, 0, 2);
		world.setBlock(i + 24, j + 10, k + 40, deepslate_bricks, 0, 2);
		world.setBlock(i + 25, j + 10, k + 40, deepslate_bricks, 1, 2);
		world.setBlock(i + 26, j + 10, k + 40, deepslate_bricks, 0, 2);
		world.setBlock(i + 27, j + 10, k + 40, deepslate_bricks, 4, 2);
		world.setBlock(i + 17, j + 10, k + 41, SoulFire, 15, 2);
		world.setBlock(i + 18, j + 10, k + 41, SoulFire, 15, 2);
		world.setBlock(i + 19, j + 10, k + 41, SoulFire, 15, 2);
		world.setBlock(i + 23, j + 10, k + 41, NovaCraftBlocks.dim_vanite_torch, 5, 2);
		world.setBlock(i + 24, j + 10, k + 41, NovaCraftBlocks.dim_vanite_torch, 5, 2);
		world.setBlock(i + 26, j + 10, k + 41, NovaCraftBlocks.dim_vanite_torch, 5, 2);
		world.setBlock(i + 17, j + 10, k + 42, SoulFire, 15, 2);
		world.setBlock(i + 18, j + 10, k + 42, SoulFire, 15, 2);
		world.setBlock(i + 19, j + 10, k + 42, SoulFire, 15, 2);
		world.setBlock(i + 23, j + 10, k + 42, NovaCraftBlocks.dim_vanite_torch, 5, 2);
		world.setBlock(i + 24, j + 10, k + 42, NovaCraftBlocks.dim_vanite_torch, 5, 2);
		world.setBlock(i + 17, j + 10, k + 43, SoulFire, 15, 2);
		world.setBlock(i + 18, j + 10, k + 43, SoulFire, 15, 2);
		world.setBlock(i + 19, j + 10, k + 43, SoulFire, 15, 2);
		world.setBlock(i + 23, j + 10, k + 43, NovaCraftBlocks.dim_vanite_torch, 5, 2);
		world.setBlock(i + 15, j + 10, k + 45, deepslate_bricks, 3, 2);
		world.setBlock(i + 21, j + 10, k + 45, deepslate_bricks, 2, 2);
		world.setBlock(i + 15, j + 10, k + 46, deepslate_bricks, 2, 2);
		world.setBlock(i + 21, j + 10, k + 46, deepslate_bricks, 3, 2);
		world.setBlock(i + 15, j + 10, k + 47, deepslate_bricks, 3, 2);
		world.setBlock(i + 21, j + 10, k + 47, deepslate_bricks, 3, 2);
		world.setBlock(i + 15, j + 10, k + 48, deepslate_bricks, 2, 2);
		world.setBlock(i + 21, j + 10, k + 48, deepslate_bricks, 3, 2);
		world.setBlock(i + 15, j + 10, k + 49, deepslate_bricks, 2, 2);
		world.setBlock(i + 21, j + 10, k + 49, deepslate_bricks, 2, 2);
		world.setBlock(i + 16, j + 10, k + 50, deepslate_bricks, 2, 2);
		world.setBlock(i + 17, j + 10, k + 50, deepslate_bricks, 2, 2);
		world.setBlock(i + 18, j + 10, k + 50, deepslate_bricks, 2, 2);
		world.setBlock(i + 19, j + 10, k + 50, deepslate_bricks, 2, 2);
		world.setBlock(i + 20, j + 10, k + 50, deepslate_bricks, 3, 2);
		world.setBlock(i + 21, j + 10, k + 50, deepslate_bricks, 2, 2);
		world.setBlock(i + 16, j + 11, k + 18, deepslate_bricks, 1, 2);
		world.setBlock(i + 17, j + 11, k + 18, deepslate_bricks, 1, 2);
		world.setBlock(i + 18, j + 11, k + 18, deepslate_bricks, 1, 2);
		world.setBlock(i + 19, j + 11, k + 18, deepslate_bricks, 0, 2);
		world.setBlock(i + 16, j + 11, k + 19, deepslate_bricks, 0, 2);
		world.setBlock(i + 17, j + 11, k + 19, deepslate_bricks, 0, 2);
		world.setBlock(i + 18, j + 11, k + 19, deepslate_bricks, 1, 2);
		world.setBlock(i + 19, j + 11, k + 19, deepslate_bricks, 0, 2);
		world.setBlock(i + 20, j + 11, k + 19, deepslate_bricks, 0, 2);
		world.setBlock(i + 16, j + 11, k + 20, deepslate_bricks, 0, 2);
		world.setBlock(i + 17, j + 11, k + 20, deepslate_bricks, 0, 2);
		world.setBlock(i + 18, j + 11, k + 20, deepslate_bricks, 0, 2);
		world.setBlock(i + 19, j + 11, k + 20, deepslate_bricks, 1, 2);
		world.setBlock(i + 20, j + 11, k + 20, deepslate_bricks, 0, 2);
		world.setBlock(i + 16, j + 11, k + 21, deepslate_bricks, 2, 2);
		world.setBlock(i + 17, j + 11, k + 21, deepslate_bricks, 1, 2);
		world.setBlock(i + 18, j + 11, k + 21, deepslate_bricks, 0, 2);
		world.setBlock(i + 19, j + 11, k + 21, deepslate_bricks, 0, 2);
		world.setBlock(i + 20, j + 11, k + 21, deepslate_bricks, 1, 2);
		world.setBlock(i + 16, j + 11, k + 22, deepslate_bricks, 1, 2);
		world.setBlock(i + 17, j + 11, k + 22, deepslate_bricks, 1, 2);
		world.setBlock(i + 18, j + 11, k + 22, deepslate_bricks, 0, 2);
		world.setBlock(i + 19, j + 11, k + 22, deepslate_bricks, 0, 2);
		world.setBlock(i + 16, j + 11, k + 23, deepslate_bricks, 0, 2);
		world.setBlock(i + 17, j + 11, k + 23, deepslate_bricks, 0, 2);
		world.setBlock(i + 18, j + 11, k + 23, deepslate_bricks, 0, 2);
		world.setBlock(i + 19, j + 11, k + 23, deepslate_bricks, 0, 2);
		world.setBlock(i + 16, j + 11, k + 24, deepslate_bricks, 1, 2);
		world.setBlock(i + 17, j + 11, k + 24, deepslate_bricks, 0, 2);
		world.setBlock(i + 18, j + 11, k + 24, deepslate_bricks, 0, 2);
		world.setBlock(i + 19, j + 11, k + 24, deepslate_bricks, 0, 2);
		world.setBlock(i + 33, j + 11, k + 24, Blocks.redstone_lamp, 0, 2);
		world.setBlock(i + 16, j + 11, k + 25, deepslate_bricks, 1, 2);
		world.setBlock(i + 17, j + 11, k + 25, deepslate_bricks, 1, 2);
		world.setBlock(i + 18, j + 11, k + 25, deepslate_bricks, 0, 2);
		world.setBlock(i + 19, j + 11, k + 25, deepslate_bricks, 1, 2);
		world.setBlock(i + 20, j + 11, k + 25, deepslate_bricks, 1, 2);
		world.setBlock(i + 16, j + 11, k + 26, deepslate_bricks, 0, 2);
		world.setBlock(i + 17, j + 11, k + 26, deepslate_bricks, 0, 2);
		world.setBlock(i + 18, j + 11, k + 26, deepslate_bricks, 1, 2);
		world.setBlock(i + 19, j + 11, k + 26, deepslate_bricks, 0, 2);
		world.setBlock(i + 20, j + 11, k + 26, deepslate_bricks, 0, 2);
		world.setBlock(i + 16, j + 11, k + 27, deepslate_bricks, 1, 2);
		world.setBlock(i + 17, j + 11, k + 27, deepslate_bricks, 0, 2);
		world.setBlock(i + 18, j + 11, k + 27, deepslate_bricks, 1, 2);
		world.setBlock(i + 19, j + 11, k + 27, deepslate_bricks, 0, 2);
		world.setBlock(i + 20, j + 11, k + 27, deepslate_bricks, 0, 2);
		world.setBlock(i + 16, j + 11, k + 28, deepslate_bricks, 0, 2);
		world.setBlock(i + 17, j + 11, k + 28, deepslate_bricks, 0, 2);
		world.setBlock(i + 18, j + 11, k + 28, deepslate_bricks, 1, 2);
		world.setBlock(i + 19, j + 11, k + 28, deepslate_bricks, 0, 2);
		world.setBlock(i + 20, j + 11, k + 28, deepslate_bricks, 0, 2);
		world.setBlock(i + 26, j + 11, k + 28, NovaCraftBlocks.dim_vanite_torch, 5, 2);
		world.setBlock(i + 27, j + 11, k + 28, NovaCraftBlocks.dim_vanite_torch, 5, 2);
		world.setBlock(i + 16, j + 11, k + 29, deepslate_bricks, 0, 2);
		world.setBlock(i + 17, j + 11, k + 29, deepslate_bricks, 1, 2);
		world.setBlock(i + 18, j + 11, k + 29, deepslate_bricks, 0, 2);
		world.setBlock(i + 19, j + 11, k + 29, deepslate_bricks, 0, 2);
		world.setBlock(i + 20, j + 11, k + 29, deepslate_bricks, 0, 2);
		world.setBlock(i + 25, j + 11, k + 29, NovaCraftBlocks.dim_vanite_torch, 5, 2);
		world.setBlock(i + 26, j + 11, k + 29, NovaCraftBlocks.dim_vanite_torch, 5, 2);
		world.setBlock(i + 27, j + 11, k + 29, NovaCraftBlocks.dim_vanite_torch, 5, 2);
		world.setBlock(i + 16, j + 11, k + 30, deepslate_bricks, 0, 2);
		world.setBlock(i + 17, j + 11, k + 30, deepslate_bricks, 0, 2);
		world.setBlock(i + 18, j + 11, k + 30, deepslate_bricks, 1, 2);
		world.setBlock(i + 19, j + 11, k + 30, deepslate_bricks, 1, 2);
		world.setBlock(i + 20, j + 11, k + 30, deepslate_bricks, 1, 2);
		world.setBlock(i + 33, j + 11, k + 30, Blocks.redstone_lamp, 0, 2);
		world.setBlock(i + 16, j + 11, k + 31, deepslate_bricks, 0, 2);
		world.setBlock(i + 17, j + 11, k + 31, deepslate_bricks, 0, 2);
		world.setBlock(i + 18, j + 11, k + 31, deepslate_bricks, 1, 2);
		world.setBlock(i + 19, j + 11, k + 31, deepslate_bricks, 0, 2);
		world.setBlock(i + 20, j + 11, k + 31, deepslate_bricks, 0, 2);
		world.setBlock(i + 17, j + 11, k + 32, deepslate_bricks, 1, 2);
		world.setBlock(i + 18, j + 11, k + 32, deepslate_bricks, 0, 2);
		world.setBlock(i + 19, j + 11, k + 32, deepslate_bricks, 0, 2);
		world.setBlock(i + 20, j + 11, k + 32, deepslate_bricks, 0, 2);
		world.setBlock(i + 16, j + 11, k + 33, deepslate_bricks, 0, 2);
		world.setBlock(i + 17, j + 11, k + 33, deepslate_bricks, 0, 2);
		world.setBlock(i + 18, j + 11, k + 33, deepslate_bricks, 0, 2);
		world.setBlock(i + 19, j + 11, k + 33, deepslate_bricks, 0, 2);
		world.setBlock(i + 16, j + 11, k + 34, deepslate_bricks, 1, 2);
		world.setBlock(i + 17, j + 11, k + 34, deepslate_bricks, 0, 2);
		world.setBlock(i + 18, j + 11, k + 34, deepslate_bricks, 0, 2);
		world.setBlock(i + 19, j + 11, k + 34, deepslate_bricks, 0, 2);
		world.setBlock(i + 16, j + 11, k + 35, deepslate_bricks, 1, 2);
		world.setBlock(i + 17, j + 11, k + 35, deepslate_bricks, 0, 2);
		world.setBlock(i + 18, j + 11, k + 35, deepslate_bricks, 0, 2);
		world.setBlock(i + 19, j + 11, k + 35, deepslate_bricks, 1, 2);
		world.setBlock(i + 20, j + 11, k + 35, deepslate_bricks, 1, 2);
		world.setBlock(i + 16, j + 11, k + 36, deepslate_bricks, 0, 2);
		world.setBlock(i + 17, j + 11, k + 36, deepslate_bricks, 0, 2);
		world.setBlock(i + 18, j + 11, k + 36, deepslate_bricks, 0, 2);
		world.setBlock(i + 19, j + 11, k + 36, deepslate_bricks, 0, 2);
		world.setBlock(i + 20, j + 11, k + 36, deepslate_bricks, 1, 2);
		world.setBlock(i + 16, j + 11, k + 37, cobbled_deepslate, 0, 2);
		world.setBlock(i + 17, j + 11, k + 37, cobbled_deepslate, 0, 2);
		world.setBlock(i + 18, j + 11, k + 37, cobbled_deepslate, 0, 2);
		world.setBlock(i + 19, j + 11, k + 37, cobbled_deepslate, 0, 2);
		world.setBlock(i + 20, j + 11, k + 37, cobbled_deepslate, 0, 2);
		world.setBlock(i + 16, j + 11, k + 38, cobbled_deepslate, 0, 2);
		world.setBlock(i + 17, j + 11, k + 38, cobbled_deepslate, 0, 2);
		world.setBlock(i + 18, j + 11, k + 38, cobbled_deepslate, 0, 2);
		world.setBlock(i + 19, j + 11, k + 38, cobbled_deepslate, 0, 2);
		world.setBlock(i + 20, j + 11, k + 38, cobbled_deepslate, 0, 2);
		world.setBlock(i + 16, j + 11, k + 39, cobbled_deepslate, 0, 2);
		world.setBlock(i + 17, j + 11, k + 39, cobbled_deepslate, 0, 2);
		world.setBlock(i + 18, j + 11, k + 39, cobbled_deepslate, 0, 2);
		world.setBlock(i + 19, j + 11, k + 39, cobbled_deepslate, 0, 2);
		world.setBlock(i + 20, j + 11, k + 39, cobbled_deepslate, 0, 2);
		world.setBlock(i + 26, j + 11, k + 39, NovaCraftBlocks.dim_vanite_torch, 5, 2);
		world.setBlock(i + 27, j + 11, k + 39, NovaCraftBlocks.dim_vanite_torch, 5, 2);
		world.setBlock(i + 16, j + 11, k + 40, cobbled_deepslate, 0, 2);
		world.setBlock(i + 17, j + 11, k + 40, cobbled_deepslate, 0, 2);
		world.setBlock(i + 18, j + 11, k + 40, cobbled_deepslate, 0, 2);
		world.setBlock(i + 19, j + 11, k + 40, cobbled_deepslate, 0, 2);
		world.setBlock(i + 20, j + 11, k + 40, cobbled_deepslate, 0, 2);
		world.setBlock(i + 26, j + 11, k + 40, NovaCraftBlocks.dim_vanite_torch, 5, 2);
		world.setBlock(i + 27, j + 11, k + 40, NovaCraftBlocks.dim_vanite_torch, 5, 2);
		world.setBlock(i + 16, j + 11, k + 41, cobbled_deepslate, 0, 2);
		world.setBlock(i + 17, j + 11, k + 41, cobbled_deepslate, 0, 2);
		world.setBlock(i + 18, j + 11, k + 41, cobbled_deepslate, 0, 2);
		world.setBlock(i + 19, j + 11, k + 41, cobbled_deepslate, 0, 2);
		world.setBlock(i + 20, j + 11, k + 41, cobbled_deepslate, 0, 2);
		world.setBlock(i + 16, j + 11, k + 42, cobbled_deepslate, 0, 2);
		world.setBlock(i + 17, j + 11, k + 42, cobbled_deepslate, 0, 2);
		world.setBlock(i + 18, j + 11, k + 42, cobbled_deepslate, 0, 2);
		world.setBlock(i + 19, j + 11, k + 42, cobbled_deepslate, 0, 2);
		world.setBlock(i + 20, j + 11, k + 42, cobbled_deepslate, 0, 2);
		world.setBlock(i + 16, j + 11, k + 43, cobbled_deepslate, 0, 2);
		world.setBlock(i + 17, j + 11, k + 43, cobbled_deepslate, 0, 2);
		world.setBlock(i + 18, j + 11, k + 43, cobbled_deepslate, 0, 2);
		world.setBlock(i + 19, j + 11, k + 43, cobbled_deepslate, 0, 2);
		world.setBlock(i + 20, j + 11, k + 43, cobbled_deepslate, 0, 2);
		world.setBlock(i + 16, j + 11, k + 44, deepslate_bricks, 0, 2);
		world.setBlock(i + 17, j + 11, k + 44, deepslate_bricks, 0, 2);
		world.setBlock(i + 18, j + 11, k + 44, deepslate_bricks, 1, 2);
		world.setBlock(i + 19, j + 11, k + 44, deepslate_bricks, 0, 2);
		world.setBlock(i + 20, j + 11, k + 44, cobbled_deepslate, 0, 2);
		world.setBlock(i + 16, j + 11, k + 45, deepslate_bricks, 1, 2);
		world.setBlock(i + 17, j + 11, k + 45, deepslate_bricks, 0, 2);
		world.setBlock(i + 18, j + 11, k + 45, deepslate_bricks, 1, 2);
		world.setBlock(i + 19, j + 11, k + 45, deepslate_bricks, 0, 2);
		world.setBlock(i + 20, j + 11, k + 45, cobbled_deepslate, 0, 2);
		world.setBlock(i + 16, j + 11, k + 46, deepslate_bricks, 0, 2);
		world.setBlock(i + 17, j + 11, k + 46, deepslate_bricks, 0, 2);
		world.setBlock(i + 18, j + 11, k + 46, deepslate_bricks, 0, 2);
		world.setBlock(i + 19, j + 11, k + 46, deepslate_bricks, 0, 2);
		world.setBlock(i + 20, j + 11, k + 46, cobbled_deepslate, 0, 2);
		world.setBlock(i + 16, j + 11, k + 47, deepslate_bricks, 0, 2);
		world.setBlock(i + 17, j + 11, k + 47, deepslate_bricks, 1, 2);
		world.setBlock(i + 18, j + 11, k + 47, deepslate_bricks, 0, 2);
		world.setBlock(i + 19, j + 11, k + 47, deepslate_bricks, 0, 2);
		world.setBlock(i + 20, j + 11, k + 47, cobbled_deepslate, 0, 2);
		world.setBlock(i + 16, j + 11, k + 48, deepslate_bricks, 0, 2);
		world.setBlock(i + 17, j + 11, k + 48, deepslate_bricks, 1, 2);
		world.setBlock(i + 18, j + 11, k + 48, deepslate_bricks, 0, 2);
		world.setBlock(i + 19, j + 11, k + 48, deepslate_bricks, 0, 2);
		world.setBlock(i + 20, j + 11, k + 48, cobbled_deepslate, 0, 2);
		world.setBlock(i + 16, j + 11, k + 49, deepslate_bricks, 0, 2);
		world.setBlock(i + 17, j + 11, k + 49, deepslate_bricks, 1, 2);
		world.setBlock(i + 18, j + 11, k + 49, deepslate_bricks, 0, 2);
		world.setBlock(i + 19, j + 11, k + 49, deepslate_bricks, 0, 2);
		world.setBlock(i + 16, j + 12, k + 18, deepslate_bricks, 0, 2);
		world.setBlock(i + 17, j + 12, k + 18, deepslate_bricks, 0, 2);
		world.setBlock(i + 18, j + 12, k + 18, deepslate_bricks, 1, 2);
		world.setBlock(i + 19, j + 12, k + 18, deepslate_bricks, 0, 2);
		world.setBlock(i + 20, j + 12, k + 18, deepslate_bricks, 1, 2);
		world.setBlock(i + 16, j + 12, k + 19, deepslate_bricks, 1, 2);
		world.setBlock(i + 17, j + 12, k + 19, deepslate_bricks, 0, 2);
		world.setBlock(i + 18, j + 12, k + 19, deepslate_bricks, 0, 2);
		world.setBlock(i + 19, j + 12, k + 19, deepslate_bricks, 1, 2);
		world.setBlock(i + 20, j + 12, k + 19, deepslate_bricks, 0, 2);
		world.setBlock(i + 16, j + 12, k + 20, deepslate_bricks, 3, 2);
		world.setBlock(i + 17, j + 12, k + 20, deepslate_bricks, 2, 2);
		world.setBlock(i + 18, j + 12, k + 20, deepslate_bricks, 0, 2);
		world.setBlock(i + 19, j + 12, k + 20, deepslate_bricks, 0, 2);
		world.setBlock(i + 20, j + 12, k + 20, deepslate_bricks, 0, 2);
		world.setBlock(i + 16, j + 12, k + 21, deepslate_bricks, 2, 2);
		world.setBlock(i + 17, j + 12, k + 21, deepslate_bricks, 2, 2);
		world.setBlock(i + 18, j + 12, k + 21, deepslate_bricks, 2, 2);
		world.setBlock(i + 19, j + 12, k + 21, deepslate_bricks, 2, 2);
		world.setBlock(i + 20, j + 12, k + 21, deepslate_bricks, 1, 2);
		world.setBlock(i + 16, j + 12, k + 22, deepslate_bricks, 2, 2);
		world.setBlock(i + 17, j + 12, k + 22, deepslate_bricks, 2, 2);
		world.setBlock(i + 18, j + 12, k + 22, deepslate_bricks, 2, 2);
		world.setBlock(i + 19, j + 12, k + 22, deepslate_bricks, 1, 2);
		world.setBlock(i + 16, j + 12, k + 23, deepslate_bricks, 0, 2);
		world.setBlock(i + 17, j + 12, k + 23, deepslate_bricks, 0, 2);
		world.setBlock(i + 18, j + 12, k + 23, deepslate_bricks, 0, 2);
		world.setBlock(i + 19, j + 12, k + 23, deepslate_bricks, 0, 2);
		world.setBlock(i + 32, j + 12, k + 23, polished_deepslate_stairs, 4, 2);
		world.setBlock(i + 33, j + 12, k + 23, deepslate_bricks, 4, 2);
		world.setBlock(i + 34, j + 12, k + 23, polished_deepslate_stairs, 5, 2);
		world.setBlock(i + 16, j + 12, k + 24, deepslate_bricks, 1, 2);
		world.setBlock(i + 17, j + 12, k + 24, deepslate_bricks, 0, 2);
		world.setBlock(i + 18, j + 12, k + 24, deepslate_bricks, 0, 2);
		world.setBlock(i + 19, j + 12, k + 24, deepslate_bricks, 1, 2);
		world.setBlock(i + 20, j + 12, k + 24, deepslate_bricks, 0, 2);
		world.setBlock(i + 32, j + 12, k + 24, deepslate_bricks, 4, 2);
		world.setBlock(i + 34, j + 12, k + 24, polished_deepslate, 0, 2);
		world.setBlock(i + 16, j + 12, k + 25, deepslate_bricks, 0, 2);
		world.setBlock(i + 17, j + 12, k + 25, deepslate_bricks, 1, 2);
		world.setBlock(i + 18, j + 12, k + 25, deepslate_bricks, 0, 2);
		world.setBlock(i + 19, j + 12, k + 25, deepslate_bricks, 0, 2);
		world.setBlock(i + 20, j + 12, k + 25, deepslate_bricks, 0, 2);
		world.setBlock(i + 32, j + 12, k + 25, polished_deepslate_stairs, 4, 2);
		world.setBlock(i + 33, j + 12, k + 25, deepslate_bricks, 4, 2);
		world.setBlock(i + 34, j + 12, k + 25, polished_deepslate_stairs, 5, 2);
		world.setBlock(i + 16, j + 12, k + 26, deepslate_bricks, 1, 2);
		world.setBlock(i + 17, j + 12, k + 26, deepslate_bricks, 0, 2);
		world.setBlock(i + 18, j + 12, k + 26, deepslate_bricks, 0, 2);
		world.setBlock(i + 19, j + 12, k + 26, deepslate_bricks, 0, 2);
		world.setBlock(i + 20, j + 12, k + 26, deepslate_bricks, 0, 2);
		world.setBlock(i + 16, j + 12, k + 27, deepslate_bricks, 0, 2);
		world.setBlock(i + 17, j + 12, k + 27, deepslate_bricks, 0, 2);
		world.setBlock(i + 18, j + 12, k + 27, deepslate_bricks, 0, 2);
		world.setBlock(i + 19, j + 12, k + 27, deepslate_bricks, 0, 2);
		world.setBlock(i + 20, j + 12, k + 27, deepslate_bricks, 0, 2);
		world.setBlock(i + 16, j + 12, k + 28, deepslate_bricks, 0, 2);
		world.setBlock(i + 17, j + 12, k + 28, deepslate_bricks, 0, 2);
		world.setBlock(i + 18, j + 12, k + 28, deepslate_bricks, 0, 2);
		world.setBlock(i + 19, j + 12, k + 28, deepslate_bricks, 0, 2);
		world.setBlock(i + 20, j + 12, k + 28, deepslate_bricks, 1, 2);
		world.setBlock(i + 16, j + 12, k + 29, deepslate_bricks, 0, 2);
		world.setBlock(i + 17, j + 12, k + 29, deepslate_bricks, 0, 2);
		world.setBlock(i + 18, j + 12, k + 29, deepslate_bricks, 1, 2);
		world.setBlock(i + 19, j + 12, k + 29, deepslate_bricks, 0, 2);
		world.setBlock(i + 20, j + 12, k + 29, deepslate_bricks, 0, 2);
		world.setBlock(i + 32, j + 12, k + 29, polished_deepslate_stairs, 4, 2);
		world.setBlock(i + 33, j + 12, k + 29, deepslate_bricks, 4, 2);
		world.setBlock(i + 34, j + 12, k + 29, polished_deepslate_stairs, 5, 2);
		world.setBlock(i + 16, j + 12, k + 30, deepslate_bricks, 0, 2);
		world.setBlock(i + 17, j + 12, k + 30, deepslate_bricks, 0, 2);
		world.setBlock(i + 18, j + 12, k + 30, deepslate_bricks, 1, 2);
		world.setBlock(i + 19, j + 12, k + 30, deepslate_bricks, 0, 2);
		world.setBlock(i + 20, j + 12, k + 30, deepslate_bricks, 0, 2);
		world.setBlock(i + 32, j + 12, k + 30, deepslate_bricks, 4, 2);
		world.setBlock(i + 34, j + 12, k + 30, deepslate_bricks, 4, 2);
		world.setBlock(i + 16, j + 12, k + 31, deepslate_bricks, 1, 2);
		world.setBlock(i + 17, j + 12, k + 31, deepslate_bricks, 0, 2);
		world.setBlock(i + 18, j + 12, k + 31, deepslate_bricks, 0, 2);
		world.setBlock(i + 19, j + 12, k + 31, deepslate_bricks, 1, 2);
		world.setBlock(i + 20, j + 12, k + 31, deepslate_bricks, 0, 2);
		world.setBlock(i + 32, j + 12, k + 31, polished_deepslate_stairs, 4, 2);
		world.setBlock(i + 33, j + 12, k + 31, deepslate_bricks, 4, 2);
		world.setBlock(i + 34, j + 12, k + 31, polished_deepslate_stairs, 5, 2);
		world.setBlock(i + 16, j + 12, k + 32, deepslate_bricks, 1, 2);
		world.setBlock(i + 17, j + 12, k + 32, deepslate_bricks, 1, 2);
		world.setBlock(i + 18, j + 12, k + 32, deepslate_bricks, 0, 2);
		world.setBlock(i + 19, j + 12, k + 32, deepslate_bricks, 0, 2);
		world.setBlock(i + 20, j + 12, k + 32, deepslate_bricks, 0, 2);
		world.setBlock(i + 16, j + 12, k + 33, deepslate_bricks, 1, 2);
		world.setBlock(i + 17, j + 12, k + 33, deepslate_bricks, 0, 2);
		world.setBlock(i + 18, j + 12, k + 33, deepslate_bricks, 0, 2);
		world.setBlock(i + 19, j + 12, k + 33, deepslate_bricks, 0, 2);
		world.setBlock(i + 20, j + 12, k + 33, deepslate_bricks, 1, 2);
		world.setBlock(i + 16, j + 12, k + 34, deepslate_bricks, 0, 2);
		world.setBlock(i + 17, j + 12, k + 34, deepslate_bricks, 0, 2);
		world.setBlock(i + 18, j + 12, k + 34, deepslate_bricks, 0, 2);
		world.setBlock(i + 19, j + 12, k + 34, deepslate_bricks, 0, 2);
		world.setBlock(i + 20, j + 12, k + 34, deepslate_bricks, 0, 2);
		world.setBlock(i + 16, j + 12, k + 35, deepslate_bricks, 0, 2);
		world.setBlock(i + 17, j + 12, k + 35, deepslate_bricks, 1, 2);
		world.setBlock(i + 18, j + 12, k + 35, deepslate_bricks, 0, 2);
		world.setBlock(i + 19, j + 12, k + 35, deepslate_bricks, 1, 2);
		world.setBlock(i + 20, j + 12, k + 35, deepslate_bricks, 0, 2);
		world.setBlock(i + 16, j + 12, k + 36, deepslate_bricks, 1, 2);
		world.setBlock(i + 17, j + 12, k + 36, deepslate_bricks, 0, 2);
		world.setBlock(i + 18, j + 12, k + 36, deepslate_bricks, 1, 2);
		world.setBlock(i + 19, j + 12, k + 36, deepslate_bricks, 0, 2);
		world.setBlock(i + 20, j + 12, k + 36, deepslate_bricks, 0, 2);
		world.setBlock(i + 16, j + 12, k + 37, cobbled_deepslate, 0, 2);
		world.setBlock(i + 17, j + 12, k + 37, cobbled_deepslate, 0, 2);
		world.setBlock(i + 18, j + 12, k + 37, cobbled_deepslate, 0, 2);
		world.setBlock(i + 19, j + 12, k + 37, cobbled_deepslate, 0, 2);
		world.setBlock(i + 20, j + 12, k + 37, cobbled_deepslate, 0, 2);
		world.setBlock(i + 16, j + 12, k + 38, cobbled_deepslate, 0, 2);
		world.setBlock(i + 17, j + 12, k + 38, cobbled_deepslate, 0, 2);
		world.setBlock(i + 18, j + 12, k + 38, cobbled_deepslate, 0, 2);
		world.setBlock(i + 19, j + 12, k + 38, cobbled_deepslate, 0, 2);
		world.setBlock(i + 20, j + 12, k + 38, cobbled_deepslate, 0, 2);
		world.setBlock(i + 16, j + 12, k + 39, cobbled_deepslate, 0, 2);
		world.setBlock(i + 17, j + 12, k + 39, cobbled_deepslate, 0, 2);
		world.setBlock(i + 18, j + 12, k + 39, cobbled_deepslate, 0, 2);
		world.setBlock(i + 19, j + 12, k + 39, cobbled_deepslate, 0, 2);
		world.setBlock(i + 20, j + 12, k + 39, cobbled_deepslate, 0, 2);
		world.setBlock(i + 16, j + 12, k + 40, deepslate_bricks, 1, 2);
		world.setBlock(i + 17, j + 12, k + 40, deepslate_bricks, 0, 2);
		world.setBlock(i + 18, j + 12, k + 40, cobbled_deepslate, 0, 2);
		world.setBlock(i + 19, j + 12, k + 40, cobbled_deepslate, 0, 2);
		world.setBlock(i + 20, j + 12, k + 40, cobbled_deepslate, 0, 2);
		world.setBlock(i + 16, j + 12, k + 41, deepslate_bricks, 0, 2);
		world.setBlock(i + 17, j + 12, k + 41, deepslate_bricks, 0, 2);
		world.setBlock(i + 18, j + 12, k + 41, deepslate_bricks, 0, 2);
		world.setBlock(i + 19, j + 12, k + 41, deepslate_bricks, 0, 2);
		world.setBlock(i + 20, j + 12, k + 41, cobbled_deepslate, 0, 2);
		world.setBlock(i + 16, j + 12, k + 42, deepslate_bricks, 1, 2);
		world.setBlock(i + 17, j + 12, k + 42, deepslate_bricks, 1, 2);
		world.setBlock(i + 18, j + 12, k + 42, deepslate_bricks, 1, 2);
		world.setBlock(i + 19, j + 12, k + 42, deepslate_bricks, 0, 2);
		world.setBlock(i + 20, j + 12, k + 42, deepslate_bricks, 0, 2);
		
		
		
		
		
		
		
		
		
		
		
		
		
		
		
		
		
		
		
		
		
		
		
		
		
		
		
		
		
		
		
		



















		world.setBlock(i + 16, j + 12, k + 43, deepslate_bricks, 0, 2);
		world.setBlock(i + 17, j + 12, k + 43, deepslate_bricks, 0, 2);
		world.setBlock(i + 18, j + 12, k + 43, deepslate_bricks, 1, 2);
		world.setBlock(i + 19, j + 12, k + 43, deepslate_bricks, 1, 2);
		world.setBlock(i + 20, j + 12, k + 43, deepslate_bricks, 0, 2);
		world.setBlock(i + 16, j + 12, k + 44, deepslate_bricks, 0, 2);
		world.setBlock(i + 17, j + 12, k + 44, deepslate_bricks, 1, 2);
		world.setBlock(i + 18, j + 12, k + 44, deepslate_bricks, 0, 2);
		world.setBlock(i + 19, j + 12, k + 44, deepslate_bricks, 0, 2);
		world.setBlock(i + 20, j + 12, k + 44, deepslate_bricks, 0, 2);
		world.setBlock(i + 16, j + 12, k + 45, deepslate_bricks, 1, 2);
		world.setBlock(i + 17, j + 12, k + 45, deepslate_bricks, 1, 2);
		world.setBlock(i + 18, j + 12, k + 45, deepslate_bricks, 0, 2);
		world.setBlock(i + 19, j + 12, k + 45, deepslate_bricks, 1, 2);
		world.setBlock(i + 20, j + 12, k + 45, deepslate_bricks, 0, 2);
		world.setBlock(i + 16, j + 12, k + 46, deepslate_bricks, 0, 2);
		world.setBlock(i + 17, j + 12, k + 46, deepslate_bricks, 0, 2);
		world.setBlock(i + 18, j + 12, k + 46, deepslate_bricks, 0, 2);
		world.setBlock(i + 19, j + 12, k + 46, deepslate_bricks, 0, 2);
		world.setBlock(i + 20, j + 12, k + 46, cobbled_deepslate, 0, 2);
		world.setBlock(i + 16, j + 12, k + 47, deepslate_bricks, 0, 2);
		world.setBlock(i + 17, j + 12, k + 47, deepslate_bricks, 0, 2);
		world.setBlock(i + 18, j + 12, k + 47, deepslate_bricks, 0, 2);
		world.setBlock(i + 19, j + 12, k + 47, deepslate_bricks, 1, 2);
		world.setBlock(i + 20, j + 12, k + 47, cobbled_deepslate, 0, 2);
		world.setBlock(i + 16, j + 12, k + 48, deepslate_bricks, 1, 2);
		world.setBlock(i + 17, j + 12, k + 48, deepslate_bricks, 1, 2);
		world.setBlock(i + 18, j + 12, k + 48, deepslate_bricks, 1, 2);
		world.setBlock(i + 19, j + 12, k + 48, deepslate_bricks, 0, 2);
		world.setBlock(i + 20, j + 12, k + 48, cobbled_deepslate, 0, 2);
		world.setBlock(i + 16, j + 12, k + 49, deepslate_bricks, 1, 2);
		world.setBlock(i + 17, j + 12, k + 49, deepslate_bricks, 0, 2);
		world.setBlock(i + 18, j + 12, k + 49, deepslate_bricks, 0, 2);
		world.setBlock(i + 19, j + 12, k + 49, deepslate_bricks, 0, 2);
		world.setBlock(i + 20, j + 12, k + 49, cobbled_deepslate, 0, 2);
		world.setBlock(i + 16, j + 13, k + 18, deepslate_bricks, 1, 2);
		world.setBlock(i + 17, j + 13, k + 18, deepslate_bricks, 0, 2);
		world.setBlock(i + 18, j + 13, k + 18, deepslate_bricks, 0, 2);
		world.setBlock(i + 19, j + 13, k + 18, deepslate_bricks, 1, 2);
		world.setBlock(i + 20, j + 13, k + 18, deepslate_bricks, 0, 2);
		world.setBlock(i + 16, j + 13, k + 19, deepslate_bricks, 0, 2);
		world.setBlock(i + 17, j + 13, k + 19, deepslate_bricks, 0, 2);
		world.setBlock(i + 18, j + 13, k + 19, deepslate_bricks, 0, 2);
		world.setBlock(i + 19, j + 13, k + 19, deepslate_bricks, 0, 2);
		world.setBlock(i + 20, j + 13, k + 19, deepslate_bricks, 1, 2);
		world.setBlock(i + 16, j + 13, k + 20, deepslate_bricks, 2, 2);
		world.setBlock(i + 17, j + 13, k + 20, deepslate_bricks, 2, 2);
		world.setBlock(i + 18, j + 13, k + 20, deepslate_bricks, 2, 2);
		world.setBlock(i + 19, j + 13, k + 20, deepslate_bricks, 2, 2);
		world.setBlock(i + 20, j + 13, k + 20, deepslate_bricks, 2, 2);
		world.setBlock(i + 16, j + 13, k + 21, deepslate_bricks, 3, 2);
		world.setBlock(i + 17, j + 13, k + 21, deepslate_bricks, 2, 2);
		world.setBlock(i + 18, j + 13, k + 21, deepslate_bricks, 3, 2);
		world.setBlock(i + 19, j + 13, k + 21, deepslate_bricks, 2, 2);
		world.setBlock(i + 20, j + 13, k + 21, deepslate_bricks, 2, 2);
		world.setBlock(i + 16, j + 13, k + 22, deepslate_bricks, 2, 2);
		world.setBlock(i + 17, j + 13, k + 22, deepslate_bricks, 2, 2);
		world.setBlock(i + 18, j + 13, k + 22, deepslate_bricks, 3, 2);
		world.setBlock(i + 19, j + 13, k + 22, deepslate_bricks, 2, 2);
		world.setBlock(i + 20, j + 13, k + 22, deepslate_bricks, 3, 2);
		world.setBlock(i + 16, j + 13, k + 23, deepslate_bricks, 0, 2);
		world.setBlock(i + 17, j + 13, k + 23, deepslate_bricks, 2, 2);
		world.setBlock(i + 18, j + 13, k + 23, deepslate_bricks, 3, 2);
		world.setBlock(i + 19, j + 13, k + 23, deepslate_bricks, 3, 2);
		world.setBlock(i + 32, j + 13, k + 23, polished_deepslate, 0, 2);
		world.setBlock(i + 33, j + 13, k + 23, deepslate_bricks, 4, 2);
		world.setBlock(i + 34, j + 13, k + 23, polished_deepslate, 0, 2);
		world.setBlock(i + 16, j + 13, k + 24, deepslate_bricks, 0, 2);
		world.setBlock(i + 17, j + 13, k + 24, deepslate_bricks, 1, 2);
		world.setBlock(i + 18, j + 13, k + 24, deepslate_bricks, 0, 2);
		world.setBlock(i + 19, j + 13, k + 24, deepslate_bricks, 1, 2);
		world.setBlock(i + 20, j + 13, k + 24, deepslate_bricks, 0, 2);
		world.setBlock(i + 32, j + 13, k + 24, deepslate_bricks, 4, 2);
		world.setBlock(i + 34, j + 13, k + 24, deepslate_bricks, 4, 2);
		world.setBlock(i + 16, j + 13, k + 25, deepslate_bricks, 1, 2);
		world.setBlock(i + 17, j + 13, k + 25, deepslate_bricks, 1, 2);
		world.setBlock(i + 18, j + 13, k + 25, deepslate_bricks, 0, 2);
		world.setBlock(i + 19, j + 13, k + 25, deepslate_bricks, 1, 2);
		world.setBlock(i + 20, j + 13, k + 25, deepslate_bricks, 1, 2);
		world.setBlock(i + 32, j + 13, k + 25, polished_deepslate, 0, 2);
		world.setBlock(i + 33, j + 13, k + 25, deepslate_bricks, 4, 2);
		world.setBlock(i + 34, j + 13, k + 25, polished_deepslate, 0, 2);
		world.setBlock(i + 16, j + 13, k + 26, deepslate_bricks, 0, 2);
		world.setBlock(i + 17, j + 13, k + 26, deepslate_bricks, 1, 2);
		world.setBlock(i + 18, j + 13, k + 26, deepslate_bricks, 1, 2);
		world.setBlock(i + 19, j + 13, k + 26, deepslate_bricks, 0, 2);
		world.setBlock(i + 20, j + 13, k + 26, deepslate_bricks, 1, 2);
		world.setBlock(i + 16, j + 13, k + 27, deepslate_bricks, 0, 2);
		world.setBlock(i + 17, j + 13, k + 27, deepslate_bricks, 1, 2);
		world.setBlock(i + 18, j + 13, k + 27, deepslate_bricks, 1, 2);
		world.setBlock(i + 19, j + 13, k + 27, deepslate_bricks, 1, 2);
		world.setBlock(i + 20, j + 13, k + 27, deepslate_bricks, 0, 2);
		world.setBlock(i + 16, j + 13, k + 28, deepslate_bricks, 1, 2);
		world.setBlock(i + 17, j + 13, k + 28, deepslate_bricks, 0, 2);
		world.setBlock(i + 18, j + 13, k + 28, deepslate_bricks, 0, 2);
		world.setBlock(i + 19, j + 13, k + 28, deepslate_bricks, 0, 2);
		world.setBlock(i + 20, j + 13, k + 28, deepslate_bricks, 0, 2);
		world.setBlock(i + 16, j + 13, k + 29, deepslate_bricks, 1, 2);
		world.setBlock(i + 17, j + 13, k + 29, deepslate_bricks, 0, 2);
		world.setBlock(i + 18, j + 13, k + 29, deepslate_bricks, 0, 2);
		world.setBlock(i + 19, j + 13, k + 29, deepslate_bricks, 0, 2);
		world.setBlock(i + 20, j + 13, k + 29, deepslate_bricks, 1, 2);
		world.setBlock(i + 32, j + 13, k + 29, polished_deepslate, 0, 2);
		world.setBlock(i + 33, j + 13, k + 29, deepslate_bricks, 4, 2);
		world.setBlock(i + 34, j + 13, k + 29, polished_deepslate, 0, 2);
		world.setBlock(i + 16, j + 13, k + 30, deepslate_bricks, 1, 2);
		world.setBlock(i + 17, j + 13, k + 30, deepslate_bricks, 0, 2);
		world.setBlock(i + 18, j + 13, k + 30, deepslate_bricks, 0, 2);
		world.setBlock(i + 19, j + 13, k + 30, deepslate_bricks, 0, 2);
		world.setBlock(i + 20, j + 13, k + 30, deepslate_bricks, 0, 2);
		world.setBlock(i + 32, j + 13, k + 30, deepslate_bricks, 4, 2);
		world.setBlock(i + 34, j + 13, k + 30, deepslate_bricks, 4, 2);
		world.setBlock(i + 16, j + 13, k + 31, deepslate_bricks, 0, 2);
		world.setBlock(i + 17, j + 13, k + 31, deepslate_bricks, 1, 2);
		world.setBlock(i + 18, j + 13, k + 31, deepslate_bricks, 1, 2);
		world.setBlock(i + 19, j + 13, k + 31, deepslate_bricks, 0, 2);
		world.setBlock(i + 20, j + 13, k + 31, deepslate_bricks, 0, 2);
		world.setBlock(i + 32, j + 13, k + 31, polished_deepslate, 0, 2);
		world.setBlock(i + 33, j + 13, k + 31, deepslate_bricks, 4, 2);
		world.setBlock(i + 34, j + 13, k + 31, polished_deepslate, 0, 2);
		world.setBlock(i + 16, j + 13, k + 32, deepslate_bricks, 0, 2);
		world.setBlock(i + 17, j + 13, k + 32, deepslate_bricks, 0, 2);
		world.setBlock(i + 18, j + 13, k + 32, deepslate_bricks, 0, 2);
		world.setBlock(i + 19, j + 13, k + 32, deepslate_bricks, 1, 2);
		world.setBlock(i + 20, j + 13, k + 32, deepslate_bricks, 1, 2);
