package com.NovaCraft.world.ancient_city;

import java.util.Random;

import com.NovaCraft.Items.NovaCraftItems;
import com.NovaCraft.registry.OtherModBlocks;
import com.NovaCraft.registry.OtherModItems;
import com.NovaCraftBlocks.NovaCraftBlocks;

import cpw.mods.fml.common.Loader;
import net.minecraft.block.Block;
import net.minecraft.enchantment.Enchantment;
import net.minecraft.enchantment.EnchantmentData;
import net.minecraft.init.Blocks;
import net.minecraft.init.Items;
import net.minecraft.item.ItemStack;
import net.minecraft.tileentity.TileEntityChest;
import net.minecraft.util.MathHelper;
import net.minecraft.world.World;
import net.minecraft.world.gen.feature.WorldGenerator;

public class AncientCitySculkWallNegXGen extends WorldGenerator
{
	public AncientCitySculkWallNegXGen() {

	}

	private static final Block sculk_block = NovaCraftBlocks.sculk_block;
	private static final Block sculk_tulip = NovaCraftBlocks.sculk_tulip;
    
    public boolean generate(final World world, final Random random, final int i, final int j, final int k) {
    	
		world.setBlock(i + 7, j + 0, k + 1, NovaCraftBlocks.sculk_vein, 0, 2);
		world.setBlock(i + 11, j + 0, k + 10, NovaCraftBlocks.sculk_vein, 0, 2);
		world.setBlock(i + 12, j + 0, k + 10, NovaCraftBlocks.sculk_vein, 0, 2);
		world.setBlock(i + 8, j + 0, k + 11, NovaCraftBlocks.sculk_vein, 0, 2);
		world.setBlock(i + 12, j + 0, k + 11, NovaCraftBlocks.sculk_vein, 0, 2);
		world.setBlock(i + 27, j + 0, k + 16, sculk_block, 0, 2);
		world.setBlock(i + 21, j + 0, k + 17, sculk_block, 0, 2);
		world.setBlock(i + 27, j + 0, k + 17, sculk_block, 0, 2);
		world.setBlock(i + 28, j + 0, k + 17, sculk_block, 0, 2);
		world.setBlock(i + 20, j + 0, k + 18, sculk_block, 0, 2);
		world.setBlock(i + 21, j + 0, k + 18, sculk_block, 0, 2);
		world.setBlock(i + 22, j + 0, k + 18, sculk_block, 0, 2);
		world.setBlock(i + 26, j + 0, k + 18, sculk_block, 0, 2);
		world.setBlock(i + 27, j + 0, k + 18, sculk_block, 0, 2);
		world.setBlock(i + 28, j + 0, k + 18, sculk_block, 0, 2);
		world.setBlock(i + 29, j + 0, k + 18, sculk_block, 0, 2);
		world.setBlock(i + 19, j + 0, k + 19, sculk_block, 0, 2);
		world.setBlock(i + 20, j + 0, k + 19, sculk_block, 0, 2);
		world.setBlock(i + 21, j + 0, k + 19, sculk_block, 0, 2);
		world.setBlock(i + 22, j + 0, k + 19, sculk_block, 0, 2);
		world.setBlock(i + 26, j + 0, k + 19, sculk_block, 0, 2);
		world.setBlock(i + 27, j + 0, k + 19, sculk_block, 0, 2);
		world.setBlock(i + 28, j + 0, k + 19, sculk_block, 0, 2);
		world.setBlock(i + 29, j + 0, k + 19, sculk_block, 0, 2);
		world.setBlock(i + 18, j + 0, k + 20, sculk_block, 0, 2);
		world.setBlock(i + 19, j + 0, k + 20, sculk_block, 0, 2);
		world.setBlock(i + 20, j + 0, k + 20, sculk_block, 0, 2);
		world.setBlock(i + 26, j + 0, k + 20, sculk_block, 0, 2);
		world.setBlock(i + 27, j + 0, k + 20, sculk_block, 0, 2);
		world.setBlock(i + 28, j + 0, k + 20, sculk_block, 0, 2);
		world.setBlock(i + 29, j + 0, k + 20, sculk_block, 0, 2);
		world.setBlock(i + 26, j + 0, k + 21, sculk_block, 0, 2);
		world.setBlock(i + 27, j + 0, k + 21, sculk_block, 0, 2);
		world.setBlock(i + 28, j + 0, k + 21, sculk_block, 0, 2);
		world.setBlock(i + 29, j + 0, k + 21, sculk_block, 0, 2);
		world.setBlock(i + 26, j + 0, k + 22, sculk_block, 0, 2);
		world.setBlock(i + 27, j + 0, k + 22, sculk_block, 0, 2);
		world.setBlock(i + 28, j + 0, k + 22, sculk_block, 0, 2);
		world.setBlock(i + 29, j + 0, k + 22, sculk_block, 0, 2);
		world.setBlock(i + 26, j + 0, k + 23, sculk_block, 0, 2);
		world.setBlock(i + 27, j + 0, k + 23, sculk_block, 0, 2);
		world.setBlock(i + 28, j + 0, k + 23, sculk_block, 0, 2);
		world.setBlock(i + 29, j + 0, k + 23, sculk_block, 0, 2);
		world.setBlock(i + 26, j + 0, k + 24, sculk_block, 0, 2);
		world.setBlock(i + 27, j + 0, k + 24, sculk_block, 0, 2);
		world.setBlock(i + 28, j + 0, k + 24, sculk_block, 0, 2);
		world.setBlock(i + 29, j + 0, k + 24, sculk_block, 0, 2);
		world.setBlock(i + 27, j + 0, k + 25, sculk_block, 0, 2);
		world.setBlock(i + 28, j + 0, k + 25, sculk_block, 0, 2);
		world.setBlock(i + 29, j + 0, k + 25, sculk_block, 0, 2);
		world.setBlock(i + 27, j + 0, k + 26, sculk_block, 0, 2);
		world.setBlock(i + 28, j + 0, k + 26, sculk_block, 0, 2);
		world.setBlock(i + 29, j + 0, k + 26, sculk_block, 0, 2);
		world.setBlock(i + 27, j + 0, k + 27, sculk_block, 0, 2);
		world.setBlock(i + 28, j + 0, k + 27, sculk_block, 0, 2);
		world.setBlock(i + 29, j + 0, k + 27, sculk_block, 0, 2);
		world.setBlock(i + 27, j + 0, k + 28, sculk_block, 0, 2);
		world.setBlock(i + 28, j + 0, k + 28, sculk_block, 0, 2);
		world.setBlock(i + 27, j + 0, k + 29, sculk_block, 0, 2);
		world.setBlock(i + 28, j + 0, k + 29, sculk_block, 0, 2);
		world.setBlock(i + 5, j + 0, k + 30, NovaCraftBlocks.sculk_vein, 0, 2);
		world.setBlock(i + 6, j + 0, k + 30, NovaCraftBlocks.sculk_vein, 0, 2);
		world.setBlock(i + 21, j + 0, k + 30, NovaCraftBlocks.sculk_vein, 0, 2);
		world.setBlock(i + 6, j + 0, k + 31, NovaCraftBlocks.sculk_vein, 0, 2);
		world.setBlock(i + 21, j + 0, k + 31, NovaCraftBlocks.sculk_vein, 0, 2);
		world.setBlock(i + 8, j + 0, k + 36, NovaCraftBlocks.sculk_vein, 0, 2);
		world.setBlock(i + 8, j + 1, k + 12, NovaCraftBlocks.sculk_vein, 0, 2);
		world.setBlock(i + 9, j + 1, k + 12, NovaCraftBlocks.sculk_vein, 0, 2);
		world.setBlock(i + 23, j + 1, k + 12, sculk_block, 0, 2);
		world.setBlock(i + 23, j + 1, k + 13, sculk_block, 0, 2);
		world.setBlock(i + 24, j + 1, k + 13, sculk_block, 0, 2);
		world.setBlock(i + 18, j + 1, k + 14, sculk_tulip, 0, 2);
		world.setBlock(i + 19, j + 1, k + 14, sculk_tulip, 0, 2);
		world.setBlock(i + 20, j + 1, k + 14, sculk_tulip, 0, 2);
		world.setBlock(i + 23, j + 1, k + 14, sculk_block, 0, 2);
		world.setBlock(i + 24, j + 1, k + 14, sculk_block, 0, 2);
		world.setBlock(i + 25, j + 1, k + 14, sculk_block, 0, 2);
		world.setBlock(i + 17, j + 1, k + 15, sculk_tulip, 0, 2);
		world.setBlock(i + 18, j + 1, k + 15, sculk_tulip, 0, 2);
		world.setBlock(i + 19, j + 1, k + 15, sculk_tulip, 0, 2);
		world.setBlock(i + 20, j + 1, k + 15, sculk_tulip, 0, 2);
		world.setBlock(i + 21, j + 1, k + 15, sculk_tulip, 0, 2);
		world.setBlock(i + 23, j + 1, k + 15, sculk_block, 0, 2);
		world.setBlock(i + 24, j + 1, k + 15, sculk_block, 0, 2);
		world.setBlock(i + 25, j + 1, k + 15, sculk_block, 0, 2);
		world.setBlock(i + 26, j + 1, k + 15, sculk_block, 0, 2);
		world.setBlock(i + 17, j + 1, k + 16, sculk_tulip, 0, 2);
		world.setBlock(i + 18, j + 1, k + 16, sculk_tulip, 0, 2);
		world.setBlock(i + 19, j + 1, k + 16, sculk_tulip, 0, 2);
		world.setBlock(i + 20, j + 1, k + 16, sculk_tulip, 0, 2);
		world.setBlock(i + 21, j + 1, k + 16, sculk_block, 0, 2);
		world.setBlock(i + 22, j + 1, k + 16, sculk_block, 0, 2);
		world.setBlock(i + 23, j + 1, k + 16, sculk_block, 0, 2);
		world.setBlock(i + 24, j + 1, k + 16, sculk_block, 0, 2);
		world.setBlock(i + 25, j + 1, k + 16, sculk_block, 0, 2);
		world.setBlock(i + 26, j + 1, k + 16, sculk_block, 0, 2);
		world.setBlock(i + 17, j + 1, k + 17, sculk_tulip, 0, 2);
		world.setBlock(i + 18, j + 1, k + 17, sculk_block, 0, 2);
		world.setBlock(i + 19, j + 1, k + 17, sculk_tulip, 0, 2);
		world.setBlock(i + 20, j + 1, k + 17, sculk_block, 0, 2);
		world.setBlock(i + 21, j + 1, k + 17, sculk_block, 0, 2);
		world.setBlock(i + 22, j + 1, k + 17, sculk_block, 0, 2);
		world.setBlock(i + 23, j + 1, k + 17, sculk_block, 0, 2);
		world.setBlock(i + 24, j + 1, k + 17, sculk_block, 0, 2);
		world.setBlock(i + 25, j + 1, k + 17, sculk_block, 0, 2);
		world.setBlock(i + 26, j + 1, k + 17, sculk_block, 0, 2);
		world.setBlock(i + 18, j + 1, k + 18, sculk_block, 0, 2);
		world.setBlock(i + 19, j + 1, k + 18, sculk_block, 0, 2);
		world.setBlock(i + 20, j + 1, k + 18, sculk_block, 0, 2);
		world.setBlock(i + 21, j + 1, k + 18, sculk_block, 0, 2);
		world.setBlock(i + 22, j + 1, k + 18, sculk_block, 0, 2);
		world.setBlock(i + 23, j + 1, k + 18, sculk_block, 0, 2);
		world.setBlock(i + 24, j + 1, k + 18, sculk_block, 0, 2);
		world.setBlock(i + 25, j + 1, k + 18, sculk_block, 0, 2);
		world.setBlock(i + 18, j + 1, k + 19, sculk_block, 0, 2);
		world.setBlock(i + 19, j + 1, k + 19, sculk_block, 0, 2);
		world.setBlock(i + 20, j + 1, k + 19, sculk_block, 0, 2);
		world.setBlock(i + 21, j + 1, k + 19, sculk_block, 0, 2);
		world.setBlock(i + 22, j + 1, k + 19, sculk_block, 0, 2);
		world.setBlock(i + 23, j + 1, k + 19, sculk_block, 0, 2);
		world.setBlock(i + 24, j + 1, k + 19, sculk_block, 0, 2);
		world.setBlock(i + 25, j + 1, k + 19, sculk_block, 0, 2);
		world.setBlock(i + 17, j + 1, k + 20, sculk_block, 0, 2);
		world.setBlock(i + 18, j + 1, k + 20, sculk_block, 0, 2);
		world.setBlock(i + 19, j + 1, k + 20, sculk_block, 0, 2);
		world.setBlock(i + 20, j + 1, k + 20, sculk_block, 0, 2);
		world.setBlock(i + 21, j + 1, k + 20, sculk_block, 0, 2);
		world.setBlock(i + 22, j + 1, k + 20, sculk_block, 0, 2);
		world.setBlock(i + 23, j + 1, k + 20, sculk_block, 0, 2);
		world.setBlock(i + 24, j + 1, k + 20, sculk_block, 0, 2);
		world.setBlock(i + 25, j + 1, k + 20, sculk_block, 0, 2);
		world.setBlock(i + 29, j + 1, k + 20, NovaCraftBlocks.sculk_tentacle_2, 1, 2);
		world.setBlock(i + 18, j + 1, k + 21, sculk_block, 0, 2);
		world.setBlock(i + 19, j + 1, k + 21, sculk_block, 0, 2);
		world.setBlock(i + 20, j + 1, k + 21, sculk_block, 0, 2);
		world.setBlock(i + 21, j + 1, k + 21, sculk_block, 0, 2);
		world.setBlock(i + 22, j + 1, k + 21, sculk_block, 0, 2);
		world.setBlock(i + 23, j + 1, k + 21, sculk_block, 0, 2);
		world.setBlock(i + 24, j + 1, k + 21, sculk_block, 0, 2);
		world.setBlock(i + 25, j + 1, k + 21, sculk_block, 0, 2);
		world.setBlock(i + 28, j + 1, k + 21, sculk_tulip, 0, 2);
		world.setBlock(i + 21, j + 1, k + 22, NovaCraftBlocks.sculk_vein, 0, 2);
		world.setBlock(i + 22, j + 1, k + 22, sculk_block, 0, 2);
		world.setBlock(i + 23, j + 1, k + 22, sculk_block, 0, 2);
		world.setBlock(i + 24, j + 1, k + 22, sculk_block, 0, 2);
		world.setBlock(i + 25, j + 1, k + 22, sculk_block, 0, 2);
		world.setBlock(i + 22, j + 1, k + 23, sculk_block, 0, 2);
		world.setBlock(i + 23, j + 1, k + 23, sculk_block, 0, 2);
		world.setBlock(i + 24, j + 1, k + 23, sculk_block, 0, 2);
		world.setBlock(i + 25, j + 1, k + 23, sculk_block, 0, 2);
		world.setBlock(i + 28, j + 1, k + 23, NovaCraftBlocks.sculk_vein, 1, 2);
		world.setBlock(i + 22, j + 1, k + 24, sculk_block, 0, 2);
		world.setBlock(i + 23, j + 1, k + 24, sculk_block, 0, 2);
		world.setBlock(i + 24, j + 1, k + 24, sculk_block, 0, 2);
		world.setBlock(i + 25, j + 1, k + 24, sculk_block, 0, 2);
		world.setBlock(i + 22, j + 1, k + 25, sculk_block, 0, 2);
		world.setBlock(i + 23, j + 1, k + 25, sculk_block, 0, 2);
		world.setBlock(i + 24, j + 1, k + 25, sculk_block, 0, 2);
		world.setBlock(i + 25, j + 1, k + 25, sculk_block, 0, 2);
		world.setBlock(i + 26, j + 1, k + 25, sculk_block, 0, 2);
		world.setBlock(i + 28, j + 1, k + 25, NovaCraftBlocks.sculk_vein, 1, 2);
		world.setBlock(i + 22, j + 1, k + 26, sculk_block, 0, 2);
		world.setBlock(i + 23, j + 1, k + 26, sculk_block, 0, 2);
		world.setBlock(i + 24, j + 1, k + 26, sculk_block, 0, 2);
		world.setBlock(i + 25, j + 1, k + 26, sculk_block, 0, 2);
		world.setBlock(i + 26, j + 1, k + 26, sculk_block, 0, 2);
		world.setBlock(i + 23, j + 1, k + 27, sculk_block, 0, 2);
		world.setBlock(i + 24, j + 1, k + 27, sculk_block, 0, 2);
		world.setBlock(i + 25, j + 1, k + 27, sculk_block, 0, 2);
		world.setBlock(i + 26, j + 1, k + 27, sculk_block, 0, 2);
		world.setBlock(i + 23, j + 1, k + 28, sculk_block, 0, 2);
		world.setBlock(i + 24, j + 1, k + 28, sculk_block, 0, 2);
		world.setBlock(i + 25, j + 1, k + 28, sculk_block, 0, 2);
		world.setBlock(i + 26, j + 1, k + 28, sculk_block, 0, 2);
		world.setBlock(i + 23, j + 1, k + 29, sculk_block, 0, 2);
		world.setBlock(i + 24, j + 1, k + 29, sculk_block, 0, 2);
		world.setBlock(i + 25, j + 1, k + 29, sculk_block, 0, 2);
		world.setBlock(i + 26, j + 1, k + 29, sculk_block, 0, 2);
		world.setBlock(i + 5, j + 1, k + 30, NovaCraftBlocks.sculk_vein, 0, 2);
		world.setBlock(i + 6, j + 1, k + 30, NovaCraftBlocks.sculk_vein, 0, 2);
		world.setBlock(i + 23, j + 1, k + 30, sculk_block, 0, 2);
		world.setBlock(i + 24, j + 1, k + 30, sculk_block, 0, 2);
		world.setBlock(i + 25, j + 1, k + 30, sculk_block, 0, 2);
		world.setBlock(i + 26, j + 1, k + 30, sculk_block, 0, 2);
		world.setBlock(i + 27, j + 1, k + 30, sculk_block, 0, 2);
		world.setBlock(i + 6, j + 1, k + 31, NovaCraftBlocks.sculk_vein, 0, 2);
		world.setBlock(i + 23, j + 1, k + 31, sculk_block, 0, 2);
		world.setBlock(i + 24, j + 1, k + 31, sculk_block, 0, 2);
		world.setBlock(i + 25, j + 1, k + 31, sculk_block, 0, 2);
		world.setBlock(i + 26, j + 1, k + 31, sculk_block, 0, 2);
		world.setBlock(i + 24, j + 1, k + 32, sculk_block, 0, 2);
		world.setBlock(i + 25, j + 1, k + 32, sculk_block, 0, 2);
		world.setBlock(i + 7, j + 1, k + 35, NovaCraftBlocks.sculk_vein, 0, 2);
		world.setBlock(i + 7, j + 1, k + 36, NovaCraftBlocks.sculk_vein, 0, 2);
		world.setBlock(i + 8, j + 1, k + 36, NovaCraftBlocks.sculk_vein, 0, 2);
		world.setBlock(i + 15, j + 2, k + 3, NovaCraftBlocks.sculk_vein, 0, 2);
		world.setBlock(i + 20, j + 2, k + 10, sculk_block, 0, 2);
		world.setBlock(i + 21, j + 2, k + 10, sculk_block, 0, 2);
		world.setBlock(i + 22, j + 2, k + 11, sculk_block, 0, 2);
		world.setBlock(i + 20, j + 2, k + 12, sculk_block, 0, 2);
		world.setBlock(i + 21, j + 2, k + 12, sculk_block, 0, 2);
		world.setBlock(i + 22, j + 2, k + 12, sculk_block, 0, 2);
		world.setBlock(i + 18, j + 2, k + 13, sculk_tulip, 0, 2);
		world.setBlock(i + 19, j + 2, k + 13, sculk_block, 0, 2);
		world.setBlock(i + 20, j + 2, k + 13, sculk_block, 0, 2);
		world.setBlock(i + 21, j + 2, k + 13, sculk_block, 0, 2);
		world.setBlock(i + 22, j + 2, k + 13, sculk_block, 0, 2);
		world.setBlock(i + 17, j + 2, k + 14, sculk_block, 0, 2);
		world.setBlock(i + 18, j + 2, k + 14, sculk_block, 0, 2);
		world.setBlock(i + 19, j + 2, k + 14, sculk_block, 0, 2);
		world.setBlock(i + 20, j + 2, k + 14, sculk_block, 0, 2);
		world.setBlock(i + 21, j + 2, k + 14, sculk_block, 0, 2);
		world.setBlock(i + 22, j + 2, k + 14, sculk_block, 0, 2);
		world.setBlock(i + 16, j + 2, k + 15, sculk_tulip, 0, 2);
		world.setBlock(i + 17, j + 2, k + 15, sculk_block, 0, 2);
		world.setBlock(i + 18, j + 2, k + 15, sculk_block, 0, 2);
		world.setBlock(i + 19, j + 2, k + 15, sculk_block, 0, 2);
		world.setBlock(i + 20, j + 2, k + 15, sculk_block, 0, 2);
		world.setBlock(i + 21, j + 2, k + 15, sculk_block, 0, 2);
		world.setBlock(i + 22, j + 2, k + 15, sculk_block, 0, 2);
		world.setBlock(i + 24, j + 2, k + 15, NovaCraftBlocks.sculk_tentacle_2, 1, 2);
		world.setBlock(i + 16, j + 2, k + 16, sculk_block, 0, 2);
		world.setBlock(i + 17, j + 2, k + 16, sculk_block, 0, 2);
		world.setBlock(i + 18, j + 2, k + 16, sculk_block, 0, 2);
		world.setBlock(i + 19, j + 2, k + 16, sculk_block, 0, 2);
		world.setBlock(i + 20, j + 2, k + 16, sculk_block, 0, 2);
		world.setBlock(i + 21, j + 2, k + 16, sculk_block, 0, 2);
		world.setBlock(i + 16, j + 2, k + 17, sculk_tulip, 0, 2);
		world.setBlock(i + 17, j + 2, k + 17, sculk_block, 0, 2);
		world.setBlock(i + 18, j + 2, k + 17, sculk_block, 0, 2);
		world.setBlock(i + 19, j + 2, k + 17, sculk_block, 0, 2);
		world.setBlock(i + 20, j + 2, k + 17, sculk_block, 0, 2);
		world.setBlock(i + 21, j + 2, k + 17, sculk_block, 0, 2);
		world.setBlock(i + 17, j + 2, k + 18, sculk_block, 0, 2);
		world.setBlock(i + 18, j + 2, k + 18, sculk_block, 0, 2);
		world.setBlock(i + 19, j + 2, k + 18, sculk_block, 0, 2);
		world.setBlock(i + 20, j + 2, k + 18, sculk_block, 0, 2);
		world.setBlock(i + 21, j + 2, k + 18, sculk_block, 0, 2);
		world.setBlock(i + 25, j + 2, k + 18, NovaCraftBlocks.sculk_vein, 1, 2);
		world.setBlock(i + 9, j + 2, k + 19, NovaCraftBlocks.sculk_vein, 0, 2);
		world.setBlock(i + 17, j + 2, k + 19, sculk_block, 0, 2);
		world.setBlock(i + 18, j + 2, k + 19, sculk_block, 0, 2);
		world.setBlock(i + 19, j + 2, k + 19, sculk_block, 0, 2);
		world.setBlock(i + 20, j + 2, k + 19, sculk_block, 0, 2);
		world.setBlock(i + 21, j + 2, k + 19, sculk_block, 0, 2);
		world.setBlock(i + 10, j + 2, k + 20, NovaCraftBlocks.sculk_vein, 0, 2);
		world.setBlock(i + 16, j + 2, k + 20, sculk_block, 0, 2);
		world.setBlock(i + 17, j + 2, k + 20, sculk_block, 0, 2);
		world.setBlock(i + 18, j + 2, k + 20, sculk_block, 0, 2);
		world.setBlock(i + 19, j + 2, k + 20, sculk_block, 0, 2);
		world.setBlock(i + 20, j + 2, k + 20, sculk_block, 0, 2);
		world.setBlock(i + 21, j + 2, k + 20, sculk_block, 0, 2);
		world.setBlock(i + 16, j + 2, k + 21, sculk_block, 0, 2);
		world.setBlock(i + 17, j + 2, k + 21, sculk_block, 0, 2);
		world.setBlock(i + 18, j + 2, k + 21, sculk_block, 0, 2);
		world.setBlock(i + 19, j + 2, k + 21, sculk_block, 0, 2);
		world.setBlock(i + 20, j + 2, k + 21, sculk_block, 0, 2);
		world.setBlock(i + 21, j + 2, k + 21, sculk_block, 0, 2);
		world.setBlock(i + 19, j + 2, k + 22, sculk_block, 0, 2);
		world.setBlock(i + 20, j + 2, k + 22, sculk_block, 0, 2);
		world.setBlock(i + 21, j + 2, k + 22, sculk_block, 0, 2);
		world.setBlock(i + 19, j + 2, k + 23, sculk_block, 0, 2);
		world.setBlock(i + 20, j + 2, k + 23, sculk_block, 0, 2);
		world.setBlock(i + 21, j + 2, k + 23, sculk_block, 0, 2);
		world.setBlock(i + 24, j + 2, k + 23, NovaCraftBlocks.sculk_vein, 1, 2);
		world.setBlock(i + 19, j + 2, k + 24, sculk_block, 0, 2);
		world.setBlock(i + 20, j + 2, k + 24, sculk_block, 0, 2);
		world.setBlock(i + 21, j + 2, k + 24, sculk_block, 0, 2);
		world.setBlock(i + 19, j + 2, k + 25, sculk_block, 0, 2);
		world.setBlock(i + 20, j + 2, k + 25, sculk_block, 0, 2);
		world.setBlock(i + 21, j + 2, k + 25, sculk_block, 0, 2);
		world.setBlock(i + 25, j + 2, k + 25, sculk_tulip, 0, 2);
		world.setBlock(i + 19, j + 2, k + 26, sculk_block, 0, 2);
		world.setBlock(i + 20, j + 2, k + 26, sculk_block, 0, 2);
		world.setBlock(i + 21, j + 2, k + 26, sculk_block, 0, 2);
		world.setBlock(i + 19, j + 2, k + 27, sculk_block, 0, 2);
		world.setBlock(i + 20, j + 2, k + 27, sculk_block, 0, 2);
		world.setBlock(i + 21, j + 2, k + 27, sculk_block, 0, 2);
		world.setBlock(i + 22, j + 2, k + 27, sculk_block, 0, 2);
		world.setBlock(i + 25, j + 2, k + 27, NovaCraftBlocks.sculk_tentacle_2, 1, 2);
		world.setBlock(i + 19, j + 2, k + 28, sculk_block, 0, 2);
		world.setBlock(i + 20, j + 2, k + 28, sculk_block, 0, 2);
		world.setBlock(i + 21, j + 2, k + 28, sculk_block, 0, 2);
		world.setBlock(i + 22, j + 2, k + 28, sculk_block, 0, 2);
		world.setBlock(i + 19, j + 2, k + 29, sculk_block, 0, 2);
		world.setBlock(i + 20, j + 2, k + 29, sculk_block, 0, 2);
		world.setBlock(i + 21, j + 2, k + 29, sculk_block, 0, 2);
		world.setBlock(i + 22, j + 2, k + 29, sculk_block, 0, 2);
		world.setBlock(i + 20, j + 2, k + 30, sculk_block, 0, 2);
		world.setBlock(i + 21, j + 2, k + 30, sculk_block, 0, 2);
		world.setBlock(i + 22, j + 2, k + 30, sculk_block, 0, 2);
		world.setBlock(i + 25, j + 2, k + 30, sculk_tulip, 0, 2);
		world.setBlock(i + 20, j + 2, k + 31, sculk_block, 0, 2);
		world.setBlock(i + 21, j + 2, k + 31, sculk_block, 0, 2);
		world.setBlock(i + 22, j + 2, k + 31, sculk_block, 0, 2);
		world.setBlock(i + 20, j + 2, k + 32, sculk_block, 0, 2);
		world.setBlock(i + 21, j + 2, k + 32, sculk_block, 0, 2);
		world.setBlock(i + 22, j + 2, k + 32, sculk_block, 0, 2);
		world.setBlock(i + 23, j + 2, k + 32, sculk_block, 0, 2);
		world.setBlock(i + 20, j + 2, k + 33, sculk_block, 0, 2);
		world.setBlock(i + 21, j + 2, k + 33, sculk_block, 0, 2);
		world.setBlock(i + 22, j + 2, k + 33, sculk_block, 0, 2);
		world.setBlock(i + 23, j + 2, k + 33, sculk_block, 0, 2);
		world.setBlock(i + 7, j + 2, k + 35, NovaCraftBlocks.sculk_vein, 0, 2);
		world.setBlock(i + 14, j + 3, k + 2, NovaCraftBlocks.sculk_vein, 0, 2);
		world.setBlock(i + 15, j + 3, k + 2, NovaCraftBlocks.sculk_vein, 0, 2);
		world.setBlock(i + 14, j + 3, k + 3, NovaCraftBlocks.sculk_vein, 0, 2);
		world.setBlock(i + 15, j + 3, k + 3, NovaCraftBlocks.sculk_vein, 0, 2);
		world.setBlock(i + 19, j + 3, k + 8, sculk_block, 0, 2);
		world.setBlock(i + 19, j + 3, k + 9, sculk_block, 0, 2);
		world.setBlock(i + 20, j + 3, k + 9, sculk_block, 0, 2);
		world.setBlock(i + 19, j + 3, k + 10, sculk_block, 0, 2);
		world.setBlock(i + 20, j + 3, k + 10, sculk_block, 0, 2);
		world.setBlock(i + 21, j + 3, k + 10, sculk_block, 0, 2);
		world.setBlock(i + 17, j + 3, k + 11, sculk_block, 0, 2);
		world.setBlock(i + 18, j + 3, k + 11, sculk_block, 0, 2);
		world.setBlock(i + 19, j + 3, k + 11, sculk_block, 0, 2);
		world.setBlock(i + 20, j + 3, k + 11, sculk_block, 0, 2);
		world.setBlock(i + 21, j + 3, k + 11, sculk_block, 0, 2);
		world.setBlock(i + 17, j + 3, k + 12, sculk_block, 0, 2);
		world.setBlock(i + 18, j + 3, k + 12, sculk_block, 0, 2);
		world.setBlock(i + 19, j + 3, k + 12, sculk_block, 0, 2);
		world.setBlock(i + 20, j + 3, k + 12, sculk_block, 0, 2);
		world.setBlock(i + 16, j + 3, k + 13, sculk_block, 0, 2);
		world.setBlock(i + 17, j + 3, k + 13, sculk_block, 0, 2);
		world.setBlock(i + 18, j + 3, k + 13, sculk_block, 0, 2);
		world.setBlock(i + 16, j + 3, k + 14, sculk_block, 0, 2);
		world.setBlock(i + 17, j + 3, k + 14, NovaCraftBlocks.sculk_tentacle_2, 1, 2);
		world.setBlock(i + 15, j + 3, k + 15, sculk_tulip, 0, 2);
		world.setBlock(i + 16, j + 3, k + 15, sculk_block, 0, 2);
		world.setBlock(i + 21, j + 3, k + 15, NovaCraftBlocks.sculk_vein, 1, 2);
		world.setBlock(i + 15, j + 3, k + 16, sculk_tulip, 0, 2);
		world.setBlock(i + 16, j + 3, k + 16, sculk_block, 0, 2);
		world.setBlock(i + 18, j + 3, k + 16, NovaCraftBlocks.sculk_tentacle_2, 1, 2);
		world.setBlock(i + 15, j + 3, k + 17, sculk_tulip, 0, 2);
		world.setBlock(i + 16, j + 3, k + 17, sculk_block, 0, 2);
		world.setBlock(i + 16, j + 3, k + 18, sculk_block, 0, 2);
		world.setBlock(i + 19, j + 3, k + 18, sculk_tulip, 0, 2);
		world.setBlock(i + 9, j + 3, k + 19, NovaCraftBlocks.sculk_vein, 0, 2);
		world.setBlock(i + 16, j + 3, k + 19, sculk_block, 0, 2);
		world.setBlock(i + 17, j + 3, k + 19, sculk_block, 0, 2);
		world.setBlock(i + 10, j + 3, k + 20, NovaCraftBlocks.sculk_vein, 0, 2);
		world.setBlock(i + 16, j + 3, k + 20, sculk_block, 0, 2);
		world.setBlock(i + 17, j + 3, k + 20, sculk_block, 0, 2);
		world.setBlock(i + 16, j + 3, k + 21, sculk_block, 0, 2);
		world.setBlock(i + 17, j + 3, k + 21, sculk_block, 0, 2);
		world.setBlock(i + 18, j + 3, k + 21, sculk_block, 0, 2);
		world.setBlock(i + 16, j + 3, k + 22, sculk_block, 0, 2);
		world.setBlock(i + 17, j + 3, k + 22, sculk_block, 0, 2);
		world.setBlock(i + 18, j + 3, k + 22, sculk_block, 0, 2);
		world.setBlock(i + 20, j + 3, k + 22, NovaCraftBlocks.sculk_tentacle_2, 1, 2);
		world.setBlock(i + 16, j + 3, k + 23, sculk_block, 0, 2);
		world.setBlock(i + 17, j + 3, k + 23, sculk_block, 0, 2);
		world.setBlock(i + 18, j + 3, k + 23, sculk_block, 0, 2);
		world.setBlock(i + 20, j + 3, k + 23, sculk_tulip, 0, 2);
		world.setBlock(i + 16, j + 3, k + 24, sculk_block, 0, 2);
		world.setBlock(i + 17, j + 3, k + 24, sculk_block, 0, 2);
		world.setBlock(i + 18, j + 3, k + 24, sculk_block, 0, 2);
		world.setBlock(i + 16, j + 3, k + 25, sculk_block, 0, 2);
		world.setBlock(i + 17, j + 3, k + 25, sculk_block, 0, 2);
		world.setBlock(i + 18, j + 3, k + 25, sculk_block, 0, 2);
		world.setBlock(i + 16, j + 3, k + 26, sculk_block, 0, 2);
		world.setBlock(i + 17, j + 3, k + 26, sculk_block, 0, 2);
		world.setBlock(i + 18, j + 3, k + 26, sculk_block, 0, 2);
		world.setBlock(i + 16, j + 3, k + 27, sculk_block, 0, 2);
		world.setBlock(i + 17, j + 3, k + 27, sculk_block, 0, 2);
		world.setBlock(i + 18, j + 3, k + 27, sculk_block, 0, 2);
		world.setBlock(i + 21, j + 3, k + 27, NovaCraftBlocks.sculk_vein, 1, 2);
		world.setBlock(i + 16, j + 3, k + 28, sculk_block, 0, 2);
		world.setBlock(i + 17, j + 3, k + 28, sculk_block, 0, 2);
		world.setBlock(i + 18, j + 3, k + 28, sculk_block, 0, 2);
		world.setBlock(i + 19, j + 3, k + 28, sculk_tulip, 0, 2);
		world.setBlock(i + 16, j + 3, k + 29, sculk_block, 0, 2);
		world.setBlock(i + 17, j + 3, k + 29, sculk_block, 0, 2);
		world.setBlock(i + 18, j + 3, k + 29, sculk_block, 0, 2);
		world.setBlock(i + 21, j + 3, k + 29, NovaCraftBlocks.sculk_tentacle_2, 1, 2);
		world.setBlock(i + 17, j + 3, k + 30, sculk_block, 0, 2);
		world.setBlock(i + 18, j + 3, k + 30, sculk_block, 0, 2);
		world.setBlock(i + 19, j + 3, k + 30, sculk_block, 0, 2);
		world.setBlock(i + 17, j + 3, k + 31, sculk_block, 0, 2);
		world.setBlock(i + 18, j + 3, k + 31, sculk_block, 0, 2);
		world.setBlock(i + 19, j + 3, k + 31, sculk_block, 0, 2);
		world.setBlock(i + 17, j + 3, k + 32, sculk_block, 0, 2);
		world.setBlock(i + 18, j + 3, k + 32, sculk_block, 0, 2);
		world.setBlock(i + 19, j + 3, k + 32, sculk_block, 0, 2);
		world.setBlock(i + 17, j + 3, k + 33, sculk_block, 0, 2);
		world.setBlock(i + 18, j + 3, k + 33, sculk_block, 0, 2);
		world.setBlock(i + 19, j + 3, k + 33, sculk_block, 0, 2);
		world.setBlock(i + 18, j + 3, k + 34, sculk_block, 0, 2);
		world.setBlock(i + 19, j + 3, k + 34, sculk_block, 0, 2);
		world.setBlock(i + 20, j + 3, k + 34, sculk_block, 0, 2);
		world.setBlock(i + 18, j + 3, k + 35, sculk_block, 0, 2);
		world.setBlock(i + 14, j + 4, k + 2, NovaCraftBlocks.sculk_vein, 0, 2);
		world.setBlock(i + 15, j + 4, k + 8, sculk_block, 0, 2);
		world.setBlock(i + 16, j + 4, k + 8, sculk_block, 0, 2);
		world.setBlock(i + 18, j + 4, k + 8, sculk_block, 0, 2);
		world.setBlock(i + 15, j + 4, k + 9, sculk_block, 0, 2);
		world.setBlock(i + 16, j + 4, k + 9, sculk_block, 0, 2);
		world.setBlock(i + 17, j + 4, k + 9, sculk_block, 0, 2);
		world.setBlock(i + 18, j + 4, k + 9, sculk_block, 0, 2);
		world.setBlock(i + 15, j + 4, k + 10, sculk_block, 0, 2);
		world.setBlock(i + 16, j + 4, k + 10, sculk_block, 0, 2);
		world.setBlock(i + 17, j + 4, k + 10, sculk_block, 0, 2);
		world.setBlock(i + 18, j + 4, k + 10, sculk_block, 0, 2);
		world.setBlock(i + 19, j + 4, k + 10, NovaCraftBlocks.sculk_tentacle_2, 1, 2);
		world.setBlock(i + 14, j + 4, k + 11, sculk_block, 0, 2);
		world.setBlock(i + 15, j + 4, k + 11, sculk_block, 0, 2);
		world.setBlock(i + 16, j + 4, k + 11, sculk_block, 0, 2);
		world.setBlock(i + 17, j + 4, k + 11, sculk_block, 0, 2);
		world.setBlock(i + 18, j + 4, k + 11, sculk_block, 0, 2);
		world.setBlock(i + 14, j + 4, k + 12, sculk_block, 0, 2);
		world.setBlock(i + 15, j + 4, k + 12, sculk_block, 0, 2);
		world.setBlock(i + 16, j + 4, k + 12, sculk_block, 0, 2);
		world.setBlock(i + 17, j + 4, k + 12, sculk_block, 0, 2);
		world.setBlock(i + 14, j + 4, k + 13, sculk_block, 0, 2);
		world.setBlock(i + 15, j + 4, k + 13, sculk_block, 0, 2);
		world.setBlock(i + 14, j + 4, k + 14, sculk_block, 0, 2);
		world.setBlock(i + 15, j + 4, k + 14, sculk_block, 0, 2);
		world.setBlock(i + 13, j + 4, k + 15, sculk_block, 0, 2);
		world.setBlock(i + 14, j + 4, k + 15, sculk_block, 0, 2);
		world.setBlock(i + 15, j + 4, k + 15, sculk_block, 0, 2);
		world.setBlock(i + 13, j + 4, k + 16, sculk_block, 0, 2);
		world.setBlock(i + 14, j + 4, k + 16, sculk_block, 0, 2);
		world.setBlock(i + 15, j + 4, k + 16, sculk_block, 0, 2);
		world.setBlock(i + 13, j + 4, k + 17, sculk_block, 0, 2);
		world.setBlock(i + 14, j + 4, k + 17, sculk_block, 0, 2);
		world.setBlock(i + 15, j + 4, k + 17, sculk_block, 0, 2);
		world.setBlock(i + 13, j + 4, k + 18, sculk_block, 0, 2);
		world.setBlock(i + 14, j + 4, k + 18, sculk_block, 0, 2);
		world.setBlock(i + 15, j + 4, k + 18, sculk_block, 0, 2);
		world.setBlock(i + 13, j + 4, k + 19, sculk_block, 0, 2);
		world.setBlock(i + 14, j + 4, k + 19, sculk_block, 0, 2);
		world.setBlock(i + 15, j + 4, k + 19, sculk_block, 0, 2);
		world.setBlock(i + 13, j + 4, k + 20, sculk_block, 0, 2);
		world.setBlock(i + 14, j + 4, k + 20, sculk_block, 0, 2);
		world.setBlock(i + 15, j + 4, k + 20, sculk_block, 0, 2);
		world.setBlock(i + 13, j + 4, k + 21, sculk_block, 0, 2);
		world.setBlock(i + 14, j + 4, k + 21, sculk_block, 0, 2);
		world.setBlock(i + 15, j + 4, k + 21, sculk_block, 0, 2);
		world.setBlock(i + 13, j + 4, k + 22, sculk_block, 0, 2);
		world.setBlock(i + 14, j + 4, k + 22, sculk_block, 0, 2);
		world.setBlock(i + 15, j + 4, k + 22, sculk_block, 0, 2);
		world.setBlock(i + 16, j + 4, k + 22, sculk_tulip, 0, 2);
		world.setBlock(i + 13, j + 4, k + 23, sculk_block, 0, 2);
		world.setBlock(i + 14, j + 4, k + 23, sculk_block, 0, 2);
		world.setBlock(i + 15, j + 4, k + 23, sculk_block, 0, 2);
		world.setBlock(i + 13, j + 4, k + 24, sculk_block, 0, 2);
		world.setBlock(i + 14, j + 4, k + 24, sculk_block, 0, 2);
		world.setBlock(i + 15, j + 4, k + 24, sculk_block, 0, 2);
		world.setBlock(i + 13, j + 4, k + 25, sculk_block, 0, 2);
		world.setBlock(i + 14, j + 4, k + 25, sculk_block, 0, 2);
		world.setBlock(i + 15, j + 4, k + 25, sculk_block, 0, 2);
		world.setBlock(i + 13, j + 4, k + 26, sculk_block, 0, 2);
		world.setBlock(i + 14, j + 4, k + 26, sculk_block, 0, 2);
		world.setBlock(i + 15, j + 4, k + 26, sculk_block, 0, 2);
		world.setBlock(i + 14, j + 4, k + 27, sculk_block, 0, 2);
		world.setBlock(i + 15, j + 4, k + 27, sculk_block, 0, 2);
		world.setBlock(i + 14, j + 4, k + 28, sculk_block, 0, 2);
		world.setBlock(i + 15, j + 4, k + 28, sculk_block, 0, 2);
		world.setBlock(i + 12, j + 4, k + 29, sculk_block, 0, 2);
		world.setBlock(i + 14, j + 4, k + 29, sculk_block, 0, 2);
		world.setBlock(i + 15, j + 4, k + 29, sculk_block, 0, 2);
		world.setBlock(i + 14, j + 4, k + 30, sculk_block, 0, 2);
		world.setBlock(i + 15, j + 4, k + 30, sculk_block, 0, 2);
		world.setBlock(i + 16, j + 4, k + 30, sculk_block, 0, 2);
		world.setBlock(i + 14, j + 4, k + 31, sculk_block, 0, 2);
		world.setBlock(i + 15, j + 4, k + 31, sculk_block, 0, 2);
		world.setBlock(i + 16, j + 4, k + 31, sculk_block, 0, 2);
		world.setBlock(i + 18, j + 4, k + 31, NovaCraftBlocks.sculk_vein, 1, 2);
		world.setBlock(i + 14, j + 4, k + 32, sculk_block, 0, 2);
		world.setBlock(i + 15, j + 4, k + 32, sculk_block, 0, 2);
		world.setBlock(i + 16, j + 4, k + 32, sculk_block, 0, 2);
		world.setBlock(i + 15, j + 4, k + 33, sculk_block, 0, 2);
		world.setBlock(i + 16, j + 4, k + 33, sculk_block, 0, 2);
		world.setBlock(i + 15, j + 4, k + 34, sculk_block, 0, 2);
		world.setBlock(i + 16, j + 4, k + 34, sculk_block, 0, 2);
		world.setBlock(i + 17, j + 4, k + 34, sculk_block, 0, 2);
		world.setBlock(i + 19, j + 4, k + 34, NovaCraftBlocks.sculk_tentacle_2, 1, 2);
		world.setBlock(i + 16, j + 4, k + 35, sculk_block, 0, 2);
		world.setBlock(i + 17, j + 4, k + 35, sculk_block, 0, 2);
		world.setBlock(i + 16, j + 4, k + 36, sculk_block, 0, 2);
		world.setBlock(i + 14, j + 5, k + 4, NovaCraftBlocks.sculk_vein, 0, 2);
		world.setBlock(i + 13, j + 5, k + 7, sculk_block, 0, 2);
		world.setBlock(i + 14, j + 5, k + 7, sculk_block, 0, 2);
		world.setBlock(i + 13, j + 5, k + 8, sculk_block, 0, 2);
		world.setBlock(i + 14, j + 5, k + 8, sculk_block, 0, 2);
		world.setBlock(i + 12, j + 5, k + 9, sculk_block, 0, 2);
		world.setBlock(i + 13, j + 5, k + 9, sculk_block, 0, 2);
		world.setBlock(i + 14, j + 5, k + 9, sculk_block, 0, 2);
		world.setBlock(i + 18, j + 5, k + 9, NovaCraftBlocks.sculk_vein, 1, 2);
		world.setBlock(i + 12, j + 5, k + 10, sculk_block, 0, 2);
		world.setBlock(i + 13, j + 5, k + 10, sculk_block, 0, 2);
		world.setBlock(i + 14, j + 5, k + 10, sculk_block, 0, 2);
		world.setBlock(i + 12, j + 5, k + 11, sculk_block, 0, 2);
		world.setBlock(i + 13, j + 5, k + 11, sculk_block, 0, 2);
		world.setBlock(i + 14, j + 5, k + 11, sculk_block, 0, 2);
		world.setBlock(i + 17, j + 5, k + 11, sculk_tulip, 0, 2);
		world.setBlock(i + 12, j + 5, k + 12, sculk_block, 0, 2);
		world.setBlock(i + 13, j + 5, k + 12, sculk_block, 0, 2);
		world.setBlock(i + 12, j + 5, k + 13, sculk_block, 0, 2);
		world.setBlock(i + 13, j + 5, k + 13, sculk_block, 0, 2);
		world.setBlock(i + 11, j + 5, k + 14, sculk_block, 0, 2);
		world.setBlock(i + 12, j + 5, k + 14, sculk_block, 0, 2);
		world.setBlock(i + 13, j + 5, k + 14, sculk_block, 0, 2);
		world.setBlock(i + 11, j + 5, k + 15, sculk_block, 0, 2);
		world.setBlock(i + 12, j + 5, k + 15, sculk_block, 0, 2);
		world.setBlock(i + 11, j + 5, k + 16, sculk_block, 0, 2);
		world.setBlock(i + 12, j + 5, k + 16, sculk_block, 0, 2);
		world.setBlock(i + 11, j + 5, k + 17, sculk_block, 0, 2);
		world.setBlock(i + 12, j + 5, k + 17, sculk_block, 0, 2);
		world.setBlock(i + 11, j + 5, k + 18, sculk_block, 0, 2);
		world.setBlock(i + 12, j + 5, k + 18, sculk_block, 0, 2);
		world.setBlock(i + 11, j + 5, k + 19, sculk_block, 0, 2);
		world.setBlock(i + 12, j + 5, k + 19, sculk_block, 0, 2);
		world.setBlock(i + 11, j + 5, k + 20, sculk_block, 0, 2);
		world.setBlock(i + 12, j + 5, k + 20, sculk_block, 0, 2);
		world.setBlock(i + 11, j + 5, k + 21, sculk_block, 0, 2);
		world.setBlock(i + 12, j + 5, k + 21, sculk_block, 0, 2);
		world.setBlock(i + 11, j + 5, k + 22, sculk_block, 0, 2);
		world.setBlock(i + 12, j + 5, k + 22, sculk_block, 0, 2);
		world.setBlock(i + 11, j + 5, k + 23, sculk_block, 0, 2);
		world.setBlock(i + 12, j + 5, k + 23, sculk_block, 0, 2);
		world.setBlock(i + 15, j + 5, k + 23, NovaCraftBlocks.sculk_tentacle_2, 1, 2);
		world.setBlock(i + 11, j + 5, k + 24, sculk_block, 0, 2);
		world.setBlock(i + 12, j + 5, k + 24, sculk_block, 0, 2);
		world.setBlock(i + 11, j + 5, k + 25, sculk_block, 0, 2);
		world.setBlock(i + 12, j + 5, k + 25, sculk_block, 0, 2);
		world.setBlock(i + 11, j + 5, k + 26, sculk_block, 0, 2);
		world.setBlock(i + 12, j + 5, k + 26, sculk_block, 0, 2);
		world.setBlock(i + 11, j + 5, k + 27, sculk_block, 0, 2);
		world.setBlock(i + 12, j + 5, k + 27, sculk_block, 0, 2);
		world.setBlock(i + 13, j + 5, k + 27, sculk_block, 0, 2);
		world.setBlock(i + 11, j + 5, k + 28, sculk_block, 0, 2);
		world.setBlock(i + 12, j + 5, k + 28, sculk_block, 0, 2);
		world.setBlock(i + 13, j + 5, k + 28, sculk_block, 0, 2);
		world.setBlock(i + 12, j + 5, k + 29, sculk_block, 0, 2);
		world.setBlock(i + 13, j + 5, k + 29, sculk_block, 0, 2);
		world.setBlock(i + 12, j + 5, k + 30, sculk_block, 0, 2);
		world.setBlock(i + 13, j + 5, k + 30, sculk_block, 0, 2);
		world.setBlock(i + 12, j + 5, k + 31, sculk_block, 0, 2);
		world.setBlock(i + 13, j + 5, k + 31, sculk_block, 0, 2);
		world.setBlock(i + 14, j + 5, k + 31, NovaCraftBlocks.sculk_tentacle_2, 1, 2);
		world.setBlock(i + 12, j + 5, k + 32, sculk_block, 0, 2);
		world.setBlock(i + 13, j + 5, k + 32, sculk_block, 0, 2);
		world.setBlock(i + 15, j + 5, k + 32, NovaCraftBlocks.sculk_vein, 1, 2);
		world.setBlock(i + 12, j + 5, k + 33, sculk_block, 0, 2);
		world.setBlock(i + 13, j + 5, k + 33, sculk_block, 0, 2);
		world.setBlock(i + 14, j + 5, k + 33, sculk_block, 0, 2);
		world.setBlock(i + 13, j + 5, k + 34, sculk_block, 0, 2);
		world.setBlock(i + 14, j + 5, k + 34, sculk_block, 0, 2);
		world.setBlock(i + 17, j + 5, k + 34, NovaCraftBlocks.sculk_tentacle_2, 1, 2);
		world.setBlock(i + 13, j + 5, k + 35, sculk_block, 0, 2);
		world.setBlock(i + 14, j + 5, k + 35, sculk_block, 0, 2);
		world.setBlock(i + 15, j + 5, k + 35, sculk_block, 0, 2);
		world.setBlock(i + 13, j + 5, k + 36, sculk_block, 0, 2);
		world.setBlock(i + 14, j + 5, k + 36, sculk_block, 0, 2);
		world.setBlock(i + 15, j + 5, k + 36, sculk_block, 0, 2);
		world.setBlock(i + 14, j + 5, k + 37, sculk_block, 0, 2);
		world.setBlock(i + 15, j + 5, k + 37, sculk_block, 0, 2);
		world.setBlock(i + 11, j + 6, k + 6, sculk_block, 0, 2);
		world.setBlock(i + 12, j + 6, k + 6, sculk_block, 0, 2);
		world.setBlock(i + 11, j + 6, k + 7, sculk_block, 0, 2);
		world.setBlock(i + 12, j + 6, k + 7, sculk_block, 0, 2);
		world.setBlock(i + 11, j + 6, k + 8, sculk_block, 0, 2);
		world.setBlock(i + 12, j + 6, k + 8, sculk_block, 0, 2);
		world.setBlock(i + 13, j + 6, k + 8, sculk_tulip, 0, 2);
		world.setBlock(i + 10, j + 6, k + 9, sculk_block, 0, 2);
		world.setBlock(i + 11, j + 6, k + 9, sculk_block, 0, 2);
		world.setBlock(i + 10, j + 6, k + 10, sculk_block, 0, 2);
		world.setBlock(i + 11, j + 6, k + 10, sculk_block, 0, 2);
		world.setBlock(i + 10, j + 6, k + 11, sculk_block, 0, 2);
		world.setBlock(i + 11, j + 6, k + 11, sculk_block, 0, 2);
		world.setBlock(i + 13, j + 6, k + 11, NovaCraftBlocks.sculk_vein, 1, 2);
		world.setBlock(i + 10, j + 6, k + 12, sculk_block, 0, 2);
		world.setBlock(i + 11, j + 6, k + 12, sculk_block, 0, 2);
		world.setBlock(i + 10, j + 6, k + 13, sculk_block, 0, 2);
		world.setBlock(i + 11, j + 6, k + 13, sculk_block, 0, 2);
		world.setBlock(i + 9, j + 6, k + 14, sculk_block, 0, 2);
		world.setBlock(i + 10, j + 6, k + 14, sculk_block, 0, 2);
		world.setBlock(i + 13, j + 6, k + 14, NovaCraftBlocks.sculk_vein, 1, 2);
		world.setBlock(i + 9, j + 6, k + 15, sculk_block, 0, 2);
		world.setBlock(i + 10, j + 6, k + 15, sculk_block, 0, 2);
		world.setBlock(i + 9, j + 6, k + 16, sculk_block, 0, 2);
		world.setBlock(i + 10, j + 6, k + 16, sculk_block, 0, 2);
		world.setBlock(i + 10, j + 6, k + 17, sculk_block, 0, 2);
		world.setBlock(i + 11, j + 6, k + 17, sculk_tulip, 0, 2);
		world.setBlock(i + 10, j + 6, k + 18, sculk_block, 0, 2);
		world.setBlock(i + 10, j + 6, k + 19, sculk_block, 0, 2);
		world.setBlock(i + 10, j + 6, k + 20, sculk_block, 0, 2);
		world.setBlock(i + 4, j + 6, k + 21, NovaCraftBlocks.sculk_vein, 0, 2);
		world.setBlock(i + 10, j + 6, k + 21, sculk_block, 0, 2);
		world.setBlock(i + 3, j + 6, k + 22, NovaCraftBlocks.sculk_vein, 0, 2);
		world.setBlock(i + 10, j + 6, k + 22, sculk_block, 0, 2);
		world.setBlock(i + 10, j + 6, k + 23, sculk_block, 0, 2);
		world.setBlock(i + 11, j + 6, k + 23, NovaCraftBlocks.sculk_vein, 1, 2);
		world.setBlock(i + 10, j + 6, k + 24, sculk_block, 0, 2);
		world.setBlock(i + 12, j + 6, k + 24, sculk_tulip, 0, 2);
		world.setBlock(i + 10, j + 6, k + 25, sculk_block, 0, 2);
		world.setBlock(i + 9, j + 6, k + 26, sculk_block, 0, 2);
		world.setBlock(i + 10, j + 6, k + 26, sculk_block, 0, 2);
		world.setBlock(i + 9, j + 6, k + 27, sculk_block, 0, 2);
		world.setBlock(i + 10, j + 6, k + 27, sculk_block, 0, 2);
		world.setBlock(i + 9, j + 6, k + 28, sculk_block, 0, 2);
		world.setBlock(i + 10, j + 6, k + 28, sculk_block, 0, 2);
		world.setBlock(i + 11, j + 6, k + 28, NovaCraftBlocks.sculk_vein, 1, 2);
		world.setBlock(i + 9, j + 6, k + 29, sculk_block, 0, 2);
		world.setBlock(i + 10, j + 6, k + 29, sculk_block, 0, 2);
		world.setBlock(i + 11, j + 6, k + 29, sculk_block, 0, 2);
		world.setBlock(i + 10, j + 6, k + 30, sculk_block, 0, 2);
		world.setBlock(i + 11, j + 6, k + 30, sculk_block, 0, 2);
		world.setBlock(i + 13, j + 6, k + 30, sculk_tulip, 0, 2);
		world.setBlock(i + 10, j + 6, k + 31, sculk_block, 0, 2);
		world.setBlock(i + 11, j + 6, k + 31, sculk_block, 0, 2);
		world.setBlock(i + 10, j + 6, k + 32, sculk_block, 0, 2);
		world.setBlock(i + 11, j + 6, k + 32, sculk_block, 0, 2);
		world.setBlock(i + 12, j + 6, k + 32, NovaCraftBlocks.sculk_tentacle_2, 1, 2);
		world.setBlock(i + 10, j + 6, k + 33, sculk_block, 0, 2);
		world.setBlock(i + 11, j + 6, k + 33, sculk_block, 0, 2);
		world.setBlock(i + 11, j + 6, k + 34, sculk_block, 0, 2);
		world.setBlock(i + 12, j + 6, k + 34, sculk_block, 0, 2);
		world.setBlock(i + 11, j + 6, k + 35, sculk_block, 0, 2);
		world.setBlock(i + 12, j + 6, k + 35, sculk_block, 0, 2);
		world.setBlock(i + 13, j + 6, k + 35, NovaCraftBlocks.sculk_tentacle_2, 1, 2);
		world.setBlock(i + 11, j + 6, k + 36, sculk_block, 0, 2);
		world.setBlock(i + 12, j + 6, k + 36, sculk_block, 0, 2);
		world.setBlock(i + 15, j + 6, k + 36, NovaCraftBlocks.sculk_vein, 1, 2);
		world.setBlock(i + 12, j + 6, k + 37, sculk_block, 0, 2);
		world.setBlock(i + 13, j + 6, k + 37, sculk_block, 0, 2);
		world.setBlock(i + 12, j + 6, k + 38, sculk_block, 0, 2);
		world.setBlock(i + 13, j + 6, k + 38, sculk_block, 0, 2);
		world.setBlock(i + 10, j + 7, k + 5, sculk_block, 0, 2);
		world.setBlock(i + 11, j + 7, k + 5, sculk_block, 0, 2);
		world.setBlock(i + 10, j + 7, k + 6, sculk_block, 0, 2);
		world.setBlock(i + 9, j + 7, k + 7, sculk_block, 0, 2);
		world.setBlock(i + 10, j + 7, k + 7, sculk_block, 0, 2);
		world.setBlock(i + 11, j + 7, k + 7, NovaCraftBlocks.sculk_tentacle_2, 1, 2);
		world.setBlock(i + 9, j + 7, k + 8, sculk_block, 0, 2);
		world.setBlock(i + 10, j + 7, k + 8, sculk_block, 0, 2);
		world.setBlock(i + 9, j + 7, k + 9, sculk_block, 0, 2);
		world.setBlock(i + 10, j + 7, k + 9, sculk_block, 0, 2);
		world.setBlock(i + 9, j + 7, k + 10, sculk_block, 0, 2);
		world.setBlock(i + 8, j + 7, k + 11, sculk_block, 0, 2);
		world.setBlock(i + 9, j + 7, k + 11, sculk_block, 0, 2);
		world.setBlock(i + 8, j + 7, k + 12, sculk_block, 0, 2);
		world.setBlock(i + 9, j + 7, k + 12, sculk_block, 0, 2);
		world.setBlock(i + 8, j + 7, k + 13, sculk_block, 0, 2);
		world.setBlock(i + 9, j + 7, k + 13, sculk_block, 0, 2);
		world.setBlock(i + 8, j + 7, k + 14, sculk_block, 0, 2);
		world.setBlock(i + 8, j + 7, k + 15, sculk_block, 0, 2);
		world.setBlock(i + 8, j + 7, k + 16, sculk_block, 0, 2);
		world.setBlock(i + 9, j + 7, k + 17, sculk_block, 0, 2);
		world.setBlock(i + 7, j + 7, k + 18, sculk_block, 0, 2);
		world.setBlock(i + 8, j + 7, k + 18, sculk_block, 0, 2);
		world.setBlock(i + 9, j + 7, k + 18, sculk_block, 0, 2);
		world.setBlock(i + 7, j + 7, k + 19, sculk_block, 0, 2);
		world.setBlock(i + 9, j + 7, k + 19, sculk_block, 0, 2);
		world.setBlock(i + 8, j + 7, k + 20, sculk_block, 0, 2);
		world.setBlock(i + 9, j + 7, k + 20, sculk_block, 0, 2);
		world.setBlock(i + 9, j + 7, k + 21, sculk_block, 0, 2);
		world.setBlock(i + 9, j + 7, k + 22, sculk_block, 0, 2);
		world.setBlock(i + 9, j + 7, k + 23, sculk_block, 0, 2);
		world.setBlock(i + 9, j + 7, k + 24, sculk_block, 0, 2);
		world.setBlock(i + 9, j + 7, k + 25, sculk_block, 0, 2);
		world.setBlock(i + 8, j + 7, k + 26, sculk_block, 0, 2);
		world.setBlock(i + 8, j + 7, k + 27, sculk_block, 0, 2);
		world.setBlock(i + 8, j + 7, k + 28, sculk_block, 0, 2);
		world.setBlock(i + 8, j + 7, k + 29, sculk_block, 0, 2);
		world.setBlock(i + 9, j + 7, k + 29, sculk_block, 0, 2);
		world.setBlock(i + 8, j + 7, k + 30, sculk_block, 0, 2);
		world.setBlock(i + 9, j + 7, k + 30, sculk_block, 0, 2);
		world.setBlock(i + 8, j + 7, k + 31, sculk_block, 0, 2);
		world.setBlock(i + 9, j + 7, k + 31, sculk_block, 0, 2);
		world.setBlock(i + 9, j + 7, k + 32, sculk_block, 0, 2);
		world.setBlock(i + 9, j + 7, k + 33, sculk_block, 0, 2);
		world.setBlock(i + 9, j + 7, k + 34, sculk_block, 0, 2);
		world.setBlock(i + 10, j + 7, k + 34, sculk_block, 0, 2);
		world.setBlock(i + 9, j + 7, k + 35, sculk_block, 0, 2);
		world.setBlock(i + 10, j + 7, k + 35, sculk_block, 0, 2);
		world.setBlock(i + 10, j + 7, k + 36, sculk_block, 0, 2);
		world.setBlock(i + 10, j + 7, k + 37, sculk_block, 0, 2);
		world.setBlock(i + 11, j + 7, k + 37, sculk_block, 0, 2);
		world.setBlock(i + 10, j + 7, k + 38, sculk_block, 0, 2);
		world.setBlock(i + 11, j + 7, k + 38, sculk_block, 0, 2);
		world.setBlock(i + 11, j + 7, k + 39, sculk_block, 0, 2);
		world.setBlock(i + 10, j + 8, k + 4, sculk_block, 0, 2);
		world.setBlock(i + 9, j + 8, k + 5, sculk_block, 0, 2);
		world.setBlock(i + 8, j + 8, k + 6, sculk_block, 0, 2);
		world.setBlock(i + 9, j + 8, k + 6, sculk_block, 0, 2);
		world.setBlock(i + 8, j + 8, k + 7, sculk_block, 0, 2);
		world.setBlock(i + 8, j + 8, k + 8, sculk_block, 0, 2);
		world.setBlock(i + 7, j + 8, k + 9, sculk_block, 0, 2);
		world.setBlock(i + 8, j + 8, k + 9, sculk_block, 0, 2);
		world.setBlock(i + 7, j + 8, k + 10, sculk_block, 0, 2);
		world.setBlock(i + 8, j + 8, k + 10, sculk_block, 0, 2);
		world.setBlock(i + 7, j + 8, k + 11, sculk_block, 0, 2);
		world.setBlock(i + 9, j + 8, k + 11, sculk_tulip, 0, 2);
		world.setBlock(i + 7, j + 8, k + 12, sculk_block, 0, 2);
		world.setBlock(i + 7, j + 8, k + 13, sculk_block, 0, 2);
		world.setBlock(i + 7, j + 8, k + 14, sculk_block, 0, 2);
		world.setBlock(i + 6, j + 8, k + 15, sculk_block, 0, 2);
		world.setBlock(i + 7, j + 8, k + 15, sculk_block, 0, 2);
		world.setBlock(i + 6, j + 8, k + 16, sculk_block, 0, 2);
		world.setBlock(i + 7, j + 8, k + 16, sculk_block, 0, 2);
		world.setBlock(i + 4, j + 8, k + 17, sculk_block, 0, 2);
		world.setBlock(i + 5, j + 8, k + 17, sculk_block, 0, 2);
		world.setBlock(i + 6, j + 8, k + 17, sculk_block, 0, 2);
		world.setBlock(i + 7, j + 8, k + 17, sculk_block, 0, 2);
		world.setBlock(i + 8, j + 8, k + 17, sculk_block, 0, 2);
		world.setBlock(i + 2, j + 8, k + 18, sculk_block, 0, 2);
		world.setBlock(i + 3, j + 8, k + 18, sculk_block, 0, 2);
		world.setBlock(i + 4, j + 8, k + 18, sculk_block, 0, 2);
		world.setBlock(i + 5, j + 8, k + 18, sculk_block, 0, 2);
		world.setBlock(i + 6, j + 8, k + 18, sculk_block, 0, 2);
		world.setBlock(i + 7, j + 8, k + 18, sculk_block, 0, 2);
		world.setBlock(i + 8, j + 8, k + 18, sculk_block, 0, 2);
		world.setBlock(i + 3, j + 8, k + 19, sculk_block, 0, 2);
		world.setBlock(i + 4, j + 8, k + 19, sculk_block, 0, 2);
		world.setBlock(i + 5, j + 8, k + 19, sculk_block, 0, 2);
		world.setBlock(i + 6, j + 8, k + 19, sculk_block, 0, 2);
		world.setBlock(i + 7, j + 8, k + 19, sculk_block, 0, 2);
		world.setBlock(i + 8, j + 8, k + 19, sculk_block, 0, 2);
		world.setBlock(i + 3, j + 8, k + 20, sculk_block, 0, 2);
		world.setBlock(i + 4, j + 8, k + 20, sculk_block, 0, 2);
		world.setBlock(i + 5, j + 8, k + 20, sculk_block, 0, 2);
		world.setBlock(i + 6, j + 8, k + 20, sculk_block, 0, 2);
		world.setBlock(i + 7, j + 8, k + 20, sculk_block, 0, 2);
		world.setBlock(i + 8, j + 8, k + 20, sculk_block, 0, 2);
		world.setBlock(i + 3, j + 8, k + 21, sculk_block, 0, 2);
		world.setBlock(i + 4, j + 8, k + 21, sculk_block, 0, 2);
		world.setBlock(i + 5, j + 8, k + 21, sculk_block, 0, 2);
		world.setBlock(i + 6, j + 8, k + 21, sculk_block, 0, 2);
		world.setBlock(i + 7, j + 8, k + 21, sculk_block, 0, 2);
		world.setBlock(i + 8, j + 8, k + 21, sculk_block, 0, 2);
		world.setBlock(i + 3, j + 8, k + 22, sculk_block, 0, 2);
		world.setBlock(i + 4, j + 8, k + 22, sculk_block, 0, 2);
		world.setBlock(i + 5, j + 8, k + 22, sculk_block, 0, 2);
		world.setBlock(i + 6, j + 8, k + 22, sculk_block, 0, 2);
		world.setBlock(i + 7, j + 8, k + 22, sculk_block, 0, 2);
		world.setBlock(i + 8, j + 8, k + 22, sculk_block, 0, 2);
		world.setBlock(i + 3, j + 8, k + 23, sculk_block, 0, 2);
		world.setBlock(i + 4, j + 8, k + 23, sculk_block, 0, 2);
		world.setBlock(i + 5, j + 8, k + 23, sculk_block, 0, 2);
		world.setBlock(i + 6, j + 8, k + 23, sculk_block, 0, 2);
		world.setBlock(i + 7, j + 8, k + 23, sculk_block, 0, 2);
		world.setBlock(i + 8, j + 8, k + 23, sculk_block, 0, 2);
		world.setBlock(i + 4, j + 8, k + 24, sculk_block, 0, 2);
		world.setBlock(i + 5, j + 8, k + 24, sculk_block, 0, 2);
		world.setBlock(i + 6, j + 8, k + 24, sculk_block, 0, 2);
		world.setBlock(i + 7, j + 8, k + 24, sculk_block, 0, 2);
		world.setBlock(i + 8, j + 8, k + 24, sculk_block, 0, 2);
		world.setBlock(i + 3, j + 8, k + 25, sculk_block, 0, 2);
		world.setBlock(i + 4, j + 8, k + 25, sculk_block, 0, 2);
		world.setBlock(i + 5, j + 8, k + 25, sculk_block, 0, 2);
		world.setBlock(i + 6, j + 8, k + 25, sculk_block, 0, 2);
		world.setBlock(i + 7, j + 8, k + 25, sculk_block, 0, 2);
		world.setBlock(i + 8, j + 8, k + 25, sculk_block, 0, 2);
		world.setBlock(i + 4, j + 8, k + 26, sculk_block, 0, 2);
		world.setBlock(i + 5, j + 8, k + 26, sculk_block, 0, 2);
		world.setBlock(i + 6, j + 8, k + 26, sculk_block, 0, 2);
		world.setBlock(i + 7, j + 8, k + 26, sculk_block, 0, 2);
		world.setBlock(i + 6, j + 8, k + 27, sculk_block, 0, 2);
		world.setBlock(i + 7, j + 8, k + 27, sculk_block, 0, 2);
		world.setBlock(i + 7, j + 8, k + 28, sculk_block, 0, 2);
		world.setBlock(i + 8, j + 8, k + 28, NovaCraftBlocks.sculk_vein, 1, 2);
		world.setBlock(i + 7, j + 8, k + 29, sculk_block, 0, 2);
		world.setBlock(i + 7, j + 8, k + 30, sculk_block, 0, 2);
		world.setBlock(i + 7, j + 8, k + 31, sculk_block, 0, 2);
		world.setBlock(i + 7, j + 8, k + 32, sculk_block, 0, 2);
		world.setBlock(i + 8, j + 8, k + 32, sculk_block, 0, 2);
		world.setBlock(i + 7, j + 8, k + 33, sculk_block, 0, 2);
		world.setBlock(i + 8, j + 8, k + 33, sculk_block, 0, 2);
		world.setBlock(i + 8, j + 8, k + 34, sculk_block, 0, 2);
		world.setBlock(i + 8, j + 8, k + 35, sculk_block, 0, 2);
		world.setBlock(i + 10, j + 8, k + 35, NovaCraftBlocks.sculk_vein, 1, 2);
		world.setBlock(i + 8, j + 8, k + 36, sculk_block, 0, 2);
		world.setBlock(i + 9, j + 8, k + 36, sculk_block, 0, 2);
		world.setBlock(i + 10, j + 8, k + 36, sculk_tulip, 0, 2);
		world.setBlock(i + 9, j + 8, k + 37, sculk_block, 0, 2);
		world.setBlock(i + 9, j + 8, k + 38, sculk_block, 0, 2);
		world.setBlock(i + 10, j + 8, k + 39, sculk_block, 0, 2);
		world.setBlock(i + 8, j + 9, k + 2, sculk_block, 0, 2);
		world.setBlock(i + 8, j + 9, k + 3, sculk_block, 0, 2);
		world.setBlock(i + 9, j + 9, k + 3, sculk_block, 0, 2);
		world.setBlock(i + 8, j + 9, k + 4, sculk_block, 0, 2);
		world.setBlock(i + 9, j + 9, k + 4, sculk_block, 0, 2);
		world.setBlock(i + 8, j + 9, k + 5, sculk_block, 0, 2);
		world.setBlock(i + 7, j + 9, k + 6, sculk_block, 0, 2);
		world.setBlock(i + 7, j + 9, k + 7, sculk_block, 0, 2);
		world.setBlock(i + 7, j + 9, k + 8, sculk_block, 0, 2);
		world.setBlock(i + 6, j + 9, k + 9, sculk_block, 0, 2);
		world.setBlock(i + 6, j + 9, k + 10, sculk_block, 0, 2);
		world.setBlock(i + 6, j + 9, k + 11, sculk_block, 0, 2);
		world.setBlock(i + 6, j + 9, k + 12, sculk_block, 0, 2);
		world.setBlock(i + 6, j + 9, k + 13, sculk_block, 0, 2);
		world.setBlock(i + 5, j + 9, k + 14, sculk_block, 0, 2);
		world.setBlock(i + 6, j + 9, k + 14, sculk_block, 0, 2);
		world.setBlock(i + 5, j + 9, k + 15, sculk_block, 0, 2);
		world.setBlock(i + 7, j + 9, k + 15, NovaCraftBlocks.sculk_tentacle_2, 1, 2);
		world.setBlock(i + 5, j + 9, k + 16, sculk_block, 0, 2);
		world.setBlock(i + 3, j + 9, k + 17, sculk_block, 0, 2);
		world.setBlock(i + 4, j + 9, k + 17, sculk_block, 0, 2);
		world.setBlock(i + 5, j + 9, k + 17, sculk_block, 0, 2);
		world.setBlock(i + 8, j + 9, k + 17, NovaCraftBlocks.sculk_tentacle_2, 1, 2);
		world.setBlock(i + 2, j + 9, k + 18, sculk_block, 0, 2);
		world.setBlock(i + 3, j + 9, k + 18, sculk_block, 0, 2);
		world.setBlock(i + 4, j + 9, k + 18, sculk_block, 0, 2);
		world.setBlock(i + 5, j + 9, k + 18, sculk_block, 0, 2);
		world.setBlock(i + 2, j + 9, k + 19, sculk_block, 0, 2);
		world.setBlock(i + 3, j + 9, k + 19, sculk_block, 0, 2);
		world.setBlock(i + 4, j + 9, k + 19, sculk_block, 0, 2);
		world.setBlock(i + 5, j + 9, k + 19, sculk_block, 0, 2);
		world.setBlock(i + 7, j + 9, k + 19, NovaCraftBlocks.sculk_vein, 1, 2);
		world.setBlock(i + 3, j + 9, k + 20, sculk_block, 0, 2);
		world.setBlock(i + 4, j + 9, k + 20, sculk_block, 0, 2);
		world.setBlock(i + 5, j + 9, k + 20, sculk_block, 0, 2);
		world.setBlock(i + 3, j + 9, k + 21, sculk_block, 0, 2);
		world.setBlock(i + 4, j + 9, k + 21, sculk_block, 0, 2);
		world.setBlock(i + 5, j + 9, k + 21, sculk_block, 0, 2);
		world.setBlock(i + 8, j + 9, k + 21, NovaCraftBlocks.sculk_tentacle_2, 1, 2);
		world.setBlock(i + 3, j + 9, k + 22, sculk_block, 0, 2);
		world.setBlock(i + 4, j + 9, k + 22, sculk_block, 0, 2);
		world.setBlock(i + 5, j + 9, k + 22, sculk_block, 0, 2);
		world.setBlock(i + 3, j + 9, k + 23, sculk_block, 0, 2);
		world.setBlock(i + 4, j + 9, k + 23, sculk_block, 0, 2);
		world.setBlock(i + 5, j + 9, k + 23, sculk_block, 0, 2);
		world.setBlock(i + 3, j + 9, k + 24, sculk_block, 0, 2);
		world.setBlock(i + 4, j + 9, k + 24, sculk_block, 0, 2);
		world.setBlock(i + 5, j + 9, k + 24, sculk_block, 0, 2);
		world.setBlock(i + 3, j + 9, k + 25, sculk_block, 0, 2);
		world.setBlock(i + 4, j + 9, k + 25, sculk_block, 0, 2);
		world.setBlock(i + 5, j + 9, k + 25, sculk_block, 0, 2);
		world.setBlock(i + 6, j + 9, k + 25, NovaCraftBlocks.sculk_vein, 1, 2);
		world.setBlock(i + 4, j + 9, k + 26, sculk_block, 0, 2);
		world.setBlock(i + 5, j + 9, k + 26, sculk_block, 0, 2);
		world.setBlock(i + 5, j + 9, k + 27, sculk_block, 0, 2);
		world.setBlock(i + 5, j + 9, k + 28, sculk_block, 0, 2);
		world.setBlock(i + 6, j + 9, k + 28, sculk_block, 0, 2);
		world.setBlock(i + 6, j + 9, k + 29, sculk_block, 0, 2);
		world.setBlock(i + 6, j + 9, k + 30, sculk_block, 0, 2);
		world.setBlock(i + 6, j + 9, k + 31, sculk_block, 0, 2);
		world.setBlock(i + 6, j + 9, k + 32, sculk_block, 0, 2);
		world.setBlock(i + 6, j + 9, k + 33, sculk_block, 0, 2);
		world.setBlock(i + 7, j + 9, k + 34, sculk_block, 0, 2);
		world.setBlock(i + 7, j + 9, k + 35, sculk_block, 0, 2);
		world.setBlock(i + 8, j + 9, k + 35, NovaCraftBlocks.sculk_vein, 1, 2);
		world.setBlock(i + 7, j + 9, k + 36, sculk_block, 0, 2);
		world.setBlock(i + 7, j + 9, k + 37, sculk_block, 0, 2);
		world.setBlock(i + 8, j + 9, k + 37, sculk_block, 0, 2);
		world.setBlock(i + 9, j + 9, k + 37, NovaCraftBlocks.sculk_tentacle_2, 1, 2);
		world.setBlock(i + 8, j + 9, k + 38, sculk_block, 0, 2);
		world.setBlock(i + 8, j + 9, k + 39, sculk_block, 0, 2);
		world.setBlock(i + 9, j + 9, k + 39, sculk_block, 0, 2);
		world.setBlock(i + 8, j + 9, k + 40, sculk_block, 0, 2);
		world.setBlock(i + 9, j + 9, k + 40, sculk_block, 0, 2);
		world.setBlock(i + 7, j + 10, k + 2, sculk_block, 0, 2);
		world.setBlock(i + 7, j + 10, k + 3, sculk_block, 0, 2);
		world.setBlock(i + 7, j + 10, k + 4, sculk_block, 0, 2);
		world.setBlock(i + 6, j + 10, k + 5, sculk_block, 0, 2);
		world.setBlock(i + 7, j + 10, k + 5, sculk_block, 0, 2);
		world.setBlock(i + 6, j + 10, k + 6, sculk_block, 0, 2);
		world.setBlock(i + 6, j + 10, k + 7, sculk_block, 0, 2);
		world.setBlock(i + 6, j + 10, k + 8, sculk_block, 0, 2);
		world.setBlock(i + 7, j + 10, k + 8, NovaCraftBlocks.sculk_vein, 1, 2);
		world.setBlock(i + 5, j + 10, k + 9, sculk_block, 0, 2);
		world.setBlock(i + 5, j + 10, k + 10, sculk_block, 0, 2);
		world.setBlock(i + 5, j + 10, k + 11, sculk_block, 0, 2);
		world.setBlock(i + 5, j + 10, k + 12, sculk_block, 0, 2);
		world.setBlock(i + 5, j + 10, k + 13, sculk_block, 0, 2);
		world.setBlock(i + 4, j + 10, k + 14, sculk_block, 0, 2);
		world.setBlock(i + 4, j + 10, k + 15, sculk_block, 0, 2);
		world.setBlock(i + 4, j + 10, k + 16, sculk_block, 0, 2);
		world.setBlock(i + 4, j + 10, k + 17, sculk_block, 0, 2);
		world.setBlock(i + 3, j + 10, k + 18, sculk_block, 0, 2);
		world.setBlock(i + 4, j + 10, k + 18, sculk_block, 0, 2);
		world.setBlock(i + 3, j + 10, k + 19, sculk_block, 0, 2);
		world.setBlock(i + 4, j + 10, k + 19, sculk_block, 0, 2);
		world.setBlock(i + 4, j + 10, k + 20, sculk_block, 0, 2);
		world.setBlock(i + 4, j + 10, k + 21, sculk_block, 0, 2);
		world.setBlock(i + 4, j + 10, k + 22, sculk_block, 0, 2);
		world.setBlock(i + 5, j + 10, k + 22, NovaCraftBlocks.sculk_vein, 1, 2);
		world.setBlock(i + 4, j + 10, k + 23, sculk_block, 0, 2);
		world.setBlock(i + 4, j + 10, k + 24, sculk_block, 0, 2);
		world.setBlock(i + 4, j + 10, k + 25, sculk_block, 0, 2);
		world.setBlock(i + 4, j + 10, k + 26, sculk_block, 0, 2);
		world.setBlock(i + 4, j + 10, k + 27, sculk_block, 0, 2);
		world.setBlock(i + 4, j + 10, k + 28, sculk_block, 0, 2);
		world.setBlock(i + 5, j + 10, k + 29, sculk_block, 0, 2);
		world.setBlock(i + 5, j + 10, k + 30, sculk_block, 0, 2);
		world.setBlock(i + 6, j + 10, k + 30, NovaCraftBlocks.sculk_vein, 1, 2);
		world.setBlock(i + 5, j + 10, k + 31, sculk_block, 0, 2);
		world.setBlock(i + 5, j + 10, k + 32, sculk_block, 0, 2);
		world.setBlock(i + 5, j + 10, k + 33, sculk_block, 0, 2);
		world.setBlock(i + 6, j + 10, k + 34, sculk_block, 0, 2);
		world.setBlock(i + 6, j + 10, k + 35, sculk_block, 0, 2);
		world.setBlock(i + 6, j + 10, k + 36, sculk_block, 0, 2);
		world.setBlock(i + 6, j + 10, k + 37, sculk_block, 0, 2);
		world.setBlock(i + 7, j + 10, k + 38, sculk_block, 0, 2);
		world.setBlock(i + 7, j + 10, k + 39, sculk_block, 0, 2);
		world.setBlock(i + 8, j + 10, k + 40, sculk_block, 0, 2);
		world.setBlock(i + 7, j + 11, k + 2, sculk_block, 0, 2);
		world.setBlock(i + 6, j + 11, k + 3, sculk_block, 0, 2);
		world.setBlock(i + 6, j + 11, k + 4, sculk_block, 0, 2);
		world.setBlock(i + 5, j + 11, k + 5, sculk_block, 0, 2);
		world.setBlock(i + 5, j + 11, k + 6, sculk_block, 0, 2);
		world.setBlock(i + 5, j + 11, k + 7, sculk_block, 0, 2);
		world.setBlock(i + 5, j + 11, k + 8, sculk_block, 0, 2);
		world.setBlock(i + 4, j + 11, k + 9, sculk_block, 0, 2);
		world.setBlock(i + 5, j + 11, k + 9, NovaCraftBlocks.sculk_tentacle_2, 1, 2);
		world.setBlock(i + 4, j + 11, k + 10, sculk_block, 0, 2);
		world.setBlock(i + 4, j + 11, k + 11, sculk_block, 0, 2);
		world.setBlock(i + 4, j + 11, k + 12, sculk_block, 0, 2);
		world.setBlock(i + 5, j + 11, k + 12, NovaCraftBlocks.sculk_tentacle_2, 1, 2);
		world.setBlock(i + 4, j + 11, k + 13, sculk_block, 0, 2);
		world.setBlock(i + 4, j + 11, k + 14, sculk_block, 0, 2);
		world.setBlock(i + 3, j + 11, k + 15, sculk_block, 0, 2);
		world.setBlock(i + 4, j + 11, k + 15, NovaCraftBlocks.sculk_vein, 1, 2);
		world.setBlock(i + 3, j + 11, k + 16, sculk_block, 0, 2);
		world.setBlock(i + 4, j + 11, k + 16, sculk_tulip, 0, 2);
		world.setBlock(i + 3, j + 11, k + 17, sculk_block, 0, 2);
		world.setBlock(i + 3, j + 11, k + 18, sculk_block, 0, 2);
		world.setBlock(i + 3, j + 11, k + 19, sculk_block, 0, 2);
		world.setBlock(i + 3, j + 11, k + 20, sculk_block, 0, 2);
		world.setBlock(i + 3, j + 11, k + 21, sculk_block, 0, 2);
		world.setBlock(i + 3, j + 11, k + 22, sculk_block, 0, 2);
		world.setBlock(i + 3, j + 11, k + 23, sculk_block, 0, 2);
		world.setBlock(i + 3, j + 11, k + 24, sculk_block, 0, 2);
		world.setBlock(i + 4, j + 11, k + 24, sculk_tulip, 0, 2);
		world.setBlock(i + 3, j + 11, k + 25, sculk_block, 0, 2);
		world.setBlock(i + 3, j + 11, k + 26, sculk_block, 0, 2);
		world.setBlock(i + 3, j + 11, k + 27, sculk_block, 0, 2);
		world.setBlock(i + 4, j + 11, k + 28, sculk_block, 0, 2);
		world.setBlock(i + 4, j + 11, k + 29, sculk_block, 0, 2);
		world.setBlock(i + 5, j + 11, k + 29, sculk_tulip, 0, 2);
		world.setBlock(i + 4, j + 11, k + 30, sculk_block, 0, 2);
		world.setBlock(i + 4, j + 11, k + 31, sculk_block, 0, 2);
		world.setBlock(i + 4, j + 11, k + 32, sculk_block, 0, 2);
		world.setBlock(i + 4, j + 11, k + 33, sculk_block, 0, 2);
		world.setBlock(i + 5, j + 11, k + 34, sculk_block, 0, 2);
		world.setBlock(i + 6, j + 11, k + 34, NovaCraftBlocks.sculk_vein, 1, 2);
		world.setBlock(i + 5, j + 11, k + 35, sculk_block, 0, 2);
		world.setBlock(i + 5, j + 11, k + 36, sculk_block, 0, 2);
		world.setBlock(i + 5, j + 11, k + 37, sculk_block, 0, 2);
		world.setBlock(i + 6, j + 11, k + 38, sculk_block, 0, 2);
		world.setBlock(i + 6, j + 11, k + 39, sculk_block, 0, 2);
		world.setBlock(i + 7, j + 11, k + 39, sculk_tulip, 0, 2);
		world.setBlock(i + 7, j + 11, k + 40, sculk_block, 0, 2);
		world.setBlock(i + 7, j + 11, k + 41, sculk_block, 0, 2);
		world.setBlock(i + 6, j + 12, k + 2, sculk_block, 0, 2);
		world.setBlock(i + 5, j + 12, k + 3, sculk_block, 0, 2);
		world.setBlock(i + 5, j + 12, k + 4, sculk_block, 0, 2);
		world.setBlock(i + 5, j + 12, k + 5, sculk_block, 0, 2);
		world.setBlock(i + 4, j + 12, k + 6, sculk_block, 0, 2);
		world.setBlock(i + 4, j + 12, k + 7, sculk_block, 0, 2);
		world.setBlock(i + 4, j + 12, k + 8, sculk_block, 0, 2);
		world.setBlock(i + 4, j + 12, k + 9, sculk_block, 0, 2);
		world.setBlock(i + 3, j + 12, k + 10, sculk_block, 0, 2);
		world.setBlock(i + 4, j + 12, k + 10, sculk_tulip, 0, 2);
		world.setBlock(i + 3, j + 12, k + 11, sculk_block, 0, 2);
		world.setBlock(i + 3, j + 12, k + 12, sculk_block, 0, 2);
		world.setBlock(i + 3, j + 12, k + 13, sculk_block, 0, 2);
		world.setBlock(i + 3, j + 12, k + 14, sculk_block, 0, 2);
		world.setBlock(i + 3, j + 12, k + 15, sculk_block, 0, 2);
		world.setBlock(i + 3, j + 12, k + 16, sculk_block, 0, 2);
		world.setBlock(i + 3, j + 12, k + 17, sculk_block, 0, 2);
		world.setBlock(i + 2, j + 12, k + 18, sculk_block, 0, 2);
		world.setBlock(i + 2, j + 12, k + 19, sculk_block, 0, 2);
		world.setBlock(i + 2, j + 12, k + 20, sculk_block, 0, 2);
		world.setBlock(i + 2, j + 12, k + 21, sculk_block, 0, 2);
		world.setBlock(i + 2, j + 12, k + 22, sculk_block, 0, 2);
		world.setBlock(i + 3, j + 12, k + 22, NovaCraftBlocks.sculk_tentacle_2, 1, 2);
		world.setBlock(i + 2, j + 12, k + 23, sculk_block, 0, 2);
		world.setBlock(i + 2, j + 12, k + 24, sculk_block, 0, 2);
		world.setBlock(i + 3, j + 12, k + 25, sculk_block, 0, 2);
		world.setBlock(i + 3, j + 12, k + 26, sculk_block, 0, 2);
		world.setBlock(i + 3, j + 12, k + 27, sculk_block, 0, 2);
		world.setBlock(i + 3, j + 12, k + 28, sculk_block, 0, 2);
		world.setBlock(i + 3, j + 12, k + 29, sculk_block, 0, 2);
		world.setBlock(i + 3, j + 12, k + 30, sculk_block, 0, 2);
		world.setBlock(i + 4, j + 12, k + 30, NovaCraftBlocks.sculk_vein, 1, 2);
		world.setBlock(i + 3, j + 12, k + 31, sculk_block, 0, 2);
		world.setBlock(i + 3, j + 12, k + 32, sculk_block, 0, 2);
		world.setBlock(i + 4, j + 12, k + 33, sculk_block, 0, 2);
		world.setBlock(i + 4, j + 12, k + 34, sculk_block, 0, 2);
		world.setBlock(i + 4, j + 12, k + 35, sculk_block, 0, 2);
		world.setBlock(i + 4, j + 12, k + 36, sculk_block, 0, 2);
		world.setBlock(i + 5, j + 12, k + 36, sculk_tulip, 0, 2);
		world.setBlock(i + 5, j + 12, k + 37, sculk_block, 0, 2);
		world.setBlock(i + 5, j + 12, k + 38, sculk_block, 0, 2);
		world.setBlock(i + 5, j + 12, k + 39, sculk_block, 0, 2);
		world.setBlock(i + 6, j + 12, k + 39, NovaCraftBlocks.sculk_tentacle_2, 1, 2);
		world.setBlock(i + 6, j + 12, k + 40, sculk_block, 0, 2);
		world.setBlock(i + 6, j + 12, k + 41, sculk_block, 0, 2);
		world.setBlock(i + 5, j + 13, k + 2, sculk_block, 0, 2);
		world.setBlock(i + 5, j + 13, k + 3, sculk_block, 0, 2);
		world.setBlock(i + 5, j + 13, k + 4, sculk_block, 0, 2);
		world.setBlock(i + 4, j + 13, k + 5, sculk_block, 0, 2);
		world.setBlock(i + 4, j + 13, k + 6, sculk_block, 0, 2);
		world.setBlock(i + 4, j + 13, k + 7, sculk_block, 0, 2);
		world.setBlock(i + 3, j + 13, k + 8, sculk_block, 0, 2);
		world.setBlock(i + 3, j + 13, k + 9, sculk_block, 0, 2);
		world.setBlock(i + 4, j + 13, k + 9, NovaCraftBlocks.sculk_tentacle_2, 1, 2);
		world.setBlock(i + 3, j + 13, k + 10, sculk_block, 0, 2);
		world.setBlock(i + 3, j + 13, k + 11, sculk_block, 0, 2);
		world.setBlock(i + 3, j + 13, k + 12, sculk_block, 0, 2);
		world.setBlock(i + 2, j + 13, k + 13, sculk_block, 0, 2);
		world.setBlock(i + 3, j + 13, k + 13, NovaCraftBlocks.sculk_tentacle_2, 1, 2);
		world.setBlock(i + 2, j + 13, k + 14, sculk_block, 0, 2);
		world.setBlock(i + 2, j + 13, k + 15, sculk_block, 0, 2);
		world.setBlock(i + 2, j + 13, k + 16, sculk_block, 0, 2);
		world.setBlock(i + 3, j + 13, k + 16, sculk_tulip, 0, 2);
		world.setBlock(i + 2, j + 13, k + 17, sculk_block, 0, 2);
		world.setBlock(i + 3, j + 13, k + 17, NovaCraftBlocks.sculk_tentacle_2, 1, 2);
		world.setBlock(i + 2, j + 13, k + 18, sculk_block, 0, 2);
		world.setBlock(i + 2, j + 13, k + 19, sculk_block, 0, 2);
		world.setBlock(i + 2, j + 13, k + 20, sculk_block, 0, 2);
		world.setBlock(i + 2, j + 13, k + 21, sculk_block, 0, 2);
		world.setBlock(i + 2, j + 13, k + 22, sculk_block, 0, 2);
		world.setBlock(i + 2, j + 13, k + 23, sculk_block, 0, 2);
		world.setBlock(i + 2, j + 13, k + 24, sculk_block, 0, 2);
		world.setBlock(i + 2, j + 13, k + 25, sculk_block, 0, 2);
		world.setBlock(i + 3, j + 13, k + 25, NovaCraftBlocks.sculk_vein, 1, 2);
		world.setBlock(i + 2, j + 13, k + 26, sculk_block, 0, 2);
		world.setBlock(i + 2, j + 13, k + 27, sculk_block, 0, 2);
		world.setBlock(i + 2, j + 13, k + 28, sculk_block, 0, 2);
		world.setBlock(i + 2, j + 13, k + 29, sculk_block, 0, 2);
		world.setBlock(i + 3, j + 13, k + 29, NovaCraftBlocks.sculk_tentacle_2, 1, 2);
		world.setBlock(i + 3, j + 13, k + 30, sculk_block, 0, 2);
		world.setBlock(i + 3, j + 13, k + 31, sculk_block, 0, 2);
		world.setBlock(i + 3, j + 13, k + 32, sculk_block, 0, 2);
		world.setBlock(i + 3, j + 13, k + 33, sculk_block, 0, 2);
		world.setBlock(i + 3, j + 13, k + 34, sculk_block, 0, 2);
		world.setBlock(i + 4, j + 13, k + 34, NovaCraftBlocks.sculk_tentacle_2, 1, 2);
		world.setBlock(i + 4, j + 13, k + 35, sculk_block, 0, 2);
		world.setBlock(i + 4, j + 13, k + 36, sculk_block, 0, 2);
		world.setBlock(i + 4, j + 13, k + 37, sculk_block, 0, 2);
		world.setBlock(i + 5, j + 13, k + 37, NovaCraftBlocks.sculk_tentacle_2, 1, 2);
		world.setBlock(i + 5, j + 13, k + 38, sculk_block, 0, 2);
		world.setBlock(i + 5, j + 13, k + 39, sculk_block, 0, 2);
		world.setBlock(i + 5, j + 13, k + 40, sculk_block, 0, 2);
		world.setBlock(i + 6, j + 13, k + 41, sculk_block, 0, 2);
		world.setBlock(i + 5, j + 14, k + 2, sculk_block, 0, 2);
		world.setBlock(i + 5, j + 14, k + 3, sculk_block, 0, 2);
		world.setBlock(i + 4, j + 14, k + 4, sculk_block, 0, 2);
		world.setBlock(i + 4, j + 14, k + 5, sculk_block, 0, 2);
		world.setBlock(i + 4, j + 14, k + 6, sculk_block, 0, 2);
		world.setBlock(i + 3, j + 14, k + 7, sculk_block, 0, 2);
		world.setBlock(i + 3, j + 14, k + 8, sculk_block, 0, 2);
		world.setBlock(i + 3, j + 14, k + 9, sculk_block, 0, 2);
		world.setBlock(i + 3, j + 14, k + 10, sculk_block, 0, 2);
		world.setBlock(i + 3, j + 14, k + 11, sculk_block, 0, 2);
		world.setBlock(i + 2, j + 14, k + 12, sculk_block, 0, 2);
		world.setBlock(i + 2, j + 14, k + 13, sculk_block, 0, 2);
		world.setBlock(i + 2, j + 14, k + 14, sculk_block, 0, 2);
		world.setBlock(i + 2, j + 14, k + 15, sculk_block, 0, 2);
		world.setBlock(i + 2, j + 14, k + 16, sculk_block, 0, 2);
		world.setBlock(i + 2, j + 14, k + 17, sculk_block, 0, 2);
		world.setBlock(i + 2, j + 14, k + 18, sculk_block, 0, 2);
		world.setBlock(i + 2, j + 14, k + 19, sculk_block, 0, 2);
		world.setBlock(i + 1, j + 14, k + 20, sculk_block, 0, 2);
		world.setBlock(i + 2, j + 14, k + 20, sculk_block, 0, 2);
		world.setBlock(i + 1, j + 14, k + 21, sculk_block, 0, 2);
		world.setBlock(i + 2, j + 14, k + 21, sculk_block, 0, 2);
		world.setBlock(i + 1, j + 14, k + 22, sculk_block, 0, 2);
		world.setBlock(i + 2, j + 14, k + 22, sculk_block, 0, 2);
		world.setBlock(i + 2, j + 14, k + 23, sculk_block, 0, 2);
		world.setBlock(i + 2, j + 14, k + 24, sculk_block, 0, 2);
		world.setBlock(i + 2, j + 14, k + 25, sculk_block, 0, 2);
		world.setBlock(i + 2, j + 14, k + 26, sculk_block, 0, 2);
		world.setBlock(i + 2, j + 14, k + 27, sculk_block, 0, 2);
		world.setBlock(i + 2, j + 14, k + 28, sculk_block, 0, 2);
		world.setBlock(i + 2, j + 14, k + 29, sculk_block, 0, 2);
		world.setBlock(i + 2, j + 14, k + 30, sculk_block, 0, 2);
		world.setBlock(i + 3, j + 14, k + 31, sculk_block, 0, 2);
		world.setBlock(i + 3, j + 14, k + 32, sculk_block, 0, 2);
		world.setBlock(i + 3, j + 14, k + 33, sculk_block, 0, 2);
		world.setBlock(i + 3, j + 14, k + 34, sculk_block, 0, 2);
		world.setBlock(i + 3, j + 14, k + 35, sculk_block, 0, 2);
		world.setBlock(i + 4, j + 14, k + 36, sculk_block, 0, 2);
		world.setBlock(i + 4, j + 14, k + 37, sculk_block, 0, 2);
		world.setBlock(i + 4, j + 14, k + 38, sculk_block, 0, 2);
		world.setBlock(i + 5, j + 14, k + 39, sculk_block, 0, 2);
		world.setBlock(i + 5, j + 14, k + 40, sculk_block, 0, 2);
		world.setBlock(i + 5, j + 14, k + 41, sculk_block, 0, 2);
		world.setBlock(i + 6, j + 14, k + 41, NovaCraftBlocks.sculk_tentacle_2, 1, 2);
		world.setBlock(i + 5, j + 15, k + 2, sculk_block, 0, 2);
		world.setBlock(i + 5, j + 15, k + 3, sculk_block, 0, 2);
		world.setBlock(i + 4, j + 15, k + 4, sculk_block, 0, 2);
		world.setBlock(i + 4, j + 15, k + 5, sculk_block, 0, 2);
		world.setBlock(i + 4, j + 15, k + 6, sculk_block, 0, 2);
		world.setBlock(i + 3, j + 15, k + 7, sculk_block, 0, 2);
		world.setBlock(i + 3, j + 15, k + 8, sculk_block, 0, 2);
		world.setBlock(i + 3, j + 15, k + 9, sculk_block, 0, 2);
		world.setBlock(i + 3, j + 15, k + 10, sculk_block, 0, 2);
		world.setBlock(i + 2, j + 15, k + 11, sculk_block, 0, 2);
		world.setBlock(i + 2, j + 15, k + 12, sculk_block, 0, 2);
		world.setBlock(i + 2, j + 15, k + 13, sculk_block, 0, 2);
		world.setBlock(i + 2, j + 15, k + 14, sculk_block, 0, 2);
		world.setBlock(i + 2, j + 15, k + 15, sculk_block, 0, 2);
		world.setBlock(i + 2, j + 15, k + 16, sculk_block, 0, 2);
		world.setBlock(i + 2, j + 15, k + 17, sculk_block, 0, 2);
		world.setBlock(i + 2, j + 15, k + 18, sculk_block, 0, 2);
		world.setBlock(i + 2, j + 15, k + 19, sculk_block, 0, 2);
		world.setBlock(i + 1, j + 15, k + 20, sculk_block, 0, 2);
		world.setBlock(i + 2, j + 15, k + 20, sculk_block, 0, 2);
		world.setBlock(i + 1, j + 15, k + 21, sculk_block, 0, 2);
		world.setBlock(i + 1, j + 15, k + 22, sculk_block, 0, 2);
		world.setBlock(i + 2, j + 15, k + 22, sculk_block, 0, 2);
		world.setBlock(i + 2, j + 15, k + 23, sculk_block, 0, 2);
		world.setBlock(i + 2, j + 15, k + 24, sculk_block, 0, 2);
		world.setBlock(i + 2, j + 15, k + 25, sculk_block, 0, 2);
		world.setBlock(i + 2, j + 15, k + 26, sculk_block, 0, 2);
		world.setBlock(i + 2, j + 15, k + 27, sculk_block, 0, 2);
		world.setBlock(i + 2, j + 15, k + 28, sculk_block, 0, 2);
		world.setBlock(i + 2, j + 15, k + 29, sculk_block, 0, 2);
		world.setBlock(i + 2, j + 15, k + 30, sculk_block, 0, 2);
		world.setBlock(i + 2, j + 15, k + 31, sculk_block, 0, 2);
		world.setBlock(i + 3, j + 15, k + 32, sculk_block, 0, 2);
		world.setBlock(i + 3, j + 15, k + 33, sculk_block, 0, 2);
		world.setBlock(i + 3, j + 15, k + 34, sculk_block, 0, 2);
		world.setBlock(i + 3, j + 15, k + 35, sculk_block, 0, 2);
		world.setBlock(i + 4, j + 15, k + 36, sculk_block, 0, 2);
		world.setBlock(i + 4, j + 15, k + 37, sculk_block, 0, 2);
		world.setBlock(i + 4, j + 15, k + 38, sculk_block, 0, 2);
		world.setBlock(i + 5, j + 15, k + 39, sculk_block, 0, 2);
		world.setBlock(i + 5, j + 15, k + 40, sculk_block, 0, 2);
		world.setBlock(i + 5, j + 15, k + 41, sculk_block, 0, 2);
		world.setBlock(i + 6, j + 16, k + 1, sculk_block, 0, 2);
		world.setBlock(i + 5, j + 16, k + 2, sculk_block, 0, 2);
		world.setBlock(i + 5, j + 16, k + 3, sculk_block, 0, 2);
		world.setBlock(i + 4, j + 16, k + 4, sculk_block, 0, 2);
		world.setBlock(i + 4, j + 16, k + 5, sculk_block, 0, 2);
		world.setBlock(i + 4, j + 16, k + 6, sculk_block, 0, 2);
		world.setBlock(i + 3, j + 16, k + 7, sculk_block, 0, 2);
		world.setBlock(i + 3, j + 16, k + 8, sculk_block, 0, 2);
		world.setBlock(i + 3, j + 16, k + 9, sculk_block, 0, 2);
		world.setBlock(i + 3, j + 16, k + 10, sculk_block, 0, 2);
		world.setBlock(i + 3, j + 16, k + 11, sculk_block, 0, 2);
		world.setBlock(i + 2, j + 16, k + 12, sculk_block, 0, 2);
		world.setBlock(i + 2, j + 16, k + 13, sculk_block, 0, 2);
		world.setBlock(i + 2, j + 16, k + 14, sculk_block, 0, 2);
		world.setBlock(i + 2, j + 16, k + 15, sculk_block, 0, 2);
		world.setBlock(i + 2, j + 16, k + 16, sculk_block, 0, 2);
		world.setBlock(i + 2, j + 16, k + 17, sculk_block, 0, 2);
		world.setBlock(i + 2, j + 16, k + 18, sculk_block, 0, 2);
		world.setBlock(i + 2, j + 16, k + 19, sculk_block, 0, 2);
		world.setBlock(i + 1, j + 16, k + 20, sculk_block, 0, 2);
		world.setBlock(i + 2, j + 16, k + 20, sculk_block, 0, 2);
		world.setBlock(i + 1, j + 16, k + 21, sculk_block, 0, 2);
		world.setBlock(i + 2, j + 16, k + 21, sculk_block, 0, 2);
		world.setBlock(i + 1, j + 16, k + 22, sculk_block, 0, 2);
		world.setBlock(i + 2, j + 16, k + 22, sculk_block, 0, 2);
		world.setBlock(i + 2, j + 16, k + 23, sculk_block, 0, 2);
		world.setBlock(i + 2, j + 16, k + 24, sculk_block, 0, 2);
		world.setBlock(i + 2, j + 16, k + 25, sculk_block, 0, 2);
		world.setBlock(i + 2, j + 16, k + 26, sculk_block, 0, 2);
		world.setBlock(i + 2, j + 16, k + 27, sculk_block, 0, 2);
		world.setBlock(i + 2, j + 16, k + 28, sculk_block, 0, 2);
		world.setBlock(i + 2, j + 16, k + 29, sculk_block, 0, 2);
		world.setBlock(i + 2, j + 16, k + 30, sculk_block, 0, 2);
		world.setBlock(i + 3, j + 16, k + 31, sculk_block, 0, 2);
		world.setBlock(i + 3, j + 16, k + 32, sculk_block, 0, 2);
		world.setBlock(i + 3, j + 16, k + 33, sculk_block, 0, 2);
		world.setBlock(i + 3, j + 16, k + 34, sculk_block, 0, 2);
		world.setBlock(i + 3, j + 16, k + 35, sculk_block, 0, 2);
		world.setBlock(i + 4, j + 16, k + 36, sculk_block, 0, 2);
		world.setBlock(i + 4, j + 16, k + 37, sculk_block, 0, 2);
		world.setBlock(i + 4, j + 16, k + 38, sculk_block, 0, 2);
		world.setBlock(i + 5, j + 16, k + 39, sculk_block, 0, 2);
		world.setBlock(i + 5, j + 16, k + 40, sculk_block, 0, 2);
		world.setBlock(i + 5, j + 16, k + 41, sculk_block, 0, 2);
		world.setBlock(i + 5, j + 17, k + 1, sculk_block, 0, 2);
		world.setBlock(i + 6, j + 17, k + 1, sculk_block, 0, 2);
		world.setBlock(i + 5, j + 17, k + 2, sculk_block, 0, 2);
		world.setBlock(i + 5, j + 17, k + 3, sculk_block, 0, 2);
		world.setBlock(i + 5, j + 17, k + 4, sculk_block, 0, 2);
		world.setBlock(i + 4, j + 17, k + 5, sculk_block, 0, 2);
		world.setBlock(i + 4, j + 17, k + 6, sculk_block, 0, 2);
		world.setBlock(i + 4, j + 17, k + 7, sculk_block, 0, 2);
		world.setBlock(i + 3, j + 17, k + 8, sculk_block, 0, 2);
		world.setBlock(i + 3, j + 17, k + 9, sculk_block, 0, 2);
		world.setBlock(i + 3, j + 17, k + 10, sculk_block, 0, 2);
		world.setBlock(i + 3, j + 17, k + 11, sculk_block, 0, 2);
		world.setBlock(i + 3, j + 17, k + 12, sculk_block, 0, 2);
		world.setBlock(i + 2, j + 17, k + 13, sculk_block, 0, 2);
		world.setBlock(i + 2, j + 17, k + 14, sculk_block, 0, 2);
		world.setBlock(i + 3, j + 17, k + 14, NovaCraftBlocks.sculk_spike, 0, 2);
		world.setBlock(i + 2, j + 17, k + 15, sculk_block, 0, 2);
		world.setBlock(i + 2, j + 17, k + 16, sculk_block, 0, 2);
		world.setBlock(i + 2, j + 17, k + 17, sculk_block, 0, 2);
		world.setBlock(i + 2, j + 17, k + 18, sculk_block, 0, 2);
		world.setBlock(i + 2, j + 17, k + 19, sculk_block, 0, 2);
		world.setBlock(i + 2, j + 17, k + 20, sculk_block, 0, 2);
		world.setBlock(i + 2, j + 17, k + 21, sculk_block, 0, 2);
		world.setBlock(i + 2, j + 17, k + 22, sculk_block, 0, 2);
		world.setBlock(i + 1, j + 17, k + 23, sculk_block, 0, 2);
		world.setBlock(i + 2, j + 17, k + 23, sculk_block, 0, 2);
		world.setBlock(i + 2, j + 17, k + 24, sculk_block, 0, 2);
		world.setBlock(i + 2, j + 17, k + 25, sculk_block, 0, 2);
		world.setBlock(i + 2, j + 17, k + 26, sculk_block, 0, 2);
		world.setBlock(i + 2, j + 17, k + 27, sculk_block, 0, 2);
		world.setBlock(i + 2, j + 17, k + 28, sculk_block, 0, 2);
		world.setBlock(i + 2, j + 17, k + 29, sculk_block, 0, 2);
		world.setBlock(i + 3, j + 17, k + 30, sculk_block, 0, 2);
		world.setBlock(i + 3, j + 17, k + 31, sculk_block, 0, 2);
		world.setBlock(i + 3, j + 17, k + 32, sculk_block, 0, 2);
		world.setBlock(i + 3, j + 17, k + 33, sculk_block, 0, 2);
		world.setBlock(i + 3, j + 17, k + 34, sculk_block, 0, 2);
		world.setBlock(i + 4, j + 17, k + 35, sculk_block, 0, 2);
		world.setBlock(i + 4, j + 17, k + 36, sculk_block, 0, 2);
		world.setBlock(i + 4, j + 17, k + 37, sculk_block, 0, 2);
		world.setBlock(i + 5, j + 17, k + 38, sculk_block, 0, 2);
		world.setBlock(i + 5, j + 17, k + 39, sculk_block, 0, 2);
		world.setBlock(i + 5, j + 17, k + 40, sculk_block, 0, 2);
		world.setBlock(i + 6, j + 17, k + 41, sculk_block, 0, 2);
		world.setBlock(i + 5, j + 18, k + 1, sculk_block, 0, 2);
		world.setBlock(i + 6, j + 18, k + 1, sculk_block, 0, 2);
		world.setBlock(i + 5, j + 18, k + 2, sculk_block, 0, 2);
		world.setBlock(i + 5, j + 18, k + 3, sculk_block, 0, 2);
		world.setBlock(i + 5, j + 18, k + 4, sculk_block, 0, 2);
		world.setBlock(i + 6, j + 18, k + 4, NovaCraftBlocks.sculk_spike, 0, 2);
		world.setBlock(i + 5, j + 18, k + 5, sculk_block, 0, 2);
		world.setBlock(i + 4, j + 18, k + 6, sculk_block, 0, 2);
		world.setBlock(i + 4, j + 18, k + 7, sculk_block, 0, 2);
		world.setBlock(i + 4, j + 18, k + 8, sculk_block, 0, 2);
		world.setBlock(i + 5, j + 18, k + 8, NovaCraftBlocks.sculk_spike, 0, 2);
		world.setBlock(i + 4, j + 18, k + 9, sculk_block, 0, 2);
		world.setBlock(i + 3, j + 18, k + 10, sculk_block, 0, 2);
		world.setBlock(i + 4, j + 18, k + 10, NovaCraftBlocks.sculk_vein, 0, 2);
		world.setBlock(i + 3, j + 18, k + 11, sculk_block, 0, 2);
		world.setBlock(i + 3, j + 18, k + 12, sculk_block, 0, 2);
		world.setBlock(i + 3, j + 18, k + 13, sculk_block, 0, 2);
		world.setBlock(i + 3, j + 18, k + 14, sculk_block, 0, 2);
		world.setBlock(i + 3, j + 18, k + 15, sculk_block, 0, 2);
		world.setBlock(i + 3, j + 18, k + 16, sculk_block, 0, 2);
		world.setBlock(i + 3, j + 18, k + 17, sculk_block, 0, 2);
		world.setBlock(i + 1, j + 18, k + 18, sculk_block, 0, 2);
		world.setBlock(i + 2, j + 18, k + 18, sculk_block, 0, 2);
		world.setBlock(i + 3, j + 18, k + 18, NovaCraftBlocks.sculk_vein, 0, 2);
		world.setBlock(i + 2, j + 18, k + 19, sculk_block, 0, 2);
		world.setBlock(i + 2, j + 18, k + 20, sculk_block, 0, 2);
		world.setBlock(i + 3, j + 18, k + 20, NovaCraftBlocks.sculk_spike, 0, 2);
		world.setBlock(i + 2, j + 18, k + 21, sculk_block, 0, 2);
		world.setBlock(i + 2, j + 18, k + 22, sculk_block, 0, 2);
		world.setBlock(i + 2, j + 18, k + 23, sculk_block, 0, 2);
		world.setBlock(i + 2, j + 18, k + 24, sculk_block, 0, 2);
		world.setBlock(i + 3, j + 18, k + 24, NovaCraftBlocks.sculk_spike, 0, 2);
		world.setBlock(i + 3, j + 18, k + 25, sculk_block, 0, 2);
		world.setBlock(i + 3, j + 18, k + 26, sculk_block, 0, 2);
		world.setBlock(i + 3, j + 18, k + 27, sculk_block, 0, 2);
		world.setBlock(i + 3, j + 18, k + 28, sculk_block, 0, 2);
		world.setBlock(i + 3, j + 18, k + 29, sculk_block, 0, 2);
		world.setBlock(i + 3, j + 18, k + 30, sculk_block, 0, 2);
		world.setBlock(i + 3, j + 18, k + 31, sculk_block, 0, 2);
		world.setBlock(i + 3, j + 18, k + 32, sculk_block, 0, 2);
		world.setBlock(i + 4, j + 18, k + 33, sculk_block, 0, 2);
		world.setBlock(i + 4, j + 18, k + 34, sculk_block, 0, 2);
		world.setBlock(i + 4, j + 18, k + 35, sculk_block, 0, 2);
		world.setBlock(i + 4, j + 18, k + 36, sculk_block, 0, 2);
		world.setBlock(i + 5, j + 18, k + 37, sculk_block, 0, 2);
		world.setBlock(i + 5, j + 18, k + 38, sculk_block, 0, 2);
		world.setBlock(i + 5, j + 18, k + 39, sculk_block, 0, 2);
		world.setBlock(i + 6, j + 18, k + 40, sculk_block, 0, 2);
		world.setBlock(i + 6, j + 18, k + 41, sculk_block, 0, 2);
		world.setBlock(i + 7, j + 19, k + 1, sculk_block, 0, 2);
		world.setBlock(i + 6, j + 19, k + 2, sculk_block, 0, 2);
		world.setBlock(i + 7, j + 19, k + 2, sculk_block, 0, 2);
		world.setBlock(i + 6, j + 19, k + 3, sculk_block, 0, 2);
		world.setBlock(i + 6, j + 19, k + 4, sculk_block, 0, 2);
		world.setBlock(i + 5, j + 19, k + 5, sculk_block, 0, 2);
		world.setBlock(i + 5, j + 19, k + 6, sculk_block, 0, 2);
		world.setBlock(i + 5, j + 19, k + 7, sculk_block, 0, 2);
		world.setBlock(i + 5, j + 19, k + 8, sculk_block, 0, 2);
		world.setBlock(i + 4, j + 19, k + 9, sculk_block, 0, 2);
		world.setBlock(i + 3, j + 19, k + 10, sculk_block, 0, 2);
		world.setBlock(i + 4, j + 19, k + 10, sculk_block, 0, 2);
		world.setBlock(i + 4, j + 19, k + 11, sculk_block, 0, 2);
		world.setBlock(i + 4, j + 19, k + 12, sculk_block, 0, 2);
		world.setBlock(i + 4, j + 19, k + 13, sculk_block, 0, 2);
		world.setBlock(i + 4, j + 19, k + 14, sculk_block, 0, 2);
		world.setBlock(i + 3, j + 19, k + 15, sculk_block, 0, 2);
		world.setBlock(i + 3, j + 19, k + 16, sculk_block, 0, 2);
		world.setBlock(i + 3, j + 19, k + 17, sculk_block, 0, 2);
		world.setBlock(i + 4, j + 19, k + 17, NovaCraftBlocks.sculk_vein, 0, 2);
		world.setBlock(i + 3, j + 19, k + 18, sculk_block, 0, 2);
		world.setBlock(i + 3, j + 19, k + 19, sculk_block, 0, 2);
		world.setBlock(i + 3, j + 19, k + 20, sculk_block, 0, 2);
		world.setBlock(i + 3, j + 19, k + 21, sculk_block, 0, 2);
		world.setBlock(i + 3, j + 19, k + 22, sculk_block, 0, 2);
		world.setBlock(i + 3, j + 19, k + 23, sculk_block, 0, 2);
		world.setBlock(i + 3, j + 19, k + 24, sculk_block, 0, 2);
		world.setBlock(i + 3, j + 19, k + 25, sculk_block, 0, 2);
		world.setBlock(i + 3, j + 19, k + 26, sculk_block, 0, 2);
		world.setBlock(i + 3, j + 19, k + 27, sculk_block, 0, 2);
		world.setBlock(i + 4, j + 19, k + 28, sculk_block, 0, 2);
		world.setBlock(i + 4, j + 19, k + 29, sculk_block, 0, 2);
		world.setBlock(i + 4, j + 19, k + 30, sculk_block, 0, 2);
		world.setBlock(i + 4, j + 19, k + 31, sculk_block, 0, 2);
		world.setBlock(i + 4, j + 19, k + 32, sculk_block, 0, 2);
		world.setBlock(i + 4, j + 19, k + 33, sculk_block, 0, 2);
		world.setBlock(i + 5, j + 19, k + 33, NovaCraftBlocks.sculk_tentacle_2, 0, 2);
		world.setBlock(i + 5, j + 19, k + 34, sculk_block, 0, 2);
		world.setBlock(i + 5, j + 19, k + 35, sculk_block, 0, 2);
		world.setBlock(i + 5, j + 19, k + 36, sculk_block, 0, 2);
		world.setBlock(i + 5, j + 19, k + 37, sculk_block, 0, 2);
		world.setBlock(i + 6, j + 19, k + 38, sculk_block, 0, 2);
		world.setBlock(i + 6, j + 19, k + 39, sculk_block, 0, 2);
		world.setBlock(i + 7, j + 19, k + 40, sculk_block, 0, 2);
		world.setBlock(i + 7, j + 19, k + 41, sculk_block, 0, 2);
		world.setBlock(i + 7, j + 20, k + 2, sculk_block, 0, 2);
		world.setBlock(i + 7, j + 20, k + 3, sculk_block, 0, 2);
		world.setBlock(i + 7, j + 20, k + 4, sculk_block, 0, 2);
		world.setBlock(i + 6, j + 20, k + 5, sculk_block, 0, 2);
		world.setBlock(i + 6, j + 20, k + 6, sculk_block, 0, 2);
		world.setBlock(i + 6, j + 20, k + 7, sculk_block, 0, 2);
		world.setBlock(i + 6, j + 20, k + 8, sculk_block, 0, 2);
		world.setBlock(i + 7, j + 20, k + 8, NovaCraftBlocks.sculk_tentacle_2, 0, 2);
		world.setBlock(i + 5, j + 20, k + 9, sculk_block, 0, 2);
		world.setBlock(i + 6, j + 20, k + 9, NovaCraftBlocks.sculk_vein, 0, 2);
		world.setBlock(i + 5, j + 20, k + 10, sculk_block, 0, 2);
		world.setBlock(i + 5, j + 20, k + 11, sculk_block, 0, 2);
		world.setBlock(i + 5, j + 20, k + 12, sculk_block, 0, 2);
		world.setBlock(i + 5, j + 20, k + 13, sculk_block, 0, 2);
		world.setBlock(i + 4, j + 20, k + 14, sculk_block, 0, 2);
		world.setBlock(i + 5, j + 20, k + 14, sculk_block, 0, 2);
		world.setBlock(i + 4, j + 20, k + 15, sculk_block, 0, 2);
		world.setBlock(i + 4, j + 20, k + 16, sculk_block, 0, 2);
		world.setBlock(i + 4, j + 20, k + 17, sculk_block, 0, 2);
		world.setBlock(i + 4, j + 20, k + 18, sculk_block, 0, 2);
		world.setBlock(i + 4, j + 20, k + 19, sculk_block, 0, 2);
		world.setBlock(i + 4, j + 20, k + 20, sculk_block, 0, 2);
		world.setBlock(i + 5, j + 20, k + 20, NovaCraftBlocks.sculk_tentacle_2, 0, 2);
		world.setBlock(i + 4, j + 20, k + 21, sculk_block, 0, 2);
		world.setBlock(i + 4, j + 20, k + 22, sculk_block, 0, 2);
		world.setBlock(i + 5, j + 20, k + 22, NovaCraftBlocks.sculk_spike, 0, 2);
		world.setBlock(i + 4, j + 20, k + 23, sculk_block, 0, 2);
		world.setBlock(i + 4, j + 20, k + 24, sculk_block, 0, 2);
		world.setBlock(i + 4, j + 20, k + 25, sculk_block, 0, 2);
		world.setBlock(i + 4, j + 20, k + 26, sculk_block, 0, 2);
		world.setBlock(i + 5, j + 20, k + 26, NovaCraftBlocks.sculk_tentacle_2, 0, 2);
		world.setBlock(i + 4, j + 20, k + 27, sculk_block, 0, 2);
		world.setBlock(i + 4, j + 20, k + 28, sculk_block, 0, 2);
		world.setBlock(i + 5, j + 20, k + 29, sculk_block, 0, 2);
		world.setBlock(i + 5, j + 20, k + 30, sculk_block, 0, 2);
		world.setBlock(i + 5, j + 20, k + 31, sculk_block, 0, 2);
		world.setBlock(i + 5, j + 20, k + 32, sculk_block, 0, 2);
		world.setBlock(i + 5, j + 20, k + 33, sculk_block, 0, 2);
		world.setBlock(i + 6, j + 20, k + 34, sculk_block, 0, 2);
		world.setBlock(i + 6, j + 20, k + 35, sculk_block, 0, 2);
		world.setBlock(i + 7, j + 20, k + 35, NovaCraftBlocks.sculk_tentacle_2, 0, 2);
		world.setBlock(i + 6, j + 20, k + 36, sculk_block, 0, 2);
		world.setBlock(i + 6, j + 20, k + 37, sculk_block, 0, 2);
		world.setBlock(i + 7, j + 20, k + 38, sculk_block, 0, 2);
		world.setBlock(i + 7, j + 20, k + 39, sculk_block, 0, 2);
		world.setBlock(i + 8, j + 20, k + 39, NovaCraftBlocks.sculk_vein, 0, 2);
		world.setBlock(i + 7, j + 20, k + 40, sculk_block, 0, 2);
		world.setBlock(i + 8, j + 20, k + 40, sculk_block, 0, 2);
		world.setBlock(i + 8, j + 20, k + 41, sculk_block, 0, 2);
		world.setBlock(i + 8, j + 21, k + 2, sculk_block, 0, 2);
		world.setBlock(i + 9, j + 21, k + 2, sculk_block, 0, 2);
		world.setBlock(i + 8, j + 21, k + 3, sculk_block, 0, 2);
		world.setBlock(i + 8, j + 21, k + 4, sculk_block, 0, 2);
		world.setBlock(i + 7, j + 21, k + 5, sculk_block, 0, 2);
		world.setBlock(i + 8, j + 21, k + 5, sculk_block, 0, 2);
		world.setBlock(i + 7, j + 21, k + 6, sculk_block, 0, 2);
		world.setBlock(i + 8, j + 21, k + 6, NovaCraftBlocks.sculk_vein, 0, 2);
		world.setBlock(i + 7, j + 21, k + 7, sculk_block, 0, 2);
		world.setBlock(i + 7, j + 21, k + 8, sculk_block, 0, 2);
		world.setBlock(i + 6, j + 21, k + 9, sculk_block, 0, 2);
		world.setBlock(i + 6, j + 21, k + 10, sculk_block, 0, 2);
		world.setBlock(i + 6, j + 21, k + 11, sculk_block, 0, 2);
		world.setBlock(i + 6, j + 21, k + 12, sculk_block, 0, 2);
		world.setBlock(i + 6, j + 21, k + 13, sculk_block, 0, 2);
		world.setBlock(i + 7, j + 21, k + 13, NovaCraftBlocks.sculk_spike, 0, 2);
		world.setBlock(i + 5, j + 21, k + 14, sculk_block, 0, 2);
		world.setBlock(i + 6, j + 21, k + 14, sculk_block, 0, 2);
		world.setBlock(i + 5, j + 21, k + 15, sculk_block, 0, 2);
		world.setBlock(i + 6, j + 21, k + 15, NovaCraftBlocks.sculk_tentacle_2, 0, 2);
		world.setBlock(i + 5, j + 21, k + 16, sculk_block, 0, 2);
		world.setBlock(i + 5, j + 21, k + 17, sculk_block, 0, 2);
		world.setBlock(i + 5, j + 21, k + 18, sculk_block, 0, 2);
		world.setBlock(i + 5, j + 21, k + 19, sculk_block, 0, 2);
		world.setBlock(i + 5, j + 21, k + 20, sculk_block, 0, 2);
		world.setBlock(i + 6, j + 21, k + 20, NovaCraftBlocks.sculk_vein, 0, 2);
		world.setBlock(i + 5, j + 21, k + 21, sculk_block, 0, 2);
		world.setBlock(i + 5, j + 21, k + 22, sculk_block, 0, 2);
		world.setBlock(i + 5, j + 21, k + 23, sculk_block, 0, 2);
		world.setBlock(i + 5, j + 21, k + 24, sculk_block, 0, 2);
		world.setBlock(i + 5, j + 21, k + 25, sculk_block, 0, 2);
		world.setBlock(i + 5, j + 21, k + 26, sculk_block, 0, 2);
		world.setBlock(i + 7, j + 21, k + 26, NovaCraftBlocks.sculk_spike, 0, 2);
		world.setBlock(i + 5, j + 21, k + 27, sculk_block, 0, 2);
		world.setBlock(i + 5, j + 21, k + 28, sculk_block, 0, 2);
		world.setBlock(i + 6, j + 21, k + 28, sculk_block, 0, 2);
		world.setBlock(i + 6, j + 21, k + 29, sculk_block, 0, 2);
		world.setBlock(i + 6, j + 21, k + 30, sculk_block, 0, 2);
		world.setBlock(i + 7, j + 21, k + 30, NovaCraftBlocks.sculk_vein, 0, 2);
		world.setBlock(i + 6, j + 21, k + 31, sculk_block, 0, 2);
		world.setBlock(i + 6, j + 21, k + 32, sculk_block, 0, 2);
		world.setBlock(i + 6, j + 21, k + 33, sculk_block, 0, 2);
		world.setBlock(i + 7, j + 21, k + 34, sculk_block, 0, 2);
		world.setBlock(i + 7, j + 21, k + 35, sculk_block, 0, 2);
		world.setBlock(i + 7, j + 21, k + 36, sculk_block, 0, 2);
		world.setBlock(i + 7, j + 21, k + 37, sculk_block, 0, 2);
		world.setBlock(i + 8, j + 21, k + 37, sculk_block, 0, 2);
		world.setBlock(i + 8, j + 21, k + 38, sculk_block, 0, 2);
		world.setBlock(i + 8, j + 21, k + 39, sculk_block, 0, 2);
		world.setBlock(i + 8, j + 21, k + 40, sculk_block, 0, 2);
		world.setBlock(i + 9, j + 21, k + 40, sculk_block, 0, 2);
		world.setBlock(i + 9, j + 22, k + 3, sculk_block, 0, 2);
		world.setBlock(i + 10, j + 22, k + 3, sculk_block, 0, 2);
		world.setBlock(i + 9, j + 22, k + 4, sculk_block, 0, 2);
		world.setBlock(i + 9, j + 22, k + 5, sculk_block, 0, 2);
		world.setBlock(i + 10, j + 22, k + 5, NovaCraftBlocks.sculk_spike, 0, 2);
		world.setBlock(i + 8, j + 22, k + 6, sculk_block, 0, 2);
		world.setBlock(i + 9, j + 22, k + 6, sculk_block, 0, 2);
		world.setBlock(i + 8, j + 22, k + 7, sculk_block, 0, 2);
		world.setBlock(i + 8, j + 22, k + 8, sculk_block, 0, 2);
		world.setBlock(i + 7, j + 22, k + 9, sculk_block, 0, 2);
		world.setBlock(i + 8, j + 22, k + 9, sculk_block, 0, 2);
		world.setBlock(i + 7, j + 22, k + 10, sculk_block, 0, 2);
		world.setBlock(i + 8, j + 22, k + 10, sculk_block, 0, 2);
		world.setBlock(i + 7, j + 22, k + 11, sculk_block, 0, 2);
		world.setBlock(i + 7, j + 22, k + 12, sculk_block, 0, 2);
		world.setBlock(i + 7, j + 22, k + 13, sculk_block, 0, 2);
		world.setBlock(i + 7, j + 22, k + 14, sculk_block, 0, 2);
		world.setBlock(i + 6, j + 22, k + 15, sculk_block, 0, 2);
		world.setBlock(i + 7, j + 22, k + 15, sculk_block, 0, 2);
		world.setBlock(i + 6, j + 22, k + 16, sculk_block, 0, 2);
		world.setBlock(i + 7, j + 22, k + 16, sculk_block, 0, 2);
		world.setBlock(i + 6, j + 22, k + 17, sculk_block, 0, 2);
		world.setBlock(i + 7, j + 22, k + 17, sculk_block, 0, 2);
		world.setBlock(i + 6, j + 22, k + 18, sculk_block, 0, 2);
		world.setBlock(i + 6, j + 22, k + 19, sculk_block, 0, 2);
		world.setBlock(i + 6, j + 22, k + 20, sculk_block, 0, 2);
		world.setBlock(i + 6, j + 22, k + 21, sculk_block, 0, 2);
		world.setBlock(i + 6, j + 22, k + 22, sculk_block, 0, 2);
		world.setBlock(i + 6, j + 22, k + 23, sculk_block, 0, 2);
		world.setBlock(i + 6, j + 22, k + 24, sculk_block, 0, 2);
		world.setBlock(i + 6, j + 22, k + 25, sculk_block, 0, 2);
		world.setBlock(i + 7, j + 22, k + 25, sculk_block, 0, 2);
		world.setBlock(i + 8, j + 22, k + 25, NovaCraftBlocks.sculk_vein, 0, 2);
		world.setBlock(i + 6, j + 22, k + 26, sculk_block, 0, 2);
		world.setBlock(i + 7, j + 22, k + 26, sculk_block, 0, 2);
		world.setBlock(i + 6, j + 22, k + 27, sculk_block, 0, 2);
		world.setBlock(i + 7, j + 22, k + 27, sculk_block, 0, 2);
		world.setBlock(i + 7, j + 22, k + 28, sculk_block, 0, 2);
		world.setBlock(i + 7, j + 22, k + 29, sculk_block, 0, 2);
		world.setBlock(i + 7, j + 22, k + 30, sculk_block, 0, 2);
		world.setBlock(i + 7, j + 22, k + 31, sculk_block, 0, 2);
		world.setBlock(i + 7, j + 22, k + 32, sculk_block, 0, 2);
		world.setBlock(i + 8, j + 22, k + 32, sculk_block, 0, 2);
		world.setBlock(i + 7, j + 22, k + 33, sculk_block, 0, 2);
		world.setBlock(i + 8, j + 22, k + 33, sculk_block, 0, 2);
		world.setBlock(i + 8, j + 22, k + 34, sculk_block, 0, 2);
		world.setBlock(i + 8, j + 22, k + 35, sculk_block, 0, 2);
		world.setBlock(i + 8, j + 22, k + 36, sculk_block, 0, 2);
		world.setBlock(i + 9, j + 22, k + 36, sculk_block, 0, 2);
		world.setBlock(i + 9, j + 22, k + 37, sculk_block, 0, 2);
		world.setBlock(i + 10, j + 22, k + 37, NovaCraftBlocks.sculk_spike, 0, 2);
		world.setBlock(i + 9, j + 22, k + 38, sculk_block, 0, 2);
		world.setBlock(i + 9, j + 22, k + 39, sculk_block, 0, 2);
		world.setBlock(i + 10, j + 22, k + 39, sculk_block, 0, 2);
		world.setBlock(i + 10, j + 23, k + 4, sculk_block, 0, 2);
		world.setBlock(i + 11, j + 23, k + 4, sculk_block, 0, 2);
		world.setBlock(i + 10, j + 23, k + 5, sculk_block, 0, 2);
		world.setBlock(i + 11, j + 23, k + 5, sculk_block, 0, 2);
		world.setBlock(i + 10, j + 23, k + 6, sculk_block, 0, 2);
		world.setBlock(i + 9, j + 23, k + 7, sculk_block, 0, 2);
		world.setBlock(i + 10, j + 23, k + 7, sculk_block, 0, 2);
		world.setBlock(i + 9, j + 23, k + 8, sculk_block, 0, 2);
		world.setBlock(i + 10, j + 23, k + 8, sculk_block, 0, 2);
		world.setBlock(i + 9, j + 23, k + 9, sculk_block, 0, 2);
		world.setBlock(i + 10, j + 23, k + 9, NovaCraftBlocks.sculk_spike, 0, 2);
		world.setBlock(i + 9, j + 23, k + 10, sculk_block, 0, 2);
		world.setBlock(i + 8, j + 23, k + 11, sculk_block, 0, 2);
		world.setBlock(i + 9, j + 23, k + 11, sculk_block, 0, 2);
		world.setBlock(i + 8, j + 23, k + 12, sculk_block, 0, 2);
		world.setBlock(i + 9, j + 23, k + 12, sculk_block, 0, 2);
		world.setBlock(i + 8, j + 23, k + 13, sculk_block, 0, 2);
		world.setBlock(i + 9, j + 23, k + 13, sculk_block, 0, 2);
		world.setBlock(i + 8, j + 23, k + 14, sculk_block, 0, 2);
		world.setBlock(i + 8, j + 23, k + 15, sculk_block, 0, 2);
		world.setBlock(i + 8, j + 23, k + 16, sculk_block, 0, 2);
		world.setBlock(i + 9, j + 23, k + 16, NovaCraftBlocks.sculk_tentacle_2, 0, 2);
		world.setBlock(i + 8, j + 23, k + 17, sculk_block, 0, 2);
		world.setBlock(i + 7, j + 23, k + 18, sculk_block, 0, 2);
		world.setBlock(i + 8, j + 23, k + 18, sculk_block, 0, 2);
		world.setBlock(i + 7, j + 23, k + 19, sculk_block, 0, 2);
		world.setBlock(i + 8, j + 23, k + 19, sculk_block, 0, 2);
		world.setBlock(i + 7, j + 23, k + 20, sculk_block, 0, 2);
		world.setBlock(i + 8, j + 23, k + 20, sculk_block, 0, 2);
		world.setBlock(i + 7, j + 23, k + 21, sculk_block, 0, 2);
		world.setBlock(i + 8, j + 23, k + 21, sculk_block, 0, 2);
		world.setBlock(i + 7, j + 23, k + 22, sculk_block, 0, 2);
		world.setBlock(i + 8, j + 23, k + 22, sculk_block, 0, 2);
		world.setBlock(i + 7, j + 23, k + 23, sculk_block, 0, 2);
		world.setBlock(i + 8, j + 23, k + 23, sculk_block, 0, 2);
		world.setBlock(i + 7, j + 23, k + 24, sculk_block, 0, 2);
		world.setBlock(i + 8, j + 23, k + 24, sculk_block, 0, 2);
		world.setBlock(i + 8, j + 23, k + 25, sculk_block, 0, 2);
		world.setBlock(i + 8, j + 23, k + 26, sculk_block, 0, 2);
		world.setBlock(i + 8, j + 23, k + 27, sculk_block, 0, 2);
		world.setBlock(i + 10, j + 23, k + 27, NovaCraftBlocks.sculk_spike, 0, 2);
		world.setBlock(i + 8, j + 23, k + 28, sculk_block, 0, 2);
		world.setBlock(i + 8, j + 23, k + 29, sculk_block, 0, 2);
		world.setBlock(i + 9, j + 23, k + 29, sculk_block, 0, 2);
		world.setBlock(i + 8, j + 23, k + 30, sculk_block, 0, 2);
		world.setBlock(i + 9, j + 23, k + 30, sculk_block, 0, 2);
		world.setBlock(i + 8, j + 23, k + 31, sculk_block, 0, 2);
		world.setBlock(i + 9, j + 23, k + 31, sculk_block, 0, 2);
		world.setBlock(i + 9, j + 23, k + 32, sculk_block, 0, 2);
		world.setBlock(i + 9, j + 23, k + 33, sculk_block, 0, 2);
		world.setBlock(i + 10, j + 23, k + 33, NovaCraftBlocks.sculk_vein, 0, 2);
		world.setBlock(i + 9, j + 23, k + 34, sculk_block, 0, 2);
		world.setBlock(i + 10, j + 23, k + 34, sculk_block, 0, 2);
		world.setBlock(i + 9, j + 23, k + 35, sculk_block, 0, 2);
		world.setBlock(i + 10, j + 23, k + 35, sculk_block, 0, 2);
		world.setBlock(i + 10, j + 23, k + 36, sculk_block, 0, 2);
		world.setBlock(i + 10, j + 23, k + 37, sculk_block, 0, 2);
		world.setBlock(i + 11, j + 23, k + 37, sculk_block, 0, 2);
		world.setBlock(i + 10, j + 23, k + 38, sculk_block, 0, 2);
		world.setBlock(i + 11, j + 23, k + 38, sculk_block, 0, 2);
		world.setBlock(i + 12, j + 24, k + 4, sculk_block, 0, 2);
		world.setBlock(i + 13, j + 24, k + 4, sculk_block, 0, 2);
		world.setBlock(i + 12, j + 24, k + 5, sculk_block, 0, 2);
		world.setBlock(i + 13, j + 24, k + 5, sculk_block, 0, 2);
		world.setBlock(i + 11, j + 24, k + 6, sculk_block, 0, 2);
		world.setBlock(i + 12, j + 24, k + 6, sculk_block, 0, 2);
		world.setBlock(i + 11, j + 24, k + 7, sculk_block, 0, 2);
		world.setBlock(i + 12, j + 24, k + 7, sculk_block, 0, 2);
		world.setBlock(i + 13, j + 24, k + 7, NovaCraftBlocks.sculk_spike, 0, 2);
		world.setBlock(i + 11, j + 24, k + 8, sculk_block, 0, 2);
		world.setBlock(i + 12, j + 24, k + 8, sculk_block, 0, 2);
		world.setBlock(i + 10, j + 24, k + 9, sculk_block, 0, 2);
		world.setBlock(i + 11, j + 24, k + 9, sculk_block, 0, 2);
		world.setBlock(i + 10, j + 24, k + 10, sculk_block, 0, 2);
		world.setBlock(i + 11, j + 24, k + 10, sculk_block, 0, 2);
		world.setBlock(i + 10, j + 24, k + 11, sculk_block, 0, 2);
		world.setBlock(i + 11, j + 24, k + 11, sculk_block, 0, 2);
		world.setBlock(i + 10, j + 24, k + 12, sculk_block, 0, 2);
		world.setBlock(i + 11, j + 24, k + 12, sculk_block, 0, 2);
		world.setBlock(i + 10, j + 24, k + 13, sculk_block, 0, 2);
		world.setBlock(i + 11, j + 24, k + 13, sculk_block, 0, 2);
		world.setBlock(i + 9, j + 24, k + 14, sculk_block, 0, 2);
		world.setBlock(i + 10, j + 24, k + 14, sculk_block, 0, 2);
		world.setBlock(i + 9, j + 24, k + 15, sculk_block, 0, 2);
		world.setBlock(i + 10, j + 24, k + 15, sculk_block, 0, 2);
		world.setBlock(i + 9, j + 24, k + 16, sculk_block, 0, 2);
		world.setBlock(i + 10, j + 24, k + 16, sculk_block, 0, 2);
		world.setBlock(i + 9, j + 24, k + 17, sculk_block, 0, 2);
		world.setBlock(i + 10, j + 24, k + 17, sculk_block, 0, 2);
		world.setBlock(i + 9, j + 24, k + 18, sculk_block, 0, 2);
		world.setBlock(i + 10, j + 24, k + 18, sculk_block, 0, 2);
		world.setBlock(i + 9, j + 24, k + 19, sculk_block, 0, 2);
		world.setBlock(i + 10, j + 24, k + 19, sculk_block, 0, 2);
		world.setBlock(i + 9, j + 24, k + 20, sculk_block, 0, 2);
		world.setBlock(i + 10, j + 24, k + 20, sculk_block, 0, 2);
		world.setBlock(i + 9, j + 24, k + 21, sculk_block, 0, 2);
		world.setBlock(i + 10, j + 24, k + 21, sculk_block, 0, 2);
		world.setBlock(i + 9, j + 24, k + 22, sculk_block, 0, 2);
		world.setBlock(i + 10, j + 24, k + 22, sculk_block, 0, 2);
		world.setBlock(i + 9, j + 24, k + 23, sculk_block, 0, 2);
		world.setBlock(i + 10, j + 24, k + 23, sculk_block, 0, 2);
		world.setBlock(i + 9, j + 24, k + 24, sculk_block, 0, 2);
		world.setBlock(i + 10, j + 24, k + 24, sculk_block, 0, 2);
		world.setBlock(i + 9, j + 24, k + 25, sculk_block, 0, 2);
		world.setBlock(i + 10, j + 24, k + 25, sculk_block, 0, 2);
		world.setBlock(i + 9, j + 24, k + 26, sculk_block, 0, 2);
		world.setBlock(i + 10, j + 24, k + 26, sculk_block, 0, 2);
		world.setBlock(i + 11, j + 24, k + 26, NovaCraftBlocks.sculk_vein, 0, 2);
		world.setBlock(i + 9, j + 24, k + 27, sculk_block, 0, 2);
		world.setBlock(i + 10, j + 24, k + 27, sculk_block, 0, 2);
		world.setBlock(i + 9, j + 24, k + 28, sculk_block, 0, 2);
		world.setBlock(i + 10, j + 24, k + 28, sculk_block, 0, 2);
		world.setBlock(i + 11, j + 24, k + 28, NovaCraftBlocks.sculk_spike, 0, 2);
		world.setBlock(i + 10, j + 24, k + 29, sculk_block, 0, 2);
		world.setBlock(i + 11, j + 24, k + 29, sculk_block, 0, 2);
		world.setBlock(i + 10, j + 24, k + 30, sculk_block, 0, 2);
		world.setBlock(i + 11, j + 24, k + 30, sculk_block, 0, 2);
		world.setBlock(i + 10, j + 24, k + 31, sculk_block, 0, 2);
		world.setBlock(i + 11, j + 24, k + 31, sculk_block, 0, 2);
		world.setBlock(i + 10, j + 24, k + 32, sculk_block, 0, 2);
		world.setBlock(i + 11, j + 24, k + 32, sculk_block, 0, 2);
		world.setBlock(i + 10, j + 24, k + 33, sculk_block, 0, 2);
		world.setBlock(i + 11, j + 24, k + 33, sculk_block, 0, 2);
		world.setBlock(i + 11, j + 24, k + 34, sculk_block, 0, 2);
		world.setBlock(i + 12, j + 24, k + 34, sculk_block, 0, 2);
		world.setBlock(i + 14, j + 24, k + 34, NovaCraftBlocks.sculk_spike, 0, 2);
		world.setBlock(i + 11, j + 24, k + 35, sculk_block, 0, 2);
		world.setBlock(i + 12, j + 24, k + 35, sculk_block, 0, 2);
		world.setBlock(i + 11, j + 24, k + 36, sculk_block, 0, 2);
		world.setBlock(i + 12, j + 24, k + 36, sculk_block, 0, 2);
		world.setBlock(i + 12, j + 24, k + 37, sculk_block, 0, 2);
		world.setBlock(i + 13, j + 24, k + 37, sculk_block, 0, 2);
		world.setBlock(i + 14, j + 25, k + 5, sculk_block, 0, 2);
		world.setBlock(i + 15, j + 25, k + 5, sculk_block, 0, 2);
		world.setBlock(i + 13, j + 25, k + 6, sculk_block, 0, 2);
		world.setBlock(i + 14, j + 25, k + 6, sculk_block, 0, 2);
		world.setBlock(i + 15, j + 25, k + 6, sculk_block, 0, 2);
		world.setBlock(i + 13, j + 25, k + 7, sculk_block, 0, 2);
		world.setBlock(i + 14, j + 25, k + 7, sculk_block, 0, 2);
		world.setBlock(i + 13, j + 25, k + 8, sculk_block, 0, 2);
		world.setBlock(i + 14, j + 25, k + 8, sculk_block, 0, 2);
		world.setBlock(i + 16, j + 25, k + 8, NovaCraftBlocks.sculk_vein, 0, 2);
		world.setBlock(i + 12, j + 25, k + 9, sculk_block, 0, 2);
		world.setBlock(i + 13, j + 25, k + 9, sculk_block, 0, 2);
		world.setBlock(i + 14, j + 25, k + 9, sculk_block, 0, 2);
		world.setBlock(i + 12, j + 25, k + 10, sculk_block, 0, 2);
		world.setBlock(i + 13, j + 25, k + 10, sculk_block, 0, 2);
		world.setBlock(i + 16, j + 25, k + 10, NovaCraftBlocks.sculk_spike, 0, 2);
		world.setBlock(i + 12, j + 25, k + 11, sculk_block, 0, 2);
		world.setBlock(i + 13, j + 25, k + 11, sculk_block, 0, 2);
		world.setBlock(i + 12, j + 25, k + 12, sculk_block, 0, 2);
		world.setBlock(i + 13, j + 25, k + 12, sculk_block, 0, 2);
		world.setBlock(i + 12, j + 25, k + 13, sculk_block, 0, 2);
		world.setBlock(i + 13, j + 25, k + 13, sculk_block, 0, 2);
		world.setBlock(i + 11, j + 25, k + 14, sculk_block, 0, 2);
		world.setBlock(i + 12, j + 25, k + 14, sculk_block, 0, 2);
		world.setBlock(i + 13, j + 25, k + 14, sculk_block, 0, 2);
