package com.NovaCraft.world.ancient_city;

import java.util.Random;

import com.NovaCraft.Items.NovaCraftItems;
import com.NovaCraft.registry.OtherModBlocks;
import com.NovaCraft.registry.OtherModItems;
import com.NovaCraftBlocks.NovaCraftBlocks;

import cpw.mods.fml.common.Loader;
import net.minecraft.block.Block;
import net.minecraft.enchantment.Enchantment;
import net.minecraft.enchantment.EnchantmentData;
import net.minecraft.init.Blocks;
import net.minecraft.init.Items;
import net.minecraft.item.ItemStack;
import net.minecraft.tileentity.TileEntity;
import net.minecraft.tileentity.TileEntityChest;
import net.minecraft.util.MathHelper;
import net.minecraft.world.World;
import net.minecraft.world.gen.feature.WorldGenerator;

public class AncientCityObservationTowerGen extends WorldGenerator
{
	public AncientCityObservationTowerGen() {

	}

	private static final Block sculk_block = NovaCraftBlocks.sculk_block;
	private static final Block sculk_tulip = NovaCraftBlocks.sculk_tulip;
	private static final Block sculk_tendrils = NovaCraftBlocks.sculk_tendrils;
	private static final Block sculk_bush = NovaCraftBlocks.sculk_bush;
	private static final Block sculk_bloom = NovaCraftBlocks.sculk_bloom;	
	private static final Block sculk_tiles = NovaCraftBlocks.sculk_tiles;
	private static final Block sculk_bricks = NovaCraftBlocks.sculk_bricks;
    
    public boolean generate(final World world, final Random random, final int i, final int j, final int k) {
    	
		world.setBlock(i + 16, j, k, sculk_block, 0, 2);
		world.setBlock(i + 17, j, k, sculk_block, 0, 2);
		world.setBlock(i + 11, j, k + 1, sculk_block, 0, 2);
		world.setBlock(i + 12, j, k + 1, sculk_block, 0, 2);
		world.setBlock(i + 13, j, k + 1, sculk_block, 0, 2);
		world.setBlock(i + 14, j, k + 1, sculk_block, 0, 2);
		world.setBlock(i + 15, j, k + 1, sculk_block, 0, 2);
		world.setBlock(i + 16, j, k + 1, sculk_block, 0, 2);
		world.setBlock(i + 17, j, k + 1, sculk_block, 0, 2);
		world.setBlock(i + 18, j, k + 1, sculk_block, 0, 2);
		world.setBlock(i + 9, j, k + 2, sculk_block, 0, 2);
		world.setBlock(i + 10, j, k + 2, sculk_block, 0, 2);
		world.setBlock(i + 11, j, k + 2, sculk_block, 0, 2);
		world.setBlock(i + 12, j, k + 2, sculk_block, 0, 2);
		world.setBlock(i + 13, j, k + 2, sculk_block, 0, 2);
		world.setBlock(i + 14, j, k + 2, sculk_block, 0, 2);
		world.setBlock(i + 15, j, k + 2, sculk_block, 0, 2);
		world.setBlock(i + 16, j, k + 2, sculk_block, 0, 2);
		world.setBlock(i + 17, j, k + 2, sculk_block, 0, 2);
		world.setBlock(i + 18, j, k + 2, sculk_block, 0, 2);
		world.setBlock(i + 19, j, k + 2, sculk_block, 0, 2);
		world.setBlock(i + 8, j, k + 3, sculk_block, 0, 2);
		world.setBlock(i + 9, j, k + 3, sculk_block, 0, 2);
		world.setBlock(i + 10, j, k + 3, sculk_block, 0, 2);
		world.setBlock(i + 11, j, k + 3, sculk_block, 0, 2);
		world.setBlock(i + 12, j, k + 3, sculk_block, 0, 2);
		world.setBlock(i + 13, j, k + 3, sculk_block, 0, 2);
		world.setBlock(i + 14, j, k + 3, sculk_block, 0, 2);
		world.setBlock(i + 15, j, k + 3, sculk_block, 0, 2);
		world.setBlock(i + 16, j, k + 3, sculk_block, 0, 2);
		world.setBlock(i + 17, j, k + 3, sculk_block, 0, 2);
		world.setBlock(i + 18, j, k + 3, sculk_block, 0, 2);
		world.setBlock(i + 19, j, k + 3, sculk_block, 0, 2);
		world.setBlock(i + 20, j, k + 3, sculk_block, 0, 2);
		world.setBlock(i + 7, j, k + 4, sculk_block, 0, 2);
		world.setBlock(i + 8, j, k + 4, sculk_block, 0, 2);
		world.setBlock(i + 9, j, k + 4, sculk_block, 0, 2);
		world.setBlock(i + 10, j, k + 4, sculk_block, 0, 2);
		world.setBlock(i + 11, j, k + 4, sculk_block, 0, 2);
		world.setBlock(i + 12, j, k + 4, sculk_block, 0, 2);
		world.setBlock(i + 13, j, k + 4, sculk_block, 0, 2);
		world.setBlock(i + 14, j, k + 4, sculk_block, 0, 2);
		world.setBlock(i + 15, j, k + 4, sculk_block, 0, 2);
		world.setBlock(i + 16, j, k + 4, sculk_block, 0, 2);
		world.setBlock(i + 17, j, k + 4, sculk_block, 0, 2);
		world.setBlock(i + 18, j, k + 4, sculk_block, 0, 2);
		world.setBlock(i + 19, j, k + 4, sculk_block, 0, 2);
		world.setBlock(i + 20, j, k + 4, sculk_block, 0, 2);
		world.setBlock(i + 21, j, k + 4, sculk_block, 0, 2);
		world.setBlock(i + 6, j, k + 5, sculk_block, 0, 2);
		world.setBlock(i + 7, j, k + 5, sculk_block, 0, 2);
		world.setBlock(i + 8, j, k + 5, sculk_block, 0, 2);
		world.setBlock(i + 9, j, k + 5, sculk_block, 0, 2);
		world.setBlock(i + 10, j, k + 5, sculk_block, 0, 2);
		world.setBlock(i + 11, j, k + 5, sculk_block, 0, 2);
		world.setBlock(i + 12, j, k + 5, sculk_block, 0, 2);
		world.setBlock(i + 13, j, k + 5, sculk_block, 0, 2);
		world.setBlock(i + 14, j, k + 5, sculk_block, 0, 2);
		world.setBlock(i + 15, j, k + 5, sculk_block, 0, 2);
		world.setBlock(i + 16, j, k + 5, sculk_block, 0, 2);
		world.setBlock(i + 17, j, k + 5, sculk_block, 0, 2);
		world.setBlock(i + 18, j, k + 5, sculk_block, 0, 2);
		world.setBlock(i + 19, j, k + 5, sculk_block, 0, 2);
		world.setBlock(i + 20, j, k + 5, sculk_block, 0, 2);
		world.setBlock(i + 21, j, k + 5, sculk_block, 0, 2);
		world.setBlock(i + 22, j, k + 5, sculk_block, 0, 2);
		world.setBlock(i + 5, j, k + 6, sculk_block, 0, 2);
		world.setBlock(i + 6, j, k + 6, sculk_block, 0, 2);
		world.setBlock(i + 7, j, k + 6, sculk_block, 0, 2);
		world.setBlock(i + 8, j, k + 6, sculk_block, 0, 2);
		world.setBlock(i + 9, j, k + 6, sculk_block, 0, 2);
		world.setBlock(i + 10, j, k + 6, sculk_block, 0, 2);
		world.setBlock(i + 11, j, k + 6, sculk_block, 0, 2);
		world.setBlock(i + 12, j, k + 6, sculk_block, 0, 2);
		world.setBlock(i + 13, j, k + 6, sculk_block, 0, 2);
		world.setBlock(i + 14, j, k + 6, sculk_block, 0, 2);
		world.setBlock(i + 15, j, k + 6, sculk_block, 0, 2);
		world.setBlock(i + 16, j, k + 6, sculk_block, 0, 2);
		world.setBlock(i + 17, j, k + 6, sculk_block, 0, 2);
		world.setBlock(i + 18, j, k + 6, sculk_block, 0, 2);
		world.setBlock(i + 19, j, k + 6, sculk_block, 0, 2);
		world.setBlock(i + 20, j, k + 6, sculk_block, 0, 2);
		world.setBlock(i + 21, j, k + 6, sculk_block, 0, 2);
		world.setBlock(i + 22, j, k + 6, sculk_block, 0, 2);
		world.setBlock(i + 23, j, k + 6, sculk_block, 0, 2);
		world.setBlock(i + 24, j, k + 6, sculk_block, 0, 2);
		world.setBlock(i + 4, j, k + 7, sculk_block, 0, 2);
		world.setBlock(i + 5, j, k + 7, sculk_block, 0, 2);
		world.setBlock(i + 6, j, k + 7, sculk_block, 0, 2);
		world.setBlock(i + 7, j, k + 7, sculk_block, 0, 2);
		world.setBlock(i + 8, j, k + 7, sculk_block, 0, 2);
		world.setBlock(i + 9, j, k + 7, sculk_block, 0, 2);
		world.setBlock(i + 10, j, k + 7, sculk_block, 0, 2);
		world.setBlock(i + 11, j, k + 7, sculk_block, 0, 2);
		world.setBlock(i + 12, j, k + 7, sculk_block, 0, 2);
		world.setBlock(i + 13, j, k + 7, sculk_block, 0, 2);
		world.setBlock(i + 14, j, k + 7, sculk_block, 0, 2);
		world.setBlock(i + 15, j, k + 7, sculk_block, 0, 2);
		world.setBlock(i + 16, j, k + 7, sculk_block, 0, 2);
		world.setBlock(i + 17, j, k + 7, sculk_block, 0, 2);
		world.setBlock(i + 18, j, k + 7, sculk_block, 0, 2);
		world.setBlock(i + 19, j, k + 7, sculk_block, 0, 2);
		world.setBlock(i + 20, j, k + 7, sculk_block, 0, 2);
		world.setBlock(i + 21, j, k + 7, sculk_block, 0, 2);
		world.setBlock(i + 22, j, k + 7, sculk_block, 0, 2);
		world.setBlock(i + 23, j, k + 7, sculk_block, 0, 2);
		world.setBlock(i + 24, j, k + 7, sculk_block, 0, 2);
		world.setBlock(i + 25, j, k + 7, sculk_block, 0, 2);
		world.setBlock(i + 3, j, k + 8, sculk_block, 0, 2);
		world.setBlock(i + 4, j, k + 8, sculk_block, 0, 2);
		world.setBlock(i + 5, j, k + 8, sculk_block, 0, 2);
		world.setBlock(i + 6, j, k + 8, sculk_block, 0, 2);
		world.setBlock(i + 7, j, k + 8, sculk_block, 0, 2);
		world.setBlock(i + 8, j, k + 8, sculk_block, 0, 2);
		world.setBlock(i + 9, j, k + 8, sculk_block, 0, 2);
		world.setBlock(i + 10, j, k + 8, sculk_block, 0, 2);
		world.setBlock(i + 11, j, k + 8, sculk_block, 0, 2);
		world.setBlock(i + 12, j, k + 8, sculk_block, 0, 2);
		world.setBlock(i + 13, j, k + 8, sculk_block, 0, 2);
		world.setBlock(i + 14, j, k + 8, sculk_block, 0, 2);
		world.setBlock(i + 15, j, k + 8, sculk_block, 0, 2);
		world.setBlock(i + 16, j, k + 8, sculk_block, 0, 2);
		world.setBlock(i + 17, j, k + 8, sculk_block, 0, 2);
		world.setBlock(i + 18, j, k + 8, sculk_block, 0, 2);
		world.setBlock(i + 19, j, k + 8, sculk_block, 0, 2);
		world.setBlock(i + 20, j, k + 8, sculk_block, 0, 2);
		world.setBlock(i + 21, j, k + 8, sculk_block, 0, 2);
		world.setBlock(i + 22, j, k + 8, sculk_block, 0, 2);
		world.setBlock(i + 23, j, k + 8, sculk_block, 0, 2);
		world.setBlock(i + 24, j, k + 8, sculk_block, 0, 2);
		world.setBlock(i + 25, j, k + 8, sculk_block, 0, 2);
		world.setBlock(i + 26, j, k + 8, sculk_block, 0, 2);
		world.setBlock(i + 2, j, k + 9, sculk_block, 0, 2);
		world.setBlock(i + 3, j, k + 9, sculk_block, 0, 2);
		world.setBlock(i + 4, j, k + 9, sculk_block, 0, 2);
		world.setBlock(i + 5, j, k + 9, sculk_block, 0, 2);
		world.setBlock(i + 6, j, k + 9, sculk_block, 0, 2);
		world.setBlock(i + 7, j, k + 9, sculk_block, 0, 2);
		world.setBlock(i + 8, j, k + 9, sculk_block, 0, 2);
		world.setBlock(i + 9, j, k + 9, sculk_block, 0, 2);
		world.setBlock(i + 10, j, k + 9, sculk_block, 0, 2);
		world.setBlock(i + 11, j, k + 9, sculk_block, 0, 2);
		world.setBlock(i + 12, j, k + 9, sculk_block, 0, 2);
		world.setBlock(i + 13, j, k + 9, sculk_block, 0, 2);
		world.setBlock(i + 14, j, k + 9, sculk_block, 0, 2);
		world.setBlock(i + 15, j, k + 9, sculk_block, 0, 2);
		world.setBlock(i + 16, j, k + 9, sculk_block, 0, 2);
		world.setBlock(i + 17, j, k + 9, sculk_block, 0, 2);
		world.setBlock(i + 18, j, k + 9, sculk_block, 0, 2);
		world.setBlock(i + 19, j, k + 9, sculk_block, 0, 2);
		world.setBlock(i + 20, j, k + 9, sculk_block, 0, 2);
		world.setBlock(i + 21, j, k + 9, sculk_block, 0, 2);
		world.setBlock(i + 22, j, k + 9, sculk_block, 0, 2);
		world.setBlock(i + 23, j, k + 9, sculk_block, 0, 2);
		world.setBlock(i + 24, j, k + 9, sculk_block, 0, 2);
		world.setBlock(i + 25, j, k + 9, sculk_block, 0, 2);
		world.setBlock(i + 26, j, k + 9, sculk_block, 0, 2);
		world.setBlock(i + 27, j, k + 9, sculk_block, 0, 2);
		world.setBlock(i + 28, j, k + 9, sculk_block, 0, 2);
		world.setBlock(i + 1, j, k + 10, sculk_block, 0, 2);
		world.setBlock(i + 2, j, k + 10, sculk_block, 0, 2);
		world.setBlock(i + 3, j, k + 10, sculk_block, 0, 2);
		world.setBlock(i + 4, j, k + 10, sculk_block, 0, 2);
		world.setBlock(i + 5, j, k + 10, sculk_block, 0, 2);
		world.setBlock(i + 6, j, k + 10, sculk_block, 0, 2);
		world.setBlock(i + 7, j, k + 10, sculk_block, 0, 2);
		world.setBlock(i + 8, j, k + 10, sculk_block, 0, 2);
		world.setBlock(i + 9, j, k + 10, sculk_block, 0, 2);
		world.setBlock(i + 10, j, k + 10, sculk_block, 0, 2);
		world.setBlock(i + 11, j, k + 10, sculk_block, 0, 2);
		world.setBlock(i + 12, j, k + 10, sculk_block, 0, 2);
		world.setBlock(i + 13, j, k + 10, sculk_block, 0, 2);
		world.setBlock(i + 14, j, k + 10, sculk_block, 0, 2);
		world.setBlock(i + 15, j, k + 10, sculk_block, 0, 2);
		world.setBlock(i + 16, j, k + 10, sculk_block, 0, 2);
		world.setBlock(i + 17, j, k + 10, sculk_block, 0, 2);
		world.setBlock(i + 18, j, k + 10, sculk_block, 0, 2);
		world.setBlock(i + 19, j, k + 10, sculk_block, 0, 2);
		world.setBlock(i + 20, j, k + 10, sculk_block, 0, 2);
		world.setBlock(i + 21, j, k + 10, sculk_block, 0, 2);
		world.setBlock(i + 22, j, k + 10, sculk_block, 0, 2);
		world.setBlock(i + 23, j, k + 10, sculk_block, 0, 2);
		world.setBlock(i + 24, j, k + 10, sculk_block, 0, 2);
		world.setBlock(i + 25, j, k + 10, sculk_block, 0, 2);
		world.setBlock(i + 26, j, k + 10, sculk_block, 0, 2);
		world.setBlock(i + 27, j, k + 10, sculk_block, 0, 2);
		world.setBlock(i + 28, j, k + 10, sculk_block, 0, 2);
		world.setBlock(i + 29, j, k + 10, sculk_block, 0, 2);
		world.setBlock(i + 1, j, k + 11, sculk_block, 0, 2);
		world.setBlock(i + 2, j, k + 11, sculk_block, 0, 2);
		world.setBlock(i + 3, j, k + 11, sculk_block, 0, 2);
		world.setBlock(i + 4, j, k + 11, sculk_block, 0, 2);
		world.setBlock(i + 5, j, k + 11, sculk_block, 0, 2);
		world.setBlock(i + 6, j, k + 11, sculk_block, 0, 2);
		world.setBlock(i + 7, j, k + 11, sculk_block, 0, 2);
		world.setBlock(i + 8, j, k + 11, sculk_block, 0, 2);
		world.setBlock(i + 9, j, k + 11, sculk_block, 0, 2);
		world.setBlock(i + 10, j, k + 11, sculk_block, 0, 2);
		world.setBlock(i + 11, j, k + 11, sculk_block, 0, 2);
		world.setBlock(i + 12, j, k + 11, sculk_block, 0, 2);
		world.setBlock(i + 13, j, k + 11, sculk_block, 0, 2);
		world.setBlock(i + 14, j, k + 11, sculk_block, 0, 2);
		world.setBlock(i + 15, j, k + 11, sculk_block, 0, 2);
		world.setBlock(i + 16, j, k + 11, sculk_block, 0, 2);
		world.setBlock(i + 17, j, k + 11, sculk_block, 0, 2);
		world.setBlock(i + 18, j, k + 11, sculk_block, 0, 2);
		world.setBlock(i + 19, j, k + 11, sculk_block, 0, 2);
		world.setBlock(i + 20, j, k + 11, sculk_block, 0, 2);
		world.setBlock(i + 21, j, k + 11, sculk_block, 0, 2);
		world.setBlock(i + 22, j, k + 11, sculk_block, 0, 2);
		world.setBlock(i + 23, j, k + 11, sculk_block, 0, 2);
		world.setBlock(i + 24, j, k + 11, sculk_block, 0, 2);
		world.setBlock(i + 25, j, k + 11, sculk_block, 0, 2);
		world.setBlock(i + 26, j, k + 11, sculk_block, 0, 2);
		world.setBlock(i + 27, j, k + 11, sculk_block, 0, 2);
		world.setBlock(i + 28, j, k + 11, sculk_block, 0, 2);
		world.setBlock(i + 29, j, k + 11, sculk_block, 0, 2);
		world.setBlock(i + 30, j, k + 11, sculk_block, 0, 2);
		world.setBlock(i + 1, j, k + 12, sculk_block, 0, 2);
		world.setBlock(i + 2, j, k + 12, sculk_block, 0, 2);
		world.setBlock(i + 3, j, k + 12, sculk_block, 0, 2);
		world.setBlock(i + 4, j, k + 12, sculk_block, 0, 2);
		world.setBlock(i + 5, j, k + 12, sculk_block, 0, 2);
		world.setBlock(i + 6, j, k + 12, sculk_block, 0, 2);
		world.setBlock(i + 7, j, k + 12, sculk_block, 0, 2);
		world.setBlock(i + 8, j, k + 12, sculk_block, 0, 2);
		world.setBlock(i + 9, j, k + 12, sculk_block, 0, 2);
		world.setBlock(i + 10, j, k + 12, sculk_block, 0, 2);
		world.setBlock(i + 11, j, k + 12, sculk_block, 0, 2);
		world.setBlock(i + 12, j, k + 12, sculk_block, 0, 2);
		world.setBlock(i + 13, j, k + 12, sculk_block, 0, 2);
		world.setBlock(i + 14, j, k + 12, sculk_block, 0, 2);
		world.setBlock(i + 15, j, k + 12, sculk_block, 0, 2);
		world.setBlock(i + 16, j, k + 12, sculk_block, 0, 2);
		world.setBlock(i + 17, j, k + 12, sculk_block, 0, 2);
		world.setBlock(i + 18, j, k + 12, sculk_block, 0, 2);
		world.setBlock(i + 19, j, k + 12, sculk_block, 0, 2);
		world.setBlock(i + 20, j, k + 12, sculk_block, 0, 2);
		world.setBlock(i + 21, j, k + 12, sculk_block, 0, 2);
		world.setBlock(i + 22, j, k + 12, sculk_block, 0, 2);
		world.setBlock(i + 23, j, k + 12, sculk_block, 0, 2);
		world.setBlock(i + 24, j, k + 12, sculk_block, 0, 2);
		world.setBlock(i + 25, j, k + 12, sculk_block, 0, 2);
		world.setBlock(i + 26, j, k + 12, sculk_block, 0, 2);
		world.setBlock(i + 27, j, k + 12, sculk_block, 0, 2);
		world.setBlock(i + 28, j, k + 12, sculk_block, 0, 2);
		world.setBlock(i + 29, j, k + 12, sculk_block, 0, 2);
		world.setBlock(i + 30, j, k + 12, sculk_block, 0, 2);
		world.setBlock(i + 31, j, k + 12, sculk_block, 0, 2);
		world.setBlock(i + 1, j, k + 13, sculk_block, 0, 2);
		world.setBlock(i + 2, j, k + 13, sculk_block, 0, 2);
		world.setBlock(i + 3, j, k + 13, sculk_block, 0, 2);
		world.setBlock(i + 4, j, k + 13, sculk_block, 0, 2);
		world.setBlock(i + 5, j, k + 13, sculk_block, 0, 2);
		world.setBlock(i + 6, j, k + 13, sculk_block, 0, 2);
		world.setBlock(i + 7, j, k + 13, sculk_block, 0, 2);
		world.setBlock(i + 8, j, k + 13, sculk_block, 0, 2);
		world.setBlock(i + 9, j, k + 13, sculk_block, 0, 2);
		world.setBlock(i + 10, j, k + 13, sculk_block, 0, 2);
		world.setBlock(i + 11, j, k + 13, sculk_block, 0, 2);
		world.setBlock(i + 12, j, k + 13, sculk_block, 0, 2);
		world.setBlock(i + 13, j, k + 13, sculk_block, 0, 2);
		world.setBlock(i + 14, j, k + 13, sculk_block, 0, 2);
		world.setBlock(i + 15, j, k + 13, sculk_block, 0, 2);
		world.setBlock(i + 16, j, k + 13, sculk_block, 0, 2);
		world.setBlock(i + 17, j, k + 13, sculk_block, 0, 2);
		world.setBlock(i + 18, j, k + 13, sculk_block, 0, 2);
		world.setBlock(i + 19, j, k + 13, sculk_block, 0, 2);
		world.setBlock(i + 20, j, k + 13, sculk_block, 0, 2);
		world.setBlock(i + 21, j, k + 13, sculk_block, 0, 2);
		world.setBlock(i + 22, j, k + 13, sculk_block, 0, 2);
		world.setBlock(i + 23, j, k + 13, sculk_block, 0, 2);
		world.setBlock(i + 24, j, k + 13, sculk_block, 0, 2);
		world.setBlock(i + 25, j, k + 13, sculk_block, 0, 2);
		world.setBlock(i + 26, j, k + 13, sculk_block, 0, 2);
		world.setBlock(i + 27, j, k + 13, sculk_block, 0, 2);
		world.setBlock(i + 28, j, k + 13, sculk_block, 0, 2);
		world.setBlock(i + 29, j, k + 13, sculk_block, 0, 2);
		world.setBlock(i + 30, j, k + 13, sculk_block, 0, 2);
		world.setBlock(i + 31, j, k + 13, sculk_block, 0, 2);
		world.setBlock(i, j, k + 14, sculk_block, 0, 2);
		world.setBlock(i + 1, j, k + 14, sculk_block, 0, 2);
		world.setBlock(i + 2, j, k + 14, sculk_block, 0, 2);
		world.setBlock(i + 3, j, k + 14, sculk_block, 0, 2);
		world.setBlock(i + 4, j, k + 14, sculk_block, 0, 2);
		world.setBlock(i + 5, j, k + 14, sculk_block, 0, 2);
		world.setBlock(i + 6, j, k + 14, sculk_block, 0, 2);
		world.setBlock(i + 7, j, k + 14, sculk_block, 0, 2);
		world.setBlock(i + 8, j, k + 14, sculk_block, 0, 2);
		world.setBlock(i + 9, j, k + 14, sculk_block, 0, 2);
		world.setBlock(i + 10, j, k + 14, sculk_block, 0, 2);
		world.setBlock(i + 11, j, k + 14, sculk_block, 0, 2);
		world.setBlock(i + 12, j, k + 14, sculk_block, 0, 2);
		world.setBlock(i + 13, j, k + 14, sculk_block, 0, 2);
		world.setBlock(i + 14, j, k + 14, sculk_block, 0, 2);
		world.setBlock(i + 15, j, k + 14, sculk_block, 0, 2);
		world.setBlock(i + 16, j, k + 14, sculk_block, 0, 2);
		world.setBlock(i + 17, j, k + 14, sculk_block, 0, 2);
		world.setBlock(i + 18, j, k + 14, sculk_block, 0, 2);
		world.setBlock(i + 19, j, k + 14, sculk_block, 0, 2);
		world.setBlock(i + 20, j, k + 14, sculk_block, 0, 2);
		world.setBlock(i + 21, j, k + 14, sculk_block, 0, 2);
		world.setBlock(i + 22, j, k + 14, sculk_block, 0, 2);
		world.setBlock(i + 23, j, k + 14, sculk_block, 0, 2);
		world.setBlock(i + 24, j, k + 14, sculk_block, 0, 2);
		world.setBlock(i + 25, j, k + 14, sculk_block, 0, 2);
		world.setBlock(i + 26, j, k + 14, sculk_block, 0, 2);
		world.setBlock(i + 27, j, k + 14, sculk_block, 0, 2);
		world.setBlock(i + 28, j, k + 14, sculk_block, 0, 2);
		world.setBlock(i + 29, j, k + 14, sculk_block, 0, 2);
		world.setBlock(i + 30, j, k + 14, sculk_block, 0, 2);
		world.setBlock(i + 31, j, k + 14, sculk_block, 0, 2);
		world.setBlock(i + 32, j, k + 14, sculk_block, 0, 2);
		world.setBlock(i, j, k + 15, sculk_block, 0, 2);
		world.setBlock(i + 1, j, k + 15, sculk_block, 0, 2);
		world.setBlock(i + 2, j, k + 15, sculk_block, 0, 2);
		world.setBlock(i + 3, j, k + 15, sculk_block, 0, 2);
		world.setBlock(i + 4, j, k + 15, sculk_block, 0, 2);
		world.setBlock(i + 5, j, k + 15, sculk_block, 0, 2);
		world.setBlock(i + 6, j, k + 15, sculk_block, 0, 2);
		world.setBlock(i + 7, j, k + 15, sculk_block, 0, 2);
		world.setBlock(i + 8, j, k + 15, sculk_block, 0, 2);
		world.setBlock(i + 9, j, k + 15, sculk_block, 0, 2);
		world.setBlock(i + 10, j, k + 15, sculk_block, 0, 2);
		world.setBlock(i + 11, j, k + 15, sculk_block, 0, 2);
		world.setBlock(i + 12, j, k + 15, sculk_block, 0, 2);
		world.setBlock(i + 13, j, k + 15, sculk_block, 0, 2);
		world.setBlock(i + 14, j, k + 15, sculk_block, 0, 2);
		world.setBlock(i + 15, j, k + 15, sculk_block, 0, 2);
		world.setBlock(i + 16, j, k + 15, sculk_block, 0, 2);
		world.setBlock(i + 17, j, k + 15, sculk_block, 0, 2);
		world.setBlock(i + 18, j, k + 15, sculk_block, 0, 2);
		world.setBlock(i + 19, j, k + 15, sculk_block, 0, 2);
		world.setBlock(i + 20, j, k + 15, sculk_block, 0, 2);
		world.setBlock(i + 21, j, k + 15, sculk_block, 0, 2);
		world.setBlock(i + 22, j, k + 15, sculk_block, 0, 2);
		world.setBlock(i + 23, j, k + 15, sculk_block, 0, 2);
		world.setBlock(i + 24, j, k + 15, sculk_block, 0, 2);
		world.setBlock(i + 25, j, k + 15, sculk_block, 0, 2);
		world.setBlock(i + 26, j, k + 15, sculk_block, 0, 2);
		world.setBlock(i + 27, j, k + 15, sculk_block, 0, 2);
		world.setBlock(i + 28, j, k + 15, sculk_block, 0, 2);
		world.setBlock(i + 29, j, k + 15, sculk_block, 0, 2);
		world.setBlock(i + 30, j, k + 15, sculk_block, 0, 2);
		world.setBlock(i + 31, j, k + 15, sculk_block, 0, 2);
		world.setBlock(i + 32, j, k + 15, sculk_block, 0, 2);
		world.setBlock(i + 33, j, k + 15, sculk_block, 0, 2);
		world.setBlock(i, j, k + 16, sculk_block, 0, 2);
		world.setBlock(i + 1, j, k + 16, sculk_block, 0, 2);
		world.setBlock(i + 2, j, k + 16, sculk_block, 0, 2);
		world.setBlock(i + 3, j, k + 16, sculk_block, 0, 2);
		world.setBlock(i + 4, j, k + 16, sculk_block, 0, 2);
		world.setBlock(i + 5, j, k + 16, sculk_block, 0, 2);
		world.setBlock(i + 6, j, k + 16, sculk_block, 0, 2);
		world.setBlock(i + 7, j, k + 16, sculk_block, 0, 2);
		world.setBlock(i + 8, j, k + 16, sculk_block, 0, 2);
		world.setBlock(i + 9, j, k + 16, sculk_block, 0, 2);
		world.setBlock(i + 10, j, k + 16, sculk_block, 0, 2);
		world.setBlock(i + 11, j, k + 16, sculk_block, 0, 2);
		world.setBlock(i + 12, j, k + 16, sculk_block, 0, 2);
		world.setBlock(i + 13, j, k + 16, sculk_block, 0, 2);
		world.setBlock(i + 14, j, k + 16, sculk_block, 0, 2);
		world.setBlock(i + 15, j, k + 16, sculk_block, 0, 2);
		world.setBlock(i + 16, j, k + 16, sculk_block, 0, 2);
		world.setBlock(i + 17, j, k + 16, sculk_block, 0, 2);
		world.setBlock(i + 18, j, k + 16, sculk_block, 0, 2);
		world.setBlock(i + 19, j, k + 16, sculk_block, 0, 2);
		world.setBlock(i + 20, j, k + 16, sculk_block, 0, 2);
		world.setBlock(i + 21, j, k + 16, sculk_block, 0, 2);
		world.setBlock(i + 22, j, k + 16, sculk_block, 0, 2);
		world.setBlock(i + 23, j, k + 16, sculk_block, 0, 2);
		world.setBlock(i + 24, j, k + 16, sculk_block, 0, 2);
		world.setBlock(i + 25, j, k + 16, sculk_block, 0, 2);
		world.setBlock(i + 26, j, k + 16, sculk_block, 0, 2);
		world.setBlock(i + 27, j, k + 16, sculk_block, 0, 2);
		world.setBlock(i + 28, j, k + 16, sculk_block, 0, 2);
		world.setBlock(i + 29, j, k + 16, sculk_block, 0, 2);
		world.setBlock(i + 30, j, k + 16, sculk_block, 0, 2);
		world.setBlock(i + 31, j, k + 16, sculk_block, 0, 2);
		world.setBlock(i + 32, j, k + 16, sculk_block, 0, 2);
		world.setBlock(i + 33, j, k + 16, sculk_block, 0, 2);
		world.setBlock(i, j, k + 17, sculk_block, 0, 2);
		world.setBlock(i + 1, j, k + 17, sculk_block, 0, 2);
		world.setBlock(i + 2, j, k + 17, sculk_block, 0, 2);
		world.setBlock(i + 3, j, k + 17, sculk_block, 0, 2);
		world.setBlock(i + 4, j, k + 17, sculk_block, 0, 2);
		world.setBlock(i + 5, j, k + 17, sculk_block, 0, 2);
		world.setBlock(i + 6, j, k + 17, sculk_block, 0, 2);
		world.setBlock(i + 7, j, k + 17, sculk_block, 0, 2);
		world.setBlock(i + 8, j, k + 17, sculk_block, 0, 2);
		world.setBlock(i + 9, j, k + 17, sculk_block, 0, 2);
		world.setBlock(i + 10, j, k + 17, sculk_block, 0, 2);
		world.setBlock(i + 11, j, k + 17, sculk_block, 0, 2);
		world.setBlock(i + 12, j, k + 17, sculk_block, 0, 2);
		world.setBlock(i + 13, j, k + 17, sculk_block, 0, 2);
		world.setBlock(i + 14, j, k + 17, sculk_block, 0, 2);
		world.setBlock(i + 15, j, k + 17, sculk_block, 0, 2);
		world.setBlock(i + 16, j, k + 17, sculk_block, 0, 2);
		world.setBlock(i + 17, j, k + 17, sculk_block, 0, 2);
		world.setBlock(i + 18, j, k + 17, sculk_block, 0, 2);
		world.setBlock(i + 19, j, k + 17, sculk_block, 0, 2);
		world.setBlock(i + 20, j, k + 17, sculk_block, 0, 2);
		world.setBlock(i + 21, j, k + 17, sculk_block, 0, 2);
		world.setBlock(i + 22, j, k + 17, sculk_block, 0, 2);
		world.setBlock(i + 23, j, k + 17, sculk_block, 0, 2);
		world.setBlock(i + 24, j, k + 17, sculk_block, 0, 2);
		world.setBlock(i + 25, j, k + 17, sculk_block, 0, 2);
		world.setBlock(i + 26, j, k + 17, sculk_block, 0, 2);
		world.setBlock(i + 27, j, k + 17, sculk_block, 0, 2);
		world.setBlock(i + 28, j, k + 17, sculk_block, 0, 2);
		world.setBlock(i + 29, j, k + 17, sculk_block, 0, 2);
		world.setBlock(i + 30, j, k + 17, sculk_block, 0, 2);
		world.setBlock(i + 31, j, k + 17, sculk_block, 0, 2);
		world.setBlock(i + 32, j, k + 17, sculk_block, 0, 2);
		world.setBlock(i + 33, j, k + 17, sculk_block, 0, 2);
		world.setBlock(i, j, k + 18, sculk_block, 0, 2);
		world.setBlock(i + 1, j, k + 18, sculk_block, 0, 2);
		world.setBlock(i + 2, j, k + 18, sculk_block, 0, 2);
		world.setBlock(i + 3, j, k + 18, sculk_block, 0, 2);
		world.setBlock(i + 4, j, k + 18, sculk_block, 0, 2);
		world.setBlock(i + 5, j, k + 18, sculk_block, 0, 2);
		world.setBlock(i + 6, j, k + 18, sculk_block, 0, 2);
		world.setBlock(i + 7, j, k + 18, sculk_block, 0, 2);
		world.setBlock(i + 8, j, k + 18, sculk_block, 0, 2);
		world.setBlock(i + 9, j, k + 18, sculk_block, 0, 2);
		world.setBlock(i + 10, j, k + 18, sculk_block, 0, 2);
		world.setBlock(i + 11, j, k + 18, sculk_block, 0, 2);
		world.setBlock(i + 12, j, k + 18, sculk_block, 0, 2);
		world.setBlock(i + 13, j, k + 18, sculk_block, 0, 2);
		world.setBlock(i + 14, j, k + 18, sculk_block, 0, 2);
		world.setBlock(i + 15, j, k + 18, sculk_block, 0, 2);
		world.setBlock(i + 16, j, k + 18, sculk_block, 0, 2);
		world.setBlock(i + 17, j, k + 18, sculk_block, 0, 2);
		world.setBlock(i + 18, j, k + 18, sculk_block, 0, 2);
		world.setBlock(i + 19, j, k + 18, sculk_block, 0, 2);
		world.setBlock(i + 20, j, k + 18, sculk_block, 0, 2);
		world.setBlock(i + 21, j, k + 18, sculk_block, 0, 2);
		world.setBlock(i + 22, j, k + 18, sculk_block, 0, 2);
		world.setBlock(i + 23, j, k + 18, sculk_block, 0, 2);
		world.setBlock(i + 24, j, k + 18, sculk_block, 0, 2);
		world.setBlock(i + 25, j, k + 18, sculk_block, 0, 2);
		world.setBlock(i + 26, j, k + 18, sculk_block, 0, 2);
		world.setBlock(i + 27, j, k + 18, sculk_block, 0, 2);
		world.setBlock(i + 28, j, k + 18, sculk_block, 0, 2);
		world.setBlock(i + 29, j, k + 18, sculk_block, 0, 2);
		world.setBlock(i + 30, j, k + 18, sculk_block, 0, 2);
		world.setBlock(i + 31, j, k + 18, sculk_block, 0, 2);
		world.setBlock(i + 32, j, k + 18, sculk_block, 0, 2);
		world.setBlock(i + 33, j, k + 18, sculk_block, 0, 2);
		world.setBlock(i, j, k + 19, sculk_block, 0, 2);
		world.setBlock(i + 1, j, k + 19, sculk_block, 0, 2);
		world.setBlock(i + 2, j, k + 19, sculk_block, 0, 2);
		world.setBlock(i + 3, j, k + 19, sculk_block, 0, 2);
		world.setBlock(i + 4, j, k + 19, sculk_block, 0, 2);
		world.setBlock(i + 5, j, k + 19, sculk_block, 0, 2);
		world.setBlock(i + 6, j, k + 19, sculk_block, 0, 2);
		world.setBlock(i + 7, j, k + 19, sculk_block, 0, 2);
		world.setBlock(i + 8, j, k + 19, sculk_block, 0, 2);
		world.setBlock(i + 9, j, k + 19, sculk_block, 0, 2);
		world.setBlock(i + 10, j, k + 19, sculk_block, 0, 2);
		world.setBlock(i + 11, j, k + 19, sculk_block, 0, 2);
		world.setBlock(i + 12, j, k + 19, sculk_block, 0, 2);
		world.setBlock(i + 13, j, k + 19, sculk_block, 0, 2);
		world.setBlock(i + 14, j, k + 19, sculk_block, 0, 2);
		world.setBlock(i + 15, j, k + 19, sculk_block, 0, 2);
		world.setBlock(i + 16, j, k + 19, sculk_block, 0, 2);
		world.setBlock(i + 17, j, k + 19, sculk_block, 0, 2);
		world.setBlock(i + 18, j, k + 19, sculk_block, 0, 2);
		world.setBlock(i + 19, j, k + 19, sculk_block, 0, 2);
		world.setBlock(i + 20, j, k + 19, sculk_block, 0, 2);
		world.setBlock(i + 21, j, k + 19, sculk_block, 0, 2);
		world.setBlock(i + 22, j, k + 19, sculk_block, 0, 2);
		world.setBlock(i + 23, j, k + 19, sculk_block, 0, 2);
		world.setBlock(i + 24, j, k + 19, sculk_block, 0, 2);
		world.setBlock(i + 25, j, k + 19, sculk_block, 0, 2);
		world.setBlock(i + 26, j, k + 19, sculk_block, 0, 2);
		world.setBlock(i + 27, j, k + 19, sculk_block, 0, 2);
		world.setBlock(i + 28, j, k + 19, sculk_block, 0, 2);
		world.setBlock(i + 29, j, k + 19, sculk_block, 0, 2);
		world.setBlock(i + 30, j, k + 19, sculk_block, 0, 2);
		world.setBlock(i + 31, j, k + 19, sculk_block, 0, 2);
		world.setBlock(i + 32, j, k + 19, sculk_block, 0, 2);
		world.setBlock(i + 33, j, k + 19, sculk_block, 0, 2);
		world.setBlock(i + 34, j, k + 19, sculk_block, 0, 2);
		world.setBlock(i, j, k + 20, sculk_block, 0, 2);
		world.setBlock(i + 1, j, k + 20, sculk_block, 0, 2);
		world.setBlock(i + 2, j, k + 20, sculk_block, 0, 2);
		world.setBlock(i + 3, j, k + 20, sculk_block, 0, 2);
		world.setBlock(i + 4, j, k + 20, sculk_block, 0, 2);
		world.setBlock(i + 5, j, k + 20, sculk_block, 0, 2);
		world.setBlock(i + 6, j, k + 20, sculk_block, 0, 2);
		world.setBlock(i + 7, j, k + 20, sculk_block, 0, 2);
		world.setBlock(i + 8, j, k + 20, sculk_block, 0, 2);
		world.setBlock(i + 9, j, k + 20, sculk_block, 0, 2);
		world.setBlock(i + 10, j, k + 20, sculk_block, 0, 2);
		world.setBlock(i + 11, j, k + 20, sculk_block, 0, 2);
		world.setBlock(i + 12, j, k + 20, sculk_block, 0, 2);
		world.setBlock(i + 13, j, k + 20, sculk_block, 0, 2);
		world.setBlock(i + 14, j, k + 20, sculk_block, 0, 2);
		world.setBlock(i + 15, j, k + 20, sculk_block, 0, 2);
		world.setBlock(i + 16, j, k + 20, sculk_block, 0, 2);
		world.setBlock(i + 17, j, k + 20, sculk_block, 0, 2);
		world.setBlock(i + 18, j, k + 20, sculk_block, 0, 2);
		world.setBlock(i + 19, j, k + 20, sculk_block, 0, 2);
		world.setBlock(i + 20, j, k + 20, sculk_block, 0, 2);
		world.setBlock(i + 21, j, k + 20, sculk_block, 0, 2);
		world.setBlock(i + 22, j, k + 20, sculk_block, 0, 2);
		world.setBlock(i + 23, j, k + 20, sculk_block, 0, 2);
		world.setBlock(i + 24, j, k + 20, sculk_block, 0, 2);
		world.setBlock(i + 25, j, k + 20, sculk_block, 0, 2);
		world.setBlock(i + 26, j, k + 20, sculk_block, 0, 2);
		world.setBlock(i + 27, j, k + 20, sculk_block, 0, 2);
		world.setBlock(i + 28, j, k + 20, sculk_block, 0, 2);
		world.setBlock(i + 29, j, k + 20, sculk_block, 0, 2);
		world.setBlock(i + 30, j, k + 20, sculk_block, 0, 2);
		world.setBlock(i + 31, j, k + 20, sculk_block, 0, 2);
		world.setBlock(i + 32, j, k + 20, sculk_block, 0, 2);
		world.setBlock(i + 33, j, k + 20, sculk_block, 0, 2);
		world.setBlock(i + 34, j, k + 20, sculk_block, 0, 2);
		world.setBlock(i, j, k + 21, sculk_block, 0, 2);
		world.setBlock(i + 1, j, k + 21, sculk_block, 0, 2);
		world.setBlock(i + 2, j, k + 21, sculk_block, 0, 2);
		world.setBlock(i + 3, j, k + 21, sculk_block, 0, 2);
		world.setBlock(i + 4, j, k + 21, sculk_block, 0, 2);
		world.setBlock(i + 5, j, k + 21, sculk_block, 0, 2);
		world.setBlock(i + 6, j, k + 21, sculk_block, 0, 2);
		world.setBlock(i + 7, j, k + 21, sculk_block, 0, 2);
		world.setBlock(i + 8, j, k + 21, sculk_block, 0, 2);
		world.setBlock(i + 9, j, k + 21, sculk_block, 0, 2);
		world.setBlock(i + 10, j, k + 21, sculk_block, 0, 2);
		world.setBlock(i + 11, j, k + 21, sculk_block, 0, 2);
		world.setBlock(i + 12, j, k + 21, sculk_block, 0, 2);
		world.setBlock(i + 13, j, k + 21, sculk_block, 0, 2);
		world.setBlock(i + 14, j, k + 21, sculk_block, 0, 2);
		world.setBlock(i + 15, j, k + 21, sculk_block, 0, 2);
		world.setBlock(i + 16, j, k + 21, sculk_block, 0, 2);
		world.setBlock(i + 17, j, k + 21, sculk_block, 0, 2);
		world.setBlock(i + 18, j, k + 21, sculk_block, 0, 2);
		world.setBlock(i + 19, j, k + 21, sculk_block, 0, 2);
		world.setBlock(i + 20, j, k + 21, sculk_block, 0, 2);
		world.setBlock(i + 21, j, k + 21, sculk_block, 0, 2);
		world.setBlock(i + 22, j, k + 21, sculk_block, 0, 2);
		world.setBlock(i + 23, j, k + 21, sculk_block, 0, 2);
		world.setBlock(i + 24, j, k + 21, sculk_block, 0, 2);
		world.setBlock(i + 25, j, k + 21, sculk_block, 0, 2);
		world.setBlock(i + 26, j, k + 21, sculk_block, 0, 2);
		world.setBlock(i + 27, j, k + 21, sculk_block, 0, 2);
		world.setBlock(i + 28, j, k + 21, sculk_block, 0, 2);
		world.setBlock(i + 29, j, k + 21, sculk_block, 0, 2);
		world.setBlock(i + 30, j, k + 21, sculk_block, 0, 2);
		world.setBlock(i + 31, j, k + 21, sculk_block, 0, 2);
		world.setBlock(i + 32, j, k + 21, sculk_block, 0, 2);
		world.setBlock(i + 33, j, k + 21, sculk_block, 0, 2);
		world.setBlock(i + 34, j, k + 21, sculk_block, 0, 2);
		world.setBlock(i, j, k + 22, sculk_block, 0, 2);
		world.setBlock(i + 1, j, k + 22, sculk_block, 0, 2);
		world.setBlock(i + 2, j, k + 22, sculk_block, 0, 2);
		world.setBlock(i + 3, j, k + 22, sculk_block, 0, 2);
		world.setBlock(i + 4, j, k + 22, sculk_block, 0, 2);
		world.setBlock(i + 5, j, k + 22, sculk_block, 0, 2);
		world.setBlock(i + 6, j, k + 22, sculk_block, 0, 2);
		world.setBlock(i + 7, j, k + 22, sculk_block, 0, 2);
		world.setBlock(i + 8, j, k + 22, sculk_block, 0, 2);
		world.setBlock(i + 9, j, k + 22, sculk_block, 0, 2);
		world.setBlock(i + 10, j, k + 22, sculk_block, 0, 2);
		world.setBlock(i + 11, j, k + 22, sculk_block, 0, 2);
		world.setBlock(i + 12, j, k + 22, sculk_block, 0, 2);
		world.setBlock(i + 13, j, k + 22, sculk_block, 0, 2);
		world.setBlock(i + 14, j, k + 22, sculk_block, 0, 2);
		world.setBlock(i + 15, j, k + 22, sculk_block, 0, 2);
		world.setBlock(i + 16, j, k + 22, sculk_block, 0, 2);
		world.setBlock(i + 17, j, k + 22, sculk_block, 0, 2);
		world.setBlock(i + 18, j, k + 22, sculk_block, 0, 2);
		world.setBlock(i + 19, j, k + 22, sculk_block, 0, 2);
		world.setBlock(i + 20, j, k + 22, sculk_block, 0, 2);
		world.setBlock(i + 21, j, k + 22, sculk_block, 0, 2);
		world.setBlock(i + 22, j, k + 22, sculk_block, 0, 2);
		world.setBlock(i + 23, j, k + 22, sculk_block, 0, 2);
		world.setBlock(i + 24, j, k + 22, sculk_block, 0, 2);
		world.setBlock(i + 25, j, k + 22, sculk_block, 0, 2);
		world.setBlock(i + 26, j, k + 22, sculk_block, 0, 2);
		world.setBlock(i + 27, j, k + 22, sculk_block, 0, 2);
		world.setBlock(i + 28, j, k + 22, sculk_block, 0, 2);
		world.setBlock(i + 29, j, k + 22, sculk_block, 0, 2);
		world.setBlock(i + 30, j, k + 22, sculk_block, 0, 2);
		world.setBlock(i + 31, j, k + 22, sculk_block, 0, 2);
		world.setBlock(i + 32, j, k + 22, sculk_block, 0, 2);
		world.setBlock(i + 33, j, k + 22, sculk_block, 0, 2);
		world.setBlock(i + 34, j, k + 22, sculk_block, 0, 2);
		world.setBlock(i, j, k + 23, sculk_block, 0, 2);
		world.setBlock(i + 1, j, k + 23, sculk_block, 0, 2);
		world.setBlock(i + 2, j, k + 23, sculk_block, 0, 2);
		world.setBlock(i + 3, j, k + 23, sculk_block, 0, 2);
		world.setBlock(i + 4, j, k + 23, sculk_block, 0, 2);
		world.setBlock(i + 5, j, k + 23, sculk_block, 0, 2);
		world.setBlock(i + 6, j, k + 23, sculk_block, 0, 2);
		world.setBlock(i + 7, j, k + 23, sculk_block, 0, 2);
		world.setBlock(i + 8, j, k + 23, sculk_block, 0, 2);
		world.setBlock(i + 9, j, k + 23, sculk_block, 0, 2);
		world.setBlock(i + 10, j, k + 23, sculk_block, 0, 2);
		world.setBlock(i + 11, j, k + 23, sculk_block, 0, 2);
		world.setBlock(i + 12, j, k + 23, sculk_block, 0, 2);
		world.setBlock(i + 13, j, k + 23, sculk_block, 0, 2);
		world.setBlock(i + 14, j, k + 23, sculk_block, 0, 2);
		world.setBlock(i + 15, j, k + 23, sculk_block, 0, 2);
		world.setBlock(i + 16, j, k + 23, sculk_block, 0, 2);
		world.setBlock(i + 17, j, k + 23, sculk_block, 0, 2);
		world.setBlock(i + 18, j, k + 23, sculk_block, 0, 2);
		world.setBlock(i + 19, j, k + 23, sculk_block, 0, 2);
		world.setBlock(i + 20, j, k + 23, sculk_block, 0, 2);
		world.setBlock(i + 21, j, k + 23, sculk_block, 0, 2);
		world.setBlock(i + 22, j, k + 23, sculk_block, 0, 2);
		world.setBlock(i + 23, j, k + 23, sculk_block, 0, 2);
		world.setBlock(i + 24, j, k + 23, sculk_block, 0, 2);
		world.setBlock(i + 25, j, k + 23, sculk_block, 0, 2);
		world.setBlock(i + 26, j, k + 23, sculk_block, 0, 2);
		world.setBlock(i + 27, j, k + 23, sculk_block, 0, 2);
		world.setBlock(i + 28, j, k + 23, sculk_block, 0, 2);
		world.setBlock(i + 29, j, k + 23, sculk_block, 0, 2);
		world.setBlock(i + 30, j, k + 23, sculk_block, 0, 2);
		world.setBlock(i + 31, j, k + 23, sculk_block, 0, 2);
		world.setBlock(i + 32, j, k + 23, sculk_block, 0, 2);
		world.setBlock(i + 33, j, k + 23, sculk_block, 0, 2);
		world.setBlock(i + 34, j, k + 23, sculk_block, 0, 2);
		world.setBlock(i, j, k + 24, sculk_block, 0, 2);
		world.setBlock(i + 1, j, k + 24, sculk_block, 0, 2);
		world.setBlock(i + 2, j, k + 24, sculk_block, 0, 2);
		world.setBlock(i + 3, j, k + 24, sculk_block, 0, 2);
		world.setBlock(i + 4, j, k + 24, sculk_block, 0, 2);
		world.setBlock(i + 5, j, k + 24, sculk_block, 0, 2);
		world.setBlock(i + 6, j, k + 24, sculk_block, 0, 2);
		world.setBlock(i + 7, j, k + 24, sculk_block, 0, 2);
		world.setBlock(i + 8, j, k + 24, sculk_block, 0, 2);
		world.setBlock(i + 9, j, k + 24, sculk_block, 0, 2);
		world.setBlock(i + 10, j, k + 24, sculk_block, 0, 2);
		world.setBlock(i + 11, j, k + 24, sculk_block, 0, 2);
		world.setBlock(i + 12, j, k + 24, sculk_block, 0, 2);
		world.setBlock(i + 13, j, k + 24, sculk_block, 0, 2);
		world.setBlock(i + 14, j, k + 24, sculk_block, 0, 2);
		world.setBlock(i + 15, j, k + 24, sculk_block, 0, 2);
		world.setBlock(i + 16, j, k + 24, sculk_block, 0, 2);
		world.setBlock(i + 17, j, k + 24, sculk_block, 0, 2);
		world.setBlock(i + 18, j, k + 24, sculk_block, 0, 2);
		world.setBlock(i + 19, j, k + 24, sculk_block, 0, 2);
		world.setBlock(i + 20, j, k + 24, sculk_block, 0, 2);
		world.setBlock(i + 21, j, k + 24, sculk_block, 0, 2);
		world.setBlock(i + 22, j, k + 24, sculk_block, 0, 2);
		world.setBlock(i + 23, j, k + 24, sculk_block, 0, 2);
		world.setBlock(i + 24, j, k + 24, sculk_block, 0, 2);
		world.setBlock(i + 25, j, k + 24, sculk_block, 0, 2);
		world.setBlock(i + 26, j, k + 24, sculk_block, 0, 2);
		world.setBlock(i + 27, j, k + 24, sculk_block, 0, 2);
		world.setBlock(i + 28, j, k + 24, sculk_block, 0, 2);
		world.setBlock(i + 29, j, k + 24, sculk_block, 0, 2);
		world.setBlock(i + 30, j, k + 24, sculk_block, 0, 2);
		world.setBlock(i + 31, j, k + 24, sculk_block, 0, 2);
		world.setBlock(i + 32, j, k + 24, sculk_block, 0, 2);
		world.setBlock(i + 33, j, k + 24, sculk_block, 0, 2);
		world.setBlock(i, j, k + 25, sculk_block, 0, 2);
		world.setBlock(i + 1, j, k + 25, sculk_block, 0, 2);
		world.setBlock(i + 2, j, k + 25, sculk_block, 0, 2);
		world.setBlock(i + 3, j, k + 25, sculk_block, 0, 2);
		world.setBlock(i + 4, j, k + 25, sculk_block, 0, 2);
		world.setBlock(i + 5, j, k + 25, sculk_block, 0, 2);
		world.setBlock(i + 6, j, k + 25, sculk_block, 0, 2);
		world.setBlock(i + 7, j, k + 25, sculk_block, 0, 2);
		world.setBlock(i + 8, j, k + 25, sculk_block, 0, 2);
		world.setBlock(i + 9, j, k + 25, sculk_block, 0, 2);
		world.setBlock(i + 10, j, k + 25, sculk_block, 0, 2);
		world.setBlock(i + 11, j, k + 25, sculk_block, 0, 2);
		world.setBlock(i + 12, j, k + 25, sculk_block, 0, 2);
		world.setBlock(i + 13, j, k + 25, sculk_block, 0, 2);
		world.setBlock(i + 14, j, k + 25, sculk_block, 0, 2);
		world.setBlock(i + 15, j, k + 25, sculk_block, 0, 2);
		world.setBlock(i + 16, j, k + 25, sculk_block, 0, 2);
		world.setBlock(i + 17, j, k + 25, sculk_block, 0, 2);
		world.setBlock(i + 18, j, k + 25, sculk_block, 0, 2);
		world.setBlock(i + 19, j, k + 25, sculk_block, 0, 2);
		world.setBlock(i + 20, j, k + 25, sculk_block, 0, 2);
		world.setBlock(i + 21, j, k + 25, sculk_block, 0, 2);
		world.setBlock(i + 22, j, k + 25, sculk_block, 0, 2);
		world.setBlock(i + 23, j, k + 25, sculk_block, 0, 2);
		world.setBlock(i + 24, j, k + 25, sculk_block, 0, 2);
		world.setBlock(i + 25, j, k + 25, sculk_block, 0, 2);
		world.setBlock(i + 26, j, k + 25, sculk_block, 0, 2);
		world.setBlock(i + 27, j, k + 25, sculk_block, 0, 2);
		world.setBlock(i + 28, j, k + 25, sculk_block, 0, 2);
		world.setBlock(i + 29, j, k + 25, sculk_block, 0, 2);
		world.setBlock(i + 30, j, k + 25, sculk_block, 0, 2);
		world.setBlock(i + 31, j, k + 25, sculk_block, 0, 2);
		world.setBlock(i + 32, j, k + 25, sculk_block, 0, 2);
		world.setBlock(i, j, k + 26, sculk_block, 0, 2);
		world.setBlock(i + 1, j, k + 26, sculk_block, 0, 2);
		world.setBlock(i + 2, j, k + 26, sculk_block, 0, 2);
		world.setBlock(i + 3, j, k + 26, sculk_block, 0, 2);
		world.setBlock(i + 4, j, k + 26, sculk_block, 0, 2);
		world.setBlock(i + 5, j, k + 26, sculk_block, 0, 2);
		world.setBlock(i + 6, j, k + 26, sculk_block, 0, 2);
		world.setBlock(i + 7, j, k + 26, sculk_block, 0, 2);
		world.setBlock(i + 8, j, k + 26, sculk_block, 0, 2);
		world.setBlock(i + 9, j, k + 26, sculk_block, 0, 2);
		world.setBlock(i + 10, j, k + 26, sculk_block, 0, 2);
		world.setBlock(i + 11, j, k + 26, sculk_block, 0, 2);
		world.setBlock(i + 12, j, k + 26, sculk_block, 0, 2);
		world.setBlock(i + 13, j, k + 26, sculk_block, 0, 2);
		world.setBlock(i + 14, j, k + 26, sculk_block, 0, 2);
		world.setBlock(i + 15, j, k + 26, sculk_block, 0, 2);
		world.setBlock(i + 16, j, k + 26, sculk_block, 0, 2);
		world.setBlock(i + 17, j, k + 26, sculk_block, 0, 2);
		world.setBlock(i + 18, j, k + 26, sculk_block, 0, 2);
		world.setBlock(i + 19, j, k + 26, sculk_block, 0, 2);
		world.setBlock(i + 20, j, k + 26, sculk_block, 0, 2);
		world.setBlock(i + 21, j, k + 26, sculk_block, 0, 2);
		world.setBlock(i + 22, j, k + 26, sculk_block, 0, 2);
		world.setBlock(i + 23, j, k + 26, sculk_block, 0, 2);
		world.setBlock(i + 24, j, k + 26, sculk_block, 0, 2);
		world.setBlock(i + 25, j, k + 26, sculk_block, 0, 2);
		world.setBlock(i + 26, j, k + 26, sculk_block, 0, 2);
		world.setBlock(i + 27, j, k + 26, sculk_block, 0, 2);
		world.setBlock(i + 28, j, k + 26, sculk_block, 0, 2);
		world.setBlock(i + 29, j, k + 26, sculk_block, 0, 2);
		world.setBlock(i + 30, j, k + 26, sculk_block, 0, 2);
		world.setBlock(i + 31, j, k + 26, sculk_block, 0, 2);
		world.setBlock(i, j, k + 27, sculk_block, 0, 2);
		world.setBlock(i + 1, j, k + 27, sculk_block, 0, 2);
		world.setBlock(i + 2, j, k + 27, sculk_block, 0, 2);
		world.setBlock(i + 3, j, k + 27, sculk_block, 0, 2);
		world.setBlock(i + 4, j, k + 27, sculk_block, 0, 2);
		world.setBlock(i + 5, j, k + 27, sculk_block, 0, 2);
		world.setBlock(i + 6, j, k + 27, sculk_block, 0, 2);
		world.setBlock(i + 7, j, k + 27, sculk_block, 0, 2);
		world.setBlock(i + 8, j, k + 27, sculk_block, 0, 2);
		world.setBlock(i + 9, j, k + 27, sculk_block, 0, 2);
		world.setBlock(i + 10, j, k + 27, sculk_block, 0, 2);
		world.setBlock(i + 11, j, k + 27, sculk_block, 0, 2);
		world.setBlock(i + 12, j, k + 27, sculk_block, 0, 2);
		world.setBlock(i + 13, j, k + 27, sculk_block, 0, 2);
		world.setBlock(i + 14, j, k + 27, sculk_block, 0, 2);
		world.setBlock(i + 15, j, k + 27, sculk_block, 0, 2);
		world.setBlock(i + 16, j, k + 27, sculk_block, 0, 2);
		world.setBlock(i + 17, j, k + 27, sculk_block, 0, 2);
		world.setBlock(i + 18, j, k + 27, sculk_block, 0, 2);
		world.setBlock(i + 19, j, k + 27, sculk_block, 0, 2);
		world.setBlock(i + 20, j, k + 27, sculk_block, 0, 2);
		world.setBlock(i + 21, j, k + 27, sculk_block, 0, 2);
		world.setBlock(i + 22, j, k + 27, sculk_block, 0, 2);
		world.setBlock(i + 23, j, k + 27, sculk_block, 0, 2);
		world.setBlock(i + 24, j, k + 27, sculk_block, 0, 2);
		world.setBlock(i + 25, j, k + 27, sculk_block, 0, 2);
		world.setBlock(i + 26, j, k + 27, sculk_block, 0, 2);
		world.setBlock(i + 27, j, k + 27, sculk_block, 0, 2);
		world.setBlock(i + 28, j, k + 27, sculk_block, 0, 2);
		world.setBlock(i + 29, j, k + 27, sculk_block, 0, 2);
		world.setBlock(i + 30, j, k + 27, sculk_block, 0, 2);
		world.setBlock(i + 1, j, k + 28, sculk_block, 0, 2);
		world.setBlock(i + 2, j, k + 28, sculk_block, 0, 2);
		world.setBlock(i + 3, j, k + 28, sculk_block, 0, 2);
		world.setBlock(i + 4, j, k + 28, sculk_block, 0, 2);
		world.setBlock(i + 5, j, k + 28, sculk_block, 0, 2);
		world.setBlock(i + 6, j, k + 28, sculk_block, 0, 2);
		world.setBlock(i + 7, j, k + 28, sculk_block, 0, 2);
		world.setBlock(i + 8, j, k + 28, sculk_block, 0, 2);
		world.setBlock(i + 9, j, k + 28, sculk_block, 0, 2);
		world.setBlock(i + 10, j, k + 28, sculk_block, 0, 2);
		world.setBlock(i + 11, j, k + 28, sculk_block, 0, 2);
		world.setBlock(i + 12, j, k + 28, sculk_block, 0, 2);
		world.setBlock(i + 13, j, k + 28, sculk_block, 0, 2);
		world.setBlock(i + 14, j, k + 28, sculk_block, 0, 2);
		world.setBlock(i + 15, j, k + 28, sculk_block, 0, 2);
		world.setBlock(i + 16, j, k + 28, sculk_block, 0, 2);
		world.setBlock(i + 17, j, k + 28, sculk_block, 0, 2);
		world.setBlock(i + 18, j, k + 28, sculk_block, 0, 2);
		world.setBlock(i + 19, j, k + 28, sculk_block, 0, 2);
		world.setBlock(i + 20, j, k + 28, sculk_block, 0, 2);
		world.setBlock(i + 21, j, k + 28, sculk_block, 0, 2);
		world.setBlock(i + 22, j, k + 28, sculk_block, 0, 2);
		world.setBlock(i + 23, j, k + 28, sculk_block, 0, 2);
		world.setBlock(i + 24, j, k + 28, sculk_block, 0, 2);
		world.setBlock(i + 25, j, k + 28, sculk_block, 0, 2);
		world.setBlock(i + 26, j, k + 28, sculk_block, 0, 2);
		world.setBlock(i + 27, j, k + 28, sculk_block, 0, 2);
		world.setBlock(i + 28, j, k + 28, sculk_block, 0, 2);
		world.setBlock(i + 29, j, k + 28, sculk_block, 0, 2);
		world.setBlock(i + 2, j, k + 29, sculk_block, 0, 2);
		world.setBlock(i + 3, j, k + 29, sculk_block, 0, 2);
		world.setBlock(i + 4, j, k + 29, sculk_block, 0, 2);
		world.setBlock(i + 5, j, k + 29, sculk_block, 0, 2);
		world.setBlock(i + 6, j, k + 29, sculk_block, 0, 2);
		world.setBlock(i + 7, j, k + 29, sculk_block, 0, 2);
		world.setBlock(i + 8, j, k + 29, sculk_block, 0, 2);
		world.setBlock(i + 9, j, k + 29, sculk_block, 0, 2);
		world.setBlock(i + 10, j, k + 29, sculk_block, 0, 2);
		world.setBlock(i + 11, j, k + 29, sculk_block, 0, 2);
		world.setBlock(i + 12, j, k + 29, sculk_block, 0, 2);
		world.setBlock(i + 13, j, k + 29, sculk_block, 0, 2);
		world.setBlock(i + 14, j, k + 29, sculk_block, 0, 2);
		world.setBlock(i + 15, j, k + 29, sculk_block, 0, 2);
		world.setBlock(i + 16, j, k + 29, sculk_block, 0, 2);
		world.setBlock(i + 17, j, k + 29, sculk_block, 0, 2);
		world.setBlock(i + 18, j, k + 29, sculk_block, 0, 2);
		world.setBlock(i + 19, j, k + 29, sculk_block, 0, 2);
		world.setBlock(i + 20, j, k + 29, sculk_block, 0, 2);
		world.setBlock(i + 21, j, k + 29, sculk_block, 0, 2);
		world.setBlock(i + 22, j, k + 29, sculk_block, 0, 2);
		world.setBlock(i + 23, j, k + 29, sculk_block, 0, 2);
		world.setBlock(i + 24, j, k + 29, sculk_block, 0, 2);
		world.setBlock(i + 25, j, k + 29, sculk_block, 0, 2);
		world.setBlock(i + 26, j, k + 29, sculk_block, 0, 2);
		world.setBlock(i + 27, j, k + 29, sculk_block, 0, 2);
		world.setBlock(i + 28, j, k + 29, sculk_block, 0, 2);
		world.setBlock(i + 3, j, k + 30, sculk_block, 0, 2);
		world.setBlock(i + 4, j, k + 30, sculk_block, 0, 2);
		world.setBlock(i + 5, j, k + 30, sculk_block, 0, 2);
		world.setBlock(i + 6, j, k + 30, sculk_block, 0, 2);
		world.setBlock(i + 7, j, k + 30, sculk_block, 0, 2);
		world.setBlock(i + 8, j, k + 30, sculk_block, 0, 2);
		world.setBlock(i + 9, j, k + 30, sculk_block, 0, 2);
		world.setBlock(i + 10, j, k + 30, sculk_block, 0, 2);
		world.setBlock(i + 11, j, k + 30, sculk_block, 0, 2);
		world.setBlock(i + 12, j, k + 30, sculk_block, 0, 2);
		world.setBlock(i + 13, j, k + 30, sculk_block, 0, 2);
		world.setBlock(i + 14, j, k + 30, sculk_block, 0, 2);
		world.setBlock(i + 15, j, k + 30, sculk_block, 0, 2);
		world.setBlock(i + 16, j, k + 30, sculk_block, 0, 2);
		world.setBlock(i + 17, j, k + 30, sculk_block, 0, 2);
		world.setBlock(i + 18, j, k + 30, sculk_block, 0, 2);
		world.setBlock(i + 19, j, k + 30, sculk_block, 0, 2);
		world.setBlock(i + 20, j, k + 30, sculk_block, 0, 2);
		world.setBlock(i + 21, j, k + 30, sculk_block, 0, 2);
		world.setBlock(i + 22, j, k + 30, sculk_block, 0, 2);
		world.setBlock(i + 23, j, k + 30, sculk_block, 0, 2);
		world.setBlock(i + 24, j, k + 30, sculk_block, 0, 2);
		world.setBlock(i + 25, j, k + 30, sculk_block, 0, 2);
		world.setBlock(i + 26, j, k + 30, sculk_block, 0, 2);
		world.setBlock(i + 27, j, k + 30, sculk_block, 0, 2);
		world.setBlock(i + 4, j, k + 31, sculk_block, 0, 2);
		world.setBlock(i + 5, j, k + 31, sculk_block, 0, 2);
		world.setBlock(i + 6, j, k + 31, sculk_block, 0, 2);
		world.setBlock(i + 7, j, k + 31, sculk_block, 0, 2);
		world.setBlock(i + 8, j, k + 31, sculk_block, 0, 2);
		world.setBlock(i + 9, j, k + 31, sculk_block, 0, 2);
		world.setBlock(i + 10, j, k + 31, sculk_block, 0, 2);
		world.setBlock(i + 11, j, k + 31, sculk_block, 0, 2);
		world.setBlock(i + 12, j, k + 31, sculk_block, 0, 2);
		world.setBlock(i + 13, j, k + 31, sculk_block, 0, 2);
		world.setBlock(i + 14, j, k + 31, sculk_block, 0, 2);
		world.setBlock(i + 15, j, k + 31, sculk_block, 0, 2);
		world.setBlock(i + 16, j, k + 31, sculk_block, 0, 2);
		world.setBlock(i + 17, j, k + 31, sculk_block, 0, 2);
		world.setBlock(i + 18, j, k + 31, sculk_block, 0, 2);
		world.setBlock(i + 19, j, k + 31, sculk_block, 0, 2);
		world.setBlock(i + 20, j, k + 31, sculk_block, 0, 2);
		world.setBlock(i + 21, j, k + 31, sculk_block, 0, 2);
		world.setBlock(i + 22, j, k + 31, sculk_block, 0, 2);
		world.setBlock(i + 23, j, k + 31, sculk_block, 0, 2);
		world.setBlock(i + 24, j, k + 31, sculk_block, 0, 2);
		world.setBlock(i + 25, j, k + 31, sculk_block, 0, 2);
		world.setBlock(i + 26, j, k + 31, sculk_block, 0, 2);
		world.setBlock(i + 5, j, k + 32, sculk_block, 0, 2);
		world.setBlock(i + 6, j, k + 32, sculk_block, 0, 2);
		world.setBlock(i + 7, j, k + 32, sculk_block, 0, 2);
		world.setBlock(i + 8, j, k + 32, sculk_block, 0, 2);
		world.setBlock(i + 9, j, k + 32, sculk_block, 0, 2);
		world.setBlock(i + 10, j, k + 32, sculk_block, 0, 2);
		world.setBlock(i + 11, j, k + 32, sculk_block, 0, 2);
		world.setBlock(i + 12, j, k + 32, sculk_block, 0, 2);
		world.setBlock(i + 13, j, k + 32, sculk_block, 0, 2);
		world.setBlock(i + 14, j, k + 32, sculk_block, 0, 2);
		world.setBlock(i + 15, j, k + 32, sculk_block, 0, 2);
		world.setBlock(i + 16, j, k + 32, sculk_block, 0, 2);
		world.setBlock(i + 17, j, k + 32, sculk_block, 0, 2);
		world.setBlock(i + 18, j, k + 32, sculk_block, 0, 2);
		world.setBlock(i + 19, j, k + 32, sculk_block, 0, 2);
		world.setBlock(i + 20, j, k + 32, sculk_block, 0, 2);
		world.setBlock(i + 21, j, k + 32, sculk_block, 0, 2);
		world.setBlock(i + 22, j, k + 32, sculk_block, 0, 2);
		world.setBlock(i + 23, j, k + 32, sculk_block, 0, 2);
		world.setBlock(i + 24, j, k + 32, sculk_block, 0, 2);
		world.setBlock(i + 25, j, k + 32, sculk_block, 0, 2);
		world.setBlock(i + 6, j, k + 33, sculk_block, 0, 2);
		world.setBlock(i + 7, j, k + 33, sculk_block, 0, 2);
		world.setBlock(i + 8, j, k + 33, sculk_block, 0, 2);
		world.setBlock(i + 9, j, k + 33, sculk_block, 0, 2);
		world.setBlock(i + 10, j, k + 33, sculk_block, 0, 2);
		world.setBlock(i + 11, j, k + 33, sculk_block, 0, 2);
		world.setBlock(i + 12, j, k + 33, sculk_block, 0, 2);
		world.setBlock(i + 13, j, k + 33, sculk_block, 0, 2);
		world.setBlock(i + 14, j, k + 33, sculk_block, 0, 2);
		world.setBlock(i + 15, j, k + 33, sculk_block, 0, 2);
		world.setBlock(i + 16, j, k + 33, sculk_block, 0, 2);
		world.setBlock(i + 17, j, k + 33, sculk_block, 0, 2);
		world.setBlock(i + 18, j, k + 33, sculk_block, 0, 2);
		world.setBlock(i + 19, j, k + 33, sculk_block, 0, 2);
		world.setBlock(i + 20, j, k + 33, sculk_block, 0, 2);
		world.setBlock(i + 21, j, k + 33, sculk_block, 0, 2);
		world.setBlock(i + 22, j, k + 33, sculk_block, 0, 2);
		world.setBlock(i + 23, j, k + 33, sculk_block, 0, 2);
		world.setBlock(i + 24, j, k + 33, sculk_block, 0, 2);
		world.setBlock(i + 7, j, k + 34, sculk_block, 0, 2);
		world.setBlock(i + 8, j, k + 34, sculk_block, 0, 2);
		world.setBlock(i + 9, j, k + 34, sculk_block, 0, 2);
		world.setBlock(i + 10, j, k + 34, sculk_block, 0, 2);
		world.setBlock(i + 11, j, k + 34, sculk_block, 0, 2);
		world.setBlock(i + 12, j, k + 34, sculk_block, 0, 2);
		world.setBlock(i + 13, j, k + 34, sculk_block, 0, 2);
		world.setBlock(i + 14, j, k + 34, sculk_block, 0, 2);
		world.setBlock(i + 15, j, k + 34, sculk_block, 0, 2);
		world.setBlock(i + 16, j, k + 34, sculk_block, 0, 2);
		world.setBlock(i + 17, j, k + 34, sculk_block, 0, 2);
		world.setBlock(i + 18, j, k + 34, sculk_block, 0, 2);
		world.setBlock(i + 19, j, k + 34, sculk_block, 0, 2);
		world.setBlock(i + 20, j, k + 34, sculk_block, 0, 2);
		world.setBlock(i + 21, j, k + 34, sculk_block, 0, 2);
		world.setBlock(i + 22, j, k + 34, sculk_block, 0, 2);
		world.setBlock(i + 23, j, k + 34, sculk_block, 0, 2);
		world.setBlock(i + 8, j, k + 35, sculk_block, 0, 2);
		world.setBlock(i + 9, j, k + 35, sculk_block, 0, 2);
		world.setBlock(i + 10, j, k + 35, sculk_block, 0, 2);
		world.setBlock(i + 11, j, k + 35, sculk_block, 0, 2);
		world.setBlock(i + 12, j, k + 35, sculk_block, 0, 2);
		world.setBlock(i + 13, j, k + 35, sculk_block, 0, 2);
		world.setBlock(i + 14, j, k + 35, sculk_block, 0, 2);
		world.setBlock(i + 15, j, k + 35, sculk_block, 0, 2);
		world.setBlock(i + 16, j, k + 35, sculk_block, 0, 2);
		world.setBlock(i + 17, j, k + 35, sculk_block, 0, 2);
		world.setBlock(i + 18, j, k + 35, sculk_block, 0, 2);
		world.setBlock(i + 19, j, k + 35, sculk_block, 0, 2);
		world.setBlock(i + 20, j, k + 35, sculk_block, 0, 2);
		world.setBlock(i + 21, j, k + 35, sculk_block, 0, 2);
		world.setBlock(i + 22, j, k + 35, sculk_block, 0, 2);
		world.setBlock(i + 9, j, k + 36, sculk_block, 0, 2);
		world.setBlock(i + 10, j, k + 36, sculk_block, 0, 2);
		world.setBlock(i + 11, j, k + 36, sculk_block, 0, 2);
		world.setBlock(i + 12, j, k + 36, sculk_block, 0, 2);
		world.setBlock(i + 13, j, k + 36, sculk_block, 0, 2);
		world.setBlock(i + 14, j, k + 36, sculk_block, 0, 2);
		world.setBlock(i + 15, j, k + 36, sculk_block, 0, 2);
		world.setBlock(i + 16, j, k + 36, sculk_block, 0, 2);
		world.setBlock(i + 17, j, k + 36, sculk_block, 0, 2);
		world.setBlock(i + 18, j, k + 36, sculk_block, 0, 2);
		world.setBlock(i + 19, j, k + 36, sculk_block, 0, 2);
		world.setBlock(i + 20, j, k + 36, sculk_block, 0, 2);
		world.setBlock(i + 21, j, k + 36, sculk_block, 0, 2);
		world.setBlock(i + 10, j, k + 37, sculk_block, 0, 2);
		world.setBlock(i + 11, j, k + 37, sculk_block, 0, 2);
		world.setBlock(i + 12, j, k + 37, sculk_block, 0, 2);
		world.setBlock(i + 13, j, k + 37, sculk_block, 0, 2);
		world.setBlock(i + 14, j, k + 37, sculk_block, 0, 2);
		world.setBlock(i + 15, j, k + 37, sculk_block, 0, 2);
		world.setBlock(i + 16, j, k + 37, sculk_block, 0, 2);
		world.setBlock(i + 17, j, k + 37, sculk_block, 0, 2);
		world.setBlock(i + 18, j, k + 37, sculk_block, 0, 2);
		world.setBlock(i + 19, j, k + 37, sculk_block, 0, 2);
		world.setBlock(i + 20, j, k + 37, sculk_block, 0, 2);
		world.setBlock(i + 12, j, k + 38, sculk_block, 0, 2);
		world.setBlock(i + 13, j, k + 38, sculk_block, 0, 2);
		world.setBlock(i + 14, j, k + 38, sculk_block, 0, 2);
		world.setBlock(i + 15, j, k + 38, sculk_block, 0, 2);
		world.setBlock(i + 16, j, k + 38, sculk_block, 0, 2);
		world.setBlock(i + 17, j, k + 38, sculk_block, 0, 2);
		world.setBlock(i + 18, j, k + 38, sculk_block, 0, 2);
		world.setBlock(i + 19, j, k + 38, sculk_block, 0, 2);
		world.setBlock(i + 13, j, k + 39, sculk_block, 0, 2);
		world.setBlock(i + 14, j, k + 39, sculk_block, 0, 2);
		world.setBlock(i + 15, j, k + 39, sculk_block, 0, 2);
		world.setBlock(i + 16, j, k + 39, sculk_block, 0, 2);
		world.setBlock(i + 13, j + 1, k + 1, NovaCraftBlocks.sculk_tentacle_2, 1, 2);
		world.setBlock(i + 15, j + 1, k + 1, NovaCraftBlocks.sculk_spike, 1, 2);
		world.setBlock(i + 17, j + 1, k + 1, NovaCraftBlocks.sculk_tentacle_2, 1, 2);
		world.setBlock(i + 14, j + 1, k + 2, sculk_tendrils, 0, 2);
		world.setBlock(i + 15, j + 1, k + 2, NovaCraftBlocks.sculk_vein, 1, 2);
		world.setBlock(i + 17, j + 1, k + 2, sculk_tendrils, 0, 2);
		world.setBlock(i + 9, j + 1, k + 3, NovaCraftBlocks.sculk_spike, 1, 2);
		world.setBlock(i + 11, j + 1, k + 3, sculk_tendrils, 0, 2);
		world.setBlock(i + 13, j + 1, k + 3, sculk_tulip, 0, 2);
		world.setBlock(i + 11, j + 1, k + 4, NovaCraftBlocks.sculk_vein, 1, 2);
		world.setBlock(i + 16, j + 1, k + 4, sculk_bush, 0, 2);
		world.setBlock(i + 18, j + 1, k + 4, NovaCraftBlocks.sculk_tentacle_2, 1, 2);
		world.setBlock(i + 9, j + 1, k + 5, sculk_tendrils, 0, 2);
		world.setBlock(i + 10, j + 1, k + 5, NovaCraftBlocks.sculk_tentacle_2, 1, 2);
		world.setBlock(i + 12, j + 1, k + 5, sculk_tendrils, 0, 2);
		world.setBlock(i + 15, j + 1, k + 5, NovaCraftBlocks.sculk_tentacle_2, 1, 2);
		world.setBlock(i + 17, j + 1, k + 5, NovaCraftBlocks.sculk_spike, 1, 2);
		world.setBlock(i + 20, j + 1, k + 5, sculk_tendrils, 0, 2);
		world.setBlock(i + 21, j + 1, k + 5, NovaCraftBlocks.sculk_vein, 1, 2);
		world.setBlock(i + 7, j + 1, k + 6, sculk_tendrils, 0, 2);
		world.setBlock(i + 8, j + 1, k + 6, NovaCraftBlocks.sculk_tentacle_2, 1, 2);
		world.setBlock(i + 14, j + 1, k + 6, sculk_tendrils, 0, 2);
		world.setBlock(i + 10, j + 1, k + 7, NovaCraftBlocks.sculk_vein, 1, 2);
		world.setBlock(i + 12, j + 1, k + 7, sculk_tendrils, 0, 2);
		world.setBlock(i + 16, j + 1, k + 7, sculk_tendrils, 0, 2);
		world.setBlock(i + 19, j + 1, k + 7, sculk_tendrils, 0, 2);
		world.setBlock(i + 21, j + 1, k + 7, NovaCraftBlocks.sculk_tentacle_2, 1, 2);
		world.setBlock(i + 23, j + 1, k + 7, NovaCraftBlocks.sculk_vein, 1, 2);
		world.setBlock(i + 24, j + 1, k + 7, NovaCraftBlocks.sculk_spike, 1, 2);
		world.setBlock(i + 5, j + 1, k + 8, NovaCraftBlocks.sculk_spike, 1, 2);
		world.setBlock(i + 15, j + 1, k + 8, NovaCraftBlocks.sculk_vein, 1, 2);
		world.setBlock(i + 19, j + 1, k + 8, sculk_tendrils, 0, 2);
		world.setBlock(i + 22, j + 1, k + 8, sculk_tendrils, 0, 2);
		world.setBlock(i + 7, j + 1, k + 9, sculk_tendrils, 0, 2);
		world.setBlock(i + 10, j + 1, k + 9, sculk_tendrils, 0, 2);
		world.setBlock(i + 17, j + 1, k + 9, NovaCraftBlocks.sculk_tentacle_2, 1, 2);
		world.setBlock(i + 23, j + 1, k + 9, sculk_tendrils, 0, 2);
		world.setBlock(i + 24, j + 1, k + 9, NovaCraftBlocks.sculk_vein, 1, 2);
		world.setBlock(i + 26, j + 1, k + 9, NovaCraftBlocks.sculk_tentacle_2, 1, 2);
		world.setBlock(i + 3, j + 1, k + 10, sculk_tendrils, 0, 2);
		world.setBlock(i + 6, j + 1, k + 10, sculk_tendrils, 0, 2);
		world.setBlock(i + 9, j + 1, k + 10, sculk_bush, 0, 2);
		world.setBlock(i + 10, j + 1, k + 10, NovaCraftBlocks.sculk_vein, 1, 2);
		world.setBlock(i + 14, j + 1, k + 10, sculk_bloom, 0, 2);
		world.setBlock(i + 17, j + 1, k + 10, sculk_tendrils, 0, 2);
		world.setBlock(i + 20, j + 1, k + 10, sculk_tendrils, 0, 2);
		world.setBlock(i + 25, j + 1, k + 10, sculk_tulip, 0, 2);
		world.setBlock(i + 2, j + 1, k + 11, NovaCraftBlocks.sculk_tentacle_2, 1, 2);
		world.setBlock(i + 5, j + 1, k + 11, sculk_tulip, 0, 2);
		world.setBlock(i + 9, j + 1, k + 11, NovaCraftBlocks.sculk_vein, 1, 2);
		world.setBlock(i + 10, j + 1, k + 11, NovaCraftBlocks.sculk_tentacle_2, 1, 2);
		world.setBlock(i + 16, j + 1, k + 11, sculk_tulip, 0, 2);
		world.setBlock(i + 19, j + 1, k + 11, NovaCraftBlocks.sculk_spike, 1, 2);
		world.setBlock(i + 26, j + 1, k + 11, sculk_tendrils, 0, 2);
		world.setBlock(i + 29, j + 1, k + 11, NovaCraftBlocks.sculk_spike, 1, 2);
		world.setBlock(i + 6, j + 1, k + 12, NovaCraftBlocks.sculk_tentacle_2, 1, 2);
		world.setBlock(i + 11, j + 1, k + 12, sculk_tendrils, 0, 2);
		world.setBlock(i + 14, j + 1, k + 12, sculk_tendrils, 0, 2);
		world.setBlock(i + 21, j + 1, k + 12, NovaCraftBlocks.sculk_tentacle_2, 1, 2);
		world.setBlock(i + 23, j + 1, k + 12, sculk_tendrils, 0, 2);
		world.setBlock(i + 24, j + 1, k + 12, NovaCraftBlocks.sculk_tentacle_2, 1, 2);
		world.setBlock(i + 2, j + 1, k + 13, NovaCraftBlocks.sculk_vein, 1, 2);
		world.setBlock(i + 4, j + 1, k + 13, NovaCraftBlocks.sculk_spike, 1, 2);
		world.setBlock(i + 6, j + 1, k + 13, sculk_tendrils, 0, 2);
		world.setBlock(i + 8, j + 1, k + 13, NovaCraftBlocks.sculk_vein, 1, 2);
		world.setBlock(i + 9, j + 1, k + 13, NovaCraftBlocks.sculk_spike, 1, 2);
		world.setBlock(i + 16, j + 1, k + 13, sculk_tendrils, 0, 2);
		world.setBlock(i + 19, j + 1, k + 13, sculk_tendrils, 0, 2);
		world.setBlock(i + 25, j + 1, k + 13, NovaCraftBlocks.sculk_spike, 1, 2);
		world.setBlock(i + 28, j + 1, k + 13, sculk_tendrils, 0, 2);
		world.setBlock(i + 9, j + 1, k + 14, sculk_tendrils, 0, 2);
		world.setBlock(i + 12, j + 1, k + 14, sculk_tendrils, 0, 2);
		world.setBlock(i + 15, j + 1, k + 14, NovaCraftBlocks.sculk_tentacle_2, 1, 2);
		world.setBlock(i + 25, j + 1, k + 14, sculk_tendrils, 0, 2);
		world.setBlock(i + 2, j + 1, k + 15, sculk_tendrils, 0, 2);
		world.setBlock(i + 4, j + 1, k + 15, NovaCraftBlocks.sculk_vein, 1, 2);
		world.setBlock(i + 7, j + 1, k + 15, NovaCraftBlocks.sculk_vein, 1, 2);
		world.setBlock(i + 17, j + 1, k + 15, NovaCraftBlocks.sculk_spike, 1, 2);
		world.setBlock(i + 22, j + 1, k + 15, sculk_tendrils, 0, 2);
		world.setBlock(i + 28, j + 1, k + 15, NovaCraftBlocks.sculk_tentacle_2, 1, 2);
		world.setBlock(i + 30, j + 1, k + 15, NovaCraftBlocks.sculk_vein, 1, 2);
		world.setBlock(i + 31, j + 1, k + 15, NovaCraftBlocks.sculk_spike, 1, 2);
		world.setBlock(i + 1, j + 1, k + 16, NovaCraftBlocks.sculk_spike, 1, 2);
		world.setBlock(i + 5, j + 1, k + 16, sculk_tendrils, 0, 2);
		world.setBlock(i + 8, j + 1, k + 16, NovaCraftBlocks.sculk_tentacle_2, 1, 2);
		world.setBlock(i + 11, j + 1, k + 16, sculk_tendrils, 0, 2);
		world.setBlock(i + 14, j + 1, k + 16, NovaCraftBlocks.sculk_brick_wall, 0, 2);
		world.setBlock(i + 15, j + 1, k + 16, sculk_tendrils, 0, 2);
		world.setBlock(i + 18, j + 1, k + 16, NovaCraftBlocks.sculk_brick_wall, 0, 2);
		world.setBlock(i + 19, j + 1, k + 16, sculk_tendrils, 0, 2);
		world.setBlock(i + 26, j + 1, k + 16, NovaCraftBlocks.sculk_vein, 1, 2);
		world.setBlock(i + 27, j + 1, k + 16, sculk_tendrils, 0, 2);
		world.setBlock(i + 30, j + 1, k + 16, sculk_tendrils, 0, 2);
		world.setBlock(i + 2, j + 1, k + 17, sculk_tulip, 0, 2);
		world.setBlock(i + 4, j + 1, k + 17, NovaCraftBlocks.sculk_tentacle_2, 1, 2);
		world.setBlock(i + 7, j + 1, k + 17, sculk_tendrils, 0, 2);
		world.setBlock(i + 13, j + 1, k + 17, NovaCraftBlocks.sculk_spike, 1, 2);
		world.setBlock(i + 22, j + 1, k + 17, NovaCraftBlocks.sculk_spike, 1, 2);
		world.setBlock(i + 24, j + 1, k + 17, sculk_tendrils, 0, 2);
		world.setBlock(i + 25, j + 1, k + 17, sculk_tendrils, 0, 2);
		world.setBlock(i + 29, j + 1, k + 17, NovaCraftBlocks.sculk_vein, 1, 2);
		world.setBlock(i + 31, j + 1, k + 17, NovaCraftBlocks.sculk_tentacle_2, 1, 2);
		world.setBlock(i + 1, j + 1, k + 18, NovaCraftBlocks.sculk_tentacle_2, 1, 2);
		world.setBlock(i + 11, j + 1, k + 18, sculk_tendrils, 0, 2);
		world.setBlock(i + 16, j + 1, k + 18, Blocks.ladder, 4, 2);
		world.setBlock(i + 17, j + 1, k + 18, sculk_bricks, 0, 2);
		world.setBlock(i + 23, j + 1, k + 18, sculk_tendrils, 0, 2);
		world.setBlock(i + 33, j + 1, k + 18, sculk_tendrils, 0, 2);
		world.setBlock(i + 4, j + 1, k + 19, sculk_tendrils, 0, 2);
		world.setBlock(i + 6, j + 1, k + 19, sculk_tendrils, 0, 2);
		world.setBlock(i + 9, j + 1, k + 19, sculk_tendrils, 0, 2);
		world.setBlock(i + 20, j + 1, k + 19, sculk_tendrils, 0, 2);
		world.setBlock(i + 26, j + 1, k + 19, NovaCraftBlocks.sculk_tentacle_2, 1, 2);
		world.setBlock(i + 27, j + 1, k + 19, sculk_tendrils, 0, 2);
		world.setBlock(i + 29, j + 1, k + 19, sculk_tulip, 0, 2);
		world.setBlock(i + 33, j + 1, k + 19, NovaCraftBlocks.sculk_vein, 1, 2);
		world.setBlock(i + 3, j + 1, k + 20, sculk_bush, 0, 2);
		world.setBlock(i + 5, j + 1, k + 20, sculk_bloom, 0, 2);
		world.setBlock(i + 9, j + 1, k + 20, sculk_tulip, 0, 2);
		world.setBlock(i + 11, j + 1, k + 20, sculk_tendrils, 0, 2);
		world.setBlock(i + 14, j + 1, k + 20, NovaCraftBlocks.sculk_brick_wall, 0, 2);
		world.setBlock(i + 15, j + 1, k + 20, NovaCraftBlocks.sculk_spike, 1, 2);
		world.setBlock(i + 18, j + 1, k + 20, NovaCraftBlocks.sculk_brick_wall, 0, 2);
		world.setBlock(i + 22, j + 1, k + 20, sculk_bloom, 0, 2);
		world.setBlock(i + 32, j + 1, k + 20, sculk_bush, 0, 2);
		world.setBlock(i + 1, j + 1, k + 21, sculk_tendrils, 0, 2);
		world.setBlock(i + 7, j + 1, k + 21, NovaCraftBlocks.sculk_vein, 1, 2);
		world.setBlock(i + 17, j + 1, k + 21, sculk_tendrils, 0, 2);
		world.setBlock(i + 23, j + 1, k + 21, sculk_tendrils, 0, 2);
		world.setBlock(i + 29, j + 1, k + 21, sculk_tendrils, 0, 2);
		world.setBlock(i + 31, j + 1, k + 21, NovaCraftBlocks.sculk_tentacle_2, 1, 2);
		world.setBlock(i, j + 1, k + 22, NovaCraftBlocks.sculk_vein, 1, 2);
		world.setBlock(i + 3, j + 1, k + 22, NovaCraftBlocks.sculk_vein, 1, 2);
		world.setBlock(i + 5, j + 1, k + 22, NovaCraftBlocks.sculk_tentacle_2, 1, 2);
		world.setBlock(i + 8, j + 1, k + 22, sculk_tendrils, 0, 2);
		world.setBlock(i + 11, j + 1, k + 22, NovaCraftBlocks.sculk_tentacle_2, 1, 2);
		world.setBlock(i + 13, j + 1, k + 22, sculk_tendrils, 0, 2);
		world.setBlock(i + 14, j + 1, k + 22, NovaCraftBlocks.sculk_vein, 1, 2);
		world.setBlock(i + 16, j + 1, k + 22, sculk_tendrils, 0, 2);
		world.setBlock(i + 18, j + 1, k + 22, NovaCraftBlocks.sculk_tentacle_2, 1, 2);
		world.setBlock(i + 25, j + 1, k + 22, NovaCraftBlocks.sculk_vein, 1, 2);
		world.setBlock(i + 27, j + 1, k + 22, NovaCraftBlocks.sculk_vein, 1, 2);
		world.setBlock(i + 33, j + 1, k + 22, sculk_tendrils, 0, 2);
		world.setBlock(i + 1, j + 1, k + 23, NovaCraftBlocks.sculk_tentacle_2, 1, 2);
		world.setBlock(i + 9, j + 1, k + 23, sculk_tendrils, 0, 2);
		world.setBlock(i + 20, j + 1, k + 23, sculk_tendrils, 0, 2);
		world.setBlock(i + 22, j + 1, k + 23, NovaCraftBlocks.sculk_spike, 1, 2);
		world.setBlock(i + 26, j + 1, k + 23, sculk_tendrils, 0, 2);
		world.setBlock(i + 27, j + 1, k + 23, NovaCraftBlocks.sculk_tentacle_2, 1, 2);
		world.setBlock(i + 7, j + 1, k + 24, sculk_tendrils, 0, 2);
		world.setBlock(i + 15, j + 1, k + 24, NovaCraftBlocks.sculk_tentacle_2, 1, 2);
		world.setBlock(i + 20, j + 1, k + 24, sculk_tulip, 0, 2);
		world.setBlock(i + 24, j + 1, k + 24, sculk_tendrils, 0, 2);
		world.setBlock(i + 29, j + 1, k + 24, sculk_tendrils, 0, 2);
		world.setBlock(i + 31, j + 1, k + 24, sculk_tendrils, 0, 2);
		world.setBlock(i + 32, j + 1, k + 24, NovaCraftBlocks.sculk_spike, 1, 2);
		world.setBlock(i, j + 1, k + 25, NovaCraftBlocks.sculk_spike, 1, 2);
		world.setBlock(i + 3, j + 1, k + 25, sculk_tendrils, 0, 2);
		world.setBlock(i + 4, j + 1, k + 25, NovaCraftBlocks.sculk_tentacle_2, 1, 2);
		world.setBlock(i + 6, j + 1, k + 25, sculk_tendrils, 0, 2);
		world.setBlock(i + 7, j + 1, k + 25, sculk_tendrils, 0, 2);
		world.setBlock(i + 9, j + 1, k + 25, NovaCraftBlocks.sculk_tentacle_2, 1, 2);
		world.setBlock(i + 11, j + 1, k + 25, sculk_tendrils, 0, 2);
		world.setBlock(i + 13, j + 1, k + 25, sculk_tendrils, 0, 2);
		world.setBlock(i + 15, j + 1, k + 25, sculk_tendrils, 0, 2);
		world.setBlock(i + 16, j + 1, k + 25, NovaCraftBlocks.sculk_vein, 1, 2);
		world.setBlock(i + 22, j + 1, k + 25, NovaCraftBlocks.sculk_vein, 1, 2);
		world.setBlock(i + 2, j + 1, k + 26, sculk_tulip, 0, 2);
		world.setBlock(i + 3, j + 1, k + 26, NovaCraftBlocks.sculk_vein, 1, 2);
		world.setBlock(i + 9, j + 1, k + 26, sculk_tendrils, 0, 2);
		world.setBlock(i + 16, j + 1, k + 26, sculk_bloom, 0, 2);
		world.setBlock(i + 17, j + 1, k + 26, sculk_tendrils, 0, 2);
		world.setBlock(i + 19, j + 1, k + 26, NovaCraftBlocks.sculk_vein, 1, 2);
		world.setBlock(i + 24, j + 1, k + 26, sculk_bush, 0, 2);
		world.setBlock(i + 26, j + 1, k + 26, sculk_tendrils, 0, 2);
		world.setBlock(i + 29, j + 1, k + 26, sculk_tendrils, 0, 2);
		world.setBlock(i + 31, j + 1, k + 26, NovaCraftBlocks.sculk_vein, 1, 2);
		world.setBlock(i + 7, j + 1, k + 27, sculk_bush, 0, 2);
		world.setBlock(i + 14, j + 1, k + 27, NovaCraftBlocks.sculk_vein, 1, 2);
		world.setBlock(i + 18, j + 1, k + 27, NovaCraftBlocks.sculk_tentacle_2, 1, 2);
		world.setBlock(i + 21, j + 1, k + 27, sculk_tendrils, 0, 2);
		world.setBlock(i + 27, j + 1, k + 27, sculk_tendrils, 0, 2);
		world.setBlock(i + 2, j + 1, k + 28, NovaCraftBlocks.sculk_tentacle_2, 1, 2);
		world.setBlock(i + 6, j + 1, k + 28, sculk_tendrils, 0, 2);
		world.setBlock(i + 13, j + 1, k + 28, NovaCraftBlocks.sculk_vein, 1, 2);
		world.setBlock(i + 20, j + 1, k + 28, NovaCraftBlocks.sculk_vein, 1, 2);
		world.setBlock(i + 24, j + 1, k + 28, sculk_tendrils, 0, 2);
		world.setBlock(i + 27, j + 1, k + 28, NovaCraftBlocks.sculk_spike, 1, 2);
		world.setBlock(i + 9, j + 1, k + 29, sculk_tendrils, 0, 2);
		world.setBlock(i + 12, j + 1, k + 29, sculk_tendrils, 0, 2);
		world.setBlock(i + 16, j + 1, k + 29, sculk_tendrils, 0, 2);
		world.setBlock(i + 18, j + 1, k + 29, NovaCraftBlocks.sculk_vein, 1, 2);
		world.setBlock(i + 25, j + 1, k + 29, sculk_tendrils, 0, 2);
		world.setBlock(i + 4, j + 1, k + 30, NovaCraftBlocks.sculk_vein, 1, 2);
		world.setBlock(i + 5, j + 1, k + 30, NovaCraftBlocks.sculk_spike, 1, 2);
		world.setBlock(i + 7, j + 1, k + 30, NovaCraftBlocks.sculk_tentacle_2, 1, 2);
		world.setBlock(i + 20, j + 1, k + 30, sculk_tendrils, 0, 2);
		world.setBlock(i + 22, j + 1, k + 30, NovaCraftBlocks.sculk_vein, 1, 2);
		world.setBlock(i + 24, j + 1, k + 30, sculk_tendrils, 0, 2);
		world.setBlock(i + 26, j + 1, k + 30, NovaCraftBlocks.sculk_tentacle_2, 1, 2);
		world.setBlock(i + 27, j + 1, k + 30, NovaCraftBlocks.sculk_vein, 1, 2);
		world.setBlock(i + 14, j + 1, k + 31, sculk_tendrils, 0, 2);
		world.setBlock(i + 19, j + 1, k + 31, NovaCraftBlocks.sculk_tentacle_2, 1, 2);
		world.setBlock(i + 25, j + 1, k + 31, NovaCraftBlocks.sculk_vein, 1, 2);
		world.setBlock(i + 6, j + 1, k + 32, NovaCraftBlocks.sculk_vein, 1, 2);
		world.setBlock(i + 7, j + 1, k + 32, sculk_tendrils, 0, 2);
		world.setBlock(i + 11, j + 1, k + 32, sculk_tendrils, 0, 2);
		world.setBlock(i + 13, j + 1, k + 32, sculk_tulip, 0, 2);
		world.setBlock(i + 16, j + 1, k + 32, sculk_tendrils, 0, 2);
		world.setBlock(i + 19, j + 1, k + 32, NovaCraftBlocks.sculk_spike, 1, 2);
		world.setBlock(i + 22, j + 1, k + 32, sculk_tendrils, 0, 2);
		world.setBlock(i + 23, j + 1, k + 32, sculk_tulip, 0, 2);
		world.setBlock(i + 15, j + 1, k + 33, sculk_bush, 0, 2);
		world.setBlock(i + 7, j + 1, k + 34, NovaCraftBlocks.sculk_vein, 1, 2);
		world.setBlock(i + 10, j + 1, k + 34, NovaCraftBlocks.sculk_tentacle_2, 1, 2);
		world.setBlock(i + 14, j + 1, k + 34, NovaCraftBlocks.sculk_spike, 1, 2);
		world.setBlock(i + 18, j + 1, k + 34, NovaCraftBlocks.sculk_vein, 1, 2);
		world.setBlock(i + 21, j + 1, k + 34, sculk_tendrils, 0, 2);
		world.setBlock(i + 11, j + 1, k + 35, sculk_tendrils, 0, 2);
		world.setBlock(i + 14, j + 1, k + 35, NovaCraftBlocks.sculk_tentacle_2, 1, 2);
		world.setBlock(i + 16, j + 1, k + 35, sculk_tendrils, 0, 2);
		world.setBlock(i + 19, j + 1, k + 35, sculk_tendrils, 0, 2);
		world.setBlock(i + 20, j + 1, k + 35, NovaCraftBlocks.sculk_vein, 1, 2);
		world.setBlock(i + 10, j + 1, k + 36, NovaCraftBlocks.sculk_vein, 1, 2);
		world.setBlock(i + 12, j + 1, k + 37, NovaCraftBlocks.sculk_vein, 1, 2);
		world.setBlock(i + 15, j + 1, k + 37, NovaCraftBlocks.sculk_vein, 1, 2);
		world.setBlock(i + 17, j + 1, k + 37, sculk_tulip, 0, 2);
		world.setBlock(i + 15, j + 1, k + 38, sculk_tendrils, 0, 2);
		world.setBlock(i + 13, j + 1, k + 39, NovaCraftBlocks.sculk_spike, 1, 2);
		world.setBlock(i + 14, j + 2, k + 2, sculk_tendrils, 0, 2);
		world.setBlock(i + 17, j + 2, k + 2, sculk_tendrils, 0, 2);
		world.setBlock(i + 20, j + 2, k + 5, sculk_tendrils, 0, 2);
		world.setBlock(i + 12, j + 2, k + 7, sculk_tendrils, 0, 2);
		world.setBlock(i + 16, j + 2, k + 7, sculk_tendrils, 0, 2);
		world.setBlock(i + 19, j + 2, k + 7, sculk_tendrils, 0, 2);
		world.setBlock(i + 22, j + 2, k + 8, sculk_tendrils, 0, 2);
		world.setBlock(i + 7, j + 2, k + 9, sculk_tendrils, 0, 2);
		world.setBlock(i + 10, j + 2, k + 9, sculk_tendrils, 0, 2);
		world.setBlock(i + 23, j + 2, k + 9, sculk_tendrils, 0, 2);
		world.setBlock(i + 3, j + 2, k + 10, sculk_tendrils, 0, 2);
		world.setBlock(i + 6, j + 2, k + 10, sculk_tendrils, 0, 2);
		world.setBlock(i + 17, j + 2, k + 10, sculk_tendrils, 0, 2);
		world.setBlock(i + 26, j + 2, k + 11, sculk_tendrils, 0, 2);
		world.setBlock(i + 11, j + 2, k + 12, sculk_tendrils, 0, 2);
		world.setBlock(i + 14, j + 2, k + 12, sculk_tendrils, 0, 2);
		world.setBlock(i + 23, j + 2, k + 12, sculk_tendrils, 0, 2);
		world.setBlock(i + 19, j + 2, k + 13, sculk_tendrils, 0, 2);
		world.setBlock(i + 28, j + 2, k + 13, sculk_tendrils, 0, 2);
		world.setBlock(i + 9, j + 2, k + 14, sculk_tendrils, 0, 2);
		world.setBlock(i + 2, j + 2, k + 15, sculk_tendrils, 0, 2);
		world.setBlock(i + 14, j + 2, k + 16, NovaCraftBlocks.sculk_brick_wall, 0, 2);
		world.setBlock(i + 15, j + 2, k + 16, sculk_tendrils, 0, 2);
		world.setBlock(i + 18, j + 2, k + 16, NovaCraftBlocks.sculk_brick_wall, 0, 2);
		world.setBlock(i + 19, j + 2, k + 16, sculk_tendrils, 0, 2);
		world.setBlock(i + 27, j + 2, k + 16, sculk_tendrils, 0, 2);
		world.setBlock(i + 30, j + 2, k + 16, sculk_tendrils, 0, 2);
		world.setBlock(i + 7, j + 2, k + 17, sculk_tendrils, 0, 2);
		world.setBlock(i + 24, j + 2, k + 17, sculk_tendrils, 0, 2);
		world.setBlock(i + 11, j + 2, k + 18, sculk_tendrils, 0, 2);
		world.setBlock(i + 16, j + 2, k + 18, Blocks.ladder, 4, 2);
		world.setBlock(i + 17, j + 2, k + 18, sculk_bricks, 0, 2);
		world.setBlock(i + 23, j + 2, k + 18, sculk_tendrils, 0, 2);
		world.setBlock(i + 33, j + 2, k + 18, sculk_tendrils, 0, 2);
		world.setBlock(i + 4, j + 2, k + 19, sculk_tendrils, 0, 2);
		world.setBlock(i + 6, j + 2, k + 19, sculk_tendrils, 0, 2);
		world.setBlock(i + 20, j + 2, k + 19, sculk_tendrils, 0, 2);
		world.setBlock(i + 14, j + 2, k + 20, NovaCraftBlocks.sculk_brick_wall, 0, 2);
		world.setBlock(i + 18, j + 2, k + 20, NovaCraftBlocks.sculk_brick_wall, 0, 2);
		world.setBlock(i + 1, j + 2, k + 21, sculk_tendrils, 0, 2);
		world.setBlock(i + 17, j + 2, k + 21, sculk_tendrils, 0, 2);
		world.setBlock(i + 23, j + 2, k + 21, sculk_tendrils, 0, 2);
		world.setBlock(i + 29, j + 2, k + 21, sculk_tendrils, 0, 2);
		world.setBlock(i + 8, j + 2, k + 22, sculk_tendrils, 0, 2);
		world.setBlock(i + 16, j + 2, k + 22, sculk_tendrils, 0, 2);
		world.setBlock(i + 33, j + 2, k + 22, sculk_tendrils, 0, 2);
		world.setBlock(i + 20, j + 2, k + 23, sculk_tendrils, 0, 2);
		world.setBlock(i + 26, j + 2, k + 23, sculk_tendrils, 0, 2);
		world.setBlock(i + 7, j + 2, k + 24, sculk_tendrils, 0, 2);
		world.setBlock(i + 24, j + 2, k + 24, sculk_tendrils, 0, 2);
		world.setBlock(i + 31, j + 2, k + 24, sculk_tendrils, 0, 2);
		world.setBlock(i + 3, j + 2, k + 25, sculk_tendrils, 0, 2);
		world.setBlock(i + 6, j + 2, k + 25, sculk_tendrils, 0, 2);
		world.setBlock(i + 7, j + 2, k + 25, sculk_tendrils, 0, 2);
		world.setBlock(i + 11, j + 2, k + 25, sculk_tendrils, 0, 2);
		world.setBlock(i + 13, j + 2, k + 25, sculk_tendrils, 0, 2);
		world.setBlock(i + 15, j + 2, k + 25, sculk_tendrils, 0, 2);
		world.setBlock(i + 17, j + 2, k + 26, sculk_tendrils, 0, 2);
		world.setBlock(i + 26, j + 2, k + 26, sculk_tendrils, 0, 2);
		world.setBlock(i + 21, j + 2, k + 27, sculk_tendrils, 0, 2);
		world.setBlock(i + 6, j + 2, k + 28, sculk_tendrils, 0, 2);
		world.setBlock(i + 24, j + 2, k + 28, sculk_tendrils, 0, 2);
		world.setBlock(i + 12, j + 2, k + 29, sculk_tendrils, 0, 2);
		world.setBlock(i + 16, j + 2, k + 29, sculk_tendrils, 0, 2);
		world.setBlock(i + 20, j + 2, k + 30, sculk_tendrils, 0, 2);
		world.setBlock(i + 7, j + 2, k + 32, sculk_tendrils, 0, 2);
		world.setBlock(i + 11, j + 2, k + 32, sculk_tendrils, 0, 2);
		world.setBlock(i + 16, j + 2, k + 32, sculk_tendrils, 0, 2);
		world.setBlock(i + 11, j + 2, k + 35, sculk_tendrils, 0, 2);
		world.setBlock(i + 16, j + 2, k + 35, sculk_tendrils, 0, 2);
		world.setBlock(i + 19, j + 2, k + 35, sculk_tendrils, 0, 2);
		world.setBlock(i + 15, j + 2, k + 38, sculk_tendrils, 0, 2);
		world.setBlock(i + 14, j + 3, k + 2, sculk_tendrils, 0, 2);
		world.setBlock(i + 17, j + 3, k + 2, sculk_tendrils, 0, 2);
		world.setBlock(i + 20, j + 3, k + 5, sculk_tendrils, 0, 2);
		world.setBlock(i + 12, j + 3, k + 7, sculk_tendrils, 0, 2);
		world.setBlock(i + 16, j + 3, k + 7, sculk_tendrils, 0, 2);
		world.setBlock(i + 19, j + 3, k + 7, sculk_tendrils, 0, 2);
		world.setBlock(i + 7, j + 3, k + 9, sculk_tendrils, 0, 2);
		world.setBlock(i + 23, j + 3, k + 9, sculk_tendrils, 0, 2);
		world.setBlock(i + 3, j + 3, k + 10, sculk_tendrils, 0, 2);
		world.setBlock(i + 6, j + 3, k + 10, sculk_tendrils, 0, 2);
		world.setBlock(i + 17, j + 3, k + 10, sculk_tendrils, 0, 2);
		world.setBlock(i + 11, j + 3, k + 12, sculk_tendrils, 0, 2);
		world.setBlock(i + 14, j + 3, k + 12, sculk_tendrils, 0, 2);
		world.setBlock(i + 23, j + 3, k + 12, sculk_tendrils, 0, 2);
		world.setBlock(i + 19, j + 3, k + 13, sculk_tendrils, 0, 2);
		world.setBlock(i + 2, j + 3, k + 15, sculk_tendrils, 0, 2);
		world.setBlock(i + 14, j + 3, k + 16, NovaCraftBlocks.sculk_brick_wall, 0, 2);
		world.setBlock(i + 18, j + 3, k + 16, NovaCraftBlocks.sculk_brick_wall, 0, 2);
		world.setBlock(i + 19, j + 3, k + 16, sculk_tendrils, 0, 2);
		world.setBlock(i + 27, j + 3, k + 16, sculk_tendrils, 0, 2);
		world.setBlock(i + 30, j + 3, k + 16, sculk_tendrils, 0, 2);
		world.setBlock(i + 7, j + 3, k + 17, sculk_tendrils, 0, 2);
		world.setBlock(i + 11, j + 3, k + 18, sculk_tendrils, 0, 2);
		world.setBlock(i + 16, j + 3, k + 18, Blocks.ladder, 4, 2);
		world.setBlock(i + 17, j + 3, k + 18, sculk_bricks, 0, 2);
		world.setBlock(i + 23, j + 3, k + 18, sculk_tendrils, 0, 2);
		world.setBlock(i + 33, j + 3, k + 18, sculk_tendrils, 0, 2);
		world.setBlock(i + 6, j + 3, k + 19, sculk_tendrils, 0, 2);
		world.setBlock(i + 14, j + 3, k + 20, NovaCraftBlocks.sculk_brick_wall, 0, 2);
		world.setBlock(i + 18, j + 3, k + 20, NovaCraftBlocks.sculk_brick_wall, 0, 2);
		world.setBlock(i + 1, j + 3, k + 21, sculk_tendrils, 0, 2);
		world.setBlock(i + 17, j + 3, k + 21, sculk_tendrils, 0, 2);
		world.setBlock(i + 23, j + 3, k + 21, sculk_tendrils, 0, 2);
		world.setBlock(i + 8, j + 3, k + 22, sculk_tendrils, 0, 2);
		world.setBlock(i + 33, j + 3, k + 22, sculk_tendrils, 0, 2);
		world.setBlock(i + 20, j + 3, k + 23, sculk_tendrils, 0, 2);
		world.setBlock(i + 26, j + 3, k + 23, sculk_tendrils, 0, 2);
		world.setBlock(i + 7, j + 3, k + 24, sculk_tendrils, 0, 2);
		world.setBlock(i + 24, j + 3, k + 24, sculk_tendrils, 0, 2);
		world.setBlock(i + 31, j + 3, k + 24, sculk_tendrils, 0, 2);
		world.setBlock(i + 3, j + 3, k + 25, sculk_tendrils, 0, 2);
		world.setBlock(i + 11, j + 3, k + 25, sculk_tendrils, 0, 2);
		world.setBlock(i + 13, j + 3, k + 25, sculk_tendrils, 0, 2);
		world.setBlock(i + 15, j + 3, k + 25, sculk_tendrils, 0, 2);
		world.setBlock(i + 26, j + 3, k + 26, sculk_tendrils, 0, 2);
		world.setBlock(i + 21, j + 3, k + 27, sculk_tendrils, 0, 2);
		world.setBlock(i + 6, j + 3, k + 28, sculk_tendrils, 0, 2);
		world.setBlock(i + 12, j + 3, k + 29, sculk_tendrils, 0, 2);
		world.setBlock(i + 20, j + 3, k + 30, sculk_tendrils, 0, 2);
		world.setBlock(i + 7, j + 3, k + 32, sculk_tendrils, 0, 2);
		world.setBlock(i + 11, j + 3, k + 35, sculk_tendrils, 0, 2);
		world.setBlock(i + 16, j + 3, k + 35, sculk_tendrils, 0, 2);
		world.setBlock(i + 19, j + 3, k + 35, sculk_tendrils, 0, 2);
		world.setBlock(i + 15, j + 3, k + 38, sculk_tendrils, 0, 2);
		world.setBlock(i + 14, j + 4, k + 2, sculk_tendrils, 0, 2);
		world.setBlock(i + 17, j + 4, k + 2, sculk_tendrils, 0, 2);
		world.setBlock(i + 12, j + 4, k + 7, sculk_tendrils, 0, 2);
		world.setBlock(i + 16, j + 4, k + 7, sculk_tendrils, 0, 2);
		world.setBlock(i + 19, j + 4, k + 7, sculk_tendrils, 0, 2);
		world.setBlock(i + 23, j + 4, k + 9, sculk_tendrils, 0, 2);
		world.setBlock(i + 6, j + 4, k + 10, sculk_tendrils, 0, 2);
		world.setBlock(i + 17, j + 4, k + 10, sculk_tendrils, 0, 2);
		world.setBlock(i + 14, j + 4, k + 12, sculk_tendrils, 0, 2);
		world.setBlock(i + 23, j + 4, k + 12, sculk_tendrils, 0, 2);
		world.setBlock(i + 19, j + 4, k + 13, sculk_tendrils, 0, 2);
		world.setBlock(i + 2, j + 4, k + 15, sculk_tendrils, 0, 2);
		world.setBlock(i + 14, j + 4, k + 16, NovaCraftBlocks.sculk_brick_wall, 0, 2);
		world.setBlock(i + 18, j + 4, k + 16, NovaCraftBlocks.sculk_brick_wall, 0, 2);
		world.setBlock(i + 19, j + 4, k + 16, sculk_tendrils, 0, 2);
		world.setBlock(i + 27, j + 4, k + 16, sculk_tendrils, 0, 2);
		world.setBlock(i + 30, j + 4, k + 16, sculk_tendrils, 0, 2);
		world.setBlock(i + 7, j + 4, k + 17, sculk_tendrils, 0, 2);
		world.setBlock(i + 11, j + 4, k + 18, sculk_tendrils, 0, 2);
		world.setBlock(i + 16, j + 4, k + 18, Blocks.ladder, 4, 2);
		world.setBlock(i + 17, j + 4, k + 18, sculk_bricks, 0, 2);
		world.setBlock(i + 23, j + 4, k + 18, sculk_tendrils, 0, 2);
		world.setBlock(i + 33, j + 4, k + 18, sculk_tendrils, 0, 2);
		world.setBlock(i + 6, j + 4, k + 19, sculk_tendrils, 0, 2);
		world.setBlock(i + 14, j + 4, k + 20, NovaCraftBlocks.sculk_brick_wall, 0, 2);
		world.setBlock(i + 18, j + 4, k + 20, NovaCraftBlocks.sculk_brick_wall, 0, 2);
		world.setBlock(i + 1, j + 4, k + 21, sculk_tendrils, 0, 2);
		world.setBlock(i + 33, j + 4, k + 22, sculk_tendrils, 0, 2);
		world.setBlock(i + 24, j + 4, k + 24, sculk_tendrils, 0, 2);
		world.setBlock(i + 31, j + 4, k + 24, sculk_tendrils, 0, 2);
		world.setBlock(i + 3, j + 4, k + 25, sculk_tendrils, 0, 2);
		world.setBlock(i + 11, j + 4, k + 25, sculk_tendrils, 0, 2);
		world.setBlock(i + 13, j + 4, k + 25, sculk_tendrils, 0, 2);
		world.setBlock(i + 15, j + 4, k + 25, sculk_tendrils, 0, 2);
		world.setBlock(i + 26, j + 4, k + 26, sculk_tendrils, 0, 2);
		world.setBlock(i + 21, j + 4, k + 27, sculk_tendrils, 0, 2);
		world.setBlock(i + 6, j + 4, k + 28, sculk_tendrils, 0, 2);
		world.setBlock(i + 12, j + 4, k + 29, sculk_tendrils, 0, 2);
		world.setBlock(i + 20, j + 4, k + 30, sculk_tendrils, 0, 2);
		world.setBlock(i + 7, j + 4, k + 32, sculk_tendrils, 0, 2);
		world.setBlock(i + 11, j + 4, k + 35, sculk_tendrils, 0, 2);
		world.setBlock(i + 19, j + 4, k + 35, sculk_tendrils, 0, 2);
		world.setBlock(i + 15, j + 4, k + 38, sculk_tendrils, 0, 2);
		world.setBlock(i + 17, j + 5, k + 2, sculk_tendrils, 0, 2);
		world.setBlock(i + 12, j + 5, k + 7, sculk_tendrils, 0, 2);
		world.setBlock(i + 16, j + 5, k + 7, sculk_tendrils, 0, 2);
		world.setBlock(i + 23, j + 5, k + 9, sculk_tendrils, 0, 2);
		world.setBlock(i + 6, j + 5, k + 10, sculk_tendrils, 0, 2);
		world.setBlock(i + 14, j + 5, k + 12, sculk_tendrils, 0, 2);
		world.setBlock(i + 19, j + 5, k + 13, sculk_tendrils, 0, 2);
		world.setBlock(i + 2, j + 5, k + 15, sculk_tendrils, 0, 2);
		world.setBlock(i + 14, j + 5, k + 16, NovaCraftBlocks.sculk_brick_wall, 0, 2);
		world.setBlock(i + 18, j + 5, k + 16, NovaCraftBlocks.sculk_brick_wall, 0, 2);
		world.setBlock(i + 19, j + 5, k + 16, sculk_tendrils, 0, 2);
		world.setBlock(i + 27, j + 5, k + 16, sculk_tendrils, 0, 2);
		world.setBlock(i + 30, j + 5, k + 16, sculk_tendrils, 0, 2);
		world.setBlock(i + 7, j + 5, k + 17, sculk_tendrils, 0, 2);
		world.setBlock(i + 16, j + 5, k + 18, Blocks.ladder, 4, 2);
		world.setBlock(i + 17, j + 5, k + 18, sculk_bricks, 0, 2);
		world.setBlock(i + 33, j + 5, k + 18, sculk_tendrils, 0, 2);
		world.setBlock(i + 6, j + 5, k + 19, sculk_tendrils, 0, 2);
		world.setBlock(i + 14, j + 5, k + 20, NovaCraftBlocks.sculk_brick_wall, 0, 2);
		world.setBlock(i + 18, j + 5, k + 20, NovaCraftBlocks.sculk_brick_wall, 0, 2);
		world.setBlock(i + 1, j + 5, k + 21, sculk_tendrils, 0, 2);
		world.setBlock(i + 33, j + 5, k + 22, sculk_tendrils, 0, 2);
		world.setBlock(i + 3, j + 5, k + 25, sculk_tendrils, 0, 2);
		world.setBlock(i + 13, j + 5, k + 25, sculk_tendrils, 0, 2);
		world.setBlock(i + 15, j + 5, k + 25, sculk_tendrils, 0, 2);
		world.setBlock(i + 26, j + 5, k + 26, sculk_tendrils, 0, 2);
		world.setBlock(i + 6, j + 5, k + 28, sculk_tendrils, 0, 2);
		world.setBlock(i + 20, j + 5, k + 30, sculk_tendrils, 0, 2);
		world.setBlock(i + 7, j + 5, k + 32, sculk_tendrils, 0, 2);
		world.setBlock(i + 11, j + 5, k + 35, sculk_tendrils, 0, 2);
		world.setBlock(i + 19, j + 5, k + 35, sculk_tendrils, 0, 2);
		world.setBlock(i + 15, j + 5, k + 38, sculk_tendrils, 0, 2);
		world.setBlock(i + 17, j + 6, k + 2, sculk_tendrils, 0, 2);
		world.setBlock(i + 12, j + 6, k + 7, sculk_tendrils, 0, 2);
		world.setBlock(i + 16, j + 6, k + 7, sculk_tendrils, 0, 2);
		world.setBlock(i + 23, j + 6, k + 9, sculk_tendrils, 0, 2);
		world.setBlock(i + 6, j + 6, k + 10, sculk_tendrils, 0, 2);
		world.setBlock(i + 14, j + 6, k + 12, sculk_tendrils, 0, 2);
		world.setBlock(i + 19, j + 6, k + 13, sculk_tendrils, 0, 2);
		world.setBlock(i + 2, j + 6, k + 15, sculk_tendrils, 0, 2);
		world.setBlock(i + 14, j + 6, k + 16, NovaCraftBlocks.sculk_brick_wall, 0, 2);
		world.setBlock(i + 18, j + 6, k + 16, NovaCraftBlocks.sculk_brick_wall, 0, 2);
		world.setBlock(i + 19, j + 6, k + 16, sculk_tendrils, 0, 2);
		world.setBlock(i + 27, j + 6, k + 16, sculk_tendrils, 0, 2);
		world.setBlock(i + 30, j + 6, k + 16, sculk_tendrils, 0, 2);
		world.setBlock(i + 7, j + 6, k + 17, sculk_tendrils, 0, 2);
		world.setBlock(i + 16, j + 6, k + 18, Blocks.ladder, 4, 2);
		world.setBlock(i + 17, j + 6, k + 18, sculk_bricks, 0, 2);
		world.setBlock(i + 6, j + 6, k + 19, sculk_tendrils, 0, 2);
		world.setBlock(i + 14, j + 6, k + 20, NovaCraftBlocks.sculk_brick_wall, 0, 2);
		world.setBlock(i + 18, j + 6, k + 20, NovaCraftBlocks.sculk_brick_wall, 0, 2);
		world.setBlock(i + 1, j + 6, k + 21, sculk_tendrils, 0, 2);
		world.setBlock(i + 33, j + 6, k + 22, sculk_tendrils, 0, 2);
		world.setBlock(i + 3, j + 6, k + 25, sculk_tendrils, 0, 2);
		world.setBlock(i + 15, j + 6, k + 25, sculk_tendrils, 0, 2);
		world.setBlock(i + 26, j + 6, k + 26, sculk_tendrils, 0, 2);
		world.setBlock(i + 6, j + 6, k + 28, sculk_tendrils, 0, 2);
		world.setBlock(i + 20, j + 6, k + 30, sculk_tendrils, 0, 2);
		world.setBlock(i + 7, j + 6, k + 32, sculk_tendrils, 0, 2);
		world.setBlock(i + 11, j + 6, k + 35, sculk_tendrils, 0, 2);
		world.setBlock(i + 19, j + 6, k + 35, sculk_tendrils, 0, 2);
		world.setBlock(i + 15, j + 6, k + 38, sculk_tendrils, 0, 2);
		world.setBlock(i + 17, j + 7, k + 2, sculk_tendrils, 0, 2);
		world.setBlock(i + 12, j + 7, k + 7, sculk_tendrils, 0, 2);
		world.setBlock(i + 16, j + 7, k + 7, sculk_tendrils, 0, 2);
		world.setBlock(i + 23, j + 7, k + 9, sculk_tendrils, 0, 2);
		world.setBlock(i + 6, j + 7, k + 10, sculk_tendrils, 0, 2);
		world.setBlock(i + 14, j + 7, k + 12, sculk_tendrils, 0, 2);
		world.setBlock(i + 2, j + 7, k + 15, sculk_tendrils, 0, 2);
		world.setBlock(i + 14, j + 7, k + 16, NovaCraftBlocks.sculk_brick_wall, 0, 2);
		world.setBlock(i + 18, j + 7, k + 16, NovaCraftBlocks.sculk_brick_wall, 0, 2);
		world.setBlock(i + 30, j + 7, k + 16, sculk_tendrils, 0, 2);
		world.setBlock(i + 7, j + 7, k + 17, sculk_tendrils, 0, 2);
		world.setBlock(i + 16, j + 7, k + 18, Blocks.ladder, 4, 2);
		world.setBlock(i + 17, j + 7, k + 18, sculk_bricks, 0, 2);
		world.setBlock(i + 6, j + 7, k + 19, sculk_tendrils, 0, 2);
		world.setBlock(i + 14, j + 7, k + 20, NovaCraftBlocks.sculk_brick_wall, 0, 2);
		world.setBlock(i + 18, j + 7, k + 20, NovaCraftBlocks.sculk_brick_wall, 0, 2);
		world.setBlock(i + 1, j + 7, k + 21, sculk_tendrils, 0, 2);
		world.setBlock(i + 33, j + 7, k + 22, sculk_tendrils, 0, 2);
		world.setBlock(i + 3, j + 7, k + 25, sculk_tendrils, 0, 2);
		world.setBlock(i + 15, j + 7, k + 25, sculk_tendrils, 0, 2);
		world.setBlock(i + 26, j + 7, k + 26, sculk_tendrils, 0, 2);
		world.setBlock(i + 6, j + 7, k + 28, sculk_tendrils, 0, 2);
		world.setBlock(i + 20, j + 7, k + 30, sculk_tendrils, 0, 2);
		world.setBlock(i + 7, j + 7, k + 32, sculk_tendrils, 0, 2);
		world.setBlock(i + 11, j + 7, k + 35, sculk_tendrils, 0, 2);
		world.setBlock(i + 19, j + 7, k + 35, sculk_tendrils, 0, 2);
		world.setBlock(i + 12, j + 8, k + 7, sculk_tendrils, 0, 2);
		world.setBlock(i + 23, j + 8, k + 9, sculk_tendrils, 0, 2);
		world.setBlock(i + 6, j + 8, k + 10, sculk_tendrils, 0, 2);
		world.setBlock(i + 14, j + 8, k + 12, sculk_tendrils, 0, 2);
		world.setBlock(i + 14, j + 8, k + 16, NovaCraftBlocks.sculk_brick_wall, 0, 2);
		world.setBlock(i + 18, j + 8, k + 16, NovaCraftBlocks.sculk_brick_wall, 0, 2);
		world.setBlock(i + 30, j + 8, k + 16, sculk_tendrils, 0, 2);
		world.setBlock(i + 7, j + 8, k + 17, sculk_tendrils, 0, 2);
		world.setBlock(i + 16, j + 8, k + 18, Blocks.ladder, 4, 2);
		world.setBlock(i + 17, j + 8, k + 18, sculk_bricks, 0, 2);
		world.setBlock(i + 6, j + 8, k + 19, sculk_tendrils, 0, 2);
		world.setBlock(i + 14, j + 8, k + 20, NovaCraftBlocks.sculk_brick_wall, 0, 2);
		world.setBlock(i + 18, j + 8, k + 20, NovaCraftBlocks.sculk_brick_wall, 0, 2);
		world.setBlock(i + 1, j + 8, k + 21, sculk_tendrils, 0, 2);
		world.setBlock(i + 3, j + 8, k + 25, sculk_tendrils, 0, 2);
		world.setBlock(i + 15, j + 8, k + 25, sculk_tendrils, 0, 2);
		world.setBlock(i + 26, j + 8, k + 26, sculk_tendrils, 0, 2);
		world.setBlock(i + 6, j + 8, k + 28, sculk_tendrils, 0, 2);
		world.setBlock(i + 20, j + 8, k + 30, sculk_tendrils, 0, 2);
		world.setBlock(i + 7, j + 8, k + 32, sculk_tendrils, 0, 2);
		world.setBlock(i + 11, j + 8, k + 35, sculk_tendrils, 0, 2);
		world.setBlock(i + 12, j + 9, k + 7, sculk_tendrils, 0, 2);
		world.setBlock(i + 14, j + 9, k + 16, NovaCraftBlocks.sculk_brick_wall, 0, 2);
		world.setBlock(i + 18, j + 9, k + 16, NovaCraftBlocks.sculk_brick_wall, 0, 2);
		world.setBlock(i + 16, j + 9, k + 18, Blocks.ladder, 4, 2);
		world.setBlock(i + 17, j + 9, k + 18, sculk_bricks, 0, 2);
		world.setBlock(i + 6, j + 9, k + 19, sculk_tendrils, 0, 2);
		world.setBlock(i + 14, j + 9, k + 20, NovaCraftBlocks.sculk_brick_wall, 0, 2);
		world.setBlock(i + 18, j + 9, k + 20, NovaCraftBlocks.sculk_brick_wall, 0, 2);
		world.setBlock(i + 1, j + 9, k + 21, sculk_tendrils, 0, 2);
		world.setBlock(i + 3, j + 9, k + 25, sculk_tendrils, 0, 2);
		world.setBlock(i + 26, j + 9, k + 26, sculk_tendrils, 0, 2);
		world.setBlock(i + 20, j + 9, k + 30, sculk_tendrils, 0, 2);
		world.setBlock(i + 7, j + 9, k + 32, sculk_tendrils, 0, 2);
		world.setBlock(i + 14, j + 10, k + 16, NovaCraftBlocks.sculk_brick_wall, 0, 2);
		world.setBlock(i + 18, j + 10, k + 16, NovaCraftBlocks.sculk_brick_wall, 0, 2);
		world.setBlock(i + 16, j + 10, k + 18, Blocks.ladder, 4, 2);
		world.setBlock(i + 17, j + 10, k + 18, sculk_bricks, 0, 2);
		world.setBlock(i + 14, j + 10, k + 20, NovaCraftBlocks.sculk_brick_wall, 0, 2);
		world.setBlock(i + 18, j + 10, k + 20, NovaCraftBlocks.sculk_brick_wall, 0, 2);
		world.setBlock(i + 1, j + 10, k + 21, sculk_tendrils, 0, 2);
		world.setBlock(i + 3, j + 10, k + 25, sculk_tendrils, 0, 2);
		world.setBlock(i + 26, j + 10, k + 26, sculk_tendrils, 0, 2);
		world.setBlock(i + 7, j + 10, k + 32, sculk_tendrils, 0, 2);
		world.setBlock(i + 14, j + 11, k + 16, NovaCraftBlocks.sculk_brick_wall, 0, 2);
		world.setBlock(i + 18, j + 11, k + 16, NovaCraftBlocks.sculk_brick_wall, 0, 2);
		world.setBlock(i + 16, j + 11, k + 18, Blocks.ladder, 4, 2);
		world.setBlock(i + 17, j + 11, k + 18, sculk_bricks, 0, 2);
		world.setBlock(i + 14, j + 11, k + 20, NovaCraftBlocks.sculk_brick_wall, 0, 2);
		world.setBlock(i + 18, j + 11, k + 20, NovaCraftBlocks.sculk_brick_wall, 0, 2);
		world.setBlock(i + 1, j + 11, k + 21, sculk_tendrils, 0, 2);
		world.setBlock(i + 26, j + 11, k + 26, sculk_tendrils, 0, 2);
		world.setBlock(i + 7, j + 11, k + 32, sculk_tendrils, 0, 2);
		world.setBlock(i + 14, j + 12, k + 16, NovaCraftBlocks.sculk_brick_wall, 0, 2);
		world.setBlock(i + 18, j + 12, k + 16, NovaCraftBlocks.sculk_brick_wall, 0, 2);
		world.setBlock(i + 16, j + 12, k + 18, Blocks.ladder, 4, 2);
		world.setBlock(i + 17, j + 12, k + 18, sculk_bricks, 0, 2);
		world.setBlock(i + 14, j + 12, k + 20, NovaCraftBlocks.sculk_brick_wall, 0, 2);
		world.setBlock(i + 18, j + 12, k + 20, NovaCraftBlocks.sculk_brick_wall, 0, 2);
		world.setBlock(i + 1, j + 12, k + 21, sculk_tendrils, 0, 2);
		world.setBlock(i + 26, j + 12, k + 26, sculk_tendrils, 0, 2);
		world.setBlock(i + 14, j + 13, k + 16, NovaCraftBlocks.sculk_brick_wall, 0, 2);
		world.setBlock(i + 18, j + 13, k + 16, NovaCraftBlocks.sculk_brick_wall, 0, 2);
		world.setBlock(i + 16, j + 13, k + 18, Blocks.ladder, 4, 2);
		world.setBlock(i + 17, j + 13, k + 18, sculk_bricks, 0, 2);
		world.setBlock(i + 14, j + 13, k + 20, NovaCraftBlocks.sculk_brick_wall, 0, 2);
		world.setBlock(i + 18, j + 13, k + 20, NovaCraftBlocks.sculk_brick_wall, 0, 2);
		world.setBlock(i + 14, j + 14, k + 16, NovaCraftBlocks.sculk_brick_wall, 0, 2);
		world.setBlock(i + 18, j + 14, k + 16, NovaCraftBlocks.sculk_brick_wall, 0, 2);
		world.setBlock(i + 16, j + 14, k + 18, Blocks.ladder, 4, 2);
		world.setBlock(i + 17, j + 14, k + 18, sculk_bricks, 0, 2);
		world.setBlock(i + 14, j + 14, k + 20, NovaCraftBlocks.sculk_brick_wall, 0, 2);
		world.setBlock(i + 18, j + 14, k + 20, NovaCraftBlocks.sculk_brick_wall, 0, 2);
		world.setBlock(i + 14, j + 15, k + 16, NovaCraftBlocks.sculk_brick_wall, 0, 2);
		world.setBlock(i + 18, j + 15, k + 16, NovaCraftBlocks.sculk_brick_wall, 0, 2);
		world.setBlock(i + 16, j + 15, k + 18, Blocks.ladder, 4, 2);
		world.setBlock(i + 17, j + 15, k + 18, sculk_bricks, 0, 2);
		world.setBlock(i + 14, j + 15, k + 20, NovaCraftBlocks.sculk_brick_wall, 0, 2);
		world.setBlock(i + 18, j + 15, k + 20, NovaCraftBlocks.sculk_brick_wall, 0, 2);
		world.setBlock(i + 14, j + 16, k + 16, NovaCraftBlocks.sculk_brick_wall, 0, 2);
		world.setBlock(i + 18, j + 16, k + 16, NovaCraftBlocks.sculk_brick_wall, 0, 2);
		world.setBlock(i + 16, j + 16, k + 18, Blocks.ladder, 4, 2);
		world.setBlock(i + 17, j + 16, k + 18, sculk_bricks, 0, 2);
		world.setBlock(i + 14, j + 16, k + 20, NovaCraftBlocks.sculk_brick_wall, 0, 2);
		world.setBlock(i + 18, j + 16, k + 20, NovaCraftBlocks.sculk_brick_wall, 0, 2);
		world.setBlock(i + 14, j + 17, k + 16, NovaCraftBlocks.sculk_brick_wall, 0, 2);
		world.setBlock(i + 18, j + 17, k + 16, NovaCraftBlocks.sculk_brick_wall, 0, 2);
		world.setBlock(i + 16, j + 17, k + 18, Blocks.ladder, 4, 2);
		world.setBlock(i + 17, j + 17, k + 18, sculk_bricks, 0, 2);
		world.setBlock(i + 14, j + 17, k + 20, NovaCraftBlocks.sculk_brick_wall, 0, 2);
		world.setBlock(i + 18, j + 17, k + 20, NovaCraftBlocks.sculk_brick_wall, 0, 2);
		world.setBlock(i + 14, j + 18, k + 16, NovaCraftBlocks.sculk_brick_wall, 0, 2);
		world.setBlock(i + 15, j + 18, k + 16, sculk_tiles, 0, 2);
		world.setBlock(i + 17, j + 18, k + 16, sculk_tiles, 0, 2);
		world.setBlock(i + 18, j + 18, k + 16, NovaCraftBlocks.sculk_brick_wall, 0, 2);
		world.setBlock(i + 14, j + 18, k + 17, sculk_tiles, 0, 2);
		world.setBlock(i + 15, j + 18, k + 17, sculk_tiles, 0, 2);
		world.setBlock(i + 17, j + 18, k + 17, sculk_tiles, 0, 2);
		world.setBlock(i + 18, j + 18, k + 17, sculk_tiles, 0, 2);
		world.setBlock(i + 16, j + 18, k + 18, Blocks.ladder, 4, 2);
		world.setBlock(i + 17, j + 18, k + 18, sculk_bricks, 0, 2);
		world.setBlock(i + 14, j + 18, k + 19, sculk_tiles, 0, 2);
		world.setBlock(i + 15, j + 18, k + 19, sculk_tiles, 0, 2);
		world.setBlock(i + 17, j + 18, k + 19, sculk_tiles, 0, 2);
		world.setBlock(i + 18, j + 18, k + 19, sculk_tiles, 0, 2);
		world.setBlock(i + 14, j + 18, k + 20, NovaCraftBlocks.sculk_brick_wall, 0, 2);
		world.setBlock(i + 15, j + 18, k + 20, sculk_tiles, 0, 2);
		world.setBlock(i + 17, j + 18, k + 20, sculk_tiles, 0, 2);
		world.setBlock(i + 18, j + 18, k + 20, NovaCraftBlocks.sculk_brick_wall, 0, 2);
		world.setBlock(i + 15, j + 19, k + 16, sculk_bricks, 0, 2);
		world.setBlock(i + 16, j + 19, k + 16, sculk_bricks, 0, 2);
		world.setBlock(i + 17, j + 19, k + 16, sculk_bricks, 0, 2);
		world.setBlock(i + 14, j + 19, k + 17, sculk_bricks, 0, 2);
		world.setBlock(i + 15, j + 19, k + 17, sculk_tiles, 0, 2);
		world.setBlock(i + 16, j + 19, k + 17, sculk_tiles, 0, 2);
		world.setBlock(i + 17, j + 19, k + 17, sculk_tiles, 0, 2);
		world.setBlock(i + 18, j + 19, k + 17, sculk_bricks, 0, 2);
		world.setBlock(i + 14, j + 19, k + 18, sculk_bricks, 0, 2);
		world.setBlock(i + 15, j + 19, k + 18, sculk_tiles, 0, 2);
		world.setBlock(i + 16, j + 19, k + 18, Blocks.trapdoor, 11, 2);
		world.setBlock(i + 17, j + 19, k + 18, sculk_tiles, 0, 2);
		world.setBlock(i + 18, j + 19, k + 18, sculk_bricks, 0, 2);
		world.setBlock(i + 14, j + 19, k + 19, sculk_bricks, 0, 2);
		world.setBlock(i + 15, j + 19, k + 19, sculk_tiles, 0, 2);
		world.setBlock(i + 16, j + 19, k + 19, sculk_tiles, 0, 2);
		world.setBlock(i + 17, j + 19, k + 19, sculk_tiles, 0, 2);
		world.setBlock(i + 18, j + 19, k + 19, sculk_bricks, 0, 2);
		world.setBlock(i + 15, j + 19, k + 20, sculk_bricks, 0, 2);
		world.setBlock(i + 16, j + 19, k + 20, sculk_bricks, 0, 2);
		world.setBlock(i + 17, j + 19, k + 20, sculk_bricks, 0, 2);
		world.setBlock(i + 15, j + 20, k + 16, sculk_tiles, 0, 2);
		world.setBlock(i + 16, j + 20, k + 16, NovaCraftBlocks.sculk_tiled_wall, 0, 2);
		world.setBlock(i + 17, j + 20, k + 16, sculk_tiles, 0, 2);
		world.setBlock(i + 14, j + 20, k + 17, sculk_tiles, 0, 2);
		world.setBlock(i + 18, j + 20, k + 17, sculk_tiles, 0, 2);
		world.setBlock(i + 14, j + 20, k + 18, NovaCraftBlocks.sculk_tiled_wall, 0, 2);
		world.setBlock(i + 18, j + 20, k + 18, NovaCraftBlocks.sculk_tiled_wall, 0, 2);
		world.setBlock(i + 14, j + 20, k + 19, sculk_tiles, 0, 2);
		world.setBlock(i + 18, j + 20, k + 19, sculk_tiles, 0, 2);
		world.setBlock(i + 15, j + 20, k + 20, sculk_tiles, 0, 2);
		world.setBlock(i + 16, j + 20, k + 20, NovaCraftBlocks.sculk_tiled_wall, 0, 2);
		world.setBlock(i + 17, j + 20, k + 20, sculk_tiles, 0, 2);
		world.setBlock(i + 14, j + 21, k + 16, sculk_tiles, 0, 2);
		world.setBlock(i + 15, j + 21, k + 16, NovaCraftBlocks.sculk_tiled_wall, 0, 2);
		world.setBlock(i + 17, j + 21, k + 16, NovaCraftBlocks.sculk_tiled_wall, 0, 2);
		world.setBlock(i + 18, j + 21, k + 16, sculk_tiles, 0, 2);
		world.setBlock(i + 14, j + 21, k + 17, NovaCraftBlocks.sculk_tiled_wall, 0, 2);
		world.setBlock(i + 18, j + 21, k + 17, NovaCraftBlocks.sculk_tiled_wall, 0, 2);
		world.setBlock(i + 14, j + 21, k + 19, NovaCraftBlocks.sculk_tiled_wall, 0, 2);
		world.setBlock(i + 18, j + 21, k + 19, NovaCraftBlocks.sculk_tiled_wall, 0, 2);
		world.setBlock(i + 14, j + 21, k + 20, sculk_tiles, 0, 2);
		world.setBlock(i + 15, j + 21, k + 20, NovaCraftBlocks.sculk_tiled_wall, 0, 2);
		world.setBlock(i + 17, j + 21, k + 20, NovaCraftBlocks.sculk_tiled_wall, 0, 2);
		world.setBlock(i + 18, j + 21, k + 20, sculk_tiles, 0, 2);
		world.setBlock(i + 15, j + 22, k + 16, sculk_tiles, 0, 2);
		world.setBlock(i + 16, j + 22, k + 16, sculk_tiles, 0, 2);
		world.setBlock(i + 17, j + 22, k + 16, sculk_tiles, 0, 2);
		world.setBlock(i + 14, j + 22, k + 17, sculk_tiles, 0, 2);
		world.setBlock(i + 15, j + 22, k + 17, sculk_tiles, 0, 2);
		world.setBlock(i + 16, j + 22, k + 17, sculk_tiles, 0, 2);
		world.setBlock(i + 17, j + 22, k + 17, sculk_tiles, 0, 2);
		world.setBlock(i + 18, j + 22, k + 17, sculk_tiles, 0, 2);
		world.setBlock(i + 14, j + 22, k + 18, sculk_tiles, 0, 2);
		world.setBlock(i + 15, j + 22, k + 18, sculk_tiles, 0, 2);
		world.setBlock(i + 17, j + 22, k + 18, sculk_tiles, 0, 2);
		world.setBlock(i + 18, j + 22, k + 18, sculk_tiles, 0, 2);
		world.setBlock(i + 14, j + 22, k + 19, sculk_tiles, 0, 2);
		world.setBlock(i + 15, j + 22, k + 19, sculk_tiles, 0, 2);
		world.setBlock(i + 16, j + 22, k + 19, sculk_tiles, 0, 2);
		world.setBlock(i + 17, j + 22, k + 19, sculk_tiles, 0, 2);
		world.setBlock(i + 18, j + 22, k + 19, sculk_tiles, 0, 2);
		world.setBlock(i + 15, j + 22, k + 20, sculk_tiles, 0, 2);
		world.setBlock(i + 16, j + 22, k + 20, sculk_tiles, 0, 2);
		world.setBlock(i + 17, j + 22, k + 20, sculk_tiles, 0, 2);
		world.setBlock(i + 15, j + 23, k + 17, sculk_tiles, 0, 2);
		world.setBlock(i + 16, j + 23, k + 17, sculk_tiles, 0, 2);
		world.setBlock(i + 17, j + 23, k + 17, sculk_tiles, 0, 2);
		world.setBlock(i + 15, j + 23, k + 18, sculk_tiles, 0, 2);
		world.setBlock(i + 16, j + 23, k + 18, Blocks.glowstone, 0, 2);
		world.setBlock(i + 17, j + 23, k + 18, sculk_tiles, 0, 2);
		world.setBlock(i + 15, j + 23, k + 19, sculk_tiles, 0, 2);
		world.setBlock(i + 16, j + 23, k + 19, sculk_tiles, 0, 2);
		world.setBlock(i + 17, j + 23, k + 19, sculk_tiles, 0, 2);

		this.setBlockAndNotifyAdequately(world, i + 15, j + 20, k + 19, Blocks.chest, 5);
		TileEntity tile = world.getTileEntity(i + 15, j + 20, k + 19);
