package com.NovaCraft.world.ancient_city;

import java.util.Random;

import com.NovaCraft.Items.NovaCraftItems;
import com.NovaCraft.registry.OtherModBlocks;
import com.NovaCraft.registry.OtherModItems;
import com.NovaCraftBlocks.NovaCraftBlocks;

import cpw.mods.fml.common.Loader;
import net.minecraft.block.Block;
import net.minecraft.enchantment.Enchantment;
import net.minecraft.enchantment.EnchantmentData;
import net.minecraft.init.Blocks;
import net.minecraft.init.Items;
import net.minecraft.item.ItemStack;
import net.minecraft.tileentity.TileEntityChest;
import net.minecraft.util.MathHelper;
import net.minecraft.world.World;
import net.minecraft.world.gen.feature.WorldGenerator;

public class AncientCitySculkWallNegZGen2 extends WorldGenerator
{
	public AncientCitySculkWallNegZGen2() {

	}

	private static final Block sculk_block = NovaCraftBlocks.sculk_block;
    
    public boolean generate(final World world, final Random random, final int i, final int j, final int k) {
    	
    	world.setBlock(i + 43, j + 26, k + 12, sculk_block, 0, 2);
		world.setBlock(i + 44, j + 26, k + 12, sculk_block, 0, 2);
		world.setBlock(i + 45, j + 26, k + 12, sculk_block, 0, 2);
		world.setBlock(i + 46, j + 26, k + 12, sculk_block, 0, 2);
		world.setBlock(i + 47, j + 26, k + 12, sculk_block, 0, 2);
		world.setBlock(i + 48, j + 26, k + 12, sculk_block, 0, 2);
		world.setBlock(i + 49, j + 26, k + 12, sculk_block, 0, 2);
		world.setBlock(i + 21, j + 26, k + 13, NovaCraftBlocks.sculk_spike, 0, 2);
		world.setBlock(i + 16, j + 26, k + 14, NovaCraftBlocks.sculk_spike, 0, 2);
		world.setBlock(i + 46, j + 26, k + 14, NovaCraftBlocks.sculk_spike, 0, 2);
		world.setBlock(i + 8, j + 27, k + 13, sculk_block, 0, 2);
		world.setBlock(i + 9, j + 27, k + 13, sculk_block, 0, 2);
		world.setBlock(i + 10, j + 27, k + 13, sculk_block, 0, 2);
		world.setBlock(i + 11, j + 27, k + 13, sculk_block, 0, 2);
		world.setBlock(i + 12, j + 27, k + 13, sculk_block, 0, 2);
		world.setBlock(i + 13, j + 27, k + 13, sculk_block, 0, 2);
		world.setBlock(i + 14, j + 27, k + 13, sculk_block, 0, 2);
		world.setBlock(i + 15, j + 27, k + 13, sculk_block, 0, 2);
		world.setBlock(i + 16, j + 27, k + 13, sculk_block, 0, 2);
		world.setBlock(i + 17, j + 27, k + 13, sculk_block, 0, 2);
		world.setBlock(i + 18, j + 27, k + 13, sculk_block, 0, 2);
		world.setBlock(i + 19, j + 27, k + 13, sculk_block, 0, 2);
		world.setBlock(i + 20, j + 27, k + 13, sculk_block, 0, 2);
		world.setBlock(i + 21, j + 27, k + 13, sculk_block, 0, 2);
		world.setBlock(i + 22, j + 27, k + 13, sculk_block, 0, 2);
		world.setBlock(i + 23, j + 27, k + 13, sculk_block, 0, 2);
		world.setBlock(i + 24, j + 27, k + 13, sculk_block, 0, 2);
		world.setBlock(i + 25, j + 27, k + 13, sculk_block, 0, 2);
		world.setBlock(i + 26, j + 27, k + 13, sculk_block, 0, 2);
		world.setBlock(i + 27, j + 27, k + 13, sculk_block, 0, 2);
		world.setBlock(i + 28, j + 27, k + 13, sculk_block, 0, 2);
		world.setBlock(i + 29, j + 27, k + 13, sculk_block, 0, 2);
		world.setBlock(i + 30, j + 27, k + 13, sculk_block, 0, 2);
		world.setBlock(i + 31, j + 27, k + 13, sculk_block, 0, 2);
		world.setBlock(i + 32, j + 27, k + 13, sculk_block, 0, 2);
		world.setBlock(i + 33, j + 27, k + 13, sculk_block, 0, 2);
		world.setBlock(i + 34, j + 27, k + 13, sculk_block, 0, 2);
		world.setBlock(i + 35, j + 27, k + 13, sculk_block, 0, 2);
		world.setBlock(i + 36, j + 27, k + 13, sculk_block, 0, 2);
		world.setBlock(i + 37, j + 27, k + 13, sculk_block, 0, 2);
		world.setBlock(i + 38, j + 27, k + 13, sculk_block, 0, 2);
		world.setBlock(i + 39, j + 27, k + 13, sculk_block, 0, 2);
		world.setBlock(i + 40, j + 27, k + 13, sculk_block, 0, 2);
		world.setBlock(i + 41, j + 27, k + 13, sculk_block, 0, 2);
		world.setBlock(i + 42, j + 27, k + 13, sculk_block, 0, 2);
		world.setBlock(i + 43, j + 27, k + 13, sculk_block, 0, 2);
		world.setBlock(i + 44, j + 27, k + 13, sculk_block, 0, 2);
		world.setBlock(i + 45, j + 27, k + 13, sculk_block, 0, 2);
		world.setBlock(i + 46, j + 27, k + 13, sculk_block, 0, 2);
		world.setBlock(i + 47, j + 27, k + 13, sculk_block, 0, 2);
		world.setBlock(i + 48, j + 27, k + 13, sculk_block, 0, 2);
		world.setBlock(i + 8, j + 27, k + 14, sculk_block, 0, 2);
		world.setBlock(i + 9, j + 27, k + 14, sculk_block, 0, 2);
		world.setBlock(i + 10, j + 27, k + 14, sculk_block, 0, 2);
		world.setBlock(i + 11, j + 27, k + 14, sculk_block, 0, 2);
		world.setBlock(i + 12, j + 27, k + 14, sculk_block, 0, 2);
		world.setBlock(i + 13, j + 27, k + 14, sculk_block, 0, 2);
		world.setBlock(i + 14, j + 27, k + 14, sculk_block, 0, 2);
		world.setBlock(i + 15, j + 27, k + 14, sculk_block, 0, 2);
		world.setBlock(i + 16, j + 27, k + 14, sculk_block, 0, 2);
		world.setBlock(i + 17, j + 27, k + 14, sculk_block, 0, 2);
		world.setBlock(i + 18, j + 27, k + 14, sculk_block, 0, 2);
		world.setBlock(i + 19, j + 27, k + 14, sculk_block, 0, 2);
		world.setBlock(i + 20, j + 27, k + 14, sculk_block, 0, 2);
		world.setBlock(i + 21, j + 27, k + 14, sculk_block, 0, 2);
		world.setBlock(i + 22, j + 27, k + 14, sculk_block, 0, 2);
		world.setBlock(i + 23, j + 27, k + 14, sculk_block, 0, 2);
		world.setBlock(i + 24, j + 27, k + 14, sculk_block, 0, 2);
		world.setBlock(i + 25, j + 27, k + 14, sculk_block, 0, 2);
		world.setBlock(i + 26, j + 27, k + 14, sculk_block, 0, 2);
		world.setBlock(i + 27, j + 27, k + 14, sculk_block, 0, 2);
		world.setBlock(i + 28, j + 27, k + 14, sculk_block, 0, 2);
		world.setBlock(i + 29, j + 27, k + 14, sculk_block, 0, 2);
		world.setBlock(i + 30, j + 27, k + 14, sculk_block, 0, 2);
		world.setBlock(i + 31, j + 27, k + 14, sculk_block, 0, 2);
		world.setBlock(i + 32, j + 27, k + 14, sculk_block, 0, 2);
		world.setBlock(i + 33, j + 27, k + 14, sculk_block, 0, 2);
		world.setBlock(i + 34, j + 27, k + 14, sculk_block, 0, 2);
		world.setBlock(i + 35, j + 27, k + 14, sculk_block, 0, 2);
		world.setBlock(i + 36, j + 27, k + 14, sculk_block, 0, 2);
		world.setBlock(i + 37, j + 27, k + 14, sculk_block, 0, 2);
		world.setBlock(i + 38, j + 27, k + 14, sculk_block, 0, 2);
		world.setBlock(i + 39, j + 27, k + 14, sculk_block, 0, 2);
		world.setBlock(i + 40, j + 27, k + 14, sculk_block, 0, 2);
		world.setBlock(i + 41, j + 27, k + 14, sculk_block, 0, 2);
		world.setBlock(i + 42, j + 27, k + 14, sculk_block, 0, 2);
		world.setBlock(i + 43, j + 27, k + 14, sculk_block, 0, 2);
		world.setBlock(i + 44, j + 27, k + 14, sculk_block, 0, 2);
		world.setBlock(i + 45, j + 27, k + 14, sculk_block, 0, 2);
		world.setBlock(i + 46, j + 27, k + 14, sculk_block, 0, 2);
		world.setBlock(i + 47, j + 27, k + 14, sculk_block, 0, 2);
		world.setBlock(i + 48, j + 27, k + 14, sculk_block, 0, 2);
		world.setBlock(i + 7, j + 27, k + 15, sculk_block, 0, 2);
		world.setBlock(i + 10, j + 27, k + 15, NovaCraftBlocks.sculk_spike, 0, 2);
		world.setBlock(i + 29, j + 27, k + 15, NovaCraftBlocks.sculk_tentacle_2, 0, 2);
		world.setBlock(i + 37, j + 27, k + 15, NovaCraftBlocks.sculk_spike, 0, 2);
		world.setBlock(i + 7, j + 27, k + 16, sculk_block, 0, 2);
		world.setBlock(i + 7, j + 27, k + 17, sculk_block, 0, 2);
		world.setBlock(i + 16, j + 27, k + 17, NovaCraftBlocks.sculk_tentacle_2, 0, 2);
		world.setBlock(i + 7, j + 27, k + 18, sculk_block, 0, 2);
		world.setBlock(i + 8, j + 28, k + 15, sculk_block, 0, 2);
		world.setBlock(i + 9, j + 28, k + 15, sculk_block, 0, 2);
		world.setBlock(i + 10, j + 28, k + 15, sculk_block, 0, 2);
		world.setBlock(i + 11, j + 28, k + 15, sculk_block, 0, 2);
		world.setBlock(i + 12, j + 28, k + 15, sculk_block, 0, 2);
		world.setBlock(i + 13, j + 28, k + 15, sculk_block, 0, 2);
		world.setBlock(i + 14, j + 28, k + 15, sculk_block, 0, 2);
		world.setBlock(i + 15, j + 28, k + 15, sculk_block, 0, 2);
		world.setBlock(i + 16, j + 28, k + 15, sculk_block, 0, 2);
		world.setBlock(i + 17, j + 28, k + 15, sculk_block, 0, 2);
		world.setBlock(i + 18, j + 28, k + 15, sculk_block, 0, 2);
		world.setBlock(i + 19, j + 28, k + 15, sculk_block, 0, 2);
		world.setBlock(i + 20, j + 28, k + 15, sculk_block, 0, 2);
		world.setBlock(i + 21, j + 28, k + 15, sculk_block, 0, 2);
		world.setBlock(i + 22, j + 28, k + 15, sculk_block, 0, 2);
		world.setBlock(i + 23, j + 28, k + 15, sculk_block, 0, 2);
		world.setBlock(i + 24, j + 28, k + 15, sculk_block, 0, 2);
		world.setBlock(i + 25, j + 28, k + 15, sculk_block, 0, 2);
		world.setBlock(i + 26, j + 28, k + 15, sculk_block, 0, 2);
		world.setBlock(i + 27, j + 28, k + 15, sculk_block, 0, 2);
		world.setBlock(i + 28, j + 28, k + 15, sculk_block, 0, 2);
		world.setBlock(i + 29, j + 28, k + 15, sculk_block, 0, 2);
		world.setBlock(i + 30, j + 28, k + 15, sculk_block, 0, 2);
		world.setBlock(i + 31, j + 28, k + 15, sculk_block, 0, 2);
		world.setBlock(i + 32, j + 28, k + 15, sculk_block, 0, 2);
		world.setBlock(i + 33, j + 28, k + 15, sculk_block, 0, 2);
		world.setBlock(i + 34, j + 28, k + 15, sculk_block, 0, 2);
		world.setBlock(i + 35, j + 28, k + 15, sculk_block, 0, 2);
		world.setBlock(i + 36, j + 28, k + 15, sculk_block, 0, 2);
		world.setBlock(i + 37, j + 28, k + 15, sculk_block, 0, 2);
		world.setBlock(i + 38, j + 28, k + 15, sculk_block, 0, 2);
		world.setBlock(i + 39, j + 28, k + 15, sculk_block, 0, 2);
		world.setBlock(i + 40, j + 28, k + 15, sculk_block, 0, 2);
		world.setBlock(i + 41, j + 28, k + 15, sculk_block, 0, 2);
		world.setBlock(i + 42, j + 28, k + 15, sculk_block, 0, 2);
		world.setBlock(i + 43, j + 28, k + 15, sculk_block, 0, 2);
		world.setBlock(i + 44, j + 28, k + 15, sculk_block, 0, 2);
		world.setBlock(i + 45, j + 28, k + 15, sculk_block, 0, 2);
		world.setBlock(i + 46, j + 28, k + 15, sculk_block, 0, 2);
		world.setBlock(i + 47, j + 28, k + 15, sculk_block, 0, 2);
		world.setBlock(i + 8, j + 28, k + 16, sculk_block, 0, 2);
		world.setBlock(i + 9, j + 28, k + 16, sculk_block, 0, 2);
		world.setBlock(i + 10, j + 28, k + 16, sculk_block, 0, 2);
		world.setBlock(i + 11, j + 28, k + 16, sculk_block, 0, 2);
		world.setBlock(i + 12, j + 28, k + 16, sculk_block, 0, 2);
		world.setBlock(i + 13, j + 28, k + 16, sculk_block, 0, 2);
		world.setBlock(i + 14, j + 28, k + 16, sculk_block, 0, 2);
		world.setBlock(i + 15, j + 28, k + 16, sculk_block, 0, 2);
		world.setBlock(i + 16, j + 28, k + 16, sculk_block, 0, 2);
		world.setBlock(i + 17, j + 28, k + 16, sculk_block, 0, 2);
		world.setBlock(i + 18, j + 28, k + 16, sculk_block, 0, 2);
		world.setBlock(i + 19, j + 28, k + 16, sculk_block, 0, 2);
		world.setBlock(i + 20, j + 28, k + 16, sculk_block, 0, 2);
		world.setBlock(i + 21, j + 28, k + 16, sculk_block, 0, 2);
		world.setBlock(i + 22, j + 28, k + 16, sculk_block, 0, 2);
		world.setBlock(i + 23, j + 28, k + 16, sculk_block, 0, 2);
		world.setBlock(i + 24, j + 28, k + 16, sculk_block, 0, 2);
		world.setBlock(i + 25, j + 28, k + 16, sculk_block, 0, 2);
		world.setBlock(i + 26, j + 28, k + 16, sculk_block, 0, 2);
		world.setBlock(i + 27, j + 28, k + 16, sculk_block, 0, 2);
		world.setBlock(i + 28, j + 28, k + 16, sculk_block, 0, 2);
		world.setBlock(i + 29, j + 28, k + 16, sculk_block, 0, 2);
		world.setBlock(i + 30, j + 28, k + 16, sculk_block, 0, 2);
		world.setBlock(i + 31, j + 28, k + 16, sculk_block, 0, 2);
		world.setBlock(i + 32, j + 28, k + 16, sculk_block, 0, 2);
		world.setBlock(i + 33, j + 28, k + 16, sculk_block, 0, 2);
		world.setBlock(i + 34, j + 28, k + 16, sculk_block, 0, 2);
		world.setBlock(i + 35, j + 28, k + 16, sculk_block, 0, 2);
		world.setBlock(i + 36, j + 28, k + 16, sculk_block, 0, 2);
		world.setBlock(i + 37, j + 28, k + 16, sculk_block, 0, 2);
		world.setBlock(i + 38, j + 28, k + 16, sculk_block, 0, 2);
		world.setBlock(i + 39, j + 28, k + 16, sculk_block, 0, 2);
		world.setBlock(i + 40, j + 28, k + 16, sculk_block, 0, 2);
		world.setBlock(i + 41, j + 28, k + 16, sculk_block, 0, 2);
		world.setBlock(i + 42, j + 28, k + 16, sculk_block, 0, 2);
		world.setBlock(i + 43, j + 28, k + 16, sculk_block, 0, 2);
		world.setBlock(i + 44, j + 28, k + 16, sculk_block, 0, 2);
		world.setBlock(i + 45, j + 28, k + 16, sculk_block, 0, 2);
		world.setBlock(i + 46, j + 28, k + 16, sculk_block, 0, 2);
		world.setBlock(i + 47, j + 28, k + 16, sculk_block, 0, 2);
		world.setBlock(i + 8, j + 28, k + 17, sculk_block, 0, 2);
		world.setBlock(i + 9, j + 28, k + 17, sculk_block, 0, 2);
		world.setBlock(i + 10, j + 28, k + 17, sculk_block, 0, 2);
		world.setBlock(i + 11, j + 28, k + 17, sculk_block, 0, 2);
		world.setBlock(i + 12, j + 28, k + 17, sculk_block, 0, 2);
		world.setBlock(i + 13, j + 28, k + 17, sculk_block, 0, 2);
		world.setBlock(i + 14, j + 28, k + 17, sculk_block, 0, 2);
		world.setBlock(i + 15, j + 28, k + 17, sculk_block, 0, 2);
		world.setBlock(i + 16, j + 28, k + 17, sculk_block, 0, 2);
		world.setBlock(i + 17, j + 28, k + 17, sculk_block, 0, 2);
		world.setBlock(i + 18, j + 28, k + 17, sculk_block, 0, 2);
		world.setBlock(i + 19, j + 28, k + 17, sculk_block, 0, 2);
		world.setBlock(i + 20, j + 28, k + 17, sculk_block, 0, 2);
		world.setBlock(i + 21, j + 28, k + 17, sculk_block, 0, 2);
		world.setBlock(i + 22, j + 28, k + 17, sculk_block, 0, 2);
		world.setBlock(i + 23, j + 28, k + 17, sculk_block, 0, 2);
		world.setBlock(i + 24, j + 28, k + 17, sculk_block, 0, 2);
		world.setBlock(i + 25, j + 28, k + 17, sculk_block, 0, 2);
		world.setBlock(i + 26, j + 28, k + 17, sculk_block, 0, 2);
		world.setBlock(i + 27, j + 28, k + 17, sculk_block, 0, 2);
		world.setBlock(i + 28, j + 28, k + 17, sculk_block, 0, 2);
		world.setBlock(i + 29, j + 28, k + 17, sculk_block, 0, 2);
		world.setBlock(i + 30, j + 28, k + 17, sculk_block, 0, 2);
		world.setBlock(i + 31, j + 28, k + 17, sculk_block, 0, 2);
		world.setBlock(i + 32, j + 28, k + 17, sculk_block, 0, 2);
		world.setBlock(i + 33, j + 28, k + 17, sculk_block, 0, 2);
		world.setBlock(i + 34, j + 28, k + 17, sculk_block, 0, 2);
		world.setBlock(i + 35, j + 28, k + 17, sculk_block, 0, 2);
		world.setBlock(i + 36, j + 28, k + 17, sculk_block, 0, 2);
		world.setBlock(i + 37, j + 28, k + 17, sculk_block, 0, 2);
		world.setBlock(i + 38, j + 28, k + 17, sculk_block, 0, 2);
		world.setBlock(i + 39, j + 28, k + 17, sculk_block, 0, 2);
		world.setBlock(i + 40, j + 28, k + 17, sculk_block, 0, 2);
		world.setBlock(i + 41, j + 28, k + 17, sculk_block, 0, 2);
		world.setBlock(i + 42, j + 28, k + 17, sculk_block, 0, 2);
		world.setBlock(i + 43, j + 28, k + 17, sculk_block, 0, 2);
		world.setBlock(i + 44, j + 28, k + 17, sculk_block, 0, 2);
		world.setBlock(i + 45, j + 28, k + 17, sculk_block, 0, 2);
		world.setBlock(i + 46, j + 28, k + 17, sculk_block, 0, 2);
		world.setBlock(i + 47, j + 28, k + 17, sculk_block, 0, 2);
		world.setBlock(i + 7, j + 28, k + 18, sculk_block, 0, 2);
		world.setBlock(i + 32, j + 28, k + 18, NovaCraftBlocks.sculk_tentacle_2, 0, 2);
		world.setBlock(i + 43, j + 28, k + 18, NovaCraftBlocks.sculk_tentacle_2, 0, 2);
		world.setBlock(i + 6, j + 28, k + 19, sculk_block, 0, 2);
		world.setBlock(i + 7, j + 28, k + 19, NovaCraftBlocks.sculk_spike, 0, 2);
		world.setBlock(i + 13, j + 28, k + 19, NovaCraftBlocks.sculk_tentacle_2, 0, 2);
		world.setBlock(i + 37, j + 28, k + 20, NovaCraftBlocks.sculk_tentacle_2, 0, 2);
		world.setBlock(i + 8, j + 29, k + 18, sculk_block, 0, 2);
		world.setBlock(i + 9, j + 29, k + 18, sculk_block, 0, 2);
		world.setBlock(i + 10, j + 29, k + 18, sculk_block, 0, 2);
		world.setBlock(i + 11, j + 29, k + 18, sculk_block, 0, 2);
		world.setBlock(i + 12, j + 29, k + 18, sculk_block, 0, 2);
		world.setBlock(i + 13, j + 29, k + 18, sculk_block, 0, 2);
		world.setBlock(i + 14, j + 29, k + 18, sculk_block, 0, 2);
		world.setBlock(i + 15, j + 29, k + 18, sculk_block, 0, 2);
		world.setBlock(i + 16, j + 29, k + 18, sculk_block, 0, 2);
		world.setBlock(i + 17, j + 29, k + 18, sculk_block, 0, 2);
		world.setBlock(i + 18, j + 29, k + 18, sculk_block, 0, 2);
		world.setBlock(i + 19, j + 29, k + 18, sculk_block, 0, 2);
		world.setBlock(i + 20, j + 29, k + 18, sculk_block, 0, 2);
		world.setBlock(i + 21, j + 29, k + 18, sculk_block, 0, 2);
		world.setBlock(i + 22, j + 29, k + 18, sculk_block, 0, 2);
		world.setBlock(i + 23, j + 29, k + 18, sculk_block, 0, 2);
		world.setBlock(i + 24, j + 29, k + 18, sculk_block, 0, 2);
		world.setBlock(i + 25, j + 29, k + 18, sculk_block, 0, 2);
		world.setBlock(i + 26, j + 29, k + 18, sculk_block, 0, 2);
		world.setBlock(i + 27, j + 29, k + 18, sculk_block, 0, 2);
		world.setBlock(i + 28, j + 29, k + 18, sculk_block, 0, 2);
		world.setBlock(i + 29, j + 29, k + 18, sculk_block, 0, 2);
		world.setBlock(i + 30, j + 29, k + 18, sculk_block, 0, 2);
		world.setBlock(i + 31, j + 29, k + 18, sculk_block, 0, 2);
		world.setBlock(i + 32, j + 29, k + 18, sculk_block, 0, 2);
		world.setBlock(i + 33, j + 29, k + 18, sculk_block, 0, 2);
		world.setBlock(i + 34, j + 29, k + 18, sculk_block, 0, 2);
		world.setBlock(i + 35, j + 29, k + 18, sculk_block, 0, 2);
		world.setBlock(i + 36, j + 29, k + 18, sculk_block, 0, 2);
		world.setBlock(i + 37, j + 29, k + 18, sculk_block, 0, 2);
		world.setBlock(i + 38, j + 29, k + 18, sculk_block, 0, 2);
		world.setBlock(i + 39, j + 29, k + 18, sculk_block, 0, 2);
		world.setBlock(i + 40, j + 29, k + 18, sculk_block, 0, 2);
		world.setBlock(i + 41, j + 29, k + 18, sculk_block, 0, 2);
		world.setBlock(i + 42, j + 29, k + 18, sculk_block, 0, 2);
		world.setBlock(i + 43, j + 29, k + 18, sculk_block, 0, 2);
		world.setBlock(i + 44, j + 29, k + 18, sculk_block, 0, 2);
		world.setBlock(i + 45, j + 29, k + 18, sculk_block, 0, 2);
		world.setBlock(i + 46, j + 29, k + 18, sculk_block, 0, 2);
		world.setBlock(i + 7, j + 29, k + 19, sculk_block, 0, 2);
		world.setBlock(i + 8, j + 29, k + 19, sculk_block, 0, 2);
		world.setBlock(i + 9, j + 29, k + 19, sculk_block, 0, 2);
		world.setBlock(i + 10, j + 29, k + 19, sculk_block, 0, 2);
		world.setBlock(i + 11, j + 29, k + 19, sculk_block, 0, 2);
		world.setBlock(i + 12, j + 29, k + 19, sculk_block, 0, 2);
		world.setBlock(i + 13, j + 29, k + 19, sculk_block, 0, 2);
		world.setBlock(i + 14, j + 29, k + 19, sculk_block, 0, 2);
		world.setBlock(i + 15, j + 29, k + 19, sculk_block, 0, 2);
		world.setBlock(i + 16, j + 29, k + 19, sculk_block, 0, 2);
		world.setBlock(i + 17, j + 29, k + 19, sculk_block, 0, 2);
		world.setBlock(i + 18, j + 29, k + 19, sculk_block, 0, 2);
		world.setBlock(i + 19, j + 29, k + 19, sculk_block, 0, 2);
		world.setBlock(i + 20, j + 29, k + 19, sculk_block, 0, 2);
		world.setBlock(i + 21, j + 29, k + 19, sculk_block, 0, 2);
		world.setBlock(i + 22, j + 29, k + 19, sculk_block, 0, 2);
		world.setBlock(i + 23, j + 29, k + 19, sculk_block, 0, 2);
		world.setBlock(i + 24, j + 29, k + 19, sculk_block, 0, 2);
		world.setBlock(i + 25, j + 29, k + 19, sculk_block, 0, 2);
		world.setBlock(i + 26, j + 29, k + 19, sculk_block, 0, 2);
		world.setBlock(i + 27, j + 29, k + 19, sculk_block, 0, 2);
		world.setBlock(i + 28, j + 29, k + 19, sculk_block, 0, 2);
		world.setBlock(i + 29, j + 29, k + 19, sculk_block, 0, 2);
		world.setBlock(i + 30, j + 29, k + 19, sculk_block, 0, 2);
		world.setBlock(i + 31, j + 29, k + 19, sculk_block, 0, 2);
		world.setBlock(i + 32, j + 29, k + 19, sculk_block, 0, 2);
		world.setBlock(i + 33, j + 29, k + 19, sculk_block, 0, 2);
		world.setBlock(i + 34, j + 29, k + 19, sculk_block, 0, 2);
		world.setBlock(i + 35, j + 29, k + 19, sculk_block, 0, 2);
		world.setBlock(i + 36, j + 29, k + 19, sculk_block, 0, 2);
		world.setBlock(i + 37, j + 29, k + 19, sculk_block, 0, 2);
		world.setBlock(i + 38, j + 29, k + 19, sculk_block, 0, 2);
		world.setBlock(i + 39, j + 29, k + 19, sculk_block, 0, 2);
		world.setBlock(i + 40, j + 29, k + 19, sculk_block, 0, 2);
		world.setBlock(i + 41, j + 29, k + 19, sculk_block, 0, 2);
		world.setBlock(i + 42, j + 29, k + 19, sculk_block, 0, 2);
		world.setBlock(i + 43, j + 29, k + 19, sculk_block, 0, 2);
		world.setBlock(i + 44, j + 29, k + 19, sculk_block, 0, 2);
		world.setBlock(i + 45, j + 29, k + 19, sculk_block, 0, 2);
		world.setBlock(i + 46, j + 29, k + 19, sculk_block, 0, 2);
		world.setBlock(i + 6, j + 29, k + 20, sculk_block, 0, 2);
		world.setBlock(i + 7, j + 29, k + 20, sculk_block, 0, 2);
		world.setBlock(i + 8, j + 29, k + 20, sculk_block, 0, 2);
		world.setBlock(i + 9, j + 29, k + 20, sculk_block, 0, 2);
		world.setBlock(i + 10, j + 29, k + 20, sculk_block, 0, 2);
		world.setBlock(i + 11, j + 29, k + 20, sculk_block, 0, 2);
		world.setBlock(i + 12, j + 29, k + 20, sculk_block, 0, 2);
		world.setBlock(i + 13, j + 29, k + 20, sculk_block, 0, 2);
		world.setBlock(i + 14, j + 29, k + 20, sculk_block, 0, 2);
		world.setBlock(i + 15, j + 29, k + 20, sculk_block, 0, 2);
		world.setBlock(i + 16, j + 29, k + 20, sculk_block, 0, 2);
		world.setBlock(i + 17, j + 29, k + 20, sculk_block, 0, 2);
		world.setBlock(i + 18, j + 29, k + 20, sculk_block, 0, 2);
		world.setBlock(i + 19, j + 29, k + 20, sculk_block, 0, 2);
		world.setBlock(i + 20, j + 29, k + 20, sculk_block, 0, 2);
		world.setBlock(i + 21, j + 29, k + 20, sculk_block, 0, 2);
		world.setBlock(i + 22, j + 29, k + 20, sculk_block, 0, 2);
		world.setBlock(i + 23, j + 29, k + 20, sculk_block, 0, 2);
		world.setBlock(i + 24, j + 29, k + 20, sculk_block, 0, 2);
		world.setBlock(i + 25, j + 29, k + 20, sculk_block, 0, 2);
		world.setBlock(i + 26, j + 29, k + 20, sculk_block, 0, 2);
		world.setBlock(i + 27, j + 29, k + 20, sculk_block, 0, 2);
		world.setBlock(i + 28, j + 29, k + 20, sculk_block, 0, 2);
		world.setBlock(i + 29, j + 29, k + 20, sculk_block, 0, 2);
		world.setBlock(i + 30, j + 29, k + 20, sculk_block, 0, 2);
		world.setBlock(i + 31, j + 29, k + 20, sculk_block, 0, 2);
		world.setBlock(i + 32, j + 29, k + 20, sculk_block, 0, 2);
		world.setBlock(i + 33, j + 29, k + 20, sculk_block, 0, 2);
		world.setBlock(i + 34, j + 29, k + 20, sculk_block, 0, 2);
		world.setBlock(i + 35, j + 29, k + 20, sculk_block, 0, 2);
		world.setBlock(i + 36, j + 29, k + 20, sculk_block, 0, 2);
		world.setBlock(i + 37, j + 29, k + 20, sculk_block, 0, 2);
		world.setBlock(i + 38, j + 29, k + 20, sculk_block, 0, 2);
		world.setBlock(i + 39, j + 29, k + 20, sculk_block, 0, 2);
		world.setBlock(i + 40, j + 29, k + 20, sculk_block, 0, 2);
		world.setBlock(i + 41, j + 29, k + 20, sculk_block, 0, 2);
		world.setBlock(i + 42, j + 29, k + 20, sculk_block, 0, 2);
		world.setBlock(i + 43, j + 29, k + 20, sculk_block, 0, 2);
		world.setBlock(i + 44, j + 29, k + 20, sculk_block, 0, 2);
		world.setBlock(i + 45, j + 29, k + 20, sculk_block, 0, 2);
		world.setBlock(i + 46, j + 29, k + 20, sculk_block, 0, 2);
		world.setBlock(i + 5, j + 29, k + 21, sculk_block, 0, 2);
		world.setBlock(i + 6, j + 29, k + 21, sculk_block, 0, 2);
		world.setBlock(i + 27, j + 29, k + 21, NovaCraftBlocks.sculk_spike, 0, 2);
		world.setBlock(i + 16, j + 29, k + 22, NovaCraftBlocks.sculk_spike, 0, 2);
		world.setBlock(i + 23, j + 29, k + 22, NovaCraftBlocks.sculk_tentacle_2, 0, 2);
		world.setBlock(i + 6, j + 29, k + 23, NovaCraftBlocks.sculk_tentacle_2, 0, 2);
		world.setBlock(i + 36, j + 29, k + 23, NovaCraftBlocks.sculk_tentacle_2, 0, 2);
		world.setBlock(i + 34, j + 29, k + 24, NovaCraftBlocks.sculk_spike, 0, 2);
		world.setBlock(i + 28, j + 30, k + 19, sculk_block, 0, 2);
		world.setBlock(i + 7, j + 30, k + 21, sculk_block, 0, 2);
		world.setBlock(i + 8, j + 30, k + 21, sculk_block, 0, 2);
		world.setBlock(i + 9, j + 30, k + 21, sculk_block, 0, 2);
		world.setBlock(i + 10, j + 30, k + 21, sculk_block, 0, 2);
		world.setBlock(i + 11, j + 30, k + 21, sculk_block, 0, 2);
		world.setBlock(i + 12, j + 30, k + 21, sculk_block, 0, 2);
		world.setBlock(i + 13, j + 30, k + 21, sculk_block, 0, 2);
		world.setBlock(i + 14, j + 30, k + 21, sculk_block, 0, 2);
		world.setBlock(i + 15, j + 30, k + 21, sculk_block, 0, 2);
		world.setBlock(i + 16, j + 30, k + 21, sculk_block, 0, 2);
		world.setBlock(i + 17, j + 30, k + 21, sculk_block, 0, 2);
		world.setBlock(i + 18, j + 30, k + 21, sculk_block, 0, 2);
		world.setBlock(i + 19, j + 30, k + 21, sculk_block, 0, 2);
		world.setBlock(i + 20, j + 30, k + 21, sculk_block, 0, 2);
		world.setBlock(i + 21, j + 30, k + 21, sculk_block, 0, 2);
		world.setBlock(i + 22, j + 30, k + 21, sculk_block, 0, 2);
		world.setBlock(i + 23, j + 30, k + 21, sculk_block, 0, 2);
		world.setBlock(i + 24, j + 30, k + 21, sculk_block, 0, 2);
		world.setBlock(i + 25, j + 30, k + 21, sculk_block, 0, 2);
		world.setBlock(i + 26, j + 30, k + 21, sculk_block, 0, 2);
		world.setBlock(i + 27, j + 30, k + 21, sculk_block, 0, 2);
		world.setBlock(i + 28, j + 30, k + 21, sculk_block, 0, 2);
		world.setBlock(i + 29, j + 30, k + 21, sculk_block, 0, 2);
		world.setBlock(i + 30, j + 30, k + 21, sculk_block, 0, 2);
		world.setBlock(i + 31, j + 30, k + 21, sculk_block, 0, 2);
		world.setBlock(i + 32, j + 30, k + 21, sculk_block, 0, 2);
		world.setBlock(i + 33, j + 30, k + 21, sculk_block, 0, 2);
		world.setBlock(i + 34, j + 30, k + 21, sculk_block, 0, 2);
		world.setBlock(i + 35, j + 30, k + 21, sculk_block, 0, 2);
		world.setBlock(i + 36, j + 30, k + 21, sculk_block, 0, 2);
		world.setBlock(i + 37, j + 30, k + 21, sculk_block, 0, 2);
		world.setBlock(i + 38, j + 30, k + 21, sculk_block, 0, 2);
		world.setBlock(i + 39, j + 30, k + 21, sculk_block, 0, 2);
		world.setBlock(i + 40, j + 30, k + 21, sculk_block, 0, 2);
		world.setBlock(i + 41, j + 30, k + 21, sculk_block, 0, 2);
		world.setBlock(i + 42, j + 30, k + 21, sculk_block, 0, 2);
		world.setBlock(i + 43, j + 30, k + 21, sculk_block, 0, 2);
		world.setBlock(i + 44, j + 30, k + 21, sculk_block, 0, 2);
		world.setBlock(i + 45, j + 30, k + 21, sculk_block, 0, 2);
		world.setBlock(i + 46, j + 30, k + 21, sculk_block, 0, 2);
		world.setBlock(i + 5, j + 30, k + 22, sculk_block, 0, 2);
		world.setBlock(i + 6, j + 30, k + 22, sculk_block, 0, 2);
		world.setBlock(i + 7, j + 30, k + 22, sculk_block, 0, 2);
		world.setBlock(i + 8, j + 30, k + 22, sculk_block, 0, 2);
		world.setBlock(i + 9, j + 30, k + 22, sculk_block, 0, 2);
		world.setBlock(i + 10, j + 30, k + 22, sculk_block, 0, 2);
		world.setBlock(i + 11, j + 30, k + 22, sculk_block, 0, 2);
		world.setBlock(i + 12, j + 30, k + 22, sculk_block, 0, 2);
		world.setBlock(i + 13, j + 30, k + 22, sculk_block, 0, 2);
		world.setBlock(i + 14, j + 30, k + 22, sculk_block, 0, 2);
		world.setBlock(i + 15, j + 30, k + 22, sculk_block, 0, 2);
		world.setBlock(i + 16, j + 30, k + 22, sculk_block, 0, 2);
		world.setBlock(i + 17, j + 30, k + 22, sculk_block, 0, 2);
		world.setBlock(i + 18, j + 30, k + 22, sculk_block, 0, 2);
		world.setBlock(i + 19, j + 30, k + 22, sculk_block, 0, 2);
		world.setBlock(i + 20, j + 30, k + 22, sculk_block, 0, 2);
		world.setBlock(i + 21, j + 30, k + 22, sculk_block, 0, 2);
		world.setBlock(i + 22, j + 30, k + 22, sculk_block, 0, 2);
		world.setBlock(i + 23, j + 30, k + 22, sculk_block, 0, 2);
		world.setBlock(i + 24, j + 30, k + 22, sculk_block, 0, 2);
		world.setBlock(i + 25, j + 30, k + 22, sculk_block, 0, 2);
		world.setBlock(i + 26, j + 30, k + 22, sculk_block, 0, 2);
		world.setBlock(i + 27, j + 30, k + 22, sculk_block, 0, 2);
		world.setBlock(i + 28, j + 30, k + 22, sculk_block, 0, 2);
		world.setBlock(i + 29, j + 30, k + 22, sculk_block, 0, 2);
		world.setBlock(i + 30, j + 30, k + 22, sculk_block, 0, 2);
		world.setBlock(i + 31, j + 30, k + 22, sculk_block, 0, 2);
		world.setBlock(i + 32, j + 30, k + 22, sculk_block, 0, 2);
		world.setBlock(i + 33, j + 30, k + 22, sculk_block, 0, 2);
		world.setBlock(i + 34, j + 30, k + 22, sculk_block, 0, 2);
		world.setBlock(i + 35, j + 30, k + 22, sculk_block, 0, 2);
		world.setBlock(i + 36, j + 30, k + 22, sculk_block, 0, 2);
		world.setBlock(i + 37, j + 30, k + 22, sculk_block, 0, 2);
		world.setBlock(i + 38, j + 30, k + 22, sculk_block, 0, 2);
		world.setBlock(i + 39, j + 30, k + 22, sculk_block, 0, 2);
		world.setBlock(i + 40, j + 30, k + 22, sculk_block, 0, 2);
		world.setBlock(i + 41, j + 30, k + 22, sculk_block, 0, 2);
		world.setBlock(i + 42, j + 30, k + 22, sculk_block, 0, 2);
		world.setBlock(i + 43, j + 30, k + 22, sculk_block, 0, 2);
		world.setBlock(i + 44, j + 30, k + 22, sculk_block, 0, 2);
		world.setBlock(i + 45, j + 30, k + 22, sculk_block, 0, 2);
		world.setBlock(i + 4, j + 30, k + 23, sculk_block, 0, 2);
		world.setBlock(i + 5, j + 30, k + 23, sculk_block, 0, 2);
		world.setBlock(i + 6, j + 30, k + 23, sculk_block, 0, 2);
		world.setBlock(i + 7, j + 30, k + 23, sculk_block, 0, 2);
		world.setBlock(i + 8, j + 30, k + 23, sculk_block, 0, 2);
		world.setBlock(i + 9, j + 30, k + 23, sculk_block, 0, 2);
		world.setBlock(i + 10, j + 30, k + 23, sculk_block, 0, 2);
		world.setBlock(i + 11, j + 30, k + 23, sculk_block, 0, 2);
		world.setBlock(i + 12, j + 30, k + 23, sculk_block, 0, 2);
		world.setBlock(i + 13, j + 30, k + 23, sculk_block, 0, 2);
		world.setBlock(i + 14, j + 30, k + 23, sculk_block, 0, 2);
		world.setBlock(i + 15, j + 30, k + 23, sculk_block, 0, 2);
		world.setBlock(i + 16, j + 30, k + 23, sculk_block, 0, 2);
		world.setBlock(i + 17, j + 30, k + 23, sculk_block, 0, 2);
		world.setBlock(i + 18, j + 30, k + 23, sculk_block, 0, 2);
		world.setBlock(i + 19, j + 30, k + 23, sculk_block, 0, 2);
		world.setBlock(i + 20, j + 30, k + 23, sculk_block, 0, 2);
		world.setBlock(i + 21, j + 30, k + 23, sculk_block, 0, 2);
		world.setBlock(i + 22, j + 30, k + 23, sculk_block, 0, 2);
		world.setBlock(i + 23, j + 30, k + 23, sculk_block, 0, 2);
		world.setBlock(i + 24, j + 30, k + 23, sculk_block, 0, 2);
		world.setBlock(i + 25, j + 30, k + 23, sculk_block, 0, 2);
		world.setBlock(i + 26, j + 30, k + 23, sculk_block, 0, 2);
		world.setBlock(i + 27, j + 30, k + 23, sculk_block, 0, 2);
		world.setBlock(i + 28, j + 30, k + 23, sculk_block, 0, 2);
		world.setBlock(i + 29, j + 30, k + 23, sculk_block, 0, 2);
		world.setBlock(i + 30, j + 30, k + 23, sculk_block, 0, 2);
		world.setBlock(i + 31, j + 30, k + 23, sculk_block, 0, 2);
		world.setBlock(i + 32, j + 30, k + 23, sculk_block, 0, 2);
		world.setBlock(i + 33, j + 30, k + 23, sculk_block, 0, 2);
		world.setBlock(i + 34, j + 30, k + 23, sculk_block, 0, 2);
		world.setBlock(i + 35, j + 30, k + 23, sculk_block, 0, 2);
		world.setBlock(i + 36, j + 30, k + 23, sculk_block, 0, 2);
		world.setBlock(i + 37, j + 30, k + 23, sculk_block, 0, 2);
		world.setBlock(i + 38, j + 30, k + 23, sculk_block, 0, 2);
		world.setBlock(i + 39, j + 30, k + 23, sculk_block, 0, 2);
		world.setBlock(i + 40, j + 30, k + 23, sculk_block, 0, 2);
		world.setBlock(i + 41, j + 30, k + 23, sculk_block, 0, 2);
		world.setBlock(i + 42, j + 30, k + 23, sculk_block, 0, 2);
		world.setBlock(i + 43, j + 30, k + 23, sculk_block, 0, 2);
		world.setBlock(i + 44, j + 30, k + 23, sculk_block, 0, 2);
		world.setBlock(i + 45, j + 30, k + 23, sculk_block, 0, 2);
		world.setBlock(i + 4, j + 30, k + 24, sculk_block, 0, 2);
		world.setBlock(i + 5, j + 30, k + 24, sculk_block, 0, 2);
		world.setBlock(i + 6, j + 30, k + 24, sculk_block, 0, 2);
		world.setBlock(i + 7, j + 30, k + 24, sculk_block, 0, 2);
		world.setBlock(i + 8, j + 30, k + 24, sculk_block, 0, 2);
		world.setBlock(i + 9, j + 30, k + 24, sculk_block, 0, 2);
		world.setBlock(i + 14, j + 30, k + 24, NovaCraftBlocks.sculk_spike, 0, 2);
		world.setBlock(i + 21, j + 30, k + 24, sculk_block, 0, 2);
		world.setBlock(i + 29, j + 30, k + 24, NovaCraftBlocks.sculk_spike, 0, 2);
		world.setBlock(i + 31, j + 30, k + 24, sculk_block, 0, 2);
		world.setBlock(i + 32, j + 30, k + 24, sculk_block, 0, 2);
		world.setBlock(i + 33, j + 30, k + 24, sculk_block, 0, 2);
		world.setBlock(i + 34, j + 30, k + 24, sculk_block, 0, 2);
		world.setBlock(i + 35, j + 30, k + 24, sculk_block, 0, 2);
		world.setBlock(i + 44, j + 30, k + 24, sculk_block, 0, 2);
		world.setBlock(i + 45, j + 30, k + 24, sculk_block, 0, 2);
		world.setBlock(i + 4, j + 30, k + 25, sculk_block, 0, 2);
		world.setBlock(i + 28, j + 30, k + 26, NovaCraftBlocks.sculk_tentacle_2, 0, 2);
		world.setBlock(i + 5, j + 30, k + 27, NovaCraftBlocks.sculk_spike, 0, 2);
		world.setBlock(i + 31, j + 30, k + 27, NovaCraftBlocks.sculk_spike, 0, 2);
		world.setBlock(i + 36, j + 30, k + 27, NovaCraftBlocks.sculk_spike, 0, 2);
		world.setBlock(i + 40, j + 30, k + 27, NovaCraftBlocks.sculk_tentacle_2, 0, 2);
		world.setBlock(i + 23, j + 31, k + 21, sculk_block, 0, 2);
		world.setBlock(i + 10, j + 31, k + 24, sculk_block, 0, 2);
		world.setBlock(i + 11, j + 31, k + 24, sculk_block, 0, 2);
		world.setBlock(i + 12, j + 31, k + 24, sculk_block, 0, 2);
		world.setBlock(i + 13, j + 31, k + 24, sculk_block, 0, 2);
		world.setBlock(i + 14, j + 31, k + 24, sculk_block, 0, 2);
		world.setBlock(i + 15, j + 31, k + 24, sculk_block, 0, 2);
		world.setBlock(i + 16, j + 31, k + 24, sculk_block, 0, 2);
		world.setBlock(i + 17, j + 31, k + 24, sculk_block, 0, 2);
		world.setBlock(i + 18, j + 31, k + 24, sculk_block, 0, 2);
		world.setBlock(i + 19, j + 31, k + 24, sculk_block, 0, 2);
		world.setBlock(i + 20, j + 31, k + 24, sculk_block, 0, 2);
		world.setBlock(i + 22, j + 31, k + 24, sculk_block, 0, 2);
		world.setBlock(i + 23, j + 31, k + 24, sculk_block, 0, 2);
		world.setBlock(i + 24, j + 31, k + 24, sculk_block, 0, 2);
		world.setBlock(i + 25, j + 31, k + 24, sculk_block, 0, 2);
		world.setBlock(i + 26, j + 31, k + 24, sculk_block, 0, 2);
		world.setBlock(i + 27, j + 31, k + 24, sculk_block, 0, 2);
		world.setBlock(i + 28, j + 31, k + 24, sculk_block, 0, 2);
		world.setBlock(i + 29, j + 31, k + 24, sculk_block, 0, 2);
		world.setBlock(i + 30, j + 31, k + 24, sculk_block, 0, 2);
		world.setBlock(i + 31, j + 31, k + 24, sculk_block, 0, 2);
		world.setBlock(i + 32, j + 31, k + 24, sculk_block, 0, 2);
		world.setBlock(i + 34, j + 31, k + 24, sculk_block, 0, 2);
		world.setBlock(i + 35, j + 31, k + 24, sculk_block, 0, 2);
		world.setBlock(i + 36, j + 31, k + 24, sculk_block, 0, 2);
		world.setBlock(i + 37, j + 31, k + 24, sculk_block, 0, 2);
		world.setBlock(i + 38, j + 31, k + 24, sculk_block, 0, 2);
		world.setBlock(i + 39, j + 31, k + 24, sculk_block, 0, 2);
		world.setBlock(i + 40, j + 31, k + 24, sculk_block, 0, 2);
		world.setBlock(i + 41, j + 31, k + 24, sculk_block, 0, 2);
		world.setBlock(i + 42, j + 31, k + 24, sculk_block, 0, 2);
		world.setBlock(i + 43, j + 31, k + 24, sculk_block, 0, 2);
		world.setBlock(i + 44, j + 31, k + 24, sculk_block, 0, 2);
		world.setBlock(i + 5, j + 31, k + 25, sculk_block, 0, 2);
		world.setBlock(i + 6, j + 31, k + 25, sculk_block, 0, 2);
		world.setBlock(i + 7, j + 31, k + 25, sculk_block, 0, 2);
		world.setBlock(i + 8, j + 31, k + 25, sculk_block, 0, 2);
		world.setBlock(i + 9, j + 31, k + 25, sculk_block, 0, 2);
		world.setBlock(i + 10, j + 31, k + 25, sculk_block, 0, 2);
		world.setBlock(i + 11, j + 31, k + 25, sculk_block, 0, 2);
		world.setBlock(i + 12, j + 31, k + 25, sculk_block, 0, 2);
		world.setBlock(i + 13, j + 31, k + 25, sculk_block, 0, 2);
		world.setBlock(i + 14, j + 31, k + 25, sculk_block, 0, 2);
		world.setBlock(i + 15, j + 31, k + 25, sculk_block, 0, 2);
		world.setBlock(i + 16, j + 31, k + 25, sculk_block, 0, 2);
		world.setBlock(i + 17, j + 31, k + 25, sculk_block, 0, 2);
		world.setBlock(i + 18, j + 31, k + 25, sculk_block, 0, 2);
		world.setBlock(i + 19, j + 31, k + 25, sculk_block, 0, 2);
		world.setBlock(i + 20, j + 31, k + 25, sculk_block, 0, 2);
		world.setBlock(i + 21, j + 31, k + 25, sculk_block, 0, 2);
		world.setBlock(i + 22, j + 31, k + 25, sculk_block, 0, 2);
		world.setBlock(i + 23, j + 31, k + 25, sculk_block, 0, 2);
		world.setBlock(i + 24, j + 31, k + 25, sculk_block, 0, 2);
		world.setBlock(i + 25, j + 31, k + 25, sculk_block, 0, 2);
		world.setBlock(i + 26, j + 31, k + 25, sculk_block, 0, 2);
		world.setBlock(i + 27, j + 31, k + 25, sculk_block, 0, 2);
		world.setBlock(i + 28, j + 31, k + 25, sculk_block, 0, 2);
		world.setBlock(i + 29, j + 31, k + 25, sculk_block, 0, 2);
		world.setBlock(i + 30, j + 31, k + 25, sculk_block, 0, 2);
		world.setBlock(i + 31, j + 31, k + 25, sculk_block, 0, 2);
		world.setBlock(i + 32, j + 31, k + 25, sculk_block, 0, 2);
		world.setBlock(i + 33, j + 31, k + 25, sculk_block, 0, 2);
		world.setBlock(i + 34, j + 31, k + 25, sculk_block, 0, 2);
		world.setBlock(i + 35, j + 31, k + 25, sculk_block, 0, 2);
		world.setBlock(i + 36, j + 31, k + 25, sculk_block, 0, 2);
		world.setBlock(i + 37, j + 31, k + 25, sculk_block, 0, 2);
		world.setBlock(i + 38, j + 31, k + 25, sculk_block, 0, 2);
		world.setBlock(i + 39, j + 31, k + 25, sculk_block, 0, 2);
		world.setBlock(i + 40, j + 31, k + 25, sculk_block, 0, 2);
		world.setBlock(i + 41, j + 31, k + 25, sculk_block, 0, 2);
		world.setBlock(i + 42, j + 31, k + 25, sculk_block, 0, 2);
		world.setBlock(i + 43, j + 31, k + 25, sculk_block, 0, 2);
		world.setBlock(i + 44, j + 31, k + 25, sculk_block, 0, 2);
		world.setBlock(i + 5, j + 31, k + 26, sculk_block, 0, 2);
		world.setBlock(i + 6, j + 31, k + 26, sculk_block, 0, 2);
		world.setBlock(i + 7, j + 31, k + 26, sculk_block, 0, 2);
		world.setBlock(i + 8, j + 31, k + 26, sculk_block, 0, 2);
		world.setBlock(i + 9, j + 31, k + 26, sculk_block, 0, 2);
		world.setBlock(i + 10, j + 31, k + 26, sculk_block, 0, 2);
		world.setBlock(i + 11, j + 31, k + 26, sculk_block, 0, 2);
		world.setBlock(i + 12, j + 31, k + 26, sculk_block, 0, 2);
		world.setBlock(i + 13, j + 31, k + 26, sculk_block, 0, 2);
		world.setBlock(i + 14, j + 31, k + 26, sculk_block, 0, 2);
		world.setBlock(i + 15, j + 31, k + 26, sculk_block, 0, 2);
		world.setBlock(i + 16, j + 31, k + 26, sculk_block, 0, 2);
		world.setBlock(i + 17, j + 31, k + 26, sculk_block, 0, 2);
		world.setBlock(i + 18, j + 31, k + 26, sculk_block, 0, 2);
		world.setBlock(i + 19, j + 31, k + 26, sculk_block, 0, 2);
		world.setBlock(i + 20, j + 31, k + 26, sculk_block, 0, 2);
		world.setBlock(i + 21, j + 31, k + 26, sculk_block, 0, 2);
		world.setBlock(i + 22, j + 31, k + 26, sculk_block, 0, 2);
		world.setBlock(i + 23, j + 31, k + 26, sculk_block, 0, 2);
		world.setBlock(i + 24, j + 31, k + 26, sculk_block, 0, 2);
		world.setBlock(i + 25, j + 31, k + 26, sculk_block, 0, 2);
		world.setBlock(i + 26, j + 31, k + 26, sculk_block, 0, 2);
		world.setBlock(i + 27, j + 31, k + 26, sculk_block, 0, 2);
		world.setBlock(i + 28, j + 31, k + 26, sculk_block, 0, 2);
		world.setBlock(i + 29, j + 31, k + 26, sculk_block, 0, 2);
		world.setBlock(i + 30, j + 31, k + 26, sculk_block, 0, 2);
		world.setBlock(i + 31, j + 31, k + 26, sculk_block, 0, 2);
		world.setBlock(i + 32, j + 31, k + 26, sculk_block, 0, 2);
		world.setBlock(i + 33, j + 31, k + 26, sculk_block, 0, 2);
		world.setBlock(i + 34, j + 31, k + 26, sculk_block, 0, 2);
		world.setBlock(i + 35, j + 31, k + 26, sculk_block, 0, 2);
		world.setBlock(i + 36, j + 31, k + 26, sculk_block, 0, 2);
		world.setBlock(i + 37, j + 31, k + 26, sculk_block, 0, 2);
		world.setBlock(i + 38, j + 31, k + 26, sculk_block, 0, 2);
		world.setBlock(i + 39, j + 31, k + 26, sculk_block, 0, 2);
		world.setBlock(i + 40, j + 31, k + 26, sculk_block, 0, 2);
		world.setBlock(i + 41, j + 31, k + 26, sculk_block, 0, 2);
		world.setBlock(i + 42, j + 31, k + 26, sculk_block, 0, 2);
		world.setBlock(i + 43, j + 31, k + 26, sculk_block, 0, 2);
		world.setBlock(i + 44, j + 31, k + 26, sculk_block, 0, 2);
		world.setBlock(i + 5, j + 31, k + 27, sculk_block, 0, 2);
		world.setBlock(i + 6, j + 31, k + 27, sculk_block, 0, 2);
		world.setBlock(i + 7, j + 31, k + 27, sculk_block, 0, 2);
		world.setBlock(i + 8, j + 31, k + 27, sculk_block, 0, 2);
		world.setBlock(i + 9, j + 31, k + 27, sculk_block, 0, 2);
		world.setBlock(i + 10, j + 31, k + 27, sculk_block, 0, 2);
		world.setBlock(i + 11, j + 31, k + 27, sculk_block, 0, 2);
		world.setBlock(i + 12, j + 31, k + 27, sculk_block, 0, 2);
		world.setBlock(i + 13, j + 31, k + 27, sculk_block, 0, 2);
		world.setBlock(i + 14, j + 31, k + 27, sculk_block, 0, 2);
		world.setBlock(i + 15, j + 31, k + 27, sculk_block, 0, 2);
		world.setBlock(i + 16, j + 31, k + 27, sculk_block, 0, 2);
		world.setBlock(i + 17, j + 31, k + 27, sculk_block, 0, 2);
		world.setBlock(i + 18, j + 31, k + 27, sculk_block, 0, 2);
		world.setBlock(i + 19, j + 31, k + 27, sculk_block, 0, 2);
		world.setBlock(i + 20, j + 31, k + 27, sculk_block, 0, 2);
		world.setBlock(i + 21, j + 31, k + 27, sculk_block, 0, 2);
		world.setBlock(i + 22, j + 31, k + 27, sculk_block, 0, 2);
		world.setBlock(i + 23, j + 31, k + 27, sculk_block, 0, 2);
		world.setBlock(i + 24, j + 31, k + 27, sculk_block, 0, 2);
		world.setBlock(i + 25, j + 31, k + 27, sculk_block, 0, 2);
		world.setBlock(i + 26, j + 31, k + 27, sculk_block, 0, 2);
		world.setBlock(i + 27, j + 31, k + 27, sculk_block, 0, 2);
		world.setBlock(i + 28, j + 31, k + 27, sculk_block, 0, 2);
		world.setBlock(i + 29, j + 31, k + 27, sculk_block, 0, 2);
		world.setBlock(i + 30, j + 31, k + 27, sculk_block, 0, 2);
		world.setBlock(i + 31, j + 31, k + 27, sculk_block, 0, 2);
		world.setBlock(i + 32, j + 31, k + 27, sculk_block, 0, 2);
		world.setBlock(i + 33, j + 31, k + 27, sculk_block, 0, 2);
		world.setBlock(i + 34, j + 31, k + 27, sculk_block, 0, 2);
		world.setBlock(i + 35, j + 31, k + 27, sculk_block, 0, 2);
		world.setBlock(i + 36, j + 31, k + 27, sculk_block, 0, 2);
		world.setBlock(i + 37, j + 31, k + 27, sculk_block, 0, 2);
		world.setBlock(i + 38, j + 31, k + 27, sculk_block, 0, 2);
		world.setBlock(i + 39, j + 31, k + 27, sculk_block, 0, 2);
		world.setBlock(i + 40, j + 31, k + 27, sculk_block, 0, 2);
		world.setBlock(i + 41, j + 31, k + 27, sculk_block, 0, 2);
		world.setBlock(i + 42, j + 31, k + 27, sculk_block, 0, 2);
		world.setBlock(i + 43, j + 31, k + 27, sculk_block, 0, 2);
		world.setBlock(i + 44, j + 31, k + 27, sculk_block, 0, 2);
		world.setBlock(i + 4, j + 31, k + 28, sculk_block, 0, 2);
		world.setBlock(i + 5, j + 31, k + 28, sculk_block, 0, 2);
		world.setBlock(i + 6, j + 31, k + 28, sculk_block, 0, 2);
		world.setBlock(i + 7, j + 31, k + 28, sculk_block, 0, 2);
		world.setBlock(i + 8, j + 31, k + 28, sculk_block, 0, 2);
		world.setBlock(i + 9, j + 31, k + 28, sculk_block, 0, 2);
		world.setBlock(i + 10, j + 31, k + 28, sculk_block, 0, 2);
		world.setBlock(i + 11, j + 31, k + 28, sculk_block, 0, 2);
		world.setBlock(i + 19, j + 31, k + 28, sculk_block, 0, 2);
		world.setBlock(i + 20, j + 31, k + 28, sculk_block, 0, 2);
		world.setBlock(i + 21, j + 31, k + 28, sculk_block, 0, 2);
		world.setBlock(i + 22, j + 31, k + 28, sculk_block, 0, 2);
		world.setBlock(i + 23, j + 31, k + 28, sculk_block, 0, 2);
		world.setBlock(i + 31, j + 31, k + 28, sculk_block, 0, 2);
		world.setBlock(i + 32, j + 31, k + 28, sculk_block, 0, 2);
		world.setBlock(i + 33, j + 31, k + 28, sculk_block, 0, 2);
		world.setBlock(i + 34, j + 31, k + 28, sculk_block, 0, 2);
		world.setBlock(i + 35, j + 31, k + 28, sculk_block, 0, 2);
		world.setBlock(i + 43, j + 31, k + 28, sculk_block, 0, 2);
		world.setBlock(i + 3, j + 31, k + 29, sculk_block, 0, 2);
		world.setBlock(i + 4, j + 31, k + 29, sculk_block, 0, 2);
		world.setBlock(i + 5, j + 31, k + 29, sculk_block, 0, 2);
		world.setBlock(i + 6, j + 31, k + 29, sculk_block, 0, 2);
		world.setBlock(i + 40, j + 31, k + 29, NovaCraftBlocks.sculk_tentacle_2, 0, 2);
		world.setBlock(i + 3, j + 31, k + 30, sculk_block, 0, 2);
		world.setBlock(i + 2, j + 31, k + 31, sculk_block, 0, 2);
		world.setBlock(i + 10, j + 31, k + 31, NovaCraftBlocks.sculk_spike, 0, 2);
		world.setBlock(i + 30, j + 31, k + 31, NovaCraftBlocks.sculk_spike, 0, 2);
		world.setBlock(i + 20, j + 31, k + 32, NovaCraftBlocks.sculk_spike, 0, 2);
		world.setBlock(i + 41, j + 31, k + 33, NovaCraftBlocks.sculk_tentacle_2, 0, 2);
		world.setBlock(i + 12, j + 32, k + 28, sculk_block, 0, 2);
		world.setBlock(i + 13, j + 32, k + 28, sculk_block, 0, 2);
		world.setBlock(i + 14, j + 32, k + 28, sculk_block, 0, 2);
		world.setBlock(i + 15, j + 32, k + 28, sculk_block, 0, 2);
		world.setBlock(i + 16, j + 32, k + 28, sculk_block, 0, 2);
		world.setBlock(i + 17, j + 32, k + 28, sculk_block, 0, 2);
		world.setBlock(i + 18, j + 32, k + 28, sculk_block, 0, 2);
		world.setBlock(i + 24, j + 32, k + 28, sculk_block, 0, 2);
		world.setBlock(i + 25, j + 32, k + 28, sculk_block, 0, 2);
		world.setBlock(i + 26, j + 32, k + 28, sculk_block, 0, 2);
		world.setBlock(i + 27, j + 32, k + 28, sculk_block, 0, 2);
		world.setBlock(i + 28, j + 32, k + 28, sculk_block, 0, 2);
		world.setBlock(i + 29, j + 32, k + 28, sculk_block, 0, 2);
		world.setBlock(i + 30, j + 32, k + 28, sculk_block, 0, 2);
		world.setBlock(i + 36, j + 32, k + 28, sculk_block, 0, 2);
		world.setBlock(i + 37, j + 32, k + 28, sculk_block, 0, 2);
		world.setBlock(i + 38, j + 32, k + 28, sculk_block, 0, 2);
		world.setBlock(i + 39, j + 32, k + 28, sculk_block, 0, 2);
		world.setBlock(i + 40, j + 32, k + 28, sculk_block, 0, 2);
		world.setBlock(i + 41, j + 32, k + 28, sculk_block, 0, 2);
		world.setBlock(i + 42, j + 32, k + 28, sculk_block, 0, 2);
		world.setBlock(i + 7, j + 32, k + 29, sculk_block, 0, 2);
		world.setBlock(i + 8, j + 32, k + 29, sculk_block, 0, 2);
		world.setBlock(i + 9, j + 32, k + 29, sculk_block, 0, 2);
		world.setBlock(i + 10, j + 32, k + 29, sculk_block, 0, 2);
		world.setBlock(i + 11, j + 32, k + 29, sculk_block, 0, 2);
		world.setBlock(i + 12, j + 32, k + 29, sculk_block, 0, 2);
		world.setBlock(i + 13, j + 32, k + 29, sculk_block, 0, 2);
		world.setBlock(i + 14, j + 32, k + 29, sculk_block, 0, 2);
		world.setBlock(i + 15, j + 32, k + 29, sculk_block, 0, 2);
		world.setBlock(i + 16, j + 32, k + 29, sculk_block, 0, 2);
		world.setBlock(i + 17, j + 32, k + 29, sculk_block, 0, 2);
		world.setBlock(i + 18, j + 32, k + 29, sculk_block, 0, 2);
		world.setBlock(i + 19, j + 32, k + 29, sculk_block, 0, 2);
		world.setBlock(i + 20, j + 32, k + 29, sculk_block, 0, 2);
		world.setBlock(i + 21, j + 32, k + 29, sculk_block, 0, 2);
		world.setBlock(i + 22, j + 32, k + 29, sculk_block, 0, 2);
		world.setBlock(i + 23, j + 32, k + 29, sculk_block, 0, 2);
		world.setBlock(i + 24, j + 32, k + 29, sculk_block, 0, 2);
		world.setBlock(i + 25, j + 32, k + 29, sculk_block, 0, 2);
		world.setBlock(i + 26, j + 32, k + 29, sculk_block, 0, 2);
		world.setBlock(i + 27, j + 32, k + 29, sculk_block, 0, 2);
		world.setBlock(i + 28, j + 32, k + 29, sculk_block, 0, 2);
		world.setBlock(i + 29, j + 32, k + 29, sculk_block, 0, 2);
		world.setBlock(i + 30, j + 32, k + 29, sculk_block, 0, 2);
		world.setBlock(i + 31, j + 32, k + 29, sculk_block, 0, 2);
		world.setBlock(i + 32, j + 32, k + 29, sculk_block, 0, 2);
		world.setBlock(i + 33, j + 32, k + 29, sculk_block, 0, 2);
		world.setBlock(i + 34, j + 32, k + 29, sculk_block, 0, 2);
		world.setBlock(i + 35, j + 32, k + 29, sculk_block, 0, 2);
		world.setBlock(i + 36, j + 32, k + 29, sculk_block, 0, 2);
		world.setBlock(i + 37, j + 32, k + 29, sculk_block, 0, 2);
		world.setBlock(i + 38, j + 32, k + 29, sculk_block, 0, 2);
		world.setBlock(i + 39, j + 32, k + 29, sculk_block, 0, 2);
		world.setBlock(i + 40, j + 32, k + 29, sculk_block, 0, 2);
		world.setBlock(i + 41, j + 32, k + 29, sculk_block, 0, 2);
		world.setBlock(i + 42, j + 32, k + 29, sculk_block, 0, 2);
		world.setBlock(i + 4, j + 32, k + 30, sculk_block, 0, 2);
		world.setBlock(i + 5, j + 32, k + 30, sculk_block, 0, 2);
		world.setBlock(i + 6, j + 32, k + 30, sculk_block, 0, 2);
		world.setBlock(i + 7, j + 32, k + 30, sculk_block, 0, 2);
		world.setBlock(i + 8, j + 32, k + 30, sculk_block, 0, 2);
		world.setBlock(i + 9, j + 32, k + 30, sculk_block, 0, 2);
		world.setBlock(i + 10, j + 32, k + 30, sculk_block, 0, 2);
		world.setBlock(i + 11, j + 32, k + 30, sculk_block, 0, 2);
		world.setBlock(i + 12, j + 32, k + 30, sculk_block, 0, 2);
		world.setBlock(i + 13, j + 32, k + 30, sculk_block, 0, 2);
		world.setBlock(i + 14, j + 32, k + 30, sculk_block, 0, 2);
		world.setBlock(i + 15, j + 32, k + 30, sculk_block, 0, 2);
		world.setBlock(i + 16, j + 32, k + 30, sculk_block, 0, 2);
		world.setBlock(i + 17, j + 32, k + 30, sculk_block, 0, 2);
		world.setBlock(i + 18, j + 32, k + 30, sculk_block, 0, 2);
		world.setBlock(i + 19, j + 32, k + 30, sculk_block, 0, 2);
		world.setBlock(i + 20, j + 32, k + 30, sculk_block, 0, 2);
		world.setBlock(i + 21, j + 32, k + 30, sculk_block, 0, 2);
		world.setBlock(i + 22, j + 32, k + 30, sculk_block, 0, 2);
		world.setBlock(i + 23, j + 32, k + 30, sculk_block, 0, 2);
		world.setBlock(i + 24, j + 32, k + 30, sculk_block, 0, 2);
		world.setBlock(i + 25, j + 32, k + 30, sculk_block, 0, 2);
		world.setBlock(i + 26, j + 32, k + 30, sculk_block, 0, 2);
		world.setBlock(i + 27, j + 32, k + 30, sculk_block, 0, 2);
		world.setBlock(i + 28, j + 32, k + 30, sculk_block, 0, 2);
		world.setBlock(i + 29, j + 32, k + 30, sculk_block, 0, 2);
		world.setBlock(i + 30, j + 32, k + 30, sculk_block, 0, 2);
		world.setBlock(i + 31, j + 32, k + 30, sculk_block, 0, 2);
		world.setBlock(i + 32, j + 32, k + 30, sculk_block, 0, 2);
		world.setBlock(i + 33, j + 32, k + 30, sculk_block, 0, 2);
		world.setBlock(i + 34, j + 32, k + 30, sculk_block, 0, 2);
		world.setBlock(i + 35, j + 32, k + 30, sculk_block, 0, 2);
		world.setBlock(i + 36, j + 32, k + 30, sculk_block, 0, 2);
		world.setBlock(i + 37, j + 32, k + 30, sculk_block, 0, 2);
		world.setBlock(i + 38, j + 32, k + 30, sculk_block, 0, 2);
		world.setBlock(i + 39, j + 32, k + 30, sculk_block, 0, 2);
		world.setBlock(i + 40, j + 32, k + 30, sculk_block, 0, 2);
		world.setBlock(i + 41, j + 32, k + 30, sculk_block, 0, 2);
		world.setBlock(i + 42, j + 32, k + 30, sculk_block, 0, 2);
		world.setBlock(i + 2, j + 32, k + 31, sculk_block, 0, 2);
		world.setBlock(i + 3, j + 32, k + 31, sculk_block, 0, 2);
		world.setBlock(i + 4, j + 32, k + 31, sculk_block, 0, 2);
		world.setBlock(i + 5, j + 32, k + 31, sculk_block, 0, 2);
		world.setBlock(i + 6, j + 32, k + 31, sculk_block, 0, 2);
		world.setBlock(i + 7, j + 32, k + 31, sculk_block, 0, 2);
		world.setBlock(i + 8, j + 32, k + 31, sculk_block, 0, 2);
		world.setBlock(i + 9, j + 32, k + 31, sculk_block, 0, 2);
		world.setBlock(i + 10, j + 32, k + 31, sculk_block, 0, 2);
		world.setBlock(i + 11, j + 32, k + 31, sculk_block, 0, 2);
		world.setBlock(i + 12, j + 32, k + 31, sculk_block, 0, 2);
		world.setBlock(i + 13, j + 32, k + 31, sculk_block, 0, 2);
		world.setBlock(i + 14, j + 32, k + 31, sculk_block, 0, 2);
		world.setBlock(i + 15, j + 32, k + 31, sculk_block, 0, 2);
		world.setBlock(i + 16, j + 32, k + 31, sculk_block, 0, 2);
		world.setBlock(i + 17, j + 32, k + 31, sculk_block, 0, 2);
		world.setBlock(i + 18, j + 32, k + 31, sculk_block, 0, 2);
		world.setBlock(i + 19, j + 32, k + 31, sculk_block, 0, 2);
		world.setBlock(i + 20, j + 32, k + 31, sculk_block, 0, 2);
		world.setBlock(i + 21, j + 32, k + 31, sculk_block, 0, 2);
		world.setBlock(i + 22, j + 32, k + 31, sculk_block, 0, 2);
		world.setBlock(i + 23, j + 32, k + 31, sculk_block, 0, 2);
		world.setBlock(i + 24, j + 32, k + 31, sculk_block, 0, 2);
		world.setBlock(i + 25, j + 32, k + 31, sculk_block, 0, 2);
		world.setBlock(i + 26, j + 32, k + 31, sculk_block, 0, 2);
		world.setBlock(i + 27, j + 32, k + 31, sculk_block, 0, 2);
		world.setBlock(i + 28, j + 32, k + 31, sculk_block, 0, 2);
		world.setBlock(i + 29, j + 32, k + 31, sculk_block, 0, 2);
		world.setBlock(i + 30, j + 32, k + 31, sculk_block, 0, 2);
		world.setBlock(i + 31, j + 32, k + 31, sculk_block, 0, 2);
		world.setBlock(i + 32, j + 32, k + 31, sculk_block, 0, 2);
		world.setBlock(i + 33, j + 32, k + 31, sculk_block, 0, 2);
		world.setBlock(i + 34, j + 32, k + 31, sculk_block, 0, 2);
		world.setBlock(i + 35, j + 32, k + 31, sculk_block, 0, 2);
		world.setBlock(i + 36, j + 32, k + 31, sculk_block, 0, 2);
		world.setBlock(i + 37, j + 32, k + 31, sculk_block, 0, 2);
		world.setBlock(i + 38, j + 32, k + 31, sculk_block, 0, 2);
		world.setBlock(i + 39, j + 32, k + 31, sculk_block, 0, 2);
		world.setBlock(i + 40, j + 32, k + 31, sculk_block, 0, 2);
		world.setBlock(i + 41, j + 32, k + 31, sculk_block, 0, 2);
		world.setBlock(i + 42, j + 32, k + 31, sculk_block, 0, 2);
		world.setBlock(i + 43, j + 32, k + 31, sculk_block, 0, 2);
		world.setBlock(i + 2, j + 32, k + 32, sculk_block, 0, 2);
		world.setBlock(i + 3, j + 32, k + 32, sculk_block, 0, 2);
		world.setBlock(i + 4, j + 32, k + 32, sculk_block, 0, 2);
		world.setBlock(i + 5, j + 32, k + 32, sculk_block, 0, 2);
		world.setBlock(i + 6, j + 32, k + 32, sculk_block, 0, 2);
		world.setBlock(i + 7, j + 32, k + 32, sculk_block, 0, 2);
		world.setBlock(i + 8, j + 32, k + 32, sculk_block, 0, 2);
		world.setBlock(i + 9, j + 32, k + 32, sculk_block, 0, 2);
		world.setBlock(i + 10, j + 32, k + 32, sculk_block, 0, 2);
		world.setBlock(i + 11, j + 32, k + 32, sculk_block, 0, 2);
		world.setBlock(i + 12, j + 32, k + 32, sculk_block, 0, 2);
		world.setBlock(i + 13, j + 32, k + 32, sculk_block, 0, 2);
		world.setBlock(i + 14, j + 32, k + 32, sculk_block, 0, 2);
		world.setBlock(i + 15, j + 32, k + 32, sculk_block, 0, 2);
		world.setBlock(i + 16, j + 32, k + 32, sculk_block, 0, 2);
		world.setBlock(i + 17, j + 32, k + 32, sculk_block, 0, 2);
		world.setBlock(i + 18, j + 32, k + 32, sculk_block, 0, 2);
		world.setBlock(i + 19, j + 32, k + 32, sculk_block, 0, 2);
		world.setBlock(i + 20, j + 32, k + 32, sculk_block, 0, 2);
		world.setBlock(i + 21, j + 32, k + 32, sculk_block, 0, 2);
		world.setBlock(i + 22, j + 32, k + 32, sculk_block, 0, 2);
		world.setBlock(i + 23, j + 32, k + 32, sculk_block, 0, 2);
		world.setBlock(i + 24, j + 32, k + 32, sculk_block, 0, 2);
		world.setBlock(i + 25, j + 32, k + 32, sculk_block, 0, 2);
		world.setBlock(i + 26, j + 32, k + 32, sculk_block, 0, 2);
		world.setBlock(i + 27, j + 32, k + 32, sculk_block, 0, 2);
		world.setBlock(i + 28, j + 32, k + 32, sculk_block, 0, 2);
		world.setBlock(i + 29, j + 32, k + 32, sculk_block, 0, 2);
		world.setBlock(i + 30, j + 32, k + 32, sculk_block, 0, 2);
		world.setBlock(i + 31, j + 32, k + 32, sculk_block, 0, 2);
		world.setBlock(i + 32, j + 32, k + 32, sculk_block, 0, 2);
		world.setBlock(i + 33, j + 32, k + 32, sculk_block, 0, 2);
		world.setBlock(i + 34, j + 32, k + 32, sculk_block, 0, 2);
		world.setBlock(i + 35, j + 32, k + 32, sculk_block, 0, 2);
		world.setBlock(i + 36, j + 32, k + 32, sculk_block, 0, 2);
		world.setBlock(i + 37, j + 32, k + 32, sculk_block, 0, 2);
		world.setBlock(i + 38, j + 32, k + 32, sculk_block, 0, 2);
		world.setBlock(i + 39, j + 32, k + 32, sculk_block, 0, 2);
		world.setBlock(i + 40, j + 32, k + 32, sculk_block, 0, 2);
		world.setBlock(i + 41, j + 32, k + 32, sculk_block, 0, 2);
		world.setBlock(i + 42, j + 32, k + 32, sculk_block, 0, 2);
		world.setBlock(i + 43, j + 32, k + 32, sculk_block, 0, 2);
		world.setBlock(i + 2, j + 32, k + 33, sculk_block, 0, 2);
		world.setBlock(i + 3, j + 32, k + 33, sculk_block, 0, 2);
		world.setBlock(i + 4, j + 32, k + 33, sculk_block, 0, 2);
		world.setBlock(i + 5, j + 32, k + 33, sculk_block, 0, 2);
		world.setBlock(i + 6, j + 32, k + 33, sculk_block, 0, 2);
		world.setBlock(i + 7, j + 32, k + 33, sculk_block, 0, 2);
		world.setBlock(i + 8, j + 32, k + 33, sculk_block, 0, 2);
		world.setBlock(i + 9, j + 32, k + 33, sculk_block, 0, 2);
		world.setBlock(i + 10, j + 32, k + 33, sculk_block, 0, 2);
		world.setBlock(i + 11, j + 32, k + 33, sculk_block, 0, 2);
		world.setBlock(i + 12, j + 32, k + 33, sculk_block, 0, 2);
		world.setBlock(i + 13, j + 32, k + 33, sculk_block, 0, 2);
		world.setBlock(i + 14, j + 32, k + 33, sculk_block, 0, 2);
		world.setBlock(i + 15, j + 32, k + 33, sculk_block, 0, 2);
		world.setBlock(i + 16, j + 32, k + 33, sculk_block, 0, 2);
		world.setBlock(i + 17, j + 32, k + 33, sculk_block, 0, 2);
		world.setBlock(i + 18, j + 32, k + 33, sculk_block, 0, 2);
		world.setBlock(i + 19, j + 32, k + 33, sculk_block, 0, 2);
		world.setBlock(i + 20, j + 32, k + 33, sculk_block, 0, 2);
		world.setBlock(i + 21, j + 32, k + 33, sculk_block, 0, 2);
		world.setBlock(i + 22, j + 32, k + 33, sculk_block, 0, 2);
		world.setBlock(i + 23, j + 32, k + 33, sculk_block, 0, 2);
		world.setBlock(i + 24, j + 32, k + 33, sculk_block, 0, 2);
		world.setBlock(i + 25, j + 32, k + 33, sculk_block, 0, 2);
		world.setBlock(i + 26, j + 32, k + 33, sculk_block, 0, 2);
		world.setBlock(i + 27, j + 32, k + 33, sculk_block, 0, 2);
		world.setBlock(i + 28, j + 32, k + 33, sculk_block, 0, 2);
		world.setBlock(i + 29, j + 32, k + 33, sculk_block, 0, 2);
		world.setBlock(i + 30, j + 32, k + 33, sculk_block, 0, 2);
		world.setBlock(i + 31, j + 32, k + 33, sculk_block, 0, 2);
		world.setBlock(i + 32, j + 32, k + 33, sculk_block, 0, 2);
		world.setBlock(i + 33, j + 32, k + 33, sculk_block, 0, 2);
		world.setBlock(i + 34, j + 32, k + 33, sculk_block, 0, 2);
		world.setBlock(i + 35, j + 32, k + 33, sculk_block, 0, 2);
		world.setBlock(i + 36, j + 32, k + 33, sculk_block, 0, 2);
		world.setBlock(i + 37, j + 32, k + 33, sculk_block, 0, 2);
		world.setBlock(i + 38, j + 32, k + 33, sculk_block, 0, 2);
		world.setBlock(i + 39, j + 32, k + 33, sculk_block, 0, 2);
		world.setBlock(i + 40, j + 32, k + 33, sculk_block, 0, 2);
		world.setBlock(i + 41, j + 32, k + 33, sculk_block, 0, 2);
		world.setBlock(i + 42, j + 32, k + 33, sculk_block, 0, 2);
		world.setBlock(i + 43, j + 32, k + 33, sculk_block, 0, 2);
		world.setBlock(i + 3, j + 32, k + 34, sculk_block, 0, 2);
		world.setBlock(i + 4, j + 32, k + 34, sculk_block, 0, 2);
		world.setBlock(i + 5, j + 32, k + 34, sculk_block, 0, 2);
		world.setBlock(i + 6, j + 32, k + 34, sculk_block, 0, 2);
		world.setBlock(i + 7, j + 32, k + 34, sculk_block, 0, 2);
		world.setBlock(i + 8, j + 32, k + 34, sculk_block, 0, 2);
		world.setBlock(i + 3, j + 32, k + 35, sculk_block, 0, 2);
		world.setBlock(i + 4, j + 32, k + 35, sculk_block, 0, 2);
		world.setBlock(i + 5, j + 32, k + 35, sculk_block, 0, 2);
		world.setBlock(i + 34, j + 32, k + 35, NovaCraftBlocks.sculk_tentacle_2, 0, 2);
		world.setBlock(i + 40, j + 32, k + 36, NovaCraftBlocks.sculk_tentacle_2, 0, 2);
		world.setBlock(i + 11, j + 32, k + 37, NovaCraftBlocks.sculk_spike, 0, 2);
		world.setBlock(i + 21, j + 32, k + 38, NovaCraftBlocks.sculk_spike, 0, 2);
		world.setBlock(i + 26, j + 32, k + 38, NovaCraftBlocks.sculk_spike, 0, 2);
		world.setBlock(i + 14, j + 32, k + 39, NovaCraftBlocks.sculk_spike, 0, 2);
		world.setBlock(i + 10, j + 32, k + 40, NovaCraftBlocks.sculk_spike, 0, 2);
		world.setBlock(i + 15, j + 32, k + 40, NovaCraftBlocks.sculk_tentacle_2, 0, 2);
		world.setBlock(i + 21, j + 32, k + 40, NovaCraftBlocks.sculk_tentacle_2, 0, 2);
		world.setBlock(i + 8, j + 32, k + 41, NovaCraftBlocks.sculk_tentacle_2, 0, 2);
		world.setBlock(i + 40, j + 33, k + 29, sculk_block, 0, 2);
		world.setBlock(i + 39, j + 33, k + 30, sculk_block, 0, 2);
		world.setBlock(i + 40, j + 33, k + 30, sculk_block, 0, 2);
		world.setBlock(i + 9, j + 33, k + 34, sculk_block, 0, 2);
		world.setBlock(i + 10, j + 33, k + 34, sculk_block, 0, 2);
		world.setBlock(i + 11, j + 33, k + 34, sculk_block, 0, 2);
		world.setBlock(i + 12, j + 33, k + 34, sculk_block, 0, 2);
		world.setBlock(i + 13, j + 33, k + 34, sculk_block, 0, 2);
		world.setBlock(i + 14, j + 33, k + 34, sculk_block, 0, 2);
		world.setBlock(i + 15, j + 33, k + 34, sculk_block, 0, 2);
		world.setBlock(i + 16, j + 33, k + 34, sculk_block, 0, 2);
		world.setBlock(i + 17, j + 33, k + 34, sculk_block, 0, 2);
		world.setBlock(i + 18, j + 33, k + 34, sculk_block, 0, 2);
		world.setBlock(i + 19, j + 33, k + 34, sculk_block, 0, 2);
		world.setBlock(i + 20, j + 33, k + 34, sculk_block, 0, 2);
		world.setBlock(i + 21, j + 33, k + 34, sculk_block, 0, 2);
		world.setBlock(i + 22, j + 33, k + 34, sculk_block, 0, 2);
		world.setBlock(i + 23, j + 33, k + 34, sculk_block, 0, 2);
		world.setBlock(i + 24, j + 33, k + 34, sculk_block, 0, 2);
		world.setBlock(i + 25, j + 33, k + 34, sculk_block, 0, 2);
		world.setBlock(i + 26, j + 33, k + 34, sculk_block, 0, 2);
		world.setBlock(i + 27, j + 33, k + 34, sculk_block, 0, 2);
		world.setBlock(i + 28, j + 33, k + 34, sculk_block, 0, 2);
		world.setBlock(i + 29, j + 33, k + 34, sculk_block, 0, 2);
		world.setBlock(i + 30, j + 33, k + 34, sculk_block, 0, 2);
		world.setBlock(i + 31, j + 33, k + 34, sculk_block, 0, 2);
		world.setBlock(i + 32, j + 33, k + 34, sculk_block, 0, 2);
		world.setBlock(i + 33, j + 33, k + 34, sculk_block, 0, 2);
		world.setBlock(i + 34, j + 33, k + 34, sculk_block, 0, 2);
		world.setBlock(i + 35, j + 33, k + 34, sculk_block, 0, 2);
		world.setBlock(i + 36, j + 33, k + 34, sculk_block, 0, 2);
		world.setBlock(i + 37, j + 33, k + 34, sculk_block, 0, 2);
		world.setBlock(i + 38, j + 33, k + 34, sculk_block, 0, 2);
		world.setBlock(i + 39, j + 33, k + 34, sculk_block, 0, 2);
		world.setBlock(i + 40, j + 33, k + 34, sculk_block, 0, 2);
		world.setBlock(i + 41, j + 33, k + 34, sculk_block, 0, 2);
		world.setBlock(i + 42, j + 33, k + 34, sculk_block, 0, 2);
		world.setBlock(i + 43, j + 33, k + 34, sculk_block, 0, 2);
		world.setBlock(i + 6, j + 33, k + 35, sculk_block, 0, 2);
		world.setBlock(i + 7, j + 33, k + 35, sculk_block, 0, 2);
		world.setBlock(i + 8, j + 33, k + 35, sculk_block, 0, 2);
		world.setBlock(i + 9, j + 33, k + 35, sculk_block, 0, 2);
		world.setBlock(i + 10, j + 33, k + 35, sculk_block, 0, 2);
		world.setBlock(i + 11, j + 33, k + 35, sculk_block, 0, 2);
		world.setBlock(i + 12, j + 33, k + 35, sculk_block, 0, 2);
		world.setBlock(i + 13, j + 33, k + 35, sculk_block, 0, 2);
		world.setBlock(i + 14, j + 33, k + 35, sculk_block, 0, 2);
		world.setBlock(i + 15, j + 33, k + 35, sculk_block, 0, 2);
		world.setBlock(i + 16, j + 33, k + 35, sculk_block, 0, 2);
		world.setBlock(i + 17, j + 33, k + 35, sculk_block, 0, 2);
		world.setBlock(i + 18, j + 33, k + 35, sculk_block, 0, 2);
		world.setBlock(i + 19, j + 33, k + 35, sculk_block, 0, 2);
		world.setBlock(i + 20, j + 33, k + 35, sculk_block, 0, 2);
		world.setBlock(i + 21, j + 33, k + 35, sculk_block, 0, 2);
		world.setBlock(i + 22, j + 33, k + 35, sculk_block, 0, 2);
		world.setBlock(i + 23, j + 33, k + 35, sculk_block, 0, 2);
		world.setBlock(i + 24, j + 33, k + 35, sculk_block, 0, 2);
		world.setBlock(i + 25, j + 33, k + 35, sculk_block, 0, 2);
		world.setBlock(i + 26, j + 33, k + 35, sculk_block, 0, 2);
		world.setBlock(i + 27, j + 33, k + 35, sculk_block, 0, 2);
		world.setBlock(i + 28, j + 33, k + 35, sculk_block, 0, 2);
		world.setBlock(i + 29, j + 33, k + 35, sculk_block, 0, 2);
		world.setBlock(i + 30, j + 33, k + 35, sculk_block, 0, 2);
		world.setBlock(i + 31, j + 33, k + 35, sculk_block, 0, 2);
		world.setBlock(i + 32, j + 33, k + 35, sculk_block, 0, 2);
		world.setBlock(i + 33, j + 33, k + 35, sculk_block, 0, 2);
		world.setBlock(i + 34, j + 33, k + 35, sculk_block, 0, 2);
		world.setBlock(i + 35, j + 33, k + 35, sculk_block, 0, 2);
		world.setBlock(i + 36, j + 33, k + 35, sculk_block, 0, 2);
		world.setBlock(i + 37, j + 33, k + 35, sculk_block, 0, 2);
		world.setBlock(i + 38, j + 33, k + 35, sculk_block, 0, 2);
		world.setBlock(i + 39, j + 33, k + 35, sculk_block, 0, 2);
		world.setBlock(i + 40, j + 33, k + 35, sculk_block, 0, 2);
		world.setBlock(i + 41, j + 33, k + 35, sculk_block, 0, 2);
		world.setBlock(i + 42, j + 33, k + 35, sculk_block, 0, 2);
		world.setBlock(i + 6, j + 33, k + 36, sculk_block, 0, 2);
		world.setBlock(i + 7, j + 33, k + 36, sculk_block, 0, 2);
		world.setBlock(i + 8, j + 33, k + 36, sculk_block, 0, 2);
		world.setBlock(i + 9, j + 33, k + 36, sculk_block, 0, 2);
		world.setBlock(i + 10, j + 33, k + 36, sculk_block, 0, 2);
		world.setBlock(i + 11, j + 33, k + 36, sculk_block, 0, 2);
		world.setBlock(i + 12, j + 33, k + 36, sculk_block, 0, 2);
		world.setBlock(i + 13, j + 33, k + 36, sculk_block, 0, 2);
		world.setBlock(i + 14, j + 33, k + 36, sculk_block, 0, 2);
		world.setBlock(i + 15, j + 33, k + 36, sculk_block, 0, 2);
		world.setBlock(i + 16, j + 33, k + 36, sculk_block, 0, 2);
		world.setBlock(i + 17, j + 33, k + 36, sculk_block, 0, 2);
		world.setBlock(i + 18, j + 33, k + 36, sculk_block, 0, 2);
		world.setBlock(i + 19, j + 33, k + 36, sculk_block, 0, 2);
		world.setBlock(i + 20, j + 33, k + 36, sculk_block, 0, 2);
		world.setBlock(i + 21, j + 33, k + 36, sculk_block, 0, 2);
		world.setBlock(i + 22, j + 33, k + 36, sculk_block, 0, 2);
		world.setBlock(i + 23, j + 33, k + 36, sculk_block, 0, 2);
		world.setBlock(i + 24, j + 33, k + 36, sculk_block, 0, 2);
		world.setBlock(i + 25, j + 33, k + 36, sculk_block, 0, 2);
		world.setBlock(i + 26, j + 33, k + 36, sculk_block, 0, 2);
		world.setBlock(i + 27, j + 33, k + 36, sculk_block, 0, 2);
		world.setBlock(i + 28, j + 33, k + 36, sculk_block, 0, 2);
		world.setBlock(i + 29, j + 33, k + 36, sculk_block, 0, 2);
		world.setBlock(i + 30, j + 33, k + 36, sculk_block, 0, 2);
		world.setBlock(i + 31, j + 33, k + 36, sculk_block, 0, 2);
		world.setBlock(i + 32, j + 33, k + 36, sculk_block, 0, 2);
		world.setBlock(i + 33, j + 33, k + 36, sculk_block, 0, 2);
		world.setBlock(i + 34, j + 33, k + 36, sculk_block, 0, 2);
		world.setBlock(i + 35, j + 33, k + 36, sculk_block, 0, 2);
		world.setBlock(i + 36, j + 33, k + 36, sculk_block, 0, 2);
		world.setBlock(i + 37, j + 33, k + 36, sculk_block, 0, 2);
		world.setBlock(i + 38, j + 33, k + 36, sculk_block, 0, 2);
		world.setBlock(i + 39, j + 33, k + 36, sculk_block, 0, 2);
		world.setBlock(i + 40, j + 33, k + 36, sculk_block, 0, 2);
		world.setBlock(i + 41, j + 33, k + 36, sculk_block, 0, 2);
		world.setBlock(i + 6, j + 33, k + 37, sculk_block, 0, 2);
		world.setBlock(i + 7, j + 33, k + 37, sculk_block, 0, 2);
		world.setBlock(i + 8, j + 33, k + 37, sculk_block, 0, 2);
		world.setBlock(i + 9, j + 33, k + 37, sculk_block, 0, 2);
		world.setBlock(i + 10, j + 33, k + 37, sculk_block, 0, 2);
		world.setBlock(i + 11, j + 33, k + 37, sculk_block, 0, 2);
		world.setBlock(i + 12, j + 33, k + 37, sculk_block, 0, 2);
		world.setBlock(i + 13, j + 33, k + 37, sculk_block, 0, 2);
		world.setBlock(i + 14, j + 33, k + 37, sculk_block, 0, 2);
		world.setBlock(i + 15, j + 33, k + 37, sculk_block, 0, 2);
		world.setBlock(i + 16, j + 33, k + 37, sculk_block, 0, 2);
		world.setBlock(i + 17, j + 33, k + 37, sculk_block, 0, 2);
		world.setBlock(i + 18, j + 33, k + 37, sculk_block, 0, 2);
		world.setBlock(i + 19, j + 33, k + 37, sculk_block, 0, 2);
		world.setBlock(i + 20, j + 33, k + 37, sculk_block, 0, 2);
		world.setBlock(i + 21, j + 33, k + 37, sculk_block, 0, 2);
		world.setBlock(i + 22, j + 33, k + 37, sculk_block, 0, 2);
		world.setBlock(i + 23, j + 33, k + 37, sculk_block, 0, 2);
		world.setBlock(i + 24, j + 33, k + 37, sculk_block, 0, 2);
		world.setBlock(i + 25, j + 33, k + 37, sculk_block, 0, 2);
		world.setBlock(i + 26, j + 33, k + 37, sculk_block, 0, 2);
		world.setBlock(i + 27, j + 33, k + 37, sculk_block, 0, 2);
		world.setBlock(i + 28, j + 33, k + 37, sculk_block, 0, 2);
		world.setBlock(i + 29, j + 33, k + 37, sculk_block, 0, 2);
		world.setBlock(i + 30, j + 33, k + 37, sculk_block, 0, 2);
		world.setBlock(i + 31, j + 33, k + 37, sculk_block, 0, 2);
		world.setBlock(i + 32, j + 33, k + 37, sculk_block, 0, 2);
		world.setBlock(i + 33, j + 33, k + 37, sculk_block, 0, 2);
		world.setBlock(i + 34, j + 33, k + 37, sculk_block, 0, 2);
		world.setBlock(i + 35, j + 33, k + 37, sculk_block, 0, 2);
		world.setBlock(i + 36, j + 33, k + 37, sculk_block, 0, 2);
		world.setBlock(i + 37, j + 33, k + 37, sculk_block, 0, 2);
		world.setBlock(i + 38, j + 33, k + 37, sculk_block, 0, 2);
		world.setBlock(i + 39, j + 33, k + 37, sculk_block, 0, 2);
		world.setBlock(i + 40, j + 33, k + 37, sculk_block, 0, 2);
		world.setBlock(i + 41, j + 33, k + 37, sculk_block, 0, 2);
		world.setBlock(i + 42, j + 33, k + 37, sculk_block, 0, 2);
		world.setBlock(i + 43, j + 33, k + 37, sculk_block, 0, 2);
		world.setBlock(i + 6, j + 33, k + 38, sculk_block, 0, 2);
		world.setBlock(i + 7, j + 33, k + 38, sculk_block, 0, 2);
		world.setBlock(i + 8, j + 33, k + 38, sculk_block, 0, 2);
		world.setBlock(i + 9, j + 33, k + 38, sculk_block, 0, 2);
		world.setBlock(i + 10, j + 33, k + 38, sculk_block, 0, 2);
		world.setBlock(i + 11, j + 33, k + 38, sculk_block, 0, 2);
		world.setBlock(i + 12, j + 33, k + 38, sculk_block, 0, 2);
		world.setBlock(i + 13, j + 33, k + 38, sculk_block, 0, 2);
		world.setBlock(i + 14, j + 33, k + 38, sculk_block, 0, 2);
		world.setBlock(i + 15, j + 33, k + 38, sculk_block, 0, 2);
		world.setBlock(i + 16, j + 33, k + 38, sculk_block, 0, 2);
		world.setBlock(i + 17, j + 33, k + 38, sculk_block, 0, 2);
		world.setBlock(i + 18, j + 33, k + 38, sculk_block, 0, 2);
		world.setBlock(i + 19, j + 33, k + 38, sculk_block, 0, 2);
		world.setBlock(i + 20, j + 33, k + 38, sculk_block, 0, 2);
		world.setBlock(i + 21, j + 33, k + 38, sculk_block, 0, 2);
		world.setBlock(i + 22, j + 33, k + 38, sculk_block, 0, 2);
		world.setBlock(i + 23, j + 33, k + 38, sculk_block, 0, 2);
		world.setBlock(i + 24, j + 33, k + 38, sculk_block, 0, 2);
		world.setBlock(i + 25, j + 33, k + 38, sculk_block, 0, 2);
		world.setBlock(i + 26, j + 33, k + 38, sculk_block, 0, 2);
		world.setBlock(i + 27, j + 33, k + 38, sculk_block, 0, 2);
		world.setBlock(i + 28, j + 33, k + 38, sculk_block, 0, 2);
		world.setBlock(i + 29, j + 33, k + 38, sculk_block, 0, 2);
		world.setBlock(i + 30, j + 33, k + 38, sculk_block, 0, 2);
		world.setBlock(i + 31, j + 33, k + 38, sculk_block, 0, 2);
		world.setBlock(i + 32, j + 33, k + 38, sculk_block, 0, 2);
		world.setBlock(i + 33, j + 33, k + 38, sculk_block, 0, 2);
		world.setBlock(i + 34, j + 33, k + 38, sculk_block, 0, 2);
		world.setBlock(i + 35, j + 33, k + 38, sculk_block, 0, 2);
		world.setBlock(i + 36, j + 33, k + 38, sculk_block, 0, 2);
		world.setBlock(i + 37, j + 33, k + 38, sculk_block, 0, 2);
		world.setBlock(i + 38, j + 33, k + 38, sculk_block, 0, 2);
		world.setBlock(i + 39, j + 33, k + 38, sculk_block, 0, 2);
		world.setBlock(i + 40, j + 33, k + 38, sculk_block, 0, 2);
		world.setBlock(i + 41, j + 33, k + 38, sculk_block, 0, 2);
		world.setBlock(i + 42, j + 33, k + 38, sculk_block, 0, 2);
		world.setBlock(i + 43, j + 33, k + 38, sculk_block, 0, 2);
		world.setBlock(i + 6, j + 33, k + 39, sculk_block, 0, 2);
		world.setBlock(i + 7, j + 33, k + 39, sculk_block, 0, 2);
		world.setBlock(i + 8, j + 33, k + 39, sculk_block, 0, 2);
		world.setBlock(i + 9, j + 33, k + 39, sculk_block, 0, 2);
		world.setBlock(i + 10, j + 33, k + 39, sculk_block, 0, 2);
		world.setBlock(i + 11, j + 33, k + 39, sculk_block, 0, 2);
		world.setBlock(i + 12, j + 33, k + 39, sculk_block, 0, 2);
		world.setBlock(i + 13, j + 33, k + 39, sculk_block, 0, 2);
		world.setBlock(i + 14, j + 33, k + 39, sculk_block, 0, 2);
		world.setBlock(i + 15, j + 33, k + 39, sculk_block, 0, 2);
		world.setBlock(i + 16, j + 33, k + 39, sculk_block, 0, 2);
		world.setBlock(i + 17, j + 33, k + 39, sculk_block, 0, 2);
		world.setBlock(i + 18, j + 33, k + 39, sculk_block, 0, 2);
		world.setBlock(i + 19, j + 33, k + 39, sculk_block, 0, 2);
		world.setBlock(i + 20, j + 33, k + 39, sculk_block, 0, 2);
		world.setBlock(i + 21, j + 33, k + 39, sculk_block, 0, 2);
		world.setBlock(i + 22, j + 33, k + 39, sculk_block, 0, 2);
		world.setBlock(i + 23, j + 33, k + 39, sculk_block, 0, 2);
		world.setBlock(i + 24, j + 33, k + 39, sculk_block, 0, 2);
		world.setBlock(i + 25, j + 33, k + 39, sculk_block, 0, 2);
		world.setBlock(i + 26, j + 33, k + 39, sculk_block, 0, 2);
		world.setBlock(i + 27, j + 33, k + 39, sculk_block, 0, 2);
		world.setBlock(i + 28, j + 33, k + 39, sculk_block, 0, 2);
		world.setBlock(i + 29, j + 33, k + 39, sculk_block, 0, 2);
		world.setBlock(i + 30, j + 33, k + 39, sculk_block, 0, 2);
		world.setBlock(i + 31, j + 33, k + 39, sculk_block, 0, 2);
		world.setBlock(i + 32, j + 33, k + 39, sculk_block, 0, 2);
		world.setBlock(i + 33, j + 33, k + 39, sculk_block, 0, 2);
		world.setBlock(i + 34, j + 33, k + 39, sculk_block, 0, 2);
		world.setBlock(i + 35, j + 33, k + 39, sculk_block, 0, 2);
		world.setBlock(i + 36, j + 33, k + 39, sculk_block, 0, 2);
		world.setBlock(i + 37, j + 33, k + 39, sculk_block, 0, 2);
		world.setBlock(i + 38, j + 33, k + 39, sculk_block, 0, 2);
		world.setBlock(i + 39, j + 33, k + 39, sculk_block, 0, 2);
		world.setBlock(i + 40, j + 33, k + 39, sculk_block, 0, 2);
		world.setBlock(i + 41, j + 33, k + 39, sculk_block, 0, 2);
		world.setBlock(i + 42, j + 33, k + 39, sculk_block, 0, 2);
		world.setBlock(i + 43, j + 33, k + 39, sculk_block, 0, 2);
		world.setBlock(i + 6, j + 33, k + 40, sculk_block, 0, 2);
		world.setBlock(i + 7, j + 33, k + 40, sculk_block, 0, 2);
		world.setBlock(i + 8, j + 33, k + 40, sculk_block, 0, 2);
		world.setBlock(i + 9, j + 33, k + 40, sculk_block, 0, 2);
		world.setBlock(i + 10, j + 33, k + 40, sculk_block, 0, 2);
		world.setBlock(i + 11, j + 33, k + 40, sculk_block, 0, 2);
		world.setBlock(i + 12, j + 33, k + 40, sculk_block, 0, 2);
		world.setBlock(i + 13, j + 33, k + 40, sculk_block, 0, 2);
		world.setBlock(i + 14, j + 33, k + 40, sculk_block, 0, 2);
		world.setBlock(i + 15, j + 33, k + 40, sculk_block, 0, 2);
		world.setBlock(i + 16, j + 33, k + 40, sculk_block, 0, 2);
		world.setBlock(i + 17, j + 33, k + 40, sculk_block, 0, 2);
		world.setBlock(i + 18, j + 33, k + 40, sculk_block, 0, 2);
		world.setBlock(i + 19, j + 33, k + 40, sculk_block, 0, 2);
		world.setBlock(i + 20, j + 33, k + 40, sculk_block, 0, 2);
		world.setBlock(i + 21, j + 33, k + 40, sculk_block, 0, 2);
		world.setBlock(i + 22, j + 33, k + 40, sculk_block, 0, 2);
		world.setBlock(i + 23, j + 33, k + 40, sculk_block, 0, 2);
		world.setBlock(i + 24, j + 33, k + 40, sculk_block, 0, 2);
		world.setBlock(i + 25, j + 33, k + 40, sculk_block, 0, 2);
		world.setBlock(i + 26, j + 33, k + 40, sculk_block, 0, 2);
		world.setBlock(i + 27, j + 33, k + 40, sculk_block, 0, 2);
		world.setBlock(i + 28, j + 33, k + 40, sculk_block, 0, 2);
		world.setBlock(i + 29, j + 33, k + 40, sculk_block, 0, 2);
		world.setBlock(i + 30, j + 33, k + 40, sculk_block, 0, 2);
		world.setBlock(i + 31, j + 33, k + 40, sculk_block, 0, 2);
		world.setBlock(i + 32, j + 33, k + 40, sculk_block, 0, 2);
		world.setBlock(i + 33, j + 33, k + 40, sculk_block, 0, 2);
		world.setBlock(i + 34, j + 33, k + 40, sculk_block, 0, 2);
		world.setBlock(i + 35, j + 33, k + 40, sculk_block, 0, 2);
		world.setBlock(i + 36, j + 33, k + 40, sculk_block, 0, 2);
		world.setBlock(i + 37, j + 33, k + 40, sculk_block, 0, 2);
		world.setBlock(i + 38, j + 33, k + 40, sculk_block, 0, 2);
		world.setBlock(i + 39, j + 33, k + 40, sculk_block, 0, 2);
		world.setBlock(i + 40, j + 33, k + 40, sculk_block, 0, 2);
		world.setBlock(i + 41, j + 33, k + 40, sculk_block, 0, 2);
		world.setBlock(i + 42, j + 33, k + 40, sculk_block, 0, 2);
		world.setBlock(i + 43, j + 33, k + 40, sculk_block, 0, 2);
		world.setBlock(i + 44, j + 33, k + 40, sculk_block, 0, 2);
		world.setBlock(i + 6, j + 33, k + 41, sculk_block, 0, 2);
		world.setBlock(i + 7, j + 33, k + 41, sculk_block, 0, 2);
		world.setBlock(i + 8, j + 33, k + 41, sculk_block, 0, 2);
		world.setBlock(i + 9, j + 33, k + 41, sculk_block, 0, 2);
		world.setBlock(i + 10, j + 33, k + 41, sculk_block, 0, 2);
		world.setBlock(i + 20, j + 33, k + 41, sculk_block, 0, 2);
		world.setBlock(i + 21, j + 33, k + 41, sculk_block, 0, 2);
		world.setBlock(i + 22, j + 33, k + 41, sculk_block, 0, 2);
		world.setBlock(i + 31, j + 33, k + 41, sculk_block, 0, 2);
		world.setBlock(i + 32, j + 33, k + 41, sculk_block, 0, 2);
		world.setBlock(i + 33, j + 33, k + 41, sculk_block, 0, 2);
		world.setBlock(i + 34, j + 33, k + 41, sculk_block, 0, 2);
		world.setBlock(i + 44, j + 33, k + 41, sculk_block, 0, 2);
		world.setBlock(i + 7, j + 33, k + 42, sculk_block, 0, 2);
		world.setBlock(i + 11, j + 34, k + 41, sculk_block, 0, 2);
		world.setBlock(i + 12, j + 34, k + 41, sculk_block, 0, 2);
		world.setBlock(i + 13, j + 34, k + 41, sculk_block, 0, 2);
		world.setBlock(i + 14, j + 34, k + 41, sculk_block, 0, 2);
		world.setBlock(i + 15, j + 34, k + 41, sculk_block, 0, 2);
		world.setBlock(i + 16, j + 34, k + 41, sculk_block, 0, 2);
		world.setBlock(i + 17, j + 34, k + 41, sculk_block, 0, 2);
		world.setBlock(i + 18, j + 34, k + 41, sculk_block, 0, 2);
		world.setBlock(i + 19, j + 34, k + 41, sculk_block, 0, 2);
		world.setBlock(i + 23, j + 34, k + 41, sculk_block, 0, 2);
		world.setBlock(i + 24, j + 34, k + 41, sculk_block, 0, 2);
		world.setBlock(i + 25, j + 34, k + 41, sculk_block, 0, 2);
		world.setBlock(i + 26, j + 34, k + 41, sculk_block, 0, 2);
		world.setBlock(i + 27, j + 34, k + 41, sculk_block, 0, 2);
		world.setBlock(i + 28, j + 34, k + 41, sculk_block, 0, 2);
		world.setBlock(i + 29, j + 34, k + 41, sculk_block, 0, 2);
		world.setBlock(i + 30, j + 34, k + 41, sculk_block, 0, 2);
		world.setBlock(i + 35, j + 34, k + 41, sculk_block, 0, 2);
		world.setBlock(i + 36, j + 34, k + 41, sculk_block, 0, 2);
		world.setBlock(i + 37, j + 34, k + 41, sculk_block, 0, 2);
		world.setBlock(i + 38, j + 34, k + 41, sculk_block, 0, 2);
		world.setBlock(i + 39, j + 34, k + 41, sculk_block, 0, 2);
		world.setBlock(i + 40, j + 34, k + 41, sculk_block, 0, 2);
		world.setBlock(i + 41, j + 34, k + 41, sculk_block, 0, 2);
		world.setBlock(i + 42, j + 34, k + 41, sculk_block, 0, 2);
		world.setBlock(i + 43, j + 34, k + 41, sculk_block, 0, 2);
		world.setBlock(i + 8, j + 34, k + 42, sculk_block, 0, 2);
		world.setBlock(i + 9, j + 34, k + 42, sculk_block, 0, 2);
		world.setBlock(i + 10, j + 34, k + 42, sculk_block, 0, 2);
		world.setBlock(i + 11, j + 34, k + 42, sculk_block, 0, 2);
		world.setBlock(i + 19, j + 34, k + 42, sculk_block, 0, 2);
		world.setBlock(i + 20, j + 34, k + 42, sculk_block, 0, 2);
		world.setBlock(i + 21, j + 34, k + 42, sculk_block, 0, 2);
		world.setBlock(i + 22, j + 34, k + 42, sculk_block, 0, 2);
		world.setBlock(i + 23, j + 34, k + 42, sculk_block, 0, 2);
		world.setBlock(i + 30, j + 34, k + 42, sculk_block, 0, 2);
		world.setBlock(i + 31, j + 34, k + 42, sculk_block, 0, 2);
		world.setBlock(i + 32, j + 34, k + 42, sculk_block, 0, 2);
		world.setBlock(i + 33, j + 34, k + 42, sculk_block, 0, 2);
		world.setBlock(i + 34, j + 34, k + 42, sculk_block, 0, 2);
		world.setBlock(i + 35, j + 34, k + 42, sculk_block, 0, 2);
		world.setBlock(i + 7, j + 34, k + 43, sculk_block, 0, 2);
		world.setBlock(i + 8, j + 34, k + 43, sculk_block, 0, 2);
    	
    	return true;
    }

}
