package com.NovaCraft.world.ancient_city;

import cpw.mods.fml.common.registry.GameRegistry;
import net.minecraft.world.gen.feature.*;
import net.minecraft.block.*;
import net.minecraft.world.*;
import java.util.*;

import com.NovaCraft.config.Configs;
import com.NovaCraft.registry.OtherModBlocks;
import com.NovaCraftBlocks.NovaCraftBlocks;

import cpw.mods.fml.common.Loader;
import net.minecraft.init.*;

public class AncientCityColumnGen1 extends WorldGenerator
{
	public AncientCityColumnGen1() {

	}

	private static final Block sculk_block = NovaCraftBlocks.sculk_block;
	
	private Block PlaceDeepslate;

	private Block determineIfDeepslateExists(World world, int x, int y, int z) {
		Block existingBlock = world.getBlock(x, y, z);
		if (Configs.enableDeepslateInAncientCity && Loader.isModLoaded("etfuturum")) {
			try {
				Block deepslate = GameRegistry.findBlock("etfuturum", "deepslate");
				if (deepslate != null && (existingBlock == null || existingBlock != deepslate)) {
					return deepslate;
				}
			} catch (Exception ex) {
				if (Configs.enableDebugMode) {
					System.out.println("Missing Deepslate from Et Futurum Requiem, using Grimstone instead...");
				}
				return NovaCraftBlocks.grimstone;
			}
		}

		return NovaCraftBlocks.grimstone;
	}
    
    public boolean generate(final World world, final Random random, final int i, final int j, final int k) {
    	PlaceDeepslate = determineIfDeepslateExists(world, i + 15, j + 0, k + 2);
    	
		world.setBlock(i + 12, j + 0, k + 2, sculk_block, 0, 2);
		world.setBlock(i + 13, j + 0, k + 2, sculk_block, 0, 2);
		world.setBlock(i + 14, j + 0, k + 2, sculk_block, 0, 2);
		world.setBlock(i + 15, j + 0, k + 2, PlaceDeepslate, 0, 2);
		world.setBlock(i + 16, j + 0, k + 2, PlaceDeepslate, 0, 2);
		world.setBlock(i + 11, j + 0, k + 3, sculk_block, 0, 2);
		world.setBlock(i + 12, j + 0, k + 3, sculk_block, 0, 2);
		world.setBlock(i + 13, j + 0, k + 3, PlaceDeepslate, 0, 2);
		world.setBlock(i + 14, j + 0, k + 3, PlaceDeepslate, 0, 2);
		world.setBlock(i + 15, j + 0, k + 3, PlaceDeepslate, 0, 2);
		world.setBlock(i + 16, j + 0, k + 3, PlaceDeepslate, 0, 2);
		world.setBlock(i + 17, j + 0, k + 3, PlaceDeepslate, 0, 2);
		world.setBlock(i + 10, j + 0, k + 4, sculk_block, 0, 2);
		world.setBlock(i + 11, j + 0, k + 4, sculk_block, 0, 2);
		world.setBlock(i + 12, j + 0, k + 4, PlaceDeepslate, 0, 2);
		world.setBlock(i + 13, j + 0, k + 4, PlaceDeepslate, 0, 2);
		world.setBlock(i + 14, j + 0, k + 4, PlaceDeepslate, 0, 2);
		world.setBlock(i + 15, j + 0, k + 4, PlaceDeepslate, 0, 2);
		world.setBlock(i + 16, j + 0, k + 4, PlaceDeepslate, 0, 2);
		world.setBlock(i + 17, j + 0, k + 4, PlaceDeepslate, 0, 2);
		world.setBlock(i + 18, j + 0, k + 4, PlaceDeepslate, 0, 2);
		world.setBlock(i + 9, j + 0, k + 5, sculk_block, 0, 2);
		world.setBlock(i + 10, j + 0, k + 5, PlaceDeepslate, 0, 2);
		world.setBlock(i + 11, j + 0, k + 5, PlaceDeepslate, 0, 2);
		world.setBlock(i + 12, j + 0, k + 5, PlaceDeepslate, 0, 2);
		world.setBlock(i + 13, j + 0, k + 5, PlaceDeepslate, 0, 2);
		world.setBlock(i + 14, j + 0, k + 5, PlaceDeepslate, 0, 2);
		world.setBlock(i + 15, j + 0, k + 5, PlaceDeepslate, 0, 2);
		world.setBlock(i + 16, j + 0, k + 5, PlaceDeepslate, 0, 2);
		world.setBlock(i + 17, j + 0, k + 5, PlaceDeepslate, 0, 2);
		world.setBlock(i + 18, j + 0, k + 5, PlaceDeepslate, 0, 2);
		world.setBlock(i + 19, j + 0, k + 5, PlaceDeepslate, 0, 2);
		world.setBlock(i + 9, j + 0, k + 6, sculk_block, 0, 2);
		world.setBlock(i + 10, j + 0, k + 6, PlaceDeepslate, 0, 2);
		world.setBlock(i + 11, j + 0, k + 6, PlaceDeepslate, 0, 2);
		world.setBlock(i + 12, j + 0, k + 6, PlaceDeepslate, 0, 2);
		world.setBlock(i + 13, j + 0, k + 6, PlaceDeepslate, 0, 2);
		world.setBlock(i + 14, j + 0, k + 6, PlaceDeepslate, 0, 2);
		world.setBlock(i + 15, j + 0, k + 6, PlaceDeepslate, 0, 2);
		world.setBlock(i + 16, j + 0, k + 6, PlaceDeepslate, 0, 2);
		world.setBlock(i + 17, j + 0, k + 6, PlaceDeepslate, 0, 2);
		world.setBlock(i + 18, j + 0, k + 6, PlaceDeepslate, 0, 2);
		world.setBlock(i + 19, j + 0, k + 6, PlaceDeepslate, 0, 2);
		world.setBlock(i + 20, j + 0, k + 6, PlaceDeepslate, 0, 2);
		world.setBlock(i + 9, j + 0, k + 7, sculk_block, 0, 2);
		world.setBlock(i + 10, j + 0, k + 7, PlaceDeepslate, 0, 2);
		world.setBlock(i + 11, j + 0, k + 7, PlaceDeepslate, 0, 2);
		world.setBlock(i + 12, j + 0, k + 7, PlaceDeepslate, 0, 2);
		world.setBlock(i + 13, j + 0, k + 7, PlaceDeepslate, 0, 2);
		world.setBlock(i + 14, j + 0, k + 7, PlaceDeepslate, 0, 2);
		world.setBlock(i + 15, j + 0, k + 7, PlaceDeepslate, 0, 2);
		world.setBlock(i + 16, j + 0, k + 7, PlaceDeepslate, 0, 2);
		world.setBlock(i + 17, j + 0, k + 7, PlaceDeepslate, 0, 2);
		world.setBlock(i + 18, j + 0, k + 7, PlaceDeepslate, 0, 2);
		world.setBlock(i + 19, j + 0, k + 7, PlaceDeepslate, 0, 2);
		world.setBlock(i + 20, j + 0, k + 7, PlaceDeepslate, 0, 2);
		world.setBlock(i + 9, j + 0, k + 8, PlaceDeepslate, 0, 2);
		world.setBlock(i + 10, j + 0, k + 8, PlaceDeepslate, 0, 2);
		world.setBlock(i + 11, j + 0, k + 8, PlaceDeepslate, 0, 2);
		world.setBlock(i + 12, j + 0, k + 8, PlaceDeepslate, 0, 2);
		world.setBlock(i + 13, j + 0, k + 8, PlaceDeepslate, 0, 2);
		world.setBlock(i + 14, j + 0, k + 8, PlaceDeepslate, 0, 2);
		world.setBlock(i + 15, j + 0, k + 8, PlaceDeepslate, 0, 2);
		world.setBlock(i + 16, j + 0, k + 8, PlaceDeepslate, 0, 2);
		world.setBlock(i + 17, j + 0, k + 8, PlaceDeepslate, 0, 2);
		world.setBlock(i + 18, j + 0, k + 8, PlaceDeepslate, 0, 2);
		world.setBlock(i + 19, j + 0, k + 8, PlaceDeepslate, 0, 2);
		world.setBlock(i + 20, j + 0, k + 8, PlaceDeepslate, 0, 2);
		world.setBlock(i + 21, j + 0, k + 8, PlaceDeepslate, 0, 2);
		world.setBlock(i + 9, j + 0, k + 9, PlaceDeepslate, 0, 2);
		world.setBlock(i + 10, j + 0, k + 9, PlaceDeepslate, 0, 2);
		world.setBlock(i + 11, j + 0, k + 9, PlaceDeepslate, 0, 2);
		world.setBlock(i + 12, j + 0, k + 9, PlaceDeepslate, 0, 2);
		world.setBlock(i + 13, j + 0, k + 9, PlaceDeepslate, 0, 2);
		world.setBlock(i + 14, j + 0, k + 9, PlaceDeepslate, 0, 2);
		world.setBlock(i + 15, j + 0, k + 9, PlaceDeepslate, 0, 2);
		world.setBlock(i + 16, j + 0, k + 9, PlaceDeepslate, 0, 2);
		world.setBlock(i + 17, j + 0, k + 9, PlaceDeepslate, 0, 2);
		world.setBlock(i + 18, j + 0, k + 9, PlaceDeepslate, 0, 2);
		world.setBlock(i + 19, j + 0, k + 9, PlaceDeepslate, 0, 2);
		world.setBlock(i + 20, j + 0, k + 9, PlaceDeepslate, 0, 2);
		world.setBlock(i + 21, j + 0, k + 9, PlaceDeepslate, 0, 2);
		world.setBlock(i + 22, j + 0, k + 9, PlaceDeepslate, 0, 2);
		world.setBlock(i + 9, j + 0, k + 10, PlaceDeepslate, 0, 2);
		world.setBlock(i + 10, j + 0, k + 10, PlaceDeepslate, 0, 2);
		world.setBlock(i + 11, j + 0, k + 10, PlaceDeepslate, 0, 2);
		world.setBlock(i + 12, j + 0, k + 10, PlaceDeepslate, 0, 2);
		world.setBlock(i + 13, j + 0, k + 10, PlaceDeepslate, 0, 2);
		world.setBlock(i + 14, j + 0, k + 10, PlaceDeepslate, 0, 2);
		world.setBlock(i + 15, j + 0, k + 10, PlaceDeepslate, 0, 2);
		world.setBlock(i + 16, j + 0, k + 10, PlaceDeepslate, 0, 2);
		world.setBlock(i + 17, j + 0, k + 10, PlaceDeepslate, 0, 2);
		world.setBlock(i + 18, j + 0, k + 10, PlaceDeepslate, 0, 2);
		world.setBlock(i + 19, j + 0, k + 10, PlaceDeepslate, 0, 2);
		world.setBlock(i + 20, j + 0, k + 10, PlaceDeepslate, 0, 2);
		world.setBlock(i + 21, j + 0, k + 10, PlaceDeepslate, 0, 2);
		world.setBlock(i + 22, j + 0, k + 10, PlaceDeepslate, 0, 2);
		world.setBlock(i + 9, j + 0, k + 11, PlaceDeepslate, 0, 2);
		world.setBlock(i + 10, j + 0, k + 11, PlaceDeepslate, 0, 2);
		world.setBlock(i + 11, j + 0, k + 11, PlaceDeepslate, 0, 2);
		world.setBlock(i + 12, j + 0, k + 11, PlaceDeepslate, 0, 2);
		world.setBlock(i + 13, j + 0, k + 11, PlaceDeepslate, 0, 2);
		world.setBlock(i + 14, j + 0, k + 11, PlaceDeepslate, 0, 2);
		world.setBlock(i + 15, j + 0, k + 11, PlaceDeepslate, 0, 2);
		world.setBlock(i + 16, j + 0, k + 11, PlaceDeepslate, 0, 2);
		world.setBlock(i + 17, j + 0, k + 11, PlaceDeepslate, 0, 2);
		world.setBlock(i + 18, j + 0, k + 11, PlaceDeepslate, 0, 2);
		world.setBlock(i + 19, j + 0, k + 11, PlaceDeepslate, 0, 2);
		world.setBlock(i + 20, j + 0, k + 11, PlaceDeepslate, 0, 2);
		world.setBlock(i + 21, j + 0, k + 11, PlaceDeepslate, 0, 2);
		world.setBlock(i + 22, j + 0, k + 11, PlaceDeepslate, 0, 2);
		world.setBlock(i + 23, j + 0, k + 11, PlaceDeepslate, 0, 2);
		world.setBlock(i + 9, j + 0, k + 12, PlaceDeepslate, 0, 2);
		world.setBlock(i + 10, j + 0, k + 12, PlaceDeepslate, 0, 2);
		world.setBlock(i + 11, j + 0, k + 12, PlaceDeepslate, 0, 2);
		world.setBlock(i + 12, j + 0, k + 12, PlaceDeepslate, 0, 2);
		world.setBlock(i + 13, j + 0, k + 12, PlaceDeepslate, 0, 2);
		world.setBlock(i + 14, j + 0, k + 12, PlaceDeepslate, 0, 2);
		world.setBlock(i + 15, j + 0, k + 12, PlaceDeepslate, 0, 2);
		world.setBlock(i + 16, j + 0, k + 12, PlaceDeepslate, 0, 2);
		world.setBlock(i + 17, j + 0, k + 12, PlaceDeepslate, 0, 2);
		world.setBlock(i + 18, j + 0, k + 12, PlaceDeepslate, 0, 2);
		world.setBlock(i + 19, j + 0, k + 12, PlaceDeepslate, 0, 2);
		world.setBlock(i + 20, j + 0, k + 12, PlaceDeepslate, 0, 2);
		world.setBlock(i + 21, j + 0, k + 12, PlaceDeepslate, 0, 2);
		world.setBlock(i + 22, j + 0, k + 12, PlaceDeepslate, 0, 2);
		world.setBlock(i + 23, j + 0, k + 12, PlaceDeepslate, 0, 2);
		world.setBlock(i + 9, j + 0, k + 13, PlaceDeepslate, 0, 2);
		world.setBlock(i + 10, j + 0, k + 13, PlaceDeepslate, 0, 2);
		world.setBlock(i + 11, j + 0, k + 13, PlaceDeepslate, 0, 2);
		world.setBlock(i + 12, j + 0, k + 13, PlaceDeepslate, 0, 2);
		world.setBlock(i + 13, j + 0, k + 13, PlaceDeepslate, 0, 2);
		world.setBlock(i + 14, j + 0, k + 13, PlaceDeepslate, 0, 2);
		world.setBlock(i + 15, j + 0, k + 13, PlaceDeepslate, 0, 2);
		world.setBlock(i + 16, j + 0, k + 13, PlaceDeepslate, 0, 2);
		world.setBlock(i + 17, j + 0, k + 13, PlaceDeepslate, 0, 2);
		world.setBlock(i + 18, j + 0, k + 13, PlaceDeepslate, 0, 2);
		world.setBlock(i + 19, j + 0, k + 13, PlaceDeepslate, 0, 2);
		world.setBlock(i + 20, j + 0, k + 13, PlaceDeepslate, 0, 2);
		world.setBlock(i + 21, j + 0, k + 13, PlaceDeepslate, 0, 2);
		world.setBlock(i + 22, j + 0, k + 13, PlaceDeepslate, 0, 2);
		world.setBlock(i + 23, j + 0, k + 13, PlaceDeepslate, 0, 2);
		world.setBlock(i + 9, j + 0, k + 14, PlaceDeepslate, 0, 2);
		world.setBlock(i + 10, j + 0, k + 14, PlaceDeepslate, 0, 2);
		world.setBlock(i + 11, j + 0, k + 14, PlaceDeepslate, 0, 2);
		world.setBlock(i + 12, j + 0, k + 14, PlaceDeepslate, 0, 2);
		world.setBlock(i + 13, j + 0, k + 14, PlaceDeepslate, 0, 2);
		world.setBlock(i + 14, j + 0, k + 14, PlaceDeepslate, 0, 2);
		world.setBlock(i + 15, j + 0, k + 14, PlaceDeepslate, 0, 2);
		world.setBlock(i + 16, j + 0, k + 14, PlaceDeepslate, 0, 2);
		world.setBlock(i + 17, j + 0, k + 14, PlaceDeepslate, 0, 2);
		world.setBlock(i + 18, j + 0, k + 14, PlaceDeepslate, 0, 2);
		world.setBlock(i + 19, j + 0, k + 14, PlaceDeepslate, 0, 2);
		world.setBlock(i + 20, j + 0, k + 14, PlaceDeepslate, 0, 2);
		world.setBlock(i + 21, j + 0, k + 14, PlaceDeepslate, 0, 2);
		world.setBlock(i + 22, j + 0, k + 14, PlaceDeepslate, 0, 2);
		world.setBlock(i + 23, j + 0, k + 14, PlaceDeepslate, 0, 2);
		world.setBlock(i + 9, j + 0, k + 15, PlaceDeepslate, 0, 2);
		world.setBlock(i + 10, j + 0, k + 15, PlaceDeepslate, 0, 2);
		world.setBlock(i + 11, j + 0, k + 15, PlaceDeepslate, 0, 2);
		world.setBlock(i + 12, j + 0, k + 15, PlaceDeepslate, 0, 2);
		world.setBlock(i + 13, j + 0, k + 15, PlaceDeepslate, 0, 2);
		world.setBlock(i + 14, j + 0, k + 15, PlaceDeepslate, 0, 2);
		world.setBlock(i + 15, j + 0, k + 15, PlaceDeepslate, 0, 2);
		world.setBlock(i + 16, j + 0, k + 15, PlaceDeepslate, 0, 2);
		world.setBlock(i + 17, j + 0, k + 15, PlaceDeepslate, 0, 2);
		world.setBlock(i + 18, j + 0, k + 15, PlaceDeepslate, 0, 2);
		world.setBlock(i + 19, j + 0, k + 15, PlaceDeepslate, 0, 2);
		world.setBlock(i + 20, j + 0, k + 15, PlaceDeepslate, 0, 2);
		world.setBlock(i + 21, j + 0, k + 15, PlaceDeepslate, 0, 2);
		world.setBlock(i + 22, j + 0, k + 15, PlaceDeepslate, 0, 2);
		world.setBlock(i + 23, j + 0, k + 15, PlaceDeepslate, 0, 2);
		world.setBlock(i + 10, j + 0, k + 16, PlaceDeepslate, 0, 2);
		world.setBlock(i + 11, j + 0, k + 16, PlaceDeepslate, 0, 2);
		world.setBlock(i + 12, j + 0, k + 16, PlaceDeepslate, 0, 2);
		world.setBlock(i + 13, j + 0, k + 16, PlaceDeepslate, 0, 2);
		world.setBlock(i + 14, j + 0, k + 16, PlaceDeepslate, 0, 2);
		world.setBlock(i + 15, j + 0, k + 16, PlaceDeepslate, 0, 2);
		world.setBlock(i + 16, j + 0, k + 16, PlaceDeepslate, 0, 2);
		world.setBlock(i + 17, j + 0, k + 16, PlaceDeepslate, 0, 2);
		world.setBlock(i + 18, j + 0, k + 16, PlaceDeepslate, 0, 2);
		world.setBlock(i + 19, j + 0, k + 16, PlaceDeepslate, 0, 2);
		world.setBlock(i + 20, j + 0, k + 16, PlaceDeepslate, 0, 2);
		world.setBlock(i + 21, j + 0, k + 16, PlaceDeepslate, 0, 2);
		world.setBlock(i + 22, j + 0, k + 16, PlaceDeepslate, 0, 2);
		world.setBlock(i + 11, j + 0, k + 17, PlaceDeepslate, 0, 2);
		world.setBlock(i + 12, j + 0, k + 17, PlaceDeepslate, 0, 2);
		world.setBlock(i + 13, j + 0, k + 17, PlaceDeepslate, 0, 2);
		world.setBlock(i + 14, j + 0, k + 17, PlaceDeepslate, 0, 2);
		world.setBlock(i + 15, j + 0, k + 17, PlaceDeepslate, 0, 2);
		world.setBlock(i + 16, j + 0, k + 17, PlaceDeepslate, 0, 2);
		world.setBlock(i + 17, j + 0, k + 17, PlaceDeepslate, 0, 2);
		world.setBlock(i + 18, j + 0, k + 17, PlaceDeepslate, 0, 2);
		world.setBlock(i + 19, j + 0, k + 17, PlaceDeepslate, 0, 2);
		world.setBlock(i + 20, j + 0, k + 17, PlaceDeepslate, 0, 2);
		world.setBlock(i + 21, j + 0, k + 17, PlaceDeepslate, 0, 2);
		world.setBlock(i + 12, j + 0, k + 18, PlaceDeepslate, 0, 2);
		world.setBlock(i + 13, j + 0, k + 18, PlaceDeepslate, 0, 2);
		world.setBlock(i + 14, j + 0, k + 18, PlaceDeepslate, 0, 2);
		world.setBlock(i + 15, j + 0, k + 18, PlaceDeepslate, 0, 2);
		world.setBlock(i + 16, j + 0, k + 18, PlaceDeepslate, 0, 2);
		world.setBlock(i + 17, j + 0, k + 18, PlaceDeepslate, 0, 2);
		world.setBlock(i + 18, j + 0, k + 18, PlaceDeepslate, 0, 2);
		world.setBlock(i + 19, j + 0, k + 18, PlaceDeepslate, 0, 2);
		world.setBlock(i + 20, j + 0, k + 18, PlaceDeepslate, 0, 2);
		world.setBlock(i + 12, j + 1, k + 3, sculk_block, 0, 2);
		world.setBlock(i + 13, j + 1, k + 3, sculk_block, 0, 2);
		world.setBlock(i + 14, j + 1, k + 3, PlaceDeepslate, 0, 2);
		world.setBlock(i + 15, j + 1, k + 3, PlaceDeepslate, 0, 2);
		world.setBlock(i + 16, j + 1, k + 3, PlaceDeepslate, 0, 2);
		world.setBlock(i + 11, j + 1, k + 4, sculk_block, 0, 2);
		world.setBlock(i + 12, j + 1, k + 4, sculk_block, 0, 2);
		world.setBlock(i + 13, j + 1, k + 4, PlaceDeepslate, 0, 2);
		world.setBlock(i + 14, j + 1, k + 4, PlaceDeepslate, 0, 2);
		world.setBlock(i + 15, j + 1, k + 4, PlaceDeepslate, 0, 2);
		world.setBlock(i + 16, j + 1, k + 4, PlaceDeepslate, 0, 2);
		world.setBlock(i + 17, j + 1, k + 4, PlaceDeepslate, 0, 2);
		world.setBlock(i + 10, j + 1, k + 5, sculk_block, 0, 2);
		world.setBlock(i + 11, j + 1, k + 5, PlaceDeepslate, 0, 2);
		world.setBlock(i + 12, j + 1, k + 5, PlaceDeepslate, 0, 2);
		world.setBlock(i + 13, j + 1, k + 5, PlaceDeepslate, 0, 2);
		world.setBlock(i + 14, j + 1, k + 5, PlaceDeepslate, 0, 2);
		world.setBlock(i + 15, j + 1, k + 5, PlaceDeepslate, 0, 2);
		world.setBlock(i + 16, j + 1, k + 5, PlaceDeepslate, 0, 2);
		world.setBlock(i + 17, j + 1, k + 5, PlaceDeepslate, 0, 2);
		world.setBlock(i + 18, j + 1, k + 5, PlaceDeepslate, 0, 2);
		world.setBlock(i + 10, j + 1, k + 6, sculk_block, 0, 2);
		world.setBlock(i + 11, j + 1, k + 6, PlaceDeepslate, 0, 2);
		world.setBlock(i + 12, j + 1, k + 6, PlaceDeepslate, 0, 2);
		world.setBlock(i + 13, j + 1, k + 6, PlaceDeepslate, 0, 2);
		world.setBlock(i + 14, j + 1, k + 6, PlaceDeepslate, 0, 2);
		world.setBlock(i + 15, j + 1, k + 6, PlaceDeepslate, 0, 2);
		world.setBlock(i + 16, j + 1, k + 6, PlaceDeepslate, 0, 2);
		world.setBlock(i + 17, j + 1, k + 6, PlaceDeepslate, 0, 2);
		world.setBlock(i + 18, j + 1, k + 6, PlaceDeepslate, 0, 2);
		world.setBlock(i + 19, j + 1, k + 6, PlaceDeepslate, 0, 2);
		world.setBlock(i + 10, j + 1, k + 7, sculk_block, 0, 2);
		world.setBlock(i + 11, j + 1, k + 7, PlaceDeepslate, 0, 2);
		world.setBlock(i + 12, j + 1, k + 7, PlaceDeepslate, 0, 2);
		world.setBlock(i + 13, j + 1, k + 7, PlaceDeepslate, 0, 2);
		world.setBlock(i + 14, j + 1, k + 7, PlaceDeepslate, 0, 2);
		world.setBlock(i + 15, j + 1, k + 7, PlaceDeepslate, 0, 2);
		world.setBlock(i + 16, j + 1, k + 7, PlaceDeepslate, 0, 2);
		world.setBlock(i + 17, j + 1, k + 7, PlaceDeepslate, 0, 2);
		world.setBlock(i + 18, j + 1, k + 7, PlaceDeepslate, 0, 2);
		world.setBlock(i + 19, j + 1, k + 7, PlaceDeepslate, 0, 2);
		world.setBlock(i + 10, j + 1, k + 8, PlaceDeepslate, 0, 2);
		world.setBlock(i + 11, j + 1, k + 8, PlaceDeepslate, 0, 2);
		world.setBlock(i + 12, j + 1, k + 8, PlaceDeepslate, 0, 2);
		world.setBlock(i + 13, j + 1, k + 8, PlaceDeepslate, 0, 2);
		world.setBlock(i + 14, j + 1, k + 8, PlaceDeepslate, 0, 2);
		world.setBlock(i + 15, j + 1, k + 8, PlaceDeepslate, 0, 2);
		world.setBlock(i + 16, j + 1, k + 8, PlaceDeepslate, 0, 2);
		world.setBlock(i + 17, j + 1, k + 8, PlaceDeepslate, 0, 2);
		world.setBlock(i + 18, j + 1, k + 8, PlaceDeepslate, 0, 2);
		world.setBlock(i + 19, j + 1, k + 8, PlaceDeepslate, 0, 2);
		world.setBlock(i + 20, j + 1, k + 8, PlaceDeepslate, 0, 2);
		world.setBlock(i + 10, j + 1, k + 9, PlaceDeepslate, 0, 2);
		world.setBlock(i + 11, j + 1, k + 9, PlaceDeepslate, 0, 2);
		world.setBlock(i + 12, j + 1, k + 9, PlaceDeepslate, 0, 2);
		world.setBlock(i + 13, j + 1, k + 9, PlaceDeepslate, 0, 2);
		world.setBlock(i + 14, j + 1, k + 9, PlaceDeepslate, 0, 2);
		world.setBlock(i + 15, j + 1, k + 9, PlaceDeepslate, 0, 2);
		world.setBlock(i + 16, j + 1, k + 9, PlaceDeepslate, 0, 2);
		world.setBlock(i + 17, j + 1, k + 9, PlaceDeepslate, 0, 2);
		world.setBlock(i + 18, j + 1, k + 9, PlaceDeepslate, 0, 2);
		world.setBlock(i + 19, j + 1, k + 9, PlaceDeepslate, 0, 2);
		world.setBlock(i + 20, j + 1, k + 9, PlaceDeepslate, 0, 2);
		world.setBlock(i + 21, j + 1, k + 9, PlaceDeepslate, 0, 2);
		world.setBlock(i + 10, j + 1, k + 10, PlaceDeepslate, 0, 2);
		world.setBlock(i + 11, j + 1, k + 10, PlaceDeepslate, 0, 2);
		world.setBlock(i + 12, j + 1, k + 10, PlaceDeepslate, 0, 2);
		world.setBlock(i + 13, j + 1, k + 10, PlaceDeepslate, 0, 2);
		world.setBlock(i + 14, j + 1, k + 10, PlaceDeepslate, 0, 2);
		world.setBlock(i + 15, j + 1, k + 10, PlaceDeepslate, 0, 2);
		world.setBlock(i + 16, j + 1, k + 10, PlaceDeepslate, 0, 2);
		world.setBlock(i + 17, j + 1, k + 10, PlaceDeepslate, 0, 2);
		world.setBlock(i + 18, j + 1, k + 10, PlaceDeepslate, 0, 2);
		world.setBlock(i + 19, j + 1, k + 10, PlaceDeepslate, 0, 2);
		world.setBlock(i + 20, j + 1, k + 10, PlaceDeepslate, 0, 2);
		world.setBlock(i + 21, j + 1, k + 10, PlaceDeepslate, 0, 2);
		world.setBlock(i + 10, j + 1, k + 11, PlaceDeepslate, 0, 2);
		world.setBlock(i + 11, j + 1, k + 11, PlaceDeepslate, 0, 2);
		world.setBlock(i + 12, j + 1, k + 11, PlaceDeepslate, 0, 2);
		world.setBlock(i + 13, j + 1, k + 11, PlaceDeepslate, 0, 2);
		world.setBlock(i + 14, j + 1, k + 11, PlaceDeepslate, 0, 2);
		world.setBlock(i + 15, j + 1, k + 11, PlaceDeepslate, 0, 2);
		world.setBlock(i + 16, j + 1, k + 11, PlaceDeepslate, 0, 2);
		world.setBlock(i + 17, j + 1, k + 11, PlaceDeepslate, 0, 2);
		world.setBlock(i + 18, j + 1, k + 11, PlaceDeepslate, 0, 2);
		world.setBlock(i + 19, j + 1, k + 11, PlaceDeepslate, 0, 2);
		world.setBlock(i + 20, j + 1, k + 11, PlaceDeepslate, 0, 2);
		world.setBlock(i + 21, j + 1, k + 11, PlaceDeepslate, 0, 2);
		world.setBlock(i + 22, j + 1, k + 11, PlaceDeepslate, 0, 2);
		world.setBlock(i + 10, j + 1, k + 12, PlaceDeepslate, 0, 2);
		world.setBlock(i + 11, j + 1, k + 12, PlaceDeepslate, 0, 2);
		world.setBlock(i + 12, j + 1, k + 12, PlaceDeepslate, 0, 2);
		world.setBlock(i + 13, j + 1, k + 12, PlaceDeepslate, 0, 2);
		world.setBlock(i + 14, j + 1, k + 12, PlaceDeepslate, 0, 2);
		world.setBlock(i + 15, j + 1, k + 12, PlaceDeepslate, 0, 2);
		world.setBlock(i + 16, j + 1, k + 12, PlaceDeepslate, 0, 2);
		world.setBlock(i + 17, j + 1, k + 12, PlaceDeepslate, 0, 2);
		world.setBlock(i + 18, j + 1, k + 12, PlaceDeepslate, 0, 2);
		world.setBlock(i + 19, j + 1, k + 12, PlaceDeepslate, 0, 2);
		world.setBlock(i + 20, j + 1, k + 12, PlaceDeepslate, 0, 2);
		world.setBlock(i + 21, j + 1, k + 12, PlaceDeepslate, 0, 2);
		world.setBlock(i + 22, j + 1, k + 12, PlaceDeepslate, 0, 2);
		world.setBlock(i + 10, j + 1, k + 13, PlaceDeepslate, 0, 2);
		world.setBlock(i + 11, j + 1, k + 13, PlaceDeepslate, 0, 2);
		world.setBlock(i + 12, j + 1, k + 13, PlaceDeepslate, 0, 2);
		world.setBlock(i + 13, j + 1, k + 13, PlaceDeepslate, 0, 2);
		world.setBlock(i + 14, j + 1, k + 13, PlaceDeepslate, 0, 2);
		world.setBlock(i + 15, j + 1, k + 13, PlaceDeepslate, 0, 2);
		world.setBlock(i + 16, j + 1, k + 13, PlaceDeepslate, 0, 2);
		world.setBlock(i + 17, j + 1, k + 13, PlaceDeepslate, 0, 2);
		world.setBlock(i + 18, j + 1, k + 13, PlaceDeepslate, 0, 2);
		world.setBlock(i + 19, j + 1, k + 13, PlaceDeepslate, 0, 2);
		world.setBlock(i + 20, j + 1, k + 13, PlaceDeepslate, 0, 2);
		world.setBlock(i + 21, j + 1, k + 13, PlaceDeepslate, 0, 2);
		world.setBlock(i + 22, j + 1, k + 13, PlaceDeepslate, 0, 2);
		world.setBlock(i + 10, j + 1, k + 14, PlaceDeepslate, 0, 2);
		world.setBlock(i + 11, j + 1, k + 14, PlaceDeepslate, 0, 2);
		world.setBlock(i + 12, j + 1, k + 14, PlaceDeepslate, 0, 2);
		world.setBlock(i + 13, j + 1, k + 14, PlaceDeepslate, 0, 2);
		world.setBlock(i + 14, j + 1, k + 14, PlaceDeepslate, 0, 2);
		world.setBlock(i + 15, j + 1, k + 14, PlaceDeepslate, 0, 2);
		world.setBlock(i + 16, j + 1, k + 14, PlaceDeepslate, 0, 2);
		world.setBlock(i + 17, j + 1, k + 14, PlaceDeepslate, 0, 2);
		world.setBlock(i + 18, j + 1, k + 14, PlaceDeepslate, 0, 2);
		world.setBlock(i + 19, j + 1, k + 14, PlaceDeepslate, 0, 2);
		world.setBlock(i + 20, j + 1, k + 14, PlaceDeepslate, 0, 2);
		world.setBlock(i + 21, j + 1, k + 14, PlaceDeepslate, 0, 2);
		world.setBlock(i + 22, j + 1, k + 14, PlaceDeepslate, 0, 2);
		world.setBlock(i + 10, j + 1, k + 15, PlaceDeepslate, 0, 2);
		world.setBlock(i + 11, j + 1, k + 15, PlaceDeepslate, 0, 2);
		world.setBlock(i + 12, j + 1, k + 15, PlaceDeepslate, 0, 2);
		world.setBlock(i + 13, j + 1, k + 15, PlaceDeepslate, 0, 2);
		world.setBlock(i + 14, j + 1, k + 15, PlaceDeepslate, 0, 2);
		world.setBlock(i + 15, j + 1, k + 15, PlaceDeepslate, 0, 2);
		world.setBlock(i + 16, j + 1, k + 15, PlaceDeepslate, 0, 2);
		world.setBlock(i + 17, j + 1, k + 15, PlaceDeepslate, 0, 2);
		world.setBlock(i + 18, j + 1, k + 15, PlaceDeepslate, 0, 2);
		world.setBlock(i + 19, j + 1, k + 15, PlaceDeepslate, 0, 2);
		world.setBlock(i + 20, j + 1, k + 15, PlaceDeepslate, 0, 2);
		world.setBlock(i + 21, j + 1, k + 15, PlaceDeepslate, 0, 2);
		world.setBlock(i + 22, j + 1, k + 15, PlaceDeepslate, 0, 2);
		world.setBlock(i + 11, j + 1, k + 16, PlaceDeepslate, 0, 2);
		world.setBlock(i + 12, j + 1, k + 16, PlaceDeepslate, 0, 2);
		world.setBlock(i + 13, j + 1, k + 16, PlaceDeepslate, 0, 2);
		world.setBlock(i + 14, j + 1, k + 16, PlaceDeepslate, 0, 2);
		world.setBlock(i + 15, j + 1, k + 16, PlaceDeepslate, 0, 2);
		world.setBlock(i + 16, j + 1, k + 16, PlaceDeepslate, 0, 2);
		world.setBlock(i + 17, j + 1, k + 16, PlaceDeepslate, 0, 2);
		world.setBlock(i + 18, j + 1, k + 16, PlaceDeepslate, 0, 2);
		world.setBlock(i + 19, j + 1, k + 16, PlaceDeepslate, 0, 2);
		world.setBlock(i + 20, j + 1, k + 16, PlaceDeepslate, 0, 2);
		world.setBlock(i + 21, j + 1, k + 16, PlaceDeepslate, 0, 2);
		world.setBlock(i + 12, j + 1, k + 17, PlaceDeepslate, 0, 2);
		world.setBlock(i + 13, j + 1, k + 17, PlaceDeepslate, 0, 2);
		world.setBlock(i + 14, j + 1, k + 17, PlaceDeepslate, 0, 2);
		world.setBlock(i + 15, j + 1, k + 17, PlaceDeepslate, 0, 2);
		world.setBlock(i + 16, j + 1, k + 17, PlaceDeepslate, 0, 2);
		world.setBlock(i + 17, j + 1, k + 17, PlaceDeepslate, 0, 2);
		world.setBlock(i + 18, j + 1, k + 17, PlaceDeepslate, 0, 2);
		world.setBlock(i + 19, j + 1, k + 17, PlaceDeepslate, 0, 2);
		world.setBlock(i + 20, j + 1, k + 17, PlaceDeepslate, 0, 2);
		world.setBlock(i + 12, j + 2, k + 4, sculk_block, 0, 2);
		world.setBlock(i + 13, j + 2, k + 4, sculk_block, 0, 2);
		world.setBlock(i + 14, j + 2, k + 4, PlaceDeepslate, 0, 2);
		world.setBlock(i + 15, j + 2, k + 4, PlaceDeepslate, 0, 2);
		world.setBlock(i + 16, j + 2, k + 4, PlaceDeepslate, 0, 2);
		world.setBlock(i + 11, j + 2, k + 5, sculk_block, 0, 2);
		world.setBlock(i + 12, j + 2, k + 5, PlaceDeepslate, 0, 2);
		world.setBlock(i + 13, j + 2, k + 5, PlaceDeepslate, 0, 2);
		world.setBlock(i + 14, j + 2, k + 5, PlaceDeepslate, 0, 2);
		world.setBlock(i + 15, j + 2, k + 5, PlaceDeepslate, 0, 2);
		world.setBlock(i + 16, j + 2, k + 5, PlaceDeepslate, 0, 2);
		world.setBlock(i + 17, j + 2, k + 5, PlaceDeepslate, 0, 2);
		world.setBlock(i + 11, j + 2, k + 6, sculk_block, 0, 2);
		world.setBlock(i + 12, j + 2, k + 6, PlaceDeepslate, 0, 2);
		world.setBlock(i + 13, j + 2, k + 6, PlaceDeepslate, 0, 2);
		world.setBlock(i + 14, j + 2, k + 6, PlaceDeepslate, 0, 2);
		world.setBlock(i + 15, j + 2, k + 6, PlaceDeepslate, 0, 2);
		world.setBlock(i + 16, j + 2, k + 6, PlaceDeepslate, 0, 2);
		world.setBlock(i + 17, j + 2, k + 6, PlaceDeepslate, 0, 2);
		world.setBlock(i + 18, j + 2, k + 6, PlaceDeepslate, 0, 2);
		world.setBlock(i + 11, j + 2, k + 7, sculk_block, 0, 2);
		world.setBlock(i + 12, j + 2, k + 7, PlaceDeepslate, 0, 2);
		world.setBlock(i + 13, j + 2, k + 7, PlaceDeepslate, 0, 2);
		world.setBlock(i + 14, j + 2, k + 7, PlaceDeepslate, 0, 2);
		world.setBlock(i + 15, j + 2, k + 7, PlaceDeepslate, 0, 2);
		world.setBlock(i + 16, j + 2, k + 7, PlaceDeepslate, 0, 2);
		world.setBlock(i + 17, j + 2, k + 7, PlaceDeepslate, 0, 2);
		world.setBlock(i + 18, j + 2, k + 7, PlaceDeepslate, 0, 2);
		world.setBlock(i + 11, j + 2, k + 8, PlaceDeepslate, 0, 2);
		world.setBlock(i + 12, j + 2, k + 8, PlaceDeepslate, 0, 2);
		world.setBlock(i + 13, j + 2, k + 8, PlaceDeepslate, 0, 2);
		world.setBlock(i + 14, j + 2, k + 8, PlaceDeepslate, 0, 2);
		world.setBlock(i + 15, j + 2, k + 8, PlaceDeepslate, 0, 2);
		world.setBlock(i + 16, j + 2, k + 8, PlaceDeepslate, 0, 2);
		world.setBlock(i + 17, j + 2, k + 8, PlaceDeepslate, 0, 2);
		world.setBlock(i + 18, j + 2, k + 8, PlaceDeepslate, 0, 2);
		world.setBlock(i + 19, j + 2, k + 8, PlaceDeepslate, 0, 2);
		world.setBlock(i + 11, j + 2, k + 9, PlaceDeepslate, 0, 2);
		world.setBlock(i + 12, j + 2, k + 9, PlaceDeepslate, 0, 2);
		world.setBlock(i + 13, j + 2, k + 9, PlaceDeepslate, 0, 2);
		world.setBlock(i + 14, j + 2, k + 9, PlaceDeepslate, 0, 2);
		world.setBlock(i + 15, j + 2, k + 9, PlaceDeepslate, 0, 2);
		world.setBlock(i + 16, j + 2, k + 9, PlaceDeepslate, 0, 2);
		world.setBlock(i + 17, j + 2, k + 9, PlaceDeepslate, 0, 2);
		world.setBlock(i + 18, j + 2, k + 9, PlaceDeepslate, 0, 2);
		world.setBlock(i + 19, j + 2, k + 9, PlaceDeepslate, 0, 2);
		world.setBlock(i + 20, j + 2, k + 9, PlaceDeepslate, 0, 2);
		world.setBlock(i + 11, j + 2, k + 10, PlaceDeepslate, 0, 2);
		world.setBlock(i + 12, j + 2, k + 10, PlaceDeepslate, 0, 2);
		world.setBlock(i + 13, j + 2, k + 10, PlaceDeepslate, 0, 2);
		world.setBlock(i + 14, j + 2, k + 10, PlaceDeepslate, 0, 2);
		world.setBlock(i + 15, j + 2, k + 10, PlaceDeepslate, 0, 2);
		world.setBlock(i + 16, j + 2, k + 10, PlaceDeepslate, 0, 2);
		world.setBlock(i + 17, j + 2, k + 10, PlaceDeepslate, 0, 2);
		world.setBlock(i + 18, j + 2, k + 10, PlaceDeepslate, 0, 2);
		world.setBlock(i + 19, j + 2, k + 10, PlaceDeepslate, 0, 2);
		world.setBlock(i + 20, j + 2, k + 10, PlaceDeepslate, 0, 2);
		world.setBlock(i + 11, j + 2, k + 11, PlaceDeepslate, 0, 2);
		world.setBlock(i + 12, j + 2, k + 11, PlaceDeepslate, 0, 2);
		world.setBlock(i + 13, j + 2, k + 11, PlaceDeepslate, 0, 2);
		world.setBlock(i + 14, j + 2, k + 11, PlaceDeepslate, 0, 2);
		world.setBlock(i + 15, j + 2, k + 11, PlaceDeepslate, 0, 2);
		world.setBlock(i + 16, j + 2, k + 11, PlaceDeepslate, 0, 2);
		world.setBlock(i + 17, j + 2, k + 11, PlaceDeepslate, 0, 2);
		world.setBlock(i + 18, j + 2, k + 11, PlaceDeepslate, 0, 2);
		world.setBlock(i + 19, j + 2, k + 11, PlaceDeepslate, 0, 2);
		world.setBlock(i + 20, j + 2, k + 11, PlaceDeepslate, 0, 2);
		world.setBlock(i + 21, j + 2, k + 11, PlaceDeepslate, 0, 2);
		world.setBlock(i + 11, j + 2, k + 12, PlaceDeepslate, 0, 2);
		world.setBlock(i + 12, j + 2, k + 12, PlaceDeepslate, 0, 2);
		world.setBlock(i + 13, j + 2, k + 12, PlaceDeepslate, 0, 2);
		world.setBlock(i + 14, j + 2, k + 12, PlaceDeepslate, 0, 2);
		world.setBlock(i + 15, j + 2, k + 12, PlaceDeepslate, 0, 2);
		world.setBlock(i + 16, j + 2, k + 12, PlaceDeepslate, 0, 2);
		world.setBlock(i + 17, j + 2, k + 12, PlaceDeepslate, 0, 2);
		world.setBlock(i + 18, j + 2, k + 12, PlaceDeepslate, 0, 2);
		world.setBlock(i + 19, j + 2, k + 12, PlaceDeepslate, 0, 2);
		world.setBlock(i + 20, j + 2, k + 12, PlaceDeepslate, 0, 2);
		world.setBlock(i + 21, j + 2, k + 12, PlaceDeepslate, 0, 2);
		world.setBlock(i + 11, j + 2, k + 13, PlaceDeepslate, 0, 2);
		world.setBlock(i + 12, j + 2, k + 13, PlaceDeepslate, 0, 2);
		world.setBlock(i + 13, j + 2, k + 13, PlaceDeepslate, 0, 2);
		world.setBlock(i + 14, j + 2, k + 13, PlaceDeepslate, 0, 2);
		world.setBlock(i + 15, j + 2, k + 13, PlaceDeepslate, 0, 2);
		world.setBlock(i + 16, j + 2, k + 13, PlaceDeepslate, 0, 2);
		world.setBlock(i + 17, j + 2, k + 13, PlaceDeepslate, 0, 2);
		world.setBlock(i + 18, j + 2, k + 13, PlaceDeepslate, 0, 2);
		world.setBlock(i + 19, j + 2, k + 13, PlaceDeepslate, 0, 2);
		world.setBlock(i + 20, j + 2, k + 13, PlaceDeepslate, 0, 2);
		world.setBlock(i + 21, j + 2, k + 13, PlaceDeepslate, 0, 2);
		world.setBlock(i + 11, j + 2, k + 14, PlaceDeepslate, 0, 2);
		world.setBlock(i + 12, j + 2, k + 14, PlaceDeepslate, 0, 2);
		world.setBlock(i + 13, j + 2, k + 14, PlaceDeepslate, 0, 2);
		world.setBlock(i + 14, j + 2, k + 14, PlaceDeepslate, 0, 2);
		world.setBlock(i + 15, j + 2, k + 14, PlaceDeepslate, 0, 2);
		world.setBlock(i + 16, j + 2, k + 14, PlaceDeepslate, 0, 2);
		world.setBlock(i + 17, j + 2, k + 14, PlaceDeepslate, 0, 2);
		world.setBlock(i + 18, j + 2, k + 14, PlaceDeepslate, 0, 2);
		world.setBlock(i + 19, j + 2, k + 14, PlaceDeepslate, 0, 2);
		world.setBlock(i + 20, j + 2, k + 14, PlaceDeepslate, 0, 2);
		world.setBlock(i + 21, j + 2, k + 14, PlaceDeepslate, 0, 2);
		world.setBlock(i + 11, j + 2, k + 15, PlaceDeepslate, 0, 2);
		world.setBlock(i + 12, j + 2, k + 15, PlaceDeepslate, 0, 2);
		world.setBlock(i + 13, j + 2, k + 15, PlaceDeepslate, 0, 2);
		world.setBlock(i + 14, j + 2, k + 15, PlaceDeepslate, 0, 2);
		world.setBlock(i + 15, j + 2, k + 15, PlaceDeepslate, 0, 2);
		world.setBlock(i + 16, j + 2, k + 15, PlaceDeepslate, 0, 2);
		world.setBlock(i + 17, j + 2, k + 15, PlaceDeepslate, 0, 2);
		world.setBlock(i + 18, j + 2, k + 15, PlaceDeepslate, 0, 2);
		world.setBlock(i + 19, j + 2, k + 15, PlaceDeepslate, 0, 2);
		world.setBlock(i + 20, j + 2, k + 15, PlaceDeepslate, 0, 2);
		world.setBlock(i + 21, j + 2, k + 15, PlaceDeepslate, 0, 2);
		world.setBlock(i + 12, j + 2, k + 16, PlaceDeepslate, 0, 2);
		world.setBlock(i + 13, j + 2, k + 16, PlaceDeepslate, 0, 2);
		world.setBlock(i + 14, j + 2, k + 16, PlaceDeepslate, 0, 2);
		world.setBlock(i + 15, j + 2, k + 16, PlaceDeepslate, 0, 2);
		world.setBlock(i + 16, j + 2, k + 16, PlaceDeepslate, 0, 2);
		world.setBlock(i + 17, j + 2, k + 16, PlaceDeepslate, 0, 2);
		world.setBlock(i + 18, j + 2, k + 16, PlaceDeepslate, 0, 2);
		world.setBlock(i + 19, j + 2, k + 16, PlaceDeepslate, 0, 2);
		world.setBlock(i + 20, j + 2, k + 16, PlaceDeepslate, 0, 2);
		world.setBlock(i + 12, j + 3, k + 4, sculk_block, 0, 2);
		world.setBlock(i + 13, j + 3, k + 4, PlaceDeepslate, 0, 2);
		world.setBlock(i + 14, j + 3, k + 4, PlaceDeepslate, 0, 2);
		world.setBlock(i + 15, j + 3, k + 4, PlaceDeepslate, 0, 2);
		world.setBlock(i + 16, j + 3, k + 4, PlaceDeepslate, 0, 2);
		world.setBlock(i + 11, j + 3, k + 5, sculk_block, 0, 2);
		world.setBlock(i + 12, j + 3, k + 5, PlaceDeepslate, 0, 2);
		world.setBlock(i + 13, j + 3, k + 5, PlaceDeepslate, 0, 2);
		world.setBlock(i + 14, j + 3, k + 5, PlaceDeepslate, 0, 2);
		world.setBlock(i + 15, j + 3, k + 5, PlaceDeepslate, 0, 2);
		world.setBlock(i + 16, j + 3, k + 5, PlaceDeepslate, 0, 2);
		world.setBlock(i + 17, j + 3, k + 5, PlaceDeepslate, 0, 2);
		world.setBlock(i + 11, j + 3, k + 6, PlaceDeepslate, 0, 2);
		world.setBlock(i + 12, j + 3, k + 6, PlaceDeepslate, 0, 2);
		world.setBlock(i + 13, j + 3, k + 6, PlaceDeepslate, 0, 2);
		world.setBlock(i + 14, j + 3, k + 6, PlaceDeepslate, 0, 2);
		world.setBlock(i + 15, j + 3, k + 6, PlaceDeepslate, 0, 2);
		world.setBlock(i + 16, j + 3, k + 6, PlaceDeepslate, 0, 2);
		world.setBlock(i + 17, j + 3, k + 6, PlaceDeepslate, 0, 2);
		world.setBlock(i + 18, j + 3, k + 6, PlaceDeepslate, 0, 2);
		world.setBlock(i + 11, j + 3, k + 7, PlaceDeepslate, 0, 2);
		world.setBlock(i + 12, j + 3, k + 7, PlaceDeepslate, 0, 2);
		world.setBlock(i + 13, j + 3, k + 7, PlaceDeepslate, 0, 2);
		world.setBlock(i + 14, j + 3, k + 7, PlaceDeepslate, 0, 2);
		world.setBlock(i + 15, j + 3, k + 7, PlaceDeepslate, 0, 2);
		world.setBlock(i + 16, j + 3, k + 7, PlaceDeepslate, 0, 2);
		world.setBlock(i + 17, j + 3, k + 7, PlaceDeepslate, 0, 2);
		world.setBlock(i + 18, j + 3, k + 7, PlaceDeepslate, 0, 2);
		world.setBlock(i + 11, j + 3, k + 8, PlaceDeepslate, 0, 2);
		world.setBlock(i + 12, j + 3, k + 8, PlaceDeepslate, 0, 2);
		world.setBlock(i + 13, j + 3, k + 8, PlaceDeepslate, 0, 2);
		world.setBlock(i + 14, j + 3, k + 8, PlaceDeepslate, 0, 2);
		world.setBlock(i + 15, j + 3, k + 8, PlaceDeepslate, 0, 2);
		world.setBlock(i + 16, j + 3, k + 8, PlaceDeepslate, 0, 2);
		world.setBlock(i + 17, j + 3, k + 8, PlaceDeepslate, 0, 2);
		world.setBlock(i + 18, j + 3, k + 8, PlaceDeepslate, 0, 2);
		world.setBlock(i + 19, j + 3, k + 8, PlaceDeepslate, 0, 2);
		world.setBlock(i + 11, j + 3, k + 9, PlaceDeepslate, 0, 2);
		world.setBlock(i + 12, j + 3, k + 9, PlaceDeepslate, 0, 2);
		world.setBlock(i + 13, j + 3, k + 9, PlaceDeepslate, 0, 2);
		world.setBlock(i + 14, j + 3, k + 9, PlaceDeepslate, 0, 2);
		world.setBlock(i + 15, j + 3, k + 9, PlaceDeepslate, 0, 2);
		world.setBlock(i + 16, j + 3, k + 9, PlaceDeepslate, 0, 2);
		world.setBlock(i + 17, j + 3, k + 9, PlaceDeepslate, 0, 2);
		world.setBlock(i + 18, j + 3, k + 9, PlaceDeepslate, 0, 2);
		world.setBlock(i + 19, j + 3, k + 9, PlaceDeepslate, 0, 2);
		world.setBlock(i + 20, j + 3, k + 9, PlaceDeepslate, 0, 2);
		world.setBlock(i + 11, j + 3, k + 10, PlaceDeepslate, 0, 2);
		world.setBlock(i + 12, j + 3, k + 10, PlaceDeepslate, 0, 2);
		world.setBlock(i + 13, j + 3, k + 10, PlaceDeepslate, 0, 2);
		world.setBlock(i + 14, j + 3, k + 10, PlaceDeepslate, 0, 2);
		world.setBlock(i + 15, j + 3, k + 10, PlaceDeepslate, 0, 2);
		world.setBlock(i + 16, j + 3, k + 10, PlaceDeepslate, 0, 2);
		world.setBlock(i + 17, j + 3, k + 10, PlaceDeepslate, 0, 2);
		world.setBlock(i + 18, j + 3, k + 10, PlaceDeepslate, 0, 2);
		world.setBlock(i + 19, j + 3, k + 10, PlaceDeepslate, 0, 2);
		world.setBlock(i + 20, j + 3, k + 10, PlaceDeepslate, 0, 2);
		world.setBlock(i + 11, j + 3, k + 11, PlaceDeepslate, 0, 2);
		world.setBlock(i + 12, j + 3, k + 11, PlaceDeepslate, 0, 2);
		world.setBlock(i + 13, j + 3, k + 11, PlaceDeepslate, 0, 2);
		world.setBlock(i + 14, j + 3, k + 11, PlaceDeepslate, 0, 2);
		world.setBlock(i + 15, j + 3, k + 11, PlaceDeepslate, 0, 2);
		world.setBlock(i + 16, j + 3, k + 11, PlaceDeepslate, 0, 2);
		world.setBlock(i + 17, j + 3, k + 11, PlaceDeepslate, 0, 2);
		world.setBlock(i + 18, j + 3, k + 11, PlaceDeepslate, 0, 2);
		world.setBlock(i + 19, j + 3, k + 11, PlaceDeepslate, 0, 2);
		world.setBlock(i + 20, j + 3, k + 11, PlaceDeepslate, 0, 2);
		world.setBlock(i + 21, j + 3, k + 11, PlaceDeepslate, 0, 2);
		world.setBlock(i + 11, j + 3, k + 12, PlaceDeepslate, 0, 2);
		world.setBlock(i + 12, j + 3, k + 12, PlaceDeepslate, 0, 2);
		world.setBlock(i + 13, j + 3, k + 12, PlaceDeepslate, 0, 2);
		world.setBlock(i + 14, j + 3, k + 12, PlaceDeepslate, 0, 2);
		world.setBlock(i + 15, j + 3, k + 12, PlaceDeepslate, 0, 2);
		world.setBlock(i + 16, j + 3, k + 12, PlaceDeepslate, 0, 2);
		world.setBlock(i + 17, j + 3, k + 12, PlaceDeepslate, 0, 2);
		world.setBlock(i + 18, j + 3, k + 12, PlaceDeepslate, 0, 2);
		world.setBlock(i + 19, j + 3, k + 12, PlaceDeepslate, 0, 2);
		world.setBlock(i + 20, j + 3, k + 12, PlaceDeepslate, 0, 2);
		world.setBlock(i + 21, j + 3, k + 12, PlaceDeepslate, 0, 2);
		world.setBlock(i + 11, j + 3, k + 13, PlaceDeepslate, 0, 2);
		world.setBlock(i + 12, j + 3, k + 13, PlaceDeepslate, 0, 2);
		world.setBlock(i + 13, j + 3, k + 13, PlaceDeepslate, 0, 2);
		world.setBlock(i + 14, j + 3, k + 13, PlaceDeepslate, 0, 2);
		world.setBlock(i + 15, j + 3, k + 13, PlaceDeepslate, 0, 2);
		world.setBlock(i + 16, j + 3, k + 13, PlaceDeepslate, 0, 2);
		world.setBlock(i + 17, j + 3, k + 13, PlaceDeepslate, 0, 2);
		world.setBlock(i + 18, j + 3, k + 13, PlaceDeepslate, 0, 2);
		world.setBlock(i + 19, j + 3, k + 13, PlaceDeepslate, 0, 2);
		world.setBlock(i + 20, j + 3, k + 13, PlaceDeepslate, 0, 2);
		world.setBlock(i + 21, j + 3, k + 13, PlaceDeepslate, 0, 2);
		world.setBlock(i + 11, j + 3, k + 14, PlaceDeepslate, 0, 2);
		world.setBlock(i + 12, j + 3, k + 14, PlaceDeepslate, 0, 2);
		world.setBlock(i + 13, j + 3, k + 14, PlaceDeepslate, 0, 2);
		world.setBlock(i + 14, j + 3, k + 14, PlaceDeepslate, 0, 2);
		world.setBlock(i + 15, j + 3, k + 14, PlaceDeepslate, 0, 2);
		world.setBlock(i + 16, j + 3, k + 14, PlaceDeepslate, 0, 2);
		world.setBlock(i + 17, j + 3, k + 14, PlaceDeepslate, 0, 2);
		world.setBlock(i + 18, j + 3, k + 14, PlaceDeepslate, 0, 2);
		world.setBlock(i + 19, j + 3, k + 14, PlaceDeepslate, 0, 2);
		world.setBlock(i + 20, j + 3, k + 14, PlaceDeepslate, 0, 2);
		world.setBlock(i + 21, j + 3, k + 14, PlaceDeepslate, 0, 2);
		world.setBlock(i + 11, j + 3, k + 15, PlaceDeepslate, 0, 2);
		world.setBlock(i + 12, j + 3, k + 15, PlaceDeepslate, 0, 2);
		world.setBlock(i + 13, j + 3, k + 15, PlaceDeepslate, 0, 2);
		world.setBlock(i + 14, j + 3, k + 15, PlaceDeepslate, 0, 2);
		world.setBlock(i + 15, j + 3, k + 15, PlaceDeepslate, 0, 2);
		world.setBlock(i + 16, j + 3, k + 15, PlaceDeepslate, 0, 2);
		world.setBlock(i + 17, j + 3, k + 15, PlaceDeepslate, 0, 2);
		world.setBlock(i + 18, j + 3, k + 15, PlaceDeepslate, 0, 2);
		world.setBlock(i + 19, j + 3, k + 15, PlaceDeepslate, 0, 2);
		world.setBlock(i + 20, j + 3, k + 15, PlaceDeepslate, 0, 2);
		world.setBlock(i + 21, j + 3, k + 15, PlaceDeepslate, 0, 2);
		world.setBlock(i + 12, j + 3, k + 16, PlaceDeepslate, 0, 2);
		world.setBlock(i + 13, j + 3, k + 16, PlaceDeepslate, 0, 2);
		world.setBlock(i + 14, j + 3, k + 16, PlaceDeepslate, 0, 2);
		world.setBlock(i + 15, j + 3, k + 16, PlaceDeepslate, 0, 2);
		world.setBlock(i + 16, j + 3, k + 16, PlaceDeepslate, 0, 2);
		world.setBlock(i + 17, j + 3, k + 16, PlaceDeepslate, 0, 2);
		world.setBlock(i + 18, j + 3, k + 16, PlaceDeepslate, 0, 2);
		world.setBlock(i + 19, j + 3, k + 16, PlaceDeepslate, 0, 2);
		world.setBlock(i + 20, j + 3, k + 16, PlaceDeepslate, 0, 2);
		world.setBlock(i + 12, j + 4, k + 4, sculk_block, 0, 2);
		world.setBlock(i + 13, j + 4, k + 4, PlaceDeepslate, 0, 2);
		world.setBlock(i + 14, j + 4, k + 4, PlaceDeepslate, 0, 2);
		world.setBlock(i + 15, j + 4, k + 4, PlaceDeepslate, 0, 2);
		world.setBlock(i + 16, j + 4, k + 4, PlaceDeepslate, 0, 2);
		world.setBlock(i + 11, j + 4, k + 5, PlaceDeepslate, 0, 2);
		world.setBlock(i + 12, j + 4, k + 5, PlaceDeepslate, 0, 2);
		world.setBlock(i + 13, j + 4, k + 5, PlaceDeepslate, 0, 2);
		world.setBlock(i + 14, j + 4, k + 5, PlaceDeepslate, 0, 2);
		world.setBlock(i + 15, j + 4, k + 5, PlaceDeepslate, 0, 2);
		world.setBlock(i + 16, j + 4, k + 5, PlaceDeepslate, 0, 2);
		world.setBlock(i + 17, j + 4, k + 5, PlaceDeepslate, 0, 2);
		world.setBlock(i + 11, j + 4, k + 6, PlaceDeepslate, 0, 2);
		world.setBlock(i + 12, j + 4, k + 6, PlaceDeepslate, 0, 2);
		world.setBlock(i + 13, j + 4, k + 6, PlaceDeepslate, 0, 2);
		world.setBlock(i + 14, j + 4, k + 6, PlaceDeepslate, 0, 2);
		world.setBlock(i + 15, j + 4, k + 6, PlaceDeepslate, 0, 2);
		world.setBlock(i + 16, j + 4, k + 6, PlaceDeepslate, 0, 2);
		world.setBlock(i + 17, j + 4, k + 6, PlaceDeepslate, 0, 2);
		world.setBlock(i + 18, j + 4, k + 6, PlaceDeepslate, 0, 2);
		world.setBlock(i + 11, j + 4, k + 7, PlaceDeepslate, 0, 2);
		world.setBlock(i + 12, j + 4, k + 7, PlaceDeepslate, 0, 2);
		world.setBlock(i + 13, j + 4, k + 7, PlaceDeepslate, 0, 2);
		world.setBlock(i + 14, j + 4, k + 7, PlaceDeepslate, 0, 2);
		world.setBlock(i + 15, j + 4, k + 7, PlaceDeepslate, 0, 2);
		world.setBlock(i + 16, j + 4, k + 7, PlaceDeepslate, 0, 2);
		world.setBlock(i + 17, j + 4, k + 7, PlaceDeepslate, 0, 2);
		world.setBlock(i + 18, j + 4, k + 7, PlaceDeepslate, 0, 2);
		world.setBlock(i + 11, j + 4, k + 8, PlaceDeepslate, 0, 2);
		world.setBlock(i + 12, j + 4, k + 8, PlaceDeepslate, 0, 2);
		world.setBlock(i + 13, j + 4, k + 8, PlaceDeepslate, 0, 2);
		world.setBlock(i + 14, j + 4, k + 8, PlaceDeepslate, 0, 2);
		world.setBlock(i + 15, j + 4, k + 8, PlaceDeepslate, 0, 2);
		world.setBlock(i + 16, j + 4, k + 8, PlaceDeepslate, 0, 2);
		world.setBlock(i + 17, j + 4, k + 8, PlaceDeepslate, 0, 2);
		world.setBlock(i + 18, j + 4, k + 8, PlaceDeepslate, 0, 2);
		world.setBlock(i + 19, j + 4, k + 8, PlaceDeepslate, 0, 2);
		world.setBlock(i + 11, j + 4, k + 9, PlaceDeepslate, 0, 2);
		world.setBlock(i + 12, j + 4, k + 9, PlaceDeepslate, 0, 2);
		world.setBlock(i + 13, j + 4, k + 9, PlaceDeepslate, 0, 2);
		world.setBlock(i + 14, j + 4, k + 9, PlaceDeepslate, 0, 2);
		world.setBlock(i + 15, j + 4, k + 9, PlaceDeepslate, 0, 2);
		world.setBlock(i + 16, j + 4, k + 9, PlaceDeepslate, 0, 2);
		world.setBlock(i + 17, j + 4, k + 9, PlaceDeepslate, 0, 2);
		world.setBlock(i + 18, j + 4, k + 9, PlaceDeepslate, 0, 2);
		world.setBlock(i + 19, j + 4, k + 9, PlaceDeepslate, 0, 2);
		world.setBlock(i + 20, j + 4, k + 9, PlaceDeepslate, 0, 2);
		world.setBlock(i + 11, j + 4, k + 10, PlaceDeepslate, 0, 2);
		world.setBlock(i + 12, j + 4, k + 10, PlaceDeepslate, 0, 2);
		world.setBlock(i + 13, j + 4, k + 10, PlaceDeepslate, 0, 2);
		world.setBlock(i + 14, j + 4, k + 10, PlaceDeepslate, 0, 2);
		world.setBlock(i + 15, j + 4, k + 10, PlaceDeepslate, 0, 2);
		world.setBlock(i + 16, j + 4, k + 10, PlaceDeepslate, 0, 2);
		world.setBlock(i + 17, j + 4, k + 10, PlaceDeepslate, 0, 2);
		world.setBlock(i + 18, j + 4, k + 10, PlaceDeepslate, 0, 2);
		world.setBlock(i + 19, j + 4, k + 10, PlaceDeepslate, 0, 2);
		world.setBlock(i + 20, j + 4, k + 10, PlaceDeepslate, 0, 2);
		world.setBlock(i + 11, j + 4, k + 11, PlaceDeepslate, 0, 2);
		world.setBlock(i + 12, j + 4, k + 11, PlaceDeepslate, 0, 2);
		world.setBlock(i + 13, j + 4, k + 11, PlaceDeepslate, 0, 2);
		world.setBlock(i + 14, j + 4, k + 11, PlaceDeepslate, 0, 2);
		world.setBlock(i + 15, j + 4, k + 11, PlaceDeepslate, 0, 2);
		world.setBlock(i + 16, j + 4, k + 11, PlaceDeepslate, 0, 2);
		world.setBlock(i + 17, j + 4, k + 11, PlaceDeepslate, 0, 2);
		world.setBlock(i + 18, j + 4, k + 11, PlaceDeepslate, 0, 2);
		world.setBlock(i + 19, j + 4, k + 11, PlaceDeepslate, 0, 2);
		world.setBlock(i + 20, j + 4, k + 11, PlaceDeepslate, 0, 2);
		world.setBlock(i + 21, j + 4, k + 11, PlaceDeepslate, 0, 2);
		world.setBlock(i + 11, j + 4, k + 12, PlaceDeepslate, 0, 2);
		world.setBlock(i + 12, j + 4, k + 12, PlaceDeepslate, 0, 2);
		world.setBlock(i + 13, j + 4, k + 12, PlaceDeepslate, 0, 2);
		world.setBlock(i + 14, j + 4, k + 12, PlaceDeepslate, 0, 2);
		world.setBlock(i + 15, j + 4, k + 12, PlaceDeepslate, 0, 2);
		world.setBlock(i + 16, j + 4, k + 12, PlaceDeepslate, 0, 2);
		world.setBlock(i + 17, j + 4, k + 12, PlaceDeepslate, 0, 2);
		world.setBlock(i + 18, j + 4, k + 12, PlaceDeepslate, 0, 2);
		world.setBlock(i + 19, j + 4, k + 12, PlaceDeepslate, 0, 2);
		world.setBlock(i + 20, j + 4, k + 12, PlaceDeepslate, 0, 2);
		world.setBlock(i + 21, j + 4, k + 12, PlaceDeepslate, 0, 2);
		world.setBlock(i + 11, j + 4, k + 13, PlaceDeepslate, 0, 2);
		world.setBlock(i + 12, j + 4, k + 13, PlaceDeepslate, 0, 2);
		world.setBlock(i + 13, j + 4, k + 13, PlaceDeepslate, 0, 2);
		world.setBlock(i + 14, j + 4, k + 13, PlaceDeepslate, 0, 2);
		world.setBlock(i + 15, j + 4, k + 13, PlaceDeepslate, 0, 2);
		world.setBlock(i + 16, j + 4, k + 13, PlaceDeepslate, 0, 2);
		world.setBlock(i + 17, j + 4, k + 13, PlaceDeepslate, 0, 2);
		world.setBlock(i + 18, j + 4, k + 13, PlaceDeepslate, 0, 2);
		world.setBlock(i + 19, j + 4, k + 13, PlaceDeepslate, 0, 2);
		world.setBlock(i + 20, j + 4, k + 13, PlaceDeepslate, 0, 2);
		world.setBlock(i + 21, j + 4, k + 13, PlaceDeepslate, 0, 2);
		world.setBlock(i + 11, j + 4, k + 14, PlaceDeepslate, 0, 2);
		world.setBlock(i + 12, j + 4, k + 14, PlaceDeepslate, 0, 2);
		world.setBlock(i + 13, j + 4, k + 14, PlaceDeepslate, 0, 2);
		world.setBlock(i + 14, j + 4, k + 14, PlaceDeepslate, 0, 2);
		world.setBlock(i + 15, j + 4, k + 14, PlaceDeepslate, 0, 2);
		world.setBlock(i + 16, j + 4, k + 14, PlaceDeepslate, 0, 2);
		world.setBlock(i + 17, j + 4, k + 14, PlaceDeepslate, 0, 2);
		world.setBlock(i + 18, j + 4, k + 14, PlaceDeepslate, 0, 2);
		world.setBlock(i + 19, j + 4, k + 14, PlaceDeepslate, 0, 2);
		world.setBlock(i + 20, j + 4, k + 14, PlaceDeepslate, 0, 2);
		world.setBlock(i + 21, j + 4, k + 14, PlaceDeepslate, 0, 2);
		world.setBlock(i + 11, j + 4, k + 15, PlaceDeepslate, 0, 2);
		world.setBlock(i + 12, j + 4, k + 15, PlaceDeepslate, 0, 2);
		world.setBlock(i + 13, j + 4, k + 15, PlaceDeepslate, 0, 2);
		world.setBlock(i + 14, j + 4, k + 15, PlaceDeepslate, 0, 2);
		world.setBlock(i + 15, j + 4, k + 15, PlaceDeepslate, 0, 2);
		world.setBlock(i + 16, j + 4, k + 15, PlaceDeepslate, 0, 2);
		world.setBlock(i + 17, j + 4, k + 15, PlaceDeepslate, 0, 2);
		world.setBlock(i + 18, j + 4, k + 15, PlaceDeepslate, 0, 2);
		world.setBlock(i + 19, j + 4, k + 15, PlaceDeepslate, 0, 2);
		world.setBlock(i + 20, j + 4, k + 15, PlaceDeepslate, 0, 2);
		world.setBlock(i + 21, j + 4, k + 15, PlaceDeepslate, 0, 2);
		world.setBlock(i + 12, j + 4, k + 16, PlaceDeepslate, 0, 2);
		world.setBlock(i + 13, j + 4, k + 16, PlaceDeepslate, 0, 2);
		world.setBlock(i + 14, j + 4, k + 16, PlaceDeepslate, 0, 2);
		world.setBlock(i + 15, j + 4, k + 16, PlaceDeepslate, 0, 2);
		world.setBlock(i + 16, j + 4, k + 16, PlaceDeepslate, 0, 2);
		world.setBlock(i + 17, j + 4, k + 16, PlaceDeepslate, 0, 2);
		world.setBlock(i + 18, j + 4, k + 16, PlaceDeepslate, 0, 2);
		world.setBlock(i + 19, j + 4, k + 16, PlaceDeepslate, 0, 2);
		world.setBlock(i + 20, j + 4, k + 16, PlaceDeepslate, 0, 2);
		world.setBlock(i + 12, j + 5, k + 4, PlaceDeepslate, 0, 2);
		world.setBlock(i + 13, j + 5, k + 4, PlaceDeepslate, 0, 2);
		world.setBlock(i + 14, j + 5, k + 4, PlaceDeepslate, 0, 2);
		world.setBlock(i + 15, j + 5, k + 4, PlaceDeepslate, 0, 2);
		world.setBlock(i + 16, j + 5, k + 4, PlaceDeepslate, 0, 2);
		world.setBlock(i + 11, j + 5, k + 5, PlaceDeepslate, 0, 2);
		world.setBlock(i + 12, j + 5, k + 5, PlaceDeepslate, 0, 2);
		world.setBlock(i + 13, j + 5, k + 5, PlaceDeepslate, 0, 2);
		world.setBlock(i + 14, j + 5, k + 5, PlaceDeepslate, 0, 2);
		world.setBlock(i + 15, j + 5, k + 5, PlaceDeepslate, 0, 2);
		world.setBlock(i + 16, j + 5, k + 5, PlaceDeepslate, 0, 2);
		world.setBlock(i + 17, j + 5, k + 5, PlaceDeepslate, 0, 2);
		world.setBlock(i + 11, j + 5, k + 6, PlaceDeepslate, 0, 2);
		world.setBlock(i + 12, j + 5, k + 6, PlaceDeepslate, 0, 2);
		world.setBlock(i + 13, j + 5, k + 6, PlaceDeepslate, 0, 2);
		world.setBlock(i + 14, j + 5, k + 6, PlaceDeepslate, 0, 2);
		world.setBlock(i + 15, j + 5, k + 6, PlaceDeepslate, 0, 2);
		world.setBlock(i + 16, j + 5, k + 6, PlaceDeepslate, 0, 2);
		world.setBlock(i + 17, j + 5, k + 6, PlaceDeepslate, 0, 2);
		world.setBlock(i + 18, j + 5, k + 6, PlaceDeepslate, 0, 2);
		world.setBlock(i + 11, j + 5, k + 7, PlaceDeepslate, 0, 2);
		world.setBlock(i + 12, j + 5, k + 7, PlaceDeepslate, 0, 2);
		world.setBlock(i + 13, j + 5, k + 7, PlaceDeepslate, 0, 2);
		world.setBlock(i + 14, j + 5, k + 7, PlaceDeepslate, 0, 2);
		world.setBlock(i + 15, j + 5, k + 7, PlaceDeepslate, 0, 2);
		world.setBlock(i + 16, j + 5, k + 7, PlaceDeepslate, 0, 2);
		world.setBlock(i + 17, j + 5, k + 7, PlaceDeepslate, 0, 2);
		world.setBlock(i + 18, j + 5, k + 7, PlaceDeepslate, 0, 2);
		world.setBlock(i + 11, j + 5, k + 8, PlaceDeepslate, 0, 2);
		world.setBlock(i + 12, j + 5, k + 8, PlaceDeepslate, 0, 2);
		world.setBlock(i + 13, j + 5, k + 8, PlaceDeepslate, 0, 2);
		world.setBlock(i + 14, j + 5, k + 8, PlaceDeepslate, 0, 2);
		world.setBlock(i + 15, j + 5, k + 8, PlaceDeepslate, 0, 2);
		world.setBlock(i + 16, j + 5, k + 8, PlaceDeepslate, 0, 2);
		world.setBlock(i + 17, j + 5, k + 8, PlaceDeepslate, 0, 2);
		world.setBlock(i + 18, j + 5, k + 8, PlaceDeepslate, 0, 2);
		world.setBlock(i + 19, j + 5, k + 8, PlaceDeepslate, 0, 2);
		world.setBlock(i + 11, j + 5, k + 9, PlaceDeepslate, 0, 2);
		world.setBlock(i + 12, j + 5, k + 9, PlaceDeepslate, 0, 2);
		world.setBlock(i + 13, j + 5, k + 9, PlaceDeepslate, 0, 2);
		world.setBlock(i + 14, j + 5, k + 9, PlaceDeepslate, 0, 2);
		world.setBlock(i + 15, j + 5, k + 9, PlaceDeepslate, 0, 2);
		world.setBlock(i + 16, j + 5, k + 9, PlaceDeepslate, 0, 2);
		world.setBlock(i + 17, j + 5, k + 9, PlaceDeepslate, 0, 2);
		world.setBlock(i + 18, j + 5, k + 9, PlaceDeepslate, 0, 2);
		world.setBlock(i + 19, j + 5, k + 9, PlaceDeepslate, 0, 2);
		world.setBlock(i + 20, j + 5, k + 9, PlaceDeepslate, 0, 2);
		world.setBlock(i + 11, j + 5, k + 10, PlaceDeepslate, 0, 2);
		world.setBlock(i + 12, j + 5, k + 10, PlaceDeepslate, 0, 2);
		world.setBlock(i + 13, j + 5, k + 10, PlaceDeepslate, 0, 2);
		world.setBlock(i + 14, j + 5, k + 10, PlaceDeepslate, 0, 2);
		world.setBlock(i + 15, j + 5, k + 10, PlaceDeepslate, 0, 2);
		world.setBlock(i + 16, j + 5, k + 10, PlaceDeepslate, 0, 2);
		world.setBlock(i + 17, j + 5, k + 10, PlaceDeepslate, 0, 2);
		world.setBlock(i + 18, j + 5, k + 10, PlaceDeepslate, 0, 2);
		world.setBlock(i + 19, j + 5, k + 10, PlaceDeepslate, 0, 2);
		world.setBlock(i + 20, j + 5, k + 10, PlaceDeepslate, 0, 2);
		world.setBlock(i + 11, j + 5, k + 11, PlaceDeepslate, 0, 2);
		world.setBlock(i + 12, j + 5, k + 11, PlaceDeepslate, 0, 2);
		world.setBlock(i + 13, j + 5, k + 11, PlaceDeepslate, 0, 2);
		world.setBlock(i + 14, j + 5, k + 11, PlaceDeepslate, 0, 2);
		world.setBlock(i + 15, j + 5, k + 11, PlaceDeepslate, 0, 2);
		world.setBlock(i + 16, j + 5, k + 11, PlaceDeepslate, 0, 2);
		world.setBlock(i + 17, j + 5, k + 11, PlaceDeepslate, 0, 2);
		world.setBlock(i + 18, j + 5, k + 11, PlaceDeepslate, 0, 2);
		world.setBlock(i + 19, j + 5, k + 11, PlaceDeepslate, 0, 2);
		world.setBlock(i + 20, j + 5, k + 11, PlaceDeepslate, 0, 2);
		world.setBlock(i + 21, j + 5, k + 11, PlaceDeepslate, 0, 2);
		world.setBlock(i + 11, j + 5, k + 12, PlaceDeepslate, 0, 2);
		world.setBlock(i + 12, j + 5, k + 12, PlaceDeepslate, 0, 2);
		world.setBlock(i + 13, j + 5, k + 12, PlaceDeepslate, 0, 2);
		world.setBlock(i + 14, j + 5, k + 12, PlaceDeepslate, 0, 2);
		world.setBlock(i + 15, j + 5, k + 12, PlaceDeepslate, 0, 2);
		world.setBlock(i + 16, j + 5, k + 12, PlaceDeepslate, 0, 2);
		world.setBlock(i + 17, j + 5, k + 12, PlaceDeepslate, 0, 2);
		world.setBlock(i + 18, j + 5, k + 12, PlaceDeepslate, 0, 2);
		world.setBlock(i + 19, j + 5, k + 12, PlaceDeepslate, 0, 2);
		world.setBlock(i + 20, j + 5, k + 12, PlaceDeepslate, 0, 2);
		world.setBlock(i + 21, j + 5, k + 12, PlaceDeepslate, 0, 2);
		world.setBlock(i + 11, j + 5, k + 13, PlaceDeepslate, 0, 2);
		world.setBlock(i + 12, j + 5, k + 13, PlaceDeepslate, 0, 2);
		world.setBlock(i + 13, j + 5, k + 13, PlaceDeepslate, 0, 2);
		world.setBlock(i + 14, j + 5, k + 13, PlaceDeepslate, 0, 2);
		world.setBlock(i + 15, j + 5, k + 13, PlaceDeepslate, 0, 2);
		world.setBlock(i + 16, j + 5, k + 13, PlaceDeepslate, 0, 2);
		world.setBlock(i + 17, j + 5, k + 13, PlaceDeepslate, 0, 2);
		world.setBlock(i + 18, j + 5, k + 13, PlaceDeepslate, 0, 2);
		world.setBlock(i + 19, j + 5, k + 13, PlaceDeepslate, 0, 2);
		world.setBlock(i + 20, j + 5, k + 13, PlaceDeepslate, 0, 2);
		world.setBlock(i + 21, j + 5, k + 13, PlaceDeepslate, 0, 2);
		world.setBlock(i + 11, j + 5, k + 14, PlaceDeepslate, 0, 2);
		world.setBlock(i + 12, j + 5, k + 14, PlaceDeepslate, 0, 2);
		world.setBlock(i + 13, j + 5, k + 14, PlaceDeepslate, 0, 2);
		world.setBlock(i + 14, j + 5, k + 14, PlaceDeepslate, 0, 2);
		world.setBlock(i + 15, j + 5, k + 14, PlaceDeepslate, 0, 2);
		world.setBlock(i + 16, j + 5, k + 14, PlaceDeepslate, 0, 2);
		world.setBlock(i + 17, j + 5, k + 14, PlaceDeepslate, 0, 2);
		world.setBlock(i + 18, j + 5, k + 14, PlaceDeepslate, 0, 2);
		world.setBlock(i + 19, j + 5, k + 14, PlaceDeepslate, 0, 2);
		world.setBlock(i + 20, j + 5, k + 14, PlaceDeepslate, 0, 2);
		world.setBlock(i + 21, j + 5, k + 14, PlaceDeepslate, 0, 2);
		world.setBlock(i + 11, j + 5, k + 15, PlaceDeepslate, 0, 2);
		world.setBlock(i + 12, j + 5, k + 15, PlaceDeepslate, 0, 2);
		world.setBlock(i + 13, j + 5, k + 15, PlaceDeepslate, 0, 2);
		world.setBlock(i + 14, j + 5, k + 15, PlaceDeepslate, 0, 2);
		world.setBlock(i + 15, j + 5, k + 15, PlaceDeepslate, 0, 2);
		world.setBlock(i + 16, j + 5, k + 15, PlaceDeepslate, 0, 2);
		world.setBlock(i + 17, j + 5, k + 15, PlaceDeepslate, 0, 2);
		world.setBlock(i + 18, j + 5, k + 15, PlaceDeepslate, 0, 2);
		world.setBlock(i + 19, j + 5, k + 15, PlaceDeepslate, 0, 2);
		world.setBlock(i + 20, j + 5, k + 15, PlaceDeepslate, 0, 2);
		world.setBlock(i + 21, j + 5, k + 15, PlaceDeepslate, 0, 2);
		world.setBlock(i + 12, j + 5, k + 16, PlaceDeepslate, 0, 2);
		world.setBlock(i + 13, j + 5, k + 16, PlaceDeepslate, 0, 2);
		world.setBlock(i + 14, j + 5, k + 16, PlaceDeepslate, 0, 2);
		world.setBlock(i + 15, j + 5, k + 16, PlaceDeepslate, 0, 2);
		world.setBlock(i + 16, j + 5, k + 16, PlaceDeepslate, 0, 2);
		world.setBlock(i + 17, j + 5, k + 16, PlaceDeepslate, 0, 2);
		world.setBlock(i + 18, j + 5, k + 16, PlaceDeepslate, 0, 2);
		world.setBlock(i + 19, j + 5, k + 16, PlaceDeepslate, 0, 2);
		world.setBlock(i + 20, j + 5, k + 16, PlaceDeepslate, 0, 2);
		world.setBlock(i + 12, j + 6, k + 4, PlaceDeepslate, 0, 2);
		world.setBlock(i + 13, j + 6, k + 4, PlaceDeepslate, 0, 2);
		world.setBlock(i + 14, j + 6, k + 4, PlaceDeepslate, 0, 2);
		world.setBlock(i + 15, j + 6, k + 4, PlaceDeepslate, 0, 2);
		world.setBlock(i + 16, j + 6, k + 4, PlaceDeepslate, 0, 2);
		world.setBlock(i + 11, j + 6, k + 5, PlaceDeepslate, 0, 2);
		world.setBlock(i + 12, j + 6, k + 5, PlaceDeepslate, 0, 2);
		world.setBlock(i + 13, j + 6, k + 5, PlaceDeepslate, 0, 2);
		world.setBlock(i + 14, j + 6, k + 5, PlaceDeepslate, 0, 2);
		world.setBlock(i + 15, j + 6, k + 5, PlaceDeepslate, 0, 2);
		world.setBlock(i + 16, j + 6, k + 5, PlaceDeepslate, 0, 2);
		world.setBlock(i + 17, j + 6, k + 5, PlaceDeepslate, 0, 2);
		world.setBlock(i + 11, j + 6, k + 6, PlaceDeepslate, 0, 2);
		world.setBlock(i + 12, j + 6, k + 6, PlaceDeepslate, 0, 2);
		world.setBlock(i + 13, j + 6, k + 6, PlaceDeepslate, 0, 2);
		world.setBlock(i + 14, j + 6, k + 6, PlaceDeepslate, 0, 2);
		world.setBlock(i + 15, j + 6, k + 6, PlaceDeepslate, 0, 2);
		world.setBlock(i + 16, j + 6, k + 6, PlaceDeepslate, 0, 2);
		world.setBlock(i + 17, j + 6, k + 6, PlaceDeepslate, 0, 2);
		world.setBlock(i + 18, j + 6, k + 6, PlaceDeepslate, 0, 2);
		world.setBlock(i + 11, j + 6, k + 7, PlaceDeepslate, 0, 2);
		world.setBlock(i + 12, j + 6, k + 7, PlaceDeepslate, 0, 2);
		world.setBlock(i + 13, j + 6, k + 7, PlaceDeepslate, 0, 2);
		world.setBlock(i + 14, j + 6, k + 7, PlaceDeepslate, 0, 2);
		world.setBlock(i + 15, j + 6, k + 7, PlaceDeepslate, 0, 2);
		world.setBlock(i + 16, j + 6, k + 7, PlaceDeepslate, 0, 2);
		world.setBlock(i + 17, j + 6, k + 7, PlaceDeepslate, 0, 2);
		world.setBlock(i + 18, j + 6, k + 7, PlaceDeepslate, 0, 2);
		world.setBlock(i + 11, j + 6, k + 8, PlaceDeepslate, 0, 2);
		world.setBlock(i + 12, j + 6, k + 8, PlaceDeepslate, 0, 2);
		world.setBlock(i + 13, j + 6, k + 8, PlaceDeepslate, 0, 2);
		world.setBlock(i + 14, j + 6, k + 8, PlaceDeepslate, 0, 2);
		world.setBlock(i + 15, j + 6, k + 8, PlaceDeepslate, 0, 2);
		world.setBlock(i + 16, j + 6, k + 8, PlaceDeepslate, 0, 2);
		world.setBlock(i + 17, j + 6, k + 8, PlaceDeepslate, 0, 2);
		world.setBlock(i + 18, j + 6, k + 8, PlaceDeepslate, 0, 2);
		world.setBlock(i + 19, j + 6, k + 8, PlaceDeepslate, 0, 2);
		world.setBlock(i + 11, j + 6, k + 9, PlaceDeepslate, 0, 2);
		world.setBlock(i + 12, j + 6, k + 9, PlaceDeepslate, 0, 2);
		world.setBlock(i + 13, j + 6, k + 9, PlaceDeepslate, 0, 2);
		world.setBlock(i + 14, j + 6, k + 9, PlaceDeepslate, 0, 2);
		world.setBlock(i + 15, j + 6, k + 9, PlaceDeepslate, 0, 2);
		world.setBlock(i + 16, j + 6, k + 9, PlaceDeepslate, 0, 2);
		world.setBlock(i + 17, j + 6, k + 9, PlaceDeepslate, 0, 2);
		world.setBlock(i + 18, j + 6, k + 9, PlaceDeepslate, 0, 2);
		world.setBlock(i + 19, j + 6, k + 9, PlaceDeepslate, 0, 2);
		world.setBlock(i + 20, j + 6, k + 9, PlaceDeepslate, 0, 2);
		world.setBlock(i + 11, j + 6, k + 10, PlaceDeepslate, 0, 2);
		world.setBlock(i + 12, j + 6, k + 10, PlaceDeepslate, 0, 2);
		world.setBlock(i + 13, j + 6, k + 10, PlaceDeepslate, 0, 2);
		world.setBlock(i + 14, j + 6, k + 10, PlaceDeepslate, 0, 2);
		world.setBlock(i + 15, j + 6, k + 10, PlaceDeepslate, 0, 2);
		world.setBlock(i + 16, j + 6, k + 10, PlaceDeepslate, 0, 2);
		world.setBlock(i + 17, j + 6, k + 10, PlaceDeepslate, 0, 2);
		world.setBlock(i + 18, j + 6, k + 10, PlaceDeepslate, 0, 2);
		world.setBlock(i + 19, j + 6, k + 10, PlaceDeepslate, 0, 2);
		world.setBlock(i + 20, j + 6, k + 10, PlaceDeepslate, 0, 2);
		world.setBlock(i + 11, j + 6, k + 11, PlaceDeepslate, 0, 2);
		world.setBlock(i + 12, j + 6, k + 11, PlaceDeepslate, 0, 2);
		world.setBlock(i + 13, j + 6, k + 11, PlaceDeepslate, 0, 2);
		world.setBlock(i + 14, j + 6, k + 11, PlaceDeepslate, 0, 2);
		world.setBlock(i + 15, j + 6, k + 11, PlaceDeepslate, 0, 2);
		world.setBlock(i + 16, j + 6, k + 11, PlaceDeepslate, 0, 2);
		world.setBlock(i + 17, j + 6, k + 11, PlaceDeepslate, 0, 2);
		world.setBlock(i + 18, j + 6, k + 11, PlaceDeepslate, 0, 2);
		world.setBlock(i + 19, j + 6, k + 11, PlaceDeepslate, 0, 2);
		world.setBlock(i + 20, j + 6, k + 11, PlaceDeepslate, 0, 2);
		world.setBlock(i + 21, j + 6, k + 11, PlaceDeepslate, 0, 2);
		world.setBlock(i + 11, j + 6, k + 12, PlaceDeepslate, 0, 2);
		world.setBlock(i + 12, j + 6, k + 12, PlaceDeepslate, 0, 2);
		world.setBlock(i + 13, j + 6, k + 12, PlaceDeepslate, 0, 2);
		world.setBlock(i + 14, j + 6, k + 12, PlaceDeepslate, 0, 2);
		world.setBlock(i + 15, j + 6, k + 12, PlaceDeepslate, 0, 2);
		world.setBlock(i + 16, j + 6, k + 12, PlaceDeepslate, 0, 2);
		world.setBlock(i + 17, j + 6, k + 12, PlaceDeepslate, 0, 2);
		world.setBlock(i + 18, j + 6, k + 12, PlaceDeepslate, 0, 2);
		world.setBlock(i + 19, j + 6, k + 12, PlaceDeepslate, 0, 2);
		world.setBlock(i + 20, j + 6, k + 12, PlaceDeepslate, 0, 2);
		world.setBlock(i + 21, j + 6, k + 12, PlaceDeepslate, 0, 2);
		world.setBlock(i + 11, j + 6, k + 13, PlaceDeepslate, 0, 2);
		world.setBlock(i + 12, j + 6, k + 13, PlaceDeepslate, 0, 2);
		world.setBlock(i + 13, j + 6, k + 13, PlaceDeepslate, 0, 2);
		world.setBlock(i + 14, j + 6, k + 13, PlaceDeepslate, 0, 2);
		world.setBlock(i + 15, j + 6, k + 13, PlaceDeepslate, 0, 2);
		world.setBlock(i + 16, j + 6, k + 13, PlaceDeepslate, 0, 2);
		world.setBlock(i + 17, j + 6, k + 13, PlaceDeepslate, 0, 2);
		world.setBlock(i + 18, j + 6, k + 13, PlaceDeepslate, 0, 2);
		world.setBlock(i + 19, j + 6, k + 13, PlaceDeepslate, 0, 2);
		world.setBlock(i + 20, j + 6, k + 13, PlaceDeepslate, 0, 2);
		world.setBlock(i + 21, j + 6, k + 13, PlaceDeepslate, 0, 2);
		world.setBlock(i + 11, j + 6, k + 14, PlaceDeepslate, 0, 2);
		world.setBlock(i + 12, j + 6, k + 14, PlaceDeepslate, 0, 2);
		world.setBlock(i + 13, j + 6, k + 14, PlaceDeepslate, 0, 2);
		world.setBlock(i + 14, j + 6, k + 14, PlaceDeepslate, 0, 2);
		world.setBlock(i + 15, j + 6, k + 14, PlaceDeepslate, 0, 2);
		world.setBlock(i + 16, j + 6, k + 14, PlaceDeepslate, 0, 2);
		world.setBlock(i + 17, j + 6, k + 14, PlaceDeepslate, 0, 2);
		world.setBlock(i + 18, j + 6, k + 14, PlaceDeepslate, 0, 2);
		world.setBlock(i + 19, j + 6, k + 14, PlaceDeepslate, 0, 2);
		world.setBlock(i + 20, j + 6, k + 14, PlaceDeepslate, 0, 2);
		world.setBlock(i + 21, j + 6, k + 14, PlaceDeepslate, 0, 2);
		world.setBlock(i + 11, j + 6, k + 15, PlaceDeepslate, 0, 2);
		world.setBlock(i + 12, j + 6, k + 15, PlaceDeepslate, 0, 2);
		world.setBlock(i + 13, j + 6, k + 15, PlaceDeepslate, 0, 2);
		world.setBlock(i + 14, j + 6, k + 15, PlaceDeepslate, 0, 2);
		world.setBlock(i + 15, j + 6, k + 15, PlaceDeepslate, 0, 2);
		world.setBlock(i + 16, j + 6, k + 15, PlaceDeepslate, 0, 2);
		world.setBlock(i + 17, j + 6, k + 15, PlaceDeepslate, 0, 2);
		world.setBlock(i + 18, j + 6, k + 15, PlaceDeepslate, 0, 2);
		world.setBlock(i + 19, j + 6, k + 15, PlaceDeepslate, 0, 2);
		world.setBlock(i + 20, j + 6, k + 15, PlaceDeepslate, 0, 2);
		world.setBlock(i + 21, j + 6, k + 15, PlaceDeepslate, 0, 2);
		world.setBlock(i + 12, j + 6, k + 16, PlaceDeepslate, 0, 2);
		world.setBlock(i + 13, j + 6, k + 16, PlaceDeepslate, 0, 2);
		world.setBlock(i + 14, j + 6, k + 16, PlaceDeepslate, 0, 2);
		world.setBlock(i + 15, j + 6, k + 16, PlaceDeepslate, 0, 2);
		world.setBlock(i + 16, j + 6, k + 16, PlaceDeepslate, 0, 2);
		world.setBlock(i + 17, j + 6, k + 16, PlaceDeepslate, 0, 2);
		world.setBlock(i + 18, j + 6, k + 16, PlaceDeepslate, 0, 2);
		world.setBlock(i + 19, j + 6, k + 16, PlaceDeepslate, 0, 2);
		world.setBlock(i + 20, j + 6, k + 16, PlaceDeepslate, 0, 2);
		world.setBlock(i + 12, j + 7, k + 4, PlaceDeepslate, 0, 2);
		world.setBlock(i + 13, j + 7, k + 4, PlaceDeepslate, 0, 2);
		world.setBlock(i + 14, j + 7, k + 4, PlaceDeepslate, 0, 2);
		world.setBlock(i + 15, j + 7, k + 4, PlaceDeepslate, 0, 2);
		world.setBlock(i + 16, j + 7, k + 4, PlaceDeepslate, 0, 2);
		world.setBlock(i + 11, j + 7, k + 5, PlaceDeepslate, 0, 2);
		world.setBlock(i + 12, j + 7, k + 5, PlaceDeepslate, 0, 2);
		world.setBlock(i + 13, j + 7, k + 5, PlaceDeepslate, 0, 2);
		world.setBlock(i + 14, j + 7, k + 5, PlaceDeepslate, 0, 2);
		world.setBlock(i + 15, j + 7, k + 5, PlaceDeepslate, 0, 2);
		world.setBlock(i + 16, j + 7, k + 5, PlaceDeepslate, 0, 2);
		world.setBlock(i + 17, j + 7, k + 5, PlaceDeepslate, 0, 2);
		world.setBlock(i + 11, j + 7, k + 6, PlaceDeepslate, 0, 2);
		world.setBlock(i + 12, j + 7, k + 6, PlaceDeepslate, 0, 2);
		world.setBlock(i + 13, j + 7, k + 6, PlaceDeepslate, 0, 2);
		world.setBlock(i + 14, j + 7, k + 6, PlaceDeepslate, 0, 2);
		world.setBlock(i + 15, j + 7, k + 6, PlaceDeepslate, 0, 2);
		world.setBlock(i + 16, j + 7, k + 6, PlaceDeepslate, 0, 2);
		world.setBlock(i + 17, j + 7, k + 6, PlaceDeepslate, 0, 2);
		world.setBlock(i + 18, j + 7, k + 6, PlaceDeepslate, 0, 2);
		world.setBlock(i + 11, j + 7, k + 7, PlaceDeepslate, 0, 2);
		world.setBlock(i + 12, j + 7, k + 7, PlaceDeepslate, 0, 2);
		world.setBlock(i + 13, j + 7, k + 7, PlaceDeepslate, 0, 2);
		world.setBlock(i + 14, j + 7, k + 7, PlaceDeepslate, 0, 2);
		world.setBlock(i + 15, j + 7, k + 7, PlaceDeepslate, 0, 2);
		world.setBlock(i + 16, j + 7, k + 7, PlaceDeepslate, 0, 2);
		world.setBlock(i + 17, j + 7, k + 7, PlaceDeepslate, 0, 2);
		world.setBlock(i + 18, j + 7, k + 7, PlaceDeepslate, 0, 2);
		world.setBlock(i + 11, j + 7, k + 8, PlaceDeepslate, 0, 2);
		world.setBlock(i + 12, j + 7, k + 8, PlaceDeepslate, 0, 2);
		world.setBlock(i + 13, j + 7, k + 8, PlaceDeepslate, 0, 2);
		world.setBlock(i + 14, j + 7, k + 8, PlaceDeepslate, 0, 2);
		world.setBlock(i + 15, j + 7, k + 8, PlaceDeepslate, 0, 2);
		world.setBlock(i + 16, j + 7, k + 8, PlaceDeepslate, 0, 2);
		world.setBlock(i + 17, j + 7, k + 8, PlaceDeepslate, 0, 2);
		world.setBlock(i + 18, j + 7, k + 8, PlaceDeepslate, 0, 2);
		world.setBlock(i + 19, j + 7, k + 8, PlaceDeepslate, 0, 2);
		world.setBlock(i + 11, j + 7, k + 9, PlaceDeepslate, 0, 2);
		world.setBlock(i + 12, j + 7, k + 9, PlaceDeepslate, 0, 2);
		world.setBlock(i + 13, j + 7, k + 9, PlaceDeepslate, 0, 2);
		world.setBlock(i + 14, j + 7, k + 9, PlaceDeepslate, 0, 2);
		world.setBlock(i + 15, j + 7, k + 9, PlaceDeepslate, 0, 2);
		world.setBlock(i + 16, j + 7, k + 9, PlaceDeepslate, 0, 2);
		world.setBlock(i + 17, j + 7, k + 9, PlaceDeepslate, 0, 2);
		world.setBlock(i + 18, j + 7, k + 9, PlaceDeepslate, 0, 2);
		world.setBlock(i + 19, j + 7, k + 9, PlaceDeepslate, 0, 2);
		world.setBlock(i + 20, j + 7, k + 9, PlaceDeepslate, 0, 2);
		world.setBlock(i + 11, j + 7, k + 10, PlaceDeepslate, 0, 2);
		world.setBlock(i + 12, j + 7, k + 10, PlaceDeepslate, 0, 2);
		world.setBlock(i + 13, j + 7, k + 10, PlaceDeepslate, 0, 2);
		world.setBlock(i + 14, j + 7, k + 10, PlaceDeepslate, 0, 2);
		world.setBlock(i + 15, j + 7, k + 10, PlaceDeepslate, 0, 2);
		world.setBlock(i + 16, j + 7, k + 10, PlaceDeepslate, 0, 2);
		world.setBlock(i + 17, j + 7, k + 10, PlaceDeepslate, 0, 2);
		world.setBlock(i + 18, j + 7, k + 10, PlaceDeepslate, 0, 2);
		world.setBlock(i + 19, j + 7, k + 10, PlaceDeepslate, 0, 2);
		world.setBlock(i + 20, j + 7, k + 10, PlaceDeepslate, 0, 2);
		world.setBlock(i + 11, j + 7, k + 11, PlaceDeepslate, 0, 2);
		world.setBlock(i + 12, j + 7, k + 11, PlaceDeepslate, 0, 2);
		world.setBlock(i + 13, j + 7, k + 11, PlaceDeepslate, 0, 2);
		world.setBlock(i + 14, j + 7, k + 11, PlaceDeepslate, 0, 2);
		world.setBlock(i + 15, j + 7, k + 11, PlaceDeepslate, 0, 2);
		world.setBlock(i + 16, j + 7, k + 11, PlaceDeepslate, 0, 2);
		world.setBlock(i + 17, j + 7, k + 11, PlaceDeepslate, 0, 2);
		world.setBlock(i + 18, j + 7, k + 11, PlaceDeepslate, 0, 2);
		world.setBlock(i + 19, j + 7, k + 11, PlaceDeepslate, 0, 2);
		world.setBlock(i + 20, j + 7, k + 11, PlaceDeepslate, 0, 2);
		world.setBlock(i + 21, j + 7, k + 11, PlaceDeepslate, 0, 2);
		world.setBlock(i + 11, j + 7, k + 12, PlaceDeepslate, 0, 2);
		world.setBlock(i + 12, j + 7, k + 12, PlaceDeepslate, 0, 2);
		world.setBlock(i + 13, j + 7, k + 12, PlaceDeepslate, 0, 2);
		world.setBlock(i + 14, j + 7, k + 12, PlaceDeepslate, 0, 2);
		world.setBlock(i + 15, j + 7, k + 12, PlaceDeepslate, 0, 2);
		world.setBlock(i + 16, j + 7, k + 12, PlaceDeepslate, 0, 2);
		world.setBlock(i + 17, j + 7, k + 12, PlaceDeepslate, 0, 2);
		world.setBlock(i + 18, j + 7, k + 12, PlaceDeepslate, 0, 2);
		world.setBlock(i + 19, j + 7, k + 12, PlaceDeepslate, 0, 2);
		world.setBlock(i + 20, j + 7, k + 12, PlaceDeepslate, 0, 2);
		world.setBlock(i + 21, j + 7, k + 12, PlaceDeepslate, 0, 2);
		world.setBlock(i + 11, j + 7, k + 13, PlaceDeepslate, 0, 2);
		world.setBlock(i + 12, j + 7, k + 13, PlaceDeepslate, 0, 2);
		world.setBlock(i + 13, j + 7, k + 13, PlaceDeepslate, 0, 2);
		world.setBlock(i + 14, j + 7, k + 13, PlaceDeepslate, 0, 2);
		world.setBlock(i + 15, j + 7, k + 13, PlaceDeepslate, 0, 2);
		world.setBlock(i + 16, j + 7, k + 13, PlaceDeepslate, 0, 2);
		world.setBlock(i + 17, j + 7, k + 13, PlaceDeepslate, 0, 2);
		world.setBlock(i + 18, j + 7, k + 13, PlaceDeepslate, 0, 2);
		world.setBlock(i + 19, j + 7, k + 13, PlaceDeepslate, 0, 2);
		world.setBlock(i + 20, j + 7, k + 13, PlaceDeepslate, 0, 2);
		world.setBlock(i + 21, j + 7, k + 13, PlaceDeepslate, 0, 2);
		world.setBlock(i + 11, j + 7, k + 14, PlaceDeepslate, 0, 2);
		world.setBlock(i + 12, j + 7, k + 14, PlaceDeepslate, 0, 2);
		world.setBlock(i + 13, j + 7, k + 14, PlaceDeepslate, 0, 2);
		world.setBlock(i + 14, j + 7, k + 14, PlaceDeepslate, 0, 2);
		world.setBlock(i + 15, j + 7, k + 14, PlaceDeepslate, 0, 2);
		world.setBlock(i + 16, j + 7, k + 14, PlaceDeepslate, 0, 2);
		world.setBlock(i + 17, j + 7, k + 14, PlaceDeepslate, 0, 2);
		world.setBlock(i + 18, j + 7, k + 14, PlaceDeepslate, 0, 2);
		world.setBlock(i + 19, j + 7, k + 14, PlaceDeepslate, 0, 2);
		world.setBlock(i + 20, j + 7, k + 14, PlaceDeepslate, 0, 2);
		world.setBlock(i + 21, j + 7, k + 14, PlaceDeepslate, 0, 2);
		world.setBlock(i + 11, j + 7, k + 15, PlaceDeepslate, 0, 2);
		world.setBlock(i + 12, j + 7, k + 15, PlaceDeepslate, 0, 2);
		world.setBlock(i + 13, j + 7, k + 15, PlaceDeepslate, 0, 2);
		world.setBlock(i + 14, j + 7, k + 15, PlaceDeepslate, 0, 2);
		world.setBlock(i + 15, j + 7, k + 15, PlaceDeepslate, 0, 2);
		world.setBlock(i + 16, j + 7, k + 15, PlaceDeepslate, 0, 2);
		world.setBlock(i + 17, j + 7, k + 15, PlaceDeepslate, 0, 2);
		world.setBlock(i + 18, j + 7, k + 15, PlaceDeepslate, 0, 2);
		world.setBlock(i + 19, j + 7, k + 15, PlaceDeepslate, 0, 2);
		world.setBlock(i + 20, j + 7, k + 15, PlaceDeepslate, 0, 2);
		world.setBlock(i + 21, j + 7, k + 15, PlaceDeepslate, 0, 2);
		world.setBlock(i + 12, j + 7, k + 16, PlaceDeepslate, 0, 2);
		world.setBlock(i + 13, j + 7, k + 16, PlaceDeepslate, 0, 2);
		world.setBlock(i + 14, j + 7, k + 16, PlaceDeepslate, 0, 2);
		world.setBlock(i + 15, j + 7, k + 16, PlaceDeepslate, 0, 2);
		world.setBlock(i + 16, j + 7, k + 16, PlaceDeepslate, 0, 2);
		world.setBlock(i + 17, j + 7, k + 16, PlaceDeepslate, 0, 2);
		world.setBlock(i + 18, j + 7, k + 16, PlaceDeepslate, 0, 2);
		world.setBlock(i + 19, j + 7, k + 16, PlaceDeepslate, 0, 2);
		world.setBlock(i + 20, j + 7, k + 16, PlaceDeepslate, 0, 2);
		world.setBlock(i + 12, j + 8, k + 4, PlaceDeepslate, 0, 2);
		world.setBlock(i + 13, j + 8, k + 4, PlaceDeepslate, 0, 2);
		world.setBlock(i + 14, j + 8, k + 4, PlaceDeepslate, 0, 2);
		world.setBlock(i + 15, j + 8, k + 4, PlaceDeepslate, 0, 2);
		world.setBlock(i + 16, j + 8, k + 4, PlaceDeepslate, 0, 2);
		world.setBlock(i + 11, j + 8, k + 5, PlaceDeepslate, 0, 2);
		world.setBlock(i + 12, j + 8, k + 5, PlaceDeepslate, 0, 2);
		world.setBlock(i + 13, j + 8, k + 5, PlaceDeepslate, 0, 2);
		world.setBlock(i + 14, j + 8, k + 5, PlaceDeepslate, 0, 2);
		world.setBlock(i + 15, j + 8, k + 5, PlaceDeepslate, 0, 2);
		world.setBlock(i + 16, j + 8, k + 5, PlaceDeepslate, 0, 2);
		world.setBlock(i + 17, j + 8, k + 5, PlaceDeepslate, 0, 2);
		world.setBlock(i + 11, j + 8, k + 6, PlaceDeepslate, 0, 2);
		world.setBlock(i + 12, j + 8, k + 6, PlaceDeepslate, 0, 2);
		world.setBlock(i + 13, j + 8, k + 6, PlaceDeepslate, 0, 2);
		world.setBlock(i + 14, j + 8, k + 6, PlaceDeepslate, 0, 2);
		world.setBlock(i + 15, j + 8, k + 6, PlaceDeepslate, 0, 2);
		world.setBlock(i + 16, j + 8, k + 6, PlaceDeepslate, 0, 2);
		world.setBlock(i + 17, j + 8, k + 6, PlaceDeepslate, 0, 2);
		world.setBlock(i + 18, j + 8, k + 6, PlaceDeepslate, 0, 2);
		world.setBlock(i + 11, j + 8, k + 7, PlaceDeepslate, 0, 2);
		world.setBlock(i + 12, j + 8, k + 7, PlaceDeepslate, 0, 2);
		world.setBlock(i + 13, j + 8, k + 7, PlaceDeepslate, 0, 2);
		world.setBlock(i + 14, j + 8, k + 7, PlaceDeepslate, 0, 2);
		world.setBlock(i + 15, j + 8, k + 7, PlaceDeepslate, 0, 2);
		world.setBlock(i + 16, j + 8, k + 7, PlaceDeepslate, 0, 2);
		world.setBlock(i + 17, j + 8, k + 7, PlaceDeepslate, 0, 2);
		world.setBlock(i + 18, j + 8, k + 7, PlaceDeepslate, 0, 2);
		world.setBlock(i + 11, j + 8, k + 8, PlaceDeepslate, 0, 2);
		world.setBlock(i + 12, j + 8, k + 8, PlaceDeepslate, 0, 2);
		world.setBlock(i + 13, j + 8, k + 8, PlaceDeepslate, 0, 2);
		world.setBlock(i + 14, j + 8, k + 8, PlaceDeepslate, 0, 2);
		world.setBlock(i + 15, j + 8, k + 8, PlaceDeepslate, 0, 2);
		world.setBlock(i + 16, j + 8, k + 8, PlaceDeepslate, 0, 2);
		world.setBlock(i + 17, j + 8, k + 8, PlaceDeepslate, 0, 2);
		world.setBlock(i + 18, j + 8, k + 8, PlaceDeepslate, 0, 2);
		world.setBlock(i + 19, j + 8, k + 8, PlaceDeepslate, 0, 2);
		world.setBlock(i + 11, j + 8, k + 9, PlaceDeepslate, 0, 2);
		world.setBlock(i + 12, j + 8, k + 9, PlaceDeepslate, 0, 2);
		world.setBlock(i + 13, j + 8, k + 9, PlaceDeepslate, 0, 2);
		world.setBlock(i + 14, j + 8, k + 9, PlaceDeepslate, 0, 2);
		world.setBlock(i + 15, j + 8, k + 9, PlaceDeepslate, 0, 2);
		world.setBlock(i + 16, j + 8, k + 9, PlaceDeepslate, 0, 2);
		world.setBlock(i + 17, j + 8, k + 9, PlaceDeepslate, 0, 2);
		world.setBlock(i + 18, j + 8, k + 9, PlaceDeepslate, 0, 2);
		world.setBlock(i + 19, j + 8, k + 9, PlaceDeepslate, 0, 2);
		world.setBlock(i + 20, j + 8, k + 9, PlaceDeepslate, 0, 2);
		world.setBlock(i + 11, j + 8, k + 10, PlaceDeepslate, 0, 2);
		world.setBlock(i + 12, j + 8, k + 10, PlaceDeepslate, 0, 2);
		world.setBlock(i + 13, j + 8, k + 10, PlaceDeepslate, 0, 2);
		world.setBlock(i + 14, j + 8, k + 10, PlaceDeepslate, 0, 2);
		world.setBlock(i + 15, j + 8, k + 10, PlaceDeepslate, 0, 2);
		world.setBlock(i + 16, j + 8, k + 10, PlaceDeepslate, 0, 2);
		world.setBlock(i + 17, j + 8, k + 10, PlaceDeepslate, 0, 2);
		world.setBlock(i + 18, j + 8, k + 10, PlaceDeepslate, 0, 2);
		world.setBlock(i + 19, j + 8, k + 10, PlaceDeepslate, 0, 2);
		world.setBlock(i + 20, j + 8, k + 10, PlaceDeepslate, 0, 2);
		world.setBlock(i + 11, j + 8, k + 11, PlaceDeepslate, 0, 2);
		world.setBlock(i + 12, j + 8, k + 11, PlaceDeepslate, 0, 2);
		world.setBlock(i + 13, j + 8, k + 11, PlaceDeepslate, 0, 2);
		world.setBlock(i + 14, j + 8, k + 11, PlaceDeepslate, 0, 2);
		world.setBlock(i + 15, j + 8, k + 11, PlaceDeepslate, 0, 2);
		world.setBlock(i + 16, j + 8, k + 11, PlaceDeepslate, 0, 2);
		world.setBlock(i + 17, j + 8, k + 11, PlaceDeepslate, 0, 2);
		world.setBlock(i + 18, j + 8, k + 11, PlaceDeepslate, 0, 2);
		world.setBlock(i + 19, j + 8, k + 11, PlaceDeepslate, 0, 2);
		world.setBlock(i + 20, j + 8, k + 11, PlaceDeepslate, 0, 2);
		world.setBlock(i + 21, j + 8, k + 11, PlaceDeepslate, 0, 2);
		world.setBlock(i + 11, j + 8, k + 12, PlaceDeepslate, 0, 2);
		world.setBlock(i + 12, j + 8, k + 12, PlaceDeepslate, 0, 2);
		world.setBlock(i + 13, j + 8, k + 12, PlaceDeepslate, 0, 2);
		world.setBlock(i + 14, j + 8, k + 12, PlaceDeepslate, 0, 2);
		world.setBlock(i + 15, j + 8, k + 12, PlaceDeepslate, 0, 2);
		world.setBlock(i + 16, j + 8, k + 12, PlaceDeepslate, 0, 2);
		world.setBlock(i + 17, j + 8, k + 12, PlaceDeepslate, 0, 2);
		world.setBlock(i + 18, j + 8, k + 12, PlaceDeepslate, 0, 2);
		world.setBlock(i + 19, j + 8, k + 12, PlaceDeepslate, 0, 2);
		world.setBlock(i + 20, j + 8, k + 12, PlaceDeepslate, 0, 2);
		world.setBlock(i + 21, j + 8, k + 12, PlaceDeepslate, 0, 2);
		world.setBlock(i + 11, j + 8, k + 13, PlaceDeepslate, 0, 2);
		world.setBlock(i + 12, j + 8, k + 13, PlaceDeepslate, 0, 2);
		world.setBlock(i + 13, j + 8, k + 13, PlaceDeepslate, 0, 2);
		world.setBlock(i + 14, j + 8, k + 13, PlaceDeepslate, 0, 2);
		world.setBlock(i + 15, j + 8, k + 13, PlaceDeepslate, 0, 2);
		world.setBlock(i + 16, j + 8, k + 13, PlaceDeepslate, 0, 2);
		world.setBlock(i + 17, j + 8, k + 13, PlaceDeepslate, 0, 2);
		world.setBlock(i + 18, j + 8, k + 13, PlaceDeepslate, 0, 2);
		world.setBlock(i + 19, j + 8, k + 13, PlaceDeepslate, 0, 2);
		world.setBlock(i + 20, j + 8, k + 13, PlaceDeepslate, 0, 2);
		world.setBlock(i + 21, j + 8, k + 13, PlaceDeepslate, 0, 2);
		world.setBlock(i + 11, j + 8, k + 14, PlaceDeepslate, 0, 2);
		world.setBlock(i + 12, j + 8, k + 14, PlaceDeepslate, 0, 2);
		world.setBlock(i + 13, j + 8, k + 14, PlaceDeepslate, 0, 2);
		world.setBlock(i + 14, j + 8, k + 14, PlaceDeepslate, 0, 2);
		world.setBlock(i + 15, j + 8, k + 14, PlaceDeepslate, 0, 2);
		world.setBlock(i + 16, j + 8, k + 14, PlaceDeepslate, 0, 2);
		world.setBlock(i + 17, j + 8, k + 14, PlaceDeepslate, 0, 2);
		world.setBlock(i + 18, j + 8, k + 14, PlaceDeepslate, 0, 2);
		world.setBlock(i + 19, j + 8, k + 14, PlaceDeepslate, 0, 2);
		world.setBlock(i + 20, j + 8, k + 14, PlaceDeepslate, 0, 2);
		world.setBlock(i + 21, j + 8, k + 14, PlaceDeepslate, 0, 2);
		world.setBlock(i + 11, j + 8, k + 15, PlaceDeepslate, 0, 2);
		world.setBlock(i + 12, j + 8, k + 15, PlaceDeepslate, 0, 2);
		world.setBlock(i + 13, j + 8, k + 15, PlaceDeepslate, 0, 2);
		world.setBlock(i + 14, j + 8, k + 15, PlaceDeepslate, 0, 2);
		world.setBlock(i + 15, j + 8, k + 15, PlaceDeepslate, 0, 2);
		world.setBlock(i + 16, j + 8, k + 15, PlaceDeepslate, 0, 2);
		world.setBlock(i + 17, j + 8, k + 15, PlaceDeepslate, 0, 2);
		world.setBlock(i + 18, j + 8, k + 15, PlaceDeepslate, 0, 2);
		world.setBlock(i + 19, j + 8, k + 15, PlaceDeepslate, 0, 2);
		world.setBlock(i + 20, j + 8, k + 15, PlaceDeepslate, 0, 2);
		world.setBlock(i + 21, j + 8, k + 15, PlaceDeepslate, 0, 2);
		world.setBlock(i + 12, j + 8, k + 16, PlaceDeepslate, 0, 2);
		world.setBlock(i + 13, j + 8, k + 16, PlaceDeepslate, 0, 2);
		world.setBlock(i + 14, j + 8, k + 16, PlaceDeepslate, 0, 2);
		world.setBlock(i + 15, j + 8, k + 16, PlaceDeepslate, 0, 2);
		world.setBlock(i + 16, j + 8, k + 16, PlaceDeepslate, 0, 2);
		world.setBlock(i + 17, j + 8, k + 16, PlaceDeepslate, 0, 2);
		world.setBlock(i + 18, j + 8, k + 16, PlaceDeepslate, 0, 2);
		world.setBlock(i + 19, j + 8, k + 16, PlaceDeepslate, 0, 2);
		world.setBlock(i + 20, j + 8, k + 16, PlaceDeepslate, 0, 2);
		world.setBlock(i + 12, j + 9, k + 4, sculk_block, 0, 2);
		world.setBlock(i + 13, j + 9, k + 4, sculk_block, 0, 2);
		world.setBlock(i + 14, j + 9, k + 4, PlaceDeepslate, 0, 2);
		world.setBlock(i + 15, j + 9, k + 4, PlaceDeepslate, 0, 2);
		world.setBlock(i + 16, j + 9, k + 4, PlaceDeepslate, 0, 2);
		world.setBlock(i + 11, j + 9, k + 5, sculk_block, 0, 2);
		world.setBlock(i + 12, j + 9, k + 5, PlaceDeepslate, 0, 2);
		world.setBlock(i + 13, j + 9, k + 5, PlaceDeepslate, 0, 2);
		world.setBlock(i + 14, j + 9, k + 5, PlaceDeepslate, 0, 2);
		world.setBlock(i + 15, j + 9, k + 5, PlaceDeepslate, 0, 2);
		world.setBlock(i + 16, j + 9, k + 5, PlaceDeepslate, 0, 2);
		world.setBlock(i + 17, j + 9, k + 5, PlaceDeepslate, 0, 2);
		world.setBlock(i + 11, j + 9, k + 6, PlaceDeepslate, 0, 2);
		world.setBlock(i + 12, j + 9, k + 6, PlaceDeepslate, 0, 2);
		world.setBlock(i + 13, j + 9, k + 6, PlaceDeepslate, 0, 2);
		world.setBlock(i + 14, j + 9, k + 6, PlaceDeepslate, 0, 2);
		world.setBlock(i + 15, j + 9, k + 6, PlaceDeepslate, 0, 2);
		world.setBlock(i + 16, j + 9, k + 6, PlaceDeepslate, 0, 2);
		world.setBlock(i + 17, j + 9, k + 6, PlaceDeepslate, 0, 2);
		world.setBlock(i + 18, j + 9, k + 6, PlaceDeepslate, 0, 2);
		world.setBlock(i + 11, j + 9, k + 7, PlaceDeepslate, 0, 2);
		world.setBlock(i + 12, j + 9, k + 7, PlaceDeepslate, 0, 2);
		world.setBlock(i + 13, j + 9, k + 7, PlaceDeepslate, 0, 2);
		world.setBlock(i + 14, j + 9, k + 7, PlaceDeepslate, 0, 2);
		world.setBlock(i + 15, j + 9, k + 7, PlaceDeepslate, 0, 2);
		world.setBlock(i + 16, j + 9, k + 7, PlaceDeepslate, 0, 2);
		world.setBlock(i + 17, j + 9, k + 7, PlaceDeepslate, 0, 2);
		world.setBlock(i + 18, j + 9, k + 7, PlaceDeepslate, 0, 2);
		world.setBlock(i + 11, j + 9, k + 8, PlaceDeepslate, 0, 2);
		world.setBlock(i + 12, j + 9, k + 8, PlaceDeepslate, 0, 2);
		world.setBlock(i + 13, j + 9, k + 8, PlaceDeepslate, 0, 2);
		world.setBlock(i + 14, j + 9, k + 8, PlaceDeepslate, 0, 2);
		world.setBlock(i + 15, j + 9, k + 8, PlaceDeepslate, 0, 2);
		world.setBlock(i + 16, j + 9, k + 8, PlaceDeepslate, 0, 2);
		world.setBlock(i + 17, j + 9, k + 8, PlaceDeepslate, 0, 2);
		world.setBlock(i + 18, j + 9, k + 8, PlaceDeepslate, 0, 2);
		world.setBlock(i + 19, j + 9, k + 8, PlaceDeepslate, 0, 2);
		world.setBlock(i + 11, j + 9, k + 9, PlaceDeepslate, 0, 2);
		world.setBlock(i + 12, j + 9, k + 9, PlaceDeepslate, 0, 2);
		world.setBlock(i + 13, j + 9, k + 9, PlaceDeepslate, 0, 2);
		world.setBlock(i + 14, j + 9, k + 9, PlaceDeepslate, 0, 2);
		world.setBlock(i + 15, j + 9, k + 9, PlaceDeepslate, 0, 2);
		world.setBlock(i + 16, j + 9, k + 9, PlaceDeepslate, 0, 2);
		world.setBlock(i + 17, j + 9, k + 9, PlaceDeepslate, 0, 2);
		world.setBlock(i + 18, j + 9, k + 9, PlaceDeepslate, 0, 2);
		world.setBlock(i + 19, j + 9, k + 9, PlaceDeepslate, 0, 2);
		world.setBlock(i + 20, j + 9, k + 9, PlaceDeepslate, 0, 2);
		world.setBlock(i + 11, j + 9, k + 10, PlaceDeepslate, 0, 2);
		world.setBlock(i + 12, j + 9, k + 10, PlaceDeepslate, 0, 2);
		world.setBlock(i + 13, j + 9, k + 10, PlaceDeepslate, 0, 2);
		world.setBlock(i + 14, j + 9, k + 10, PlaceDeepslate, 0, 2);
		world.setBlock(i + 15, j + 9, k + 10, PlaceDeepslate, 0, 2);
		world.setBlock(i + 16, j + 9, k + 10, PlaceDeepslate, 0, 2);
		world.setBlock(i + 17, j + 9, k + 10, PlaceDeepslate, 0, 2);
		world.setBlock(i + 18, j + 9, k + 10, PlaceDeepslate, 0, 2);
		world.setBlock(i + 19, j + 9, k + 10, PlaceDeepslate, 0, 2);
		world.setBlock(i + 20, j + 9, k + 10, PlaceDeepslate, 0, 2);
		world.setBlock(i + 11, j + 9, k + 11, PlaceDeepslate, 0, 2);
		world.setBlock(i + 12, j + 9, k + 11, PlaceDeepslate, 0, 2);
		world.setBlock(i + 13, j + 9, k + 11, PlaceDeepslate, 0, 2);
		world.setBlock(i + 14, j + 9, k + 11, PlaceDeepslate, 0, 2);
		world.setBlock(i + 15, j + 9, k + 11, PlaceDeepslate, 0, 2);
		world.setBlock(i + 16, j + 9, k + 11, PlaceDeepslate, 0, 2);
		world.setBlock(i + 17, j + 9, k + 11, PlaceDeepslate, 0, 2);
		world.setBlock(i + 18, j + 9, k + 11, PlaceDeepslate, 0, 2);
		world.setBlock(i + 19, j + 9, k + 11, PlaceDeepslate, 0, 2);
		world.setBlock(i + 20, j + 9, k + 11, PlaceDeepslate, 0, 2);
		world.setBlock(i + 21, j + 9, k + 11, PlaceDeepslate, 0, 2);
		world.setBlock(i + 11, j + 9, k + 12, PlaceDeepslate, 0, 2);
		world.setBlock(i + 12, j + 9, k + 12, PlaceDeepslate, 0, 2);
		world.setBlock(i + 13, j + 9, k + 12, PlaceDeepslate, 0, 2);
		world.setBlock(i + 14, j + 9, k + 12, PlaceDeepslate, 0, 2);
		world.setBlock(i + 15, j + 9, k + 12, PlaceDeepslate, 0, 2);
		world.setBlock(i + 16, j + 9, k + 12, PlaceDeepslate, 0, 2);
		world.setBlock(i + 17, j + 9, k + 12, PlaceDeepslate, 0, 2);
		world.setBlock(i + 18, j + 9, k + 12, PlaceDeepslate, 0, 2);
		world.setBlock(i + 19, j + 9, k + 12, PlaceDeepslate, 0, 2);
		world.setBlock(i + 20, j + 9, k + 12, PlaceDeepslate, 0, 2);
		world.setBlock(i + 21, j + 9, k + 12, PlaceDeepslate, 0, 2);
		world.setBlock(i + 11, j + 9, k + 13, PlaceDeepslate, 0, 2);
		world.setBlock(i + 12, j + 9, k + 13, PlaceDeepslate, 0, 2);
		world.setBlock(i + 13, j + 9, k + 13, PlaceDeepslate, 0, 2);
		world.setBlock(i + 14, j + 9, k + 13, PlaceDeepslate, 0, 2);
		world.setBlock(i + 15, j + 9, k + 13, PlaceDeepslate, 0, 2);
		world.setBlock(i + 16, j + 9, k + 13, PlaceDeepslate, 0, 2);
		world.setBlock(i + 17, j + 9, k + 13, PlaceDeepslate, 0, 2);
		world.setBlock(i + 18, j + 9, k + 13, PlaceDeepslate, 0, 2);
		world.setBlock(i + 19, j + 9, k + 13, PlaceDeepslate, 0, 2);
		world.setBlock(i + 20, j + 9, k + 13, PlaceDeepslate, 0, 2);
		world.setBlock(i + 21, j + 9, k + 13, PlaceDeepslate, 0, 2);
		world.setBlock(i + 11, j + 9, k + 14, PlaceDeepslate, 0, 2);
		world.setBlock(i + 12, j + 9, k + 14, PlaceDeepslate, 0, 2);
		world.setBlock(i + 13, j + 9, k + 14, PlaceDeepslate, 0, 2);
		world.setBlock(i + 14, j + 9, k + 14, PlaceDeepslate, 0, 2);
		world.setBlock(i + 15, j + 9, k + 14, PlaceDeepslate, 0, 2);
		world.setBlock(i + 16, j + 9, k + 14, PlaceDeepslate, 0, 2);
		world.setBlock(i + 17, j + 9, k + 14, PlaceDeepslate, 0, 2);
		world.setBlock(i + 18, j + 9, k + 14, PlaceDeepslate, 0, 2);
		world.setBlock(i + 19, j + 9, k + 14, PlaceDeepslate, 0, 2);
		world.setBlock(i + 20, j + 9, k + 14, PlaceDeepslate, 0, 2);
		world.setBlock(i + 21, j + 9, k + 14, PlaceDeepslate, 0, 2);
		world.setBlock(i + 11, j + 9, k + 15, PlaceDeepslate, 0, 2);
		world.setBlock(i + 12, j + 9, k + 15, PlaceDeepslate, 0, 2);
		world.setBlock(i + 13, j + 9, k + 15, PlaceDeepslate, 0, 2);
		world.setBlock(i + 14, j + 9, k + 15, PlaceDeepslate, 0, 2);
		world.setBlock(i + 15, j + 9, k + 15, PlaceDeepslate, 0, 2);
		world.setBlock(i + 16, j + 9, k + 15, PlaceDeepslate, 0, 2);
		world.setBlock(i + 17, j + 9, k + 15, PlaceDeepslate, 0, 2);
		world.setBlock(i + 18, j + 9, k + 15, PlaceDeepslate, 0, 2);
		world.setBlock(i + 19, j + 9, k + 15, PlaceDeepslate, 0, 2);
		world.setBlock(i + 20, j + 9, k + 15, PlaceDeepslate, 0, 2);
		world.setBlock(i + 21, j + 9, k + 15, PlaceDeepslate, 0, 2);
		world.setBlock(i + 12, j + 9, k + 16, PlaceDeepslate, 0, 2);
		world.setBlock(i + 13, j + 9, k + 16, PlaceDeepslate, 0, 2);
		world.setBlock(i + 14, j + 9, k + 16, PlaceDeepslate, 0, 2);
		world.setBlock(i + 15, j + 9, k + 16, PlaceDeepslate, 0, 2);
		world.setBlock(i + 16, j + 9, k + 16, PlaceDeepslate, 0, 2);
		world.setBlock(i + 17, j + 9, k + 16, PlaceDeepslate, 0, 2);
		world.setBlock(i + 18, j + 9, k + 16, PlaceDeepslate, 0, 2);
		world.setBlock(i + 19, j + 9, k + 16, PlaceDeepslate, 0, 2);
		world.setBlock(i + 20, j + 9, k + 16, PlaceDeepslate, 0, 2);
		world.setBlock(i + 12, j + 10, k + 4, sculk_block, 0, 2);
		world.setBlock(i + 13, j + 10, k + 4, sculk_block, 0, 2);
		world.setBlock(i + 14, j + 10, k + 4, sculk_block, 0, 2);
		world.setBlock(i + 15, j + 10, k + 4, PlaceDeepslate, 0, 2);
		world.setBlock(i + 16, j + 10, k + 4, PlaceDeepslate, 0, 2);
		world.setBlock(i + 11, j + 10, k + 5, sculk_block, 0, 2);
		world.setBlock(i + 12, j + 10, k + 5, PlaceDeepslate, 0, 2);
		world.setBlock(i + 13, j + 10, k + 5, PlaceDeepslate, 0, 2);
		world.setBlock(i + 14, j + 10, k + 5, PlaceDeepslate, 0, 2);
		world.setBlock(i + 15, j + 10, k + 5, PlaceDeepslate, 0, 2);
		world.setBlock(i + 16, j + 10, k + 5, PlaceDeepslate, 0, 2);
		world.setBlock(i + 17, j + 10, k + 5, PlaceDeepslate, 0, 2);
		world.setBlock(i + 11, j + 10, k + 6, sculk_block, 0, 2);
		world.setBlock(i + 12, j + 10, k + 6, PlaceDeepslate, 0, 2);
		world.setBlock(i + 13, j + 10, k + 6, PlaceDeepslate, 0, 2);
		world.setBlock(i + 14, j + 10, k + 6, PlaceDeepslate, 0, 2);
		world.setBlock(i + 15, j + 10, k + 6, PlaceDeepslate, 0, 2);
		world.setBlock(i + 16, j + 10, k + 6, PlaceDeepslate, 0, 2);
		world.setBlock(i + 17, j + 10, k + 6, PlaceDeepslate, 0, 2);
		world.setBlock(i + 18, j + 10, k + 6, PlaceDeepslate, 0, 2);
		world.setBlock(i + 11, j + 10, k + 7, PlaceDeepslate, 0, 2);
		world.setBlock(i + 12, j + 10, k + 7, PlaceDeepslate, 0, 2);
		world.setBlock(i + 13, j + 10, k + 7, PlaceDeepslate, 0, 2);
		world.setBlock(i + 14, j + 10, k + 7, PlaceDeepslate, 0, 2);
		world.setBlock(i + 15, j + 10, k + 7, PlaceDeepslate, 0, 2);
		world.setBlock(i + 16, j + 10, k + 7, PlaceDeepslate, 0, 2);
		world.setBlock(i + 17, j + 10, k + 7, PlaceDeepslate, 0, 2);
		world.setBlock(i + 18, j + 10, k + 7, PlaceDeepslate, 0, 2);
		world.setBlock(i + 11, j + 10, k + 8, PlaceDeepslate, 0, 2);
		world.setBlock(i + 12, j + 10, k + 8, PlaceDeepslate, 0, 2);
		world.setBlock(i + 13, j + 10, k + 8, PlaceDeepslate, 0, 2);
		world.setBlock(i + 14, j + 10, k + 8, PlaceDeepslate, 0, 2);
		world.setBlock(i + 15, j + 10, k + 8, PlaceDeepslate, 0, 2);
		world.setBlock(i + 16, j + 10, k + 8, PlaceDeepslate, 0, 2);
		world.setBlock(i + 17, j + 10, k + 8, PlaceDeepslate, 0, 2);
		world.setBlock(i + 18, j + 10, k + 8, PlaceDeepslate, 0, 2);
		world.setBlock(i + 19, j + 10, k + 8, PlaceDeepslate, 0, 2);
		world.setBlock(i + 11, j + 10, k + 9, PlaceDeepslate, 0, 2);
		world.setBlock(i + 12, j + 10, k + 9, PlaceDeepslate, 0, 2);
		world.setBlock(i + 13, j + 10, k + 9, PlaceDeepslate, 0, 2);
		world.setBlock(i + 14, j + 10, k + 9, PlaceDeepslate, 0, 2);
		world.setBlock(i + 15, j + 10, k + 9, PlaceDeepslate, 0, 2);
		world.setBlock(i + 16, j + 10, k + 9, PlaceDeepslate, 0, 2);
		world.setBlock(i + 17, j + 10, k + 9, PlaceDeepslate, 0, 2);
		world.setBlock(i + 18, j + 10, k + 9, PlaceDeepslate, 0, 2);
		world.setBlock(i + 19, j + 10, k + 9, PlaceDeepslate, 0, 2);
		world.setBlock(i + 20, j + 10, k + 9, PlaceDeepslate, 0, 2);
		world.setBlock(i + 11, j + 10, k + 10, PlaceDeepslate, 0, 2);
		world.setBlock(i + 12, j + 10, k + 10, PlaceDeepslate, 0, 2);
		world.setBlock(i + 13, j + 10, k + 10, PlaceDeepslate, 0, 2);
		world.setBlock(i + 14, j + 10, k + 10, PlaceDeepslate, 0, 2);
		world.setBlock(i + 15, j + 10, k + 10, PlaceDeepslate, 0, 2);
		world.setBlock(i + 16, j + 10, k + 10, PlaceDeepslate, 0, 2);
		world.setBlock(i + 17, j + 10, k + 10, PlaceDeepslate, 0, 2);
		world.setBlock(i + 18, j + 10, k + 10, PlaceDeepslate, 0, 2);
		world.setBlock(i + 19, j + 10, k + 10, PlaceDeepslate, 0, 2);
		world.setBlock(i + 20, j + 10, k + 10, PlaceDeepslate, 0, 2);
		world.setBlock(i + 11, j + 10, k + 11, PlaceDeepslate, 0, 2);
		world.setBlock(i + 12, j + 10, k + 11, PlaceDeepslate, 0, 2);
		world.setBlock(i + 13, j + 10, k + 11, PlaceDeepslate, 0, 2);
		world.setBlock(i + 14, j + 10, k + 11, PlaceDeepslate, 0, 2);
		world.setBlock(i + 15, j + 10, k + 11, PlaceDeepslate, 0, 2);
		world.setBlock(i + 16, j + 10, k + 11, PlaceDeepslate, 0, 2);
		world.setBlock(i + 17, j + 10, k + 11, PlaceDeepslate, 0, 2);
		world.setBlock(i + 18, j + 10, k + 11, PlaceDeepslate, 0, 2);
		world.setBlock(i + 19, j + 10, k + 11, PlaceDeepslate, 0, 2);
		world.setBlock(i + 20, j + 10, k + 11, PlaceDeepslate, 0, 2);
		world.setBlock(i + 21, j + 10, k + 11, PlaceDeepslate, 0, 2);
		world.setBlock(i + 11, j + 10, k + 12, PlaceDeepslate, 0, 2);
		world.setBlock(i + 12, j + 10, k + 12, PlaceDeepslate, 0, 2);
		world.setBlock(i + 13, j + 10, k + 12, PlaceDeepslate, 0, 2);
		world.setBlock(i + 14, j + 10, k + 12, PlaceDeepslate, 0, 2);
		world.setBlock(i + 15, j + 10, k + 12, PlaceDeepslate, 0, 2);
		world.setBlock(i + 16, j + 10, k + 12, PlaceDeepslate, 0, 2);
		world.setBlock(i + 17, j + 10, k + 12, PlaceDeepslate, 0, 2);
		world.setBlock(i + 18, j + 10, k + 12, PlaceDeepslate, 0, 2);
		world.setBlock(i + 19, j + 10, k + 12, PlaceDeepslate, 0, 2);
		world.setBlock(i + 20, j + 10, k + 12, PlaceDeepslate, 0, 2);
		world.setBlock(i + 21, j + 10, k + 12, PlaceDeepslate, 0, 2);
		world.setBlock(i + 11, j + 10, k + 13, PlaceDeepslate, 0, 2);
		world.setBlock(i + 12, j + 10, k + 13, PlaceDeepslate, 0, 2);
		world.setBlock(i + 13, j + 10, k + 13, PlaceDeepslate, 0, 2);
		world.setBlock(i + 14, j + 10, k + 13, PlaceDeepslate, 0, 2);
		world.setBlock(i + 15, j + 10, k + 13, PlaceDeepslate, 0, 2);
		world.setBlock(i + 16, j + 10, k + 13, PlaceDeepslate, 0, 2);
		world.setBlock(i + 17, j + 10, k + 13, PlaceDeepslate, 0, 2);
		world.setBlock(i + 18, j + 10, k + 13, PlaceDeepslate, 0, 2);
		world.setBlock(i + 19, j + 10, k + 13, PlaceDeepslate, 0, 2);
		world.setBlock(i + 20, j + 10, k + 13, PlaceDeepslate, 0, 2);
		world.setBlock(i + 21, j + 10, k + 13, PlaceDeepslate, 0, 2);
		world.setBlock(i + 11, j + 10, k + 14, PlaceDeepslate, 0, 2);
		world.setBlock(i + 12, j + 10, k + 14, PlaceDeepslate, 0, 2);
		world.setBlock(i + 13, j + 10, k + 14, PlaceDeepslate, 0, 2);
		world.setBlock(i + 14, j + 10, k + 14, PlaceDeepslate, 0, 2);
		world.setBlock(i + 15, j + 10, k + 14, PlaceDeepslate, 0, 2);
		world.setBlock(i + 16, j + 10, k + 14, PlaceDeepslate, 0, 2);
		world.setBlock(i + 17, j + 10, k + 14, PlaceDeepslate, 0, 2);
		world.setBlock(i + 18, j + 10, k + 14, PlaceDeepslate, 0, 2);
		world.setBlock(i + 19, j + 10, k + 14, PlaceDeepslate, 0, 2);
		world.setBlock(i + 20, j + 10, k + 14, PlaceDeepslate, 0, 2);
		world.setBlock(i + 21, j + 10, k + 14, PlaceDeepslate, 0, 2);
		world.setBlock(i + 11, j + 10, k + 15, PlaceDeepslate, 0, 2);
		world.setBlock(i + 12, j + 10, k + 15, PlaceDeepslate, 0, 2);
		world.setBlock(i + 13, j + 10, k + 15, PlaceDeepslate, 0, 2);
		world.setBlock(i + 14, j + 10, k + 15, PlaceDeepslate, 0, 2);
		world.setBlock(i + 15, j + 10, k + 15, PlaceDeepslate, 0, 2);
		world.setBlock(i + 16, j + 10, k + 15, PlaceDeepslate, 0, 2);
		world.setBlock(i + 17, j + 10, k + 15, PlaceDeepslate, 0, 2);
		world.setBlock(i + 18, j + 10, k + 15, PlaceDeepslate, 0, 2);
		world.setBlock(i + 19, j + 10, k + 15, PlaceDeepslate, 0, 2);
		world.setBlock(i + 20, j + 10, k + 15, PlaceDeepslate, 0, 2);
		world.setBlock(i + 21, j + 10, k + 15, PlaceDeepslate, 0, 2);
		world.setBlock(i + 12, j + 10, k + 16, PlaceDeepslate, 0, 2);
		world.setBlock(i + 13, j + 10, k + 16, PlaceDeepslate, 0, 2);
		world.setBlock(i + 14, j + 10, k + 16, PlaceDeepslate, 0, 2);
		world.setBlock(i + 15, j + 10, k + 16, PlaceDeepslate, 0, 2);
		world.setBlock(i + 16, j + 10, k + 16, PlaceDeepslate, 0, 2);
		world.setBlock(i + 17, j + 10, k + 16, PlaceDeepslate, 0, 2);
		world.setBlock(i + 18, j + 10, k + 16, PlaceDeepslate, 0, 2);
		world.setBlock(i + 19, j + 10, k + 16, PlaceDeepslate, 0, 2);
		world.setBlock(i + 20, j + 10, k + 16, PlaceDeepslate, 0, 2);
		world.setBlock(i + 12, j + 11, k + 4, sculk_block, 0, 2);
		world.setBlock(i + 13, j + 11, k + 4, sculk_block, 0, 2);
		world.setBlock(i + 14, j + 11, k + 4, sculk_block, 0, 2);
		world.setBlock(i + 15, j + 11, k + 4, sculk_block, 0, 2);
		world.setBlock(i + 16, j + 11, k + 4, PlaceDeepslate, 0, 2);
		world.setBlock(i + 11, j + 11, k + 5, sculk_block, 0, 2);
		world.setBlock(i + 12, j + 11, k + 5, sculk_block, 0, 2);
		world.setBlock(i + 13, j + 11, k + 5, sculk_block, 0, 2);
		world.setBlock(i + 14, j + 11, k + 5, sculk_block, 0, 2);
		world.setBlock(i + 15, j + 11, k + 5, sculk_block, 0, 2);
		world.setBlock(i + 16, j + 11, k + 5, PlaceDeepslate, 0, 2);
		world.setBlock(i + 17, j + 11, k + 5, PlaceDeepslate, 0, 2);
		world.setBlock(i + 11, j + 11, k + 6, sculk_block, 0, 2);
		world.setBlock(i + 12, j + 11, k + 6, sculk_block, 0, 2);
		world.setBlock(i + 13, j + 11, k + 6, sculk_block, 0, 2);
		world.setBlock(i + 14, j + 11, k + 6, sculk_block, 0, 2);
		world.setBlock(i + 15, j + 11, k + 6, sculk_block, 0, 2);
		world.setBlock(i + 16, j + 11, k + 6, PlaceDeepslate, 0, 2);
		world.setBlock(i + 17, j + 11, k + 6, PlaceDeepslate, 0, 2);
		world.setBlock(i + 18, j + 11, k + 6, PlaceDeepslate, 0, 2);
		world.setBlock(i + 11, j + 11, k + 7, PlaceDeepslate, 0, 2);
		world.setBlock(i + 12, j + 11, k + 7, PlaceDeepslate, 0, 2);
		world.setBlock(i + 13, j + 11, k + 7, PlaceDeepslate, 0, 2);
		world.setBlock(i + 14, j + 11, k + 7, PlaceDeepslate, 0, 2);
		world.setBlock(i + 15, j + 11, k + 7, PlaceDeepslate, 0, 2);
		world.setBlock(i + 16, j + 11, k + 7, PlaceDeepslate, 0, 2);
		world.setBlock(i + 17, j + 11, k + 7, PlaceDeepslate, 0, 2);
		world.setBlock(i + 18, j + 11, k + 7, PlaceDeepslate, 0, 2);
		world.setBlock(i + 11, j + 11, k + 8, PlaceDeepslate, 0, 2);
		world.setBlock(i + 12, j + 11, k + 8, PlaceDeepslate, 0, 2);
		world.setBlock(i + 13, j + 11, k + 8, PlaceDeepslate, 0, 2);
		world.setBlock(i + 14, j + 11, k + 8, PlaceDeepslate, 0, 2);
		world.setBlock(i + 15, j + 11, k + 8, PlaceDeepslate, 0, 2);
		world.setBlock(i + 16, j + 11, k + 8, PlaceDeepslate, 0, 2);
		world.setBlock(i + 17, j + 11, k + 8, PlaceDeepslate, 0, 2);
		world.setBlock(i + 18, j + 11, k + 8, PlaceDeepslate, 0, 2);
		world.setBlock(i + 19, j + 11, k + 8, PlaceDeepslate, 0, 2);
		world.setBlock(i + 11, j + 11, k + 9, PlaceDeepslate, 0, 2);
		world.setBlock(i + 12, j + 11, k + 9, PlaceDeepslate, 0, 2);
		world.setBlock(i + 13, j + 11, k + 9, PlaceDeepslate, 0, 2);
		world.setBlock(i + 14, j + 11, k + 9, PlaceDeepslate, 0, 2);
		world.setBlock(i + 15, j + 11, k + 9, PlaceDeepslate, 0, 2);
		world.setBlock(i + 16, j + 11, k + 9, PlaceDeepslate, 0, 2);
		world.setBlock(i + 17, j + 11, k + 9, PlaceDeepslate, 0, 2);
		world.setBlock(i + 18, j + 11, k + 9, PlaceDeepslate, 0, 2);
		world.setBlock(i + 19, j + 11, k + 9, PlaceDeepslate, 0, 2);
		world.setBlock(i + 20, j + 11, k + 9, PlaceDeepslate, 0, 2);
		world.setBlock(i + 11, j + 11, k + 10, PlaceDeepslate, 0, 2);
		world.setBlock(i + 12, j + 11, k + 10, PlaceDeepslate, 0, 2);
		world.setBlock(i + 13, j + 11, k + 10, PlaceDeepslate, 0, 2);
		world.setBlock(i + 14, j + 11, k + 10, PlaceDeepslate, 0, 2);
		world.setBlock(i + 15, j + 11, k + 10, PlaceDeepslate, 0, 2);
		world.setBlock(i + 16, j + 11, k + 10, PlaceDeepslate, 0, 2);
		world.setBlock(i + 17, j + 11, k + 10, PlaceDeepslate, 0, 2);
		world.setBlock(i + 18, j + 11, k + 10, PlaceDeepslate, 0, 2);
		world.setBlock(i + 19, j + 11, k + 10, PlaceDeepslate, 0, 2);
		world.setBlock(i + 20, j + 11, k + 10, PlaceDeepslate, 0, 2);
		world.setBlock(i + 11, j + 11, k + 11, PlaceDeepslate, 0, 2);
		world.setBlock(i + 12, j + 11, k + 11, PlaceDeepslate, 0, 2);
		world.setBlock(i + 13, j + 11, k + 11, PlaceDeepslate, 0, 2);
		world.setBlock(i + 14, j + 11, k + 11, PlaceDeepslate, 0, 2);
		world.setBlock(i + 15, j + 11, k + 11, PlaceDeepslate, 0, 2);
		world.setBlock(i + 16, j + 11, k + 11, PlaceDeepslate, 0, 2);
		world.setBlock(i + 17, j + 11, k + 11, PlaceDeepslate, 0, 2);
		world.setBlock(i + 18, j + 11, k + 11, PlaceDeepslate, 0, 2);
		world.setBlock(i + 19, j + 11, k + 11, PlaceDeepslate, 0, 2);
		world.setBlock(i + 20, j + 11, k + 11, PlaceDeepslate, 0, 2);
		world.setBlock(i + 21, j + 11, k + 11, PlaceDeepslate, 0, 2);
		world.setBlock(i + 11, j + 11, k + 12, PlaceDeepslate, 0, 2);
		world.setBlock(i + 12, j + 11, k + 12, PlaceDeepslate, 0, 2);
		world.setBlock(i + 13, j + 11, k + 12, PlaceDeepslate, 0, 2);
		world.setBlock(i + 14, j + 11, k + 12, PlaceDeepslate, 0, 2);
		world.setBlock(i + 15, j + 11, k + 12, PlaceDeepslate, 0, 2);
		world.setBlock(i + 16, j + 11, k + 12, PlaceDeepslate, 0, 2);
		world.setBlock(i + 17, j + 11, k + 12, PlaceDeepslate, 0, 2);
		world.setBlock(i + 18, j + 11, k + 12, PlaceDeepslate, 0, 2);
		world.setBlock(i + 19, j + 11, k + 12, PlaceDeepslate, 0, 2);
		world.setBlock(i + 20, j + 11, k + 12, PlaceDeepslate, 0, 2);
		world.setBlock(i + 21, j + 11, k + 12, PlaceDeepslate, 0, 2);
		world.setBlock(i + 11, j + 11, k + 13, PlaceDeepslate, 0, 2);
		world.setBlock(i + 12, j + 11, k + 13, PlaceDeepslate, 0, 2);
		world.setBlock(i + 13, j + 11, k + 13, PlaceDeepslate, 0, 2);
		world.setBlock(i + 14, j + 11, k + 13, PlaceDeepslate, 0, 2);
		world.setBlock(i + 15, j + 11, k + 13, PlaceDeepslate, 0, 2);
		world.setBlock(i + 16, j + 11, k + 13, PlaceDeepslate, 0, 2);
		world.setBlock(i + 17, j + 11, k + 13, PlaceDeepslate, 0, 2);
		world.setBlock(i + 18, j + 11, k + 13, PlaceDeepslate, 0, 2);
		world.setBlock(i + 19, j + 11, k + 13, PlaceDeepslate, 0, 2);
		world.setBlock(i + 20, j + 11, k + 13, PlaceDeepslate, 0, 2);
		world.setBlock(i + 21, j + 11, k + 13, PlaceDeepslate, 0, 2);
		world.setBlock(i + 11, j + 11, k + 14, PlaceDeepslate, 0, 2);
		world.setBlock(i + 12, j + 11, k + 14, PlaceDeepslate, 0, 2);
		world.setBlock(i + 13, j + 11, k + 14, PlaceDeepslate, 0, 2);
		world.setBlock(i + 14, j + 11, k + 14, PlaceDeepslate, 0, 2);
		world.setBlock(i + 15, j + 11, k + 14, PlaceDeepslate, 0, 2);
		world.setBlock(i + 16, j + 11, k + 14, PlaceDeepslate, 0, 2);
		world.setBlock(i + 17, j + 11, k + 14, PlaceDeepslate, 0, 2);
		world.setBlock(i + 18, j + 11, k + 14, PlaceDeepslate, 0, 2);
		world.setBlock(i + 19, j + 11, k + 14, PlaceDeepslate, 0, 2);
		world.setBlock(i + 20, j + 11, k + 14, PlaceDeepslate, 0, 2);
		world.setBlock(i + 21, j + 11, k + 14, PlaceDeepslate, 0, 2);
		world.setBlock(i + 11, j + 11, k + 15, PlaceDeepslate, 0, 2);
		world.setBlock(i + 12, j + 11, k + 15, PlaceDeepslate, 0, 2);
		world.setBlock(i + 13, j + 11, k + 15, PlaceDeepslate, 0, 2);
		world.setBlock(i + 14, j + 11, k + 15, PlaceDeepslate, 0, 2);
		world.setBlock(i + 15, j + 11, k + 15, PlaceDeepslate, 0, 2);
		world.setBlock(i + 16, j + 11, k + 15, PlaceDeepslate, 0, 2);
		world.setBlock(i + 17, j + 11, k + 15, PlaceDeepslate, 0, 2);
		world.setBlock(i + 18, j + 11, k + 15, PlaceDeepslate, 0, 2);
		world.setBlock(i + 19, j + 11, k + 15, PlaceDeepslate, 0, 2);
		world.setBlock(i + 20, j + 11, k + 15, PlaceDeepslate, 0, 2);
		world.setBlock(i + 21, j + 11, k + 15, PlaceDeepslate, 0, 2);
		world.setBlock(i + 12, j + 11, k + 16, PlaceDeepslate, 0, 2);
		world.setBlock(i + 13, j + 11, k + 16, PlaceDeepslate, 0, 2);
		world.setBlock(i + 14, j + 11, k + 16, PlaceDeepslate, 0, 2);
		world.setBlock(i + 15, j + 11, k + 16, PlaceDeepslate, 0, 2);
		world.setBlock(i + 16, j + 11, k + 16, PlaceDeepslate, 0, 2);
