package com.NovaCraft.world.ancient_city;

import java.util.Random;

import com.NovaCraft.Items.NovaCraftItems;
import com.NovaCraft.registry.OtherModBlocks;
import com.NovaCraft.registry.OtherModItems;
import com.NovaCraftBlocks.NovaCraftBlocks;

import cpw.mods.fml.common.Loader;
import net.minecraft.block.Block;
import net.minecraft.enchantment.Enchantment;
import net.minecraft.enchantment.EnchantmentData;
import net.minecraft.init.Blocks;
import net.minecraft.init.Items;
import net.minecraft.item.ItemStack;
import net.minecraft.tileentity.TileEntityChest;
import net.minecraft.util.MathHelper;
import net.minecraft.world.World;
import net.minecraft.world.gen.feature.WorldGenerator;

public class AncientCitySculkWallNegXPosZGen extends WorldGenerator
{
	public AncientCitySculkWallNegXPosZGen() {

	}
	
	private static final Block grimstone = NovaCraftBlocks.grimstone;
	private static final Block sculk_grimstone = NovaCraftBlocks.sculk_grimstone;
	private static final Block sculk_block = NovaCraftBlocks.sculk_block;
	private static final Block sculk_tulip = NovaCraftBlocks.sculk_tulip;
	private static final Block sculk_tendrils = NovaCraftBlocks.sculk_tendrils;
	private static final Block sculk_bush = NovaCraftBlocks.sculk_bush;
	private static final Block sculk_bloom = NovaCraftBlocks.sculk_bloom;	
	private static final Block sculk_tiles = NovaCraftBlocks.sculk_tiles;
	private static final Block sculk_bricks = NovaCraftBlocks.sculk_bricks;
    
    public boolean generate(final World world, final Random random, final int i, final int j, final int k) {
    	
		world.setBlock(i + 0, j + 0, k + 4, sculk_block, 0, 2);
		world.setBlock(i + 1, j + 0, k + 4, sculk_block, 0, 2);
		world.setBlock(i + 2, j + 0, k + 4, sculk_block, 0, 2);
		world.setBlock(i + 1, j + 0, k + 5, sculk_block, 0, 2);
		world.setBlock(i + 2, j + 0, k + 5, sculk_block, 0, 2);
		world.setBlock(i + 3, j + 0, k + 5, sculk_block, 0, 2);
		world.setBlock(i + 2, j + 0, k + 6, sculk_block, 0, 2);
		world.setBlock(i + 3, j + 0, k + 6, sculk_block, 0, 2);
		world.setBlock(i + 4, j + 0, k + 6, sculk_block, 0, 2);
		world.setBlock(i + 3, j + 0, k + 7, sculk_block, 0, 2);
		world.setBlock(i + 4, j + 0, k + 7, sculk_block, 0, 2);
		world.setBlock(i + 5, j + 0, k + 7, sculk_block, 0, 2);
		world.setBlock(i + 4, j + 0, k + 8, sculk_block, 0, 2);
		world.setBlock(i + 5, j + 0, k + 8, sculk_block, 0, 2);
		world.setBlock(i + 6, j + 0, k + 8, sculk_block, 0, 2);
		world.setBlock(i + 5, j + 0, k + 9, sculk_block, 0, 2);
		world.setBlock(i + 6, j + 0, k + 9, sculk_block, 0, 2);
		world.setBlock(i + 5, j + 0, k + 10, sculk_block, 0, 2);
		world.setBlock(i + 6, j + 0, k + 10, sculk_block, 0, 2);
		world.setBlock(i + 7, j + 0, k + 10, sculk_block, 0, 2);
		world.setBlock(i + 6, j + 0, k + 11, sculk_block, 0, 2);
		world.setBlock(i + 7, j + 0, k + 11, sculk_block, 0, 2);
		world.setBlock(i + 8, j + 0, k + 11, sculk_block, 0, 2);
		world.setBlock(i + 7, j + 0, k + 12, sculk_block, 0, 2);
		world.setBlock(i + 8, j + 0, k + 12, sculk_block, 0, 2);
		world.setBlock(i + 13, j + 0, k + 12, NovaCraftBlocks.sculk_vein, 0, 2);
		world.setBlock(i + 14, j + 0, k + 12, NovaCraftBlocks.sculk_vein, 0, 2);
		world.setBlock(i + 7, j + 0, k + 13, sculk_block, 0, 2);
		world.setBlock(i + 8, j + 0, k + 13, sculk_block, 0, 2);
		world.setBlock(i + 9, j + 0, k + 13, sculk_block, 0, 2);
		world.setBlock(i + 14, j + 0, k + 13, NovaCraftBlocks.sculk_vein, 0, 2);
		world.setBlock(i + 8, j + 0, k + 14, sculk_block, 0, 2);
		world.setBlock(i + 9, j + 0, k + 14, sculk_block, 0, 2);
		world.setBlock(i + 8, j + 0, k + 15, sculk_block, 0, 2);
		world.setBlock(i + 9, j + 0, k + 15, sculk_block, 0, 2);
		world.setBlock(i + 10, j + 0, k + 15, sculk_block, 0, 2);
		world.setBlock(i + 9, j + 0, k + 16, sculk_block, 0, 2);
		world.setBlock(i + 10, j + 0, k + 16, sculk_block, 0, 2);
		world.setBlock(i + 9, j + 0, k + 17, sculk_block, 0, 2);
		world.setBlock(i + 10, j + 0, k + 17, sculk_block, 0, 2);
		world.setBlock(i + 11, j + 0, k + 17, sculk_block, 0, 2);
		world.setBlock(i + 10, j + 0, k + 18, sculk_block, 0, 2);
		world.setBlock(i + 11, j + 0, k + 18, sculk_block, 0, 2);
		world.setBlock(i + 10, j + 0, k + 19, sculk_block, 0, 2);
		world.setBlock(i + 11, j + 0, k + 19, sculk_block, 0, 2);
		world.setBlock(i + 10, j + 0, k + 20, sculk_block, 0, 2);
		world.setBlock(i + 11, j + 0, k + 20, sculk_block, 0, 2);
		world.setBlock(i + 12, j + 0, k + 20, sculk_block, 0, 2);
		world.setBlock(i + 11, j + 0, k + 21, sculk_block, 0, 2);
		world.setBlock(i + 12, j + 0, k + 21, sculk_block, 0, 2);
		world.setBlock(i + 11, j + 0, k + 22, sculk_block, 0, 2);
		world.setBlock(i + 12, j + 0, k + 22, sculk_block, 0, 2);
		world.setBlock(i + 11, j + 0, k + 23, sculk_block, 0, 2);
		world.setBlock(i + 12, j + 0, k + 23, sculk_block, 0, 2);
		world.setBlock(i + 13, j + 0, k + 23, sculk_block, 0, 2);
		world.setBlock(i + 12, j + 0, k + 24, sculk_block, 0, 2);
		world.setBlock(i + 13, j + 0, k + 24, sculk_block, 0, 2);
		world.setBlock(i + 12, j + 0, k + 25, sculk_block, 0, 2);
		world.setBlock(i + 13, j + 0, k + 25, sculk_block, 0, 2);
		world.setBlock(i + 12, j + 0, k + 26, sculk_block, 0, 2);
		world.setBlock(i + 13, j + 0, k + 26, sculk_block, 0, 2);
		world.setBlock(i + 12, j + 0, k + 27, sculk_block, 0, 2);
		world.setBlock(i + 13, j + 0, k + 27, sculk_block, 0, 2);
		world.setBlock(i + 12, j + 0, k + 28, sculk_block, 0, 2);
		world.setBlock(i + 13, j + 0, k + 28, sculk_block, 0, 2);
		world.setBlock(i + 14, j + 0, k + 28, sculk_block, 0, 2);
		world.setBlock(i + 13, j + 0, k + 29, sculk_block, 0, 2);
		world.setBlock(i + 14, j + 0, k + 29, sculk_block, 0, 2);
		world.setBlock(i + 13, j + 0, k + 30, sculk_block, 0, 2);
		world.setBlock(i + 14, j + 0, k + 30, sculk_block, 0, 2);
		world.setBlock(i + 4, j + 1, k + 3, sculk_block, 0, 2);
		world.setBlock(i + 3, j + 1, k + 4, sculk_block, 0, 2);
		world.setBlock(i + 4, j + 1, k + 4, sculk_block, 0, 2);
		world.setBlock(i + 5, j + 1, k + 4, sculk_block, 0, 2);
		world.setBlock(i + 19, j + 1, k + 4, NovaCraftBlocks.sculk_vein, 0, 2);
		world.setBlock(i + 20, j + 1, k + 4, NovaCraftBlocks.sculk_vein, 0, 2);
		world.setBlock(i + 4, j + 1, k + 5, sculk_block, 0, 2);
		world.setBlock(i + 5, j + 1, k + 5, sculk_block, 0, 2);
		world.setBlock(i + 6, j + 1, k + 5, sculk_block, 0, 2);
		world.setBlock(i + 5, j + 1, k + 6, sculk_block, 0, 2);
		world.setBlock(i + 6, j + 1, k + 6, sculk_block, 0, 2);
		world.setBlock(i + 5, j + 1, k + 7, NovaCraftBlocks.sculk_vein, 1, 2);
		world.setBlock(i + 6, j + 1, k + 7, sculk_block, 0, 2);
		world.setBlock(i + 7, j + 1, k + 7, sculk_block, 0, 2);
		world.setBlock(i + 7, j + 1, k + 8, sculk_block, 0, 2);
		world.setBlock(i + 8, j + 1, k + 8, sculk_block, 0, 2);
		world.setBlock(i + 7, j + 1, k + 9, sculk_block, 0, 2);
		world.setBlock(i + 8, j + 1, k + 9, sculk_block, 0, 2);
		world.setBlock(i + 8, j + 1, k + 10, sculk_block, 0, 2);
		world.setBlock(i + 9, j + 1, k + 10, sculk_block, 0, 2);
		world.setBlock(i + 9, j + 1, k + 11, sculk_block, 0, 2);
		world.setBlock(i + 10, j + 1, k + 11, sculk_block, 0, 2);
		world.setBlock(i + 7, j + 1, k + 12, NovaCraftBlocks.sculk_vein, 1, 2);
		world.setBlock(i + 9, j + 1, k + 12, sculk_block, 0, 2);
		world.setBlock(i + 10, j + 1, k + 12, sculk_block, 0, 2);
		world.setBlock(i + 10, j + 1, k + 13, sculk_block, 0, 2);
		world.setBlock(i + 11, j + 1, k + 13, sculk_block, 0, 2);
		world.setBlock(i + 10, j + 1, k + 14, sculk_block, 0, 2);
		world.setBlock(i + 11, j + 1, k + 14, sculk_block, 0, 2);
		world.setBlock(i + 9, j + 1, k + 15, NovaCraftBlocks.sculk_sensor, 0, 2);
		world.setBlock(i + 11, j + 1, k + 15, sculk_block, 0, 2);
		world.setBlock(i + 12, j + 1, k + 15, sculk_block, 0, 2);
		world.setBlock(i + 11, j + 1, k + 16, sculk_block, 0, 2);
		world.setBlock(i + 12, j + 1, k + 16, sculk_block, 0, 2);
		world.setBlock(i + 10, j + 1, k + 17, NovaCraftBlocks.sculk_vein, 1, 2);
		world.setBlock(i + 12, j + 1, k + 17, sculk_block, 0, 2);
		world.setBlock(i + 13, j + 1, k + 17, sculk_block, 0, 2);
		world.setBlock(i + 12, j + 1, k + 18, sculk_block, 0, 2);
		world.setBlock(i + 13, j + 1, k + 18, sculk_block, 0, 2);
		world.setBlock(i + 17, j + 1, k + 18, NovaCraftBlocks.sculk_vein, 0, 2);
		world.setBlock(i + 12, j + 1, k + 19, sculk_block, 0, 2);
		world.setBlock(i + 13, j + 1, k + 19, sculk_block, 0, 2);
		world.setBlock(i + 13, j + 1, k + 20, sculk_block, 0, 2);
		world.setBlock(i + 14, j + 1, k + 20, sculk_block, 0, 2);
		world.setBlock(i + 13, j + 1, k + 21, sculk_block, 0, 2);
		world.setBlock(i + 14, j + 1, k + 21, sculk_block, 0, 2);
		world.setBlock(i + 13, j + 1, k + 22, sculk_block, 0, 2);
		world.setBlock(i + 14, j + 1, k + 22, sculk_block, 0, 2);
		world.setBlock(i + 14, j + 1, k + 23, sculk_block, 0, 2);
		world.setBlock(i + 15, j + 1, k + 23, sculk_block, 0, 2);
		world.setBlock(i + 14, j + 1, k + 24, sculk_block, 0, 2);
		world.setBlock(i + 15, j + 1, k + 24, sculk_block, 0, 2);
		world.setBlock(i + 14, j + 1, k + 25, sculk_block, 0, 2);
		world.setBlock(i + 15, j + 1, k + 25, sculk_block, 0, 2);
		world.setBlock(i + 12, j + 1, k + 26, NovaCraftBlocks.sculk_vein, 1, 2);
		world.setBlock(i + 14, j + 1, k + 26, sculk_block, 0, 2);
		world.setBlock(i + 15, j + 1, k + 26, sculk_block, 0, 2);
		world.setBlock(i + 14, j + 1, k + 27, sculk_block, 0, 2);
		world.setBlock(i + 15, j + 1, k + 27, sculk_block, 0, 2);
		world.setBlock(i + 15, j + 1, k + 28, sculk_block, 0, 2);
		world.setBlock(i + 16, j + 1, k + 28, sculk_block, 0, 2);
		world.setBlock(i + 15, j + 1, k + 29, sculk_block, 0, 2);
		world.setBlock(i + 16, j + 1, k + 29, sculk_block, 0, 2);
		world.setBlock(i + 15, j + 1, k + 30, sculk_block, 0, 2);
		world.setBlock(i + 16, j + 1, k + 30, sculk_block, 0, 2);
		world.setBlock(i + 5, j + 2, k + 3, sculk_block, 0, 2);
		world.setBlock(i + 6, j + 2, k + 3, sculk_block, 0, 2);
		world.setBlock(i + 5, j + 2, k + 4, NovaCraftBlocks.sculk_vein, 1, 2);
		world.setBlock(i + 6, j + 2, k + 4, sculk_block, 0, 2);
		world.setBlock(i + 7, j + 2, k + 4, sculk_block, 0, 2);
		world.setBlock(i + 20, j + 2, k + 4, NovaCraftBlocks.sculk_vein, 0, 2);
		world.setBlock(i + 7, j + 2, k + 5, sculk_block, 0, 2);
		world.setBlock(i + 8, j + 2, k + 5, sculk_block, 0, 2);
		world.setBlock(i + 5, j + 2, k + 6, NovaCraftBlocks.sculk_sensor, 0, 2);
		world.setBlock(i + 7, j + 2, k + 6, sculk_block, 0, 2);
		world.setBlock(i + 8, j + 2, k + 6, sculk_block, 0, 2);
		world.setBlock(i + 8, j + 2, k + 7, sculk_block, 0, 2);
		world.setBlock(i + 9, j + 2, k + 7, sculk_block, 0, 2);
		world.setBlock(i + 9, j + 2, k + 8, sculk_block, 0, 2);
		world.setBlock(i + 10, j + 2, k + 8, sculk_block, 0, 2);
		world.setBlock(i + 9, j + 2, k + 9, sculk_block, 0, 2);
		world.setBlock(i + 10, j + 2, k + 9, sculk_block, 0, 2);
		world.setBlock(i + 9, j + 2, k + 10, NovaCraftBlocks.sculk_tentacle_2, 1, 2);
		world.setBlock(i + 10, j + 2, k + 10, sculk_block, 0, 2);
		world.setBlock(i + 11, j + 2, k + 10, sculk_block, 0, 2);
		world.setBlock(i + 11, j + 2, k + 11, sculk_block, 0, 2);
		world.setBlock(i + 12, j + 2, k + 11, sculk_block, 0, 2);
		world.setBlock(i + 10, j + 2, k + 12, NovaCraftBlocks.sculk_vein, 1, 2);
		world.setBlock(i + 11, j + 2, k + 12, sculk_block, 0, 2);
		world.setBlock(i + 12, j + 2, k + 12, sculk_block, 0, 2);
		world.setBlock(i + 12, j + 2, k + 13, sculk_block, 0, 2);
		world.setBlock(i + 13, j + 2, k + 13, sculk_block, 0, 2);
		world.setBlock(i + 12, j + 2, k + 14, sculk_block, 0, 2);
		world.setBlock(i + 13, j + 2, k + 14, sculk_block, 0, 2);
		world.setBlock(i + 13, j + 2, k + 15, sculk_block, 0, 2);
		world.setBlock(i + 13, j + 2, k + 16, sculk_block, 0, 2);
		world.setBlock(i + 14, j + 2, k + 16, sculk_block, 0, 2);
		world.setBlock(i + 14, j + 2, k + 17, sculk_block, 0, 2);
		world.setBlock(i + 14, j + 2, k + 18, sculk_block, 0, 2);
		world.setBlock(i + 15, j + 2, k + 18, sculk_block, 0, 2);
		world.setBlock(i + 18, j + 2, k + 18, NovaCraftBlocks.sculk_vein, 0, 2);
		world.setBlock(i + 14, j + 2, k + 19, sculk_block, 0, 2);
		world.setBlock(i + 15, j + 2, k + 19, sculk_block, 0, 2);
		world.setBlock(i + 15, j + 2, k + 20, sculk_block, 0, 2);
		world.setBlock(i + 13, j + 2, k + 21, NovaCraftBlocks.sculk_tentacle_2, 1, 2);
		world.setBlock(i + 15, j + 2, k + 21, sculk_block, 0, 2);
		world.setBlock(i + 16, j + 2, k + 21, sculk_block, 0, 2);
		world.setBlock(i + 15, j + 2, k + 22, sculk_block, 0, 2);
		world.setBlock(i + 16, j + 2, k + 22, sculk_block, 0, 2);
		world.setBlock(i + 16, j + 2, k + 23, sculk_block, 0, 2);
		world.setBlock(i + 14, j + 2, k + 24, NovaCraftBlocks.sculk_sensor, 0, 2);
		world.setBlock(i + 16, j + 2, k + 24, sculk_block, 0, 2);
		world.setBlock(i + 16, j + 2, k + 25, sculk_block, 0, 2);
		world.setBlock(i + 17, j + 2, k + 25, sculk_block, 0, 2);
		world.setBlock(i + 16, j + 2, k + 26, sculk_block, 0, 2);
		world.setBlock(i + 17, j + 2, k + 26, sculk_block, 0, 2);
		world.setBlock(i + 16, j + 2, k + 27, sculk_block, 0, 2);
		world.setBlock(i + 17, j + 2, k + 27, sculk_block, 0, 2);
		world.setBlock(i + 15, j + 2, k + 28, NovaCraftBlocks.sculk_vein, 1, 2);
		world.setBlock(i + 17, j + 2, k + 28, sculk_block, 0, 2);
		world.setBlock(i + 17, j + 2, k + 29, sculk_block, 0, 2);
		world.setBlock(i + 17, j + 2, k + 30, sculk_block, 0, 2);
		world.setBlock(i + 7, j + 3, k + 2, sculk_block, 0, 2);
		world.setBlock(i + 7, j + 3, k + 3, sculk_block, 0, 2);
		world.setBlock(i + 8, j + 3, k + 3, sculk_block, 0, 2);
		world.setBlock(i + 8, j + 3, k + 4, sculk_block, 0, 2);
		world.setBlock(i + 9, j + 3, k + 4, sculk_block, 0, 2);
		world.setBlock(i + 9, j + 3, k + 5, sculk_block, 0, 2);
		world.setBlock(i + 9, j + 3, k + 6, sculk_block, 0, 2);
		world.setBlock(i + 10, j + 3, k + 6, sculk_block, 0, 2);
		world.setBlock(i + 10, j + 3, k + 7, sculk_block, 0, 2);
		world.setBlock(i + 11, j + 3, k + 7, sculk_block, 0, 2);
		world.setBlock(i + 11, j + 3, k + 8, sculk_block, 0, 2);
		world.setBlock(i + 11, j + 3, k + 9, sculk_block, 0, 2);
		world.setBlock(i + 12, j + 3, k + 9, sculk_block, 0, 2);
		world.setBlock(i + 12, j + 3, k + 10, sculk_block, 0, 2);
		world.setBlock(i + 13, j + 3, k + 11, sculk_block, 0, 2);
		world.setBlock(i + 13, j + 3, k + 12, sculk_block, 0, 2);
		world.setBlock(i + 14, j + 3, k + 12, sculk_block, 0, 2);
		world.setBlock(i + 14, j + 3, k + 13, sculk_block, 0, 2);
		world.setBlock(i + 14, j + 3, k + 14, sculk_block, 0, 2);
		world.setBlock(i + 14, j + 3, k + 15, sculk_block, 0, 2);
		world.setBlock(i + 15, j + 3, k + 15, sculk_block, 0, 2);
		world.setBlock(i + 15, j + 3, k + 16, sculk_block, 0, 2);
		world.setBlock(i + 15, j + 3, k + 17, sculk_block, 0, 2);
		world.setBlock(i + 16, j + 3, k + 17, sculk_block, 0, 2);
		world.setBlock(i + 16, j + 3, k + 18, sculk_block, 0, 2);
		world.setBlock(i + 14, j + 3, k + 19, NovaCraftBlocks.sculk_vein, 1, 2);
		world.setBlock(i + 16, j + 3, k + 19, sculk_block, 0, 2);
		world.setBlock(i + 16, j + 3, k + 20, sculk_block, 0, 2);
		world.setBlock(i + 17, j + 3, k + 20, sculk_block, 0, 2);
		world.setBlock(i + 17, j + 3, k + 21, sculk_block, 0, 2);
		world.setBlock(i + 17, j + 3, k + 22, sculk_block, 0, 2);
		world.setBlock(i + 17, j + 3, k + 23, sculk_block, 0, 2);
		world.setBlock(i + 18, j + 3, k + 23, sculk_block, 0, 2);
		world.setBlock(i + 17, j + 3, k + 24, sculk_block, 0, 2);
		world.setBlock(i + 18, j + 3, k + 24, sculk_block, 0, 2);
		world.setBlock(i + 16, j + 3, k + 25, NovaCraftBlocks.sculk_vein, 1, 2);
		world.setBlock(i + 18, j + 3, k + 25, sculk_block, 0, 2);
		world.setBlock(i + 18, j + 3, k + 26, sculk_block, 0, 2);
		world.setBlock(i + 18, j + 3, k + 27, sculk_block, 0, 2);
		world.setBlock(i + 18, j + 3, k + 28, sculk_block, 0, 2);
		world.setBlock(i + 17, j + 3, k + 29, NovaCraftBlocks.sculk_sensor, 0, 2);
		world.setBlock(i + 18, j + 3, k + 29, sculk_block, 0, 2);
		world.setBlock(i + 19, j + 3, k + 29, sculk_block, 0, 2);
		world.setBlock(i + 18, j + 3, k + 30, sculk_block, 0, 2);
		world.setBlock(i + 19, j + 3, k + 30, sculk_block, 0, 2);
		world.setBlock(i + 8, j + 4, k + 1, sculk_block, 0, 2);
		world.setBlock(i + 8, j + 4, k + 2, sculk_block, 0, 2);
		world.setBlock(i + 9, j + 4, k + 3, sculk_block, 0, 2);
		world.setBlock(i + 10, j + 4, k + 4, sculk_block, 0, 2);
		world.setBlock(i + 10, j + 4, k + 5, sculk_block, 0, 2);
		world.setBlock(i + 11, j + 4, k + 5, sculk_block, 0, 2);
		world.setBlock(i + 11, j + 4, k + 6, sculk_block, 0, 2);
		world.setBlock(i + 12, j + 4, k + 7, sculk_block, 0, 2);
		world.setBlock(i + 12, j + 4, k + 8, sculk_block, 0, 2);
		world.setBlock(i + 13, j + 4, k + 8, sculk_block, 0, 2);
		world.setBlock(i + 13, j + 4, k + 9, sculk_block, 0, 2);
		world.setBlock(i + 13, j + 4, k + 10, sculk_block, 0, 2);
		world.setBlock(i + 14, j + 4, k + 10, sculk_block, 0, 2);
		world.setBlock(i + 14, j + 4, k + 11, sculk_block, 0, 2);
		world.setBlock(i + 15, j + 4, k + 12, sculk_block, 0, 2);
		world.setBlock(i + 14, j + 4, k + 13, NovaCraftBlocks.sculk_vein, 1, 2);
		world.setBlock(i + 15, j + 4, k + 13, sculk_block, 0, 2);
		world.setBlock(i + 15, j + 4, k + 14, sculk_block, 0, 2);
		world.setBlock(i + 16, j + 4, k + 14, sculk_block, 0, 2);
		world.setBlock(i + 16, j + 4, k + 15, sculk_block, 0, 2);
		world.setBlock(i + 16, j + 4, k + 16, sculk_block, 0, 2);
		world.setBlock(i + 17, j + 4, k + 16, sculk_block, 0, 2);
		world.setBlock(i + 17, j + 4, k + 17, sculk_block, 0, 2);
		world.setBlock(i + 17, j + 4, k + 18, sculk_block, 0, 2);
		world.setBlock(i + 17, j + 4, k + 19, sculk_block, 0, 2);
		world.setBlock(i + 18, j + 4, k + 19, sculk_block, 0, 2);
		world.setBlock(i + 18, j + 4, k + 20, sculk_block, 0, 2);
		world.setBlock(i + 17, j + 4, k + 21, NovaCraftBlocks.sculk_vein, 1, 2);
		world.setBlock(i + 18, j + 4, k + 21, sculk_block, 0, 2);
		world.setBlock(i + 18, j + 4, k + 22, sculk_block, 0, 2);
		world.setBlock(i + 19, j + 4, k + 23, sculk_block, 0, 2);
		world.setBlock(i + 19, j + 4, k + 24, sculk_block, 0, 2);
		world.setBlock(i + 19, j + 4, k + 25, sculk_block, 0, 2);
		world.setBlock(i + 19, j + 4, k + 26, sculk_block, 0, 2);
		world.setBlock(i + 19, j + 4, k + 27, sculk_block, 0, 2);
		world.setBlock(i + 19, j + 4, k + 28, sculk_block, 0, 2);
		world.setBlock(i + 20, j + 4, k + 28, sculk_block, 0, 2);
		world.setBlock(i + 20, j + 4, k + 29, sculk_block, 0, 2);
		world.setBlock(i + 20, j + 4, k + 30, sculk_block, 0, 2);
		world.setBlock(i + 9, j + 5, k + 1, sculk_block, 0, 2);
		world.setBlock(i + 9, j + 5, k + 2, sculk_block, 0, 2);
		world.setBlock(i + 10, j + 5, k + 2, sculk_block, 0, 2);
		world.setBlock(i + 10, j + 5, k + 3, sculk_block, 0, 2);
		world.setBlock(i + 11, j + 5, k + 4, sculk_block, 0, 2);
		world.setBlock(i + 10, j + 5, k + 5, NovaCraftBlocks.sculk_sensor, 0, 2);
		world.setBlock(i + 12, j + 5, k + 5, sculk_block, 0, 2);
		world.setBlock(i + 11, j + 5, k + 6, NovaCraftBlocks.sculk_tentacle_2, 1, 2);
		world.setBlock(i + 12, j + 5, k + 6, sculk_block, 0, 2);
		world.setBlock(i + 13, j + 5, k + 7, sculk_block, 0, 2);
		world.setBlock(i + 14, j + 5, k + 8, sculk_block, 0, 2);
		world.setBlock(i + 14, j + 5, k + 9, sculk_block, 0, 2);
		world.setBlock(i + 15, j + 5, k + 10, sculk_block, 0, 2);
		world.setBlock(i + 15, j + 5, k + 11, sculk_block, 0, 2);
		world.setBlock(i + 16, j + 5, k + 12, sculk_block, 0, 2);
		world.setBlock(i + 16, j + 5, k + 13, sculk_block, 0, 2);
		world.setBlock(i + 17, j + 5, k + 14, sculk_block, 0, 2);
		world.setBlock(i + 17, j + 5, k + 15, sculk_block, 0, 2);
		world.setBlock(i + 18, j + 5, k + 16, sculk_block, 0, 2);
		world.setBlock(i + 18, j + 5, k + 17, sculk_block, 0, 2);
		world.setBlock(i + 17, j + 5, k + 18, NovaCraftBlocks.sculk_sensor, 0, 2);
		world.setBlock(i + 18, j + 5, k + 18, sculk_block, 0, 2);
		world.setBlock(i + 19, j + 5, k + 19, sculk_block, 0, 2);
		world.setBlock(i + 19, j + 5, k + 20, sculk_block, 0, 2);
		world.setBlock(i + 19, j + 5, k + 21, sculk_block, 0, 2);
		world.setBlock(i + 19, j + 5, k + 22, sculk_block, 0, 2);
		world.setBlock(i + 20, j + 5, k + 23, sculk_block, 0, 2);
		world.setBlock(i + 20, j + 5, k + 24, sculk_block, 0, 2);
		world.setBlock(i + 20, j + 5, k + 25, sculk_block, 0, 2);
		world.setBlock(i + 20, j + 5, k + 26, sculk_block, 0, 2);
		world.setBlock(i + 20, j + 5, k + 27, sculk_block, 0, 2);
		world.setBlock(i + 21, j + 5, k + 28, sculk_block, 0, 2);
		world.setBlock(i + 21, j + 5, k + 29, sculk_block, 0, 2);
		world.setBlock(i + 9, j + 6, k + 0, sculk_block, 0, 2);
		world.setBlock(i + 10, j + 6, k + 1, sculk_block, 0, 2);
		world.setBlock(i + 11, j + 6, k + 2, sculk_block, 0, 2);
		world.setBlock(i + 11, j + 6, k + 3, sculk_block, 0, 2);
		world.setBlock(i + 12, j + 6, k + 4, sculk_block, 0, 2);
		world.setBlock(i + 12, j + 6, k + 5, NovaCraftBlocks.sculk_vein, 1, 2);
		world.setBlock(i + 13, j + 6, k + 5, sculk_block, 0, 2);
		world.setBlock(i + 13, j + 6, k + 6, sculk_block, 0, 2);
		world.setBlock(i + 14, j + 6, k + 7, sculk_block, 0, 2);
		world.setBlock(i + 15, j + 6, k + 8, sculk_block, 0, 2);
		world.setBlock(i + 15, j + 6, k + 9, sculk_block, 0, 2);
		world.setBlock(i + 16, j + 6, k + 10, sculk_block, 0, 2);
		world.setBlock(i + 16, j + 6, k + 11, sculk_block, 0, 2);
		world.setBlock(i + 17, j + 6, k + 12, sculk_block, 0, 2);
		world.setBlock(i + 16, j + 6, k + 13, NovaCraftBlocks.sculk_sensor, 0, 2);
		world.setBlock(i + 17, j + 6, k + 13, sculk_block, 0, 2);
		world.setBlock(i + 18, j + 6, k + 14, sculk_block, 0, 2);
		world.setBlock(i + 17, j + 6, k + 15, NovaCraftBlocks.sculk_tentacle_2, 1, 2);
		world.setBlock(i + 18, j + 6, k + 15, sculk_block, 0, 2);
		world.setBlock(i + 18, j + 6, k + 16, sculk_block, 0, 2);
		world.setBlock(i + 19, j + 6, k + 17, sculk_block, 0, 2);
		world.setBlock(i + 19, j + 6, k + 18, sculk_block, 0, 2);
		world.setBlock(i + 20, j + 6, k + 19, sculk_block, 0, 2);
		world.setBlock(i + 20, j + 6, k + 20, sculk_block, 0, 2);
		world.setBlock(i + 20, j + 6, k + 21, sculk_block, 0, 2);
		world.setBlock(i + 20, j + 6, k + 22, sculk_block, 0, 2);
		world.setBlock(i + 21, j + 6, k + 23, sculk_block, 0, 2);
		world.setBlock(i + 21, j + 6, k + 24, sculk_block, 0, 2);
		world.setBlock(i + 20, j + 6, k + 25, NovaCraftBlocks.sculk_tentacle_2, 1, 2);
		world.setBlock(i + 21, j + 6, k + 25, sculk_block, 0, 2);
		world.setBlock(i + 20, j + 6, k + 26, NovaCraftBlocks.sculk_sensor, 0, 2);
		world.setBlock(i + 21, j + 6, k + 26, sculk_block, 0, 2);
		world.setBlock(i + 21, j + 6, k + 27, sculk_block, 0, 2);
		world.setBlock(i + 21, j + 6, k + 28, sculk_block, 0, 2);
		world.setBlock(i + 10, j + 7, k + 0, sculk_block, 0, 2);
		world.setBlock(i + 11, j + 7, k + 1, sculk_block, 0, 2);
		world.setBlock(i + 11, j + 7, k + 2, sculk_block, 0, 2);
		world.setBlock(i + 12, j + 7, k + 3, sculk_block, 0, 2);
		world.setBlock(i + 13, j + 7, k + 4, sculk_block, 0, 2);
		world.setBlock(i + 14, j + 7, k + 5, sculk_block, 0, 2);
		world.setBlock(i + 14, j + 7, k + 6, sculk_block, 0, 2);
		world.setBlock(i + 15, j + 7, k + 7, sculk_block, 0, 2);
		world.setBlock(i + 15, j + 7, k + 8, sculk_block, 0, 2);
		world.setBlock(i + 16, j + 7, k + 9, sculk_block, 0, 2);
		world.setBlock(i + 17, j + 7, k + 10, sculk_block, 0, 2);
		world.setBlock(i + 17, j + 7, k + 11, sculk_block, 0, 2);
		world.setBlock(i + 18, j + 7, k + 12, sculk_block, 0, 2);
		world.setBlock(i + 18, j + 7, k + 13, sculk_block, 0, 2);
		world.setBlock(i + 18, j + 7, k + 14, sculk_block, 0, 2);
		world.setBlock(i + 19, j + 7, k + 15, sculk_block, 0, 2);
		world.setBlock(i + 19, j + 7, k + 16, sculk_block, 0, 2);
		world.setBlock(i + 19, j + 7, k + 17, NovaCraftBlocks.sculk_vein, 1, 2);
		world.setBlock(i + 20, j + 7, k + 17, sculk_block, 0, 2);
		world.setBlock(i + 20, j + 7, k + 18, sculk_block, 0, 2);
		world.setBlock(i + 20, j + 7, k + 19, sculk_block, 0, 2);
		world.setBlock(i + 21, j + 7, k + 20, sculk_block, 0, 2);
		world.setBlock(i + 21, j + 7, k + 21, sculk_block, 0, 2);
		world.setBlock(i + 21, j + 7, k + 22, sculk_block, 0, 2);
		world.setBlock(i + 21, j + 7, k + 23, sculk_block, 0, 2);
		world.setBlock(i + 22, j + 7, k + 24, sculk_block, 0, 2);
		world.setBlock(i + 22, j + 7, k + 25, sculk_block, 0, 2);
		world.setBlock(i + 21, j + 7, k + 26, NovaCraftBlocks.sculk_vein, 1, 2);
		world.setBlock(i + 22, j + 7, k + 26, sculk_block, 0, 2);
		world.setBlock(i + 22, j + 7, k + 27, sculk_block, 0, 2);
		world.setBlock(i + 22, j + 7, k + 28, sculk_block, 0, 2);
		world.setBlock(i + 10, j + 8, k + 0, sculk_block, 0, 2);
		world.setBlock(i + 11, j + 8, k + 1, sculk_block, 0, 2);
		world.setBlock(i + 11, j + 8, k + 2, NovaCraftBlocks.sculk_vein, 1, 2);
		world.setBlock(i + 12, j + 8, k + 2, sculk_block, 0, 2);
		world.setBlock(i + 13, j + 8, k + 3, sculk_block, 0, 2);
		world.setBlock(i + 13, j + 8, k + 4, sculk_block, 0, 2);
		world.setBlock(i + 14, j + 8, k + 5, sculk_block, 0, 2);
		world.setBlock(i + 15, j + 8, k + 6, sculk_block, 0, 2);
		world.setBlock(i + 15, j + 8, k + 7, sculk_block, 0, 2);
		world.setBlock(i + 16, j + 8, k + 8, sculk_block, 0, 2);
		world.setBlock(i + 16, j + 8, k + 9, NovaCraftBlocks.sculk_vein, 1, 2);
		world.setBlock(i + 17, j + 8, k + 9, sculk_block, 0, 2);
		world.setBlock(i + 17, j + 8, k + 10, sculk_block, 0, 2);
		world.setBlock(i + 18, j + 8, k + 11, sculk_block, 0, 2);
		world.setBlock(i + 18, j + 8, k + 12, sculk_block, 0, 2);
		world.setBlock(i + 18, j + 8, k + 13, sculk_block, 0, 2);
		world.setBlock(i + 19, j + 8, k + 14, sculk_block, 0, 2);
		world.setBlock(i + 19, j + 8, k + 15, sculk_block, 0, 2);
		world.setBlock(i + 20, j + 8, k + 16, sculk_block, 0, 2);
		world.setBlock(i + 20, j + 8, k + 17, sculk_block, 0, 2);
		world.setBlock(i + 20, j + 8, k + 18, sculk_block, 0, 2);
		world.setBlock(i + 21, j + 8, k + 19, sculk_block, 0, 2);
		world.setBlock(i + 21, j + 8, k + 20, sculk_block, 0, 2);
		world.setBlock(i + 21, j + 8, k + 21, sculk_block, 0, 2);
		world.setBlock(i + 22, j + 8, k + 22, sculk_block, 0, 2);
		world.setBlock(i + 22, j + 8, k + 23, sculk_block, 0, 2);
		world.setBlock(i + 22, j + 8, k + 24, sculk_block, 0, 2);
		world.setBlock(i + 22, j + 8, k + 25, sculk_block, 0, 2);
		world.setBlock(i + 22, j + 8, k + 26, sculk_block, 0, 2);
		world.setBlock(i + 11, j + 9, k + 0, sculk_block, 0, 2);
		world.setBlock(i + 12, j + 9, k + 1, sculk_block, 0, 2);
		world.setBlock(i + 12, j + 9, k + 2, sculk_block, 0, 2);
		world.setBlock(i + 13, j + 9, k + 3, sculk_block, 0, 2);
		world.setBlock(i + 14, j + 9, k + 4, sculk_block, 0, 2);
		world.setBlock(i + 14, j + 9, k + 5, sculk_block, 0, 2);
		world.setBlock(i + 15, j + 9, k + 6, sculk_block, 0, 2);
		world.setBlock(i + 16, j + 9, k + 7, sculk_block, 0, 2);
		world.setBlock(i + 16, j + 9, k + 8, sculk_block, 0, 2);
		world.setBlock(i + 17, j + 9, k + 9, sculk_block, 0, 2);
		world.setBlock(i + 17, j + 9, k + 10, sculk_block, 0, 2);
		world.setBlock(i + 18, j + 9, k + 11, sculk_block, 0, 2);
		world.setBlock(i + 18, j + 9, k + 12, sculk_block, 0, 2);
		world.setBlock(i + 19, j + 9, k + 13, sculk_block, 0, 2);
		world.setBlock(i + 19, j + 9, k + 14, sculk_block, 0, 2);
		world.setBlock(i + 20, j + 9, k + 15, sculk_block, 0, 2);
		world.setBlock(i + 20, j + 9, k + 16, sculk_block, 0, 2);
		world.setBlock(i + 20, j + 9, k + 17, sculk_block, 0, 2);
		world.setBlock(i + 21, j + 9, k + 18, sculk_block, 0, 2);
		world.setBlock(i + 21, j + 9, k + 19, sculk_block, 0, 2);
		world.setBlock(i + 21, j + 9, k + 20, sculk_block, 0, 2);
		world.setBlock(i + 21, j + 9, k + 21, NovaCraftBlocks.sculk_sensor, 0, 2);
		world.setBlock(i + 22, j + 9, k + 21, sculk_block, 0, 2);
		world.setBlock(i + 22, j + 9, k + 22, sculk_block, 0, 2);
		world.setBlock(i + 22, j + 9, k + 23, sculk_block, 0, 2);
		world.setBlock(i + 22, j + 9, k + 24, sculk_block, 0, 2);
		world.setBlock(i + 22, j + 9, k + 25, sculk_block, 0, 2);
		world.setBlock(i + 11, j + 10, k + 0, sculk_block, 0, 2);
		world.setBlock(i + 12, j + 10, k + 1, sculk_block, 0, 2);
		world.setBlock(i + 13, j + 10, k + 2, sculk_block, 0, 2);
		world.setBlock(i + 13, j + 10, k + 3, sculk_block, 0, 2);
		world.setBlock(i + 14, j + 10, k + 4, sculk_block, 0, 2);
		world.setBlock(i + 15, j + 10, k + 5, sculk_block, 0, 2);
		world.setBlock(i + 15, j + 10, k + 6, sculk_block, 0, 2);
		world.setBlock(i + 16, j + 10, k + 7, sculk_block, 0, 2);
		world.setBlock(i + 16, j + 10, k + 8, sculk_block, 0, 2);
		world.setBlock(i + 17, j + 10, k + 9, sculk_block, 0, 2);
		world.setBlock(i + 17, j + 10, k + 10, sculk_block, 0, 2);
		world.setBlock(i + 18, j + 10, k + 11, sculk_block, 0, 2);
		world.setBlock(i + 18, j + 10, k + 12, sculk_block, 0, 2);
		world.setBlock(i + 19, j + 10, k + 13, sculk_block, 0, 2);
		world.setBlock(i + 19, j + 10, k + 14, sculk_block, 0, 2);
		world.setBlock(i + 20, j + 10, k + 15, sculk_block, 0, 2);
		world.setBlock(i + 20, j + 10, k + 16, sculk_block, 0, 2);
		world.setBlock(i + 20, j + 10, k + 17, sculk_block, 0, 2);
		world.setBlock(i + 21, j + 10, k + 18, sculk_block, 0, 2);
		world.setBlock(i + 21, j + 10, k + 19, sculk_block, 0, 2);
		world.setBlock(i + 21, j + 10, k + 20, sculk_block, 0, 2);
		world.setBlock(i + 22, j + 10, k + 21, sculk_block, 0, 2);
		world.setBlock(i + 22, j + 10, k + 22, sculk_block, 0, 2);
		world.setBlock(i + 22, j + 10, k + 23, sculk_block, 0, 2);
		world.setBlock(i + 22, j + 10, k + 24, sculk_block, 0, 2);
		world.setBlock(i + 11, j + 11, k + 0, sculk_block, 0, 2);
		world.setBlock(i + 12, j + 11, k + 1, sculk_block, 0, 2);
		world.setBlock(i + 12, j + 11, k + 2, sculk_block, 0, 2);
		world.setBlock(i + 13, j + 11, k + 3, sculk_block, 0, 2);
		world.setBlock(i + 14, j + 11, k + 4, sculk_block, 0, 2);
		world.setBlock(i + 14, j + 11, k + 5, sculk_block, 0, 2);
		world.setBlock(i + 15, j + 11, k + 6, sculk_block, 0, 2);
		world.setBlock(i + 16, j + 11, k + 7, sculk_block, 0, 2);
		world.setBlock(i + 16, j + 11, k + 8, sculk_block, 0, 2);
		world.setBlock(i + 17, j + 11, k + 9, sculk_block, 0, 2);
		world.setBlock(i + 17, j + 11, k + 10, sculk_block, 0, 2);
		world.setBlock(i + 18, j + 11, k + 11, sculk_block, 0, 2);
		world.setBlock(i + 18, j + 11, k + 12, sculk_block, 0, 2);
		world.setBlock(i + 19, j + 11, k + 13, sculk_block, 0, 2);
		world.setBlock(i + 19, j + 11, k + 14, sculk_block, 0, 2);
		world.setBlock(i + 20, j + 11, k + 15, sculk_block, 0, 2);
		world.setBlock(i + 20, j + 11, k + 16, sculk_block, 0, 2);
		world.setBlock(i + 20, j + 11, k + 17, sculk_block, 0, 2);
		world.setBlock(i + 21, j + 11, k + 18, sculk_block, 0, 2);
		world.setBlock(i + 21, j + 11, k + 19, sculk_block, 0, 2);
		world.setBlock(i + 21, j + 11, k + 20, sculk_block, 0, 2);
		world.setBlock(i + 22, j + 11, k + 21, sculk_block, 0, 2);
		world.setBlock(i + 22, j + 11, k + 22, sculk_block, 0, 2);
		world.setBlock(i + 22, j + 11, k + 23, sculk_block, 0, 2);
		world.setBlock(i + 22, j + 11, k + 24, sculk_block, 0, 2);
		world.setBlock(i + 22, j + 11, k + 25, sculk_block, 0, 2);
		world.setBlock(i + 11, j + 12, k + 1, sculk_block, 0, 2);
		world.setBlock(i + 12, j + 12, k + 2, sculk_block, 0, 2);
		world.setBlock(i + 13, j + 12, k + 3, sculk_block, 0, 2);
		world.setBlock(i + 13, j + 12, k + 4, sculk_block, 0, 2);
		world.setBlock(i + 14, j + 12, k + 5, sculk_block, 0, 2);
		world.setBlock(i + 15, j + 12, k + 6, sculk_block, 0, 2);
		world.setBlock(i + 15, j + 12, k + 7, sculk_block, 0, 2);
		world.setBlock(i + 16, j + 12, k + 8, sculk_block, 0, 2);
		world.setBlock(i + 17, j + 12, k + 9, sculk_block, 0, 2);
		world.setBlock(i + 17, j + 12, k + 10, sculk_block, 0, 2);
		world.setBlock(i + 17, j + 12, k + 11, NovaCraftBlocks.sculk_tentacle_2, 0, 2);
		world.setBlock(i + 18, j + 12, k + 11, sculk_block, 0, 2);
		world.setBlock(i + 18, j + 12, k + 12, sculk_block, 0, 2);
		world.setBlock(i + 18, j + 12, k + 13, sculk_block, 0, 2);
		world.setBlock(i + 19, j + 12, k + 14, sculk_block, 0, 2);
		world.setBlock(i + 19, j + 12, k + 15, sculk_block, 0, 2);
		world.setBlock(i + 20, j + 12, k + 16, sculk_block, 0, 2);
		world.setBlock(i + 20, j + 12, k + 17, sculk_block, 0, 2);
		world.setBlock(i + 20, j + 12, k + 18, sculk_block, 0, 2);
		world.setBlock(i + 21, j + 12, k + 19, sculk_block, 0, 2);
		world.setBlock(i + 21, j + 12, k + 20, sculk_block, 0, 2);
		world.setBlock(i + 21, j + 12, k + 21, sculk_block, 0, 2);
		world.setBlock(i + 22, j + 12, k + 22, sculk_block, 0, 2);
		world.setBlock(i + 22, j + 12, k + 23, sculk_block, 0, 2);
		world.setBlock(i + 22, j + 12, k + 24, sculk_block, 0, 2);
		world.setBlock(i + 22, j + 12, k + 25, sculk_block, 0, 2);
		world.setBlock(i + 22, j + 12, k + 26, sculk_block, 0, 2);
		world.setBlock(i + 11, j + 13, k + 1, sculk_block, 0, 2);
		world.setBlock(i + 11, j + 13, k + 2, sculk_block, 0, 2);
		world.setBlock(i + 12, j + 13, k + 3, sculk_block, 0, 2);
		world.setBlock(i + 13, j + 13, k + 4, sculk_block, 0, 2);
		world.setBlock(i + 13, j + 13, k + 5, NovaCraftBlocks.sculk_tentacle_2, 0, 2);
		world.setBlock(i + 14, j + 13, k + 5, sculk_block, 0, 2);
		world.setBlock(i + 14, j + 13, k + 6, sculk_block, 0, 2);
		world.setBlock(i + 15, j + 13, k + 7, sculk_block, 0, 2);
		world.setBlock(i + 15, j + 13, k + 8, sculk_block, 0, 2);
		world.setBlock(i + 16, j + 13, k + 9, sculk_block, 0, 2);
		world.setBlock(i + 17, j + 13, k + 10, sculk_block, 0, 2);
		world.setBlock(i + 17, j + 13, k + 11, sculk_block, 0, 2);
		world.setBlock(i + 18, j + 13, k + 12, sculk_block, 0, 2);
		world.setBlock(i + 17, j + 13, k + 13, NovaCraftBlocks.sculk_vein, 0, 2);
		world.setBlock(i + 18, j + 13, k + 13, sculk_block, 0, 2);
		world.setBlock(i + 18, j + 13, k + 14, sculk_block, 0, 2);
		world.setBlock(i + 19, j + 13, k + 15, sculk_block, 0, 2);
		world.setBlock(i + 19, j + 13, k + 16, sculk_block, 0, 2);
		world.setBlock(i + 20, j + 13, k + 17, sculk_block, 0, 2);
		world.setBlock(i + 20, j + 13, k + 18, sculk_block, 0, 2);
		world.setBlock(i + 20, j + 13, k + 19, sculk_block, 0, 2);
		world.setBlock(i + 21, j + 13, k + 20, sculk_block, 0, 2);
		world.setBlock(i + 20, j + 13, k + 21, NovaCraftBlocks.sculk_tentacle_2, 0, 2);
		world.setBlock(i + 21, j + 13, k + 21, sculk_block, 0, 2);
		world.setBlock(i + 21, j + 13, k + 22, sculk_block, 0, 2);
		world.setBlock(i + 21, j + 13, k + 23, sculk_block, 0, 2);
		world.setBlock(i + 22, j + 13, k + 24, sculk_block, 0, 2);
		world.setBlock(i + 22, j + 13, k + 25, sculk_block, 0, 2);
		world.setBlock(i + 22, j + 13, k + 26, sculk_block, 0, 2);
		world.setBlock(i + 9, j + 14, k + 0, sculk_block, 0, 2);
		world.setBlock(i + 10, j + 14, k + 1, sculk_block, 0, 2);
		world.setBlock(i + 10, j + 14, k + 2, NovaCraftBlocks.sculk_tentacle_2, 0, 2);
		world.setBlock(i + 11, j + 14, k + 2, sculk_block, 0, 2);
		world.setBlock(i + 11, j + 14, k + 3, sculk_block, 0, 2);
		world.setBlock(i + 12, j + 14, k + 4, sculk_block, 0, 2);
		world.setBlock(i + 12, j + 14, k + 5, NovaCraftBlocks.sculk_spike, 0, 2);
		world.setBlock(i + 13, j + 14, k + 5, sculk_block, 0, 2);
		world.setBlock(i + 13, j + 14, k + 6, sculk_block, 0, 2);
		world.setBlock(i + 14, j + 14, k + 7, sculk_block, 0, 2);
		world.setBlock(i + 15, j + 14, k + 8, sculk_block, 0, 2);
		world.setBlock(i + 15, j + 14, k + 9, sculk_block, 0, 2);
		world.setBlock(i + 16, j + 14, k + 10, sculk_block, 0, 2);
		world.setBlock(i + 16, j + 14, k + 11, sculk_block, 0, 2);
		world.setBlock(i + 17, j + 14, k + 12, sculk_block, 0, 2);
		world.setBlock(i + 17, j + 14, k + 13, sculk_block, 0, 2);
		world.setBlock(i + 18, j + 14, k + 14, sculk_block, 0, 2);
		world.setBlock(i + 18, j + 14, k + 15, sculk_block, 0, 2);
		world.setBlock(i + 18, j + 14, k + 16, sculk_block, 0, 2);
		world.setBlock(i + 18, j + 14, k + 17, NovaCraftBlocks.sculk_vein, 0, 2);
		world.setBlock(i + 19, j + 14, k + 17, sculk_block, 0, 2);
		world.setBlock(i + 19, j + 14, k + 18, sculk_block, 0, 2);
		world.setBlock(i + 20, j + 14, k + 19, sculk_block, 0, 2);
		world.setBlock(i + 20, j + 14, k + 20, sculk_block, 0, 2);
		world.setBlock(i + 20, j + 14, k + 21, sculk_block, 0, 2);
		world.setBlock(i + 20, j + 14, k + 22, sculk_block, 0, 2);
		world.setBlock(i + 21, j + 14, k + 23, sculk_block, 0, 2);
		world.setBlock(i + 21, j + 14, k + 24, sculk_block, 0, 2);
		world.setBlock(i + 21, j + 14, k + 25, sculk_block, 0, 2);
		world.setBlock(i + 21, j + 14, k + 26, sculk_block, 0, 2);
		world.setBlock(i + 8, j + 15, k + 0, sculk_block, 0, 2);
		world.setBlock(i + 9, j + 15, k + 1, sculk_block, 0, 2);
		world.setBlock(i + 9, j + 15, k + 2, sculk_block, 0, 2);
		world.setBlock(i + 10, j + 15, k + 2, sculk_block, 0, 2);
		world.setBlock(i + 10, j + 15, k + 3, sculk_block, 0, 2);
		world.setBlock(i + 11, j + 15, k + 4, sculk_block, 0, 2);
		world.setBlock(i + 12, j + 15, k + 5, sculk_block, 0, 2);
		world.setBlock(i + 12, j + 15, k + 6, sculk_block, 0, 2);
		world.setBlock(i + 13, j + 15, k + 7, sculk_block, 0, 2);
		world.setBlock(i + 14, j + 15, k + 8, sculk_block, 0, 2);
		world.setBlock(i + 14, j + 15, k + 9, sculk_block, 0, 2);
		world.setBlock(i + 14, j + 15, k + 10, NovaCraftBlocks.sculk_vein, 0, 2);
		world.setBlock(i + 15, j + 15, k + 10, sculk_block, 0, 2);
		world.setBlock(i + 15, j + 15, k + 11, sculk_block, 0, 2);
		world.setBlock(i + 16, j + 15, k + 12, sculk_block, 0, 2);
		world.setBlock(i + 16, j + 15, k + 13, sculk_block, 0, 2);
		world.setBlock(i + 17, j + 15, k + 14, sculk_block, 0, 2);
		world.setBlock(i + 17, j + 15, k + 15, sculk_block, 0, 2);
		world.setBlock(i + 18, j + 15, k + 16, sculk_block, 0, 2);
		world.setBlock(i + 18, j + 15, k + 17, sculk_block, 0, 2);
		world.setBlock(i + 18, j + 15, k + 18, sculk_block, 0, 2);
		world.setBlock(i + 19, j + 15, k + 19, sculk_block, 0, 2);
		world.setBlock(i + 18, j + 15, k + 20, NovaCraftBlocks.sculk_spike, 0, 2);
		world.setBlock(i + 19, j + 15, k + 20, sculk_block, 0, 2);
		world.setBlock(i + 19, j + 15, k + 21, sculk_block, 0, 2);
		world.setBlock(i + 19, j + 15, k + 22, sculk_block, 0, 2);
		world.setBlock(i + 20, j + 15, k + 23, sculk_block, 0, 2);
		world.setBlock(i + 20, j + 15, k + 24, sculk_block, 0, 2);
		world.setBlock(i + 19, j + 15, k + 25, NovaCraftBlocks.sculk_tentacle_2, 0, 2);
		world.setBlock(i + 20, j + 15, k + 25, sculk_block, 0, 2);
		world.setBlock(i + 20, j + 15, k + 26, sculk_block, 0, 2);
		world.setBlock(i + 6, j + 16, k + 0, sculk_block, 0, 2);
		world.setBlock(i + 7, j + 16, k + 0, sculk_block, 0, 2);
		world.setBlock(i + 7, j + 16, k + 1, sculk_block, 0, 2);
		world.setBlock(i + 8, j + 16, k + 1, sculk_block, 0, 2);
		world.setBlock(i + 8, j + 16, k + 2, sculk_block, 0, 2);
		world.setBlock(i + 9, j + 16, k + 3, sculk_block, 0, 2);
		world.setBlock(i + 9, j + 16, k + 4, NovaCraftBlocks.sculk_vein, 0, 2);
		world.setBlock(i + 10, j + 16, k + 4, sculk_block, 0, 2);
		world.setBlock(i + 10, j + 16, k + 5, sculk_block, 0, 2);
		world.setBlock(i + 11, j + 16, k + 5, sculk_block, 0, 2);
		world.setBlock(i + 10, j + 16, k + 6, NovaCraftBlocks.sculk_tentacle_2, 0, 2);
		world.setBlock(i + 11, j + 16, k + 6, sculk_block, 0, 2);
		world.setBlock(i + 12, j + 16, k + 7, sculk_block, 0, 2);
		world.setBlock(i + 11, j + 16, k + 8, NovaCraftBlocks.sculk_vein, 0, 2);
		world.setBlock(i + 12, j + 16, k + 8, sculk_block, 0, 2);
		world.setBlock(i + 13, j + 16, k + 8, sculk_block, 0, 2);
		world.setBlock(i + 14, j + 16, k + 9, sculk_block, 0, 2);
		world.setBlock(i + 14, j + 16, k + 10, sculk_block, 0, 2);
		world.setBlock(i + 14, j + 16, k + 11, sculk_block, 0, 2);
		world.setBlock(i + 15, j + 16, k + 12, sculk_block, 0, 2);
		world.setBlock(i + 14, j + 16, k + 13, NovaCraftBlocks.sculk_spike, 0, 2);
		world.setBlock(i + 15, j + 16, k + 13, sculk_block, 0, 2);
		world.setBlock(i + 15, j + 16, k + 14, sculk_block, 0, 2);
		world.setBlock(i + 16, j + 16, k + 14, sculk_block, 0, 2);
		world.setBlock(i + 16, j + 16, k + 15, sculk_block, 0, 2);
		world.setBlock(i + 16, j + 16, k + 16, sculk_block, 0, 2);
		world.setBlock(i + 17, j + 16, k + 16, sculk_block, 0, 2);
		world.setBlock(i + 17, j + 16, k + 17, sculk_block, 0, 2);
		world.setBlock(i + 17, j + 16, k + 18, sculk_block, 0, 2);
		world.setBlock(i + 17, j + 16, k + 19, sculk_block, 0, 2);
		world.setBlock(i + 18, j + 16, k + 19, sculk_block, 0, 2);
		world.setBlock(i + 18, j + 16, k + 20, sculk_block, 0, 2);
		world.setBlock(i + 17, j + 16, k + 21, NovaCraftBlocks.sculk_vein, 0, 2);
		world.setBlock(i + 18, j + 16, k + 21, sculk_block, 0, 2);
		world.setBlock(i + 18, j + 16, k + 22, sculk_block, 0, 2);
		world.setBlock(i + 19, j + 16, k + 23, sculk_block, 0, 2);
		world.setBlock(i + 19, j + 16, k + 24, sculk_block, 0, 2);
		world.setBlock(i + 19, j + 16, k + 25, sculk_block, 0, 2);
		world.setBlock(i + 5, j + 17, k + 1, sculk_block, 0, 2);
		world.setBlock(i + 6, j + 17, k + 1, sculk_block, 0, 2);
		world.setBlock(i + 6, j + 17, k + 2, sculk_block, 0, 2);
		world.setBlock(i + 7, j + 17, k + 2, sculk_block, 0, 2);
		world.setBlock(i + 7, j + 17, k + 3, sculk_block, 0, 2);
		world.setBlock(i + 8, j + 17, k + 3, sculk_block, 0, 2);
		world.setBlock(i + 7, j + 17, k + 4, NovaCraftBlocks.sculk_tentacle_2, 0, 2);
		world.setBlock(i + 8, j + 17, k + 4, sculk_block, 0, 2);
		world.setBlock(i + 9, j + 17, k + 4, sculk_block, 0, 2);
		world.setBlock(i + 9, j + 17, k + 5, sculk_block, 0, 2);
		world.setBlock(i + 9, j + 17, k + 6, sculk_block, 0, 2);
		world.setBlock(i + 10, j + 17, k + 6, sculk_block, 0, 2);
		world.setBlock(i + 10, j + 17, k + 7, sculk_block, 0, 2);
		world.setBlock(i + 11, j + 17, k + 7, sculk_block, 0, 2);
		world.setBlock(i + 11, j + 17, k + 8, sculk_block, 0, 2);
		world.setBlock(i + 9, j + 17, k + 9, NovaCraftBlocks.sculk_vein, 0, 2);
		world.setBlock(i + 11, j + 17, k + 9, sculk_block, 0, 2);
		world.setBlock(i + 12, j + 17, k + 9, sculk_block, 0, 2);
		world.setBlock(i + 13, j + 17, k + 9, sculk_block, 0, 2);
		world.setBlock(i + 12, j + 17, k + 10, sculk_block, 0, 2);
		world.setBlock(i + 13, j + 17, k + 10, sculk_block, 0, 2);
		world.setBlock(i + 13, j + 17, k + 11, sculk_block, 0, 2);
		world.setBlock(i + 12, j + 17, k + 12, NovaCraftBlocks.sculk_vein, 0, 2);
		world.setBlock(i + 13, j + 17, k + 12, sculk_block, 0, 2);
		world.setBlock(i + 14, j + 17, k + 12, sculk_block, 0, 2);
		world.setBlock(i + 14, j + 17, k + 13, sculk_block, 0, 2);
		world.setBlock(i + 14, j + 17, k + 14, sculk_block, 0, 2);
		world.setBlock(i + 14, j + 17, k + 15, sculk_block, 0, 2);
		world.setBlock(i + 15, j + 17, k + 15, sculk_block, 0, 2);
		world.setBlock(i + 15, j + 17, k + 16, sculk_block, 0, 2);
		world.setBlock(i + 15, j + 17, k + 17, sculk_block, 0, 2);
		world.setBlock(i + 16, j + 17, k + 17, sculk_block, 0, 2);
		world.setBlock(i + 15, j + 17, k + 18, NovaCraftBlocks.sculk_tentacle_2, 0, 2);
		world.setBlock(i + 16, j + 17, k + 18, sculk_block, 0, 2);
		world.setBlock(i + 16, j + 17, k + 19, sculk_block, 0, 2);
		world.setBlock(i + 16, j + 17, k + 20, sculk_block, 0, 2);
		world.setBlock(i + 17, j + 17, k + 20, sculk_block, 0, 2);
		world.setBlock(i + 17, j + 17, k + 21, sculk_block, 0, 2);
		world.setBlock(i + 17, j + 17, k + 22, sculk_block, 0, 2);
		world.setBlock(i + 17, j + 17, k + 23, sculk_block, 0, 2);
		world.setBlock(i + 18, j + 17, k + 23, sculk_block, 0, 2);
		world.setBlock(i + 17, j + 17, k + 24, sculk_block, 0, 2);
		world.setBlock(i + 18, j + 17, k + 24, sculk_block, 0, 2);
		world.setBlock(i + 4, j + 18, k + 2, sculk_block, 0, 2);
		world.setBlock(i + 5, j + 18, k + 2, sculk_block, 0, 2);
		world.setBlock(i + 5, j + 18, k + 3, sculk_block, 0, 2);
		world.setBlock(i + 6, j + 18, k + 3, sculk_block, 0, 2);
		world.setBlock(i + 4, j + 18, k + 4, NovaCraftBlocks.sculk_vein, 0, 2);
		world.setBlock(i + 6, j + 18, k + 4, sculk_block, 0, 2);
		world.setBlock(i + 7, j + 18, k + 4, sculk_block, 0, 2);
		world.setBlock(i + 7, j + 18, k + 5, sculk_block, 0, 2);
		world.setBlock(i + 8, j + 18, k + 5, sculk_block, 0, 2);
		world.setBlock(i + 7, j + 18, k + 6, sculk_block, 0, 2);
		world.setBlock(i + 8, j + 18, k + 6, sculk_block, 0, 2);
		world.setBlock(i + 8, j + 18, k + 7, sculk_block, 0, 2);
		world.setBlock(i + 9, j + 18, k + 7, sculk_block, 0, 2);
		world.setBlock(i + 9, j + 18, k + 8, sculk_block, 0, 2);
		world.setBlock(i + 10, j + 18, k + 8, sculk_block, 0, 2);
		world.setBlock(i + 8, j + 18, k + 9, NovaCraftBlocks.sculk_vein, 0, 2);
		world.setBlock(i + 9, j + 18, k + 9, sculk_block, 0, 2);
		world.setBlock(i + 10, j + 18, k + 9, sculk_block, 0, 2);
		world.setBlock(i + 10, j + 18, k + 10, sculk_block, 0, 2);
		world.setBlock(i + 11, j + 18, k + 10, sculk_block, 0, 2);
		world.setBlock(i + 11, j + 18, k + 11, sculk_block, 0, 2);
		world.setBlock(i + 12, j + 18, k + 11, sculk_block, 0, 2);
		world.setBlock(i + 11, j + 18, k + 12, sculk_block, 0, 2);
		world.setBlock(i + 12, j + 18, k + 12, sculk_block, 0, 2);
		world.setBlock(i + 12, j + 18, k + 13, sculk_block, 0, 2);
		world.setBlock(i + 13, j + 18, k + 13, sculk_block, 0, 2);
		world.setBlock(i + 12, j + 18, k + 14, sculk_block, 0, 2);
		world.setBlock(i + 13, j + 18, k + 14, sculk_block, 0, 2);
		world.setBlock(i + 13, j + 18, k + 15, sculk_block, 0, 2);
		world.setBlock(i + 13, j + 18, k + 16, sculk_block, 0, 2);
		world.setBlock(i + 14, j + 18, k + 16, sculk_block, 0, 2);
		world.setBlock(i + 14, j + 18, k + 17, sculk_block, 0, 2);
		world.setBlock(i + 12, j + 18, k + 18, NovaCraftBlocks.sculk_vein, 0, 2);
		world.setBlock(i + 14, j + 18, k + 18, sculk_block, 0, 2);
		world.setBlock(i + 15, j + 18, k + 18, sculk_block, 0, 2);
		world.setBlock(i + 15, j + 18, k + 19, sculk_block, 0, 2);
		world.setBlock(i + 15, j + 18, k + 20, sculk_block, 0, 2);
		world.setBlock(i + 15, j + 18, k + 21, sculk_block, 0, 2);
		world.setBlock(i + 16, j + 18, k + 21, sculk_block, 0, 2);
		world.setBlock(i + 15, j + 18, k + 22, sculk_block, 0, 2);
		world.setBlock(i + 16, j + 18, k + 22, sculk_block, 0, 2);
		world.setBlock(i + 15, j + 18, k + 23, NovaCraftBlocks.sculk_vein, 0, 2);
		world.setBlock(i + 16, j + 18, k + 23, sculk_block, 0, 2);
		world.setBlock(i + 16, j + 18, k + 24, sculk_block, 0, 2);
		world.setBlock(i + 14, j + 18, k + 25, NovaCraftBlocks.sculk_spike, 0, 2);
		world.setBlock(i + 16, j + 18, k + 25, sculk_block, 0, 2);
		world.setBlock(i + 3, j + 19, k + 2, sculk_block, 0, 2);
		world.setBlock(i + 2, j + 19, k + 3, sculk_block, 0, 2);
		world.setBlock(i + 3, j + 19, k + 3, sculk_block, 0, 2);
		world.setBlock(i + 4, j + 19, k + 3, sculk_block, 0, 2);
		world.setBlock(i + 3, j + 19, k + 4, sculk_block, 0, 2);
		world.setBlock(i + 4, j + 19, k + 4, sculk_block, 0, 2);
		world.setBlock(i + 5, j + 19, k + 4, sculk_block, 0, 2);
		world.setBlock(i + 4, j + 19, k + 5, sculk_block, 0, 2);
		world.setBlock(i + 5, j + 19, k + 5, sculk_block, 0, 2);
		world.setBlock(i + 6, j + 19, k + 5, sculk_block, 0, 2);
		world.setBlock(i + 5, j + 19, k + 6, sculk_block, 0, 2);
		world.setBlock(i + 6, j + 19, k + 6, sculk_block, 0, 2);
		world.setBlock(i + 6, j + 19, k + 7, sculk_block, 0, 2);
		world.setBlock(i + 7, j + 19, k + 7, sculk_block, 0, 2);
		world.setBlock(i + 7, j + 19, k + 8, sculk_block, 0, 2);
		world.setBlock(i + 8, j + 19, k + 8, sculk_block, 0, 2);
		world.setBlock(i + 7, j + 19, k + 9, sculk_block, 0, 2);
		world.setBlock(i + 8, j + 19, k + 9, sculk_block, 0, 2);
		world.setBlock(i + 8, j + 19, k + 10, sculk_block, 0, 2);
		world.setBlock(i + 9, j + 19, k + 10, sculk_block, 0, 2);
		world.setBlock(i + 9, j + 19, k + 11, sculk_block, 0, 2);
		world.setBlock(i + 10, j + 19, k + 11, sculk_block, 0, 2);
		world.setBlock(i + 9, j + 19, k + 12, sculk_block, 0, 2);
		world.setBlock(i + 10, j + 19, k + 12, sculk_block, 0, 2);
		world.setBlock(i + 10, j + 19, k + 13, sculk_block, 0, 2);
		world.setBlock(i + 11, j + 19, k + 13, sculk_block, 0, 2);
		world.setBlock(i + 10, j + 19, k + 14, sculk_block, 0, 2);
		world.setBlock(i + 11, j + 19, k + 14, sculk_block, 0, 2);
		world.setBlock(i + 11, j + 19, k + 15, sculk_block, 0, 2);
		world.setBlock(i + 12, j + 19, k + 15, sculk_block, 0, 2);
		world.setBlock(i + 11, j + 19, k + 16, sculk_block, 0, 2);
		world.setBlock(i + 12, j + 19, k + 16, sculk_block, 0, 2);
		world.setBlock(i + 12, j + 19, k + 17, sculk_block, 0, 2);
		world.setBlock(i + 13, j + 19, k + 17, sculk_block, 0, 2);
		world.setBlock(i + 12, j + 19, k + 18, sculk_block, 0, 2);
		world.setBlock(i + 13, j + 19, k + 18, sculk_block, 0, 2);
		world.setBlock(i + 12, j + 19, k + 19, sculk_block, 0, 2);
		world.setBlock(i + 13, j + 19, k + 19, sculk_block, 0, 2);
		world.setBlock(i + 14, j + 19, k + 19, sculk_block, 0, 2);
		world.setBlock(i + 13, j + 19, k + 20, sculk_block, 0, 2);
		world.setBlock(i + 14, j + 19, k + 20, sculk_block, 0, 2);
		world.setBlock(i + 13, j + 19, k + 21, sculk_block, 0, 2);
		world.setBlock(i + 14, j + 19, k + 21, sculk_block, 0, 2);
		world.setBlock(i + 13, j + 19, k + 22, sculk_block, 0, 2);
		world.setBlock(i + 14, j + 19, k + 22, sculk_block, 0, 2);
		world.setBlock(i + 14, j + 19, k + 23, sculk_block, 0, 2);
		world.setBlock(i + 15, j + 19, k + 23, sculk_block, 0, 2);
		world.setBlock(i + 14, j + 19, k + 24, sculk_block, 0, 2);
		world.setBlock(i + 15, j + 19, k + 24, sculk_block, 0, 2);
		world.setBlock(i + 14, j + 19, k + 25, sculk_block, 0, 2);
		world.setBlock(i + 15, j + 19, k + 25, sculk_block, 0, 2);
		world.setBlock(i + 14, j + 19, k + 26, sculk_block, 0, 2);
		world.setBlock(i + 15, j + 19, k + 26, sculk_block, 0, 2);
		world.setBlock(i + 14, j + 19, k + 27, sculk_block, 0, 2);
    	
    	return true;
    }

}
