package com.NovaCraft.world.ancient_city;

import net.minecraft.world.gen.feature.*;
import net.minecraft.block.*;
import net.minecraft.enchantment.Enchantment;
import net.minecraft.enchantment.EnchantmentData;
import net.minecraft.world.*;
import java.util.*;

import com.NovaCraft.Items.NovaCraftItems;
import com.NovaCraft.registry.OtherModBlocks;
import com.NovaCraft.registry.OtherModItems;
import com.NovaCraftBlocks.NovaCraftBlocks;

import cpw.mods.fml.common.Loader;
import net.minecraft.init.*;
import net.minecraft.item.ItemStack;
import net.minecraft.tileentity.TileEntityChest;
import net.minecraft.tileentity.TileEntityMobSpawner;
import net.minecraft.util.MathHelper;

public class AncientCityFurnaceRoomGen1 extends WorldGenerator
{
	public AncientCityFurnaceRoomGen1() {

	}
	
	private static final Block cobbled_deepslate = OtherModBlocks.cobbled_deepslate;
	private static final Block deepslate = OtherModBlocks.deepslate;
	private static final Block sculk_block = NovaCraftBlocks.sculk_block;
	private static final Block soul_lantern = OtherModBlocks.soul_lantern; //1
	private static final Block soul_sand = Blocks.netherrack;
	
	private static final Block polished_deepslate = OtherModBlocks.polished_deepslate;
	private static final Block deepslate_brick_slab = OtherModBlocks.deepslate_brick_slab;
	private static final Block deepslate_tile_stairs = OtherModBlocks.deepslate_tile_stairs;
	private static final Block deepslate_brick_stairs = OtherModBlocks.deepslate_brick_stairs;
	private static final Block polished_deepslate_stairs = OtherModBlocks.polished_deepslate_stairs;
	private static final Block deepslate_wall = OtherModBlocks.deepslate_wall;
	private static final Block deepslate_brick_wall = OtherModBlocks.deepslate_brick_wall;
	private static final Block fence_dark_oak = OtherModBlocks.fence_dark_oak;
	private static final Block blue_ice = OtherModBlocks.blue_ice;
	private static final Block iron_trapdoor = OtherModBlocks.iron_trapdoor;
	
	private static final Block deepslate_bricks = OtherModBlocks.deepslate_bricks;
	private static final Block cobbled_deepslate_stairs = OtherModBlocks.cobbled_deepslate_stairs;
	
	private static final Block basalt = OtherModBlocks.Basalt; //netherlicious
	private static final Block basalt1 = OtherModBlocks.basalt; //et futurum requiem
	
	//0 -> deepslate bricks
	//1 -> cracked deepslate bricks
	//2 -> deepslate tiles
	//3 -> cracked deepslate bricks
	//4 -> chiseled deepslate bricks
	
	 public boolean generate(final World world, final Random random, final int i, final int j, final int k) {
		 		
		 world.setBlock(i + 1, j + 0, k + 4, NovaCraftBlocks.nullstone_bricks, 0, 2);
			world.setBlock(i + 2, j + 0, k + 4, NovaCraftBlocks.nullstone_bricks, 0, 2);
			world.setBlock(i + 0, j + 0, k + 5, NovaCraftBlocks.nullstone_bricks, 0, 2);
			world.setBlock(i + 1, j + 0, k + 5, NovaCraftBlocks.nullstone_bricks, 0, 2);
			world.setBlock(i + 2, j + 0, k + 5, NovaCraftBlocks.nullstone_bricks, 0, 2);
			world.setBlock(i + 0, j + 0, k + 6, NovaCraftBlocks.nullstone_bricks, 0, 2);
			world.setBlock(i + 1, j + 0, k + 6, NovaCraftBlocks.nullstone_bricks, 0, 2);
			world.setBlock(i + 2, j + 0, k + 6, NovaCraftBlocks.nullstone_bricks, 0, 2);
			world.setBlock(i + 0, j + 0, k + 7, NovaCraftBlocks.nullstone_bricks, 0, 2);
			world.setBlock(i + 1, j + 0, k + 7, NovaCraftBlocks.nullstone_bricks, 0, 2);
			world.setBlock(i + 2, j + 0, k + 7, NovaCraftBlocks.nullstone_bricks, 0, 2);
			world.setBlock(i + 0, j + 0, k + 8, NovaCraftBlocks.nullstone_bricks, 0, 2);
			world.setBlock(i + 1, j + 0, k + 8, NovaCraftBlocks.nullstone_bricks, 0, 2);
			world.setBlock(i + 2, j + 0, k + 8, NovaCraftBlocks.nullstone_bricks, 0, 2);
			world.setBlock(i + 0, j + 0, k + 9, NovaCraftBlocks.nullstone_bricks, 0, 2);
			world.setBlock(i + 1, j + 0, k + 9, NovaCraftBlocks.nullstone_bricks, 0, 2);
			world.setBlock(i + 2, j + 0, k + 9, NovaCraftBlocks.nullstone_bricks, 0, 2);
			world.setBlock(i + 1, j + 0, k + 10, NovaCraftBlocks.nullstone_bricks, 0, 2);
			world.setBlock(i + 2, j + 0, k + 10, NovaCraftBlocks.nullstone_bricks, 0, 2);
			world.setBlock(i + 4, j + 1, k + 1, NovaCraftBlocks.nullstone_bricks, 0, 2);
			world.setBlock(i + 5, j + 1, k + 1, NovaCraftBlocks.nullstone_bricks, 0, 2);
			world.setBlock(i + 6, j + 1, k + 1, NovaCraftBlocks.nullstone_bricks, 0, 2);
			world.setBlock(i + 7, j + 1, k + 1, NovaCraftBlocks.nullstone_bricks, 0, 2);
			world.setBlock(i + 8, j + 1, k + 1, NovaCraftBlocks.nullstone_bricks, 0, 2);
			world.setBlock(i + 9, j + 1, k + 1, NovaCraftBlocks.nullstone_bricks, 0, 2);
			world.setBlock(i + 10, j + 1, k + 1, NovaCraftBlocks.nullstone_bricks, 0, 2);
			world.setBlock(i + 4, j + 1, k + 2, NovaCraftBlocks.nullstone_bricks, 0, 2);
			world.setBlock(i + 5, j + 1, k + 2, NovaCraftBlocks.nullstone_bricks, 0, 2);
			world.setBlock(i + 6, j + 1, k + 2, NovaCraftBlocks.nullstone_bricks, 0, 2);
			world.setBlock(i + 7, j + 1, k + 2, NovaCraftBlocks.nullstone_bricks, 0, 2);
			world.setBlock(i + 8, j + 1, k + 2, NovaCraftBlocks.nullstone_bricks, 0, 2);
			world.setBlock(i + 9, j + 1, k + 2, NovaCraftBlocks.nullstone_bricks, 0, 2);
			world.setBlock(i + 10, j + 1, k + 2, NovaCraftBlocks.nullstone_bricks, 0, 2);
			world.setBlock(i + 4, j + 1, k + 3, NovaCraftBlocks.nullstone_bricks, 0, 2);
			world.setBlock(i + 5, j + 1, k + 3, NovaCraftBlocks.nullstone_bricks, 0, 2);
			world.setBlock(i + 6, j + 1, k + 3, NovaCraftBlocks.nullstone_bricks, 0, 2);
			world.setBlock(i + 7, j + 1, k + 3, NovaCraftBlocks.nullstone_bricks, 0, 2);
			world.setBlock(i + 8, j + 1, k + 3, NovaCraftBlocks.nullstone_bricks, 0, 2);
			world.setBlock(i + 9, j + 1, k + 3, NovaCraftBlocks.nullstone_bricks, 0, 2);
			world.setBlock(i + 10, j + 1, k + 3, NovaCraftBlocks.nullstone_bricks, 0, 2);
			world.setBlock(i + 1, j + 1, k + 4, NovaCraftBlocks.nullstone_bricks, 0, 2);
			world.setBlock(i + 2, j + 1, k + 4, NovaCraftBlocks.nullstone_bricks, 0, 2);
			world.setBlock(i + 3, j + 1, k + 4, NovaCraftBlocks.nullstone_bricks, 0, 2);
			world.setBlock(i + 4, j + 1, k + 4, NovaCraftBlocks.nullstone_bricks, 0, 2);
			world.setBlock(i + 5, j + 1, k + 4, NovaCraftBlocks.nullstone_bricks, 0, 2);
			world.setBlock(i + 6, j + 1, k + 4, NovaCraftBlocks.nullstone_bricks, 0, 2);
			world.setBlock(i + 7, j + 1, k + 4, NovaCraftBlocks.nullstone_bricks, 0, 2);
			world.setBlock(i + 8, j + 1, k + 4, NovaCraftBlocks.nullstone_bricks, 0, 2);
			world.setBlock(i + 9, j + 1, k + 4, NovaCraftBlocks.nullstone_bricks, 0, 2);
			world.setBlock(i + 10, j + 1, k + 4, NovaCraftBlocks.nullstone_bricks, 0, 2);
			world.setBlock(i + 11, j + 1, k + 4, NovaCraftBlocks.nullstone_bricks, 0, 2);
			world.setBlock(i + 12, j + 1, k + 4, NovaCraftBlocks.nullstone_bricks, 0, 2);
			world.setBlock(i + 13, j + 1, k + 4, NovaCraftBlocks.nullstone_bricks, 0, 2);
			world.setBlock(i + 0, j + 1, k + 5, NovaCraftBlocks.nullstone_bricks, 0, 2);
			world.setBlock(i + 2, j + 1, k + 5, Blocks.air, 0, 2);
			world.setBlock(i + 3, j + 1, k + 5, NovaCraftBlocks.nullstone_bricks, 0, 2);
			world.setBlock(i + 4, j + 1, k + 5, NovaCraftBlocks.nullstone_bricks, 0, 2);
			world.setBlock(i + 5, j + 1, k + 5, NovaCraftBlocks.nullstone_bricks, 0, 2);
			world.setBlock(i + 6, j + 1, k + 5, NovaCraftBlocks.nullstone_bricks, 0, 2);
			world.setBlock(i + 7, j + 1, k + 5, NovaCraftBlocks.nullstone_bricks, 0, 2);
			world.setBlock(i + 8, j + 1, k + 5, NovaCraftBlocks.nullstone_bricks, 0, 2);
			world.setBlock(i + 9, j + 1, k + 5, NovaCraftBlocks.nullstone_bricks, 0, 2);
			world.setBlock(i + 10, j + 1, k + 5, NovaCraftBlocks.nullstone_bricks, 0, 2);
			world.setBlock(i + 11, j + 1, k + 5, NovaCraftBlocks.nullstone_bricks, 0, 2);
			world.setBlock(i + 12, j + 1, k + 5, NovaCraftBlocks.nullstone_bricks, 0, 2);
			world.setBlock(i + 13, j + 1, k + 5, NovaCraftBlocks.nullstone_bricks, 0, 2);
			world.setBlock(i + 0, j + 1, k + 6, NovaCraftBlocks.nullstone_bricks, 0, 2);
			world.setBlock(i + 2, j + 1, k + 6, Blocks.air, 0, 2);
			world.setBlock(i + 3, j + 1, k + 6, NovaCraftBlocks.nullstone_bricks, 0, 2);
			world.setBlock(i + 4, j + 1, k + 6, NovaCraftBlocks.nullstone_bricks, 0, 2);
			world.setBlock(i + 5, j + 1, k + 6, NovaCraftBlocks.nullstone_bricks, 0, 2);
			world.setBlock(i + 6, j + 1, k + 6, NovaCraftBlocks.nullstone_bricks, 0, 2);
			world.setBlock(i + 7, j + 1, k + 6, NovaCraftBlocks.nullstone_bricks, 0, 2);
			world.setBlock(i + 8, j + 1, k + 6, NovaCraftBlocks.nullstone_bricks, 0, 2);
			world.setBlock(i + 9, j + 1, k + 6, NovaCraftBlocks.nullstone_bricks, 0, 2);
			world.setBlock(i + 10, j + 1, k + 6, NovaCraftBlocks.nullstone_bricks, 0, 2);
			world.setBlock(i + 11, j + 1, k + 6, NovaCraftBlocks.nullstone_bricks, 0, 2);
			world.setBlock(i + 12, j + 1, k + 6, NovaCraftBlocks.nullstone_bricks, 0, 2);
			world.setBlock(i + 13, j + 1, k + 6, NovaCraftBlocks.nullstone_bricks, 0, 2);
			world.setBlock(i + 0, j + 1, k + 7, NovaCraftBlocks.nullstone_bricks, 0, 2);
			world.setBlock(i + 2, j + 1, k + 7, Blocks.air, 0, 2);
			world.setBlock(i + 3, j + 1, k + 7, NovaCraftBlocks.nullstone_bricks, 0, 2);
			world.setBlock(i + 4, j + 1, k + 7, NovaCraftBlocks.nullstone_bricks, 0, 2);
			world.setBlock(i + 5, j + 1, k + 7, NovaCraftBlocks.nullstone_bricks, 0, 2);
			world.setBlock(i + 6, j + 1, k + 7, NovaCraftBlocks.nullstone_bricks, 0, 2);
			world.setBlock(i + 7, j + 1, k + 7, NovaCraftBlocks.nullstone_bricks, 0, 2);
			world.setBlock(i + 8, j + 1, k + 7, NovaCraftBlocks.nullstone_bricks, 0, 2);
			world.setBlock(i + 9, j + 1, k + 7, NovaCraftBlocks.nullstone_bricks, 0, 2);
			world.setBlock(i + 10, j + 1, k + 7, NovaCraftBlocks.nullstone_bricks, 0, 2);
			world.setBlock(i + 11, j + 1, k + 7, NovaCraftBlocks.nullstone_bricks, 0, 2);
			world.setBlock(i + 12, j + 1, k + 7, NovaCraftBlocks.nullstone_bricks, 0, 2);
			world.setBlock(i + 13, j + 1, k + 7, NovaCraftBlocks.nullstone_bricks, 0, 2);
			world.setBlock(i + 0, j + 1, k + 8, NovaCraftBlocks.nullstone_bricks, 0, 2);
			world.setBlock(i + 2, j + 1, k + 8, Blocks.air, 0, 2);
			world.setBlock(i + 3, j + 1, k + 8, NovaCraftBlocks.nullstone_bricks, 0, 2);
			world.setBlock(i + 4, j + 1, k + 8, NovaCraftBlocks.nullstone_bricks, 0, 2);
			world.setBlock(i + 5, j + 1, k + 8, NovaCraftBlocks.nullstone_bricks, 0, 2);
			world.setBlock(i + 6, j + 1, k + 8, NovaCraftBlocks.nullstone_bricks, 0, 2);
			world.setBlock(i + 7, j + 1, k + 8, NovaCraftBlocks.nullstone_bricks, 0, 2);
			world.setBlock(i + 8, j + 1, k + 8, NovaCraftBlocks.nullstone_bricks, 0, 2);
			world.setBlock(i + 9, j + 1, k + 8, NovaCraftBlocks.nullstone_bricks, 0, 2);
			world.setBlock(i + 10, j + 1, k + 8, NovaCraftBlocks.nullstone_bricks, 0, 2);
			world.setBlock(i + 11, j + 1, k + 8, NovaCraftBlocks.nullstone_bricks, 0, 2);
			world.setBlock(i + 12, j + 1, k + 8, NovaCraftBlocks.nullstone_bricks, 0, 2);
			world.setBlock(i + 13, j + 1, k + 8, NovaCraftBlocks.nullstone_bricks, 0, 2);
			world.setBlock(i + 0, j + 1, k + 9, NovaCraftBlocks.nullstone_bricks, 0, 2);
			world.setBlock(i + 2, j + 1, k + 9, Blocks.air, 0, 2);
			world.setBlock(i + 3, j + 1, k + 9, NovaCraftBlocks.nullstone_bricks, 0, 2);
			world.setBlock(i + 4, j + 1, k + 9, NovaCraftBlocks.nullstone_bricks, 0, 2);
			world.setBlock(i + 5, j + 1, k + 9, NovaCraftBlocks.nullstone_bricks, 0, 2);
			world.setBlock(i + 6, j + 1, k + 9, NovaCraftBlocks.nullstone_bricks, 0, 2);
			world.setBlock(i + 7, j + 1, k + 9, NovaCraftBlocks.nullstone_bricks, 0, 2);
			world.setBlock(i + 8, j + 1, k + 9, NovaCraftBlocks.nullstone_bricks, 0, 2);
			world.setBlock(i + 9, j + 1, k + 9, NovaCraftBlocks.nullstone_bricks, 0, 2);
			world.setBlock(i + 10, j + 1, k + 9, NovaCraftBlocks.nullstone_bricks, 0, 2);
			world.setBlock(i + 11, j + 1, k + 9, NovaCraftBlocks.nullstone_bricks, 0, 2);
			world.setBlock(i + 12, j + 1, k + 9, NovaCraftBlocks.nullstone_bricks, 0, 2);
			world.setBlock(i + 13, j + 1, k + 9, NovaCraftBlocks.nullstone_bricks, 0, 2);
			world.setBlock(i + 1, j + 1, k + 10, NovaCraftBlocks.nullstone_bricks, 0, 2);
			world.setBlock(i + 2, j + 1, k + 10, NovaCraftBlocks.nullstone_bricks, 0, 2);
			world.setBlock(i + 3, j + 1, k + 10, NovaCraftBlocks.nullstone_bricks, 0, 2);
			world.setBlock(i + 4, j + 1, k + 10, NovaCraftBlocks.nullstone_bricks, 0, 2);
			world.setBlock(i + 5, j + 1, k + 10, NovaCraftBlocks.nullstone_bricks, 0, 2);
			world.setBlock(i + 6, j + 1, k + 10, NovaCraftBlocks.nullstone_bricks, 0, 2);
			world.setBlock(i + 7, j + 1, k + 10, NovaCraftBlocks.nullstone_bricks, 0, 2);
			world.setBlock(i + 8, j + 1, k + 10, NovaCraftBlocks.nullstone_bricks, 0, 2);
			world.setBlock(i + 9, j + 1, k + 10, NovaCraftBlocks.nullstone_bricks, 0, 2);
			world.setBlock(i + 10, j + 1, k + 10, NovaCraftBlocks.nullstone_bricks, 0, 2);
			world.setBlock(i + 11, j + 1, k + 10, NovaCraftBlocks.nullstone_bricks, 0, 2);
			world.setBlock(i + 12, j + 1, k + 10, NovaCraftBlocks.nullstone_bricks, 0, 2);
			world.setBlock(i + 13, j + 1, k + 10, NovaCraftBlocks.nullstone_bricks, 0, 2);
			world.setBlock(i + 4, j + 1, k + 11, NovaCraftBlocks.nullstone_bricks, 0, 2);
			world.setBlock(i + 5, j + 1, k + 11, NovaCraftBlocks.nullstone_bricks, 0, 2);
			world.setBlock(i + 6, j + 1, k + 11, NovaCraftBlocks.nullstone_bricks, 0, 2);
			world.setBlock(i + 7, j + 1, k + 11, NovaCraftBlocks.nullstone_bricks, 0, 2);
			world.setBlock(i + 8, j + 1, k + 11, NovaCraftBlocks.nullstone_bricks, 0, 2);
			world.setBlock(i + 9, j + 1, k + 11, NovaCraftBlocks.nullstone_bricks, 0, 2);
			world.setBlock(i + 10, j + 1, k + 11, NovaCraftBlocks.nullstone_bricks, 0, 2);
			world.setBlock(i + 4, j + 1, k + 12, NovaCraftBlocks.nullstone_bricks, 0, 2);
			world.setBlock(i + 5, j + 1, k + 12, NovaCraftBlocks.nullstone_bricks, 0, 2);
			world.setBlock(i + 6, j + 1, k + 12, NovaCraftBlocks.nullstone_bricks, 0, 2);
			world.setBlock(i + 7, j + 1, k + 12, NovaCraftBlocks.nullstone_bricks, 0, 2);
			world.setBlock(i + 8, j + 1, k + 12, NovaCraftBlocks.nullstone_bricks, 0, 2);
			world.setBlock(i + 9, j + 1, k + 12, NovaCraftBlocks.nullstone_bricks, 0, 2);
			world.setBlock(i + 10, j + 1, k + 12, NovaCraftBlocks.nullstone_bricks, 0, 2);
			world.setBlock(i + 4, j + 1, k + 13, NovaCraftBlocks.nullstone_bricks, 0, 2);
			world.setBlock(i + 5, j + 1, k + 13, NovaCraftBlocks.nullstone_bricks, 0, 2);
			world.setBlock(i + 6, j + 1, k + 13, NovaCraftBlocks.nullstone_bricks, 0, 2);
			world.setBlock(i + 7, j + 1, k + 13, NovaCraftBlocks.nullstone_bricks, 0, 2);
			world.setBlock(i + 8, j + 1, k + 13, NovaCraftBlocks.nullstone_bricks, 0, 2);
			world.setBlock(i + 9, j + 1, k + 13, NovaCraftBlocks.nullstone_bricks, 0, 2);
			world.setBlock(i + 10, j + 1, k + 13, NovaCraftBlocks.nullstone_bricks, 0, 2);
			world.setBlock(i + 5, j + 2, k + 0, NovaCraftBlocks.nullstone_bricks, 0, 2);
			world.setBlock(i + 6, j + 2, k + 0, NovaCraftBlocks.nullstone_bricks, 0, 2);
			world.setBlock(i + 7, j + 2, k + 0, NovaCraftBlocks.nullstone_bricks, 0, 2);
			world.setBlock(i + 8, j + 2, k + 0, NovaCraftBlocks.nullstone_bricks, 0, 2);
			world.setBlock(i + 9, j + 2, k + 0, NovaCraftBlocks.nullstone_bricks, 0, 2);
			world.setBlock(i + 4, j + 2, k + 1, NovaCraftBlocks.nullstone_bricks, 0, 2);
			world.setBlock(i + 5, j + 2, k + 1, Blocks.lava, 0, 2);
			world.setBlock(i + 6, j + 2, k + 1, Blocks.lava, 0, 2);
			world.setBlock(i + 7, j + 2, k + 1, Blocks.lava, 0, 2);
			world.setBlock(i + 8, j + 2, k + 1, Blocks.lava, 0, 2);
			world.setBlock(i + 9, j + 2, k + 1, Blocks.lava, 0, 2);
			world.setBlock(i + 10, j + 2, k + 1, NovaCraftBlocks.nullstone_bricks, 0, 2);
			world.setBlock(i + 4, j + 2, k + 2, NovaCraftBlocks.nullstone_bricks, 0, 2);
			world.setBlock(i + 5, j + 2, k + 2, NovaCraftBlocks.vanite_glass, 0, 2);
			world.setBlock(i + 6, j + 2, k + 2, NovaCraftBlocks.vanite_glass, 0, 2);
			world.setBlock(i + 7, j + 2, k + 2, Blocks.lava, 0, 2);
			world.setBlock(i + 8, j + 2, k + 2, NovaCraftBlocks.vanite_glass, 0, 2);
			world.setBlock(i + 9, j + 2, k + 2, NovaCraftBlocks.vanite_glass, 0, 2);
			world.setBlock(i + 10, j + 2, k + 2, NovaCraftBlocks.nullstone_bricks, 0, 2);
			world.setBlock(i + 4, j + 2, k + 3, NovaCraftBlocks.polished_vanite_bricks, 0, 2);
			world.setBlock(i + 5, j + 2, k + 3, Blocks.air, 0, 2);
			world.setBlock(i + 6, j + 2, k + 3, Blocks.air, 0, 2);
			world.setBlock(i + 7, j + 2, k + 3, NovaCraftBlocks.vanite_glass, 0, 2);
			world.setBlock(i + 8, j + 2, k + 3, Blocks.air, 0, 2);
			world.setBlock(i + 9, j + 2, k + 3, Blocks.air, 0, 2);
			world.setBlock(i + 10, j + 2, k + 3, NovaCraftBlocks.polished_vanite_bricks, 0, 2);
			world.setBlock(i + 1, j + 2, k + 4, NovaCraftBlocks.nullstone_bricks, 0, 2);
			world.setBlock(i + 2, j + 2, k + 4, NovaCraftBlocks.nullstone_bricks, 0, 2);
			world.setBlock(i + 3, j + 2, k + 4, NovaCraftBlocks.polished_vanite_bricks, 0, 2);
			world.setBlock(i + 5, j + 2, k + 4, Blocks.air, 0, 2);
			world.setBlock(i + 6, j + 2, k + 4, Blocks.air, 0, 2);
			world.setBlock(i + 7, j + 2, k + 4, Blocks.air, 0, 2);
			world.setBlock(i + 8, j + 2, k + 4, Blocks.air, 0, 2);
			world.setBlock(i + 9, j + 2, k + 4, Blocks.air, 0, 2);
			world.setBlock(i + 10, j + 2, k + 4, Blocks.air, 0, 2);
			world.setBlock(i + 11, j + 2, k + 4, NovaCraftBlocks.polished_vanite_bricks, 0, 2);
			world.setBlock(i + 12, j + 2, k + 4, NovaCraftBlocks.nullstone_bricks, 0, 2);
			world.setBlock(i + 13, j + 2, k + 4, NovaCraftBlocks.nullstone_bricks, 0, 2);
			world.setBlock(i + 0, j + 2, k + 5, NovaCraftBlocks.nullstone_bricks, 0, 2);
			world.setBlock(i + 1, j + 2, k + 5, Blocks.hopper, 0, 2);
			world.setBlock(i + 2, j + 2, k + 5, Blocks.air, 0, 2);
			world.setBlock(i + 3, j + 2, k + 5, Blocks.air, 0, 2);
			world.setBlock(i + 4, j + 2, k + 5, Blocks.air, 0, 2);
			world.setBlock(i + 5, j + 2, k + 5, Blocks.air, 0, 2);
			world.setBlock(i + 6, j + 2, k + 5, Blocks.air, 0, 2);
			world.setBlock(i + 7, j + 2, k + 5, Blocks.air, 0, 2);
			world.setBlock(i + 8, j + 2, k + 5, Blocks.air, 0, 2);
			world.setBlock(i + 9, j + 2, k + 5, Blocks.air, 0, 2);
			world.setBlock(i + 10, j + 2, k + 5, Blocks.air, 0, 2);
			world.setBlock(i + 11, j + 2, k + 5, Blocks.air, 0, 2);
			world.setBlock(i + 12, j + 2, k + 5, NovaCraftBlocks.vanite_glass, 0, 2);
			world.setBlock(i + 13, j + 2, k + 5, Blocks.lava, 0, 2);
			world.setBlock(i + 14, j + 2, k + 5, NovaCraftBlocks.nullstone_bricks, 0, 2);
			world.setBlock(i + 0, j + 2, k + 6, NovaCraftBlocks.nullstone_bricks, 0, 2);
			world.setBlock(i + 1, j + 2, k + 6, Blocks.hopper, 0, 2);
			world.setBlock(i + 2, j + 2, k + 6, Blocks.air, 0, 2);
			world.setBlock(i + 3, j + 2, k + 6, Blocks.air, 0, 2);
			world.setBlock(i + 4, j + 2, k + 6, Blocks.air, 0, 2);
			world.setBlock(i + 5, j + 2, k + 6, Blocks.air, 0, 2);
			world.setBlock(i + 6, j + 2, k + 6, Blocks.air, 0, 2);
			world.setBlock(i + 7, j + 2, k + 6, Blocks.air, 0, 2);
			world.setBlock(i + 8, j + 2, k + 6, Blocks.air, 0, 2);
			world.setBlock(i + 9, j + 2, k + 6, Blocks.air, 0, 2);
			world.setBlock(i + 10, j + 2, k + 6, Blocks.air, 0, 2);
			world.setBlock(i + 11, j + 2, k + 6, Blocks.air, 0, 2);
			world.setBlock(i + 12, j + 2, k + 6, NovaCraftBlocks.vanite_glass, 0, 2);
			world.setBlock(i + 13, j + 2, k + 6, Blocks.lava, 0, 2);
			world.setBlock(i + 14, j + 2, k + 6, NovaCraftBlocks.nullstone_bricks, 0, 2);
			world.setBlock(i + 0, j + 2, k + 7, NovaCraftBlocks.nullstone_bricks, 0, 2);
			world.setBlock(i + 1, j + 2, k + 7, Blocks.hopper, 0, 2);
			world.setBlock(i + 2, j + 2, k + 7, Blocks.air, 0, 2);
			world.setBlock(i + 3, j + 2, k + 7, Blocks.air, 0, 2);
			world.setBlock(i + 4, j + 2, k + 7, Blocks.air, 0, 2);
			world.setBlock(i + 5, j + 2, k + 7, Blocks.air, 0, 2);
			world.setBlock(i + 6, j + 2, k + 7, Blocks.air, 0, 2);
			world.setBlock(i + 7, j + 2, k + 7, Blocks.quartz_block, 2, 2);
			world.setBlock(i + 8, j + 2, k + 7, NovaCraftBlocks.vanite_brick_stairs, 2, 2);
			world.setBlock(i + 9, j + 2, k + 7, Blocks.air, 0, 2);
			world.setBlock(i + 10, j + 2, k + 7, Blocks.air, 0, 2);
			world.setBlock(i + 11, j + 2, k + 7, NovaCraftBlocks.vanite_glass, 0, 2);
			world.setBlock(i + 12, j + 2, k + 7, Blocks.lava, 0, 2);
			world.setBlock(i + 13, j + 2, k + 7, Blocks.lava, 0, 2);
			world.setBlock(i + 14, j + 2, k + 7, NovaCraftBlocks.nullstone_bricks, 0, 2);
			world.setBlock(i + 0, j + 2, k + 8, NovaCraftBlocks.nullstone_bricks, 0, 2);
			world.setBlock(i + 1, j + 2, k + 8, Blocks.hopper, 0, 2);
			world.setBlock(i + 2, j + 2, k + 8, Blocks.air, 0, 2);
			world.setBlock(i + 3, j + 2, k + 8, Blocks.air, 0, 2);
			world.setBlock(i + 4, j + 2, k + 8, Blocks.air, 0, 2);
			world.setBlock(i + 5, j + 2, k + 8, Blocks.air, 0, 2);
			world.setBlock(i + 6, j + 2, k + 8, Blocks.air, 0, 2);
			world.setBlock(i + 7, j + 2, k + 8, Blocks.air, 0, 2);
			world.setBlock(i + 8, j + 2, k + 8, NovaCraftBlocks.vanite_brick_slab, 8, 2);
			world.setBlock(i + 9, j + 2, k + 8, Blocks.air, 0, 2);
			world.setBlock(i + 10, j + 2, k + 8, Blocks.air, 0, 2);
			world.setBlock(i + 11, j + 2, k + 8, Blocks.air, 0, 2);
			world.setBlock(i + 12, j + 2, k + 8, NovaCraftBlocks.vanite_glass, 0, 2);
			world.setBlock(i + 13, j + 2, k + 8, Blocks.lava, 0, 2);
			world.setBlock(i + 14, j + 2, k + 8, NovaCraftBlocks.nullstone_bricks, 0, 2);
			world.setBlock(i + 0, j + 2, k + 9, NovaCraftBlocks.nullstone_bricks, 0, 2);
			world.setBlock(i + 1, j + 2, k + 9, Blocks.hopper, 0, 2);
			world.setBlock(i + 2, j + 2, k + 9, Blocks.air, 0, 2);
			world.setBlock(i + 3, j + 2, k + 9, Blocks.air, 0, 2);
			world.setBlock(i + 4, j + 2, k + 9, Blocks.air, 0, 2);
			world.setBlock(i + 5, j + 2, k + 9, Blocks.air, 0, 2);
			world.setBlock(i + 6, j + 2, k + 9, Blocks.air, 0, 2);
			world.setBlock(i + 7, j + 2, k + 9, Blocks.air, 0, 2);
			world.setBlock(i + 8, j + 2, k + 9, Blocks.air, 0, 2);
			world.setBlock(i + 9, j + 2, k + 9, Blocks.air, 0, 2);
			world.setBlock(i + 10, j + 2, k + 9, Blocks.air, 0, 2);
			world.setBlock(i + 11, j + 2, k + 9, Blocks.air, 0, 2);
			world.setBlock(i + 12, j + 2, k + 9, NovaCraftBlocks.vanite_glass, 0, 2);
			world.setBlock(i + 13, j + 2, k + 9, Blocks.lava, 0, 2);
			world.setBlock(i + 14, j + 2, k + 9, NovaCraftBlocks.nullstone_bricks, 0, 2);
			world.setBlock(i + 1, j + 2, k + 10, NovaCraftBlocks.nullstone_bricks, 0, 2);
			world.setBlock(i + 2, j + 2, k + 10, NovaCraftBlocks.nullstone_bricks, 0, 2);
			world.setBlock(i + 3, j + 2, k + 10, NovaCraftBlocks.polished_vanite_bricks, 0, 2);
			world.setBlock(i + 5, j + 2, k + 10, Blocks.air, 0, 2);
			world.setBlock(i + 6, j + 2, k + 10, Blocks.air, 0, 2);
			world.setBlock(i + 7, j + 2, k + 10, Blocks.air, 0, 2);
			world.setBlock(i + 8, j + 2, k + 10, Blocks.air, 0, 2);
			world.setBlock(i + 9, j + 2, k + 10, Blocks.air, 0, 2);
			world.setBlock(i + 10, j + 2, k + 10, Blocks.air, 0, 2);
			world.setBlock(i + 11, j + 2, k + 10, NovaCraftBlocks.polished_vanite_bricks, 0, 2);
			world.setBlock(i + 12, j + 2, k + 10, NovaCraftBlocks.nullstone_bricks, 0, 2);
			world.setBlock(i + 13, j + 2, k + 10, NovaCraftBlocks.nullstone_bricks, 0, 2);
			world.setBlock(i + 4, j + 2, k + 11, NovaCraftBlocks.polished_vanite_bricks, 0, 2);
			world.setBlock(i + 5, j + 2, k + 11, Blocks.air, 0, 2);
			world.setBlock(i + 6, j + 2, k + 11, Blocks.air, 0, 2);
			world.setBlock(i + 7, j + 2, k + 11, NovaCraftBlocks.vanite_glass, 0, 2);
			world.setBlock(i + 8, j + 2, k + 11, Blocks.air, 0, 2);
			world.setBlock(i + 9, j + 2, k + 11, Blocks.air, 0, 2);
			world.setBlock(i + 10, j + 2, k + 11, NovaCraftBlocks.polished_vanite_bricks, 0, 2);
			world.setBlock(i + 4, j + 2, k + 12, NovaCraftBlocks.nullstone_bricks, 0, 2);
			world.setBlock(i + 5, j + 2, k + 12, NovaCraftBlocks.vanite_glass, 0, 2);
			world.setBlock(i + 6, j + 2, k + 12, NovaCraftBlocks.vanite_glass, 0, 2);
			world.setBlock(i + 7, j + 2, k + 12, Blocks.lava, 0, 2);
			world.setBlock(i + 8, j + 2, k + 12, NovaCraftBlocks.vanite_glass, 0, 2);
			world.setBlock(i + 9, j + 2, k + 12, NovaCraftBlocks.vanite_glass, 0, 2);
			world.setBlock(i + 10, j + 2, k + 12, NovaCraftBlocks.nullstone_bricks, 0, 2);
			world.setBlock(i + 4, j + 2, k + 13, NovaCraftBlocks.nullstone_bricks, 0, 2);
			world.setBlock(i + 5, j + 2, k + 13, Blocks.lava, 0, 2);
			world.setBlock(i + 6, j + 2, k + 13, Blocks.lava, 0, 2);
			world.setBlock(i + 7, j + 2, k + 13, Blocks.lava, 0, 2);
			world.setBlock(i + 8, j + 2, k + 13, Blocks.lava, 0, 2);
			world.setBlock(i + 9, j + 2, k + 13, Blocks.lava, 0, 2);
			world.setBlock(i + 10, j + 2, k + 13, NovaCraftBlocks.nullstone_bricks, 0, 2);
			world.setBlock(i + 5, j + 2, k + 14, NovaCraftBlocks.nullstone_bricks, 0, 2);
			world.setBlock(i + 6, j + 2, k + 14, NovaCraftBlocks.nullstone_bricks, 0, 2);
			world.setBlock(i + 7, j + 2, k + 14, NovaCraftBlocks.nullstone_bricks, 0, 2);
			world.setBlock(i + 8, j + 2, k + 14, NovaCraftBlocks.nullstone_bricks, 0, 2);
			world.setBlock(i + 9, j + 2, k + 14, NovaCraftBlocks.nullstone_bricks, 0, 2);
			world.setBlock(i + 5, j + 3, k + 0, NovaCraftBlocks.nullstone_bricks, 0, 2);
			world.setBlock(i + 6, j + 3, k + 0, NovaCraftBlocks.nullstone_bricks, 0, 2);
			world.setBlock(i + 7, j + 3, k + 0, NovaCraftBlocks.nullstone_bricks, 0, 2);
			world.setBlock(i + 8, j + 3, k + 0, NovaCraftBlocks.nullstone_bricks, 0, 2);
			world.setBlock(i + 9, j + 3, k + 0, NovaCraftBlocks.nullstone_bricks, 0, 2);
			world.setBlock(i + 4, j + 3, k + 1, NovaCraftBlocks.nullstone_bricks, 0, 2);
			world.setBlock(i + 5, j + 3, k + 1, Blocks.lava, 0, 2);
			world.setBlock(i + 6, j + 3, k + 1, Blocks.lava, 0, 2);
			world.setBlock(i + 7, j + 3, k + 1, Blocks.lava, 0, 2);
			world.setBlock(i + 8, j + 3, k + 1, Blocks.lava, 0, 2);
			world.setBlock(i + 9, j + 3, k + 1, Blocks.lava, 0, 2);
			world.setBlock(i + 10, j + 3, k + 1, NovaCraftBlocks.nullstone_bricks, 0, 2);
			world.setBlock(i + 4, j + 3, k + 2, NovaCraftBlocks.nullstone_bricks, 0, 2);
			world.setBlock(i + 5, j + 3, k + 2, NovaCraftBlocks.vanite_glass, 0, 2);
			world.setBlock(i + 6, j + 3, k + 2, NovaCraftBlocks.vanite_glass, 0, 2);
			world.setBlock(i + 7, j + 3, k + 2, Blocks.lava, 2, 2);
			world.setBlock(i + 8, j + 3, k + 2, NovaCraftBlocks.vanite_glass, 0, 2);
			world.setBlock(i + 9, j + 3, k + 2, NovaCraftBlocks.vanite_glass, 0, 2);
			world.setBlock(i + 10, j + 3, k + 2, NovaCraftBlocks.nullstone_bricks, 0, 2);
			world.setBlock(i + 4, j + 3, k + 3, NovaCraftBlocks.polished_vanite_bricks, 0, 2);
			world.setBlock(i + 5, j + 3, k + 3, Blocks.air, 0, 2);
			world.setBlock(i + 6, j + 3, k + 3, Blocks.air, 0, 2);
			world.setBlock(i + 7, j + 3, k + 3, Blocks.air, 0, 2);
			world.setBlock(i + 8, j + 3, k + 3, Blocks.air, 0, 2);
			world.setBlock(i + 9, j + 3, k + 3, Blocks.air, 0, 2);
			world.setBlock(i + 10, j + 3, k + 3, NovaCraftBlocks.polished_vanite_bricks, 0, 2);
			world.setBlock(i + 1, j + 3, k + 4, NovaCraftBlocks.nullstone_bricks, 0, 2);
			world.setBlock(i + 2, j + 3, k + 4, NovaCraftBlocks.nullstone_bricks, 0, 2);
			world.setBlock(i + 3, j + 3, k + 4, NovaCraftBlocks.polished_vanite_bricks, 0, 2);
			world.setBlock(i + 4, j + 3, k + 4, Blocks.air, 0, 2);
			world.setBlock(i + 5, j + 3, k + 4, Blocks.air, 0, 2);
			world.setBlock(i + 6, j + 3, k + 4, Blocks.air, 0, 2);
			world.setBlock(i + 7, j + 3, k + 4, Blocks.air, 0, 2);
			world.setBlock(i + 8, j + 3, k + 4, Blocks.air, 0, 2);
			world.setBlock(i + 9, j + 3, k + 4, Blocks.air, 0, 2);
			world.setBlock(i + 10, j + 3, k + 4, Blocks.air, 0, 2);
			world.setBlock(i + 11, j + 3, k + 4, NovaCraftBlocks.polished_vanite_bricks, 0, 2);
			world.setBlock(i + 12, j + 3, k + 4, NovaCraftBlocks.nullstone_bricks, 0, 2);
			world.setBlock(i + 13, j + 3, k + 4, NovaCraftBlocks.nullstone_bricks, 0, 2);
			world.setBlock(i + 0, j + 3, k + 5, NovaCraftBlocks.nullstone_bricks, 0, 2);
			world.setBlock(i + 2, j + 3, k + 5, Blocks.air, 0, 2);
			world.setBlock(i + 3, j + 3, k + 5, Blocks.air, 0, 2);
			world.setBlock(i + 4, j + 3, k + 5, Blocks.air, 0, 2);
			world.setBlock(i + 5, j + 3, k + 5, Blocks.air, 0, 2);
			world.setBlock(i + 6, j + 3, k + 5, Blocks.air, 0, 2);
			world.setBlock(i + 7, j + 3, k + 5, Blocks.air, 0, 2);
			world.setBlock(i + 8, j + 3, k + 5, Blocks.air, 0, 2);
			world.setBlock(i + 9, j + 3, k + 5, Blocks.air, 0, 2);
			world.setBlock(i + 10, j + 3, k + 5, Blocks.air, 0, 2);
			world.setBlock(i + 11, j + 3, k + 5, Blocks.air, 0, 2);
			world.setBlock(i + 12, j + 3, k + 5, NovaCraftBlocks.vanite_glass, 0, 2);
			world.setBlock(i + 13, j + 3, k + 5, Blocks.lava, 0, 2);
			world.setBlock(i + 14, j + 3, k + 5, NovaCraftBlocks.nullstone_bricks, 0, 2);
			world.setBlock(i + 0, j + 3, k + 6, NovaCraftBlocks.nullstone_bricks, 0, 2);
			world.setBlock(i + 2, j + 3, k + 6, Blocks.air, 0, 2);
			world.setBlock(i + 3, j + 3, k + 6, Blocks.air, 0, 2);
			world.setBlock(i + 4, j + 3, k + 6, Blocks.air, 0, 2);
			world.setBlock(i + 5, j + 3, k + 6, Blocks.air, 0, 2);
			world.setBlock(i + 6, j + 3, k + 6, Blocks.air, 0, 2);
			world.setBlock(i + 7, j + 3, k + 6, Blocks.air, 0, 2);
			world.setBlock(i + 8, j + 3, k + 6, Blocks.air, 0, 2);
			world.setBlock(i + 9, j + 3, k + 6, Blocks.air, 0, 2);
			world.setBlock(i + 10, j + 3, k + 6, Blocks.air, 0, 2);
			world.setBlock(i + 11, j + 3, k + 6, Blocks.air, 0, 2);
			world.setBlock(i + 12, j + 3, k + 6, NovaCraftBlocks.vanite_glass, 0, 2);
			world.setBlock(i + 13, j + 3, k + 6, Blocks.lava, 0, 2);
			world.setBlock(i + 14, j + 3, k + 6, NovaCraftBlocks.nullstone_bricks, 0, 2);
			world.setBlock(i + 0, j + 3, k + 7, NovaCraftBlocks.nullstone_bricks, 0, 2);
			world.setBlock(i + 2, j + 3, k + 7, Blocks.air, 0, 2);
			world.setBlock(i + 3, j + 3, k + 7, Blocks.air, 0, 2);
			world.setBlock(i + 4, j + 3, k + 7, Blocks.air, 0, 2);
			world.setBlock(i + 5, j + 3, k + 7, Blocks.air, 0, 2);
			world.setBlock(i + 6, j + 3, k + 7, Blocks.air, 0, 2);
			world.setBlock(i + 7, j + 3, k + 7, Blocks.quartz_block, 2, 2);
			world.setBlock(i + 8, j + 3, k + 7, Blocks.air, 0, 2);
			world.setBlock(i + 9, j + 3, k + 7, Blocks.air, 0, 2);
			world.setBlock(i + 10, j + 3, k + 7, Blocks.air, 0, 2);
			world.setBlock(i + 11, j + 3, k + 7, Blocks.air, 0, 2);
			world.setBlock(i + 12, j + 3, k + 7, Blocks.lava, 2, 2);
			world.setBlock(i + 13, j + 3, k + 7, Blocks.lava, 0, 2);
			world.setBlock(i + 14, j + 3, k + 7, NovaCraftBlocks.nullstone_bricks, 0, 2);
			world.setBlock(i + 0, j + 3, k + 8, NovaCraftBlocks.nullstone_bricks, 0, 2);
			world.setBlock(i + 2, j + 3, k + 8, Blocks.air, 0, 2);
			world.setBlock(i + 3, j + 3, k + 8, Blocks.air, 0, 2);
			world.setBlock(i + 4, j + 3, k + 8, Blocks.air, 0, 2);
			world.setBlock(i + 5, j + 3, k + 8, Blocks.air, 0, 2);
			world.setBlock(i + 6, j + 3, k + 8, NovaCraftBlocks.vanite_brick_slab, 8, 2);
			world.setBlock(i + 7, j + 3, k + 8, NovaCraftBlocks.vanite_brick_stairs, 1, 2);
			world.setBlock(i + 8, j + 3, k + 8, Blocks.air, 0, 2);
			world.setBlock(i + 9, j + 3, k + 8, Blocks.air, 0, 2);
			world.setBlock(i + 10, j + 3, k + 8, Blocks.air, 0, 2);
			world.setBlock(i + 11, j + 3, k + 8, Blocks.air, 0, 2);
			world.setBlock(i + 12, j + 3, k + 8, NovaCraftBlocks.vanite_glass, 0, 2);
			world.setBlock(i + 13, j + 3, k + 8, Blocks.lava, 0, 2);
			world.setBlock(i + 14, j + 3, k + 8, NovaCraftBlocks.nullstone_bricks, 0, 2);
			world.setBlock(i + 0, j + 3, k + 9, NovaCraftBlocks.nullstone_bricks, 0, 2);
			world.setBlock(i + 2, j + 3, k + 9, Blocks.air, 0, 2);
			world.setBlock(i + 3, j + 3, k + 9, Blocks.air, 0, 2);
			world.setBlock(i + 4, j + 3, k + 9, Blocks.air, 0, 2);
			world.setBlock(i + 5, j + 3, k + 9, Blocks.air, 0, 2);
			world.setBlock(i + 6, j + 3, k + 9, Blocks.air, 0, 2);
			world.setBlock(i + 7, j + 3, k + 9, Blocks.air, 0, 2);
			world.setBlock(i + 8, j + 3, k + 9, Blocks.air, 0, 2);
			world.setBlock(i + 9, j + 3, k + 9, Blocks.air, 0, 2);
			world.setBlock(i + 10, j + 3, k + 9, Blocks.air, 0, 2);
			world.setBlock(i + 11, j + 3, k + 9, Blocks.air, 0, 2);
			world.setBlock(i + 12, j + 3, k + 9, NovaCraftBlocks.vanite_glass, 0, 2);
			world.setBlock(i + 13, j + 3, k + 9, Blocks.lava, 0, 2);
			world.setBlock(i + 14, j + 3, k + 9, NovaCraftBlocks.nullstone_bricks, 0, 2);
			world.setBlock(i + 1, j + 3, k + 10, NovaCraftBlocks.nullstone_bricks, 0, 2);
			world.setBlock(i + 2, j + 3, k + 10, NovaCraftBlocks.nullstone_bricks, 0, 2);
			world.setBlock(i + 3, j + 3, k + 10, NovaCraftBlocks.polished_vanite_bricks, 0, 2);
			world.setBlock(i + 4, j + 3, k + 10, Blocks.air, 0, 2);
			world.setBlock(i + 5, j + 3, k + 10, Blocks.air, 0, 2);
			world.setBlock(i + 6, j + 3, k + 10, Blocks.air, 0, 2);
			world.setBlock(i + 7, j + 3, k + 10, Blocks.air, 0, 2);
			world.setBlock(i + 8, j + 3, k + 10, Blocks.air, 0, 2);
			world.setBlock(i + 9, j + 3, k + 10, Blocks.air, 0, 2);
			world.setBlock(i + 10, j + 3, k + 10, Blocks.air, 0, 2);
			world.setBlock(i + 11, j + 3, k + 10, NovaCraftBlocks.polished_vanite_bricks, 0, 2);
			world.setBlock(i + 12, j + 3, k + 10, NovaCraftBlocks.nullstone_bricks, 0, 2);
			world.setBlock(i + 13, j + 3, k + 10, NovaCraftBlocks.nullstone_bricks, 0, 2);
			world.setBlock(i + 4, j + 3, k + 11, NovaCraftBlocks.polished_vanite_bricks, 0, 2);
			world.setBlock(i + 5, j + 3, k + 11, Blocks.air, 0, 2);
			world.setBlock(i + 6, j + 3, k + 11, Blocks.air, 0, 2);
			world.setBlock(i + 7, j + 3, k + 11, Blocks.air, 0, 2);
			world.setBlock(i + 8, j + 3, k + 11, Blocks.air, 0, 2);
			world.setBlock(i + 9, j + 3, k + 11, Blocks.air, 0, 2);
			world.setBlock(i + 10, j + 3, k + 11, NovaCraftBlocks.polished_vanite_bricks, 0, 2);
			world.setBlock(i + 4, j + 3, k + 12, NovaCraftBlocks.nullstone_bricks, 0, 2);
			world.setBlock(i + 5, j + 3, k + 12, NovaCraftBlocks.vanite_glass, 0, 2);
			world.setBlock(i + 6, j + 3, k + 12, NovaCraftBlocks.vanite_glass, 0, 2);
			world.setBlock(i + 7, j + 3, k + 12, Blocks.lava, 2, 2);
			world.setBlock(i + 8, j + 3, k + 12, NovaCraftBlocks.vanite_glass, 0, 2);
			world.setBlock(i + 9, j + 3, k + 12, NovaCraftBlocks.vanite_glass, 0, 2);
			world.setBlock(i + 10, j + 3, k + 12, NovaCraftBlocks.nullstone_bricks, 0, 2);
			world.setBlock(i + 4, j + 3, k + 13, NovaCraftBlocks.nullstone_bricks, 0, 2);
			world.setBlock(i + 5, j + 3, k + 13, Blocks.lava, 0, 2);
			world.setBlock(i + 6, j + 3, k + 13, Blocks.lava, 0, 2);
			world.setBlock(i + 7, j + 3, k + 13, Blocks.lava, 0, 2);
			world.setBlock(i + 8, j + 3, k + 13, Blocks.lava, 0, 2);
			world.setBlock(i + 9, j + 3, k + 13, Blocks.lava, 0, 2);
			world.setBlock(i + 10, j + 3, k + 13, NovaCraftBlocks.nullstone_bricks, 0, 2);
			world.setBlock(i + 5, j + 3, k + 14, NovaCraftBlocks.nullstone_bricks, 0, 2);
			world.setBlock(i + 6, j + 3, k + 14, NovaCraftBlocks.nullstone_bricks, 0, 2);
			world.setBlock(i + 7, j + 3, k + 14, NovaCraftBlocks.nullstone_bricks, 0, 2);
			world.setBlock(i + 8, j + 3, k + 14, NovaCraftBlocks.nullstone_bricks, 0, 2);
			world.setBlock(i + 9, j + 3, k + 14, NovaCraftBlocks.nullstone_bricks, 0, 2);
			world.setBlock(i + 5, j + 4, k + 0, NovaCraftBlocks.nullstone_bricks, 0, 2);
			world.setBlock(i + 6, j + 4, k + 0, NovaCraftBlocks.nullstone_bricks, 0, 2);
			world.setBlock(i + 7, j + 4, k + 0, NovaCraftBlocks.nullstone_bricks, 0, 2);
			world.setBlock(i + 8, j + 4, k + 0, NovaCraftBlocks.nullstone_bricks, 0, 2);
			world.setBlock(i + 9, j + 4, k + 0, NovaCraftBlocks.nullstone_bricks, 0, 2);
			world.setBlock(i + 4, j + 4, k + 1, NovaCraftBlocks.nullstone_bricks, 0, 2);
			world.setBlock(i + 5, j + 4, k + 1, Blocks.lava, 0, 2);
			world.setBlock(i + 6, j + 4, k + 1, Blocks.lava, 0, 2);
			world.setBlock(i + 7, j + 4, k + 1, Blocks.lava, 0, 2);
			world.setBlock(i + 8, j + 4, k + 1, Blocks.lava, 0, 2);
			world.setBlock(i + 9, j + 4, k + 1, Blocks.lava, 0, 2);
			world.setBlock(i + 10, j + 4, k + 1, NovaCraftBlocks.nullstone_bricks, 0, 2);
			world.setBlock(i + 4, j + 4, k + 2, NovaCraftBlocks.nullstone_bricks, 0, 2);
			world.setBlock(i + 5, j + 4, k + 2, NovaCraftBlocks.vanite_glass, 0, 2);
			world.setBlock(i + 6, j + 4, k + 2, NovaCraftBlocks.vanite_glass, 0, 2);
			world.setBlock(i + 7, j + 4, k + 2, NovaCraftBlocks.vanite_glass, 0, 2);
			world.setBlock(i + 8, j + 4, k + 2, NovaCraftBlocks.vanite_glass, 0, 2);
			world.setBlock(i + 9, j + 4, k + 2, NovaCraftBlocks.vanite_glass, 0, 2);
			world.setBlock(i + 10, j + 4, k + 2, NovaCraftBlocks.nullstone_bricks, 0, 2);
			world.setBlock(i + 4, j + 4, k + 3, NovaCraftBlocks.polished_vanite_bricks, 0, 2);
			world.setBlock(i + 5, j + 4, k + 3, Blocks.air, 0, 2);
			world.setBlock(i + 6, j + 4, k + 3, Blocks.air, 0, 2);
			world.setBlock(i + 7, j + 4, k + 3, Blocks.air, 0, 2);
			world.setBlock(i + 8, j + 4, k + 3, Blocks.air, 0, 2);
			world.setBlock(i + 9, j + 4, k + 3, Blocks.air, 0, 2);
			world.setBlock(i + 10, j + 4, k + 3, NovaCraftBlocks.polished_vanite_bricks, 0, 2);
			world.setBlock(i + 1, j + 4, k + 4, NovaCraftBlocks.nullstone_bricks, 0, 2);
			world.setBlock(i + 2, j + 4, k + 4, NovaCraftBlocks.nullstone_bricks, 0, 2);
			world.setBlock(i + 3, j + 4, k + 4, NovaCraftBlocks.polished_vanite_bricks, 0, 2);
			world.setBlock(i + 4, j + 4, k + 4, Blocks.air, 0, 2);
			world.setBlock(i + 5, j + 4, k + 4, Blocks.air, 0, 2);
			world.setBlock(i + 6, j + 4, k + 4, Blocks.air, 0, 2);
			world.setBlock(i + 7, j + 4, k + 4, Blocks.air, 0, 2);
			world.setBlock(i + 8, j + 4, k + 4, Blocks.air, 0, 2);
			world.setBlock(i + 9, j + 4, k + 4, Blocks.air, 0, 2);
			world.setBlock(i + 10, j + 4, k + 4, Blocks.air, 0, 2);
			world.setBlock(i + 11, j + 4, k + 4, NovaCraftBlocks.polished_vanite_bricks, 0, 2);
			world.setBlock(i + 12, j + 4, k + 4, NovaCraftBlocks.nullstone_bricks, 0, 2);
			world.setBlock(i + 13, j + 4, k + 4, NovaCraftBlocks.nullstone_bricks, 0, 2);
			world.setBlock(i + 0, j + 4, k + 5, NovaCraftBlocks.nullstone_bricks, 0, 2);
			world.setBlock(i + 1, j + 4, k + 5, Blocks.hopper, 0, 2);
			world.setBlock(i + 2, j + 4, k + 5, Blocks.air, 0, 2);
			world.setBlock(i + 3, j + 4, k + 5, Blocks.air, 0, 2);
			world.setBlock(i + 4, j + 4, k + 5, Blocks.air, 0, 2);
			world.setBlock(i + 5, j + 4, k + 5, Blocks.air, 0, 2);
			world.setBlock(i + 6, j + 4, k + 5, Blocks.air, 0, 2);
			world.setBlock(i + 7, j + 4, k + 5, Blocks.air, 0, 2);
			world.setBlock(i + 8, j + 4, k + 5, Blocks.air, 0, 2);
			world.setBlock(i + 9, j + 4, k + 5, Blocks.air, 0, 2);
			world.setBlock(i + 10, j + 4, k + 5, Blocks.air, 0, 2);
			world.setBlock(i + 11, j + 4, k + 5, Blocks.air, 0, 2);
			world.setBlock(i + 12, j + 4, k + 5, NovaCraftBlocks.vanite_glass, 0, 2);
			world.setBlock(i + 13, j + 4, k + 5, Blocks.lava, 0, 2);
			world.setBlock(i + 14, j + 4, k + 5, NovaCraftBlocks.nullstone_bricks, 0, 2);
			world.setBlock(i + 0, j + 4, k + 6, NovaCraftBlocks.nullstone_bricks, 0, 2);
			world.setBlock(i + 1, j + 4, k + 6, Blocks.hopper, 0, 2);
			world.setBlock(i + 2, j + 4, k + 6, Blocks.air, 0, 2);
			world.setBlock(i + 3, j + 4, k + 6, Blocks.air, 0, 2);
			world.setBlock(i + 4, j + 4, k + 6, Blocks.air, 0, 2);
			world.setBlock(i + 5, j + 4, k + 6, Blocks.air, 0, 2);
			world.setBlock(i + 6, j + 4, k + 6, NovaCraftBlocks.vanite_brick_slab, 8, 2);
			world.setBlock(i + 7, j + 4, k + 6, Blocks.air, 0, 2);
			world.setBlock(i + 8, j + 4, k + 6, Blocks.air, 0, 2);
			world.setBlock(i + 9, j + 4, k + 6, Blocks.air, 0, 2);
			world.setBlock(i + 10, j + 4, k + 6, Blocks.air, 0, 2);
			world.setBlock(i + 11, j + 4, k + 6, Blocks.air, 0, 2);
			world.setBlock(i + 12, j + 4, k + 6, NovaCraftBlocks.vanite_glass, 0, 2);
			world.setBlock(i + 13, j + 4, k + 6, Blocks.lava, 0, 2);
			world.setBlock(i + 14, j + 4, k + 6, NovaCraftBlocks.nullstone_bricks, 0, 2);
			world.setBlock(i + 0, j + 4, k + 7, NovaCraftBlocks.nullstone_bricks, 0, 2);
			world.setBlock(i + 1, j + 4, k + 7, Blocks.hopper, 0, 2);
			world.setBlock(i + 2, j + 4, k + 7, Blocks.air, 0, 2);
			world.setBlock(i + 3, j + 4, k + 7, Blocks.air, 0, 2);
			world.setBlock(i + 4, j + 4, k + 7, Blocks.air, 0, 2);
			world.setBlock(i + 5, j + 4, k + 7, Blocks.air, 0, 2);
			world.setBlock(i + 6, j + 4, k + 7, NovaCraftBlocks.vanite_brick_stairs, 3, 2);
			world.setBlock(i + 7, j + 4, k + 7, Blocks.quartz_block, 2, 2);
			world.setBlock(i + 8, j + 4, k + 7, Blocks.air, 0, 2);
			world.setBlock(i + 9, j + 4, k + 7, Blocks.air, 0, 2);
			world.setBlock(i + 10, j + 4, k + 7, Blocks.air, 0, 2);
			world.setBlock(i + 11, j + 4, k + 7, Blocks.air, 0, 2);
			world.setBlock(i + 12, j + 4, k + 7, NovaCraftBlocks.vanite_glass, 0, 2);
			world.setBlock(i + 13, j + 4, k + 7, Blocks.lava, 0, 2);
			world.setBlock(i + 14, j + 4, k + 7, NovaCraftBlocks.nullstone_bricks, 0, 2);
			world.setBlock(i + 0, j + 4, k + 8, NovaCraftBlocks.nullstone_bricks, 0, 2);
			world.setBlock(i + 1, j + 4, k + 8, Blocks.hopper, 0, 2);
			world.setBlock(i + 2, j + 4, k + 8, Blocks.air, 0, 2);
			world.setBlock(i + 3, j + 4, k + 8, Blocks.air, 0, 2);
			world.setBlock(i + 4, j + 4, k + 8, Blocks.air, 0, 2);
			world.setBlock(i + 5, j + 4, k + 8, Blocks.air, 0, 2);
			world.setBlock(i + 6, j + 4, k + 8, Blocks.air, 0, 2);
			world.setBlock(i + 7, j + 4, k + 8, Blocks.air, 0, 2);
			world.setBlock(i + 8, j + 4, k + 8, Blocks.air, 0, 2);
			world.setBlock(i + 9, j + 4, k + 8, Blocks.air, 0, 2);
			world.setBlock(i + 10, j + 4, k + 8, Blocks.air, 0, 2);
			world.setBlock(i + 11, j + 4, k + 8, Blocks.air, 0, 2);
			world.setBlock(i + 12, j + 4, k + 8, NovaCraftBlocks.vanite_glass, 0, 2);
			world.setBlock(i + 13, j + 4, k + 8, Blocks.lava, 0, 2);
			world.setBlock(i + 14, j + 4, k + 8, NovaCraftBlocks.nullstone_bricks, 0, 2);
			world.setBlock(i + 0, j + 4, k + 9, NovaCraftBlocks.nullstone_bricks, 0, 2);
			world.setBlock(i + 1, j + 4, k + 9, Blocks.hopper, 0, 2);
			world.setBlock(i + 2, j + 4, k + 9, Blocks.air, 0, 2);
			world.setBlock(i + 3, j + 4, k + 9, Blocks.air, 0, 2);
			world.setBlock(i + 4, j + 4, k + 9, Blocks.air, 0, 2);
			world.setBlock(i + 5, j + 4, k + 9, Blocks.air, 0, 2);
			world.setBlock(i + 6, j + 4, k + 9, Blocks.air, 0, 2);
			world.setBlock(i + 7, j + 4, k + 9, Blocks.air, 0, 2);
			world.setBlock(i + 8, j + 4, k + 9, Blocks.air, 0, 2);
			world.setBlock(i + 9, j + 4, k + 9, Blocks.air, 0, 2);
			world.setBlock(i + 10, j + 4, k + 9, Blocks.air, 0, 2);
			world.setBlock(i + 11, j + 4, k + 9, Blocks.air, 0, 2);
			world.setBlock(i + 12, j + 4, k + 9, NovaCraftBlocks.vanite_glass, 0, 2);
			world.setBlock(i + 13, j + 4, k + 9, Blocks.lava, 0, 2);
			world.setBlock(i + 14, j + 4, k + 9, NovaCraftBlocks.nullstone_bricks, 0, 2);
			world.setBlock(i + 1, j + 4, k + 10, NovaCraftBlocks.nullstone_bricks, 0, 2);
			world.setBlock(i + 2, j + 4, k + 10, NovaCraftBlocks.nullstone_bricks, 0, 2);
			world.setBlock(i + 3, j + 4, k + 10, NovaCraftBlocks.polished_vanite_bricks, 0, 2);
			world.setBlock(i + 4, j + 4, k + 10, Blocks.air, 0, 2);
			world.setBlock(i + 5, j + 4, k + 10, Blocks.air, 0, 2);
			world.setBlock(i + 6, j + 4, k + 10, Blocks.air, 0, 2);
			world.setBlock(i + 7, j + 4, k + 10, Blocks.air, 0, 2);
			world.setBlock(i + 8, j + 4, k + 10, Blocks.air, 0, 2);
			world.setBlock(i + 9, j + 4, k + 10, Blocks.air, 0, 2);
			world.setBlock(i + 10, j + 4, k + 10, Blocks.air, 0, 2);
			world.setBlock(i + 11, j + 4, k + 10, NovaCraftBlocks.polished_vanite_bricks, 0, 2);
			world.setBlock(i + 12, j + 4, k + 10, NovaCraftBlocks.nullstone_bricks, 0, 2);
			world.setBlock(i + 13, j + 4, k + 10, NovaCraftBlocks.nullstone_bricks, 0, 2);
			world.setBlock(i + 4, j + 4, k + 11, NovaCraftBlocks.polished_vanite_bricks, 0, 2);
			world.setBlock(i + 5, j + 4, k + 11, Blocks.air, 0, 2);
			world.setBlock(i + 6, j + 4, k + 11, Blocks.air, 0, 2);
			world.setBlock(i + 7, j + 4, k + 11, Blocks.air, 0, 2);
			world.setBlock(i + 8, j + 4, k + 11, Blocks.air, 0, 2);
			world.setBlock(i + 9, j + 4, k + 11, Blocks.air, 0, 2);
			world.setBlock(i + 10, j + 4, k + 11, NovaCraftBlocks.polished_vanite_bricks, 0, 2);
			world.setBlock(i + 4, j + 4, k + 12, NovaCraftBlocks.nullstone_bricks, 0, 2);
			world.setBlock(i + 5, j + 4, k + 12, NovaCraftBlocks.vanite_glass, 0, 2);
			world.setBlock(i + 6, j + 4, k + 12, NovaCraftBlocks.vanite_glass, 0, 2);
			world.setBlock(i + 7, j + 4, k + 12, NovaCraftBlocks.vanite_glass, 0, 2);
			world.setBlock(i + 8, j + 4, k + 12, NovaCraftBlocks.vanite_glass, 0, 2);
			world.setBlock(i + 9, j + 4, k + 12, NovaCraftBlocks.vanite_glass, 0, 2);
			world.setBlock(i + 10, j + 4, k + 12, NovaCraftBlocks.nullstone_bricks, 0, 2);
			world.setBlock(i + 4, j + 4, k + 13, NovaCraftBlocks.nullstone_bricks, 0, 2);
			world.setBlock(i + 5, j + 4, k + 13, Blocks.lava, 0, 2);
			world.setBlock(i + 6, j + 4, k + 13, Blocks.lava, 0, 2);
			world.setBlock(i + 7, j + 4, k + 13, Blocks.lava, 0, 2);
			world.setBlock(i + 8, j + 4, k + 13, Blocks.lava, 0, 2);
			world.setBlock(i + 9, j + 4, k + 13, Blocks.lava, 0, 2);
			world.setBlock(i + 10, j + 4, k + 13, NovaCraftBlocks.nullstone_bricks, 0, 2);
			world.setBlock(i + 5, j + 4, k + 14, NovaCraftBlocks.nullstone_bricks, 0, 2);
			world.setBlock(i + 6, j + 4, k + 14, NovaCraftBlocks.nullstone_bricks, 0, 2);
			world.setBlock(i + 7, j + 4, k + 14, NovaCraftBlocks.nullstone_bricks, 0, 2);
			world.setBlock(i + 8, j + 4, k + 14, NovaCraftBlocks.nullstone_bricks, 0, 2);
			world.setBlock(i + 9, j + 4, k + 14, NovaCraftBlocks.nullstone_bricks, 0, 2);
			world.setBlock(i + 5, j + 5, k + 0, NovaCraftBlocks.nullstone_bricks, 0, 2);
			world.setBlock(i + 6, j + 5, k + 0, NovaCraftBlocks.nullstone_bricks, 0, 2);
			world.setBlock(i + 7, j + 5, k + 0, NovaCraftBlocks.nullstone_bricks, 0, 2);
			world.setBlock(i + 8, j + 5, k + 0, NovaCraftBlocks.nullstone_bricks, 0, 2);
			world.setBlock(i + 9, j + 5, k + 0, NovaCraftBlocks.nullstone_bricks, 0, 2);
			world.setBlock(i + 4, j + 5, k + 1, NovaCraftBlocks.nullstone_bricks, 0, 2);
			world.setBlock(i + 5, j + 5, k + 1, Blocks.lava, 0, 2);
			world.setBlock(i + 6, j + 5, k + 1, Blocks.lava, 0, 2);
			world.setBlock(i + 7, j + 5, k + 1, Blocks.lava, 0, 2);
			world.setBlock(i + 8, j + 5, k + 1, Blocks.lava, 0, 2);
			world.setBlock(i + 9, j + 5, k + 1, Blocks.lava, 0, 2);
			world.setBlock(i + 10, j + 5, k + 1, NovaCraftBlocks.nullstone_bricks, 0, 2);
			world.setBlock(i + 4, j + 5, k + 2, NovaCraftBlocks.nullstone_bricks, 0, 2);
			world.setBlock(i + 5, j + 5, k + 2, NovaCraftBlocks.vanite_glass, 0, 2);
			world.setBlock(i + 6, j + 5, k + 2, NovaCraftBlocks.vanite_glass, 0, 2);
			world.setBlock(i + 7, j + 5, k + 2, NovaCraftBlocks.vanite_glass, 0, 2);
			world.setBlock(i + 8, j + 5, k + 2, NovaCraftBlocks.vanite_glass, 0, 2);
			world.setBlock(i + 9, j + 5, k + 2, NovaCraftBlocks.vanite_glass, 0, 2);
			world.setBlock(i + 10, j + 5, k + 2, NovaCraftBlocks.nullstone_bricks, 0, 2);
			world.setBlock(i + 4, j + 5, k + 3, NovaCraftBlocks.polished_vanite_bricks, 0, 2);
			world.setBlock(i + 5, j + 5, k + 3, Blocks.air, 0, 2);
			world.setBlock(i + 6, j + 5, k + 3, Blocks.air, 0, 2);
			world.setBlock(i + 7, j + 5, k + 3, Blocks.air, 0, 2);
			world.setBlock(i + 8, j + 5, k + 3, Blocks.air, 0, 2);
			world.setBlock(i + 9, j + 5, k + 3, Blocks.air, 0, 2);
			world.setBlock(i + 10, j + 5, k + 3, NovaCraftBlocks.polished_vanite_bricks, 0, 2);
			world.setBlock(i + 1, j + 5, k + 4, NovaCraftBlocks.nullstone_bricks, 0, 2);
			world.setBlock(i + 2, j + 5, k + 4, NovaCraftBlocks.nullstone_bricks, 0, 2);
			world.setBlock(i + 3, j + 5, k + 4, NovaCraftBlocks.polished_vanite_bricks, 0, 2);
			world.setBlock(i + 4, j + 5, k + 4, Blocks.air, 0, 2);
			world.setBlock(i + 5, j + 5, k + 4, Blocks.air, 0, 2);
			world.setBlock(i + 6, j + 5, k + 4, Blocks.air, 0, 2);
			world.setBlock(i + 7, j + 5, k + 4, Blocks.air, 0, 2);
			world.setBlock(i + 8, j + 5, k + 4, Blocks.air, 0, 2);
			world.setBlock(i + 9, j + 5, k + 4, Blocks.air, 0, 2);
			world.setBlock(i + 10, j + 5, k + 4, Blocks.air, 0, 2);
			world.setBlock(i + 11, j + 5, k + 4, NovaCraftBlocks.polished_vanite_bricks, 0, 2);
			world.setBlock(i + 12, j + 5, k + 4, NovaCraftBlocks.nullstone_bricks, 0, 2);
			world.setBlock(i + 13, j + 5, k + 4, NovaCraftBlocks.nullstone_bricks, 0, 2);
			world.setBlock(i + 0, j + 5, k + 5, NovaCraftBlocks.nullstone_bricks, 0, 2);
			world.setBlock(i + 2, j + 5, k + 5, Blocks.air, 0, 2);
			world.setBlock(i + 3, j + 5, k + 5, Blocks.air, 0, 2);
			world.setBlock(i + 4, j + 5, k + 5, Blocks.air, 0, 2);
			world.setBlock(i + 5, j + 5, k + 5, Blocks.air, 0, 2);
			world.setBlock(i + 6, j + 5, k + 5, Blocks.air, 0, 2);
			world.setBlock(i + 7, j + 5, k + 5, Blocks.air, 0, 2);
			world.setBlock(i + 8, j + 5, k + 5, Blocks.air, 0, 2);
			world.setBlock(i + 9, j + 5, k + 5, Blocks.air, 0, 2);
			world.setBlock(i + 10, j + 5, k + 5, Blocks.air, 0, 2);
			world.setBlock(i + 11, j + 5, k + 5, Blocks.air, 0, 2);
			world.setBlock(i + 12, j + 5, k + 5, NovaCraftBlocks.vanite_glass, 0, 2);
			world.setBlock(i + 13, j + 5, k + 5, Blocks.lava, 0, 2);
			world.setBlock(i + 14, j + 5, k + 5, NovaCraftBlocks.nullstone_bricks, 0, 2);
			world.setBlock(i + 0, j + 5, k + 6, NovaCraftBlocks.nullstone_bricks, 0, 2);
			world.setBlock(i + 2, j + 5, k + 6, Blocks.air, 0, 2);
			world.setBlock(i + 3, j + 5, k + 6, Blocks.air, 0, 2);
			world.setBlock(i + 4, j + 5, k + 6, Blocks.air, 0, 2);
			world.setBlock(i + 5, j + 5, k + 6, Blocks.air, 0, 2);
			world.setBlock(i + 6, j + 5, k + 6, Blocks.air, 0, 2);
			world.setBlock(i + 7, j + 5, k + 6, NovaCraftBlocks.vanite_brick_stairs, 0, 2);
			world.setBlock(i + 8, j + 5, k + 6, NovaCraftBlocks.vanite_brick_slab, 8, 2);
			world.setBlock(i + 9, j + 5, k + 6, Blocks.air, 0, 2);
			world.setBlock(i + 10, j + 5, k + 6, Blocks.air, 0, 2);
			world.setBlock(i + 11, j + 5, k + 6, Blocks.air, 0, 2);
			world.setBlock(i + 12, j + 5, k + 6, NovaCraftBlocks.vanite_glass, 0, 2);
			world.setBlock(i + 13, j + 5, k + 6, Blocks.lava, 0, 2);
			world.setBlock(i + 14, j + 5, k + 6, NovaCraftBlocks.nullstone_bricks, 0, 2);
			world.setBlock(i + 0, j + 5, k + 7, NovaCraftBlocks.nullstone_bricks, 0, 2);
			world.setBlock(i + 2, j + 5, k + 7, Blocks.air, 0, 2);
			world.setBlock(i + 3, j + 5, k + 7, Blocks.air, 0, 2);
			world.setBlock(i + 4, j + 5, k + 7, Blocks.air, 0, 2);
			world.setBlock(i + 5, j + 5, k + 7, Blocks.air, 0, 2);
			world.setBlock(i + 6, j + 5, k + 7, Blocks.air, 0, 2);
			world.setBlock(i + 7, j + 5, k + 7, Blocks.quartz_block, 2, 2);
			world.setBlock(i + 8, j + 5, k + 7, Blocks.air, 0, 2);
			world.setBlock(i + 9, j + 5, k + 7, Blocks.air, 0, 2);
			world.setBlock(i + 10, j + 5, k + 7, Blocks.air, 0, 2);
			world.setBlock(i + 11, j + 5, k + 7, Blocks.air, 0, 2);
			world.setBlock(i + 12, j + 5, k + 7, NovaCraftBlocks.vanite_glass, 0, 2);
			world.setBlock(i + 13, j + 5, k + 7, Blocks.lava, 0, 2);
			world.setBlock(i + 14, j + 5, k + 7, NovaCraftBlocks.nullstone_bricks, 0, 2);
			world.setBlock(i + 0, j + 5, k + 8, NovaCraftBlocks.nullstone_bricks, 0, 2);
			world.setBlock(i + 2, j + 5, k + 8, Blocks.air, 0, 2);
			world.setBlock(i + 3, j + 5, k + 8, Blocks.air, 0, 2);
			world.setBlock(i + 4, j + 5, k + 8, Blocks.air, 0, 2);
			world.setBlock(i + 5, j + 5, k + 8, Blocks.air, 0, 2);
			world.setBlock(i + 6, j + 5, k + 8, Blocks.air, 0, 2);
			world.setBlock(i + 7, j + 5, k + 8, Blocks.air, 0, 2);
			world.setBlock(i + 8, j + 5, k + 8, Blocks.air, 0, 2);
			world.setBlock(i + 9, j + 5, k + 8, Blocks.air, 0, 2);
			world.setBlock(i + 10, j + 5, k + 8, Blocks.air, 0, 2);
			world.setBlock(i + 11, j + 5, k + 8, Blocks.air, 0, 2);
			world.setBlock(i + 12, j + 5, k + 8, NovaCraftBlocks.vanite_glass, 0, 2);
			world.setBlock(i + 13, j + 5, k + 8, Blocks.lava, 0, 2);
			world.setBlock(i + 14, j + 5, k + 8, NovaCraftBlocks.nullstone_bricks, 0, 2);
			world.setBlock(i + 0, j + 5, k + 9, NovaCraftBlocks.nullstone_bricks, 0, 2);
			world.setBlock(i + 2, j + 5, k + 9, Blocks.air, 0, 2);
			world.setBlock(i + 3, j + 5, k + 9, Blocks.air, 0, 2);
			world.setBlock(i + 4, j + 5, k + 9, Blocks.air, 0, 2);
			world.setBlock(i + 5, j + 5, k + 9, Blocks.air, 0, 2);
			world.setBlock(i + 6, j + 5, k + 9, Blocks.air, 0, 2);
			world.setBlock(i + 7, j + 5, k + 9, Blocks.air, 0, 2);
			world.setBlock(i + 8, j + 5, k + 9, Blocks.air, 0, 2);
			world.setBlock(i + 9, j + 5, k + 9, Blocks.air, 0, 2);
			world.setBlock(i + 10, j + 5, k + 9, Blocks.air, 0, 2);
			world.setBlock(i + 11, j + 5, k + 9, Blocks.air, 0, 2);
			world.setBlock(i + 12, j + 5, k + 9, NovaCraftBlocks.vanite_glass, 0, 2);
			world.setBlock(i + 13, j + 5, k + 9, Blocks.lava, 0, 2);
			world.setBlock(i + 14, j + 5, k + 9, NovaCraftBlocks.nullstone_bricks, 0, 2);
			world.setBlock(i + 1, j + 5, k + 10, NovaCraftBlocks.nullstone_bricks, 0, 2);
			world.setBlock(i + 2, j + 5, k + 10, NovaCraftBlocks.nullstone_bricks, 0, 2);
			world.setBlock(i + 3, j + 5, k + 10, NovaCraftBlocks.polished_vanite_bricks, 0, 2);
			world.setBlock(i + 4, j + 5, k + 10, Blocks.air, 0, 2);
			world.setBlock(i + 5, j + 5, k + 10, Blocks.air, 0, 2);
			world.setBlock(i + 6, j + 5, k + 10, Blocks.air, 0, 2);
			world.setBlock(i + 7, j + 5, k + 10, Blocks.air, 0, 2);
			world.setBlock(i + 8, j + 5, k + 10, Blocks.air, 0, 2);
			world.setBlock(i + 9, j + 5, k + 10, Blocks.air, 0, 2);
			world.setBlock(i + 10, j + 5, k + 10, Blocks.air, 0, 2);
			world.setBlock(i + 11, j + 5, k + 10, NovaCraftBlocks.polished_vanite_bricks, 0, 2);
			world.setBlock(i + 12, j + 5, k + 10, NovaCraftBlocks.nullstone_bricks, 0, 2);
			world.setBlock(i + 13, j + 5, k + 10, NovaCraftBlocks.nullstone_bricks, 0, 2);
			world.setBlock(i + 4, j + 5, k + 11, NovaCraftBlocks.polished_vanite_bricks, 0, 2);
			world.setBlock(i + 5, j + 5, k + 11, Blocks.air, 0, 2);
			world.setBlock(i + 6, j + 5, k + 11, Blocks.air, 0, 2);
			world.setBlock(i + 7, j + 5, k + 11, Blocks.air, 0, 2);
			world.setBlock(i + 8, j + 5, k + 11, Blocks.air, 0, 2);
			world.setBlock(i + 9, j + 5, k + 11, Blocks.air, 0, 2);
			world.setBlock(i + 10, j + 5, k + 11, NovaCraftBlocks.polished_vanite_bricks, 0, 2);
			world.setBlock(i + 4, j + 5, k + 12, NovaCraftBlocks.nullstone_bricks, 0, 2);
			world.setBlock(i + 5, j + 5, k + 12, NovaCraftBlocks.vanite_glass, 0, 2);
			world.setBlock(i + 6, j + 5, k + 12, NovaCraftBlocks.vanite_glass, 0, 2);
			world.setBlock(i + 7, j + 5, k + 12, NovaCraftBlocks.vanite_glass, 0, 2);
			world.setBlock(i + 8, j + 5, k + 12, NovaCraftBlocks.vanite_glass, 0, 2);
			world.setBlock(i + 9, j + 5, k + 12, NovaCraftBlocks.vanite_glass, 0, 2);
			world.setBlock(i + 10, j + 5, k + 12, NovaCraftBlocks.nullstone_bricks, 0, 2);
			world.setBlock(i + 4, j + 5, k + 13, NovaCraftBlocks.nullstone_bricks, 0, 2);
			world.setBlock(i + 5, j + 5, k + 13, Blocks.lava, 0, 2);
			world.setBlock(i + 6, j + 5, k + 13, Blocks.lava, 0, 2);
			world.setBlock(i + 7, j + 5, k + 13, Blocks.lava, 0, 2);
			world.setBlock(i + 8, j + 5, k + 13, Blocks.lava, 0, 2);
			world.setBlock(i + 9, j + 5, k + 13, Blocks.lava, 0, 2);
			world.setBlock(i + 10, j + 5, k + 13, NovaCraftBlocks.nullstone_bricks, 0, 2);
			world.setBlock(i + 5, j + 5, k + 14, NovaCraftBlocks.nullstone_bricks, 0, 2);
			world.setBlock(i + 6, j + 5, k + 14, NovaCraftBlocks.nullstone_bricks, 0, 2);
			world.setBlock(i + 7, j + 5, k + 14, NovaCraftBlocks.nullstone_bricks, 0, 2);
			world.setBlock(i + 8, j + 5, k + 14, NovaCraftBlocks.nullstone_bricks, 0, 2);
			world.setBlock(i + 9, j + 5, k + 14, NovaCraftBlocks.nullstone_bricks, 0, 2);
			world.setBlock(i + 5, j + 6, k + 0, NovaCraftBlocks.nullstone_bricks, 0, 2);
			world.setBlock(i + 6, j + 6, k + 0, Blocks.air, 0, 2); //
			world.setBlock(i + 7, j + 6, k + 0, Blocks.air, 0, 2); //
			world.setBlock(i + 8, j + 6, k + 0, NovaCraftBlocks.nullstone_bricks, 0, 2);
			world.setBlock(i + 9, j + 6, k + 0, NovaCraftBlocks.nullstone_bricks, 0, 2);
			world.setBlock(i + 4, j + 6, k + 1, NovaCraftBlocks.nullstone_bricks, 0, 2);
			world.setBlock(i + 5, j + 6, k + 1, Blocks.lava, 0, 2);
			world.setBlock(i + 6, j + 6, k + 1, Blocks.lava, 0, 2);
			world.setBlock(i + 7, j + 6, k + 1, Blocks.lava, 0, 2);
			world.setBlock(i + 8, j + 6, k + 1, Blocks.lava, 0, 2);
			world.setBlock(i + 9, j + 6, k + 1, Blocks.lava, 0, 2);
			world.setBlock(i + 10, j + 6, k + 1, NovaCraftBlocks.nullstone_bricks, 0, 2);
			world.setBlock(i + 4, j + 6, k + 2, NovaCraftBlocks.nullstone_bricks, 0, 2);
			world.setBlock(i + 5, j + 6, k + 2, NovaCraftBlocks.vanite_glass, 0, 2);
			world.setBlock(i + 6, j + 6, k + 2, NovaCraftBlocks.vanite_glass, 0, 2);
			world.setBlock(i + 7, j + 6, k + 2, NovaCraftBlocks.vanite_glass, 0, 2);
			world.setBlock(i + 8, j + 6, k + 2, NovaCraftBlocks.vanite_glass, 0, 2);
			world.setBlock(i + 9, j + 6, k + 2, NovaCraftBlocks.vanite_glass, 0, 2);
			world.setBlock(i + 10, j + 6, k + 2, NovaCraftBlocks.nullstone_bricks, 0, 2);
			world.setBlock(i + 4, j + 6, k + 3, NovaCraftBlocks.polished_vanite_bricks, 0, 2);
			world.setBlock(i + 5, j + 6, k + 3, Blocks.air, 0, 2);
			world.setBlock(i + 6, j + 6, k + 3, Blocks.air, 0, 2);
			world.setBlock(i + 7, j + 6, k + 3, Blocks.air, 0, 2);
			world.setBlock(i + 8, j + 6, k + 3, Blocks.air, 0, 2);
			world.setBlock(i + 9, j + 6, k + 3, Blocks.air, 0, 2);
			world.setBlock(i + 10, j + 6, k + 3, NovaCraftBlocks.polished_vanite_bricks, 0, 2);
			world.setBlock(i + 1, j + 6, k + 4, NovaCraftBlocks.nullstone_bricks, 0, 2);
			world.setBlock(i + 2, j + 6, k + 4, NovaCraftBlocks.nullstone_bricks, 0, 2);
			world.setBlock(i + 3, j + 6, k + 4, NovaCraftBlocks.polished_vanite_bricks, 0, 2);
			world.setBlock(i + 4, j + 6, k + 4, Blocks.air, 0, 2);
			world.setBlock(i + 5, j + 6, k + 4, Blocks.air, 0, 2);
			world.setBlock(i + 6, j + 6, k + 4, Blocks.air, 0, 2);
			world.setBlock(i + 7, j + 6, k + 4, Blocks.air, 0, 2);
			world.setBlock(i + 8, j + 6, k + 4, Blocks.air, 0, 2);
			world.setBlock(i + 9, j + 6, k + 4, Blocks.air, 0, 2);
			world.setBlock(i + 10, j + 6, k + 4, Blocks.air, 0, 2);
			world.setBlock(i + 11, j + 6, k + 4, NovaCraftBlocks.polished_vanite_bricks, 0, 2);
			world.setBlock(i + 12, j + 6, k + 4, NovaCraftBlocks.nullstone_bricks, 0, 2);
			world.setBlock(i + 13, j + 6, k + 4, NovaCraftBlocks.nullstone_bricks, 0, 2);
			world.setBlock(i + 0, j + 6, k + 5, NovaCraftBlocks.nullstone_bricks, 0, 2);
			world.setBlock(i + 1, j + 6, k + 5, Blocks.air, 0, 2);
			world.setBlock(i + 2, j + 6, k + 5, Blocks.air, 0, 2);
			world.setBlock(i + 3, j + 6, k + 5, Blocks.air, 0, 2);
			world.setBlock(i + 4, j + 6, k + 5, Blocks.air, 0, 2);
			world.setBlock(i + 5, j + 6, k + 5, Blocks.air, 0, 2);
			world.setBlock(i + 6, j + 6, k + 5, Blocks.air, 0, 2);
			world.setBlock(i + 7, j + 6, k + 5, Blocks.air, 0, 2);
			world.setBlock(i + 8, j + 6, k + 5, Blocks.air, 0, 2);
			world.setBlock(i + 9, j + 6, k + 5, Blocks.air, 0, 2);
			world.setBlock(i + 10, j + 6, k + 5, Blocks.air, 0, 2);
			world.setBlock(i + 11, j + 6, k + 5, Blocks.air, 0, 2);
			world.setBlock(i + 12, j + 6, k + 5, NovaCraftBlocks.vanite_glass, 0, 2);
			world.setBlock(i + 13, j + 6, k + 5, Blocks.lava, 0, 2);
			world.setBlock(i + 14, j + 6, k + 5, NovaCraftBlocks.nullstone_bricks, 0, 2);
			world.setBlock(i + 0, j + 6, k + 6, NovaCraftBlocks.nullstone_bricks, 0, 2);
			world.setBlock(i + 1, j + 6, k + 6, Blocks.air, 0, 2);
			world.setBlock(i + 2, j + 6, k + 6, Blocks.air, 0, 2);
			world.setBlock(i + 3, j + 6, k + 6, Blocks.air, 0, 2);
			world.setBlock(i + 4, j + 6, k + 6, Blocks.air, 0, 2);
			world.setBlock(i + 5, j + 6, k + 6, Blocks.air, 0, 2);
			world.setBlock(i + 6, j + 6, k + 6, Blocks.air, 0, 2);
			world.setBlock(i + 7, j + 6, k + 6, Blocks.air, 0, 2);
			world.setBlock(i + 8, j + 6, k + 6, Blocks.air, 0, 2);
			world.setBlock(i + 9, j + 6, k + 6, Blocks.air, 0, 2);
			world.setBlock(i + 10, j + 6, k + 6, Blocks.air, 0, 2);
			world.setBlock(i + 11, j + 6, k + 6, Blocks.air, 0, 2);
			world.setBlock(i + 12, j + 6, k + 6, NovaCraftBlocks.vanite_glass, 0, 2);
			world.setBlock(i + 13, j + 6, k + 6, Blocks.lava, 0, 2);
			world.setBlock(i + 14, j + 6, k + 6, NovaCraftBlocks.nullstone_bricks, 0, 2);
			world.setBlock(i + 0, j + 6, k + 7, NovaCraftBlocks.nullstone_bricks, 0, 2);
			world.setBlock(i + 1, j + 6, k + 7, Blocks.air, 0, 2);
			world.setBlock(i + 2, j + 6, k + 7, Blocks.air, 0, 2);
			world.setBlock(i + 3, j + 6, k + 7, Blocks.air, 0, 2);
			world.setBlock(i + 4, j + 6, k + 7, Blocks.air, 0, 2);
			world.setBlock(i + 5, j + 6, k + 7, Blocks.air, 0, 2);
			world.setBlock(i + 6, j + 6, k + 7, Blocks.air, 0, 2);
			world.setBlock(i + 7, j + 6, k + 7, Blocks.quartz_block, 2, 2);
			world.setBlock(i + 8, j + 6, k + 7, NovaCraftBlocks.vanite_brick_stairs, 2, 2);
			world.setBlock(i + 9, j + 6, k + 7, Blocks.air, 0, 2);
			world.setBlock(i + 10, j + 6, k + 7, Blocks.air, 0, 2);
			world.setBlock(i + 11, j + 6, k + 7, Blocks.air, 0, 2);
			world.setBlock(i + 12, j + 6, k + 7, NovaCraftBlocks.vanite_glass, 0, 2);
			world.setBlock(i + 13, j + 6, k + 7, Blocks.lava, 0, 2);
			world.setBlock(i + 14, j + 6, k + 7, NovaCraftBlocks.nullstone_bricks, 0, 2);
			world.setBlock(i + 0, j + 6, k + 8, NovaCraftBlocks.nullstone_bricks, 0, 2);
			world.setBlock(i + 1, j + 6, k + 8, Blocks.air, 0, 2);
			world.setBlock(i + 2, j + 6, k + 8, Blocks.air, 0, 2);
			world.setBlock(i + 3, j + 6, k + 8, Blocks.air, 0, 2);
			world.setBlock(i + 4, j + 6, k + 8, Blocks.air, 0, 2);
			world.setBlock(i + 5, j + 6, k + 8, Blocks.air, 0, 2);
			world.setBlock(i + 6, j + 6, k + 8, Blocks.air, 0, 2);
			world.setBlock(i + 7, j + 6, k + 8, Blocks.air, 0, 2);
			world.setBlock(i + 8, j + 6, k + 8, NovaCraftBlocks.vanite_brick_slab, 8, 2);
			world.setBlock(i + 9, j + 6, k + 8, Blocks.air, 0, 2);
			world.setBlock(i + 10, j + 6, k + 8, Blocks.air, 0, 2);
			world.setBlock(i + 11, j + 6, k + 8, Blocks.air, 0, 2);
			world.setBlock(i + 12, j + 6, k + 8, NovaCraftBlocks.vanite_glass, 0, 2);
			world.setBlock(i + 13, j + 6, k + 8, Blocks.lava, 0, 2);
			world.setBlock(i + 14, j + 6, k + 8, NovaCraftBlocks.nullstone_bricks, 0, 2);
			world.setBlock(i + 0, j + 6, k + 9, NovaCraftBlocks.nullstone_bricks, 0, 2);
			world.setBlock(i + 1, j + 6, k + 9, Blocks.air, 0, 2);
			world.setBlock(i + 2, j + 6, k + 9, Blocks.air, 0, 2);
			world.setBlock(i + 3, j + 6, k + 9, Blocks.air, 0, 2);
			world.setBlock(i + 4, j + 6, k + 9, Blocks.air, 0, 2);
			world.setBlock(i + 5, j + 6, k + 9, Blocks.air, 0, 2);
			world.setBlock(i + 6, j + 6, k + 9, Blocks.air, 0, 2);
			world.setBlock(i + 7, j + 6, k + 9, Blocks.air, 0, 2);
			world.setBlock(i + 8, j + 6, k + 9, Blocks.air, 0, 2);
			world.setBlock(i + 9, j + 6, k + 9, Blocks.air, 0, 2);
			world.setBlock(i + 10, j + 6, k + 9, Blocks.air, 0, 2);
			world.setBlock(i + 11, j + 6, k + 9, Blocks.air, 0, 2);
			world.setBlock(i + 12, j + 6, k + 9, NovaCraftBlocks.vanite_glass, 0, 2);
			world.setBlock(i + 13, j + 6, k + 9, Blocks.lava, 0, 2);
			world.setBlock(i + 14, j + 6, k + 9, NovaCraftBlocks.nullstone_bricks, 0, 2);
			world.setBlock(i + 1, j + 6, k + 10, NovaCraftBlocks.nullstone_bricks, 0, 2);
			world.setBlock(i + 2, j + 6, k + 10, NovaCraftBlocks.nullstone_bricks, 0, 2);
			world.setBlock(i + 3, j + 6, k + 10, NovaCraftBlocks.polished_vanite_bricks, 0, 2);
			world.setBlock(i + 4, j + 6, k + 10, Blocks.air, 0, 2);
			world.setBlock(i + 5, j + 6, k + 10, Blocks.air, 0, 2);
			world.setBlock(i + 6, j + 6, k + 10, Blocks.air, 0, 2);
			world.setBlock(i + 7, j + 6, k + 10, Blocks.air, 0, 2);
			world.setBlock(i + 8, j + 6, k + 10, Blocks.air, 0, 2);
			world.setBlock(i + 9, j + 6, k + 10, Blocks.air, 0, 2);
			world.setBlock(i + 10, j + 6, k + 10, Blocks.air, 0, 2);
			world.setBlock(i + 11, j + 6, k + 10, NovaCraftBlocks.polished_vanite_bricks, 0, 2);
			world.setBlock(i + 12, j + 6, k + 10, NovaCraftBlocks.nullstone_bricks, 0, 2);
			world.setBlock(i + 13, j + 6, k + 10, NovaCraftBlocks.nullstone_bricks, 0, 2);
			world.setBlock(i + 4, j + 6, k + 11, NovaCraftBlocks.polished_vanite_bricks, 0, 2);
			world.setBlock(i + 5, j + 6, k + 11, Blocks.air, 0, 2);
			world.setBlock(i + 6, j + 6, k + 11, Blocks.air, 0, 2);
			world.setBlock(i + 7, j + 6, k + 11, Blocks.air, 0, 2);
			world.setBlock(i + 8, j + 6, k + 11, Blocks.air, 0, 2);
			world.setBlock(i + 9, j + 6, k + 11, Blocks.air, 0, 2);
			world.setBlock(i + 10, j + 6, k + 11, NovaCraftBlocks.polished_vanite_bricks, 0, 2);
			world.setBlock(i + 4, j + 6, k + 12, NovaCraftBlocks.nullstone_bricks, 0, 2);
			world.setBlock(i + 5, j + 6, k + 12, NovaCraftBlocks.vanite_glass, 0, 2);
			world.setBlock(i + 6, j + 6, k + 12, NovaCraftBlocks.vanite_glass, 0, 2);
			world.setBlock(i + 7, j + 6, k + 12, NovaCraftBlocks.vanite_glass, 0, 2);
			world.setBlock(i + 8, j + 6, k + 12, NovaCraftBlocks.vanite_glass, 0, 2);
			world.setBlock(i + 9, j + 6, k + 12, NovaCraftBlocks.vanite_glass, 0, 2);
			world.setBlock(i + 10, j + 6, k + 12, NovaCraftBlocks.nullstone_bricks, 0, 2);
			world.setBlock(i + 4, j + 6, k + 13, NovaCraftBlocks.nullstone_bricks, 0, 2);
			world.setBlock(i + 5, j + 6, k + 13, Blocks.lava, 0, 2);
			world.setBlock(i + 6, j + 6, k + 13, Blocks.lava, 0, 2);
			world.setBlock(i + 7, j + 6, k + 13, Blocks.lava, 0, 2);
			world.setBlock(i + 8, j + 6, k + 13, Blocks.lava, 0, 2);
			world.setBlock(i + 9, j + 6, k + 13, Blocks.lava, 0, 2);
			world.setBlock(i + 10, j + 6, k + 13, NovaCraftBlocks.nullstone_bricks, 0, 2);
			world.setBlock(i + 5, j + 6, k + 14, NovaCraftBlocks.nullstone_bricks, 0, 2);
			world.setBlock(i + 6, j + 6, k + 14, NovaCraftBlocks.nullstone_bricks, 0, 2);
			world.setBlock(i + 7, j + 6, k + 14, NovaCraftBlocks.nullstone_bricks, 0, 2);
			world.setBlock(i + 8, j + 6, k + 14, NovaCraftBlocks.nullstone_bricks, 0, 2);
			world.setBlock(i + 9, j + 6, k + 14, NovaCraftBlocks.nullstone_bricks, 0, 2);
			world.setBlock(i + 5, j + 7, k + 0, NovaCraftBlocks.nullstone_bricks, 0, 2);
			world.setBlock(i + 6, j + 7, k + 0, NovaCraftBlocks.nullstone_bricks, 0, 2);
			world.setBlock(i + 7, j + 7, k + 0, NovaCraftBlocks.nullstone_bricks, 0, 2);
			world.setBlock(i + 8, j + 7, k + 0, NovaCraftBlocks.nullstone_bricks, 0, 2);
			world.setBlock(i + 9, j + 7, k + 0, NovaCraftBlocks.nullstone_bricks, 0, 2);
			world.setBlock(i + 4, j + 7, k + 1, NovaCraftBlocks.nullstone_bricks, 0, 2);
			world.setBlock(i + 5, j + 7, k + 1, NovaCraftBlocks.vanite_glass, 0, 2);
			world.setBlock(i + 6, j + 7, k + 1, NovaCraftBlocks.vanite_glass, 0, 2);
			world.setBlock(i + 7, j + 7, k + 1, NovaCraftBlocks.vanite_glass, 0, 2);
			world.setBlock(i + 8, j + 7, k + 1, NovaCraftBlocks.vanite_glass, 0, 2);
			world.setBlock(i + 9, j + 7, k + 1, NovaCraftBlocks.vanite_glass, 0, 2);
			world.setBlock(i + 10, j + 7, k + 1, NovaCraftBlocks.nullstone_bricks, 0, 2);
			world.setBlock(i + 4, j + 7, k + 2, NovaCraftBlocks.nullstone_bricks, 0, 2);
			world.setBlock(i + 5, j + 7, k + 2, NovaCraftBlocks.nullstone_bricks, 0, 2);
			world.setBlock(i + 6, j + 7, k + 2, NovaCraftBlocks.nullstone_bricks, 0, 2);
			world.setBlock(i + 7, j + 7, k + 2, NovaCraftBlocks.nullstone_bricks, 0, 2);
			world.setBlock(i + 8, j + 7, k + 2, NovaCraftBlocks.nullstone_bricks, 0, 2);
			world.setBlock(i + 9, j + 7, k + 2, NovaCraftBlocks.nullstone_bricks, 0, 2);
			world.setBlock(i + 10, j + 7, k + 2, NovaCraftBlocks.nullstone_bricks, 0, 2);
			world.setBlock(i + 4, j + 7, k + 3, NovaCraftBlocks.polished_vanite_bricks, 0, 2);
			world.setBlock(i + 5, j + 7, k + 3, NovaCraftBlocks.polished_vanite_bricks, 0, 2);
			world.setBlock(i + 6, j + 7, k + 3, NovaCraftBlocks.polished_vanite_bricks, 0, 2);
			world.setBlock(i + 7, j + 7, k + 3, NovaCraftBlocks.polished_vanite_bricks, 0, 2);
			world.setBlock(i + 8, j + 7, k + 3, NovaCraftBlocks.polished_vanite_bricks, 0, 2);
			world.setBlock(i + 9, j + 7, k + 3, NovaCraftBlocks.polished_vanite_bricks, 0, 2);
			world.setBlock(i + 10, j + 7, k + 3, NovaCraftBlocks.polished_vanite_bricks, 0, 2);
			world.setBlock(i + 1, j + 7, k + 4, NovaCraftBlocks.nullstone_bricks, 0, 2);
			world.setBlock(i + 2, j + 7, k + 4, NovaCraftBlocks.nullstone_bricks, 0, 2);
			world.setBlock(i + 3, j + 7, k + 4, NovaCraftBlocks.polished_vanite_bricks, 0, 2);
			world.setBlock(i + 4, j + 7, k + 4, Blocks.air, 0, 2);
			world.setBlock(i + 5, j + 7, k + 4, Blocks.air, 0, 2);
			world.setBlock(i + 6, j + 7, k + 4, Blocks.air, 0, 2);
			world.setBlock(i + 7, j + 7, k + 4, Blocks.air, 0, 2);
			world.setBlock(i + 8, j + 7, k + 4, Blocks.air, 0, 2);
			world.setBlock(i + 9, j + 7, k + 4, Blocks.air, 0, 2);
			world.setBlock(i + 10, j + 7, k + 4, Blocks.air, 0, 2);
			world.setBlock(i + 11, j + 7, k + 4, NovaCraftBlocks.polished_vanite_bricks, 0, 2);
			world.setBlock(i + 12, j + 7, k + 4, NovaCraftBlocks.nullstone_bricks, 0, 2);
			world.setBlock(i + 13, j + 7, k + 4, NovaCraftBlocks.nullstone_bricks, 0, 2);
			world.setBlock(i + 0, j + 7, k + 5, NovaCraftBlocks.nullstone_bricks, 0, 2);
			world.setBlock(i + 1, j + 7, k + 5, NovaCraftBlocks.nullstone_bricks, 0, 2);
			world.setBlock(i + 2, j + 7, k + 5, NovaCraftBlocks.carved_vanite_bricks, 0, 2);
			world.setBlock(i + 3, j + 7, k + 5, NovaCraftBlocks.polished_vanite_bricks, 0, 2);
			world.setBlock(i + 4, j + 7, k + 5, Blocks.air, 0, 2);
			world.setBlock(i + 5, j + 7, k + 5, Blocks.air, 0, 2);
			world.setBlock(i + 6, j + 7, k + 5, Blocks.air, 0, 2);
			world.setBlock(i + 7, j + 7, k + 5, Blocks.air, 0, 2);
			world.setBlock(i + 8, j + 7, k + 5, Blocks.air, 0, 2);
			world.setBlock(i + 9, j + 7, k + 5, Blocks.air, 0, 2);
			world.setBlock(i + 10, j + 7, k + 5, Blocks.air, 0, 2);
			world.setBlock(i + 11, j + 7, k + 5, NovaCraftBlocks.polished_vanite_bricks, 0, 2);
			world.setBlock(i + 12, j + 7, k + 5, NovaCraftBlocks.nullstone_bricks, 0, 2);
			world.setBlock(i + 13, j + 7, k + 5, NovaCraftBlocks.vanite_glass, 0, 2);
			world.setBlock(i + 14, j + 7, k + 5, NovaCraftBlocks.nullstone_bricks, 0, 2);
			world.setBlock(i + 0, j + 7, k + 6, NovaCraftBlocks.nullstone_bricks, 0, 2);
			world.setBlock(i + 1, j + 7, k + 6, NovaCraftBlocks.nullstone_bricks, 0, 2);
			world.setBlock(i + 2, j + 7, k + 6, NovaCraftBlocks.carved_vanite_bricks, 0, 2);
			world.setBlock(i + 3, j + 7, k + 6, NovaCraftBlocks.polished_vanite_bricks, 0, 2);
			world.setBlock(i + 4, j + 7, k + 6, Blocks.air, 0, 2);
			world.setBlock(i + 5, j + 7, k + 6, Blocks.air, 0, 2);
			world.setBlock(i + 6, j + 7, k + 6, Blocks.air, 0, 2);
			world.setBlock(i + 7, j + 7, k + 6, Blocks.air, 0, 2);
			world.setBlock(i + 8, j + 7, k + 6, Blocks.air, 0, 2);
			world.setBlock(i + 9, j + 7, k + 6, Blocks.air, 0, 2);
			world.setBlock(i + 10, j + 7, k + 6, Blocks.air, 0, 2);
			world.setBlock(i + 11, j + 7, k + 6, NovaCraftBlocks.polished_vanite_bricks, 0, 2);
			world.setBlock(i + 12, j + 7, k + 6, NovaCraftBlocks.nullstone_bricks, 0, 2);
			world.setBlock(i + 13, j + 7, k + 6, NovaCraftBlocks.vanite_glass, 0, 2);
			world.setBlock(i + 14, j + 7, k + 6, NovaCraftBlocks.nullstone_bricks, 0, 2);
			world.setBlock(i + 0, j + 7, k + 7, NovaCraftBlocks.nullstone_bricks, 0, 2);
			world.setBlock(i + 1, j + 7, k + 7, NovaCraftBlocks.nullstone_bricks, 0, 2);
			world.setBlock(i + 2, j + 7, k + 7, NovaCraftBlocks.carved_vanite_bricks, 0, 2);
			world.setBlock(i + 3, j + 7, k + 7, NovaCraftBlocks.polished_vanite_bricks, 0, 2);
			world.setBlock(i + 4, j + 7, k + 7, Blocks.air, 0, 2);
			world.setBlock(i + 5, j + 7, k + 7, Blocks.air, 0, 2);
			world.setBlock(i + 6, j + 7, k + 7, Blocks.air, 0, 2);
			world.setBlock(i + 7, j + 7, k + 7, Blocks.quartz_block, 2, 2);
			world.setBlock(i + 8, j + 7, k + 7, Blocks.air, 0, 2);
			world.setBlock(i + 9, j + 7, k + 7, Blocks.air, 0, 2);
			world.setBlock(i + 10, j + 7, k + 7, Blocks.air, 0, 2);
			world.setBlock(i + 11, j + 7, k + 7, NovaCraftBlocks.polished_vanite_bricks, 0, 2);
			world.setBlock(i + 12, j + 7, k + 7, NovaCraftBlocks.nullstone_bricks, 0, 2);
			world.setBlock(i + 13, j + 7, k + 7, NovaCraftBlocks.vanite_glass, 0, 2);
			world.setBlock(i + 14, j + 7, k + 7, NovaCraftBlocks.nullstone_bricks, 0, 2);
			world.setBlock(i + 0, j + 7, k + 8, NovaCraftBlocks.nullstone_bricks, 0, 2);
			world.setBlock(i + 1, j + 7, k + 8, NovaCraftBlocks.nullstone_bricks, 0, 2);
			world.setBlock(i + 2, j + 7, k + 8, NovaCraftBlocks.carved_vanite_bricks, 0, 2);
			world.setBlock(i + 3, j + 7, k + 8, NovaCraftBlocks.polished_vanite_bricks, 0, 2);
			world.setBlock(i + 4, j + 7, k + 8, Blocks.air, 0, 2);
			world.setBlock(i + 5, j + 7, k + 8, Blocks.air, 0, 2);
			world.setBlock(i + 6, j + 7, k + 8, NovaCraftBlocks.vanite_brick_slab, 8, 2);
			world.setBlock(i + 7, j + 7, k + 8, NovaCraftBlocks.vanite_brick_stairs, 1, 2);
			world.setBlock(i + 8, j + 7, k + 8, Blocks.air, 0, 2);
			world.setBlock(i + 9, j + 7, k + 8, Blocks.air, 0, 2);
			world.setBlock(i + 10, j + 7, k + 8, Blocks.air, 0, 2);
			world.setBlock(i + 11, j + 7, k + 8, NovaCraftBlocks.polished_vanite_bricks, 0, 2);
			world.setBlock(i + 12, j + 7, k + 8, NovaCraftBlocks.nullstone_bricks, 0, 2);
			world.setBlock(i + 13, j + 7, k + 8, NovaCraftBlocks.vanite_glass, 0, 2);
			world.setBlock(i + 14, j + 7, k + 8, NovaCraftBlocks.nullstone_bricks, 0, 2);
			world.setBlock(i + 0, j + 7, k + 9, NovaCraftBlocks.nullstone_bricks, 0, 2);
			world.setBlock(i + 1, j + 7, k + 9, NovaCraftBlocks.nullstone_bricks, 0, 2);
			world.setBlock(i + 2, j + 7, k + 9, NovaCraftBlocks.carved_vanite_bricks, 0, 2);
			world.setBlock(i + 3, j + 7, k + 9, NovaCraftBlocks.polished_vanite_bricks, 0, 2);
			world.setBlock(i + 4, j + 7, k + 9, Blocks.air, 0, 2);
			world.setBlock(i + 5, j + 7, k + 9, Blocks.air, 0, 2);
			world.setBlock(i + 6, j + 7, k + 9, Blocks.air, 0, 2);
			world.setBlock(i + 7, j + 7, k + 9, Blocks.air, 0, 2);
			world.setBlock(i + 8, j + 7, k + 9, Blocks.air, 0, 2);
			world.setBlock(i + 9, j + 7, k + 9, Blocks.air, 0, 2);
			world.setBlock(i + 10, j + 7, k + 9, Blocks.air, 0, 2);
			world.setBlock(i + 11, j + 7, k + 9, NovaCraftBlocks.polished_vanite_bricks, 0, 2);
			world.setBlock(i + 12, j + 7, k + 9, NovaCraftBlocks.nullstone_bricks, 0, 2);
			world.setBlock(i + 13, j + 7, k + 9, NovaCraftBlocks.vanite_glass, 0, 2);
			world.setBlock(i + 14, j + 7, k + 9, NovaCraftBlocks.nullstone_bricks, 0, 2);
			world.setBlock(i + 1, j + 7, k + 10, NovaCraftBlocks.nullstone_bricks, 0, 2);
			world.setBlock(i + 2, j + 7, k + 10, NovaCraftBlocks.nullstone_bricks, 0, 2);
			world.setBlock(i + 3, j + 7, k + 10, NovaCraftBlocks.polished_vanite_bricks, 0, 2);
			world.setBlock(i + 4, j + 7, k + 10, Blocks.air, 0, 2);
			world.setBlock(i + 5, j + 7, k + 10, Blocks.air, 0, 2);
			world.setBlock(i + 6, j + 7, k + 10, Blocks.air, 0, 2);
			world.setBlock(i + 7, j + 7, k + 10, Blocks.air, 0, 2);
			world.setBlock(i + 8, j + 7, k + 10, Blocks.air, 0, 2);
			world.setBlock(i + 9, j + 7, k + 10, Blocks.air, 0, 2);
			world.setBlock(i + 10, j + 7, k + 10, Blocks.air, 0, 2);
			world.setBlock(i + 11, j + 7, k + 10, NovaCraftBlocks.polished_vanite_bricks, 0, 2);
			world.setBlock(i + 12, j + 7, k + 10, NovaCraftBlocks.nullstone_bricks, 0, 2);
			world.setBlock(i + 13, j + 7, k + 10, NovaCraftBlocks.nullstone_bricks, 0, 2);
			world.setBlock(i + 4, j + 7, k + 11, NovaCraftBlocks.polished_vanite_bricks, 0, 2);
			world.setBlock(i + 5, j + 7, k + 11, NovaCraftBlocks.polished_vanite_bricks, 0, 2);
			world.setBlock(i + 6, j + 7, k + 11, NovaCraftBlocks.polished_vanite_bricks, 0, 2);
			world.setBlock(i + 7, j + 7, k + 11, NovaCraftBlocks.polished_vanite_bricks, 0, 2);
			world.setBlock(i + 8, j + 7, k + 11, NovaCraftBlocks.polished_vanite_bricks, 0, 2);
			world.setBlock(i + 9, j + 7, k + 11, NovaCraftBlocks.polished_vanite_bricks, 0, 2);
			world.setBlock(i + 10, j + 7, k + 11, NovaCraftBlocks.polished_vanite_bricks, 0, 2);
			world.setBlock(i + 4, j + 7, k + 12, NovaCraftBlocks.nullstone_bricks, 0, 2);
			world.setBlock(i + 5, j + 7, k + 12, NovaCraftBlocks.nullstone_bricks, 0, 2);
			world.setBlock(i + 6, j + 7, k + 12, NovaCraftBlocks.nullstone_bricks, 0, 2);
			world.setBlock(i + 7, j + 7, k + 12, NovaCraftBlocks.nullstone_bricks, 0, 2);
			world.setBlock(i + 8, j + 7, k + 12, NovaCraftBlocks.nullstone_bricks, 0, 2);
			world.setBlock(i + 9, j + 7, k + 12, NovaCraftBlocks.nullstone_bricks, 0, 2);
			world.setBlock(i + 10, j + 7, k + 12, NovaCraftBlocks.nullstone_bricks, 0, 2);
			world.setBlock(i + 4, j + 7, k + 13, NovaCraftBlocks.nullstone_bricks, 0, 2);
			world.setBlock(i + 5, j + 7, k + 13, NovaCraftBlocks.vanite_glass, 0, 2);
			world.setBlock(i + 6, j + 7, k + 13, NovaCraftBlocks.vanite_glass, 0, 2);
			world.setBlock(i + 7, j + 7, k + 13, NovaCraftBlocks.vanite_glass, 0, 2);
			world.setBlock(i + 8, j + 7, k + 13, NovaCraftBlocks.vanite_glass, 0, 2);
			world.setBlock(i + 9, j + 7, k + 13, NovaCraftBlocks.vanite_glass, 0, 2);
			world.setBlock(i + 10, j + 7, k + 13, NovaCraftBlocks.nullstone_bricks, 0, 2);
			world.setBlock(i + 5, j + 7, k + 14, NovaCraftBlocks.nullstone_bricks, 0, 2);
			world.setBlock(i + 6, j + 7, k + 14, NovaCraftBlocks.nullstone_bricks, 0, 2);
			world.setBlock(i + 7, j + 7, k + 14, NovaCraftBlocks.nullstone_bricks, 0, 2);
			world.setBlock(i + 8, j + 7, k + 14, NovaCraftBlocks.nullstone_bricks, 0, 2);
			world.setBlock(i + 9, j + 7, k + 14, NovaCraftBlocks.nullstone_bricks, 0, 2);
			world.setBlock(i + 0, j + 8, k + 0, Blocks.air, 0, 2);
			world.setBlock(i + 1, j + 8, k + 0, Blocks.air, 0, 2);
			world.setBlock(i + 2, j + 8, k + 0, Blocks.air, 0, 2);
			world.setBlock(i + 3, j + 8, k + 0, Blocks.air, 0, 2);
			world.setBlock(i + 4, j + 8, k + 0, Blocks.air, 0, 2);
			world.setBlock(i + 5, j + 8, k + 0, Blocks.air, 0, 2);
			world.setBlock(i + 6, j + 8, k + 0, Blocks.air, 0, 2);
			world.setBlock(i + 7, j + 8, k + 0, Blocks.air, 0, 2);
			world.setBlock(i + 8, j + 8, k + 0, Blocks.air, 0, 2);
			world.setBlock(i + 9, j + 8, k + 0, Blocks.air, 0, 2);
			world.setBlock(i + 10, j + 8, k + 0, Blocks.air, 0, 2);
			world.setBlock(i + 11, j + 8, k + 0, Blocks.air, 0, 2);
			world.setBlock(i + 12, j + 8, k + 0, Blocks.air, 0, 2);
			world.setBlock(i + 13, j + 8, k + 0, Blocks.air, 0, 2);
			world.setBlock(i + 14, j + 8, k + 0, Blocks.air, 0, 2);
			world.setBlock(i + 0, j + 8, k + 1, Blocks.air, 0, 2);
			world.setBlock(i + 1, j + 8, k + 1, Blocks.air, 0, 2);
			world.setBlock(i + 2, j + 8, k + 1, Blocks.air, 0, 2);
			world.setBlock(i + 3, j + 8, k + 1, Blocks.air, 0, 2);
			world.setBlock(i + 4, j + 8, k + 1, Blocks.air, 0, 2);
			world.setBlock(i + 5, j + 8, k + 1, Blocks.air, 0, 2);
			world.setBlock(i + 6, j + 8, k + 1, Blocks.air, 0, 2);
			world.setBlock(i + 7, j + 8, k + 1, Blocks.air, 0, 2);
			world.setBlock(i + 8, j + 8, k + 1, Blocks.air, 0, 2);
			world.setBlock(i + 9, j + 8, k + 1, Blocks.air, 0, 2);
			world.setBlock(i + 10, j + 8, k + 1, Blocks.air, 0, 2);
			world.setBlock(i + 11, j + 8, k + 1, Blocks.air, 0, 2);
			world.setBlock(i + 12, j + 8, k + 1, Blocks.air, 0, 2);
			world.setBlock(i + 13, j + 8, k + 1, Blocks.air, 0, 2);
			world.setBlock(i + 14, j + 8, k + 1, Blocks.air, 0, 2);
			world.setBlock(i + 0, j + 8, k + 2, Blocks.air, 0, 2);
			world.setBlock(i + 1, j + 8, k + 2, Blocks.air, 0, 2);
			world.setBlock(i + 2, j + 8, k + 2, Blocks.air, 0, 2);
			world.setBlock(i + 3, j + 8, k + 2, Blocks.air, 0, 2);
			world.setBlock(i + 4, j + 8, k + 2, Blocks.air, 0, 2);
			world.setBlock(i + 5, j + 8, k + 2, NovaCraftBlocks.vanite_brick_stairs, 0, 2);
			world.setBlock(i + 6, j + 8, k + 2, NovaCraftBlocks.vanite_brick_stairs, 2, 2);
			world.setBlock(i + 7, j + 8, k + 2, NovaCraftBlocks.vanite_brick_stairs, 2, 2);
			world.setBlock(i + 8, j + 8, k + 2, NovaCraftBlocks.vanite_brick_stairs, 2, 2);
			world.setBlock(i + 9, j + 8, k + 2, NovaCraftBlocks.vanite_brick_stairs, 1, 2);
			world.setBlock(i + 10, j + 8, k + 2, Blocks.air, 0, 2);
			world.setBlock(i + 11, j + 8, k + 2, Blocks.air, 0, 2);
			world.setBlock(i + 12, j + 8, k + 2, Blocks.air, 0, 2);
			world.setBlock(i + 13, j + 8, k + 2, Blocks.air, 0, 2);
			world.setBlock(i + 14, j + 8, k + 2, Blocks.air, 0, 2);
			world.setBlock(i + 0, j + 8, k + 3, Blocks.air, 0, 2);
			world.setBlock(i + 1, j + 8, k + 3, Blocks.air, 0, 2);
			world.setBlock(i + 2, j + 8, k + 3, Blocks.air, 0, 2);
			world.setBlock(i + 3, j + 8, k + 3, Blocks.air, 0, 2);
			world.setBlock(i + 4, j + 8, k + 3, NovaCraftBlocks.polished_vanite_bricks, 0, 2);
			world.setBlock(i + 5, j + 8, k + 3, NovaCraftBlocks.vanite_bricks, 0, 2);
			world.setBlock(i + 6, j + 8, k + 3, NovaCraftBlocks.vanite_bricks, 0, 2);
			world.setBlock(i + 7, j + 8, k + 3, NovaCraftBlocks.vanite_bricks, 0, 2);
			world.setBlock(i + 8, j + 8, k + 3, NovaCraftBlocks.vanite_bricks, 0, 2);
			world.setBlock(i + 9, j + 8, k + 3, NovaCraftBlocks.vanite_bricks, 0, 2);
			world.setBlock(i + 10, j + 8, k + 3, NovaCraftBlocks.polished_vanite_bricks, 0, 2);
			world.setBlock(i + 11, j + 8, k + 3, Blocks.air, 0, 2);
			world.setBlock(i + 12, j + 8, k + 3, Blocks.air, 0, 2);
			world.setBlock(i + 13, j + 8, k + 3, Blocks.air, 0, 2);
			world.setBlock(i + 14, j + 8, k + 3, Blocks.air, 0, 2);
			world.setBlock(i + 0, j + 8, k + 4, Blocks.air, 0, 2);
			world.setBlock(i + 1, j + 8, k + 4, Blocks.air, 0, 2);
			world.setBlock(i + 2, j + 8, k + 4, Blocks.air, 0, 2);
			world.setBlock(i + 3, j + 8, k + 4, NovaCraftBlocks.polished_vanite_bricks, 0, 2);
			world.setBlock(i + 4, j + 8, k + 4, NovaCraftBlocks.carved_vanite_bricks, 0, 2);
			world.setBlock(i + 5, j + 8, k + 4, NovaCraftBlocks.carved_vanite_bricks, 0, 2);
			world.setBlock(i + 6, j + 8, k + 4, NovaCraftBlocks.carved_vanite_bricks, 0, 2);
			world.setBlock(i + 7, j + 8, k + 4, NovaCraftBlocks.sculk_block, 0, 2);
			world.setBlock(i + 8, j + 8, k + 4, NovaCraftBlocks.carved_vanite_bricks, 0, 2);
			world.setBlock(i + 9, j + 8, k + 4, NovaCraftBlocks.sculk_block, 0, 2);
			world.setBlock(i + 10, j + 8, k + 4, NovaCraftBlocks.carved_vanite_bricks, 0, 2);
			world.setBlock(i + 11, j + 8, k + 4, NovaCraftBlocks.polished_vanite_bricks, 0, 2);
			world.setBlock(i + 12, j + 8, k + 4, Blocks.air, 0, 2);
			world.setBlock(i + 13, j + 8, k + 4, Blocks.air, 0, 2);
			world.setBlock(i + 14, j + 8, k + 4, Blocks.air, 0, 2);
			world.setBlock(i + 0, j + 8, k + 5, Blocks.air, 0, 2);
			world.setBlock(i + 1, j + 8, k + 5, Blocks.air, 0, 2);
			world.setBlock(i + 2, j + 8, k + 5, NovaCraftBlocks.vanite_brick_stairs, 2, 2);
			world.setBlock(i + 3, j + 8, k + 5, NovaCraftBlocks.carved_vanite_bricks, 0, 2);
			world.setBlock(i + 4, j + 8, k + 5, NovaCraftBlocks.sculk_block, 0, 2);
			world.setBlock(i + 5, j + 8, k + 5, NovaCraftBlocks.carved_vanite_bricks, 0, 2);
			world.setBlock(i + 6, j + 8, k + 5, NovaCraftBlocks.carved_vanite_bricks, 0, 2);
			world.setBlock(i + 7, j + 8, k + 5, NovaCraftBlocks.carved_vanite_bricks, 0, 2);
			world.setBlock(i + 8, j + 8, k + 5, NovaCraftBlocks.carved_vanite_bricks, 0, 2);
			world.setBlock(i + 9, j + 8, k + 5, NovaCraftBlocks.carved_vanite_bricks, 0, 2);
			world.setBlock(i + 10, j + 8, k + 5, NovaCraftBlocks.carved_vanite_bricks, 0, 2);
			world.setBlock(i + 11, j + 8, k + 5, NovaCraftBlocks.vanite_bricks, 0, 2);
			world.setBlock(i + 12, j + 8, k + 5, NovaCraftBlocks.vanite_brick_stairs, 2, 2);
			world.setBlock(i + 13, j + 8, k + 5, Blocks.air, 0, 2);
			world.setBlock(i + 14, j + 8, k + 5, Blocks.air, 0, 2);
			world.setBlock(i + 0, j + 8, k + 6, Blocks.air, 0, 2);
			world.setBlock(i + 1, j + 8, k + 6, Blocks.air, 0, 2);
			world.setBlock(i + 2, j + 8, k + 6, NovaCraftBlocks.vanite_brick_stairs, 0, 2);
			world.setBlock(i + 3, j + 8, k + 6, NovaCraftBlocks.carved_vanite_bricks, 0, 2);
			world.setBlock(i + 4, j + 8, k + 6, NovaCraftBlocks.carved_vanite_bricks, 0, 2);
			world.setBlock(i + 5, j + 8, k + 6, NovaCraftBlocks.carved_vanite_bricks, 0, 2);
			world.setBlock(i + 6, j + 8, k + 6, NovaCraftBlocks.carved_vanite_bricks, 0, 2);
			world.setBlock(i + 7, j + 8, k + 6, NovaCraftBlocks.carved_vanite_bricks, 0, 2);
			world.setBlock(i + 8, j + 8, k + 6, Blocks.air, 0, 2);
			world.setBlock(i + 9, j + 8, k + 6, NovaCraftBlocks.carved_vanite_bricks, 0, 2);
			world.setBlock(i + 10, j + 8, k + 6, NovaCraftBlocks.carved_vanite_bricks, 0, 2);
			world.setBlock(i + 11, j + 8, k + 6, NovaCraftBlocks.vanite_bricks, 0, 2);
			world.setBlock(i + 12, j + 8, k + 6, NovaCraftBlocks.vanite_brick_stairs, 1, 2);
			world.setBlock(i + 13, j + 8, k + 6, Blocks.air, 0, 2);
			world.setBlock(i + 14, j + 8, k + 6, Blocks.air, 0, 2);
			world.setBlock(i + 0, j + 8, k + 7, Blocks.air, 0, 2);
			world.setBlock(i + 1, j + 8, k + 7, Blocks.air, 0, 2);
			world.setBlock(i + 2, j + 8, k + 7, NovaCraftBlocks.vanite_brick_stairs, 0, 2);
			world.setBlock(i + 3, j + 8, k + 7, NovaCraftBlocks.carved_vanite_bricks, 0, 2);
			world.setBlock(i + 4, j + 8, k + 7, NovaCraftBlocks.carved_vanite_bricks, 0, 2);
			world.setBlock(i + 5, j + 8, k + 7, NovaCraftBlocks.carved_vanite_bricks, 0, 2);
			world.setBlock(i + 6, j + 8, k + 7, NovaCraftBlocks.vanite_brick_stairs, 3, 2);
			world.setBlock(i + 7, j + 8, k + 7, Blocks.quartz_block, 2, 2);
			world.setBlock(i + 8, j + 8, k + 7, Blocks.air, 0, 2);
			world.setBlock(i + 9, j + 8, k + 7, NovaCraftBlocks.carved_vanite_bricks, 0, 2);
			world.setBlock(i + 10, j + 8, k + 7, NovaCraftBlocks.carved_vanite_bricks, 0, 2);
			world.setBlock(i + 11, j + 8, k + 7, NovaCraftBlocks.vanite_bricks, 0, 2);
			world.setBlock(i + 12, j + 8, k + 7, NovaCraftBlocks.vanite_brick_stairs, 1, 2);
			world.setBlock(i + 13, j + 8, k + 7, Blocks.air, 0, 2);
			world.setBlock(i + 14, j + 8, k + 7, Blocks.air, 0, 2);
			world.setBlock(i + 0, j + 8, k + 8, Blocks.air, 0, 2);
			world.setBlock(i + 1, j + 8, k + 8, Blocks.air, 0, 2);
			world.setBlock(i + 2, j + 8, k + 8, NovaCraftBlocks.vanite_brick_stairs, 0, 2);
			world.setBlock(i + 3, j + 8, k + 8, NovaCraftBlocks.carved_vanite_bricks, 0, 2);
			world.setBlock(i + 4, j + 8, k + 8, NovaCraftBlocks.carved_vanite_bricks, 0, 2);
			world.setBlock(i + 5, j + 8, k + 8, NovaCraftBlocks.carved_vanite_bricks, 0, 2);
			world.setBlock(i + 6, j + 8, k + 8, Blocks.air, 0, 2);
			world.setBlock(i + 7, j + 8, k + 8, Blocks.air, 0, 2);
			world.setBlock(i + 8, j + 8, k + 8, Blocks.air, 0, 2);
			world.setBlock(i + 9, j + 8, k + 8, NovaCraftBlocks.carved_vanite_bricks, 0, 2);
			world.setBlock(i + 10, j + 8, k + 8, NovaCraftBlocks.carved_vanite_bricks, 0, 2);
			world.setBlock(i + 11, j + 8, k + 8, NovaCraftBlocks.vanite_bricks, 0, 2);
			world.setBlock(i + 12, j + 8, k + 8, NovaCraftBlocks.vanite_brick_stairs, 1, 2);
			world.setBlock(i + 13, j + 8, k + 8, Blocks.air, 0, 2);
			world.setBlock(i + 14, j + 8, k + 8, Blocks.air, 0, 2);
			world.setBlock(i + 0, j + 8, k + 9, Blocks.air, 0, 2);
			world.setBlock(i + 1, j + 8, k + 9, Blocks.air, 0, 2);
			world.setBlock(i + 2, j + 8, k + 9, NovaCraftBlocks.vanite_brick_stairs, 3, 2);
			world.setBlock(i + 3, j + 8, k + 9, NovaCraftBlocks.carved_vanite_bricks, 0, 2);
			world.setBlock(i + 4, j + 8, k + 9, NovaCraftBlocks.carved_vanite_bricks, 0, 2);
			world.setBlock(i + 5, j + 8, k + 9, NovaCraftBlocks.sculk_block, 0, 2);
			world.setBlock(i + 6, j + 8, k + 9, NovaCraftBlocks.carved_vanite_bricks, 0, 2);
			world.setBlock(i + 7, j + 8, k + 9, NovaCraftBlocks.carved_vanite_bricks, 0, 2);
			world.setBlock(i + 8, j + 8, k + 9, NovaCraftBlocks.carved_vanite_bricks, 0, 2);
			world.setBlock(i + 9, j + 8, k + 9, NovaCraftBlocks.carved_vanite_bricks, 0, 2);
			world.setBlock(i + 10, j + 8, k + 9, NovaCraftBlocks.carved_vanite_bricks, 0, 2);
			world.setBlock(i + 11, j + 8, k + 9, NovaCraftBlocks.vanite_bricks, 0, 2);
			world.setBlock(i + 12, j + 8, k + 9, NovaCraftBlocks.vanite_brick_stairs, 3, 2);
			world.setBlock(i + 13, j + 8, k + 9, Blocks.air, 0, 2);
			world.setBlock(i + 14, j + 8, k + 9, Blocks.air, 0, 2);
			world.setBlock(i + 0, j + 8, k + 10, Blocks.air, 0, 2);
			world.setBlock(i + 1, j + 8, k + 10, Blocks.air, 0, 2);
			world.setBlock(i + 2, j + 8, k + 10, Blocks.air, 0, 2);
			world.setBlock(i + 3, j + 8, k + 10, NovaCraftBlocks.polished_vanite_bricks, 0, 2);
			world.setBlock(i + 4, j + 8, k + 10, NovaCraftBlocks.carved_vanite_bricks, 0, 2);
			world.setBlock(i + 5, j + 8, k + 10, NovaCraftBlocks.carved_vanite_bricks, 0, 2);
			world.setBlock(i + 6, j + 8, k + 10, NovaCraftBlocks.carved_vanite_bricks, 0, 2);
			world.setBlock(i + 7, j + 8, k + 10, NovaCraftBlocks.carved_vanite_bricks, 0, 2);
			world.setBlock(i + 8, j + 8, k + 10, NovaCraftBlocks.carved_vanite_bricks, 0, 2);
			world.setBlock(i + 9, j + 8, k + 10, NovaCraftBlocks.sculk_block, 0, 2);
			world.setBlock(i + 10, j + 8, k + 10, NovaCraftBlocks.carved_vanite_bricks, 0, 2);
			world.setBlock(i + 11, j + 8, k + 10, NovaCraftBlocks.polished_vanite_bricks, 0, 2);
			world.setBlock(i + 12, j + 8, k + 10, Blocks.air, 0, 2);
			world.setBlock(i + 13, j + 8, k + 10, Blocks.air, 0, 2);
			world.setBlock(i + 14, j + 8, k + 10, Blocks.air, 0, 2);
			world.setBlock(i + 0, j + 8, k + 11, Blocks.air, 0, 2);
			world.setBlock(i + 1, j + 8, k + 11, Blocks.air, 0, 2);
			world.setBlock(i + 2, j + 8, k + 11, Blocks.air, 0, 2);
			world.setBlock(i + 3, j + 8, k + 11, Blocks.air, 0, 2);
			world.setBlock(i + 4, j + 8, k + 11, NovaCraftBlocks.polished_vanite_bricks, 0, 2);
			world.setBlock(i + 5, j + 8, k + 11, NovaCraftBlocks.vanite_bricks, 0, 2);
			world.setBlock(i + 6, j + 8, k + 11, NovaCraftBlocks.vanite_bricks, 0, 2);
			world.setBlock(i + 7, j + 8, k + 11, NovaCraftBlocks.vanite_bricks, 0, 2);
			world.setBlock(i + 8, j + 8, k + 11, NovaCraftBlocks.vanite_bricks, 0, 2);
			world.setBlock(i + 9, j + 8, k + 11, NovaCraftBlocks.vanite_bricks, 0, 2);
			world.setBlock(i + 10, j + 8, k + 11, NovaCraftBlocks.polished_vanite_bricks, 0, 2);
			world.setBlock(i + 11, j + 8, k + 11, Blocks.air, 0, 2);
			world.setBlock(i + 12, j + 8, k + 11, Blocks.air, 0, 2);
			world.setBlock(i + 13, j + 8, k + 11, Blocks.air, 0, 2);
			world.setBlock(i + 14, j + 8, k + 11, Blocks.air, 0, 2);
			world.setBlock(i + 0, j + 8, k + 12, Blocks.air, 0, 2);
			world.setBlock(i + 1, j + 8, k + 12, Blocks.air, 0, 2);
			world.setBlock(i + 2, j + 8, k + 12, Blocks.air, 0, 2);
			world.setBlock(i + 3, j + 8, k + 12, Blocks.air, 0, 2);
			world.setBlock(i + 4, j + 8, k + 12, Blocks.air, 0, 2);
			world.setBlock(i + 5, j + 8, k + 12, NovaCraftBlocks.vanite_brick_stairs, 0, 2);
			world.setBlock(i + 6, j + 8, k + 12, NovaCraftBlocks.vanite_brick_stairs, 3, 2);
			world.setBlock(i + 7, j + 8, k + 12, NovaCraftBlocks.vanite_brick_stairs, 3, 2);
			world.setBlock(i + 8, j + 8, k + 12, NovaCraftBlocks.vanite_brick_stairs, 3, 2);
			world.setBlock(i + 9, j + 8, k + 12, NovaCraftBlocks.vanite_brick_stairs, 1, 2);
			world.setBlock(i + 10, j + 8, k + 12, Blocks.air, 0, 2);
			world.setBlock(i + 11, j + 8, k + 12, Blocks.air, 0, 2);
			world.setBlock(i + 12, j + 8, k + 12, Blocks.air, 0, 2);
			world.setBlock(i + 13, j + 8, k + 12, Blocks.air, 0, 2);
			world.setBlock(i + 14, j + 8, k + 12, Blocks.air, 0, 2);
			world.setBlock(i + 0, j + 8, k + 13, Blocks.air, 0, 2);
			world.setBlock(i + 1, j + 8, k + 13, Blocks.air, 0, 2);
			world.setBlock(i + 2, j + 8, k + 13, Blocks.air, 0, 2);
			world.setBlock(i + 3, j + 8, k + 13, Blocks.air, 0, 2);
			world.setBlock(i + 4, j + 8, k + 13, Blocks.air, 0, 2);
			world.setBlock(i + 5, j + 8, k + 13, Blocks.air, 0, 2);
			world.setBlock(i + 6, j + 8, k + 13, Blocks.air, 0, 2);
			world.setBlock(i + 7, j + 8, k + 13, Blocks.air, 0, 2);
			world.setBlock(i + 8, j + 8, k + 13, Blocks.air, 0, 2);
			world.setBlock(i + 9, j + 8, k + 13, Blocks.air, 0, 2);
			world.setBlock(i + 10, j + 8, k + 13, Blocks.air, 0, 2);
			world.setBlock(i + 11, j + 8, k + 13, Blocks.air, 0, 2);
			world.setBlock(i + 12, j + 8, k + 13, Blocks.air, 0, 2);
			world.setBlock(i + 13, j + 8, k + 13, Blocks.air, 0, 2);
			world.setBlock(i + 14, j + 8, k + 13, Blocks.air, 0, 2);
			world.setBlock(i + 0, j + 8, k + 14, Blocks.air, 0, 2);
			world.setBlock(i + 1, j + 8, k + 14, Blocks.air, 0, 2);
			world.setBlock(i + 2, j + 8, k + 14, Blocks.air, 0, 2);
			world.setBlock(i + 3, j + 8, k + 14, Blocks.air, 0, 2);
			world.setBlock(i + 4, j + 8, k + 14, Blocks.air, 0, 2);
			world.setBlock(i + 5, j + 8, k + 14, Blocks.air, 0, 2);
			world.setBlock(i + 6, j + 8, k + 14, Blocks.air, 0, 2);
			world.setBlock(i + 7, j + 8, k + 14, Blocks.air, 0, 2);
			world.setBlock(i + 8, j + 8, k + 14, Blocks.air, 0, 2);
			world.setBlock(i + 9, j + 8, k + 14, Blocks.air, 0, 2);
			world.setBlock(i + 10, j + 8, k + 14, Blocks.air, 0, 2);
			world.setBlock(i + 11, j + 8, k + 14, Blocks.air, 0, 2);
			world.setBlock(i + 12, j + 8, k + 14, Blocks.air, 0, 2);
			world.setBlock(i + 13, j + 8, k + 14, Blocks.air, 0, 2);
			world.setBlock(i + 14, j + 8, k + 14, Blocks.air, 0, 2);
			world.setBlock(i + 0, j + 9, k + 0, Blocks.air, 0, 2);
			world.setBlock(i + 1, j + 9, k + 0, Blocks.air, 0, 2);
			world.setBlock(i + 2, j + 9, k + 0, Blocks.air, 0, 2);
			world.setBlock(i + 3, j + 9, k + 0, Blocks.air, 0, 2);
			world.setBlock(i + 4, j + 9, k + 0, Blocks.air, 0, 2);
			world.setBlock(i + 5, j + 9, k + 0, Blocks.air, 0, 2);
			world.setBlock(i + 6, j + 9, k + 0, Blocks.air, 0, 2);
			world.setBlock(i + 7, j + 9, k + 0, Blocks.air, 0, 2);
			world.setBlock(i + 8, j + 9, k + 0, Blocks.air, 0, 2);
			world.setBlock(i + 9, j + 9, k + 0, Blocks.air, 0, 2);
			world.setBlock(i + 10, j + 9, k + 0, Blocks.air, 0, 2);
			world.setBlock(i + 11, j + 9, k + 0, Blocks.air, 0, 2);
			world.setBlock(i + 12, j + 9, k + 0, Blocks.air, 0, 2);
			world.setBlock(i + 13, j + 9, k + 0, Blocks.air, 0, 2);
			world.setBlock(i + 14, j + 9, k + 0, Blocks.air, 0, 2);
			world.setBlock(i + 0, j + 9, k + 1, Blocks.air, 0, 2);
			world.setBlock(i + 1, j + 9, k + 1, Blocks.air, 0, 2);
			world.setBlock(i + 2, j + 9, k + 1, Blocks.air, 0, 2);
			world.setBlock(i + 3, j + 9, k + 1, Blocks.air, 0, 2);
			world.setBlock(i + 4, j + 9, k + 1, Blocks.air, 0, 2);
			world.setBlock(i + 5, j + 9, k + 1, Blocks.air, 0, 2);
			world.setBlock(i + 6, j + 9, k + 1, Blocks.air, 0, 2);
			world.setBlock(i + 7, j + 9, k + 1, Blocks.air, 0, 2);
			world.setBlock(i + 8, j + 9, k + 1, Blocks.air, 0, 2);
			world.setBlock(i + 9, j + 9, k + 1, Blocks.air, 0, 2);
			world.setBlock(i + 10, j + 9, k + 1, Blocks.air, 0, 2);
			world.setBlock(i + 11, j + 9, k + 1, Blocks.air, 0, 2);
			world.setBlock(i + 12, j + 9, k + 1, Blocks.air, 0, 2);
			world.setBlock(i + 13, j + 9, k + 1, Blocks.air, 0, 2);
			world.setBlock(i + 14, j + 9, k + 1, Blocks.air, 0, 2);
			world.setBlock(i + 0, j + 9, k + 2, Blocks.air, 0, 2);
			world.setBlock(i + 1, j + 9, k + 2, Blocks.air, 0, 2);
			world.setBlock(i + 2, j + 9, k + 2, Blocks.air, 0, 2);
			world.setBlock(i + 3, j + 9, k + 2, Blocks.air, 0, 2);
			world.setBlock(i + 4, j + 9, k + 2, Blocks.air, 0, 2);
			world.setBlock(i + 5, j + 9, k + 2, Blocks.air, 0, 2);
			world.setBlock(i + 6, j + 9, k + 2, Blocks.air, 0, 2);
			world.setBlock(i + 7, j + 9, k + 2, Blocks.air, 0, 2);
			world.setBlock(i + 8, j + 9, k + 2, Blocks.air, 0, 2);
			world.setBlock(i + 9, j + 9, k + 2, Blocks.air, 0, 2);
			world.setBlock(i + 10, j + 9, k + 2, Blocks.air, 0, 2);
			world.setBlock(i + 11, j + 9, k + 2, Blocks.air, 0, 2);
			world.setBlock(i + 12, j + 9, k + 2, Blocks.air, 0, 2);
			world.setBlock(i + 13, j + 9, k + 2, Blocks.air, 0, 2);
			world.setBlock(i + 14, j + 9, k + 2, Blocks.air, 0, 2);
			world.setBlock(i + 0, j + 9, k + 3, Blocks.air, 0, 2);
			world.setBlock(i + 1, j + 9, k + 3, Blocks.air, 0, 2);
			world.setBlock(i + 2, j + 9, k + 3, Blocks.air, 0, 2);
			world.setBlock(i + 3, j + 9, k + 3, Blocks.air, 0, 2);
			world.setBlock(i + 4, j + 9, k + 3, NovaCraftBlocks.polished_vanite_bricks, 0, 2);
			world.setBlock(i + 5, j + 9, k + 3, NovaCraftBlocks.vanite_bricks, 0, 2);
			world.setBlock(i + 6, j + 9, k + 3, NovaCraftBlocks.vanite_bricks, 0, 2);
			world.setBlock(i + 7, j + 9, k + 3, NovaCraftBlocks.vanite_bricks, 0, 2);
			world.setBlock(i + 8, j + 9, k + 3, NovaCraftBlocks.vanite_bricks, 0, 2);
			world.setBlock(i + 9, j + 9, k + 3, NovaCraftBlocks.vanite_bricks, 0, 2);
			world.setBlock(i + 10, j + 9, k + 3, NovaCraftBlocks.polished_vanite_bricks, 0, 2);
			world.setBlock(i + 11, j + 9, k + 3, Blocks.air, 0, 2);
			world.setBlock(i + 12, j + 9, k + 3, Blocks.air, 0, 2);
			world.setBlock(i + 13, j + 9, k + 3, Blocks.air, 0, 2);
			world.setBlock(i + 14, j + 9, k + 3, Blocks.air, 0, 2);
			world.setBlock(i + 0, j + 9, k + 4, Blocks.air, 0, 2);
			world.setBlock(i + 1, j + 9, k + 4, Blocks.air, 0, 2);
			world.setBlock(i + 2, j + 9, k + 4, Blocks.air, 0, 2);
			world.setBlock(i + 3, j + 9, k + 4, NovaCraftBlocks.polished_vanite_bricks, 0, 2);
			world.setBlock(i + 4, j + 9, k + 4, Blocks.air, 0, 2);
			world.setBlock(i + 5, j + 9, k + 4, Blocks.air, 0, 2);
			world.setBlock(i + 6, j + 9, k + 4, Blocks.air, 0, 2);
			world.setBlock(i + 7, j + 9, k + 4, NovaCraftBlocks.sculk_tentacle_2, 1, 2);
			world.setBlock(i + 8, j + 9, k + 4, Blocks.air, 0, 2);
			world.setBlock(i + 10, j + 9, k + 4, Blocks.air, 0, 2);
			world.setBlock(i + 11, j + 9, k + 4, NovaCraftBlocks.polished_vanite_bricks, 0, 2);
			world.setBlock(i + 12, j + 9, k + 4, Blocks.air, 0, 2);
			world.setBlock(i + 13, j + 9, k + 4, Blocks.air, 0, 2);
			world.setBlock(i + 14, j + 9, k + 4, Blocks.air, 0, 2);
			world.setBlock(i + 0, j + 9, k + 5, Blocks.air, 0, 2);
			world.setBlock(i + 1, j + 9, k + 5, Blocks.air, 0, 2);
			world.setBlock(i + 2, j + 9, k + 5, Blocks.air, 0, 2);
			world.setBlock(i + 3, j + 9, k + 5, NovaCraftBlocks.vanite_bricks, 0, 2);
			world.setBlock(i + 4, j + 9, k + 5, NovaCraftBlocks.sculk_spike, 1, 2);
			world.setBlock(i + 5, j + 9, k + 5, NovaCraftBlocks.carved_vanite_bricks, 0, 2);
			world.setBlock(i + 6, j + 9, k + 5, Blocks.air, 0, 2);
			world.setBlock(i + 7, j + 9, k + 5, Blocks.air, 0, 2);
			world.setBlock(i + 8, j + 9, k + 5, Blocks.air, 0, 2);
			world.setBlock(i + 9, j + 9, k + 5, Blocks.air, 0, 2);
			world.setBlock(i + 10, j + 9, k + 5, Blocks.air, 0, 2);
			world.setBlock(i + 11, j + 9, k + 5, NovaCraftBlocks.vanite_bricks, 0, 2);
			world.setBlock(i + 12, j + 9, k + 5, Blocks.air, 0, 2);
			world.setBlock(i + 13, j + 9, k + 5, Blocks.air, 0, 2);
			world.setBlock(i + 14, j + 9, k + 5, Blocks.air, 0, 2);
			world.setBlock(i + 0, j + 9, k + 6, Blocks.air, 0, 2);
			world.setBlock(i + 1, j + 9, k + 6, Blocks.air, 0, 2);
			world.setBlock(i + 2, j + 9, k + 6, Blocks.air, 0, 2);
			world.setBlock(i + 3, j + 9, k + 6, Blocks.air, 0, 2);
			world.setBlock(i + 4, j + 9, k + 6, Blocks.air, 0, 2);
			world.setBlock(i + 5, j + 9, k + 6, Blocks.air, 0, 2);
			world.setBlock(i + 6, j + 9, k + 6, Blocks.air, 0, 2);
			world.setBlock(i + 7, j + 9, k + 6, Blocks.air, 0, 2);
			world.setBlock(i + 8, j + 9, k + 6, Blocks.air, 0, 2);
			world.setBlock(i + 9, j + 9, k + 6, NovaCraftBlocks.carved_vanite_bricks, 0, 2);
			world.setBlock(i + 10, j + 9, k + 6, Blocks.air, 0, 2);
			world.setBlock(i + 11, j + 9, k + 6, NovaCraftBlocks.vanite_bricks, 0, 2);
			world.setBlock(i + 12, j + 9, k + 6, Blocks.air, 0, 2);
			world.setBlock(i + 13, j + 9, k + 6, Blocks.air, 0, 2);
			world.setBlock(i + 14, j + 9, k + 6, Blocks.air, 0, 2);
			world.setBlock(i + 0, j + 9, k + 7, Blocks.air, 0, 2);
			world.setBlock(i + 1, j + 9, k + 7, Blocks.air, 0, 2);
			world.setBlock(i + 2, j + 9, k + 7, Blocks.air, 0, 2);
			world.setBlock(i + 3, j + 9, k + 7, Blocks.air, 0, 2);
			world.setBlock(i + 4, j + 9, k + 7, Blocks.air, 0, 2);
			world.setBlock(i + 5, j + 9, k + 7, Blocks.air, 0, 2);
			world.setBlock(i + 6, j + 9, k + 7, Blocks.air, 0, 2);
			world.setBlock(i + 7, j + 9, k + 7, Blocks.quartz_block, 2, 2);
			world.setBlock(i + 8, j + 9, k + 7, Blocks.air, 0, 2);
			world.setBlock(i + 9, j + 9, k + 7, Blocks.air, 0, 2);
			world.setBlock(i + 10, j + 9, k + 7, Blocks.air, 0, 2);
			world.setBlock(i + 11, j + 9, k + 7, NovaCraftBlocks.vanite_bricks, 0, 2);
			world.setBlock(i + 12, j + 9, k + 7, Blocks.air, 0, 2);
			world.setBlock(i + 13, j + 9, k + 7, Blocks.air, 0, 2);
			world.setBlock(i + 14, j + 9, k + 7, Blocks.air, 0, 2);
			world.setBlock(i + 0, j + 9, k + 8, Blocks.air, 0, 2);
			world.setBlock(i + 1, j + 9, k + 8, Blocks.air, 0, 2);
			world.setBlock(i + 2, j + 9, k + 8, Blocks.air, 0, 2);
			world.setBlock(i + 3, j + 9, k + 8, Blocks.air, 0, 2);
			world.setBlock(i + 4, j + 9, k + 8, Blocks.air, 0, 2);
