package com.NovaCraft.world.ancient_city;

import net.minecraft.world.gen.feature.*;
import net.minecraft.block.*;
import net.minecraft.enchantment.Enchantment;
import net.minecraft.enchantment.EnchantmentData;
import net.minecraft.world.*;
import java.util.*;

import com.NovaCraft.Items.NovaCraftItems;
import com.NovaCraft.entity.EntityWardenVessel;
import com.NovaCraft.registry.OtherModBlocks;
import com.NovaCraft.registry.OtherModItems;
import com.NovaCraftBlocks.NovaCraftBlocks;

import cpw.mods.fml.common.Loader;
import net.minecraft.init.*;
import net.minecraft.item.ItemStack;
import net.minecraft.tileentity.TileEntityChest;
import net.minecraft.tileentity.TileEntityMobSpawner;
import net.minecraft.util.MathHelper;

public class AncientCityShrineGen1 extends WorldGenerator
{
	public AncientCityShrineGen1() {

	}
	
	private static final Block cobbled_deepslate = OtherModBlocks.cobbled_deepslate;
	private static final Block deepslate = OtherModBlocks.deepslate;
	private static final Block sculk_block = NovaCraftBlocks.sculk_block;
	private static final Block soul_lantern = OtherModBlocks.soul_lantern; //1
	private static final Block soul_sand = Blocks.netherrack;
	
	private static final Block polished_deepslate = OtherModBlocks.polished_deepslate;
	private static final Block deepslate_brick_slab = OtherModBlocks.deepslate_brick_slab;
	private static final Block deepslate_tile_stairs = OtherModBlocks.deepslate_tile_stairs;
	private static final Block deepslate_brick_stairs = OtherModBlocks.deepslate_brick_stairs;
	private static final Block polished_deepslate_stairs = OtherModBlocks.polished_deepslate_stairs;
	private static final Block deepslate_wall = OtherModBlocks.deepslate_wall;
	private static final Block deepslate_brick_wall = OtherModBlocks.deepslate_brick_wall;
	private static final Block fence_dark_oak = OtherModBlocks.fence_dark_oak;
	private static final Block blue_ice = OtherModBlocks.blue_ice;
	private static final Block iron_trapdoor = OtherModBlocks.iron_trapdoor;
	
	private static final Block deepslate_bricks = OtherModBlocks.deepslate_bricks;
	private static final Block cobbled_deepslate_stairs = OtherModBlocks.cobbled_deepslate_stairs;
	
	private static final Block basalt = OtherModBlocks.Basalt; //netherlicious
	private static final Block basalt1 = OtherModBlocks.basalt; //et futurum requiem

	//0 -> deepslate bricks
	//1 -> cracked deepslate bricks
	//2 -> deepslate tiles
	//3 -> cracked deepslate bricks
	//4 -> chiseled deepslate bricks
    
    public boolean generate(final World world, final Random random, final int i, final int j, final int k) {
    	
    	world.setBlock(i + 0, j + 0, k + 0, Blocks.air, 0, 2);
		world.setBlock(i + 1, j + 0, k + 0, Blocks.air, 0, 2);
		world.setBlock(i + 2, j + 0, k + 0, Blocks.air, 0, 2);
		world.setBlock(i + 3, j + 0, k + 0, Blocks.air, 0, 2);
		world.setBlock(i + 4, j + 0, k + 0, Blocks.air, 0, 2);
		world.setBlock(i + 5, j + 0, k + 0, Blocks.air, 0, 2);
		world.setBlock(i + 6, j + 0, k + 0, Blocks.air, 0, 2);
		world.setBlock(i + 7, j + 0, k + 0, Blocks.air, 0, 2);
		world.setBlock(i + 8, j + 0, k + 0, Blocks.air, 0, 2);
		world.setBlock(i + 9, j + 0, k + 0, Blocks.air, 0, 2);
		world.setBlock(i + 10, j + 0, k + 0, Blocks.air, 0, 2);
		world.setBlock(i + 11, j + 0, k + 0, Blocks.air, 0, 2);
		world.setBlock(i + 12, j + 0, k + 0, Blocks.air, 0, 2);
		world.setBlock(i + 13, j + 0, k + 0, Blocks.air, 0, 2);
		world.setBlock(i + 14, j + 0, k + 0, Blocks.air, 0, 2);
		world.setBlock(i + 15, j + 0, k + 0, Blocks.air, 0, 2);
		world.setBlock(i + 16, j + 0, k + 0, Blocks.air, 0, 2);
		world.setBlock(i + 17, j + 0, k + 0, Blocks.air, 0, 2);
		world.setBlock(i + 18, j + 0, k + 0, Blocks.air, 0, 2);
		world.setBlock(i + 19, j + 0, k + 0, Blocks.air, 0, 2);
		world.setBlock(i + 20, j + 0, k + 0, Blocks.air, 0, 2);
		world.setBlock(i + 0, j + 0, k + 1, Blocks.air, 0, 2);
		world.setBlock(i + 1, j + 0, k + 1, deepslate, 0, 2);
		world.setBlock(i + 2, j + 0, k + 1, deepslate, 0, 2);
		world.setBlock(i + 3, j + 0, k + 1, deepslate, 0, 2);
		world.setBlock(i + 4, j + 0, k + 1, deepslate, 0, 2);
		world.setBlock(i + 5, j + 0, k + 1, deepslate, 0, 2);
		world.setBlock(i + 6, j + 0, k + 1, deepslate, 0, 2);
		world.setBlock(i + 7, j + 0, k + 1, deepslate, 0, 2);
		world.setBlock(i + 8, j + 0, k + 1, deepslate, 0, 2);
		world.setBlock(i + 9, j + 0, k + 1, deepslate, 0, 2);
		world.setBlock(i + 10, j + 0, k + 1, deepslate, 0, 2);
		world.setBlock(i + 11, j + 0, k + 1, deepslate, 0, 2);
		world.setBlock(i + 12, j + 0, k + 1, Blocks.air, 0, 2);
		world.setBlock(i + 13, j + 0, k + 1, deepslate, 0, 2);
		world.setBlock(i + 14, j + 0, k + 1, deepslate, 0, 2);
		world.setBlock(i + 15, j + 0, k + 1, deepslate, 0, 2);
		world.setBlock(i + 16, j + 0, k + 1, deepslate, 0, 2);
		world.setBlock(i + 17, j + 0, k + 1, deepslate, 0, 2);
		world.setBlock(i + 18, j + 0, k + 1, deepslate, 0, 2);
		world.setBlock(i + 19, j + 0, k + 1, deepslate, 0, 2);
		world.setBlock(i + 20, j + 0, k + 1, Blocks.air, 0, 2);
		world.setBlock(i + 0, j + 0, k + 2, Blocks.air, 0, 2);
		world.setBlock(i + 1, j + 0, k + 2, deepslate, 0, 2);
		world.setBlock(i + 2, j + 0, k + 2, deepslate, 0, 2);
		world.setBlock(i + 3, j + 0, k + 2, deepslate, 0, 2);
		world.setBlock(i + 4, j + 0, k + 2, deepslate, 0, 2);
		world.setBlock(i + 5, j + 0, k + 2, deepslate, 0, 2);
		world.setBlock(i + 6, j + 0, k + 2, deepslate, 0, 2);
		world.setBlock(i + 7, j + 0, k + 2, deepslate, 0, 2);
		world.setBlock(i + 8, j + 0, k + 2, deepslate, 0, 2);
		world.setBlock(i + 9, j + 0, k + 2, deepslate, 0, 2);
		world.setBlock(i + 10, j + 0, k + 2, deepslate, 0, 2);
		world.setBlock(i + 11, j + 0, k + 2, deepslate, 0, 2);
		world.setBlock(i + 12, j + 0, k + 2, deepslate, 0, 2);
		world.setBlock(i + 13, j + 0, k + 2, deepslate, 0, 2);
		world.setBlock(i + 14, j + 0, k + 2, deepslate, 0, 2);
		world.setBlock(i + 15, j + 0, k + 2, deepslate, 0, 2);
		world.setBlock(i + 16, j + 0, k + 2, Blocks.air, 0, 2);
		world.setBlock(i + 17, j + 0, k + 2, deepslate, 0, 2);
		world.setBlock(i + 18, j + 0, k + 2, deepslate, 0, 2);
		world.setBlock(i + 19, j + 0, k + 2, deepslate, 0, 2);
		world.setBlock(i + 20, j + 0, k + 2, Blocks.air, 0, 2);
		world.setBlock(i + 0, j + 0, k + 3, Blocks.air, 0, 2);
		world.setBlock(i + 1, j + 0, k + 3, deepslate, 0, 2);
		world.setBlock(i + 2, j + 0, k + 3, deepslate, 0, 2);
		world.setBlock(i + 3, j + 0, k + 3, deepslate, 0, 2);
		world.setBlock(i + 4, j + 0, k + 3, deepslate, 0, 2);
		world.setBlock(i + 5, j + 0, k + 3, deepslate, 0, 2);
		world.setBlock(i + 6, j + 0, k + 3, deepslate, 0, 2);
		world.setBlock(i + 7, j + 0, k + 3, deepslate, 0, 2);
		world.setBlock(i + 8, j + 0, k + 3, deepslate, 0, 2);
		world.setBlock(i + 9, j + 0, k + 3, deepslate, 0, 2);
		world.setBlock(i + 10, j + 0, k + 3, deepslate, 0, 2);
		world.setBlock(i + 11, j + 0, k + 3, deepslate, 0, 2);
		world.setBlock(i + 12, j + 0, k + 3, deepslate, 0, 2);
		world.setBlock(i + 13, j + 0, k + 3, deepslate, 0, 2);
		world.setBlock(i + 14, j + 0, k + 3, deepslate, 0, 2);
		world.setBlock(i + 15, j + 0, k + 3, deepslate, 0, 2);
		world.setBlock(i + 16, j + 0, k + 3, deepslate, 0, 2);
		world.setBlock(i + 17, j + 0, k + 3, deepslate, 0, 2);
		world.setBlock(i + 18, j + 0, k + 3, deepslate, 0, 2);
		world.setBlock(i + 19, j + 0, k + 3, deepslate, 0, 2);
		world.setBlock(i + 20, j + 0, k + 3, Blocks.air, 0, 2);
		world.setBlock(i + 0, j + 0, k + 4, Blocks.air, 0, 2);
		world.setBlock(i + 1, j + 0, k + 4, deepslate, 0, 2);
		world.setBlock(i + 2, j + 0, k + 4, deepslate, 0, 2);
		world.setBlock(i + 3, j + 0, k + 4, deepslate, 0, 2);
		world.setBlock(i + 4, j + 0, k + 4, deepslate, 0, 2);
		world.setBlock(i + 5, j + 0, k + 4, deepslate, 0, 2);
		world.setBlock(i + 6, j + 0, k + 4, deepslate, 0, 2);
		world.setBlock(i + 7, j + 0, k + 4, deepslate, 0, 2);
		world.setBlock(i + 8, j + 0, k + 4, deepslate, 0, 2);
		world.setBlock(i + 9, j + 0, k + 4, deepslate, 0, 2);
		world.setBlock(i + 10, j + 0, k + 4, deepslate, 0, 2);
		world.setBlock(i + 11, j + 0, k + 4, deepslate, 0, 2);
		world.setBlock(i + 12, j + 0, k + 4, deepslate, 0, 2);
		world.setBlock(i + 13, j + 0, k + 4, deepslate, 0, 2);
		world.setBlock(i + 14, j + 0, k + 4, deepslate, 0, 2);
		world.setBlock(i + 15, j + 0, k + 4, deepslate, 0, 2);
		world.setBlock(i + 16, j + 0, k + 4, deepslate, 0, 2);
		world.setBlock(i + 17, j + 0, k + 4, deepslate, 0, 2);
		world.setBlock(i + 18, j + 0, k + 4, deepslate, 0, 2);
		world.setBlock(i + 19, j + 0, k + 4, deepslate, 0, 2);
		world.setBlock(i + 20, j + 0, k + 4, Blocks.air, 0, 2);
		world.setBlock(i + 0, j + 0, k + 5, Blocks.air, 0, 2);
		world.setBlock(i + 1, j + 0, k + 5, deepslate, 0, 2);
		world.setBlock(i + 2, j + 0, k + 5, deepslate, 0, 2);
		world.setBlock(i + 3, j + 0, k + 5, deepslate, 0, 2);
		world.setBlock(i + 4, j + 0, k + 5, deepslate, 0, 2);
		world.setBlock(i + 5, j + 0, k + 5, deepslate, 0, 2);
		world.setBlock(i + 6, j + 0, k + 5, deepslate, 0, 2);
		world.setBlock(i + 7, j + 0, k + 5, deepslate, 0, 2);
		world.setBlock(i + 8, j + 0, k + 5, deepslate, 0, 2);
		world.setBlock(i + 9, j + 0, k + 5, deepslate, 0, 2);
		world.setBlock(i + 10, j + 0, k + 5, deepslate, 0, 2);
		world.setBlock(i + 11, j + 0, k + 5, deepslate, 0, 2);
		world.setBlock(i + 12, j + 0, k + 5, deepslate, 0, 2);
		world.setBlock(i + 13, j + 0, k + 5, deepslate, 0, 2);
		world.setBlock(i + 14, j + 0, k + 5, deepslate, 0, 2);
		world.setBlock(i + 15, j + 0, k + 5, deepslate, 0, 2);
		world.setBlock(i + 16, j + 0, k + 5, deepslate, 0, 2);
		world.setBlock(i + 17, j + 0, k + 5, deepslate, 0, 2);
		world.setBlock(i + 18, j + 0, k + 5, deepslate, 0, 2);
		world.setBlock(i + 19, j + 0, k + 5, deepslate, 0, 2);
		world.setBlock(i + 20, j + 0, k + 5, Blocks.air, 0, 2);
		world.setBlock(i + 0, j + 0, k + 6, Blocks.air, 0, 2);
		world.setBlock(i + 1, j + 0, k + 6, deepslate, 0, 2);
		world.setBlock(i + 2, j + 0, k + 6, deepslate, 0, 2);
		world.setBlock(i + 3, j + 0, k + 6, deepslate, 0, 2);
		world.setBlock(i + 4, j + 0, k + 6, deepslate, 0, 2);
		world.setBlock(i + 5, j + 0, k + 6, deepslate, 0, 2);
		world.setBlock(i + 6, j + 0, k + 6, deepslate, 0, 2);
		world.setBlock(i + 7, j + 0, k + 6, deepslate, 0, 2);
		world.setBlock(i + 8, j + 0, k + 6, deepslate, 0, 2);
		world.setBlock(i + 9, j + 0, k + 6, Blocks.air, 0, 2);
		world.setBlock(i + 10, j + 0, k + 6, Blocks.air, 0, 2);
		world.setBlock(i + 11, j + 0, k + 6, deepslate, 0, 2);
		world.setBlock(i + 12, j + 0, k + 6, deepslate, 0, 2);
		world.setBlock(i + 13, j + 0, k + 6, deepslate, 0, 2);
		world.setBlock(i + 14, j + 0, k + 6, deepslate, 0, 2);
		world.setBlock(i + 15, j + 0, k + 6, deepslate, 0, 2);
		world.setBlock(i + 16, j + 0, k + 6, deepslate, 0, 2);
		world.setBlock(i + 17, j + 0, k + 6, cobbled_deepslate_stairs, 1, 2);
		world.setBlock(i + 18, j + 0, k + 6, Blocks.air, 0, 2);
		world.setBlock(i + 19, j + 0, k + 6, Blocks.air, 0, 2);
		world.setBlock(i + 20, j + 0, k + 6, Blocks.air, 0, 2);
		world.setBlock(i + 0, j + 0, k + 7, Blocks.air, 0, 2);
		world.setBlock(i + 1, j + 0, k + 7, deepslate, 0, 2);
		world.setBlock(i + 2, j + 0, k + 7, deepslate, 0, 2);
		world.setBlock(i + 3, j + 0, k + 7, deepslate, 0, 2);
		world.setBlock(i + 4, j + 0, k + 7, deepslate, 0, 2);
		world.setBlock(i + 5, j + 0, k + 7, deepslate, 0, 2);
		world.setBlock(i + 6, j + 0, k + 7, deepslate, 0, 2);
		world.setBlock(i + 7, j + 0, k + 7, deepslate, 0, 2);
		world.setBlock(i + 8, j + 0, k + 7, deepslate, 0, 2);
		world.setBlock(i + 9, j + 0, k + 7, deepslate, 0, 2);
		world.setBlock(i + 10, j + 0, k + 7, deepslate, 0, 2);
		world.setBlock(i + 11, j + 0, k + 7, deepslate, 0, 2);
		world.setBlock(i + 12, j + 0, k + 7, deepslate, 0, 2);
		world.setBlock(i + 13, j + 0, k + 7, deepslate, 0, 2);
		world.setBlock(i + 14, j + 0, k + 7, deepslate, 0, 2);
		world.setBlock(i + 15, j + 0, k + 7, deepslate, 0, 2);
		world.setBlock(i + 16, j + 0, k + 7, deepslate, 0, 2);
		world.setBlock(i + 17, j + 0, k + 7, cobbled_deepslate_stairs, 1, 2);
		world.setBlock(i + 18, j + 0, k + 7, Blocks.air, 0, 2);
		world.setBlock(i + 19, j + 0, k + 7, Blocks.air, 0, 2);
		world.setBlock(i + 20, j + 0, k + 7, Blocks.air, 0, 2);
		world.setBlock(i + 0, j + 0, k + 8, Blocks.air, 0, 2);
		world.setBlock(i + 1, j + 0, k + 8, deepslate, 0, 2);
		world.setBlock(i + 2, j + 0, k + 8, deepslate, 0, 2);
		world.setBlock(i + 3, j + 0, k + 8, deepslate, 0, 2);
		world.setBlock(i + 4, j + 0, k + 8, deepslate, 0, 2);
		world.setBlock(i + 5, j + 0, k + 8, deepslate, 0, 2);
		world.setBlock(i + 6, j + 0, k + 8, deepslate, 0, 2);
		world.setBlock(i + 7, j + 0, k + 8, NovaCraftBlocks.sculk_block, 0, 2);
		world.setBlock(i + 8, j + 0, k + 8, NovaCraftBlocks.sculk_block, 0, 2);
		world.setBlock(i + 9, j + 0, k + 8, NovaCraftBlocks.sculk_block, 0, 2);
		world.setBlock(i + 10, j + 0, k + 8, NovaCraftBlocks.sculk_block, 0, 2);
		world.setBlock(i + 11, j + 0, k + 8, NovaCraftBlocks.sculk_block, 0, 2);
		world.setBlock(i + 12, j + 0, k + 8, NovaCraftBlocks.sculk_block, 0, 2);
		world.setBlock(i + 13, j + 0, k + 8, NovaCraftBlocks.sculk_block, 0, 2);
		world.setBlock(i + 14, j + 0, k + 8, NovaCraftBlocks.sculk_block, 0, 2);
		world.setBlock(i + 15, j + 0, k + 8, NovaCraftBlocks.sculk_block, 0, 2);
		world.setBlock(i + 16, j + 0, k + 8, NovaCraftBlocks.sculk_block, 0, 2);
		world.setBlock(i + 17, j + 0, k + 8, deepslate, 0, 2);
		world.setBlock(i + 18, j + 0, k + 8, deepslate, 0, 2);
		world.setBlock(i + 19, j + 0, k + 8, deepslate, 0, 2);
		world.setBlock(i + 20, j + 0, k + 8, Blocks.air, 0, 2);
		world.setBlock(i + 0, j + 0, k + 9, Blocks.air, 0, 2);
		world.setBlock(i + 1, j + 0, k + 9, Blocks.air, 0, 2);
		world.setBlock(i + 2, j + 0, k + 9, deepslate, 0, 2);
		world.setBlock(i + 3, j + 0, k + 9, deepslate, 0, 2);
		world.setBlock(i + 4, j + 0, k + 9, deepslate, 0, 2);
		world.setBlock(i + 5, j + 0, k + 9, deepslate, 0, 2);
		world.setBlock(i + 6, j + 0, k + 9, deepslate, 0, 2);
		world.setBlock(i + 7, j + 0, k + 9, NovaCraftBlocks.sculk_block, 0, 2);
		world.setBlock(i + 8, j + 0, k + 9, NovaCraftBlocks.sculk_block, 0, 2);
		world.setBlock(i + 9, j + 0, k + 9, NovaCraftBlocks.sculk_block, 0, 2);
		world.setBlock(i + 10, j + 0, k + 9, deepslate, 0, 2);
		world.setBlock(i + 11, j + 0, k + 9, deepslate, 0, 2);
		world.setBlock(i + 12, j + 0, k + 9, deepslate, 0, 2);
		world.setBlock(i + 13, j + 0, k + 9, Blocks.air, 0, 2);
		world.setBlock(i + 14, j + 0, k + 9, Blocks.air, 0, 2);
		world.setBlock(i + 15, j + 0, k + 9, deepslate, 0, 2);
		world.setBlock(i + 16, j + 0, k + 9, deepslate, 0, 2);
		world.setBlock(i + 17, j + 0, k + 9, deepslate, 0, 2);
		world.setBlock(i + 18, j + 0, k + 9, deepslate, 0, 2);
		world.setBlock(i + 19, j + 0, k + 9, deepslate, 0, 2);
		world.setBlock(i + 20, j + 0, k + 9, Blocks.air, 0, 2);
		world.setBlock(i + 0, j + 0, k + 10, Blocks.air, 0, 2);
		world.setBlock(i + 1, j + 0, k + 10, deepslate, 0, 2);
		world.setBlock(i + 2, j + 0, k + 10, deepslate, 0, 2);
		world.setBlock(i + 3, j + 0, k + 10, deepslate, 0, 2);
		world.setBlock(i + 4, j + 0, k + 10, deepslate, 0, 2);
		world.setBlock(i + 5, j + 0, k + 10, deepslate, 0, 2);
		world.setBlock(i + 6, j + 0, k + 10, NovaCraftBlocks.sculk_block, 0, 2);
		world.setBlock(i + 7, j + 0, k + 10, NovaCraftBlocks.sculk_block, 0, 2);
		world.setBlock(i + 8, j + 0, k + 10, NovaCraftBlocks.sculk_block, 0, 2);
		world.setBlock(i + 9, j + 0, k + 10, NovaCraftBlocks.sculk_block, 0, 2);
		world.setBlock(i + 10, j + 0, k + 10, deepslate, 0, 2);
		world.setBlock(i + 11, j + 0, k + 10, deepslate, 0, 2);
		world.setBlock(i + 12, j + 0, k + 10, deepslate, 0, 2);
		world.setBlock(i + 13, j + 0, k + 10, deepslate, 0, 2);
		world.setBlock(i + 14, j + 0, k + 10, deepslate, 0, 2);
		world.setBlock(i + 15, j + 0, k + 10, Blocks.air, 0, 2);
		world.setBlock(i + 16, j + 0, k + 10, deepslate, 0, 2);
		world.setBlock(i + 17, j + 0, k + 10, deepslate, 0, 2);
		world.setBlock(i + 18, j + 0, k + 10, deepslate, 0, 2);
		world.setBlock(i + 19, j + 0, k + 10, deepslate, 0, 2);
		world.setBlock(i + 20, j + 0, k + 10, Blocks.air, 0, 2);
		world.setBlock(i + 0, j + 0, k + 11, Blocks.air, 0, 2);
		world.setBlock(i + 1, j + 0, k + 11, deepslate, 0, 2);
		world.setBlock(i + 2, j + 0, k + 11, deepslate, 0, 2);
		world.setBlock(i + 3, j + 0, k + 11, deepslate, 0, 2);
		world.setBlock(i + 4, j + 0, k + 11, deepslate, 0, 2);
		world.setBlock(i + 5, j + 0, k + 11, deepslate, 0, 2);
		world.setBlock(i + 6, j + 0, k + 11, NovaCraftBlocks.sculk_block, 0, 2);
		world.setBlock(i + 7, j + 0, k + 11, NovaCraftBlocks.sculk_block, 0, 2);
		world.setBlock(i + 8, j + 0, k + 11, NovaCraftBlocks.sculk_block, 0, 2);
		world.setBlock(i + 9, j + 0, k + 11, NovaCraftBlocks.sculk_block, 0, 2);
		world.setBlock(i + 10, j + 0, k + 11, deepslate, 0, 2);
		world.setBlock(i + 11, j + 0, k + 11, deepslate, 0, 2);
		world.setBlock(i + 12, j + 0, k + 11, deepslate, 0, 2);
		world.setBlock(i + 13, j + 0, k + 11, deepslate, 0, 2);
		world.setBlock(i + 14, j + 0, k + 11, deepslate, 0, 2);
		world.setBlock(i + 15, j + 0, k + 11, deepslate, 0, 2);
		world.setBlock(i + 16, j + 0, k + 11, Blocks.air, 0, 2);
		world.setBlock(i + 17, j + 0, k + 11, deepslate, 0, 2);
		world.setBlock(i + 18, j + 0, k + 11, Blocks.air, 0, 2);
		world.setBlock(i + 19, j + 0, k + 11, deepslate, 0, 2);
		world.setBlock(i + 20, j + 0, k + 11, Blocks.air, 0, 2);
		world.setBlock(i + 0, j + 0, k + 12, Blocks.air, 0, 2);
		world.setBlock(i + 1, j + 0, k + 12, deepslate, 0, 2);
		world.setBlock(i + 2, j + 0, k + 12, deepslate, 0, 2);
		world.setBlock(i + 3, j + 0, k + 12, deepslate, 0, 2);
		world.setBlock(i + 4, j + 0, k + 12, deepslate, 0, 2);
		world.setBlock(i + 5, j + 0, k + 12, deepslate, 0, 2);
		world.setBlock(i + 6, j + 0, k + 12, deepslate, 0, 2);
		world.setBlock(i + 7, j + 0, k + 12, NovaCraftBlocks.sculk_block, 0, 2);
		world.setBlock(i + 8, j + 0, k + 12, NovaCraftBlocks.sculk_block, 0, 2);
		world.setBlock(i + 9, j + 0, k + 12, NovaCraftBlocks.sculk_block, 0, 2);
		world.setBlock(i + 10, j + 0, k + 12, deepslate, 0, 2);
		world.setBlock(i + 11, j + 0, k + 12, deepslate, 0, 2);
		world.setBlock(i + 12, j + 0, k + 12, deepslate, 0, 2);
		world.setBlock(i + 13, j + 0, k + 12, deepslate, 0, 2);
		world.setBlock(i + 14, j + 0, k + 12, deepslate, 0, 2);
		world.setBlock(i + 15, j + 0, k + 12, deepslate, 0, 2);
		world.setBlock(i + 16, j + 0, k + 12, deepslate, 0, 2);
		world.setBlock(i + 17, j + 0, k + 12, deepslate, 0, 2);
		world.setBlock(i + 18, j + 0, k + 12, deepslate, 0, 2);
		world.setBlock(i + 19, j + 0, k + 12, deepslate, 0, 2);
		world.setBlock(i + 20, j + 0, k + 12, Blocks.air, 0, 2);
		world.setBlock(i + 0, j + 0, k + 13, Blocks.air, 0, 2);
		world.setBlock(i + 1, j + 0, k + 13, deepslate, 0, 2);
		world.setBlock(i + 2, j + 0, k + 13, deepslate, 0, 2);
		world.setBlock(i + 3, j + 0, k + 13, deepslate, 0, 2);
		world.setBlock(i + 4, j + 0, k + 13, deepslate, 0, 2);
		world.setBlock(i + 5, j + 0, k + 13, deepslate, 0, 2);
		world.setBlock(i + 6, j + 0, k + 13, NovaCraftBlocks.sculk_block, 0, 2);
		world.setBlock(i + 7, j + 0, k + 13, NovaCraftBlocks.sculk_block, 0, 2);
		world.setBlock(i + 8, j + 0, k + 13, deepslate, 0, 2);
		world.setBlock(i + 9, j + 0, k + 13, NovaCraftBlocks.sculk_block, 0, 2);
		world.setBlock(i + 10, j + 0, k + 13, deepslate, 0, 2);
		world.setBlock(i + 11, j + 0, k + 13, deepslate, 0, 2);
		world.setBlock(i + 12, j + 0, k + 13, deepslate, 0, 2);
		world.setBlock(i + 13, j + 0, k + 13, deepslate, 0, 2);
		world.setBlock(i + 14, j + 0, k + 13, deepslate, 0, 2);
		world.setBlock(i + 15, j + 0, k + 13, deepslate, 0, 2);
		world.setBlock(i + 16, j + 0, k + 13, deepslate, 0, 2);
		world.setBlock(i + 17, j + 0, k + 13, deepslate, 0, 2);
		world.setBlock(i + 18, j + 0, k + 13, deepslate, 0, 2);
		world.setBlock(i + 19, j + 0, k + 13, deepslate, 0, 2);
		world.setBlock(i + 20, j + 0, k + 13, Blocks.air, 0, 2);
		world.setBlock(i + 0, j + 0, k + 14, Blocks.air, 0, 2);
		world.setBlock(i + 1, j + 0, k + 14, Blocks.air, 0, 2);
		world.setBlock(i + 2, j + 0, k + 14, Blocks.air, 0, 2);
		world.setBlock(i + 3, j + 0, k + 14, NovaCraftBlocks.sculk_block, 0, 2);
		world.setBlock(i + 4, j + 0, k + 14, deepslate, 0, 2);
		world.setBlock(i + 5, j + 0, k + 14, NovaCraftBlocks.sculk_block, 0, 2);
		world.setBlock(i + 6, j + 0, k + 14, Blocks.air, 0, 2);
		world.setBlock(i + 7, j + 0, k + 14, NovaCraftBlocks.sculk_block, 0, 2);
		world.setBlock(i + 8, j + 0, k + 14, NovaCraftBlocks.sculk_block, 0, 2);
		world.setBlock(i + 9, j + 0, k + 14, NovaCraftBlocks.sculk_block, 0, 2);
		world.setBlock(i + 10, j + 0, k + 14, deepslate, 0, 2);
		world.setBlock(i + 11, j + 0, k + 14, deepslate, 0, 2);
		world.setBlock(i + 12, j + 0, k + 14, deepslate, 0, 2);
		world.setBlock(i + 13, j + 0, k + 14, deepslate, 0, 2);
		world.setBlock(i + 14, j + 0, k + 14, deepslate, 0, 2);
		world.setBlock(i + 15, j + 0, k + 14, deepslate, 0, 2);
		world.setBlock(i + 16, j + 0, k + 14, deepslate, 0, 2);
		world.setBlock(i + 17, j + 0, k + 14, deepslate, 0, 2);
		world.setBlock(i + 18, j + 0, k + 14, deepslate, 0, 2);
		world.setBlock(i + 19, j + 0, k + 14, deepslate, 0, 2);
		world.setBlock(i + 20, j + 0, k + 14, Blocks.air, 0, 2);
		world.setBlock(i + 0, j + 0, k + 15, Blocks.air, 0, 2);
		world.setBlock(i + 1, j + 0, k + 15, deepslate, 0, 2);
		world.setBlock(i + 2, j + 0, k + 15, NovaCraftBlocks.sculk_block, 0, 2);
		world.setBlock(i + 3, j + 0, k + 15, NovaCraftBlocks.sculk_block, 0, 2);
		world.setBlock(i + 4, j + 0, k + 15, NovaCraftBlocks.sculk_block, 0, 2);
		world.setBlock(i + 5, j + 0, k + 15, deepslate, 0, 2);
		world.setBlock(i + 6, j + 0, k + 15, NovaCraftBlocks.sculk_block, 0, 2);
		world.setBlock(i + 7, j + 0, k + 15, NovaCraftBlocks.sculk_block, 0, 2);
		world.setBlock(i + 8, j + 0, k + 15, NovaCraftBlocks.sculk_block, 0, 2);
		world.setBlock(i + 9, j + 0, k + 15, NovaCraftBlocks.sculk_block, 0, 2);
		world.setBlock(i + 10, j + 0, k + 15, deepslate, 0, 2);
		world.setBlock(i + 11, j + 0, k + 15, deepslate, 0, 2);
		world.setBlock(i + 12, j + 0, k + 15, deepslate, 0, 2);
		world.setBlock(i + 13, j + 0, k + 15, deepslate, 0, 2);
		world.setBlock(i + 14, j + 0, k + 15, deepslate, 0, 2);
		world.setBlock(i + 15, j + 0, k + 15, deepslate, 0, 2);
		world.setBlock(i + 16, j + 0, k + 15, deepslate, 0, 2);
		world.setBlock(i + 17, j + 0, k + 15, deepslate, 0, 2);
		world.setBlock(i + 18, j + 0, k + 15, deepslate, 0, 2);
		world.setBlock(i + 19, j + 0, k + 15, deepslate, 0, 2);
		world.setBlock(i + 20, j + 0, k + 15, Blocks.air, 0, 2);
		world.setBlock(i + 0, j + 0, k + 16, Blocks.air, 0, 2);
		world.setBlock(i + 1, j + 0, k + 16, deepslate, 0, 2);
		world.setBlock(i + 2, j + 0, k + 16, deepslate, 0, 2);
		world.setBlock(i + 3, j + 0, k + 16, deepslate, 0, 2);
		world.setBlock(i + 4, j + 0, k + 16, NovaCraftBlocks.sculk_block, 0, 2);
		world.setBlock(i + 5, j + 0, k + 16, NovaCraftBlocks.sculk_block, 0, 2);
		world.setBlock(i + 6, j + 0, k + 16, NovaCraftBlocks.sculk_block, 0, 2);
		world.setBlock(i + 7, j + 0, k + 16, NovaCraftBlocks.sculk_block, 0, 2);
		world.setBlock(i + 8, j + 0, k + 16, NovaCraftBlocks.sculk_block, 0, 2);
		world.setBlock(i + 9, j + 0, k + 16, NovaCraftBlocks.sculk_block, 0, 2);
		world.setBlock(i + 10, j + 0, k + 16, deepslate, 0, 2);
		world.setBlock(i + 11, j + 0, k + 16, deepslate, 0, 2);
		world.setBlock(i + 12, j + 0, k + 16, deepslate, 0, 2);
		world.setBlock(i + 13, j + 0, k + 16, deepslate, 0, 2);
		world.setBlock(i + 14, j + 0, k + 16, Blocks.air, 0, 2);
		world.setBlock(i + 15, j + 0, k + 16, deepslate, 0, 2);
		world.setBlock(i + 16, j + 0, k + 16, deepslate, 0, 2);
		world.setBlock(i + 17, j + 0, k + 16, deepslate, 0, 2);
		world.setBlock(i + 18, j + 0, k + 16, Blocks.air, 0, 2);
		world.setBlock(i + 19, j + 0, k + 16, deepslate, 0, 2);
		world.setBlock(i + 20, j + 0, k + 16, Blocks.air, 0, 2);
		world.setBlock(i + 0, j + 0, k + 17, Blocks.air, 0, 2);
		world.setBlock(i + 1, j + 0, k + 17, deepslate, 0, 2);
		world.setBlock(i + 2, j + 0, k + 17, deepslate_brick_stairs, 3, 2);
		world.setBlock(i + 3, j + 0, k + 17, NovaCraftBlocks.sculk_block, 0, 2);
		world.setBlock(i + 4, j + 0, k + 17, NovaCraftBlocks.sculk_block, 0, 2);
		world.setBlock(i + 5, j + 0, k + 17, NovaCraftBlocks.sculk_block, 0, 2);
		world.setBlock(i + 6, j + 0, k + 17, NovaCraftBlocks.sculk_block, 0, 2);
		world.setBlock(i + 7, j + 0, k + 17, NovaCraftBlocks.sculk_block, 0, 2);
		world.setBlock(i + 8, j + 0, k + 17, NovaCraftBlocks.sculk_block, 0, 2);
		world.setBlock(i + 9, j + 0, k + 17, NovaCraftBlocks.sculk_block, 0, 2);
		world.setBlock(i + 10, j + 0, k + 17, deepslate, 0, 2);
		world.setBlock(i + 11, j + 0, k + 17, cobbled_deepslate, 0, 2);
		world.setBlock(i + 12, j + 0, k + 17, cobbled_deepslate, 0, 2);
		world.setBlock(i + 13, j + 0, k + 17, Blocks.air, 0, 2);
		world.setBlock(i + 14, j + 0, k + 17, deepslate, 0, 2);
		world.setBlock(i + 15, j + 0, k + 17, deepslate, 0, 2);
		world.setBlock(i + 16, j + 0, k + 17, deepslate, 0, 2);
		world.setBlock(i + 17, j + 0, k + 17, deepslate, 0, 2);
		world.setBlock(i + 18, j + 0, k + 17, deepslate, 0, 2);
		world.setBlock(i + 19, j + 0, k + 17, deepslate, 0, 2);
		world.setBlock(i + 20, j + 0, k + 17, Blocks.air, 0, 2);
		world.setBlock(i + 0, j + 0, k + 18, Blocks.air, 0, 2);
		world.setBlock(i + 1, j + 0, k + 18, Blocks.air, 0, 2);
		world.setBlock(i + 2, j + 0, k + 18, Blocks.air, 0, 2);
		world.setBlock(i + 3, j + 0, k + 18, Blocks.air, 0, 2);
		world.setBlock(i + 4, j + 0, k + 18, Blocks.air, 0, 2);
		world.setBlock(i + 5, j + 0, k + 18, Blocks.air, 0, 2);
		world.setBlock(i + 6, j + 0, k + 18, Blocks.air, 0, 2);
		world.setBlock(i + 7, j + 0, k + 18, Blocks.air, 0, 2);
		world.setBlock(i + 8, j + 0, k + 18, Blocks.air, 0, 2);
		world.setBlock(i + 9, j + 0, k + 18, Blocks.air, 0, 2);
		world.setBlock(i + 10, j + 0, k + 18, Blocks.air, 0, 2);
		world.setBlock(i + 11, j + 0, k + 18, Blocks.air, 0, 2);
		world.setBlock(i + 12, j + 0, k + 18, Blocks.air, 0, 2);
		world.setBlock(i + 13, j + 0, k + 18, Blocks.air, 0, 2);
		world.setBlock(i + 14, j + 0, k + 18, Blocks.air, 0, 2);
		world.setBlock(i + 15, j + 0, k + 18, Blocks.air, 0, 2);
		world.setBlock(i + 16, j + 0, k + 18, Blocks.air, 0, 2);
		world.setBlock(i + 17, j + 0, k + 18, Blocks.air, 0, 2);
		world.setBlock(i + 18, j + 0, k + 18, Blocks.air, 0, 2);
		world.setBlock(i + 19, j + 0, k + 18, Blocks.air, 0, 2);
		world.setBlock(i + 20, j + 0, k + 18, Blocks.air, 0, 2);
		world.setBlock(i + 0, j + 1, k + 0, Blocks.air, 0, 2);
		world.setBlock(i + 1, j + 1, k + 0, Blocks.air, 0, 2);
		world.setBlock(i + 2, j + 1, k + 0, Blocks.air, 0, 2);
		world.setBlock(i + 3, j + 1, k + 0, Blocks.air, 0, 2);
		world.setBlock(i + 4, j + 1, k + 0, Blocks.air, 0, 2);
		world.setBlock(i + 5, j + 1, k + 0, Blocks.air, 0, 2);
		world.setBlock(i + 6, j + 1, k + 0, Blocks.air, 0, 2);
		world.setBlock(i + 7, j + 1, k + 0, Blocks.air, 0, 2);
		world.setBlock(i + 8, j + 1, k + 0, Blocks.air, 0, 2);
		world.setBlock(i + 9, j + 1, k + 0, Blocks.air, 0, 2);
		world.setBlock(i + 10, j + 1, k + 0, Blocks.air, 0, 2);
		world.setBlock(i + 11, j + 1, k + 0, Blocks.air, 0, 2);
		world.setBlock(i + 12, j + 1, k + 0, Blocks.air, 0, 2);
		world.setBlock(i + 13, j + 1, k + 0, Blocks.air, 0, 2);
		world.setBlock(i + 14, j + 1, k + 0, Blocks.air, 0, 2);
		world.setBlock(i + 15, j + 1, k + 0, Blocks.air, 0, 2);
		world.setBlock(i + 16, j + 1, k + 0, Blocks.air, 0, 2);
		world.setBlock(i + 17, j + 1, k + 0, Blocks.air, 0, 2);
		world.setBlock(i + 18, j + 1, k + 0, Blocks.air, 0, 2);
		world.setBlock(i + 19, j + 1, k + 0, Blocks.air, 0, 2);
		world.setBlock(i + 20, j + 1, k + 0, Blocks.air, 0, 2);
		world.setBlock(i + 0, j + 1, k + 1, Blocks.air, 0, 2);
		world.setBlock(i + 1, j + 1, k + 1, deepslate, 0, 2);
		world.setBlock(i + 2, j + 1, k + 1, deepslate, 0, 2);
		world.setBlock(i + 3, j + 1, k + 1, deepslate, 0, 2);
		world.setBlock(i + 4, j + 1, k + 1, deepslate, 0, 2);
		world.setBlock(i + 5, j + 1, k + 1, deepslate, 0, 2);
		world.setBlock(i + 6, j + 1, k + 1, deepslate, 0, 2);
		world.setBlock(i + 7, j + 1, k + 1, deepslate, 0, 2);
		world.setBlock(i + 8, j + 1, k + 1, deepslate, 0, 2);
		world.setBlock(i + 9, j + 1, k + 1, deepslate, 0, 2);
		world.setBlock(i + 10, j + 1, k + 1, deepslate, 0, 2);
		world.setBlock(i + 11, j + 1, k + 1, deepslate, 0, 2);
		world.setBlock(i + 12, j + 1, k + 1, deepslate, 0, 2);
		world.setBlock(i + 13, j + 1, k + 1, deepslate, 0, 2);
		world.setBlock(i + 14, j + 1, k + 1, deepslate, 0, 2);
		world.setBlock(i + 15, j + 1, k + 1, deepslate, 0, 2);
		world.setBlock(i + 16, j + 1, k + 1, Blocks.air, 0, 2);
		world.setBlock(i + 17, j + 1, k + 1, deepslate, 0, 2);
		world.setBlock(i + 18, j + 1, k + 1, Blocks.air, 0, 2);
		world.setBlock(i + 19, j + 1, k + 1, deepslate, 0, 2);
		world.setBlock(i + 20, j + 1, k + 1, Blocks.air, 0, 2);
		world.setBlock(i + 0, j + 1, k + 2, Blocks.air, 0, 2);
		world.setBlock(i + 1, j + 1, k + 2, deepslate, 0, 2);
		world.setBlock(i + 2, j + 1, k + 2, deepslate, 0, 2);
		world.setBlock(i + 3, j + 1, k + 2, deepslate, 0, 2);
		world.setBlock(i + 4, j + 1, k + 2, deepslate, 0, 2);
		world.setBlock(i + 5, j + 1, k + 2, deepslate, 0, 2);
		world.setBlock(i + 6, j + 1, k + 2, deepslate, 0, 2);
		world.setBlock(i + 7, j + 1, k + 2, deepslate, 0, 2);
		world.setBlock(i + 8, j + 1, k + 2, deepslate, 0, 2);
		world.setBlock(i + 9, j + 1, k + 2, deepslate, 0, 2);
		world.setBlock(i + 10, j + 1, k + 2, deepslate, 0, 2);
		world.setBlock(i + 11, j + 1, k + 2, deepslate, 0, 2);
		world.setBlock(i + 12, j + 1, k + 2, deepslate, 0, 2);
		world.setBlock(i + 13, j + 1, k + 2, deepslate, 0, 2);
		world.setBlock(i + 14, j + 1, k + 2, deepslate, 0, 2);
		world.setBlock(i + 15, j + 1, k + 2, deepslate, 0, 2);
		world.setBlock(i + 16, j + 1, k + 2, deepslate, 0, 2);
		world.setBlock(i + 17, j + 1, k + 2, deepslate, 0, 2);
		world.setBlock(i + 18, j + 1, k + 2, deepslate, 0, 2);
		world.setBlock(i + 19, j + 1, k + 2, deepslate, 0, 2);
		world.setBlock(i + 20, j + 1, k + 2, Blocks.air, 0, 2);
		world.setBlock(i + 0, j + 1, k + 3, Blocks.air, 0, 2);
		world.setBlock(i + 1, j + 1, k + 3, deepslate, 0, 2);
		world.setBlock(i + 2, j + 1, k + 3, deepslate, 0, 2);
		world.setBlock(i + 3, j + 1, k + 3, deepslate, 0, 2);
		world.setBlock(i + 4, j + 1, k + 3, deepslate, 0, 2);
		world.setBlock(i + 5, j + 1, k + 3, deepslate, 0, 2);
		world.setBlock(i + 6, j + 1, k + 3, deepslate, 0, 2);
		world.setBlock(i + 7, j + 1, k + 3, deepslate, 0, 2);
		world.setBlock(i + 8, j + 1, k + 3, deepslate, 0, 2);
		world.setBlock(i + 9, j + 1, k + 3, deepslate, 0, 2);
		world.setBlock(i + 10, j + 1, k + 3, deepslate, 0, 2);
		world.setBlock(i + 11, j + 1, k + 3, deepslate, 0, 2);
		world.setBlock(i + 12, j + 1, k + 3, deepslate, 0, 2);
		world.setBlock(i + 13, j + 1, k + 3, deepslate, 0, 2);
		world.setBlock(i + 14, j + 1, k + 3, deepslate, 0, 2);
		world.setBlock(i + 15, j + 1, k + 3, deepslate, 0, 2);
		world.setBlock(i + 16, j + 1, k + 3, deepslate, 0, 2);
		world.setBlock(i + 17, j + 1, k + 3, deepslate, 0, 2);
		world.setBlock(i + 18, j + 1, k + 3, deepslate, 0, 2);
		world.setBlock(i + 19, j + 1, k + 3, deepslate, 0, 2);
		world.setBlock(i + 20, j + 1, k + 3, Blocks.air, 0, 2);
		world.setBlock(i + 0, j + 1, k + 4, Blocks.air, 0, 2);
		world.setBlock(i + 1, j + 1, k + 4, deepslate, 0, 2);
		world.setBlock(i + 2, j + 1, k + 4, deepslate, 0, 2);
		world.setBlock(i + 3, j + 1, k + 4, deepslate, 0, 2);
		world.setBlock(i + 4, j + 1, k + 4, deepslate, 0, 2);
		world.setBlock(i + 5, j + 1, k + 4, deepslate, 0, 2);
		world.setBlock(i + 6, j + 1, k + 4, deepslate, 0, 2);
		world.setBlock(i + 7, j + 1, k + 4, deepslate, 0, 2);
		world.setBlock(i + 8, j + 1, k + 4, Blocks.air, 0, 2);
		world.setBlock(i + 9, j + 1, k + 4, deepslate, 0, 2);
		world.setBlock(i + 10, j + 1, k + 4, deepslate, 0, 2);
		world.setBlock(i + 11, j + 1, k + 4, deepslate, 0, 2);
		world.setBlock(i + 12, j + 1, k + 4, deepslate, 0, 2);
		world.setBlock(i + 13, j + 1, k + 4, deepslate, 0, 2);
		world.setBlock(i + 14, j + 1, k + 4, deepslate, 0, 2);
		world.setBlock(i + 15, j + 1, k + 4, deepslate, 0, 2);
		world.setBlock(i + 16, j + 1, k + 4, deepslate, 0, 2);
		world.setBlock(i + 17, j + 1, k + 4, deepslate, 0, 2);
		world.setBlock(i + 18, j + 1, k + 4, deepslate, 0, 2);
		world.setBlock(i + 19, j + 1, k + 4, deepslate, 0, 2);
		world.setBlock(i + 20, j + 1, k + 4, Blocks.air, 0, 2);
		world.setBlock(i + 0, j + 1, k + 5, Blocks.air, 0, 2);
		world.setBlock(i + 1, j + 1, k + 5, deepslate, 0, 2);
		world.setBlock(i + 2, j + 1, k + 5, deepslate, 0, 2);
		world.setBlock(i + 3, j + 1, k + 5, deepslate, 0, 2);
		world.setBlock(i + 4, j + 1, k + 5, deepslate, 0, 2);
		world.setBlock(i + 5, j + 1, k + 5, deepslate, 0, 2);
		world.setBlock(i + 6, j + 1, k + 5, deepslate, 0, 2);
		world.setBlock(i + 7, j + 1, k + 5, deepslate, 0, 2);
		world.setBlock(i + 8, j + 1, k + 5, deepslate, 0, 2);
		world.setBlock(i + 9, j + 1, k + 5, deepslate, 0, 2);
		world.setBlock(i + 10, j + 1, k + 5, deepslate, 0, 2);
		world.setBlock(i + 11, j + 1, k + 5, deepslate, 0, 2);
		world.setBlock(i + 12, j + 1, k + 5, deepslate, 0, 2);
		world.setBlock(i + 13, j + 1, k + 5, Blocks.air, 0, 2);
		world.setBlock(i + 14, j + 1, k + 5, deepslate, 0, 2);
		world.setBlock(i + 15, j + 1, k + 5, deepslate, 0, 2);
		world.setBlock(i + 16, j + 1, k + 5, deepslate, 0, 2);
		world.setBlock(i + 17, j + 1, k + 5, deepslate, 0, 2);
		world.setBlock(i + 18, j + 1, k + 5, deepslate, 0, 2);
		world.setBlock(i + 19, j + 1, k + 5, polished_deepslate, 0, 2);
		world.setBlock(i + 20, j + 1, k + 5, Blocks.air, 0, 2);
		world.setBlock(i + 0, j + 1, k + 6, Blocks.air, 0, 2);
		world.setBlock(i + 1, j + 1, k + 6, deepslate, 0, 2);
		world.setBlock(i + 2, j + 1, k + 6, deepslate, 0, 2);
		world.setBlock(i + 3, j + 1, k + 6, deepslate, 0, 2);
		world.setBlock(i + 4, j + 1, k + 6, deepslate, 0, 2);
		world.setBlock(i + 5, j + 1, k + 6, deepslate, 0, 2);
		world.setBlock(i + 6, j + 1, k + 6, deepslate, 0, 2);
		world.setBlock(i + 7, j + 1, k + 6, deepslate, 0, 2);
		world.setBlock(i + 8, j + 1, k + 6, deepslate, 0, 2);
		world.setBlock(i + 9, j + 1, k + 6, deepslate, 0, 2);
		world.setBlock(i + 10, j + 1, k + 6, deepslate, 0, 2);
		world.setBlock(i + 11, j + 1, k + 6, deepslate, 0, 2);
		world.setBlock(i + 12, j + 1, k + 6, deepslate, 0, 2);
		world.setBlock(i + 13, j + 1, k + 6, deepslate, 0, 2);
		world.setBlock(i + 14, j + 1, k + 6, deepslate, 0, 2);
		world.setBlock(i + 15, j + 1, k + 6, deepslate, 0, 2);
		world.setBlock(i + 16, j + 1, k + 6, cobbled_deepslate_stairs, 1, 2);
		world.setBlock(i + 17, j + 1, k + 6, Blocks.air, 0, 2);
		world.setBlock(i + 18, j + 1, k + 6, Blocks.air, 0, 2);
		world.setBlock(i + 19, j + 1, k + 6, Blocks.air, 0, 2);
		world.setBlock(i + 20, j + 1, k + 6, Blocks.air, 0, 2);
		world.setBlock(i + 0, j + 1, k + 7, Blocks.air, 0, 2);
		world.setBlock(i + 1, j + 1, k + 7, deepslate, 0, 2);
		world.setBlock(i + 2, j + 1, k + 7, deepslate, 0, 2);
		world.setBlock(i + 3, j + 1, k + 7, deepslate, 0, 2);
		world.setBlock(i + 4, j + 1, k + 7, deepslate, 0, 2);
		world.setBlock(i + 5, j + 1, k + 7, deepslate, 0, 2);
		world.setBlock(i + 6, j + 1, k + 7, Blocks.air, 0, 2);
		world.setBlock(i + 7, j + 1, k + 7, deepslate, 0, 2);
		world.setBlock(i + 8, j + 1, k + 7, deepslate, 0, 2);
		world.setBlock(i + 9, j + 1, k + 7, deepslate, 0, 2);
		world.setBlock(i + 10, j + 1, k + 7, deepslate, 0, 2);
		world.setBlock(i + 11, j + 1, k + 7, deepslate, 0, 2);
		world.setBlock(i + 12, j + 1, k + 7, deepslate, 0, 2);
		world.setBlock(i + 13, j + 1, k + 7, deepslate, 0, 2);
		world.setBlock(i + 14, j + 1, k + 7, deepslate, 0, 2);
		world.setBlock(i + 15, j + 1, k + 7, deepslate, 0, 2);
		world.setBlock(i + 16, j + 1, k + 7, cobbled_deepslate_stairs, 1, 2);
		world.setBlock(i + 17, j + 1, k + 7, NovaCraftBlocks.sculk_vein, 2, 2);
		world.setBlock(i + 18, j + 1, k + 7, Blocks.air, 0, 2);
		world.setBlock(i + 19, j + 1, k + 7, Blocks.air, 0, 2);
		world.setBlock(i + 20, j + 1, k + 7, Blocks.air, 0, 2);
		world.setBlock(i + 0, j + 1, k + 8, Blocks.air, 0, 2);
		world.setBlock(i + 1, j + 1, k + 8, deepslate, 0, 2);
		world.setBlock(i + 2, j + 1, k + 8, deepslate, 0, 2);
		world.setBlock(i + 3, j + 1, k + 8, deepslate, 0, 2);
		world.setBlock(i + 4, j + 1, k + 8, deepslate, 0, 2);
		world.setBlock(i + 5, j + 1, k + 8, deepslate, 0, 2);
		world.setBlock(i + 6, j + 1, k + 8, deepslate, 0, 2);
		world.setBlock(i + 7, j + 1, k + 8, deepslate, 0, 2);
		world.setBlock(i + 8, j + 1, k + 8, NovaCraftBlocks.sculk_block, 0, 2);
		world.setBlock(i + 9, j + 1, k + 8, NovaCraftBlocks.sculk_block, 0, 2);
		world.setBlock(i + 10, j + 1, k + 8, NovaCraftBlocks.sculk_block, 0, 2);
		world.setBlock(i + 11, j + 1, k + 8, NovaCraftBlocks.sculk_block, 0, 2);
		world.setBlock(i + 12, j + 1, k + 8, NovaCraftBlocks.sculk_block, 0, 2);
		world.setBlock(i + 13, j + 1, k + 8, NovaCraftBlocks.sculk_block, 0, 2);
		world.setBlock(i + 14, j + 1, k + 8, NovaCraftBlocks.sculk_block, 0, 2);
		world.setBlock(i + 15, j + 1, k + 8, NovaCraftBlocks.sculk_block, 0, 2);
		world.setBlock(i + 16, j + 1, k + 8, NovaCraftBlocks.sculk_block, 0, 2);
		world.setBlock(i + 17, j + 1, k + 8, deepslate, 0, 2);
		world.setBlock(i + 18, j + 1, k + 8, deepslate, 0, 2);
		world.setBlock(i + 19, j + 1, k + 8, polished_deepslate, 0, 2);
		world.setBlock(i + 20, j + 1, k + 8, Blocks.air, 0, 2);
		world.setBlock(i + 0, j + 1, k + 9, Blocks.air, 0, 2);
		world.setBlock(i + 1, j + 1, k + 9, deepslate, 0, 2);
		world.setBlock(i + 2, j + 1, k + 9, deepslate, 0, 2);
		world.setBlock(i + 3, j + 1, k + 9, deepslate, 0, 2);
		world.setBlock(i + 4, j + 1, k + 9, deepslate, 0, 2);
		world.setBlock(i + 5, j + 1, k + 9, deepslate, 0, 2);
		world.setBlock(i + 6, j + 1, k + 9, deepslate, 0, 2);
		world.setBlock(i + 7, j + 1, k + 9, deepslate, 0, 2);
		world.setBlock(i + 8, j + 1, k + 9, deepslate, 0, 2);
		world.setBlock(i + 9, j + 1, k + 9, NovaCraftBlocks.sculk_block, 0, 2);
		world.setBlock(i + 10, j + 1, k + 9, deepslate, 0, 2);
		world.setBlock(i + 11, j + 1, k + 9, deepslate, 0, 2);
		world.setBlock(i + 12, j + 1, k + 9, deepslate, 0, 2);
		world.setBlock(i + 13, j + 1, k + 9, deepslate, 0, 2);
		world.setBlock(i + 14, j + 1, k + 9, deepslate, 0, 2);
		world.setBlock(i + 15, j + 1, k + 9, deepslate, 0, 2);
		world.setBlock(i + 16, j + 1, k + 9, deepslate, 0, 2);
		world.setBlock(i + 17, j + 1, k + 9, deepslate, 0, 2);
		world.setBlock(i + 18, j + 1, k + 9, deepslate, 0, 2);
		world.setBlock(i + 19, j + 1, k + 9, deepslate, 0, 2);
		world.setBlock(i + 20, j + 1, k + 9, Blocks.air, 0, 2);
		world.setBlock(i + 0, j + 1, k + 10, Blocks.air, 0, 2);
		world.setBlock(i + 1, j + 1, k + 10, deepslate, 0, 2);
		world.setBlock(i + 2, j + 1, k + 10, deepslate, 0, 2);
		world.setBlock(i + 3, j + 1, k + 10, deepslate, 0, 2);
		world.setBlock(i + 4, j + 1, k + 10, deepslate, 0, 2);
		world.setBlock(i + 5, j + 1, k + 10, deepslate, 0, 2);
		world.setBlock(i + 6, j + 1, k + 10, deepslate, 0, 2);
		world.setBlock(i + 7, j + 1, k + 10, deepslate, 0, 2);
		world.setBlock(i + 8, j + 1, k + 10, deepslate, 0, 2);
		world.setBlock(i + 9, j + 1, k + 10, NovaCraftBlocks.sculk_block, 0, 2);
		world.setBlock(i + 10, j + 1, k + 10, deepslate, 0, 2);
		world.setBlock(i + 11, j + 1, k + 10, deepslate, 0, 2);
		world.setBlock(i + 12, j + 1, k + 10, deepslate, 0, 2);
		world.setBlock(i + 13, j + 1, k + 10, deepslate, 0, 2);
		world.setBlock(i + 14, j + 1, k + 10, deepslate, 0, 2);
		world.setBlock(i + 15, j + 1, k + 10, deepslate, 0, 2);
		world.setBlock(i + 16, j + 1, k + 10, deepslate, 0, 2);
		world.setBlock(i + 17, j + 1, k + 10, deepslate, 0, 2);
		world.setBlock(i + 18, j + 1, k + 10, deepslate, 0, 2);
		world.setBlock(i + 19, j + 1, k + 10, deepslate, 0, 2);
		world.setBlock(i + 20, j + 1, k + 10, Blocks.air, 0, 2);
		world.setBlock(i + 0, j + 1, k + 11, Blocks.air, 0, 2);
		world.setBlock(i + 1, j + 1, k + 11, deepslate, 0, 2);
		world.setBlock(i + 2, j + 1, k + 11, deepslate, 0, 2);
		world.setBlock(i + 3, j + 1, k + 11, deepslate, 0, 2);
		world.setBlock(i + 4, j + 1, k + 11, deepslate, 0, 2);
		world.setBlock(i + 5, j + 1, k + 11, Blocks.air, 0, 2);
		world.setBlock(i + 6, j + 1, k + 11, deepslate, 0, 2);
		world.setBlock(i + 7, j + 1, k + 11, deepslate, 0, 2);
		world.setBlock(i + 8, j + 1, k + 11, deepslate, 0, 2);
		world.setBlock(i + 9, j + 1, k + 11, NovaCraftBlocks.sculk_block, 0, 2);
		world.setBlock(i + 10, j + 1, k + 11, deepslate, 0, 2);
		world.setBlock(i + 11, j + 1, k + 11, deepslate, 0, 2);
		world.setBlock(i + 12, j + 1, k + 11, deepslate, 0, 2);
		world.setBlock(i + 13, j + 1, k + 11, deepslate, 0, 2);
		world.setBlock(i + 14, j + 1, k + 11, deepslate, 0, 2);
		world.setBlock(i + 15, j + 1, k + 11, deepslate, 0, 2);
		world.setBlock(i + 16, j + 1, k + 11, deepslate, 0, 2);
		world.setBlock(i + 17, j + 1, k + 11, deepslate, 0, 2);
		world.setBlock(i + 18, j + 1, k + 11, deepslate, 0, 2);
		world.setBlock(i + 19, j + 1, k + 11, deepslate, 0, 2);
		world.setBlock(i + 20, j + 1, k + 11, Blocks.air, 0, 2);
		world.setBlock(i + 0, j + 1, k + 12, Blocks.air, 0, 2);
		world.setBlock(i + 1, j + 1, k + 12, deepslate, 0, 2);
		world.setBlock(i + 2, j + 1, k + 12, deepslate, 0, 2);
		world.setBlock(i + 3, j + 1, k + 12, deepslate, 0, 2);
		world.setBlock(i + 4, j + 1, k + 12, deepslate, 0, 2);
		world.setBlock(i + 5, j + 1, k + 12, deepslate, 0, 2);
		world.setBlock(i + 6, j + 1, k + 12, deepslate, 0, 2);
		world.setBlock(i + 7, j + 1, k + 12, deepslate, 0, 2);
		world.setBlock(i + 8, j + 1, k + 12, deepslate, 0, 2);
		world.setBlock(i + 9, j + 1, k + 12, NovaCraftBlocks.sculk_block, 0, 2);
		world.setBlock(i + 10, j + 1, k + 12, deepslate, 0, 2);
		world.setBlock(i + 11, j + 1, k + 12, deepslate, 0, 2);
		world.setBlock(i + 12, j + 1, k + 12, deepslate, 0, 2);
		world.setBlock(i + 13, j + 1, k + 12, deepslate, 0, 2);
		world.setBlock(i + 14, j + 1, k + 12, deepslate, 0, 2);
		world.setBlock(i + 15, j + 1, k + 12, deepslate, 0, 2);
		world.setBlock(i + 16, j + 1, k + 12, deepslate, 0, 2);
		world.setBlock(i + 17, j + 1, k + 12, deepslate, 0, 2);
		world.setBlock(i + 18, j + 1, k + 12, deepslate, 0, 2);
		world.setBlock(i + 19, j + 1, k + 12, deepslate, 0, 2);
		world.setBlock(i + 20, j + 1, k + 12, Blocks.air, 0, 2);
		world.setBlock(i + 0, j + 1, k + 13, Blocks.air, 0, 2);
		world.setBlock(i + 1, j + 1, k + 13, deepslate, 0, 2);
		world.setBlock(i + 2, j + 1, k + 13, deepslate, 0, 2);
		world.setBlock(i + 3, j + 1, k + 13, deepslate, 0, 2);
		world.setBlock(i + 4, j + 1, k + 13, deepslate, 0, 2);
		world.setBlock(i + 5, j + 1, k + 13, deepslate, 0, 2);
		world.setBlock(i + 6, j + 1, k + 13, deepslate, 0, 2);
		world.setBlock(i + 7, j + 1, k + 13, deepslate, 0, 2);
		world.setBlock(i + 8, j + 1, k + 13, deepslate, 0, 2);
		world.setBlock(i + 9, j + 1, k + 13, NovaCraftBlocks.sculk_block, 0, 2);
		world.setBlock(i + 10, j + 1, k + 13, Blocks.air, 0, 2);
		world.setBlock(i + 11, j + 1, k + 13, deepslate, 0, 2);
		world.setBlock(i + 12, j + 1, k + 13, deepslate, 0, 2);
		world.setBlock(i + 13, j + 1, k + 13, deepslate, 0, 2);
		world.setBlock(i + 14, j + 1, k + 13, deepslate, 0, 2);
		world.setBlock(i + 15, j + 1, k + 13, deepslate, 0, 2);
		world.setBlock(i + 16, j + 1, k + 13, deepslate, 0, 2);
		world.setBlock(i + 17, j + 1, k + 13, Blocks.air, 0, 2);
		world.setBlock(i + 18, j + 1, k + 13, deepslate, 0, 2);
		world.setBlock(i + 19, j + 1, k + 13, deepslate, 0, 2);
		world.setBlock(i + 20, j + 1, k + 13, Blocks.air, 0, 2);
		world.setBlock(i + 0, j + 1, k + 14, Blocks.air, 0, 2);
		world.setBlock(i + 1, j + 1, k + 14, deepslate, 0, 2);
		world.setBlock(i + 2, j + 1, k + 14, deepslate, 0, 2);
		world.setBlock(i + 3, j + 1, k + 14, deepslate, 0, 2);
		world.setBlock(i + 4, j + 1, k + 14, Blocks.air, 0, 2);
		world.setBlock(i + 5, j + 1, k + 14, deepslate, 0, 2);
		world.setBlock(i + 6, j + 1, k + 14, deepslate, 0, 2);
		world.setBlock(i + 7, j + 1, k + 14, deepslate, 0, 2);
		world.setBlock(i + 8, j + 1, k + 14, deepslate, 0, 2);
		world.setBlock(i + 9, j + 1, k + 14, NovaCraftBlocks.sculk_block, 0, 2);
		world.setBlock(i + 10, j + 1, k + 14, deepslate, 0, 2);
		world.setBlock(i + 11, j + 1, k + 14, deepslate, 0, 2);
		world.setBlock(i + 12, j + 1, k + 14, deepslate, 0, 2);
		world.setBlock(i + 13, j + 1, k + 14, deepslate, 0, 2);
		world.setBlock(i + 14, j + 1, k + 14, deepslate, 0, 2);
		world.setBlock(i + 15, j + 1, k + 14, deepslate, 0, 2);
		world.setBlock(i + 16, j + 1, k + 14, deepslate, 0, 2);
		world.setBlock(i + 17, j + 1, k + 14, deepslate, 0, 2);
		world.setBlock(i + 18, j + 1, k + 14, deepslate, 0, 2);
		world.setBlock(i + 19, j + 1, k + 14, deepslate, 0, 2);
		world.setBlock(i + 20, j + 1, k + 14, Blocks.air, 0, 2);
		world.setBlock(i + 0, j + 1, k + 15, Blocks.air, 0, 2);
		world.setBlock(i + 1, j + 1, k + 15, deepslate, 0, 2);
		world.setBlock(i + 2, j + 1, k + 15, deepslate, 0, 2);
		world.setBlock(i + 3, j + 1, k + 15, deepslate, 0, 2);
		world.setBlock(i + 4, j + 1, k + 15, deepslate, 0, 2);
		world.setBlock(i + 5, j + 1, k + 15, deepslate, 0, 2);
		world.setBlock(i + 6, j + 1, k + 15, deepslate, 0, 2);
		world.setBlock(i + 7, j + 1, k + 15, deepslate, 0, 2);
		world.setBlock(i + 8, j + 1, k + 15, deepslate, 0, 2);
		world.setBlock(i + 9, j + 1, k + 15, NovaCraftBlocks.sculk_block, 0, 2);
		world.setBlock(i + 10, j + 1, k + 15, deepslate, 0, 2);
		world.setBlock(i + 11, j + 1, k + 15, deepslate, 0, 2);
		world.setBlock(i + 12, j + 1, k + 15, deepslate, 0, 2);
		world.setBlock(i + 13, j + 1, k + 15, Blocks.air, 0, 2);
		world.setBlock(i + 14, j + 1, k + 15, deepslate, 0, 2);
		world.setBlock(i + 15, j + 1, k + 15, deepslate, 0, 2);
		world.setBlock(i + 16, j + 1, k + 15, deepslate, 0, 2);
		world.setBlock(i + 17, j + 1, k + 15, deepslate, 0, 2);
		world.setBlock(i + 18, j + 1, k + 15, deepslate, 0, 2);
		world.setBlock(i + 19, j + 1, k + 15, deepslate, 0, 2);
		world.setBlock(i + 20, j + 1, k + 15, Blocks.air, 0, 2);
		world.setBlock(i + 0, j + 1, k + 16, Blocks.air, 0, 2);
		world.setBlock(i + 1, j + 1, k + 16, deepslate, 0, 2);
		world.setBlock(i + 2, j + 1, k + 16, deepslate_brick_stairs, 3, 2);
		world.setBlock(i + 3, j + 1, k + 16, deepslate, 0, 2);
		world.setBlock(i + 4, j + 1, k + 16, Blocks.air, 0, 2);
		world.setBlock(i + 5, j + 1, k + 16, deepslate, 0, 2);
		world.setBlock(i + 6, j + 1, k + 16, deepslate, 0, 2);
		world.setBlock(i + 7, j + 1, k + 16, NovaCraftBlocks.sculk_block, 0, 2);
		world.setBlock(i + 8, j + 1, k + 16, deepslate, 0, 2);
		world.setBlock(i + 9, j + 1, k + 16, NovaCraftBlocks.sculk_block, 0, 2);
		world.setBlock(i + 10, j + 1, k + 16, deepslate, 0, 2);
		world.setBlock(i + 11, j + 1, k + 16, cobbled_deepslate, 0, 2);
		world.setBlock(i + 12, j + 1, k + 16, deepslate, 0, 2);
		world.setBlock(i + 13, j + 1, k + 16, deepslate, 0, 2);
		world.setBlock(i + 14, j + 1, k + 16, deepslate, 0, 2);
		world.setBlock(i + 15, j + 1, k + 16, deepslate, 0, 2);
		world.setBlock(i + 16, j + 1, k + 16, deepslate, 0, 2);
		world.setBlock(i + 17, j + 1, k + 16, deepslate, 0, 2);
		world.setBlock(i + 18, j + 1, k + 16, deepslate, 0, 2);
		world.setBlock(i + 19, j + 1, k + 16, deepslate, 0, 2);
		world.setBlock(i + 20, j + 1, k + 16, Blocks.air, 0, 2);
		world.setBlock(i + 0, j + 1, k + 17, Blocks.air, 0, 2);
		world.setBlock(i + 1, j + 1, k + 17, deepslate, 0, 2);
		world.setBlock(i + 2, j + 1, k + 17, Blocks.air, 0, 2);
		world.setBlock(i + 3, j + 1, k + 17, NovaCraftBlocks.sculk_block, 0, 2);
		world.setBlock(i + 4, j + 1, k + 17, NovaCraftBlocks.sculk_block, 0, 2);
		world.setBlock(i + 5, j + 1, k + 17, NovaCraftBlocks.sculk_block, 0, 2);
		world.setBlock(i + 6, j + 1, k + 17, NovaCraftBlocks.sculk_block, 0, 2);
		world.setBlock(i + 7, j + 1, k + 17, Blocks.air, 0, 2);
		world.setBlock(i + 8, j + 1, k + 17, NovaCraftBlocks.sculk_block, 0, 2);
		world.setBlock(i + 9, j + 1, k + 17, NovaCraftBlocks.sculk_block, 0, 2);
		world.setBlock(i + 10, j + 1, k + 17, cobbled_deepslate, 0, 2);
		world.setBlock(i + 11, j + 1, k + 17, Blocks.air, 0, 2);
		world.setBlock(i + 12, j + 1, k + 17, Blocks.air, 0, 2);
		world.setBlock(i + 13, j + 1, k + 17, Blocks.air, 0, 2);
		world.setBlock(i + 14, j + 1, k + 17, deepslate, 0, 2);
		world.setBlock(i + 15, j + 1, k + 17, deepslate, 0, 2);
		world.setBlock(i + 16, j + 1, k + 17, deepslate, 0, 2);
		world.setBlock(i + 17, j + 1, k + 17, deepslate, 0, 2);
		world.setBlock(i + 18, j + 1, k + 17, deepslate, 0, 2);
		world.setBlock(i + 19, j + 1, k + 17, deepslate, 0, 2);
		world.setBlock(i + 20, j + 1, k + 17, Blocks.air, 0, 2);
		world.setBlock(i + 0, j + 1, k + 18, Blocks.air, 0, 2);
		world.setBlock(i + 1, j + 1, k + 18, Blocks.air, 0, 2);
		world.setBlock(i + 2, j + 1, k + 18, Blocks.air, 0, 2);
		world.setBlock(i + 3, j + 1, k + 18, Blocks.air, 0, 2);
		world.setBlock(i + 4, j + 1, k + 18, Blocks.air, 0, 2);
		world.setBlock(i + 5, j + 1, k + 18, Blocks.air, 0, 2);
		world.setBlock(i + 6, j + 1, k + 18, Blocks.air, 0, 2);
		world.setBlock(i + 7, j + 1, k + 18, Blocks.air, 0, 2);
		world.setBlock(i + 8, j + 1, k + 18, Blocks.air, 0, 2);
		world.setBlock(i + 9, j + 1, k + 18, Blocks.air, 0, 2);
		world.setBlock(i + 10, j + 1, k + 18, Blocks.air, 0, 2);
		world.setBlock(i + 11, j + 1, k + 18, Blocks.air, 0, 2);
		world.setBlock(i + 12, j + 1, k + 18, Blocks.air, 0, 2);
		world.setBlock(i + 13, j + 1, k + 18, Blocks.air, 0, 2);
		world.setBlock(i + 14, j + 1, k + 18, Blocks.air, 0, 2);
		world.setBlock(i + 15, j + 1, k + 18, Blocks.air, 0, 2);
		world.setBlock(i + 16, j + 1, k + 18, Blocks.air, 0, 2);
		world.setBlock(i + 17, j + 1, k + 18, Blocks.air, 0, 2);
		world.setBlock(i + 18, j + 1, k + 18, Blocks.air, 0, 2);
		world.setBlock(i + 19, j + 1, k + 18, Blocks.air, 0, 2);
		world.setBlock(i + 20, j + 1, k + 18, Blocks.air, 0, 2);
		world.setBlock(i + 0, j + 2, k + 0, Blocks.air, 0, 2);
		world.setBlock(i + 1, j + 2, k + 0, Blocks.air, 0, 2);
		world.setBlock(i + 2, j + 2, k + 0, Blocks.air, 0, 2);
		world.setBlock(i + 3, j + 2, k + 0, Blocks.air, 0, 2);
		world.setBlock(i + 4, j + 2, k + 0, Blocks.air, 0, 2);
		world.setBlock(i + 5, j + 2, k + 0, Blocks.air, 0, 2);
		world.setBlock(i + 6, j + 2, k + 0, Blocks.air, 0, 2);
		world.setBlock(i + 7, j + 2, k + 0, Blocks.air, 0, 2);
		world.setBlock(i + 8, j + 2, k + 0, Blocks.air, 0, 2);
		world.setBlock(i + 9, j + 2, k + 0, Blocks.air, 0, 2);
		world.setBlock(i + 10, j + 2, k + 0, Blocks.air, 0, 2);
		world.setBlock(i + 11, j + 2, k + 0, Blocks.air, 0, 2);
		world.setBlock(i + 12, j + 2, k + 0, Blocks.air, 0, 2);
		world.setBlock(i + 13, j + 2, k + 0, Blocks.air, 0, 2);
		world.setBlock(i + 14, j + 2, k + 0, Blocks.air, 0, 2);
		world.setBlock(i + 15, j + 2, k + 0, Blocks.air, 0, 2);
		world.setBlock(i + 16, j + 2, k + 0, Blocks.air, 0, 2);
		world.setBlock(i + 17, j + 2, k + 0, Blocks.air, 0, 2);
		world.setBlock(i + 18, j + 2, k + 0, Blocks.air, 0, 2);
		world.setBlock(i + 19, j + 2, k + 0, Blocks.air, 0, 2);
		world.setBlock(i + 20, j + 2, k + 0, Blocks.air, 0, 2);
		world.setBlock(i + 0, j + 2, k + 1, Blocks.air, 0, 2);
		world.setBlock(i + 1, j + 2, k + 1, deepslate, 0, 2);
		world.setBlock(i + 2, j + 2, k + 1, polished_deepslate, 0, 2);
		world.setBlock(i + 3, j + 2, k + 1, deepslate, 0, 2);
		world.setBlock(i + 4, j + 2, k + 1, polished_deepslate, 0, 2);
		world.setBlock(i + 5, j + 2, k + 1, deepslate, 0, 2);
		world.setBlock(i + 6, j + 2, k + 1, polished_deepslate, 0, 2);
		world.setBlock(i + 7, j + 2, k + 1, deepslate, 0, 2);
		world.setBlock(i + 8, j + 2, k + 1, polished_deepslate, 0, 2);
		world.setBlock(i + 9, j + 2, k + 1, deepslate, 0, 2);
		world.setBlock(i + 10, j + 2, k + 1, polished_deepslate, 0, 2);
		world.setBlock(i + 11, j + 2, k + 1, deepslate, 0, 2);
		world.setBlock(i + 12, j + 2, k + 1, polished_deepslate, 0, 2);
		world.setBlock(i + 13, j + 2, k + 1, Blocks.air, 0, 2);
		world.setBlock(i + 14, j + 2, k + 1, polished_deepslate, 0, 2);
		world.setBlock(i + 15, j + 2, k + 1, deepslate, 0, 2);
		world.setBlock(i + 16, j + 2, k + 1, polished_deepslate, 0, 2);
		world.setBlock(i + 17, j + 2, k + 1, deepslate, 0, 2);
		world.setBlock(i + 18, j + 2, k + 1, polished_deepslate, 0, 2);
		world.setBlock(i + 19, j + 2, k + 1, deepslate, 0, 2);
		world.setBlock(i + 20, j + 2, k + 1, Blocks.air, 0, 2);
		world.setBlock(i + 0, j + 2, k + 2, NovaCraftBlocks.sculk_vein, 4, 2);
		world.setBlock(i + 1, j + 2, k + 2, polished_deepslate, 0, 2);
		world.setBlock(i + 2, j + 2, k + 2, deepslate, 0, 2);
		world.setBlock(i + 3, j + 2, k + 2, deepslate, 0, 2);
		world.setBlock(i + 4, j + 2, k + 2, deepslate, 0, 2);
		world.setBlock(i + 5, j + 2, k + 2, deepslate, 0, 2);
		world.setBlock(i + 6, j + 2, k + 2, deepslate, 0, 2);
		world.setBlock(i + 7, j + 2, k + 2, deepslate, 0, 2);
		world.setBlock(i + 8, j + 2, k + 2, deepslate, 0, 2);
		world.setBlock(i + 9, j + 2, k + 2, deepslate, 0, 2);
		world.setBlock(i + 10, j + 2, k + 2, deepslate, 0, 2);
		world.setBlock(i + 11, j + 2, k + 2, deepslate, 0, 2);
		world.setBlock(i + 12, j + 2, k + 2, deepslate, 0, 2);
		world.setBlock(i + 13, j + 2, k + 2, deepslate, 0, 2);
		world.setBlock(i + 14, j + 2, k + 2, deepslate, 0, 2);
		world.setBlock(i + 15, j + 2, k + 2, deepslate, 0, 2);
		world.setBlock(i + 16, j + 2, k + 2, deepslate, 0, 2);
		world.setBlock(i + 17, j + 2, k + 2, deepslate, 0, 2);
		world.setBlock(i + 18, j + 2, k + 2, deepslate, 0, 2);
		world.setBlock(i + 19, j + 2, k + 2, polished_deepslate, 0, 2);
		world.setBlock(i + 20, j + 2, k + 2, Blocks.air, 0, 2);
		world.setBlock(i + 0, j + 2, k + 3, NovaCraftBlocks.sculk_vein, 4, 2);
		world.setBlock(i + 1, j + 2, k + 3, deepslate, 0, 2);
		world.setBlock(i + 2, j + 2, k + 3, NovaCraftBlocks.sculk_block, 0, 2);
		world.setBlock(i + 3, j + 2, k + 3, NovaCraftBlocks.sculk_block, 0, 2);
		world.setBlock(i + 4, j + 2, k + 3, deepslate, 0, 2);
		world.setBlock(i + 5, j + 2, k + 3, deepslate, 0, 2);
		world.setBlock(i + 6, j + 2, k + 3, deepslate, 0, 2);
		world.setBlock(i + 7, j + 2, k + 3, deepslate, 0, 2);
		world.setBlock(i + 8, j + 2, k + 3, deepslate, 0, 2);
		world.setBlock(i + 9, j + 2, k + 3, deepslate, 0, 2);
		world.setBlock(i + 10, j + 2, k + 3, deepslate, 0, 2);
		world.setBlock(i + 11, j + 2, k + 3, deepslate, 0, 2);
		world.setBlock(i + 12, j + 2, k + 3, deepslate, 0, 2);
		world.setBlock(i + 13, j + 2, k + 3, deepslate, 0, 2);
		world.setBlock(i + 14, j + 2, k + 3, deepslate, 0, 2);
		world.setBlock(i + 15, j + 2, k + 3, deepslate, 0, 2);
		world.setBlock(i + 16, j + 2, k + 3, deepslate, 0, 2);
		world.setBlock(i + 17, j + 2, k + 3, deepslate, 0, 2);
		world.setBlock(i + 18, j + 2, k + 3, deepslate, 0, 2);
		world.setBlock(i + 19, j + 2, k + 3, deepslate, 0, 2);
		world.setBlock(i + 20, j + 2, k + 3, Blocks.air, 0, 2);
		world.setBlock(i + 0, j + 2, k + 4, NovaCraftBlocks.sculk_vein, 4, 2);
		world.setBlock(i + 1, j + 2, k + 4, polished_deepslate, 0, 2);
		world.setBlock(i + 2, j + 2, k + 4, deepslate, 0, 2);
		world.setBlock(i + 3, j + 2, k + 4, NovaCraftBlocks.sculk_vein, 1, 2);
		world.setBlock(i + 4, j + 2, k + 4, deepslate, 0, 2);
		world.setBlock(i + 5, j + 2, k + 4, deepslate, 0, 2);
		world.setBlock(i + 6, j + 2, k + 4, deepslate, 0, 2);
		world.setBlock(i + 7, j + 2, k + 4, deepslate, 0, 2);
		world.setBlock(i + 8, j + 2, k + 4, deepslate, 0, 2);
		world.setBlock(i + 9, j + 2, k + 4, deepslate, 0, 2);
		world.setBlock(i + 10, j + 2, k + 4, Blocks.air, 0, 2);
		world.setBlock(i + 11, j + 2, k + 4, deepslate, 0, 2);
		world.setBlock(i + 12, j + 2, k + 4, deepslate, 0, 2);
		world.setBlock(i + 13, j + 2, k + 4, deepslate, 0, 2);
		world.setBlock(i + 14, j + 2, k + 4, deepslate, 0, 2);
		world.setBlock(i + 15, j + 2, k + 4, Blocks.air, 0, 2);
		world.setBlock(i + 16, j + 2, k + 4, deepslate, 0, 2);
		world.setBlock(i + 17, j + 2, k + 4, deepslate, 0, 2);
		world.setBlock(i + 18, j + 2, k + 4, deepslate, 0, 2);
		world.setBlock(i + 19, j + 2, k + 4, polished_deepslate, 0, 2);
		world.setBlock(i + 20, j + 2, k + 4, Blocks.air, 0, 2);
		world.setBlock(i + 0, j + 2, k + 5, NovaCraftBlocks.sculk_vein, 4, 2);
		world.setBlock(i + 1, j + 2, k + 5, deepslate, 0, 2);
		world.setBlock(i + 2, j + 2, k + 5, deepslate, 0, 2);
		world.setBlock(i + 3, j + 2, k + 5, deepslate, 0, 2);
		world.setBlock(i + 4, j + 2, k + 5, deepslate, 0, 2);
		world.setBlock(i + 5, j + 2, k + 5, deepslate, 0, 2);
		world.setBlock(i + 6, j + 2, k + 5, NovaCraftBlocks.sculk_block, 0, 2);
		world.setBlock(i + 7, j + 2, k + 5, deepslate, 0, 2);
		world.setBlock(i + 8, j + 2, k + 5, deepslate, 0, 2);
		world.setBlock(i + 9, j + 2, k + 5, deepslate, 0, 2);
		world.setBlock(i + 10, j + 2, k + 5, deepslate, 0, 2);
		world.setBlock(i + 11, j + 2, k + 5, deepslate, 0, 2);
		world.setBlock(i + 12, j + 2, k + 5, deepslate, 0, 2);
		world.setBlock(i + 13, j + 2, k + 5, deepslate, 0, 2);
		world.setBlock(i + 14, j + 2, k + 5, deepslate, 0, 2);
		world.setBlock(i + 15, j + 2, k + 5, deepslate, 0, 2);
		world.setBlock(i + 16, j + 2, k + 5, deepslate, 0, 2);
		world.setBlock(i + 17, j + 2, k + 5, deepslate, 0, 2);
		world.setBlock(i + 18, j + 2, k + 5, deepslate, 0, 2);
		world.setBlock(i + 19, j + 2, k + 5, polished_deepslate, 0, 2);
		world.setBlock(i + 20, j + 2, k + 5, Blocks.air, 0, 2);
		world.setBlock(i + 0, j + 2, k + 6, Blocks.air, 0, 2);
		world.setBlock(i + 1, j + 2, k + 6, polished_deepslate, 0, 2);
		world.setBlock(i + 2, j + 2, k + 6, NovaCraftBlocks.sculk_block, 0, 2);
		world.setBlock(i + 3, j + 2, k + 6, deepslate, 0, 2);
		world.setBlock(i + 4, j + 2, k + 6, deepslate, 0, 2);
		world.setBlock(i + 5, j + 2, k + 6, deepslate, 0, 2);
		world.setBlock(i + 6, j + 2, k + 6, deepslate, 0, 2);
		world.setBlock(i + 7, j + 2, k + 6, deepslate, 0, 2);
		world.setBlock(i + 8, j + 2, k + 6, deepslate, 0, 2);
		world.setBlock(i + 9, j + 2, k + 6, deepslate, 0, 2);
		world.setBlock(i + 10, j + 2, k + 6, deepslate, 0, 2);
		world.setBlock(i + 11, j + 2, k + 6, deepslate, 0, 2);
		world.setBlock(i + 12, j + 2, k + 6, deepslate, 0, 2);
		world.setBlock(i + 13, j + 2, k + 6, deepslate, 0, 2);
		world.setBlock(i + 14, j + 2, k + 6, deepslate, 0, 2);
		world.setBlock(i + 15, j + 2, k + 6, cobbled_deepslate_stairs, 1, 2);
		world.setBlock(i + 16, j + 2, k + 6, NovaCraftBlocks.sculk_vein, 3, 2);
		world.setBlock(i + 17, j + 2, k + 6, Blocks.air, 0, 2);
		world.setBlock(i + 18, j + 2, k + 6, Blocks.air, 0, 2);
		world.setBlock(i + 19, j + 2, k + 6, Blocks.air, 0, 2);
		world.setBlock(i + 20, j + 2, k + 6, Blocks.air, 0, 2);
		world.setBlock(i + 0, j + 2, k + 7, Blocks.air, 0, 2);
		world.setBlock(i + 1, j + 2, k + 7, deepslate, 0, 2);
		world.setBlock(i + 2, j + 2, k + 7, NovaCraftBlocks.sculk_vein, 1, 2);
		world.setBlock(i + 3, j + 2, k + 7, NovaCraftBlocks.sculk_block, 0, 2);
		world.setBlock(i + 4, j + 2, k + 7, deepslate, 0, 2);
		world.setBlock(i + 5, j + 2, k + 7, deepslate, 0, 2);
		world.setBlock(i + 6, j + 2, k + 7, deepslate, 0, 2);
		world.setBlock(i + 7, j + 2, k + 7, deepslate, 0, 2);
		world.setBlock(i + 8, j + 2, k + 7, deepslate, 0, 2);
		world.setBlock(i + 9, j + 2, k + 7, deepslate, 0, 2);
		world.setBlock(i + 10, j + 2, k + 7, deepslate, 0, 2);
		world.setBlock(i + 11, j + 2, k + 7, deepslate, 0, 2);
		world.setBlock(i + 12, j + 2, k + 7, deepslate, 0, 2);
		world.setBlock(i + 13, j + 2, k + 7, deepslate, 0, 2);
		world.setBlock(i + 14, j + 2, k + 7, deepslate, 0, 2);
		world.setBlock(i + 15, j + 2, k + 7, cobbled_deepslate_stairs, 1, 2);
		world.setBlock(i + 16, j + 2, k + 7, Blocks.air, 0, 2);
		world.setBlock(i + 17, j + 2, k + 7, NovaCraftBlocks.sculk_vein, 2, 2);
		world.setBlock(i + 18, j + 2, k + 7, Blocks.air, 0, 2);
		world.setBlock(i + 19, j + 2, k + 7, Blocks.air, 0, 2);
		world.setBlock(i + 20, j + 2, k + 7, Blocks.air, 0, 2);
		world.setBlock(i + 0, j + 2, k + 8, Blocks.air, 0, 2);
		world.setBlock(i + 1, j + 2, k + 8, polished_deepslate, 0, 2);
		world.setBlock(i + 2, j + 2, k + 8, deepslate, 0, 2);
		world.setBlock(i + 3, j + 2, k + 8, deepslate, 0, 2);
		world.setBlock(i + 4, j + 2, k + 8, deepslate, 0, 2);
		world.setBlock(i + 5, j + 2, k + 8, deepslate, 0, 2);
		world.setBlock(i + 6, j + 2, k + 8, deepslate, 0, 2);
		world.setBlock(i + 7, j + 2, k + 8, deepslate, 0, 2);
		world.setBlock(i + 8, j + 2, k + 8, NovaCraftBlocks.sculk_block, 0, 2);
		world.setBlock(i + 9, j + 2, k + 8, deepslate, 0, 2);
		world.setBlock(i + 10, j + 2, k + 8, NovaCraftBlocks.sculk_block, 0, 2);
		world.setBlock(i + 11, j + 2, k + 8, NovaCraftBlocks.sculk_block, 0, 2);
		world.setBlock(i + 12, j + 2, k + 8, NovaCraftBlocks.sculk_block, 0, 2);
		world.setBlock(i + 13, j + 2, k + 8, NovaCraftBlocks.sculk_block, 0, 2);
		world.setBlock(i + 14, j + 2, k + 8, NovaCraftBlocks.sculk_block, 0, 2);
		world.setBlock(i + 15, j + 2, k + 8, NovaCraftBlocks.sculk_block, 0, 2);
		world.setBlock(i + 16, j + 2, k + 8, NovaCraftBlocks.sculk_block, 0, 2);
		world.setBlock(i + 17, j + 2, k + 8, deepslate, 0, 2);
		world.setBlock(i + 18, j + 2, k + 8, deepslate, 0, 2);
		world.setBlock(i + 19, j + 2, k + 8, polished_deepslate, 0, 2);
		world.setBlock(i + 20, j + 2, k + 8, Blocks.air, 0, 2);
		world.setBlock(i + 0, j + 2, k + 9, Blocks.air, 0, 2);
		world.setBlock(i + 1, j + 2, k + 9, deepslate, 0, 2);
		world.setBlock(i + 2, j + 2, k + 9, deepslate, 0, 2);
		world.setBlock(i + 3, j + 2, k + 9, deepslate, 0, 2);
		world.setBlock(i + 4, j + 2, k + 9, deepslate, 0, 2);
		world.setBlock(i + 5, j + 2, k + 9, deepslate, 0, 2);
		world.setBlock(i + 6, j + 2, k + 9, deepslate, 0, 2);
		world.setBlock(i + 7, j + 2, k + 9, deepslate, 0, 2);
		world.setBlock(i + 8, j + 2, k + 9, NovaCraftBlocks.sculk_block, 0, 2);
		world.setBlock(i + 9, j + 2, k + 9, NovaCraftBlocks.sculk_block, 0, 2);
		world.setBlock(i + 10, j + 2, k + 9, Blocks.air, 0, 2);
		world.setBlock(i + 11, j + 2, k + 9, deepslate, 0, 2);
		world.setBlock(i + 12, j + 2, k + 9, deepslate, 0, 2);
		world.setBlock(i + 13, j + 2, k + 9, deepslate, 0, 2);
		world.setBlock(i + 14, j + 2, k + 9, deepslate, 0, 2);
		world.setBlock(i + 15, j + 2, k + 9, deepslate, 0, 2);
		world.setBlock(i + 16, j + 2, k + 9, deepslate, 0, 2);
		world.setBlock(i + 17, j + 2, k + 9, deepslate, 0, 2);
		world.setBlock(i + 18, j + 2, k + 9, deepslate, 0, 2);
		world.setBlock(i + 19, j + 2, k + 9, polished_deepslate, 0, 2);
		world.setBlock(i + 20, j + 2, k + 9, Blocks.air, 0, 2);
		world.setBlock(i + 0, j + 2, k + 10, Blocks.air, 0, 2);
		world.setBlock(i + 1, j + 2, k + 10, polished_deepslate, 0, 2);
		world.setBlock(i + 2, j + 2, k + 10, deepslate, 0, 2);
		world.setBlock(i + 3, j + 2, k + 10, deepslate, 0, 2);
		world.setBlock(i + 4, j + 2, k + 10, deepslate, 0, 2);
		world.setBlock(i + 5, j + 2, k + 10, deepslate, 0, 2);
		world.setBlock(i + 6, j + 2, k + 10, deepslate, 0, 2);
		world.setBlock(i + 7, j + 2, k + 10, deepslate, 0, 2);
		world.setBlock(i + 8, j + 2, k + 10, deepslate, 0, 2);
		world.setBlock(i + 9, j + 2, k + 10, NovaCraftBlocks.sculk_block, 0, 2);
		world.setBlock(i + 10, j + 2, k + 10, deepslate, 0, 2);
		world.setBlock(i + 11, j + 2, k + 10, deepslate, 0, 2);
		world.setBlock(i + 12, j + 2, k + 10, deepslate, 0, 2);
		world.setBlock(i + 13, j + 2, k + 10, deepslate, 0, 2);
		world.setBlock(i + 14, j + 2, k + 10, deepslate, 0, 2);
		world.setBlock(i + 15, j + 2, k + 10, deepslate, 0, 2);
		world.setBlock(i + 16, j + 2, k + 10, deepslate, 0, 2);
		world.setBlock(i + 17, j + 2, k + 10, deepslate, 0, 2);
		world.setBlock(i + 18, j + 2, k + 10, deepslate, 0, 2);
		world.setBlock(i + 19, j + 2, k + 10, deepslate, 0, 2);
		world.setBlock(i + 20, j + 2, k + 10, Blocks.air, 0, 2);
		world.setBlock(i + 0, j + 2, k + 11, Blocks.air, 0, 2);
		world.setBlock(i + 1, j + 2, k + 11, deepslate, 0, 2);
		world.setBlock(i + 2, j + 2, k + 11, deepslate, 0, 2);
		world.setBlock(i + 3, j + 2, k + 11, deepslate, 0, 2);
		world.setBlock(i + 4, j + 2, k + 11, deepslate, 0, 2);
		world.setBlock(i + 5, j + 2, k + 11, deepslate, 0, 2);
		world.setBlock(i + 6, j + 2, k + 11, deepslate, 0, 2);
		world.setBlock(i + 7, j + 2, k + 11, deepslate, 0, 2);
		world.setBlock(i + 8, j + 2, k + 11, NovaCraftBlocks.sculk_block, 0, 2);
		world.setBlock(i + 10, j + 2, k + 11, deepslate, 0, 2);
		world.setBlock(i + 11, j + 2, k + 11, deepslate, 0, 2);
		world.setBlock(i + 12, j + 2, k + 11, deepslate, 0, 2);
		world.setBlock(i + 13, j + 2, k + 11, deepslate, 0, 2);
		world.setBlock(i + 14, j + 2, k + 11, deepslate, 0, 2);
		world.setBlock(i + 15, j + 2, k + 11, deepslate, 0, 2);
		world.setBlock(i + 16, j + 2, k + 11, deepslate, 0, 2);
		world.setBlock(i + 17, j + 2, k + 11, deepslate, 0, 2);
		world.setBlock(i + 18, j + 2, k + 11, Blocks.air, 0, 2);
		world.setBlock(i + 19, j + 2, k + 11, polished_deepslate, 0, 2);
		world.setBlock(i + 20, j + 2, k + 11, Blocks.air, 0, 2);
		world.setBlock(i + 0, j + 2, k + 12, Blocks.air, 0, 2);
		world.setBlock(i + 1, j + 2, k + 12, polished_deepslate, 0, 2);
		world.setBlock(i + 2, j + 2, k + 12, deepslate, 0, 2);
		world.setBlock(i + 3, j + 2, k + 12, deepslate, 0, 2);
		world.setBlock(i + 4, j + 2, k + 12, deepslate, 0, 2);
		world.setBlock(i + 5, j + 2, k + 12, deepslate, 0, 2);
		world.setBlock(i + 6, j + 2, k + 12, deepslate, 0, 2);
		world.setBlock(i + 7, j + 2, k + 12, Blocks.air, 0, 2);
		world.setBlock(i + 8, j + 2, k + 12, deepslate, 0, 2);
		world.setBlock(i + 9, j + 2, k + 12, NovaCraftBlocks.sculk_block, 0, 2);
		world.setBlock(i + 10, j + 2, k + 12, deepslate, 0, 2);
		world.setBlock(i + 11, j + 2, k + 12, deepslate, 0, 2);
		world.setBlock(i + 12, j + 2, k + 12, deepslate, 0, 2);
		world.setBlock(i + 13, j + 2, k + 12, deepslate, 0, 2);
		world.setBlock(i + 14, j + 2, k + 12, deepslate, 0, 2);
		world.setBlock(i + 15, j + 2, k + 12, deepslate, 0, 2);
		world.setBlock(i + 16, j + 2, k + 12, deepslate, 0, 2);
		world.setBlock(i + 17, j + 2, k + 12, deepslate, 0, 2);
		world.setBlock(i + 18, j + 2, k + 12, deepslate, 0, 2);
		world.setBlock(i + 19, j + 2, k + 12, polished_deepslate, 0, 2);
		world.setBlock(i + 20, j + 2, k + 12, Blocks.air, 0, 2);
		world.setBlock(i + 0, j + 2, k + 13, Blocks.air, 0, 2);
		world.setBlock(i + 1, j + 2, k + 13, deepslate, 0, 2);
		world.setBlock(i + 2, j + 2, k + 13, deepslate, 0, 2);
		world.setBlock(i + 3, j + 2, k + 13, deepslate, 0, 2);
		world.setBlock(i + 4, j + 2, k + 13, deepslate, 0, 2);
		world.setBlock(i + 5, j + 2, k + 13, deepslate, 0, 2);
		world.setBlock(i + 6, j + 2, k + 13, deepslate, 0, 2);
		world.setBlock(i + 7, j + 2, k + 13, deepslate, 0, 2);
		world.setBlock(i + 8, j + 2, k + 13, deepslate, 0, 2);
		world.setBlock(i + 9, j + 2, k + 13, NovaCraftBlocks.sculk_block, 0, 2);
		world.setBlock(i + 10, j + 2, k + 13, deepslate, 0, 2);
		world.setBlock(i + 11, j + 2, k + 13, deepslate, 0, 2);
		world.setBlock(i + 12, j + 2, k + 13, deepslate, 0, 2);
		world.setBlock(i + 13, j + 2, k + 13, deepslate, 0, 2);
		world.setBlock(i + 14, j + 2, k + 13, deepslate, 0, 2);
		world.setBlock(i + 15, j + 2, k + 13, deepslate, 0, 2);
		world.setBlock(i + 16, j + 2, k + 13, deepslate, 0, 2);
		world.setBlock(i + 17, j + 2, k + 13, deepslate, 0, 2);
		world.setBlock(i + 18, j + 2, k + 13, deepslate, 0, 2);
		world.setBlock(i + 19, j + 2, k + 13, deepslate, 0, 2);
		world.setBlock(i + 20, j + 2, k + 13, Blocks.air, 0, 2);
		world.setBlock(i + 0, j + 2, k + 14, Blocks.air, 0, 2);
		world.setBlock(i + 1, j + 2, k + 14, polished_deepslate, 0, 2);
		world.setBlock(i + 2, j + 2, k + 14, deepslate, 0, 2);
		world.setBlock(i + 3, j + 2, k + 14, Blocks.air, 0, 2);
		world.setBlock(i + 4, j + 2, k + 14, deepslate, 0, 2);
		world.setBlock(i + 5, j + 2, k + 14, deepslate, 0, 2);
		world.setBlock(i + 6, j + 2, k + 14, deepslate, 0, 2);
		world.setBlock(i + 7, j + 2, k + 14, deepslate, 0, 2);
		world.setBlock(i + 8, j + 2, k + 14, deepslate, 0, 2);
		world.setBlock(i + 9, j + 2, k + 14, NovaCraftBlocks.sculk_block, 0, 2);
		world.setBlock(i + 10, j + 2, k + 14, deepslate, 0, 2);
		world.setBlock(i + 11, j + 2, k + 14, deepslate, 0, 2);
		world.setBlock(i + 12, j + 2, k + 14, deepslate, 0, 2);
		world.setBlock(i + 13, j + 2, k + 14, deepslate, 0, 2);
		world.setBlock(i + 14, j + 2, k + 14, deepslate, 0, 2);
		world.setBlock(i + 15, j + 2, k + 14, deepslate, 0, 2);
		world.setBlock(i + 16, j + 2, k + 14, deepslate, 0, 2);
		world.setBlock(i + 17, j + 2, k + 14, deepslate, 0, 2);
		world.setBlock(i + 18, j + 2, k + 14, deepslate, 0, 2);
		world.setBlock(i + 19, j + 2, k + 14, polished_deepslate, 0, 2);
		world.setBlock(i + 20, j + 2, k + 14, Blocks.air, 0, 2);
		world.setBlock(i + 0, j + 2, k + 15, Blocks.air, 0, 2);
		world.setBlock(i + 1, j + 2, k + 15, deepslate, 0, 2);
		world.setBlock(i + 2, j + 2, k + 15, deepslate_brick_stairs, 3, 2);
		world.setBlock(i + 3, j + 2, k + 15, deepslate, 0, 2);
		world.setBlock(i + 4, j + 2, k + 15, deepslate, 0, 2);
		world.setBlock(i + 5, j + 2, k + 15, deepslate, 0, 2);
		world.setBlock(i + 6, j + 2, k + 15, deepslate, 0, 2);
		world.setBlock(i + 7, j + 2, k + 15, deepslate, 0, 2);
		world.setBlock(i + 8, j + 2, k + 15, deepslate, 0, 2);
		world.setBlock(i + 9, j + 2, k + 15, NovaCraftBlocks.sculk_block, 0, 2);
		world.setBlock(i + 10, j + 2, k + 15, deepslate, 0, 2);
		world.setBlock(i + 11, j + 2, k + 15, deepslate, 0, 2);
		world.setBlock(i + 12, j + 2, k + 15, cobbled_deepslate, 0, 2);
		world.setBlock(i + 13, j + 2, k + 15, deepslate, 0, 2);
		world.setBlock(i + 14, j + 2, k + 15, deepslate, 0, 2);
		world.setBlock(i + 15, j + 2, k + 15, deepslate, 0, 2);
		world.setBlock(i + 16, j + 2, k + 15, deepslate, 0, 2);
		world.setBlock(i + 17, j + 2, k + 15, deepslate, 0, 2);
		world.setBlock(i + 18, j + 2, k + 15, deepslate, 0, 2);
		world.setBlock(i + 19, j + 2, k + 15, deepslate, 0, 2);
		world.setBlock(i + 20, j + 2, k + 15, Blocks.air, 0, 2);
		world.setBlock(i + 0, j + 2, k + 16, Blocks.air, 0, 2);
		world.setBlock(i + 1, j + 2, k + 16, polished_deepslate, 0, 2);
		world.setBlock(i + 2, j + 2, k + 16, Blocks.air, 0, 2);
		world.setBlock(i + 3, j + 2, k + 16, deepslate, 0, 2);
		world.setBlock(i + 4, j + 2, k + 16, deepslate, 0, 2);
		world.setBlock(i + 5, j + 2, k + 16, deepslate, 0, 2);
		world.setBlock(i + 6, j + 2, k + 16, deepslate, 0, 2);
		world.setBlock(i + 7, j + 2, k + 16, deepslate, 0, 2);
		world.setBlock(i + 8, j + 2, k + 16, Blocks.air, 0, 2);
		world.setBlock(i + 9, j + 2, k + 16, NovaCraftBlocks.sculk_block, 0, 2);
		world.setBlock(i + 10, j + 2, k + 16, deepslate, 0, 2);
		world.setBlock(i + 11, j + 2, k + 16, Blocks.air, 0, 2);
		world.setBlock(i + 12, j + 2, k + 16, Blocks.air, 0, 2);
		world.setBlock(i + 13, j + 2, k + 16, deepslate, 0, 2);
		world.setBlock(i + 14, j + 2, k + 16, deepslate, 0, 2);
		world.setBlock(i + 15, j + 2, k + 16, deepslate, 0, 2);
		world.setBlock(i + 16, j + 2, k + 16, deepslate, 0, 2);
		world.setBlock(i + 17, j + 2, k + 16, deepslate, 0, 2);
		world.setBlock(i + 18, j + 2, k + 16, deepslate, 0, 2);
		world.setBlock(i + 19, j + 2, k + 16, polished_deepslate, 0, 2);
		world.setBlock(i + 20, j + 2, k + 16, Blocks.air, 0, 2);
		world.setBlock(i + 0, j + 2, k + 17, Blocks.air, 0, 2);
		world.setBlock(i + 1, j + 2, k + 17, deepslate, 0, 2);
		world.setBlock(i + 2, j + 2, k + 17, NovaCraftBlocks.sculk_vein, 4, 2);
		world.setBlock(i + 3, j + 2, k + 17, polished_deepslate, 0, 2);
		world.setBlock(i + 4, j + 2, k + 17, NovaCraftBlocks.sculk_block, 0, 2);
		world.setBlock(i + 5, j + 2, k + 17, polished_deepslate, 0, 2);
		world.setBlock(i + 6, j + 2, k + 17, NovaCraftBlocks.sculk_block, 0, 2);
		world.setBlock(i + 7, j + 2, k + 17, NovaCraftBlocks.sculk_block, 0, 2);
		world.setBlock(i + 8, j + 2, k + 17, deepslate, 0, 2);
		world.setBlock(i + 9, j + 2, k + 17, polished_deepslate, 0, 2);
		world.setBlock(i + 10, j + 2, k + 17, NovaCraftBlocks.sculk_vein, 5, 2);
		world.setBlock(i + 11, j + 2, k + 17, Blocks.air, 0, 2);
		world.setBlock(i + 12, j + 2, k + 17, Blocks.air, 0, 2);
		world.setBlock(i + 13, j + 2, k + 17, Blocks.air, 0, 2);
		world.setBlock(i + 14, j + 2, k + 17, polished_deepslate, 0, 2);
		world.setBlock(i + 15, j + 2, k + 17, deepslate, 0, 2);
		world.setBlock(i + 16, j + 2, k + 17, polished_deepslate, 0, 2);
		world.setBlock(i + 17, j + 2, k + 17, deepslate, 0, 2);
		world.setBlock(i + 18, j + 2, k + 17, polished_deepslate, 0, 2);
		world.setBlock(i + 19, j + 2, k + 17, deepslate, 0, 2);
		world.setBlock(i + 20, j + 2, k + 17, Blocks.air, 0, 2);
		world.setBlock(i + 0, j + 2, k + 18, Blocks.air, 0, 2);
		world.setBlock(i + 1, j + 2, k + 18, Blocks.air, 0, 2);
		world.setBlock(i + 2, j + 2, k + 18, Blocks.air, 0, 2);
		world.setBlock(i + 3, j + 2, k + 18, NovaCraftBlocks.sculk_vein, 3, 2);
		world.setBlock(i + 4, j + 2, k + 18, Blocks.air, 0, 2);
		world.setBlock(i + 5, j + 2, k + 18, NovaCraftBlocks.sculk_vein, 3, 2);
		world.setBlock(i + 6, j + 2, k + 18, Blocks.air, 0, 2);
		world.setBlock(i + 7, j + 2, k + 18, Blocks.air, 0, 2);
		world.setBlock(i + 8, j + 2, k + 18, NovaCraftBlocks.sculk_vein, 3, 2);
		world.setBlock(i + 9, j + 2, k + 18, NovaCraftBlocks.sculk_vein, 3, 2);
		world.setBlock(i + 10, j + 2, k + 18, Blocks.air, 0, 2);
		world.setBlock(i + 11, j + 2, k + 18, Blocks.air, 0, 2);
		world.setBlock(i + 12, j + 2, k + 18, Blocks.air, 0, 2);
		world.setBlock(i + 13, j + 2, k + 18, Blocks.air, 0, 2);
		world.setBlock(i + 14, j + 2, k + 18, Blocks.air, 0, 2);
		world.setBlock(i + 15, j + 2, k + 18, Blocks.air, 0, 2);
		world.setBlock(i + 16, j + 2, k + 18, Blocks.air, 0, 2);
		world.setBlock(i + 17, j + 2, k + 18, Blocks.air, 0, 2);
		world.setBlock(i + 18, j + 2, k + 18, Blocks.air, 0, 2);
		world.setBlock(i + 19, j + 2, k + 18, Blocks.air, 0, 2);
		world.setBlock(i + 20, j + 2, k + 18, Blocks.air, 0, 2);
		world.setBlock(i + 0, j + 3, k + 0, Blocks.air, 0, 2);
		world.setBlock(i + 1, j + 3, k + 0, Blocks.air, 0, 2);
		world.setBlock(i + 2, j + 3, k + 0, Blocks.air, 0, 2);
		world.setBlock(i + 3, j + 3, k + 0, NovaCraftBlocks.sculk_vein, 2, 2);
		world.setBlock(i + 4, j + 3, k + 0, Blocks.air, 0, 2);
		world.setBlock(i + 5, j + 3, k + 0, Blocks.air, 0, 2);
		world.setBlock(i + 6, j + 3, k + 0, Blocks.air, 0, 2);
		world.setBlock(i + 7, j + 3, k + 0, NovaCraftBlocks.sculk_vein, 2, 2);
		world.setBlock(i + 8, j + 3, k + 0, Blocks.air, 0, 2);
		world.setBlock(i + 9, j + 3, k + 0, Blocks.air, 0, 2);
		world.setBlock(i + 10, j + 3, k + 0, Blocks.air, 0, 2);
		world.setBlock(i + 11, j + 3, k + 0, Blocks.air, 0, 2);
		world.setBlock(i + 12, j + 3, k + 0, Blocks.air, 0, 2);
		world.setBlock(i + 13, j + 3, k + 0, Blocks.air, 0, 2);
		world.setBlock(i + 14, j + 3, k + 0, Blocks.air, 0, 2);
		world.setBlock(i + 15, j + 3, k + 0, Blocks.air, 0, 2);
		world.setBlock(i + 16, j + 3, k + 0, Blocks.air, 0, 2);
		world.setBlock(i + 17, j + 3, k + 0, Blocks.air, 0, 2);
		world.setBlock(i + 18, j + 3, k + 0, Blocks.air, 0, 2);
		world.setBlock(i + 19, j + 3, k + 0, Blocks.air, 0, 2);
		world.setBlock(i + 20, j + 3, k + 0, Blocks.air, 0, 2);
		world.setBlock(i + 0, j + 3, k + 1, NovaCraftBlocks.sculk_vein, 4, 2);
		world.setBlock(i + 1, j + 3, k + 1, deepslate, 0, 2);
		world.setBlock(i + 2, j + 3, k + 1, deepslate, 0, 2);
		world.setBlock(i + 3, j + 3, k + 1, polished_deepslate, 0, 2);
		world.setBlock(i + 4, j + 3, k + 1, polished_deepslate, 0, 2);
		world.setBlock(i + 5, j + 3, k + 1, polished_deepslate, 0, 2);
		world.setBlock(i + 6, j + 3, k + 1, polished_deepslate, 0, 2);
		world.setBlock(i + 7, j + 3, k + 1, polished_deepslate, 0, 2);
		world.setBlock(i + 8, j + 3, k + 1, polished_deepslate, 0, 2);
		world.setBlock(i + 9, j + 3, k + 1, polished_deepslate, 0, 2);
		world.setBlock(i + 10, j + 3, k + 1, polished_deepslate, 0, 2);
		world.setBlock(i + 11, j + 3, k + 1, polished_deepslate, 0, 2);
		world.setBlock(i + 12, j + 3, k + 1, polished_deepslate, 0, 2);
		world.setBlock(i + 13, j + 3, k + 1, polished_deepslate, 0, 2);
		world.setBlock(i + 14, j + 3, k + 1, polished_deepslate, 0, 2);
		world.setBlock(i + 15, j + 3, k + 1, polished_deepslate, 0, 2);
		world.setBlock(i + 16, j + 3, k + 1, polished_deepslate, 0, 2);
		world.setBlock(i + 17, j + 3, k + 1, polished_deepslate, 0, 2);
		world.setBlock(i + 18, j + 3, k + 1, polished_deepslate, 0, 2);
		world.setBlock(i + 19, j + 3, k + 1, polished_deepslate, 0, 2);
		world.setBlock(i + 20, j + 3, k + 1, Blocks.air, 0, 2);
		world.setBlock(i + 0, j + 3, k + 2, Blocks.air, 0, 2);
		world.setBlock(i + 1, j + 3, k + 2, NovaCraftBlocks.sculk_block, 0, 2);
		world.setBlock(i + 2, j + 3, k + 2, NovaCraftBlocks.sculk_vein, 1, 2);
		world.setBlock(i + 3, j + 3, k + 2, NovaCraftBlocks.sculk_block, 0, 2);
		world.setBlock(i + 4, j + 3, k + 2, deepslate, 0, 2);
		world.setBlock(i + 5, j + 3, k + 2, deepslate, 0, 2);
		world.setBlock(i + 6, j + 3, k + 2, deepslate, 0, 2);
		world.setBlock(i + 7, j + 3, k + 2, deepslate, 0, 2);
		world.setBlock(i + 8, j + 3, k + 2, deepslate, 0, 2);
		world.setBlock(i + 9, j + 3, k + 2, Blocks.air, 0, 2);
		world.setBlock(i + 10, j + 3, k + 2, deepslate, 0, 2);
		world.setBlock(i + 11, j + 3, k + 2, deepslate, 0, 2);
		world.setBlock(i + 12, j + 3, k + 2, deepslate, 0, 2);
		world.setBlock(i + 13, j + 3, k + 2, deepslate, 0, 2);
		world.setBlock(i + 14, j + 3, k + 2, deepslate, 0, 2);
		world.setBlock(i + 15, j + 3, k + 2, deepslate, 0, 2);
		world.setBlock(i + 16, j + 3, k + 2, deepslate, 0, 2);
		world.setBlock(i + 17, j + 3, k + 2, NovaCraftBlocks.sculk_vein, 1, 2);
		world.setBlock(i + 18, j + 3, k + 2, NovaCraftBlocks.sculk_block, 0, 2);
		world.setBlock(i + 19, j + 3, k + 2, polished_deepslate, 0, 2);
		world.setBlock(i + 20, j + 3, k + 2, Blocks.air, 0, 2);
		world.setBlock(i + 0, j + 3, k + 3, Blocks.air, 0, 2);
		world.setBlock(i + 1, j + 3, k + 3, NovaCraftBlocks.sculk_block, 0, 2);
		world.setBlock(i + 2, j + 3, k + 3, Blocks.air, 0, 2);
		world.setBlock(i + 3, j + 3, k + 3, Blocks.air, 0, 2);
		world.setBlock(i + 4, j + 3, k + 3, deepslate_brick_stairs, 0, 2);
		world.setBlock(i + 5, j + 3, k + 3, NovaCraftBlocks.sculk_block, 0, 2);
		world.setBlock(i + 6, j + 3, k + 3, NovaCraftBlocks.sculk_block, 0, 2);
		world.setBlock(i + 7, j + 3, k + 3, NovaCraftBlocks.sculk_block, 0, 2);
		world.setBlock(i + 8, j + 3, k + 3, NovaCraftBlocks.sculk_block, 0, 2);
		world.setBlock(i + 9, j + 3, k + 3, deepslate, 0, 2);
		world.setBlock(i + 10, j + 3, k + 3, deepslate, 0, 2);
		world.setBlock(i + 11, j + 3, k + 3, deepslate, 0, 2);
		world.setBlock(i + 12, j + 3, k + 3, deepslate, 0, 2);
		world.setBlock(i + 13, j + 3, k + 3, deepslate, 0, 2);
		world.setBlock(i + 14, j + 3, k + 3, deepslate, 0, 2);
		world.setBlock(i + 15, j + 3, k + 3, deepslate, 0, 2);
		world.setBlock(i + 16, j + 3, k + 3, deepslate, 0, 2);
		world.setBlock(i + 17, j + 3, k + 3, NovaCraftBlocks.sculk_block, 0, 2);
		world.setBlock(i + 18, j + 3, k + 3, NovaCraftBlocks.sculk_block, 0, 2);
		world.setBlock(i + 19, j + 3, k + 3, polished_deepslate, 0, 2);
		world.setBlock(i + 20, j + 3, k + 3, Blocks.air, 0, 2);
		world.setBlock(i + 0, j + 3, k + 4, Blocks.air, 0, 2);
		world.setBlock(i + 1, j + 3, k + 4, NovaCraftBlocks.sculk_block, 0, 2);
		world.setBlock(i + 2, j + 3, k + 4, NovaCraftBlocks.sculk_vein, 1, 2);
		world.setBlock(i + 3, j + 3, k + 4, Blocks.air, 0, 2);
		world.setBlock(i + 4, j + 3, k + 4, deepslate_brick_stairs, 0, 2);
		world.setBlock(i + 5, j + 3, k + 4, NovaCraftBlocks.sculk_block, 0, 2);
		world.setBlock(i + 6, j + 3, k + 4, NovaCraftBlocks.sculk_block, 0, 2);
		world.setBlock(i + 7, j + 3, k + 4, NovaCraftBlocks.sculk_block, 0, 2);
		world.setBlock(i + 8, j + 3, k + 4, NovaCraftBlocks.sculk_block, 0, 2);
		world.setBlock(i + 9, j + 3, k + 4, NovaCraftBlocks.sculk_block, 0, 2);
		world.setBlock(i + 10, j + 3, k + 4, deepslate, 0, 2);
		world.setBlock(i + 11, j + 3, k + 4, NovaCraftBlocks.sculk_block, 0, 2);
		world.setBlock(i + 12, j + 3, k + 4, NovaCraftBlocks.sculk_block, 0, 2);
		world.setBlock(i + 13, j + 3, k + 4, deepslate, 0, 2);
		world.setBlock(i + 14, j + 3, k + 4, deepslate, 0, 2);
		world.setBlock(i + 15, j + 3, k + 4, NovaCraftBlocks.sculk_block, 0, 2);
		world.setBlock(i + 16, j + 3, k + 4, NovaCraftBlocks.sculk_block, 0, 2);
		world.setBlock(i + 17, j + 3, k + 4, NovaCraftBlocks.sculk_block, 0, 2);
		world.setBlock(i + 18, j + 3, k + 4, deepslate, 0, 2);
		world.setBlock(i + 19, j + 3, k + 4, polished_deepslate, 0, 2);
		world.setBlock(i + 20, j + 3, k + 4, Blocks.air, 0, 2);
		world.setBlock(i + 0, j + 3, k + 5, Blocks.air, 0, 2);
		world.setBlock(i + 1, j + 3, k + 5, NovaCraftBlocks.sculk_block, 0, 2);
		world.setBlock(i + 2, j + 3, k + 5, NovaCraftBlocks.sculk_vein, 1, 2);
		world.setBlock(i + 3, j + 3, k + 5, NovaCraftBlocks.sculk_block, 0, 2);
		world.setBlock(i + 4, j + 3, k + 5, deepslate, 0, 2);
		world.setBlock(i + 5, j + 3, k + 5, NovaCraftBlocks.sculk_block, 0, 2);
		world.setBlock(i + 6, j + 3, k + 5, Blocks.air, 0, 2);
		world.setBlock(i + 7, j + 3, k + 5, NovaCraftBlocks.sculk_block, 0, 2);
		world.setBlock(i + 8, j + 3, k + 5, NovaCraftBlocks.sculk_block, 0, 2);
		world.setBlock(i + 9, j + 3, k + 5, NovaCraftBlocks.sculk_block, 0, 2);
		world.setBlock(i + 10, j + 3, k + 5, NovaCraftBlocks.sculk_block, 0, 2);
		world.setBlock(i + 11, j + 3, k + 5, NovaCraftBlocks.sculk_block, 0, 2);
		world.setBlock(i + 12, j + 3, k + 5, NovaCraftBlocks.sculk_block, 0, 2);
		world.setBlock(i + 13, j + 3, k + 5, NovaCraftBlocks.sculk_block, 0, 2);
		world.setBlock(i + 14, j + 3, k + 5, NovaCraftBlocks.sculk_block, 0, 2);
		world.setBlock(i + 15, j + 3, k + 5, NovaCraftBlocks.sculk_block, 0, 2);
		world.setBlock(i + 16, j + 3, k + 5, NovaCraftBlocks.sculk_block, 0, 2);
		world.setBlock(i + 17, j + 3, k + 5, deepslate, 0, 2);
		world.setBlock(i + 18, j + 3, k + 5, deepslate, 0, 2);
		world.setBlock(i + 19, j + 3, k + 5, polished_deepslate, 0, 2);
		world.setBlock(i + 20, j + 3, k + 5, Blocks.air, 0, 2);
		world.setBlock(i + 0, j + 3, k + 6, Blocks.air, 0, 2);
		world.setBlock(i + 1, j + 3, k + 6, NovaCraftBlocks.sculk_vein, 1, 2);
		world.setBlock(i + 2, j + 3, k + 6, Blocks.air, 0, 2);
		world.setBlock(i + 3, j + 3, k + 6, NovaCraftBlocks.sculk_vein, 1, 2);
		world.setBlock(i + 4, j + 3, k + 6, deepslate_brick_stairs, 0, 2);
		world.setBlock(i + 5, j + 3, k + 6, deepslate, 0, 2);
		world.setBlock(i + 6, j + 3, k + 6, NovaCraftBlocks.sculk_block, 0, 2);
		world.setBlock(i + 7, j + 3, k + 6, NovaCraftBlocks.sculk_block, 0, 2);
		world.setBlock(i + 8, j + 3, k + 6, cobbled_deepslate, 0, 2);
		world.setBlock(i + 9, j + 3, k + 6, NovaCraftBlocks.sculk_block, 0, 2);
		world.setBlock(i + 10, j + 3, k + 6, NovaCraftBlocks.sculk_block, 0, 2);
		world.setBlock(i + 11, j + 3, k + 6, NovaCraftBlocks.sculk_block, 0, 2);
		world.setBlock(i + 12, j + 3, k + 6, NovaCraftBlocks.sculk_block, 0, 2);
		world.setBlock(i + 13, j + 3, k + 6, NovaCraftBlocks.sculk_block, 0, 2);
		world.setBlock(i + 14, j + 3, k + 6, cobbled_deepslate_stairs, 1, 2);
		world.setBlock(i + 15, j + 3, k + 6, Blocks.air, 0, 2);
		world.setBlock(i + 16, j + 3, k + 6, Blocks.air, 0, 2);
		world.setBlock(i + 17, j + 3, k + 6, NovaCraftBlocks.sculk_vein, 3, 2);
		world.setBlock(i + 18, j + 3, k + 6, cobbled_deepslate_stairs, 4, 2);
		world.setBlock(i + 19, j + 3, k + 6, polished_deepslate, 0, 2);
		world.setBlock(i + 20, j + 3, k + 6, Blocks.air, 0, 2);
		world.setBlock(i + 0, j + 3, k + 7, Blocks.air, 0, 2);
		world.setBlock(i + 1, j + 3, k + 7, deepslate, 0, 2);
		world.setBlock(i + 2, j + 3, k + 7, Blocks.air, 0, 2);
		world.setBlock(i + 3, j + 3, k + 7, Blocks.air, 0, 2);
		world.setBlock(i + 4, j + 3, k + 7, deepslate_brick_stairs, 0, 2);
		world.setBlock(i + 5, j + 3, k + 7, NovaCraftBlocks.sculk_block, 0, 2);
		world.setBlock(i + 6, j + 3, k + 7, NovaCraftBlocks.sculk_block, 0, 2);
		world.setBlock(i + 7, j + 3, k + 7, NovaCraftBlocks.sculk_block, 0, 2);
		world.setBlock(i + 8, j + 3, k + 7, NovaCraftBlocks.sculk_block, 0, 2);
		world.setBlock(i + 9, j + 3, k + 7, NovaCraftBlocks.sculk_block, 0, 2);
		world.setBlock(i + 10, j + 3, k + 7, NovaCraftBlocks.sculk_block, 0, 2);
		world.setBlock(i + 11, j + 3, k + 7, NovaCraftBlocks.sculk_block, 0, 2);
		world.setBlock(i + 12, j + 3, k + 7, NovaCraftBlocks.sculk_block, 0, 2);
		world.setBlock(i + 13, j + 3, k + 7, NovaCraftBlocks.sculk_block, 0, 2);
		world.setBlock(i + 14, j + 3, k + 7, cobbled_deepslate_stairs, 1, 2);
		world.setBlock(i + 15, j + 3, k + 7, NovaCraftBlocks.sculk_vein, 2, 2);
		world.setBlock(i + 16, j + 3, k + 7, NovaCraftBlocks.sculk_vein, 2, 2);
		world.setBlock(i + 17, j + 3, k + 7, Blocks.air, 0, 2);
		world.setBlock(i + 18, j + 3, k + 7, cobbled_deepslate_stairs, 4, 2);
		world.setBlock(i + 19, j + 3, k + 7, polished_deepslate, 0, 2);
		world.setBlock(i + 20, j + 3, k + 7, Blocks.air, 0, 2);
		world.setBlock(i + 0, j + 3, k + 8, Blocks.air, 0, 2);
		world.setBlock(i + 1, j + 3, k + 8, deepslate, 0, 2);
		world.setBlock(i + 2, j + 3, k + 8, NovaCraftBlocks.sculk_vein, 1, 2);
		world.setBlock(i + 3, j + 3, k + 8, NovaCraftBlocks.sculk_vein, 1, 2);
		world.setBlock(i + 4, j + 3, k + 8, NovaCraftBlocks.sculk_block, 0, 2);
		world.setBlock(i + 5, j + 3, k + 8, deepslate, 0, 2);
		world.setBlock(i + 6, j + 3, k + 8, NovaCraftBlocks.sculk_block, 0, 2);
		world.setBlock(i + 7, j + 3, k + 8, NovaCraftBlocks.sculk_block, 0, 2);
		world.setBlock(i + 8, j + 3, k + 8, NovaCraftBlocks.sculk_block, 0, 2);
		world.setBlock(i + 9, j + 3, k + 8, NovaCraftBlocks.sculk_block, 0, 2);
		world.setBlock(i + 10, j + 3, k + 8, NovaCraftBlocks.sculk_block, 0, 2);
		world.setBlock(i + 11, j + 3, k + 8, NovaCraftBlocks.sculk_block, 0, 2);
		world.setBlock(i + 12, j + 3, k + 8, NovaCraftBlocks.sculk_block, 0, 2);
		world.setBlock(i + 13, j + 3, k + 8, NovaCraftBlocks.sculk_block, 0, 2);
		world.setBlock(i + 14, j + 3, k + 8, deepslate, 0, 2);
		world.setBlock(i + 15, j + 3, k + 8, deepslate, 0, 2);
		world.setBlock(i + 16, j + 3, k + 8, deepslate, 0, 2);
		world.setBlock(i + 17, j + 3, k + 8, deepslate, 0, 2);
		world.setBlock(i + 18, j + 3, k + 8, deepslate, 0, 2);
		world.setBlock(i + 19, j + 3, k + 8, polished_deepslate, 0, 2);
		world.setBlock(i + 20, j + 3, k + 8, Blocks.air, 0, 2);
		world.setBlock(i + 0, j + 3, k + 9, Blocks.air, 0, 2);
		world.setBlock(i + 1, j + 3, k + 9, Blocks.air, 0, 2);
		world.setBlock(i + 2, j + 3, k + 9, Blocks.air, 0, 2);
		world.setBlock(i + 3, j + 3, k + 9, Blocks.air, 0, 2);
		world.setBlock(i + 4, j + 3, k + 9, deepslate_brick_stairs, 0, 2);
		world.setBlock(i + 5, j + 3, k + 9, deepslate, 0, 2);
		world.setBlock(i + 6, j + 3, k + 9, deepslate, 0, 2);
		world.setBlock(i + 7, j + 3, k + 9, NovaCraftBlocks.sculk_block, 0, 2);
		world.setBlock(i + 8, j + 3, k + 9, Blocks.air, 0, 2);
		world.setBlock(i + 9, j + 3, k + 9, NovaCraftBlocks.sculk_block, 0, 2);
		world.setBlock(i + 10, j + 3, k + 9, deepslate, 0, 2);
		world.setBlock(i + 11, j + 3, k + 9, deepslate, 0, 2);
		world.setBlock(i + 12, j + 3, k + 9, deepslate, 0, 2);
		world.setBlock(i + 13, j + 3, k + 9, deepslate, 0, 2);
		world.setBlock(i + 14, j + 3, k + 9, deepslate, 0, 2);
		world.setBlock(i + 15, j + 3, k + 9, deepslate, 0, 2);
		world.setBlock(i + 16, j + 3, k + 9, deepslate, 0, 2);
		world.setBlock(i + 17, j + 3, k + 9, deepslate, 0, 2);
		world.setBlock(i + 18, j + 3, k + 9, deepslate, 0, 2);
		world.setBlock(i + 19, j + 3, k + 9, polished_deepslate, 0, 2);
		world.setBlock(i + 20, j + 3, k + 9, Blocks.air, 0, 2);
		world.setBlock(i + 0, j + 3, k + 10, Blocks.air, 0, 2);
		world.setBlock(i + 1, j + 3, k + 10, deepslate, 0, 2);
		world.setBlock(i + 2, j + 3, k + 10, Blocks.air, 0, 2);
		world.setBlock(i + 3, j + 3, k + 10, deepslate, 0, 2);
		world.setBlock(i + 4, j + 3, k + 10, deepslate, 0, 2);
		world.setBlock(i + 5, j + 3, k + 10, deepslate, 0, 2);
		world.setBlock(i + 6, j + 3, k + 10, deepslate, 0, 2);
		world.setBlock(i + 7, j + 3, k + 10, NovaCraftBlocks.sculk_block, 0, 2);
		world.setBlock(i + 8, j + 3, k + 10, NovaCraftBlocks.sculk_block, 0, 2);
		world.setBlock(i + 9, j + 3, k + 10, NovaCraftBlocks.sculk_block, 0, 2);
		world.setBlock(i + 10, j + 3, k + 10, deepslate, 0, 2);
		world.setBlock(i + 11, j + 3, k + 10, deepslate, 0, 2);
		world.setBlock(i + 12, j + 3, k + 10, deepslate, 0, 2);
		world.setBlock(i + 13, j + 3, k + 10, deepslate, 0, 2);
		world.setBlock(i + 14, j + 3, k + 10, deepslate, 0, 2);
		world.setBlock(i + 15, j + 3, k + 10, deepslate, 0, 2);
		world.setBlock(i + 16, j + 3, k + 10, deepslate, 0, 2);
		world.setBlock(i + 17, j + 3, k + 10, deepslate, 0, 2);
		world.setBlock(i + 18, j + 3, k + 10, deepslate, 0, 2);
		world.setBlock(i + 19, j + 3, k + 10, polished_deepslate, 0, 2);
		world.setBlock(i + 20, j + 3, k + 10, Blocks.air, 0, 2);
		world.setBlock(i + 0, j + 3, k + 11, Blocks.air, 0, 2);
		world.setBlock(i + 1, j + 3, k + 11, deepslate, 0, 2);
		world.setBlock(i + 2, j + 3, k + 11, Blocks.air, 0, 2);
		world.setBlock(i + 3, j + 3, k + 11, Blocks.air, 0, 2);
		world.setBlock(i + 4, j + 3, k + 11, deepslate_brick_stairs, 0, 2);
		world.setBlock(i + 5, j + 3, k + 11, deepslate, 0, 2);
		world.setBlock(i + 6, j + 3, k + 11, NovaCraftBlocks.sculk_block, 0, 2);
		world.setBlock(i + 7, j + 3, k + 11, NovaCraftBlocks.sculk_block, 0, 2);
		world.setBlock(i + 8, j + 3, k + 11, NovaCraftBlocks.sculk_block, 0, 2);
		world.setBlock(i + 9, j + 3, k + 11, NovaCraftBlocks.sculk_block, 0, 2);
		world.setBlock(i + 10, j + 3, k + 11, deepslate, 0, 2);
		world.setBlock(i + 11, j + 3, k + 11, deepslate, 0, 2);
		world.setBlock(i + 12, j + 3, k + 11, deepslate, 0, 2);
		world.setBlock(i + 13, j + 3, k + 11, deepslate, 0, 2);
		world.setBlock(i + 14, j + 3, k + 11, deepslate, 0, 2);
		world.setBlock(i + 15, j + 3, k + 11, deepslate, 0, 2);
		world.setBlock(i + 16, j + 3, k + 11, deepslate, 0, 2);
		world.setBlock(i + 17, j + 3, k + 11, deepslate, 0, 2);
		world.setBlock(i + 18, j + 3, k + 11, deepslate, 0, 2);
		world.setBlock(i + 19, j + 3, k + 11, polished_deepslate, 0, 2);
		world.setBlock(i + 20, j + 3, k + 11, Blocks.air, 0, 2);
		world.setBlock(i + 0, j + 3, k + 12, Blocks.air, 0, 2);
		world.setBlock(i + 1, j + 3, k + 12, deepslate, 0, 2);
		world.setBlock(i + 2, j + 3, k + 12, Blocks.air, 0, 2);
		world.setBlock(i + 3, j + 3, k + 12, Blocks.air, 0, 2);
		world.setBlock(i + 4, j + 3, k + 12, deepslate_brick_stairs, 0, 2);
		world.setBlock(i + 5, j + 3, k + 12, deepslate, 0, 2);
		world.setBlock(i + 6, j + 3, k + 12, deepslate, 0, 2);
		world.setBlock(i + 7, j + 3, k + 12, NovaCraftBlocks.sculk_block, 0, 2);
		world.setBlock(i + 8, j + 3, k + 12, NovaCraftBlocks.sculk_block, 0, 2);
		world.setBlock(i + 9, j + 3, k + 12, NovaCraftBlocks.sculk_block, 0, 2);
		world.setBlock(i + 10, j + 3, k + 12, deepslate, 0, 2);
		world.setBlock(i + 11, j + 3, k + 12, deepslate, 0, 2);
		world.setBlock(i + 12, j + 3, k + 12, deepslate, 0, 2);
		world.setBlock(i + 13, j + 3, k + 12, deepslate, 0, 2);
		world.setBlock(i + 14, j + 3, k + 12, deepslate, 0, 2);
		world.setBlock(i + 15, j + 3, k + 12, deepslate, 0, 2);
		world.setBlock(i + 16, j + 3, k + 12, deepslate, 0, 2);
		world.setBlock(i + 17, j + 3, k + 12, deepslate, 0, 2);
		world.setBlock(i + 18, j + 3, k + 12, deepslate, 0, 2);
		world.setBlock(i + 19, j + 3, k + 12, polished_deepslate, 0, 2);
		world.setBlock(i + 20, j + 3, k + 12, Blocks.air, 0, 2);
		world.setBlock(i + 0, j + 3, k + 13, Blocks.air, 0, 2);
		world.setBlock(i + 1, j + 3, k + 13, deepslate, 0, 2);
		world.setBlock(i + 2, j + 3, k + 13, Blocks.air, 0, 2);
		world.setBlock(i + 3, j + 3, k + 13, deepslate, 0, 2);
		world.setBlock(i + 4, j + 3, k + 13, deepslate, 0, 2);
		world.setBlock(i + 5, j + 3, k + 13, deepslate, 0, 2);
		world.setBlock(i + 6, j + 3, k + 13, deepslate, 0, 2);
		world.setBlock(i + 7, j + 3, k + 13, NovaCraftBlocks.sculk_block, 0, 2);
		world.setBlock(i + 8, j + 3, k + 13, NovaCraftBlocks.sculk_block, 0, 2);
		world.setBlock(i + 9, j + 3, k + 13, NovaCraftBlocks.sculk_block, 0, 2);
		world.setBlock(i + 10, j + 3, k + 13, deepslate, 0, 2);
		world.setBlock(i + 11, j + 3, k + 13, cobbled_deepslate, 0, 2);
		world.setBlock(i + 12, j + 3, k + 13, deepslate, 0, 2);
		world.setBlock(i + 13, j + 3, k + 13, deepslate, 0, 2);
		world.setBlock(i + 14, j + 3, k + 13, deepslate, 0, 2);
		world.setBlock(i + 15, j + 3, k + 13, deepslate, 0, 2);
		world.setBlock(i + 16, j + 3, k + 13, deepslate, 0, 2);
		world.setBlock(i + 17, j + 3, k + 13, deepslate, 0, 2);
		world.setBlock(i + 18, j + 3, k + 13, deepslate, 0, 2);
		world.setBlock(i + 19, j + 3, k + 13, polished_deepslate, 0, 2);
		world.setBlock(i + 20, j + 3, k + 13, Blocks.air, 0, 2);
		world.setBlock(i + 0, j + 3, k + 14, Blocks.air, 0, 2);
		world.setBlock(i + 1, j + 3, k + 14, deepslate, 0, 2);
		world.setBlock(i + 2, j + 3, k + 14, Blocks.air, 0, 2);
		world.setBlock(i + 3, j + 3, k + 14, Blocks.air, 0, 2);
		world.setBlock(i + 4, j + 3, k + 14, deepslate_brick_stairs, 0, 2);
		world.setBlock(i + 5, j + 3, k + 14, deepslate, 0, 2);
		world.setBlock(i + 6, j + 3, k + 14, NovaCraftBlocks.sculk_block, 0, 2);
		world.setBlock(i + 7, j + 3, k + 14, NovaCraftBlocks.sculk_block, 0, 2);
		world.setBlock(i + 8, j + 3, k + 14, NovaCraftBlocks.sculk_block, 0, 2);
		world.setBlock(i + 9, j + 3, k + 14, NovaCraftBlocks.sculk_block, 0, 2);
		world.setBlock(i + 10, j + 3, k + 14, deepslate, 0, 2);
		world.setBlock(i + 11, j + 3, k + 14, Blocks.air, 0, 2);
		world.setBlock(i + 12, j + 3, k + 14, deepslate, 0, 2);
		world.setBlock(i + 13, j + 3, k + 14, cobbled_deepslate, 0, 2);
		world.setBlock(i + 14, j + 3, k + 14, deepslate, 0, 2);
		world.setBlock(i + 15, j + 3, k + 14, cobbled_deepslate, 0, 2);
		world.setBlock(i + 16, j + 3, k + 14, deepslate, 0, 2);
		world.setBlock(i + 17, j + 3, k + 14, deepslate, 0, 2);
		world.setBlock(i + 18, j + 3, k + 14, deepslate, 0, 2);
		world.setBlock(i + 19, j + 3, k + 14, polished_deepslate, 0, 2);
		world.setBlock(i + 20, j + 3, k + 14, Blocks.air, 0, 2);
		world.setBlock(i + 0, j + 3, k + 15, Blocks.air, 0, 2);
		world.setBlock(i + 1, j + 3, k + 15, deepslate, 0, 2);
		world.setBlock(i + 2, j + 3, k + 15, Blocks.air, 0, 2);
		world.setBlock(i + 3, j + 3, k + 15, Blocks.air, 0, 2);
		world.setBlock(i + 4, j + 3, k + 15, deepslate_brick_stairs, 0, 2);
		world.setBlock(i + 5, j + 3, k + 15, deepslate, 0, 2);
		world.setBlock(i + 6, j + 3, k + 15, NovaCraftBlocks.sculk_vein, 1, 2);
		world.setBlock(i + 7, j + 3, k + 15, NovaCraftBlocks.sculk_block, 0, 2);
		world.setBlock(i + 8, j + 3, k + 15, cobbled_deepslate, 0, 2);
		world.setBlock(i + 9, j + 3, k + 15, NovaCraftBlocks.sculk_block, 0, 2);
		world.setBlock(i + 10, j + 3, k + 15, cobbled_deepslate, 0, 2);
		world.setBlock(i + 11, j + 3, k + 15, Blocks.air, 0, 2);
		world.setBlock(i + 12, j + 3, k + 15, Blocks.air, 0, 2);
		world.setBlock(i + 13, j + 3, k + 15, cobbled_deepslate, 0, 2);
		world.setBlock(i + 14, j + 3, k + 15, deepslate, 0, 2);
		world.setBlock(i + 15, j + 3, k + 15, deepslate, 0, 2);
		world.setBlock(i + 16, j + 3, k + 15, deepslate, 0, 2);
		world.setBlock(i + 17, j + 3, k + 15, deepslate, 0, 2);
		world.setBlock(i + 18, j + 3, k + 15, deepslate, 0, 2);
		world.setBlock(i + 19, j + 3, k + 15, polished_deepslate, 0, 2);
		world.setBlock(i + 20, j + 3, k + 15, Blocks.air, 0, 2);
		world.setBlock(i + 0, j + 3, k + 16, Blocks.air, 0, 2);
		world.setBlock(i + 1, j + 3, k + 16, Blocks.air, 0, 2);
		world.setBlock(i + 2, j + 3, k + 16, Blocks.air, 0, 2);
		world.setBlock(i + 3, j + 3, k + 16, deepslate, 0, 2);
		world.setBlock(i + 4, j + 3, k + 16, deepslate, 0, 2);
		world.setBlock(i + 5, j + 3, k + 16, deepslate, 0, 2);
		world.setBlock(i + 6, j + 3, k + 16, deepslate, 0, 2);
		world.setBlock(i + 7, j + 3, k + 16, NovaCraftBlocks.sculk_block, 0, 2);
		world.setBlock(i + 8, j + 3, k + 16, deepslate, 0, 2);
		world.setBlock(i + 9, j + 3, k + 16, cobbled_deepslate, 0, 2);
		world.setBlock(i + 10, j + 3, k + 16, NovaCraftBlocks.sculk_vein, 5, 2);
		world.setBlock(i + 11, j + 3, k + 16, Blocks.air, 0, 2);
		world.setBlock(i + 12, j + 3, k + 16, Blocks.air, 0, 2);
		world.setBlock(i + 13, j + 3, k + 16, Blocks.air, 0, 2);
		world.setBlock(i + 14, j + 3, k + 16, deepslate, 0, 2);
		world.setBlock(i + 15, j + 3, k + 16, deepslate, 0, 2);
		world.setBlock(i + 16, j + 3, k + 16, deepslate, 0, 2);
		world.setBlock(i + 17, j + 3, k + 16, deepslate, 0, 2);
		world.setBlock(i + 18, j + 3, k + 16, deepslate, 0, 2);
		world.setBlock(i + 19, j + 3, k + 16, polished_deepslate, 0, 2);
		world.setBlock(i + 20, j + 3, k + 16, Blocks.air, 0, 2);
		world.setBlock(i + 0, j + 3, k + 17, Blocks.air, 0, 2);
		world.setBlock(i + 1, j + 3, k + 17, deepslate, 0, 2);
		world.setBlock(i + 2, j + 3, k + 17, Blocks.air, 0, 2);
		world.setBlock(i + 3, j + 3, k + 17, polished_deepslate, 0, 2);
		world.setBlock(i + 4, j + 3, k + 17, polished_deepslate, 0, 2);
		world.setBlock(i + 5, j + 3, k + 17, polished_deepslate, 0, 2);
		world.setBlock(i + 6, j + 3, k + 17, polished_deepslate, 0, 2);
		world.setBlock(i + 7, j + 3, k + 17, polished_deepslate, 0, 2);
		world.setBlock(i + 8, j + 3, k + 17, polished_deepslate, 0, 2);
		world.setBlock(i + 9, j + 3, k + 17, polished_deepslate, 0, 2);
		world.setBlock(i + 10, j + 3, k + 17, Blocks.air, 0, 2);
		world.setBlock(i + 11, j + 3, k + 17, Blocks.air, 0, 2);
		world.setBlock(i + 12, j + 3, k + 17, Blocks.air, 0, 2);
		world.setBlock(i + 13, j + 3, k + 17, Blocks.air, 0, 2);
		world.setBlock(i + 14, j + 3, k + 17, cobbled_deepslate, 0, 2);
		world.setBlock(i + 15, j + 3, k + 17, polished_deepslate, 0, 2);
		world.setBlock(i + 16, j + 3, k + 17, polished_deepslate, 0, 2);
		world.setBlock(i + 17, j + 3, k + 17, polished_deepslate, 0, 2);
		world.setBlock(i + 18, j + 3, k + 17, polished_deepslate, 0, 2);
		world.setBlock(i + 19, j + 3, k + 17, polished_deepslate, 0, 2);
		world.setBlock(i + 20, j + 3, k + 17, Blocks.air, 0, 2);
		world.setBlock(i + 0, j + 3, k + 18, Blocks.air, 0, 2);
		world.setBlock(i + 1, j + 3, k + 18, Blocks.air, 0, 2);
		world.setBlock(i + 2, j + 3, k + 18, Blocks.air, 0, 2);
		world.setBlock(i + 3, j + 3, k + 18, Blocks.air, 0, 2);
		world.setBlock(i + 4, j + 3, k + 18, NovaCraftBlocks.sculk_vein, 3, 2);
		world.setBlock(i + 5, j + 3, k + 18, Blocks.air, 0, 2);
		world.setBlock(i + 6, j + 3, k + 18, NovaCraftBlocks.sculk_vein, 3, 2);
		world.setBlock(i + 7, j + 3, k + 18, NovaCraftBlocks.sculk_vein, 3, 2);
		world.setBlock(i + 8, j + 3, k + 18, NovaCraftBlocks.sculk_vein, 3, 2);
		world.setBlock(i + 9, j + 3, k + 18, Blocks.air, 0, 2);
		world.setBlock(i + 10, j + 3, k + 18, Blocks.air, 0, 2);
		world.setBlock(i + 11, j + 3, k + 18, Blocks.air, 0, 2);
		world.setBlock(i + 12, j + 3, k + 18, Blocks.air, 0, 2);
		world.setBlock(i + 13, j + 3, k + 18, Blocks.air, 0, 2);
		world.setBlock(i + 14, j + 3, k + 18, Blocks.air, 0, 2);
		world.setBlock(i + 15, j + 3, k + 18, Blocks.air, 0, 2);
		world.setBlock(i + 16, j + 3, k + 18, Blocks.air, 0, 2);
		world.setBlock(i + 17, j + 3, k + 18, Blocks.air, 0, 2);
		world.setBlock(i + 18, j + 3, k + 18, Blocks.air, 0, 2);
		world.setBlock(i + 19, j + 3, k + 18, Blocks.air, 0, 2);
		world.setBlock(i + 20, j + 3, k + 18, Blocks.air, 0, 2);
		world.setBlock(i + 0, j + 4, k + 0, Blocks.air, 0, 2);
		world.setBlock(i + 1, j + 4, k + 0, Blocks.air, 0, 2);
		world.setBlock(i + 2, j + 4, k + 0, NovaCraftBlocks.sculk_vein, 2, 2);
		world.setBlock(i + 3, j + 4, k + 0, Blocks.air, 0, 2);
		world.setBlock(i + 4, j + 4, k + 0, NovaCraftBlocks.sculk_vein, 2, 2);
		world.setBlock(i + 5, j + 4, k + 0, Blocks.air, 0, 2);
		world.setBlock(i + 6, j + 4, k + 0, NovaCraftBlocks.sculk_vein, 2, 2);
		world.setBlock(i + 7, j + 4, k + 0, Blocks.air, 0, 2);
		world.setBlock(i + 8, j + 4, k + 0, NovaCraftBlocks.sculk_vein, 2, 2);
		world.setBlock(i + 9, j + 4, k + 0, Blocks.air, 0, 2);
		world.setBlock(i + 10, j + 4, k + 0, Blocks.air, 0, 2);
		world.setBlock(i + 11, j + 4, k + 0, Blocks.air, 0, 2);
		world.setBlock(i + 12, j + 4, k + 0, Blocks.air, 0, 2);
		world.setBlock(i + 13, j + 4, k + 0, Blocks.air, 0, 2);
		world.setBlock(i + 14, j + 4, k + 0, Blocks.air, 0, 2);
		world.setBlock(i + 15, j + 4, k + 0, Blocks.air, 0, 2);
		world.setBlock(i + 16, j + 4, k + 0, Blocks.air, 0, 2);
