package com.NovaCraft.world.ancient_city;

import net.minecraft.world.gen.feature.*;
import net.minecraft.block.*;
import net.minecraft.world.*;
import java.util.*;

import com.NovaCraft.registry.OtherModBlocks;
import com.NovaCraftBlocks.NovaCraftBlocks;

import cpw.mods.fml.common.Loader;
import net.minecraft.init.*;

public class AncientCityColumnGen2 extends WorldGenerator
{
	public AncientCityColumnGen2() {

	}
	
	private static final Block cobbled_deepslate = OtherModBlocks.cobbled_deepslate;
	private static final Block deepslate = OtherModBlocks.deepslate;
	private static final Block sculk_block = NovaCraftBlocks.sculk_block;
	private static final Block soul_lantern = OtherModBlocks.soul_lantern; //1
	private static final Block soul_sand = Blocks.netherrack;
	
	private static final Block polished_deepslate = OtherModBlocks.polished_deepslate;
	private static final Block deepslate_brick_slab = OtherModBlocks.deepslate_brick_slab;
	private static final Block deepslate_tile_stairs = OtherModBlocks.deepslate_tile_stairs;
	private static final Block deepslate_brick_stairs = OtherModBlocks.deepslate_brick_stairs;
	private static final Block polished_deepslate_stairs = OtherModBlocks.polished_deepslate_stairs;
	private static final Block deepslate_wall = OtherModBlocks.deepslate_wall;
	private static final Block fence_dark_oak = OtherModBlocks.fence_dark_oak;
	private static final Block blue_ice = OtherModBlocks.blue_ice;
	private static final Block iron_trapdoor = OtherModBlocks.iron_trapdoor;
	
	private static final Block deepslate_bricks = OtherModBlocks.deepslate_bricks;
	private static final Block cobbled_deepslate_stairs = OtherModBlocks.cobbled_deepslate_stairs;
	
	private static final Block basalt = OtherModBlocks.Basalt; //netherlicious
	private static final Block basalt1 = OtherModBlocks.basalt; //et futurum requiem

	//0 -> deepslate bricks
	//1 -> cracked deepslate bricks
	//2 -> deepslate tiles
	//3 -> cracked deepslate bricks
	//4 -> chiseled deepslate bricks
    
    public boolean generate(final World world, final Random random, final int i, final int j, final int k) {
    	
    	world.setBlock(i + 20, j + 20, k + 10, deepslate, 0, 2);
		world.setBlock(i + 10, j + 20, k + 11, sculk_block, 0, 2);
		world.setBlock(i + 11, j + 20, k + 11, deepslate, 0, 2);
		world.setBlock(i + 12, j + 20, k + 11, deepslate, 0, 2);
		world.setBlock(i + 13, j + 20, k + 11, deepslate, 0, 2);
		world.setBlock(i + 14, j + 20, k + 11, deepslate, 0, 2);
		world.setBlock(i + 15, j + 20, k + 11, deepslate, 0, 2);
		world.setBlock(i + 16, j + 20, k + 11, deepslate, 0, 2);
		world.setBlock(i + 17, j + 20, k + 11, deepslate, 0, 2);
		world.setBlock(i + 18, j + 20, k + 11, deepslate, 0, 2);
		world.setBlock(i + 19, j + 20, k + 11, deepslate, 0, 2);
		world.setBlock(i + 20, j + 20, k + 11, deepslate, 0, 2);
		world.setBlock(i + 21, j + 20, k + 11, deepslate, 0, 2);
		world.setBlock(i + 10, j + 20, k + 12, sculk_block, 0, 2);
		world.setBlock(i + 11, j + 20, k + 12, deepslate, 0, 2);
		world.setBlock(i + 12, j + 20, k + 12, deepslate, 0, 2);
		world.setBlock(i + 13, j + 20, k + 12, deepslate, 0, 2);
		world.setBlock(i + 14, j + 20, k + 12, deepslate, 0, 2);
		world.setBlock(i + 15, j + 20, k + 12, deepslate, 0, 2);
		world.setBlock(i + 16, j + 20, k + 12, deepslate, 0, 2);
		world.setBlock(i + 17, j + 20, k + 12, deepslate, 0, 2);
		world.setBlock(i + 18, j + 20, k + 12, deepslate, 0, 2);
		world.setBlock(i + 19, j + 20, k + 12, deepslate, 0, 2);
		world.setBlock(i + 20, j + 20, k + 12, deepslate, 0, 2);
		world.setBlock(i + 21, j + 20, k + 12, deepslate, 0, 2);
		world.setBlock(i + 11, j + 20, k + 13, sculk_block, 0, 2);
		world.setBlock(i + 12, j + 20, k + 13, deepslate, 0, 2);
		world.setBlock(i + 13, j + 20, k + 13, deepslate, 0, 2);
		world.setBlock(i + 14, j + 20, k + 13, deepslate, 0, 2);
		world.setBlock(i + 15, j + 20, k + 13, deepslate, 0, 2);
		world.setBlock(i + 16, j + 20, k + 13, deepslate, 0, 2);
		world.setBlock(i + 17, j + 20, k + 13, deepslate, 0, 2);
		world.setBlock(i + 18, j + 20, k + 13, deepslate, 0, 2);
		world.setBlock(i + 19, j + 20, k + 13, deepslate, 0, 2);
		world.setBlock(i + 20, j + 20, k + 13, deepslate, 0, 2);
		world.setBlock(i + 21, j + 20, k + 13, deepslate, 0, 2);
		world.setBlock(i + 11, j + 20, k + 14, sculk_block, 0, 2);
		world.setBlock(i + 12, j + 20, k + 14, deepslate, 0, 2);
		world.setBlock(i + 13, j + 20, k + 14, deepslate, 0, 2);
		world.setBlock(i + 14, j + 20, k + 14, deepslate, 0, 2);
		world.setBlock(i + 15, j + 20, k + 14, deepslate, 0, 2);
		world.setBlock(i + 16, j + 20, k + 14, deepslate, 0, 2);
		world.setBlock(i + 17, j + 20, k + 14, deepslate, 0, 2);
		world.setBlock(i + 18, j + 20, k + 14, deepslate, 0, 2);
		world.setBlock(i + 19, j + 20, k + 14, deepslate, 0, 2);
		world.setBlock(i + 20, j + 20, k + 14, deepslate, 0, 2);
		world.setBlock(i + 21, j + 20, k + 14, deepslate, 0, 2);
		world.setBlock(i + 11, j + 20, k + 15, sculk_block, 0, 2);
		world.setBlock(i + 12, j + 20, k + 15, deepslate, 0, 2);
		world.setBlock(i + 13, j + 20, k + 15, deepslate, 0, 2);
		world.setBlock(i + 14, j + 20, k + 15, deepslate, 0, 2);
		world.setBlock(i + 15, j + 20, k + 15, deepslate, 0, 2);
		world.setBlock(i + 16, j + 20, k + 15, deepslate, 0, 2);
		world.setBlock(i + 17, j + 20, k + 15, deepslate, 0, 2);
		world.setBlock(i + 18, j + 20, k + 15, deepslate, 0, 2);
		world.setBlock(i + 19, j + 20, k + 15, deepslate, 0, 2);
		world.setBlock(i + 20, j + 20, k + 15, deepslate, 0, 2);
		world.setBlock(i + 21, j + 20, k + 15, deepslate, 0, 2);
		world.setBlock(i + 22, j + 20, k + 15, sculk_block, 0, 2);
		world.setBlock(i + 11, j + 20, k + 16, sculk_block, 0, 2);
		world.setBlock(i + 12, j + 20, k + 16, sculk_block, 0, 2);
		world.setBlock(i + 13, j + 20, k + 16, sculk_block, 0, 2);
		world.setBlock(i + 14, j + 20, k + 16, sculk_block, 0, 2);
		world.setBlock(i + 15, j + 20, k + 16, deepslate, 0, 2);
		world.setBlock(i + 16, j + 20, k + 16, deepslate, 0, 2);
		world.setBlock(i + 17, j + 20, k + 16, deepslate, 0, 2);
		world.setBlock(i + 18, j + 20, k + 16, deepslate, 0, 2);
		world.setBlock(i + 19, j + 20, k + 16, deepslate, 0, 2);
		world.setBlock(i + 20, j + 20, k + 16, deepslate, 0, 2);
		world.setBlock(i + 21, j + 20, k + 16, sculk_block, 0, 2);
		world.setBlock(i + 15, j + 20, k + 17, sculk_block, 0, 2);
		world.setBlock(i + 19, j + 20, k + 17, sculk_block, 0, 2);
		world.setBlock(i + 20, j + 20, k + 17, sculk_block, 0, 2);
		world.setBlock(i + 11, j + 21, k + 4, deepslate, 0, 2);
		world.setBlock(i + 12, j + 21, k + 4, deepslate, 0, 2);
		world.setBlock(i + 13, j + 21, k + 4, deepslate, 0, 2);
		world.setBlock(i + 14, j + 21, k + 4, deepslate, 0, 2);
		world.setBlock(i + 15, j + 21, k + 4, deepslate, 0, 2);
		world.setBlock(i + 16, j + 21, k + 4, deepslate, 0, 2);
		world.setBlock(i + 17, j + 21, k + 4, deepslate, 0, 2);
		world.setBlock(i + 11, j + 21, k + 5, deepslate, 0, 2);
		world.setBlock(i + 12, j + 21, k + 5, deepslate, 0, 2);
		world.setBlock(i + 13, j + 21, k + 5, deepslate, 0, 2);
		world.setBlock(i + 14, j + 21, k + 5, deepslate, 0, 2);
		world.setBlock(i + 15, j + 21, k + 5, deepslate, 0, 2);
		world.setBlock(i + 16, j + 21, k + 5, deepslate, 0, 2);
		world.setBlock(i + 17, j + 21, k + 5, deepslate, 0, 2);
		world.setBlock(i + 10, j + 21, k + 6, deepslate, 0, 2);
		world.setBlock(i + 11, j + 21, k + 6, deepslate, 0, 2);
		world.setBlock(i + 12, j + 21, k + 6, deepslate, 0, 2);
		world.setBlock(i + 13, j + 21, k + 6, deepslate, 0, 2);
		world.setBlock(i + 14, j + 21, k + 6, deepslate, 0, 2);
		world.setBlock(i + 15, j + 21, k + 6, deepslate, 0, 2);
		world.setBlock(i + 16, j + 21, k + 6, deepslate, 0, 2);
		world.setBlock(i + 17, j + 21, k + 6, deepslate, 0, 2);
		world.setBlock(i + 18, j + 21, k + 6, deepslate, 0, 2);
		world.setBlock(i + 10, j + 21, k + 7, deepslate, 0, 2);
		world.setBlock(i + 11, j + 21, k + 7, deepslate, 0, 2);
		world.setBlock(i + 12, j + 21, k + 7, deepslate, 0, 2);
		world.setBlock(i + 13, j + 21, k + 7, deepslate, 0, 2);
		world.setBlock(i + 14, j + 21, k + 7, deepslate, 0, 2);
		world.setBlock(i + 15, j + 21, k + 7, deepslate, 0, 2);
		world.setBlock(i + 16, j + 21, k + 7, deepslate, 0, 2);
		world.setBlock(i + 17, j + 21, k + 7, deepslate, 0, 2);
		world.setBlock(i + 18, j + 21, k + 7, deepslate, 0, 2);
		world.setBlock(i + 9, j + 21, k + 8, sculk_block, 0, 2);
		world.setBlock(i + 10, j + 21, k + 8, deepslate, 0, 2);
		world.setBlock(i + 11, j + 21, k + 8, deepslate, 0, 2);
		world.setBlock(i + 12, j + 21, k + 8, deepslate, 0, 2);
		world.setBlock(i + 13, j + 21, k + 8, deepslate, 0, 2);
		world.setBlock(i + 14, j + 21, k + 8, deepslate, 0, 2);
		world.setBlock(i + 15, j + 21, k + 8, deepslate, 0, 2);
		world.setBlock(i + 16, j + 21, k + 8, deepslate, 0, 2);
		world.setBlock(i + 17, j + 21, k + 8, deepslate, 0, 2);
		world.setBlock(i + 18, j + 21, k + 8, deepslate, 0, 2);
		world.setBlock(i + 19, j + 21, k + 8, deepslate, 0, 2);
		world.setBlock(i + 10, j + 21, k + 9, sculk_block, 0, 2);
		world.setBlock(i + 11, j + 21, k + 9, deepslate, 0, 2);
		world.setBlock(i + 12, j + 21, k + 9, deepslate, 0, 2);
		world.setBlock(i + 13, j + 21, k + 9, deepslate, 0, 2);
		world.setBlock(i + 14, j + 21, k + 9, deepslate, 0, 2);
		world.setBlock(i + 15, j + 21, k + 9, deepslate, 0, 2);
		world.setBlock(i + 16, j + 21, k + 9, deepslate, 0, 2);
		world.setBlock(i + 17, j + 21, k + 9, deepslate, 0, 2);
		world.setBlock(i + 18, j + 21, k + 9, deepslate, 0, 2);
		world.setBlock(i + 19, j + 21, k + 9, deepslate, 0, 2);
		world.setBlock(i + 20, j + 21, k + 9, deepslate, 0, 2);
		world.setBlock(i + 10, j + 21, k + 10, sculk_block, 0, 2);
		world.setBlock(i + 11, j + 21, k + 10, deepslate, 0, 2);
		world.setBlock(i + 12, j + 21, k + 10, deepslate, 0, 2);
		world.setBlock(i + 13, j + 21, k + 10, deepslate, 0, 2);
		world.setBlock(i + 14, j + 21, k + 10, deepslate, 0, 2);
		world.setBlock(i + 15, j + 21, k + 10, deepslate, 0, 2);
		world.setBlock(i + 16, j + 21, k + 10, deepslate, 0, 2);
		world.setBlock(i + 17, j + 21, k + 10, deepslate, 0, 2);
		world.setBlock(i + 18, j + 21, k + 10, deepslate, 0, 2);
		world.setBlock(i + 19, j + 21, k + 10, deepslate, 0, 2);
		world.setBlock(i + 20, j + 21, k + 10, deepslate, 0, 2);
		world.setBlock(i + 10, j + 21, k + 11, sculk_block, 0, 2);
		world.setBlock(i + 11, j + 21, k + 11, deepslate, 0, 2);
		world.setBlock(i + 12, j + 21, k + 11, deepslate, 0, 2);
		world.setBlock(i + 13, j + 21, k + 11, deepslate, 0, 2);
		world.setBlock(i + 14, j + 21, k + 11, deepslate, 0, 2);
		world.setBlock(i + 15, j + 21, k + 11, deepslate, 0, 2);
		world.setBlock(i + 16, j + 21, k + 11, deepslate, 0, 2);
		world.setBlock(i + 17, j + 21, k + 11, deepslate, 0, 2);
		world.setBlock(i + 18, j + 21, k + 11, deepslate, 0, 2);
		world.setBlock(i + 19, j + 21, k + 11, deepslate, 0, 2);
		world.setBlock(i + 20, j + 21, k + 11, deepslate, 0, 2);
		world.setBlock(i + 21, j + 21, k + 11, deepslate, 0, 2);
		world.setBlock(i + 10, j + 21, k + 12, sculk_block, 0, 2);
		world.setBlock(i + 11, j + 21, k + 12, deepslate, 0, 2);
		world.setBlock(i + 12, j + 21, k + 12, deepslate, 0, 2);
		world.setBlock(i + 13, j + 21, k + 12, deepslate, 0, 2);
		world.setBlock(i + 14, j + 21, k + 12, deepslate, 0, 2);
		world.setBlock(i + 15, j + 21, k + 12, deepslate, 0, 2);
		world.setBlock(i + 16, j + 21, k + 12, deepslate, 0, 2);
		world.setBlock(i + 17, j + 21, k + 12, deepslate, 0, 2);
		world.setBlock(i + 18, j + 21, k + 12, deepslate, 0, 2);
		world.setBlock(i + 19, j + 21, k + 12, deepslate, 0, 2);
		world.setBlock(i + 20, j + 21, k + 12, deepslate, 0, 2);
		world.setBlock(i + 21, j + 21, k + 12, deepslate, 0, 2);
		world.setBlock(i + 10, j + 21, k + 13, sculk_block, 0, 2);
		world.setBlock(i + 11, j + 21, k + 13, deepslate, 0, 2);
		world.setBlock(i + 12, j + 21, k + 13, deepslate, 0, 2);
		world.setBlock(i + 13, j + 21, k + 13, deepslate, 0, 2);
		world.setBlock(i + 14, j + 21, k + 13, deepslate, 0, 2);
		world.setBlock(i + 15, j + 21, k + 13, deepslate, 0, 2);
		world.setBlock(i + 16, j + 21, k + 13, deepslate, 0, 2);
		world.setBlock(i + 17, j + 21, k + 13, deepslate, 0, 2);
		world.setBlock(i + 18, j + 21, k + 13, deepslate, 0, 2);
		world.setBlock(i + 19, j + 21, k + 13, deepslate, 0, 2);
		world.setBlock(i + 20, j + 21, k + 13, deepslate, 0, 2);
		world.setBlock(i + 21, j + 21, k + 13, deepslate, 0, 2);
		world.setBlock(i + 10, j + 21, k + 14, sculk_block, 0, 2);
		world.setBlock(i + 11, j + 21, k + 14, deepslate, 0, 2);
		world.setBlock(i + 12, j + 21, k + 14, deepslate, 0, 2);
		world.setBlock(i + 13, j + 21, k + 14, deepslate, 0, 2);
		world.setBlock(i + 14, j + 21, k + 14, deepslate, 0, 2);
		world.setBlock(i + 15, j + 21, k + 14, deepslate, 0, 2);
		world.setBlock(i + 16, j + 21, k + 14, deepslate, 0, 2);
		world.setBlock(i + 17, j + 21, k + 14, deepslate, 0, 2);
		world.setBlock(i + 18, j + 21, k + 14, deepslate, 0, 2);
		world.setBlock(i + 19, j + 21, k + 14, deepslate, 0, 2);
		world.setBlock(i + 20, j + 21, k + 14, deepslate, 0, 2);
		world.setBlock(i + 21, j + 21, k + 14, deepslate, 0, 2);
		world.setBlock(i + 22, j + 21, k + 14, sculk_block, 0, 2);
		world.setBlock(i + 11, j + 21, k + 15, sculk_block, 0, 2);
		world.setBlock(i + 12, j + 21, k + 15, deepslate, 0, 2);
		world.setBlock(i + 13, j + 21, k + 15, deepslate, 0, 2);
		world.setBlock(i + 14, j + 21, k + 15, deepslate, 0, 2);
		world.setBlock(i + 15, j + 21, k + 15, deepslate, 0, 2);
		world.setBlock(i + 16, j + 21, k + 15, deepslate, 0, 2);
		world.setBlock(i + 17, j + 21, k + 15, deepslate, 0, 2);
		world.setBlock(i + 18, j + 21, k + 15, deepslate, 0, 2);
		world.setBlock(i + 19, j + 21, k + 15, deepslate, 0, 2);
		world.setBlock(i + 20, j + 21, k + 15, deepslate, 0, 2);
		world.setBlock(i + 21, j + 21, k + 15, sculk_block, 0, 2);
		world.setBlock(i + 11, j + 21, k + 16, sculk_block, 0, 2);
		world.setBlock(i + 12, j + 21, k + 16, sculk_block, 0, 2);
		world.setBlock(i + 13, j + 21, k + 16, sculk_block, 0, 2);
		world.setBlock(i + 14, j + 21, k + 16, sculk_block, 0, 2);
		world.setBlock(i + 15, j + 21, k + 16, sculk_block, 0, 2);
		world.setBlock(i + 16, j + 21, k + 16, deepslate, 0, 2);
		world.setBlock(i + 17, j + 21, k + 16, deepslate, 0, 2);
		world.setBlock(i + 18, j + 21, k + 16, deepslate, 0, 2);
		world.setBlock(i + 19, j + 21, k + 16, sculk_block, 0, 2);
		world.setBlock(i + 20, j + 21, k + 16, sculk_block, 0, 2);
		world.setBlock(i + 16, j + 21, k + 17, sculk_block, 0, 2);
		world.setBlock(i + 18, j + 21, k + 17, sculk_block, 0, 2);
		world.setBlock(i + 11, j + 22, k + 3, deepslate, 0, 2);
		world.setBlock(i + 12, j + 22, k + 3, deepslate, 0, 2);
		world.setBlock(i + 13, j + 22, k + 3, deepslate, 0, 2);
		world.setBlock(i + 14, j + 22, k + 3, deepslate, 0, 2);
		world.setBlock(i + 15, j + 22, k + 3, deepslate, 0, 2);
		world.setBlock(i + 16, j + 22, k + 3, deepslate, 0, 2);
		world.setBlock(i + 10, j + 22, k + 4, deepslate, 0, 2);
		world.setBlock(i + 11, j + 22, k + 4, deepslate, 0, 2);
		world.setBlock(i + 12, j + 22, k + 4, deepslate, 0, 2);
		world.setBlock(i + 13, j + 22, k + 4, deepslate, 0, 2);
		world.setBlock(i + 14, j + 22, k + 4, deepslate, 0, 2);
		world.setBlock(i + 15, j + 22, k + 4, deepslate, 0, 2);
		world.setBlock(i + 16, j + 22, k + 4, deepslate, 0, 2);
		world.setBlock(i + 17, j + 22, k + 4, deepslate, 0, 2);
		world.setBlock(i + 10, j + 22, k + 5, deepslate, 0, 2);
		world.setBlock(i + 11, j + 22, k + 5, deepslate, 0, 2);
		world.setBlock(i + 12, j + 22, k + 5, deepslate, 0, 2);
		world.setBlock(i + 13, j + 22, k + 5, deepslate, 0, 2);
		world.setBlock(i + 14, j + 22, k + 5, deepslate, 0, 2);
		world.setBlock(i + 15, j + 22, k + 5, deepslate, 0, 2);
		world.setBlock(i + 16, j + 22, k + 5, deepslate, 0, 2);
		world.setBlock(i + 17, j + 22, k + 5, deepslate, 0, 2);
		world.setBlock(i + 10, j + 22, k + 6, deepslate, 0, 2);
		world.setBlock(i + 11, j + 22, k + 6, deepslate, 0, 2);
		world.setBlock(i + 12, j + 22, k + 6, deepslate, 0, 2);
		world.setBlock(i + 13, j + 22, k + 6, deepslate, 0, 2);
		world.setBlock(i + 14, j + 22, k + 6, deepslate, 0, 2);
		world.setBlock(i + 15, j + 22, k + 6, deepslate, 0, 2);
		world.setBlock(i + 16, j + 22, k + 6, deepslate, 0, 2);
		world.setBlock(i + 17, j + 22, k + 6, deepslate, 0, 2);
		world.setBlock(i + 18, j + 22, k + 6, deepslate, 0, 2);
		world.setBlock(i + 10, j + 22, k + 7, deepslate, 0, 2);
		world.setBlock(i + 11, j + 22, k + 7, deepslate, 0, 2);
		world.setBlock(i + 12, j + 22, k + 7, deepslate, 0, 2);
		world.setBlock(i + 13, j + 22, k + 7, deepslate, 0, 2);
		world.setBlock(i + 14, j + 22, k + 7, deepslate, 0, 2);
		world.setBlock(i + 15, j + 22, k + 7, deepslate, 0, 2);
		world.setBlock(i + 16, j + 22, k + 7, deepslate, 0, 2);
		world.setBlock(i + 17, j + 22, k + 7, deepslate, 0, 2);
		world.setBlock(i + 18, j + 22, k + 7, deepslate, 0, 2);
		world.setBlock(i + 9, j + 22, k + 8, sculk_block, 0, 2);
		world.setBlock(i + 10, j + 22, k + 8, deepslate, 0, 2);
		world.setBlock(i + 11, j + 22, k + 8, deepslate, 0, 2);
		world.setBlock(i + 12, j + 22, k + 8, deepslate, 0, 2);
		world.setBlock(i + 13, j + 22, k + 8, deepslate, 0, 2);
		world.setBlock(i + 14, j + 22, k + 8, deepslate, 0, 2);
		world.setBlock(i + 15, j + 22, k + 8, deepslate, 0, 2);
		world.setBlock(i + 16, j + 22, k + 8, deepslate, 0, 2);
		world.setBlock(i + 17, j + 22, k + 8, deepslate, 0, 2);
		world.setBlock(i + 18, j + 22, k + 8, deepslate, 0, 2);
		world.setBlock(i + 19, j + 22, k + 8, deepslate, 0, 2);
		world.setBlock(i + 10, j + 22, k + 9, sculk_block, 0, 2);
		world.setBlock(i + 11, j + 22, k + 9, deepslate, 0, 2);
		world.setBlock(i + 12, j + 22, k + 9, deepslate, 0, 2);
		world.setBlock(i + 13, j + 22, k + 9, deepslate, 0, 2);
		world.setBlock(i + 14, j + 22, k + 9, deepslate, 0, 2);
		world.setBlock(i + 15, j + 22, k + 9, deepslate, 0, 2);
		world.setBlock(i + 16, j + 22, k + 9, deepslate, 0, 2);
		world.setBlock(i + 17, j + 22, k + 9, deepslate, 0, 2);
		world.setBlock(i + 18, j + 22, k + 9, deepslate, 0, 2);
		world.setBlock(i + 19, j + 22, k + 9, deepslate, 0, 2);
		world.setBlock(i + 20, j + 22, k + 9, deepslate, 0, 2);
		world.setBlock(i + 10, j + 22, k + 10, sculk_block, 0, 2);
		world.setBlock(i + 11, j + 22, k + 10, deepslate, 0, 2);
		world.setBlock(i + 12, j + 22, k + 10, deepslate, 0, 2);
		world.setBlock(i + 13, j + 22, k + 10, deepslate, 0, 2);
		world.setBlock(i + 14, j + 22, k + 10, deepslate, 0, 2);
		world.setBlock(i + 15, j + 22, k + 10, deepslate, 0, 2);
		world.setBlock(i + 16, j + 22, k + 10, deepslate, 0, 2);
		world.setBlock(i + 17, j + 22, k + 10, deepslate, 0, 2);
		world.setBlock(i + 18, j + 22, k + 10, deepslate, 0, 2);
		world.setBlock(i + 19, j + 22, k + 10, deepslate, 0, 2);
		world.setBlock(i + 20, j + 22, k + 10, deepslate, 0, 2);
		world.setBlock(i + 10, j + 22, k + 11, sculk_block, 0, 2);
		world.setBlock(i + 11, j + 22, k + 11, deepslate, 0, 2);
		world.setBlock(i + 12, j + 22, k + 11, deepslate, 0, 2);
		world.setBlock(i + 13, j + 22, k + 11, deepslate, 0, 2);
		world.setBlock(i + 14, j + 22, k + 11, deepslate, 0, 2);
		world.setBlock(i + 15, j + 22, k + 11, deepslate, 0, 2);
		world.setBlock(i + 16, j + 22, k + 11, deepslate, 0, 2);
		world.setBlock(i + 17, j + 22, k + 11, deepslate, 0, 2);
		world.setBlock(i + 18, j + 22, k + 11, deepslate, 0, 2);
		world.setBlock(i + 19, j + 22, k + 11, deepslate, 0, 2);
		world.setBlock(i + 20, j + 22, k + 11, deepslate, 0, 2);
		world.setBlock(i + 21, j + 22, k + 11, deepslate, 0, 2);
		world.setBlock(i + 10, j + 22, k + 12, sculk_block, 0, 2);
		world.setBlock(i + 11, j + 22, k + 12, deepslate, 0, 2);
		world.setBlock(i + 12, j + 22, k + 12, deepslate, 0, 2);
		world.setBlock(i + 13, j + 22, k + 12, deepslate, 0, 2);
		world.setBlock(i + 14, j + 22, k + 12, deepslate, 0, 2);
		world.setBlock(i + 15, j + 22, k + 12, deepslate, 0, 2);
		world.setBlock(i + 16, j + 22, k + 12, deepslate, 0, 2);
		world.setBlock(i + 17, j + 22, k + 12, deepslate, 0, 2);
		world.setBlock(i + 18, j + 22, k + 12, deepslate, 0, 2);
		world.setBlock(i + 19, j + 22, k + 12, deepslate, 0, 2);
		world.setBlock(i + 20, j + 22, k + 12, deepslate, 0, 2);
		world.setBlock(i + 21, j + 22, k + 12, deepslate, 0, 2);
		world.setBlock(i + 9, j + 22, k + 13, sculk_block, 0, 2);
		world.setBlock(i + 10, j + 22, k + 13, deepslate, 0, 2);
		world.setBlock(i + 11, j + 22, k + 13, deepslate, 0, 2);
		world.setBlock(i + 12, j + 22, k + 13, deepslate, 0, 2);
		world.setBlock(i + 13, j + 22, k + 13, deepslate, 0, 2);
		world.setBlock(i + 14, j + 22, k + 13, deepslate, 0, 2);
		world.setBlock(i + 15, j + 22, k + 13, deepslate, 0, 2);
		world.setBlock(i + 16, j + 22, k + 13, deepslate, 0, 2);
		world.setBlock(i + 17, j + 22, k + 13, deepslate, 0, 2);
		world.setBlock(i + 18, j + 22, k + 13, deepslate, 0, 2);
		world.setBlock(i + 19, j + 22, k + 13, deepslate, 0, 2);
		world.setBlock(i + 20, j + 22, k + 13, deepslate, 0, 2);
		world.setBlock(i + 21, j + 22, k + 13, deepslate, 0, 2);
		world.setBlock(i + 10, j + 22, k + 14, sculk_block, 0, 2);
		world.setBlock(i + 11, j + 22, k + 14, deepslate, 0, 2);
		world.setBlock(i + 12, j + 22, k + 14, deepslate, 0, 2);
		world.setBlock(i + 13, j + 22, k + 14, deepslate, 0, 2);
		world.setBlock(i + 14, j + 22, k + 14, deepslate, 0, 2);
		world.setBlock(i + 15, j + 22, k + 14, deepslate, 0, 2);
		world.setBlock(i + 16, j + 22, k + 14, deepslate, 0, 2);
		world.setBlock(i + 17, j + 22, k + 14, deepslate, 0, 2);
		world.setBlock(i + 18, j + 22, k + 14, deepslate, 0, 2);
		world.setBlock(i + 19, j + 22, k + 14, deepslate, 0, 2);
		world.setBlock(i + 20, j + 22, k + 14, deepslate, 0, 2);
		world.setBlock(i + 21, j + 22, k + 14, deepslate, 0, 2);
		world.setBlock(i + 22, j + 22, k + 14, sculk_block, 0, 2);
		world.setBlock(i + 10, j + 22, k + 15, sculk_block, 0, 2);
		world.setBlock(i + 11, j + 22, k + 15, deepslate, 0, 2);
		world.setBlock(i + 12, j + 22, k + 15, deepslate, 0, 2);
		world.setBlock(i + 13, j + 22, k + 15, deepslate, 0, 2);
		world.setBlock(i + 14, j + 22, k + 15, deepslate, 0, 2);
		world.setBlock(i + 15, j + 22, k + 15, deepslate, 0, 2);
		world.setBlock(i + 16, j + 22, k + 15, deepslate, 0, 2);
		world.setBlock(i + 17, j + 22, k + 15, deepslate, 0, 2);
		world.setBlock(i + 18, j + 22, k + 15, deepslate, 0, 2);
		world.setBlock(i + 19, j + 22, k + 15, deepslate, 0, 2);
		world.setBlock(i + 20, j + 22, k + 15, deepslate, 0, 2);
		world.setBlock(i + 21, j + 22, k + 15, sculk_block, 0, 2);
		world.setBlock(i + 11, j + 22, k + 16, sculk_block, 0, 2);
		world.setBlock(i + 12, j + 22, k + 16, sculk_block, 0, 2);
		world.setBlock(i + 13, j + 22, k + 16, deepslate, 0, 2);
		world.setBlock(i + 14, j + 22, k + 16, sculk_block, 0, 2);
		world.setBlock(i + 15, j + 22, k + 16, sculk_block, 0, 2);
		world.setBlock(i + 16, j + 22, k + 16, sculk_block, 0, 2);
		world.setBlock(i + 17, j + 22, k + 16, deepslate, 0, 2);
		world.setBlock(i + 18, j + 22, k + 16, sculk_block, 0, 2);
		world.setBlock(i + 19, j + 22, k + 16, sculk_block, 0, 2);
		world.setBlock(i + 20, j + 22, k + 16, sculk_block, 0, 2);
		world.setBlock(i + 13, j + 22, k + 17, sculk_block, 0, 2);
		world.setBlock(i + 17, j + 22, k + 17, sculk_block, 0, 2);
		world.setBlock(i + 12, j + 23, k + 2, deepslate, 0, 2);
		world.setBlock(i + 13, j + 23, k + 2, deepslate, 0, 2);
		world.setBlock(i + 14, j + 23, k + 2, deepslate, 0, 2);
		world.setBlock(i + 10, j + 23, k + 3, deepslate, 0, 2);
		world.setBlock(i + 11, j + 23, k + 3, deepslate, 0, 2);
		world.setBlock(i + 12, j + 23, k + 3, deepslate, 0, 2);
		world.setBlock(i + 13, j + 23, k + 3, deepslate, 0, 2);
		world.setBlock(i + 14, j + 23, k + 3, deepslate, 0, 2);
		world.setBlock(i + 15, j + 23, k + 3, deepslate, 0, 2);
		world.setBlock(i + 16, j + 23, k + 3, deepslate, 0, 2);
		world.setBlock(i + 17, j + 23, k + 3, deepslate, 0, 2);
		world.setBlock(i + 9, j + 23, k + 4, deepslate, 0, 2);
		world.setBlock(i + 10, j + 23, k + 4, deepslate, 0, 2);
		world.setBlock(i + 11, j + 23, k + 4, deepslate, 0, 2);
		world.setBlock(i + 12, j + 23, k + 4, deepslate, 0, 2);
		world.setBlock(i + 13, j + 23, k + 4, deepslate, 0, 2);
		world.setBlock(i + 14, j + 23, k + 4, deepslate, 0, 2);
		world.setBlock(i + 15, j + 23, k + 4, deepslate, 0, 2);
		world.setBlock(i + 16, j + 23, k + 4, deepslate, 0, 2);
		world.setBlock(i + 17, j + 23, k + 4, deepslate, 0, 2);
		world.setBlock(i + 9, j + 23, k + 5, deepslate, 0, 2);
		world.setBlock(i + 10, j + 23, k + 5, deepslate, 0, 2);
		world.setBlock(i + 11, j + 23, k + 5, deepslate, 0, 2);
		world.setBlock(i + 12, j + 23, k + 5, deepslate, 0, 2);
		world.setBlock(i + 13, j + 23, k + 5, deepslate, 0, 2);
		world.setBlock(i + 14, j + 23, k + 5, deepslate, 0, 2);
		world.setBlock(i + 15, j + 23, k + 5, deepslate, 0, 2);
		world.setBlock(i + 16, j + 23, k + 5, deepslate, 0, 2);
		world.setBlock(i + 17, j + 23, k + 5, deepslate, 0, 2);
		world.setBlock(i + 9, j + 23, k + 6, deepslate, 0, 2);
		world.setBlock(i + 10, j + 23, k + 6, deepslate, 0, 2);
		world.setBlock(i + 11, j + 23, k + 6, deepslate, 0, 2);
		world.setBlock(i + 12, j + 23, k + 6, deepslate, 0, 2);
		world.setBlock(i + 13, j + 23, k + 6, deepslate, 0, 2);
		world.setBlock(i + 14, j + 23, k + 6, deepslate, 0, 2);
		world.setBlock(i + 15, j + 23, k + 6, deepslate, 0, 2);
		world.setBlock(i + 16, j + 23, k + 6, deepslate, 0, 2);
		world.setBlock(i + 17, j + 23, k + 6, deepslate, 0, 2);
		world.setBlock(i + 18, j + 23, k + 6, deepslate, 0, 2);
		world.setBlock(i + 9, j + 23, k + 7, deepslate, 0, 2);
		world.setBlock(i + 10, j + 23, k + 7, deepslate, 0, 2);
		world.setBlock(i + 11, j + 23, k + 7, deepslate, 0, 2);
		world.setBlock(i + 12, j + 23, k + 7, deepslate, 0, 2);
		world.setBlock(i + 13, j + 23, k + 7, deepslate, 0, 2);
		world.setBlock(i + 14, j + 23, k + 7, deepslate, 0, 2);
		world.setBlock(i + 15, j + 23, k + 7, deepslate, 0, 2);
		world.setBlock(i + 16, j + 23, k + 7, deepslate, 0, 2);
		world.setBlock(i + 17, j + 23, k + 7, deepslate, 0, 2);
		world.setBlock(i + 18, j + 23, k + 7, deepslate, 0, 2);
		world.setBlock(i + 8, j + 23, k + 8, sculk_block, 0, 2);
		world.setBlock(i + 9, j + 23, k + 8, deepslate, 0, 2);
		world.setBlock(i + 10, j + 23, k + 8, deepslate, 0, 2);
		world.setBlock(i + 11, j + 23, k + 8, deepslate, 0, 2);
		world.setBlock(i + 12, j + 23, k + 8, deepslate, 0, 2);
		world.setBlock(i + 13, j + 23, k + 8, deepslate, 0, 2);
		world.setBlock(i + 14, j + 23, k + 8, deepslate, 0, 2);
		world.setBlock(i + 15, j + 23, k + 8, deepslate, 0, 2);
		world.setBlock(i + 16, j + 23, k + 8, deepslate, 0, 2);
		world.setBlock(i + 17, j + 23, k + 8, deepslate, 0, 2);
		world.setBlock(i + 18, j + 23, k + 8, deepslate, 0, 2);
		world.setBlock(i + 19, j + 23, k + 8, deepslate, 0, 2);
		world.setBlock(i + 8, j + 23, k + 9, sculk_block, 0, 2);
		world.setBlock(i + 9, j + 23, k + 9, sculk_block, 0, 2);
		world.setBlock(i + 10, j + 23, k + 9, deepslate, 0, 2);
		world.setBlock(i + 11, j + 23, k + 9, deepslate, 0, 2);
		world.setBlock(i + 12, j + 23, k + 9, deepslate, 0, 2);
		world.setBlock(i + 13, j + 23, k + 9, deepslate, 0, 2);
		world.setBlock(i + 14, j + 23, k + 9, deepslate, 0, 2);
		world.setBlock(i + 15, j + 23, k + 9, deepslate, 0, 2);
		world.setBlock(i + 16, j + 23, k + 9, deepslate, 0, 2);
		world.setBlock(i + 17, j + 23, k + 9, deepslate, 0, 2);
		world.setBlock(i + 18, j + 23, k + 9, deepslate, 0, 2);
		world.setBlock(i + 19, j + 23, k + 9, deepslate, 0, 2);
		world.setBlock(i + 20, j + 23, k + 9, deepslate, 0, 2);
		world.setBlock(i + 9, j + 23, k + 10, sculk_block, 0, 2);
		world.setBlock(i + 10, j + 23, k + 10, deepslate, 0, 2);
		world.setBlock(i + 11, j + 23, k + 10, deepslate, 0, 2);
		world.setBlock(i + 12, j + 23, k + 10, deepslate, 0, 2);
		world.setBlock(i + 13, j + 23, k + 10, deepslate, 0, 2);
		world.setBlock(i + 14, j + 23, k + 10, deepslate, 0, 2);
		world.setBlock(i + 15, j + 23, k + 10, deepslate, 0, 2);
		world.setBlock(i + 16, j + 23, k + 10, deepslate, 0, 2);
		world.setBlock(i + 17, j + 23, k + 10, deepslate, 0, 2);
		world.setBlock(i + 18, j + 23, k + 10, deepslate, 0, 2);
		world.setBlock(i + 19, j + 23, k + 10, deepslate, 0, 2);
		world.setBlock(i + 20, j + 23, k + 10, deepslate, 0, 2);
		world.setBlock(i + 9, j + 23, k + 11, sculk_block, 0, 2);
		world.setBlock(i + 10, j + 23, k + 11, deepslate, 0, 2);
		world.setBlock(i + 11, j + 23, k + 11, deepslate, 0, 2);
		world.setBlock(i + 12, j + 23, k + 11, deepslate, 0, 2);
		world.setBlock(i + 13, j + 23, k + 11, deepslate, 0, 2);
		world.setBlock(i + 14, j + 23, k + 11, deepslate, 0, 2);
		world.setBlock(i + 15, j + 23, k + 11, deepslate, 0, 2);
		world.setBlock(i + 16, j + 23, k + 11, deepslate, 0, 2);
		world.setBlock(i + 17, j + 23, k + 11, deepslate, 0, 2);
		world.setBlock(i + 18, j + 23, k + 11, deepslate, 0, 2);
		world.setBlock(i + 19, j + 23, k + 11, deepslate, 0, 2);
		world.setBlock(i + 20, j + 23, k + 11, deepslate, 0, 2);
		world.setBlock(i + 21, j + 23, k + 11, deepslate, 0, 2);
		world.setBlock(i + 9, j + 23, k + 12, sculk_block, 0, 2);
		world.setBlock(i + 10, j + 23, k + 12, deepslate, 0, 2);
		world.setBlock(i + 11, j + 23, k + 12, deepslate, 0, 2);
		world.setBlock(i + 12, j + 23, k + 12, deepslate, 0, 2);
		world.setBlock(i + 13, j + 23, k + 12, deepslate, 0, 2);
		world.setBlock(i + 14, j + 23, k + 12, deepslate, 0, 2);
		world.setBlock(i + 15, j + 23, k + 12, deepslate, 0, 2);
		world.setBlock(i + 16, j + 23, k + 12, deepslate, 0, 2);
		world.setBlock(i + 17, j + 23, k + 12, deepslate, 0, 2);
		world.setBlock(i + 18, j + 23, k + 12, deepslate, 0, 2);
		world.setBlock(i + 19, j + 23, k + 12, deepslate, 0, 2);
		world.setBlock(i + 20, j + 23, k + 12, deepslate, 0, 2);
		world.setBlock(i + 21, j + 23, k + 12, deepslate, 0, 2);
		world.setBlock(i + 8, j + 23, k + 13, sculk_block, 0, 2);
		world.setBlock(i + 9, j + 23, k + 13, deepslate, 0, 2);
		world.setBlock(i + 10, j + 23, k + 13, deepslate, 0, 2);
		world.setBlock(i + 11, j + 23, k + 13, deepslate, 0, 2);
		world.setBlock(i + 12, j + 23, k + 13, deepslate, 0, 2);
		world.setBlock(i + 13, j + 23, k + 13, deepslate, 0, 2);
		world.setBlock(i + 14, j + 23, k + 13, deepslate, 0, 2);
		world.setBlock(i + 15, j + 23, k + 13, deepslate, 0, 2);
		world.setBlock(i + 16, j + 23, k + 13, deepslate, 0, 2);
		world.setBlock(i + 17, j + 23, k + 13, deepslate, 0, 2);
		world.setBlock(i + 18, j + 23, k + 13, deepslate, 0, 2);
		world.setBlock(i + 19, j + 23, k + 13, deepslate, 0, 2);
		world.setBlock(i + 20, j + 23, k + 13, deepslate, 0, 2);
		world.setBlock(i + 21, j + 23, k + 13, deepslate, 0, 2);
		world.setBlock(i + 9, j + 23, k + 14, sculk_block, 0, 2);
		world.setBlock(i + 10, j + 23, k + 14, deepslate, 0, 2);
		world.setBlock(i + 11, j + 23, k + 14, deepslate, 0, 2);
		world.setBlock(i + 12, j + 23, k + 14, deepslate, 0, 2);
		world.setBlock(i + 13, j + 23, k + 14, deepslate, 0, 2);
		world.setBlock(i + 14, j + 23, k + 14, deepslate, 0, 2);
		world.setBlock(i + 15, j + 23, k + 14, deepslate, 0, 2);
		world.setBlock(i + 16, j + 23, k + 14, deepslate, 0, 2);
		world.setBlock(i + 17, j + 23, k + 14, deepslate, 0, 2);
		world.setBlock(i + 18, j + 23, k + 14, deepslate, 0, 2);
		world.setBlock(i + 19, j + 23, k + 14, deepslate, 0, 2);
		world.setBlock(i + 20, j + 23, k + 14, deepslate, 0, 2);
		world.setBlock(i + 21, j + 23, k + 14, deepslate, 0, 2);
		world.setBlock(i + 22, j + 23, k + 14, sculk_block, 0, 2);
		world.setBlock(i + 10, j + 23, k + 15, sculk_block, 0, 2);
		world.setBlock(i + 11, j + 23, k + 15, deepslate, 0, 2);
		world.setBlock(i + 12, j + 23, k + 15, deepslate, 0, 2);
		world.setBlock(i + 13, j + 23, k + 15, deepslate, 0, 2);
		world.setBlock(i + 14, j + 23, k + 15, deepslate, 0, 2);
		world.setBlock(i + 15, j + 23, k + 15, deepslate, 0, 2);
		world.setBlock(i + 16, j + 23, k + 15, deepslate, 0, 2);
		world.setBlock(i + 17, j + 23, k + 15, deepslate, 0, 2);
		world.setBlock(i + 18, j + 23, k + 15, deepslate, 0, 2);
		world.setBlock(i + 19, j + 23, k + 15, deepslate, 0, 2);
		world.setBlock(i + 20, j + 23, k + 15, deepslate, 0, 2);
		world.setBlock(i + 21, j + 23, k + 15, sculk_block, 0, 2);
		world.setBlock(i + 10, j + 23, k + 16, sculk_block, 0, 2);
		world.setBlock(i + 11, j + 23, k + 16, sculk_block, 0, 2);
		world.setBlock(i + 12, j + 23, k + 16, sculk_block, 0, 2);
		world.setBlock(i + 13, j + 23, k + 16, sculk_block, 0, 2);
		world.setBlock(i + 14, j + 23, k + 16, deepslate, 0, 2);
		world.setBlock(i + 15, j + 23, k + 16, sculk_block, 0, 2);
		world.setBlock(i + 16, j + 23, k + 16, deepslate, 0, 2);
		world.setBlock(i + 17, j + 23, k + 16, deepslate, 0, 2);
		world.setBlock(i + 18, j + 23, k + 16, deepslate, 0, 2);
		world.setBlock(i + 19, j + 23, k + 16, sculk_block, 0, 2);
		world.setBlock(i + 20, j + 23, k + 16, sculk_block, 0, 2);
		world.setBlock(i + 14, j + 23, k + 17, sculk_block, 0, 2);
		world.setBlock(i + 16, j + 23, k + 17, sculk_block, 0, 2);
		world.setBlock(i + 17, j + 23, k + 17, sculk_block, 0, 2);
		world.setBlock(i + 18, j + 23, k + 17, sculk_block, 0, 2);
		world.setBlock(i + 10, j + 24, k + 1, deepslate, 0, 2);
		world.setBlock(i + 11, j + 24, k + 1, deepslate, 0, 2);
		world.setBlock(i + 12, j + 24, k + 1, deepslate, 0, 2);
		world.setBlock(i + 13, j + 24, k + 1, deepslate, 0, 2);
		world.setBlock(i + 14, j + 24, k + 1, deepslate, 0, 2);
		world.setBlock(i + 8, j + 24, k + 2, deepslate, 0, 2);
		world.setBlock(i + 9, j + 24, k + 2, deepslate, 0, 2);
		world.setBlock(i + 10, j + 24, k + 2, deepslate, 0, 2);
		world.setBlock(i + 11, j + 24, k + 2, deepslate, 0, 2);
		world.setBlock(i + 12, j + 24, k + 2, deepslate, 0, 2);
		world.setBlock(i + 13, j + 24, k + 2, deepslate, 0, 2);
		world.setBlock(i + 14, j + 24, k + 2, deepslate, 0, 2);
		world.setBlock(i + 15, j + 24, k + 2, deepslate, 0, 2);
		world.setBlock(i + 16, j + 24, k + 2, deepslate, 0, 2);
		world.setBlock(i + 7, j + 24, k + 3, deepslate, 0, 2);
		world.setBlock(i + 8, j + 24, k + 3, deepslate, 0, 2);
		world.setBlock(i + 9, j + 24, k + 3, deepslate, 0, 2);
		world.setBlock(i + 10, j + 24, k + 3, deepslate, 0, 2);
		world.setBlock(i + 11, j + 24, k + 3, deepslate, 0, 2);
		world.setBlock(i + 12, j + 24, k + 3, deepslate, 0, 2);
		world.setBlock(i + 13, j + 24, k + 3, deepslate, 0, 2);
		world.setBlock(i + 14, j + 24, k + 3, deepslate, 0, 2);
		world.setBlock(i + 15, j + 24, k + 3, deepslate, 0, 2);
		world.setBlock(i + 16, j + 24, k + 3, deepslate, 0, 2);
		world.setBlock(i + 17, j + 24, k + 3, deepslate, 0, 2);
		world.setBlock(i + 8, j + 24, k + 4, deepslate, 0, 2);
		world.setBlock(i + 9, j + 24, k + 4, deepslate, 0, 2);
		world.setBlock(i + 10, j + 24, k + 4, deepslate, 0, 2);
		world.setBlock(i + 11, j + 24, k + 4, deepslate, 0, 2);
		world.setBlock(i + 12, j + 24, k + 4, deepslate, 0, 2);
		world.setBlock(i + 13, j + 24, k + 4, deepslate, 0, 2);
		world.setBlock(i + 14, j + 24, k + 4, deepslate, 0, 2);
		world.setBlock(i + 15, j + 24, k + 4, deepslate, 0, 2);
		world.setBlock(i + 16, j + 24, k + 4, deepslate, 0, 2);
		world.setBlock(i + 17, j + 24, k + 4, deepslate, 0, 2);
		world.setBlock(i + 8, j + 24, k + 5, deepslate, 0, 2);
		world.setBlock(i + 9, j + 24, k + 5, deepslate, 0, 2);
		world.setBlock(i + 10, j + 24, k + 5, deepslate, 0, 2);
		world.setBlock(i + 11, j + 24, k + 5, deepslate, 0, 2);
		world.setBlock(i + 12, j + 24, k + 5, deepslate, 0, 2);
		world.setBlock(i + 13, j + 24, k + 5, deepslate, 0, 2);
		world.setBlock(i + 14, j + 24, k + 5, deepslate, 0, 2);
		world.setBlock(i + 15, j + 24, k + 5, deepslate, 0, 2);
		world.setBlock(i + 16, j + 24, k + 5, deepslate, 0, 2);
		world.setBlock(i + 17, j + 24, k + 5, deepslate, 0, 2);
		world.setBlock(i + 18, j + 24, k + 5, deepslate, 0, 2);
		world.setBlock(i + 5, j + 24, k + 6, sculk_block, 0, 2);
		world.setBlock(i + 6, j + 24, k + 6, sculk_block, 0, 2);
		world.setBlock(i + 8, j + 24, k + 6, deepslate, 0, 2);
		world.setBlock(i + 9, j + 24, k + 6, deepslate, 0, 2);
		world.setBlock(i + 10, j + 24, k + 6, deepslate, 0, 2);
		world.setBlock(i + 11, j + 24, k + 6, deepslate, 0, 2);
		world.setBlock(i + 12, j + 24, k + 6, deepslate, 0, 2);
		world.setBlock(i + 13, j + 24, k + 6, deepslate, 0, 2);
		world.setBlock(i + 14, j + 24, k + 6, deepslate, 0, 2);
		world.setBlock(i + 15, j + 24, k + 6, deepslate, 0, 2);
		world.setBlock(i + 16, j + 24, k + 6, deepslate, 0, 2);
		world.setBlock(i + 17, j + 24, k + 6, deepslate, 0, 2);
		world.setBlock(i + 18, j + 24, k + 6, deepslate, 0, 2);
		world.setBlock(i + 4, j + 24, k + 7, sculk_block, 0, 2);
		world.setBlock(i + 7, j + 24, k + 7, sculk_block, 0, 2);
		world.setBlock(i + 8, j + 24, k + 7, deepslate, 0, 2);
		world.setBlock(i + 9, j + 24, k + 7, deepslate, 0, 2);
		world.setBlock(i + 10, j + 24, k + 7, deepslate, 0, 2);
		world.setBlock(i + 11, j + 24, k + 7, deepslate, 0, 2);
		world.setBlock(i + 12, j + 24, k + 7, deepslate, 0, 2);
		world.setBlock(i + 13, j + 24, k + 7, deepslate, 0, 2);
		world.setBlock(i + 14, j + 24, k + 7, deepslate, 0, 2);
		world.setBlock(i + 15, j + 24, k + 7, deepslate, 0, 2);
		world.setBlock(i + 16, j + 24, k + 7, deepslate, 0, 2);
		world.setBlock(i + 17, j + 24, k + 7, deepslate, 0, 2);
		world.setBlock(i + 18, j + 24, k + 7, deepslate, 0, 2);
		world.setBlock(i + 2, j + 24, k + 8, sculk_block, 0, 2);
		world.setBlock(i + 3, j + 24, k + 8, sculk_block, 0, 2);
		world.setBlock(i + 4, j + 24, k + 8, sculk_block, 0, 2);
		world.setBlock(i + 7, j + 24, k + 8, sculk_block, 0, 2);
		world.setBlock(i + 8, j + 24, k + 8, deepslate, 0, 2);
		world.setBlock(i + 9, j + 24, k + 8, deepslate, 0, 2);
		world.setBlock(i + 10, j + 24, k + 8, deepslate, 0, 2);
		world.setBlock(i + 11, j + 24, k + 8, deepslate, 0, 2);
		world.setBlock(i + 12, j + 24, k + 8, deepslate, 0, 2);
		world.setBlock(i + 13, j + 24, k + 8, deepslate, 0, 2);
		world.setBlock(i + 14, j + 24, k + 8, deepslate, 0, 2);
		world.setBlock(i + 15, j + 24, k + 8, deepslate, 0, 2);
		world.setBlock(i + 16, j + 24, k + 8, deepslate, 0, 2);
		world.setBlock(i + 17, j + 24, k + 8, deepslate, 0, 2);
		world.setBlock(i + 18, j + 24, k + 8, deepslate, 0, 2);
		world.setBlock(i + 19, j + 24, k + 8, deepslate, 0, 2);
		world.setBlock(i + 7, j + 24, k + 9, sculk_block, 0, 2);
		world.setBlock(i + 8, j + 24, k + 9, deepslate, 0, 2);
		world.setBlock(i + 9, j + 24, k + 9, deepslate, 0, 2);
		world.setBlock(i + 10, j + 24, k + 9, deepslate, 0, 2);
		world.setBlock(i + 11, j + 24, k + 9, deepslate, 0, 2);
		world.setBlock(i + 12, j + 24, k + 9, deepslate, 0, 2);
		world.setBlock(i + 13, j + 24, k + 9, deepslate, 0, 2);
		world.setBlock(i + 14, j + 24, k + 9, deepslate, 0, 2);
		world.setBlock(i + 15, j + 24, k + 9, deepslate, 0, 2);
		world.setBlock(i + 16, j + 24, k + 9, deepslate, 0, 2);
		world.setBlock(i + 17, j + 24, k + 9, deepslate, 0, 2);
		world.setBlock(i + 18, j + 24, k + 9, deepslate, 0, 2);
		world.setBlock(i + 19, j + 24, k + 9, deepslate, 0, 2);
		world.setBlock(i + 20, j + 24, k + 9, deepslate, 0, 2);
		world.setBlock(i + 4, j + 24, k + 10, sculk_block, 0, 2);
		world.setBlock(i + 7, j + 24, k + 10, sculk_block, 0, 2);
		world.setBlock(i + 8, j + 24, k + 10, sculk_block, 0, 2);
		world.setBlock(i + 9, j + 24, k + 10, deepslate, 0, 2);
		world.setBlock(i + 10, j + 24, k + 10, deepslate, 0, 2);
		world.setBlock(i + 11, j + 24, k + 10, deepslate, 0, 2);
		world.setBlock(i + 12, j + 24, k + 10, deepslate, 0, 2);
		world.setBlock(i + 13, j + 24, k + 10, deepslate, 0, 2);
		world.setBlock(i + 14, j + 24, k + 10, deepslate, 0, 2);
		world.setBlock(i + 15, j + 24, k + 10, deepslate, 0, 2);
		world.setBlock(i + 16, j + 24, k + 10, deepslate, 0, 2);
		world.setBlock(i + 17, j + 24, k + 10, deepslate, 0, 2);
		world.setBlock(i + 18, j + 24, k + 10, deepslate, 0, 2);
		world.setBlock(i + 19, j + 24, k + 10, deepslate, 0, 2);
		world.setBlock(i + 20, j + 24, k + 10, deepslate, 0, 2);
		world.setBlock(i + 21, j + 24, k + 10, deepslate, 0, 2);
		world.setBlock(i + 3, j + 24, k + 11, sculk_block, 0, 2);
		world.setBlock(i + 4, j + 24, k + 11, sculk_block, 0, 2);
		world.setBlock(i + 8, j + 24, k + 11, sculk_block, 0, 2);
		world.setBlock(i + 9, j + 24, k + 11, deepslate, 0, 2);
		world.setBlock(i + 10, j + 24, k + 11, deepslate, 0, 2);
		world.setBlock(i + 11, j + 24, k + 11, deepslate, 0, 2);
		world.setBlock(i + 12, j + 24, k + 11, deepslate, 0, 2);
		world.setBlock(i + 13, j + 24, k + 11, deepslate, 0, 2);
		world.setBlock(i + 14, j + 24, k + 11, deepslate, 0, 2);
		world.setBlock(i + 15, j + 24, k + 11, deepslate, 0, 2);
		world.setBlock(i + 16, j + 24, k + 11, deepslate, 0, 2);
		world.setBlock(i + 17, j + 24, k + 11, deepslate, 0, 2);
		world.setBlock(i + 18, j + 24, k + 11, deepslate, 0, 2);
		world.setBlock(i + 19, j + 24, k + 11, deepslate, 0, 2);
		world.setBlock(i + 20, j + 24, k + 11, deepslate, 0, 2);
		world.setBlock(i + 21, j + 24, k + 11, deepslate, 0, 2);
		world.setBlock(i + 2, j + 24, k + 12, sculk_block, 0, 2);
		world.setBlock(i + 4, j + 24, k + 12, sculk_block, 0, 2);
		world.setBlock(i + 8, j + 24, k + 12, sculk_block, 0, 2);
		world.setBlock(i + 9, j + 24, k + 12, deepslate, 0, 2);
		world.setBlock(i + 10, j + 24, k + 12, deepslate, 0, 2);
		world.setBlock(i + 11, j + 24, k + 12, deepslate, 0, 2);
		world.setBlock(i + 12, j + 24, k + 12, deepslate, 0, 2);
		world.setBlock(i + 13, j + 24, k + 12, deepslate, 0, 2);
		world.setBlock(i + 14, j + 24, k + 12, deepslate, 0, 2);
		world.setBlock(i + 15, j + 24, k + 12, deepslate, 0, 2);
		world.setBlock(i + 16, j + 24, k + 12, deepslate, 0, 2);
		world.setBlock(i + 17, j + 24, k + 12, deepslate, 0, 2);
		world.setBlock(i + 18, j + 24, k + 12, deepslate, 0, 2);
		world.setBlock(i + 19, j + 24, k + 12, deepslate, 0, 2);
		world.setBlock(i + 20, j + 24, k + 12, deepslate, 0, 2);
		world.setBlock(i + 21, j + 24, k + 12, deepslate, 0, 2);
		world.setBlock(i + 4, j + 24, k + 13, sculk_block, 0, 2);
		world.setBlock(i + 8, j + 24, k + 13, sculk_block, 0, 2);
		world.setBlock(i + 9, j + 24, k + 13, deepslate, 0, 2);
		world.setBlock(i + 10, j + 24, k + 13, deepslate, 0, 2);
		world.setBlock(i + 11, j + 24, k + 13, deepslate, 0, 2);
		world.setBlock(i + 12, j + 24, k + 13, deepslate, 0, 2);
		world.setBlock(i + 13, j + 24, k + 13, deepslate, 0, 2);
		world.setBlock(i + 14, j + 24, k + 13, deepslate, 0, 2);
		world.setBlock(i + 15, j + 24, k + 13, deepslate, 0, 2);
		world.setBlock(i + 16, j + 24, k + 13, deepslate, 0, 2);
		world.setBlock(i + 17, j + 24, k + 13, deepslate, 0, 2);
		world.setBlock(i + 18, j + 24, k + 13, deepslate, 0, 2);
		world.setBlock(i + 19, j + 24, k + 13, deepslate, 0, 2);
		world.setBlock(i + 20, j + 24, k + 13, deepslate, 0, 2);
		world.setBlock(i + 21, j + 24, k + 13, deepslate, 0, 2);
		world.setBlock(i + 5, j + 24, k + 14, sculk_block, 0, 2);
		world.setBlock(i + 6, j + 24, k + 14, sculk_block, 0, 2);
		world.setBlock(i + 8, j + 24, k + 14, sculk_block, 0, 2);
		world.setBlock(i + 9, j + 24, k + 14, deepslate, 0, 2);
		world.setBlock(i + 10, j + 24, k + 14, deepslate, 0, 2);
		world.setBlock(i + 11, j + 24, k + 14, deepslate, 0, 2);
		world.setBlock(i + 12, j + 24, k + 14, deepslate, 0, 2);
		world.setBlock(i + 13, j + 24, k + 14, deepslate, 0, 2);
		world.setBlock(i + 14, j + 24, k + 14, deepslate, 0, 2);
		world.setBlock(i + 15, j + 24, k + 14, deepslate, 0, 2);
		world.setBlock(i + 16, j + 24, k + 14, deepslate, 0, 2);
		world.setBlock(i + 17, j + 24, k + 14, deepslate, 0, 2);
		world.setBlock(i + 18, j + 24, k + 14, deepslate, 0, 2);
		world.setBlock(i + 19, j + 24, k + 14, deepslate, 0, 2);
		world.setBlock(i + 20, j + 24, k + 14, deepslate, 0, 2);
		world.setBlock(i + 21, j + 24, k + 14, deepslate, 0, 2);
		world.setBlock(i + 4, j + 24, k + 15, sculk_block, 0, 2);
		world.setBlock(i + 8, j + 24, k + 15, sculk_block, 0, 2);
		world.setBlock(i + 9, j + 24, k + 15, sculk_block, 0, 2);
		world.setBlock(i + 10, j + 24, k + 15, deepslate, 0, 2);
		world.setBlock(i + 11, j + 24, k + 15, deepslate, 0, 2);
		world.setBlock(i + 12, j + 24, k + 15, deepslate, 0, 2);
		world.setBlock(i + 13, j + 24, k + 15, deepslate, 0, 2);
		world.setBlock(i + 14, j + 24, k + 15, deepslate, 0, 2);
		world.setBlock(i + 15, j + 24, k + 15, deepslate, 0, 2);
		world.setBlock(i + 16, j + 24, k + 15, deepslate, 0, 2);
		world.setBlock(i + 17, j + 24, k + 15, deepslate, 0, 2);
		world.setBlock(i + 18, j + 24, k + 15, deepslate, 0, 2);
		world.setBlock(i + 19, j + 24, k + 15, deepslate, 0, 2);
		world.setBlock(i + 20, j + 24, k + 15, deepslate, 0, 2);
		world.setBlock(i + 21, j + 24, k + 15, deepslate, 0, 2);
		world.setBlock(i + 22, j + 24, k + 15, sculk_block, 0, 2);
		world.setBlock(i + 9, j + 24, k + 16, sculk_block, 0, 2);
		world.setBlock(i + 10, j + 24, k + 16, sculk_block, 0, 2);
		world.setBlock(i + 11, j + 24, k + 16, sculk_block, 0, 2);
		world.setBlock(i + 12, j + 24, k + 16, sculk_block, 0, 2);
		world.setBlock(i + 13, j + 24, k + 16, sculk_block, 0, 2);
		world.setBlock(i + 14, j + 24, k + 16, sculk_block, 0, 2);
		world.setBlock(i + 15, j + 24, k + 16, sculk_block, 0, 2);
		world.setBlock(i + 16, j + 24, k + 16, sculk_block, 0, 2);
		world.setBlock(i + 17, j + 24, k + 16, sculk_block, 0, 2);
		world.setBlock(i + 18, j + 24, k + 16, sculk_block, 0, 2);
		world.setBlock(i + 19, j + 24, k + 16, sculk_block, 0, 2);
		world.setBlock(i + 20, j + 24, k + 16, sculk_block, 0, 2);
		world.setBlock(i + 21, j + 24, k + 16, sculk_block, 0, 2);
		world.setBlock(i + 8, j + 25, k + 0, deepslate, 0, 2);
		world.setBlock(i + 9, j + 25, k + 0, deepslate, 0, 2);
		world.setBlock(i + 10, j + 25, k + 0, deepslate, 0, 2);
		world.setBlock(i + 11, j + 25, k + 0, deepslate, 0, 2);
		world.setBlock(i + 12, j + 25, k + 0, deepslate, 0, 2);
		world.setBlock(i + 13, j + 25, k + 0, deepslate, 0, 2);
		world.setBlock(i + 14, j + 25, k + 0, deepslate, 0, 2);
		world.setBlock(i + 15, j + 25, k + 0, deepslate, 0, 2);
		world.setBlock(i + 16, j + 25, k + 0, deepslate, 0, 2);
		world.setBlock(i + 7, j + 25, k + 1, deepslate, 0, 2);
		world.setBlock(i + 8, j + 25, k + 1, deepslate, 0, 2);
		world.setBlock(i + 9, j + 25, k + 1, deepslate, 0, 2);
		world.setBlock(i + 10, j + 25, k + 1, deepslate, 0, 2);
		world.setBlock(i + 11, j + 25, k + 1, deepslate, 0, 2);
		world.setBlock(i + 12, j + 25, k + 1, deepslate, 0, 2);
		world.setBlock(i + 13, j + 25, k + 1, deepslate, 0, 2);
		world.setBlock(i + 14, j + 25, k + 1, deepslate, 0, 2);
		world.setBlock(i + 15, j + 25, k + 1, deepslate, 0, 2);
		world.setBlock(i + 16, j + 25, k + 1, deepslate, 0, 2);
		world.setBlock(i + 17, j + 25, k + 1, deepslate, 0, 2);
		world.setBlock(i + 6, j + 25, k + 2, deepslate, 0, 2);
		world.setBlock(i + 7, j + 25, k + 2, deepslate, 0, 2);
		world.setBlock(i + 8, j + 25, k + 2, deepslate, 0, 2);
		world.setBlock(i + 9, j + 25, k + 2, deepslate, 0, 2);
		world.setBlock(i + 10, j + 25, k + 2, deepslate, 0, 2);
		world.setBlock(i + 11, j + 25, k + 2, deepslate, 0, 2);
		world.setBlock(i + 12, j + 25, k + 2, deepslate, 0, 2);
		world.setBlock(i + 13, j + 25, k + 2, deepslate, 0, 2);
		world.setBlock(i + 14, j + 25, k + 2, deepslate, 0, 2);
		world.setBlock(i + 15, j + 25, k + 2, deepslate, 0, 2);
		world.setBlock(i + 16, j + 25, k + 2, deepslate, 0, 2);
		world.setBlock(i + 17, j + 25, k + 2, deepslate, 0, 2);
		world.setBlock(i + 6, j + 25, k + 3, deepslate, 0, 2);
		world.setBlock(i + 7, j + 25, k + 3, deepslate, 0, 2);
		world.setBlock(i + 8, j + 25, k + 3, deepslate, 0, 2);
		world.setBlock(i + 9, j + 25, k + 3, deepslate, 0, 2);
		world.setBlock(i + 10, j + 25, k + 3, deepslate, 0, 2);
		world.setBlock(i + 11, j + 25, k + 3, deepslate, 0, 2);
		world.setBlock(i + 12, j + 25, k + 3, deepslate, 0, 2);
		world.setBlock(i + 13, j + 25, k + 3, deepslate, 0, 2);
		world.setBlock(i + 14, j + 25, k + 3, deepslate, 0, 2);
		world.setBlock(i + 15, j + 25, k + 3, deepslate, 0, 2);
		world.setBlock(i + 16, j + 25, k + 3, deepslate, 0, 2);
		world.setBlock(i + 17, j + 25, k + 3, deepslate, 0, 2);
		world.setBlock(i + 18, j + 25, k + 3, deepslate, 0, 2);
		world.setBlock(i + 5, j + 25, k + 4, deepslate, 0, 2);
		world.setBlock(i + 6, j + 25, k + 4, deepslate, 0, 2);
		world.setBlock(i + 7, j + 25, k + 4, deepslate, 0, 2);
		world.setBlock(i + 8, j + 25, k + 4, deepslate, 0, 2);
		world.setBlock(i + 9, j + 25, k + 4, deepslate, 0, 2);
		world.setBlock(i + 10, j + 25, k + 4, deepslate, 0, 2);
		world.setBlock(i + 11, j + 25, k + 4, deepslate, 0, 2);
		world.setBlock(i + 12, j + 25, k + 4, deepslate, 0, 2);
		world.setBlock(i + 13, j + 25, k + 4, deepslate, 0, 2);
		world.setBlock(i + 14, j + 25, k + 4, deepslate, 0, 2);
		world.setBlock(i + 15, j + 25, k + 4, deepslate, 0, 2);
		world.setBlock(i + 16, j + 25, k + 4, deepslate, 0, 2);
		world.setBlock(i + 17, j + 25, k + 4, deepslate, 0, 2);
		world.setBlock(i + 18, j + 25, k + 4, deepslate, 0, 2);
		world.setBlock(i + 5, j + 25, k + 5, deepslate, 0, 2);
		world.setBlock(i + 6, j + 25, k + 5, deepslate, 0, 2);
		world.setBlock(i + 7, j + 25, k + 5, deepslate, 0, 2);
		world.setBlock(i + 8, j + 25, k + 5, deepslate, 0, 2);
		world.setBlock(i + 9, j + 25, k + 5, deepslate, 0, 2);
		world.setBlock(i + 10, j + 25, k + 5, deepslate, 0, 2);
		world.setBlock(i + 11, j + 25, k + 5, deepslate, 0, 2);
		world.setBlock(i + 12, j + 25, k + 5, deepslate, 0, 2);
		world.setBlock(i + 13, j + 25, k + 5, deepslate, 0, 2);
		world.setBlock(i + 14, j + 25, k + 5, deepslate, 0, 2);
		world.setBlock(i + 15, j + 25, k + 5, deepslate, 0, 2);
		world.setBlock(i + 16, j + 25, k + 5, deepslate, 0, 2);
		world.setBlock(i + 17, j + 25, k + 5, deepslate, 0, 2);
		world.setBlock(i + 18, j + 25, k + 5, deepslate, 0, 2);
		world.setBlock(i + 4, j + 25, k + 6, deepslate, 0, 2);
		world.setBlock(i + 5, j + 25, k + 6, deepslate, 0, 2);
		world.setBlock(i + 6, j + 25, k + 6, deepslate, 0, 2);
		world.setBlock(i + 7, j + 25, k + 6, deepslate, 0, 2);
		world.setBlock(i + 8, j + 25, k + 6, deepslate, 0, 2);
		world.setBlock(i + 9, j + 25, k + 6, deepslate, 0, 2);
		world.setBlock(i + 10, j + 25, k + 6, deepslate, 0, 2);
		world.setBlock(i + 11, j + 25, k + 6, deepslate, 0, 2);
		world.setBlock(i + 12, j + 25, k + 6, deepslate, 0, 2);
		world.setBlock(i + 13, j + 25, k + 6, deepslate, 0, 2);
		world.setBlock(i + 14, j + 25, k + 6, deepslate, 0, 2);
		world.setBlock(i + 15, j + 25, k + 6, deepslate, 0, 2);
		world.setBlock(i + 16, j + 25, k + 6, deepslate, 0, 2);
		world.setBlock(i + 17, j + 25, k + 6, deepslate, 0, 2);
		world.setBlock(i + 18, j + 25, k + 6, deepslate, 0, 2);
		world.setBlock(i + 3, j + 25, k + 7, deepslate, 0, 2);
		world.setBlock(i + 4, j + 25, k + 7, deepslate, 0, 2);
		world.setBlock(i + 5, j + 25, k + 7, sculk_block, 0, 2);
		world.setBlock(i + 6, j + 25, k + 7, sculk_block, 0, 2);
		world.setBlock(i + 7, j + 25, k + 7, deepslate, 0, 2);
		world.setBlock(i + 8, j + 25, k + 7, deepslate, 0, 2);
		world.setBlock(i + 9, j + 25, k + 7, deepslate, 0, 2);
		world.setBlock(i + 10, j + 25, k + 7, deepslate, 0, 2);
		world.setBlock(i + 11, j + 25, k + 7, deepslate, 0, 2);
		world.setBlock(i + 12, j + 25, k + 7, deepslate, 0, 2);
		world.setBlock(i + 13, j + 25, k + 7, deepslate, 0, 2);
		world.setBlock(i + 14, j + 25, k + 7, deepslate, 0, 2);
		world.setBlock(i + 15, j + 25, k + 7, deepslate, 0, 2);
		world.setBlock(i + 16, j + 25, k + 7, deepslate, 0, 2);
		world.setBlock(i + 17, j + 25, k + 7, deepslate, 0, 2);
		world.setBlock(i + 18, j + 25, k + 7, deepslate, 0, 2);
		world.setBlock(i + 2, j + 25, k + 8, deepslate, 0, 2);
		world.setBlock(i + 3, j + 25, k + 8, deepslate, 0, 2);
		world.setBlock(i + 4, j + 25, k + 8, deepslate, 0, 2);
		world.setBlock(i + 5, j + 25, k + 8, sculk_block, 0, 2);
		world.setBlock(i + 6, j + 25, k + 8, sculk_block, 0, 2);
		world.setBlock(i + 7, j + 25, k + 8, deepslate, 0, 2);
		world.setBlock(i + 8, j + 25, k + 8, deepslate, 0, 2);
		world.setBlock(i + 9, j + 25, k + 8, deepslate, 0, 2);
		world.setBlock(i + 10, j + 25, k + 8, deepslate, 0, 2);
		world.setBlock(i + 11, j + 25, k + 8, deepslate, 0, 2);
		world.setBlock(i + 12, j + 25, k + 8, deepslate, 0, 2);
		world.setBlock(i + 13, j + 25, k + 8, deepslate, 0, 2);
		world.setBlock(i + 14, j + 25, k + 8, deepslate, 0, 2);
		world.setBlock(i + 15, j + 25, k + 8, deepslate, 0, 2);
		world.setBlock(i + 16, j + 25, k + 8, deepslate, 0, 2);
		world.setBlock(i + 17, j + 25, k + 8, deepslate, 0, 2);
		world.setBlock(i + 18, j + 25, k + 8, deepslate, 0, 2);
		world.setBlock(i + 19, j + 25, k + 8, deepslate, 0, 2);
		world.setBlock(i + 2, j + 25, k + 9, sculk_block, 0, 2);
		world.setBlock(i + 3, j + 25, k + 9, sculk_block, 0, 2);
		world.setBlock(i + 4, j + 25, k + 9, sculk_block, 0, 2);
		world.setBlock(i + 5, j + 25, k + 9, sculk_block, 0, 2);
		world.setBlock(i + 6, j + 25, k + 9, sculk_block, 0, 2);
		world.setBlock(i + 7, j + 25, k + 9, deepslate, 0, 2);
		world.setBlock(i + 8, j + 25, k + 9, deepslate, 0, 2);
		world.setBlock(i + 9, j + 25, k + 9, deepslate, 0, 2);
		world.setBlock(i + 10, j + 25, k + 9, deepslate, 0, 2);
		world.setBlock(i + 11, j + 25, k + 9, deepslate, 0, 2);
		world.setBlock(i + 12, j + 25, k + 9, deepslate, 0, 2);
		world.setBlock(i + 13, j + 25, k + 9, deepslate, 0, 2);
		world.setBlock(i + 14, j + 25, k + 9, deepslate, 0, 2);
		world.setBlock(i + 15, j + 25, k + 9, deepslate, 0, 2);
		world.setBlock(i + 16, j + 25, k + 9, deepslate, 0, 2);
		world.setBlock(i + 17, j + 25, k + 9, deepslate, 0, 2);
		world.setBlock(i + 18, j + 25, k + 9, deepslate, 0, 2);
		world.setBlock(i + 19, j + 25, k + 9, deepslate, 0, 2);
		world.setBlock(i + 20, j + 25, k + 9, deepslate, 0, 2);
		world.setBlock(i + 2, j + 25, k + 10, sculk_block, 0, 2);
		world.setBlock(i + 3, j + 25, k + 10, sculk_block, 0, 2);
		world.setBlock(i + 4, j + 25, k + 10, deepslate, 0, 2);
		world.setBlock(i + 5, j + 25, k + 10, sculk_block, 0, 2);
		world.setBlock(i + 6, j + 25, k + 10, sculk_block, 0, 2);
		world.setBlock(i + 7, j + 25, k + 10, deepslate, 0, 2);
		world.setBlock(i + 8, j + 25, k + 10, deepslate, 0, 2);
		world.setBlock(i + 9, j + 25, k + 10, deepslate, 0, 2);
		world.setBlock(i + 10, j + 25, k + 10, deepslate, 0, 2);
		world.setBlock(i + 11, j + 25, k + 10, deepslate, 0, 2);
		world.setBlock(i + 12, j + 25, k + 10, deepslate, 0, 2);
		world.setBlock(i + 13, j + 25, k + 10, deepslate, 0, 2);
		world.setBlock(i + 14, j + 25, k + 10, deepslate, 0, 2);
		world.setBlock(i + 15, j + 25, k + 10, deepslate, 0, 2);
		world.setBlock(i + 16, j + 25, k + 10, deepslate, 0, 2);
		world.setBlock(i + 17, j + 25, k + 10, deepslate, 0, 2);
		world.setBlock(i + 18, j + 25, k + 10, deepslate, 0, 2);
		world.setBlock(i + 19, j + 25, k + 10, deepslate, 0, 2);
		world.setBlock(i + 20, j + 25, k + 10, deepslate, 0, 2);
		world.setBlock(i + 21, j + 25, k + 10, deepslate, 0, 2);
		world.setBlock(i + 2, j + 25, k + 11, sculk_block, 0, 2);
		world.setBlock(i + 3, j + 25, k + 11, deepslate, 0, 2);
		world.setBlock(i + 4, j + 25, k + 11, deepslate, 0, 2);
		world.setBlock(i + 5, j + 25, k + 11, sculk_block, 0, 2);
		world.setBlock(i + 6, j + 25, k + 11, sculk_block, 0, 2);
		world.setBlock(i + 7, j + 25, k + 11, sculk_block, 0, 2);
		world.setBlock(i + 8, j + 25, k + 11, deepslate, 0, 2);
		world.setBlock(i + 9, j + 25, k + 11, deepslate, 0, 2);
		world.setBlock(i + 10, j + 25, k + 11, deepslate, 0, 2);
		world.setBlock(i + 11, j + 25, k + 11, deepslate, 0, 2);
		world.setBlock(i + 12, j + 25, k + 11, deepslate, 0, 2);
		world.setBlock(i + 13, j + 25, k + 11, deepslate, 0, 2);
		world.setBlock(i + 14, j + 25, k + 11, deepslate, 0, 2);
		world.setBlock(i + 15, j + 25, k + 11, deepslate, 0, 2);
		world.setBlock(i + 16, j + 25, k + 11, deepslate, 0, 2);
		world.setBlock(i + 17, j + 25, k + 11, deepslate, 0, 2);
		world.setBlock(i + 18, j + 25, k + 11, deepslate, 0, 2);
		world.setBlock(i + 19, j + 25, k + 11, deepslate, 0, 2);
		world.setBlock(i + 20, j + 25, k + 11, deepslate, 0, 2);
		world.setBlock(i + 21, j + 25, k + 11, deepslate, 0, 2);
		world.setBlock(i + 2, j + 25, k + 12, deepslate, 0, 2);
		world.setBlock(i + 3, j + 25, k + 12, deepslate, 0, 2);
		world.setBlock(i + 4, j + 25, k + 12, deepslate, 0, 2);
		world.setBlock(i + 5, j + 25, k + 12, sculk_block, 0, 2);
		world.setBlock(i + 6, j + 25, k + 12, sculk_block, 0, 2);
		world.setBlock(i + 7, j + 25, k + 12, sculk_block, 0, 2);
		world.setBlock(i + 8, j + 25, k + 12, deepslate, 0, 2);
		world.setBlock(i + 9, j + 25, k + 12, deepslate, 0, 2);
		world.setBlock(i + 10, j + 25, k + 12, deepslate, 0, 2);
		world.setBlock(i + 11, j + 25, k + 12, deepslate, 0, 2);
		world.setBlock(i + 12, j + 25, k + 12, deepslate, 0, 2);
		world.setBlock(i + 13, j + 25, k + 12, deepslate, 0, 2);
		world.setBlock(i + 14, j + 25, k + 12, deepslate, 0, 2);
		world.setBlock(i + 15, j + 25, k + 12, deepslate, 0, 2);
		world.setBlock(i + 16, j + 25, k + 12, deepslate, 0, 2);
		world.setBlock(i + 17, j + 25, k + 12, deepslate, 0, 2);
		world.setBlock(i + 18, j + 25, k + 12, deepslate, 0, 2);
		world.setBlock(i + 19, j + 25, k + 12, deepslate, 0, 2);
		world.setBlock(i + 20, j + 25, k + 12, deepslate, 0, 2);
		world.setBlock(i + 21, j + 25, k + 12, deepslate, 0, 2);
		world.setBlock(i + 2, j + 25, k + 13, deepslate, 0, 2);
		world.setBlock(i + 3, j + 25, k + 13, deepslate, 0, 2);
		world.setBlock(i + 4, j + 25, k + 13, deepslate, 0, 2);
		world.setBlock(i + 5, j + 25, k + 13, sculk_block, 0, 2);
		world.setBlock(i + 6, j + 25, k + 13, sculk_block, 0, 2);
		world.setBlock(i + 7, j + 25, k + 13, sculk_block, 0, 2);
		world.setBlock(i + 8, j + 25, k + 13, deepslate, 0, 2);
		world.setBlock(i + 9, j + 25, k + 13, deepslate, 0, 2);
		world.setBlock(i + 10, j + 25, k + 13, deepslate, 0, 2);
		world.setBlock(i + 11, j + 25, k + 13, deepslate, 0, 2);
		world.setBlock(i + 12, j + 25, k + 13, deepslate, 0, 2);
		world.setBlock(i + 13, j + 25, k + 13, deepslate, 0, 2);
		world.setBlock(i + 14, j + 25, k + 13, deepslate, 0, 2);
		world.setBlock(i + 15, j + 25, k + 13, deepslate, 0, 2);
		world.setBlock(i + 16, j + 25, k + 13, deepslate, 0, 2);
		world.setBlock(i + 17, j + 25, k + 13, deepslate, 0, 2);
		world.setBlock(i + 18, j + 25, k + 13, deepslate, 0, 2);
		world.setBlock(i + 19, j + 25, k + 13, deepslate, 0, 2);
		world.setBlock(i + 20, j + 25, k + 13, deepslate, 0, 2);
		world.setBlock(i + 21, j + 25, k + 13, deepslate, 0, 2);
		world.setBlock(i + 2, j + 25, k + 14, deepslate, 0, 2);
		world.setBlock(i + 3, j + 25, k + 14, deepslate, 0, 2);
		world.setBlock(i + 4, j + 25, k + 14, deepslate, 0, 2);
		world.setBlock(i + 5, j + 25, k + 14, deepslate, 0, 2);
		world.setBlock(i + 6, j + 25, k + 14, deepslate, 0, 2);
		world.setBlock(i + 7, j + 25, k + 14, sculk_block, 0, 2);
		world.setBlock(i + 8, j + 25, k + 14, deepslate, 0, 2);
		world.setBlock(i + 9, j + 25, k + 14, deepslate, 0, 2);
		world.setBlock(i + 10, j + 25, k + 14, deepslate, 0, 2);
		world.setBlock(i + 11, j + 25, k + 14, deepslate, 0, 2);
		world.setBlock(i + 12, j + 25, k + 14, deepslate, 0, 2);
		world.setBlock(i + 13, j + 25, k + 14, deepslate, 0, 2);
		world.setBlock(i + 14, j + 25, k + 14, deepslate, 0, 2);
		world.setBlock(i + 15, j + 25, k + 14, deepslate, 0, 2);
		world.setBlock(i + 16, j + 25, k + 14, deepslate, 0, 2);
		world.setBlock(i + 17, j + 25, k + 14, deepslate, 0, 2);
		world.setBlock(i + 18, j + 25, k + 14, deepslate, 0, 2);
		world.setBlock(i + 19, j + 25, k + 14, deepslate, 0, 2);
		world.setBlock(i + 20, j + 25, k + 14, deepslate, 0, 2);
		world.setBlock(i + 21, j + 25, k + 14, deepslate, 0, 2);
		world.setBlock(i + 2, j + 25, k + 15, deepslate, 0, 2);
		world.setBlock(i + 3, j + 25, k + 15, deepslate, 0, 2);
		world.setBlock(i + 4, j + 25, k + 15, deepslate, 0, 2);
		world.setBlock(i + 5, j + 25, k + 15, sculk_block, 0, 2);
		world.setBlock(i + 6, j + 25, k + 15, sculk_block, 0, 2);
		world.setBlock(i + 7, j + 25, k + 15, sculk_block, 0, 2);
		world.setBlock(i + 8, j + 25, k + 15, deepslate, 0, 2);
		world.setBlock(i + 9, j + 25, k + 15, deepslate, 0, 2);
		world.setBlock(i + 10, j + 25, k + 15, deepslate, 0, 2);
		world.setBlock(i + 11, j + 25, k + 15, deepslate, 0, 2);
		world.setBlock(i + 12, j + 25, k + 15, deepslate, 0, 2);
		world.setBlock(i + 13, j + 25, k + 15, deepslate, 0, 2);
		world.setBlock(i + 14, j + 25, k + 15, deepslate, 0, 2);
		world.setBlock(i + 15, j + 25, k + 15, deepslate, 0, 2);
		world.setBlock(i + 16, j + 25, k + 15, deepslate, 0, 2);
		world.setBlock(i + 17, j + 25, k + 15, deepslate, 0, 2);
		world.setBlock(i + 18, j + 25, k + 15, deepslate, 0, 2);
		world.setBlock(i + 19, j + 25, k + 15, deepslate, 0, 2);
		world.setBlock(i + 20, j + 25, k + 15, deepslate, 0, 2);
		world.setBlock(i + 21, j + 25, k + 15, deepslate, 0, 2);
		world.setBlock(i + 4, j + 25, k + 16, sculk_block, 0, 2);
		world.setBlock(i + 8, j + 25, k + 16, sculk_block, 0, 2);
		world.setBlock(i + 9, j + 25, k + 16, sculk_block, 0, 2);
		world.setBlock(i + 10, j + 25, k + 16, sculk_block, 0, 2);
		world.setBlock(i + 11, j + 25, k + 16, sculk_block, 0, 2);
		world.setBlock(i + 12, j + 25, k + 16, sculk_block, 0, 2);
		world.setBlock(i + 13, j + 25, k + 16, sculk_block, 0, 2);
		world.setBlock(i + 14, j + 25, k + 16, sculk_block, 0, 2);
		world.setBlock(i + 15, j + 25, k + 16, sculk_block, 0, 2);
		world.setBlock(i + 16, j + 25, k + 16, sculk_block, 0, 2);
		world.setBlock(i + 17, j + 25, k + 16, sculk_block, 0, 2);
		world.setBlock(i + 18, j + 25, k + 16, sculk_block, 0, 2);
		world.setBlock(i + 19, j + 25, k + 16, sculk_block, 0, 2);
		world.setBlock(i + 20, j + 25, k + 16, sculk_block, 0, 2);
		world.setBlock(i + 21, j + 25, k + 16, sculk_block, 0, 2);
		world.setBlock(i + 6, j + 26, k + 0, deepslate, 0, 2);
		world.setBlock(i + 7, j + 26, k + 0, deepslate, 0, 2);
		world.setBlock(i + 8, j + 26, k + 0, deepslate, 0, 2);
		world.setBlock(i + 9, j + 26, k + 0, deepslate, 0, 2);
		world.setBlock(i + 10, j + 26, k + 0, deepslate, 0, 2);
		world.setBlock(i + 11, j + 26, k + 0, deepslate, 0, 2);
		world.setBlock(i + 12, j + 26, k + 0, deepslate, 0, 2);
		world.setBlock(i + 13, j + 26, k + 0, deepslate, 0, 2);
		world.setBlock(i + 14, j + 26, k + 0, deepslate, 0, 2);
		world.setBlock(i + 15, j + 26, k + 0, deepslate, 0, 2);
		world.setBlock(i + 16, j + 26, k + 0, deepslate, 0, 2);
		world.setBlock(i + 17, j + 26, k + 0, deepslate, 0, 2);
		world.setBlock(i + 6, j + 26, k + 1, deepslate, 0, 2);
		world.setBlock(i + 7, j + 26, k + 1, deepslate, 0, 2);
		world.setBlock(i + 8, j + 26, k + 1, deepslate, 0, 2);
		world.setBlock(i + 9, j + 26, k + 1, deepslate, 0, 2);
		world.setBlock(i + 10, j + 26, k + 1, deepslate, 0, 2);
		world.setBlock(i + 11, j + 26, k + 1, deepslate, 0, 2);
		world.setBlock(i + 12, j + 26, k + 1, deepslate, 0, 2);
		world.setBlock(i + 13, j + 26, k + 1, deepslate, 0, 2);
		world.setBlock(i + 14, j + 26, k + 1, deepslate, 0, 2);
		world.setBlock(i + 15, j + 26, k + 1, deepslate, 0, 2);
		world.setBlock(i + 16, j + 26, k + 1, deepslate, 0, 2);
		world.setBlock(i + 17, j + 26, k + 1, deepslate, 0, 2);
		world.setBlock(i + 5, j + 26, k + 2, deepslate, 0, 2);
		world.setBlock(i + 6, j + 26, k + 2, deepslate, 0, 2);
		world.setBlock(i + 7, j + 26, k + 2, deepslate, 0, 2);
		world.setBlock(i + 8, j + 26, k + 2, deepslate, 0, 2);
		world.setBlock(i + 9, j + 26, k + 2, deepslate, 0, 2);
		world.setBlock(i + 10, j + 26, k + 2, deepslate, 0, 2);
		world.setBlock(i + 11, j + 26, k + 2, deepslate, 0, 2);
		world.setBlock(i + 12, j + 26, k + 2, deepslate, 0, 2);
		world.setBlock(i + 13, j + 26, k + 2, deepslate, 0, 2);
		world.setBlock(i + 14, j + 26, k + 2, deepslate, 0, 2);
		world.setBlock(i + 15, j + 26, k + 2, deepslate, 0, 2);
		world.setBlock(i + 16, j + 26, k + 2, deepslate, 0, 2);
		world.setBlock(i + 17, j + 26, k + 2, deepslate, 0, 2);
		world.setBlock(i + 18, j + 26, k + 2, deepslate, 0, 2);
		world.setBlock(i + 4, j + 26, k + 3, deepslate, 0, 2);
		world.setBlock(i + 5, j + 26, k + 3, deepslate, 0, 2);
		world.setBlock(i + 6, j + 26, k + 3, deepslate, 0, 2);
		world.setBlock(i + 7, j + 26, k + 3, deepslate, 0, 2);
		world.setBlock(i + 8, j + 26, k + 3, deepslate, 0, 2);
		world.setBlock(i + 9, j + 26, k + 3, deepslate, 0, 2);
		world.setBlock(i + 10, j + 26, k + 3, deepslate, 0, 2);
		world.setBlock(i + 11, j + 26, k + 3, deepslate, 0, 2);
		world.setBlock(i + 12, j + 26, k + 3, deepslate, 0, 2);
		world.setBlock(i + 13, j + 26, k + 3, deepslate, 0, 2);
		world.setBlock(i + 14, j + 26, k + 3, deepslate, 0, 2);
		world.setBlock(i + 15, j + 26, k + 3, deepslate, 0, 2);
		world.setBlock(i + 16, j + 26, k + 3, deepslate, 0, 2);
		world.setBlock(i + 17, j + 26, k + 3, deepslate, 0, 2);
		world.setBlock(i + 18, j + 26, k + 3, deepslate, 0, 2);
		world.setBlock(i + 4, j + 26, k + 4, deepslate, 0, 2);
		world.setBlock(i + 5, j + 26, k + 4, deepslate, 0, 2);
		world.setBlock(i + 6, j + 26, k + 4, deepslate, 0, 2);
		world.setBlock(i + 7, j + 26, k + 4, deepslate, 0, 2);
		world.setBlock(i + 8, j + 26, k + 4, deepslate, 0, 2);
		world.setBlock(i + 9, j + 26, k + 4, deepslate, 0, 2);
		world.setBlock(i + 10, j + 26, k + 4, deepslate, 0, 2);
		world.setBlock(i + 11, j + 26, k + 4, deepslate, 0, 2);
		world.setBlock(i + 12, j + 26, k + 4, deepslate, 0, 2);
		world.setBlock(i + 13, j + 26, k + 4, deepslate, 0, 2);
		world.setBlock(i + 14, j + 26, k + 4, deepslate, 0, 2);
		world.setBlock(i + 15, j + 26, k + 4, deepslate, 0, 2);
		world.setBlock(i + 16, j + 26, k + 4, deepslate, 0, 2);
		world.setBlock(i + 17, j + 26, k + 4, deepslate, 0, 2);
		world.setBlock(i + 18, j + 26, k + 4, deepslate, 0, 2);
		world.setBlock(i + 3, j + 26, k + 5, deepslate, 0, 2);
		world.setBlock(i + 4, j + 26, k + 5, deepslate, 0, 2);
		world.setBlock(i + 5, j + 26, k + 5, deepslate, 0, 2);
		world.setBlock(i + 6, j + 26, k + 5, deepslate, 0, 2);
		world.setBlock(i + 7, j + 26, k + 5, deepslate, 0, 2);
		world.setBlock(i + 8, j + 26, k + 5, deepslate, 0, 2);
		world.setBlock(i + 9, j + 26, k + 5, deepslate, 0, 2);
		world.setBlock(i + 10, j + 26, k + 5, deepslate, 0, 2);
		world.setBlock(i + 11, j + 26, k + 5, deepslate, 0, 2);
		world.setBlock(i + 12, j + 26, k + 5, deepslate, 0, 2);
		world.setBlock(i + 13, j + 26, k + 5, deepslate, 0, 2);
		world.setBlock(i + 14, j + 26, k + 5, deepslate, 0, 2);
		world.setBlock(i + 15, j + 26, k + 5, deepslate, 0, 2);
		world.setBlock(i + 16, j + 26, k + 5, deepslate, 0, 2);
		world.setBlock(i + 17, j + 26, k + 5, deepslate, 0, 2);
		world.setBlock(i + 18, j + 26, k + 5, deepslate, 0, 2);
		world.setBlock(i + 2, j + 26, k + 6, deepslate, 0, 2);
		world.setBlock(i + 3, j + 26, k + 6, deepslate, 0, 2);
		world.setBlock(i + 4, j + 26, k + 6, deepslate, 0, 2);
		world.setBlock(i + 5, j + 26, k + 6, deepslate, 0, 2);
		world.setBlock(i + 6, j + 26, k + 6, deepslate, 0, 2);
		world.setBlock(i + 7, j + 26, k + 6, deepslate, 0, 2);
		world.setBlock(i + 8, j + 26, k + 6, deepslate, 0, 2);
		world.setBlock(i + 9, j + 26, k + 6, deepslate, 0, 2);
		world.setBlock(i + 10, j + 26, k + 6, deepslate, 0, 2);
		world.setBlock(i + 11, j + 26, k + 6, deepslate, 0, 2);
		world.setBlock(i + 12, j + 26, k + 6, deepslate, 0, 2);
		world.setBlock(i + 13, j + 26, k + 6, deepslate, 0, 2);
		world.setBlock(i + 14, j + 26, k + 6, deepslate, 0, 2);
		world.setBlock(i + 15, j + 26, k + 6, deepslate, 0, 2);
		world.setBlock(i + 16, j + 26, k + 6, deepslate, 0, 2);
		world.setBlock(i + 17, j + 26, k + 6, deepslate, 0, 2);
		world.setBlock(i + 18, j + 26, k + 6, deepslate, 0, 2);
		world.setBlock(i + 2, j + 26, k + 7, deepslate, 0, 2);
		world.setBlock(i + 3, j + 26, k + 7, deepslate, 0, 2);
		world.setBlock(i + 4, j + 26, k + 7, deepslate, 0, 2);
		world.setBlock(i + 5, j + 26, k + 7, deepslate, 0, 2);
		world.setBlock(i + 6, j + 26, k + 7, deepslate, 0, 2);
		world.setBlock(i + 7, j + 26, k + 7, deepslate, 0, 2);
		world.setBlock(i + 8, j + 26, k + 7, deepslate, 0, 2);
		world.setBlock(i + 9, j + 26, k + 7, deepslate, 0, 2);
		world.setBlock(i + 10, j + 26, k + 7, deepslate, 0, 2);
		world.setBlock(i + 11, j + 26, k + 7, deepslate, 0, 2);
		world.setBlock(i + 12, j + 26, k + 7, deepslate, 0, 2);
		world.setBlock(i + 13, j + 26, k + 7, deepslate, 0, 2);
		world.setBlock(i + 14, j + 26, k + 7, deepslate, 0, 2);
		world.setBlock(i + 15, j + 26, k + 7, deepslate, 0, 2);
		world.setBlock(i + 16, j + 26, k + 7, deepslate, 0, 2);
		world.setBlock(i + 17, j + 26, k + 7, deepslate, 0, 2);
		world.setBlock(i + 18, j + 26, k + 7, deepslate, 0, 2);
		world.setBlock(i + 1, j + 26, k + 8, deepslate, 0, 2);
		world.setBlock(i + 2, j + 26, k + 8, deepslate, 0, 2);
		world.setBlock(i + 3, j + 26, k + 8, deepslate, 0, 2);
		world.setBlock(i + 4, j + 26, k + 8, deepslate, 0, 2);
		world.setBlock(i + 5, j + 26, k + 8, deepslate, 0, 2);
		world.setBlock(i + 6, j + 26, k + 8, deepslate, 0, 2);
		world.setBlock(i + 7, j + 26, k + 8, deepslate, 0, 2);
		world.setBlock(i + 8, j + 26, k + 8, deepslate, 0, 2);
		world.setBlock(i + 9, j + 26, k + 8, deepslate, 0, 2);
		world.setBlock(i + 10, j + 26, k + 8, deepslate, 0, 2);
		world.setBlock(i + 11, j + 26, k + 8, deepslate, 0, 2);
		world.setBlock(i + 12, j + 26, k + 8, deepslate, 0, 2);
		world.setBlock(i + 13, j + 26, k + 8, deepslate, 0, 2);
		world.setBlock(i + 14, j + 26, k + 8, deepslate, 0, 2);
		world.setBlock(i + 15, j + 26, k + 8, deepslate, 0, 2);
		world.setBlock(i + 16, j + 26, k + 8, deepslate, 0, 2);
		world.setBlock(i + 17, j + 26, k + 8, deepslate, 0, 2);
		world.setBlock(i + 18, j + 26, k + 8, deepslate, 0, 2);
		world.setBlock(i + 19, j + 26, k + 8, deepslate, 0, 2);
		world.setBlock(i + 1, j + 26, k + 9, deepslate, 0, 2);
		world.setBlock(i + 2, j + 26, k + 9, deepslate, 0, 2);
		world.setBlock(i + 3, j + 26, k + 9, deepslate, 0, 2);
		world.setBlock(i + 4, j + 26, k + 9, deepslate, 0, 2);
		world.setBlock(i + 5, j + 26, k + 9, deepslate, 0, 2);
		world.setBlock(i + 6, j + 26, k + 9, deepslate, 0, 2);
		world.setBlock(i + 7, j + 26, k + 9, deepslate, 0, 2);
		world.setBlock(i + 8, j + 26, k + 9, deepslate, 0, 2);
		world.setBlock(i + 9, j + 26, k + 9, deepslate, 0, 2);
		world.setBlock(i + 10, j + 26, k + 9, deepslate, 0, 2);
		world.setBlock(i + 11, j + 26, k + 9, deepslate, 0, 2);
		world.setBlock(i + 12, j + 26, k + 9, deepslate, 0, 2);
		world.setBlock(i + 13, j + 26, k + 9, deepslate, 0, 2);
		world.setBlock(i + 14, j + 26, k + 9, deepslate, 0, 2);
		world.setBlock(i + 15, j + 26, k + 9, deepslate, 0, 2);
		world.setBlock(i + 16, j + 26, k + 9, deepslate, 0, 2);
		world.setBlock(i + 17, j + 26, k + 9, deepslate, 0, 2);
		world.setBlock(i + 18, j + 26, k + 9, deepslate, 0, 2);
		world.setBlock(i + 19, j + 26, k + 9, deepslate, 0, 2);
		world.setBlock(i + 20, j + 26, k + 9, deepslate, 0, 2);
		world.setBlock(i + 1, j + 26, k + 10, deepslate, 0, 2);
		world.setBlock(i + 2, j + 26, k + 10, deepslate, 0, 2);
		world.setBlock(i + 3, j + 26, k + 10, deepslate, 0, 2);
		world.setBlock(i + 4, j + 26, k + 10, deepslate, 0, 2);
		world.setBlock(i + 5, j + 26, k + 10, deepslate, 0, 2);
		world.setBlock(i + 6, j + 26, k + 10, deepslate, 0, 2);
		world.setBlock(i + 7, j + 26, k + 10, deepslate, 0, 2);
		world.setBlock(i + 8, j + 26, k + 10, deepslate, 0, 2);
		world.setBlock(i + 9, j + 26, k + 10, deepslate, 0, 2);
		world.setBlock(i + 10, j + 26, k + 10, deepslate, 0, 2);
		world.setBlock(i + 11, j + 26, k + 10, deepslate, 0, 2);
		world.setBlock(i + 12, j + 26, k + 10, deepslate, 0, 2);
		world.setBlock(i + 13, j + 26, k + 10, deepslate, 0, 2);
		world.setBlock(i + 14, j + 26, k + 10, deepslate, 0, 2);
		world.setBlock(i + 15, j + 26, k + 10, deepslate, 0, 2);
		world.setBlock(i + 16, j + 26, k + 10, deepslate, 0, 2);
		world.setBlock(i + 17, j + 26, k + 10, deepslate, 0, 2);
		world.setBlock(i + 18, j + 26, k + 10, deepslate, 0, 2);
		world.setBlock(i + 19, j + 26, k + 10, deepslate, 0, 2);
		world.setBlock(i + 20, j + 26, k + 10, deepslate, 0, 2);
		world.setBlock(i + 21, j + 26, k + 10, deepslate, 0, 2);
		world.setBlock(i + 1, j + 26, k + 11, deepslate, 0, 2);
		world.setBlock(i + 2, j + 26, k + 11, deepslate, 0, 2);
		world.setBlock(i + 3, j + 26, k + 11, deepslate, 0, 2);
		world.setBlock(i + 4, j + 26, k + 11, deepslate, 0, 2);
		world.setBlock(i + 5, j + 26, k + 11, deepslate, 0, 2);
		world.setBlock(i + 6, j + 26, k + 11, deepslate, 0, 2);
		world.setBlock(i + 7, j + 26, k + 11, deepslate, 0, 2);
		world.setBlock(i + 8, j + 26, k + 11, deepslate, 0, 2);
		world.setBlock(i + 9, j + 26, k + 11, deepslate, 0, 2);
		world.setBlock(i + 10, j + 26, k + 11, deepslate, 0, 2);
		world.setBlock(i + 11, j + 26, k + 11, deepslate, 0, 2);
		world.setBlock(i + 12, j + 26, k + 11, deepslate, 0, 2);
		world.setBlock(i + 13, j + 26, k + 11, deepslate, 0, 2);
		world.setBlock(i + 14, j + 26, k + 11, deepslate, 0, 2);
		world.setBlock(i + 15, j + 26, k + 11, deepslate, 0, 2);
		world.setBlock(i + 16, j + 26, k + 11, deepslate, 0, 2);
		world.setBlock(i + 17, j + 26, k + 11, deepslate, 0, 2);
		world.setBlock(i + 18, j + 26, k + 11, deepslate, 0, 2);
		world.setBlock(i + 19, j + 26, k + 11, deepslate, 0, 2);
		world.setBlock(i + 20, j + 26, k + 11, deepslate, 0, 2);
		world.setBlock(i + 21, j + 26, k + 11, deepslate, 0, 2);
		world.setBlock(i + 1, j + 26, k + 12, deepslate, 0, 2);
		world.setBlock(i + 2, j + 26, k + 12, deepslate, 0, 2);
		world.setBlock(i + 3, j + 26, k + 12, deepslate, 0, 2);
		world.setBlock(i + 4, j + 26, k + 12, deepslate, 0, 2);
		world.setBlock(i + 5, j + 26, k + 12, deepslate, 0, 2);
		world.setBlock(i + 6, j + 26, k + 12, deepslate, 0, 2);
		world.setBlock(i + 7, j + 26, k + 12, deepslate, 0, 2);
		world.setBlock(i + 8, j + 26, k + 12, deepslate, 0, 2);
		world.setBlock(i + 9, j + 26, k + 12, deepslate, 0, 2);
		world.setBlock(i + 10, j + 26, k + 12, deepslate, 0, 2);
		world.setBlock(i + 11, j + 26, k + 12, deepslate, 0, 2);
		world.setBlock(i + 12, j + 26, k + 12, deepslate, 0, 2);
		world.setBlock(i + 13, j + 26, k + 12, deepslate, 0, 2);
		world.setBlock(i + 14, j + 26, k + 12, deepslate, 0, 2);
		world.setBlock(i + 15, j + 26, k + 12, deepslate, 0, 2);
		world.setBlock(i + 16, j + 26, k + 12, deepslate, 0, 2);
		world.setBlock(i + 17, j + 26, k + 12, deepslate, 0, 2);
		world.setBlock(i + 18, j + 26, k + 12, deepslate, 0, 2);
		world.setBlock(i + 19, j + 26, k + 12, deepslate, 0, 2);
		world.setBlock(i + 20, j + 26, k + 12, deepslate, 0, 2);
		world.setBlock(i + 21, j + 26, k + 12, deepslate, 0, 2);
		world.setBlock(i + 1, j + 26, k + 13, deepslate, 0, 2);
		world.setBlock(i + 2, j + 26, k + 13, deepslate, 0, 2);
		world.setBlock(i + 3, j + 26, k + 13, deepslate, 0, 2);
		world.setBlock(i + 4, j + 26, k + 13, deepslate, 0, 2);
		world.setBlock(i + 5, j + 26, k + 13, deepslate, 0, 2);
		world.setBlock(i + 6, j + 26, k + 13, deepslate, 0, 2);
		world.setBlock(i + 7, j + 26, k + 13, deepslate, 0, 2);
		world.setBlock(i + 8, j + 26, k + 13, deepslate, 0, 2);
		world.setBlock(i + 9, j + 26, k + 13, deepslate, 0, 2);
		world.setBlock(i + 10, j + 26, k + 13, deepslate, 0, 2);
		world.setBlock(i + 11, j + 26, k + 13, deepslate, 0, 2);
		world.setBlock(i + 12, j + 26, k + 13, deepslate, 0, 2);
		world.setBlock(i + 13, j + 26, k + 13, deepslate, 0, 2);
		world.setBlock(i + 14, j + 26, k + 13, deepslate, 0, 2);
		world.setBlock(i + 15, j + 26, k + 13, deepslate, 0, 2);
		world.setBlock(i + 16, j + 26, k + 13, deepslate, 0, 2);
		world.setBlock(i + 17, j + 26, k + 13, deepslate, 0, 2);
		world.setBlock(i + 18, j + 26, k + 13, deepslate, 0, 2);
		world.setBlock(i + 19, j + 26, k + 13, deepslate, 0, 2);
		world.setBlock(i + 20, j + 26, k + 13, deepslate, 0, 2);
		world.setBlock(i + 21, j + 26, k + 13, deepslate, 0, 2);
		world.setBlock(i + 1, j + 26, k + 14, deepslate, 0, 2);
		world.setBlock(i + 2, j + 26, k + 14, deepslate, 0, 2);
		world.setBlock(i + 3, j + 26, k + 14, deepslate, 0, 2);
		world.setBlock(i + 4, j + 26, k + 14, deepslate, 0, 2);
		world.setBlock(i + 5, j + 26, k + 14, deepslate, 0, 2);
		world.setBlock(i + 6, j + 26, k + 14, deepslate, 0, 2);
		world.setBlock(i + 7, j + 26, k + 14, deepslate, 0, 2);
		world.setBlock(i + 8, j + 26, k + 14, deepslate, 0, 2);
		world.setBlock(i + 9, j + 26, k + 14, deepslate, 0, 2);
		world.setBlock(i + 10, j + 26, k + 14, deepslate, 0, 2);
		world.setBlock(i + 11, j + 26, k + 14, deepslate, 0, 2);
		world.setBlock(i + 12, j + 26, k + 14, deepslate, 0, 2);
		world.setBlock(i + 13, j + 26, k + 14, deepslate, 0, 2);
		world.setBlock(i + 14, j + 26, k + 14, deepslate, 0, 2);
		world.setBlock(i + 15, j + 26, k + 14, deepslate, 0, 2);
		world.setBlock(i + 16, j + 26, k + 14, deepslate, 0, 2);
		world.setBlock(i + 17, j + 26, k + 14, deepslate, 0, 2);
		world.setBlock(i + 18, j + 26, k + 14, deepslate, 0, 2);
		world.setBlock(i + 19, j + 26, k + 14, deepslate, 0, 2);
		world.setBlock(i + 20, j + 26, k + 14, deepslate, 0, 2);
		world.setBlock(i + 21, j + 26, k + 14, deepslate, 0, 2);
		world.setBlock(i + 1, j + 26, k + 15, deepslate, 0, 2);
		world.setBlock(i + 2, j + 26, k + 15, deepslate, 0, 2);
		world.setBlock(i + 3, j + 26, k + 15, deepslate, 0, 2);
		world.setBlock(i + 4, j + 26, k + 15, deepslate, 0, 2);
		world.setBlock(i + 5, j + 26, k + 15, deepslate, 0, 2);
		world.setBlock(i + 6, j + 26, k + 15, deepslate, 0, 2);
		world.setBlock(i + 7, j + 26, k + 15, deepslate, 0, 2);
		world.setBlock(i + 8, j + 26, k + 15, deepslate, 0, 2);
		world.setBlock(i + 9, j + 26, k + 15, deepslate, 0, 2);
		world.setBlock(i + 10, j + 26, k + 15, deepslate, 0, 2);
		world.setBlock(i + 11, j + 26, k + 15, deepslate, 0, 2);
		world.setBlock(i + 12, j + 26, k + 15, deepslate, 0, 2);
		world.setBlock(i + 13, j + 26, k + 15, deepslate, 0, 2);
		world.setBlock(i + 14, j + 26, k + 15, deepslate, 0, 2);
		world.setBlock(i + 15, j + 26, k + 15, deepslate, 0, 2);
		world.setBlock(i + 16, j + 26, k + 15, deepslate, 0, 2);
		world.setBlock(i + 17, j + 26, k + 15, deepslate, 0, 2);
		world.setBlock(i + 18, j + 26, k + 15, deepslate, 0, 2);
		world.setBlock(i + 19, j + 26, k + 15, deepslate, 0, 2);
		world.setBlock(i + 20, j + 26, k + 15, deepslate, 0, 2);
		world.setBlock(i + 21, j + 26, k + 15, deepslate, 0, 2);
		world.setBlock(i + 2, j + 26, k + 16, deepslate, 0, 2);
		world.setBlock(i + 3, j + 26, k + 16, deepslate, 0, 2);
		world.setBlock(i + 4, j + 26, k + 16, deepslate, 0, 2);
		world.setBlock(i + 5, j + 26, k + 16, sculk_block, 0, 2);
		world.setBlock(i + 6, j + 26, k + 16, sculk_block, 0, 2);
		world.setBlock(i + 7, j + 26, k + 16, sculk_block, 0, 2);
		world.setBlock(i + 8, j + 26, k + 16, sculk_block, 0, 2);
		world.setBlock(i + 9, j + 26, k + 16, deepslate, 0, 2);
		world.setBlock(i + 10, j + 26, k + 16, deepslate, 0, 2);
		world.setBlock(i + 11, j + 26, k + 16, deepslate, 0, 2);
		world.setBlock(i + 12, j + 26, k + 16, deepslate, 0, 2);
		world.setBlock(i + 13, j + 26, k + 16, deepslate, 0, 2);
		world.setBlock(i + 14, j + 26, k + 16, deepslate, 0, 2);
		world.setBlock(i + 15, j + 26, k + 16, deepslate, 0, 2);
		world.setBlock(i + 16, j + 26, k + 16, deepslate, 0, 2);
		world.setBlock(i + 17, j + 26, k + 16, deepslate, 0, 2);
		world.setBlock(i + 18, j + 26, k + 16, deepslate, 0, 2);
		world.setBlock(i + 19, j + 26, k + 16, deepslate, 0, 2);
		world.setBlock(i + 20, j + 26, k + 16, sculk_block, 0, 2);
		world.setBlock(i + 21, j + 26, k + 16, sculk_block, 0, 2);
		world.setBlock(i + 4, j + 26, k + 17, sculk_block, 0, 2);
		world.setBlock(i + 9, j + 26, k + 17, sculk_block, 0, 2);
		world.setBlock(i + 10, j + 26, k + 17, sculk_block, 0, 2);
		world.setBlock(i + 11, j + 26, k + 17, sculk_block, 0, 2);
		world.setBlock(i + 12, j + 26, k + 17, sculk_block, 0, 2);
		world.setBlock(i + 13, j + 26, k + 17, sculk_block, 0, 2);
		world.setBlock(i + 14, j + 26, k + 17, sculk_block, 0, 2);
		world.setBlock(i + 15, j + 26, k + 17, sculk_block, 0, 2);
		world.setBlock(i + 16, j + 26, k + 17, sculk_block, 0, 2);
		world.setBlock(i + 17, j + 26, k + 17, sculk_block, 0, 2);
		world.setBlock(i + 18, j + 26, k + 17, sculk_block, 0, 2);
		world.setBlock(i + 19, j + 26, k + 17, sculk_block, 0, 2);
		world.setBlock(i + 5, j + 27, k + 0, deepslate, 0, 2);
		world.setBlock(i + 6, j + 27, k + 0, deepslate, 0, 2);
		world.setBlock(i + 7, j + 27, k + 0, deepslate, 0, 2);
		world.setBlock(i + 8, j + 27, k + 0, deepslate, 0, 2);
		world.setBlock(i + 9, j + 27, k + 0, deepslate, 0, 2);
		world.setBlock(i + 10, j + 27, k + 0, deepslate, 0, 2);
		world.setBlock(i + 11, j + 27, k + 0, deepslate, 0, 2);
		world.setBlock(i + 12, j + 27, k + 0, deepslate, 0, 2);
		world.setBlock(i + 13, j + 27, k + 0, deepslate, 0, 2);
		world.setBlock(i + 14, j + 27, k + 0, deepslate, 0, 2);
		world.setBlock(i + 15, j + 27, k + 0, deepslate, 0, 2);
		world.setBlock(i + 16, j + 27, k + 0, deepslate, 0, 2);
		world.setBlock(i + 17, j + 27, k + 0, deepslate, 0, 2);
		world.setBlock(i + 5, j + 27, k + 1, deepslate, 0, 2);
		world.setBlock(i + 6, j + 27, k + 1, deepslate, 0, 2);
		world.setBlock(i + 7, j + 27, k + 1, deepslate, 0, 2);
		world.setBlock(i + 8, j + 27, k + 1, deepslate, 0, 2);
		world.setBlock(i + 9, j + 27, k + 1, deepslate, 0, 2);
		world.setBlock(i + 10, j + 27, k + 1, deepslate, 0, 2);
		world.setBlock(i + 11, j + 27, k + 1, deepslate, 0, 2);
		world.setBlock(i + 12, j + 27, k + 1, deepslate, 0, 2);
		world.setBlock(i + 13, j + 27, k + 1, deepslate, 0, 2);
		world.setBlock(i + 14, j + 27, k + 1, deepslate, 0, 2);
		world.setBlock(i + 15, j + 27, k + 1, deepslate, 0, 2);
		world.setBlock(i + 16, j + 27, k + 1, deepslate, 0, 2);
		world.setBlock(i + 17, j + 27, k + 1, deepslate, 0, 2);
		world.setBlock(i + 18, j + 27, k + 1, deepslate, 0, 2);
		world.setBlock(i + 4, j + 27, k + 2, deepslate, 0, 2);
		world.setBlock(i + 5, j + 27, k + 2, deepslate, 0, 2);
		world.setBlock(i + 6, j + 27, k + 2, deepslate, 0, 2);
		world.setBlock(i + 7, j + 27, k + 2, deepslate, 0, 2);
		world.setBlock(i + 8, j + 27, k + 2, deepslate, 0, 2);
		world.setBlock(i + 9, j + 27, k + 2, deepslate, 0, 2);
		world.setBlock(i + 10, j + 27, k + 2, deepslate, 0, 2);
		world.setBlock(i + 11, j + 27, k + 2, deepslate, 0, 2);
		world.setBlock(i + 12, j + 27, k + 2, deepslate, 0, 2);
		world.setBlock(i + 13, j + 27, k + 2, deepslate, 0, 2);
		world.setBlock(i + 14, j + 27, k + 2, deepslate, 0, 2);
		world.setBlock(i + 15, j + 27, k + 2, deepslate, 0, 2);
		world.setBlock(i + 16, j + 27, k + 2, deepslate, 0, 2);
		world.setBlock(i + 17, j + 27, k + 2, deepslate, 0, 2);
		world.setBlock(i + 18, j + 27, k + 2, deepslate, 0, 2);
		world.setBlock(i + 3, j + 27, k + 3, deepslate, 0, 2);
		world.setBlock(i + 4, j + 27, k + 3, deepslate, 0, 2);
		world.setBlock(i + 5, j + 27, k + 3, deepslate, 0, 2);
		world.setBlock(i + 6, j + 27, k + 3, deepslate, 0, 2);
		world.setBlock(i + 7, j + 27, k + 3, deepslate, 0, 2);
		world.setBlock(i + 8, j + 27, k + 3, deepslate, 0, 2);
		world.setBlock(i + 9, j + 27, k + 3, deepslate, 0, 2);
		world.setBlock(i + 10, j + 27, k + 3, deepslate, 0, 2);
		world.setBlock(i + 11, j + 27, k + 3, deepslate, 0, 2);
		world.setBlock(i + 12, j + 27, k + 3, deepslate, 0, 2);
		world.setBlock(i + 13, j + 27, k + 3, deepslate, 0, 2);
		world.setBlock(i + 14, j + 27, k + 3, deepslate, 0, 2);
		world.setBlock(i + 15, j + 27, k + 3, deepslate, 0, 2);
		world.setBlock(i + 16, j + 27, k + 3, deepslate, 0, 2);
		world.setBlock(i + 17, j + 27, k + 3, deepslate, 0, 2);
		world.setBlock(i + 18, j + 27, k + 3, deepslate, 0, 2);
		world.setBlock(i + 2, j + 27, k + 4, deepslate, 0, 2);
		world.setBlock(i + 3, j + 27, k + 4, deepslate, 0, 2);
		world.setBlock(i + 4, j + 27, k + 4, deepslate, 0, 2);
		world.setBlock(i + 5, j + 27, k + 4, deepslate, 0, 2);
		world.setBlock(i + 6, j + 27, k + 4, deepslate, 0, 2);
		world.setBlock(i + 7, j + 27, k + 4, deepslate, 0, 2);
		world.setBlock(i + 8, j + 27, k + 4, deepslate, 0, 2);
		world.setBlock(i + 9, j + 27, k + 4, deepslate, 0, 2);
		world.setBlock(i + 10, j + 27, k + 4, deepslate, 0, 2);
		world.setBlock(i + 11, j + 27, k + 4, deepslate, 0, 2);
		world.setBlock(i + 12, j + 27, k + 4, deepslate, 0, 2);
		world.setBlock(i + 13, j + 27, k + 4, deepslate, 0, 2);
		world.setBlock(i + 14, j + 27, k + 4, deepslate, 0, 2);
		world.setBlock(i + 15, j + 27, k + 4, deepslate, 0, 2);
		world.setBlock(i + 16, j + 27, k + 4, deepslate, 0, 2);
		world.setBlock(i + 17, j + 27, k + 4, deepslate, 0, 2);
		world.setBlock(i + 18, j + 27, k + 4, deepslate, 0, 2);
		world.setBlock(i + 2, j + 27, k + 5, deepslate, 0, 2);
		world.setBlock(i + 3, j + 27, k + 5, deepslate, 0, 2);
		world.setBlock(i + 4, j + 27, k + 5, deepslate, 0, 2);
		world.setBlock(i + 5, j + 27, k + 5, deepslate, 0, 2);
		world.setBlock(i + 6, j + 27, k + 5, deepslate, 0, 2);
		world.setBlock(i + 7, j + 27, k + 5, deepslate, 0, 2);
		world.setBlock(i + 8, j + 27, k + 5, deepslate, 0, 2);
		world.setBlock(i + 9, j + 27, k + 5, deepslate, 0, 2);
		world.setBlock(i + 10, j + 27, k + 5, deepslate, 0, 2);
		world.setBlock(i + 11, j + 27, k + 5, deepslate, 0, 2);
		world.setBlock(i + 12, j + 27, k + 5, deepslate, 0, 2);
		world.setBlock(i + 13, j + 27, k + 5, deepslate, 0, 2);
		world.setBlock(i + 14, j + 27, k + 5, deepslate, 0, 2);
		world.setBlock(i + 15, j + 27, k + 5, deepslate, 0, 2);
		world.setBlock(i + 16, j + 27, k + 5, deepslate, 0, 2);
		world.setBlock(i + 17, j + 27, k + 5, deepslate, 0, 2);
		world.setBlock(i + 18, j + 27, k + 5, deepslate, 0, 2);
		world.setBlock(i + 1, j + 27, k + 6, deepslate, 0, 2);
		world.setBlock(i + 2, j + 27, k + 6, deepslate, 0, 2);
		world.setBlock(i + 3, j + 27, k + 6, deepslate, 0, 2);
		world.setBlock(i + 4, j + 27, k + 6, deepslate, 0, 2);
		world.setBlock(i + 5, j + 27, k + 6, deepslate, 0, 2);
		world.setBlock(i + 6, j + 27, k + 6, deepslate, 0, 2);
		world.setBlock(i + 7, j + 27, k + 6, deepslate, 0, 2);
		world.setBlock(i + 8, j + 27, k + 6, deepslate, 0, 2);
		world.setBlock(i + 9, j + 27, k + 6, deepslate, 0, 2);
		world.setBlock(i + 10, j + 27, k + 6, deepslate, 0, 2);
		world.setBlock(i + 11, j + 27, k + 6, deepslate, 0, 2);
		world.setBlock(i + 12, j + 27, k + 6, deepslate, 0, 2);
		world.setBlock(i + 13, j + 27, k + 6, deepslate, 0, 2);
		world.setBlock(i + 14, j + 27, k + 6, deepslate, 0, 2);
		world.setBlock(i + 15, j + 27, k + 6, deepslate, 0, 2);
		world.setBlock(i + 16, j + 27, k + 6, deepslate, 0, 2);
		world.setBlock(i + 17, j + 27, k + 6, deepslate, 0, 2);
		world.setBlock(i + 18, j + 27, k + 6, deepslate, 0, 2);
		world.setBlock(i + 1, j + 27, k + 7, deepslate, 0, 2);
		world.setBlock(i + 2, j + 27, k + 7, deepslate, 0, 2);
		world.setBlock(i + 3, j + 27, k + 7, deepslate, 0, 2);
		world.setBlock(i + 4, j + 27, k + 7, deepslate, 0, 2);
		world.setBlock(i + 5, j + 27, k + 7, deepslate, 0, 2);
		world.setBlock(i + 6, j + 27, k + 7, deepslate, 0, 2);
		world.setBlock(i + 7, j + 27, k + 7, deepslate, 0, 2);
		world.setBlock(i + 8, j + 27, k + 7, deepslate, 0, 2);
		world.setBlock(i + 9, j + 27, k + 7, deepslate, 0, 2);
		world.setBlock(i + 10, j + 27, k + 7, deepslate, 0, 2);
		world.setBlock(i + 11, j + 27, k + 7, deepslate, 0, 2);
		world.setBlock(i + 12, j + 27, k + 7, deepslate, 0, 2);
		world.setBlock(i + 13, j + 27, k + 7, deepslate, 0, 2);
		world.setBlock(i + 14, j + 27, k + 7, deepslate, 0, 2);
		world.setBlock(i + 15, j + 27, k + 7, deepslate, 0, 2);
		world.setBlock(i + 16, j + 27, k + 7, deepslate, 0, 2);
		world.setBlock(i + 17, j + 27, k + 7, deepslate, 0, 2);
		world.setBlock(i + 18, j + 27, k + 7, deepslate, 0, 2);
		world.setBlock(i + 1, j + 27, k + 8, deepslate, 0, 2);
		world.setBlock(i + 2, j + 27, k + 8, deepslate, 0, 2);
		world.setBlock(i + 3, j + 27, k + 8, deepslate, 0, 2);
		world.setBlock(i + 4, j + 27, k + 8, deepslate, 0, 2);
		world.setBlock(i + 5, j + 27, k + 8, deepslate, 0, 2);
		world.setBlock(i + 6, j + 27, k + 8, deepslate, 0, 2);
		world.setBlock(i + 7, j + 27, k + 8, deepslate, 0, 2);
		world.setBlock(i + 8, j + 27, k + 8, deepslate, 0, 2);
		world.setBlock(i + 9, j + 27, k + 8, deepslate, 0, 2);
		world.setBlock(i + 10, j + 27, k + 8, deepslate, 0, 2);
		world.setBlock(i + 11, j + 27, k + 8, deepslate, 0, 2);
		world.setBlock(i + 12, j + 27, k + 8, deepslate, 0, 2);
		world.setBlock(i + 13, j + 27, k + 8, deepslate, 0, 2);
		world.setBlock(i + 14, j + 27, k + 8, deepslate, 0, 2);
		world.setBlock(i + 15, j + 27, k + 8, deepslate, 0, 2);
		world.setBlock(i + 16, j + 27, k + 8, deepslate, 0, 2);
		world.setBlock(i + 17, j + 27, k + 8, deepslate, 0, 2);
		world.setBlock(i + 18, j + 27, k + 8, deepslate, 0, 2);
		world.setBlock(i + 19, j + 27, k + 8, deepslate, 0, 2);
		world.setBlock(i + 0, j + 27, k + 9, deepslate, 0, 2);
		world.setBlock(i + 1, j + 27, k + 9, deepslate, 0, 2);
		world.setBlock(i + 2, j + 27, k + 9, deepslate, 0, 2);
		world.setBlock(i + 3, j + 27, k + 9, deepslate, 0, 2);
		world.setBlock(i + 4, j + 27, k + 9, deepslate, 0, 2);
		world.setBlock(i + 5, j + 27, k + 9, deepslate, 0, 2);
		world.setBlock(i + 6, j + 27, k + 9, deepslate, 0, 2);
		world.setBlock(i + 7, j + 27, k + 9, deepslate, 0, 2);
		world.setBlock(i + 8, j + 27, k + 9, deepslate, 0, 2);
		world.setBlock(i + 9, j + 27, k + 9, deepslate, 0, 2);
		world.setBlock(i + 10, j + 27, k + 9, deepslate, 0, 2);
		world.setBlock(i + 11, j + 27, k + 9, deepslate, 0, 2);
		world.setBlock(i + 12, j + 27, k + 9, deepslate, 0, 2);
		world.setBlock(i + 13, j + 27, k + 9, deepslate, 0, 2);
		world.setBlock(i + 14, j + 27, k + 9, deepslate, 0, 2);
		world.setBlock(i + 15, j + 27, k + 9, deepslate, 0, 2);
		world.setBlock(i + 16, j + 27, k + 9, deepslate, 0, 2);
		world.setBlock(i + 17, j + 27, k + 9, deepslate, 0, 2);
		world.setBlock(i + 18, j + 27, k + 9, deepslate, 0, 2);
		world.setBlock(i + 19, j + 27, k + 9, deepslate, 0, 2);
		world.setBlock(i + 20, j + 27, k + 9, deepslate, 0, 2);
		world.setBlock(i + 0, j + 27, k + 10, deepslate, 0, 2);
		world.setBlock(i + 1, j + 27, k + 10, deepslate, 0, 2);
		world.setBlock(i + 2, j + 27, k + 10, deepslate, 0, 2);
		world.setBlock(i + 3, j + 27, k + 10, deepslate, 0, 2);
		world.setBlock(i + 4, j + 27, k + 10, deepslate, 0, 2);
		world.setBlock(i + 5, j + 27, k + 10, deepslate, 0, 2);
		world.setBlock(i + 6, j + 27, k + 10, deepslate, 0, 2);
		world.setBlock(i + 7, j + 27, k + 10, deepslate, 0, 2);
		world.setBlock(i + 8, j + 27, k + 10, deepslate, 0, 2);
		world.setBlock(i + 9, j + 27, k + 10, deepslate, 0, 2);
		world.setBlock(i + 10, j + 27, k + 10, deepslate, 0, 2);
		world.setBlock(i + 11, j + 27, k + 10, deepslate, 0, 2);
		world.setBlock(i + 12, j + 27, k + 10, deepslate, 0, 2);
		world.setBlock(i + 13, j + 27, k + 10, deepslate, 0, 2);
		world.setBlock(i + 14, j + 27, k + 10, deepslate, 0, 2);
		world.setBlock(i + 15, j + 27, k + 10, deepslate, 0, 2);
		world.setBlock(i + 16, j + 27, k + 10, deepslate, 0, 2);
		world.setBlock(i + 17, j + 27, k + 10, deepslate, 0, 2);
		world.setBlock(i + 18, j + 27, k + 10, deepslate, 0, 2);
		world.setBlock(i + 19, j + 27, k + 10, deepslate, 0, 2);
		world.setBlock(i + 20, j + 27, k + 10, deepslate, 0, 2);
		world.setBlock(i + 21, j + 27, k + 10, deepslate, 0, 2);
		world.setBlock(i + 0, j + 27, k + 11, deepslate, 0, 2);
		world.setBlock(i + 1, j + 27, k + 11, deepslate, 0, 2);
		world.setBlock(i + 2, j + 27, k + 11, deepslate, 0, 2);
		world.setBlock(i + 3, j + 27, k + 11, deepslate, 0, 2);
		world.setBlock(i + 4, j + 27, k + 11, deepslate, 0, 2);
		world.setBlock(i + 5, j + 27, k + 11, deepslate, 0, 2);
		world.setBlock(i + 6, j + 27, k + 11, deepslate, 0, 2);
		world.setBlock(i + 7, j + 27, k + 11, deepslate, 0, 2);
		world.setBlock(i + 8, j + 27, k + 11, deepslate, 0, 2);
		world.setBlock(i + 9, j + 27, k + 11, deepslate, 0, 2);
		world.setBlock(i + 10, j + 27, k + 11, deepslate, 0, 2);
		world.setBlock(i + 11, j + 27, k + 11, deepslate, 0, 2);
		world.setBlock(i + 12, j + 27, k + 11, deepslate, 0, 2);
		world.setBlock(i + 13, j + 27, k + 11, deepslate, 0, 2);
		world.setBlock(i + 14, j + 27, k + 11, deepslate, 0, 2);
		world.setBlock(i + 15, j + 27, k + 11, deepslate, 0, 2);
		world.setBlock(i + 16, j + 27, k + 11, deepslate, 0, 2);
		world.setBlock(i + 17, j + 27, k + 11, deepslate, 0, 2);
		world.setBlock(i + 18, j + 27, k + 11, deepslate, 0, 2);
		world.setBlock(i + 19, j + 27, k + 11, deepslate, 0, 2);
		world.setBlock(i + 20, j + 27, k + 11, deepslate, 0, 2);
		world.setBlock(i + 21, j + 27, k + 11, deepslate, 0, 2);
		world.setBlock(i + 0, j + 27, k + 12, deepslate, 0, 2);
		world.setBlock(i + 1, j + 27, k + 12, deepslate, 0, 2);
		world.setBlock(i + 2, j + 27, k + 12, deepslate, 0, 2);
		world.setBlock(i + 3, j + 27, k + 12, deepslate, 0, 2);
		world.setBlock(i + 4, j + 27, k + 12, deepslate, 0, 2);
		world.setBlock(i + 5, j + 27, k + 12, deepslate, 0, 2);
		world.setBlock(i + 6, j + 27, k + 12, deepslate, 0, 2);
		world.setBlock(i + 7, j + 27, k + 12, deepslate, 0, 2);
		world.setBlock(i + 8, j + 27, k + 12, deepslate, 0, 2);
		world.setBlock(i + 9, j + 27, k + 12, deepslate, 0, 2);
		world.setBlock(i + 10, j + 27, k + 12, deepslate, 0, 2);
		world.setBlock(i + 11, j + 27, k + 12, deepslate, 0, 2);
		world.setBlock(i + 12, j + 27, k + 12, deepslate, 0, 2);
		world.setBlock(i + 13, j + 27, k + 12, deepslate, 0, 2);
		world.setBlock(i + 14, j + 27, k + 12, deepslate, 0, 2);
		world.setBlock(i + 15, j + 27, k + 12, deepslate, 0, 2);
		world.setBlock(i + 16, j + 27, k + 12, deepslate, 0, 2);
		world.setBlock(i + 17, j + 27, k + 12, deepslate, 0, 2);
		world.setBlock(i + 18, j + 27, k + 12, deepslate, 0, 2);
		world.setBlock(i + 19, j + 27, k + 12, deepslate, 0, 2);
		world.setBlock(i + 20, j + 27, k + 12, deepslate, 0, 2);
		world.setBlock(i + 21, j + 27, k + 12, deepslate, 0, 2);
		world.setBlock(i + 0, j + 27, k + 13, deepslate, 0, 2);
		world.setBlock(i + 1, j + 27, k + 13, deepslate, 0, 2);
		world.setBlock(i + 2, j + 27, k + 13, deepslate, 0, 2);
		world.setBlock(i + 3, j + 27, k + 13, deepslate, 0, 2);
		world.setBlock(i + 4, j + 27, k + 13, deepslate, 0, 2);
		world.setBlock(i + 5, j + 27, k + 13, deepslate, 0, 2);
		world.setBlock(i + 6, j + 27, k + 13, deepslate, 0, 2);
		world.setBlock(i + 7, j + 27, k + 13, deepslate, 0, 2);
		world.setBlock(i + 8, j + 27, k + 13, deepslate, 0, 2);
		world.setBlock(i + 9, j + 27, k + 13, deepslate, 0, 2);
		world.setBlock(i + 10, j + 27, k + 13, deepslate, 0, 2);
		world.setBlock(i + 11, j + 27, k + 13, deepslate, 0, 2);
		world.setBlock(i + 12, j + 27, k + 13, deepslate, 0, 2);
		world.setBlock(i + 13, j + 27, k + 13, deepslate, 0, 2);
		world.setBlock(i + 14, j + 27, k + 13, deepslate, 0, 2);
		world.setBlock(i + 15, j + 27, k + 13, deepslate, 0, 2);
		world.setBlock(i + 16, j + 27, k + 13, deepslate, 0, 2);
		world.setBlock(i + 17, j + 27, k + 13, deepslate, 0, 2);
		world.setBlock(i + 18, j + 27, k + 13, deepslate, 0, 2);
		world.setBlock(i + 19, j + 27, k + 13, deepslate, 0, 2);
		world.setBlock(i + 20, j + 27, k + 13, deepslate, 0, 2);
		world.setBlock(i + 21, j + 27, k + 13, deepslate, 0, 2);
		world.setBlock(i + 0, j + 27, k + 14, deepslate, 0, 2);
		world.setBlock(i + 1, j + 27, k + 14, deepslate, 0, 2);
		world.setBlock(i + 2, j + 27, k + 14, deepslate, 0, 2);
		world.setBlock(i + 3, j + 27, k + 14, deepslate, 0, 2);
		world.setBlock(i + 4, j + 27, k + 14, deepslate, 0, 2);
		world.setBlock(i + 5, j + 27, k + 14, deepslate, 0, 2);
		world.setBlock(i + 6, j + 27, k + 14, deepslate, 0, 2);
		world.setBlock(i + 7, j + 27, k + 14, deepslate, 0, 2);
		world.setBlock(i + 8, j + 27, k + 14, deepslate, 0, 2);
		world.setBlock(i + 9, j + 27, k + 14, deepslate, 0, 2);
		world.setBlock(i + 10, j + 27, k + 14, deepslate, 0, 2);
		world.setBlock(i + 11, j + 27, k + 14, deepslate, 0, 2);
		world.setBlock(i + 12, j + 27, k + 14, deepslate, 0, 2);
		world.setBlock(i + 13, j + 27, k + 14, deepslate, 0, 2);
		world.setBlock(i + 14, j + 27, k + 14, deepslate, 0, 2);
		world.setBlock(i + 15, j + 27, k + 14, deepslate, 0, 2);
		world.setBlock(i + 16, j + 27, k + 14, deepslate, 0, 2);
		world.setBlock(i + 17, j + 27, k + 14, deepslate, 0, 2);
		world.setBlock(i + 18, j + 27, k + 14, deepslate, 0, 2);
		world.setBlock(i + 19, j + 27, k + 14, deepslate, 0, 2);
		world.setBlock(i + 20, j + 27, k + 14, deepslate, 0, 2);
		world.setBlock(i + 21, j + 27, k + 14, deepslate, 0, 2);
		world.setBlock(i + 0, j + 27, k + 15, deepslate, 0, 2);
		world.setBlock(i + 1, j + 27, k + 15, deepslate, 0, 2);
		world.setBlock(i + 2, j + 27, k + 15, deepslate, 0, 2);
		world.setBlock(i + 3, j + 27, k + 15, deepslate, 0, 2);
		world.setBlock(i + 4, j + 27, k + 15, deepslate, 0, 2);
		world.setBlock(i + 5, j + 27, k + 15, deepslate, 0, 2);
		world.setBlock(i + 6, j + 27, k + 15, deepslate, 0, 2);
		world.setBlock(i + 7, j + 27, k + 15, deepslate, 0, 2);
		world.setBlock(i + 8, j + 27, k + 15, deepslate, 0, 2);
		world.setBlock(i + 9, j + 27, k + 15, deepslate, 0, 2);
		world.setBlock(i + 10, j + 27, k + 15, deepslate, 0, 2);
		world.setBlock(i + 11, j + 27, k + 15, deepslate, 0, 2);
		world.setBlock(i + 12, j + 27, k + 15, deepslate, 0, 2);
		world.setBlock(i + 13, j + 27, k + 15, deepslate, 0, 2);
		world.setBlock(i + 14, j + 27, k + 15, deepslate, 0, 2);
		world.setBlock(i + 15, j + 27, k + 15, deepslate, 0, 2);
		world.setBlock(i + 16, j + 27, k + 15, deepslate, 0, 2);
		world.setBlock(i + 17, j + 27, k + 15, deepslate, 0, 2);
		world.setBlock(i + 18, j + 27, k + 15, deepslate, 0, 2);
		world.setBlock(i + 19, j + 27, k + 15, deepslate, 0, 2);
		world.setBlock(i + 20, j + 27, k + 15, deepslate, 0, 2);
		world.setBlock(i + 21, j + 27, k + 15, deepslate, 0, 2);
		world.setBlock(i + 1, j + 27, k + 16, deepslate, 0, 2);
		world.setBlock(i + 2, j + 27, k + 16, deepslate, 0, 2);
		world.setBlock(i + 3, j + 27, k + 16, deepslate, 0, 2);
		world.setBlock(i + 4, j + 27, k + 16, deepslate, 0, 2);
		world.setBlock(i + 5, j + 27, k + 16, deepslate, 0, 2);
		world.setBlock(i + 6, j + 27, k + 16, deepslate, 0, 2);
		world.setBlock(i + 7, j + 27, k + 16, deepslate, 0, 2);
		world.setBlock(i + 8, j + 27, k + 16, deepslate, 0, 2);
		world.setBlock(i + 9, j + 27, k + 16, deepslate, 0, 2);
		world.setBlock(i + 10, j + 27, k + 16, deepslate, 0, 2);
		world.setBlock(i + 11, j + 27, k + 16, deepslate, 0, 2);
		world.setBlock(i + 12, j + 27, k + 16, deepslate, 0, 2);
		world.setBlock(i + 13, j + 27, k + 16, deepslate, 0, 2);
		world.setBlock(i + 14, j + 27, k + 16, deepslate, 0, 2);
		world.setBlock(i + 15, j + 27, k + 16, deepslate, 0, 2);
		world.setBlock(i + 16, j + 27, k + 16, deepslate, 0, 2);
		world.setBlock(i + 17, j + 27, k + 16, deepslate, 0, 2);
		world.setBlock(i + 18, j + 27, k + 16, deepslate, 0, 2);
		world.setBlock(i + 19, j + 27, k + 16, deepslate, 0, 2);
		world.setBlock(i + 20, j + 27, k + 16, sculk_block, 0, 2);
		world.setBlock(i + 21, j + 27, k + 16, sculk_block, 0, 2);
		world.setBlock(i + 2, j + 27, k + 17, deepslate, 0, 2);
		world.setBlock(i + 3, j + 27, k + 17, deepslate, 0, 2);
		world.setBlock(i + 4, j + 27, k + 17, deepslate, 0, 2);
		world.setBlock(i + 5, j + 27, k + 17, sculk_block, 0, 2);
		world.setBlock(i + 6, j + 27, k + 17, sculk_block, 0, 2);
		world.setBlock(i + 7, j + 27, k + 17, sculk_block, 0, 2);
		world.setBlock(i + 8, j + 27, k + 17, sculk_block, 0, 2);
		world.setBlock(i + 9, j + 27, k + 17, sculk_block, 0, 2);
		world.setBlock(i + 10, j + 27, k + 17, sculk_block, 0, 2);
		world.setBlock(i + 11, j + 27, k + 17, sculk_block, 0, 2);
		world.setBlock(i + 12, j + 27, k + 17, sculk_block, 0, 2);
		world.setBlock(i + 13, j + 27, k + 17, sculk_block, 0, 2);
		world.setBlock(i + 14, j + 27, k + 17, sculk_block, 0, 2);
		world.setBlock(i + 15, j + 27, k + 17, sculk_block, 0, 2);
		world.setBlock(i + 16, j + 27, k + 17, sculk_block, 0, 2);
		world.setBlock(i + 17, j + 27, k + 17, sculk_block, 0, 2);
		world.setBlock(i + 18, j + 27, k + 17, sculk_block, 0, 2);
		world.setBlock(i + 19, j + 27, k + 17, sculk_block, 0, 2);
		world.setBlock(i + 3, j + 27, k + 18, sculk_block, 0, 2);
		world.setBlock(i + 4, j + 27, k + 18, sculk_block, 0, 2);
		world.setBlock(i + 3, j + 28, k + 0, deepslate, 0, 2);
		world.setBlock(i + 4, j + 28, k + 0, deepslate, 0, 2);
		world.setBlock(i + 5, j + 28, k + 0, deepslate, 0, 2);
		world.setBlock(i + 6, j + 28, k + 0, deepslate, 0, 2);
		world.setBlock(i + 7, j + 28, k + 0, deepslate, 0, 2);
		world.setBlock(i + 8, j + 28, k + 0, deepslate, 0, 2);
		world.setBlock(i + 9, j + 28, k + 0, deepslate, 0, 2);
