package com.NovaCraft.world.ancient_city;

import cpw.mods.fml.common.registry.GameRegistry;
import net.minecraft.world.gen.feature.*;
import net.minecraft.block.*;
import net.minecraft.enchantment.Enchantment;
import net.minecraft.enchantment.EnchantmentData;
import net.minecraft.world.*;
import java.util.*;

import com.NovaCraft.Items.NovaCraftItems;
import com.NovaCraft.config.Configs;
import com.NovaCraft.registry.OtherModBlocks;
import com.NovaCraft.registry.OtherModItems;
import com.NovaCraftBlocks.NovaCraftBlocks;
import com.NovaCraftBlocks.sculk.BlockSculkEndstone;

import cpw.mods.fml.common.Loader;
import net.minecraft.init.*;
import net.minecraft.item.ItemStack;
import net.minecraft.tileentity.TileEntityChest;
import net.minecraft.tileentity.TileEntityMobSpawner;
import net.minecraft.util.MathHelper;

public class AncientCitySmallRoomGen1 extends WorldGenerator
{
	public AncientCitySmallRoomGen1() {

	}
	private Block PlaceDeepslateBricks;
	private Block PlaceDeepslateTiles;
	private Block PlaceCrackedDeepslateTiles;
	private Block PlaceCrackedDeepslateBricks;
	private Block PlaceChiseledDeepslate;
	private Block PlaceCobbledDeepslate;

	private Block determineIfCobbledDeepslateExists(World world, int x, int y, int z) {
		Block existingBlock = world.getBlock(x, y, z);
		if (Configs.enableCobbledDeepslateInAncientCity && Loader.isModLoaded("etfuturum")) {
			try {
				Block cobbled_deepslate = GameRegistry.findBlock("etfuturum", "cobbled_deepslate");
				if (cobbled_deepslate != null && (existingBlock == null || existingBlock != cobbled_deepslate)) {
					return cobbled_deepslate;
				}
			} catch (Exception ex) {
				if (Configs.enableDebugMode) {
					System.out.println("Missing Cobbled Deepslate from Et Futurum Requiem, using Cobbled Grimstone instead...");
				}
				return NovaCraftBlocks.cobbled_grimstone;
			}
		}

		return NovaCraftBlocks.cobbled_grimstone;
	}

	private Block determineIfDeepslateBricksExists(World world, int x, int y, int z) {
		Block existingBlock = world.getBlock(x, y, z);
		if (Configs.enableDeepslateBricksInAncientCity && Loader.isModLoaded("etfuturum")) {
			try {
				Block deepslate_bricks = GameRegistry.findBlock("etfuturum", "deepslate_bricks");
				if (deepslate_bricks != null && (existingBlock == null || existingBlock != deepslate_bricks)) {
					return deepslate_bricks;
				}
			} catch (Exception ex) {
				if (Configs.enableDebugMode) {
					System.out.println("Missing Deepslate Bricks from Et Futurum Requiem, using Grimstone Bricks instead...");
				}
				return NovaCraftBlocks.grimstone_bricks;
			}
		}

		return NovaCraftBlocks.grimstone_bricks;
	}

	private Block determineIfCrackedDeepslateBricksExists(World world, int x, int y, int z) {
		Block existingBlock = world.getBlock(x, y, z);
		if (Configs.enableDeepslateBricksInAncientCity && Loader.isModLoaded("etfuturum")) {
			try {
				Block deepslate_bricks = GameRegistry.findBlock("etfuturum", "deepslate_bricks");
				if (deepslate_bricks != null && (existingBlock == null || existingBlock != deepslate_bricks)) {
					return deepslate_bricks;
				}
			} catch (Exception ex) {
				if (Configs.enableDebugMode) {
					System.out.println("Missing Cracked Deepslate Bricks from Et Futurum Requiem, using Cracked Grimstone Bricks instead...");
				}
				return NovaCraftBlocks.cracked_grimstone_bricks;
			}
		}

		return NovaCraftBlocks.cracked_grimstone_bricks;
	}

	private Block determineIfDeepslateTilesExist(World world, int x, int y, int z) {
		Block existingBlock = world.getBlock(x, y, z);
		if (Configs.enableDeepslateBricksInAncientCity && Loader.isModLoaded("etfuturum")) {
			try {
				Block deepslate_bricks = GameRegistry.findBlock("etfuturum", "deepslate_bricks");
				if (deepslate_bricks != null && (existingBlock == null || existingBlock != deepslate_bricks)) {
					return deepslate_bricks;
				}
			} catch (Exception ex) {
				if (Configs.enableDebugMode) {
					System.out.println("Missing Deepslate Tiles from Et Futurum Requiem, using Grimstone Tiles instead...");
				}
				return NovaCraftBlocks.grimstone_tiles;
			}
		}

		return NovaCraftBlocks.grimstone_tiles;
	}

	private Block determineIfCrackedDeepslateTilesExist(World world, int x, int y, int z) {
		Block existingBlock = world.getBlock(x, y, z);
		if (Configs.enableDeepslateBricksInAncientCity && Loader.isModLoaded("etfuturum")) {
			try {
				Block deepslate_bricks = GameRegistry.findBlock("etfuturum", "deepslate_bricks");
				if (deepslate_bricks != null && (existingBlock == null || existingBlock != deepslate_bricks)) {
					return deepslate_bricks;
				}
			} catch (Exception ex) {
				if (Configs.enableDebugMode) {
					System.out.println("Missing Cracked Deepslate Tiles from Et Futurum Requiem, using Cracked Grimstone Tiles instead...");
				}
				return NovaCraftBlocks.cracked_grimstone_tiles;
			}
		}

		return NovaCraftBlocks.cracked_grimstone_tiles;
	}

	private Block determineIfChiseledDeepslateExist(World world, int x, int y, int z) {
		Block existingBlock = world.getBlock(x, y, z);
		if (Configs.enableDeepslateBricksInAncientCity && Loader.isModLoaded("etfuturum")) {
			try {
				Block deepslate_bricks = GameRegistry.findBlock("etfuturum", "deepslate_bricks");
				if (deepslate_bricks != null && (existingBlock == null || existingBlock != deepslate_bricks)) {
					return deepslate_bricks;
				}
			} catch (Exception ex) {
				if (Configs.enableDebugMode) {
					System.out.println("Missing Chiseled Deepslate from Et Futurum Requiem, using Chiseled Grimstone instead...");
				}
				return NovaCraftBlocks.chiseled_grimstone;
			}
		}

		return NovaCraftBlocks.chiseled_grimstone;
	}
    
    public boolean generate(final World world, final Random random, final int i, final int j, final int k) {
    	PlaceCobbledDeepslate = determineIfCobbledDeepslateExists(world, i + 1, j + 0, k + 3);
    	PlaceDeepslateBricks = determineIfDeepslateBricksExists(world, i + 16, j + 0, k + 1);
    	PlaceCrackedDeepslateBricks = determineIfCrackedDeepslateBricksExists(world, i + 3, j + 0, k + 2);
    	PlaceDeepslateTiles = determineIfDeepslateTilesExist(world, i + 15, j + 0, k + 7);
    	PlaceCrackedDeepslateTiles = determineIfCrackedDeepslateTilesExist(world, i + 16, j + 0, k + 8);
    	PlaceChiseledDeepslate = determineIfChiseledDeepslateExist(world, i + 15, j + 1, k + 5);
    	
    	world.setBlock(i + 0, j + 0, k + 0, Blocks.air, 0, 2);
		world.setBlock(i + 1, j + 0, k + 0, Blocks.air, 0, 2);
		world.setBlock(i + 2, j + 0, k + 0, Blocks.air, 0, 2);
		world.setBlock(i + 3, j + 0, k + 0, Blocks.air, 0, 2);
		world.setBlock(i + 4, j + 0, k + 0, Blocks.air, 0, 2);
		world.setBlock(i + 5, j + 0, k + 0, Blocks.air, 0, 2);
		world.setBlock(i + 6, j + 0, k + 0, Blocks.air, 0, 2);
		world.setBlock(i + 7, j + 0, k + 0, Blocks.air, 0, 2);
		world.setBlock(i + 8, j + 0, k + 0, Blocks.air, 0, 2);
		world.setBlock(i + 9, j + 0, k + 0, Blocks.air, 0, 2);
		world.setBlock(i + 10, j + 0, k + 0, Blocks.air, 0, 2);
		world.setBlock(i + 11, j + 0, k + 0, Blocks.air, 0, 2);
		world.setBlock(i + 12, j + 0, k + 0, Blocks.air, 0, 2);
		world.setBlock(i + 13, j + 0, k + 0, Blocks.air, 0, 2);
		world.setBlock(i + 14, j + 0, k + 0, Blocks.air, 0, 2);
		world.setBlock(i + 15, j + 0, k + 0, Blocks.air, 0, 2);
		world.setBlock(i + 16, j + 0, k + 0, Blocks.air, 0, 2);
		world.setBlock(i + 17, j + 0, k + 0, Blocks.air, 0, 2);
		world.setBlock(i + 18, j + 0, k + 0, Blocks.air, 0, 2);
		world.setBlock(i + 19, j + 0, k + 0, Blocks.air, 0, 2);
		world.setBlock(i + 0, j + 0, k + 1, Blocks.air, 0, 2);
		world.setBlock(i + 1, j + 0, k + 1, Blocks.air, 0, 2);
		world.setBlock(i + 2, j + 0, k + 1, Blocks.air, 0, 2);
		world.setBlock(i + 3, j + 0, k + 1, Blocks.air, 0, 2);
		world.setBlock(i + 4, j + 0, k + 1, Blocks.air, 0, 2);
		world.setBlock(i + 5, j + 0, k + 1, Blocks.air, 0, 2);
		world.setBlock(i + 6, j + 0, k + 1, Blocks.air, 0, 2);
		world.setBlock(i + 7, j + 0, k + 1, Blocks.air, 0, 2);
		world.setBlock(i + 8, j + 0, k + 1, Blocks.air, 0, 2);
		world.setBlock(i + 9, j + 0, k + 1, Blocks.air, 0, 2);
		world.setBlock(i + 10, j + 0, k + 1, Blocks.air, 0, 2);
		world.setBlock(i + 11, j + 0, k + 1, Blocks.air, 0, 2);
		world.setBlock(i + 12, j + 0, k + 1, Blocks.air, 0, 2);
		world.setBlock(i + 13, j + 0, k + 1, Blocks.air, 0, 2);
		world.setBlock(i + 14, j + 0, k + 1, Blocks.air, 0, 2);
		world.setBlock(i + 15, j + 0, k + 1, Blocks.air, 0, 2);
		world.setBlock(i + 16, j + 0, k + 1, PlaceDeepslateBricks, 0, 2);
		world.setBlock(i + 17, j + 0, k + 1, PlaceDeepslateBricks, 0, 2);
		world.setBlock(i + 18, j + 0, k + 1, PlaceDeepslateBricks, 0, 2);
		world.setBlock(i + 19, j + 0, k + 1, Blocks.air, 0, 2);
		world.setBlock(i + 0, j + 0, k + 2, Blocks.air, 0, 2);
		world.setBlock(i + 1, j + 0, k + 2, Blocks.air, 0, 2);
		world.setBlock(i + 2, j + 0, k + 2, PlaceDeepslateBricks, 0, 2);
		world.setBlock(i + 3, j + 0, k + 2, PlaceCrackedDeepslateBricks, 1, 2);
		world.setBlock(i + 4, j + 0, k + 2, PlaceCrackedDeepslateBricks, 1, 2);
		world.setBlock(i + 5, j + 0, k + 2, PlaceDeepslateBricks, 0, 2);
		world.setBlock(i + 6, j + 0, k + 2, Blocks.air, 0, 2);
		world.setBlock(i + 7, j + 0, k + 2, PlaceCrackedDeepslateBricks, 1, 2);
		world.setBlock(i + 8, j + 0, k + 2, PlaceCrackedDeepslateBricks, 1, 2);
		world.setBlock(i + 9, j + 0, k + 2, PlaceCrackedDeepslateBricks, 1, 2);
		world.setBlock(i + 10, j + 0, k + 2, PlaceDeepslateBricks, 0, 2);
		world.setBlock(i + 11, j + 0, k + 2, PlaceCrackedDeepslateBricks, 1, 2);
		world.setBlock(i + 12, j + 0, k + 2, PlaceCrackedDeepslateBricks, 1, 2);
		world.setBlock(i + 13, j + 0, k + 2, PlaceDeepslateBricks, 0, 2);
		world.setBlock(i + 14, j + 0, k + 2, PlaceDeepslateBricks, 0, 2);
		world.setBlock(i + 15, j + 0, k + 2, PlaceCrackedDeepslateBricks, 1, 2);
		world.setBlock(i + 16, j + 0, k + 2, PlaceDeepslateBricks, 0, 2);
		world.setBlock(i + 17, j + 0, k + 2, PlaceCrackedDeepslateBricks, 1, 2);
		world.setBlock(i + 18, j + 0, k + 2, PlaceCrackedDeepslateBricks, 1, 2);
		world.setBlock(i + 19, j + 0, k + 2, Blocks.air, 0, 2);
		world.setBlock(i + 0, j + 0, k + 3, Blocks.air, 0, 2);
		world.setBlock(i + 1, j + 0, k + 3, PlaceCobbledDeepslate, 0, 2);
		world.setBlock(i + 2, j + 0, k + 3, PlaceCobbledDeepslate, 0, 2);
		world.setBlock(i + 3, j + 0, k + 3, PlaceCobbledDeepslate, 0, 2);
		world.setBlock(i + 4, j + 0, k + 3, PlaceCobbledDeepslate, 0, 2);
		world.setBlock(i + 5, j + 0, k + 3, PlaceCobbledDeepslate, 0, 2);
		world.setBlock(i + 6, j + 0, k + 3, PlaceCobbledDeepslate, 0, 2);
		world.setBlock(i + 7, j + 0, k + 3, PlaceCobbledDeepslate, 0, 2);
		world.setBlock(i + 8, j + 0, k + 3, PlaceCobbledDeepslate, 0, 2);
		world.setBlock(i + 9, j + 0, k + 3, PlaceCobbledDeepslate, 0, 2);
		world.setBlock(i + 10, j + 0, k + 3, PlaceCobbledDeepslate, 0, 2);
		world.setBlock(i + 11, j + 0, k + 3, PlaceCobbledDeepslate, 0, 2);
		world.setBlock(i + 12, j + 0, k + 3, Blocks.air, 0, 2);
		world.setBlock(i + 13, j + 0, k + 3, PlaceCobbledDeepslate, 0, 2);
		world.setBlock(i + 14, j + 0, k + 3, PlaceCobbledDeepslate, 0, 2);
		world.setBlock(i + 15, j + 0, k + 3, PlaceCobbledDeepslate, 0, 2);
		world.setBlock(i + 16, j + 0, k + 3, PlaceCrackedDeepslateBricks, 1, 2);
		world.setBlock(i + 17, j + 0, k + 3, Blocks.air, 0, 2);
		world.setBlock(i + 18, j + 0, k + 3, Blocks.air, 0, 2);
		world.setBlock(i + 19, j + 0, k + 3, Blocks.air, 0, 2);
		world.setBlock(i + 0, j + 0, k + 4, Blocks.air, 0, 2);
		world.setBlock(i + 1, j + 0, k + 4, Blocks.air, 0, 2);
		world.setBlock(i + 2, j + 0, k + 4, PlaceCobbledDeepslate, 0, 2);
		world.setBlock(i + 3, j + 0, k + 4, NovaCraftBlocks.sculk_vein, 0, 2);
		world.setBlock(i + 4, j + 0, k + 4, Blocks.air, 0, 2);
		world.setBlock(i + 5, j + 0, k + 4, Blocks.air, 0, 2);
		world.setBlock(i + 6, j + 0, k + 4, Blocks.air, 0, 2);
		world.setBlock(i + 7, j + 0, k + 4, Blocks.air, 0, 2);
		world.setBlock(i + 8, j + 0, k + 4, PlaceDeepslateBricks, 0, 2);
		world.setBlock(i + 9, j + 0, k + 4, PlaceDeepslateBricks, 0, 2);
		world.setBlock(i + 10, j + 0, k + 4, PlaceCobbledDeepslate, 0, 2);
		world.setBlock(i + 11, j + 0, k + 4, PlaceCobbledDeepslate, 0, 2);
		world.setBlock(i + 12, j + 0, k + 4, PlaceCobbledDeepslate, 0, 2);
		world.setBlock(i + 13, j + 0, k + 4, PlaceCobbledDeepslate, 0, 2);
		world.setBlock(i + 14, j + 0, k + 4, PlaceCobbledDeepslate, 0, 2);
		world.setBlock(i + 15, j + 0, k + 4, PlaceCobbledDeepslate, 0, 2);
		world.setBlock(i + 16, j + 0, k + 4, PlaceDeepslateBricks, 0, 2);
		world.setBlock(i + 17, j + 0, k + 4, Blocks.air, 0, 2);
		world.setBlock(i + 18, j + 0, k + 4, Blocks.air, 0, 2);
		world.setBlock(i + 19, j + 0, k + 4, Blocks.air, 0, 2);
		world.setBlock(i + 0, j + 0, k + 5, Blocks.air, 0, 2);
		world.setBlock(i + 1, j + 0, k + 5, PlaceCobbledDeepslate, 0, 2);
		world.setBlock(i + 2, j + 0, k + 5, PlaceCobbledDeepslate, 0, 2);
		world.setBlock(i + 3, j + 0, k + 5, Blocks.air, 0, 2);
		world.setBlock(i + 4, j + 0, k + 5, PlaceCrackedDeepslateBricks, 1, 2);
		world.setBlock(i + 5, j + 0, k + 5, PlaceDeepslateBricks, 0, 2);
		world.setBlock(i + 6, j + 0, k + 5, PlaceCrackedDeepslateBricks, 1, 2);
		world.setBlock(i + 7, j + 0, k + 5, Blocks.air, 0, 2);
		world.setBlock(i + 8, j + 0, k + 5, PlaceDeepslateBricks, 0, 2);
		world.setBlock(i + 9, j + 0, k + 5, PlaceDeepslateBricks, 0, 2);
		world.setBlock(i + 10, j + 0, k + 5, PlaceCobbledDeepslate, 0, 2);
		world.setBlock(i + 11, j + 0, k + 5, PlaceCobbledDeepslate, 0, 2);
		world.setBlock(i + 12, j + 0, k + 5, PlaceCobbledDeepslate, 0, 2);
		world.setBlock(i + 13, j + 0, k + 5, PlaceCobbledDeepslate, 0, 2);
		world.setBlock(i + 14, j + 0, k + 5, NovaCraftBlocks.sculk_vein, 4, 2);
		world.setBlock(i + 15, j + 0, k + 5, PlaceCobbledDeepslate, 0, 2);
		world.setBlock(i + 16, j + 0, k + 5, PlaceDeepslateBricks, 0, 2);
		world.setBlock(i + 17, j + 0, k + 5, Blocks.air, 0, 2);
		world.setBlock(i + 18, j + 0, k + 5, Blocks.air, 0, 2);
		world.setBlock(i + 19, j + 0, k + 5, PlaceCobbledDeepslate, 0, 2);
		world.setBlock(i + 0, j + 0, k + 6, Blocks.air, 0, 2);
		world.setBlock(i + 1, j + 0, k + 6, PlaceCobbledDeepslate, 0, 2);
		world.setBlock(i + 2, j + 0, k + 6, PlaceCobbledDeepslate, 0, 2);
		world.setBlock(i + 3, j + 0, k + 6, PlaceDeepslateBricks, 0, 2);
		world.setBlock(i + 4, j + 0, k + 6, PlaceCobbledDeepslate, 0, 2);
		world.setBlock(i + 5, j + 0, k + 6, PlaceCobbledDeepslate, 0, 2);
		world.setBlock(i + 6, j + 0, k + 6, PlaceDeepslateBricks, 0, 2);
		world.setBlock(i + 7, j + 0, k + 6, PlaceDeepslateBricks, 0, 2);
		world.setBlock(i + 8, j + 0, k + 6, NovaCraftBlocks.sculk_block, 0, 2);
		world.setBlock(i + 9, j + 0, k + 6, NovaCraftBlocks.sculk_block, 0, 2);
		world.setBlock(i + 10, j + 0, k + 6, NovaCraftBlocks.sculk_block, 0, 2);
		world.setBlock(i + 11, j + 0, k + 6, PlaceDeepslateBricks, 0, 2);
		world.setBlock(i + 12, j + 0, k + 6, PlaceCobbledDeepslate, 0, 2);
		world.setBlock(i + 13, j + 0, k + 6, NovaCraftBlocks.sculk_block, 0, 2);
		world.setBlock(i + 14, j + 0, k + 6, Blocks.air, 0, 2);
		world.setBlock(i + 15, j + 0, k + 6, NovaCraftBlocks.sculk_block, 0, 2);
		world.setBlock(i + 16, j + 0, k + 6, NovaCraftBlocks.sculk_vein, 3, 2);
		world.setBlock(i + 17, j + 0, k + 6, Blocks.air, 0, 2);
		world.setBlock(i + 18, j + 0, k + 6, Blocks.air, 0, 2);
		world.setBlock(i + 19, j + 0, k + 6, Blocks.air, 0, 2);
		world.setBlock(i + 0, j + 0, k + 7, Blocks.air, 0, 2);
		world.setBlock(i + 1, j + 0, k + 7, PlaceCobbledDeepslate, 0, 2);
		world.setBlock(i + 2, j + 0, k + 7, PlaceDeepslateBricks, 0, 2);
		world.setBlock(i + 3, j + 0, k + 7, PlaceDeepslateBricks, 0, 2);
		world.setBlock(i + 4, j + 0, k + 7, NovaCraftBlocks.sculk_block, 0, 2);
		world.setBlock(i + 5, j + 0, k + 7, PlaceDeepslateBricks, 0, 2);
		world.setBlock(i + 6, j + 0, k + 7, PlaceCrackedDeepslateBricks, 1, 2);
		world.setBlock(i + 7, j + 0, k + 7, NovaCraftBlocks.sculk_block, 0, 2);
		world.setBlock(i + 8, j + 0, k + 7, NovaCraftBlocks.sculk_block, 0, 2);
		world.setBlock(i + 9, j + 0, k + 7, NovaCraftBlocks.sculk_block, 0, 2);
		world.setBlock(i + 10, j + 0, k + 7, NovaCraftBlocks.sculk_block, 0, 2);
		world.setBlock(i + 11, j + 0, k + 7, NovaCraftBlocks.sculk_block, 0, 2);
		world.setBlock(i + 12, j + 0, k + 7, NovaCraftBlocks.sculk_vein, 3, 2);
		world.setBlock(i + 13, j + 0, k + 7, NovaCraftBlocks.sculk_block, 0, 2);
		world.setBlock(i + 14, j + 0, k + 7, NovaCraftBlocks.sculk_vein, 4, 2);
		world.setBlock(i + 15, j + 0, k + 7, PlaceDeepslateTiles, 2, 2);
		world.setBlock(i + 16, j + 0, k + 7, NovaCraftBlocks.sculk_block, 0, 2);
		world.setBlock(i + 17, j + 0, k + 7, Blocks.air, 0, 2);
		world.setBlock(i + 18, j + 0, k + 7, Blocks.air, 0, 2);
		world.setBlock(i + 19, j + 0, k + 7, Blocks.air, 0, 2);
		world.setBlock(i + 0, j + 0, k + 8, Blocks.air, 0, 2);
		world.setBlock(i + 1, j + 0, k + 8, NovaCraftBlocks.sculk_vein, 3, 2);
		world.setBlock(i + 2, j + 0, k + 8, NovaCraftBlocks.sculk_block, 0, 2);
		world.setBlock(i + 3, j + 0, k + 8, NovaCraftBlocks.sculk_vein, 3, 2);
		world.setBlock(i + 4, j + 0, k + 8, Blocks.air, 0, 2);
		world.setBlock(i + 5, j + 0, k + 8, NovaCraftBlocks.sculk_block, 0, 2);
		world.setBlock(i + 6, j + 0, k + 8, NovaCraftBlocks.sculk_block, 0, 2);
		world.setBlock(i + 7, j + 0, k + 8, NovaCraftBlocks.sculk_block, 0, 2);
		world.setBlock(i + 8, j + 0, k + 8, NovaCraftBlocks.sculk_block, 0, 2);
		world.setBlock(i + 9, j + 0, k + 8, NovaCraftBlocks.sculk_block, 0, 2);
		world.setBlock(i + 10, j + 0, k + 8, NovaCraftBlocks.sculk_block, 0, 2);
		world.setBlock(i + 11, j + 0, k + 8, NovaCraftBlocks.sculk_block, 0, 2);
		world.setBlock(i + 12, j + 0, k + 8, NovaCraftBlocks.sculk_block, 0, 2);
		world.setBlock(i + 13, j + 0, k + 8, NovaCraftBlocks.sculk_block, 0, 2);
		world.setBlock(i + 14, j + 0, k + 8, NovaCraftBlocks.sculk_vein, 4, 2);
		world.setBlock(i + 15, j + 0, k + 8, PlaceDeepslateTiles, 2, 2);
		world.setBlock(i + 16, j + 0, k + 8, PlaceCrackedDeepslateTiles, 3, 2);
		world.setBlock(i + 17, j + 0, k + 8, NovaCraftBlocks.sculk_vein, 5, 2);
		world.setBlock(i + 18, j + 0, k + 8, Blocks.air, 0, 2);
		world.setBlock(i + 19, j + 0, k + 8, Blocks.air, 0, 2);
		world.setBlock(i + 0, j + 0, k + 9, Blocks.air, 0, 2);
		world.setBlock(i + 1, j + 0, k + 9, PlaceCobbledDeepslate, 0, 2);
		world.setBlock(i + 2, j + 0, k + 9, PlaceDeepslateBricks, 0, 2);
		world.setBlock(i + 3, j + 0, k + 9, PlaceCrackedDeepslateBricks, 1, 2);
		world.setBlock(i + 4, j + 0, k + 9, NovaCraftBlocks.sculk_block, 0, 2);
		world.setBlock(i + 5, j + 0, k + 9, NovaCraftBlocks.sculk_block, 0, 2);
		world.setBlock(i + 6, j + 0, k + 9, NovaCraftBlocks.sculk_block, 0, 2);
		world.setBlock(i + 7, j + 0, k + 9, NovaCraftBlocks.sculk_block, 0, 2);
		world.setBlock(i + 8, j + 0, k + 9, NovaCraftBlocks.sculk_block, 0, 2);
		world.setBlock(i + 9, j + 0, k + 9, NovaCraftBlocks.sculk_block, 0, 2);
		world.setBlock(i + 10, j + 0, k + 9, Blocks.air, 0, 2);
		world.setBlock(i + 11, j + 0, k + 9, NovaCraftBlocks.sculk_block, 0, 2);
		world.setBlock(i + 12, j + 0, k + 9, PlaceCrackedDeepslateBricks, 1, 2);
		world.setBlock(i + 13, j + 0, k + 9, PlaceCobbledDeepslate, 0, 2);
		world.setBlock(i + 14, j + 0, k + 9, NovaCraftBlocks.sculk_vein, 4, 2);
		world.setBlock(i + 15, j + 0, k + 9, PlaceDeepslateTiles, 2, 2);
		world.setBlock(i + 16, j + 0, k + 9, NovaCraftBlocks.sculk_block, 0, 2);
		world.setBlock(i + 17, j + 0, k + 9, Blocks.air, 0, 2);
		world.setBlock(i + 18, j + 0, k + 9, Blocks.air, 0, 2);
		world.setBlock(i + 19, j + 0, k + 9, Blocks.air, 0, 2);
		world.setBlock(i + 0, j + 0, k + 10, NovaCraftBlocks.sculk_vein, 4, 2);
		world.setBlock(i + 1, j + 0, k + 10, PlaceCobbledDeepslate, 0, 2);
		world.setBlock(i + 2, j + 0, k + 10, PlaceCobbledDeepslate, 0, 2);
		world.setBlock(i + 3, j + 0, k + 10, PlaceDeepslateBricks, 0, 2);
		world.setBlock(i + 4, j + 0, k + 10, NovaCraftBlocks.sculk_block, 0, 2);
		world.setBlock(i + 5, j + 0, k + 10, NovaCraftBlocks.sculk_block, 0, 2);
		world.setBlock(i + 6, j + 0, k + 10, NovaCraftBlocks.sculk_block, 0, 2);
		world.setBlock(i + 7, j + 0, k + 10, NovaCraftBlocks.sculk_block, 0, 2);
		world.setBlock(i + 8, j + 0, k + 10, NovaCraftBlocks.sculk_block, 0, 2);
		world.setBlock(i + 9, j + 0, k + 10, NovaCraftBlocks.sculk_block, 0, 2);
		world.setBlock(i + 10, j + 0, k + 10, NovaCraftBlocks.sculk_block, 0, 2);
		world.setBlock(i + 11, j + 0, k + 10, PlaceDeepslateBricks, 0, 2);
		world.setBlock(i + 12, j + 0, k + 10, PlaceCrackedDeepslateBricks, 1, 2);
		world.setBlock(i + 13, j + 0, k + 10, NovaCraftBlocks.sculk_block, 0, 2);
		world.setBlock(i + 14, j + 0, k + 10, Blocks.air, 0, 2);
		world.setBlock(i + 15, j + 0, k + 10, NovaCraftBlocks.sculk_block, 0, 2);
		world.setBlock(i + 16, j + 0, k + 10, NovaCraftBlocks.sculk_block, 0, 2);
		world.setBlock(i + 17, j + 0, k + 10, NovaCraftBlocks.sculk_block, 0, 2);
		world.setBlock(i + 18, j + 0, k + 10, Blocks.air, 0, 2);
		world.setBlock(i + 19, j + 0, k + 10, PlaceCobbledDeepslate, 0, 2);
		world.setBlock(i + 0, j + 0, k + 11, Blocks.air, 0, 2);
		world.setBlock(i + 1, j + 0, k + 11, NovaCraftBlocks.sculk_block, 0, 2);
		world.setBlock(i + 2, j + 0, k + 11, NovaCraftBlocks.sculk_block, 0, 2);
		world.setBlock(i + 3, j + 0, k + 11, NovaCraftBlocks.sculk_block, 0, 2);
		world.setBlock(i + 4, j + 0, k + 11, NovaCraftBlocks.sculk_block, 0, 2);
		world.setBlock(i + 5, j + 0, k + 11, NovaCraftBlocks.sculk_block, 0, 2);
		world.setBlock(i + 6, j + 0, k + 11, NovaCraftBlocks.sculk_block, 0, 2);
		world.setBlock(i + 7, j + 0, k + 11, NovaCraftBlocks.sculk_block, 0, 2);
		world.setBlock(i + 8, j + 0, k + 11, NovaCraftBlocks.sculk_block, 0, 2);
		world.setBlock(i + 9, j + 0, k + 11, NovaCraftBlocks.sculk_block, 0, 2);
		world.setBlock(i + 10, j + 0, k + 11, PlaceDeepslateBricks, 0, 2);
		world.setBlock(i + 11, j + 0, k + 11, PlaceCrackedDeepslateBricks, 1, 2);
		world.setBlock(i + 12, j + 0, k + 11, PlaceDeepslateBricks, 0, 2);
		world.setBlock(i + 13, j + 0, k + 11, PlaceCobbledDeepslate, 0, 2);
		world.setBlock(i + 14, j + 0, k + 11, NovaCraftBlocks.sculk_block, 0, 2);
		world.setBlock(i + 15, j + 0, k + 11, NovaCraftBlocks.sculk_block, 0, 2);
		world.setBlock(i + 16, j + 0, k + 11, Blocks.air, 0, 2);
		world.setBlock(i + 17, j + 0, k + 11, Blocks.air, 0, 2);
		world.setBlock(i + 18, j + 0, k + 11, Blocks.air, 0, 2);
		world.setBlock(i + 19, j + 0, k + 11, Blocks.air, 0, 2);
		world.setBlock(i + 0, j + 0, k + 12, NovaCraftBlocks.sculk_vein, 4, 2);
		world.setBlock(i + 1, j + 0, k + 12, PlaceCobbledDeepslate, 0, 2);
		world.setBlock(i + 2, j + 0, k + 12, PlaceCobbledDeepslate, 0, 2);
		world.setBlock(i + 3, j + 0, k + 12, PlaceCobbledDeepslate, 0, 2);
		world.setBlock(i + 4, j + 0, k + 12, NovaCraftBlocks.sculk_block, 0, 2);
		world.setBlock(i + 5, j + 0, k + 12, NovaCraftBlocks.sculk_block, 0, 2);
		world.setBlock(i + 6, j + 0, k + 12, NovaCraftBlocks.sculk_block, 0, 2);
		world.setBlock(i + 7, j + 0, k + 12, NovaCraftBlocks.sculk_block, 0, 2);
		world.setBlock(i + 8, j + 0, k + 12, Blocks.air, 0, 2);
		world.setBlock(i + 9, j + 0, k + 12, NovaCraftBlocks.sculk_block, 0, 2);
		world.setBlock(i + 10, j + 0, k + 12, PlaceDeepslateBricks, 0, 2);
		world.setBlock(i + 11, j + 0, k + 12, PlaceDeepslateBricks, 0, 2);
		world.setBlock(i + 12, j + 0, k + 12, PlaceDeepslateBricks, 0, 2);
		world.setBlock(i + 13, j + 0, k + 12, PlaceCobbledDeepslate, 0, 2);
		world.setBlock(i + 14, j + 0, k + 12, PlaceCobbledDeepslate, 0, 2);
		world.setBlock(i + 15, j + 0, k + 12, NovaCraftBlocks.sculk_vein, 5, 2);
		world.setBlock(i + 16, j + 0, k + 12, NovaCraftBlocks.sculk_block, 0, 2);
		world.setBlock(i + 17, j + 0, k + 12, Blocks.air, 0, 2);
		world.setBlock(i + 18, j + 0, k + 12, Blocks.air, 0, 2);
		world.setBlock(i + 19, j + 0, k + 12, Blocks.air, 0, 2);
		world.setBlock(i + 0, j + 0, k + 13, Blocks.air, 0, 2);
		world.setBlock(i + 1, j + 0, k + 13, PlaceCobbledDeepslate, 0, 2);
		world.setBlock(i + 2, j + 0, k + 13, PlaceCobbledDeepslate, 0, 2);
		world.setBlock(i + 3, j + 0, k + 13, Blocks.air, 0, 2);
		world.setBlock(i + 4, j + 0, k + 13, PlaceCrackedDeepslateBricks, 1, 2);
		world.setBlock(i + 5, j + 0, k + 13, NovaCraftBlocks.sculk_block, 0, 2);
		world.setBlock(i + 6, j + 0, k + 13, PlaceCobbledDeepslate, 0, 2);
		world.setBlock(i + 7, j + 0, k + 13, NovaCraftBlocks.sculk_vein, 4, 2);
		world.setBlock(i + 8, j + 0, k + 13, NovaCraftBlocks.sculk_block, 0, 2);
		world.setBlock(i + 9, j + 0, k + 13, PlaceCobbledDeepslate, 0, 2);
		world.setBlock(i + 10, j + 0, k + 13, PlaceCobbledDeepslate, 0, 2);
		world.setBlock(i + 11, j + 0, k + 13, PlaceCobbledDeepslate, 0, 2);
		world.setBlock(i + 12, j + 0, k + 13, PlaceCobbledDeepslate, 0, 2);
		world.setBlock(i + 13, j + 0, k + 13, Blocks.air, 0, 2);
		world.setBlock(i + 14, j + 0, k + 13, PlaceCobbledDeepslate, 0, 2);
		world.setBlock(i + 15, j + 0, k + 13, NovaCraftBlocks.sculk_block, 0, 2);
		world.setBlock(i + 16, j + 0, k + 13, NovaCraftBlocks.sculk_block, 0, 2);
		world.setBlock(i + 17, j + 0, k + 13, Blocks.air, 0, 2);
		world.setBlock(i + 18, j + 0, k + 13, Blocks.air, 0, 2);
		world.setBlock(i + 19, j + 0, k + 13, Blocks.air, 0, 2);
		world.setBlock(i + 0, j + 0, k + 14, Blocks.air, 0, 2);
		world.setBlock(i + 1, j + 0, k + 14, PlaceDeepslateBricks, 0, 2);
		world.setBlock(i + 2, j + 0, k + 14, PlaceDeepslateBricks, 0, 2);
		world.setBlock(i + 3, j + 0, k + 14, PlaceDeepslateBricks, 0, 2);
		world.setBlock(i + 4, j + 0, k + 14, PlaceDeepslateBricks, 0, 2);
		world.setBlock(i + 5, j + 0, k + 14, NovaCraftBlocks.sculk_vein, 4, 2);
		world.setBlock(i + 6, j + 0, k + 14, PlaceDeepslateBricks, 0, 2);
		world.setBlock(i + 7, j + 0, k + 14, PlaceDeepslateBricks, 0, 2);
		world.setBlock(i + 8, j + 0, k + 14, PlaceDeepslateBricks, 0, 2);
		world.setBlock(i + 9, j + 0, k + 14, PlaceDeepslateBricks, 0, 2);
		world.setBlock(i + 10, j + 0, k + 14, PlaceDeepslateBricks, 0, 2);
		world.setBlock(i + 11, j + 0, k + 14, PlaceCrackedDeepslateBricks, 1, 2);
		world.setBlock(i + 12, j + 0, k + 14, PlaceDeepslateBricks, 0, 2);
		world.setBlock(i + 13, j + 0, k + 14, PlaceDeepslateBricks, 0, 2);
		world.setBlock(i + 14, j + 0, k + 14, PlaceCrackedDeepslateBricks, 1, 2);
		world.setBlock(i + 15, j + 0, k + 14, NovaCraftBlocks.sculk_block, 0, 2);
		world.setBlock(i + 16, j + 0, k + 14, PlaceDeepslateBricks, 0, 2);
		world.setBlock(i + 17, j + 0, k + 14, NovaCraftBlocks.sculk_block, 0, 2);
		world.setBlock(i + 18, j + 0, k + 14, PlaceDeepslateBricks, 0, 2);
		world.setBlock(i + 19, j + 0, k + 14, Blocks.air, 0, 2);
		world.setBlock(i + 0, j + 0, k + 15, Blocks.air, 0, 2);
		world.setBlock(i + 1, j + 0, k + 15, Blocks.air, 0, 2);
		world.setBlock(i + 2, j + 0, k + 15, Blocks.air, 0, 2);
		world.setBlock(i + 3, j + 0, k + 15, Blocks.air, 0, 2);
		world.setBlock(i + 4, j + 0, k + 15, Blocks.air, 0, 2);
		world.setBlock(i + 5, j + 0, k + 15, Blocks.air, 0, 2);
		world.setBlock(i + 6, j + 0, k + 15, Blocks.air, 0, 2);
		world.setBlock(i + 7, j + 0, k + 15, Blocks.air, 0, 2);
		world.setBlock(i + 8, j + 0, k + 15, Blocks.air, 0, 2);
		world.setBlock(i + 9, j + 0, k + 15, Blocks.air, 0, 2);
		world.setBlock(i + 10, j + 0, k + 15, Blocks.air, 0, 2);
		world.setBlock(i + 11, j + 0, k + 15, Blocks.air, 0, 2);
		world.setBlock(i + 12, j + 0, k + 15, NovaCraftBlocks.sculk_vein, 3, 2);
		world.setBlock(i + 13, j + 0, k + 15, Blocks.air, 0, 2);
		world.setBlock(i + 14, j + 0, k + 15, NovaCraftBlocks.sculk_vein, 3, 2);
		world.setBlock(i + 15, j + 0, k + 15, Blocks.air, 0, 2);
		world.setBlock(i + 16, j + 0, k + 15, NovaCraftBlocks.sculk_block, 0, 2);
		world.setBlock(i + 17, j + 0, k + 15, NovaCraftBlocks.sculk_block, 0, 2);
		world.setBlock(i + 18, j + 0, k + 15, PlaceDeepslateBricks, 0, 2);
		world.setBlock(i + 19, j + 0, k + 15, Blocks.air, 0, 2);
		world.setBlock(i + 0, j + 1, k + 0, Blocks.air, 0, 2);
		world.setBlock(i + 1, j + 1, k + 0, Blocks.air, 0, 2);
		world.setBlock(i + 2, j + 1, k + 0, Blocks.air, 0, 2);
		world.setBlock(i + 3, j + 1, k + 0, Blocks.air, 0, 2);
		world.setBlock(i + 4, j + 1, k + 0, Blocks.air, 0, 2);
		world.setBlock(i + 5, j + 1, k + 0, Blocks.air, 0, 2);
		world.setBlock(i + 6, j + 1, k + 0, Blocks.air, 0, 2);
		world.setBlock(i + 7, j + 1, k + 0, Blocks.air, 0, 2);
		world.setBlock(i + 8, j + 1, k + 0, Blocks.air, 0, 2);
		world.setBlock(i + 9, j + 1, k + 0, Blocks.air, 0, 2);
		world.setBlock(i + 10, j + 1, k + 0, Blocks.air, 0, 2);
		world.setBlock(i + 11, j + 1, k + 0, Blocks.air, 0, 2);
		world.setBlock(i + 12, j + 1, k + 0, Blocks.air, 0, 2);
		world.setBlock(i + 13, j + 1, k + 0, Blocks.air, 0, 2);
		world.setBlock(i + 14, j + 1, k + 0, Blocks.air, 0, 2);
		world.setBlock(i + 15, j + 1, k + 0, Blocks.air, 0, 2);
		world.setBlock(i + 16, j + 1, k + 0, Blocks.air, 0, 2);
		world.setBlock(i + 17, j + 1, k + 0, Blocks.air, 0, 2);
		world.setBlock(i + 18, j + 1, k + 0, Blocks.air, 0, 2);
		world.setBlock(i + 19, j + 1, k + 0, Blocks.air, 0, 2);
		world.setBlock(i + 0, j + 1, k + 1, Blocks.air, 0, 2);
		world.setBlock(i + 1, j + 1, k + 1, Blocks.air, 0, 2);
		world.setBlock(i + 2, j + 1, k + 1, Blocks.air, 0, 2);
		world.setBlock(i + 3, j + 1, k + 1, Blocks.air, 0, 2);
		world.setBlock(i + 4, j + 1, k + 1, Blocks.air, 0, 2);
		world.setBlock(i + 5, j + 1, k + 1, Blocks.air, 0, 2);
		world.setBlock(i + 6, j + 1, k + 1, Blocks.air, 0, 2);
		world.setBlock(i + 7, j + 1, k + 1, Blocks.air, 0, 2);
		world.setBlock(i + 8, j + 1, k + 1, Blocks.air, 0, 2);
		world.setBlock(i + 9, j + 1, k + 1, Blocks.air, 0, 2);
		world.setBlock(i + 10, j + 1, k + 1, Blocks.air, 0, 2);
		world.setBlock(i + 11, j + 1, k + 1, Blocks.air, 0, 2);
		world.setBlock(i + 12, j + 1, k + 1, Blocks.air, 0, 2);
		world.setBlock(i + 13, j + 1, k + 1, Blocks.air, 0, 2);
		world.setBlock(i + 14, j + 1, k + 1, Blocks.air, 0, 2);
		world.setBlock(i + 15, j + 1, k + 1, Blocks.air, 0, 2);
		world.setBlock(i + 16, j + 1, k + 1, PlaceCrackedDeepslateBricks, 1, 2);
		world.setBlock(i + 17, j + 1, k + 1, PlaceDeepslateBricks, 0, 2);
		world.setBlock(i + 18, j + 1, k + 1, PlaceDeepslateBricks, 0, 2);
		world.setBlock(i + 19, j + 1, k + 1, Blocks.air, 0, 2);
		world.setBlock(i + 0, j + 1, k + 2, Blocks.air, 0, 2);
		world.setBlock(i + 1, j + 1, k + 2, PlaceCobbledDeepslate, 0, 2);
		world.setBlock(i + 2, j + 1, k + 2, PlaceCobbledDeepslate, 0, 2);
		world.setBlock(i + 3, j + 1, k + 2, PlaceCobbledDeepslate, 0, 2);
		world.setBlock(i + 4, j + 1, k + 2, PlaceCobbledDeepslate, 0, 2);
		world.setBlock(i + 5, j + 1, k + 2, PlaceCobbledDeepslate, 0, 2);
		world.setBlock(i + 6, j + 1, k + 2, PlaceCobbledDeepslate, 0, 2);
		world.setBlock(i + 7, j + 1, k + 2, PlaceCobbledDeepslate, 0, 2);
		world.setBlock(i + 8, j + 1, k + 2, Blocks.air, 0, 2);
		world.setBlock(i + 9, j + 1, k + 2, PlaceCobbledDeepslate, 0, 2);
		world.setBlock(i + 10, j + 1, k + 2, PlaceCobbledDeepslate, 0, 2);
		world.setBlock(i + 11, j + 1, k + 2, PlaceCobbledDeepslate, 0, 2);
		world.setBlock(i + 12, j + 1, k + 2, PlaceDeepslateBricks, 0, 2);
		world.setBlock(i + 13, j + 1, k + 2, PlaceDeepslateBricks, 0, 2);
		world.setBlock(i + 14, j + 1, k + 2, PlaceCobbledDeepslate, 0, 2);
		world.setBlock(i + 15, j + 1, k + 2, PlaceCobbledDeepslate, 0, 2);
		world.setBlock(i + 16, j + 1, k + 2, PlaceCrackedDeepslateBricks, 1, 2);
		world.setBlock(i + 17, j + 1, k + 2, PlaceCrackedDeepslateBricks, 1, 2);
		world.setBlock(i + 18, j + 1, k + 2, PlaceDeepslateBricks, 0, 2);
		world.setBlock(i + 19, j + 1, k + 2, Blocks.air, 0, 2);
		world.setBlock(i + 0, j + 1, k + 3, Blocks.air, 0, 2);
		world.setBlock(i + 1, j + 1, k + 3, PlaceCobbledDeepslate, 0, 2);
		world.setBlock(i + 2, j + 1, k + 3, PlaceCobbledDeepslate, 0, 2);
		world.setBlock(i + 3, j + 1, k + 3, PlaceCobbledDeepslate, 0, 2);
		world.setBlock(i + 4, j + 1, k + 3, PlaceCobbledDeepslate, 0, 2);
		world.setBlock(i + 5, j + 1, k + 3, PlaceCobbledDeepslate, 0, 2);
		world.setBlock(i + 6, j + 1, k + 3, PlaceCobbledDeepslate, 0, 2);
		world.setBlock(i + 7, j + 1, k + 3, PlaceCobbledDeepslate, 0, 2);
		world.setBlock(i + 8, j + 1, k + 3, PlaceCobbledDeepslate, 0, 2);
		world.setBlock(i + 9, j + 1, k + 3, Blocks.air, 0, 2);
		world.setBlock(i + 10, j + 1, k + 3, PlaceCobbledDeepslate, 0, 2);
		world.setBlock(i + 11, j + 1, k + 3, PlaceCobbledDeepslate, 0, 2);
		world.setBlock(i + 12, j + 1, k + 3, PlaceCobbledDeepslate, 0, 2);
		world.setBlock(i + 13, j + 1, k + 3, PlaceCobbledDeepslate, 0, 2);
		world.setBlock(i + 14, j + 1, k + 3, PlaceCobbledDeepslate, 0, 2);
		world.setBlock(i + 15, j + 1, k + 3, PlaceCobbledDeepslate, 0, 2);
		world.setBlock(i + 16, j + 1, k + 3, PlaceDeepslateTiles, 2, 2);
		world.setBlock(i + 17, j + 1, k + 3, Blocks.air, 0, 2);
		world.setBlock(i + 18, j + 1, k + 3, Blocks.air, 0, 2);
		world.setBlock(i + 19, j + 1, k + 3, Blocks.air, 0, 2);
		world.setBlock(i + 0, j + 1, k + 4, Blocks.air, 0, 2);
		world.setBlock(i + 1, j + 1, k + 4, PlaceCobbledDeepslate, 0, 2);
		world.setBlock(i + 2, j + 1, k + 4, PlaceCobbledDeepslate, 0, 2);
		world.setBlock(i + 3, j + 1, k + 4, PlaceCobbledDeepslate, 0, 2);
		world.setBlock(i + 4, j + 1, k + 4, PlaceCobbledDeepslate, 0, 2);
		world.setBlock(i + 5, j + 1, k + 4, PlaceCobbledDeepslate, 0, 2);
		world.setBlock(i + 6, j + 1, k + 4, PlaceCobbledDeepslate, 0, 2);
		world.setBlock(i + 7, j + 1, k + 4, PlaceDeepslateBricks, 0, 2);
		world.setBlock(i + 8, j + 1, k + 4, Blocks.air, 0, 2);
		world.setBlock(i + 9, j + 1, k + 4, Blocks.air, 0, 2);
		world.setBlock(i + 10, j + 1, k + 4, Blocks.air, 0, 2);
		world.setBlock(i + 11, j + 1, k + 4, Blocks.air, 0, 2);
		world.setBlock(i + 12, j + 1, k + 4, Blocks.air, 0, 2);
		world.setBlock(i + 13, j + 1, k + 4, PlaceCobbledDeepslate, 0, 2);
		world.setBlock(i + 14, j + 1, k + 4, PlaceCobbledDeepslate, 0, 2);
		world.setBlock(i + 15, j + 1, k + 4, PlaceCobbledDeepslate, 0, 2);
		world.setBlock(i + 16, j + 1, k + 4, PlaceDeepslateBricks, 0, 2);
		world.setBlock(i + 17, j + 1, k + 4, Blocks.air, 0, 2);
		world.setBlock(i + 18, j + 1, k + 4, Blocks.air, 0, 2);
		world.setBlock(i + 19, j + 1, k + 4, Blocks.air, 0, 2);
		world.setBlock(i + 0, j + 1, k + 5, Blocks.air, 0, 2);
		world.setBlock(i + 1, j + 1, k + 5, PlaceCobbledDeepslate, 0, 2);
		world.setBlock(i + 2, j + 1, k + 5, PlaceCobbledDeepslate, 0, 2);
		world.setBlock(i + 3, j + 1, k + 5, PlaceDeepslateBricks, 0, 2);
		world.setBlock(i + 4, j + 1, k + 5, Blocks.air, 0, 2);
		world.setBlock(i + 5, j + 1, k + 5, Blocks.air, 0, 2);
		world.setBlock(i + 6, j + 1, k + 5, Blocks.air, 0, 2);
		world.setBlock(i + 7, j + 1, k + 5, PlaceDeepslateBricks, 0, 2);
		world.setBlock(i + 8, j + 1, k + 5, NovaCraftBlocks.sculk_vein, 1, 2);
		world.setBlock(i + 9, j + 1, k + 5, NovaCraftBlocks.sculk_vein, 1, 2);
		world.setBlock(i + 10, j + 1, k + 5, NovaCraftBlocks.sculk_vein, 1, 2);
		world.setBlock(i + 11, j + 1, k + 5, Blocks.air, 0, 2);
		world.setBlock(i + 12, j + 1, k + 5, Blocks.air, 0, 2);
		world.setBlock(i + 13, j + 1, k + 5, NovaCraftBlocks.sculk_vein, 1, 2);
		world.setBlock(i + 14, j + 1, k + 5, NovaCraftBlocks.sculk_vein, 4, 2);
		world.setBlock(i + 15, j + 1, k + 5, PlaceChiseledDeepslate, 4, 2);
		world.setBlock(i + 16, j + 1, k + 5, NovaCraftBlocks.sculk_vein, 5, 2);
		world.setBlock(i + 17, j + 1, k + 5, Blocks.air, 0, 2);
		world.setBlock(i + 18, j + 1, k + 5, Blocks.air, 0, 2);
		world.setBlock(i + 19, j + 1, k + 5, Blocks.air, 0, 2);
		world.setBlock(i + 0, j + 1, k + 6, Blocks.air, 0, 2);
		world.setBlock(i + 1, j + 1, k + 6, PlaceCobbledDeepslate, 0, 2);
		world.setBlock(i + 2, j + 1, k + 6, Blocks.air, 0, 2);
		world.setBlock(i + 3, j + 1, k + 6, Blocks.air, 0, 2);
		world.setBlock(i + 4, j + 1, k + 6, NovaCraftBlocks.sculk_vein, 1, 2);
		world.setBlock(i + 5, j + 1, k + 6, Blocks.air, 0, 2);
		world.setBlock(i + 6, j + 1, k + 6, Blocks.air, 0, 2);
		world.setBlock(i + 7, j + 1, k + 6, NovaCraftBlocks.sculk_vein, 1, 2);
		world.setBlock(i + 8, j + 1, k + 6, Blocks.air, 0, 2);
		world.setBlock(i + 9, j + 1, k + 6, Blocks.air, 0, 2);
		world.setBlock(i + 10, j + 1, k + 6, Blocks.air, 0, 2);
		world.setBlock(i + 11, j + 1, k + 6, NovaCraftBlocks.sculk_vein, 1, 2);
		world.setBlock(i + 12, j + 1, k + 6, NovaCraftBlocks.sculk_vein, 1, 2);
		world.setBlock(i + 13, j + 1, k + 6, Blocks.air, 0, 2);
		world.setBlock(i + 14, j + 1, k + 6, NovaCraftBlocks.sculk_block, 0, 2);
		world.setBlock(i + 15, j + 1, k + 6, NovaCraftBlocks.sculk_block, 0, 2);
		world.setBlock(i + 16, j + 1, k + 6, Blocks.air, 0, 2);
		world.setBlock(i + 17, j + 1, k + 6, Blocks.air, 0, 2);
		world.setBlock(i + 18, j + 1, k + 6, Blocks.air, 0, 2);
		world.setBlock(i + 19, j + 1, k + 6, Blocks.air, 0, 2);
		world.setBlock(i + 0, j + 1, k + 7, Blocks.air, 0, 2);
		world.setBlock(i + 1, j + 1, k + 7, PlaceCobbledDeepslate, 0, 2);
		world.setBlock(i + 2, j + 1, k + 7, Blocks.air, 0, 2);
		world.setBlock(i + 3, j + 1, k + 7, NovaCraftBlocks.sculk_vein, 1, 2);
		world.setBlock(i + 4, j + 1, k + 7, Blocks.air, 0, 2);
		world.setBlock(i + 5, j + 1, k + 7, NovaCraftBlocks.sculk_vein, 1, 2);
		world.setBlock(i + 6, j + 1, k + 7, NovaCraftBlocks.sculk_vein, 1, 2);
		world.setBlock(i + 7, j + 1, k + 7, Blocks.air, 0, 2);
		world.setBlock(i + 8, j + 1, k + 7, Blocks.air, 0, 2);
		world.setBlock(i + 9, j + 1, k + 7, Blocks.air, 0, 2);
		world.setBlock(i + 10, j + 1, k + 7, Blocks.air, 0, 2);
		world.setBlock(i + 11, j + 1, k + 7, Blocks.air, 0, 2);
		world.setBlock(i + 12, j + 1, k + 7, Blocks.air, 0, 2);
		world.setBlock(i + 13, j + 1, k + 7, Blocks.air, 0, 2);
		world.setBlock(i + 14, j + 1, k + 7, NovaCraftBlocks.sculk_vein, 4, 2);
		world.setBlock(i + 15, j + 1, k + 7, PlaceDeepslateTiles, 2, 2);
		world.setBlock(i + 16, j + 1, k + 7, NovaCraftBlocks.sculk_block, 0, 2);
		world.setBlock(i + 17, j + 1, k + 7, Blocks.air, 0, 2);
		world.setBlock(i + 18, j + 1, k + 7, Blocks.air, 0, 2);
		world.setBlock(i + 19, j + 1, k + 7, Blocks.air, 0, 2);
		world.setBlock(i + 0, j + 1, k + 8, Blocks.air, 0, 2);
		world.setBlock(i + 1, j + 1, k + 8, PlaceCobbledDeepslate, 0, 2);
		world.setBlock(i + 2, j + 1, k + 8, PlaceCobbledDeepslate, 0, 2);
		world.setBlock(i + 3, j + 1, k + 8, PlaceCobbledDeepslate, 0, 2);
		world.setBlock(i + 4, j + 1, k + 8, Blocks.air, 0, 2);
		world.setBlock(i + 5, j + 1, k + 8, Blocks.air, 0, 2);
		world.setBlock(i + 6, j + 1, k + 8, Blocks.air, 0, 2);
		world.setBlock(i + 7, j + 1, k + 8, Blocks.air, 0, 2);
		world.setBlock(i + 8, j + 1, k + 8, Blocks.air, 0, 2);
		world.setBlock(i + 9, j + 1, k + 8, Blocks.air, 0, 2);
		world.setBlock(i + 10, j + 1, k + 8, NovaCraftBlocks.sculk_spike, 1, 2);
		world.setBlock(i + 11, j + 1, k + 8, Blocks.air, 0, 2);
		world.setBlock(i + 12, j + 1, k + 8, Blocks.air, 0, 2);
		world.setBlock(i + 13, j + 1, k + 8, Blocks.air, 0, 2);
		world.setBlock(i + 14, j + 1, k + 8, NovaCraftBlocks.sculk_block, 0, 2);
		world.setBlock(i + 15, j + 1, k + 8, PlaceDeepslateTiles, 2, 2);
		world.setBlock(i + 16, j + 1, k + 8, NovaCraftBlocks.sculk_block, 0, 2);
		world.setBlock(i + 17, j + 1, k + 8, Blocks.air, 0, 2);
		world.setBlock(i + 18, j + 1, k + 8, Blocks.air, 0, 2);
		world.setBlock(i + 19, j + 1, k + 8, Blocks.air, 0, 2);
		world.setBlock(i + 0, j + 1, k + 9, Blocks.air, 0, 2);
		world.setBlock(i + 1, j + 1, k + 9, PlaceCobbledDeepslate, 0, 2);
		world.setBlock(i + 2, j + 1, k + 9, Blocks.air, 0, 2);
		world.setBlock(i + 3, j + 1, k + 9, NovaCraftBlocks.sculk_vein, 1, 2);
		world.setBlock(i + 4, j + 1, k + 9, Blocks.air, 0, 2);
		world.setBlock(i + 5, j + 1, k + 9, Blocks.air, 0, 2);
		world.setBlock(i + 6, j + 1, k + 9, Blocks.air, 0, 2);
		world.setBlock(i + 7, j + 1, k + 9, NovaCraftBlocks.sculk_spike, 1, 2);
		world.setBlock(i + 8, j + 1, k + 9, Blocks.air, 0, 2);
		world.setBlock(i + 9, j + 1, k + 9, NovaCraftBlocks.sculk_spike, 1, 2);
		world.setBlock(i + 10, j + 1, k + 9, Blocks.air, 0, 2);
		world.setBlock(i + 11, j + 1, k + 9, Blocks.air, 0, 2);
		world.setBlock(i + 12, j + 1, k + 9, NovaCraftBlocks.sculk_vein, 1, 2);
		world.setBlock(i + 13, j + 1, k + 9, NovaCraftBlocks.sculk_vein, 1, 2);
		world.setBlock(i + 14, j + 1, k + 9, NovaCraftBlocks.sculk_vein, 4, 2);
		world.setBlock(i + 15, j + 1, k + 9, PlaceCrackedDeepslateTiles, 3, 2);
		world.setBlock(i + 16, j + 1, k + 9, PlaceDeepslateTiles, 2, 2);
		world.setBlock(i + 17, j + 1, k + 9, NovaCraftBlocks.sculk_vein, 5, 2);
		world.setBlock(i + 18, j + 1, k + 9, Blocks.air, 0, 2);
		world.setBlock(i + 19, j + 1, k + 9, Blocks.air, 0, 2);
		world.setBlock(i + 0, j + 1, k + 10, NovaCraftBlocks.sculk_vein, 4, 2);
		world.setBlock(i + 1, j + 1, k + 10, PlaceCobbledDeepslate, 0, 2);
		world.setBlock(i + 2, j + 1, k + 10, PlaceCobbledDeepslate, 0, 2);
		world.setBlock(i + 3, j + 1, k + 10, NovaCraftBlocks.sculk_vein, 1, 2);
		world.setBlock(i + 4, j + 1, k + 10, Blocks.air, 0, 2);
		world.setBlock(i + 5, j + 1, k + 10, Blocks.air, 0, 2);
		world.setBlock(i + 6, j + 1, k + 10, Blocks.air, 0, 2);
		world.setBlock(i + 7, j + 1, k + 10, Blocks.air, 0, 2);
		world.setBlock(i + 8, j + 1, k + 10, Blocks.air, 0, 2);
		world.setBlock(i + 9, j + 1, k + 10, Blocks.air, 0, 2);
		world.setBlock(i + 10, j + 1, k + 10, Blocks.air, 0, 2);
		world.setBlock(i + 11, j + 1, k + 10, NovaCraftBlocks.sculk_vein, 1, 2);
		world.setBlock(i + 12, j + 1, k + 10, NovaCraftBlocks.sculk_vein, 1, 2);
		world.setBlock(i + 13, j + 1, k + 10, NovaCraftBlocks.sculk_vein, 2, 2);
		world.setBlock(i + 14, j + 1, k + 10, NovaCraftBlocks.sculk_block, 0, 2);
		world.setBlock(i + 15, j + 1, k + 10, PlaceChiseledDeepslate, 4, 2);
		world.setBlock(i + 16, j + 1, k + 10, PlaceCrackedDeepslateBricks, 1, 2);
		world.setBlock(i + 17, j + 1, k + 10, PlaceDeepslateBricks, 0, 2);
		world.setBlock(i + 18, j + 1, k + 10, NovaCraftBlocks.sculk_vein, 5, 2);
		world.setBlock(i + 19, j + 1, k + 10, PlaceCobbledDeepslate, 0, 2);
		world.setBlock(i + 0, j + 1, k + 11, Blocks.air, 0, 2);
		world.setBlock(i + 1, j + 1, k + 11, NovaCraftBlocks.sculk_block, 0, 2);
		world.setBlock(i + 2, j + 1, k + 11, Blocks.air, 0, 2);
		world.setBlock(i + 3, j + 1, k + 11, Blocks.air, 0, 2);
		world.setBlock(i + 4, j + 1, k + 11, Blocks.air, 0, 2);
		world.setBlock(i + 5, j + 1, k + 11, Blocks.mob_spawner, 0, 2);
		TileEntityMobSpawner tileentitymobspawner2 = (TileEntityMobSpawner)world.getTileEntity(i + 5, j + 1, k + 11);
        
        if (tileentitymobspawner2 != null)
        {
        	tileentitymobspawner2.func_145881_a().setEntityName("nova_craft.sculk_incinerator");
        }
        
		world.setBlock(i + 6, j + 1, k + 11, Blocks.air, 0, 2);
		world.setBlock(i + 7, j + 1, k + 11, Blocks.air, 0, 2);
		world.setBlock(i + 8, j + 1, k + 11, Blocks.air, 0, 2);
		world.setBlock(i + 9, j + 1, k + 11, Blocks.air, 0, 2);
		world.setBlock(i + 10, j + 1, k + 11, NovaCraftBlocks.sculk_vein, 1, 2);
		world.setBlock(i + 11, j + 1, k + 11, Blocks.air, 0, 2);
		world.setBlock(i + 12, j + 1, k + 11, Blocks.air, 0, 2);
		world.setBlock(i + 13, j + 1, k + 11, PlaceCobbledDeepslate, 0, 2);
		world.setBlock(i + 14, j + 1, k + 11, PlaceCobbledDeepslate, 0, 2);
		world.setBlock(i + 15, j + 1, k + 11, PlaceCobbledDeepslate, 0, 2);
		world.setBlock(i + 16, j + 1, k + 11, PlaceCobbledDeepslate, 0, 2);
		world.setBlock(i + 17, j + 1, k + 11, NovaCraftBlocks.sculk_vein, 5, 2);
		world.setBlock(i + 18, j + 1, k + 11, Blocks.air, 0, 2);
		world.setBlock(i + 19, j + 1, k + 11, Blocks.air, 0, 2);
		world.setBlock(i + 0, j + 1, k + 12, NovaCraftBlocks.sculk_vein, 4, 2);
		world.setBlock(i + 1, j + 1, k + 12, PlaceCobbledDeepslate, 0, 2);
		world.setBlock(i + 2, j + 1, k + 12, NovaCraftBlocks.sculk_vein, 1, 2);
		world.setBlock(i + 3, j + 1, k + 12, NovaCraftBlocks.sculk_vein, 1, 2);
		world.setBlock(i + 4, j + 1, k + 12, Blocks.air, 0, 2);
		world.setBlock(i + 5, j + 1, k + 12, Blocks.air, 0, 2);
		world.setBlock(i + 6, j + 1, k + 12, NovaCraftBlocks.sculk_vein, 2, 2);
		world.setBlock(i + 7, j + 1, k + 12, NovaCraftBlocks.sculk_vein, 2, 2);
		world.setBlock(i + 8, j + 1, k + 12, NovaCraftBlocks.sculk_vein, 2, 2);
		world.setBlock(i + 9, j + 1, k + 12, NovaCraftBlocks.sculk_vein, 2, 2);
		world.setBlock(i + 10, j + 1, k + 12, NovaCraftBlocks.sculk_vein, 1, 2);
		world.setBlock(i + 11, j + 1, k + 12, Blocks.air, 0, 2);
		world.setBlock(i + 12, j + 1, k + 12, Blocks.air, 0, 2);
		world.setBlock(i + 13, j + 1, k + 12, Blocks.air, 0, 2);
		world.setBlock(i + 14, j + 1, k + 12, PlaceCobbledDeepslate, 0, 2);
		world.setBlock(i + 15, j + 1, k + 12, PlaceCobbledDeepslate, 0, 2);
		world.setBlock(i + 16, j + 1, k + 12, NovaCraftBlocks.sculk_block, 0, 2);
		world.setBlock(i + 17, j + 1, k + 12, Blocks.air, 0, 2);
		world.setBlock(i + 18, j + 1, k + 12, Blocks.air, 0, 2);
		world.setBlock(i + 19, j + 1, k + 12, Blocks.air, 0, 2);
		world.setBlock(i + 0, j + 1, k + 13, Blocks.air, 0, 2);
		world.setBlock(i + 1, j + 1, k + 13, PlaceCobbledDeepslate, 0, 2);
		world.setBlock(i + 2, j + 1, k + 13, PlaceCobbledDeepslate, 0, 2);
		world.setBlock(i + 3, j + 1, k + 13, Blocks.air, 0, 2);
		world.setBlock(i + 4, j + 1, k + 13, NovaCraftBlocks.sculk_vein, 1, 2);
		world.setBlock(i + 5, j + 1, k + 13, NovaCraftBlocks.sculk_block, 0, 2);
		world.setBlock(i + 6, j + 1, k + 13, PlaceCobbledDeepslate, 0, 2);
		world.setBlock(i + 7, j + 1, k + 13, PlaceCobbledDeepslate, 0, 2);
		world.setBlock(i + 8, j + 1, k + 13, PlaceCobbledDeepslate, 0, 2);
		world.setBlock(i + 9, j + 1, k + 13, PlaceCobbledDeepslate, 0, 2);
		world.setBlock(i + 10, j + 1, k + 13, PlaceCobbledDeepslate, 0, 2);
		world.setBlock(i + 11, j + 1, k + 13, PlaceCobbledDeepslate, 0, 2);
		world.setBlock(i + 12, j + 1, k + 13, PlaceCobbledDeepslate, 0, 2);
		world.setBlock(i + 13, j + 1, k + 13, PlaceCobbledDeepslate, 0, 2);
		world.setBlock(i + 14, j + 1, k + 13, PlaceCobbledDeepslate, 0, 2);
		world.setBlock(i + 15, j + 1, k + 13, PlaceCobbledDeepslate, 0, 2);
		world.setBlock(i + 16, j + 1, k + 13, NovaCraftBlocks.sculk_block, 0, 2);
		world.setBlock(i + 17, j + 1, k + 13, Blocks.air, 0, 2);
		world.setBlock(i + 18, j + 1, k + 13, Blocks.air, 0, 2);
		world.setBlock(i + 19, j + 1, k + 13, Blocks.air, 0, 2);
		world.setBlock(i + 0, j + 1, k + 14, Blocks.air, 0, 2);
		world.setBlock(i + 1, j + 1, k + 14, Blocks.air, 0, 2);
		world.setBlock(i + 2, j + 1, k + 14, PlaceCobbledDeepslate, 0, 2);
		world.setBlock(i + 3, j + 1, k + 14, PlaceCobbledDeepslate, 0, 2);
		world.setBlock(i + 4, j + 1, k + 14, PlaceCobbledDeepslate, 0, 2);
		world.setBlock(i + 5, j + 1, k + 14, NovaCraftBlocks.sculk_vein, 4, 2);
		world.setBlock(i + 6, j + 1, k + 14, PlaceCobbledDeepslate, 0, 2);
		world.setBlock(i + 7, j + 1, k + 14, PlaceCobbledDeepslate, 0, 2);
		world.setBlock(i + 8, j + 1, k + 14, NovaCraftBlocks.sculk_vein, 4, 2);
		world.setBlock(i + 9, j + 1, k + 14, PlaceCobbledDeepslate, 0, 2);
		world.setBlock(i + 10, j + 1, k + 14, PlaceCobbledDeepslate, 0, 2);
		world.setBlock(i + 11, j + 1, k + 14, PlaceCobbledDeepslate, 0, 2);
		world.setBlock(i + 12, j + 1, k + 14, NovaCraftBlocks.sculk_block, 0, 2);
		world.setBlock(i + 13, j + 1, k + 14, PlaceCobbledDeepslate, 0, 2);
		world.setBlock(i + 14, j + 1, k + 14, NovaCraftBlocks.sculk_block, 0, 2);
		world.setBlock(i + 15, j + 1, k + 14, NovaCraftBlocks.sculk_block, 0, 2);
		world.setBlock(i + 16, j + 1, k + 14, PlaceDeepslateBricks, 0, 2);
		world.setBlock(i + 17, j + 1, k + 14, NovaCraftBlocks.sculk_block, 0, 2);
		world.setBlock(i + 18, j + 1, k + 14, PlaceDeepslateBricks, 0, 2);
		world.setBlock(i + 19, j + 1, k + 14, Blocks.air, 0, 2);
		world.setBlock(i + 0, j + 1, k + 15, Blocks.air, 0, 2);
		world.setBlock(i + 1, j + 1, k + 15, Blocks.air, 0, 2);
		world.setBlock(i + 2, j + 1, k + 15, Blocks.air, 0, 2);
		world.setBlock(i + 3, j + 1, k + 15, Blocks.air, 0, 2);
		world.setBlock(i + 4, j + 1, k + 15, Blocks.air, 0, 2);
		world.setBlock(i + 5, j + 1, k + 15, Blocks.air, 0, 2);
		world.setBlock(i + 6, j + 1, k + 15, Blocks.air, 0, 2);
		world.setBlock(i + 7, j + 1, k + 15, Blocks.air, 0, 2);
		world.setBlock(i + 8, j + 1, k + 15, Blocks.air, 0, 2);
		world.setBlock(i + 9, j + 1, k + 15, Blocks.air, 0, 2);
		world.setBlock(i + 10, j + 1, k + 15, Blocks.air, 0, 2);
		world.setBlock(i + 11, j + 1, k + 15, NovaCraftBlocks.sculk_vein, 3, 2);
		world.setBlock(i + 12, j + 1, k + 15, Blocks.air, 0, 2);
		world.setBlock(i + 13, j + 1, k + 15, NovaCraftBlocks.sculk_vein, 3, 2);
		world.setBlock(i + 14, j + 1, k + 15, Blocks.air, 0, 2);
		world.setBlock(i + 15, j + 1, k + 15, Blocks.air, 0, 2);
		world.setBlock(i + 16, j + 1, k + 15, NovaCraftBlocks.sculk_block, 0, 2);
		world.setBlock(i + 17, j + 1, k + 15, NovaCraftBlocks.sculk_block, 0, 2);
		world.setBlock(i + 18, j + 1, k + 15, PlaceDeepslateBricks, 0, 2);
		world.setBlock(i + 19, j + 1, k + 15, Blocks.air, 0, 2);
		world.setBlock(i + 0, j + 2, k + 0, Blocks.air, 0, 2);
		world.setBlock(i + 1, j + 2, k + 0, Blocks.air, 0, 2);
		world.setBlock(i + 2, j + 2, k + 0, Blocks.air, 0, 2);
		world.setBlock(i + 3, j + 2, k + 0, Blocks.air, 0, 2);
		world.setBlock(i + 4, j + 2, k + 0, Blocks.air, 0, 2);
		world.setBlock(i + 5, j + 2, k + 0, Blocks.air, 0, 2);
		world.setBlock(i + 6, j + 2, k + 0, Blocks.air, 0, 2);
		world.setBlock(i + 7, j + 2, k + 0, Blocks.air, 0, 2);
		world.setBlock(i + 8, j + 2, k + 0, Blocks.air, 0, 2);
		world.setBlock(i + 9, j + 2, k + 0, Blocks.air, 0, 2);
		world.setBlock(i + 10, j + 2, k + 0, Blocks.air, 0, 2);
		world.setBlock(i + 11, j + 2, k + 0, Blocks.air, 0, 2);
		world.setBlock(i + 12, j + 2, k + 0, Blocks.air, 0, 2);
		world.setBlock(i + 13, j + 2, k + 0, Blocks.air, 0, 2);
		world.setBlock(i + 14, j + 2, k + 0, Blocks.air, 0, 2);
		world.setBlock(i + 15, j + 2, k + 0, Blocks.air, 0, 2);
		world.setBlock(i + 16, j + 2, k + 0, Blocks.air, 0, 2);
		world.setBlock(i + 17, j + 2, k + 0, Blocks.air, 0, 2);
		world.setBlock(i + 18, j + 2, k + 0, Blocks.air, 0, 2);
		world.setBlock(i + 19, j + 2, k + 0, Blocks.air, 0, 2);
		world.setBlock(i + 0, j + 2, k + 1, Blocks.air, 0, 2);
		world.setBlock(i + 1, j + 2, k + 1, Blocks.air, 0, 2);
		world.setBlock(i + 2, j + 2, k + 1, Blocks.air, 0, 2);
		world.setBlock(i + 3, j + 2, k + 1, Blocks.air, 0, 2);
		world.setBlock(i + 4, j + 2, k + 1, Blocks.air, 0, 2);
		world.setBlock(i + 5, j + 2, k + 1, Blocks.air, 0, 2);
		world.setBlock(i + 6, j + 2, k + 1, Blocks.air, 0, 2);
		world.setBlock(i + 7, j + 2, k + 1, Blocks.air, 0, 2);
		world.setBlock(i + 8, j + 2, k + 1, Blocks.air, 0, 2);
		world.setBlock(i + 9, j + 2, k + 1, Blocks.air, 0, 2);
		world.setBlock(i + 10, j + 2, k + 1, Blocks.air, 0, 2);
		world.setBlock(i + 11, j + 2, k + 1, Blocks.air, 0, 2);
		world.setBlock(i + 12, j + 2, k + 1, Blocks.air, 0, 2);
		world.setBlock(i + 13, j + 2, k + 1, Blocks.air, 0, 2);
		world.setBlock(i + 14, j + 2, k + 1, Blocks.air, 0, 2);
		world.setBlock(i + 15, j + 2, k + 1, Blocks.air, 0, 2);
		world.setBlock(i + 16, j + 2, k + 1, PlaceDeepslateBricks, 0, 2);
		world.setBlock(i + 17, j + 2, k + 1, PlaceCrackedDeepslateBricks, 1, 2);
		world.setBlock(i + 18, j + 2, k + 1, Blocks.air, 0, 2);
		world.setBlock(i + 19, j + 2, k + 1, Blocks.air, 0, 2);
		world.setBlock(i + 0, j + 2, k + 2, Blocks.air, 0, 2);
		world.setBlock(i + 1, j + 2, k + 2, PlaceCobbledDeepslate, 0, 2);
		world.setBlock(i + 2, j + 2, k + 2, PlaceCobbledDeepslate, 0, 2);
		world.setBlock(i + 3, j + 2, k + 2, PlaceCobbledDeepslate, 0, 2);
		world.setBlock(i + 4, j + 2, k + 2, Blocks.air, 0, 2);
		world.setBlock(i + 5, j + 2, k + 2, Blocks.air, 0, 2);
		world.setBlock(i + 6, j + 2, k + 2, PlaceCobbledDeepslate, 0, 2);
		world.setBlock(i + 7, j + 2, k + 2, PlaceCobbledDeepslate, 0, 2);
		world.setBlock(i + 8, j + 2, k + 2, PlaceCobbledDeepslate, 0, 2);
		world.setBlock(i + 9, j + 2, k + 2, Blocks.air, 0, 2);
		world.setBlock(i + 10, j + 2, k + 2, PlaceCobbledDeepslate, 0, 2);
		world.setBlock(i + 11, j + 2, k + 2, PlaceCobbledDeepslate, 0, 2);
		world.setBlock(i + 12, j + 2, k + 2, PlaceCobbledDeepslate, 0, 2);
		world.setBlock(i + 13, j + 2, k + 2, PlaceCobbledDeepslate, 0, 2);
		world.setBlock(i + 14, j + 2, k + 2, PlaceCobbledDeepslate, 0, 2);
		world.setBlock(i + 15, j + 2, k + 2, PlaceCobbledDeepslate, 0, 2);
		world.setBlock(i + 16, j + 2, k + 2, PlaceDeepslateBricks, 0, 2);
		world.setBlock(i + 17, j + 2, k + 2, PlaceDeepslateBricks, 0, 2);
		world.setBlock(i + 18, j + 2, k + 2, Blocks.air, 0, 2);
		world.setBlock(i + 19, j + 2, k + 2, Blocks.air, 0, 2);
		world.setBlock(i + 0, j + 2, k + 3, Blocks.air, 0, 2);
		world.setBlock(i + 1, j + 2, k + 3, PlaceCobbledDeepslate, 0, 2);
		world.setBlock(i + 2, j + 2, k + 3, PlaceCobbledDeepslate, 0, 2);
		world.setBlock(i + 3, j + 2, k + 3, PlaceCobbledDeepslate, 0, 2);
		world.setBlock(i + 4, j + 2, k + 3, PlaceCobbledDeepslate, 0, 2);
		world.setBlock(i + 5, j + 2, k + 3, PlaceCobbledDeepslate, 0, 2);
		world.setBlock(i + 6, j + 2, k + 3, PlaceCobbledDeepslate, 0, 2);
		world.setBlock(i + 7, j + 2, k + 3, PlaceCobbledDeepslate, 0, 2);
		world.setBlock(i + 8, j + 2, k + 3, PlaceCobbledDeepslate, 0, 2);
		world.setBlock(i + 9, j + 2, k + 3, PlaceCobbledDeepslate, 0, 2);
		world.setBlock(i + 10, j + 2, k + 3, PlaceCobbledDeepslate, 0, 2);
		world.setBlock(i + 11, j + 2, k + 3, PlaceCobbledDeepslate, 0, 2);
		world.setBlock(i + 12, j + 2, k + 3, PlaceCobbledDeepslate, 0, 2);
		world.setBlock(i + 13, j + 2, k + 3, PlaceCobbledDeepslate, 0, 2);
		world.setBlock(i + 14, j + 2, k + 3, PlaceCobbledDeepslate, 0, 2);
		world.setBlock(i + 15, j + 2, k + 3, PlaceCobbledDeepslate, 0, 2);
		world.setBlock(i + 16, j + 2, k + 3, PlaceCobbledDeepslate, 0, 2);
		world.setBlock(i + 17, j + 2, k + 3, Blocks.air, 0, 2);
		world.setBlock(i + 18, j + 2, k + 3, Blocks.air, 0, 2);
		world.setBlock(i + 19, j + 2, k + 3, Blocks.air, 0, 2);
		world.setBlock(i + 0, j + 2, k + 4, Blocks.air, 0, 2);
		world.setBlock(i + 1, j + 2, k + 4, PlaceCobbledDeepslate, 0, 2);
		world.setBlock(i + 2, j + 2, k + 4, PlaceCobbledDeepslate, 0, 2);
		world.setBlock(i + 3, j + 2, k + 4, PlaceDeepslateBricks, 0, 2);
		world.setBlock(i + 4, j + 2, k + 4, PlaceDeepslateTiles, 2, 2);
		world.setBlock(i + 5, j + 2, k + 4, PlaceDeepslateTiles, 2, 2);
		world.setBlock(i + 6, j + 2, k + 4, PlaceDeepslateTiles, 2, 2);
		world.setBlock(i + 7, j + 2, k + 4, PlaceDeepslateBricks, 0, 2);
		world.setBlock(i + 8, j + 2, k + 4, Blocks.air, 0, 2);
		world.setBlock(i + 9, j + 2, k + 4, Blocks.air, 0, 2);
		world.setBlock(i + 10, j + 2, k + 4, Blocks.air, 0, 2);
		world.setBlock(i + 11, j + 2, k + 4, Blocks.air, 0, 2);
		world.setBlock(i + 12, j + 2, k + 4, Blocks.air, 0, 2);
		world.setBlock(i + 13, j + 2, k + 4, PlaceCobbledDeepslate, 0, 2);
		world.setBlock(i + 14, j + 2, k + 4, PlaceCobbledDeepslate, 0, 2);
		world.setBlock(i + 15, j + 2, k + 4, PlaceCobbledDeepslate, 0, 2);
		world.setBlock(i + 16, j + 2, k + 4, PlaceCobbledDeepslate, 0, 2);
		world.setBlock(i + 17, j + 2, k + 4, Blocks.air, 0, 2);
		world.setBlock(i + 18, j + 2, k + 4, Blocks.air, 0, 2);
		world.setBlock(i + 19, j + 2, k + 4, Blocks.air, 0, 2);
		world.setBlock(i + 0, j + 2, k + 5, Blocks.air, 0, 2);
		world.setBlock(i + 1, j + 2, k + 5, PlaceCobbledDeepslate, 0, 2);
		world.setBlock(i + 2, j + 2, k + 5, PlaceCobbledDeepslate, 0, 2);
		world.setBlock(i + 3, j + 2, k + 5, PlaceDeepslateBricks, 0, 2);
		world.setBlock(i + 4, j + 2, k + 5, PlaceCrackedDeepslateTiles, 3, 2);
		world.setBlock(i + 5, j + 2, k + 5, PlaceCrackedDeepslateTiles, 3, 2);
		world.setBlock(i + 6, j + 2, k + 5, PlaceDeepslateTiles, 2, 2);
		world.setBlock(i + 7, j + 2, k + 5, PlaceDeepslateBricks, 0, 2);
		world.setBlock(i + 8, j + 2, k + 5, Blocks.air, 0, 2);
		world.setBlock(i + 9, j + 2, k + 5, Blocks.air, 0, 2);
		world.setBlock(i + 10, j + 2, k + 5, Blocks.air, 0, 2);
		world.setBlock(i + 11, j + 2, k + 5, Blocks.air, 0, 2);
		world.setBlock(i + 12, j + 2, k + 5, Blocks.air, 0, 2);
		world.setBlock(i + 13, j + 2, k + 5, NovaCraftBlocks.sculk_vein, 4, 2);
		world.setBlock(i + 14, j + 2, k + 5, PlaceCrackedDeepslateTiles, 3, 2);
		world.setBlock(i + 15, j + 2, k + 5, Blocks.air, 0, 2);
		world.setBlock(i + 16, j + 2, k + 5, Blocks.air, 0, 2);
		world.setBlock(i + 17, j + 2, k + 5, Blocks.air, 0, 2);
		world.setBlock(i + 18, j + 2, k + 5, Blocks.air, 0, 2);
		world.setBlock(i + 19, j + 2, k + 5, PlaceChiseledDeepslate, 4, 2);
		world.setBlock(i + 0, j + 2, k + 6, Blocks.air, 0, 2);
		world.setBlock(i + 1, j + 2, k + 6, PlaceCobbledDeepslate, 0, 2);
		world.setBlock(i + 2, j + 2, k + 6, PlaceCobbledDeepslate, 0, 2);
		world.setBlock(i + 3, j + 2, k + 6, Blocks.air, 0, 2);
		world.setBlock(i + 4, j + 2, k + 6, Blocks.air, 0, 2);
		world.setBlock(i + 5, j + 2, k + 6, Blocks.air, 0, 2);
		world.setBlock(i + 6, j + 2, k + 6, Blocks.air, 0, 2);
		world.setBlock(i + 7, j + 2, k + 6, Blocks.air, 0, 2);
		world.setBlock(i + 8, j + 2, k + 6, Blocks.air, 0, 2);
		world.setBlock(i + 9, j + 2, k + 6, Blocks.air, 0, 2);
		world.setBlock(i + 10, j + 2, k + 6, Blocks.air, 0, 2);
		world.setBlock(i + 11, j + 2, k + 6, Blocks.air, 0, 2);
		world.setBlock(i + 12, j + 2, k + 6, Blocks.air, 0, 2);
		world.setBlock(i + 13, j + 2, k + 6, Blocks.air, 0, 2);
		world.setBlock(i + 14, j + 2, k + 6, NovaCraftBlocks.sculk_block, 0, 2);
		world.setBlock(i + 15, j + 2, k + 6, PlaceDeepslateTiles, 2, 2);
		world.setBlock(i + 16, j + 2, k + 6, NovaCraftBlocks.sculk_vein, 5, 2);
		world.setBlock(i + 17, j + 2, k + 6, Blocks.air, 0, 2);
		world.setBlock(i + 18, j + 2, k + 6, Blocks.air, 0, 2);
		world.setBlock(i + 19, j + 2, k + 6, Blocks.air, 0, 2);
		world.setBlock(i + 0, j + 2, k + 7, Blocks.air, 0, 2);
		world.setBlock(i + 1, j + 2, k + 7, PlaceCobbledDeepslate, 0, 2);
		world.setBlock(i + 2, j + 2, k + 7, Blocks.air, 0, 2);
		world.setBlock(i + 3, j + 2, k + 7, Blocks.air, 0, 2);
		world.setBlock(i + 4, j + 2, k + 7, Blocks.air, 0, 2);
		world.setBlock(i + 5, j + 2, k + 7, Blocks.air, 0, 2);
		world.setBlock(i + 6, j + 2, k + 7, Blocks.air, 0, 2);
		world.setBlock(i + 7, j + 2, k + 7, Blocks.air, 0, 2);
		world.setBlock(i + 8, j + 2, k + 7, Blocks.air, 0, 2);
		world.setBlock(i + 9, j + 2, k + 7, Blocks.air, 0, 2);
		world.setBlock(i + 10, j + 2, k + 7, Blocks.air, 0, 2);
		world.setBlock(i + 11, j + 2, k + 7, Blocks.air, 0, 2);
		world.setBlock(i + 12, j + 2, k + 7, Blocks.air, 0, 2);
		world.setBlock(i + 13, j + 2, k + 7, Blocks.air, 0, 2);
		world.setBlock(i + 14, j + 2, k + 7, Blocks.air, 0, 2);
		world.setBlock(i + 15, j + 2, k + 7, NovaCraftBlocks.sculk_vein, 1, 2);
		world.setBlock(i + 16, j + 2, k + 7, Blocks.air, 0, 2);
		world.setBlock(i + 17, j + 2, k + 7, Blocks.air, 0, 2);
		world.setBlock(i + 18, j + 2, k + 7, Blocks.air, 0, 2);
		world.setBlock(i + 19, j + 2, k + 7, Blocks.air, 0, 2);
		world.setBlock(i + 0, j + 2, k + 8, Blocks.air, 0, 2);
		world.setBlock(i + 1, j + 2, k + 8, PlaceCobbledDeepslate, 0, 2);
		world.setBlock(i + 2, j + 2, k + 8, PlaceCobbledDeepslate, 0, 2);
		world.setBlock(i + 3, j + 2, k + 8, PlaceCobbledDeepslate, 0, 2);
		world.setBlock(i + 4, j + 2, k + 8, Blocks.air, 0, 2);
		world.setBlock(i + 5, j + 2, k + 8, Blocks.air, 0, 2);
		world.setBlock(i + 6, j + 2, k + 8, Blocks.air, 0, 2);
		world.setBlock(i + 7, j + 2, k + 8, Blocks.air, 0, 2);
		world.setBlock(i + 8, j + 2, k + 8, Blocks.air, 0, 2);
		world.setBlock(i + 9, j + 2, k + 8, Blocks.air, 0, 2);
		world.setBlock(i + 10, j + 2, k + 8, Blocks.air, 0, 2);
		world.setBlock(i + 11, j + 2, k + 8, Blocks.air, 0, 2);
		world.setBlock(i + 12, j + 2, k + 8, Blocks.air, 0, 2);
		world.setBlock(i + 13, j + 2, k + 8, Blocks.air, 0, 2);
		world.setBlock(i + 14, j + 2, k + 8, NovaCraftBlocks.sculk_block, 0, 2);
		world.setBlock(i + 15, j + 2, k + 8, NovaCraftBlocks.sculk_block, 0, 2);
		world.setBlock(i + 16, j + 2, k + 8, Blocks.air, 0, 2);
		world.setBlock(i + 17, j + 2, k + 8, Blocks.air, 0, 2);
		world.setBlock(i + 18, j + 2, k + 8, Blocks.air, 0, 2);
		world.setBlock(i + 19, j + 2, k + 8, Blocks.air, 0, 2);
		world.setBlock(i + 0, j + 2, k + 9, Blocks.air, 0, 2);
		world.setBlock(i + 1, j + 2, k + 9, PlaceCobbledDeepslate, 0, 2);
		world.setBlock(i + 2, j + 2, k + 9, Blocks.air, 0, 2);
		world.setBlock(i + 3, j + 2, k + 9, Blocks.air, 0, 2);
		world.setBlock(i + 4, j + 2, k + 9, Blocks.air, 0, 2);
		world.setBlock(i + 5, j + 2, k + 9, Blocks.air, 0, 2);
		world.setBlock(i + 6, j + 2, k + 9, Blocks.air, 0, 2);
		world.setBlock(i + 7, j + 2, k + 9, Blocks.air, 0, 2);
		world.setBlock(i + 8, j + 2, k + 9, Blocks.air, 0, 2);
		world.setBlock(i + 9, j + 2, k + 9, Blocks.air, 0, 2);
		world.setBlock(i + 10, j + 2, k + 9, Blocks.air, 0, 2);
		world.setBlock(i + 11, j + 2, k + 9, Blocks.air, 0, 2);
		world.setBlock(i + 12, j + 2, k + 9, Blocks.air, 0, 2);
		world.setBlock(i + 13, j + 2, k + 9, NovaCraftBlocks.sculk_vein, 4, 2);
		world.setBlock(i + 14, j + 2, k + 9, PlaceDeepslateTiles, 2, 2);
		world.setBlock(i + 15, j + 2, k + 9, PlaceDeepslateTiles, 2, 2);
		world.setBlock(i + 16, j + 2, k + 9, NovaCraftBlocks.sculk_vein, 1, 2);
		world.setBlock(i + 17, j + 2, k + 9, Blocks.air, 0, 2);
		world.setBlock(i + 18, j + 2, k + 9, Blocks.air, 0, 2);
		world.setBlock(i + 19, j + 2, k + 9, Blocks.air, 0, 2);
		world.setBlock(i + 0, j + 2, k + 10, Blocks.air, 0, 2);
		world.setBlock(i + 1, j + 2, k + 10, PlaceCobbledDeepslate, 0, 2);
		world.setBlock(i + 2, j + 2, k + 10, PlaceCobbledDeepslate, 0, 2);
		world.setBlock(i + 3, j + 2, k + 10, Blocks.air, 0, 2);
		world.setBlock(i + 4, j + 2, k + 10, Blocks.air, 0, 2);
		world.setBlock(i + 5, j + 2, k + 10, Blocks.air, 0, 2);
		world.setBlock(i + 6, j + 2, k + 10, Blocks.air, 0, 2);
		world.setBlock(i + 7, j + 2, k + 10, Blocks.air, 0, 2);
		world.setBlock(i + 8, j + 2, k + 10, Blocks.air, 0, 2);
		world.setBlock(i + 9, j + 2, k + 10, Blocks.air, 0, 2);
		world.setBlock(i + 10, j + 2, k + 10, Blocks.air, 0, 2);
		world.setBlock(i + 11, j + 2, k + 10, Blocks.air, 0, 2);
		world.setBlock(i + 12, j + 2, k + 10, Blocks.air, 0, 2);
		world.setBlock(i + 13, j + 2, k + 10, Blocks.air, 0, 2);
		world.setBlock(i + 14, j + 2, k + 10, NovaCraftBlocks.sculk_vein, 4, 2);
		world.setBlock(i + 15, j + 2, k + 10, PlaceChiseledDeepslate, 4, 2);
		world.setBlock(i + 16, j + 2, k + 10, PlaceCrackedDeepslateBricks, 1, 2);
		world.setBlock(i + 17, j + 2, k + 10, Blocks.air, 0, 2);
		world.setBlock(i + 18, j + 2, k + 10, Blocks.air, 0, 2);
		world.setBlock(i + 19, j + 2, k + 10, PlaceChiseledDeepslate, 4, 2);
		world.setBlock(i + 0, j + 2, k + 11, NovaCraftBlocks.sculk_vein, 4, 2);
		world.setBlock(i + 1, j + 2, k + 11, PlaceCobbledDeepslate, 0, 2);
		world.setBlock(i + 2, j + 2, k + 11, PlaceCobbledDeepslate, 0, 2);
		world.setBlock(i + 3, j + 2, k + 11, Blocks.air, 0, 2);
		world.setBlock(i + 4, j + 2, k + 11, Blocks.air, 0, 2);
		world.setBlock(i + 5, j + 2, k + 11, Blocks.air, 0, 2);
		world.setBlock(i + 6, j + 2, k + 11, Blocks.air, 0, 2);
		world.setBlock(i + 7, j + 2, k + 11, Blocks.air, 0, 2);
		world.setBlock(i + 8, j + 2, k + 11, Blocks.air, 0, 2);
		world.setBlock(i + 9, j + 2, k + 11, Blocks.air, 0, 2);
		world.setBlock(i + 10, j + 2, k + 11, Blocks.air, 0, 2);
		world.setBlock(i + 11, j + 2, k + 11, Blocks.air, 0, 2);
		world.setBlock(i + 12, j + 2, k + 11, Blocks.air, 0, 2);
		world.setBlock(i + 13, j + 2, k + 11, PlaceCobbledDeepslate, 0, 2);
		world.setBlock(i + 14, j + 2, k + 11, PlaceCobbledDeepslate, 0, 2);
		world.setBlock(i + 15, j + 2, k + 11, PlaceCobbledDeepslate, 0, 2);
		world.setBlock(i + 16, j + 2, k + 11, PlaceCobbledDeepslate, 0, 2);
		world.setBlock(i + 17, j + 2, k + 11, NovaCraftBlocks.sculk_vein, 5, 2);
		world.setBlock(i + 18, j + 2, k + 11, Blocks.air, 0, 2);
		world.setBlock(i + 19, j + 2, k + 11, Blocks.air, 0, 2);
		world.setBlock(i + 0, j + 2, k + 12, Blocks.air, 0, 2);
		world.setBlock(i + 1, j + 2, k + 12, PlaceCobbledDeepslate, 0, 2);
		world.setBlock(i + 2, j + 2, k + 12, PlaceCobbledDeepslate, 0, 2);
		world.setBlock(i + 3, j + 2, k + 12, Blocks.air, 0, 2);
		world.setBlock(i + 4, j + 2, k + 12, Blocks.air, 0, 2);
		world.setBlock(i + 5, j + 2, k + 12, NovaCraftBlocks.sculk_vein, 2, 2);
		world.setBlock(i + 6, j + 2, k + 12, Blocks.air, 0, 2);
		world.setBlock(i + 7, j + 2, k + 12, Blocks.air, 0, 2);
		world.setBlock(i + 8, j + 2, k + 12, Blocks.air, 0, 2);
		world.setBlock(i + 9, j + 2, k + 12, Blocks.air, 0, 2);
		world.setBlock(i + 10, j + 2, k + 12, Blocks.air, 0, 2);
		world.setBlock(i + 11, j + 2, k + 12, Blocks.air, 0, 2);
		world.setBlock(i + 12, j + 2, k + 12, Blocks.air, 0, 2);
		world.setBlock(i + 13, j + 2, k + 12, PlaceCobbledDeepslate, 0, 2);
		world.setBlock(i + 14, j + 2, k + 12, Blocks.air, 0, 2);
		world.setBlock(i + 15, j + 2, k + 12, PlaceCobbledDeepslate, 0, 2);
		world.setBlock(i + 16, j + 2, k + 12, NovaCraftBlocks.sculk_block, 0, 2);
		world.setBlock(i + 17, j + 2, k + 12, Blocks.air, 0, 2);
		world.setBlock(i + 18, j + 2, k + 12, Blocks.air, 0, 2);
		world.setBlock(i + 19, j + 2, k + 12, Blocks.air, 0, 2);
		world.setBlock(i + 0, j + 2, k + 13, Blocks.air, 0, 2);
		world.setBlock(i + 1, j + 2, k + 13, PlaceCobbledDeepslate, 0, 2);
		world.setBlock(i + 2, j + 2, k + 13, PlaceCobbledDeepslate, 0, 2);
		world.setBlock(i + 3, j + 2, k + 13, PlaceCobbledDeepslate, 0, 2);
		world.setBlock(i + 4, j + 2, k + 13, PlaceCobbledDeepslate, 0, 2);
		world.setBlock(i + 5, j + 2, k + 13, PlaceCobbledDeepslate, 0, 2);
		world.setBlock(i + 6, j + 2, k + 13, PlaceCobbledDeepslate, 0, 2);
		world.setBlock(i + 7, j + 2, k + 13, PlaceCobbledDeepslate, 0, 2);
		world.setBlock(i + 8, j + 2, k + 13, PlaceCobbledDeepslate, 0, 2);
		world.setBlock(i + 9, j + 2, k + 13, PlaceCobbledDeepslate, 0, 2);
		world.setBlock(i + 10, j + 2, k + 13, PlaceCobbledDeepslate, 0, 2);
		world.setBlock(i + 11, j + 2, k + 13, PlaceCobbledDeepslate, 0, 2);
		world.setBlock(i + 12, j + 2, k + 13, PlaceCobbledDeepslate, 0, 2);
		world.setBlock(i + 13, j + 2, k + 13, PlaceCobbledDeepslate, 0, 2);
		world.setBlock(i + 14, j + 2, k + 13, PlaceCobbledDeepslate, 0, 2);
		world.setBlock(i + 15, j + 2, k + 13, NovaCraftBlocks.sculk_block, 0, 2);
		world.setBlock(i + 16, j + 2, k + 13, NovaCraftBlocks.sculk_spike, 1, 2);
		world.setBlock(i + 17, j + 2, k + 13, Blocks.air, 0, 2);
		world.setBlock(i + 18, j + 2, k + 13, Blocks.air, 0, 2);
		world.setBlock(i + 19, j + 2, k + 13, Blocks.air, 0, 2);
		world.setBlock(i + 0, j + 2, k + 14, Blocks.air, 0, 2);
		world.setBlock(i + 1, j + 2, k + 14, PlaceCobbledDeepslate, 0, 2);
		world.setBlock(i + 2, j + 2, k + 14, PlaceCobbledDeepslate, 0, 2);
		world.setBlock(i + 3, j + 2, k + 14, PlaceCobbledDeepslate, 0, 2);
		world.setBlock(i + 4, j + 2, k + 14, PlaceCobbledDeepslate, 0, 2);
		world.setBlock(i + 5, j + 2, k + 14, PlaceCobbledDeepslate, 0, 2);
		world.setBlock(i + 6, j + 2, k + 14, PlaceCobbledDeepslate, 0, 2);
		world.setBlock(i + 7, j + 2, k + 14, PlaceCobbledDeepslate, 0, 2);
		world.setBlock(i + 8, j + 2, k + 14, NovaCraftBlocks.sculk_block, 0, 2);
		world.setBlock(i + 9, j + 2, k + 14, PlaceCobbledDeepslate, 0, 2);
		world.setBlock(i + 10, j + 2, k + 14, NovaCraftBlocks.sculk_vein, 3, 2);
		world.setBlock(i + 11, j + 2, k + 14, NovaCraftBlocks.sculk_block, 0, 2);
		world.setBlock(i + 12, j + 2, k + 14, NovaCraftBlocks.sculk_block, 0, 2);
		world.setBlock(i + 13, j + 2, k + 14, PlaceCobbledDeepslate, 0, 2);
		world.setBlock(i + 14, j + 2, k + 14, NovaCraftBlocks.sculk_block, 0, 2);
		world.setBlock(i + 15, j + 2, k + 14, NovaCraftBlocks.sculk_block, 0, 2);
		world.setBlock(i + 16, j + 2, k + 14, NovaCraftBlocks.sculk_block, 0, 2);
		world.setBlock(i + 17, j + 2, k + 14, NovaCraftBlocks.sculk_block, 0, 2);
		world.setBlock(i + 18, j + 2, k + 14, Blocks.air, 0, 2);
		world.setBlock(i + 19, j + 2, k + 14, Blocks.air, 0, 2);
		world.setBlock(i + 0, j + 2, k + 15, Blocks.air, 0, 2);
		world.setBlock(i + 1, j + 2, k + 15, Blocks.air, 0, 2);
		world.setBlock(i + 2, j + 2, k + 15, Blocks.air, 0, 2);
		world.setBlock(i + 3, j + 2, k + 15, Blocks.air, 0, 2);
		world.setBlock(i + 4, j + 2, k + 15, Blocks.air, 0, 2);
		world.setBlock(i + 5, j + 2, k + 15, Blocks.air, 0, 2);
		world.setBlock(i + 6, j + 2, k + 15, Blocks.air, 0, 2);
		world.setBlock(i + 7, j + 2, k + 15, NovaCraftBlocks.sculk_vein, 3, 2);
		world.setBlock(i + 8, j + 2, k + 15, Blocks.air, 0, 2);
		world.setBlock(i + 9, j + 2, k + 15, NovaCraftBlocks.sculk_vein, 3, 2);
		world.setBlock(i + 10, j + 2, k + 15, Blocks.air, 0, 2);
		world.setBlock(i + 11, j + 2, k + 15, Blocks.air, 0, 2);
		world.setBlock(i + 12, j + 2, k + 15, Blocks.air, 0, 2);
		world.setBlock(i + 13, j + 2, k + 15, NovaCraftBlocks.sculk_vein, 3, 2);
		world.setBlock(i + 14, j + 2, k + 15, Blocks.air, 0, 2);
		world.setBlock(i + 15, j + 2, k + 15, Blocks.air, 0, 2);
		world.setBlock(i + 16, j + 2, k + 15, NovaCraftBlocks.sculk_block, 0, 2);
		world.setBlock(i + 17, j + 2, k + 15, NovaCraftBlocks.sculk_block, 0, 2);
		world.setBlock(i + 18, j + 2, k + 15, Blocks.air, 0, 2);
		world.setBlock(i + 19, j + 2, k + 15, Blocks.air, 0, 2);
		world.setBlock(i + 0, j + 3, k + 0, Blocks.air, 0, 2);
		world.setBlock(i + 1, j + 3, k + 0, Blocks.air, 0, 2);
		world.setBlock(i + 2, j + 3, k + 0, Blocks.air, 0, 2);
		world.setBlock(i + 3, j + 3, k + 0, Blocks.air, 0, 2);
		world.setBlock(i + 4, j + 3, k + 0, Blocks.air, 0, 2);
		world.setBlock(i + 5, j + 3, k + 0, Blocks.air, 0, 2);
		world.setBlock(i + 6, j + 3, k + 0, Blocks.air, 0, 2);
		world.setBlock(i + 7, j + 3, k + 0, Blocks.air, 0, 2);
		world.setBlock(i + 8, j + 3, k + 0, Blocks.air, 0, 2);
		world.setBlock(i + 9, j + 3, k + 0, Blocks.air, 0, 2);
		world.setBlock(i + 10, j + 3, k + 0, Blocks.air, 0, 2);
		world.setBlock(i + 11, j + 3, k + 0, Blocks.air, 0, 2);
		world.setBlock(i + 12, j + 3, k + 0, Blocks.air, 0, 2);
		world.setBlock(i + 13, j + 3, k + 0, Blocks.air, 0, 2);
		world.setBlock(i + 14, j + 3, k + 0, Blocks.air, 0, 2);
		world.setBlock(i + 15, j + 3, k + 0, Blocks.air, 0, 2);
		world.setBlock(i + 16, j + 3, k + 0, Blocks.air, 0, 2);
		world.setBlock(i + 17, j + 3, k + 0, Blocks.air, 0, 2);
		world.setBlock(i + 18, j + 3, k + 0, Blocks.air, 0, 2);
		world.setBlock(i + 19, j + 3, k + 0, Blocks.air, 0, 2);
		world.setBlock(i + 0, j + 3, k + 1, Blocks.air, 0, 2);
		world.setBlock(i + 1, j + 3, k + 1, Blocks.air, 0, 2);
		world.setBlock(i + 2, j + 3, k + 1, Blocks.air, 0, 2);
		world.setBlock(i + 3, j + 3, k + 1, Blocks.air, 0, 2);
		world.setBlock(i + 4, j + 3, k + 1, Blocks.air, 0, 2);
		world.setBlock(i + 5, j + 3, k + 1, Blocks.air, 0, 2);
		world.setBlock(i + 6, j + 3, k + 1, Blocks.air, 0, 2);
		world.setBlock(i + 7, j + 3, k + 1, Blocks.air, 0, 2);
		world.setBlock(i + 8, j + 3, k + 1, Blocks.air, 0, 2);
		world.setBlock(i + 9, j + 3, k + 1, Blocks.air, 0, 2);
		world.setBlock(i + 10, j + 3, k + 1, Blocks.air, 0, 2);
		world.setBlock(i + 11, j + 3, k + 1, Blocks.air, 0, 2);
		world.setBlock(i + 12, j + 3, k + 1, Blocks.air, 0, 2);
		world.setBlock(i + 13, j + 3, k + 1, Blocks.air, 0, 2);
		world.setBlock(i + 14, j + 3, k + 1, Blocks.air, 0, 2);
		world.setBlock(i + 15, j + 3, k + 1, Blocks.air, 0, 2);
		world.setBlock(i + 16, j + 3, k + 1, PlaceCrackedDeepslateBricks, 1, 2);
		world.setBlock(i + 17, j + 3, k + 1, PlaceDeepslateBricks, 0, 2);
		world.setBlock(i + 18, j + 3, k + 1, PlaceDeepslateBricks, 0, 2);
		world.setBlock(i + 19, j + 3, k + 1, Blocks.air, 0, 2);
		world.setBlock(i + 0, j + 3, k + 2, Blocks.air, 0, 2);
		world.setBlock(i + 1, j + 3, k + 2, Blocks.air, 0, 2);
		world.setBlock(i + 2, j + 3, k + 2, PlaceCobbledDeepslate, 0, 2);
		world.setBlock(i + 3, j + 3, k + 2, PlaceCobbledDeepslate, 0, 2);
		world.setBlock(i + 4, j + 3, k + 2, PlaceCobbledDeepslate, 0, 2);
		world.setBlock(i + 5, j + 3, k + 2, PlaceCobbledDeepslate, 0, 2);
		world.setBlock(i + 6, j + 3, k + 2, PlaceCobbledDeepslate, 0, 2);
		world.setBlock(i + 7, j + 3, k + 2, PlaceCobbledDeepslate, 0, 2);
		world.setBlock(i + 8, j + 3, k + 2, PlaceCobbledDeepslate, 0, 2);
		world.setBlock(i + 9, j + 3, k + 2, Blocks.air, 0, 2);
		world.setBlock(i + 10, j + 3, k + 2, PlaceCobbledDeepslate, 0, 2);
		world.setBlock(i + 11, j + 3, k + 2, PlaceCobbledDeepslate, 0, 2);
		world.setBlock(i + 12, j + 3, k + 2, PlaceCobbledDeepslate, 0, 2);
		world.setBlock(i + 13, j + 3, k + 2, PlaceCobbledDeepslate, 0, 2);
		world.setBlock(i + 14, j + 3, k + 2, PlaceCobbledDeepslate, 0, 2);
		world.setBlock(i + 15, j + 3, k + 2, Blocks.air, 0, 2);
		world.setBlock(i + 16, j + 3, k + 2, PlaceDeepslateBricks, 0, 2);
		world.setBlock(i + 17, j + 3, k + 2, Blocks.air, 0, 2);
		world.setBlock(i + 18, j + 3, k + 2, PlaceDeepslateBricks, 0, 2);
		world.setBlock(i + 19, j + 3, k + 2, Blocks.air, 0, 2);
		world.setBlock(i + 0, j + 3, k + 3, Blocks.air, 0, 2);
		world.setBlock(i + 1, j + 3, k + 3, PlaceCobbledDeepslate, 0, 2);
		world.setBlock(i + 2, j + 3, k + 3, PlaceCobbledDeepslate, 0, 2);
		world.setBlock(i + 3, j + 3, k + 3, PlaceCobbledDeepslate, 0, 2);
		world.setBlock(i + 4, j + 3, k + 3, PlaceCobbledDeepslate, 0, 2);
		world.setBlock(i + 5, j + 3, k + 3, PlaceCobbledDeepslate, 0, 2);
		world.setBlock(i + 6, j + 3, k + 3, PlaceCobbledDeepslate, 0, 2);
		world.setBlock(i + 7, j + 3, k + 3, PlaceCobbledDeepslate, 0, 2);
		world.setBlock(i + 8, j + 3, k + 3, PlaceCobbledDeepslate, 0, 2);
		world.setBlock(i + 9, j + 3, k + 3, PlaceCobbledDeepslate, 0, 2);
		world.setBlock(i + 10, j + 3, k + 3, PlaceCobbledDeepslate, 0, 2);
		world.setBlock(i + 11, j + 3, k + 3, PlaceCobbledDeepslate, 0, 2);
		world.setBlock(i + 12, j + 3, k + 3, PlaceCobbledDeepslate, 0, 2);
		world.setBlock(i + 13, j + 3, k + 3, PlaceCobbledDeepslate, 0, 2);
		world.setBlock(i + 14, j + 3, k + 3, PlaceCobbledDeepslate, 0, 2);
		world.setBlock(i + 15, j + 3, k + 3, Blocks.air, 0, 2);
		world.setBlock(i + 16, j + 3, k + 3, Blocks.air, 0, 2);
		world.setBlock(i + 17, j + 3, k + 3, Blocks.air, 0, 2);
		world.setBlock(i + 18, j + 3, k + 3, Blocks.air, 0, 2);
		world.setBlock(i + 19, j + 3, k + 3, Blocks.air, 0, 2);
		world.setBlock(i + 0, j + 3, k + 4, Blocks.air, 0, 2);
		world.setBlock(i + 1, j + 3, k + 4, PlaceCobbledDeepslate, 0, 2);
		world.setBlock(i + 2, j + 3, k + 4, PlaceCobbledDeepslate, 0, 2);
		world.setBlock(i + 3, j + 3, k + 4, Blocks.air, 0, 2);
		world.setBlock(i + 4, j + 3, k + 4, Blocks.air, 0, 2);
		world.setBlock(i + 6, j + 3, k + 4, Blocks.air, 0, 2);
		world.setBlock(i + 7, j + 3, k + 4, Blocks.air, 0, 2);
		world.setBlock(i + 8, j + 3, k + 4, Blocks.air, 0, 2);
		world.setBlock(i + 9, j + 3, k + 4, Blocks.air, 0, 2);
		world.setBlock(i + 10, j + 3, k + 4, Blocks.air, 0, 2);
		world.setBlock(i + 11, j + 3, k + 4, Blocks.air, 0, 2);
		world.setBlock(i + 12, j + 3, k + 4, Blocks.air, 0, 2);
		world.setBlock(i + 13, j + 3, k + 4, PlaceCobbledDeepslate, 0, 2);
		world.setBlock(i + 14, j + 3, k + 4, Blocks.air, 0, 2);
		world.setBlock(i + 15, j + 3, k + 4, PlaceCobbledDeepslate, 0, 2);
		world.setBlock(i + 16, j + 3, k + 4, PlaceCobbledDeepslate, 0, 2);
		world.setBlock(i + 17, j + 3, k + 4, Blocks.air, 0, 2);
		world.setBlock(i + 18, j + 3, k + 4, Blocks.air, 0, 2);
		world.setBlock(i + 19, j + 3, k + 4, Blocks.air, 0, 2);
		world.setBlock(i + 0, j + 3, k + 5, Blocks.air, 0, 2);
		world.setBlock(i + 1, j + 3, k + 5, PlaceCobbledDeepslate, 0, 2);
		world.setBlock(i + 2, j + 3, k + 5, PlaceCobbledDeepslate, 0, 2);
		world.setBlock(i + 3, j + 3, k + 5, Blocks.air, 0, 2);
		world.setBlock(i + 4, j + 3, k + 5, Blocks.air, 0, 2);
		world.setBlock(i + 5, j + 3, k + 5, Blocks.air, 0, 2);
		world.setBlock(i + 6, j + 3, k + 5, Blocks.air, 0, 2);
		world.setBlock(i + 7, j + 3, k + 5, Blocks.air, 0, 2);
		world.setBlock(i + 8, j + 3, k + 5, Blocks.air, 0, 2);
		world.setBlock(i + 9, j + 3, k + 5, Blocks.air, 0, 2);
		world.setBlock(i + 10, j + 3, k + 5, Blocks.air, 0, 2);
		world.setBlock(i + 11, j + 3, k + 5, Blocks.air, 0, 2);
		world.setBlock(i + 12, j + 3, k + 5, Blocks.air, 0, 2);
		world.setBlock(i + 13, j + 3, k + 5, Blocks.air, 0, 2);
		world.setBlock(i + 14, j + 3, k + 5, PlaceDeepslateTiles, 2, 2);
		world.setBlock(i + 15, j + 3, k + 5, Blocks.air, 0, 2);
		world.setBlock(i + 16, j + 3, k + 5, Blocks.air, 0, 2);
		world.setBlock(i + 17, j + 3, k + 5, Blocks.air, 0, 2);
		world.setBlock(i + 18, j + 3, k + 5, Blocks.air, 0, 2);
		world.setBlock(i + 19, j + 3, k + 5, PlaceDeepslateBricks, 0, 2);
		world.setBlock(i + 0, j + 3, k + 6, Blocks.air, 0, 2);
		world.setBlock(i + 1, j + 3, k + 6, PlaceCobbledDeepslate, 0, 2);
		world.setBlock(i + 2, j + 3, k + 6, Blocks.air, 0, 2);
		world.setBlock(i + 3, j + 3, k + 6, Blocks.air, 0, 2);
		world.setBlock(i + 4, j + 3, k + 6, Blocks.air, 0, 2);
		world.setBlock(i + 5, j + 3, k + 6, Blocks.air, 0, 2);
		world.setBlock(i + 6, j + 3, k + 6, Blocks.air, 0, 2);
		world.setBlock(i + 7, j + 3, k + 6, Blocks.air, 0, 2);
		world.setBlock(i + 8, j + 3, k + 6, Blocks.air, 0, 2);
		world.setBlock(i + 9, j + 3, k + 6, Blocks.air, 0, 2);
		world.setBlock(i + 10, j + 3, k + 6, Blocks.air, 0, 2);
		world.setBlock(i + 11, j + 3, k + 6, Blocks.air, 0, 2);
		world.setBlock(i + 12, j + 3, k + 6, Blocks.air, 0, 2);
		world.setBlock(i + 13, j + 3, k + 6, NovaCraftBlocks.sculk_vein, 4, 2);
		world.setBlock(i + 14, j + 3, k + 6, PlaceDeepslateTiles, 2, 2);
		world.setBlock(i + 15, j + 3, k + 6, PlaceDeepslateTiles, 2, 2);
		world.setBlock(i + 16, j + 3, k + 6, Blocks.air, 0, 2);
		world.setBlock(i + 17, j + 3, k + 6, Blocks.air, 0, 2);
		world.setBlock(i + 18, j + 3, k + 6, Blocks.air, 0, 2);
		world.setBlock(i + 19, j + 3, k + 6, Blocks.air, 0, 2);
		world.setBlock(i + 0, j + 3, k + 7, Blocks.air, 0, 2);
		world.setBlock(i + 1, j + 3, k + 7, Blocks.air, 0, 2);
		world.setBlock(i + 2, j + 3, k + 7, Blocks.air, 0, 2);
		world.setBlock(i + 3, j + 3, k + 7, Blocks.air, 0, 2);
		world.setBlock(i + 4, j + 3, k + 7, Blocks.air, 0, 2);
		world.setBlock(i + 5, j + 3, k + 7, Blocks.air, 0, 2);
		world.setBlock(i + 6, j + 3, k + 7, Blocks.air, 0, 2);
		world.setBlock(i + 7, j + 3, k + 7, Blocks.air, 0, 2);
		world.setBlock(i + 8, j + 3, k + 7, Blocks.air, 0, 2);
		world.setBlock(i + 9, j + 3, k + 7, Blocks.air, 0, 2);
		world.setBlock(i + 10, j + 3, k + 7, Blocks.air, 0, 2);
		world.setBlock(i + 11, j + 3, k + 7, Blocks.air, 0, 2);
		world.setBlock(i + 12, j + 3, k + 7, Blocks.air, 0, 2);
		world.setBlock(i + 13, j + 3, k + 7, Blocks.air, 0, 2);
		world.setBlock(i + 14, j + 3, k + 7, NovaCraftBlocks.sculk_vein, 3, 2);
		world.setBlock(i + 15, j + 3, k + 7, NovaCraftBlocks.sculk_vein, 3, 2);
		world.setBlock(i + 16, j + 3, k + 7, Blocks.air, 0, 2);
		world.setBlock(i + 17, j + 3, k + 7, Blocks.air, 0, 2);
		world.setBlock(i + 18, j + 3, k + 7, Blocks.air, 0, 2);
		world.setBlock(i + 19, j + 3, k + 7, Blocks.air, 0, 2);
		world.setBlock(i + 0, j + 3, k + 8, Blocks.air, 0, 2);
		world.setBlock(i + 1, j + 3, k + 8, PlaceCobbledDeepslate, 0, 2);
		world.setBlock(i + 2, j + 3, k + 8, PlaceCobbledDeepslate, 0, 2);
		world.setBlock(i + 3, j + 3, k + 8, PlaceChiseledDeepslate, 4, 2);
		world.setBlock(i + 4, j + 3, k + 8, Blocks.air, 0, 2);
		world.setBlock(i + 5, j + 3, k + 8, Blocks.air, 0, 2);
		world.setBlock(i + 6, j + 3, k + 8, Blocks.air, 0, 2);
		world.setBlock(i + 7, j + 3, k + 8, Blocks.air, 0, 2);
		world.setBlock(i + 8, j + 3, k + 8, Blocks.air, 0, 2);
		world.setBlock(i + 9, j + 3, k + 8, Blocks.air, 0, 2);
		world.setBlock(i + 10, j + 3, k + 8, Blocks.air, 0, 2);
		world.setBlock(i + 11, j + 3, k + 8, Blocks.air, 0, 2);
		world.setBlock(i + 12, j + 3, k + 8, Blocks.air, 0, 2);
		world.setBlock(i + 13, j + 3, k + 8, NovaCraftBlocks.sculk_vein, 4, 2);
		world.setBlock(i + 14, j + 3, k + 8, PlaceDeepslateTiles, 2, 2);
		world.setBlock(i + 15, j + 3, k + 8, PlaceCrackedDeepslateTiles, 3, 2);
		world.setBlock(i + 16, j + 3, k + 8, NovaCraftBlocks.sculk_vein, 5, 2);
		world.setBlock(i + 17, j + 3, k + 8, Blocks.air, 0, 2);
		world.setBlock(i + 18, j + 3, k + 8, Blocks.air, 0, 2);
		world.setBlock(i + 19, j + 3, k + 8, Blocks.air, 0, 2);
		world.setBlock(i + 0, j + 3, k + 9, Blocks.air, 0, 2);
		world.setBlock(i + 1, j + 3, k + 9, PlaceCobbledDeepslate, 0, 2);
		world.setBlock(i + 2, j + 3, k + 9, Blocks.air, 0, 2);
		world.setBlock(i + 3, j + 3, k + 9, Blocks.air, 0, 2);
		world.setBlock(i + 4, j + 3, k + 9, Blocks.air, 0, 2);
		world.setBlock(i + 5, j + 3, k + 9, Blocks.air, 0, 2);
		world.setBlock(i + 6, j + 3, k + 9, Blocks.air, 0, 2);
		world.setBlock(i + 7, j + 3, k + 9, Blocks.air, 0, 2);
		world.setBlock(i + 8, j + 3, k + 9, Blocks.air, 0, 2);
		world.setBlock(i + 9, j + 3, k + 9, Blocks.air, 0, 2);
		world.setBlock(i + 10, j + 3, k + 9, Blocks.air, 0, 2);
		world.setBlock(i + 11, j + 3, k + 9, Blocks.air, 0, 2);
		world.setBlock(i + 12, j + 3, k + 9, Blocks.air, 0, 2);
		world.setBlock(i + 13, j + 3, k + 9, Blocks.air, 0, 2);
		world.setBlock(i + 14, j + 3, k + 9, PlaceDeepslateTiles, 2, 2);
		world.setBlock(i + 15, j + 3, k + 9, PlaceDeepslateTiles, 2, 2);
		world.setBlock(i + 16, j + 3, k + 9, Blocks.air, 0, 2);
		world.setBlock(i + 17, j + 3, k + 9, Blocks.air, 0, 2);
		world.setBlock(i + 18, j + 3, k + 9, Blocks.air, 0, 2);
		world.setBlock(i + 19, j + 3, k + 9, Blocks.air, 0, 2);
		world.setBlock(i + 0, j + 3, k + 10, Blocks.air, 0, 2);
		world.setBlock(i + 1, j + 3, k + 10, PlaceCobbledDeepslate, 0, 2);
		world.setBlock(i + 2, j + 3, k + 10, PlaceCobbledDeepslate, 0, 2);
		world.setBlock(i + 3, j + 3, k + 10, Blocks.air, 0, 2);
		world.setBlock(i + 4, j + 3, k + 10, Blocks.air, 0, 2);
		world.setBlock(i + 5, j + 3, k + 10, Blocks.air, 0, 2);
		world.setBlock(i + 6, j + 3, k + 10, Blocks.air, 0, 2);
		world.setBlock(i + 7, j + 3, k + 10, Blocks.air, 0, 2);
		world.setBlock(i + 8, j + 3, k + 10, Blocks.air, 0, 2);
		world.setBlock(i + 9, j + 3, k + 10, Blocks.air, 0, 2);
		world.setBlock(i + 10, j + 3, k + 10, Blocks.air, 0, 2);
		world.setBlock(i + 11, j + 3, k + 10, Blocks.air, 0, 2);
		world.setBlock(i + 12, j + 3, k + 10, Blocks.air, 0, 2);
		world.setBlock(i + 13, j + 3, k + 10, Blocks.air, 0, 2);
		world.setBlock(i + 14, j + 3, k + 10, PlaceDeepslateBricks, 0, 2);
		world.setBlock(i + 15, j + 3, k + 10, PlaceChiseledDeepslate, 4, 2);
		world.setBlock(i + 16, j + 3, k + 10, PlaceChiseledDeepslate, 4, 2);
		world.setBlock(i + 17, j + 3, k + 10, Blocks.air, 0, 2);
		world.setBlock(i + 18, j + 3, k + 10, Blocks.air, 0, 2);
		world.setBlock(i + 19, j + 3, k + 10, PlaceDeepslateBricks, 0, 2);
		world.setBlock(i + 0, j + 3, k + 11, Blocks.air, 0, 2);
		world.setBlock(i + 1, j + 3, k + 11, PlaceCobbledDeepslate, 0, 2);
		world.setBlock(i + 2, j + 3, k + 11, PlaceCobbledDeepslate, 0, 2);
		world.setBlock(i + 3, j + 3, k + 11, Blocks.air, 0, 2);
		world.setBlock(i + 4, j + 3, k + 11, Blocks.air, 0, 2);
		world.setBlock(i + 5, j + 3, k + 11, Blocks.air, 0, 2);
		world.setBlock(i + 6, j + 3, k + 11, Blocks.air, 0, 2);
		world.setBlock(i + 7, j + 3, k + 11, Blocks.air, 0, 2);
		world.setBlock(i + 8, j + 3, k + 11, Blocks.air, 0, 2);
		world.setBlock(i + 9, j + 3, k + 11, Blocks.air, 0, 2);
		world.setBlock(i + 10, j + 3, k + 11, Blocks.air, 0, 2);
		world.setBlock(i + 11, j + 3, k + 11, Blocks.air, 0, 2);
		world.setBlock(i + 12, j + 3, k + 11, Blocks.air, 0, 2);
		world.setBlock(i + 13, j + 3, k + 11, PlaceCobbledDeepslate, 0, 2);
		world.setBlock(i + 14, j + 3, k + 11, PlaceCobbledDeepslate, 0, 2);
		world.setBlock(i + 15, j + 3, k + 11, PlaceCobbledDeepslate, 0, 2);
		world.setBlock(i + 16, j + 3, k + 11, NovaCraftBlocks.sculk_vein, 1, 2);
		world.setBlock(i + 17, j + 3, k + 11, Blocks.air, 0, 2);
		world.setBlock(i + 18, j + 3, k + 11, Blocks.air, 0, 2);
		world.setBlock(i + 19, j + 3, k + 11, Blocks.air, 0, 2);
		world.setBlock(i + 0, j + 3, k + 12, Blocks.air, 0, 2);
		world.setBlock(i + 1, j + 3, k + 12, PlaceCobbledDeepslate, 0, 2);
		world.setBlock(i + 2, j + 3, k + 12, PlaceCobbledDeepslate, 0, 2);
		world.setBlock(i + 3, j + 3, k + 12, Blocks.air, 0, 2);
		world.setBlock(i + 4, j + 3, k + 12, Blocks.air, 0, 2);
		world.setBlock(i + 5, j + 3, k + 12, Blocks.air, 0, 2);
		world.setBlock(i + 6, j + 3, k + 12, Blocks.air, 0, 2);
		world.setBlock(i + 7, j + 3, k + 12, Blocks.air, 0, 2);
		world.setBlock(i + 8, j + 3, k + 12, Blocks.air, 0, 2);
		world.setBlock(i + 9, j + 3, k + 12, Blocks.air, 0, 2);
		world.setBlock(i + 10, j + 3, k + 12, Blocks.air, 0, 2);
		world.setBlock(i + 11, j + 3, k + 12, Blocks.air, 0, 2);
		world.setBlock(i + 12, j + 3, k + 12, NovaCraftBlocks.sculk_vein, 4, 2);
		world.setBlock(i + 13, j + 3, k + 12, PlaceCobbledDeepslate, 0, 2);
		world.setBlock(i + 14, j + 3, k + 12, PlaceCobbledDeepslate, 0, 2);
		world.setBlock(i + 15, j + 3, k + 12, NovaCraftBlocks.sculk_block, 0, 2);
		world.setBlock(i + 16, j + 3, k + 12, NovaCraftBlocks.sculk_block, 0, 2);
		world.setBlock(i + 17, j + 3, k + 12, Blocks.air, 0, 2);
		world.setBlock(i + 18, j + 3, k + 12, Blocks.air, 0, 2);
		world.setBlock(i + 19, j + 3, k + 12, Blocks.air, 0, 2);
		world.setBlock(i + 0, j + 3, k + 13, Blocks.air, 0, 2);
		world.setBlock(i + 1, j + 3, k + 13, PlaceCobbledDeepslate, 0, 2);
		world.setBlock(i + 2, j + 3, k + 13, PlaceCobbledDeepslate, 0, 2);
		world.setBlock(i + 3, j + 3, k + 13, PlaceCobbledDeepslate, 0, 2);
		world.setBlock(i + 4, j + 3, k + 13, Blocks.air, 0, 2);
		world.setBlock(i + 5, j + 3, k + 13, PlaceCobbledDeepslate, 0, 2);
		world.setBlock(i + 6, j + 3, k + 13, PlaceCobbledDeepslate, 0, 2);
		world.setBlock(i + 7, j + 3, k + 13, PlaceCobbledDeepslate, 0, 2);
		world.setBlock(i + 8, j + 3, k + 13, PlaceCobbledDeepslate, 0, 2);
		world.setBlock(i + 9, j + 3, k + 13, PlaceCobbledDeepslate, 0, 2);
		world.setBlock(i + 10, j + 3, k + 13, PlaceCobbledDeepslate, 0, 2);
		world.setBlock(i + 11, j + 3, k + 13, PlaceCobbledDeepslate, 0, 2);
		world.setBlock(i + 12, j + 3, k + 13, PlaceCobbledDeepslate, 0, 2);
		world.setBlock(i + 13, j + 3, k + 13, NovaCraftBlocks.sculk_block, 0, 2);
		world.setBlock(i + 14, j + 3, k + 13, NovaCraftBlocks.sculk_block, 0, 2);
		world.setBlock(i + 15, j + 3, k + 13, NovaCraftBlocks.sculk_block, 0, 2);
		world.setBlock(i + 16, j + 3, k + 13, Blocks.air, 0, 2);
		world.setBlock(i + 17, j + 3, k + 13, Blocks.air, 0, 2);
		world.setBlock(i + 18, j + 3, k + 13, Blocks.air, 0, 2);
		world.setBlock(i + 19, j + 3, k + 13, Blocks.air, 0, 2);
		world.setBlock(i + 0, j + 3, k + 14, Blocks.air, 0, 2);
		world.setBlock(i + 1, j + 3, k + 14, PlaceCobbledDeepslate, 0, 2);
		world.setBlock(i + 2, j + 3, k + 14, PlaceCobbledDeepslate, 0, 2);
		world.setBlock(i + 3, j + 3, k + 14, PlaceCobbledDeepslate, 0, 2);
		world.setBlock(i + 4, j + 3, k + 14, PlaceCobbledDeepslate, 0, 2);
		world.setBlock(i + 5, j + 3, k + 14, PlaceCobbledDeepslate, 0, 2);
		world.setBlock(i + 6, j + 3, k + 14, PlaceCobbledDeepslate, 0, 2);
		world.setBlock(i + 7, j + 3, k + 14, PlaceCobbledDeepslate, 0, 2);
		world.setBlock(i + 8, j + 3, k + 14, NovaCraftBlocks.sculk_vein, 3, 2);
		world.setBlock(i + 9, j + 3, k + 14, NovaCraftBlocks.sculk_block, 0, 2);
		world.setBlock(i + 10, j + 3, k + 14, NovaCraftBlocks.sculk_block, 0, 2);
		world.setBlock(i + 11, j + 3, k + 14, NovaCraftBlocks.sculk_block, 0, 2);
		world.setBlock(i + 12, j + 3, k + 14, NovaCraftBlocks.sculk_block, 0, 2);
		world.setBlock(i + 13, j + 3, k + 14, NovaCraftBlocks.sculk_block, 0, 2);
		world.setBlock(i + 14, j + 3, k + 14, NovaCraftBlocks.sculk_block, 0, 2);
		world.setBlock(i + 15, j + 3, k + 14, Blocks.air, 0, 2);
		world.setBlock(i + 16, j + 3, k + 14, NovaCraftBlocks.sculk_block, 0, 2);
		world.setBlock(i + 17, j + 3, k + 14, NovaCraftBlocks.sculk_block, 0, 2);
		world.setBlock(i + 18, j + 3, k + 14, PlaceCrackedDeepslateBricks, 1, 2);
		world.setBlock(i + 19, j + 3, k + 14, Blocks.air, 0, 2);
		world.setBlock(i + 0, j + 3, k + 15, Blocks.air, 0, 2);
		world.setBlock(i + 1, j + 3, k + 15, Blocks.air, 0, 2);
		world.setBlock(i + 2, j + 3, k + 15, Blocks.air, 0, 2);
		world.setBlock(i + 3, j + 3, k + 15, Blocks.air, 0, 2);
		world.setBlock(i + 4, j + 3, k + 15, Blocks.air, 0, 2);
		world.setBlock(i + 5, j + 3, k + 15, Blocks.air, 0, 2);
		world.setBlock(i + 6, j + 3, k + 15, NovaCraftBlocks.sculk_vein, 3, 2);
		world.setBlock(i + 7, j + 3, k + 15, NovaCraftBlocks.sculk_vein, 3, 2);
		world.setBlock(i + 8, j + 3, k + 15, Blocks.air, 0, 2);
		world.setBlock(i + 9, j + 3, k + 15, Blocks.air, 0, 2);
		world.setBlock(i + 10, j + 3, k + 15, Blocks.air, 0, 2);
		world.setBlock(i + 11, j + 3, k + 15, Blocks.air, 0, 2);
		world.setBlock(i + 12, j + 3, k + 15, Blocks.air, 0, 2);
		world.setBlock(i + 13, j + 3, k + 15, Blocks.air, 0, 2);
		world.setBlock(i + 14, j + 3, k + 15, Blocks.air, 0, 2);
		world.setBlock(i + 15, j + 3, k + 15, Blocks.air, 0, 2);
		world.setBlock(i + 16, j + 3, k + 15, NovaCraftBlocks.sculk_block, 0, 2);
		world.setBlock(i + 17, j + 3, k + 15, NovaCraftBlocks.sculk_block, 0, 2);
		world.setBlock(i + 18, j + 3, k + 15, PlaceDeepslateBricks, 0, 2);
		world.setBlock(i + 19, j + 3, k + 15, Blocks.air, 0, 2);
		world.setBlock(i + 0, j + 4, k + 0, Blocks.air, 0, 2);
		world.setBlock(i + 1, j + 4, k + 0, Blocks.air, 0, 2);
		world.setBlock(i + 2, j + 4, k + 0, Blocks.air, 0, 2);
		world.setBlock(i + 3, j + 4, k + 0, Blocks.air, 0, 2);
		world.setBlock(i + 4, j + 4, k + 0, Blocks.air, 0, 2);
		world.setBlock(i + 5, j + 4, k + 0, Blocks.air, 0, 2);
		world.setBlock(i + 6, j + 4, k + 0, Blocks.air, 0, 2);
		world.setBlock(i + 7, j + 4, k + 0, Blocks.air, 0, 2);
		world.setBlock(i + 8, j + 4, k + 0, Blocks.air, 0, 2);
		world.setBlock(i + 9, j + 4, k + 0, Blocks.air, 0, 2);
		world.setBlock(i + 10, j + 4, k + 0, Blocks.air, 0, 2);
		world.setBlock(i + 11, j + 4, k + 0, Blocks.air, 0, 2);
		world.setBlock(i + 12, j + 4, k + 0, Blocks.air, 0, 2);
		world.setBlock(i + 13, j + 4, k + 0, Blocks.air, 0, 2);
		world.setBlock(i + 14, j + 4, k + 0, Blocks.air, 0, 2);
		world.setBlock(i + 15, j + 4, k + 0, Blocks.air, 0, 2);
		world.setBlock(i + 16, j + 4, k + 0, Blocks.air, 0, 2);
		world.setBlock(i + 17, j + 4, k + 0, Blocks.air, 0, 2);
		world.setBlock(i + 18, j + 4, k + 0, Blocks.air, 0, 2);
		world.setBlock(i + 19, j + 4, k + 0, Blocks.air, 0, 2);
		world.setBlock(i + 0, j + 4, k + 1, Blocks.air, 0, 2);
		world.setBlock(i + 1, j + 4, k + 1, Blocks.air, 0, 2);
		world.setBlock(i + 2, j + 4, k + 1, Blocks.air, 0, 2);
		world.setBlock(i + 3, j + 4, k + 1, Blocks.air, 0, 2);
		world.setBlock(i + 4, j + 4, k + 1, Blocks.air, 0, 2);
		world.setBlock(i + 5, j + 4, k + 1, Blocks.air, 0, 2);
		world.setBlock(i + 6, j + 4, k + 1, Blocks.air, 0, 2);
		world.setBlock(i + 7, j + 4, k + 1, Blocks.air, 0, 2);
		world.setBlock(i + 8, j + 4, k + 1, Blocks.air, 0, 2);
		world.setBlock(i + 9, j + 4, k + 1, Blocks.air, 0, 2);
		world.setBlock(i + 10, j + 4, k + 1, Blocks.air, 0, 2);
		world.setBlock(i + 11, j + 4, k + 1, Blocks.air, 0, 2);
		world.setBlock(i + 12, j + 4, k + 1, Blocks.air, 0, 2);
		world.setBlock(i + 13, j + 4, k + 1, Blocks.air, 0, 2);
		world.setBlock(i + 14, j + 4, k + 1, Blocks.air, 0, 2);
		world.setBlock(i + 15, j + 4, k + 1, Blocks.air, 0, 2);
		world.setBlock(i + 16, j + 4, k + 1, PlaceCrackedDeepslateBricks, 1, 2);
		world.setBlock(i + 17, j + 4, k + 1, PlaceDeepslateBricks, 0, 2);
		world.setBlock(i + 18, j + 4, k + 1, PlaceCrackedDeepslateBricks, 1, 2);
		world.setBlock(i + 19, j + 4, k + 1, Blocks.air, 0, 2);
		world.setBlock(i + 0, j + 4, k + 2, Blocks.air, 0, 2);
		world.setBlock(i + 1, j + 4, k + 2, Blocks.air, 0, 2);
		world.setBlock(i + 2, j + 4, k + 2, Blocks.air, 0, 2);
		world.setBlock(i + 3, j + 4, k + 2, Blocks.air, 0, 2);
		world.setBlock(i + 4, j + 4, k + 2, Blocks.air, 0, 2);
		world.setBlock(i + 5, j + 4, k + 2, Blocks.air, 0, 2);
		world.setBlock(i + 6, j + 4, k + 2, Blocks.air, 0, 2);
		world.setBlock(i + 7, j + 4, k + 2, Blocks.air, 0, 2);
		world.setBlock(i + 8, j + 4, k + 2, Blocks.air, 0, 2);
		world.setBlock(i + 9, j + 4, k + 2, Blocks.air, 0, 2);
		world.setBlock(i + 10, j + 4, k + 2, Blocks.air, 0, 2);
		world.setBlock(i + 11, j + 4, k + 2, Blocks.air, 0, 2);
		world.setBlock(i + 12, j + 4, k + 2, Blocks.air, 0, 2);
		world.setBlock(i + 13, j + 4, k + 2, Blocks.air, 0, 2);
		world.setBlock(i + 14, j + 4, k + 2, Blocks.air, 0, 2);
		world.setBlock(i + 15, j + 4, k + 2, Blocks.air, 0, 2);
		world.setBlock(i + 16, j + 4, k + 2, PlaceCrackedDeepslateBricks, 1, 2);
		world.setBlock(i + 17, j + 4, k + 2, Blocks.air, 0, 2);
		world.setBlock(i + 18, j + 4, k + 2, PlaceDeepslateBricks, 0, 2);
		world.setBlock(i + 19, j + 4, k + 2, Blocks.air, 0, 2);
		world.setBlock(i + 0, j + 4, k + 3, Blocks.air, 0, 2);
		world.setBlock(i + 1, j + 4, k + 3, Blocks.air, 0, 2);
		world.setBlock(i + 2, j + 4, k + 3, PlaceCobbledDeepslate, 0, 2);
		world.setBlock(i + 3, j + 4, k + 3, Blocks.air, 0, 2);
		world.setBlock(i + 4, j + 4, k + 3, Blocks.air, 0, 2);
		world.setBlock(i + 5, j + 4, k + 3, PlaceCobbledDeepslate, 0, 2);
		world.setBlock(i + 6, j + 4, k + 3, PlaceCobbledDeepslate, 0, 2);
		world.setBlock(i + 7, j + 4, k + 3, PlaceDeepslateBricks, 0, 2);
		world.setBlock(i + 8, j + 4, k + 3, PlaceDeepslateTiles, 2, 2);
		world.setBlock(i + 9, j + 4, k + 3, PlaceChiseledDeepslate, 4, 2);
		world.setBlock(i + 10, j + 4, k + 3, Blocks.air, 0, 2);
		world.setBlock(i + 11, j + 4, k + 3, Blocks.air, 0, 2);
		world.setBlock(i + 12, j + 4, k + 3, Blocks.air, 0, 2);
		world.setBlock(i + 13, j + 4, k + 3, Blocks.air, 0, 2);
		world.setBlock(i + 14, j + 4, k + 3, Blocks.air, 0, 2);
		world.setBlock(i + 15, j + 4, k + 3, Blocks.air, 0, 2);
		world.setBlock(i + 16, j + 4, k + 3, Blocks.air, 0, 2);
		world.setBlock(i + 17, j + 4, k + 3, Blocks.air, 0, 2);
		world.setBlock(i + 18, j + 4, k + 3, Blocks.air, 0, 2);
		world.setBlock(i + 19, j + 4, k + 3, Blocks.air, 0, 2);
		world.setBlock(i + 0, j + 4, k + 4, Blocks.air, 0, 2);
		world.setBlock(i + 1, j + 4, k + 4, Blocks.air, 0, 2);
		world.setBlock(i + 2, j + 4, k + 4, PlaceCobbledDeepslate, 0, 2);
		world.setBlock(i + 3, j + 4, k + 4, Blocks.air, 0, 2);
		world.setBlock(i + 4, j + 4, k + 4, Blocks.air, 0, 2);
		world.setBlock(i + 5, j + 4, k + 4, Blocks.air, 0, 2);
		world.setBlock(i + 6, j + 4, k + 4, Blocks.air, 0, 2);
		world.setBlock(i + 7, j + 4, k + 4, Blocks.air, 0, 2);
		world.setBlock(i + 8, j + 4, k + 4, Blocks.air, 0, 2);
		world.setBlock(i + 9, j + 4, k + 4, Blocks.air, 0, 2);
		world.setBlock(i + 10, j + 4, k + 4, Blocks.air, 0, 2);
		world.setBlock(i + 11, j + 4, k + 4, Blocks.air, 0, 2);
		world.setBlock(i + 12, j + 4, k + 4, Blocks.air, 0, 2);
		world.setBlock(i + 13, j + 4, k + 4, Blocks.air, 0, 2);
		world.setBlock(i + 14, j + 4, k + 4, Blocks.air, 0, 2);
		world.setBlock(i + 15, j + 4, k + 4, Blocks.air, 0, 2);
		world.setBlock(i + 16, j + 4, k + 4, Blocks.air, 0, 2);
		world.setBlock(i + 17, j + 4, k + 4, Blocks.air, 0, 2);
		world.setBlock(i + 18, j + 4, k + 4, Blocks.air, 0, 2);
		world.setBlock(i + 19, j + 4, k + 4, Blocks.air, 0, 2);
		world.setBlock(i + 0, j + 4, k + 5, Blocks.air, 0, 2);
		world.setBlock(i + 1, j + 4, k + 5, Blocks.air, 0, 2);
		world.setBlock(i + 2, j + 4, k + 5, PlaceCobbledDeepslate, 0, 2);
		world.setBlock(i + 3, j + 4, k + 5, Blocks.air, 0, 2);
		world.setBlock(i + 4, j + 4, k + 5, Blocks.air, 0, 2);
		world.setBlock(i + 5, j + 4, k + 5, Blocks.air, 0, 2);
		world.setBlock(i + 6, j + 4, k + 5, Blocks.air, 0, 2);
		world.setBlock(i + 7, j + 4, k + 5, Blocks.air, 0, 2);
		world.setBlock(i + 8, j + 4, k + 5, Blocks.air, 0, 2);
		world.setBlock(i + 9, j + 4, k + 5, Blocks.air, 0, 2);
		world.setBlock(i + 10, j + 4, k + 5, Blocks.air, 0, 2);
		world.setBlock(i + 11, j + 4, k + 5, Blocks.air, 0, 2);
		world.setBlock(i + 12, j + 4, k + 5, Blocks.air, 0, 2);
		world.setBlock(i + 13, j + 4, k + 5, Blocks.air, 0, 2);
		world.setBlock(i + 14, j + 4, k + 5, PlaceCrackedDeepslateTiles, 3, 2);
		world.setBlock(i + 15, j + 4, k + 5, Blocks.air, 0, 2);
		world.setBlock(i + 16, j + 4, k + 5, Blocks.air, 0, 2);
		world.setBlock(i + 17, j + 4, k + 5, Blocks.air, 0, 2);
		world.setBlock(i + 18, j + 4, k + 5, Blocks.air, 0, 2);
		world.setBlock(i + 19, j + 4, k + 5, Blocks.air, 0, 2);
		world.setBlock(i + 0, j + 4, k + 6, Blocks.air, 0, 2);
		world.setBlock(i + 1, j + 4, k + 6, Blocks.air, 0, 2);
		world.setBlock(i + 2, j + 4, k + 6, Blocks.air, 0, 2);
		world.setBlock(i + 3, j + 4, k + 6, Blocks.air, 0, 2);
		world.setBlock(i + 4, j + 4, k + 6, Blocks.air, 0, 2);
		world.setBlock(i + 5, j + 4, k + 6, Blocks.air, 0, 2);
		world.setBlock(i + 6, j + 4, k + 6, Blocks.air, 0, 2);
		world.setBlock(i + 7, j + 4, k + 6, Blocks.air, 0, 2);
		world.setBlock(i + 8, j + 4, k + 6, Blocks.air, 0, 2);
		world.setBlock(i + 9, j + 4, k + 6, Blocks.air, 0, 2);
		world.setBlock(i + 10, j + 4, k + 6, Blocks.air, 0, 2);
		world.setBlock(i + 11, j + 4, k + 6, Blocks.air, 0, 2);
		world.setBlock(i + 12, j + 4, k + 6, Blocks.air, 0, 2);
		world.setBlock(i + 13, j + 4, k + 6, Blocks.air, 0, 2);
		world.setBlock(i + 14, j + 4, k + 6, Blocks.air, 0, 2);
		world.setBlock(i + 15, j + 4, k + 6, Blocks.air, 0, 2);
		world.setBlock(i + 16, j + 4, k + 6, Blocks.air, 0, 2);
		world.setBlock(i + 17, j + 4, k + 6, Blocks.air, 0, 2);
		world.setBlock(i + 18, j + 4, k + 6, Blocks.air, 0, 2);
		world.setBlock(i + 19, j + 4, k + 6, Blocks.air, 0, 2);
		world.setBlock(i + 0, j + 4, k + 7, Blocks.air, 0, 2);
		world.setBlock(i + 1, j + 4, k + 7, Blocks.air, 0, 2);
		world.setBlock(i + 2, j + 4, k + 7, Blocks.air, 0, 2);
		world.setBlock(i + 3, j + 4, k + 7, Blocks.air, 0, 2);
		world.setBlock(i + 4, j + 4, k + 7, Blocks.air, 0, 2);
		world.setBlock(i + 5, j + 4, k + 7, Blocks.air, 0, 2);
		world.setBlock(i + 6, j + 4, k + 7, Blocks.air, 0, 2);
		world.setBlock(i + 7, j + 4, k + 7, Blocks.air, 0, 2);
		world.setBlock(i + 8, j + 4, k + 7, Blocks.air, 0, 2);
		world.setBlock(i + 9, j + 4, k + 7, Blocks.air, 0, 2);
		world.setBlock(i + 10, j + 4, k + 7, Blocks.air, 0, 2);
		world.setBlock(i + 11, j + 4, k + 7, Blocks.air, 0, 2);
		world.setBlock(i + 12, j + 4, k + 7, Blocks.air, 0, 2);
		world.setBlock(i + 13, j + 4, k + 7, Blocks.air, 0, 2);
		world.setBlock(i + 14, j + 4, k + 7, Blocks.air, 0, 2);
		world.setBlock(i + 15, j + 4, k + 7, Blocks.air, 0, 2);
		world.setBlock(i + 16, j + 4, k + 7, Blocks.air, 0, 2);
		world.setBlock(i + 17, j + 4, k + 7, Blocks.air, 0, 2);
		world.setBlock(i + 18, j + 4, k + 7, Blocks.air, 0, 2);
		world.setBlock(i + 19, j + 4, k + 7, Blocks.air, 0, 2);
		world.setBlock(i + 0, j + 4, k + 8, Blocks.air, 0, 2);
		world.setBlock(i + 1, j + 4, k + 8, Blocks.air, 0, 2);
		world.setBlock(i + 2, j + 4, k + 8, PlaceCobbledDeepslate, 0, 2);
		world.setBlock(i + 3, j + 4, k + 8, PlaceDeepslateBricks, 0, 2);
		world.setBlock(i + 4, j + 4, k + 8, Blocks.air, 0, 2);
		world.setBlock(i + 5, j + 4, k + 8, Blocks.air, 0, 2);
		world.setBlock(i + 6, j + 4, k + 8, Blocks.air, 0, 2);
		world.setBlock(i + 7, j + 4, k + 8, Blocks.air, 0, 2);
		world.setBlock(i + 8, j + 4, k + 8, Blocks.air, 0, 2);
		world.setBlock(i + 9, j + 4, k + 8, Blocks.air, 0, 2);
		world.setBlock(i + 10, j + 4, k + 8, Blocks.air, 0, 2);
		world.setBlock(i + 11, j + 4, k + 8, Blocks.air, 0, 2);
		world.setBlock(i + 12, j + 4, k + 8, Blocks.air, 0, 2);
		world.setBlock(i + 13, j + 4, k + 8, Blocks.air, 0, 2);
		world.setBlock(i + 14, j + 4, k + 8, Blocks.air, 0, 2);
		world.setBlock(i + 15, j + 4, k + 8, Blocks.air, 0, 2);
		world.setBlock(i + 16, j + 4, k + 8, Blocks.air, 0, 2);
		world.setBlock(i + 17, j + 4, k + 8, Blocks.air, 0, 2);
		world.setBlock(i + 18, j + 4, k + 8, Blocks.air, 0, 2);
		world.setBlock(i + 19, j + 4, k + 8, Blocks.air, 0, 2);
		world.setBlock(i + 0, j + 4, k + 9, Blocks.air, 0, 2);
		world.setBlock(i + 1, j + 4, k + 9, Blocks.air, 0, 2);
		world.setBlock(i + 2, j + 4, k + 9, PlaceCobbledDeepslate, 0, 2);
		world.setBlock(i + 3, j + 4, k + 9, Blocks.air, 0, 2);
		world.setBlock(i + 4, j + 4, k + 9, Blocks.air, 0, 2);
		world.setBlock(i + 5, j + 4, k + 9, Blocks.air, 0, 2);
		world.setBlock(i + 6, j + 4, k + 9, Blocks.air, 0, 2);
		world.setBlock(i + 7, j + 4, k + 9, Blocks.air, 0, 2);
		world.setBlock(i + 8, j + 4, k + 9, Blocks.air, 0, 2);
		world.setBlock(i + 9, j + 4, k + 9, Blocks.air, 0, 2);
		world.setBlock(i + 10, j + 4, k + 9, Blocks.air, 0, 2);
		world.setBlock(i + 11, j + 4, k + 9, Blocks.air, 0, 2);
		world.setBlock(i + 12, j + 4, k + 9, Blocks.air, 0, 2);
		world.setBlock(i + 13, j + 4, k + 9, Blocks.air, 0, 2);
		world.setBlock(i + 14, j + 4, k + 9, PlaceDeepslateTiles, 2, 2);
