package com.NovaCraft.world.ancient_city;

import cpw.mods.fml.common.registry.GameRegistry;
import net.minecraft.world.gen.feature.*;
import net.minecraft.block.*;
import net.minecraft.enchantment.Enchantment;
import net.minecraft.enchantment.EnchantmentData;
import net.minecraft.world.*;
import java.util.*;

import com.NovaCraft.Items.NovaCraftItems;
import com.NovaCraft.config.Configs;
import com.NovaCraft.entity.EntityWardenVessel;
import com.NovaCraft.registry.OtherModBlocks;
import com.NovaCraft.registry.OtherModItems;
import com.NovaCraftBlocks.NovaCraftBlocks;

import cpw.mods.fml.common.Loader;
import net.minecraft.init.*;
import net.minecraft.item.ItemStack;
import net.minecraft.tileentity.TileEntityChest;
import net.minecraft.tileentity.TileEntityMobSpawner;
import net.minecraft.util.MathHelper;

public class AncientCityNegativeXShrineGen1 extends WorldGenerator
{
	public AncientCityNegativeXShrineGen1() {

	}
	
	private Block PlaceDeepslate;
	private Block PlaceDeepslateBricks;
	private Block PlaceDeepslateTiles;
	private Block PlaceCrackedDeepslateTiles;
	private Block PlaceCrackedDeepslateBricks;
	private Block PlaceChiseledDeepslate;
	private Block PlacePolishedDeepslate;
	private Block PlaceCobbledDeepslate;
	
	private Block PlaceDeepslateBrickSlab;
	private Block PlaceDeepslateTileStairs;
	private Block PlaceDeepslateBrickStairs;
	private Block PlaceCobbledDeepslateStairs;
	private Block PlaceDeepslateBrickWall;

	private Block determineIfCobbledDeepslateExists(World world, int x, int y, int z) {
		Block existingBlock = world.getBlock(x, y, z);
		if (Configs.enableCobbledDeepslateInAncientCity && Loader.isModLoaded("etfuturum")) {
			try {
				Block cobbled_deepslate = GameRegistry.findBlock("etfuturum", "cobbled_deepslate");
				if (cobbled_deepslate != null && (existingBlock == null || existingBlock != cobbled_deepslate)) {
					return cobbled_deepslate;
				}
			} catch (Exception ex) {
				if (Configs.enableDebugMode) {
					System.out.println("Missing Cobbled Deepslate from Et Futurum Requiem, using Cobbled Grimstone instead...");
				}
				return NovaCraftBlocks.cobbled_grimstone;
			}
		}

		return NovaCraftBlocks.cobbled_grimstone;
	}

	private Block determineIfDeepslateExists(World world, int x, int y, int z) {
		Block existingBlock = world.getBlock(x, y, z);
		if (Configs.enableDeepslateInAncientCity && Loader.isModLoaded("etfuturum")) {
			try {
				Block deepslate = GameRegistry.findBlock("etfuturum", "deepslate");
				if (deepslate != null && (existingBlock == null || existingBlock != deepslate)) {
					return deepslate;
				}
			} catch (Exception ex) {
				if (Configs.enableDebugMode) {
					System.out.println("Missing Deepslate from Et Futurum Requiem, using Grimstone instead...");
				}
				return NovaCraftBlocks.grimstone;
			}
		}

		return NovaCraftBlocks.grimstone;
	}

	private Block determineIfDeepslateBricksExists(World world, int x, int y, int z) {
		Block existingBlock = world.getBlock(x, y, z);
		if (Configs.enableDeepslateBricksInAncientCity && Loader.isModLoaded("etfuturum")) {
			try {
				Block deepslate_bricks = GameRegistry.findBlock("etfuturum", "deepslate_bricks");
				if (deepslate_bricks != null && (existingBlock == null || existingBlock != deepslate_bricks)) {
					return deepslate_bricks;
				}
			} catch (Exception ex) {
				if (Configs.enableDebugMode) {
					System.out.println("Missing Deepslate Bricks from Et Futurum Requiem, using Grimstone Bricks instead...");
				}
				return NovaCraftBlocks.grimstone_bricks;
			}
		}

		return NovaCraftBlocks.grimstone_bricks;
	}

	private Block determineIfCrackedDeepslateBricksExists(World world, int x, int y, int z) {
		Block existingBlock = world.getBlock(x, y, z);
		if (Configs.enableDeepslateBricksInAncientCity && Loader.isModLoaded("etfuturum")) {
			try {
				Block deepslate_bricks = GameRegistry.findBlock("etfuturum", "deepslate_bricks");
				if (deepslate_bricks != null && (existingBlock == null || existingBlock != deepslate_bricks)) {
					return deepslate_bricks;
				}
			} catch (Exception ex) {
				if (Configs.enableDebugMode) {
					System.out.println("Missing Cracked Deepslate Bricks from Et Futurum Requiem, using Cracked Grimstone Bricks instead...");
				}
				return NovaCraftBlocks.cracked_grimstone_bricks;
			}
		}

		return NovaCraftBlocks.cracked_grimstone_bricks;
	}

	private Block determineIfDeepslateTilesExist(World world, int x, int y, int z) {
		Block existingBlock = world.getBlock(x, y, z);
		if (Configs.enableDeepslateBricksInAncientCity && Loader.isModLoaded("etfuturum")) {
			try {
				Block deepslate_bricks = GameRegistry.findBlock("etfuturum", "deepslate_bricks");
				if (deepslate_bricks != null && (existingBlock == null || existingBlock != deepslate_bricks)) {
					return deepslate_bricks;
				}
			} catch (Exception ex) {
				if (Configs.enableDebugMode) {
					System.out.println("Missing Deepslate Tiles from Et Futurum Requiem, using Grimstone Tiles instead...");
				}
				return NovaCraftBlocks.grimstone_tiles;
			}
		}

		return NovaCraftBlocks.grimstone_tiles;
	}

	private Block determineIfCrackedDeepslateTilesExist(World world, int x, int y, int z) {
		Block existingBlock = world.getBlock(x, y, z);
		if (Configs.enableDeepslateBricksInAncientCity && Loader.isModLoaded("etfuturum")) {
			try {
				Block deepslate_bricks = GameRegistry.findBlock("etfuturum", "deepslate_bricks");
				if (deepslate_bricks != null && (existingBlock == null || existingBlock != deepslate_bricks)) {
					return deepslate_bricks;
				}
			} catch (Exception ex) {
				if (Configs.enableDebugMode) {
					System.out.println("Missing Cracked Deepslate Tiles from Et Futurum Requiem, using Cracked Grimstone Tiles instead...");
				}
				return NovaCraftBlocks.cracked_grimstone_tiles;
			}
		}

		return NovaCraftBlocks.cracked_grimstone_tiles;
	}

	private Block determineIfPolishedDeepslateExists(World world, int x, int y, int z) {
		Block existingBlock = world.getBlock(x, y, z);
		if (Configs.enableDeepslateBricksInAncientCity && Loader.isModLoaded("etfuturum")) {
			try {
				Block polished_deepslate = GameRegistry.findBlock("etfuturum", "polished_deepslate");
				if (polished_deepslate != null && (existingBlock == null || existingBlock != polished_deepslate)) {
					return polished_deepslate;
				}
			} catch (Exception ex) {
				if (Configs.enableDebugMode) {
					System.out.println("Missing Polished Deepslate from Et Futurum Requiem, using Polished Grimstone instead...");
				}
				return NovaCraftBlocks.polished_grimstone;
			}
		}

		return NovaCraftBlocks.polished_grimstone;
	}

	private Block determineIfChiseledDeepslateExist(World world, int x, int y, int z) {
		Block existingBlock = world.getBlock(x, y, z);
		if (Configs.enableDeepslateBricksInAncientCity && Loader.isModLoaded("etfuturum")) {
			try {
				Block deepslate_bricks = GameRegistry.findBlock("etfuturum", "deepslate_bricks");
				if (deepslate_bricks != null && (existingBlock == null || existingBlock != deepslate_bricks)) {
					return deepslate_bricks;
				}
			} catch (Exception ex) {
				if (Configs.enableDebugMode) {
					System.out.println("Missing Chiseled Deepslate from Et Futurum Requiem, using Chiseled Grimstone instead...");
				}
				return NovaCraftBlocks.chiseled_grimstone;
			}
		}

		return NovaCraftBlocks.chiseled_grimstone;
	}

	private Block determineIfDeepslateTileStairsExists(World world, int x, int y, int z) {
		Block existingBlock = world.getBlock(x, y, z);
		if (Configs.enableDeepslateBricksInAncientCity && Loader.isModLoaded("etfuturum")) {
			try {
				Block deepslate_tile_stairs = GameRegistry.findBlock("etfuturum", "deepslate_tile_stairs");
				if (deepslate_tile_stairs != null && (existingBlock == null || existingBlock != deepslate_tile_stairs)) {
					return deepslate_tile_stairs;
				}
			} catch (Exception ex) {
				if (Configs.enableDebugMode) {
					System.out.println("Missing Deepslate Tile Stairs from Et Futurum Requiem, using Grimstone Tile Stairs instead...");
				}
				return NovaCraftBlocks.grimstone_tiled_stairs;
			}
		}

		return NovaCraftBlocks.grimstone_tiled_stairs;
	}

	private Block determineIfDeepslateBrickStairsExists(World world, int x, int y, int z) {
		Block existingBlock = world.getBlock(x, y, z);
		if (Configs.enableDeepslateBricksInAncientCity && Loader.isModLoaded("etfuturum")) {
			try {
				Block deepslate_brick_stairs = GameRegistry.findBlock("etfuturum", "deepslate_brick_stairs");
				if (deepslate_brick_stairs != null && (existingBlock == null || existingBlock != deepslate_brick_stairs)) {
					return deepslate_brick_stairs;
				}
			} catch (Exception ex) {
				if (Configs.enableDebugMode) {
					System.out.println("Missing Deepslate Tile Stairs from Et Futurum Requiem, using Grimstone Tile Stairs instead...");
				}
				return NovaCraftBlocks.grimstone_brick_stairs;
			}
		}

		return NovaCraftBlocks.grimstone_brick_stairs;
	}

	private Block determineIfDeepslateSlabExists(World world, int x, int y, int z) {
		Block existingBlock = world.getBlock(x, y, z);
		if (Configs.enableDeepslateBricksInAncientCity && Loader.isModLoaded("etfuturum")) {
			try {
				Block deepslate_brick_wall = GameRegistry.findBlock("etfuturum", "deepslate_brick_wall");
				if (deepslate_brick_wall != null && (existingBlock == null || existingBlock != deepslate_brick_wall)) {
					return deepslate_brick_wall;
				}
			} catch (Exception ex) {
				if (Configs.enableDebugMode) {
					System.out.println("Missing Deepslate Brick Wall from Et Futurum Requiem, using Grimstone Brick Wall instead...");
				}
				return NovaCraftBlocks.grimstone_brick_wall;
			}
		}

		return NovaCraftBlocks.grimstone_brick_wall;
	}

	private Block determineIfDeepslateBrickWallExists(World world, int x, int y, int z) {
		Block existingBlock = world.getBlock(x, y, z);
		if (Configs.enableDeepslateBricksInAncientCity && Loader.isModLoaded("etfuturum")) {
			try {
				Block deepslate_brick_wall = GameRegistry.findBlock("etfuturum", "deepslate_brick_wall");
				if (deepslate_brick_wall != null && (existingBlock == null || existingBlock != deepslate_brick_wall)) {
					return deepslate_brick_wall;
				}
			} catch (Exception ex) {
				if (Configs.enableDebugMode) {
					System.out.println("Missing Deepslate Brick Slab from Et Futurum Requiem, using Grimstone Brick Slab instead...");
				}
				return NovaCraftBlocks.grimstone_brick_wall;
			}
		}

		return NovaCraftBlocks.grimstone_brick_wall;
	}

	private Block determineIfCobbledDeepslateStairsExists(World world, int x, int y, int z) {
		Block existingBlock = world.getBlock(x, y, z);
		if (Configs.enableCobbledDeepslateInAncientCity && Loader.isModLoaded("etfuturum")) {
			try {
				Block cobbled_deepslate_stairs = GameRegistry.findBlock("etfuturum", "cobbled_deepslate_stairs");
				if (cobbled_deepslate_stairs != null && (existingBlock == null || existingBlock != cobbled_deepslate_stairs)) {
					return cobbled_deepslate_stairs;
				}
			} catch (Exception ex) {
				if (Configs.enableDebugMode) {
					System.out.println("Missing Cobbled Deepslate Stairs from Et Futurum Requiem, using Cobbled Grimstone Stairs instead...");
				}
				return NovaCraftBlocks.cobbled_grimstone_stairs;
			}
		}

		return NovaCraftBlocks.cobbled_grimstone_stairs;
	}
    
    public boolean generate(final World world, final Random random, final int i, final int j, final int k) {
    	PlaceDeepslate = determineIfDeepslateExists(world, i + 0, j + 0, k + 1);
    	PlaceCobbledDeepslate = determineIfCobbledDeepslateExists(world, i + 16, j + 0, k + 9);
    	
    	PlaceDeepslateBricks = determineIfDeepslateBricksExists(world, i + 1, j + 4, k + 7);
    	PlaceCrackedDeepslateBricks = determineIfCrackedDeepslateBricksExists(world, i + 1, j + 4, k + 8);
    	PlaceDeepslateTiles = determineIfDeepslateTilesExist(world, i + 0, j + 4, k + 1);
    	PlaceCrackedDeepslateTiles = determineIfCrackedDeepslateTilesExist(world, i + 4, j + 4, k + 2);
    	PlaceChiseledDeepslate = determineIfChiseledDeepslateExist(world, i + 2, j + 4, k + 19);
    	PlacePolishedDeepslate = determineIfPolishedDeepslateExists(world, i + 4, j + 1, k + 1);
    	
    	PlaceDeepslateTileStairs = determineIfDeepslateTileStairsExists(world, i + 1, j + 4, k + 14);
    	PlaceDeepslateBrickStairs = determineIfDeepslateBrickStairsExists(world, i + 16, j + 0, k + 18);
    	PlaceDeepslateBrickWall = determineIfDeepslateBrickWallExists(world, i + 10, j + 5, k + 6);
    	PlaceCobbledDeepslateStairs = determineIfCobbledDeepslateStairsExists(world, i + 5, j + 0, k + 3);
    	PlaceDeepslateBrickSlab = determineIfDeepslateSlabExists(world, i + 2, j + 4, k + 6);

		world.setBlock(i + 0, j + 0, k + 0, Blocks.air, 0, 2);
		world.setBlock(i + 1, j + 0, k + 0, Blocks.air, 0, 2);
		world.setBlock(i + 2, j + 0, k + 0, Blocks.air, 0, 2);
		world.setBlock(i + 3, j + 0, k + 0, Blocks.air, 0, 2);
		world.setBlock(i + 4, j + 0, k + 0, Blocks.air, 0, 2);
		world.setBlock(i + 5, j + 0, k + 0, Blocks.air, 0, 2);
		world.setBlock(i + 6, j + 0, k + 0, Blocks.air, 0, 2);
		world.setBlock(i + 7, j + 0, k + 0, Blocks.air, 0, 2);
		world.setBlock(i + 8, j + 0, k + 0, Blocks.air, 0, 2);
		world.setBlock(i + 9, j + 0, k + 0, Blocks.air, 0, 2);
		world.setBlock(i + 10, j + 0, k + 0, Blocks.air, 0, 2);
		world.setBlock(i + 11, j + 0, k + 0, Blocks.air, 0, 2);
		world.setBlock(i + 12, j + 0, k + 0, Blocks.air, 0, 2);
		world.setBlock(i + 13, j + 0, k + 0, Blocks.air, 0, 2);
		world.setBlock(i + 14, j + 0, k + 0, Blocks.air, 0, 2);
		world.setBlock(i + 15, j + 0, k + 0, Blocks.air, 0, 2);
		world.setBlock(i + 16, j + 0, k + 0, Blocks.air, 0, 2);
		world.setBlock(i + 17, j + 0, k + 0, Blocks.air, 0, 2);
		world.setBlock(i + 0, j + 0, k + 1, PlaceDeepslate, 0, 2);
		world.setBlock(i + 1, j + 0, k + 1, PlaceDeepslate, 0, 2);
		world.setBlock(i + 2, j + 0, k + 1, PlaceDeepslate, 0, 2);
		world.setBlock(i + 3, j + 0, k + 1, PlaceDeepslate, 0, 2);
		world.setBlock(i + 4, j + 0, k + 1, PlaceDeepslate, 0, 2);
		world.setBlock(i + 5, j + 0, k + 1, Blocks.air, 0, 2);
		world.setBlock(i + 6, j + 0, k + 1, Blocks.air, 0, 2);
		world.setBlock(i + 7, j + 0, k + 1, Blocks.air, 0, 2);
		world.setBlock(i + 8, j + 0, k + 1, PlaceDeepslate, 0, 2);
		world.setBlock(i + 9, j + 0, k + 1, PlaceDeepslate, 0, 2);
		world.setBlock(i + 10, j + 0, k + 1, PlaceDeepslate, 0, 2);
		world.setBlock(i + 11, j + 0, k + 1, PlaceDeepslate, 0, 2);
		world.setBlock(i + 12, j + 0, k + 1, PlaceDeepslate, 0, 2);
		world.setBlock(i + 13, j + 0, k + 1, PlaceDeepslate, 0, 2);
		world.setBlock(i + 14, j + 0, k + 1, PlaceDeepslate, 0, 2);
		world.setBlock(i + 15, j + 0, k + 1, PlaceDeepslate, 0, 2);
		world.setBlock(i + 16, j + 0, k + 1, PlaceDeepslate, 0, 2);
		world.setBlock(i + 17, j + 0, k + 1, Blocks.air, 0, 2);
		world.setBlock(i + 0, j + 0, k + 2, PlaceDeepslate, 0, 2);
		world.setBlock(i + 1, j + 0, k + 2, PlaceDeepslate, 0, 2);
		world.setBlock(i + 2, j + 0, k + 2, PlaceDeepslate, 0, 2);
		world.setBlock(i + 3, j + 0, k + 2, PlaceDeepslate, 0, 2);
		world.setBlock(i + 4, j + 0, k + 2, PlaceDeepslate, 0, 2);
		world.setBlock(i + 5, j + 0, k + 2, Blocks.air, 0, 2);
		world.setBlock(i + 6, j + 0, k + 2, Blocks.air, 0, 2);
		world.setBlock(i + 7, j + 0, k + 2, PlaceDeepslate, 0, 2);
		world.setBlock(i + 8, j + 0, k + 2, PlaceDeepslate, 0, 2);
		world.setBlock(i + 9, j + 0, k + 2, PlaceDeepslate, 0, 2);
		world.setBlock(i + 10, j + 0, k + 2, PlaceDeepslate, 0, 2);
		world.setBlock(i + 11, j + 0, k + 2, PlaceDeepslate, 0, 2);
		world.setBlock(i + 12, j + 0, k + 2, PlaceDeepslate, 0, 2);
		world.setBlock(i + 13, j + 0, k + 2, PlaceDeepslate, 0, 2);
		world.setBlock(i + 14, j + 0, k + 2, PlaceDeepslate, 0, 2);
		world.setBlock(i + 15, j + 0, k + 2, Blocks.air, 0, 2);
		world.setBlock(i + 16, j + 0, k + 2, PlaceDeepslate, 0, 2);
		world.setBlock(i + 17, j + 0, k + 2, Blocks.air, 0, 2);
		world.setBlock(i + 0, j + 0, k + 3, PlaceDeepslate, 0, 2);
		world.setBlock(i + 1, j + 0, k + 3, Blocks.air, 0, 2);
		world.setBlock(i + 2, j + 0, k + 3, PlaceDeepslate, 0, 2);
		world.setBlock(i + 3, j + 0, k + 3, PlaceDeepslate, 0, 2);
		world.setBlock(i + 4, j + 0, k + 3, PlaceDeepslate, 0, 2);
		world.setBlock(i + 5, j + 0, k + 3, PlaceCobbledDeepslateStairs, 2, 2);
		world.setBlock(i + 6, j + 0, k + 3, PlaceCobbledDeepslateStairs, 2, 2);
		world.setBlock(i + 7, j + 0, k + 3, PlaceDeepslate, 0, 2);
		world.setBlock(i + 8, j + 0, k + 3, PlaceDeepslate, 0, 2);
		world.setBlock(i + 9, j + 0, k + 3, PlaceDeepslate, 0, 2);
		world.setBlock(i + 10, j + 0, k + 3, PlaceDeepslate, 0, 2);
		world.setBlock(i + 11, j + 0, k + 3, PlaceDeepslate, 0, 2);
		world.setBlock(i + 12, j + 0, k + 3, PlaceDeepslate, 0, 2);
		world.setBlock(i + 13, j + 0, k + 3, PlaceDeepslate, 0, 2);
		world.setBlock(i + 14, j + 0, k + 3, PlaceDeepslate, 0, 2);
		world.setBlock(i + 15, j + 0, k + 3, PlaceDeepslate, 0, 2);
		world.setBlock(i + 16, j + 0, k + 3, PlaceDeepslate, 0, 2);
		world.setBlock(i + 17, j + 0, k + 3, Blocks.air, 0, 2);
		world.setBlock(i + 0, j + 0, k + 4, PlaceDeepslate, 0, 2);
		world.setBlock(i + 1, j + 0, k + 4, PlaceDeepslate, 0, 2);
		world.setBlock(i + 2, j + 0, k + 4, PlaceDeepslate, 0, 2);
		world.setBlock(i + 3, j + 0, k + 4, PlaceDeepslate, 0, 2);
		world.setBlock(i + 4, j + 0, k + 4, Blocks.air, 0, 2);
		world.setBlock(i + 5, j + 0, k + 4, PlaceDeepslate, 0, 2);
		world.setBlock(i + 6, j + 0, k + 4, PlaceDeepslate, 0, 2);
		world.setBlock(i + 7, j + 0, k + 4, PlaceDeepslate, 0, 2);
		world.setBlock(i + 8, j + 0, k + 4, PlaceDeepslate, 0, 2);
		world.setBlock(i + 9, j + 0, k + 4, PlaceDeepslate, 0, 2);
		world.setBlock(i + 10, j + 0, k + 4, PlaceDeepslate, 0, 2);
		world.setBlock(i + 11, j + 0, k + 4, PlaceDeepslate, 0, 2);
		world.setBlock(i + 12, j + 0, k + 4, PlaceDeepslate, 0, 2);
		world.setBlock(i + 13, j + 0, k + 4, PlaceDeepslate, 0, 2);
		world.setBlock(i + 14, j + 0, k + 4, PlaceDeepslate, 0, 2);
		world.setBlock(i + 15, j + 0, k + 4, PlaceDeepslate, 0, 2);
		world.setBlock(i + 16, j + 0, k + 4, PlaceDeepslate, 0, 2);
		world.setBlock(i + 17, j + 0, k + 4, Blocks.air, 0, 2);
		world.setBlock(i + 0, j + 0, k + 5, PlaceDeepslate, 0, 2);
		world.setBlock(i + 1, j + 0, k + 5, PlaceDeepslate, 0, 2);
		world.setBlock(i + 2, j + 0, k + 5, PlaceDeepslate, 0, 2);
		world.setBlock(i + 3, j + 0, k + 5, PlaceDeepslate, 0, 2);
		world.setBlock(i + 4, j + 0, k + 5, Blocks.air, 0, 2);
		world.setBlock(i + 5, j + 0, k + 5, PlaceDeepslate, 0, 2);
		world.setBlock(i + 6, j + 0, k + 5, PlaceDeepslate, 0, 2);
		world.setBlock(i + 7, j + 0, k + 5, PlaceDeepslate, 0, 2);
		world.setBlock(i + 8, j + 0, k + 5, PlaceDeepslate, 0, 2);
		world.setBlock(i + 9, j + 0, k + 5, PlaceDeepslate, 0, 2);
		world.setBlock(i + 10, j + 0, k + 5, PlaceDeepslate, 0, 2);
		world.setBlock(i + 11, j + 0, k + 5, PlaceDeepslate, 0, 2);
		world.setBlock(i + 12, j + 0, k + 5, PlaceDeepslate, 0, 2);
		world.setBlock(i + 13, j + 0, k + 5, PlaceDeepslate, 0, 2);
		world.setBlock(i + 14, j + 0, k + 5, PlaceDeepslate, 0, 2);
		world.setBlock(i + 15, j + 0, k + 5, PlaceDeepslate, 0, 2);
		world.setBlock(i + 16, j + 0, k + 5, Blocks.air, 0, 2);
		world.setBlock(i + 17, j + 0, k + 5, Blocks.air, 0, 2);
		world.setBlock(i + 0, j + 0, k + 6, PlaceDeepslate, 0, 2);
		world.setBlock(i + 1, j + 0, k + 6, PlaceDeepslate, 0, 2);
		world.setBlock(i + 2, j + 0, k + 6, PlaceDeepslate, 0, 2);
		world.setBlock(i + 3, j + 0, k + 6, PlaceDeepslate, 0, 2);
		world.setBlock(i + 4, j + 0, k + 6, PlaceDeepslate, 0, 2);
		world.setBlock(i + 5, j + 0, k + 6, Blocks.air, 0, 2);
		world.setBlock(i + 6, j + 0, k + 6, PlaceDeepslate, 0, 2);
		world.setBlock(i + 7, j + 0, k + 6, PlaceDeepslate, 0, 2);
		world.setBlock(i + 8, j + 0, k + 6, PlaceDeepslate, 0, 2);
		world.setBlock(i + 9, j + 0, k + 6, PlaceDeepslate, 0, 2);
		world.setBlock(i + 10, j + 0, k + 6, PlaceDeepslate, 0, 2);
		world.setBlock(i + 11, j + 0, k + 6, PlaceDeepslate, 0, 2);
		world.setBlock(i + 12, j + 0, k + 6, PlaceDeepslate, 0, 2);
		world.setBlock(i + 13, j + 0, k + 6, PlaceDeepslate, 0, 2);
		world.setBlock(i + 14, j + 0, k + 6, PlaceDeepslate, 0, 2);
		world.setBlock(i + 15, j + 0, k + 6, PlaceDeepslate, 0, 2);
		world.setBlock(i + 16, j + 0, k + 6, PlaceDeepslate, 0, 2);
		world.setBlock(i + 17, j + 0, k + 6, Blocks.air, 0, 2);
		world.setBlock(i + 0, j + 0, k + 7, PlaceDeepslate, 0, 2);
		world.setBlock(i + 1, j + 0, k + 7, Blocks.air, 0, 2);
		world.setBlock(i + 2, j + 0, k + 7, PlaceDeepslate, 0, 2);
		world.setBlock(i + 3, j + 0, k + 7, PlaceDeepslate, 0, 2);
		world.setBlock(i + 4, j + 0, k + 7, PlaceDeepslate, 0, 2);
		world.setBlock(i + 5, j + 0, k + 7, PlaceDeepslate, 0, 2);
		world.setBlock(i + 6, j + 0, k + 7, PlaceDeepslate, 0, 2);
		world.setBlock(i + 7, j + 0, k + 7, PlaceDeepslate, 0, 2);
		world.setBlock(i + 8, j + 0, k + 7, PlaceDeepslate, 0, 2);
		world.setBlock(i + 9, j + 0, k + 7, PlaceDeepslate, 0, 2);
		world.setBlock(i + 10, j + 0, k + 7, PlaceDeepslate, 0, 2);
		world.setBlock(i + 11, j + 0, k + 7, PlaceDeepslate, 0, 2);
		world.setBlock(i + 12, j + 0, k + 7, PlaceDeepslate, 0, 2);
		world.setBlock(i + 13, j + 0, k + 7, PlaceDeepslate, 0, 2);
		world.setBlock(i + 14, j + 0, k + 7, PlaceDeepslate, 0, 2);
		world.setBlock(i + 15, j + 0, k + 7, PlaceDeepslate, 0, 2);
		world.setBlock(i + 16, j + 0, k + 7, PlaceDeepslate, 0, 2);
		world.setBlock(i + 17, j + 0, k + 7, Blocks.air, 0, 2);
		world.setBlock(i + 0, j + 0, k + 8, Blocks.air, 0, 2);
		world.setBlock(i + 1, j + 0, k + 8, PlaceDeepslate, 0, 2);
		world.setBlock(i + 2, j + 0, k + 8, PlaceDeepslate, 0, 2);
		world.setBlock(i + 3, j + 0, k + 8, PlaceDeepslate, 0, 2);
		world.setBlock(i + 4, j + 0, k + 8, PlaceDeepslate, 0, 2);
		world.setBlock(i + 5, j + 0, k + 8, PlaceDeepslate, 0, 2);
		world.setBlock(i + 6, j + 0, k + 8, PlaceDeepslate, 0, 2);
		world.setBlock(i + 7, j + 0, k + 8, PlaceDeepslate, 0, 2);
		world.setBlock(i + 8, j + 0, k + 8, PlaceDeepslate, 0, 2);
		world.setBlock(i + 9, j + 0, k + 8, PlaceDeepslate, 0, 2);
		world.setBlock(i + 10, j + 0, k + 8, Blocks.air, 0, 2);
		world.setBlock(i + 11, j + 0, k + 8, PlaceDeepslate, 0, 2);
		world.setBlock(i + 12, j + 0, k + 8, PlaceDeepslate, 0, 2);
		world.setBlock(i + 13, j + 0, k + 8, PlaceDeepslate, 0, 2);
		world.setBlock(i + 14, j + 0, k + 8, PlaceDeepslate, 0, 2);
		world.setBlock(i + 15, j + 0, k + 8, PlaceDeepslate, 0, 2);
		world.setBlock(i + 16, j + 0, k + 8, Blocks.air, 0, 2);
		world.setBlock(i + 17, j + 0, k + 8, Blocks.air, 0, 2);
		world.setBlock(i + 0, j + 0, k + 9, Blocks.air, 0, 2);
		world.setBlock(i + 1, j + 0, k + 9, PlaceDeepslate, 0, 2);
		world.setBlock(i + 2, j + 0, k + 9, PlaceDeepslate, 0, 2);
		world.setBlock(i + 3, j + 0, k + 9, PlaceDeepslate, 0, 2);
		world.setBlock(i + 4, j + 0, k + 9, PlaceDeepslate, 0, 2);
		world.setBlock(i + 5, j + 0, k + 9, PlaceDeepslate, 0, 2);
		world.setBlock(i + 6, j + 0, k + 9, PlaceDeepslate, 0, 2);
		world.setBlock(i + 7, j + 0, k + 9, NovaCraftBlocks.sculk_block, 0, 2);
		world.setBlock(i + 8, j + 0, k + 9, PlaceDeepslate, 0, 2);
		world.setBlock(i + 9, j + 0, k + 9, PlaceDeepslate, 0, 2);
		world.setBlock(i + 10, j + 0, k + 9, PlaceDeepslate, 0, 2);
		world.setBlock(i + 11, j + 0, k + 9, PlaceDeepslate, 0, 2);
		world.setBlock(i + 12, j + 0, k + 9, PlaceDeepslate, 0, 2);
		world.setBlock(i + 13, j + 0, k + 9, PlaceDeepslate, 0, 2);
		world.setBlock(i + 14, j + 0, k + 9, PlaceDeepslate, 0, 2);
		world.setBlock(i + 15, j + 0, k + 9, PlaceDeepslate, 0, 2);
		world.setBlock(i + 16, j + 0, k + 9, PlaceCobbledDeepslate, 0, 2);
		world.setBlock(i + 17, j + 0, k + 9, Blocks.air, 0, 2);
		world.setBlock(i + 0, j + 0, k + 10, PlaceDeepslate, 0, 2);
		world.setBlock(i + 1, j + 0, k + 10, PlaceDeepslate, 0, 2);
		world.setBlock(i + 2, j + 0, k + 10, PlaceDeepslate, 0, 2);
		world.setBlock(i + 3, j + 0, k + 10, Blocks.air, 0, 2);
		world.setBlock(i + 4, j + 0, k + 10, PlaceDeepslate, 0, 2);
		world.setBlock(i + 5, j + 0, k + 10, PlaceDeepslate, 0, 2);
		world.setBlock(i + 6, j + 0, k + 10, NovaCraftBlocks.sculk_block, 0, 2);
		world.setBlock(i + 7, j + 0, k + 10, Blocks.air, 0, 2);
		world.setBlock(i + 8, j + 0, k + 10, PlaceDeepslate, 0, 2);
		world.setBlock(i + 9, j + 0, k + 10, PlaceDeepslate, 0, 2);
		world.setBlock(i + 10, j + 0, k + 10, PlaceDeepslate, 0, 2);
		world.setBlock(i + 11, j + 0, k + 10, Blocks.air, 0, 2);
		world.setBlock(i + 12, j + 0, k + 10, PlaceDeepslate, 0, 2);
		world.setBlock(i + 13, j + 0, k + 10, PlaceDeepslate, 0, 2);
		world.setBlock(i + 14, j + 0, k + 10, PlaceDeepslate, 0, 2);
		world.setBlock(i + 15, j + 0, k + 10, PlaceDeepslate, 0, 2);
		world.setBlock(i + 16, j + 0, k + 10, PlaceDeepslate, 0, 2);
		world.setBlock(i + 17, j + 0, k + 10, Blocks.air, 0, 2);
		world.setBlock(i + 0, j + 0, k + 11, PlaceDeepslate, 0, 2);
		world.setBlock(i + 1, j + 0, k + 11, PlaceDeepslate, 0, 2);
		world.setBlock(i + 2, j + 0, k + 11, Blocks.air, 0, 2);
		world.setBlock(i + 3, j + 0, k + 11, PlaceDeepslate, 0, 2);
		world.setBlock(i + 4, j + 0, k + 11, PlaceDeepslate, 0, 2);
		world.setBlock(i + 5, j + 0, k + 11, PlaceDeepslate, 0, 2);
		world.setBlock(i + 6, j + 0, k + 11, PlaceDeepslate, 0, 2);
		world.setBlock(i + 7, j + 0, k + 11, NovaCraftBlocks.sculk_block, 0, 2);
		world.setBlock(i + 8, j + 0, k + 11, PlaceDeepslate, 0, 2);
		world.setBlock(i + 9, j + 0, k + 11, PlaceDeepslate, 0, 2);
		world.setBlock(i + 10, j + 0, k + 11, PlaceDeepslate, 0, 2);
		world.setBlock(i + 11, j + 0, k + 11, PlaceDeepslate, 0, 2);
		world.setBlock(i + 12, j + 0, k + 11, PlaceDeepslate, 0, 2);
		world.setBlock(i + 13, j + 0, k + 11, PlaceDeepslate, 0, 2);
		world.setBlock(i + 14, j + 0, k + 11, PlaceDeepslate, 0, 2);
		world.setBlock(i + 15, j + 0, k + 11, Blocks.air, 0, 2);
		world.setBlock(i + 16, j + 0, k + 11, PlaceDeepslate, 0, 2);
		world.setBlock(i + 17, j + 0, k + 11, Blocks.air, 0, 2);
		world.setBlock(i + 0, j + 0, k + 12, PlaceDeepslate, 0, 2);
		world.setBlock(i + 1, j + 0, k + 12, PlaceDeepslate, 0, 2);
		world.setBlock(i + 2, j + 0, k + 12, PlaceDeepslate, 0, 2);
		world.setBlock(i + 3, j + 0, k + 12, PlaceDeepslate, 0, 2);
		world.setBlock(i + 4, j + 0, k + 12, PlaceDeepslate, 0, 2);
		world.setBlock(i + 5, j + 0, k + 12, PlaceDeepslate, 0, 2);
		world.setBlock(i + 6, j + 0, k + 12, PlaceDeepslate, 0, 2);
		world.setBlock(i + 7, j + 0, k + 12, NovaCraftBlocks.sculk_block, 0, 2);
		world.setBlock(i + 8, j + 0, k + 12, PlaceDeepslate, 0, 2);
		world.setBlock(i + 9, j + 0, k + 12, PlaceDeepslate, 0, 2);
		world.setBlock(i + 10, j + 0, k + 12, PlaceDeepslate, 0, 2);
		world.setBlock(i + 11, j + 0, k + 12, PlaceDeepslate, 0, 2);
		world.setBlock(i + 12, j + 0, k + 12, PlaceDeepslate, 0, 2);
		world.setBlock(i + 13, j + 0, k + 12, PlaceDeepslate, 0, 2);
		world.setBlock(i + 14, j + 0, k + 12, PlaceDeepslate, 0, 2);
		world.setBlock(i + 15, j + 0, k + 12, Blocks.air, 0, 2);
		world.setBlock(i + 16, j + 0, k + 12, PlaceDeepslate, 0, 2);
		world.setBlock(i + 17, j + 0, k + 12, Blocks.air, 0, 2);
		world.setBlock(i + 0, j + 0, k + 13, PlaceDeepslate, 0, 2);
		world.setBlock(i + 1, j + 0, k + 13, PlaceDeepslate, 0, 2);
		world.setBlock(i + 2, j + 0, k + 13, PlaceDeepslate, 0, 2);
		world.setBlock(i + 3, j + 0, k + 13, PlaceDeepslate, 0, 2);
		world.setBlock(i + 4, j + 0, k + 13, PlaceDeepslate, 0, 2);
		world.setBlock(i + 5, j + 0, k + 13, PlaceDeepslate, 0, 2);
		world.setBlock(i + 6, j + 0, k + 13, PlaceDeepslate, 0, 2);
		world.setBlock(i + 7, j + 0, k + 13, NovaCraftBlocks.sculk_block, 0, 2);
		world.setBlock(i + 8, j + 0, k + 13, PlaceDeepslate, 0, 2);
		world.setBlock(i + 9, j + 0, k + 13, PlaceDeepslate, 0, 2);
		world.setBlock(i + 10, j + 0, k + 13, PlaceDeepslate, 0, 2);
		world.setBlock(i + 11, j + 0, k + 13, PlaceDeepslate, 0, 2);
		world.setBlock(i + 12, j + 0, k + 13, PlaceDeepslate, 0, 2);
		world.setBlock(i + 13, j + 0, k + 13, Blocks.air, 0, 2);
		world.setBlock(i + 14, j + 0, k + 13, PlaceDeepslate, 0, 2);
		world.setBlock(i + 15, j + 0, k + 13, PlaceDeepslate, 0, 2);
		world.setBlock(i + 16, j + 0, k + 13, PlaceDeepslate, 0, 2);
		world.setBlock(i + 17, j + 0, k + 13, Blocks.air, 0, 2);
		world.setBlock(i + 0, j + 0, k + 14, PlaceDeepslate, 0, 2);
		world.setBlock(i + 1, j + 0, k + 14, PlaceDeepslate, 0, 2);
		world.setBlock(i + 2, j + 0, k + 14, PlaceDeepslate, 0, 2);
		world.setBlock(i + 3, j + 0, k + 14, Blocks.air, 0, 2);
		world.setBlock(i + 4, j + 0, k + 14, PlaceDeepslate, 0, 2);
		world.setBlock(i + 5, j + 0, k + 14, PlaceDeepslate, 0, 2);
		world.setBlock(i + 6, j + 0, k + 14, PlaceDeepslate, 0, 2);
		world.setBlock(i + 7, j + 0, k + 14, NovaCraftBlocks.sculk_block, 0, 2);
		world.setBlock(i + 8, j + 0, k + 14, PlaceDeepslate, 0, 2);
		world.setBlock(i + 9, j + 0, k + 14, PlaceDeepslate, 0, 2);
		world.setBlock(i + 10, j + 0, k + 14, PlaceDeepslate, 0, 2);
		world.setBlock(i + 11, j + 0, k + 14, PlaceDeepslate, 0, 2);
		world.setBlock(i + 12, j + 0, k + 14, PlaceDeepslate, 0, 2);
		world.setBlock(i + 13, j + 0, k + 14, PlaceDeepslate, 0, 2);
		world.setBlock(i + 14, j + 0, k + 14, Blocks.air, 0, 2);
		world.setBlock(i + 15, j + 0, k + 14, PlaceDeepslate, 0, 2);
		world.setBlock(i + 16, j + 0, k + 14, PlaceDeepslate, 0, 2);
		world.setBlock(i + 17, j + 0, k + 14, Blocks.air, 0, 2);
		world.setBlock(i + 0, j + 0, k + 15, PlaceDeepslate, 0, 2);
		world.setBlock(i + 1, j + 0, k + 15, PlaceDeepslate, 0, 2);
		world.setBlock(i + 2, j + 0, k + 15, PlaceDeepslate, 0, 2);
		world.setBlock(i + 3, j + 0, k + 15, PlaceDeepslate, 0, 2);
		world.setBlock(i + 4, j + 0, k + 15, PlaceDeepslate, 0, 2);
		world.setBlock(i + 5, j + 0, k + 15, PlaceDeepslate, 0, 2);
		world.setBlock(i + 6, j + 0, k + 15, PlaceDeepslate, 0, 2);
		world.setBlock(i + 7, j + 0, k + 15, PlaceDeepslate, 0, 2);
		world.setBlock(i + 8, j + 0, k + 15, PlaceDeepslate, 0, 2);
		world.setBlock(i + 9, j + 0, k + 15, PlaceDeepslate, 0, 2);
		world.setBlock(i + 10, j + 0, k + 15, PlaceDeepslate, 0, 2);
		world.setBlock(i + 11, j + 0, k + 15, PlaceDeepslate, 0, 2);
		world.setBlock(i + 12, j + 0, k + 15, PlaceDeepslate, 0, 2);
		world.setBlock(i + 13, j + 0, k + 15, PlaceDeepslate, 0, 2);
		world.setBlock(i + 14, j + 0, k + 15, PlaceDeepslate, 0, 2);
		world.setBlock(i + 15, j + 0, k + 15, PlaceDeepslate, 0, 2);
		world.setBlock(i + 16, j + 0, k + 15, PlaceDeepslate, 0, 2);
		world.setBlock(i + 17, j + 0, k + 15, Blocks.air, 0, 2);
		world.setBlock(i + 0, j + 0, k + 16, PlaceDeepslate, 0, 2);
		world.setBlock(i + 1, j + 0, k + 16, PlaceDeepslate, 0, 2);
		world.setBlock(i + 2, j + 0, k + 16, PlaceDeepslate, 0, 2);
		world.setBlock(i + 3, j + 0, k + 16, PlaceDeepslate, 0, 2);
		world.setBlock(i + 4, j + 0, k + 16, PlaceDeepslate, 0, 2);
		world.setBlock(i + 5, j + 0, k + 16, PlaceDeepslate, 0, 2);
		world.setBlock(i + 6, j + 0, k + 16, PlaceDeepslate, 0, 2);
		world.setBlock(i + 7, j + 0, k + 16, PlaceDeepslate, 0, 2);
		world.setBlock(i + 8, j + 0, k + 16, PlaceDeepslate, 0, 2);
		world.setBlock(i + 9, j + 0, k + 16, PlaceDeepslate, 0, 2);
		world.setBlock(i + 10, j + 0, k + 16, PlaceDeepslate, 0, 2);
		world.setBlock(i + 11, j + 0, k + 16, PlaceDeepslate, 0, 2);
		world.setBlock(i + 12, j + 0, k + 16, PlaceDeepslate, 0, 2);
		world.setBlock(i + 13, j + 0, k + 16, PlaceDeepslate, 0, 2);
		world.setBlock(i + 14, j + 0, k + 16, PlaceDeepslate, 0, 2);
		world.setBlock(i + 15, j + 0, k + 16, PlaceDeepslate, 0, 2);
		world.setBlock(i + 16, j + 0, k + 16, PlaceDeepslate, 0, 2);
		world.setBlock(i + 17, j + 0, k + 16, Blocks.air, 0, 2);
		world.setBlock(i + 0, j + 0, k + 17, PlaceDeepslate, 0, 2);
		world.setBlock(i + 1, j + 0, k + 17, PlaceDeepslate, 0, 2);
		world.setBlock(i + 2, j + 0, k + 17, PlaceDeepslate, 0, 2);
		world.setBlock(i + 3, j + 0, k + 17, PlaceDeepslate, 0, 2);
		world.setBlock(i + 4, j + 0, k + 17, PlaceDeepslate, 0, 2);
		world.setBlock(i + 5, j + 0, k + 17, PlaceDeepslate, 0, 2);
		world.setBlock(i + 6, j + 0, k + 17, PlaceDeepslate, 0, 2);
		world.setBlock(i + 7, j + 0, k + 17, PlaceDeepslate, 0, 2);
		world.setBlock(i + 8, j + 0, k + 17, PlaceDeepslate, 0, 2);
		world.setBlock(i + 9, j + 0, k + 17, PlaceDeepslate, 0, 2);
		world.setBlock(i + 10, j + 0, k + 17, PlaceDeepslate, 0, 2);
		world.setBlock(i + 11, j + 0, k + 17, PlaceDeepslate, 0, 2);
		world.setBlock(i + 12, j + 0, k + 17, PlaceDeepslate, 0, 2);
		world.setBlock(i + 13, j + 0, k + 17, PlaceDeepslate, 0, 2);
		world.setBlock(i + 14, j + 0, k + 17, PlaceDeepslate, 0, 2);
		world.setBlock(i + 15, j + 0, k + 17, PlaceDeepslate, 0, 2);
		world.setBlock(i + 16, j + 0, k + 17, PlaceDeepslate, 0, 2);
		world.setBlock(i + 17, j + 0, k + 17, Blocks.air, 0, 2);
		world.setBlock(i + 0, j + 0, k + 18, PlaceDeepslate, 0, 2);
		world.setBlock(i + 1, j + 0, k + 18, PlaceDeepslate, 0, 2);
		world.setBlock(i + 2, j + 0, k + 18, PlaceDeepslate, 0, 2);
		world.setBlock(i + 3, j + 0, k + 18, PlaceDeepslate, 0, 2);
		world.setBlock(i + 4, j + 0, k + 18, PlaceDeepslate, 0, 2);
		world.setBlock(i + 5, j + 0, k + 18, PlaceDeepslate, 0, 2);
		world.setBlock(i + 6, j + 0, k + 18, PlaceDeepslate, 0, 2);
		world.setBlock(i + 7, j + 0, k + 18, PlaceDeepslate, 0, 2);
		world.setBlock(i + 8, j + 0, k + 18, PlaceDeepslate, 0, 2);
		world.setBlock(i + 9, j + 0, k + 18, Blocks.air, 0, 2);
		world.setBlock(i + 10, j + 0, k + 18, PlaceDeepslate, 0, 2);
		world.setBlock(i + 11, j + 0, k + 18, PlaceDeepslate, 0, 2);
		world.setBlock(i + 12, j + 0, k + 18, PlaceDeepslate, 0, 2);
		world.setBlock(i + 13, j + 0, k + 18, PlaceDeepslate, 0, 2);
		world.setBlock(i + 14, j + 0, k + 18, PlaceDeepslate, 0, 2);
		world.setBlock(i + 15, j + 0, k + 18, PlaceDeepslate, 0, 2);
		world.setBlock(i + 16, j + 0, k + 18, PlaceDeepslateBrickStairs, 1, 2);
		world.setBlock(i + 17, j + 0, k + 18, Blocks.air, 0, 2);
		world.setBlock(i + 0, j + 0, k + 19, PlaceDeepslate, 0, 2);
		world.setBlock(i + 1, j + 0, k + 19, PlaceDeepslate, 0, 2);
		world.setBlock(i + 2, j + 0, k + 19, PlaceDeepslate, 0, 2);
		world.setBlock(i + 3, j + 0, k + 19, PlaceDeepslate, 0, 2);
		world.setBlock(i + 4, j + 0, k + 19, PlaceDeepslate, 0, 2);
		world.setBlock(i + 5, j + 0, k + 19, PlaceDeepslate, 0, 2);
		world.setBlock(i + 6, j + 0, k + 19, PlaceDeepslate, 0, 2);
		world.setBlock(i + 7, j + 0, k + 19, Blocks.air, 0, 2);
		world.setBlock(i + 8, j + 0, k + 19, PlaceDeepslate, 0, 2);
		world.setBlock(i + 9, j + 0, k + 19, PlaceDeepslate, 0, 2);
		world.setBlock(i + 10, j + 0, k + 19, PlaceDeepslate, 0, 2);
		world.setBlock(i + 11, j + 0, k + 19, PlaceDeepslate, 0, 2);
		world.setBlock(i + 12, j + 0, k + 19, PlaceDeepslate, 0, 2);
		world.setBlock(i + 13, j + 0, k + 19, PlaceDeepslate, 0, 2);
		world.setBlock(i + 14, j + 0, k + 19, PlaceDeepslate, 0, 2);
		world.setBlock(i + 15, j + 0, k + 19, PlaceDeepslate, 0, 2);
		world.setBlock(i + 16, j + 0, k + 19, PlaceDeepslate, 0, 2);
		world.setBlock(i + 17, j + 0, k + 19, Blocks.air, 0, 2);
		world.setBlock(i + 0, j + 0, k + 20, Blocks.air, 0, 2);
		world.setBlock(i + 1, j + 0, k + 20, Blocks.air, 0, 2);
		world.setBlock(i + 2, j + 0, k + 20, Blocks.air, 0, 2);
		world.setBlock(i + 3, j + 0, k + 20, Blocks.air, 0, 2);
		world.setBlock(i + 4, j + 0, k + 20, Blocks.air, 0, 2);
		world.setBlock(i + 5, j + 0, k + 20, Blocks.air, 0, 2);
		world.setBlock(i + 6, j + 0, k + 20, Blocks.air, 0, 2);
		world.setBlock(i + 7, j + 0, k + 20, Blocks.air, 0, 2);
		world.setBlock(i + 8, j + 0, k + 20, Blocks.air, 0, 2);
		world.setBlock(i + 9, j + 0, k + 20, Blocks.air, 0, 2);
		world.setBlock(i + 10, j + 0, k + 20, Blocks.air, 0, 2);
		world.setBlock(i + 11, j + 0, k + 20, Blocks.air, 0, 2);
		world.setBlock(i + 12, j + 0, k + 20, Blocks.air, 0, 2);
		world.setBlock(i + 13, j + 0, k + 20, Blocks.air, 0, 2);
		world.setBlock(i + 14, j + 0, k + 20, Blocks.air, 0, 2);
		world.setBlock(i + 15, j + 0, k + 20, Blocks.air, 0, 2);
		world.setBlock(i + 16, j + 0, k + 20, Blocks.air, 0, 2);
		world.setBlock(i + 17, j + 0, k + 20, Blocks.air, 0, 2);
		world.setBlock(i + 0, j + 1, k + 0, Blocks.air, 0, 2);
		world.setBlock(i + 1, j + 1, k + 0, Blocks.air, 0, 2);
		world.setBlock(i + 2, j + 1, k + 0, Blocks.air, 0, 2);
		world.setBlock(i + 3, j + 1, k + 0, Blocks.air, 0, 2);
		world.setBlock(i + 4, j + 1, k + 0, Blocks.air, 0, 2);
		world.setBlock(i + 5, j + 1, k + 0, Blocks.air, 0, 2);
		world.setBlock(i + 6, j + 1, k + 0, Blocks.air, 0, 2);
		world.setBlock(i + 7, j + 1, k + 0, Blocks.air, 0, 2);
		world.setBlock(i + 8, j + 1, k + 0, Blocks.air, 0, 2);
		world.setBlock(i + 9, j + 1, k + 0, Blocks.air, 0, 2);
		world.setBlock(i + 10, j + 1, k + 0, Blocks.air, 0, 2);
		world.setBlock(i + 11, j + 1, k + 0, Blocks.air, 0, 2);
		world.setBlock(i + 12, j + 1, k + 0, Blocks.air, 0, 2);
		world.setBlock(i + 13, j + 1, k + 0, Blocks.air, 0, 2);
		world.setBlock(i + 14, j + 1, k + 0, Blocks.air, 0, 2);
		world.setBlock(i + 15, j + 1, k + 0, Blocks.air, 0, 2);
		world.setBlock(i + 16, j + 1, k + 0, Blocks.air, 0, 2);
		world.setBlock(i + 17, j + 1, k + 0, Blocks.air, 0, 2);
		world.setBlock(i + 0, j + 1, k + 1, PlaceDeepslate, 0, 2);
		world.setBlock(i + 1, j + 1, k + 1, PlaceDeepslate, 0, 2);
		world.setBlock(i + 2, j + 1, k + 1, PlaceDeepslate, 0, 2);
		world.setBlock(i + 3, j + 1, k + 1, Blocks.air, 0, 2);
		world.setBlock(i + 4, j + 1, k + 1, PlacePolishedDeepslate, 0, 2);
		world.setBlock(i + 5, j + 1, k + 1, Blocks.air, 0, 2);
		world.setBlock(i + 6, j + 1, k + 1, Blocks.air, 0, 2);
		world.setBlock(i + 7, j + 1, k + 1, PlacePolishedDeepslate, 0, 2);
		world.setBlock(i + 8, j + 1, k + 1, PlaceDeepslate, 0, 2);
		world.setBlock(i + 9, j + 1, k + 1, PlaceDeepslate, 0, 2);
		world.setBlock(i + 10, j + 1, k + 1, PlaceDeepslate, 0, 2);
		world.setBlock(i + 11, j + 1, k + 1, PlaceDeepslate, 0, 2);
		world.setBlock(i + 12, j + 1, k + 1, PlaceDeepslate, 0, 2);
		world.setBlock(i + 13, j + 1, k + 1, PlaceDeepslate, 0, 2);
		world.setBlock(i + 14, j + 1, k + 1, PlaceDeepslate, 0, 2);
		world.setBlock(i + 15, j + 1, k + 1, PlaceDeepslate, 0, 2);
		world.setBlock(i + 16, j + 1, k + 1, PlaceDeepslate, 0, 2);
		world.setBlock(i + 17, j + 1, k + 1, Blocks.air, 0, 2);
		world.setBlock(i + 0, j + 1, k + 2, PlaceDeepslate, 0, 2);
		world.setBlock(i + 1, j + 1, k + 2, PlaceDeepslate, 0, 2);
		world.setBlock(i + 2, j + 1, k + 2, PlaceDeepslate, 0, 2);
		world.setBlock(i + 3, j + 1, k + 2, PlaceDeepslate, 0, 2);
		world.setBlock(i + 4, j + 1, k + 2, PlaceDeepslate, 0, 2);
		world.setBlock(i + 5, j + 1, k + 2, Blocks.air, 0, 2);
		world.setBlock(i + 6, j + 1, k + 2, Blocks.air, 0, 2);
		world.setBlock(i + 7, j + 1, k + 2, Blocks.air, 0, 2);
		world.setBlock(i + 8, j + 1, k + 2, PlaceDeepslate, 0, 2);
		world.setBlock(i + 9, j + 1, k + 2, PlaceDeepslate, 0, 2);
		world.setBlock(i + 10, j + 1, k + 2, PlaceDeepslate, 0, 2);
		world.setBlock(i + 11, j + 1, k + 2, PlaceDeepslate, 0, 2);
		world.setBlock(i + 12, j + 1, k + 2, PlaceDeepslate, 0, 2);
		world.setBlock(i + 13, j + 1, k + 2, PlaceDeepslate, 0, 2);
		world.setBlock(i + 14, j + 1, k + 2, PlaceDeepslate, 0, 2);
		world.setBlock(i + 15, j + 1, k + 2, PlaceDeepslate, 0, 2);
		world.setBlock(i + 16, j + 1, k + 2, PlaceDeepslate, 0, 2);
		world.setBlock(i + 17, j + 1, k + 2, Blocks.air, 0, 2);
		world.setBlock(i + 0, j + 1, k + 3, PlaceDeepslate, 0, 2);
		world.setBlock(i + 1, j + 1, k + 3, PlaceDeepslate, 0, 2);
		world.setBlock(i + 2, j + 1, k + 3, PlaceDeepslate, 0, 2);
		world.setBlock(i + 3, j + 1, k + 3, PlaceDeepslate, 0, 2);
		world.setBlock(i + 4, j + 1, k + 3, PlaceDeepslate, 0, 2);
		world.setBlock(i + 5, j + 1, k + 3, Blocks.air, 0, 2);
		world.setBlock(i + 6, j + 1, k + 3, Blocks.air, 0, 2);
		world.setBlock(i + 7, j + 1, k + 3, PlaceDeepslate, 0, 2);
		world.setBlock(i + 8, j + 1, k + 3, PlaceDeepslate, 0, 2);
		world.setBlock(i + 9, j + 1, k + 3, PlaceDeepslate, 0, 2);
		world.setBlock(i + 10, j + 1, k + 3, PlaceDeepslate, 0, 2);
		world.setBlock(i + 11, j + 1, k + 3, PlaceDeepslate, 0, 2);
		world.setBlock(i + 12, j + 1, k + 3, PlaceDeepslate, 0, 2);
		world.setBlock(i + 13, j + 1, k + 3, PlaceDeepslate, 0, 2);
		world.setBlock(i + 14, j + 1, k + 3, PlaceDeepslate, 0, 2);
		world.setBlock(i + 15, j + 1, k + 3, PlaceDeepslate, 0, 2);
		world.setBlock(i + 16, j + 1, k + 3, PlaceDeepslate, 0, 2);
		world.setBlock(i + 17, j + 1, k + 3, Blocks.air, 0, 2);
		world.setBlock(i + 0, j + 1, k + 4, PlaceDeepslate, 0, 2);
		world.setBlock(i + 1, j + 1, k + 4, Blocks.air, 0, 2);
		world.setBlock(i + 2, j + 1, k + 4, PlaceDeepslate, 0, 2);
		world.setBlock(i + 3, j + 1, k + 4, PlaceDeepslate, 0, 2);
		world.setBlock(i + 4, j + 1, k + 4, PlaceDeepslate, 0, 2);
		world.setBlock(i + 5, j + 1, k + 4, PlaceCobbledDeepslateStairs, 2, 2);
		world.setBlock(i + 6, j + 1, k + 4, PlaceCobbledDeepslateStairs, 2, 2);
		world.setBlock(i + 7, j + 1, k + 4, PlaceDeepslate, 0, 2);
		world.setBlock(i + 8, j + 1, k + 4, PlaceDeepslate, 0, 2);
		world.setBlock(i + 9, j + 1, k + 4, PlaceDeepslate, 0, 2);
		world.setBlock(i + 10, j + 1, k + 4, Blocks.air, 0, 2);
		world.setBlock(i + 11, j + 1, k + 4, PlaceDeepslate, 0, 2);
		world.setBlock(i + 12, j + 1, k + 4, PlaceDeepslate, 0, 2);
		world.setBlock(i + 13, j + 1, k + 4, PlaceDeepslate, 0, 2);
		world.setBlock(i + 14, j + 1, k + 4, PlaceDeepslate, 0, 2);
		world.setBlock(i + 15, j + 1, k + 4, PlaceDeepslate, 0, 2);
		world.setBlock(i + 16, j + 1, k + 4, PlaceDeepslate, 0, 2);
		world.setBlock(i + 17, j + 1, k + 4, Blocks.air, 0, 2);
		world.setBlock(i + 0, j + 1, k + 5, PlaceDeepslate, 0, 2);
		world.setBlock(i + 1, j + 1, k + 5, PlaceDeepslate, 0, 2);
		world.setBlock(i + 2, j + 1, k + 5, PlaceDeepslate, 0, 2);
		world.setBlock(i + 3, j + 1, k + 5, PlaceDeepslate, 0, 2);
		world.setBlock(i + 4, j + 1, k + 5, PlaceDeepslate, 0, 2);
		world.setBlock(i + 5, j + 1, k + 5, PlaceDeepslate, 0, 2);
		world.setBlock(i + 6, j + 1, k + 5, PlaceDeepslate, 0, 2);
		world.setBlock(i + 7, j + 1, k + 5, PlaceDeepslate, 0, 2);
		world.setBlock(i + 8, j + 1, k + 5, PlaceDeepslate, 0, 2);
		world.setBlock(i + 9, j + 1, k + 5, PlaceDeepslate, 0, 2);
		world.setBlock(i + 10, j + 1, k + 5, PlaceDeepslate, 0, 2);
		world.setBlock(i + 11, j + 1, k + 5, PlaceDeepslate, 0, 2);
		world.setBlock(i + 12, j + 1, k + 5, PlaceDeepslate, 0, 2);
		world.setBlock(i + 13, j + 1, k + 5, PlaceDeepslate, 0, 2);
		world.setBlock(i + 14, j + 1, k + 5, PlaceDeepslate, 0, 2);
		world.setBlock(i + 15, j + 1, k + 5, PlaceDeepslate, 0, 2);
		world.setBlock(i + 16, j + 1, k + 5, PlaceDeepslate, 0, 2);
		world.setBlock(i + 17, j + 1, k + 5, Blocks.air, 0, 2);
		world.setBlock(i + 0, j + 1, k + 6, PlaceDeepslate, 0, 2);
		world.setBlock(i + 1, j + 1, k + 6, PlaceDeepslate, 0, 2);
		world.setBlock(i + 2, j + 1, k + 6, PlaceDeepslate, 0, 2);
		world.setBlock(i + 3, j + 1, k + 6, PlaceDeepslate, 0, 2);
		world.setBlock(i + 4, j + 1, k + 6, PlaceDeepslate, 0, 2);
		world.setBlock(i + 5, j + 1, k + 6, PlaceDeepslate, 0, 2);
		world.setBlock(i + 6, j + 1, k + 6, PlaceDeepslate, 0, 2);
		world.setBlock(i + 7, j + 1, k + 6, PlaceDeepslate, 0, 2);
		world.setBlock(i + 8, j + 1, k + 6, PlaceDeepslate, 0, 2);
		world.setBlock(i + 9, j + 1, k + 6, PlaceDeepslate, 0, 2);
		world.setBlock(i + 10, j + 1, k + 6, PlaceDeepslate, 0, 2);
		world.setBlock(i + 11, j + 1, k + 6, PlaceDeepslate, 0, 2);
		world.setBlock(i + 12, j + 1, k + 6, PlaceDeepslate, 0, 2);
		world.setBlock(i + 13, j + 1, k + 6, PlaceDeepslate, 0, 2);
		world.setBlock(i + 14, j + 1, k + 6, PlaceDeepslate, 0, 2);
		world.setBlock(i + 15, j + 1, k + 6, PlaceDeepslate, 0, 2);
		world.setBlock(i + 16, j + 1, k + 6, PlaceDeepslate, 0, 2);
		world.setBlock(i + 17, j + 1, k + 6, Blocks.air, 0, 2);
		world.setBlock(i + 0, j + 1, k + 7, PlaceDeepslate, 0, 2);
		world.setBlock(i + 1, j + 1, k + 7, PlaceDeepslate, 0, 2);
		world.setBlock(i + 2, j + 1, k + 7, PlaceDeepslate, 0, 2);
		world.setBlock(i + 3, j + 1, k + 7, PlaceDeepslate, 0, 2);
		world.setBlock(i + 4, j + 1, k + 7, Blocks.air, 0, 2);
		world.setBlock(i + 5, j + 1, k + 7, PlaceDeepslate, 0, 2);
		world.setBlock(i + 6, j + 1, k + 7, PlaceDeepslate, 0, 2);
		world.setBlock(i + 7, j + 1, k + 7, PlaceDeepslate, 0, 2);
		world.setBlock(i + 8, j + 1, k + 7, PlaceDeepslate, 0, 2);
		world.setBlock(i + 9, j + 1, k + 7, PlaceDeepslate, 0, 2);
		world.setBlock(i + 10, j + 1, k + 7, PlaceDeepslate, 0, 2);
		world.setBlock(i + 11, j + 1, k + 7, PlaceDeepslate, 0, 2);
		world.setBlock(i + 12, j + 1, k + 7, PlaceDeepslate, 0, 2);
		world.setBlock(i + 13, j + 1, k + 7, PlaceDeepslate, 0, 2);
		world.setBlock(i + 14, j + 1, k + 7, PlaceDeepslate, 0, 2);
		world.setBlock(i + 15, j + 1, k + 7, Blocks.air, 0, 2);
		world.setBlock(i + 16, j + 1, k + 7, PlaceCobbledDeepslate, 0, 2);
		world.setBlock(i + 17, j + 1, k + 7, Blocks.air, 0, 2);
		world.setBlock(i + 0, j + 1, k + 8, PlaceDeepslate, 0, 2);
		world.setBlock(i + 1, j + 1, k + 8, PlaceDeepslate, 0, 2);
		world.setBlock(i + 2, j + 1, k + 8, PlaceDeepslate, 0, 2);
		world.setBlock(i + 3, j + 1, k + 8, PlaceDeepslate, 0, 2);
		world.setBlock(i + 4, j + 1, k + 8, PlaceDeepslate, 0, 2);
		world.setBlock(i + 5, j + 1, k + 8, PlaceDeepslate, 0, 2);
		world.setBlock(i + 6, j + 1, k + 8, PlaceDeepslate, 0, 2);
		world.setBlock(i + 7, j + 1, k + 8, PlaceDeepslate, 0, 2);
		world.setBlock(i + 8, j + 1, k + 8, PlaceDeepslate, 0, 2);
		world.setBlock(i + 9, j + 1, k + 8, PlaceDeepslate, 0, 2);
		world.setBlock(i + 10, j + 1, k + 8, PlaceDeepslate, 0, 2);
		world.setBlock(i + 11, j + 1, k + 8, Blocks.air, 0, 2);
		world.setBlock(i + 12, j + 1, k + 8, PlaceDeepslate, 0, 2);
		world.setBlock(i + 13, j + 1, k + 8, PlaceDeepslate, 0, 2);
		world.setBlock(i + 14, j + 1, k + 8, PlaceDeepslate, 0, 2);
		world.setBlock(i + 15, j + 1, k + 8, PlaceDeepslate, 0, 2);
		world.setBlock(i + 16, j + 1, k + 8, Blocks.air, 0, 2);
		world.setBlock(i + 17, j + 1, k + 8, Blocks.air, 0, 2);
		world.setBlock(i + 0, j + 1, k + 9, PlaceDeepslate, 0, 2);
		world.setBlock(i + 1, j + 1, k + 9, PlaceDeepslate, 0, 2);
		world.setBlock(i + 2, j + 1, k + 9, PlaceDeepslate, 0, 2);
		world.setBlock(i + 3, j + 1, k + 9, PlaceDeepslate, 0, 2);
		world.setBlock(i + 4, j + 1, k + 9, PlaceDeepslate, 0, 2);
		world.setBlock(i + 5, j + 1, k + 9, PlaceDeepslate, 0, 2);
		world.setBlock(i + 6, j + 1, k + 9, PlaceDeepslate, 0, 2);
		world.setBlock(i + 7, j + 1, k + 9, NovaCraftBlocks.sculk_block, 0, 2);
		world.setBlock(i + 8, j + 1, k + 9, PlaceDeepslate, 0, 2);
		world.setBlock(i + 9, j + 1, k + 9, PlaceDeepslate, 0, 2);
		world.setBlock(i + 10, j + 1, k + 9, PlaceDeepslate, 0, 2);
		world.setBlock(i + 11, j + 1, k + 9, PlaceDeepslate, 0, 2);
		world.setBlock(i + 12, j + 1, k + 9, PlaceDeepslate, 0, 2);
		world.setBlock(i + 13, j + 1, k + 9, PlaceDeepslate, 0, 2);
		world.setBlock(i + 14, j + 1, k + 9, PlaceDeepslate, 0, 2);
		world.setBlock(i + 15, j + 1, k + 9, PlaceCobbledDeepslate, 0, 2);
		world.setBlock(i + 16, j + 1, k + 9, Blocks.air, 0, 2);
		world.setBlock(i + 17, j + 1, k + 9, Blocks.air, 0, 2);
		world.setBlock(i + 0, j + 1, k + 10, PlaceDeepslate, 0, 2);
		world.setBlock(i + 1, j + 1, k + 10, PlaceDeepslate, 0, 2);
		world.setBlock(i + 2, j + 1, k + 10, PlaceDeepslate, 0, 2);
		world.setBlock(i + 3, j + 1, k + 10, PlaceDeepslate, 0, 2);
		world.setBlock(i + 4, j + 1, k + 10, PlaceDeepslate, 0, 2);
		world.setBlock(i + 5, j + 1, k + 10, PlaceDeepslate, 0, 2);
		world.setBlock(i + 6, j + 1, k + 10, NovaCraftBlocks.sculk_block, 0, 2);
		world.setBlock(i + 7, j + 1, k + 10, Blocks.air, 0, 2);
		world.setBlock(i + 8, j + 1, k + 10, PlaceDeepslate, 0, 2);
		world.setBlock(i + 9, j + 1, k + 10, PlaceDeepslate, 0, 2);
		world.setBlock(i + 10, j + 1, k + 10, PlaceDeepslate, 0, 2);
		world.setBlock(i + 11, j + 1, k + 10, PlaceDeepslate, 0, 2);
		world.setBlock(i + 12, j + 1, k + 10, PlaceDeepslate, 0, 2);
		world.setBlock(i + 13, j + 1, k + 10, PlaceDeepslate, 0, 2);
		world.setBlock(i + 14, j + 1, k + 10, PlaceDeepslate, 0, 2);
		world.setBlock(i + 15, j + 1, k + 10, PlaceDeepslate, 0, 2);
		world.setBlock(i + 16, j + 1, k + 10, PlaceCobbledDeepslate, 0, 2);
		world.setBlock(i + 17, j + 1, k + 10, Blocks.air, 0, 2);
		world.setBlock(i + 0, j + 1, k + 11, PlaceDeepslate, 0, 2);
		world.setBlock(i + 1, j + 1, k + 11, PlaceDeepslate, 0, 2);
		world.setBlock(i + 2, j + 1, k + 11, PlaceDeepslate, 0, 2);
		world.setBlock(i + 3, j + 1, k + 11, PlaceDeepslate, 0, 2);
		world.setBlock(i + 4, j + 1, k + 11, PlaceDeepslate, 0, 2);
		world.setBlock(i + 5, j + 1, k + 11, PlaceDeepslate, 0, 2);
		world.setBlock(i + 6, j + 1, k + 11, PlaceDeepslate, 0, 2);
		world.setBlock(i + 7, j + 1, k + 11, NovaCraftBlocks.sculk_block, 0, 2);
		world.setBlock(i + 8, j + 1, k + 11, PlaceDeepslate, 0, 2);
		world.setBlock(i + 9, j + 1, k + 11, PlaceDeepslate, 0, 2);
		world.setBlock(i + 10, j + 1, k + 11, PlaceDeepslate, 0, 2);
		world.setBlock(i + 11, j + 1, k + 11, Blocks.air, 0, 2);
		world.setBlock(i + 12, j + 1, k + 11, PlaceDeepslate, 0, 2);
		world.setBlock(i + 13, j + 1, k + 11, PlaceDeepslate, 0, 2);
		world.setBlock(i + 14, j + 1, k + 11, PlaceDeepslate, 0, 2);
		world.setBlock(i + 15, j + 1, k + 11, PlaceDeepslate, 0, 2);
		world.setBlock(i + 16, j + 1, k + 11, PlaceDeepslate, 0, 2);
		world.setBlock(i + 17, j + 1, k + 11, Blocks.air, 0, 2);
		world.setBlock(i + 0, j + 1, k + 12, PlaceDeepslate, 0, 2);
		world.setBlock(i + 1, j + 1, k + 12, PlaceDeepslate, 0, 2);
		world.setBlock(i + 2, j + 1, k + 12, NovaCraftBlocks.sculk_block, 0, 2);
		world.setBlock(i + 3, j + 1, k + 12, PlaceDeepslate, 0, 2);
		world.setBlock(i + 4, j + 1, k + 12, PlaceDeepslate, 0, 2);
		world.setBlock(i + 5, j + 1, k + 12, PlaceDeepslate, 0, 2);
		world.setBlock(i + 6, j + 1, k + 12, PlaceDeepslate, 0, 2);
		world.setBlock(i + 7, j + 1, k + 12, NovaCraftBlocks.sculk_block, 0, 2);
		world.setBlock(i + 8, j + 1, k + 12, PlaceDeepslate, 0, 2);
		world.setBlock(i + 9, j + 1, k + 12, NovaCraftBlocks.sculk_block, 0, 2);
		world.setBlock(i + 10, j + 1, k + 12, PlaceDeepslate, 0, 2);
		world.setBlock(i + 11, j + 1, k + 12, PlaceDeepslate, 0, 2);
		world.setBlock(i + 12, j + 1, k + 12, PlaceDeepslate, 0, 2);
		world.setBlock(i + 13, j + 1, k + 12, PlaceDeepslate, 0, 2);
		world.setBlock(i + 14, j + 1, k + 12, PlaceDeepslate, 0, 2);
		world.setBlock(i + 15, j + 1, k + 12, PlaceDeepslate, 0, 2);
		world.setBlock(i + 16, j + 1, k + 12, PlaceDeepslate, 0, 2);
		world.setBlock(i + 17, j + 1, k + 12, Blocks.air, 0, 2);
		world.setBlock(i + 0, j + 1, k + 13, PlaceDeepslate, 0, 2);
		world.setBlock(i + 1, j + 1, k + 13, PlaceDeepslate, 0, 2);
		world.setBlock(i + 2, j + 1, k + 13, PlaceDeepslate, 0, 2);
		world.setBlock(i + 3, j + 1, k + 13, PlaceDeepslate, 0, 2);
		world.setBlock(i + 4, j + 1, k + 13, PlaceDeepslate, 0, 2);
		world.setBlock(i + 5, j + 1, k + 13, PlaceDeepslate, 0, 2);
		world.setBlock(i + 6, j + 1, k + 13, PlaceDeepslate, 0, 2);
		world.setBlock(i + 7, j + 1, k + 13, NovaCraftBlocks.sculk_block, 0, 2);
		world.setBlock(i + 8, j + 1, k + 13, PlaceDeepslate, 0, 2);
		world.setBlock(i + 9, j + 1, k + 13, PlaceDeepslate, 0, 2);
		world.setBlock(i + 10, j + 1, k + 13, PlaceDeepslate, 0, 2);
		world.setBlock(i + 11, j + 1, k + 13, PlaceDeepslate, 0, 2);
		world.setBlock(i + 12, j + 1, k + 13, PlaceDeepslate, 0, 2);
		world.setBlock(i + 13, j + 1, k + 13, PlaceDeepslate, 0, 2);
		world.setBlock(i + 14, j + 1, k + 13, Blocks.air, 0, 2);
		world.setBlock(i + 15, j + 1, k + 13, PlaceDeepslate, 0, 2);
		world.setBlock(i + 16, j + 1, k + 13, PlaceDeepslate, 0, 2);
		world.setBlock(i + 17, j + 1, k + 13, Blocks.air, 0, 2);
		world.setBlock(i + 0, j + 1, k + 14, PlaceDeepslate, 0, 2);
		world.setBlock(i + 1, j + 1, k + 14, PlaceDeepslate, 0, 2);
		world.setBlock(i + 2, j + 1, k + 14, PlaceDeepslate, 0, 2);
		world.setBlock(i + 3, j + 1, k + 14, PlaceDeepslate, 0, 2);
		world.setBlock(i + 4, j + 1, k + 14, PlaceDeepslate, 0, 2);
		world.setBlock(i + 5, j + 1, k + 14, PlaceDeepslate, 0, 2);
		world.setBlock(i + 6, j + 1, k + 14, PlaceDeepslate, 0, 2);
		world.setBlock(i + 7, j + 1, k + 14, NovaCraftBlocks.sculk_block, 0, 2);
		world.setBlock(i + 8, j + 1, k + 14, PlaceDeepslate, 0, 2);
		world.setBlock(i + 9, j + 1, k + 14, PlaceDeepslate, 0, 2);
		world.setBlock(i + 10, j + 1, k + 14, PlaceDeepslate, 0, 2);
		world.setBlock(i + 11, j + 1, k + 14, PlaceDeepslate, 0, 2);
		world.setBlock(i + 12, j + 1, k + 14, PlaceDeepslate, 0, 2);
		world.setBlock(i + 13, j + 1, k + 14, PlaceDeepslate, 0, 2);
		world.setBlock(i + 14, j + 1, k + 14, PlaceDeepslate, 0, 2);
		world.setBlock(i + 15, j + 1, k + 14, PlaceDeepslate, 0, 2);
		world.setBlock(i + 16, j + 1, k + 14, PlaceDeepslate, 0, 2);
		world.setBlock(i + 17, j + 1, k + 14, Blocks.air, 0, 2);
		world.setBlock(i + 0, j + 1, k + 15, PlaceDeepslate, 0, 2);
		world.setBlock(i + 1, j + 1, k + 15, PlaceDeepslate, 0, 2);
		world.setBlock(i + 2, j + 1, k + 15, PlaceDeepslate, 0, 2);
		world.setBlock(i + 3, j + 1, k + 15, PlaceDeepslate, 0, 2);
		world.setBlock(i + 4, j + 1, k + 15, PlaceDeepslate, 0, 2);
		world.setBlock(i + 5, j + 1, k + 15, PlaceDeepslate, 0, 2);
		world.setBlock(i + 6, j + 1, k + 15, PlaceDeepslate, 0, 2);
		world.setBlock(i + 7, j + 1, k + 15, NovaCraftBlocks.sculk_block, 0, 2);
		world.setBlock(i + 8, j + 1, k + 15, PlaceDeepslate, 0, 2);
		world.setBlock(i + 9, j + 1, k + 15, PlaceDeepslate, 0, 2);
		world.setBlock(i + 10, j + 1, k + 15, PlaceDeepslate, 0, 2);
		world.setBlock(i + 11, j + 1, k + 15, PlaceDeepslate, 0, 2);
		world.setBlock(i + 12, j + 1, k + 15, PlaceDeepslate, 0, 2);
		world.setBlock(i + 13, j + 1, k + 15, PlaceDeepslate, 0, 2);
		world.setBlock(i + 14, j + 1, k + 15, PlaceDeepslate, 0, 2);
		world.setBlock(i + 15, j + 1, k + 15, NovaCraftBlocks.sculk_block, 0, 2);
		world.setBlock(i + 16, j + 1, k + 15, PlaceDeepslate, 0, 2);
		world.setBlock(i + 17, j + 1, k + 15, Blocks.air, 0, 2);
		world.setBlock(i + 0, j + 1, k + 16, PlaceDeepslate, 0, 2);
		world.setBlock(i + 1, j + 1, k + 16, PlaceDeepslate, 0, 2);
		world.setBlock(i + 2, j + 1, k + 16, PlaceDeepslate, 0, 2);
		world.setBlock(i + 3, j + 1, k + 16, PlaceDeepslate, 0, 2);
		world.setBlock(i + 4, j + 1, k + 16, PlaceDeepslate, 0, 2);
		world.setBlock(i + 5, j + 1, k + 16, PlaceDeepslate, 0, 2);
		world.setBlock(i + 6, j + 1, k + 16, Blocks.air, 0, 2);
		world.setBlock(i + 7, j + 1, k + 16, PlaceDeepslate, 0, 2);
		world.setBlock(i + 8, j + 1, k + 16, PlaceDeepslate, 0, 2);
		world.setBlock(i + 9, j + 1, k + 16, PlaceDeepslate, 0, 2);
		world.setBlock(i + 10, j + 1, k + 16, PlaceDeepslate, 0, 2);
		world.setBlock(i + 11, j + 1, k + 16, PlaceDeepslate, 0, 2);
		world.setBlock(i + 12, j + 1, k + 16, PlaceDeepslate, 0, 2);
		world.setBlock(i + 13, j + 1, k + 16, PlaceDeepslate, 0, 2);
		world.setBlock(i + 14, j + 1, k + 16, PlaceDeepslate, 0, 2);
		world.setBlock(i + 15, j + 1, k + 16, PlaceDeepslate, 0, 2);
		world.setBlock(i + 16, j + 1, k + 16, PlaceDeepslate, 0, 2);
		world.setBlock(i + 17, j + 1, k + 16, Blocks.air, 0, 2);
		world.setBlock(i + 0, j + 1, k + 17, PlaceDeepslate, 0, 2);
		world.setBlock(i + 1, j + 1, k + 17, PlaceDeepslate, 0, 2);
		world.setBlock(i + 2, j + 1, k + 17, PlaceDeepslate, 0, 2);
		world.setBlock(i + 3, j + 1, k + 17, PlaceDeepslate, 0, 2);
		world.setBlock(i + 4, j + 1, k + 17, PlaceDeepslate, 0, 2);
		world.setBlock(i + 5, j + 1, k + 17, PlaceDeepslate, 0, 2);
		world.setBlock(i + 6, j + 1, k + 17, Blocks.air, 0, 2);
		world.setBlock(i + 7, j + 1, k + 17, PlaceDeepslate, 0, 2);
		world.setBlock(i + 8, j + 1, k + 17, PlaceDeepslate, 0, 2);
		world.setBlock(i + 9, j + 1, k + 17, PlaceDeepslate, 0, 2);
		world.setBlock(i + 10, j + 1, k + 17, PlaceDeepslate, 0, 2);
		world.setBlock(i + 11, j + 1, k + 17, PlaceDeepslate, 0, 2);
		world.setBlock(i + 12, j + 1, k + 17, PlaceDeepslate, 0, 2);
		world.setBlock(i + 13, j + 1, k + 17, PlaceDeepslate, 0, 2);
		world.setBlock(i + 14, j + 1, k + 17, PlaceDeepslate, 0, 2);
		world.setBlock(i + 15, j + 1, k + 17, PlaceDeepslate, 0, 2);
		world.setBlock(i + 16, j + 1, k + 17, PlaceDeepslate, 0, 2);
		world.setBlock(i + 17, j + 1, k + 17, Blocks.air, 0, 2);
		world.setBlock(i + 0, j + 1, k + 18, PlaceDeepslate, 0, 2);
		world.setBlock(i + 1, j + 1, k + 18, PlaceDeepslate, 0, 2);
		world.setBlock(i + 2, j + 1, k + 18, PlaceDeepslate, 0, 2);
		world.setBlock(i + 3, j + 1, k + 18, PlaceDeepslate, 0, 2);
		world.setBlock(i + 4, j + 1, k + 18, PlaceDeepslate, 0, 2);
		world.setBlock(i + 5, j + 1, k + 18, PlaceDeepslate, 0, 2);
		world.setBlock(i + 6, j + 1, k + 18, PlaceDeepslate, 0, 2);
		world.setBlock(i + 7, j + 1, k + 18, PlaceDeepslate, 0, 2);
		world.setBlock(i + 8, j + 1, k + 18, PlaceDeepslate, 0, 2);
		world.setBlock(i + 9, j + 1, k + 18, PlaceDeepslate, 0, 2);
		world.setBlock(i + 10, j + 1, k + 18, PlaceDeepslate, 0, 2);
		world.setBlock(i + 11, j + 1, k + 18, PlaceDeepslate, 0, 2);
		world.setBlock(i + 12, j + 1, k + 18, PlaceDeepslate, 0, 2);
		world.setBlock(i + 13, j + 1, k + 18, PlaceDeepslate, 0, 2);
		world.setBlock(i + 14, j + 1, k + 18, PlaceDeepslate, 0, 2);
		world.setBlock(i + 15, j + 1, k + 18, PlaceDeepslateBrickStairs, 1, 2);
		world.setBlock(i + 16, j + 1, k + 18, Blocks.air, 0, 2);
		world.setBlock(i + 17, j + 1, k + 18, Blocks.air, 0, 2);
		world.setBlock(i + 0, j + 1, k + 19, Blocks.air, 0, 2);
		world.setBlock(i + 1, j + 1, k + 19, PlaceDeepslate, 0, 2);
		world.setBlock(i + 2, j + 1, k + 19, Blocks.air, 0, 2);
		world.setBlock(i + 3, j + 1, k + 19, PlaceDeepslate, 0, 2);
		world.setBlock(i + 4, j + 1, k + 19, PlaceDeepslate, 0, 2);
		world.setBlock(i + 5, j + 1, k + 19, PlaceDeepslate, 0, 2);
		world.setBlock(i + 6, j + 1, k + 19, PlaceDeepslate, 0, 2);
		world.setBlock(i + 7, j + 1, k + 19, PlaceDeepslate, 0, 2);
		world.setBlock(i + 8, j + 1, k + 19, PlaceDeepslate, 0, 2);
		world.setBlock(i + 9, j + 1, k + 19, PlaceDeepslate, 0, 2);
		world.setBlock(i + 10, j + 1, k + 19, PlaceDeepslate, 0, 2);
		world.setBlock(i + 11, j + 1, k + 19, PlaceDeepslate, 0, 2);
		world.setBlock(i + 12, j + 1, k + 19, PlaceDeepslate, 0, 2);
		world.setBlock(i + 13, j + 1, k + 19, PlaceDeepslate, 0, 2);
		world.setBlock(i + 14, j + 1, k + 19, PlaceDeepslate, 0, 2);
		world.setBlock(i + 15, j + 1, k + 19, PlaceDeepslate, 0, 2);
		world.setBlock(i + 16, j + 1, k + 19, PlaceDeepslate, 0, 2);
		world.setBlock(i + 17, j + 1, k + 19, Blocks.air, 0, 2);
		world.setBlock(i + 0, j + 1, k + 20, Blocks.air, 0, 2);
		world.setBlock(i + 1, j + 1, k + 20, Blocks.air, 0, 2);
		world.setBlock(i + 2, j + 1, k + 20, Blocks.air, 0, 2);
		world.setBlock(i + 3, j + 1, k + 20, Blocks.air, 0, 2);
		world.setBlock(i + 4, j + 1, k + 20, Blocks.air, 0, 2);
		world.setBlock(i + 5, j + 1, k + 20, Blocks.air, 0, 2);
		world.setBlock(i + 6, j + 1, k + 20, Blocks.air, 0, 2);
		world.setBlock(i + 7, j + 1, k + 20, Blocks.air, 0, 2);
		world.setBlock(i + 8, j + 1, k + 20, Blocks.air, 0, 2);
		world.setBlock(i + 9, j + 1, k + 20, Blocks.air, 0, 2);
		world.setBlock(i + 10, j + 1, k + 20, Blocks.air, 0, 2);
		world.setBlock(i + 11, j + 1, k + 20, Blocks.air, 0, 2);
		world.setBlock(i + 12, j + 1, k + 20, Blocks.air, 0, 2);
		world.setBlock(i + 13, j + 1, k + 20, Blocks.air, 0, 2);
		world.setBlock(i + 14, j + 1, k + 20, Blocks.air, 0, 2);
		world.setBlock(i + 15, j + 1, k + 20, Blocks.air, 0, 2);
		world.setBlock(i + 16, j + 1, k + 20, Blocks.air, 0, 2);
		world.setBlock(i + 17, j + 1, k + 20, Blocks.air, 0, 2);
		world.setBlock(i + 0, j + 2, k + 0, Blocks.air, 0, 2);
		world.setBlock(i + 1, j + 2, k + 0, Blocks.air, 0, 2);
		world.setBlock(i + 2, j + 2, k + 0, Blocks.air, 0, 2);
		world.setBlock(i + 3, j + 2, k + 0, Blocks.air, 0, 2);
		world.setBlock(i + 4, j + 2, k + 0, Blocks.air, 0, 2);
		world.setBlock(i + 5, j + 2, k + 0, Blocks.air, 0, 2);
		world.setBlock(i + 6, j + 2, k + 0, Blocks.air, 0, 2);
		world.setBlock(i + 7, j + 2, k + 0, Blocks.air, 0, 2);
		world.setBlock(i + 8, j + 2, k + 0, Blocks.air, 0, 2);
		world.setBlock(i + 9, j + 2, k + 0, Blocks.air, 0, 2);
		world.setBlock(i + 10, j + 2, k + 0, Blocks.air, 0, 2);
		world.setBlock(i + 11, j + 2, k + 0, Blocks.air, 0, 2);
		world.setBlock(i + 12, j + 2, k + 0, Blocks.air, 0, 2);
		world.setBlock(i + 13, j + 2, k + 0, Blocks.air, 0, 2);
		world.setBlock(i + 14, j + 2, k + 0, Blocks.air, 0, 2);
		world.setBlock(i + 15, j + 2, k + 0, Blocks.air, 0, 2);
		world.setBlock(i + 16, j + 2, k + 0, Blocks.air, 0, 2);
		world.setBlock(i + 17, j + 2, k + 0, Blocks.air, 0, 2);
		world.setBlock(i + 0, j + 2, k + 1, PlaceDeepslate, 0, 2);
		world.setBlock(i + 1, j + 2, k + 1, PlacePolishedDeepslate, 0, 2);
		world.setBlock(i + 2, j + 2, k + 1, PlaceDeepslate, 0, 2);
		world.setBlock(i + 3, j + 2, k + 1, PlacePolishedDeepslate, 0, 2);
		world.setBlock(i + 4, j + 2, k + 1, PlacePolishedDeepslate, 0, 2);
		world.setBlock(i + 5, j + 2, k + 1, Blocks.air, 0, 2);
		world.setBlock(i + 6, j + 2, k + 1, Blocks.air, 0, 2);
		world.setBlock(i + 7, j + 2, k + 1, PlacePolishedDeepslate, 0, 2);
		world.setBlock(i + 8, j + 2, k + 1, PlacePolishedDeepslate, 0, 2);
		world.setBlock(i + 9, j + 2, k + 1, Blocks.air, 0, 2);
		world.setBlock(i + 10, j + 2, k + 1, PlacePolishedDeepslate, 0, 2);
		world.setBlock(i + 11, j + 2, k + 1, PlacePolishedDeepslate, 0, 2);
		world.setBlock(i + 12, j + 2, k + 1, PlaceDeepslate, 0, 2);
		world.setBlock(i + 13, j + 2, k + 1, PlacePolishedDeepslate, 0, 2);
		world.setBlock(i + 14, j + 2, k + 1, PlaceDeepslate, 0, 2);
		world.setBlock(i + 15, j + 2, k + 1, PlacePolishedDeepslate, 0, 2);
		world.setBlock(i + 16, j + 2, k + 1, PlaceDeepslate, 0, 2);
		world.setBlock(i + 17, j + 2, k + 1, Blocks.air, 0, 2);
		world.setBlock(i + 0, j + 2, k + 2, PlacePolishedDeepslate, 0, 2);
		world.setBlock(i + 1, j + 2, k + 2, PlaceDeepslate, 0, 2);
		world.setBlock(i + 2, j + 2, k + 2, PlaceDeepslate, 0, 2);
		world.setBlock(i + 3, j + 2, k + 2, PlaceDeepslate, 0, 2);
		world.setBlock(i + 4, j + 2, k + 2, PlaceDeepslate, 0, 2);
		world.setBlock(i + 5, j + 2, k + 2, Blocks.air, 0, 2);
		world.setBlock(i + 6, j + 2, k + 2, NovaCraftBlocks.sculk_vein, 4, 2);
		world.setBlock(i + 7, j + 2, k + 2, PlaceDeepslate, 0, 2);
		world.setBlock(i + 8, j + 2, k + 2, PlaceDeepslate, 0, 2);
		world.setBlock(i + 9, j + 2, k + 2, PlaceDeepslate, 0, 2);
		world.setBlock(i + 10, j + 2, k + 2, PlaceDeepslate, 0, 2);
		world.setBlock(i + 11, j + 2, k + 2, PlaceDeepslate, 0, 2);
		world.setBlock(i + 12, j + 2, k + 2, PlaceDeepslate, 0, 2);
		world.setBlock(i + 13, j + 2, k + 2, PlaceDeepslate, 0, 2);
		world.setBlock(i + 14, j + 2, k + 2, PlaceDeepslate, 0, 2);
		world.setBlock(i + 15, j + 2, k + 2, Blocks.air, 0, 2);
		world.setBlock(i + 16, j + 2, k + 2, PlacePolishedDeepslate, 0, 2);
		world.setBlock(i + 17, j + 2, k + 2, Blocks.air, 0, 2);
		world.setBlock(i + 0, j + 2, k + 3, PlaceDeepslate, 0, 2);
		world.setBlock(i + 1, j + 2, k + 3, PlaceDeepslate, 0, 2);
		world.setBlock(i + 2, j + 2, k + 3, Blocks.air, 0, 2);
		world.setBlock(i + 3, j + 2, k + 3, PlaceDeepslate, 0, 2);
		world.setBlock(i + 4, j + 2, k + 3, PlaceDeepslate, 0, 2);
		world.setBlock(i + 5, j + 2, k + 3, Blocks.air, 0, 2);
		world.setBlock(i + 6, j + 2, k + 3, NovaCraftBlocks.sculk_vein, 4, 2);
		world.setBlock(i + 7, j + 2, k + 3, PlaceDeepslate, 0, 2);
		world.setBlock(i + 8, j + 2, k + 3, PlaceDeepslate, 0, 2);
		world.setBlock(i + 9, j + 2, k + 3, PlaceDeepslate, 0, 2);
		world.setBlock(i + 10, j + 2, k + 3, PlaceDeepslate, 0, 2);
		world.setBlock(i + 11, j + 2, k + 3, PlaceDeepslate, 0, 2);
		world.setBlock(i + 12, j + 2, k + 3, PlaceDeepslate, 0, 2);
		world.setBlock(i + 13, j + 2, k + 3, PlaceDeepslate, 0, 2);
		world.setBlock(i + 14, j + 2, k + 3, PlaceDeepslate, 0, 2);
		world.setBlock(i + 15, j + 2, k + 3, PlaceDeepslate, 0, 2);
		world.setBlock(i + 16, j + 2, k + 3, PlaceDeepslate, 0, 2);
		world.setBlock(i + 17, j + 2, k + 3, Blocks.air, 0, 2);
		world.setBlock(i + 0, j + 2, k + 4, PlacePolishedDeepslate, 0, 2);
		world.setBlock(i + 1, j + 2, k + 4, PlaceDeepslate, 0, 2);
		world.setBlock(i + 2, j + 2, k + 4, PlaceDeepslate, 0, 2);
		world.setBlock(i + 3, j + 2, k + 4, PlaceDeepslate, 0, 2);
		world.setBlock(i + 4, j + 2, k + 4, PlaceDeepslate, 0, 2);
		world.setBlock(i + 5, j + 2, k + 4, Blocks.air, 0, 2);
		world.setBlock(i + 6, j + 2, k + 4, NovaCraftBlocks.sculk_vein, 4, 2);
		world.setBlock(i + 7, j + 2, k + 4, PlaceDeepslate, 0, 2);
		world.setBlock(i + 8, j + 2, k + 4, PlaceDeepslate, 0, 2);
		world.setBlock(i + 9, j + 2, k + 4, PlaceDeepslate, 0, 2);
		world.setBlock(i + 10, j + 2, k + 4, PlaceDeepslate, 0, 2);
		world.setBlock(i + 11, j + 2, k + 4, PlaceDeepslate, 0, 2);
		world.setBlock(i + 12, j + 2, k + 4, PlaceDeepslate, 0, 2);
		world.setBlock(i + 13, j + 2, k + 4, PlaceDeepslate, 0, 2);
		world.setBlock(i + 14, j + 2, k + 4, PlaceDeepslate, 0, 2);
		world.setBlock(i + 15, j + 2, k + 4, PlaceDeepslate, 0, 2);
		world.setBlock(i + 16, j + 2, k + 4, PlacePolishedDeepslate, 0, 2);
		world.setBlock(i + 17, j + 2, k + 4, Blocks.air, 0, 2);
		world.setBlock(i + 0, j + 2, k + 5, PlaceDeepslate, 0, 2);
		world.setBlock(i + 1, j + 2, k + 5, PlaceDeepslate, 0, 2);
		world.setBlock(i + 2, j + 2, k + 5, PlaceDeepslate, 0, 2);
		world.setBlock(i + 3, j + 2, k + 5, PlaceDeepslate, 0, 2);
		world.setBlock(i + 4, j + 2, k + 5, PlaceDeepslate, 0, 2);
		world.setBlock(i + 5, j + 2, k + 5, PlaceCobbledDeepslateStairs, 2, 2);
		world.setBlock(i + 6, j + 2, k + 5, PlaceCobbledDeepslateStairs, 2, 2);
		world.setBlock(i + 7, j + 2, k + 5, PlaceDeepslate, 0, 2);
		world.setBlock(i + 8, j + 2, k + 5, PlaceDeepslate, 0, 2);
		world.setBlock(i + 9, j + 2, k + 5, PlaceDeepslate, 0, 2);
		world.setBlock(i + 10, j + 2, k + 5, PlaceDeepslate, 0, 2);
		world.setBlock(i + 11, j + 2, k + 5, NovaCraftBlocks.sculk_block, 0, 2);
		world.setBlock(i + 12, j + 2, k + 5, PlaceDeepslate, 0, 2);
		world.setBlock(i + 13, j + 2, k + 5, PlaceDeepslate, 0, 2);
		world.setBlock(i + 14, j + 2, k + 5, PlaceDeepslate, 0, 2);
		world.setBlock(i + 15, j + 2, k + 5, PlaceDeepslate, 0, 2);
		world.setBlock(i + 16, j + 2, k + 5, PlaceDeepslate, 0, 2);
		world.setBlock(i + 17, j + 2, k + 5, Blocks.air, 0, 2);
		world.setBlock(i + 0, j + 2, k + 6, PlacePolishedDeepslate, 0, 2);
		world.setBlock(i + 1, j + 2, k + 6, PlaceDeepslate, 0, 2);
		world.setBlock(i + 2, j + 2, k + 6, PlaceDeepslate, 0, 2);
		world.setBlock(i + 3, j + 2, k + 6, PlaceDeepslate, 0, 2);
		world.setBlock(i + 4, j + 2, k + 6, PlaceDeepslate, 0, 2);
		world.setBlock(i + 5, j + 2, k + 6, PlaceDeepslate, 0, 2);
		world.setBlock(i + 6, j + 2, k + 6, PlaceDeepslate, 0, 2);
		world.setBlock(i + 7, j + 2, k + 6, PlaceDeepslate, 0, 2);
		world.setBlock(i + 8, j + 2, k + 6, PlaceDeepslate, 0, 2);
		world.setBlock(i + 9, j + 2, k + 6, PlaceDeepslate, 0, 2);
		world.setBlock(i + 10, j + 2, k + 6, PlaceDeepslate, 0, 2);
		world.setBlock(i + 11, j + 2, k + 6, NovaCraftBlocks.sculk_block, 0, 2);
		world.setBlock(i + 12, j + 2, k + 6, PlaceDeepslate, 0, 2);
		world.setBlock(i + 13, j + 2, k + 6, PlaceDeepslate, 0, 2);
		world.setBlock(i + 14, j + 2, k + 6, PlaceDeepslate, 0, 2);
		world.setBlock(i + 15, j + 2, k + 6, PlaceDeepslate, 0, 2);
		world.setBlock(i + 16, j + 2, k + 6, PlacePolishedDeepslate, 0, 2);
		world.setBlock(i + 17, j + 2, k + 6, Blocks.air, 0, 2);
		world.setBlock(i + 0, j + 2, k + 7, PlaceDeepslate, 0, 2);
		world.setBlock(i + 1, j + 2, k + 7, PlaceDeepslate, 0, 2);
		world.setBlock(i + 2, j + 2, k + 7, PlaceDeepslate, 0, 2);
		world.setBlock(i + 3, j + 2, k + 7, NovaCraftBlocks.sculk_block, 0, 2);
		world.setBlock(i + 4, j + 2, k + 7, PlaceDeepslate, 0, 2);
		world.setBlock(i + 5, j + 2, k + 7, PlaceDeepslate, 0, 2);
		world.setBlock(i + 6, j + 2, k + 7, PlaceDeepslate, 0, 2);
		world.setBlock(i + 7, j + 2, k + 7, PlaceDeepslate, 0, 2);
		world.setBlock(i + 8, j + 2, k + 7, PlaceDeepslate, 0, 2);
		world.setBlock(i + 9, j + 2, k + 7, PlaceDeepslate, 0, 2);
		world.setBlock(i + 10, j + 2, k + 7, PlaceDeepslate, 0, 2);
		world.setBlock(i + 11, j + 2, k + 7, PlaceDeepslate, 0, 2);
		world.setBlock(i + 12, j + 2, k + 7, PlaceDeepslate, 0, 2);
		world.setBlock(i + 13, j + 2, k + 7, Blocks.air, 0, 2);
		world.setBlock(i + 14, j + 2, k + 7, PlaceDeepslate, 0, 2);
		world.setBlock(i + 15, j + 2, k + 7, PlaceDeepslate, 0, 2);
		world.setBlock(i + 16, j + 2, k + 7, Blocks.air, 0, 2);
		world.setBlock(i + 17, j + 2, k + 7, Blocks.air, 0, 2);
		world.setBlock(i + 0, j + 2, k + 8, PlacePolishedDeepslate, 0, 2);
		world.setBlock(i + 1, j + 2, k + 8, PlaceDeepslate, 0, 2);
		world.setBlock(i + 2, j + 2, k + 8, PlaceDeepslate, 0, 2);
		world.setBlock(i + 3, j + 2, k + 8, PlaceDeepslate, 0, 2);
		world.setBlock(i + 4, j + 2, k + 8, PlaceDeepslate, 0, 2);
		world.setBlock(i + 5, j + 2, k + 8, PlaceDeepslate, 0, 2);
		world.setBlock(i + 6, j + 2, k + 8, Blocks.air, 0, 2);
		world.setBlock(i + 7, j + 2, k + 8, PlaceDeepslate, 0, 2);
		world.setBlock(i + 8, j + 2, k + 8, PlaceDeepslate, 0, 2);
		world.setBlock(i + 9, j + 2, k + 8, PlaceDeepslate, 0, 2);
		world.setBlock(i + 10, j + 2, k + 8, PlaceDeepslate, 0, 2);
		world.setBlock(i + 11, j + 2, k + 8, PlaceDeepslate, 0, 2);
		world.setBlock(i + 12, j + 2, k + 8, PlaceDeepslate, 0, 2);
		world.setBlock(i + 13, j + 2, k + 8, PlaceDeepslate, 0, 2);
		world.setBlock(i + 14, j + 2, k + 8, PlaceCobbledDeepslate, 0, 2);
		world.setBlock(i + 15, j + 2, k + 8, Blocks.air, 0, 2);
		world.setBlock(i + 16, j + 2, k + 8, Blocks.air, 0, 2);
		world.setBlock(i + 17, j + 2, k + 8, Blocks.air, 0, 2);
		world.setBlock(i + 0, j + 2, k + 9, PlaceDeepslate, 0, 2);
		world.setBlock(i + 1, j + 2, k + 9, PlaceDeepslate, 0, 2);
		world.setBlock(i + 2, j + 2, k + 9, PlaceDeepslate, 0, 2);
		world.setBlock(i + 3, j + 2, k + 9, PlaceDeepslate, 0, 2);
		world.setBlock(i + 4, j + 2, k + 9, PlaceDeepslate, 0, 2);
		world.setBlock(i + 5, j + 2, k + 9, PlaceDeepslate, 0, 2);
		world.setBlock(i + 6, j + 2, k + 9, PlaceDeepslate, 0, 2);
		world.setBlock(i + 7, j + 2, k + 9, PlaceDeepslate, 0, 2);
		world.setBlock(i + 8, j + 2, k + 9, Blocks.air, 0, 2);
		world.setBlock(i + 9, j + 2, k + 9, PlaceDeepslate, 0, 2);
		world.setBlock(i + 10, j + 2, k + 9, PlaceDeepslate, 0, 2);
		world.setBlock(i + 11, j + 2, k + 9, PlaceDeepslate, 0, 2);
		world.setBlock(i + 12, j + 2, k + 9, PlaceDeepslate, 0, 2);
		world.setBlock(i + 13, j + 2, k + 9, NovaCraftBlocks.sculk_vein, 2, 2);
		world.setBlock(i + 14, j + 2, k + 9, PlaceDeepslate, 0, 2);
		world.setBlock(i + 15, j + 2, k + 9, Blocks.air, 0, 2);
		world.setBlock(i + 16, j + 2, k + 9, Blocks.air, 0, 2);
		world.setBlock(i + 17, j + 2, k + 9, Blocks.air, 0, 2);
		world.setBlock(i + 0, j + 2, k + 10, PlacePolishedDeepslate, 0, 2);
		world.setBlock(i + 1, j + 2, k + 10, PlaceDeepslate, 0, 2);
		world.setBlock(i + 2, j + 2, k + 10, PlaceDeepslate, 0, 2);
		world.setBlock(i + 3, j + 2, k + 10, PlaceDeepslate, 0, 2);
		world.setBlock(i + 4, j + 2, k + 10, PlaceDeepslate, 0, 2);
		world.setBlock(i + 5, j + 2, k + 10, PlaceDeepslate, 0, 2);
		world.setBlock(i + 6, j + 2, k + 10, PlaceDeepslate, 0, 2);
		world.setBlock(i + 7, j + 2, k + 10, NovaCraftBlocks.sculk_block, 0, 2);
		world.setBlock(i + 8, j + 2, k + 10, PlaceDeepslate, 0, 2);
		world.setBlock(i + 9, j + 2, k + 10, PlaceDeepslate, 0, 2);
		world.setBlock(i + 10, j + 2, k + 10, PlaceDeepslate, 0, 2);
		world.setBlock(i + 11, j + 2, k + 10, PlaceDeepslate, 0, 2);
		world.setBlock(i + 12, j + 2, k + 10, PlaceDeepslate, 0, 2);
		world.setBlock(i + 13, j + 2, k + 10, PlaceDeepslate, 0, 2);
		world.setBlock(i + 14, j + 2, k + 10, PlaceDeepslate, 0, 2);
		world.setBlock(i + 15, j + 2, k + 10, PlaceDeepslate, 0, 2);
		world.setBlock(i + 16, j + 2, k + 10, Blocks.air, 0, 2);
		world.setBlock(i + 17, j + 2, k + 10, Blocks.air, 0, 2);
		world.setBlock(i + 0, j + 2, k + 11, PlaceDeepslate, 0, 2);
		world.setBlock(i + 1, j + 2, k + 11, PlaceDeepslate, 0, 2);
		world.setBlock(i + 2, j + 2, k + 11, NovaCraftBlocks.sculk_block, 0, 2);
		world.setBlock(i + 3, j + 2, k + 11, PlaceDeepslate, 0, 2);
		world.setBlock(i + 4, j + 2, k + 11, PlaceDeepslate, 0, 2);
		world.setBlock(i + 5, j + 2, k + 11, PlaceDeepslate, 0, 2);
		world.setBlock(i + 6, j + 2, k + 11, NovaCraftBlocks.sculk_block, 0, 2);
		world.setBlock(i + 7, j + 2, k + 11, Blocks.air, 0, 2);
		world.setBlock(i + 8, j + 2, k + 11, NovaCraftBlocks.sculk_block, 0, 2);
		world.setBlock(i + 9, j + 2, k + 11, NovaCraftBlocks.sculk_block, 0, 2);
		world.setBlock(i + 10, j + 2, k + 11, PlaceDeepslate, 0, 2);
		world.setBlock(i + 11, j + 2, k + 11, PlaceDeepslate, 0, 2);
		world.setBlock(i + 12, j + 2, k + 11, PlaceDeepslate, 0, 2);
		world.setBlock(i + 13, j + 2, k + 11, PlaceDeepslate, 0, 2);
		world.setBlock(i + 14, j + 2, k + 11, PlaceDeepslate, 0, 2);
		world.setBlock(i + 15, j + 2, k + 11, PlaceDeepslate, 0, 2);
		world.setBlock(i + 16, j + 2, k + 11, PlacePolishedDeepslate, 0, 2);
		world.setBlock(i + 17, j + 2, k + 11, Blocks.air, 0, 2);
		world.setBlock(i + 0, j + 2, k + 12, PlacePolishedDeepslate, 0, 2);
		world.setBlock(i + 1, j + 2, k + 12, NovaCraftBlocks.sculk_block, 0, 2);
		world.setBlock(i + 2, j + 2, k + 12, NovaCraftBlocks.sculk_vein, 3, 2);
		world.setBlock(i + 3, j + 2, k + 12, NovaCraftBlocks.sculk_block, 0, 2);
		world.setBlock(i + 4, j + 2, k + 12, PlaceDeepslate, 0, 2);
		world.setBlock(i + 5, j + 2, k + 12, PlaceDeepslate, 0, 2);
		world.setBlock(i + 6, j + 2, k + 12, PlaceDeepslate, 0, 2);
		world.setBlock(i + 7, j + 2, k + 12, NovaCraftBlocks.sculk_block, 0, 2);
		world.setBlock(i + 8, j + 2, k + 12, NovaCraftBlocks.sculk_block, 0, 2);
		world.setBlock(i + 9, j + 2, k + 12, Blocks.air, 0, 2);
		world.setBlock(i + 10, j + 2, k + 12, NovaCraftBlocks.sculk_block, 0, 2);
		world.setBlock(i + 11, j + 2, k + 12, PlaceDeepslate, 0, 2);
		world.setBlock(i + 12, j + 2, k + 12, PlaceDeepslate, 0, 2);
		world.setBlock(i + 13, j + 2, k + 12, PlaceDeepslate, 0, 2);
		world.setBlock(i + 14, j + 2, k + 12, Blocks.air, 0, 2);
		world.setBlock(i + 15, j + 2, k + 12, PlaceDeepslate, 0, 2);
		world.setBlock(i + 16, j + 2, k + 12, PlaceDeepslate, 0, 2);
		world.setBlock(i + 17, j + 2, k + 12, Blocks.air, 0, 2);
		world.setBlock(i + 0, j + 2, k + 13, PlaceDeepslate, 0, 2);
		world.setBlock(i + 1, j + 2, k + 13, PlaceDeepslate, 0, 2);
		world.setBlock(i + 2, j + 2, k + 13, NovaCraftBlocks.sculk_block, 0, 2);
		world.setBlock(i + 3, j + 2, k + 13, PlaceDeepslate, 0, 2);
		world.setBlock(i + 4, j + 2, k + 13, PlaceDeepslate, 0, 2);
		world.setBlock(i + 5, j + 2, k + 13, PlaceDeepslate, 0, 2);
		world.setBlock(i + 6, j + 2, k + 13, PlaceDeepslate, 0, 2);
		world.setBlock(i + 7, j + 2, k + 13, NovaCraftBlocks.sculk_block, 0, 2);
		world.setBlock(i + 8, j + 2, k + 13, PlaceDeepslate, 0, 2);
		world.setBlock(i + 9, j + 2, k + 13, NovaCraftBlocks.sculk_block, 0, 2);
		world.setBlock(i + 10, j + 2, k + 13, PlaceDeepslate, 0, 2);
		world.setBlock(i + 11, j + 2, k + 13, PlaceDeepslate, 0, 2);
		world.setBlock(i + 12, j + 2, k + 13, PlaceDeepslate, 0, 2);
		world.setBlock(i + 13, j + 2, k + 13, PlaceDeepslate, 0, 2);
		world.setBlock(i + 14, j + 2, k + 13, PlaceDeepslate, 0, 2);
		world.setBlock(i + 15, j + 2, k + 13, PlaceDeepslate, 0, 2);
		world.setBlock(i + 16, j + 2, k + 13, PlacePolishedDeepslate, 0, 2);
		world.setBlock(i + 17, j + 2, k + 13, Blocks.air, 0, 2);
		world.setBlock(i + 0, j + 2, k + 14, PlacePolishedDeepslate, 0, 2);
		world.setBlock(i + 1, j + 2, k + 14, PlaceDeepslate, 0, 2);
		world.setBlock(i + 2, j + 2, k + 14, Blocks.air, 0, 2);
		world.setBlock(i + 3, j + 2, k + 14, NovaCraftBlocks.sculk_block, 0, 2);
		world.setBlock(i + 4, j + 2, k + 14, PlaceDeepslate, 0, 2);
		world.setBlock(i + 5, j + 2, k + 14, PlaceDeepslate, 0, 2);
		world.setBlock(i + 6, j + 2, k + 14, PlaceDeepslate, 0, 2);
		world.setBlock(i + 7, j + 2, k + 14, NovaCraftBlocks.sculk_block, 0, 2);
		world.setBlock(i + 8, j + 2, k + 14, NovaCraftBlocks.sculk_block, 0, 2);
		world.setBlock(i + 9, j + 2, k + 14, Blocks.air, 0, 2);
		world.setBlock(i + 10, j + 2, k + 14, PlaceDeepslate, 0, 2);
		world.setBlock(i + 11, j + 2, k + 14, PlaceDeepslate, 0, 2);
		world.setBlock(i + 12, j + 2, k + 14, PlaceDeepslate, 0, 2);
		world.setBlock(i + 13, j + 2, k + 14, PlaceDeepslate, 0, 2);
		world.setBlock(i + 14, j + 2, k + 14, PlaceDeepslate, 0, 2);
		world.setBlock(i + 15, j + 2, k + 14, PlaceDeepslate, 0, 2);
		world.setBlock(i + 16, j + 2, k + 14, PlaceDeepslate, 0, 2);
		world.setBlock(i + 17, j + 2, k + 14, Blocks.air, 0, 2);
		world.setBlock(i + 0, j + 2, k + 15, PlaceDeepslate, 0, 2);
		world.setBlock(i + 1, j + 2, k + 15, PlaceDeepslate, 0, 2);
		world.setBlock(i + 2, j + 2, k + 15, NovaCraftBlocks.sculk_block, 0, 2);
		world.setBlock(i + 3, j + 2, k + 15, PlaceDeepslate, 0, 2);
		world.setBlock(i + 4, j + 2, k + 15, PlaceDeepslate, 0, 2);
		world.setBlock(i + 5, j + 2, k + 15, Blocks.air, 0, 2);
		world.setBlock(i + 6, j + 2, k + 15, PlaceDeepslate, 0, 2);
		world.setBlock(i + 7, j + 2, k + 15, NovaCraftBlocks.sculk_block, 0, 2);
		world.setBlock(i + 8, j + 2, k + 15, PlaceDeepslate, 0, 2);
		world.setBlock(i + 9, j + 2, k + 15, PlaceDeepslate, 0, 2);
		world.setBlock(i + 10, j + 2, k + 15, PlaceDeepslate, 0, 2);
		world.setBlock(i + 11, j + 2, k + 15, PlaceDeepslate, 0, 2);
		world.setBlock(i + 12, j + 2, k + 15, PlaceDeepslate, 0, 2);
		world.setBlock(i + 13, j + 2, k + 15, Blocks.air, 0, 2);
		world.setBlock(i + 14, j + 2, k + 15, NovaCraftBlocks.sculk_block, 0, 2);
		world.setBlock(i + 15, j + 2, k + 15, Blocks.air, 0, 2);
		world.setBlock(i + 16, j + 2, k + 15, PlacePolishedDeepslate, 0, 2);
		world.setBlock(i + 17, j + 2, k + 15, Blocks.air, 0, 2);
		world.setBlock(i + 0, j + 2, k + 16, PlacePolishedDeepslate, 0, 2);
		world.setBlock(i + 1, j + 2, k + 16, PlaceDeepslate, 0, 2);
		world.setBlock(i + 2, j + 2, k + 16, PlaceDeepslate, 0, 2);
		world.setBlock(i + 3, j + 2, k + 16, PlaceDeepslate, 0, 2);
		world.setBlock(i + 4, j + 2, k + 16, PlaceDeepslate, 0, 2);
		world.setBlock(i + 5, j + 2, k + 16, PlaceDeepslate, 0, 2);
		world.setBlock(i + 6, j + 2, k + 16, PlaceDeepslate, 0, 2);
		world.setBlock(i + 7, j + 2, k + 16, PlaceDeepslate, 0, 2);
		world.setBlock(i + 8, j + 2, k + 16, PlaceDeepslate, 0, 2);
		world.setBlock(i + 9, j + 2, k + 16, Blocks.air, 0, 2);
		world.setBlock(i + 10, j + 2, k + 16, PlaceDeepslate, 0, 2);
		world.setBlock(i + 11, j + 2, k + 16, PlaceDeepslate, 0, 2);
		world.setBlock(i + 12, j + 2, k + 16, PlaceDeepslate, 0, 2);
		world.setBlock(i + 13, j + 2, k + 16, NovaCraftBlocks.sculk_block, 0, 2);
		world.setBlock(i + 14, j + 2, k + 16, PlaceDeepslate, 0, 2);
		world.setBlock(i + 15, j + 2, k + 16, PlaceDeepslate, 0, 2);
		world.setBlock(i + 16, j + 2, k + 16, PlaceDeepslate, 0, 2);
		world.setBlock(i + 17, j + 2, k + 16, Blocks.air, 0, 2);
		world.setBlock(i + 0, j + 2, k + 17, PlaceDeepslate, 0, 2);
		world.setBlock(i + 1, j + 2, k + 17, PlaceDeepslate, 0, 2);
		world.setBlock(i + 2, j + 2, k + 17, PlaceDeepslate, 0, 2);
		world.setBlock(i + 3, j + 2, k + 17, PlaceDeepslate, 0, 2);
		world.setBlock(i + 4, j + 2, k + 17, PlaceDeepslate, 0, 2);
		world.setBlock(i + 5, j + 2, k + 17, PlaceDeepslate, 0, 2);
		world.setBlock(i + 6, j + 2, k + 17, PlaceDeepslate, 0, 2);
		world.setBlock(i + 7, j + 2, k + 17, PlaceDeepslate, 0, 2);
		world.setBlock(i + 8, j + 2, k + 17, PlaceDeepslate, 0, 2);
		world.setBlock(i + 9, j + 2, k + 17, PlaceDeepslate, 0, 2);
		world.setBlock(i + 10, j + 2, k + 17, PlaceDeepslate, 0, 2);
		world.setBlock(i + 11, j + 2, k + 17, PlaceDeepslate, 0, 2);
		world.setBlock(i + 12, j + 2, k + 17, Blocks.air, 0, 2);
		world.setBlock(i + 13, j + 2, k + 17, PlaceDeepslate, 0, 2);
		world.setBlock(i + 14, j + 2, k + 17, NovaCraftBlocks.sculk_block, 0, 2);
		world.setBlock(i + 15, j + 2, k + 17, PlaceDeepslate, 0, 2);
		world.setBlock(i + 16, j + 2, k + 17, PlacePolishedDeepslate, 0, 2);
		world.setBlock(i + 17, j + 2, k + 17, Blocks.air, 0, 2);
		world.setBlock(i + 0, j + 2, k + 18, PlacePolishedDeepslate, 0, 2);
		world.setBlock(i + 1, j + 2, k + 18, PlaceDeepslate, 0, 2);
		world.setBlock(i + 2, j + 2, k + 18, PlaceDeepslate, 0, 2);
		world.setBlock(i + 3, j + 2, k + 18, PlaceDeepslate, 0, 2);
		world.setBlock(i + 4, j + 2, k + 18, NovaCraftBlocks.sculk_block, 0, 2);
		world.setBlock(i + 5, j + 2, k + 18, PlaceDeepslate, 0, 2);
		world.setBlock(i + 6, j + 2, k + 18, PlaceDeepslate, 0, 2);
		world.setBlock(i + 7, j + 2, k + 18, PlaceDeepslate, 0, 2);
		world.setBlock(i + 8, j + 2, k + 18, NovaCraftBlocks.sculk_block, 0, 2);
		world.setBlock(i + 9, j + 2, k + 18, PlaceDeepslate, 0, 2);
		world.setBlock(i + 10, j + 2, k + 18, PlaceDeepslate, 0, 2);
		world.setBlock(i + 11, j + 2, k + 18, PlaceDeepslate, 0, 2);
		world.setBlock(i + 12, j + 2, k + 18, PlaceDeepslate, 0, 2);
		world.setBlock(i + 13, j + 2, k + 18, PlaceDeepslate, 0, 2);
		world.setBlock(i + 14, j + 2, k + 18, PlaceDeepslateBrickStairs, 1, 2);
		world.setBlock(i + 15, j + 2, k + 18, NovaCraftBlocks.sculk_vein, 3, 2);
		world.setBlock(i + 16, j + 2, k + 18, Blocks.air, 0, 2);
		world.setBlock(i + 17, j + 2, k + 18, Blocks.air, 0, 2);
		world.setBlock(i + 0, j + 2, k + 19, PlaceDeepslate, 0, 2);
		world.setBlock(i + 1, j + 2, k + 19, PlacePolishedDeepslate, 0, 2);
		world.setBlock(i + 2, j + 2, k + 19, PlaceDeepslate, 0, 2);
		world.setBlock(i + 3, j + 2, k + 19, PlacePolishedDeepslate, 0, 2);
		world.setBlock(i + 4, j + 2, k + 19, PlaceDeepslate, 0, 2);
		world.setBlock(i + 5, j + 2, k + 19, PlacePolishedDeepslate, 0, 2);
		world.setBlock(i + 6, j + 2, k + 19, PlaceDeepslate, 0, 2);
		world.setBlock(i + 7, j + 2, k + 19, PlacePolishedDeepslate, 0, 2);
		world.setBlock(i + 8, j + 2, k + 19, PlaceDeepslate, 0, 2);
		world.setBlock(i + 9, j + 2, k + 19, PlacePolishedDeepslate, 0, 2);
		world.setBlock(i + 10, j + 2, k + 19, PlaceDeepslate, 0, 2);
		world.setBlock(i + 11, j + 2, k + 19, PlacePolishedDeepslate, 0, 2);
		world.setBlock(i + 12, j + 2, k + 19, PlaceDeepslate, 0, 2);
		world.setBlock(i + 13, j + 2, k + 19, PlacePolishedDeepslate, 0, 2);
		world.setBlock(i + 14, j + 2, k + 19, PlaceDeepslate, 0, 2);
		world.setBlock(i + 15, j + 2, k + 19, PlacePolishedDeepslate, 0, 2);
		world.setBlock(i + 16, j + 2, k + 19, PlaceDeepslate, 0, 2);
		world.setBlock(i + 17, j + 2, k + 19, Blocks.air, 0, 2);
		world.setBlock(i + 0, j + 2, k + 20, Blocks.air, 0, 2);
		world.setBlock(i + 1, j + 2, k + 20, Blocks.air, 0, 2);
		world.setBlock(i + 2, j + 2, k + 20, Blocks.air, 0, 2);
		world.setBlock(i + 3, j + 2, k + 20, Blocks.air, 0, 2);
		world.setBlock(i + 4, j + 2, k + 20, Blocks.air, 0, 2);
		world.setBlock(i + 5, j + 2, k + 20, Blocks.air, 0, 2);
		world.setBlock(i + 6, j + 2, k + 20, Blocks.air, 0, 2);
		world.setBlock(i + 7, j + 2, k + 20, Blocks.air, 0, 2);
		world.setBlock(i + 8, j + 2, k + 20, Blocks.air, 0, 2);
		world.setBlock(i + 9, j + 2, k + 20, Blocks.air, 0, 2);
		world.setBlock(i + 10, j + 2, k + 20, Blocks.air, 0, 2);
		world.setBlock(i + 11, j + 2, k + 20, Blocks.air, 0, 2);
		world.setBlock(i + 12, j + 2, k + 20, Blocks.air, 0, 2);
		world.setBlock(i + 13, j + 2, k + 20, Blocks.air, 0, 2);
		world.setBlock(i + 14, j + 2, k + 20, Blocks.air, 0, 2);
		world.setBlock(i + 15, j + 2, k + 20, Blocks.air, 0, 2);
		world.setBlock(i + 16, j + 2, k + 20, Blocks.air, 0, 2);
		world.setBlock(i + 17, j + 2, k + 20, Blocks.air, 0, 2);
		world.setBlock(i + 0, j + 3, k + 0, Blocks.air, 0, 2);
		world.setBlock(i + 1, j + 3, k + 0, Blocks.air, 0, 2);
		world.setBlock(i + 2, j + 3, k + 0, Blocks.air, 0, 2);
		world.setBlock(i + 3, j + 3, k + 0, Blocks.air, 0, 2);
		world.setBlock(i + 4, j + 3, k + 0, Blocks.air, 0, 2);
		world.setBlock(i + 5, j + 3, k + 0, Blocks.air, 0, 2);
		world.setBlock(i + 6, j + 3, k + 0, Blocks.air, 0, 2);
		world.setBlock(i + 7, j + 3, k + 0, NovaCraftBlocks.sculk_vein, 2, 2);
		world.setBlock(i + 8, j + 3, k + 0, Blocks.air, 0, 2);
		world.setBlock(i + 9, j + 3, k + 0, Blocks.air, 0, 2);
		world.setBlock(i + 10, j + 3, k + 0, Blocks.air, 0, 2);
		world.setBlock(i + 11, j + 3, k + 0, Blocks.air, 0, 2);
		world.setBlock(i + 12, j + 3, k + 0, Blocks.air, 0, 2);
		world.setBlock(i + 13, j + 3, k + 0, Blocks.air, 0, 2);
		world.setBlock(i + 14, j + 3, k + 0, NovaCraftBlocks.sculk_vein, 2, 2);
		world.setBlock(i + 15, j + 3, k + 0, Blocks.air, 0, 2);
		world.setBlock(i + 16, j + 3, k + 0, Blocks.air, 0, 2);
		world.setBlock(i + 17, j + 3, k + 0, Blocks.air, 0, 2);
		world.setBlock(i + 0, j + 3, k + 1, PlacePolishedDeepslate, 0, 2);
		world.setBlock(i + 1, j + 3, k + 1, PlacePolishedDeepslate, 0, 2);
		world.setBlock(i + 2, j + 3, k + 1, PlacePolishedDeepslate, 0, 2);
		world.setBlock(i + 3, j + 3, k + 1, PlacePolishedDeepslate, 0, 2);
		world.setBlock(i + 4, j + 3, k + 1, PlacePolishedDeepslate, 0, 2);
		world.setBlock(i + 5, j + 3, k + 1, PlacePolishedDeepslate, 0, 2);
		world.setBlock(i + 6, j + 3, k + 1, PlacePolishedDeepslate, 0, 2);
		world.setBlock(i + 7, j + 3, k + 1, PlacePolishedDeepslate, 0, 2);
		world.setBlock(i + 8, j + 3, k + 1, PlacePolishedDeepslate, 0, 2);
		world.setBlock(i + 9, j + 3, k + 1, PlacePolishedDeepslate, 0, 2);
		world.setBlock(i + 10, j + 3, k + 1, PlacePolishedDeepslate, 0, 2);
		world.setBlock(i + 11, j + 3, k + 1, PlacePolishedDeepslate, 0, 2);
		world.setBlock(i + 12, j + 3, k + 1, PlacePolishedDeepslate, 0, 2);
		world.setBlock(i + 13, j + 3, k + 1, PlacePolishedDeepslate, 0, 2);
		world.setBlock(i + 14, j + 3, k + 1, PlacePolishedDeepslate, 0, 2);
		world.setBlock(i + 15, j + 3, k + 1, PlacePolishedDeepslate, 0, 2);
		world.setBlock(i + 16, j + 3, k + 1, PlacePolishedDeepslate, 0, 2);
		world.setBlock(i + 17, j + 3, k + 1, Blocks.air, 0, 2);
		world.setBlock(i + 0, j + 3, k + 2, PlacePolishedDeepslate, 0, 2);
		world.setBlock(i + 1, j + 3, k + 2, PlaceDeepslate, 0, 2);
		world.setBlock(i + 2, j + 3, k + 2, PlaceDeepslate, 0, 2);
		world.setBlock(i + 3, j + 3, k + 2, PlaceDeepslate, 0, 2);
		world.setBlock(i + 4, j + 3, k + 2, PlaceDeepslate, 0, 2);
		world.setBlock(i + 5, j + 3, k + 2, PlaceCobbledDeepslateStairs, 7, 2);
		world.setBlock(i + 6, j + 3, k + 2, PlaceCobbledDeepslateStairs, 7, 2);
		world.setBlock(i + 7, j + 3, k + 2, NovaCraftBlocks.sculk_block, 0, 2);
		world.setBlock(i + 8, j + 3, k + 2, NovaCraftBlocks.sculk_block, 0, 2);
		world.setBlock(i + 9, j + 3, k + 2, NovaCraftBlocks.sculk_block, 0, 2);
		world.setBlock(i + 10, j + 3, k + 2, NovaCraftBlocks.sculk_block, 0, 2);
		world.setBlock(i + 11, j + 3, k + 2, NovaCraftBlocks.sculk_block, 0, 2);
		world.setBlock(i + 12, j + 3, k + 2, PlaceDeepslate, 0, 2);
		world.setBlock(i + 13, j + 3, k + 2, PlaceDeepslate, 0, 2);
		world.setBlock(i + 14, j + 3, k + 2, PlaceDeepslate, 0, 2);
		world.setBlock(i + 15, j + 3, k + 2, NovaCraftBlocks.sculk_block, 0, 2);
		world.setBlock(i + 16, j + 3, k + 2, PlacePolishedDeepslate, 0, 2);
		world.setBlock(i + 17, j + 3, k + 2, Blocks.air, 0, 2);
		world.setBlock(i + 0, j + 3, k + 3, PlacePolishedDeepslate, 0, 2);
		world.setBlock(i + 1, j + 3, k + 3, PlaceDeepslate, 0, 2);
		world.setBlock(i + 2, j + 3, k + 3, PlaceDeepslate, 0, 2);
		world.setBlock(i + 3, j + 3, k + 3, PlaceDeepslate, 0, 2);
		world.setBlock(i + 4, j + 3, k + 3, Blocks.air, 0, 2);
		world.setBlock(i + 5, j + 3, k + 3, Blocks.air, 0, 2);
		world.setBlock(i + 6, j + 3, k + 3, Blocks.air, 0, 2);
		world.setBlock(i + 7, j + 3, k + 3, NovaCraftBlocks.sculk_block, 0, 2);
		world.setBlock(i + 8, j + 3, k + 3, NovaCraftBlocks.sculk_block, 0, 2);
		world.setBlock(i + 9, j + 3, k + 3, NovaCraftBlocks.sculk_block, 0, 2);
		world.setBlock(i + 10, j + 3, k + 3, NovaCraftBlocks.sculk_block, 0, 2);
		world.setBlock(i + 11, j + 3, k + 3, NovaCraftBlocks.sculk_block, 0, 2);
		world.setBlock(i + 12, j + 3, k + 3, NovaCraftBlocks.sculk_block, 0, 2);
		world.setBlock(i + 13, j + 3, k + 3, NovaCraftBlocks.sculk_block, 0, 2);
		world.setBlock(i + 14, j + 3, k + 3, NovaCraftBlocks.sculk_block, 0, 2);
		world.setBlock(i + 15, j + 3, k + 3, NovaCraftBlocks.sculk_block, 0, 2);
		world.setBlock(i + 16, j + 3, k + 3, PlacePolishedDeepslate, 0, 2);
		world.setBlock(i + 17, j + 3, k + 3, Blocks.air, 0, 2);
		world.setBlock(i + 0, j + 3, k + 4, PlacePolishedDeepslate, 0, 2);
		world.setBlock(i + 1, j + 3, k + 4, PlaceDeepslate, 0, 2);
		world.setBlock(i + 2, j + 3, k + 4, PlaceDeepslate, 0, 2);
		world.setBlock(i + 3, j + 3, k + 4, PlaceDeepslate, 0, 2);
		world.setBlock(i + 4, j + 3, k + 4, PlaceDeepslate, 0, 2);
		world.setBlock(i + 5, j + 3, k + 4, Blocks.air, 0, 2);
		world.setBlock(i + 6, j + 3, k + 4, Blocks.air, 0, 2);
		world.setBlock(i + 7, j + 3, k + 4, NovaCraftBlocks.sculk_block, 0, 2);
		world.setBlock(i + 8, j + 3, k + 4, PlaceDeepslate, 0, 2);
		world.setBlock(i + 9, j + 3, k + 4, PlaceDeepslate, 0, 2);
		world.setBlock(i + 10, j + 3, k + 4, PlaceDeepslate, 0, 2);
		world.setBlock(i + 11, j + 3, k + 4, NovaCraftBlocks.sculk_block, 0, 2);
		world.setBlock(i + 12, j + 3, k + 4, PlaceDeepslate, 0, 2);
		world.setBlock(i + 13, j + 3, k + 4, PlaceDeepslate, 0, 2);
		world.setBlock(i + 14, j + 3, k + 4, PlaceDeepslate, 0, 2);
		world.setBlock(i + 15, j + 3, k + 4, PlaceDeepslate, 0, 2);
		world.setBlock(i + 16, j + 3, k + 4, PlacePolishedDeepslate, 0, 2);
		world.setBlock(i + 17, j + 3, k + 4, Blocks.air, 0, 2);
		world.setBlock(i + 0, j + 3, k + 5, PlacePolishedDeepslate, 0, 2);
		world.setBlock(i + 1, j + 3, k + 5, PlaceDeepslate, 0, 2);
		world.setBlock(i + 2, j + 3, k + 5, PlaceDeepslate, 0, 2);
		world.setBlock(i + 3, j + 3, k + 5, PlaceDeepslate, 0, 2);
		world.setBlock(i + 4, j + 3, k + 5, PlaceDeepslate, 0, 2);
		world.setBlock(i + 5, j + 3, k + 5, Blocks.air, 0, 2);
		world.setBlock(i + 6, j + 3, k + 5, Blocks.air, 0, 2);
		world.setBlock(i + 7, j + 3, k + 5, NovaCraftBlocks.sculk_block, 0, 2);
		world.setBlock(i + 8, j + 3, k + 5, PlaceDeepslate, 0, 2);
		world.setBlock(i + 9, j + 3, k + 5, PlaceDeepslate, 0, 2);
		world.setBlock(i + 10, j + 3, k + 5, NovaCraftBlocks.sculk_block, 0, 2);
		world.setBlock(i + 11, j + 3, k + 5, Blocks.air, 0, 2);
		world.setBlock(i + 12, j + 3, k + 5, NovaCraftBlocks.sculk_block, 0, 2);
		world.setBlock(i + 13, j + 3, k + 5, PlaceCobbledDeepslate, 0, 2);
		world.setBlock(i + 14, j + 3, k + 5, PlaceDeepslate, 0, 2);
		world.setBlock(i + 15, j + 3, k + 5, PlaceDeepslate, 0, 2);
		world.setBlock(i + 16, j + 3, k + 5, PlacePolishedDeepslate, 0, 2);
		world.setBlock(i + 17, j + 3, k + 5, Blocks.air, 0, 2);
		world.setBlock(i + 0, j + 3, k + 6, PlacePolishedDeepslate, 0, 2);
		world.setBlock(i + 1, j + 3, k + 6, PlaceDeepslate, 0, 2);
		world.setBlock(i + 2, j + 3, k + 6, PlaceDeepslate, 0, 2);
		world.setBlock(i + 3, j + 3, k + 6, NovaCraftBlocks.sculk_block, 0, 2);
		world.setBlock(i + 4, j + 3, k + 6, PlaceDeepslate, 0, 2);
		world.setBlock(i + 5, j + 3, k + 6, PlaceCobbledDeepslateStairs, 2, 2);
		world.setBlock(i + 6, j + 3, k + 6, PlaceCobbledDeepslateStairs, 2, 2);
		world.setBlock(i + 7, j + 3, k + 6, NovaCraftBlocks.sculk_block, 0, 2);
		world.setBlock(i + 8, j + 3, k + 6, PlaceDeepslate, 0, 2);
		world.setBlock(i + 9, j + 3, k + 6, NovaCraftBlocks.sculk_vein, 1, 2);
		world.setBlock(i + 10, j + 3, k + 6, NovaCraftBlocks.sculk_block, 0, 2);
		world.setBlock(i + 11, j + 3, k + 6, Blocks.air, 0, 2);
		world.setBlock(i + 12, j + 3, k + 6, NovaCraftBlocks.sculk_block, 0, 2);
		world.setBlock(i + 13, j + 3, k + 6, NovaCraftBlocks.sculk_block, 0, 2);
		world.setBlock(i + 14, j + 3, k + 6, PlaceDeepslate, 0, 2);
		world.setBlock(i + 15, j + 3, k + 6, PlaceDeepslate, 0, 2);
		world.setBlock(i + 16, j + 3, k + 6, PlaceCobbledDeepslate, 0, 2);
		world.setBlock(i + 17, j + 3, k + 6, Blocks.air, 0, 2);
		world.setBlock(i + 0, j + 3, k + 7, PlacePolishedDeepslate, 0, 2);
		world.setBlock(i + 1, j + 3, k + 7, PlaceDeepslate, 0, 2);
		world.setBlock(i + 2, j + 3, k + 7, NovaCraftBlocks.sculk_block, 0, 2);
		world.setBlock(i + 3, j + 3, k + 7, NovaCraftBlocks.sculk_block, 0, 2);
		world.setBlock(i + 4, j + 3, k + 7, NovaCraftBlocks.sculk_block, 0, 2);
		world.setBlock(i + 5, j + 3, k + 7, PlaceDeepslate, 0, 2);
		world.setBlock(i + 6, j + 3, k + 7, NovaCraftBlocks.sculk_vein, 1, 2);
		world.setBlock(i + 7, j + 3, k + 7, NovaCraftBlocks.sculk_block, 0, 2);
		world.setBlock(i + 8, j + 3, k + 7, NovaCraftBlocks.sculk_block, 0, 2);
		world.setBlock(i + 9, j + 3, k + 7, PlaceDeepslate, 0, 2);
		world.setBlock(i + 10, j + 3, k + 7, PlaceDeepslate, 0, 2);
		world.setBlock(i + 11, j + 3, k + 7, NovaCraftBlocks.sculk_block, 0, 2);
		world.setBlock(i + 12, j + 3, k + 7, NovaCraftBlocks.sculk_block, 0, 2);
		world.setBlock(i + 13, j + 3, k + 7, PlaceCobbledDeepslate, 0, 2);
		world.setBlock(i + 14, j + 3, k + 7, PlaceCobbledDeepslate, 0, 2);
		world.setBlock(i + 15, j + 3, k + 7, Blocks.air, 0, 2);
		world.setBlock(i + 16, j + 3, k + 7, Blocks.air, 0, 2);
		world.setBlock(i + 17, j + 3, k + 7, Blocks.air, 0, 2);
		world.setBlock(i + 0, j + 3, k + 8, PlacePolishedDeepslate, 0, 2);
		world.setBlock(i + 1, j + 3, k + 8, PlaceDeepslate, 0, 2);
		world.setBlock(i + 2, j + 3, k + 8, PlaceDeepslate, 0, 2);
		world.setBlock(i + 3, j + 3, k + 8, NovaCraftBlocks.sculk_block, 0, 2);
		world.setBlock(i + 4, j + 3, k + 8, NovaCraftBlocks.sculk_block, 0, 2);
		world.setBlock(i + 5, j + 3, k + 8, NovaCraftBlocks.sculk_block, 0, 2);
		world.setBlock(i + 6, j + 3, k + 8, NovaCraftBlocks.sculk_block, 0, 2);
		world.setBlock(i + 7, j + 3, k + 8, NovaCraftBlocks.sculk_block, 0, 2);
		world.setBlock(i + 8, j + 3, k + 8, NovaCraftBlocks.sculk_block, 0, 2);
		world.setBlock(i + 9, j + 3, k + 8, NovaCraftBlocks.sculk_block, 0, 2);
		world.setBlock(i + 10, j + 3, k + 8, PlaceDeepslate, 0, 2);
		world.setBlock(i + 11, j + 3, k + 8, NovaCraftBlocks.sculk_block, 0, 2);
		world.setBlock(i + 12, j + 3, k + 8, NovaCraftBlocks.sculk_block, 0, 2);
		world.setBlock(i + 13, j + 3, k + 8, PlaceDeepslate, 0, 2);
		world.setBlock(i + 14, j + 3, k + 8, Blocks.air, 0, 2);
		world.setBlock(i + 15, j + 3, k + 8, Blocks.air, 0, 2);
		world.setBlock(i + 16, j + 3, k + 8, Blocks.air, 0, 2);
		world.setBlock(i + 17, j + 3, k + 8, Blocks.air, 0, 2);
		world.setBlock(i + 0, j + 3, k + 9, PlacePolishedDeepslate, 0, 2);
		world.setBlock(i + 1, j + 3, k + 9, Blocks.air, 0, 2);
		world.setBlock(i + 2, j + 3, k + 9, PlaceDeepslate, 0, 2);
		world.setBlock(i + 3, j + 3, k + 9, NovaCraftBlocks.sculk_block, 0, 2);
		world.setBlock(i + 4, j + 3, k + 9, NovaCraftBlocks.sculk_block, 0, 2);
		world.setBlock(i + 5, j + 3, k + 9, NovaCraftBlocks.sculk_block, 0, 2);
		world.setBlock(i + 6, j + 3, k + 9, NovaCraftBlocks.sculk_block, 0, 2);
		world.setBlock(i + 7, j + 3, k + 9, PlaceCobbledDeepslate, 0, 2);
		world.setBlock(i + 8, j + 3, k + 9, NovaCraftBlocks.sculk_block, 0, 2);
		world.setBlock(i + 9, j + 3, k + 9, PlaceDeepslate, 0, 2);
		world.setBlock(i + 10, j + 3, k + 9, PlaceDeepslate, 0, 2);
		world.setBlock(i + 11, j + 3, k + 9, NovaCraftBlocks.sculk_block, 0, 2);
		world.setBlock(i + 12, j + 3, k + 9, PlaceCobbledDeepslate, 0, 2);
		world.setBlock(i + 13, j + 3, k + 9, NovaCraftBlocks.sculk_vein, 5, 2);
		world.setBlock(i + 14, j + 3, k + 9, NovaCraftBlocks.sculk_vein, 2, 2);
		world.setBlock(i + 15, j + 3, k + 9, Blocks.air, 0, 2);
		world.setBlock(i + 16, j + 3, k + 9, Blocks.air, 0, 2);
		world.setBlock(i + 17, j + 3, k + 9, Blocks.air, 0, 2);
		world.setBlock(i + 0, j + 3, k + 10, PlacePolishedDeepslate, 0, 2);
		world.setBlock(i + 1, j + 3, k + 10, PlaceDeepslate, 0, 2);
		world.setBlock(i + 2, j + 3, k + 10, PlaceDeepslate, 0, 2);
		world.setBlock(i + 3, j + 3, k + 10, PlaceDeepslate, 0, 2);
		world.setBlock(i + 4, j + 3, k + 10, NovaCraftBlocks.sculk_block, 0, 2);
		world.setBlock(i + 5, j + 3, k + 10, NovaCraftBlocks.sculk_block, 0, 2);
		world.setBlock(i + 6, j + 3, k + 10, NovaCraftBlocks.sculk_block, 0, 2);
		world.setBlock(i + 7, j + 3, k + 10, NovaCraftBlocks.sculk_block, 0, 2);
		world.setBlock(i + 8, j + 3, k + 10, NovaCraftBlocks.sculk_block, 0, 2);
		world.setBlock(i + 9, j + 3, k + 10, NovaCraftBlocks.sculk_block, 0, 2);
		world.setBlock(i + 10, j + 3, k + 10, PlaceDeepslate, 0, 2);
		world.setBlock(i + 11, j + 3, k + 10, NovaCraftBlocks.sculk_block, 0, 2);
		world.setBlock(i + 12, j + 3, k + 10, NovaCraftBlocks.sculk_block, 0, 2);
		world.setBlock(i + 13, j + 3, k + 10, NovaCraftBlocks.sculk_block, 0, 2);
		world.setBlock(i + 14, j + 3, k + 10, PlaceCobbledDeepslate, 0, 2);
		world.setBlock(i + 15, j + 3, k + 10, Blocks.air, 0, 2);
		world.setBlock(i + 16, j + 3, k + 10, Blocks.air, 0, 2);
		world.setBlock(i + 17, j + 3, k + 10, Blocks.air, 0, 2);
		world.setBlock(i + 0, j + 3, k + 11, PlacePolishedDeepslate, 0, 2);
		world.setBlock(i + 1, j + 3, k + 11, PlaceDeepslate, 0, 2);
		world.setBlock(i + 2, j + 3, k + 11, NovaCraftBlocks.sculk_block, 0, 2);
		world.setBlock(i + 3, j + 3, k + 11, NovaCraftBlocks.sculk_block, 0, 2);
		world.setBlock(i + 4, j + 3, k + 11, NovaCraftBlocks.sculk_block, 0, 2);
		world.setBlock(i + 5, j + 3, k + 11, NovaCraftBlocks.sculk_block, 0, 2);
		world.setBlock(i + 6, j + 3, k + 11, NovaCraftBlocks.sculk_block, 0, 2);
		world.setBlock(i + 7, j + 3, k + 11, NovaCraftBlocks.sculk_block, 0, 2);
		world.setBlock(i + 8, j + 3, k + 11, Blocks.air, 0, 2);
		world.setBlock(i + 9, j + 3, k + 11, NovaCraftBlocks.sculk_block, 0, 2);
		world.setBlock(i + 10, j + 3, k + 11, NovaCraftBlocks.sculk_block, 0, 2);
		world.setBlock(i + 11, j + 3, k + 11, NovaCraftBlocks.sculk_block, 0, 2);
		world.setBlock(i + 12, j + 3, k + 11, PlaceCobbledDeepslate, 0, 2);
		world.setBlock(i + 13, j + 3, k + 11, NovaCraftBlocks.sculk_block, 0, 2);
		world.setBlock(i + 14, j + 3, k + 11, NovaCraftBlocks.sculk_block, 0, 2);
		world.setBlock(i + 15, j + 3, k + 11, PlaceCobbledDeepslate, 0, 2);
		world.setBlock(i + 16, j + 3, k + 11, PlacePolishedDeepslate, 0, 2);
		world.setBlock(i + 17, j + 3, k + 11, Blocks.air, 0, 2);
		world.setBlock(i + 0, j + 3, k + 12, PlacePolishedDeepslate, 0, 2);
		world.setBlock(i + 1, j + 3, k + 12, NovaCraftBlocks.sculk_block, 0, 2);
		world.setBlock(i + 2, j + 3, k + 12, NovaCraftBlocks.sculk_vein, 3, 2);
		world.setBlock(i + 3, j + 3, k + 12, NovaCraftBlocks.sculk_block, 0, 2);
		world.setBlock(i + 4, j + 3, k + 12, NovaCraftBlocks.sculk_block, 0, 2);
		world.setBlock(i + 5, j + 3, k + 12, PlaceCobbledDeepslate, 0, 2);
		world.setBlock(i + 6, j + 3, k + 12, NovaCraftBlocks.sculk_block, 0, 2);
		world.setBlock(i + 7, j + 3, k + 12, NovaCraftBlocks.sculk_block, 0, 2);
		world.setBlock(i + 8, j + 3, k + 12, NovaCraftBlocks.sculk_block, 0, 2);
		world.setBlock(i + 9, j + 3, k + 12, NovaCraftBlocks.sculk_block, 0, 2);
		world.setBlock(i + 10, j + 3, k + 12, NovaCraftBlocks.sculk_block, 0, 2);
		world.setBlock(i + 11, j + 3, k + 12, NovaCraftBlocks.sculk_block, 0, 2);
		world.setBlock(i + 12, j + 3, k + 12, NovaCraftBlocks.sculk_block, 0, 2);
		world.setBlock(i + 13, j + 3, k + 12, PlaceCobbledDeepslate, 0, 2);
		world.setBlock(i + 14, j + 3, k + 12, PlaceCobbledDeepslate, 0, 2);
		world.setBlock(i + 15, j + 3, k + 12, PlaceDeepslate, 0, 2);
		world.setBlock(i + 16, j + 3, k + 12, PlacePolishedDeepslate, 0, 2);
		world.setBlock(i + 17, j + 3, k + 12, Blocks.air, 0, 2);
		world.setBlock(i + 0, j + 3, k + 13, PlacePolishedDeepslate, 0, 2);
		world.setBlock(i + 1, j + 3, k + 13, PlaceDeepslate, 0, 2);
		world.setBlock(i + 2, j + 3, k + 13, NovaCraftBlocks.sculk_block, 0, 2);
		world.setBlock(i + 3, j + 3, k + 13, NovaCraftBlocks.sculk_block, 0, 2);
		world.setBlock(i + 4, j + 3, k + 13, PlaceCobbledDeepslate, 0, 2);
		world.setBlock(i + 5, j + 3, k + 13, NovaCraftBlocks.sculk_block, 0, 2);
		world.setBlock(i + 6, j + 3, k + 13, NovaCraftBlocks.sculk_block, 0, 2);
		world.setBlock(i + 7, j + 3, k + 13, NovaCraftBlocks.sculk_block, 0, 2);
		world.setBlock(i + 8, j + 3, k + 13, NovaCraftBlocks.sculk_block, 0, 2);
		world.setBlock(i + 9, j + 3, k + 13, NovaCraftBlocks.sculk_block, 0, 2);
		world.setBlock(i + 10, j + 3, k + 13, NovaCraftBlocks.sculk_block, 0, 2);
		world.setBlock(i + 11, j + 3, k + 13, NovaCraftBlocks.sculk_block, 0, 2);
		world.setBlock(i + 12, j + 3, k + 13, NovaCraftBlocks.sculk_block, 0, 2);
		world.setBlock(i + 13, j + 3, k + 13, NovaCraftBlocks.sculk_block, 0, 2);
		world.setBlock(i + 14, j + 3, k + 13, NovaCraftBlocks.sculk_block, 0, 2);
		world.setBlock(i + 15, j + 3, k + 13, PlaceDeepslate, 0, 2);
		world.setBlock(i + 16, j + 3, k + 13, PlacePolishedDeepslate, 0, 2);
