package com.NovaCraft.world.ancient_city;

import com.NovaCraft.config.ConfigsCompact;
import cpw.mods.fml.common.Loader;
import cpw.mods.fml.common.registry.GameRegistry;
import net.minecraft.world.gen.feature.*;
import net.minecraft.block.*;
import net.minecraft.world.*;
import java.util.*;

import com.NovaCraft.config.Configs;
import com.NovaCraft.registry.OtherModBlocks;
import com.NovaCraftBlocks.NovaCraftBlocks;

import net.minecraft.init.*;

public class AncientCityCenterPortalGen2 extends WorldGenerator
{
	public AncientCityCenterPortalGen2() {

	}
	//0 -> deepslate bricks
	//1 -> cracked deepslate bricks
	//2 -> deepslate tiles
	//3 -> cracked deepslate bricks
	//4 -> chiseled deepslate bricks
	private Block PlaceDeepslateBricks;
	private Block PlaceDeepslateTiles;
	private Block PlaceCrackedDeepslateTiles;
	private Block PlaceCrackedDeepslateBricks;
	private Block PlaceCobbledDeepslate;

	private Block determineIfCobbledDeepslateExists(World world, int x, int y, int z) {
		Block existingBlock = world.getBlock(x, y, z);
		if (ConfigsCompact.enableDeepslate && Loader.isModLoaded("etfuturum")) {
			try {
				Block cobbled_deepslate = GameRegistry.findBlock("etfuturum", "cobbled_deepslate");
				if (cobbled_deepslate != null && (existingBlock == null || existingBlock != cobbled_deepslate)) {
					return cobbled_deepslate;
				}
			} catch (Exception ex) {
				if (Configs.enableDebugMode) {
					System.out.println("Missing Cobbled Deepslate from Et Futurum Requiem, using Cobbled Grimstone instead...");
				}
				return NovaCraftBlocks.cobbled_grimstone;
			}
		}

		return NovaCraftBlocks.cobbled_grimstone;
	}

	private Block determineIfDeepslateBricksExists(World world, int x, int y, int z) {
		Block existingBlock = world.getBlock(x, y, z);
		if (ConfigsCompact.enableDeepslateBricks && Loader.isModLoaded("etfuturum")) {
			try {
				Block deepslate_bricks = GameRegistry.findBlock("etfuturum", "deepslate_bricks");
				if (deepslate_bricks != null && (existingBlock == null || existingBlock != deepslate_bricks)) {
					return deepslate_bricks;
				}
			} catch (Exception ex) {
				if (Configs.enableDebugMode) {
					System.out.println("Missing Deepslate Bricks from Et Futurum Requiem, using Grimstone Bricks instead...");
				}
				return NovaCraftBlocks.grimstone_bricks;
			}
		}

		return NovaCraftBlocks.grimstone_bricks;
	}

	private Block determineIfCrackedDeepslateBricksExists(World world, int x, int y, int z) {
		Block existingBlock = world.getBlock(x, y, z);
		if (ConfigsCompact.enableDeepslateBricks && Loader.isModLoaded("etfuturum")) {
			try {
				Block deepslate_bricks = GameRegistry.findBlock("etfuturum", "deepslate_bricks");
				if (deepslate_bricks != null && (existingBlock == null || existingBlock != deepslate_bricks)) {
					return deepslate_bricks;
				}
			} catch (Exception ex) {
				if (Configs.enableDebugMode) {
					System.out.println("Missing Cracked Deepslate Bricks from Et Futurum Requiem, using Cracked Grimstone Bricks instead...");
				}
				return NovaCraftBlocks.cracked_grimstone_bricks;
			}
		}

		return NovaCraftBlocks.cracked_grimstone_bricks;
	}

	private Block determineIfDeepslateTilesExist(World world, int x, int y, int z) {
		Block existingBlock = world.getBlock(x, y, z);
		if (ConfigsCompact.enableDeepslateBricks && Loader.isModLoaded("etfuturum")) {
			try {
				Block deepslate_bricks = GameRegistry.findBlock("etfuturum", "deepslate_bricks");
				if (deepslate_bricks != null && (existingBlock == null || existingBlock != deepslate_bricks)) {
					return deepslate_bricks;
				}
			} catch (Exception ex) {
				if (Configs.enableDebugMode) {
					System.out.println("Missing Deepslate Tiles from Et Futurum Requiem, using Grimstone Tiles instead...");
				}
				return NovaCraftBlocks.grimstone_tiles;
			}
		}

		return NovaCraftBlocks.grimstone_tiles;
	}

	private Block determineIfCrackedDeepslateTilesExist(World world, int x, int y, int z) {
		Block existingBlock = world.getBlock(x, y, z);
		if (ConfigsCompact.enableDeepslateBricks && Loader.isModLoaded("etfuturum")) {
			try {
				Block deepslate_bricks = GameRegistry.findBlock("etfuturum", "deepslate_bricks");
				if (deepslate_bricks != null && (existingBlock == null || existingBlock != deepslate_bricks)) {
					return deepslate_bricks;
				}
			} catch (Exception ex) {
				if (Configs.enableDebugMode) {
					System.out.println("Missing Cracked Deepslate Tiles from Et Futurum Requiem, using Cracked Grimstone Tiles instead...");
				}
				return NovaCraftBlocks.cracked_grimstone_tiles;
			}
		}

		return NovaCraftBlocks.cracked_grimstone_tiles;
	}

	public boolean generate(final World world, final Random random, final int i, final int j, final int k) {		
		PlaceDeepslateBricks = determineIfDeepslateBricksExists(world, i + 16, j + 16, k + 18);
		PlaceCrackedDeepslateBricks = determineIfCrackedDeepslateBricksExists(world, i + 17, j + 16, k + 18);		
		PlaceDeepslateTiles = determineIfDeepslateTilesExist(world, i + 16, j + 16, k + 22);
		PlaceCrackedDeepslateTiles = determineIfCrackedDeepslateTilesExist(world, i + 20, j + 16, k + 22);
		PlaceCobbledDeepslate = determineIfCobbledDeepslateExists(world, i + 18, j + 16, k + 41);
		
		world.setBlock(i + 16, j + 16, k + 18, PlaceDeepslateBricks, 0, 2);
		world.setBlock(i + 17, j + 16, k + 18, PlaceCrackedDeepslateBricks, 1, 2);
		world.setBlock(i + 18, j + 16, k + 18, PlaceDeepslateBricks, 0, 2);
		world.setBlock(i + 19, j + 16, k + 18, PlaceDeepslateBricks, 0, 2);
		world.setBlock(i + 16, j + 16, k + 19, PlaceCrackedDeepslateBricks, 1, 2);
		world.setBlock(i + 17, j + 16, k + 19, PlaceCrackedDeepslateBricks, 1, 2);
		world.setBlock(i + 18, j + 16, k + 19, PlaceDeepslateBricks, 0, 2);
		world.setBlock(i + 19, j + 16, k + 19, PlaceDeepslateBricks, 0, 2);
		world.setBlock(i + 20, j + 16, k + 19, PlaceDeepslateBricks, 0, 2);
		world.setBlock(i + 16, j + 16, k + 20, PlaceDeepslateBricks, 0, 2);
		world.setBlock(i + 17, j + 16, k + 20, PlaceDeepslateBricks, 0, 2);
		world.setBlock(i + 18, j + 16, k + 20, PlaceDeepslateBricks, 0, 2);
		world.setBlock(i + 19, j + 16, k + 20, PlaceDeepslateBricks, 0, 2);
		world.setBlock(i + 20, j + 16, k + 20, PlaceDeepslateBricks, 0, 2);
		world.setBlock(i + 16, j + 16, k + 21, PlaceCrackedDeepslateBricks, 1, 2);
		world.setBlock(i + 17, j + 16, k + 21, PlaceCrackedDeepslateBricks, 1, 2);
		world.setBlock(i + 18, j + 16, k + 21, PlaceCrackedDeepslateBricks, 1, 2);
		world.setBlock(i + 19, j + 16, k + 21, PlaceDeepslateBricks, 0, 2);
		world.setBlock(i + 20, j + 16, k + 21, PlaceDeepslateBricks, 0, 2);
		world.setBlock(i + 16, j + 16, k + 22, PlaceDeepslateTiles, 2, 2);
		world.setBlock(i + 17, j + 16, k + 22, PlaceDeepslateTiles, 2, 2);
		world.setBlock(i + 18, j + 16, k + 22, PlaceDeepslateTiles, 2, 2);
		world.setBlock(i + 19, j + 16, k + 22, PlaceDeepslateTiles, 2, 2);
		world.setBlock(i + 20, j + 16, k + 22, PlaceCrackedDeepslateTiles, 3, 2);
		world.setBlock(i + 16, j + 16, k + 23, PlaceDeepslateTiles, 2, 2);
		world.setBlock(i + 17, j + 16, k + 23, PlaceDeepslateTiles, 2, 2);
		world.setBlock(i + 18, j + 16, k + 23, PlaceCrackedDeepslateTiles, 3, 2);
		world.setBlock(i + 19, j + 16, k + 23, PlaceCrackedDeepslateTiles, 3, 2);
		world.setBlock(i + 20, j + 16, k + 23, PlaceCrackedDeepslateTiles, 3, 2);
		world.setBlock(i + 17, j + 16, k + 24, PlaceCrackedDeepslateTiles, 3, 2);
		world.setBlock(i + 18, j + 16, k + 24, PlaceCrackedDeepslateTiles, 3, 2);
		world.setBlock(i + 19, j + 16, k + 24, PlaceDeepslateTiles, 2, 2);
		world.setBlock(i + 16, j + 16, k + 25, PlaceDeepslateTiles, 2, 2);
		world.setBlock(i + 17, j + 16, k + 25, PlaceDeepslateTiles, 2, 2);
		world.setBlock(i + 18, j + 16, k + 25, PlaceCrackedDeepslateTiles, 3, 2);
		world.setBlock(i + 19, j + 16, k + 25, PlaceDeepslateTiles, 2, 2);
		world.setBlock(i + 20, j + 16, k + 25, PlaceDeepslateTiles, 2, 2);
		world.setBlock(i + 16, j + 16, k + 26, PlaceCrackedDeepslateTiles, 3, 2);
		world.setBlock(i + 17, j + 16, k + 26, PlaceCrackedDeepslateTiles, 3, 2);
		world.setBlock(i + 18, j + 16, k + 26, PlaceCrackedDeepslateTiles, 3, 2);
		world.setBlock(i + 19, j + 16, k + 26, PlaceDeepslateTiles, 2, 2);
		world.setBlock(i + 20, j + 16, k + 26, PlaceDeepslateTiles, 2, 2);
		world.setBlock(i + 17, j + 16, k + 27, PlaceDeepslateTiles, 2, 2);
		world.setBlock(i + 18, j + 16, k + 27, PlaceCrackedDeepslateTiles, 3, 2);
		world.setBlock(i + 19, j + 16, k + 27, PlaceDeepslateTiles, 2, 2);
		world.setBlock(i + 17, j + 16, k + 28, PlaceCrackedDeepslateTiles, 3, 2);
		world.setBlock(i + 18, j + 16, k + 28, PlaceDeepslateTiles, 2, 2);
		world.setBlock(i + 19, j + 16, k + 28, PlaceDeepslateTiles, 2, 2);
		world.setBlock(i + 16, j + 16, k + 29, PlaceCrackedDeepslateTiles, 3, 2);
		world.setBlock(i + 17, j + 16, k + 29, PlaceCrackedDeepslateTiles, 3, 2);
		world.setBlock(i + 18, j + 16, k + 29, PlaceDeepslateTiles, 2, 2);
		world.setBlock(i + 19, j + 16, k + 29, PlaceDeepslateTiles, 2, 2);
		world.setBlock(i + 20, j + 16, k + 29, PlaceCrackedDeepslateTiles, 3, 2);
		world.setBlock(i + 16, j + 16, k + 30, PlaceDeepslateTiles, 2, 2);
		world.setBlock(i + 17, j + 16, k + 30, PlaceDeepslateTiles, 2, 2);
		world.setBlock(i + 18, j + 16, k + 30, PlaceDeepslateTiles, 2, 2);
		world.setBlock(i + 19, j + 16, k + 30, PlaceDeepslateTiles, 2, 2);
		world.setBlock(i + 20, j + 16, k + 30, PlaceDeepslateTiles, 2, 2);
		world.setBlock(i + 17, j + 16, k + 31, PlaceCrackedDeepslateTiles, 3, 2);
		world.setBlock(i + 18, j + 16, k + 31, PlaceDeepslateTiles, 2, 2);
		world.setBlock(i + 19, j + 16, k + 31, PlaceDeepslateTiles, 2, 2);
		world.setBlock(i + 17, j + 16, k + 32, PlaceCrackedDeepslateTiles, 3, 2);
		world.setBlock(i + 18, j + 16, k + 32, PlaceDeepslateTiles, 2, 2);
		world.setBlock(i + 19, j + 16, k + 32, PlaceCrackedDeepslateTiles, 3, 2);
		world.setBlock(i + 16, j + 16, k + 33, PlaceDeepslateTiles, 2, 2);
		world.setBlock(i + 17, j + 16, k + 33, PlaceCrackedDeepslateTiles, 3, 2);
		world.setBlock(i + 18, j + 16, k + 33, PlaceDeepslateTiles, 2, 2);
		world.setBlock(i + 19, j + 16, k + 33, PlaceDeepslateTiles, 2, 2);
		world.setBlock(i + 20, j + 16, k + 33, PlaceDeepslateTiles, 2, 2);
		world.setBlock(i + 16, j + 16, k + 34, PlaceDeepslateTiles, 2, 2);
		world.setBlock(i + 17, j + 16, k + 34, PlaceDeepslateTiles, 2, 2);
		world.setBlock(i + 18, j + 16, k + 34, PlaceDeepslateTiles, 2, 2);
		world.setBlock(i + 19, j + 16, k + 34, PlaceCrackedDeepslateTiles, 3, 2);
		world.setBlock(i + 20, j + 16, k + 34, PlaceDeepslateTiles, 2, 2);
		world.setBlock(i + 17, j + 16, k + 35, PlaceDeepslateTiles, 2, 2);
		world.setBlock(i + 18, j + 16, k + 35, PlaceCrackedDeepslateTiles, 3, 2);
		world.setBlock(i + 19, j + 16, k + 35, PlaceDeepslateTiles, 2, 2);
		world.setBlock(i + 17, j + 16, k + 36, PlaceCrackedDeepslateTiles, 3, 2);
		world.setBlock(i + 18, j + 16, k + 36, PlaceDeepslateTiles, 2, 2);
		world.setBlock(i + 19, j + 16, k + 36, PlaceCrackedDeepslateTiles, 3, 2);
		world.setBlock(i + 16, j + 16, k + 37, PlaceCrackedDeepslateTiles, 3, 2);
		world.setBlock(i + 17, j + 16, k + 37, PlaceDeepslateTiles, 2, 2);
		world.setBlock(i + 18, j + 16, k + 37, PlaceDeepslateTiles, 2, 2);
		world.setBlock(i + 19, j + 16, k + 37, PlaceDeepslateTiles, 2, 2);
		world.setBlock(i + 20, j + 16, k + 37, PlaceDeepslateTiles, 2, 2);
		world.setBlock(i + 16, j + 16, k + 38, PlaceDeepslateTiles, 2, 2);
		world.setBlock(i + 17, j + 16, k + 38, PlaceDeepslateTiles, 2, 2);
		world.setBlock(i + 18, j + 16, k + 38, PlaceDeepslateTiles, 2, 2);
		world.setBlock(i + 19, j + 16, k + 38, PlaceDeepslateTiles, 2, 2);
		world.setBlock(i + 20, j + 16, k + 38, PlaceDeepslateTiles, 2, 2);
		world.setBlock(i + 17, j + 16, k + 39, PlaceDeepslateTiles, 2, 2);
		world.setBlock(i + 18, j + 16, k + 39, PlaceCrackedDeepslateTiles, 3, 2);
		world.setBlock(i + 17, j + 16, k + 40, PlaceDeepslateTiles, 2, 2);
		world.setBlock(i + 18, j + 16, k + 40, PlaceDeepslateTiles, 2, 2);
		world.setBlock(i + 19, j + 16, k + 40, PlaceCrackedDeepslateTiles, 3, 2);
		world.setBlock(i + 16, j + 16, k + 41, PlaceDeepslateTiles, 2, 2);
		world.setBlock(i + 17, j + 16, k + 41, PlaceCrackedDeepslateTiles, 3, 2);
		world.setBlock(i + 18, j + 16, k + 41, PlaceCobbledDeepslate, 0, 2);
		world.setBlock(i + 19, j + 16, k + 41, PlaceCobbledDeepslate, 0, 2);
		world.setBlock(i + 20, j + 16, k + 41, PlaceDeepslateTiles, 2, 2);
		world.setBlock(i + 16, j + 16, k + 42, PlaceCrackedDeepslateTiles, 3, 2);
		world.setBlock(i + 17, j + 16, k + 42, PlaceCobbledDeepslate, 0, 2);
		world.setBlock(i + 18, j + 16, k + 42, PlaceCobbledDeepslate, 0, 2);
		world.setBlock(i + 19, j + 16, k + 42, PlaceCobbledDeepslate, 0, 2);
		world.setBlock(i + 20, j + 16, k + 42, PlaceDeepslateTiles, 2, 2);
		world.setBlock(i + 17, j + 16, k + 43, PlaceCobbledDeepslate, 0, 2);
		world.setBlock(i + 18, j + 16, k + 43, PlaceDeepslateTiles, 2, 2);
		world.setBlock(i + 19, j + 16, k + 43, PlaceCobbledDeepslate, 0, 2);
		world.setBlock(i + 16, j + 16, k + 44, PlaceDeepslateTiles, 2, 2);
		world.setBlock(i + 17, j + 16, k + 44, PlaceCobbledDeepslate, 0, 2);
		world.setBlock(i + 18, j + 16, k + 44, PlaceCobbledDeepslate, 0, 2);
		world.setBlock(i + 19, j + 16, k + 44, PlaceCobbledDeepslate, 0, 2);
		world.setBlock(i + 20, j + 16, k + 44, PlaceCrackedDeepslateTiles, 3, 2);
		world.setBlock(i + 16, j + 16, k + 45, PlaceCrackedDeepslateTiles, 3, 2);
		world.setBlock(i + 17, j + 16, k + 45, PlaceCobbledDeepslate, 0, 2);
		world.setBlock(i + 18, j + 16, k + 45, PlaceCobbledDeepslate, 0, 2);
		world.setBlock(i + 19, j + 16, k + 45, PlaceCobbledDeepslate, 0, 2);
		world.setBlock(i + 20, j + 16, k + 45, PlaceCrackedDeepslateTiles, 3, 2);
		world.setBlock(i + 17, j + 16, k + 46, PlaceCobbledDeepslate, 0, 2);
		world.setBlock(i + 18, j + 16, k + 46, PlaceCobbledDeepslate, 0, 2);
		world.setBlock(i + 19, j + 16, k + 46, PlaceCobbledDeepslate, 0, 2);
		world.setBlock(i + 16, j + 16, k + 47, PlaceCobbledDeepslate, 0, 2);
		world.setBlock(i + 17, j + 16, k + 47, PlaceCobbledDeepslate, 0, 2);
		world.setBlock(i + 18, j + 16, k + 47, PlaceDeepslateBricks, 0, 2);
		world.setBlock(i + 19, j + 16, k + 47, PlaceCrackedDeepslateBricks, 1, 2);
		world.setBlock(i + 20, j + 16, k + 47, PlaceCrackedDeepslateBricks, 1, 2);
		world.setBlock(i + 16, j + 16, k + 48, PlaceCrackedDeepslateBricks, 1, 2);
		world.setBlock(i + 17, j + 16, k + 48, PlaceDeepslateBricks, 0, 2);
		world.setBlock(i + 18, j + 16, k + 48, PlaceDeepslateBricks, 0, 2);
		world.setBlock(i + 19, j + 16, k + 48, PlaceDeepslateBricks, 0, 2);
		world.setBlock(i + 20, j + 16, k + 48, PlaceDeepslateBricks, 0, 2);
		world.setBlock(i + 18, j + 16, k + 49, PlaceDeepslateBricks, 0, 2);
		world.setBlock(i + 19, j + 16, k + 49, PlaceCrackedDeepslateBricks, 1, 2);
		world.setBlock(i + 20, j + 16, k + 49, PlaceCrackedDeepslateBricks, 1, 2);
		world.setBlock(i + 16, j + 17, k + 18, PlaceDeepslateBricks, 0, 2);
		world.setBlock(i + 17, j + 17, k + 18, PlaceCrackedDeepslateBricks, 1, 2);
		world.setBlock(i + 18, j + 17, k + 18, PlaceDeepslateBricks, 0, 2);
		world.setBlock(i + 19, j + 17, k + 18, PlaceCrackedDeepslateBricks, 1, 2);
		world.setBlock(i + 16, j + 17, k + 19, PlaceDeepslateBricks, 0, 2);
		world.setBlock(i + 17, j + 17, k + 19, PlaceDeepslateBricks, 0, 2);
		world.setBlock(i + 18, j + 17, k + 19, PlaceCrackedDeepslateBricks, 1, 2);
		world.setBlock(i + 19, j + 17, k + 19, PlaceDeepslateBricks, 0, 2);
		world.setBlock(i + 20, j + 17, k + 19, PlaceDeepslateBricks, 0, 2);
		world.setBlock(i + 16, j + 17, k + 20, PlaceCrackedDeepslateBricks, 1, 2);
		world.setBlock(i + 17, j + 17, k + 20, PlaceCrackedDeepslateBricks, 1, 2);
		world.setBlock(i + 18, j + 17, k + 20, PlaceDeepslateBricks, 0, 2);
		world.setBlock(i + 19, j + 17, k + 20, PlaceDeepslateBricks, 0, 2);
		world.setBlock(i + 20, j + 17, k + 20, PlaceDeepslateBricks, 0, 2);
		world.setBlock(i + 16, j + 17, k + 21, PlaceDeepslateBricks, 0, 2);
		world.setBlock(i + 17, j + 17, k + 21, PlaceDeepslateBricks, 0, 2);
		world.setBlock(i + 18, j + 17, k + 21, PlaceDeepslateBricks, 0, 2);
		world.setBlock(i + 19, j + 17, k + 21, PlaceCrackedDeepslateBricks, 1, 2);
		world.setBlock(i + 20, j + 17, k + 21, PlaceCrackedDeepslateBricks, 1, 2);
		world.setBlock(i + 16, j + 17, k + 22, PlaceCrackedDeepslateTiles, 3, 2);
		world.setBlock(i + 17, j + 17, k + 22, PlaceDeepslateTiles, 2, 2);
		world.setBlock(i + 18, j + 17, k + 22, PlaceDeepslateTiles, 2, 2);
		world.setBlock(i + 19, j + 17, k + 22, PlaceDeepslateTiles, 2, 2);
		world.setBlock(i + 20, j + 17, k + 22, PlaceDeepslateTiles, 2, 2);
		world.setBlock(i + 16, j + 17, k + 23, PlaceCrackedDeepslateTiles, 3, 2);
		world.setBlock(i + 18, j + 17, k + 23, NovaCraftBlocks.reinforced_nullstone, 0, 2);
		world.setBlock(i + 20, j + 17, k + 23, PlaceDeepslateTiles, 2, 2);
		world.setBlock(i + 18, j + 17, k + 24, NovaCraftBlocks.reinforced_nullstone, 0, 2);
		world.setBlock(i + 18, j + 17, k + 25, NovaCraftBlocks.reinforced_nullstone, 0, 2);
		world.setBlock(i + 18, j + 17, k + 26, NovaCraftBlocks.reinforced_nullstone, 0, 2);
		world.setBlock(i + 18, j + 17, k + 27, NovaCraftBlocks.reinforced_nullstone, 0, 2);
		world.setBlock(i + 18, j + 17, k + 28, NovaCraftBlocks.reinforced_nullstone, 0, 2);
		world.setBlock(i + 18, j + 17, k + 29, NovaCraftBlocks.reinforced_nullstone, 0, 2);
		world.setBlock(i + 18, j + 17, k + 30, NovaCraftBlocks.reinforced_nullstone, 0, 2);
		world.setBlock(i + 18, j + 17, k + 31, NovaCraftBlocks.activated_reinforced_nullstone, 0, 2);
		world.setBlock(i + 18, j + 17, k + 32, NovaCraftBlocks.reinforced_nullstone, 0, 2);
		world.setBlock(i + 18, j + 17, k + 33, NovaCraftBlocks.reinforced_nullstone, 0, 2);
		world.setBlock(i + 18, j + 17, k + 34, NovaCraftBlocks.reinforced_nullstone, 0, 2);
		world.setBlock(i + 18, j + 17, k + 35, NovaCraftBlocks.activated_reinforced_nullstone, 0, 2);
		world.setBlock(i + 18, j + 17, k + 36, NovaCraftBlocks.reinforced_nullstone, 0, 2);
		world.setBlock(i + 18, j + 17, k + 37, NovaCraftBlocks.reinforced_nullstone, 0, 2);
		world.setBlock(i + 18, j + 17, k + 38, NovaCraftBlocks.activated_reinforced_nullstone, 0, 2);
		world.setBlock(i + 18, j + 17, k + 39, NovaCraftBlocks.reinforced_nullstone, 0, 2);
		world.setBlock(i + 18, j + 17, k + 40, NovaCraftBlocks.reinforced_nullstone, 0, 2);
		world.setBlock(i + 18, j + 17, k + 41, NovaCraftBlocks.reinforced_nullstone, 0, 2);
		world.setBlock(i + 18, j + 17, k + 42, NovaCraftBlocks.reinforced_nullstone, 0, 2);
		world.setBlock(i + 18, j + 17, k + 43, NovaCraftBlocks.reinforced_nullstone, 0, 2);
		world.setBlock(i + 16, j + 17, k + 44, PlaceCrackedDeepslateTiles, 3, 2);
		world.setBlock(i + 18, j + 17, k + 44, NovaCraftBlocks.reinforced_nullstone, 0, 2);
		world.setBlock(i + 20, j + 17, k + 44, PlaceCrackedDeepslateTiles, 3, 2);
		world.setBlock(i + 16, j + 17, k + 45, PlaceCrackedDeepslateTiles, 3, 2);
		world.setBlock(i + 17, j + 17, k + 45, PlaceCrackedDeepslateTiles, 3, 2);
		world.setBlock(i + 18, j + 17, k + 45, PlaceDeepslateTiles, 2, 2);
		world.setBlock(i + 19, j + 17, k + 45, PlaceDeepslateTiles, 2, 2);
		world.setBlock(i + 20, j + 17, k + 45, PlaceDeepslateTiles, 2, 2);
		world.setBlock(i + 16, j + 17, k + 46, PlaceDeepslateBricks, 0, 2);
		world.setBlock(i + 17, j + 17, k + 46, PlaceDeepslateTiles, 2, 2);
		world.setBlock(i + 18, j + 17, k + 46, PlaceCrackedDeepslateTiles, 3, 2);
		world.setBlock(i + 19, j + 17, k + 46, PlaceCrackedDeepslateTiles, 3, 2);
		world.setBlock(i + 20, j + 17, k + 46, PlaceDeepslateBricks, 0, 2);
		world.setBlock(i + 16, j + 17, k + 47, PlaceCrackedDeepslateBricks, 1, 2);
		world.setBlock(i + 17, j + 17, k + 47, PlaceDeepslateBricks, 0, 2);
		world.setBlock(i + 18, j + 17, k + 47, PlaceDeepslateBricks, 0, 2);
		world.setBlock(i + 19, j + 17, k + 47, PlaceDeepslateBricks, 0, 2);
		world.setBlock(i + 20, j + 17, k + 47, PlaceDeepslateBricks, 0, 2);
		world.setBlock(i + 16, j + 17, k + 48, PlaceDeepslateBricks, 0, 2);
		world.setBlock(i + 17, j + 17, k + 48, PlaceDeepslateBricks, 0, 2);
		world.setBlock(i + 18, j + 17, k + 48, PlaceCrackedDeepslateBricks, 1, 2);
		world.setBlock(i + 19, j + 17, k + 48, PlaceCrackedDeepslateBricks, 1, 2);
		world.setBlock(i + 20, j + 17, k + 48, PlaceDeepslateBricks, 0, 2);
		world.setBlock(i + 16, j + 17, k + 49, PlaceCrackedDeepslateBricks, 1, 2);
		world.setBlock(i + 17, j + 17, k + 49, PlaceCrackedDeepslateBricks, 1, 2);
		world.setBlock(i + 18, j + 17, k + 49, PlaceCrackedDeepslateBricks, 1, 2);
		world.setBlock(i + 19, j + 17, k + 49, PlaceCrackedDeepslateBricks, 1, 2);
		world.setBlock(i + 20, j + 17, k + 49, PlaceCrackedDeepslateBricks, 1, 2);
		world.setBlock(i + 16, j + 18, k + 18, PlaceCrackedDeepslateBricks, 1, 2);
		world.setBlock(i + 17, j + 18, k + 18, PlaceDeepslateBricks, 0, 2);
		world.setBlock(i + 18, j + 18, k + 18, PlaceDeepslateBricks, 0, 2);
		world.setBlock(i + 19, j + 18, k + 18, PlaceCrackedDeepslateBricks, 1, 2);
		world.setBlock(i + 20, j + 18, k + 18, PlaceDeepslateBricks, 0, 2);
		world.setBlock(i + 16, j + 18, k + 19, PlaceCrackedDeepslateBricks, 1, 2);
		world.setBlock(i + 17, j + 18, k + 19, PlaceCrackedDeepslateBricks, 1, 2);
		world.setBlock(i + 18, j + 18, k + 19, PlaceCrackedDeepslateBricks, 1, 2);
		world.setBlock(i + 19, j + 18, k + 19, PlaceDeepslateBricks, 0, 2);
		world.setBlock(i + 20, j + 18, k + 19, PlaceDeepslateBricks, 0, 2);
		world.setBlock(i + 16, j + 18, k + 20, PlaceDeepslateBricks, 0, 2);
		world.setBlock(i + 17, j + 18, k + 20, PlaceCrackedDeepslateBricks, 1, 2);
		world.setBlock(i + 18, j + 18, k + 20, PlaceDeepslateBricks, 0, 2);
		world.setBlock(i + 19, j + 18, k + 20, PlaceDeepslateBricks, 0, 2);
		world.setBlock(i + 20, j + 18, k + 20, PlaceCrackedDeepslateBricks, 1, 2);
		world.setBlock(i + 16, j + 18, k + 21, PlaceDeepslateBricks, 0, 2);
		world.setBlock(i + 17, j + 18, k + 21, PlaceDeepslateBricks, 0, 2);
		world.setBlock(i + 18, j + 18, k + 21, PlaceDeepslateBricks, 0, 2);
		world.setBlock(i + 19, j + 18, k + 21, PlaceDeepslateBricks, 0, 2);
		world.setBlock(i + 20, j + 18, k + 21, PlaceDeepslateBricks, 0, 2);
		world.setBlock(i + 16, j + 18, k + 22, PlaceDeepslateTiles, 2, 2);
		world.setBlock(i + 17, j + 18, k + 22, PlaceDeepslateTiles, 2, 2);
		world.setBlock(i + 18, j + 18, k + 22, PlaceCrackedDeepslateTiles, 3, 2);
		world.setBlock(i + 19, j + 18, k + 22, PlaceDeepslateTiles, 2, 2);
		world.setBlock(i + 20, j + 18, k + 22, PlaceDeepslateTiles, 2, 2);
		world.setBlock(i + 18, j + 18, k + 23, NovaCraftBlocks.reinforced_nullstone, 0, 2);
		world.setBlock(i + 18, j + 18, k + 44, NovaCraftBlocks.activated_reinforced_nullstone, 0, 2);
		world.setBlock(i + 16, j + 18, k + 45, PlaceDeepslateTiles, 2, 2);
		world.setBlock(i + 17, j + 18, k + 45, PlaceDeepslateTiles, 2, 2);
		world.setBlock(i + 18, j + 18, k + 45, PlaceDeepslateTiles, 2, 2);
		world.setBlock(i + 19, j + 18, k + 45, PlaceDeepslateTiles, 2, 2);
		world.setBlock(i + 20, j + 18, k + 45, PlaceDeepslateTiles, 2, 2);
		world.setBlock(i + 16, j + 18, k + 46, PlaceDeepslateBricks, 0, 2);
		world.setBlock(i + 17, j + 18, k + 46, PlaceDeepslateTiles, 2, 2);
		world.setBlock(i + 18, j + 18, k + 46, PlaceCrackedDeepslateTiles, 3, 2);
		world.setBlock(i + 19, j + 18, k + 46, PlaceCrackedDeepslateTiles, 3, 2);
		world.setBlock(i + 20, j + 18, k + 46, PlaceDeepslateBricks, 0, 2);
		world.setBlock(i + 16, j + 18, k + 47, PlaceDeepslateBricks, 0, 2);
		world.setBlock(i + 17, j + 18, k + 47, PlaceDeepslateBricks, 0, 2);
		world.setBlock(i + 18, j + 18, k + 47, PlaceCrackedDeepslateBricks, 1, 2);
		world.setBlock(i + 19, j + 18, k + 47, PlaceDeepslateBricks, 0, 2);
		world.setBlock(i + 20, j + 18, k + 47, PlaceCrackedDeepslateBricks, 1, 2);
		world.setBlock(i + 16, j + 18, k + 48, PlaceDeepslateBricks, 0, 2);
		world.setBlock(i + 17, j + 18, k + 48, PlaceDeepslateBricks, 0, 2);
		world.setBlock(i + 18, j + 18, k + 48, PlaceDeepslateBricks, 0, 2);
		world.setBlock(i + 19, j + 18, k + 48, PlaceCrackedDeepslateBricks, 1, 2);
		world.setBlock(i + 20, j + 18, k + 48, PlaceCrackedDeepslateBricks, 1, 2);
		world.setBlock(i + 16, j + 18, k + 49, PlaceDeepslateBricks, 0, 2);
		world.setBlock(i + 17, j + 18, k + 49, PlaceDeepslateBricks, 0, 2);
		world.setBlock(i + 18, j + 18, k + 49, PlaceDeepslateBricks, 0, 2);
		world.setBlock(i + 19, j + 18, k + 49, PlaceCobbledDeepslate, 0, 2);
		world.setBlock(i + 20, j + 18, k + 49, PlaceCobbledDeepslate, 0, 2);
		world.setBlock(i + 16, j + 19, k + 18, PlaceDeepslateBricks, 0, 2);
		world.setBlock(i + 17, j + 19, k + 18, PlaceDeepslateBricks, 0, 2);
		world.setBlock(i + 18, j + 19, k + 18, PlaceCobbledDeepslate, 0, 2);
		world.setBlock(i + 19, j + 19, k + 18, PlaceCobbledDeepslate, 0, 2);
		world.setBlock(i + 20, j + 19, k + 18, PlaceCobbledDeepslate, 0, 2);
		world.setBlock(i + 16, j + 19, k + 19, PlaceDeepslateBricks, 0, 2);
		world.setBlock(i + 17, j + 19, k + 19, PlaceDeepslateBricks, 0, 2);
		world.setBlock(i + 18, j + 19, k + 19, PlaceDeepslateBricks, 0, 2);
		world.setBlock(i + 19, j + 19, k + 19, PlaceDeepslateBricks, 0, 2);
		world.setBlock(i + 20, j + 19, k + 19, PlaceDeepslateBricks, 0, 2);
		world.setBlock(i + 16, j + 19, k + 20, PlaceDeepslateBricks, 0, 2);
		world.setBlock(i + 17, j + 19, k + 20, PlaceDeepslateBricks, 0, 2);
		world.setBlock(i + 18, j + 19, k + 20, PlaceDeepslateBricks, 0, 2);
		world.setBlock(i + 19, j + 19, k + 20, PlaceDeepslateBricks, 0, 2);
		world.setBlock(i + 20, j + 19, k + 20, PlaceDeepslateBricks, 0, 2);
		world.setBlock(i + 16, j + 19, k + 21, PlaceDeepslateTiles, 2, 2);
		world.setBlock(i + 17, j + 19, k + 21, PlaceCrackedDeepslateBricks, 1, 2);
		world.setBlock(i + 18, j + 19, k + 21, PlaceDeepslateBricks, 0, 2);
		world.setBlock(i + 19, j + 19, k + 21, PlaceDeepslateBricks, 0, 2);
		world.setBlock(i + 20, j + 19, k + 21, PlaceDeepslateTiles, 2, 2);
		world.setBlock(i + 16, j + 19, k + 22, PlaceCrackedDeepslateTiles, 3, 2);
		world.setBlock(i + 17, j + 19, k + 22, PlaceDeepslateTiles, 2, 2);
		world.setBlock(i + 18, j + 19, k + 22, PlaceDeepslateTiles, 2, 2);
		world.setBlock(i + 19, j + 19, k + 22, PlaceDeepslateTiles, 2, 2);
		world.setBlock(i + 20, j + 19, k + 22, PlaceDeepslateTiles, 2, 2);
		world.setBlock(i + 18, j + 19, k + 23, NovaCraftBlocks.activated_reinforced_nullstone, 0, 2);
		world.setBlock(i + 18, j + 19, k + 44, NovaCraftBlocks.reinforced_nullstone, 0, 2);
		world.setBlock(i + 16, j + 19, k + 45, PlaceDeepslateTiles, 2, 2);
		world.setBlock(i + 17, j + 19, k + 45, PlaceDeepslateTiles, 2, 2);
		world.setBlock(i + 18, j + 19, k + 45, PlaceCrackedDeepslateTiles, 3, 2);
		world.setBlock(i + 19, j + 19, k + 45, PlaceDeepslateTiles, 2, 2);
		world.setBlock(i + 20, j + 19, k + 45, PlaceDeepslateTiles, 2, 2);
		world.setBlock(i + 16, j + 19, k + 46, PlaceDeepslateTiles, 2, 2);
		world.setBlock(i + 17, j + 19, k + 46, PlaceDeepslateTiles, 2, 2);
		world.setBlock(i + 18, j + 19, k + 46, PlaceCrackedDeepslateTiles, 3, 2);
		world.setBlock(i + 19, j + 19, k + 46, PlaceDeepslateTiles, 2, 2);
		world.setBlock(i + 20, j + 19, k + 46, PlaceCrackedDeepslateTiles, 3, 2);
		world.setBlock(i + 16, j + 19, k + 47, PlaceDeepslateBricks, 0, 2);
		world.setBlock(i + 17, j + 19, k + 47, PlaceDeepslateBricks, 0, 2);
		world.setBlock(i + 18, j + 19, k + 47, PlaceCrackedDeepslateBricks, 1, 2);
		world.setBlock(i + 19, j + 19, k + 47, PlaceCrackedDeepslateBricks, 1, 2);
		world.setBlock(i + 20, j + 19, k + 47, PlaceCrackedDeepslateBricks, 1, 2);
		world.setBlock(i + 16, j + 19, k + 48, PlaceDeepslateBricks, 0, 2);
		world.setBlock(i + 17, j + 19, k + 48, PlaceDeepslateBricks, 0, 2);
		world.setBlock(i + 18, j + 19, k + 48, PlaceCobbledDeepslate, 0, 2);
		world.setBlock(i + 19, j + 19, k + 48, PlaceCobbledDeepslate, 0, 2);
		world.setBlock(i + 20, j + 19, k + 48, PlaceCobbledDeepslate, 0, 2);
		world.setBlock(i + 16, j + 19, k + 49, PlaceCobbledDeepslate, 0, 2);
		world.setBlock(i + 17, j + 19, k + 49, PlaceCobbledDeepslate, 0, 2);
		world.setBlock(i + 18, j + 19, k + 49, PlaceCobbledDeepslate, 0, 2);
		world.setBlock(i + 19, j + 19, k + 49, PlaceCobbledDeepslate, 0, 2);
		world.setBlock(i + 20, j + 19, k + 49, PlaceCobbledDeepslate, 0, 2);
		world.setBlock(i + 17, j + 20, k + 15, PlaceCobbledDeepslate, 0, 2);
		world.setBlock(i + 18, j + 20, k + 15, PlaceCobbledDeepslate, 0, 2);
		world.setBlock(i + 19, j + 20, k + 15, PlaceCobbledDeepslate, 0, 2);
		world.setBlock(i + 17, j + 20, k + 16, PlaceCobbledDeepslate, 0, 2);
		world.setBlock(i + 18, j + 20, k + 16, PlaceCobbledDeepslate, 0, 2);
		world.setBlock(i + 19, j + 20, k + 16, PlaceCobbledDeepslate, 0, 2);
		world.setBlock(i + 17, j + 20, k + 17, PlaceCobbledDeepslate, 0, 2);
		world.setBlock(i + 18, j + 20, k + 17, PlaceCobbledDeepslate, 0, 2);
		world.setBlock(i + 19, j + 20, k + 17, PlaceCobbledDeepslate, 0, 2);
		world.setBlock(i + 16, j + 20, k + 18, PlaceCobbledDeepslate, 0, 2);
		world.setBlock(i + 17, j + 20, k + 18, PlaceCobbledDeepslate, 0, 2);
		world.setBlock(i + 18, j + 20, k + 18, PlaceCobbledDeepslate, 0, 2);
		world.setBlock(i + 19, j + 20, k + 18, PlaceCobbledDeepslate, 0, 2);
		world.setBlock(i + 20, j + 20, k + 18, PlaceCobbledDeepslate, 0, 2);
		world.setBlock(i + 16, j + 20, k + 19, PlaceCrackedDeepslateBricks, 1, 2);
		world.setBlock(i + 17, j + 20, k + 19, PlaceDeepslateBricks, 0, 2);
		world.setBlock(i + 18, j + 20, k + 19, PlaceDeepslateBricks, 0, 2);
		world.setBlock(i + 19, j + 20, k + 19, PlaceCobbledDeepslate, 0, 2);
		world.setBlock(i + 20, j + 20, k + 19, PlaceCobbledDeepslate, 0, 2);
		world.setBlock(i + 16, j + 20, k + 20, PlaceCrackedDeepslateBricks, 1, 2);
		world.setBlock(i + 17, j + 20, k + 20, PlaceDeepslateBricks, 0, 2);
		world.setBlock(i + 18, j + 20, k + 20, PlaceDeepslateBricks, 0, 2);
		world.setBlock(i + 19, j + 20, k + 20, PlaceDeepslateBricks, 0, 2);
		world.setBlock(i + 20, j + 20, k + 20, PlaceDeepslateBricks, 0, 2);
		world.setBlock(i + 16, j + 20, k + 21, PlaceDeepslateTiles, 2, 2);
		world.setBlock(i + 17, j + 20, k + 21, PlaceDeepslateBricks, 0, 2);
		world.setBlock(i + 18, j + 20, k + 21, PlaceCrackedDeepslateBricks, 1, 2);
		world.setBlock(i + 19, j + 20, k + 21, PlaceDeepslateBricks, 0, 2);
		world.setBlock(i + 20, j + 20, k + 21, PlaceDeepslateTiles, 2, 2);
		world.setBlock(i + 17, j + 20, k + 22, PlaceDeepslateTiles, 2, 2);
		world.setBlock(i + 18, j + 20, k + 22, PlaceDeepslateTiles, 2, 2);
		world.setBlock(i + 19, j + 20, k + 22, PlaceCrackedDeepslateTiles, 3, 2);
		world.setBlock(i + 18, j + 20, k + 23, NovaCraftBlocks.reinforced_nullstone, 0, 2);
		world.setBlock(i + 18, j + 20, k + 44, NovaCraftBlocks.reinforced_nullstone, 0, 2);
		world.setBlock(i + 17, j + 20, k + 45, PlaceDeepslateTiles, 2, 2);
		world.setBlock(i + 18, j + 20, k + 45, PlaceDeepslateTiles, 2, 2);
		world.setBlock(i + 19, j + 20, k + 45, PlaceCrackedDeepslateTiles, 3, 2);
		world.setBlock(i + 16, j + 20, k + 46, PlaceDeepslateTiles, 2, 2);
		world.setBlock(i + 17, j + 20, k + 46, PlaceDeepslateTiles, 2, 2);
		world.setBlock(i + 18, j + 20, k + 46, PlaceCrackedDeepslateTiles, 3, 2);
		world.setBlock(i + 19, j + 20, k + 46, PlaceCrackedDeepslateTiles, 3, 2);
		world.setBlock(i + 20, j + 20, k + 46, PlaceDeepslateTiles, 2, 2);
		world.setBlock(i + 16, j + 20, k + 47, PlaceDeepslateBricks, 0, 2);
		world.setBlock(i + 17, j + 20, k + 47, PlaceDeepslateBricks, 0, 2);
		world.setBlock(i + 18, j + 20, k + 47, PlaceCrackedDeepslateBricks, 1, 2);
		world.setBlock(i + 19, j + 20, k + 47, PlaceDeepslateBricks, 0, 2);
		world.setBlock(i + 20, j + 20, k + 47, PlaceDeepslateBricks, 0, 2);
		world.setBlock(i + 16, j + 20, k + 48, PlaceCrackedDeepslateBricks, 1, 2);
		world.setBlock(i + 17, j + 20, k + 48, PlaceDeepslateBricks, 0, 2);
		world.setBlock(i + 18, j + 20, k + 48, PlaceCobbledDeepslate, 0, 2);
		world.setBlock(i + 19, j + 20, k + 48, PlaceCobbledDeepslate, 0, 2);
		world.setBlock(i + 20, j + 20, k + 48, PlaceCobbledDeepslate, 0, 2);
		world.setBlock(i + 16, j + 20, k + 49, PlaceCobbledDeepslate, 0, 2);
		world.setBlock(i + 17, j + 20, k + 49, PlaceCobbledDeepslate, 0, 2);
		world.setBlock(i + 18, j + 20, k + 49, PlaceCobbledDeepslate, 0, 2);
		world.setBlock(i + 19, j + 20, k + 49, PlaceCobbledDeepslate, 0, 2);
		world.setBlock(i + 20, j + 20, k + 49, PlaceCobbledDeepslate, 0, 2);
		world.setBlock(i + 17, j + 20, k + 50, PlaceCobbledDeepslate, 0, 2);
		world.setBlock(i + 18, j + 20, k + 50, PlaceCobbledDeepslate, 0, 2);
		world.setBlock(i + 19, j + 20, k + 50, PlaceCobbledDeepslate, 0, 2);
		world.setBlock(i + 17, j + 20, k + 51, PlaceCobbledDeepslate, 0, 2);
		world.setBlock(i + 18, j + 20, k + 51, PlaceCobbledDeepslate, 0, 2);
		world.setBlock(i + 17, j + 20, k + 52, PlaceCobbledDeepslate, 0, 2);
		world.setBlock(i + 18, j + 20, k + 52, PlaceCobbledDeepslate, 0, 2);
		world.setBlock(i + 19, j + 20, k + 52, PlaceCobbledDeepslate, 0, 2);
		world.setBlock(i + 17, j + 20, k + 53, PlaceCobbledDeepslate, 0, 2);
		world.setBlock(i + 18, j + 20, k + 53, PlaceCobbledDeepslate, 0, 2);
		world.setBlock(i + 17, j + 21, k + 14, PlaceCobbledDeepslate, 0, 2);
		world.setBlock(i + 18, j + 21, k + 14, PlaceCobbledDeepslate, 0, 2);
		world.setBlock(i + 19, j + 21, k + 14, PlaceCobbledDeepslate, 0, 2);
		world.setBlock(i + 17, j + 21, k + 15, PlaceCobbledDeepslate, 0, 2);
		world.setBlock(i + 18, j + 21, k + 15, PlaceCobbledDeepslate, 0, 2);
		world.setBlock(i + 19, j + 21, k + 15, PlaceCobbledDeepslate, 0, 2);
		world.setBlock(i + 17, j + 21, k + 16, PlaceCobbledDeepslate, 0, 2);
		world.setBlock(i + 18, j + 21, k + 16, PlaceCobbledDeepslate, 0, 2);
		world.setBlock(i + 19, j + 21, k + 16, PlaceCobbledDeepslate, 0, 2);
		world.setBlock(i + 17, j + 21, k + 17, PlaceCobbledDeepslate, 0, 2);
		world.setBlock(i + 18, j + 21, k + 17, PlaceCobbledDeepslate, 0, 2);
		world.setBlock(i + 19, j + 21, k + 17, PlaceCobbledDeepslate, 0, 2);
		world.setBlock(i + 16, j + 21, k + 18, PlaceCobbledDeepslate, 0, 2);
		world.setBlock(i + 17, j + 21, k + 18, PlaceCobbledDeepslate, 0, 2);
		world.setBlock(i + 18, j + 21, k + 18, PlaceCobbledDeepslate, 0, 2);
		world.setBlock(i + 19, j + 21, k + 18, PlaceCobbledDeepslate, 0, 2);
		world.setBlock(i + 20, j + 21, k + 18, PlaceCobbledDeepslate, 0, 2);
		world.setBlock(i + 16, j + 21, k + 19, PlaceDeepslateBricks, 0, 2);
		world.setBlock(i + 17, j + 21, k + 19, PlaceCrackedDeepslateBricks, 1, 2);
		world.setBlock(i + 18, j + 21, k + 19, PlaceCrackedDeepslateBricks, 1, 2);
		world.setBlock(i + 19, j + 21, k + 19, PlaceCobbledDeepslate, 0, 2);
		world.setBlock(i + 20, j + 21, k + 19, PlaceCobbledDeepslate, 0, 2);
		world.setBlock(i + 16, j + 21, k + 20, PlaceDeepslateBricks, 0, 2);
		world.setBlock(i + 17, j + 21, k + 20, PlaceDeepslateBricks, 0, 2);
		world.setBlock(i + 18, j + 21, k + 20, PlaceDeepslateBricks, 0, 2);
		world.setBlock(i + 19, j + 21, k + 20, PlaceCrackedDeepslateBricks, 1, 2);
		world.setBlock(i + 20, j + 21, k + 20, PlaceCrackedDeepslateBricks, 1, 2);
		world.setBlock(i + 16, j + 21, k + 21, PlaceCrackedDeepslateTiles, 3, 2);
		world.setBlock(i + 17, j + 21, k + 21, PlaceCrackedDeepslateBricks, 1, 2);
		world.setBlock(i + 18, j + 21, k + 21, PlaceDeepslateBricks, 0, 2);
		world.setBlock(i + 19, j + 21, k + 21, PlaceCrackedDeepslateBricks, 1, 2);
		world.setBlock(i + 20, j + 21, k + 21, PlaceDeepslateTiles, 2, 2);
		world.setBlock(i + 17, j + 21, k + 22, PlaceCrackedDeepslateTiles, 3, 2);
		world.setBlock(i + 18, j + 21, k + 22, PlaceDeepslateTiles, 2, 2);
		world.setBlock(i + 19, j + 21, k + 22, PlaceDeepslateTiles, 2, 2);
		world.setBlock(i + 18, j + 21, k + 23, NovaCraftBlocks.activated_reinforced_nullstone, 0, 2);
		world.setBlock(i + 18, j + 21, k + 44, NovaCraftBlocks.reinforced_nullstone, 0, 2);
		world.setBlock(i + 17, j + 21, k + 45, PlaceDeepslateTiles, 2, 2);
		world.setBlock(i + 18, j + 21, k + 45, PlaceDeepslateTiles, 2, 2);
		world.setBlock(i + 19, j + 21, k + 45, PlaceDeepslateTiles, 2, 2);
		world.setBlock(i + 16, j + 21, k + 46, PlaceCrackedDeepslateTiles, 3, 2);
		world.setBlock(i + 17, j + 21, k + 46, PlaceCrackedDeepslateTiles, 3, 2);
		world.setBlock(i + 18, j + 21, k + 46, PlaceDeepslateTiles, 2, 2);
		world.setBlock(i + 19, j + 21, k + 46, PlaceDeepslateTiles, 2, 2);
		world.setBlock(i + 20, j + 21, k + 46, PlaceDeepslateTiles, 2, 2);
		world.setBlock(i + 16, j + 21, k + 47, PlaceDeepslateBricks, 0, 2);
		world.setBlock(i + 17, j + 21, k + 47, PlaceDeepslateBricks, 0, 2);
		world.setBlock(i + 18, j + 21, k + 47, PlaceDeepslateBricks, 0, 2);
		world.setBlock(i + 19, j + 21, k + 47, PlaceCrackedDeepslateBricks, 1, 2);
		world.setBlock(i + 20, j + 21, k + 47, PlaceCrackedDeepslateBricks, 1, 2);
		world.setBlock(i + 16, j + 21, k + 48, PlaceCrackedDeepslateBricks, 1, 2);
		world.setBlock(i + 17, j + 21, k + 48, PlaceDeepslateBricks, 0, 2);
		world.setBlock(i + 18, j + 21, k + 48, PlaceCobbledDeepslate, 0, 2);
		world.setBlock(i + 19, j + 21, k + 48, PlaceCobbledDeepslate, 0, 2);
		world.setBlock(i + 16, j + 21, k + 49, PlaceCobbledDeepslate, 0, 2);
		world.setBlock(i + 17, j + 21, k + 49, PlaceCobbledDeepslate, 0, 2);
		world.setBlock(i + 18, j + 21, k + 49, PlaceCobbledDeepslate, 0, 2);
		world.setBlock(i + 19, j + 21, k + 49, PlaceCobbledDeepslate, 0, 2);
		world.setBlock(i + 20, j + 21, k + 49, PlaceCobbledDeepslate, 0, 2);
		world.setBlock(i + 17, j + 21, k + 50, PlaceCobbledDeepslate, 0, 2);
		world.setBlock(i + 18, j + 21, k + 50, PlaceCobbledDeepslate, 0, 2);
		world.setBlock(i + 19, j + 21, k + 50, PlaceCobbledDeepslate, 0, 2);
		world.setBlock(i + 17, j + 21, k + 51, PlaceCobbledDeepslate, 0, 2);
		world.setBlock(i + 18, j + 21, k + 51, PlaceCobbledDeepslate, 0, 2);
		world.setBlock(i + 19, j + 21, k + 51, PlaceCobbledDeepslate, 0, 2);
		world.setBlock(i + 17, j + 21, k + 52, PlaceCobbledDeepslate, 0, 2);
		world.setBlock(i + 18, j + 21, k + 52, PlaceCobbledDeepslate, 0, 2);
		world.setBlock(i + 19, j + 21, k + 52, PlaceCobbledDeepslate, 0, 2);
		world.setBlock(i + 17, j + 21, k + 53, PlaceCobbledDeepslate, 0, 2);
		world.setBlock(i + 18, j + 21, k + 53, PlaceCobbledDeepslate, 0, 2);
		world.setBlock(i + 19, j + 21, k + 53, PlaceCobbledDeepslate, 0, 2);
		world.setBlock(i + 17, j + 22, k + 14, PlaceCobbledDeepslate, 0, 2);
		world.setBlock(i + 18, j + 22, k + 14, PlaceCobbledDeepslate, 0, 2);
		world.setBlock(i + 19, j + 22, k + 14, PlaceCobbledDeepslate, 0, 2);
		world.setBlock(i + 17, j + 22, k + 15, PlaceCobbledDeepslate, 0, 2);
		world.setBlock(i + 18, j + 22, k + 15, PlaceCobbledDeepslate, 0, 2);
		world.setBlock(i + 19, j + 22, k + 15, PlaceCobbledDeepslate, 0, 2);
		world.setBlock(i + 16, j + 22, k + 18, PlaceCobbledDeepslate, 0, 2);
		world.setBlock(i + 17, j + 22, k + 18, PlaceCobbledDeepslate, 0, 2);
		world.setBlock(i + 18, j + 22, k + 18, PlaceCobbledDeepslate, 0, 2);
		world.setBlock(i + 19, j + 22, k + 18, PlaceCobbledDeepslate, 0, 2);
		world.setBlock(i + 16, j + 22, k + 19, PlaceDeepslateBricks, 0, 2);
		world.setBlock(i + 17, j + 22, k + 19, PlaceCrackedDeepslateBricks, 1, 2);
		world.setBlock(i + 18, j + 22, k + 19, PlaceDeepslateBricks, 0, 2);
		world.setBlock(i + 19, j + 22, k + 19, PlaceCobbledDeepslate, 0, 2);
		world.setBlock(i + 20, j + 22, k + 19, PlaceCobbledDeepslate, 0, 2);
		world.setBlock(i + 16, j + 22, k + 20, PlaceCrackedDeepslateBricks, 1, 2);
		world.setBlock(i + 17, j + 22, k + 20, PlaceDeepslateBricks, 0, 2);
		world.setBlock(i + 18, j + 22, k + 20, PlaceDeepslateBricks, 0, 2);
		world.setBlock(i + 19, j + 22, k + 20, PlaceDeepslateBricks, 0, 2);
		world.setBlock(i + 20, j + 22, k + 20, PlaceDeepslateBricks, 0, 2);
		world.setBlock(i + 16, j + 22, k + 21, PlaceCrackedDeepslateTiles, 3, 2);
		world.setBlock(i + 17, j + 22, k + 21, PlaceCrackedDeepslateBricks, 1, 2);
		world.setBlock(i + 18, j + 22, k + 21, PlaceDeepslateBricks, 0, 2);
		world.setBlock(i + 19, j + 22, k + 21, PlaceDeepslateBricks, 0, 2);
		world.setBlock(i + 20, j + 22, k + 21, PlaceCrackedDeepslateTiles, 3, 2);
		world.setBlock(i + 16, j + 22, k + 22, PlaceDeepslateTiles, 2, 2);
		world.setBlock(i + 17, j + 22, k + 22, PlaceDeepslateTiles, 2, 2);
		world.setBlock(i + 18, j + 22, k + 22, PlaceDeepslateTiles, 2, 2);
		world.setBlock(i + 19, j + 22, k + 22, PlaceDeepslateTiles, 2, 2);
		world.setBlock(i + 20, j + 22, k + 22, PlaceCrackedDeepslateTiles, 3, 2);
		world.setBlock(i + 18, j + 22, k + 23, NovaCraftBlocks.reinforced_nullstone, 0, 2);
		world.setBlock(i + 18, j + 22, k + 44, NovaCraftBlocks.reinforced_nullstone, 0, 2);
		world.setBlock(i + 16, j + 22, k + 45, PlaceCrackedDeepslateTiles, 3, 2);
		world.setBlock(i + 17, j + 22, k + 45, PlaceDeepslateTiles, 2, 2);
		world.setBlock(i + 18, j + 22, k + 45, PlaceCrackedDeepslateTiles, 3, 2);
		world.setBlock(i + 19, j + 22, k + 45, PlaceDeepslateTiles, 2, 2);
		world.setBlock(i + 20, j + 22, k + 45, PlaceDeepslateTiles, 2, 2);
		world.setBlock(i + 16, j + 22, k + 46, PlaceDeepslateTiles, 2, 2);
		world.setBlock(i + 17, j + 22, k + 46, PlaceCrackedDeepslateTiles, 3, 2);
		world.setBlock(i + 18, j + 22, k + 46, PlaceCrackedDeepslateTiles, 3, 2);
		world.setBlock(i + 19, j + 22, k + 46, PlaceDeepslateTiles, 2, 2);
		world.setBlock(i + 20, j + 22, k + 46, PlaceDeepslateTiles, 2, 2);
		world.setBlock(i + 16, j + 22, k + 47, PlaceCrackedDeepslateBricks, 1, 2);
		world.setBlock(i + 17, j + 22, k + 47, PlaceDeepslateBricks, 0, 2);
		world.setBlock(i + 18, j + 22, k + 47, PlaceCrackedDeepslateBricks, 1, 2);
		world.setBlock(i + 19, j + 22, k + 47, PlaceDeepslateBricks, 0, 2);
		world.setBlock(i + 20, j + 22, k + 47, PlaceDeepslateBricks, 0, 2);
		world.setBlock(i + 16, j + 22, k + 48, PlaceCrackedDeepslateBricks, 1, 2);
		world.setBlock(i + 17, j + 22, k + 48, PlaceDeepslateBricks, 0, 2);
		world.setBlock(i + 18, j + 22, k + 48, PlaceCrackedDeepslateBricks, 1, 2);
		world.setBlock(i + 19, j + 22, k + 48, PlaceCobbledDeepslate, 0, 2);
		world.setBlock(i + 20, j + 22, k + 48, PlaceCobbledDeepslate, 0, 2);
		world.setBlock(i + 16, j + 22, k + 49, PlaceCobbledDeepslate, 0, 2);
		world.setBlock(i + 17, j + 22, k + 49, PlaceCobbledDeepslate, 0, 2);
		world.setBlock(i + 18, j + 22, k + 49, PlaceCobbledDeepslate, 0, 2);
		world.setBlock(i + 19, j + 22, k + 49, PlaceCobbledDeepslate, 0, 2);
		world.setBlock(i + 20, j + 22, k + 49, PlaceCobbledDeepslate, 0, 2);
		world.setBlock(i + 17, j + 22, k + 52, PlaceCobbledDeepslate, 0, 2);
		world.setBlock(i + 18, j + 22, k + 52, PlaceCobbledDeepslate, 0, 2);
		world.setBlock(i + 19, j + 22, k + 52, PlaceCobbledDeepslate, 0, 2);
		world.setBlock(i + 17, j + 22, k + 53, PlaceCobbledDeepslate, 0, 2);
		world.setBlock(i + 18, j + 22, k + 53, PlaceCobbledDeepslate, 0, 2);
		world.setBlock(i + 17, j + 23, k + 14, PlaceCobbledDeepslate, 0, 2);
		world.setBlock(i + 18, j + 23, k + 14, PlaceCobbledDeepslate, 0, 2);
		world.setBlock(i + 19, j + 23, k + 14, PlaceCobbledDeepslate, 0, 2);
		world.setBlock(i + 17, j + 23, k + 15, PlaceCobbledDeepslate, 0, 2);
		world.setBlock(i + 18, j + 23, k + 15, PlaceCobbledDeepslate, 0, 2);
		world.setBlock(i + 19, j + 23, k + 15, PlaceCobbledDeepslate, 0, 2);
		world.setBlock(i + 16, j + 23, k + 18, PlaceCobbledDeepslate, 0, 2);
		world.setBlock(i + 17, j + 23, k + 18, PlaceCobbledDeepslate, 0, 2);
		world.setBlock(i + 18, j + 23, k + 18, PlaceCobbledDeepslate, 0, 2);
		world.setBlock(i + 19, j + 23, k + 18, PlaceCobbledDeepslate, 0, 2);
		world.setBlock(i + 20, j + 23, k + 18, PlaceCobbledDeepslate, 0, 2);
		world.setBlock(i + 16, j + 23, k + 19, PlaceDeepslateBricks, 0, 2);
		world.setBlock(i + 17, j + 23, k + 19, PlaceDeepslateBricks, 0, 2);
		world.setBlock(i + 18, j + 23, k + 19, PlaceDeepslateBricks, 0, 2);
		world.setBlock(i + 19, j + 23, k + 19, PlaceCrackedDeepslateBricks, 1, 2);
		world.setBlock(i + 20, j + 23, k + 19, PlaceCobbledDeepslate, 0, 2);
		world.setBlock(i + 16, j + 23, k + 20, PlaceDeepslateBricks, 0, 2);
		world.setBlock(i + 17, j + 23, k + 20, PlaceDeepslateBricks, 0, 2);
		world.setBlock(i + 18, j + 23, k + 20, PlaceDeepslateBricks, 0, 2);
		world.setBlock(i + 19, j + 23, k + 20, PlaceDeepslateBricks, 0, 2);
		world.setBlock(i + 20, j + 23, k + 20, PlaceCrackedDeepslateBricks, 1, 2);
		world.setBlock(i + 16, j + 23, k + 21, PlaceDeepslateBricks, 0, 2);
		world.setBlock(i + 17, j + 23, k + 21, PlaceDeepslateBricks, 0, 2);
		world.setBlock(i + 18, j + 23, k + 21, PlaceDeepslateBricks, 0, 2);
		world.setBlock(i + 19, j + 23, k + 21, PlaceDeepslateBricks, 0, 2);
		world.setBlock(i + 20, j + 23, k + 21, PlaceDeepslateBricks, 0, 2);
		world.setBlock(i + 16, j + 23, k + 22, PlaceCrackedDeepslateTiles, 3, 2);
		world.setBlock(i + 17, j + 23, k + 22, PlaceDeepslateTiles, 2, 2);
		world.setBlock(i + 18, j + 23, k + 22, PlaceCrackedDeepslateTiles, 3, 2);
		world.setBlock(i + 19, j + 23, k + 22, PlaceDeepslateTiles, 2, 2);
		world.setBlock(i + 20, j + 23, k + 22, PlaceDeepslateTiles, 2, 2);
		world.setBlock(i + 18, j + 23, k + 23, NovaCraftBlocks.activated_reinforced_nullstone, 0, 2);
		world.setBlock(i + 18, j + 23, k + 44, NovaCraftBlocks.reinforced_nullstone, 0, 2);
		world.setBlock(i + 16, j + 23, k + 45, PlaceDeepslateTiles, 2, 2);
		world.setBlock(i + 17, j + 23, k + 45, PlaceDeepslateTiles, 2, 2);
		world.setBlock(i + 18, j + 23, k + 45, PlaceDeepslateTiles, 2, 2);
		world.setBlock(i + 19, j + 23, k + 45, PlaceCrackedDeepslateTiles, 3, 2);
		world.setBlock(i + 20, j + 23, k + 45, PlaceDeepslateTiles, 2, 2);
		world.setBlock(i + 16, j + 23, k + 46, PlaceDeepslateBricks, 0, 2);
		world.setBlock(i + 17, j + 23, k + 46, PlaceDeepslateTiles, 2, 2);
		world.setBlock(i + 18, j + 23, k + 46, PlaceDeepslateTiles, 2, 2);
		world.setBlock(i + 19, j + 23, k + 46, PlaceDeepslateTiles, 2, 2);
		world.setBlock(i + 20, j + 23, k + 46, PlaceDeepslateBricks, 0, 2);
		world.setBlock(i + 16, j + 23, k + 47, PlaceDeepslateBricks, 0, 2);
		world.setBlock(i + 17, j + 23, k + 47, PlaceDeepslateBricks, 0, 2);
		world.setBlock(i + 18, j + 23, k + 47, PlaceDeepslateBricks, 0, 2);
		world.setBlock(i + 19, j + 23, k + 47, PlaceCrackedDeepslateBricks, 1, 2);
		world.setBlock(i + 20, j + 23, k + 47, PlaceCrackedDeepslateBricks, 1, 2);
		world.setBlock(i + 16, j + 23, k + 48, PlaceDeepslateBricks, 0, 2);
		world.setBlock(i + 17, j + 23, k + 48, PlaceDeepslateBricks, 0, 2);
		world.setBlock(i + 18, j + 23, k + 48, PlaceCobbledDeepslate, 0, 2);
		world.setBlock(i + 19, j + 23, k + 48, PlaceCobbledDeepslate, 0, 2);
		world.setBlock(i + 20, j + 23, k + 48, PlaceCobbledDeepslate, 0, 2);
		world.setBlock(i + 16, j + 23, k + 49, PlaceCobbledDeepslate, 0, 2);
		world.setBlock(i + 17, j + 23, k + 49, PlaceCobbledDeepslate, 0, 2);
		world.setBlock(i + 18, j + 23, k + 49, PlaceCobbledDeepslate, 0, 2);
		world.setBlock(i + 19, j + 23, k + 49, PlaceCobbledDeepslate, 0, 2);
		world.setBlock(i + 20, j + 23, k + 49, PlaceCobbledDeepslate, 0, 2);
		world.setBlock(i + 17, j + 23, k + 52, PlaceCobbledDeepslate, 0, 2);
		world.setBlock(i + 18, j + 23, k + 52, PlaceCobbledDeepslate, 0, 2);
		world.setBlock(i + 17, j + 23, k + 53, PlaceCobbledDeepslate, 0, 2);
		world.setBlock(i + 18, j + 23, k + 53, PlaceCobbledDeepslate, 0, 2);
		world.setBlock(i + 19, j + 23, k + 53, PlaceCobbledDeepslate, 0, 2);
		world.setBlock(i + 17, j + 24, k + 14, PlaceCobbledDeepslate, 0, 2);
		world.setBlock(i + 18, j + 24, k + 14, PlaceCobbledDeepslate, 0, 2);
		world.setBlock(i + 19, j + 24, k + 14, PlaceCobbledDeepslate, 0, 2);
		world.setBlock(i + 17, j + 24, k + 15, PlaceCobbledDeepslate, 0, 2);
		world.setBlock(i + 18, j + 24, k + 15, PlaceCobbledDeepslate, 0, 2);
		world.setBlock(i + 19, j + 24, k + 15, PlaceCobbledDeepslate, 0, 2);
		world.setBlock(i + 17, j + 24, k + 16, PlaceCobbledDeepslate, 0, 2);
		world.setBlock(i + 18, j + 24, k + 16, PlaceCobbledDeepslate, 0, 2);
		world.setBlock(i + 19, j + 24, k + 16, PlaceCobbledDeepslate, 0, 2);
		world.setBlock(i + 17, j + 24, k + 17, PlaceCobbledDeepslate, 0, 2);
		world.setBlock(i + 18, j + 24, k + 17, PlaceCobbledDeepslate, 0, 2);
		world.setBlock(i + 19, j + 24, k + 17, PlaceCobbledDeepslate, 0, 2);
		world.setBlock(i + 16, j + 24, k + 18, PlaceCrackedDeepslateBricks, 1, 2);
		world.setBlock(i + 17, j + 24, k + 18, PlaceCobbledDeepslate, 0, 2);
		world.setBlock(i + 18, j + 24, k + 18, PlaceCobbledDeepslate, 0, 2);
		world.setBlock(i + 19, j + 24, k + 18, PlaceCobbledDeepslate, 0, 2);
		world.setBlock(i + 20, j + 24, k + 18, PlaceCobbledDeepslate, 0, 2);
		world.setBlock(i + 16, j + 24, k + 19, PlaceCrackedDeepslateBricks, 1, 2);
		world.setBlock(i + 17, j + 24, k + 19, PlaceDeepslateBricks, 0, 2);
		world.setBlock(i + 18, j + 24, k + 19, PlaceCrackedDeepslateBricks, 1, 2);
		world.setBlock(i + 19, j + 24, k + 19, PlaceDeepslateBricks, 0, 2);
		world.setBlock(i + 20, j + 24, k + 19, PlaceDeepslateBricks, 0, 2);
		world.setBlock(i + 16, j + 24, k + 20, PlaceCrackedDeepslateBricks, 1, 2);
		world.setBlock(i + 17, j + 24, k + 20, PlaceDeepslateBricks, 0, 2);
		world.setBlock(i + 18, j + 24, k + 20, PlaceCrackedDeepslateBricks, 1, 2);
		world.setBlock(i + 19, j + 24, k + 20, PlaceDeepslateBricks, 0, 2);
		world.setBlock(i + 20, j + 24, k + 20, PlaceDeepslateBricks, 0, 2);
		world.setBlock(i + 16, j + 24, k + 21, PlaceDeepslateBricks, 0, 2);
		world.setBlock(i + 17, j + 24, k + 21, PlaceDeepslateBricks, 0, 2);
		world.setBlock(i + 18, j + 24, k + 21, PlaceCrackedDeepslateBricks, 1, 2);
		world.setBlock(i + 19, j + 24, k + 21, PlaceDeepslateBricks, 0, 2);
		world.setBlock(i + 20, j + 24, k + 21, PlaceCrackedDeepslateBricks, 1, 2);
		world.setBlock(i + 16, j + 24, k + 22, PlaceDeepslateBricks, 0, 2);
		world.setBlock(i + 17, j + 24, k + 22, PlaceCrackedDeepslateTiles, 3, 2);
		world.setBlock(i + 18, j + 24, k + 22, PlaceCrackedDeepslateTiles, 3, 2);
		world.setBlock(i + 19, j + 24, k + 22, PlaceDeepslateTiles, 2, 2);
		world.setBlock(i + 20, j + 24, k + 22, PlaceCrackedDeepslateBricks, 1, 2);
		world.setBlock(i + 16, j + 24, k + 23, PlaceCrackedDeepslateTiles, 3, 2);
		world.setBlock(i + 18, j + 24, k + 23, NovaCraftBlocks.reinforced_nullstone, 0, 2);
		world.setBlock(i + 20, j + 24, k + 23, PlaceCrackedDeepslateTiles, 3, 2);
		world.setBlock(i + 18, j + 24, k + 24, NovaCraftBlocks.reinforced_nullstone, 0, 2);
		world.setBlock(i + 18, j + 24, k + 25, NovaCraftBlocks.reinforced_nullstone, 0, 2);
		world.setBlock(i + 18, j + 24, k + 26, NovaCraftBlocks.reinforced_nullstone, 0, 2);
		world.setBlock(i + 18, j + 24, k + 27, NovaCraftBlocks.activated_reinforced_nullstone, 0, 2);
		world.setBlock(i + 18, j + 24, k + 28, NovaCraftBlocks.reinforced_nullstone, 0, 2);
		world.setBlock(i + 18, j + 24, k + 29, NovaCraftBlocks.reinforced_nullstone, 0, 2);
		world.setBlock(i + 18, j + 24, k + 30, NovaCraftBlocks.reinforced_nullstone, 0, 2);
		world.setBlock(i + 18, j + 24, k + 31, NovaCraftBlocks.activated_reinforced_nullstone, 0, 2);
		world.setBlock(i + 18, j + 24, k + 32, NovaCraftBlocks.reinforced_nullstone, 0, 2);
		world.setBlock(i + 18, j + 24, k + 33, NovaCraftBlocks.reinforced_nullstone, 0, 2);
		world.setBlock(i + 18, j + 24, k + 34, NovaCraftBlocks.reinforced_nullstone, 0, 2);
		world.setBlock(i + 18, j + 24, k + 35, NovaCraftBlocks.reinforced_nullstone, 0, 2);
		world.setBlock(i + 18, j + 24, k + 36, NovaCraftBlocks.reinforced_nullstone, 0, 2);
		world.setBlock(i + 18, j + 24, k + 37, NovaCraftBlocks.reinforced_nullstone, 0, 2);
		world.setBlock(i + 18, j + 24, k + 38, NovaCraftBlocks.reinforced_nullstone, 0, 2);
		world.setBlock(i + 18, j + 24, k + 39, NovaCraftBlocks.reinforced_nullstone, 0, 2);
		world.setBlock(i + 18, j + 24, k + 40, NovaCraftBlocks.activated_reinforced_nullstone, 0, 2);
		world.setBlock(i + 18, j + 24, k + 41, NovaCraftBlocks.reinforced_nullstone, 0, 2);
		world.setBlock(i + 18, j + 24, k + 42, NovaCraftBlocks.reinforced_nullstone, 0, 2);
		world.setBlock(i + 18, j + 24, k + 43, NovaCraftBlocks.reinforced_nullstone, 0, 2);
		world.setBlock(i + 16, j + 24, k + 44, PlaceDeepslateTiles, 2, 2);
		world.setBlock(i + 18, j + 24, k + 44, NovaCraftBlocks.reinforced_nullstone, 0, 2);
		world.setBlock(i + 20, j + 24, k + 44, PlaceDeepslateTiles, 2, 2);
		world.setBlock(i + 16, j + 24, k + 45, PlaceDeepslateTiles, 2, 2);
		world.setBlock(i + 17, j + 24, k + 45, PlaceDeepslateTiles, 2, 2);
		world.setBlock(i + 18, j + 24, k + 45, PlaceCrackedDeepslateTiles, 3, 2);
		world.setBlock(i + 19, j + 24, k + 45, PlaceDeepslateTiles, 2, 2);
		world.setBlock(i + 20, j + 24, k + 45, PlaceDeepslateBricks, 0, 2);
		world.setBlock(i + 16, j + 24, k + 46, PlaceDeepslateBricks, 0, 2);
		world.setBlock(i + 17, j + 24, k + 46, PlaceCrackedDeepslateTiles, 3, 2);
		world.setBlock(i + 18, j + 24, k + 46, PlaceCrackedDeepslateTiles, 3, 2);
		world.setBlock(i + 19, j + 24, k + 46, PlaceDeepslateTiles, 2, 2);
		world.setBlock(i + 20, j + 24, k + 46, PlaceDeepslateBricks, 0, 2);
		world.setBlock(i + 16, j + 24, k + 47, PlaceDeepslateBricks, 0, 2);
		world.setBlock(i + 17, j + 24, k + 47, PlaceCrackedDeepslateBricks, 1, 2);
		world.setBlock(i + 18, j + 24, k + 47, PlaceDeepslateBricks, 0, 2);
		world.setBlock(i + 19, j + 24, k + 47, PlaceCrackedDeepslateBricks, 1, 2);
		world.setBlock(i + 20, j + 24, k + 47, PlaceDeepslateBricks, 0, 2);
		world.setBlock(i + 16, j + 24, k + 48, PlaceDeepslateBricks, 0, 2);
		world.setBlock(i + 17, j + 24, k + 48, PlaceCobbledDeepslate, 0, 2);
		world.setBlock(i + 18, j + 24, k + 48, PlaceCobbledDeepslate, 0, 2);
		world.setBlock(i + 19, j + 24, k + 48, PlaceCobbledDeepslate, 0, 2);
		world.setBlock(i + 20, j + 24, k + 48, PlaceCobbledDeepslate, 0, 2);
		world.setBlock(i + 16, j + 24, k + 49, PlaceCobbledDeepslate, 0, 2);
		world.setBlock(i + 17, j + 24, k + 49, PlaceCobbledDeepslate, 0, 2);
		world.setBlock(i + 18, j + 24, k + 49, PlaceCobbledDeepslate, 0, 2);
		world.setBlock(i + 19, j + 24, k + 49, PlaceCobbledDeepslate, 0, 2);
		world.setBlock(i + 20, j + 24, k + 49, PlaceCobbledDeepslate, 0, 2);
		world.setBlock(i + 17, j + 24, k + 50, PlaceCobbledDeepslate, 0, 2);
		world.setBlock(i + 18, j + 24, k + 50, PlaceCobbledDeepslate, 0, 2);
		world.setBlock(i + 19, j + 24, k + 50, PlaceCobbledDeepslate, 0, 2);
		world.setBlock(i + 17, j + 24, k + 51, PlaceCobbledDeepslate, 0, 2);
		world.setBlock(i + 18, j + 24, k + 51, PlaceCobbledDeepslate, 0, 2);
		world.setBlock(i + 19, j + 24, k + 51, PlaceCobbledDeepslate, 0, 2);
		world.setBlock(i + 17, j + 24, k + 52, PlaceCobbledDeepslate, 0, 2);
		world.setBlock(i + 18, j + 24, k + 52, PlaceCobbledDeepslate, 0, 2);
		world.setBlock(i + 19, j + 24, k + 52, PlaceCobbledDeepslate, 0, 2);
		world.setBlock(i + 17, j + 24, k + 53, PlaceCobbledDeepslate, 0, 2);
		world.setBlock(i + 18, j + 24, k + 53, PlaceCobbledDeepslate, 0, 2);
		world.setBlock(i + 19, j + 24, k + 53, PlaceCobbledDeepslate, 0, 2);
		world.setBlock(i + 17, j + 25, k + 14, PlaceCobbledDeepslate, 0, 2);
		world.setBlock(i + 18, j + 25, k + 14, PlaceCobbledDeepslate, 0, 2);
		world.setBlock(i + 17, j + 25, k + 15, PlaceCobbledDeepslate, 0, 2);
		world.setBlock(i + 18, j + 25, k + 15, PlaceCobbledDeepslate, 0, 2);
		world.setBlock(i + 19, j + 25, k + 15, PlaceCobbledDeepslate, 0, 2);
		world.setBlock(i + 17, j + 25, k + 16, PlaceCobbledDeepslate, 0, 2);
		world.setBlock(i + 18, j + 25, k + 16, PlaceCobbledDeepslate, 0, 2);
		world.setBlock(i + 19, j + 25, k + 16, PlaceCobbledDeepslate, 0, 2);
		world.setBlock(i + 17, j + 25, k + 17, PlaceCobbledDeepslate, 0, 2);
		world.setBlock(i + 18, j + 25, k + 17, PlaceCobbledDeepslate, 0, 2);
		world.setBlock(i + 19, j + 25, k + 17, PlaceCobbledDeepslate, 0, 2);
		world.setBlock(i + 16, j + 25, k + 18, PlaceDeepslateBricks, 0, 2);
		world.setBlock(i + 17, j + 25, k + 18, PlaceCrackedDeepslateBricks, 1, 2);
		world.setBlock(i + 18, j + 25, k + 18, PlaceCobbledDeepslate, 0, 2);
		world.setBlock(i + 19, j + 25, k + 18, PlaceCobbledDeepslate, 0, 2);
		world.setBlock(i + 20, j + 25, k + 18, PlaceCobbledDeepslate, 0, 2);
		world.setBlock(i + 16, j + 25, k + 19, PlaceDeepslateBricks, 0, 2);
		world.setBlock(i + 17, j + 25, k + 19, PlaceCrackedDeepslateBricks, 1, 2);
		world.setBlock(i + 18, j + 25, k + 19, PlaceDeepslateBricks, 0, 2);
		world.setBlock(i + 19, j + 25, k + 19, PlaceDeepslateBricks, 0, 2);
		world.setBlock(i + 20, j + 25, k + 19, PlaceDeepslateBricks, 0, 2);
		world.setBlock(i + 16, j + 25, k + 20, PlaceDeepslateBricks, 0, 2);
		world.setBlock(i + 17, j + 25, k + 20, PlaceCrackedDeepslateBricks, 1, 2);
		world.setBlock(i + 18, j + 25, k + 20, PlaceDeepslateBricks, 0, 2);
		world.setBlock(i + 19, j + 25, k + 20, PlaceDeepslateBricks, 0, 2);
		world.setBlock(i + 20, j + 25, k + 20, PlaceDeepslateBricks, 0, 2);
		world.setBlock(i + 16, j + 25, k + 21, PlaceDeepslateBricks, 0, 2);
		world.setBlock(i + 17, j + 25, k + 21, PlaceDeepslateBricks, 0, 2);
		world.setBlock(i + 18, j + 25, k + 21, PlaceDeepslateBricks, 0, 2);
		world.setBlock(i + 19, j + 25, k + 21, PlaceCrackedDeepslateBricks, 1, 2);
		world.setBlock(i + 20, j + 25, k + 21, PlaceDeepslateBricks, 0, 2);
		world.setBlock(i + 17, j + 25, k + 22, PlaceCrackedDeepslateTiles, 3, 2);
		world.setBlock(i + 18, j + 25, k + 22, PlaceDeepslateTiles, 2, 2);
		world.setBlock(i + 19, j + 25, k + 22, PlaceCrackedDeepslateTiles, 3, 2);
		world.setBlock(i + 20, j + 25, k + 22, PlaceCrackedDeepslateBricks, 1, 2);
		world.setBlock(i + 17, j + 25, k + 23, PlaceDeepslateTiles, 2, 2);
		world.setBlock(i + 18, j + 25, k + 23, PlaceDeepslateTiles, 2, 2);
		world.setBlock(i + 19, j + 25, k + 23, PlaceDeepslateTiles, 2, 2);
		world.setBlock(i + 20, j + 25, k + 23, PlaceCrackedDeepslateBricks, 1, 2);
		world.setBlock(i + 16, j + 25, k + 24, PlaceDeepslateTiles, 2, 2);
		world.setBlock(i + 17, j + 25, k + 24, PlaceDeepslateTiles, 2, 2);
		world.setBlock(i + 18, j + 25, k + 24, PlaceDeepslateTiles, 2, 2);
		world.setBlock(i + 19, j + 25, k + 24, PlaceDeepslateTiles, 2, 2);
		world.setBlock(i + 20, j + 25, k + 24, PlaceDeepslateTiles, 2, 2);
		world.setBlock(i + 16, j + 25, k + 25, PlaceCrackedDeepslateTiles, 3, 2);
		world.setBlock(i + 17, j + 25, k + 25, PlaceCrackedDeepslateTiles, 3, 2);
		world.setBlock(i + 18, j + 25, k + 25, PlaceCrackedDeepslateTiles, 3, 2);
		world.setBlock(i + 19, j + 25, k + 25, PlaceDeepslateTiles, 2, 2);
		world.setBlock(i + 20, j + 25, k + 25, PlaceCrackedDeepslateTiles, 3, 2);
		world.setBlock(i + 16, j + 25, k + 26, PlaceDeepslateTiles, 2, 2);
		world.setBlock(i + 17, j + 25, k + 26, PlaceDeepslateTiles, 2, 2);
		world.setBlock(i + 18, j + 25, k + 26, PlaceDeepslateTiles, 2, 2);
		world.setBlock(i + 19, j + 25, k + 26, PlaceDeepslateTiles, 2, 2);
		world.setBlock(i + 20, j + 25, k + 26, PlaceDeepslateTiles, 2, 2);
		world.setBlock(i + 17, j + 25, k + 27, PlaceDeepslateTiles, 2, 2);
		world.setBlock(i + 18, j + 25, k + 27, PlaceDeepslateTiles, 2, 2);
		world.setBlock(i + 19, j + 25, k + 27, PlaceDeepslateTiles, 2, 2);
		world.setBlock(i + 17, j + 25, k + 28, PlaceDeepslateTiles, 2, 2);
		world.setBlock(i + 18, j + 25, k + 28, PlaceDeepslateTiles, 2, 2);
		world.setBlock(i + 19, j + 25, k + 28, PlaceDeepslateTiles, 2, 2);
		world.setBlock(i + 16, j + 25, k + 29, PlaceDeepslateTiles, 2, 2);
		world.setBlock(i + 17, j + 25, k + 29, PlaceDeepslateTiles, 2, 2);
		world.setBlock(i + 18, j + 25, k + 29, PlaceDeepslateTiles, 2, 2);
		world.setBlock(i + 19, j + 25, k + 29, PlaceDeepslateTiles, 2, 2);
		world.setBlock(i + 20, j + 25, k + 29, PlaceDeepslateTiles, 2, 2);
		world.setBlock(i + 16, j + 25, k + 30, PlaceDeepslateTiles, 2, 2);
		world.setBlock(i + 17, j + 25, k + 30, PlaceDeepslateTiles, 2, 2);
		world.setBlock(i + 18, j + 25, k + 30, PlaceCrackedDeepslateTiles, 3, 2);
		world.setBlock(i + 19, j + 25, k + 30, PlaceDeepslateTiles, 2, 2);
		world.setBlock(i + 20, j + 25, k + 30, PlaceDeepslateTiles, 2, 2);
		world.setBlock(i + 16, j + 25, k + 31, PlaceCrackedDeepslateTiles, 3, 2);
		world.setBlock(i + 17, j + 25, k + 31, PlaceCrackedDeepslateTiles, 3, 2);
		world.setBlock(i + 18, j + 25, k + 31, PlaceCrackedDeepslateTiles, 3, 2);
		world.setBlock(i + 19, j + 25, k + 31, PlaceCrackedDeepslateTiles, 3, 2);
		world.setBlock(i + 17, j + 25, k + 32, PlaceDeepslateTiles, 2, 2);
		world.setBlock(i + 18, j + 25, k + 32, PlaceDeepslateTiles, 2, 2);
		world.setBlock(i + 19, j + 25, k + 32, PlaceDeepslateTiles, 2, 2);
		world.setBlock(i + 16, j + 25, k + 33, PlaceCrackedDeepslateTiles, 3, 2);
		world.setBlock(i + 17, j + 25, k + 33, PlaceCrackedDeepslateTiles, 3, 2);
		world.setBlock(i + 18, j + 25, k + 33, PlaceDeepslateTiles, 2, 2);
		world.setBlock(i + 19, j + 25, k + 33, PlaceDeepslateTiles, 2, 2);
		world.setBlock(i + 20, j + 25, k + 33, PlaceDeepslateTiles, 2, 2);
		world.setBlock(i + 16, j + 25, k + 34, PlaceDeepslateTiles, 2, 2);
		world.setBlock(i + 17, j + 25, k + 34, PlaceDeepslateTiles, 2, 2);
		world.setBlock(i + 18, j + 25, k + 34, PlaceCrackedDeepslateTiles, 3, 2);
		world.setBlock(i + 19, j + 25, k + 34, PlaceDeepslateTiles, 2, 2);
		world.setBlock(i + 20, j + 25, k + 34, PlaceDeepslateTiles, 2, 2);
		world.setBlock(i + 17, j + 25, k + 35, PlaceDeepslateTiles, 2, 2);
		world.setBlock(i + 18, j + 25, k + 35, PlaceDeepslateTiles, 2, 2);
		world.setBlock(i + 19, j + 25, k + 35, PlaceDeepslateTiles, 2, 2);
		world.setBlock(i + 17, j + 25, k + 36, PlaceCrackedDeepslateTiles, 3, 2);
		world.setBlock(i + 18, j + 25, k + 36, PlaceCrackedDeepslateTiles, 3, 2);
		world.setBlock(i + 19, j + 25, k + 36, PlaceDeepslateTiles, 2, 2);
		world.setBlock(i + 16, j + 25, k + 37, PlaceDeepslateTiles, 2, 2);
		world.setBlock(i + 17, j + 25, k + 37, PlaceCrackedDeepslateTiles, 3, 2);
		world.setBlock(i + 18, j + 25, k + 37, PlaceDeepslateTiles, 2, 2);
		world.setBlock(i + 19, j + 25, k + 37, PlaceDeepslateTiles, 2, 2);
		world.setBlock(i + 20, j + 25, k + 37, PlaceDeepslateTiles, 2, 2);
		world.setBlock(i + 16, j + 25, k + 38, PlaceDeepslateTiles, 2, 2);
		world.setBlock(i + 17, j + 25, k + 38, PlaceCrackedDeepslateTiles, 3, 2);
		world.setBlock(i + 18, j + 25, k + 38, PlaceDeepslateTiles, 2, 2);
		world.setBlock(i + 19, j + 25, k + 38, PlaceDeepslateTiles, 2, 2);
		world.setBlock(i + 20, j + 25, k + 38, PlaceCrackedDeepslateTiles, 3, 2);
		world.setBlock(i + 17, j + 25, k + 39, PlaceDeepslateTiles, 2, 2);
		world.setBlock(i + 18, j + 25, k + 39, PlaceDeepslateTiles, 2, 2);
		world.setBlock(i + 19, j + 25, k + 39, PlaceDeepslateTiles, 2, 2);
		world.setBlock(i + 17, j + 25, k + 40, PlaceDeepslateTiles, 2, 2);
		world.setBlock(i + 18, j + 25, k + 40, PlaceDeepslateTiles, 2, 2);
		world.setBlock(i + 19, j + 25, k + 40, PlaceDeepslateTiles, 2, 2);
		world.setBlock(i + 16, j + 25, k + 41, PlaceDeepslateTiles, 2, 2);
		world.setBlock(i + 17, j + 25, k + 41, PlaceCrackedDeepslateTiles, 3, 2);
		world.setBlock(i + 18, j + 25, k + 41, PlaceDeepslateTiles, 2, 2);
		world.setBlock(i + 19, j + 25, k + 41, PlaceDeepslateTiles, 2, 2);
		world.setBlock(i + 20, j + 25, k + 41, PlaceCrackedDeepslateTiles, 3, 2);
		world.setBlock(i + 16, j + 25, k + 42, PlaceDeepslateTiles, 2, 2);
		world.setBlock(i + 17, j + 25, k + 42, PlaceDeepslateTiles, 2, 2);
		world.setBlock(i + 18, j + 25, k + 42, PlaceCrackedDeepslateTiles, 3, 2);
		world.setBlock(i + 19, j + 25, k + 42, PlaceCrackedDeepslateTiles, 3, 2);
		world.setBlock(i + 20, j + 25, k + 42, PlaceDeepslateTiles, 2, 2);
		world.setBlock(i + 16, j + 25, k + 43, PlaceDeepslateTiles, 2, 2);
		world.setBlock(i + 17, j + 25, k + 43, PlaceDeepslateTiles, 2, 2);
		world.setBlock(i + 18, j + 25, k + 43, PlaceDeepslateTiles, 2, 2);
		world.setBlock(i + 19, j + 25, k + 43, PlaceDeepslateTiles, 2, 2);
		world.setBlock(i + 20, j + 25, k + 43, PlaceCrackedDeepslateTiles, 3, 2);
		world.setBlock(i + 16, j + 25, k + 44, PlaceDeepslateTiles, 2, 2);
		world.setBlock(i + 17, j + 25, k + 44, PlaceCrackedDeepslateTiles, 3, 2);
		world.setBlock(i + 18, j + 25, k + 44, PlaceDeepslateTiles, 2, 2);
		world.setBlock(i + 19, j + 25, k + 44, PlaceCrackedDeepslateTiles, 3, 2);
		world.setBlock(i + 20, j + 25, k + 44, PlaceDeepslateBricks, 0, 2);
		world.setBlock(i + 16, j + 25, k + 45, PlaceDeepslateBricks, 0, 2);
		world.setBlock(i + 17, j + 25, k + 45, PlaceDeepslateTiles, 2, 2);
		world.setBlock(i + 18, j + 25, k + 45, PlaceDeepslateTiles, 2, 2);
		world.setBlock(i + 19, j + 25, k + 45, PlaceDeepslateBricks, 0, 2);
		world.setBlock(i + 20, j + 25, k + 45, PlaceDeepslateBricks, 0, 2);
		world.setBlock(i + 16, j + 25, k + 46, PlaceDeepslateBricks, 0, 2);
		world.setBlock(i + 17, j + 25, k + 46, PlaceDeepslateTiles, 2, 2);
		world.setBlock(i + 18, j + 25, k + 46, PlaceDeepslateTiles, 2, 2);
		world.setBlock(i + 19, j + 25, k + 46, PlaceDeepslateTiles, 2, 2);
		world.setBlock(i + 20, j + 25, k + 46, PlaceDeepslateBricks, 0, 2);
		world.setBlock(i + 16, j + 25, k + 47, PlaceCrackedDeepslateBricks, 1, 2);
		world.setBlock(i + 17, j + 25, k + 47, PlaceDeepslateBricks, 0, 2);
		world.setBlock(i + 18, j + 25, k + 47, PlaceDeepslateBricks, 0, 2);
		world.setBlock(i + 19, j + 25, k + 47, PlaceDeepslateBricks, 0, 2);
		world.setBlock(i + 20, j + 25, k + 47, PlaceCrackedDeepslateBricks, 1, 2);
		world.setBlock(i + 16, j + 25, k + 48, PlaceDeepslateBricks, 0, 2);
		world.setBlock(i + 17, j + 25, k + 48, PlaceCobbledDeepslate, 0, 2);
		world.setBlock(i + 18, j + 25, k + 48, PlaceCobbledDeepslate, 0, 2);
		world.setBlock(i + 19, j + 25, k + 48, PlaceCobbledDeepslate, 0, 2);
		world.setBlock(i + 20, j + 25, k + 48, PlaceCobbledDeepslate, 0, 2);
		world.setBlock(i + 16, j + 25, k + 49, PlaceCobbledDeepslate, 0, 2);
		world.setBlock(i + 17, j + 25, k + 49, PlaceCobbledDeepslate, 0, 2);
		world.setBlock(i + 18, j + 25, k + 49, PlaceCobbledDeepslate, 0, 2);
		world.setBlock(i + 19, j + 25, k + 49, PlaceCobbledDeepslate, 0, 2);
		world.setBlock(i + 17, j + 25, k + 50, PlaceCobbledDeepslate, 0, 2);
		world.setBlock(i + 18, j + 25, k + 50, PlaceCobbledDeepslate, 0, 2);
		world.setBlock(i + 17, j + 25, k + 51, PlaceCobbledDeepslate, 0, 2);
		world.setBlock(i + 18, j + 25, k + 51, PlaceCobbledDeepslate, 0, 2);
		world.setBlock(i + 19, j + 25, k + 51, PlaceCobbledDeepslate, 0, 2);
		world.setBlock(i + 17, j + 25, k + 52, PlaceCobbledDeepslate, 0, 2);
		world.setBlock(i + 18, j + 25, k + 52, PlaceCobbledDeepslate, 0, 2);
		world.setBlock(i + 19, j + 25, k + 52, PlaceCobbledDeepslate, 0, 2);
		world.setBlock(i + 17, j + 25, k + 53, PlaceCobbledDeepslate, 0, 2);
		world.setBlock(i + 18, j + 25, k + 53, PlaceCobbledDeepslate, 0, 2);
		world.setBlock(i + 16, j + 26, k + 18, PlaceDeepslateBricks, 0, 2);
		world.setBlock(i + 17, j + 26, k + 18, PlaceDeepslateBricks, 0, 2);
		world.setBlock(i + 18, j + 26, k + 18, PlaceCrackedDeepslateBricks, 1, 2);
		world.setBlock(i + 19, j + 26, k + 18, PlaceDeepslateBricks, 0, 2);
		world.setBlock(i + 20, j + 26, k + 18, PlaceCrackedDeepslateBricks, 1, 2);
		world.setBlock(i + 16, j + 26, k + 19, PlaceDeepslateBricks, 0, 2);
		world.setBlock(i + 17, j + 26, k + 19, PlaceDeepslateBricks, 0, 2);
		world.setBlock(i + 18, j + 26, k + 19, PlaceCrackedDeepslateBricks, 1, 2);
		world.setBlock(i + 19, j + 26, k + 19, PlaceDeepslateBricks, 0, 2);
		world.setBlock(i + 20, j + 26, k + 19, PlaceDeepslateBricks, 0, 2);
		world.setBlock(i + 16, j + 26, k + 20, PlaceCrackedDeepslateBricks, 1, 2);
		world.setBlock(i + 17, j + 26, k + 20, PlaceDeepslateBricks, 0, 2);
		world.setBlock(i + 18, j + 26, k + 20, PlaceCrackedDeepslateBricks, 1, 2);
		world.setBlock(i + 19, j + 26, k + 20, PlaceCrackedDeepslateBricks, 1, 2);
		world.setBlock(i + 20, j + 26, k + 20, PlaceDeepslateBricks, 0, 2);
		world.setBlock(i + 16, j + 26, k + 21, PlaceDeepslateBricks, 0, 2);
		world.setBlock(i + 17, j + 26, k + 21, PlaceDeepslateBricks, 0, 2);
		world.setBlock(i + 18, j + 26, k + 21, PlaceDeepslateBricks, 0, 2);
		world.setBlock(i + 19, j + 26, k + 21, PlaceCrackedDeepslateBricks, 1, 2);
		world.setBlock(i + 17, j + 26, k + 22, PlaceCrackedDeepslateTiles, 3, 2);
		world.setBlock(i + 18, j + 26, k + 22, PlaceDeepslateTiles, 2, 2);
		world.setBlock(i + 19, j + 26, k + 22, PlaceDeepslateTiles, 2, 2);
		world.setBlock(i + 20, j + 26, k + 22, PlaceCrackedDeepslateBricks, 1, 2);
		world.setBlock(i + 17, j + 26, k + 23, PlaceDeepslateTiles, 2, 2);
		world.setBlock(i + 18, j + 26, k + 23, PlaceDeepslateTiles, 2, 2);
		world.setBlock(i + 19, j + 26, k + 23, PlaceDeepslateTiles, 2, 2);
		world.setBlock(i + 20, j + 26, k + 23, PlaceCrackedDeepslateBricks, 1, 2);
		world.setBlock(i + 16, j + 26, k + 24, PlaceDeepslateBricks, 0, 2);
		world.setBlock(i + 17, j + 26, k + 24, PlaceDeepslateTiles, 2, 2);
		world.setBlock(i + 18, j + 26, k + 24, PlaceCrackedDeepslateTiles, 3, 2);
		world.setBlock(i + 19, j + 26, k + 24, PlaceDeepslateTiles, 2, 2);
		world.setBlock(i + 20, j + 26, k + 24, PlaceCrackedDeepslateBricks, 1, 2);
		world.setBlock(i + 16, j + 26, k + 25, PlaceDeepslateBricks, 0, 2);
		world.setBlock(i + 17, j + 26, k + 25, PlaceCrackedDeepslateTiles, 3, 2);
		world.setBlock(i + 18, j + 26, k + 25, PlaceDeepslateTiles, 2, 2);
		world.setBlock(i + 19, j + 26, k + 25, PlaceDeepslateTiles, 2, 2);
		world.setBlock(i + 20, j + 26, k + 25, PlaceDeepslateBricks, 0, 2);
		world.setBlock(i + 16, j + 26, k + 26, PlaceCrackedDeepslateBricks, 1, 2);
		world.setBlock(i + 17, j + 26, k + 26, PlaceDeepslateTiles, 2, 2);
		world.setBlock(i + 18, j + 26, k + 26, PlaceDeepslateTiles, 2, 2);
		world.setBlock(i + 19, j + 26, k + 26, PlaceDeepslateTiles, 2, 2);
		world.setBlock(i + 20, j + 26, k + 26, PlaceCrackedDeepslateBricks, 1, 2);
		world.setBlock(i + 16, j + 26, k + 27, PlaceCrackedDeepslateBricks, 1, 2);
		world.setBlock(i + 17, j + 26, k + 27, PlaceDeepslateTiles, 2, 2);
		world.setBlock(i + 18, j + 26, k + 27, PlaceDeepslateTiles, 2, 2);
		world.setBlock(i + 19, j + 26, k + 27, PlaceDeepslateTiles, 2, 2);
		world.setBlock(i + 20, j + 26, k + 27, PlaceDeepslateBricks, 0, 2);
		world.setBlock(i + 16, j + 26, k + 28, PlaceDeepslateBricks, 0, 2);
		world.setBlock(i + 17, j + 26, k + 28, PlaceCrackedDeepslateTiles, 3, 2);
		world.setBlock(i + 18, j + 26, k + 28, PlaceCrackedDeepslateTiles, 3, 2);
		world.setBlock(i + 19, j + 26, k + 28, PlaceDeepslateTiles, 2, 2);
		world.setBlock(i + 20, j + 26, k + 28, PlaceDeepslateBricks, 0, 2);
		world.setBlock(i + 16, j + 26, k + 29, PlaceDeepslateBricks, 0, 2);
		world.setBlock(i + 17, j + 26, k + 29, PlaceDeepslateTiles, 2, 2);
		world.setBlock(i + 18, j + 26, k + 29, PlaceDeepslateTiles, 2, 2);
		world.setBlock(i + 19, j + 26, k + 29, PlaceDeepslateTiles, 2, 2);
		world.setBlock(i + 20, j + 26, k + 29, PlaceDeepslateBricks, 0, 2);
		world.setBlock(i + 16, j + 26, k + 30, PlaceDeepslateBricks, 0, 2);
		world.setBlock(i + 17, j + 26, k + 30, PlaceCrackedDeepslateTiles, 3, 2);
		world.setBlock(i + 18, j + 26, k + 30, PlaceCrackedDeepslateTiles, 3, 2);
		world.setBlock(i + 19, j + 26, k + 30, PlaceDeepslateTiles, 2, 2);
		world.setBlock(i + 20, j + 26, k + 30, PlaceDeepslateBricks, 0, 2);
		world.setBlock(i + 16, j + 26, k + 31, PlaceCrackedDeepslateBricks, 1, 2);
		world.setBlock(i + 17, j + 26, k + 31, PlaceCrackedDeepslateTiles, 3, 2);
		world.setBlock(i + 18, j + 26, k + 31, PlaceDeepslateTiles, 2, 2);
		world.setBlock(i + 19, j + 26, k + 31, PlaceCrackedDeepslateTiles, 3, 2);
		world.setBlock(i + 20, j + 26, k + 31, PlaceDeepslateBricks, 0, 2);
		world.setBlock(i + 16, j + 26, k + 32, PlaceDeepslateBricks, 0, 2);
		world.setBlock(i + 17, j + 26, k + 32, PlaceDeepslateTiles, 2, 2);
		world.setBlock(i + 18, j + 26, k + 32, PlaceDeepslateTiles, 2, 2);
		world.setBlock(i + 19, j + 26, k + 32, PlaceDeepslateTiles, 2, 2);
		world.setBlock(i + 20, j + 26, k + 32, PlaceDeepslateBricks, 0, 2);
		world.setBlock(i + 16, j + 26, k + 33, PlaceDeepslateBricks, 0, 2);
		world.setBlock(i + 17, j + 26, k + 33, PlaceDeepslateTiles, 2, 2);
		world.setBlock(i + 18, j + 26, k + 33, PlaceDeepslateTiles, 2, 2);
		world.setBlock(i + 19, j + 26, k + 33, PlaceDeepslateTiles, 2, 2);
		world.setBlock(i + 20, j + 26, k + 33, PlaceDeepslateBricks, 0, 2);
		world.setBlock(i + 16, j + 26, k + 34, PlaceDeepslateBricks, 0, 2);
		world.setBlock(i + 17, j + 26, k + 34, PlaceCrackedDeepslateTiles, 3, 2);
		world.setBlock(i + 18, j + 26, k + 34, PlaceDeepslateTiles, 2, 2);
		world.setBlock(i + 19, j + 26, k + 34, PlaceDeepslateTiles, 2, 2);
		world.setBlock(i + 20, j + 26, k + 34, PlaceDeepslateBricks, 0, 2);
		world.setBlock(i + 16, j + 26, k + 35, PlaceCrackedDeepslateBricks, 1, 2);
		world.setBlock(i + 17, j + 26, k + 35, PlaceDeepslateTiles, 2, 2);
		world.setBlock(i + 18, j + 26, k + 35, PlaceDeepslateTiles, 2, 2);
		world.setBlock(i + 19, j + 26, k + 35, PlaceCrackedDeepslateTiles, 3, 2);
		world.setBlock(i + 20, j + 26, k + 35, PlaceDeepslateBricks, 0, 2);
		world.setBlock(i + 16, j + 26, k + 36, PlaceDeepslateBricks, 0, 2);
		world.setBlock(i + 17, j + 26, k + 36, PlaceCrackedDeepslateTiles, 3, 2);
		world.setBlock(i + 18, j + 26, k + 36, PlaceDeepslateTiles, 2, 2);
		world.setBlock(i + 19, j + 26, k + 36, PlaceDeepslateTiles, 2, 2);
		world.setBlock(i + 20, j + 26, k + 36, PlaceDeepslateBricks, 0, 2);
		world.setBlock(i + 16, j + 26, k + 37, PlaceDeepslateBricks, 0, 2);
		world.setBlock(i + 17, j + 26, k + 37, PlaceCrackedDeepslateTiles, 3, 2);
		world.setBlock(i + 18, j + 26, k + 37, PlaceDeepslateTiles, 2, 2);
		world.setBlock(i + 19, j + 26, k + 37, PlaceDeepslateTiles, 2, 2);
		world.setBlock(i + 20, j + 26, k + 37, PlaceDeepslateBricks, 0, 2);
		world.setBlock(i + 16, j + 26, k + 38, PlaceDeepslateBricks, 0, 2);
		world.setBlock(i + 17, j + 26, k + 38, PlaceCrackedDeepslateTiles, 3, 2);
		world.setBlock(i + 18, j + 26, k + 38, PlaceCrackedDeepslateTiles, 3, 2);
		world.setBlock(i + 19, j + 26, k + 38, PlaceDeepslateTiles, 2, 2);
		world.setBlock(i + 20, j + 26, k + 38, PlaceDeepslateBricks, 0, 2);
		world.setBlock(i + 16, j + 26, k + 39, PlaceDeepslateBricks, 0, 2);
		world.setBlock(i + 17, j + 26, k + 39, PlaceCrackedDeepslateTiles, 3, 2);
		world.setBlock(i + 18, j + 26, k + 39, PlaceDeepslateTiles, 2, 2);
		world.setBlock(i + 19, j + 26, k + 39, PlaceCrackedDeepslateTiles, 3, 2);
		world.setBlock(i + 20, j + 26, k + 39, PlaceCrackedDeepslateBricks, 1, 2);
		world.setBlock(i + 16, j + 26, k + 40, PlaceCrackedDeepslateBricks, 1, 2);
		world.setBlock(i + 17, j + 26, k + 40, PlaceDeepslateTiles, 2, 2);
		world.setBlock(i + 18, j + 26, k + 40, PlaceDeepslateTiles, 2, 2);
		world.setBlock(i + 19, j + 26, k + 40, PlaceDeepslateTiles, 2, 2);
		world.setBlock(i + 20, j + 26, k + 40, PlaceDeepslateBricks, 0, 2);
		world.setBlock(i + 16, j + 26, k + 41, PlaceDeepslateBricks, 0, 2);
		world.setBlock(i + 17, j + 26, k + 41, PlaceDeepslateTiles, 2, 2);
		world.setBlock(i + 18, j + 26, k + 41, PlaceDeepslateTiles, 2, 2);
		world.setBlock(i + 19, j + 26, k + 41, PlaceDeepslateTiles, 2, 2);
		world.setBlock(i + 20, j + 26, k + 41, PlaceCrackedDeepslateBricks, 1, 2);
		world.setBlock(i + 16, j + 26, k + 42, PlaceCrackedDeepslateBricks, 1, 2);
		world.setBlock(i + 17, j + 26, k + 42, PlaceDeepslateTiles, 2, 2);
		world.setBlock(i + 18, j + 26, k + 42, PlaceCrackedDeepslateTiles, 3, 2);
		world.setBlock(i + 19, j + 26, k + 42, PlaceDeepslateTiles, 2, 2);
		world.setBlock(i + 20, j + 26, k + 42, PlaceDeepslateBricks, 0, 2);
		world.setBlock(i + 16, j + 26, k + 43, PlaceDeepslateBricks, 0, 2);
		world.setBlock(i + 17, j + 26, k + 43, PlaceCrackedDeepslateTiles, 3, 2);
		world.setBlock(i + 18, j + 26, k + 43, PlaceDeepslateTiles, 2, 2);
		world.setBlock(i + 19, j + 26, k + 43, PlaceDeepslateTiles, 2, 2);
		world.setBlock(i + 20, j + 26, k + 43, PlaceDeepslateBricks, 0, 2);
		world.setBlock(i + 16, j + 26, k + 44, PlaceCrackedDeepslateBricks, 1, 2);
		world.setBlock(i + 17, j + 26, k + 44, PlaceDeepslateTiles, 2, 2);
		world.setBlock(i + 18, j + 26, k + 44, PlaceDeepslateTiles, 2, 2);
		world.setBlock(i + 19, j + 26, k + 44, PlaceCrackedDeepslateTiles, 3, 2);
		world.setBlock(i + 20, j + 26, k + 44, PlaceCrackedDeepslateBricks, 1, 2);
		world.setBlock(i + 16, j + 26, k + 45, PlaceCrackedDeepslateBricks, 1, 2);
		world.setBlock(i + 17, j + 26, k + 45, PlaceDeepslateTiles, 2, 2);
		world.setBlock(i + 18, j + 26, k + 45, PlaceDeepslateTiles, 2, 2);
		world.setBlock(i + 19, j + 26, k + 45, PlaceDeepslateTiles, 2, 2);
		world.setBlock(i + 20, j + 26, k + 45, PlaceDeepslateBricks, 0, 2);
		world.setBlock(i + 16, j + 26, k + 46, PlaceDeepslateBricks, 0, 2);
		world.setBlock(i + 17, j + 26, k + 46, PlaceCrackedDeepslateTiles, 3, 2);
		world.setBlock(i + 18, j + 26, k + 46, PlaceDeepslateTiles, 2, 2);
		world.setBlock(i + 20, j + 26, k + 46, PlaceDeepslateBricks, 0, 2);
		world.setBlock(i + 16, j + 26, k + 47, PlaceDeepslateBricks, 0, 2);
		world.setBlock(i + 17, j + 26, k + 47, PlaceDeepslateBricks, 0, 2);
		world.setBlock(i + 18, j + 26, k + 47, PlaceDeepslateBricks, 0, 2);
		world.setBlock(i + 19, j + 26, k + 47, PlaceDeepslateBricks, 0, 2);
		world.setBlock(i + 20, j + 26, k + 47, PlaceDeepslateBricks, 0, 2);
		world.setBlock(i + 16, j + 26, k + 48, PlaceDeepslateBricks, 0, 2);
		world.setBlock(i + 17, j + 26, k + 48, PlaceDeepslateBricks, 0, 2);
		world.setBlock(i + 18, j + 26, k + 48, PlaceCobbledDeepslate, 0, 2);
		world.setBlock(i + 19, j + 26, k + 48, PlaceCobbledDeepslate, 0, 2);
		world.setBlock(i + 20, j + 26, k + 48, PlaceCobbledDeepslate, 0, 2);
		world.setBlock(i + 16, j + 26, k + 49, PlaceCobbledDeepslate, 0, 2);
		world.setBlock(i + 17, j + 26, k + 49, PlaceCobbledDeepslate, 0, 2);
		world.setBlock(i + 18, j + 26, k + 49, PlaceCobbledDeepslate, 0, 2);
		world.setBlock(i + 19, j + 26, k + 49, PlaceCobbledDeepslate, 0, 2);
		world.setBlock(i + 20, j + 26, k + 49, PlaceCobbledDeepslate, 0, 2);
		world.setBlock(i + 16, j + 27, k + 18, PlaceDeepslateBricks, 0, 2);
		world.setBlock(i + 17, j + 27, k + 18, PlaceDeepslateBricks, 0, 2);
		world.setBlock(i + 18, j + 27, k + 18, PlaceDeepslateBricks, 0, 2);
		world.setBlock(i + 19, j + 27, k + 18, PlaceCrackedDeepslateBricks, 1, 2);
		world.setBlock(i + 20, j + 27, k + 18, PlaceDeepslateBricks, 0, 2);
		world.setBlock(i + 16, j + 27, k + 19, PlaceDeepslateBricks, 0, 2);
		world.setBlock(i + 17, j + 27, k + 19, PlaceDeepslateBricks, 0, 2);
		world.setBlock(i + 18, j + 27, k + 19, PlaceDeepslateBricks, 0, 2);
		world.setBlock(i + 19, j + 27, k + 19, PlaceDeepslateBricks, 0, 2);
		world.setBlock(i + 20, j + 27, k + 19, PlaceDeepslateBricks, 0, 2);
		world.setBlock(i + 16, j + 27, k + 20, PlaceCrackedDeepslateTiles, 3, 2);
		world.setBlock(i + 17, j + 27, k + 20, PlaceCrackedDeepslateTiles, 3, 2);
		world.setBlock(i + 18, j + 27, k + 20, PlaceDeepslateTiles, 2, 2);
		world.setBlock(i + 19, j + 27, k + 20, PlaceDeepslateTiles, 2, 2);
		world.setBlock(i + 20, j + 27, k + 20, PlaceDeepslateTiles, 2, 2);
		world.setBlock(i + 16, j + 27, k + 21, PlaceDeepslateBricks, 0, 2);
		world.setBlock(i + 17, j + 27, k + 21, PlaceCrackedDeepslateBricks, 1, 2);
		world.setBlock(i + 18, j + 27, k + 21, PlaceDeepslateBricks, 0, 2);
		world.setBlock(i + 19, j + 27, k + 21, PlaceDeepslateBricks, 0, 2);
		world.setBlock(i + 16, j + 27, k + 22, PlaceDeepslateBricks, 0, 2);
		world.setBlock(i + 17, j + 27, k + 22, PlaceDeepslateBricks, 0, 2);
		world.setBlock(i + 18, j + 27, k + 22, PlaceDeepslateBricks, 0, 2);
		world.setBlock(i + 19, j + 27, k + 22, PlaceDeepslateBricks, 0, 2);
		world.setBlock(i + 16, j + 27, k + 23, PlaceDeepslateBricks, 0, 2);
		world.setBlock(i + 17, j + 27, k + 23, PlaceCrackedDeepslateBricks, 1, 2);
		world.setBlock(i + 18, j + 27, k + 23, PlaceDeepslateBricks, 0, 2);
		world.setBlock(i + 19, j + 27, k + 23, PlaceDeepslateBricks, 0, 2);
		world.setBlock(i + 20, j + 27, k + 23, PlaceDeepslateBricks, 0, 2);
		world.setBlock(i + 16, j + 27, k + 24, PlaceDeepslateBricks, 0, 2);
		world.setBlock(i + 17, j + 27, k + 24, PlaceDeepslateBricks, 0, 2);
		world.setBlock(i + 18, j + 27, k + 24, PlaceDeepslateBricks, 0, 2);
		world.setBlock(i + 19, j + 27, k + 24, PlaceDeepslateBricks, 0, 2);
		world.setBlock(i + 20, j + 27, k + 24, PlaceDeepslateBricks, 0, 2);
		world.setBlock(i + 16, j + 27, k + 25, PlaceDeepslateBricks, 0, 2);
		world.setBlock(i + 17, j + 27, k + 25, PlaceDeepslateBricks, 0, 2);
		world.setBlock(i + 18, j + 27, k + 25, PlaceDeepslateBricks, 0, 2);
		world.setBlock(i + 19, j + 27, k + 25, PlaceDeepslateBricks, 0, 2);
		world.setBlock(i + 20, j + 27, k + 25, PlaceDeepslateBricks, 0, 2);
		world.setBlock(i + 16, j + 27, k + 26, PlaceCrackedDeepslateBricks, 1, 2);
		world.setBlock(i + 17, j + 27, k + 26, PlaceCrackedDeepslateBricks, 1, 2);
		world.setBlock(i + 18, j + 27, k + 26, PlaceCrackedDeepslateBricks, 1, 2);
		world.setBlock(i + 19, j + 27, k + 26, PlaceCrackedDeepslateBricks, 1, 2);
		world.setBlock(i + 20, j + 27, k + 26, PlaceCrackedDeepslateBricks, 1, 2);
		world.setBlock(i + 16, j + 27, k + 27, PlaceCrackedDeepslateBricks, 1, 2);
		world.setBlock(i + 17, j + 27, k + 27, PlaceCrackedDeepslateBricks, 1, 2);
		world.setBlock(i + 18, j + 27, k + 27, PlaceDeepslateBricks, 0, 2);
		world.setBlock(i + 19, j + 27, k + 27, PlaceCrackedDeepslateBricks, 1, 2);
		world.setBlock(i + 20, j + 27, k + 27, PlaceDeepslateBricks, 0, 2);
		world.setBlock(i + 16, j + 27, k + 28, PlaceCrackedDeepslateBricks, 1, 2);
		world.setBlock(i + 17, j + 27, k + 28, PlaceCrackedDeepslateBricks, 1, 2);
		world.setBlock(i + 18, j + 27, k + 28, PlaceCrackedDeepslateBricks, 1, 2);
		world.setBlock(i + 19, j + 27, k + 28, PlaceCrackedDeepslateBricks, 1, 2);
		world.setBlock(i + 20, j + 27, k + 28, PlaceDeepslateBricks, 0, 2);
		world.setBlock(i + 16, j + 27, k + 29, PlaceDeepslateBricks, 0, 2);
		world.setBlock(i + 17, j + 27, k + 29, PlaceCrackedDeepslateBricks, 1, 2);
		world.setBlock(i + 18, j + 27, k + 29, PlaceDeepslateBricks, 0, 2);
		world.setBlock(i + 19, j + 27, k + 29, PlaceDeepslateBricks, 0, 2);
		world.setBlock(i + 20, j + 27, k + 29, PlaceDeepslateBricks, 0, 2);
		world.setBlock(i + 16, j + 27, k + 30, PlaceDeepslateTiles, 2, 2);
		world.setBlock(i + 17, j + 27, k + 30, PlaceCrackedDeepslateTiles, 3, 2);
		world.setBlock(i + 18, j + 27, k + 30, PlaceCrackedDeepslateTiles, 3, 2);
		world.setBlock(i + 19, j + 27, k + 30, PlaceDeepslateTiles, 2, 2);
		world.setBlock(i + 20, j + 27, k + 30, PlaceCrackedDeepslateTiles, 3, 2);
		world.setBlock(i + 16, j + 27, k + 31, PlaceDeepslateTiles, 2, 2);
		world.setBlock(i + 17, j + 27, k + 31, PlaceDeepslateTiles, 2, 2);
		world.setBlock(i + 18, j + 27, k + 31, PlaceDeepslateTiles, 2, 2);
		world.setBlock(i + 19, j + 27, k + 31, PlaceCrackedDeepslateTiles, 3, 2);
		world.setBlock(i + 20, j + 27, k + 31, PlaceDeepslateTiles, 2, 2);
		world.setBlock(i + 16, j + 27, k + 32, PlaceDeepslateTiles, 2, 2);
		world.setBlock(i + 17, j + 27, k + 32, PlaceDeepslateTiles, 2, 2);
		world.setBlock(i + 18, j + 27, k + 32, PlaceDeepslateTiles, 2, 2);
		world.setBlock(i + 19, j + 27, k + 32, PlaceDeepslateTiles, 2, 2);
		world.setBlock(i + 20, j + 27, k + 32, PlaceCrackedDeepslateTiles, 3, 2);
		world.setBlock(i + 16, j + 27, k + 33, PlaceDeepslateTiles, 2, 2);
		world.setBlock(i + 17, j + 27, k + 33, PlaceDeepslateBricks, 0, 2);
		world.setBlock(i + 18, j + 27, k + 33, PlaceCrackedDeepslateBricks, 1, 2);
		world.setBlock(i + 19, j + 27, k + 33, PlaceCrackedDeepslateBricks, 1, 2);
		world.setBlock(i + 20, j + 27, k + 33, PlaceDeepslateBricks, 0, 2);
		world.setBlock(i + 16, j + 27, k + 34, PlaceDeepslateBricks, 0, 2);
		world.setBlock(i + 17, j + 27, k + 34, PlaceDeepslateBricks, 0, 2);
		world.setBlock(i + 18, j + 27, k + 34, PlaceDeepslateBricks, 0, 2);
		world.setBlock(i + 19, j + 27, k + 34, PlaceDeepslateBricks, 0, 2);
		world.setBlock(i + 20, j + 27, k + 34, PlaceDeepslateBricks, 0, 2);
		world.setBlock(i + 16, j + 27, k + 35, PlaceCrackedDeepslateBricks, 1, 2);
		world.setBlock(i + 17, j + 27, k + 35, PlaceDeepslateBricks, 0, 2);
		world.setBlock(i + 18, j + 27, k + 35, PlaceCrackedDeepslateBricks, 1, 2);
		world.setBlock(i + 19, j + 27, k + 35, PlaceDeepslateBricks, 0, 2);
		world.setBlock(i + 20, j + 27, k + 35, PlaceDeepslateBricks, 0, 2);
		world.setBlock(i + 16, j + 27, k + 36, PlaceDeepslateBricks, 0, 2);
		world.setBlock(i + 17, j + 27, k + 36, PlaceCrackedDeepslateBricks, 1, 2);
		world.setBlock(i + 18, j + 27, k + 36, PlaceDeepslateBricks, 0, 2);
		world.setBlock(i + 19, j + 27, k + 36, PlaceDeepslateBricks, 0, 2);
		world.setBlock(i + 20, j + 27, k + 36, PlaceDeepslateBricks, 0, 2);
		world.setBlock(i + 16, j + 27, k + 37, PlaceDeepslateBricks, 0, 2);
		world.setBlock(i + 17, j + 27, k + 37, PlaceCrackedDeepslateBricks, 1, 2);
		world.setBlock(i + 18, j + 27, k + 37, PlaceDeepslateBricks, 0, 2);
		world.setBlock(i + 19, j + 27, k + 37, PlaceDeepslateBricks, 0, 2);
		world.setBlock(i + 20, j + 27, k + 37, PlaceDeepslateBricks, 0, 2);
		world.setBlock(i + 16, j + 27, k + 38, PlaceDeepslateBricks, 0, 2);
		world.setBlock(i + 17, j + 27, k + 38, PlaceDeepslateBricks, 0, 2);
		world.setBlock(i + 18, j + 27, k + 38, PlaceCrackedDeepslateBricks, 1, 2);
		world.setBlock(i + 19, j + 27, k + 38, PlaceDeepslateBricks, 0, 2);
		world.setBlock(i + 20, j + 27, k + 38, PlaceDeepslateBricks, 0, 2);
		world.setBlock(i + 16, j + 27, k + 39, PlaceDeepslateBricks, 0, 2);
		world.setBlock(i + 17, j + 27, k + 39, PlaceCrackedDeepslateBricks, 1, 2);
		world.setBlock(i + 18, j + 27, k + 39, PlaceDeepslateBricks, 0, 2);
		world.setBlock(i + 19, j + 27, k + 39, PlaceDeepslateBricks, 0, 2);
		world.setBlock(i + 20, j + 27, k + 39, PlaceDeepslateBricks, 0, 2);
		world.setBlock(i + 16, j + 27, k + 40, PlaceCrackedDeepslateBricks, 1, 2);
		world.setBlock(i + 17, j + 27, k + 40, PlaceDeepslateBricks, 0, 2);
		world.setBlock(i + 18, j + 27, k + 40, PlaceCrackedDeepslateBricks, 1, 2);
		world.setBlock(i + 19, j + 27, k + 40, PlaceDeepslateBricks, 0, 2);
		world.setBlock(i + 20, j + 27, k + 40, PlaceDeepslateBricks, 0, 2);
		world.setBlock(i + 16, j + 27, k + 41, PlaceCrackedDeepslateBricks, 1, 2);
		world.setBlock(i + 17, j + 27, k + 41, PlaceDeepslateBricks, 0, 2);
		world.setBlock(i + 18, j + 27, k + 41, PlaceCrackedDeepslateBricks, 1, 2);
		world.setBlock(i + 19, j + 27, k + 41, PlaceCrackedDeepslateBricks, 1, 2);
		world.setBlock(i + 20, j + 27, k + 41, PlaceDeepslateBricks, 0, 2);
		world.setBlock(i + 16, j + 27, k + 42, PlaceDeepslateBricks, 0, 2);
		world.setBlock(i + 17, j + 27, k + 42, PlaceCrackedDeepslateBricks, 1, 2);
		world.setBlock(i + 18, j + 27, k + 42, PlaceCrackedDeepslateBricks, 1, 2);
		world.setBlock(i + 19, j + 27, k + 42, PlaceDeepslateBricks, 0, 2);
		world.setBlock(i + 20, j + 27, k + 42, PlaceDeepslateBricks, 0, 2);
		world.setBlock(i + 16, j + 27, k + 43, PlaceDeepslateBricks, 0, 2);
		world.setBlock(i + 17, j + 27, k + 43, PlaceDeepslateBricks, 0, 2);
		world.setBlock(i + 18, j + 27, k + 43, PlaceCrackedDeepslateBricks, 1, 2);
		world.setBlock(i + 19, j + 27, k + 43, PlaceDeepslateBricks, 0, 2);
		world.setBlock(i + 20, j + 27, k + 43, PlaceDeepslateBricks, 0, 2);
		world.setBlock(i + 16, j + 27, k + 44, PlaceDeepslateBricks, 0, 2);
		world.setBlock(i + 17, j + 27, k + 44, PlaceDeepslateBricks, 0, 2);
		world.setBlock(i + 18, j + 27, k + 44, PlaceDeepslateBricks, 0, 2);
		world.setBlock(i + 19, j + 27, k + 44, PlaceDeepslateBricks, 0, 2);
		world.setBlock(i + 20, j + 27, k + 44, PlaceDeepslateBricks, 0, 2);
		world.setBlock(i + 16, j + 27, k + 45, PlaceDeepslateBricks, 0, 2);
		world.setBlock(i + 17, j + 27, k + 45, PlaceDeepslateBricks, 0, 2);
		world.setBlock(i + 18, j + 27, k + 45, PlaceDeepslateBricks, 0, 2);
		world.setBlock(i + 19, j + 27, k + 45, PlaceDeepslateBricks, 0, 2);
		world.setBlock(i + 20, j + 27, k + 45, PlaceDeepslateBricks, 0, 2);
		world.setBlock(i + 16, j + 27, k + 46, PlaceCrackedDeepslateBricks, 1, 2);
		world.setBlock(i + 17, j + 27, k + 46, PlaceCrackedDeepslateBricks, 1, 2);
		world.setBlock(i + 18, j + 27, k + 46, PlaceDeepslateBricks, 0, 2);
		world.setBlock(i + 19, j + 27, k + 46, PlaceDeepslateBricks, 0, 2);
		world.setBlock(i + 20, j + 27, k + 46, PlaceDeepslateBricks, 0, 2);
		world.setBlock(i + 16, j + 27, k + 47, PlaceDeepslateBricks, 0, 2);
		world.setBlock(i + 17, j + 27, k + 47, PlaceDeepslateBricks, 0, 2);
		world.setBlock(i + 18, j + 27, k + 47, PlaceDeepslateBricks, 0, 2);
		world.setBlock(i + 19, j + 27, k + 47, PlaceCrackedDeepslateBricks, 1, 2);
		world.setBlock(i + 20, j + 27, k + 47, PlaceDeepslateBricks, 0, 2);
		world.setBlock(i + 16, j + 27, k + 48, PlaceDeepslateBricks, 0, 2);
		world.setBlock(i + 17, j + 27, k + 48, PlaceDeepslateBricks, 0, 2);
		world.setBlock(i + 18, j + 27, k + 48, PlaceDeepslateBricks, 0, 2);
		world.setBlock(i + 19, j + 27, k + 48, PlaceDeepslateBricks, 0, 2);
		world.setBlock(i + 20, j + 27, k + 48, PlaceCobbledDeepslate, 0, 2);
		world.setBlock(i + 16, j + 27, k + 49, PlaceCobbledDeepslate, 0, 2);
		world.setBlock(i + 17, j + 27, k + 49, PlaceCobbledDeepslate, 0, 2);
		world.setBlock(i + 18, j + 27, k + 49, PlaceCobbledDeepslate, 0, 2);
		world.setBlock(i + 19, j + 27, k + 49, PlaceCobbledDeepslate, 0, 2);
		world.setBlock(i + 20, j + 27, k + 49, PlaceCobbledDeepslate, 0, 2);
		world.setBlock(i + 16, j + 28, k + 18, PlaceDeepslateTiles, 2, 2);
		world.setBlock(i + 17, j + 28, k + 18, PlaceDeepslateBricks, 0, 2);
		world.setBlock(i + 16, j + 28, k + 19, PlaceDeepslateTiles, 2, 2);
		world.setBlock(i + 17, j + 28, k + 19, PlaceDeepslateTiles, 2, 2);
		world.setBlock(i + 18, j + 28, k + 19, PlaceDeepslateTiles, 2, 2);
		world.setBlock(i + 16, j + 28, k + 20, PlaceCrackedDeepslateTiles, 3, 2);
		world.setBlock(i + 17, j + 28, k + 20, PlaceDeepslateTiles, 2, 2);
		world.setBlock(i + 18, j + 28, k + 20, PlaceDeepslateTiles, 2, 2);
		world.setBlock(i + 19, j + 28, k + 20, PlaceCrackedDeepslateTiles, 3, 2);
		world.setBlock(i + 20, j + 28, k + 20, PlaceDeepslateTiles, 2, 2);
		world.setBlock(i + 16, j + 28, k + 21, PlaceCrackedDeepslateTiles, 3, 2);
		world.setBlock(i + 17, j + 28, k + 21, PlaceCrackedDeepslateTiles, 3, 2);
		world.setBlock(i + 18, j + 28, k + 21, PlaceCrackedDeepslateTiles, 3, 2);
		world.setBlock(i + 19, j + 28, k + 21, PlaceDeepslateTiles, 2, 2);
		world.setBlock(i + 16, j + 28, k + 22, PlaceCrackedDeepslateBricks, 1, 2);
		world.setBlock(i + 17, j + 28, k + 22, PlaceDeepslateBricks, 0, 2);
		world.setBlock(i + 18, j + 28, k + 22, PlaceDeepslateBricks, 0, 2);
		world.setBlock(i + 19, j + 28, k + 22, PlaceCrackedDeepslateBricks, 1, 2);
		world.setBlock(i + 16, j + 28, k + 23, PlaceDeepslateBricks, 0, 2);
		world.setBlock(i + 17, j + 28, k + 23, PlaceDeepslateBricks, 0, 2);
		world.setBlock(i + 18, j + 28, k + 23, PlaceDeepslateBricks, 0, 2);
		world.setBlock(i + 19, j + 28, k + 23, PlaceDeepslateBricks, 0, 2);
		world.setBlock(i + 20, j + 28, k + 23, PlaceCrackedDeepslateBricks, 1, 2);
		world.setBlock(i + 16, j + 28, k + 24, PlaceDeepslateBricks, 0, 2);
		world.setBlock(i + 17, j + 28, k + 24, PlaceDeepslateBricks, 0, 2);
		world.setBlock(i + 18, j + 28, k + 24, PlaceDeepslateBricks, 0, 2);
		world.setBlock(i + 19, j + 28, k + 24, PlaceCrackedDeepslateBricks, 1, 2);
		world.setBlock(i + 20, j + 28, k + 24, PlaceDeepslateBricks, 0, 2);
		world.setBlock(i + 16, j + 28, k + 25, PlaceDeepslateBricks, 0, 2);
		world.setBlock(i + 17, j + 28, k + 25, PlaceDeepslateTiles, 2, 2);
		world.setBlock(i + 18, j + 28, k + 25, PlaceCrackedDeepslateTiles, 3, 2);
		world.setBlock(i + 19, j + 28, k + 25, PlaceDeepslateTiles, 2, 2);
		world.setBlock(i + 20, j + 28, k + 25, PlaceCrackedDeepslateTiles, 3, 2);
		world.setBlock(i + 16, j + 28, k + 26, PlaceDeepslateBricks, 0, 2);
		world.setBlock(i + 17, j + 28, k + 26, PlaceDeepslateBricks, 0, 2);
		world.setBlock(i + 18, j + 28, k + 26, PlaceDeepslateBricks, 0, 2);
		world.setBlock(i + 19, j + 28, k + 26, PlaceDeepslateBricks, 0, 2);
		world.setBlock(i + 20, j + 28, k + 26, PlaceDeepslateBricks, 0, 2);
		world.setBlock(i + 16, j + 28, k + 27, PlaceDeepslateBricks, 0, 2);
		world.setBlock(i + 17, j + 28, k + 27, PlaceDeepslateBricks, 0, 2);
		world.setBlock(i + 18, j + 28, k + 27, PlaceDeepslateBricks, 0, 2);
		world.setBlock(i + 19, j + 28, k + 27, PlaceDeepslateBricks, 0, 2);
		world.setBlock(i + 20, j + 28, k + 27, PlaceDeepslateBricks, 0, 2);
		world.setBlock(i + 16, j + 28, k + 28, PlaceDeepslateBricks, 0, 2);
		world.setBlock(i + 17, j + 28, k + 28, PlaceCrackedDeepslateBricks, 1, 2);
		world.setBlock(i + 18, j + 28, k + 28, PlaceDeepslateBricks, 0, 2);
		world.setBlock(i + 19, j + 28, k + 28, PlaceDeepslateBricks, 0, 2);
		world.setBlock(i + 20, j + 28, k + 28, PlaceCrackedDeepslateBricks, 1, 2);
		world.setBlock(i + 16, j + 28, k + 29, PlaceDeepslateBricks, 0, 2);
		world.setBlock(i + 17, j + 28, k + 29, PlaceDeepslateBricks, 0, 2);
		world.setBlock(i + 18, j + 28, k + 29, PlaceDeepslateBricks, 0, 2);
		world.setBlock(i + 19, j + 28, k + 29, PlaceDeepslateBricks, 0, 2);
		world.setBlock(i + 20, j + 28, k + 29, PlaceCrackedDeepslateBricks, 1, 2);
		world.setBlock(i + 16, j + 28, k + 30, PlaceCrackedDeepslateBricks, 1, 2);
		world.setBlock(i + 17, j + 28, k + 30, PlaceDeepslateBricks, 0, 2);
		world.setBlock(i + 18, j + 28, k + 30, PlaceDeepslateTiles, 2, 2);
		world.setBlock(i + 19, j + 28, k + 30, PlaceCrackedDeepslateTiles, 3, 2);
		world.setBlock(i + 20, j + 28, k + 30, PlaceDeepslateTiles, 2, 2);
		world.setBlock(i + 16, j + 28, k + 31, PlaceCrackedDeepslateTiles, 3, 2);
		world.setBlock(i + 17, j + 28, k + 31, PlaceCrackedDeepslateBricks, 1, 2);
		world.setBlock(i + 18, j + 28, k + 31, PlaceDeepslateBricks, 0, 2);
		world.setBlock(i + 19, j + 28, k + 31, PlaceDeepslateBricks, 0, 2);
		world.setBlock(i + 20, j + 28, k + 31, PlaceDeepslateBricks, 0, 2);
		world.setBlock(i + 16, j + 28, k + 32, PlaceCrackedDeepslateBricks, 1, 2);
		world.setBlock(i + 17, j + 28, k + 32, PlaceDeepslateBricks, 0, 2);
		world.setBlock(i + 18, j + 28, k + 32, PlaceDeepslateBricks, 0, 2);
		world.setBlock(i + 19, j + 28, k + 32, PlaceDeepslateBricks, 0, 2);
		world.setBlock(i + 20, j + 28, k + 32, PlaceDeepslateBricks, 0, 2);
		world.setBlock(i + 16, j + 28, k + 33, PlaceCrackedDeepslateBricks, 1, 2);
		world.setBlock(i + 17, j + 28, k + 33, PlaceDeepslateBricks, 0, 2);
		world.setBlock(i + 18, j + 28, k + 33, PlaceDeepslateBricks, 0, 2);
		world.setBlock(i + 19, j + 28, k + 33, PlaceDeepslateBricks, 0, 2);
		world.setBlock(i + 20, j + 28, k + 33, PlaceDeepslateBricks, 0, 2);
		world.setBlock(i + 16, j + 28, k + 34, PlaceDeepslateBricks, 0, 2);
		world.setBlock(i + 17, j + 28, k + 34, PlaceCrackedDeepslateBricks, 1, 2);
		world.setBlock(i + 18, j + 28, k + 34, PlaceDeepslateBricks, 0, 2);
		world.setBlock(i + 19, j + 28, k + 34, PlaceCrackedDeepslateBricks, 1, 2);
		world.setBlock(i + 20, j + 28, k + 34, PlaceDeepslateBricks, 0, 2);
		world.setBlock(i + 16, j + 28, k + 35, PlaceDeepslateBricks, 0, 2);
		world.setBlock(i + 17, j + 28, k + 35, PlaceDeepslateBricks, 0, 2);
		world.setBlock(i + 18, j + 28, k + 35, PlaceDeepslateBricks, 0, 2);
		world.setBlock(i + 19, j + 28, k + 35, PlaceCrackedDeepslateBricks, 1, 2);
		world.setBlock(i + 20, j + 28, k + 35, PlaceDeepslateBricks, 0, 2);
		world.setBlock(i + 16, j + 28, k + 36, PlaceCrackedDeepslateBricks, 1, 2);
		world.setBlock(i + 17, j + 28, k + 36, PlaceDeepslateBricks, 0, 2);
		world.setBlock(i + 18, j + 28, k + 36, PlaceCrackedDeepslateBricks, 1, 2);
		world.setBlock(i + 19, j + 28, k + 36, PlaceDeepslateBricks, 0, 2);
		world.setBlock(i + 20, j + 28, k + 36, PlaceDeepslateBricks, 0, 2);
		world.setBlock(i + 16, j + 28, k + 37, PlaceCrackedDeepslateBricks, 1, 2);
		world.setBlock(i + 17, j + 28, k + 37, PlaceDeepslateBricks, 0, 2);
		world.setBlock(i + 18, j + 28, k + 37, PlaceDeepslateBricks, 0, 2);
		world.setBlock(i + 19, j + 28, k + 37, PlaceDeepslateBricks, 0, 2);
		world.setBlock(i + 20, j + 28, k + 37, PlaceDeepslateBricks, 0, 2);
		world.setBlock(i + 16, j + 28, k + 38, PlaceDeepslateBricks, 0, 2);
		world.setBlock(i + 17, j + 28, k + 38, PlaceCrackedDeepslateBricks, 1, 2);
		world.setBlock(i + 18, j + 28, k + 38, PlaceCrackedDeepslateBricks, 1, 2);
		world.setBlock(i + 19, j + 28, k + 38, PlaceCrackedDeepslateBricks, 1, 2);
		world.setBlock(i + 20, j + 28, k + 38, PlaceCrackedDeepslateBricks, 1, 2);
		world.setBlock(i + 16, j + 28, k + 39, PlaceDeepslateBricks, 0, 2);
		world.setBlock(i + 17, j + 28, k + 39, PlaceDeepslateBricks, 0, 2);
		world.setBlock(i + 18, j + 28, k + 39, PlaceDeepslateBricks, 0, 2);
		world.setBlock(i + 19, j + 28, k + 39, PlaceCrackedDeepslateBricks, 1, 2);
		world.setBlock(i + 20, j + 28, k + 39, PlaceDeepslateBricks, 0, 2);
		world.setBlock(i + 16, j + 28, k + 40, PlaceDeepslateBricks, 0, 2);
		world.setBlock(i + 17, j + 28, k + 40, PlaceDeepslateBricks, 0, 2);
		world.setBlock(i + 18, j + 28, k + 40, PlaceCrackedDeepslateBricks, 1, 2);
		world.setBlock(i + 19, j + 28, k + 40, PlaceDeepslateBricks, 0, 2);
		world.setBlock(i + 20, j + 28, k + 40, PlaceDeepslateBricks, 0, 2);
		world.setBlock(i + 16, j + 28, k + 41, PlaceDeepslateBricks, 0, 2);
		world.setBlock(i + 17, j + 28, k + 41, PlaceCrackedDeepslateBricks, 1, 2);
		world.setBlock(i + 18, j + 28, k + 41, PlaceDeepslateBricks, 0, 2);
		world.setBlock(i + 19, j + 28, k + 41, PlaceCrackedDeepslateBricks, 1, 2);
		world.setBlock(i + 20, j + 28, k + 41, PlaceCrackedDeepslateBricks, 1, 2);
		world.setBlock(i + 16, j + 28, k + 42, PlaceDeepslateBricks, 0, 2);
		world.setBlock(i + 17, j + 28, k + 42, PlaceDeepslateBricks, 0, 2);
		world.setBlock(i + 18, j + 28, k + 42, PlaceCrackedDeepslateBricks, 1, 2);
		world.setBlock(i + 19, j + 28, k + 42, PlaceCrackedDeepslateBricks, 1, 2);
		world.setBlock(i + 20, j + 28, k + 42, PlaceDeepslateBricks, 0, 2);
		world.setBlock(i + 16, j + 28, k + 43, PlaceDeepslateBricks, 0, 2);
		world.setBlock(i + 17, j + 28, k + 43, PlaceCrackedDeepslateBricks, 1, 2);
		world.setBlock(i + 18, j + 28, k + 43, PlaceDeepslateBricks, 0, 2);
		world.setBlock(i + 19, j + 28, k + 43, PlaceDeepslateBricks, 0, 2);
		world.setBlock(i + 20, j + 28, k + 43, PlaceCrackedDeepslateBricks, 1, 2);
		world.setBlock(i + 16, j + 28, k + 44, PlaceCrackedDeepslateBricks, 1, 2);
		world.setBlock(i + 17, j + 28, k + 44, PlaceDeepslateBricks, 0, 2);
		world.setBlock(i + 18, j + 28, k + 44, PlaceDeepslateBricks, 0, 2);
		world.setBlock(i + 19, j + 28, k + 44, PlaceDeepslateBricks, 0, 2);
		world.setBlock(i + 20, j + 28, k + 44, PlaceCrackedDeepslateBricks, 1, 2);
		world.setBlock(i + 16, j + 28, k + 45, PlaceDeepslateBricks, 0, 2);
		world.setBlock(i + 17, j + 28, k + 45, PlaceDeepslateBricks, 0, 2);
		world.setBlock(i + 18, j + 28, k + 45, PlaceDeepslateBricks, 0, 2);
		world.setBlock(i + 19, j + 28, k + 45, PlaceDeepslateBricks, 0, 2);
		world.setBlock(i + 20, j + 28, k + 45, PlaceDeepslateBricks, 0, 2);
		world.setBlock(i + 16, j + 28, k + 46, PlaceCrackedDeepslateBricks, 1, 2);
		world.setBlock(i + 17, j + 28, k + 46, PlaceDeepslateBricks, 0, 2);
		world.setBlock(i + 18, j + 28, k + 46, PlaceDeepslateBricks, 0, 2);
		world.setBlock(i + 19, j + 28, k + 46, PlaceDeepslateBricks, 0, 2);
		world.setBlock(i + 20, j + 28, k + 46, PlaceDeepslateBricks, 0, 2);
		world.setBlock(i + 16, j + 28, k + 47, PlaceDeepslateBricks, 0, 2);
		world.setBlock(i + 17, j + 28, k + 47, PlaceDeepslateBricks, 0, 2);
		world.setBlock(i + 18, j + 28, k + 47, PlaceDeepslateBricks, 0, 2);
		world.setBlock(i + 19, j + 28, k + 47, PlaceDeepslateBricks, 0, 2);
		world.setBlock(i + 16, j + 28, k + 48, PlaceDeepslateBricks, 0, 2);
		world.setBlock(i + 17, j + 28, k + 48, PlaceCrackedDeepslateBricks, 1, 2);
		world.setBlock(i + 18, j + 28, k + 48, PlaceDeepslateBricks, 0, 2);
		world.setBlock(i + 19, j + 28, k + 48, PlaceDeepslateBricks, 0, 2);
		world.setBlock(i + 20, j + 28, k + 48, PlaceDeepslateBricks, 0, 2);
		world.setBlock(i + 16, j + 28, k + 49, PlaceCobbledDeepslate, 0, 2);
		world.setBlock(i + 17, j + 28, k + 49, PlaceCobbledDeepslate, 0, 2);
		world.setBlock(i + 18, j + 28, k + 49, PlaceCobbledDeepslate, 0, 2);
		world.setBlock(i + 19, j + 28, k + 49, PlaceCobbledDeepslate, 0, 2);
		world.setBlock(i + 20, j + 28, k + 49, PlaceCobbledDeepslate, 0, 2);
		world.setBlock(i + 16, j + 29, k + 20, PlaceDeepslateTiles, 2, 2);
		world.setBlock(i + 17, j + 29, k + 20, PlaceDeepslateTiles, 2, 2);
		world.setBlock(i + 18, j + 29, k + 20, PlaceDeepslateTiles, 2, 2);
		world.setBlock(i + 19, j + 29, k + 20, PlaceDeepslateTiles, 2, 2);
		world.setBlock(i + 20, j + 29, k + 20, PlaceDeepslateTiles, 2, 2);
		world.setBlock(i + 16, j + 29, k + 21, PlaceDeepslateTiles, 2, 2);
