package com.NovaCraft.world.ancient_city;

import com.NovaCraft.config.ConfigsCompact;
import cpw.mods.fml.common.registry.GameRegistry;
import net.minecraft.world.gen.feature.*;
import net.minecraft.block.*;
import net.minecraft.world.*;
import java.util.*;

import com.NovaCraft.config.Configs;
import com.NovaCraft.registry.OtherModBlocks;
import com.NovaCraftBlocks.NovaCraftBlocks;

import cpw.mods.fml.common.Loader;
import net.minecraft.init.*;

public class AncientCityColumnBottomGen extends WorldGenerator
{
	public AncientCityColumnBottomGen() {

	}

	private Block PlaceDeepslate;

	private Block determineIfDeepslateExists(World world, int x, int y, int z) {
		Block existingBlock = world.getBlock(x, y, z);
		if (ConfigsCompact.enableDeepslate && Loader.isModLoaded("etfuturum")) {
			try {
				Block deepslate = GameRegistry.findBlock("etfuturum", "deepslate");
				if (deepslate != null && (existingBlock == null || existingBlock != deepslate)) {
					return deepslate;
				}
			} catch (Exception ex) {
				if (Configs.enableDebugMode) {
					System.out.println("Missing Deepslate from Et Futurum Requiem, using Grimstone instead...");
				}
				return NovaCraftBlocks.grimstone;
			}
		}

		return NovaCraftBlocks.grimstone;
	}
    
    public boolean generate(final World world, final Random random, final int i, final int j, final int k) {
    	PlaceDeepslate = determineIfDeepslateExists(world, i + 3, j + 0, k + 0);
    	
		world.setBlock(i + 3, j + 0, k + 0, PlaceDeepslate, 0, 2);
		world.setBlock(i + 4, j + 0, k + 0, PlaceDeepslate, 0, 2);
		world.setBlock(i + 5, j + 0, k + 0, PlaceDeepslate, 0, 2);
		world.setBlock(i + 6, j + 0, k + 0, PlaceDeepslate, 0, 2);
		world.setBlock(i + 7, j + 0, k + 0, PlaceDeepslate, 0, 2);
		world.setBlock(i + 8, j + 0, k + 0, PlaceDeepslate, 0, 2);
		world.setBlock(i + 9, j + 0, k + 0, PlaceDeepslate, 0, 2);
		world.setBlock(i + 10, j + 0, k + 0, PlaceDeepslate, 0, 2);
		world.setBlock(i + 11, j + 0, k + 0, PlaceDeepslate, 0, 2);
		world.setBlock(i + 12, j + 0, k + 0, PlaceDeepslate, 0, 2);
		world.setBlock(i + 13, j + 0, k + 0, PlaceDeepslate, 0, 2);
		world.setBlock(i + 14, j + 0, k + 0, PlaceDeepslate, 0, 2);
		world.setBlock(i + 15, j + 0, k + 0, PlaceDeepslate, 0, 2);
		world.setBlock(i + 16, j + 0, k + 0, PlaceDeepslate, 0, 2);
		world.setBlock(i + 17, j + 0, k + 0, PlaceDeepslate, 0, 2);
		world.setBlock(i + 2, j + 0, k + 1, PlaceDeepslate, 0, 2);
		world.setBlock(i + 3, j + 0, k + 1, PlaceDeepslate, 0, 2);
		world.setBlock(i + 4, j + 0, k + 1, PlaceDeepslate, 0, 2);
		world.setBlock(i + 5, j + 0, k + 1, PlaceDeepslate, 0, 2);
		world.setBlock(i + 6, j + 0, k + 1, PlaceDeepslate, 0, 2);
		world.setBlock(i + 7, j + 0, k + 1, PlaceDeepslate, 0, 2);
		world.setBlock(i + 8, j + 0, k + 1, PlaceDeepslate, 0, 2);
		world.setBlock(i + 9, j + 0, k + 1, PlaceDeepslate, 0, 2);
		world.setBlock(i + 10, j + 0, k + 1, PlaceDeepslate, 0, 2);
		world.setBlock(i + 11, j + 0, k + 1, PlaceDeepslate, 0, 2);
		world.setBlock(i + 12, j + 0, k + 1, PlaceDeepslate, 0, 2);
		world.setBlock(i + 13, j + 0, k + 1, PlaceDeepslate, 0, 2);
		world.setBlock(i + 14, j + 0, k + 1, PlaceDeepslate, 0, 2);
		world.setBlock(i + 15, j + 0, k + 1, PlaceDeepslate, 0, 2);
		world.setBlock(i + 16, j + 0, k + 1, PlaceDeepslate, 0, 2);
		world.setBlock(i + 17, j + 0, k + 1, PlaceDeepslate, 0, 2);
		world.setBlock(i + 18, j + 0, k + 1, PlaceDeepslate, 0, 2);
		world.setBlock(i + 1, j + 0, k + 2, PlaceDeepslate, 0, 2);
		world.setBlock(i + 2, j + 0, k + 2, PlaceDeepslate, 0, 2);
		world.setBlock(i + 3, j + 0, k + 2, PlaceDeepslate, 0, 2);
		world.setBlock(i + 4, j + 0, k + 2, PlaceDeepslate, 0, 2);
		world.setBlock(i + 5, j + 0, k + 2, PlaceDeepslate, 0, 2);
		world.setBlock(i + 6, j + 0, k + 2, PlaceDeepslate, 0, 2);
		world.setBlock(i + 7, j + 0, k + 2, PlaceDeepslate, 0, 2);
		world.setBlock(i + 8, j + 0, k + 2, PlaceDeepslate, 0, 2);
		world.setBlock(i + 9, j + 0, k + 2, PlaceDeepslate, 0, 2);
		world.setBlock(i + 10, j + 0, k + 2, PlaceDeepslate, 0, 2);
		world.setBlock(i + 11, j + 0, k + 2, PlaceDeepslate, 0, 2);
		world.setBlock(i + 12, j + 0, k + 2, PlaceDeepslate, 0, 2);
		world.setBlock(i + 13, j + 0, k + 2, PlaceDeepslate, 0, 2);
		world.setBlock(i + 14, j + 0, k + 2, PlaceDeepslate, 0, 2);
		world.setBlock(i + 15, j + 0, k + 2, PlaceDeepslate, 0, 2);
		world.setBlock(i + 16, j + 0, k + 2, PlaceDeepslate, 0, 2);
		world.setBlock(i + 17, j + 0, k + 2, PlaceDeepslate, 0, 2);
		world.setBlock(i + 18, j + 0, k + 2, PlaceDeepslate, 0, 2);
		world.setBlock(i + 0, j + 0, k + 3, PlaceDeepslate, 0, 2);
		world.setBlock(i + 1, j + 0, k + 3, PlaceDeepslate, 0, 2);
		world.setBlock(i + 2, j + 0, k + 3, PlaceDeepslate, 0, 2);
		world.setBlock(i + 3, j + 0, k + 3, PlaceDeepslate, 0, 2);
		world.setBlock(i + 4, j + 0, k + 3, PlaceDeepslate, 0, 2);
		world.setBlock(i + 5, j + 0, k + 3, PlaceDeepslate, 0, 2);
		world.setBlock(i + 6, j + 0, k + 3, PlaceDeepslate, 0, 2);
		world.setBlock(i + 7, j + 0, k + 3, PlaceDeepslate, 0, 2);
		world.setBlock(i + 8, j + 0, k + 3, PlaceDeepslate, 0, 2);
		world.setBlock(i + 9, j + 0, k + 3, PlaceDeepslate, 0, 2);
		world.setBlock(i + 10, j + 0, k + 3, PlaceDeepslate, 0, 2);
		world.setBlock(i + 11, j + 0, k + 3, PlaceDeepslate, 0, 2);
		world.setBlock(i + 12, j + 0, k + 3, PlaceDeepslate, 0, 2);
		world.setBlock(i + 13, j + 0, k + 3, PlaceDeepslate, 0, 2);
		world.setBlock(i + 14, j + 0, k + 3, PlaceDeepslate, 0, 2);
		world.setBlock(i + 15, j + 0, k + 3, PlaceDeepslate, 0, 2);
		world.setBlock(i + 16, j + 0, k + 3, PlaceDeepslate, 0, 2);
		world.setBlock(i + 17, j + 0, k + 3, PlaceDeepslate, 0, 2);
		world.setBlock(i + 18, j + 0, k + 3, PlaceDeepslate, 0, 2);
		world.setBlock(i + 0, j + 0, k + 4, PlaceDeepslate, 0, 2);
		world.setBlock(i + 1, j + 0, k + 4, PlaceDeepslate, 0, 2);
		world.setBlock(i + 2, j + 0, k + 4, PlaceDeepslate, 0, 2);
		world.setBlock(i + 3, j + 0, k + 4, PlaceDeepslate, 0, 2);
		world.setBlock(i + 4, j + 0, k + 4, PlaceDeepslate, 0, 2);
		world.setBlock(i + 5, j + 0, k + 4, PlaceDeepslate, 0, 2);
		world.setBlock(i + 6, j + 0, k + 4, PlaceDeepslate, 0, 2);
		world.setBlock(i + 7, j + 0, k + 4, PlaceDeepslate, 0, 2);
		world.setBlock(i + 8, j + 0, k + 4, PlaceDeepslate, 0, 2);
		world.setBlock(i + 9, j + 0, k + 4, PlaceDeepslate, 0, 2);
		world.setBlock(i + 10, j + 0, k + 4, PlaceDeepslate, 0, 2);
		world.setBlock(i + 11, j + 0, k + 4, PlaceDeepslate, 0, 2);
		world.setBlock(i + 12, j + 0, k + 4, PlaceDeepslate, 0, 2);
		world.setBlock(i + 13, j + 0, k + 4, PlaceDeepslate, 0, 2);
		world.setBlock(i + 14, j + 0, k + 4, PlaceDeepslate, 0, 2);
		world.setBlock(i + 15, j + 0, k + 4, PlaceDeepslate, 0, 2);
		world.setBlock(i + 16, j + 0, k + 4, PlaceDeepslate, 0, 2);
		world.setBlock(i + 17, j + 0, k + 4, PlaceDeepslate, 0, 2);
		world.setBlock(i + 18, j + 0, k + 4, PlaceDeepslate, 0, 2);
		world.setBlock(i + 0, j + 0, k + 5, PlaceDeepslate, 0, 2);
		world.setBlock(i + 1, j + 0, k + 5, PlaceDeepslate, 0, 2);
		world.setBlock(i + 2, j + 0, k + 5, PlaceDeepslate, 0, 2);
		world.setBlock(i + 3, j + 0, k + 5, PlaceDeepslate, 0, 2);
		world.setBlock(i + 4, j + 0, k + 5, PlaceDeepslate, 0, 2);
		world.setBlock(i + 5, j + 0, k + 5, PlaceDeepslate, 0, 2);
		world.setBlock(i + 6, j + 0, k + 5, PlaceDeepslate, 0, 2);
		world.setBlock(i + 7, j + 0, k + 5, PlaceDeepslate, 0, 2);
		world.setBlock(i + 8, j + 0, k + 5, PlaceDeepslate, 0, 2);
		world.setBlock(i + 9, j + 0, k + 5, PlaceDeepslate, 0, 2);
		world.setBlock(i + 10, j + 0, k + 5, PlaceDeepslate, 0, 2);
		world.setBlock(i + 11, j + 0, k + 5, PlaceDeepslate, 0, 2);
		world.setBlock(i + 12, j + 0, k + 5, PlaceDeepslate, 0, 2);
		world.setBlock(i + 13, j + 0, k + 5, PlaceDeepslate, 0, 2);
		world.setBlock(i + 14, j + 0, k + 5, PlaceDeepslate, 0, 2);
		world.setBlock(i + 15, j + 0, k + 5, PlaceDeepslate, 0, 2);
		world.setBlock(i + 16, j + 0, k + 5, PlaceDeepslate, 0, 2);
		world.setBlock(i + 17, j + 0, k + 5, PlaceDeepslate, 0, 2);
		world.setBlock(i + 18, j + 0, k + 5, PlaceDeepslate, 0, 2);
		world.setBlock(i + 0, j + 0, k + 6, PlaceDeepslate, 0, 2);
		world.setBlock(i + 1, j + 0, k + 6, PlaceDeepslate, 0, 2);
		world.setBlock(i + 2, j + 0, k + 6, PlaceDeepslate, 0, 2);
		world.setBlock(i + 3, j + 0, k + 6, PlaceDeepslate, 0, 2);
		world.setBlock(i + 4, j + 0, k + 6, PlaceDeepslate, 0, 2);
		world.setBlock(i + 5, j + 0, k + 6, PlaceDeepslate, 0, 2);
		world.setBlock(i + 6, j + 0, k + 6, PlaceDeepslate, 0, 2);
		world.setBlock(i + 7, j + 0, k + 6, PlaceDeepslate, 0, 2);
		world.setBlock(i + 8, j + 0, k + 6, PlaceDeepslate, 0, 2);
		world.setBlock(i + 9, j + 0, k + 6, PlaceDeepslate, 0, 2);
		world.setBlock(i + 10, j + 0, k + 6, PlaceDeepslate, 0, 2);
		world.setBlock(i + 11, j + 0, k + 6, PlaceDeepslate, 0, 2);
		world.setBlock(i + 12, j + 0, k + 6, PlaceDeepslate, 0, 2);
		world.setBlock(i + 13, j + 0, k + 6, PlaceDeepslate, 0, 2);
		world.setBlock(i + 14, j + 0, k + 6, PlaceDeepslate, 0, 2);
		world.setBlock(i + 15, j + 0, k + 6, PlaceDeepslate, 0, 2);
		world.setBlock(i + 16, j + 0, k + 6, PlaceDeepslate, 0, 2);
		world.setBlock(i + 17, j + 0, k + 6, PlaceDeepslate, 0, 2);
		world.setBlock(i + 18, j + 0, k + 6, PlaceDeepslate, 0, 2);
		world.setBlock(i + 0, j + 0, k + 7, PlaceDeepslate, 0, 2);
		world.setBlock(i + 1, j + 0, k + 7, PlaceDeepslate, 0, 2);
		world.setBlock(i + 2, j + 0, k + 7, PlaceDeepslate, 0, 2);
		world.setBlock(i + 3, j + 0, k + 7, PlaceDeepslate, 0, 2);
		world.setBlock(i + 4, j + 0, k + 7, PlaceDeepslate, 0, 2);
		world.setBlock(i + 5, j + 0, k + 7, PlaceDeepslate, 0, 2);
		world.setBlock(i + 6, j + 0, k + 7, PlaceDeepslate, 0, 2);
		world.setBlock(i + 7, j + 0, k + 7, PlaceDeepslate, 0, 2);
		world.setBlock(i + 8, j + 0, k + 7, PlaceDeepslate, 0, 2);
		world.setBlock(i + 9, j + 0, k + 7, PlaceDeepslate, 0, 2);
		world.setBlock(i + 10, j + 0, k + 7, PlaceDeepslate, 0, 2);
		world.setBlock(i + 11, j + 0, k + 7, PlaceDeepslate, 0, 2);
		world.setBlock(i + 12, j + 0, k + 7, PlaceDeepslate, 0, 2);
		world.setBlock(i + 13, j + 0, k + 7, PlaceDeepslate, 0, 2);
		world.setBlock(i + 14, j + 0, k + 7, PlaceDeepslate, 0, 2);
		world.setBlock(i + 15, j + 0, k + 7, PlaceDeepslate, 0, 2);
		world.setBlock(i + 16, j + 0, k + 7, PlaceDeepslate, 0, 2);
		world.setBlock(i + 17, j + 0, k + 7, PlaceDeepslate, 0, 2);
		world.setBlock(i + 18, j + 0, k + 7, PlaceDeepslate, 0, 2);
		world.setBlock(i + 0, j + 0, k + 8, PlaceDeepslate, 0, 2);
		world.setBlock(i + 1, j + 0, k + 8, PlaceDeepslate, 0, 2);
		world.setBlock(i + 2, j + 0, k + 8, PlaceDeepslate, 0, 2);
		world.setBlock(i + 3, j + 0, k + 8, PlaceDeepslate, 0, 2);
		world.setBlock(i + 4, j + 0, k + 8, PlaceDeepslate, 0, 2);
		world.setBlock(i + 5, j + 0, k + 8, PlaceDeepslate, 0, 2);
		world.setBlock(i + 6, j + 0, k + 8, PlaceDeepslate, 0, 2);
		world.setBlock(i + 7, j + 0, k + 8, PlaceDeepslate, 0, 2);
		world.setBlock(i + 8, j + 0, k + 8, PlaceDeepslate, 0, 2);
		world.setBlock(i + 9, j + 0, k + 8, PlaceDeepslate, 0, 2);
		world.setBlock(i + 10, j + 0, k + 8, PlaceDeepslate, 0, 2);
		world.setBlock(i + 11, j + 0, k + 8, PlaceDeepslate, 0, 2);
		world.setBlock(i + 12, j + 0, k + 8, PlaceDeepslate, 0, 2);
		world.setBlock(i + 13, j + 0, k + 8, PlaceDeepslate, 0, 2);
		world.setBlock(i + 14, j + 0, k + 8, PlaceDeepslate, 0, 2);
		world.setBlock(i + 15, j + 0, k + 8, PlaceDeepslate, 0, 2);
		world.setBlock(i + 16, j + 0, k + 8, PlaceDeepslate, 0, 2);
		world.setBlock(i + 17, j + 0, k + 8, PlaceDeepslate, 0, 2);
		world.setBlock(i + 18, j + 0, k + 8, PlaceDeepslate, 0, 2);
		world.setBlock(i + 19, j + 0, k + 8, PlaceDeepslate, 0, 2);
		world.setBlock(i + 0, j + 0, k + 9, PlaceDeepslate, 0, 2);
		world.setBlock(i + 1, j + 0, k + 9, PlaceDeepslate, 0, 2);
		world.setBlock(i + 2, j + 0, k + 9, PlaceDeepslate, 0, 2);
		world.setBlock(i + 3, j + 0, k + 9, PlaceDeepslate, 0, 2);
		world.setBlock(i + 4, j + 0, k + 9, PlaceDeepslate, 0, 2);
		world.setBlock(i + 5, j + 0, k + 9, PlaceDeepslate, 0, 2);
		world.setBlock(i + 6, j + 0, k + 9, PlaceDeepslate, 0, 2);
		world.setBlock(i + 7, j + 0, k + 9, PlaceDeepslate, 0, 2);
		world.setBlock(i + 8, j + 0, k + 9, PlaceDeepslate, 0, 2);
		world.setBlock(i + 9, j + 0, k + 9, PlaceDeepslate, 0, 2);
		world.setBlock(i + 10, j + 0, k + 9, PlaceDeepslate, 0, 2);
		world.setBlock(i + 11, j + 0, k + 9, PlaceDeepslate, 0, 2);
		world.setBlock(i + 12, j + 0, k + 9, PlaceDeepslate, 0, 2);
		world.setBlock(i + 13, j + 0, k + 9, PlaceDeepslate, 0, 2);
		world.setBlock(i + 14, j + 0, k + 9, PlaceDeepslate, 0, 2);
		world.setBlock(i + 15, j + 0, k + 9, PlaceDeepslate, 0, 2);
		world.setBlock(i + 16, j + 0, k + 9, PlaceDeepslate, 0, 2);
		world.setBlock(i + 17, j + 0, k + 9, PlaceDeepslate, 0, 2);
		world.setBlock(i + 18, j + 0, k + 9, PlaceDeepslate, 0, 2);
		world.setBlock(i + 19, j + 0, k + 9, PlaceDeepslate, 0, 2);
		world.setBlock(i + 20, j + 0, k + 9, PlaceDeepslate, 0, 2);
		world.setBlock(i + 0, j + 0, k + 10, PlaceDeepslate, 0, 2);
		world.setBlock(i + 1, j + 0, k + 10, PlaceDeepslate, 0, 2);
		world.setBlock(i + 2, j + 0, k + 10, PlaceDeepslate, 0, 2);
		world.setBlock(i + 3, j + 0, k + 10, PlaceDeepslate, 0, 2);
		world.setBlock(i + 4, j + 0, k + 10, PlaceDeepslate, 0, 2);
		world.setBlock(i + 5, j + 0, k + 10, PlaceDeepslate, 0, 2);
		world.setBlock(i + 6, j + 0, k + 10, PlaceDeepslate, 0, 2);
		world.setBlock(i + 7, j + 0, k + 10, PlaceDeepslate, 0, 2);
		world.setBlock(i + 8, j + 0, k + 10, PlaceDeepslate, 0, 2);
		world.setBlock(i + 9, j + 0, k + 10, PlaceDeepslate, 0, 2);
		world.setBlock(i + 10, j + 0, k + 10, PlaceDeepslate, 0, 2);
		world.setBlock(i + 11, j + 0, k + 10, PlaceDeepslate, 0, 2);
		world.setBlock(i + 12, j + 0, k + 10, PlaceDeepslate, 0, 2);
		world.setBlock(i + 13, j + 0, k + 10, PlaceDeepslate, 0, 2);
		world.setBlock(i + 14, j + 0, k + 10, PlaceDeepslate, 0, 2);
		world.setBlock(i + 15, j + 0, k + 10, PlaceDeepslate, 0, 2);
		world.setBlock(i + 16, j + 0, k + 10, PlaceDeepslate, 0, 2);
		world.setBlock(i + 17, j + 0, k + 10, PlaceDeepslate, 0, 2);
		world.setBlock(i + 18, j + 0, k + 10, PlaceDeepslate, 0, 2);
		world.setBlock(i + 19, j + 0, k + 10, PlaceDeepslate, 0, 2);
		world.setBlock(i + 20, j + 0, k + 10, PlaceDeepslate, 0, 2);
		world.setBlock(i + 21, j + 0, k + 10, PlaceDeepslate, 0, 2);
		world.setBlock(i + 0, j + 0, k + 11, PlaceDeepslate, 0, 2);
		world.setBlock(i + 1, j + 0, k + 11, PlaceDeepslate, 0, 2);
		world.setBlock(i + 2, j + 0, k + 11, PlaceDeepslate, 0, 2);
		world.setBlock(i + 3, j + 0, k + 11, PlaceDeepslate, 0, 2);
		world.setBlock(i + 4, j + 0, k + 11, PlaceDeepslate, 0, 2);
		world.setBlock(i + 5, j + 0, k + 11, PlaceDeepslate, 0, 2);
		world.setBlock(i + 6, j + 0, k + 11, PlaceDeepslate, 0, 2);
		world.setBlock(i + 7, j + 0, k + 11, PlaceDeepslate, 0, 2);
		world.setBlock(i + 8, j + 0, k + 11, PlaceDeepslate, 0, 2);
		world.setBlock(i + 9, j + 0, k + 11, PlaceDeepslate, 0, 2);
		world.setBlock(i + 10, j + 0, k + 11, PlaceDeepslate, 0, 2);
		world.setBlock(i + 11, j + 0, k + 11, PlaceDeepslate, 0, 2);
		world.setBlock(i + 12, j + 0, k + 11, PlaceDeepslate, 0, 2);
		world.setBlock(i + 13, j + 0, k + 11, PlaceDeepslate, 0, 2);
		world.setBlock(i + 14, j + 0, k + 11, PlaceDeepslate, 0, 2);
		world.setBlock(i + 15, j + 0, k + 11, PlaceDeepslate, 0, 2);
		world.setBlock(i + 16, j + 0, k + 11, PlaceDeepslate, 0, 2);
		world.setBlock(i + 17, j + 0, k + 11, PlaceDeepslate, 0, 2);
		world.setBlock(i + 18, j + 0, k + 11, PlaceDeepslate, 0, 2);
		world.setBlock(i + 19, j + 0, k + 11, PlaceDeepslate, 0, 2);
		world.setBlock(i + 20, j + 0, k + 11, PlaceDeepslate, 0, 2);
		world.setBlock(i + 21, j + 0, k + 11, PlaceDeepslate, 0, 2);
		world.setBlock(i + 0, j + 0, k + 12, PlaceDeepslate, 0, 2);
		world.setBlock(i + 1, j + 0, k + 12, PlaceDeepslate, 0, 2);
		world.setBlock(i + 2, j + 0, k + 12, PlaceDeepslate, 0, 2);
		world.setBlock(i + 3, j + 0, k + 12, PlaceDeepslate, 0, 2);
		world.setBlock(i + 4, j + 0, k + 12, PlaceDeepslate, 0, 2);
		world.setBlock(i + 5, j + 0, k + 12, PlaceDeepslate, 0, 2);
		world.setBlock(i + 6, j + 0, k + 12, PlaceDeepslate, 0, 2);
		world.setBlock(i + 7, j + 0, k + 12, PlaceDeepslate, 0, 2);
		world.setBlock(i + 8, j + 0, k + 12, PlaceDeepslate, 0, 2);
		world.setBlock(i + 9, j + 0, k + 12, PlaceDeepslate, 0, 2);
		world.setBlock(i + 10, j + 0, k + 12, PlaceDeepslate, 0, 2);
		world.setBlock(i + 11, j + 0, k + 12, PlaceDeepslate, 0, 2);
		world.setBlock(i + 12, j + 0, k + 12, PlaceDeepslate, 0, 2);
		world.setBlock(i + 13, j + 0, k + 12, PlaceDeepslate, 0, 2);
		world.setBlock(i + 14, j + 0, k + 12, PlaceDeepslate, 0, 2);
		world.setBlock(i + 15, j + 0, k + 12, PlaceDeepslate, 0, 2);
		world.setBlock(i + 16, j + 0, k + 12, PlaceDeepslate, 0, 2);
		world.setBlock(i + 17, j + 0, k + 12, PlaceDeepslate, 0, 2);
		world.setBlock(i + 18, j + 0, k + 12, PlaceDeepslate, 0, 2);
		world.setBlock(i + 19, j + 0, k + 12, PlaceDeepslate, 0, 2);
		world.setBlock(i + 20, j + 0, k + 12, PlaceDeepslate, 0, 2);
		world.setBlock(i + 21, j + 0, k + 12, PlaceDeepslate, 0, 2);
		world.setBlock(i + 0, j + 0, k + 13, PlaceDeepslate, 0, 2);
		world.setBlock(i + 1, j + 0, k + 13, PlaceDeepslate, 0, 2);
		world.setBlock(i + 2, j + 0, k + 13, PlaceDeepslate, 0, 2);
		world.setBlock(i + 3, j + 0, k + 13, PlaceDeepslate, 0, 2);
		world.setBlock(i + 4, j + 0, k + 13, PlaceDeepslate, 0, 2);
		world.setBlock(i + 5, j + 0, k + 13, PlaceDeepslate, 0, 2);
		world.setBlock(i + 6, j + 0, k + 13, PlaceDeepslate, 0, 2);
		world.setBlock(i + 7, j + 0, k + 13, PlaceDeepslate, 0, 2);
		world.setBlock(i + 8, j + 0, k + 13, PlaceDeepslate, 0, 2);
		world.setBlock(i + 9, j + 0, k + 13, PlaceDeepslate, 0, 2);
		world.setBlock(i + 10, j + 0, k + 13, PlaceDeepslate, 0, 2);
		world.setBlock(i + 11, j + 0, k + 13, PlaceDeepslate, 0, 2);
		world.setBlock(i + 12, j + 0, k + 13, PlaceDeepslate, 0, 2);
		world.setBlock(i + 13, j + 0, k + 13, PlaceDeepslate, 0, 2);
		world.setBlock(i + 14, j + 0, k + 13, PlaceDeepslate, 0, 2);
		world.setBlock(i + 15, j + 0, k + 13, PlaceDeepslate, 0, 2);
		world.setBlock(i + 16, j + 0, k + 13, PlaceDeepslate, 0, 2);
		world.setBlock(i + 17, j + 0, k + 13, PlaceDeepslate, 0, 2);
		world.setBlock(i + 18, j + 0, k + 13, PlaceDeepslate, 0, 2);
		world.setBlock(i + 19, j + 0, k + 13, PlaceDeepslate, 0, 2);
		world.setBlock(i + 20, j + 0, k + 13, PlaceDeepslate, 0, 2);
		world.setBlock(i + 21, j + 0, k + 13, PlaceDeepslate, 0, 2);
		world.setBlock(i + 0, j + 0, k + 14, PlaceDeepslate, 0, 2);
		world.setBlock(i + 1, j + 0, k + 14, PlaceDeepslate, 0, 2);
		world.setBlock(i + 2, j + 0, k + 14, PlaceDeepslate, 0, 2);
		world.setBlock(i + 3, j + 0, k + 14, PlaceDeepslate, 0, 2);
		world.setBlock(i + 4, j + 0, k + 14, PlaceDeepslate, 0, 2);
		world.setBlock(i + 5, j + 0, k + 14, PlaceDeepslate, 0, 2);
		world.setBlock(i + 6, j + 0, k + 14, PlaceDeepslate, 0, 2);
		world.setBlock(i + 7, j + 0, k + 14, PlaceDeepslate, 0, 2);
		world.setBlock(i + 8, j + 0, k + 14, PlaceDeepslate, 0, 2);
		world.setBlock(i + 9, j + 0, k + 14, PlaceDeepslate, 0, 2);
		world.setBlock(i + 10, j + 0, k + 14, PlaceDeepslate, 0, 2);
		world.setBlock(i + 11, j + 0, k + 14, PlaceDeepslate, 0, 2);
		world.setBlock(i + 12, j + 0, k + 14, PlaceDeepslate, 0, 2);
		world.setBlock(i + 13, j + 0, k + 14, PlaceDeepslate, 0, 2);
		world.setBlock(i + 14, j + 0, k + 14, PlaceDeepslate, 0, 2);
		world.setBlock(i + 15, j + 0, k + 14, PlaceDeepslate, 0, 2);
		world.setBlock(i + 16, j + 0, k + 14, PlaceDeepslate, 0, 2);
		world.setBlock(i + 17, j + 0, k + 14, PlaceDeepslate, 0, 2);
		world.setBlock(i + 18, j + 0, k + 14, PlaceDeepslate, 0, 2);
		world.setBlock(i + 19, j + 0, k + 14, PlaceDeepslate, 0, 2);
		world.setBlock(i + 20, j + 0, k + 14, PlaceDeepslate, 0, 2);
		world.setBlock(i + 21, j + 0, k + 14, PlaceDeepslate, 0, 2);
		world.setBlock(i + 0, j + 0, k + 15, PlaceDeepslate, 0, 2);
		world.setBlock(i + 1, j + 0, k + 15, PlaceDeepslate, 0, 2);
		world.setBlock(i + 2, j + 0, k + 15, PlaceDeepslate, 0, 2);
		world.setBlock(i + 3, j + 0, k + 15, PlaceDeepslate, 0, 2);
		world.setBlock(i + 4, j + 0, k + 15, PlaceDeepslate, 0, 2);
		world.setBlock(i + 5, j + 0, k + 15, PlaceDeepslate, 0, 2);
		world.setBlock(i + 6, j + 0, k + 15, PlaceDeepslate, 0, 2);
		world.setBlock(i + 7, j + 0, k + 15, PlaceDeepslate, 0, 2);
		world.setBlock(i + 8, j + 0, k + 15, PlaceDeepslate, 0, 2);
		world.setBlock(i + 9, j + 0, k + 15, PlaceDeepslate, 0, 2);
		world.setBlock(i + 10, j + 0, k + 15, PlaceDeepslate, 0, 2);
		world.setBlock(i + 11, j + 0, k + 15, PlaceDeepslate, 0, 2);
		world.setBlock(i + 12, j + 0, k + 15, PlaceDeepslate, 0, 2);
		world.setBlock(i + 13, j + 0, k + 15, PlaceDeepslate, 0, 2);
		world.setBlock(i + 14, j + 0, k + 15, PlaceDeepslate, 0, 2);
		world.setBlock(i + 15, j + 0, k + 15, PlaceDeepslate, 0, 2);
		world.setBlock(i + 16, j + 0, k + 15, PlaceDeepslate, 0, 2);
		world.setBlock(i + 17, j + 0, k + 15, PlaceDeepslate, 0, 2);
		world.setBlock(i + 18, j + 0, k + 15, PlaceDeepslate, 0, 2);
		world.setBlock(i + 19, j + 0, k + 15, PlaceDeepslate, 0, 2);
		world.setBlock(i + 20, j + 0, k + 15, PlaceDeepslate, 0, 2);
		world.setBlock(i + 21, j + 0, k + 15, PlaceDeepslate, 0, 2);
		world.setBlock(i + 0, j + 0, k + 16, PlaceDeepslate, 0, 2);
		world.setBlock(i + 1, j + 0, k + 16, PlaceDeepslate, 0, 2);
		world.setBlock(i + 2, j + 0, k + 16, PlaceDeepslate, 0, 2);
		world.setBlock(i + 3, j + 0, k + 16, PlaceDeepslate, 0, 2);
		world.setBlock(i + 4, j + 0, k + 16, PlaceDeepslate, 0, 2);
		world.setBlock(i + 5, j + 0, k + 16, PlaceDeepslate, 0, 2);
		world.setBlock(i + 6, j + 0, k + 16, PlaceDeepslate, 0, 2);
		world.setBlock(i + 7, j + 0, k + 16, PlaceDeepslate, 0, 2);
		world.setBlock(i + 8, j + 0, k + 16, PlaceDeepslate, 0, 2);
		world.setBlock(i + 9, j + 0, k + 16, PlaceDeepslate, 0, 2);
		world.setBlock(i + 10, j + 0, k + 16, PlaceDeepslate, 0, 2);
		world.setBlock(i + 11, j + 0, k + 16, PlaceDeepslate, 0, 2);
		world.setBlock(i + 12, j + 0, k + 16, PlaceDeepslate, 0, 2);
		world.setBlock(i + 13, j + 0, k + 16, PlaceDeepslate, 0, 2);
		world.setBlock(i + 14, j + 0, k + 16, PlaceDeepslate, 0, 2);
		world.setBlock(i + 15, j + 0, k + 16, PlaceDeepslate, 0, 2);
		world.setBlock(i + 16, j + 0, k + 16, PlaceDeepslate, 0, 2);
		world.setBlock(i + 17, j + 0, k + 16, PlaceDeepslate, 0, 2);
		world.setBlock(i + 18, j + 0, k + 16, PlaceDeepslate, 0, 2);
		world.setBlock(i + 19, j + 0, k + 16, PlaceDeepslate, 0, 2);
		world.setBlock(i + 20, j + 0, k + 16, PlaceDeepslate, 0, 2);
		world.setBlock(i + 21, j + 0, k + 16, PlaceDeepslate, 0, 2);
		world.setBlock(i + 0, j + 0, k + 17, PlaceDeepslate, 0, 2);
		world.setBlock(i + 1, j + 0, k + 17, PlaceDeepslate, 0, 2);
		world.setBlock(i + 2, j + 0, k + 17, PlaceDeepslate, 0, 2);
		world.setBlock(i + 3, j + 0, k + 17, PlaceDeepslate, 0, 2);
		world.setBlock(i + 4, j + 0, k + 17, PlaceDeepslate, 0, 2);
		world.setBlock(i + 5, j + 0, k + 17, PlaceDeepslate, 0, 2);
		world.setBlock(i + 6, j + 0, k + 17, PlaceDeepslate, 0, 2);
		world.setBlock(i + 7, j + 0, k + 17, PlaceDeepslate, 0, 2);
		world.setBlock(i + 8, j + 0, k + 17, PlaceDeepslate, 0, 2);
		world.setBlock(i + 9, j + 0, k + 17, PlaceDeepslate, 0, 2);
		world.setBlock(i + 10, j + 0, k + 17, PlaceDeepslate, 0, 2);
		world.setBlock(i + 11, j + 0, k + 17, PlaceDeepslate, 0, 2);
		world.setBlock(i + 12, j + 0, k + 17, PlaceDeepslate, 0, 2);
		world.setBlock(i + 13, j + 0, k + 17, PlaceDeepslate, 0, 2);
		world.setBlock(i + 14, j + 0, k + 17, PlaceDeepslate, 0, 2);
		world.setBlock(i + 15, j + 0, k + 17, PlaceDeepslate, 0, 2);
		world.setBlock(i + 16, j + 0, k + 17, PlaceDeepslate, 0, 2);
		world.setBlock(i + 17, j + 0, k + 17, PlaceDeepslate, 0, 2);
		world.setBlock(i + 18, j + 0, k + 17, PlaceDeepslate, 0, 2);
		world.setBlock(i + 19, j + 0, k + 17, PlaceDeepslate, 0, 2);
		world.setBlock(i + 20, j + 0, k + 17, PlaceDeepslate, 0, 2);
		world.setBlock(i + 21, j + 0, k + 17, PlaceDeepslate, 0, 2);
		world.setBlock(i + 1, j + 0, k + 18, PlaceDeepslate, 0, 2);
		world.setBlock(i + 2, j + 0, k + 18, PlaceDeepslate, 0, 2);
		world.setBlock(i + 3, j + 0, k + 18, PlaceDeepslate, 0, 2);
		world.setBlock(i + 4, j + 0, k + 18, PlaceDeepslate, 0, 2);
		world.setBlock(i + 5, j + 0, k + 18, PlaceDeepslate, 0, 2);
		world.setBlock(i + 6, j + 0, k + 18, PlaceDeepslate, 0, 2);
		world.setBlock(i + 7, j + 0, k + 18, PlaceDeepslate, 0, 2);
		world.setBlock(i + 8, j + 0, k + 18, PlaceDeepslate, 0, 2);
		world.setBlock(i + 9, j + 0, k + 18, PlaceDeepslate, 0, 2);
		world.setBlock(i + 10, j + 0, k + 18, PlaceDeepslate, 0, 2);
		world.setBlock(i + 11, j + 0, k + 18, PlaceDeepslate, 0, 2);
		world.setBlock(i + 12, j + 0, k + 18, PlaceDeepslate, 0, 2);
		world.setBlock(i + 13, j + 0, k + 18, PlaceDeepslate, 0, 2);
		world.setBlock(i + 14, j + 0, k + 18, PlaceDeepslate, 0, 2);
		world.setBlock(i + 15, j + 0, k + 18, PlaceDeepslate, 0, 2);
		world.setBlock(i + 16, j + 0, k + 18, PlaceDeepslate, 0, 2);
		world.setBlock(i + 17, j + 0, k + 18, PlaceDeepslate, 0, 2);
		world.setBlock(i + 18, j + 0, k + 18, PlaceDeepslate, 0, 2);
		world.setBlock(i + 19, j + 0, k + 18, PlaceDeepslate, 0, 2);
		world.setBlock(i + 20, j + 0, k + 18, PlaceDeepslate, 0, 2);
		world.setBlock(i + 21, j + 0, k + 18, PlaceDeepslate, 0, 2);
		world.setBlock(i + 2, j + 0, k + 19, PlaceDeepslate, 0, 2);
		world.setBlock(i + 3, j + 0, k + 19, PlaceDeepslate, 0, 2);
		world.setBlock(i + 4, j + 0, k + 19, PlaceDeepslate, 0, 2);
		world.setBlock(i + 5, j + 0, k + 19, PlaceDeepslate, 0, 2);
		world.setBlock(i + 6, j + 0, k + 19, PlaceDeepslate, 0, 2);
		world.setBlock(i + 7, j + 0, k + 19, PlaceDeepslate, 0, 2);
		world.setBlock(i + 8, j + 0, k + 19, PlaceDeepslate, 0, 2);
		world.setBlock(i + 9, j + 0, k + 19, PlaceDeepslate, 0, 2);
		world.setBlock(i + 10, j + 0, k + 19, PlaceDeepslate, 0, 2);
		world.setBlock(i + 11, j + 0, k + 19, PlaceDeepslate, 0, 2);
		world.setBlock(i + 12, j + 0, k + 19, PlaceDeepslate, 0, 2);
		world.setBlock(i + 13, j + 0, k + 19, PlaceDeepslate, 0, 2);
		world.setBlock(i + 14, j + 0, k + 19, PlaceDeepslate, 0, 2);
		world.setBlock(i + 15, j + 0, k + 19, PlaceDeepslate, 0, 2);
		world.setBlock(i + 16, j + 0, k + 19, PlaceDeepslate, 0, 2);
		world.setBlock(i + 17, j + 0, k + 19, PlaceDeepslate, 0, 2);
		world.setBlock(i + 18, j + 0, k + 19, PlaceDeepslate, 0, 2);
		world.setBlock(i + 19, j + 0, k + 19, PlaceDeepslate, 0, 2);
		world.setBlock(i + 20, j + 0, k + 19, PlaceDeepslate, 0, 2);
		world.setBlock(i + 3, j + 1, k + 0, PlaceDeepslate, 0, 2);
		world.setBlock(i + 4, j + 1, k + 0, PlaceDeepslate, 0, 2);
		world.setBlock(i + 5, j + 1, k + 0, PlaceDeepslate, 0, 2);
		world.setBlock(i + 6, j + 1, k + 0, PlaceDeepslate, 0, 2);
		world.setBlock(i + 7, j + 1, k + 0, PlaceDeepslate, 0, 2);
		world.setBlock(i + 8, j + 1, k + 0, PlaceDeepslate, 0, 2);
		world.setBlock(i + 9, j + 1, k + 0, PlaceDeepslate, 0, 2);
		world.setBlock(i + 10, j + 1, k + 0, PlaceDeepslate, 0, 2);
		world.setBlock(i + 11, j + 1, k + 0, PlaceDeepslate, 0, 2);
		world.setBlock(i + 12, j + 1, k + 0, PlaceDeepslate, 0, 2);
		world.setBlock(i + 13, j + 1, k + 0, PlaceDeepslate, 0, 2);
		world.setBlock(i + 14, j + 1, k + 0, PlaceDeepslate, 0, 2);
		world.setBlock(i + 15, j + 1, k + 0, PlaceDeepslate, 0, 2);
		world.setBlock(i + 16, j + 1, k + 0, PlaceDeepslate, 0, 2);
		world.setBlock(i + 17, j + 1, k + 0, PlaceDeepslate, 0, 2);
		world.setBlock(i + 2, j + 1, k + 1, PlaceDeepslate, 0, 2);
		world.setBlock(i + 3, j + 1, k + 1, PlaceDeepslate, 0, 2);
		world.setBlock(i + 4, j + 1, k + 1, PlaceDeepslate, 0, 2);
		world.setBlock(i + 5, j + 1, k + 1, PlaceDeepslate, 0, 2);
		world.setBlock(i + 6, j + 1, k + 1, PlaceDeepslate, 0, 2);
		world.setBlock(i + 7, j + 1, k + 1, PlaceDeepslate, 0, 2);
		world.setBlock(i + 8, j + 1, k + 1, PlaceDeepslate, 0, 2);
		world.setBlock(i + 9, j + 1, k + 1, PlaceDeepslate, 0, 2);
		world.setBlock(i + 10, j + 1, k + 1, PlaceDeepslate, 0, 2);
		world.setBlock(i + 11, j + 1, k + 1, PlaceDeepslate, 0, 2);
		world.setBlock(i + 12, j + 1, k + 1, PlaceDeepslate, 0, 2);
		world.setBlock(i + 13, j + 1, k + 1, PlaceDeepslate, 0, 2);
		world.setBlock(i + 14, j + 1, k + 1, PlaceDeepslate, 0, 2);
		world.setBlock(i + 15, j + 1, k + 1, PlaceDeepslate, 0, 2);
		world.setBlock(i + 16, j + 1, k + 1, PlaceDeepslate, 0, 2);
		world.setBlock(i + 17, j + 1, k + 1, PlaceDeepslate, 0, 2);
		world.setBlock(i + 18, j + 1, k + 1, PlaceDeepslate, 0, 2);
		world.setBlock(i + 1, j + 1, k + 2, PlaceDeepslate, 0, 2);
		world.setBlock(i + 2, j + 1, k + 2, PlaceDeepslate, 0, 2);
		world.setBlock(i + 3, j + 1, k + 2, PlaceDeepslate, 0, 2);
		world.setBlock(i + 4, j + 1, k + 2, PlaceDeepslate, 0, 2);
		world.setBlock(i + 5, j + 1, k + 2, PlaceDeepslate, 0, 2);
		world.setBlock(i + 6, j + 1, k + 2, PlaceDeepslate, 0, 2);
		world.setBlock(i + 7, j + 1, k + 2, PlaceDeepslate, 0, 2);
		world.setBlock(i + 8, j + 1, k + 2, PlaceDeepslate, 0, 2);
		world.setBlock(i + 9, j + 1, k + 2, PlaceDeepslate, 0, 2);
		world.setBlock(i + 10, j + 1, k + 2, PlaceDeepslate, 0, 2);
		world.setBlock(i + 11, j + 1, k + 2, PlaceDeepslate, 0, 2);
		world.setBlock(i + 12, j + 1, k + 2, PlaceDeepslate, 0, 2);
		world.setBlock(i + 13, j + 1, k + 2, PlaceDeepslate, 0, 2);
		world.setBlock(i + 14, j + 1, k + 2, PlaceDeepslate, 0, 2);
		world.setBlock(i + 15, j + 1, k + 2, PlaceDeepslate, 0, 2);
		world.setBlock(i + 16, j + 1, k + 2, PlaceDeepslate, 0, 2);
		world.setBlock(i + 17, j + 1, k + 2, PlaceDeepslate, 0, 2);
		world.setBlock(i + 18, j + 1, k + 2, PlaceDeepslate, 0, 2);
		world.setBlock(i + 0, j + 1, k + 3, PlaceDeepslate, 0, 2);
		world.setBlock(i + 1, j + 1, k + 3, PlaceDeepslate, 0, 2);
		world.setBlock(i + 2, j + 1, k + 3, PlaceDeepslate, 0, 2);
		world.setBlock(i + 3, j + 1, k + 3, PlaceDeepslate, 0, 2);
		world.setBlock(i + 4, j + 1, k + 3, PlaceDeepslate, 0, 2);
		world.setBlock(i + 5, j + 1, k + 3, PlaceDeepslate, 0, 2);
		world.setBlock(i + 6, j + 1, k + 3, PlaceDeepslate, 0, 2);
		world.setBlock(i + 7, j + 1, k + 3, PlaceDeepslate, 0, 2);
		world.setBlock(i + 8, j + 1, k + 3, PlaceDeepslate, 0, 2);
		world.setBlock(i + 9, j + 1, k + 3, PlaceDeepslate, 0, 2);
		world.setBlock(i + 10, j + 1, k + 3, PlaceDeepslate, 0, 2);
		world.setBlock(i + 11, j + 1, k + 3, PlaceDeepslate, 0, 2);
		world.setBlock(i + 12, j + 1, k + 3, PlaceDeepslate, 0, 2);
		world.setBlock(i + 13, j + 1, k + 3, PlaceDeepslate, 0, 2);
		world.setBlock(i + 14, j + 1, k + 3, PlaceDeepslate, 0, 2);
		world.setBlock(i + 15, j + 1, k + 3, PlaceDeepslate, 0, 2);
		world.setBlock(i + 16, j + 1, k + 3, PlaceDeepslate, 0, 2);
		world.setBlock(i + 17, j + 1, k + 3, PlaceDeepslate, 0, 2);
		world.setBlock(i + 18, j + 1, k + 3, PlaceDeepslate, 0, 2);
		world.setBlock(i + 0, j + 1, k + 4, PlaceDeepslate, 0, 2);
		world.setBlock(i + 1, j + 1, k + 4, PlaceDeepslate, 0, 2);
		world.setBlock(i + 2, j + 1, k + 4, PlaceDeepslate, 0, 2);
		world.setBlock(i + 3, j + 1, k + 4, PlaceDeepslate, 0, 2);
		world.setBlock(i + 4, j + 1, k + 4, PlaceDeepslate, 0, 2);
		world.setBlock(i + 5, j + 1, k + 4, PlaceDeepslate, 0, 2);
		world.setBlock(i + 6, j + 1, k + 4, PlaceDeepslate, 0, 2);
		world.setBlock(i + 7, j + 1, k + 4, PlaceDeepslate, 0, 2);
		world.setBlock(i + 8, j + 1, k + 4, PlaceDeepslate, 0, 2);
		world.setBlock(i + 9, j + 1, k + 4, PlaceDeepslate, 0, 2);
		world.setBlock(i + 10, j + 1, k + 4, PlaceDeepslate, 0, 2);
		world.setBlock(i + 11, j + 1, k + 4, PlaceDeepslate, 0, 2);
		world.setBlock(i + 12, j + 1, k + 4, PlaceDeepslate, 0, 2);
		world.setBlock(i + 13, j + 1, k + 4, PlaceDeepslate, 0, 2);
		world.setBlock(i + 14, j + 1, k + 4, PlaceDeepslate, 0, 2);
		world.setBlock(i + 15, j + 1, k + 4, PlaceDeepslate, 0, 2);
		world.setBlock(i + 16, j + 1, k + 4, PlaceDeepslate, 0, 2);
		world.setBlock(i + 17, j + 1, k + 4, PlaceDeepslate, 0, 2);
		world.setBlock(i + 18, j + 1, k + 4, PlaceDeepslate, 0, 2);
		world.setBlock(i + 0, j + 1, k + 5, PlaceDeepslate, 0, 2);
		world.setBlock(i + 1, j + 1, k + 5, PlaceDeepslate, 0, 2);
		world.setBlock(i + 2, j + 1, k + 5, PlaceDeepslate, 0, 2);
		world.setBlock(i + 3, j + 1, k + 5, PlaceDeepslate, 0, 2);
		world.setBlock(i + 4, j + 1, k + 5, PlaceDeepslate, 0, 2);
		world.setBlock(i + 5, j + 1, k + 5, PlaceDeepslate, 0, 2);
		world.setBlock(i + 6, j + 1, k + 5, PlaceDeepslate, 0, 2);
		world.setBlock(i + 7, j + 1, k + 5, PlaceDeepslate, 0, 2);
		world.setBlock(i + 8, j + 1, k + 5, PlaceDeepslate, 0, 2);
		world.setBlock(i + 9, j + 1, k + 5, PlaceDeepslate, 0, 2);
		world.setBlock(i + 10, j + 1, k + 5, PlaceDeepslate, 0, 2);
		world.setBlock(i + 11, j + 1, k + 5, PlaceDeepslate, 0, 2);
		world.setBlock(i + 12, j + 1, k + 5, PlaceDeepslate, 0, 2);
		world.setBlock(i + 13, j + 1, k + 5, PlaceDeepslate, 0, 2);
		world.setBlock(i + 14, j + 1, k + 5, PlaceDeepslate, 0, 2);
		world.setBlock(i + 15, j + 1, k + 5, PlaceDeepslate, 0, 2);
		world.setBlock(i + 16, j + 1, k + 5, PlaceDeepslate, 0, 2);
		world.setBlock(i + 17, j + 1, k + 5, PlaceDeepslate, 0, 2);
		world.setBlock(i + 18, j + 1, k + 5, PlaceDeepslate, 0, 2);
		world.setBlock(i + 0, j + 1, k + 6, PlaceDeepslate, 0, 2);
		world.setBlock(i + 1, j + 1, k + 6, PlaceDeepslate, 0, 2);
		world.setBlock(i + 2, j + 1, k + 6, PlaceDeepslate, 0, 2);
		world.setBlock(i + 3, j + 1, k + 6, PlaceDeepslate, 0, 2);
		world.setBlock(i + 4, j + 1, k + 6, PlaceDeepslate, 0, 2);
		world.setBlock(i + 5, j + 1, k + 6, PlaceDeepslate, 0, 2);
		world.setBlock(i + 6, j + 1, k + 6, PlaceDeepslate, 0, 2);
		world.setBlock(i + 7, j + 1, k + 6, PlaceDeepslate, 0, 2);
		world.setBlock(i + 8, j + 1, k + 6, PlaceDeepslate, 0, 2);
		world.setBlock(i + 9, j + 1, k + 6, PlaceDeepslate, 0, 2);
		world.setBlock(i + 10, j + 1, k + 6, PlaceDeepslate, 0, 2);
		world.setBlock(i + 11, j + 1, k + 6, PlaceDeepslate, 0, 2);
		world.setBlock(i + 12, j + 1, k + 6, PlaceDeepslate, 0, 2);
		world.setBlock(i + 13, j + 1, k + 6, PlaceDeepslate, 0, 2);
		world.setBlock(i + 14, j + 1, k + 6, PlaceDeepslate, 0, 2);
		world.setBlock(i + 15, j + 1, k + 6, PlaceDeepslate, 0, 2);
		world.setBlock(i + 16, j + 1, k + 6, PlaceDeepslate, 0, 2);
		world.setBlock(i + 17, j + 1, k + 6, PlaceDeepslate, 0, 2);
		world.setBlock(i + 18, j + 1, k + 6, PlaceDeepslate, 0, 2);
		world.setBlock(i + 0, j + 1, k + 7, PlaceDeepslate, 0, 2);
		world.setBlock(i + 1, j + 1, k + 7, PlaceDeepslate, 0, 2);
		world.setBlock(i + 2, j + 1, k + 7, PlaceDeepslate, 0, 2);
		world.setBlock(i + 3, j + 1, k + 7, PlaceDeepslate, 0, 2);
		world.setBlock(i + 4, j + 1, k + 7, PlaceDeepslate, 0, 2);
		world.setBlock(i + 5, j + 1, k + 7, PlaceDeepslate, 0, 2);
		world.setBlock(i + 6, j + 1, k + 7, PlaceDeepslate, 0, 2);
		world.setBlock(i + 7, j + 1, k + 7, PlaceDeepslate, 0, 2);
		world.setBlock(i + 8, j + 1, k + 7, PlaceDeepslate, 0, 2);
		world.setBlock(i + 9, j + 1, k + 7, PlaceDeepslate, 0, 2);
		world.setBlock(i + 10, j + 1, k + 7, PlaceDeepslate, 0, 2);
		world.setBlock(i + 11, j + 1, k + 7, PlaceDeepslate, 0, 2);
		world.setBlock(i + 12, j + 1, k + 7, PlaceDeepslate, 0, 2);
		world.setBlock(i + 13, j + 1, k + 7, PlaceDeepslate, 0, 2);
		world.setBlock(i + 14, j + 1, k + 7, PlaceDeepslate, 0, 2);
		world.setBlock(i + 15, j + 1, k + 7, PlaceDeepslate, 0, 2);
		world.setBlock(i + 16, j + 1, k + 7, PlaceDeepslate, 0, 2);
		world.setBlock(i + 17, j + 1, k + 7, PlaceDeepslate, 0, 2);
		world.setBlock(i + 18, j + 1, k + 7, PlaceDeepslate, 0, 2);
		world.setBlock(i + 0, j + 1, k + 8, PlaceDeepslate, 0, 2);
		world.setBlock(i + 1, j + 1, k + 8, PlaceDeepslate, 0, 2);
		world.setBlock(i + 2, j + 1, k + 8, PlaceDeepslate, 0, 2);
		world.setBlock(i + 3, j + 1, k + 8, PlaceDeepslate, 0, 2);
		world.setBlock(i + 4, j + 1, k + 8, PlaceDeepslate, 0, 2);
		world.setBlock(i + 5, j + 1, k + 8, PlaceDeepslate, 0, 2);
		world.setBlock(i + 6, j + 1, k + 8, PlaceDeepslate, 0, 2);
		world.setBlock(i + 7, j + 1, k + 8, PlaceDeepslate, 0, 2);
		world.setBlock(i + 8, j + 1, k + 8, PlaceDeepslate, 0, 2);
		world.setBlock(i + 9, j + 1, k + 8, PlaceDeepslate, 0, 2);
		world.setBlock(i + 10, j + 1, k + 8, PlaceDeepslate, 0, 2);
		world.setBlock(i + 11, j + 1, k + 8, PlaceDeepslate, 0, 2);
		world.setBlock(i + 12, j + 1, k + 8, PlaceDeepslate, 0, 2);
		world.setBlock(i + 13, j + 1, k + 8, PlaceDeepslate, 0, 2);
		world.setBlock(i + 14, j + 1, k + 8, PlaceDeepslate, 0, 2);
		world.setBlock(i + 15, j + 1, k + 8, PlaceDeepslate, 0, 2);
		world.setBlock(i + 16, j + 1, k + 8, PlaceDeepslate, 0, 2);
		world.setBlock(i + 17, j + 1, k + 8, PlaceDeepslate, 0, 2);
		world.setBlock(i + 18, j + 1, k + 8, PlaceDeepslate, 0, 2);
		world.setBlock(i + 19, j + 1, k + 8, PlaceDeepslate, 0, 2);
		world.setBlock(i + 0, j + 1, k + 9, PlaceDeepslate, 0, 2);
		world.setBlock(i + 1, j + 1, k + 9, PlaceDeepslate, 0, 2);
		world.setBlock(i + 2, j + 1, k + 9, PlaceDeepslate, 0, 2);
		world.setBlock(i + 3, j + 1, k + 9, PlaceDeepslate, 0, 2);
		world.setBlock(i + 4, j + 1, k + 9, PlaceDeepslate, 0, 2);
		world.setBlock(i + 5, j + 1, k + 9, PlaceDeepslate, 0, 2);
		world.setBlock(i + 6, j + 1, k + 9, PlaceDeepslate, 0, 2);
		world.setBlock(i + 7, j + 1, k + 9, PlaceDeepslate, 0, 2);
		world.setBlock(i + 8, j + 1, k + 9, PlaceDeepslate, 0, 2);
		world.setBlock(i + 9, j + 1, k + 9, PlaceDeepslate, 0, 2);
		world.setBlock(i + 10, j + 1, k + 9, PlaceDeepslate, 0, 2);
		world.setBlock(i + 11, j + 1, k + 9, PlaceDeepslate, 0, 2);
		world.setBlock(i + 12, j + 1, k + 9, PlaceDeepslate, 0, 2);
		world.setBlock(i + 13, j + 1, k + 9, PlaceDeepslate, 0, 2);
		world.setBlock(i + 14, j + 1, k + 9, PlaceDeepslate, 0, 2);
		world.setBlock(i + 15, j + 1, k + 9, PlaceDeepslate, 0, 2);
		world.setBlock(i + 16, j + 1, k + 9, PlaceDeepslate, 0, 2);
		world.setBlock(i + 17, j + 1, k + 9, PlaceDeepslate, 0, 2);
		world.setBlock(i + 18, j + 1, k + 9, PlaceDeepslate, 0, 2);
		world.setBlock(i + 19, j + 1, k + 9, PlaceDeepslate, 0, 2);
		world.setBlock(i + 20, j + 1, k + 9, PlaceDeepslate, 0, 2);
		world.setBlock(i + 0, j + 1, k + 10, PlaceDeepslate, 0, 2);
		world.setBlock(i + 1, j + 1, k + 10, PlaceDeepslate, 0, 2);
		world.setBlock(i + 2, j + 1, k + 10, PlaceDeepslate, 0, 2);
		world.setBlock(i + 3, j + 1, k + 10, PlaceDeepslate, 0, 2);
		world.setBlock(i + 4, j + 1, k + 10, PlaceDeepslate, 0, 2);
		world.setBlock(i + 5, j + 1, k + 10, PlaceDeepslate, 0, 2);
		world.setBlock(i + 6, j + 1, k + 10, PlaceDeepslate, 0, 2);
		world.setBlock(i + 7, j + 1, k + 10, PlaceDeepslate, 0, 2);
		world.setBlock(i + 8, j + 1, k + 10, PlaceDeepslate, 0, 2);
		world.setBlock(i + 9, j + 1, k + 10, PlaceDeepslate, 0, 2);
		world.setBlock(i + 10, j + 1, k + 10, PlaceDeepslate, 0, 2);
		world.setBlock(i + 11, j + 1, k + 10, PlaceDeepslate, 0, 2);
		world.setBlock(i + 12, j + 1, k + 10, PlaceDeepslate, 0, 2);
		world.setBlock(i + 13, j + 1, k + 10, PlaceDeepslate, 0, 2);
		world.setBlock(i + 14, j + 1, k + 10, PlaceDeepslate, 0, 2);
		world.setBlock(i + 15, j + 1, k + 10, PlaceDeepslate, 0, 2);
		world.setBlock(i + 16, j + 1, k + 10, PlaceDeepslate, 0, 2);
		world.setBlock(i + 17, j + 1, k + 10, PlaceDeepslate, 0, 2);
		world.setBlock(i + 18, j + 1, k + 10, PlaceDeepslate, 0, 2);
		world.setBlock(i + 19, j + 1, k + 10, PlaceDeepslate, 0, 2);
		world.setBlock(i + 20, j + 1, k + 10, PlaceDeepslate, 0, 2);
		world.setBlock(i + 21, j + 1, k + 10, PlaceDeepslate, 0, 2);
		world.setBlock(i + 0, j + 1, k + 11, PlaceDeepslate, 0, 2);
		world.setBlock(i + 1, j + 1, k + 11, PlaceDeepslate, 0, 2);
		world.setBlock(i + 2, j + 1, k + 11, PlaceDeepslate, 0, 2);
		world.setBlock(i + 3, j + 1, k + 11, PlaceDeepslate, 0, 2);
		world.setBlock(i + 4, j + 1, k + 11, PlaceDeepslate, 0, 2);
		world.setBlock(i + 5, j + 1, k + 11, PlaceDeepslate, 0, 2);
		world.setBlock(i + 6, j + 1, k + 11, PlaceDeepslate, 0, 2);
		world.setBlock(i + 7, j + 1, k + 11, PlaceDeepslate, 0, 2);
		world.setBlock(i + 8, j + 1, k + 11, PlaceDeepslate, 0, 2);
		world.setBlock(i + 9, j + 1, k + 11, PlaceDeepslate, 0, 2);
		world.setBlock(i + 10, j + 1, k + 11, PlaceDeepslate, 0, 2);
		world.setBlock(i + 11, j + 1, k + 11, PlaceDeepslate, 0, 2);
		world.setBlock(i + 12, j + 1, k + 11, PlaceDeepslate, 0, 2);
		world.setBlock(i + 13, j + 1, k + 11, PlaceDeepslate, 0, 2);
		world.setBlock(i + 14, j + 1, k + 11, PlaceDeepslate, 0, 2);
		world.setBlock(i + 15, j + 1, k + 11, PlaceDeepslate, 0, 2);
		world.setBlock(i + 16, j + 1, k + 11, PlaceDeepslate, 0, 2);
		world.setBlock(i + 17, j + 1, k + 11, PlaceDeepslate, 0, 2);
		world.setBlock(i + 18, j + 1, k + 11, PlaceDeepslate, 0, 2);
		world.setBlock(i + 19, j + 1, k + 11, PlaceDeepslate, 0, 2);
		world.setBlock(i + 20, j + 1, k + 11, PlaceDeepslate, 0, 2);
		world.setBlock(i + 21, j + 1, k + 11, PlaceDeepslate, 0, 2);
		world.setBlock(i + 0, j + 1, k + 12, PlaceDeepslate, 0, 2);
		world.setBlock(i + 1, j + 1, k + 12, PlaceDeepslate, 0, 2);
		world.setBlock(i + 2, j + 1, k + 12, PlaceDeepslate, 0, 2);
		world.setBlock(i + 3, j + 1, k + 12, PlaceDeepslate, 0, 2);
		world.setBlock(i + 4, j + 1, k + 12, PlaceDeepslate, 0, 2);
		world.setBlock(i + 5, j + 1, k + 12, PlaceDeepslate, 0, 2);
		world.setBlock(i + 6, j + 1, k + 12, PlaceDeepslate, 0, 2);
		world.setBlock(i + 7, j + 1, k + 12, PlaceDeepslate, 0, 2);
		world.setBlock(i + 8, j + 1, k + 12, PlaceDeepslate, 0, 2);
		world.setBlock(i + 9, j + 1, k + 12, PlaceDeepslate, 0, 2);
		world.setBlock(i + 10, j + 1, k + 12, PlaceDeepslate, 0, 2);
		world.setBlock(i + 11, j + 1, k + 12, PlaceDeepslate, 0, 2);
		world.setBlock(i + 12, j + 1, k + 12, PlaceDeepslate, 0, 2);
		world.setBlock(i + 13, j + 1, k + 12, PlaceDeepslate, 0, 2);
		world.setBlock(i + 14, j + 1, k + 12, PlaceDeepslate, 0, 2);
		world.setBlock(i + 15, j + 1, k + 12, PlaceDeepslate, 0, 2);
		world.setBlock(i + 16, j + 1, k + 12, PlaceDeepslate, 0, 2);
		world.setBlock(i + 17, j + 1, k + 12, PlaceDeepslate, 0, 2);
		world.setBlock(i + 18, j + 1, k + 12, PlaceDeepslate, 0, 2);
		world.setBlock(i + 19, j + 1, k + 12, PlaceDeepslate, 0, 2);
		world.setBlock(i + 20, j + 1, k + 12, PlaceDeepslate, 0, 2);
		world.setBlock(i + 21, j + 1, k + 12, PlaceDeepslate, 0, 2);
		world.setBlock(i + 0, j + 1, k + 13, PlaceDeepslate, 0, 2);
		world.setBlock(i + 1, j + 1, k + 13, PlaceDeepslate, 0, 2);
		world.setBlock(i + 2, j + 1, k + 13, PlaceDeepslate, 0, 2);
		world.setBlock(i + 3, j + 1, k + 13, PlaceDeepslate, 0, 2);
		world.setBlock(i + 4, j + 1, k + 13, PlaceDeepslate, 0, 2);
		world.setBlock(i + 5, j + 1, k + 13, PlaceDeepslate, 0, 2);
		world.setBlock(i + 6, j + 1, k + 13, PlaceDeepslate, 0, 2);
		world.setBlock(i + 7, j + 1, k + 13, PlaceDeepslate, 0, 2);
		world.setBlock(i + 8, j + 1, k + 13, PlaceDeepslate, 0, 2);
		world.setBlock(i + 9, j + 1, k + 13, PlaceDeepslate, 0, 2);
		world.setBlock(i + 10, j + 1, k + 13, PlaceDeepslate, 0, 2);
		world.setBlock(i + 11, j + 1, k + 13, PlaceDeepslate, 0, 2);
		world.setBlock(i + 12, j + 1, k + 13, PlaceDeepslate, 0, 2);
		world.setBlock(i + 13, j + 1, k + 13, PlaceDeepslate, 0, 2);
		world.setBlock(i + 14, j + 1, k + 13, PlaceDeepslate, 0, 2);
		world.setBlock(i + 15, j + 1, k + 13, PlaceDeepslate, 0, 2);
		world.setBlock(i + 16, j + 1, k + 13, PlaceDeepslate, 0, 2);
		world.setBlock(i + 17, j + 1, k + 13, PlaceDeepslate, 0, 2);
		world.setBlock(i + 18, j + 1, k + 13, PlaceDeepslate, 0, 2);
		world.setBlock(i + 19, j + 1, k + 13, PlaceDeepslate, 0, 2);
		world.setBlock(i + 20, j + 1, k + 13, PlaceDeepslate, 0, 2);
		world.setBlock(i + 21, j + 1, k + 13, PlaceDeepslate, 0, 2);
		world.setBlock(i + 0, j + 1, k + 14, PlaceDeepslate, 0, 2);
		world.setBlock(i + 1, j + 1, k + 14, PlaceDeepslate, 0, 2);
		world.setBlock(i + 2, j + 1, k + 14, PlaceDeepslate, 0, 2);
		world.setBlock(i + 3, j + 1, k + 14, PlaceDeepslate, 0, 2);
		world.setBlock(i + 4, j + 1, k + 14, PlaceDeepslate, 0, 2);
		world.setBlock(i + 5, j + 1, k + 14, PlaceDeepslate, 0, 2);
		world.setBlock(i + 6, j + 1, k + 14, PlaceDeepslate, 0, 2);
		world.setBlock(i + 7, j + 1, k + 14, PlaceDeepslate, 0, 2);
		world.setBlock(i + 8, j + 1, k + 14, PlaceDeepslate, 0, 2);
		world.setBlock(i + 9, j + 1, k + 14, PlaceDeepslate, 0, 2);
		world.setBlock(i + 10, j + 1, k + 14, PlaceDeepslate, 0, 2);
		world.setBlock(i + 11, j + 1, k + 14, PlaceDeepslate, 0, 2);
		world.setBlock(i + 12, j + 1, k + 14, PlaceDeepslate, 0, 2);
		world.setBlock(i + 13, j + 1, k + 14, PlaceDeepslate, 0, 2);
		world.setBlock(i + 14, j + 1, k + 14, PlaceDeepslate, 0, 2);
		world.setBlock(i + 15, j + 1, k + 14, PlaceDeepslate, 0, 2);
		world.setBlock(i + 16, j + 1, k + 14, PlaceDeepslate, 0, 2);
		world.setBlock(i + 17, j + 1, k + 14, PlaceDeepslate, 0, 2);
		world.setBlock(i + 18, j + 1, k + 14, PlaceDeepslate, 0, 2);
		world.setBlock(i + 19, j + 1, k + 14, PlaceDeepslate, 0, 2);
		world.setBlock(i + 20, j + 1, k + 14, PlaceDeepslate, 0, 2);
		world.setBlock(i + 21, j + 1, k + 14, PlaceDeepslate, 0, 2);
		world.setBlock(i + 0, j + 1, k + 15, PlaceDeepslate, 0, 2);
		world.setBlock(i + 1, j + 1, k + 15, PlaceDeepslate, 0, 2);
		world.setBlock(i + 2, j + 1, k + 15, PlaceDeepslate, 0, 2);
		world.setBlock(i + 3, j + 1, k + 15, PlaceDeepslate, 0, 2);
		world.setBlock(i + 4, j + 1, k + 15, PlaceDeepslate, 0, 2);
		world.setBlock(i + 5, j + 1, k + 15, PlaceDeepslate, 0, 2);
		world.setBlock(i + 6, j + 1, k + 15, PlaceDeepslate, 0, 2);
		world.setBlock(i + 7, j + 1, k + 15, PlaceDeepslate, 0, 2);
		world.setBlock(i + 8, j + 1, k + 15, PlaceDeepslate, 0, 2);
		world.setBlock(i + 9, j + 1, k + 15, PlaceDeepslate, 0, 2);
		world.setBlock(i + 10, j + 1, k + 15, PlaceDeepslate, 0, 2);
		world.setBlock(i + 11, j + 1, k + 15, PlaceDeepslate, 0, 2);
		world.setBlock(i + 12, j + 1, k + 15, PlaceDeepslate, 0, 2);
		world.setBlock(i + 13, j + 1, k + 15, PlaceDeepslate, 0, 2);
		world.setBlock(i + 14, j + 1, k + 15, PlaceDeepslate, 0, 2);
		world.setBlock(i + 15, j + 1, k + 15, PlaceDeepslate, 0, 2);
		world.setBlock(i + 16, j + 1, k + 15, PlaceDeepslate, 0, 2);
		world.setBlock(i + 17, j + 1, k + 15, PlaceDeepslate, 0, 2);
		world.setBlock(i + 18, j + 1, k + 15, PlaceDeepslate, 0, 2);
		world.setBlock(i + 19, j + 1, k + 15, PlaceDeepslate, 0, 2);
		world.setBlock(i + 20, j + 1, k + 15, PlaceDeepslate, 0, 2);
		world.setBlock(i + 21, j + 1, k + 15, PlaceDeepslate, 0, 2);
		world.setBlock(i + 0, j + 1, k + 16, PlaceDeepslate, 0, 2);
		world.setBlock(i + 1, j + 1, k + 16, PlaceDeepslate, 0, 2);
		world.setBlock(i + 2, j + 1, k + 16, PlaceDeepslate, 0, 2);
		world.setBlock(i + 3, j + 1, k + 16, PlaceDeepslate, 0, 2);
		world.setBlock(i + 4, j + 1, k + 16, PlaceDeepslate, 0, 2);
		world.setBlock(i + 5, j + 1, k + 16, PlaceDeepslate, 0, 2);
		world.setBlock(i + 6, j + 1, k + 16, PlaceDeepslate, 0, 2);
		world.setBlock(i + 7, j + 1, k + 16, PlaceDeepslate, 0, 2);
		world.setBlock(i + 8, j + 1, k + 16, PlaceDeepslate, 0, 2);
		world.setBlock(i + 9, j + 1, k + 16, PlaceDeepslate, 0, 2);
		world.setBlock(i + 10, j + 1, k + 16, PlaceDeepslate, 0, 2);
		world.setBlock(i + 11, j + 1, k + 16, PlaceDeepslate, 0, 2);
		world.setBlock(i + 12, j + 1, k + 16, PlaceDeepslate, 0, 2);
		world.setBlock(i + 13, j + 1, k + 16, PlaceDeepslate, 0, 2);
		world.setBlock(i + 14, j + 1, k + 16, PlaceDeepslate, 0, 2);
		world.setBlock(i + 15, j + 1, k + 16, PlaceDeepslate, 0, 2);
		world.setBlock(i + 16, j + 1, k + 16, PlaceDeepslate, 0, 2);
		world.setBlock(i + 17, j + 1, k + 16, PlaceDeepslate, 0, 2);
		world.setBlock(i + 18, j + 1, k + 16, PlaceDeepslate, 0, 2);
		world.setBlock(i + 19, j + 1, k + 16, PlaceDeepslate, 0, 2);
		world.setBlock(i + 20, j + 1, k + 16, PlaceDeepslate, 0, 2);
		world.setBlock(i + 21, j + 1, k + 16, PlaceDeepslate, 0, 2);
		world.setBlock(i + 0, j + 1, k + 17, PlaceDeepslate, 0, 2);
		world.setBlock(i + 1, j + 1, k + 17, PlaceDeepslate, 0, 2);
		world.setBlock(i + 2, j + 1, k + 17, PlaceDeepslate, 0, 2);
		world.setBlock(i + 3, j + 1, k + 17, PlaceDeepslate, 0, 2);
		world.setBlock(i + 4, j + 1, k + 17, PlaceDeepslate, 0, 2);
		world.setBlock(i + 5, j + 1, k + 17, PlaceDeepslate, 0, 2);
		world.setBlock(i + 6, j + 1, k + 17, PlaceDeepslate, 0, 2);
		world.setBlock(i + 7, j + 1, k + 17, PlaceDeepslate, 0, 2);
		world.setBlock(i + 8, j + 1, k + 17, PlaceDeepslate, 0, 2);
		world.setBlock(i + 9, j + 1, k + 17, PlaceDeepslate, 0, 2);
		world.setBlock(i + 10, j + 1, k + 17, PlaceDeepslate, 0, 2);
		world.setBlock(i + 11, j + 1, k + 17, PlaceDeepslate, 0, 2);
		world.setBlock(i + 12, j + 1, k + 17, PlaceDeepslate, 0, 2);
		world.setBlock(i + 13, j + 1, k + 17, PlaceDeepslate, 0, 2);
		world.setBlock(i + 14, j + 1, k + 17, PlaceDeepslate, 0, 2);
		world.setBlock(i + 15, j + 1, k + 17, PlaceDeepslate, 0, 2);
		world.setBlock(i + 16, j + 1, k + 17, PlaceDeepslate, 0, 2);
		world.setBlock(i + 17, j + 1, k + 17, PlaceDeepslate, 0, 2);
		world.setBlock(i + 18, j + 1, k + 17, PlaceDeepslate, 0, 2);
		world.setBlock(i + 19, j + 1, k + 17, PlaceDeepslate, 0, 2);
		world.setBlock(i + 20, j + 1, k + 17, PlaceDeepslate, 0, 2);
		world.setBlock(i + 21, j + 1, k + 17, PlaceDeepslate, 0, 2);
		world.setBlock(i + 1, j + 1, k + 18, PlaceDeepslate, 0, 2);
		world.setBlock(i + 2, j + 1, k + 18, PlaceDeepslate, 0, 2);
		world.setBlock(i + 3, j + 1, k + 18, PlaceDeepslate, 0, 2);
		world.setBlock(i + 4, j + 1, k + 18, PlaceDeepslate, 0, 2);
		world.setBlock(i + 5, j + 1, k + 18, PlaceDeepslate, 0, 2);
		world.setBlock(i + 6, j + 1, k + 18, PlaceDeepslate, 0, 2);
		world.setBlock(i + 7, j + 1, k + 18, PlaceDeepslate, 0, 2);
		world.setBlock(i + 8, j + 1, k + 18, PlaceDeepslate, 0, 2);
		world.setBlock(i + 9, j + 1, k + 18, PlaceDeepslate, 0, 2);
		world.setBlock(i + 10, j + 1, k + 18, PlaceDeepslate, 0, 2);
		world.setBlock(i + 11, j + 1, k + 18, PlaceDeepslate, 0, 2);
		world.setBlock(i + 12, j + 1, k + 18, PlaceDeepslate, 0, 2);
		world.setBlock(i + 13, j + 1, k + 18, PlaceDeepslate, 0, 2);
		world.setBlock(i + 14, j + 1, k + 18, PlaceDeepslate, 0, 2);
		world.setBlock(i + 15, j + 1, k + 18, PlaceDeepslate, 0, 2);
		world.setBlock(i + 16, j + 1, k + 18, PlaceDeepslate, 0, 2);
		world.setBlock(i + 17, j + 1, k + 18, PlaceDeepslate, 0, 2);
		world.setBlock(i + 18, j + 1, k + 18, PlaceDeepslate, 0, 2);
		world.setBlock(i + 19, j + 1, k + 18, PlaceDeepslate, 0, 2);
		world.setBlock(i + 20, j + 1, k + 18, PlaceDeepslate, 0, 2);
		world.setBlock(i + 21, j + 1, k + 18, PlaceDeepslate, 0, 2);
		world.setBlock(i + 2, j + 1, k + 19, PlaceDeepslate, 0, 2);
		world.setBlock(i + 3, j + 1, k + 19, PlaceDeepslate, 0, 2);
		world.setBlock(i + 4, j + 1, k + 19, PlaceDeepslate, 0, 2);
		world.setBlock(i + 5, j + 1, k + 19, PlaceDeepslate, 0, 2);
		world.setBlock(i + 6, j + 1, k + 19, PlaceDeepslate, 0, 2);
		world.setBlock(i + 7, j + 1, k + 19, PlaceDeepslate, 0, 2);
		world.setBlock(i + 8, j + 1, k + 19, PlaceDeepslate, 0, 2);
		world.setBlock(i + 9, j + 1, k + 19, PlaceDeepslate, 0, 2);
		world.setBlock(i + 10, j + 1, k + 19, PlaceDeepslate, 0, 2);
		world.setBlock(i + 11, j + 1, k + 19, PlaceDeepslate, 0, 2);
		world.setBlock(i + 12, j + 1, k + 19, PlaceDeepslate, 0, 2);
		world.setBlock(i + 13, j + 1, k + 19, PlaceDeepslate, 0, 2);
		world.setBlock(i + 14, j + 1, k + 19, PlaceDeepslate, 0, 2);
		world.setBlock(i + 15, j + 1, k + 19, PlaceDeepslate, 0, 2);
		world.setBlock(i + 16, j + 1, k + 19, PlaceDeepslate, 0, 2);
		world.setBlock(i + 17, j + 1, k + 19, PlaceDeepslate, 0, 2);
		world.setBlock(i + 18, j + 1, k + 19, PlaceDeepslate, 0, 2);
		world.setBlock(i + 19, j + 1, k + 19, PlaceDeepslate, 0, 2);
		world.setBlock(i + 20, j + 1, k + 19, PlaceDeepslate, 0, 2);
		world.setBlock(i + 3, j + 2, k + 0, PlaceDeepslate, 0, 2);
		world.setBlock(i + 4, j + 2, k + 0, PlaceDeepslate, 0, 2);
		world.setBlock(i + 5, j + 2, k + 0, PlaceDeepslate, 0, 2);
		world.setBlock(i + 6, j + 2, k + 0, PlaceDeepslate, 0, 2);
		world.setBlock(i + 7, j + 2, k + 0, PlaceDeepslate, 0, 2);
		world.setBlock(i + 8, j + 2, k + 0, PlaceDeepslate, 0, 2);
		world.setBlock(i + 9, j + 2, k + 0, PlaceDeepslate, 0, 2);
		world.setBlock(i + 10, j + 2, k + 0, PlaceDeepslate, 0, 2);
		world.setBlock(i + 11, j + 2, k + 0, PlaceDeepslate, 0, 2);
		world.setBlock(i + 12, j + 2, k + 0, PlaceDeepslate, 0, 2);
		world.setBlock(i + 13, j + 2, k + 0, PlaceDeepslate, 0, 2);
		world.setBlock(i + 14, j + 2, k + 0, PlaceDeepslate, 0, 2);
		world.setBlock(i + 15, j + 2, k + 0, PlaceDeepslate, 0, 2);
		world.setBlock(i + 16, j + 2, k + 0, PlaceDeepslate, 0, 2);
		world.setBlock(i + 17, j + 2, k + 0, PlaceDeepslate, 0, 2);
		world.setBlock(i + 2, j + 2, k + 1, PlaceDeepslate, 0, 2);
		world.setBlock(i + 3, j + 2, k + 1, PlaceDeepslate, 0, 2);
		world.setBlock(i + 4, j + 2, k + 1, PlaceDeepslate, 0, 2);
		world.setBlock(i + 5, j + 2, k + 1, PlaceDeepslate, 0, 2);
		world.setBlock(i + 6, j + 2, k + 1, PlaceDeepslate, 0, 2);
		world.setBlock(i + 7, j + 2, k + 1, PlaceDeepslate, 0, 2);
		world.setBlock(i + 8, j + 2, k + 1, PlaceDeepslate, 0, 2);
		world.setBlock(i + 9, j + 2, k + 1, PlaceDeepslate, 0, 2);
		world.setBlock(i + 10, j + 2, k + 1, PlaceDeepslate, 0, 2);
		world.setBlock(i + 11, j + 2, k + 1, PlaceDeepslate, 0, 2);
		world.setBlock(i + 12, j + 2, k + 1, PlaceDeepslate, 0, 2);
		world.setBlock(i + 13, j + 2, k + 1, PlaceDeepslate, 0, 2);
		world.setBlock(i + 14, j + 2, k + 1, PlaceDeepslate, 0, 2);
		world.setBlock(i + 15, j + 2, k + 1, PlaceDeepslate, 0, 2);
		world.setBlock(i + 16, j + 2, k + 1, PlaceDeepslate, 0, 2);
		world.setBlock(i + 17, j + 2, k + 1, PlaceDeepslate, 0, 2);
		world.setBlock(i + 18, j + 2, k + 1, PlaceDeepslate, 0, 2);
		world.setBlock(i + 1, j + 2, k + 2, PlaceDeepslate, 0, 2);
		world.setBlock(i + 2, j + 2, k + 2, PlaceDeepslate, 0, 2);
		world.setBlock(i + 3, j + 2, k + 2, PlaceDeepslate, 0, 2);
		world.setBlock(i + 4, j + 2, k + 2, PlaceDeepslate, 0, 2);
		world.setBlock(i + 5, j + 2, k + 2, PlaceDeepslate, 0, 2);
		world.setBlock(i + 6, j + 2, k + 2, PlaceDeepslate, 0, 2);
		world.setBlock(i + 7, j + 2, k + 2, PlaceDeepslate, 0, 2);
		world.setBlock(i + 8, j + 2, k + 2, PlaceDeepslate, 0, 2);
		world.setBlock(i + 9, j + 2, k + 2, PlaceDeepslate, 0, 2);
		world.setBlock(i + 10, j + 2, k + 2, PlaceDeepslate, 0, 2);
		world.setBlock(i + 11, j + 2, k + 2, PlaceDeepslate, 0, 2);
		world.setBlock(i + 12, j + 2, k + 2, PlaceDeepslate, 0, 2);
		world.setBlock(i + 13, j + 2, k + 2, PlaceDeepslate, 0, 2);
		world.setBlock(i + 14, j + 2, k + 2, PlaceDeepslate, 0, 2);
		world.setBlock(i + 15, j + 2, k + 2, PlaceDeepslate, 0, 2);
		world.setBlock(i + 16, j + 2, k + 2, PlaceDeepslate, 0, 2);
		world.setBlock(i + 17, j + 2, k + 2, PlaceDeepslate, 0, 2);
		world.setBlock(i + 18, j + 2, k + 2, PlaceDeepslate, 0, 2);
		world.setBlock(i + 0, j + 2, k + 3, PlaceDeepslate, 0, 2);
		world.setBlock(i + 1, j + 2, k + 3, PlaceDeepslate, 0, 2);
		world.setBlock(i + 2, j + 2, k + 3, PlaceDeepslate, 0, 2);
		world.setBlock(i + 3, j + 2, k + 3, PlaceDeepslate, 0, 2);
		world.setBlock(i + 4, j + 2, k + 3, PlaceDeepslate, 0, 2);
		world.setBlock(i + 5, j + 2, k + 3, PlaceDeepslate, 0, 2);
		world.setBlock(i + 6, j + 2, k + 3, PlaceDeepslate, 0, 2);
		world.setBlock(i + 7, j + 2, k + 3, PlaceDeepslate, 0, 2);
		world.setBlock(i + 8, j + 2, k + 3, PlaceDeepslate, 0, 2);
		world.setBlock(i + 9, j + 2, k + 3, PlaceDeepslate, 0, 2);
		world.setBlock(i + 10, j + 2, k + 3, PlaceDeepslate, 0, 2);
		world.setBlock(i + 11, j + 2, k + 3, PlaceDeepslate, 0, 2);
		world.setBlock(i + 12, j + 2, k + 3, PlaceDeepslate, 0, 2);
		world.setBlock(i + 13, j + 2, k + 3, PlaceDeepslate, 0, 2);
		world.setBlock(i + 14, j + 2, k + 3, PlaceDeepslate, 0, 2);
		world.setBlock(i + 15, j + 2, k + 3, PlaceDeepslate, 0, 2);
		world.setBlock(i + 16, j + 2, k + 3, PlaceDeepslate, 0, 2);
		world.setBlock(i + 17, j + 2, k + 3, PlaceDeepslate, 0, 2);
		world.setBlock(i + 18, j + 2, k + 3, PlaceDeepslate, 0, 2);
		world.setBlock(i + 0, j + 2, k + 4, PlaceDeepslate, 0, 2);
		world.setBlock(i + 1, j + 2, k + 4, PlaceDeepslate, 0, 2);
		world.setBlock(i + 2, j + 2, k + 4, PlaceDeepslate, 0, 2);
		world.setBlock(i + 3, j + 2, k + 4, PlaceDeepslate, 0, 2);
		world.setBlock(i + 4, j + 2, k + 4, PlaceDeepslate, 0, 2);
		world.setBlock(i + 5, j + 2, k + 4, PlaceDeepslate, 0, 2);
		world.setBlock(i + 6, j + 2, k + 4, PlaceDeepslate, 0, 2);
		world.setBlock(i + 7, j + 2, k + 4, PlaceDeepslate, 0, 2);
		world.setBlock(i + 8, j + 2, k + 4, PlaceDeepslate, 0, 2);
		world.setBlock(i + 9, j + 2, k + 4, PlaceDeepslate, 0, 2);
		world.setBlock(i + 10, j + 2, k + 4, PlaceDeepslate, 0, 2);
		world.setBlock(i + 11, j + 2, k + 4, PlaceDeepslate, 0, 2);
		world.setBlock(i + 12, j + 2, k + 4, PlaceDeepslate, 0, 2);
		world.setBlock(i + 13, j + 2, k + 4, PlaceDeepslate, 0, 2);
		world.setBlock(i + 14, j + 2, k + 4, PlaceDeepslate, 0, 2);
		world.setBlock(i + 15, j + 2, k + 4, PlaceDeepslate, 0, 2);
		world.setBlock(i + 16, j + 2, k + 4, PlaceDeepslate, 0, 2);
		world.setBlock(i + 17, j + 2, k + 4, PlaceDeepslate, 0, 2);
		world.setBlock(i + 18, j + 2, k + 4, PlaceDeepslate, 0, 2);
		world.setBlock(i + 0, j + 2, k + 5, PlaceDeepslate, 0, 2);
		world.setBlock(i + 1, j + 2, k + 5, PlaceDeepslate, 0, 2);
		world.setBlock(i + 2, j + 2, k + 5, PlaceDeepslate, 0, 2);
		world.setBlock(i + 3, j + 2, k + 5, PlaceDeepslate, 0, 2);
		world.setBlock(i + 4, j + 2, k + 5, PlaceDeepslate, 0, 2);
		world.setBlock(i + 5, j + 2, k + 5, PlaceDeepslate, 0, 2);
		world.setBlock(i + 6, j + 2, k + 5, PlaceDeepslate, 0, 2);
		world.setBlock(i + 7, j + 2, k + 5, PlaceDeepslate, 0, 2);
		world.setBlock(i + 8, j + 2, k + 5, PlaceDeepslate, 0, 2);
		world.setBlock(i + 9, j + 2, k + 5, PlaceDeepslate, 0, 2);
		world.setBlock(i + 10, j + 2, k + 5, PlaceDeepslate, 0, 2);
		world.setBlock(i + 11, j + 2, k + 5, PlaceDeepslate, 0, 2);
		world.setBlock(i + 12, j + 2, k + 5, PlaceDeepslate, 0, 2);
		world.setBlock(i + 13, j + 2, k + 5, PlaceDeepslate, 0, 2);
		world.setBlock(i + 14, j + 2, k + 5, PlaceDeepslate, 0, 2);
		world.setBlock(i + 15, j + 2, k + 5, PlaceDeepslate, 0, 2);
		world.setBlock(i + 16, j + 2, k + 5, PlaceDeepslate, 0, 2);
		world.setBlock(i + 17, j + 2, k + 5, PlaceDeepslate, 0, 2);
		world.setBlock(i + 18, j + 2, k + 5, PlaceDeepslate, 0, 2);
		world.setBlock(i + 0, j + 2, k + 6, PlaceDeepslate, 0, 2);
		world.setBlock(i + 1, j + 2, k + 6, PlaceDeepslate, 0, 2);
		world.setBlock(i + 2, j + 2, k + 6, PlaceDeepslate, 0, 2);
		world.setBlock(i + 3, j + 2, k + 6, PlaceDeepslate, 0, 2);
		world.setBlock(i + 4, j + 2, k + 6, PlaceDeepslate, 0, 2);
		world.setBlock(i + 5, j + 2, k + 6, PlaceDeepslate, 0, 2);
		world.setBlock(i + 6, j + 2, k + 6, PlaceDeepslate, 0, 2);
		world.setBlock(i + 7, j + 2, k + 6, PlaceDeepslate, 0, 2);
		world.setBlock(i + 8, j + 2, k + 6, PlaceDeepslate, 0, 2);
		world.setBlock(i + 9, j + 2, k + 6, PlaceDeepslate, 0, 2);
		world.setBlock(i + 10, j + 2, k + 6, PlaceDeepslate, 0, 2);
		world.setBlock(i + 11, j + 2, k + 6, PlaceDeepslate, 0, 2);
		world.setBlock(i + 12, j + 2, k + 6, PlaceDeepslate, 0, 2);
		world.setBlock(i + 13, j + 2, k + 6, PlaceDeepslate, 0, 2);
		world.setBlock(i + 14, j + 2, k + 6, PlaceDeepslate, 0, 2);
		world.setBlock(i + 15, j + 2, k + 6, PlaceDeepslate, 0, 2);
		world.setBlock(i + 16, j + 2, k + 6, PlaceDeepslate, 0, 2);
		world.setBlock(i + 17, j + 2, k + 6, PlaceDeepslate, 0, 2);
		world.setBlock(i + 18, j + 2, k + 6, PlaceDeepslate, 0, 2);
		world.setBlock(i + 0, j + 2, k + 7, PlaceDeepslate, 0, 2);
		world.setBlock(i + 1, j + 2, k + 7, PlaceDeepslate, 0, 2);
		world.setBlock(i + 2, j + 2, k + 7, PlaceDeepslate, 0, 2);
		world.setBlock(i + 3, j + 2, k + 7, PlaceDeepslate, 0, 2);
		world.setBlock(i + 4, j + 2, k + 7, PlaceDeepslate, 0, 2);
		world.setBlock(i + 5, j + 2, k + 7, PlaceDeepslate, 0, 2);
		world.setBlock(i + 6, j + 2, k + 7, PlaceDeepslate, 0, 2);
		world.setBlock(i + 7, j + 2, k + 7, PlaceDeepslate, 0, 2);
		world.setBlock(i + 8, j + 2, k + 7, PlaceDeepslate, 0, 2);
		world.setBlock(i + 9, j + 2, k + 7, PlaceDeepslate, 0, 2);
		world.setBlock(i + 10, j + 2, k + 7, PlaceDeepslate, 0, 2);
		world.setBlock(i + 11, j + 2, k + 7, PlaceDeepslate, 0, 2);
		world.setBlock(i + 12, j + 2, k + 7, PlaceDeepslate, 0, 2);
		world.setBlock(i + 13, j + 2, k + 7, PlaceDeepslate, 0, 2);
		world.setBlock(i + 14, j + 2, k + 7, PlaceDeepslate, 0, 2);
		world.setBlock(i + 15, j + 2, k + 7, PlaceDeepslate, 0, 2);
		world.setBlock(i + 16, j + 2, k + 7, PlaceDeepslate, 0, 2);
		world.setBlock(i + 17, j + 2, k + 7, PlaceDeepslate, 0, 2);
		world.setBlock(i + 18, j + 2, k + 7, PlaceDeepslate, 0, 2);
		world.setBlock(i + 0, j + 2, k + 8, PlaceDeepslate, 0, 2);
		world.setBlock(i + 1, j + 2, k + 8, PlaceDeepslate, 0, 2);
		world.setBlock(i + 2, j + 2, k + 8, PlaceDeepslate, 0, 2);
		world.setBlock(i + 3, j + 2, k + 8, PlaceDeepslate, 0, 2);
		world.setBlock(i + 4, j + 2, k + 8, PlaceDeepslate, 0, 2);
		world.setBlock(i + 5, j + 2, k + 8, PlaceDeepslate, 0, 2);
		world.setBlock(i + 6, j + 2, k + 8, PlaceDeepslate, 0, 2);
		world.setBlock(i + 7, j + 2, k + 8, PlaceDeepslate, 0, 2);
		world.setBlock(i + 8, j + 2, k + 8, PlaceDeepslate, 0, 2);
		world.setBlock(i + 9, j + 2, k + 8, PlaceDeepslate, 0, 2);
		world.setBlock(i + 10, j + 2, k + 8, PlaceDeepslate, 0, 2);
		world.setBlock(i + 11, j + 2, k + 8, PlaceDeepslate, 0, 2);
		world.setBlock(i + 12, j + 2, k + 8, PlaceDeepslate, 0, 2);
		world.setBlock(i + 13, j + 2, k + 8, PlaceDeepslate, 0, 2);
		world.setBlock(i + 14, j + 2, k + 8, PlaceDeepslate, 0, 2);
		world.setBlock(i + 15, j + 2, k + 8, PlaceDeepslate, 0, 2);
		world.setBlock(i + 16, j + 2, k + 8, PlaceDeepslate, 0, 2);
		world.setBlock(i + 17, j + 2, k + 8, PlaceDeepslate, 0, 2);
		world.setBlock(i + 18, j + 2, k + 8, PlaceDeepslate, 0, 2);
		world.setBlock(i + 19, j + 2, k + 8, PlaceDeepslate, 0, 2);
		world.setBlock(i + 0, j + 2, k + 9, PlaceDeepslate, 0, 2);
		world.setBlock(i + 1, j + 2, k + 9, PlaceDeepslate, 0, 2);
		world.setBlock(i + 2, j + 2, k + 9, PlaceDeepslate, 0, 2);
		world.setBlock(i + 3, j + 2, k + 9, PlaceDeepslate, 0, 2);
		world.setBlock(i + 4, j + 2, k + 9, PlaceDeepslate, 0, 2);
		world.setBlock(i + 5, j + 2, k + 9, PlaceDeepslate, 0, 2);
		world.setBlock(i + 6, j + 2, k + 9, PlaceDeepslate, 0, 2);
		world.setBlock(i + 7, j + 2, k + 9, PlaceDeepslate, 0, 2);
		world.setBlock(i + 8, j + 2, k + 9, PlaceDeepslate, 0, 2);
		world.setBlock(i + 9, j + 2, k + 9, PlaceDeepslate, 0, 2);
		world.setBlock(i + 10, j + 2, k + 9, PlaceDeepslate, 0, 2);
		world.setBlock(i + 11, j + 2, k + 9, PlaceDeepslate, 0, 2);
		world.setBlock(i + 12, j + 2, k + 9, PlaceDeepslate, 0, 2);
		world.setBlock(i + 13, j + 2, k + 9, PlaceDeepslate, 0, 2);
		world.setBlock(i + 14, j + 2, k + 9, PlaceDeepslate, 0, 2);
		world.setBlock(i + 15, j + 2, k + 9, PlaceDeepslate, 0, 2);
		world.setBlock(i + 16, j + 2, k + 9, PlaceDeepslate, 0, 2);
		world.setBlock(i + 17, j + 2, k + 9, PlaceDeepslate, 0, 2);
		world.setBlock(i + 18, j + 2, k + 9, PlaceDeepslate, 0, 2);
		world.setBlock(i + 19, j + 2, k + 9, PlaceDeepslate, 0, 2);
		world.setBlock(i + 20, j + 2, k + 9, PlaceDeepslate, 0, 2);
		world.setBlock(i + 0, j + 2, k + 10, PlaceDeepslate, 0, 2);
		world.setBlock(i + 1, j + 2, k + 10, PlaceDeepslate, 0, 2);
		world.setBlock(i + 2, j + 2, k + 10, PlaceDeepslate, 0, 2);
		world.setBlock(i + 3, j + 2, k + 10, PlaceDeepslate, 0, 2);
		world.setBlock(i + 4, j + 2, k + 10, PlaceDeepslate, 0, 2);
		world.setBlock(i + 5, j + 2, k + 10, PlaceDeepslate, 0, 2);
		world.setBlock(i + 6, j + 2, k + 10, PlaceDeepslate, 0, 2);
		world.setBlock(i + 7, j + 2, k + 10, PlaceDeepslate, 0, 2);
		world.setBlock(i + 8, j + 2, k + 10, PlaceDeepslate, 0, 2);
		world.setBlock(i + 9, j + 2, k + 10, PlaceDeepslate, 0, 2);
		world.setBlock(i + 10, j + 2, k + 10, PlaceDeepslate, 0, 2);
		world.setBlock(i + 11, j + 2, k + 10, PlaceDeepslate, 0, 2);
		world.setBlock(i + 12, j + 2, k + 10, PlaceDeepslate, 0, 2);
		world.setBlock(i + 13, j + 2, k + 10, PlaceDeepslate, 0, 2);
		world.setBlock(i + 14, j + 2, k + 10, PlaceDeepslate, 0, 2);
		world.setBlock(i + 15, j + 2, k + 10, PlaceDeepslate, 0, 2);
		world.setBlock(i + 16, j + 2, k + 10, PlaceDeepslate, 0, 2);
		world.setBlock(i + 17, j + 2, k + 10, PlaceDeepslate, 0, 2);
		world.setBlock(i + 18, j + 2, k + 10, PlaceDeepslate, 0, 2);
		world.setBlock(i + 19, j + 2, k + 10, PlaceDeepslate, 0, 2);
		world.setBlock(i + 20, j + 2, k + 10, PlaceDeepslate, 0, 2);
		world.setBlock(i + 21, j + 2, k + 10, PlaceDeepslate, 0, 2);
		world.setBlock(i + 0, j + 2, k + 11, PlaceDeepslate, 0, 2);
		world.setBlock(i + 1, j + 2, k + 11, PlaceDeepslate, 0, 2);
		world.setBlock(i + 2, j + 2, k + 11, PlaceDeepslate, 0, 2);
		world.setBlock(i + 3, j + 2, k + 11, PlaceDeepslate, 0, 2);
		world.setBlock(i + 4, j + 2, k + 11, PlaceDeepslate, 0, 2);
		world.setBlock(i + 5, j + 2, k + 11, PlaceDeepslate, 0, 2);
		world.setBlock(i + 6, j + 2, k + 11, PlaceDeepslate, 0, 2);
		world.setBlock(i + 7, j + 2, k + 11, PlaceDeepslate, 0, 2);
		world.setBlock(i + 8, j + 2, k + 11, PlaceDeepslate, 0, 2);
		world.setBlock(i + 9, j + 2, k + 11, PlaceDeepslate, 0, 2);
		world.setBlock(i + 10, j + 2, k + 11, PlaceDeepslate, 0, 2);
		world.setBlock(i + 11, j + 2, k + 11, PlaceDeepslate, 0, 2);
		world.setBlock(i + 12, j + 2, k + 11, PlaceDeepslate, 0, 2);
		world.setBlock(i + 13, j + 2, k + 11, PlaceDeepslate, 0, 2);
		world.setBlock(i + 14, j + 2, k + 11, PlaceDeepslate, 0, 2);
		world.setBlock(i + 15, j + 2, k + 11, PlaceDeepslate, 0, 2);
		world.setBlock(i + 16, j + 2, k + 11, PlaceDeepslate, 0, 2);
		world.setBlock(i + 17, j + 2, k + 11, PlaceDeepslate, 0, 2);
		world.setBlock(i + 18, j + 2, k + 11, PlaceDeepslate, 0, 2);
		world.setBlock(i + 19, j + 2, k + 11, PlaceDeepslate, 0, 2);
		world.setBlock(i + 20, j + 2, k + 11, PlaceDeepslate, 0, 2);
		world.setBlock(i + 21, j + 2, k + 11, PlaceDeepslate, 0, 2);
		world.setBlock(i + 0, j + 2, k + 12, PlaceDeepslate, 0, 2);
		world.setBlock(i + 1, j + 2, k + 12, PlaceDeepslate, 0, 2);
		world.setBlock(i + 2, j + 2, k + 12, PlaceDeepslate, 0, 2);
		world.setBlock(i + 3, j + 2, k + 12, PlaceDeepslate, 0, 2);
		world.setBlock(i + 4, j + 2, k + 12, PlaceDeepslate, 0, 2);
		world.setBlock(i + 5, j + 2, k + 12, PlaceDeepslate, 0, 2);
		world.setBlock(i + 6, j + 2, k + 12, PlaceDeepslate, 0, 2);
		world.setBlock(i + 7, j + 2, k + 12, PlaceDeepslate, 0, 2);
		world.setBlock(i + 8, j + 2, k + 12, PlaceDeepslate, 0, 2);
		world.setBlock(i + 9, j + 2, k + 12, PlaceDeepslate, 0, 2);
		world.setBlock(i + 10, j + 2, k + 12, PlaceDeepslate, 0, 2);
		world.setBlock(i + 11, j + 2, k + 12, PlaceDeepslate, 0, 2);
		world.setBlock(i + 12, j + 2, k + 12, PlaceDeepslate, 0, 2);
		world.setBlock(i + 13, j + 2, k + 12, PlaceDeepslate, 0, 2);
		world.setBlock(i + 14, j + 2, k + 12, PlaceDeepslate, 0, 2);
		world.setBlock(i + 15, j + 2, k + 12, PlaceDeepslate, 0, 2);
		world.setBlock(i + 16, j + 2, k + 12, PlaceDeepslate, 0, 2);
		world.setBlock(i + 17, j + 2, k + 12, PlaceDeepslate, 0, 2);
		world.setBlock(i + 18, j + 2, k + 12, PlaceDeepslate, 0, 2);
		world.setBlock(i + 19, j + 2, k + 12, PlaceDeepslate, 0, 2);
		world.setBlock(i + 20, j + 2, k + 12, PlaceDeepslate, 0, 2);
		world.setBlock(i + 21, j + 2, k + 12, PlaceDeepslate, 0, 2);
		world.setBlock(i + 0, j + 2, k + 13, PlaceDeepslate, 0, 2);
		world.setBlock(i + 1, j + 2, k + 13, PlaceDeepslate, 0, 2);
		world.setBlock(i + 2, j + 2, k + 13, PlaceDeepslate, 0, 2);
		world.setBlock(i + 3, j + 2, k + 13, PlaceDeepslate, 0, 2);
		world.setBlock(i + 4, j + 2, k + 13, PlaceDeepslate, 0, 2);
		world.setBlock(i + 5, j + 2, k + 13, PlaceDeepslate, 0, 2);
		world.setBlock(i + 6, j + 2, k + 13, PlaceDeepslate, 0, 2);
		world.setBlock(i + 7, j + 2, k + 13, PlaceDeepslate, 0, 2);
		world.setBlock(i + 8, j + 2, k + 13, PlaceDeepslate, 0, 2);
		world.setBlock(i + 9, j + 2, k + 13, PlaceDeepslate, 0, 2);
		world.setBlock(i + 10, j + 2, k + 13, PlaceDeepslate, 0, 2);
		world.setBlock(i + 11, j + 2, k + 13, PlaceDeepslate, 0, 2);
		world.setBlock(i + 12, j + 2, k + 13, PlaceDeepslate, 0, 2);
		world.setBlock(i + 13, j + 2, k + 13, PlaceDeepslate, 0, 2);
		world.setBlock(i + 14, j + 2, k + 13, PlaceDeepslate, 0, 2);
		world.setBlock(i + 15, j + 2, k + 13, PlaceDeepslate, 0, 2);
		world.setBlock(i + 16, j + 2, k + 13, PlaceDeepslate, 0, 2);
		world.setBlock(i + 17, j + 2, k + 13, PlaceDeepslate, 0, 2);
		world.setBlock(i + 18, j + 2, k + 13, PlaceDeepslate, 0, 2);
		world.setBlock(i + 19, j + 2, k + 13, PlaceDeepslate, 0, 2);
		world.setBlock(i + 20, j + 2, k + 13, PlaceDeepslate, 0, 2);
		world.setBlock(i + 21, j + 2, k + 13, PlaceDeepslate, 0, 2);
		world.setBlock(i + 0, j + 2, k + 14, PlaceDeepslate, 0, 2);
		world.setBlock(i + 1, j + 2, k + 14, PlaceDeepslate, 0, 2);
		world.setBlock(i + 2, j + 2, k + 14, PlaceDeepslate, 0, 2);
		world.setBlock(i + 3, j + 2, k + 14, PlaceDeepslate, 0, 2);
		world.setBlock(i + 4, j + 2, k + 14, PlaceDeepslate, 0, 2);
		world.setBlock(i + 5, j + 2, k + 14, PlaceDeepslate, 0, 2);
		world.setBlock(i + 6, j + 2, k + 14, PlaceDeepslate, 0, 2);
		world.setBlock(i + 7, j + 2, k + 14, PlaceDeepslate, 0, 2);
		world.setBlock(i + 8, j + 2, k + 14, PlaceDeepslate, 0, 2);
		world.setBlock(i + 9, j + 2, k + 14, PlaceDeepslate, 0, 2);
		world.setBlock(i + 10, j + 2, k + 14, PlaceDeepslate, 0, 2);
		world.setBlock(i + 11, j + 2, k + 14, PlaceDeepslate, 0, 2);
		world.setBlock(i + 12, j + 2, k + 14, PlaceDeepslate, 0, 2);
		world.setBlock(i + 13, j + 2, k + 14, PlaceDeepslate, 0, 2);
		world.setBlock(i + 14, j + 2, k + 14, PlaceDeepslate, 0, 2);
		world.setBlock(i + 15, j + 2, k + 14, PlaceDeepslate, 0, 2);
		world.setBlock(i + 16, j + 2, k + 14, PlaceDeepslate, 0, 2);
		world.setBlock(i + 17, j + 2, k + 14, PlaceDeepslate, 0, 2);
		world.setBlock(i + 18, j + 2, k + 14, PlaceDeepslate, 0, 2);
		world.setBlock(i + 19, j + 2, k + 14, PlaceDeepslate, 0, 2);
		world.setBlock(i + 20, j + 2, k + 14, PlaceDeepslate, 0, 2);
		world.setBlock(i + 21, j + 2, k + 14, PlaceDeepslate, 0, 2);
		world.setBlock(i + 0, j + 2, k + 15, PlaceDeepslate, 0, 2);
		world.setBlock(i + 1, j + 2, k + 15, PlaceDeepslate, 0, 2);
		world.setBlock(i + 2, j + 2, k + 15, PlaceDeepslate, 0, 2);
		world.setBlock(i + 3, j + 2, k + 15, PlaceDeepslate, 0, 2);
		world.setBlock(i + 4, j + 2, k + 15, PlaceDeepslate, 0, 2);
		world.setBlock(i + 5, j + 2, k + 15, PlaceDeepslate, 0, 2);
		world.setBlock(i + 6, j + 2, k + 15, PlaceDeepslate, 0, 2);
		world.setBlock(i + 7, j + 2, k + 15, PlaceDeepslate, 0, 2);
		world.setBlock(i + 8, j + 2, k + 15, PlaceDeepslate, 0, 2);
		world.setBlock(i + 9, j + 2, k + 15, PlaceDeepslate, 0, 2);
		world.setBlock(i + 10, j + 2, k + 15, PlaceDeepslate, 0, 2);
		world.setBlock(i + 11, j + 2, k + 15, PlaceDeepslate, 0, 2);
		world.setBlock(i + 12, j + 2, k + 15, PlaceDeepslate, 0, 2);
		world.setBlock(i + 13, j + 2, k + 15, PlaceDeepslate, 0, 2);
		world.setBlock(i + 14, j + 2, k + 15, PlaceDeepslate, 0, 2);
		world.setBlock(i + 15, j + 2, k + 15, PlaceDeepslate, 0, 2);
		world.setBlock(i + 16, j + 2, k + 15, PlaceDeepslate, 0, 2);
		world.setBlock(i + 17, j + 2, k + 15, PlaceDeepslate, 0, 2);
		world.setBlock(i + 18, j + 2, k + 15, PlaceDeepslate, 0, 2);
		world.setBlock(i + 19, j + 2, k + 15, PlaceDeepslate, 0, 2);
		world.setBlock(i + 20, j + 2, k + 15, PlaceDeepslate, 0, 2);
		world.setBlock(i + 21, j + 2, k + 15, PlaceDeepslate, 0, 2);
		world.setBlock(i + 0, j + 2, k + 16, PlaceDeepslate, 0, 2);
		world.setBlock(i + 1, j + 2, k + 16, PlaceDeepslate, 0, 2);
		world.setBlock(i + 2, j + 2, k + 16, PlaceDeepslate, 0, 2);
		world.setBlock(i + 3, j + 2, k + 16, PlaceDeepslate, 0, 2);
		world.setBlock(i + 4, j + 2, k + 16, PlaceDeepslate, 0, 2);
		world.setBlock(i + 5, j + 2, k + 16, PlaceDeepslate, 0, 2);
		world.setBlock(i + 6, j + 2, k + 16, PlaceDeepslate, 0, 2);
		world.setBlock(i + 7, j + 2, k + 16, PlaceDeepslate, 0, 2);
		world.setBlock(i + 8, j + 2, k + 16, PlaceDeepslate, 0, 2);
		world.setBlock(i + 9, j + 2, k + 16, PlaceDeepslate, 0, 2);
		world.setBlock(i + 10, j + 2, k + 16, PlaceDeepslate, 0, 2);
		world.setBlock(i + 11, j + 2, k + 16, PlaceDeepslate, 0, 2);
		world.setBlock(i + 12, j + 2, k + 16, PlaceDeepslate, 0, 2);
		world.setBlock(i + 13, j + 2, k + 16, PlaceDeepslate, 0, 2);
		world.setBlock(i + 14, j + 2, k + 16, PlaceDeepslate, 0, 2);
		world.setBlock(i + 15, j + 2, k + 16, PlaceDeepslate, 0, 2);
		world.setBlock(i + 16, j + 2, k + 16, PlaceDeepslate, 0, 2);
		world.setBlock(i + 17, j + 2, k + 16, PlaceDeepslate, 0, 2);
		world.setBlock(i + 18, j + 2, k + 16, PlaceDeepslate, 0, 2);
		world.setBlock(i + 19, j + 2, k + 16, PlaceDeepslate, 0, 2);
		world.setBlock(i + 20, j + 2, k + 16, PlaceDeepslate, 0, 2);
		world.setBlock(i + 21, j + 2, k + 16, PlaceDeepslate, 0, 2);
		world.setBlock(i + 0, j + 2, k + 17, PlaceDeepslate, 0, 2);
		world.setBlock(i + 1, j + 2, k + 17, PlaceDeepslate, 0, 2);
		world.setBlock(i + 2, j + 2, k + 17, PlaceDeepslate, 0, 2);
		world.setBlock(i + 3, j + 2, k + 17, PlaceDeepslate, 0, 2);
		world.setBlock(i + 4, j + 2, k + 17, PlaceDeepslate, 0, 2);
		world.setBlock(i + 5, j + 2, k + 17, PlaceDeepslate, 0, 2);
		world.setBlock(i + 6, j + 2, k + 17, PlaceDeepslate, 0, 2);
		world.setBlock(i + 7, j + 2, k + 17, PlaceDeepslate, 0, 2);
		world.setBlock(i + 8, j + 2, k + 17, PlaceDeepslate, 0, 2);
		world.setBlock(i + 9, j + 2, k + 17, PlaceDeepslate, 0, 2);
		world.setBlock(i + 10, j + 2, k + 17, PlaceDeepslate, 0, 2);
		world.setBlock(i + 11, j + 2, k + 17, PlaceDeepslate, 0, 2);
		world.setBlock(i + 12, j + 2, k + 17, PlaceDeepslate, 0, 2);
		world.setBlock(i + 13, j + 2, k + 17, PlaceDeepslate, 0, 2);
		world.setBlock(i + 14, j + 2, k + 17, PlaceDeepslate, 0, 2);
		world.setBlock(i + 15, j + 2, k + 17, PlaceDeepslate, 0, 2);
		world.setBlock(i + 16, j + 2, k + 17, PlaceDeepslate, 0, 2);
		world.setBlock(i + 17, j + 2, k + 17, PlaceDeepslate, 0, 2);
		world.setBlock(i + 18, j + 2, k + 17, PlaceDeepslate, 0, 2);
		world.setBlock(i + 19, j + 2, k + 17, PlaceDeepslate, 0, 2);
		world.setBlock(i + 20, j + 2, k + 17, PlaceDeepslate, 0, 2);
		world.setBlock(i + 21, j + 2, k + 17, PlaceDeepslate, 0, 2);
		world.setBlock(i + 1, j + 2, k + 18, PlaceDeepslate, 0, 2);
		world.setBlock(i + 2, j + 2, k + 18, PlaceDeepslate, 0, 2);
		world.setBlock(i + 3, j + 2, k + 18, PlaceDeepslate, 0, 2);
		world.setBlock(i + 4, j + 2, k + 18, PlaceDeepslate, 0, 2);
		world.setBlock(i + 5, j + 2, k + 18, PlaceDeepslate, 0, 2);
		world.setBlock(i + 6, j + 2, k + 18, PlaceDeepslate, 0, 2);
		world.setBlock(i + 7, j + 2, k + 18, PlaceDeepslate, 0, 2);
		world.setBlock(i + 8, j + 2, k + 18, PlaceDeepslate, 0, 2);
		world.setBlock(i + 9, j + 2, k + 18, PlaceDeepslate, 0, 2);
		world.setBlock(i + 10, j + 2, k + 18, PlaceDeepslate, 0, 2);
		world.setBlock(i + 11, j + 2, k + 18, PlaceDeepslate, 0, 2);
		world.setBlock(i + 12, j + 2, k + 18, PlaceDeepslate, 0, 2);
		world.setBlock(i + 13, j + 2, k + 18, PlaceDeepslate, 0, 2);
		world.setBlock(i + 14, j + 2, k + 18, PlaceDeepslate, 0, 2);
		world.setBlock(i + 15, j + 2, k + 18, PlaceDeepslate, 0, 2);
		world.setBlock(i + 16, j + 2, k + 18, PlaceDeepslate, 0, 2);
		world.setBlock(i + 17, j + 2, k + 18, PlaceDeepslate, 0, 2);
		world.setBlock(i + 18, j + 2, k + 18, PlaceDeepslate, 0, 2);
		world.setBlock(i + 19, j + 2, k + 18, PlaceDeepslate, 0, 2);
		world.setBlock(i + 20, j + 2, k + 18, PlaceDeepslate, 0, 2);
		world.setBlock(i + 21, j + 2, k + 18, PlaceDeepslate, 0, 2);
		world.setBlock(i + 2, j + 2, k + 19, PlaceDeepslate, 0, 2);
		world.setBlock(i + 3, j + 2, k + 19, PlaceDeepslate, 0, 2);
		world.setBlock(i + 4, j + 2, k + 19, PlaceDeepslate, 0, 2);
		world.setBlock(i + 5, j + 2, k + 19, PlaceDeepslate, 0, 2);
		world.setBlock(i + 6, j + 2, k + 19, PlaceDeepslate, 0, 2);
		world.setBlock(i + 7, j + 2, k + 19, PlaceDeepslate, 0, 2);
		world.setBlock(i + 8, j + 2, k + 19, PlaceDeepslate, 0, 2);
		world.setBlock(i + 9, j + 2, k + 19, PlaceDeepslate, 0, 2);
		world.setBlock(i + 10, j + 2, k + 19, PlaceDeepslate, 0, 2);
		world.setBlock(i + 11, j + 2, k + 19, PlaceDeepslate, 0, 2);
		world.setBlock(i + 12, j + 2, k + 19, PlaceDeepslate, 0, 2);
		world.setBlock(i + 13, j + 2, k + 19, PlaceDeepslate, 0, 2);
		world.setBlock(i + 14, j + 2, k + 19, PlaceDeepslate, 0, 2);
		world.setBlock(i + 15, j + 2, k + 19, PlaceDeepslate, 0, 2);
		world.setBlock(i + 16, j + 2, k + 19, PlaceDeepslate, 0, 2);
		world.setBlock(i + 17, j + 2, k + 19, PlaceDeepslate, 0, 2);
		world.setBlock(i + 18, j + 2, k + 19, PlaceDeepslate, 0, 2);
		world.setBlock(i + 19, j + 2, k + 19, PlaceDeepslate, 0, 2);
		world.setBlock(i + 20, j + 2, k + 19, PlaceDeepslate, 0, 2);
		world.setBlock(i + 3, j + 3, k + 0, PlaceDeepslate, 0, 2);
		world.setBlock(i + 4, j + 3, k + 0, PlaceDeepslate, 0, 2);
		world.setBlock(i + 5, j + 3, k + 0, PlaceDeepslate, 0, 2);
		world.setBlock(i + 6, j + 3, k + 0, PlaceDeepslate, 0, 2);
		world.setBlock(i + 7, j + 3, k + 0, PlaceDeepslate, 0, 2);
		world.setBlock(i + 8, j + 3, k + 0, PlaceDeepslate, 0, 2);
		world.setBlock(i + 9, j + 3, k + 0, PlaceDeepslate, 0, 2);
		world.setBlock(i + 10, j + 3, k + 0, PlaceDeepslate, 0, 2);
		world.setBlock(i + 11, j + 3, k + 0, PlaceDeepslate, 0, 2);
		world.setBlock(i + 12, j + 3, k + 0, PlaceDeepslate, 0, 2);
		world.setBlock(i + 13, j + 3, k + 0, PlaceDeepslate, 0, 2);
		world.setBlock(i + 14, j + 3, k + 0, PlaceDeepslate, 0, 2);
		world.setBlock(i + 15, j + 3, k + 0, PlaceDeepslate, 0, 2);
		world.setBlock(i + 16, j + 3, k + 0, PlaceDeepslate, 0, 2);
		world.setBlock(i + 17, j + 3, k + 0, PlaceDeepslate, 0, 2);
		world.setBlock(i + 2, j + 3, k + 1, PlaceDeepslate, 0, 2);
		world.setBlock(i + 3, j + 3, k + 1, PlaceDeepslate, 0, 2);
		world.setBlock(i + 4, j + 3, k + 1, PlaceDeepslate, 0, 2);
		world.setBlock(i + 5, j + 3, k + 1, PlaceDeepslate, 0, 2);
		world.setBlock(i + 6, j + 3, k + 1, PlaceDeepslate, 0, 2);
		world.setBlock(i + 7, j + 3, k + 1, PlaceDeepslate, 0, 2);
		world.setBlock(i + 8, j + 3, k + 1, PlaceDeepslate, 0, 2);
		world.setBlock(i + 9, j + 3, k + 1, PlaceDeepslate, 0, 2);
		world.setBlock(i + 10, j + 3, k + 1, PlaceDeepslate, 0, 2);
		world.setBlock(i + 11, j + 3, k + 1, PlaceDeepslate, 0, 2);
		world.setBlock(i + 12, j + 3, k + 1, PlaceDeepslate, 0, 2);
		world.setBlock(i + 13, j + 3, k + 1, PlaceDeepslate, 0, 2);
		world.setBlock(i + 14, j + 3, k + 1, PlaceDeepslate, 0, 2);
		world.setBlock(i + 15, j + 3, k + 1, PlaceDeepslate, 0, 2);
		world.setBlock(i + 16, j + 3, k + 1, PlaceDeepslate, 0, 2);
		world.setBlock(i + 17, j + 3, k + 1, PlaceDeepslate, 0, 2);
		world.setBlock(i + 18, j + 3, k + 1, PlaceDeepslate, 0, 2);
		world.setBlock(i + 1, j + 3, k + 2, PlaceDeepslate, 0, 2);
		world.setBlock(i + 2, j + 3, k + 2, PlaceDeepslate, 0, 2);
		world.setBlock(i + 3, j + 3, k + 2, PlaceDeepslate, 0, 2);
		world.setBlock(i + 4, j + 3, k + 2, PlaceDeepslate, 0, 2);
		world.setBlock(i + 5, j + 3, k + 2, PlaceDeepslate, 0, 2);
		world.setBlock(i + 6, j + 3, k + 2, PlaceDeepslate, 0, 2);
		world.setBlock(i + 7, j + 3, k + 2, PlaceDeepslate, 0, 2);
		world.setBlock(i + 8, j + 3, k + 2, PlaceDeepslate, 0, 2);
		world.setBlock(i + 9, j + 3, k + 2, PlaceDeepslate, 0, 2);
		world.setBlock(i + 10, j + 3, k + 2, PlaceDeepslate, 0, 2);
		world.setBlock(i + 11, j + 3, k + 2, PlaceDeepslate, 0, 2);
		world.setBlock(i + 12, j + 3, k + 2, PlaceDeepslate, 0, 2);
		world.setBlock(i + 13, j + 3, k + 2, PlaceDeepslate, 0, 2);
		world.setBlock(i + 14, j + 3, k + 2, PlaceDeepslate, 0, 2);
		world.setBlock(i + 15, j + 3, k + 2, PlaceDeepslate, 0, 2);
		world.setBlock(i + 16, j + 3, k + 2, PlaceDeepslate, 0, 2);
		world.setBlock(i + 17, j + 3, k + 2, PlaceDeepslate, 0, 2);
		world.setBlock(i + 18, j + 3, k + 2, PlaceDeepslate, 0, 2);
		world.setBlock(i + 0, j + 3, k + 3, PlaceDeepslate, 0, 2);
		world.setBlock(i + 1, j + 3, k + 3, PlaceDeepslate, 0, 2);
		world.setBlock(i + 2, j + 3, k + 3, PlaceDeepslate, 0, 2);
		world.setBlock(i + 3, j + 3, k + 3, PlaceDeepslate, 0, 2);
		world.setBlock(i + 4, j + 3, k + 3, PlaceDeepslate, 0, 2);
		world.setBlock(i + 5, j + 3, k + 3, PlaceDeepslate, 0, 2);
		world.setBlock(i + 6, j + 3, k + 3, PlaceDeepslate, 0, 2);
		world.setBlock(i + 7, j + 3, k + 3, PlaceDeepslate, 0, 2);
		world.setBlock(i + 8, j + 3, k + 3, PlaceDeepslate, 0, 2);
		world.setBlock(i + 9, j + 3, k + 3, PlaceDeepslate, 0, 2);
		world.setBlock(i + 10, j + 3, k + 3, PlaceDeepslate, 0, 2);
		world.setBlock(i + 11, j + 3, k + 3, PlaceDeepslate, 0, 2);
		world.setBlock(i + 12, j + 3, k + 3, PlaceDeepslate, 0, 2);
		world.setBlock(i + 13, j + 3, k + 3, PlaceDeepslate, 0, 2);
		world.setBlock(i + 14, j + 3, k + 3, PlaceDeepslate, 0, 2);
		world.setBlock(i + 15, j + 3, k + 3, PlaceDeepslate, 0, 2);
		world.setBlock(i + 16, j + 3, k + 3, PlaceDeepslate, 0, 2);
		world.setBlock(i + 17, j + 3, k + 3, PlaceDeepslate, 0, 2);
		world.setBlock(i + 18, j + 3, k + 3, PlaceDeepslate, 0, 2);
		world.setBlock(i + 0, j + 3, k + 4, PlaceDeepslate, 0, 2);
		world.setBlock(i + 1, j + 3, k + 4, PlaceDeepslate, 0, 2);
		world.setBlock(i + 2, j + 3, k + 4, PlaceDeepslate, 0, 2);
		world.setBlock(i + 3, j + 3, k + 4, PlaceDeepslate, 0, 2);
		world.setBlock(i + 4, j + 3, k + 4, PlaceDeepslate, 0, 2);
		world.setBlock(i + 5, j + 3, k + 4, PlaceDeepslate, 0, 2);
		world.setBlock(i + 6, j + 3, k + 4, PlaceDeepslate, 0, 2);
		world.setBlock(i + 7, j + 3, k + 4, PlaceDeepslate, 0, 2);
		world.setBlock(i + 8, j + 3, k + 4, PlaceDeepslate, 0, 2);
		world.setBlock(i + 9, j + 3, k + 4, PlaceDeepslate, 0, 2);
		world.setBlock(i + 10, j + 3, k + 4, PlaceDeepslate, 0, 2);
		world.setBlock(i + 11, j + 3, k + 4, PlaceDeepslate, 0, 2);
		world.setBlock(i + 12, j + 3, k + 4, PlaceDeepslate, 0, 2);
		world.setBlock(i + 13, j + 3, k + 4, PlaceDeepslate, 0, 2);
		world.setBlock(i + 14, j + 3, k + 4, PlaceDeepslate, 0, 2);
		world.setBlock(i + 15, j + 3, k + 4, PlaceDeepslate, 0, 2);
		world.setBlock(i + 16, j + 3, k + 4, PlaceDeepslate, 0, 2);
		world.setBlock(i + 17, j + 3, k + 4, PlaceDeepslate, 0, 2);
		world.setBlock(i + 18, j + 3, k + 4, PlaceDeepslate, 0, 2);
		world.setBlock(i + 0, j + 3, k + 5, PlaceDeepslate, 0, 2);
		world.setBlock(i + 1, j + 3, k + 5, PlaceDeepslate, 0, 2);
		world.setBlock(i + 2, j + 3, k + 5, PlaceDeepslate, 0, 2);
		world.setBlock(i + 3, j + 3, k + 5, PlaceDeepslate, 0, 2);
		world.setBlock(i + 4, j + 3, k + 5, PlaceDeepslate, 0, 2);
		world.setBlock(i + 5, j + 3, k + 5, PlaceDeepslate, 0, 2);
		world.setBlock(i + 6, j + 3, k + 5, PlaceDeepslate, 0, 2);
		world.setBlock(i + 7, j + 3, k + 5, PlaceDeepslate, 0, 2);
		world.setBlock(i + 8, j + 3, k + 5, PlaceDeepslate, 0, 2);
		world.setBlock(i + 9, j + 3, k + 5, PlaceDeepslate, 0, 2);
		world.setBlock(i + 10, j + 3, k + 5, PlaceDeepslate, 0, 2);
		world.setBlock(i + 11, j + 3, k + 5, PlaceDeepslate, 0, 2);
		world.setBlock(i + 12, j + 3, k + 5, PlaceDeepslate, 0, 2);
		world.setBlock(i + 13, j + 3, k + 5, PlaceDeepslate, 0, 2);
		world.setBlock(i + 14, j + 3, k + 5, PlaceDeepslate, 0, 2);
		world.setBlock(i + 15, j + 3, k + 5, PlaceDeepslate, 0, 2);
		world.setBlock(i + 16, j + 3, k + 5, PlaceDeepslate, 0, 2);
		world.setBlock(i + 17, j + 3, k + 5, PlaceDeepslate, 0, 2);
		world.setBlock(i + 18, j + 3, k + 5, PlaceDeepslate, 0, 2);
		world.setBlock(i + 0, j + 3, k + 6, PlaceDeepslate, 0, 2);
		world.setBlock(i + 1, j + 3, k + 6, PlaceDeepslate, 0, 2);
		world.setBlock(i + 2, j + 3, k + 6, PlaceDeepslate, 0, 2);
		world.setBlock(i + 3, j + 3, k + 6, PlaceDeepslate, 0, 2);
		world.setBlock(i + 4, j + 3, k + 6, PlaceDeepslate, 0, 2);
		world.setBlock(i + 5, j + 3, k + 6, PlaceDeepslate, 0, 2);
		world.setBlock(i + 6, j + 3, k + 6, PlaceDeepslate, 0, 2);
		world.setBlock(i + 7, j + 3, k + 6, PlaceDeepslate, 0, 2);
		world.setBlock(i + 8, j + 3, k + 6, PlaceDeepslate, 0, 2);
		world.setBlock(i + 9, j + 3, k + 6, PlaceDeepslate, 0, 2);
		world.setBlock(i + 10, j + 3, k + 6, PlaceDeepslate, 0, 2);
		world.setBlock(i + 11, j + 3, k + 6, PlaceDeepslate, 0, 2);
		world.setBlock(i + 12, j + 3, k + 6, PlaceDeepslate, 0, 2);
		world.setBlock(i + 13, j + 3, k + 6, PlaceDeepslate, 0, 2);
		world.setBlock(i + 14, j + 3, k + 6, PlaceDeepslate, 0, 2);
		world.setBlock(i + 15, j + 3, k + 6, PlaceDeepslate, 0, 2);
		world.setBlock(i + 16, j + 3, k + 6, PlaceDeepslate, 0, 2);
		world.setBlock(i + 17, j + 3, k + 6, PlaceDeepslate, 0, 2);
		world.setBlock(i + 18, j + 3, k + 6, PlaceDeepslate, 0, 2);
		world.setBlock(i + 0, j + 3, k + 7, PlaceDeepslate, 0, 2);
		world.setBlock(i + 1, j + 3, k + 7, PlaceDeepslate, 0, 2);
		world.setBlock(i + 2, j + 3, k + 7, PlaceDeepslate, 0, 2);
		world.setBlock(i + 3, j + 3, k + 7, PlaceDeepslate, 0, 2);
		world.setBlock(i + 4, j + 3, k + 7, PlaceDeepslate, 0, 2);
		world.setBlock(i + 5, j + 3, k + 7, PlaceDeepslate, 0, 2);
		world.setBlock(i + 6, j + 3, k + 7, PlaceDeepslate, 0, 2);
		world.setBlock(i + 7, j + 3, k + 7, PlaceDeepslate, 0, 2);
		world.setBlock(i + 8, j + 3, k + 7, PlaceDeepslate, 0, 2);
		world.setBlock(i + 9, j + 3, k + 7, PlaceDeepslate, 0, 2);
		world.setBlock(i + 10, j + 3, k + 7, PlaceDeepslate, 0, 2);
		world.setBlock(i + 11, j + 3, k + 7, PlaceDeepslate, 0, 2);
		world.setBlock(i + 12, j + 3, k + 7, PlaceDeepslate, 0, 2);
		world.setBlock(i + 13, j + 3, k + 7, PlaceDeepslate, 0, 2);
		world.setBlock(i + 14, j + 3, k + 7, PlaceDeepslate, 0, 2);
		world.setBlock(i + 15, j + 3, k + 7, PlaceDeepslate, 0, 2);
		world.setBlock(i + 16, j + 3, k + 7, PlaceDeepslate, 0, 2);
		world.setBlock(i + 17, j + 3, k + 7, PlaceDeepslate, 0, 2);
		world.setBlock(i + 18, j + 3, k + 7, PlaceDeepslate, 0, 2);
		world.setBlock(i + 0, j + 3, k + 8, PlaceDeepslate, 0, 2);
		world.setBlock(i + 1, j + 3, k + 8, PlaceDeepslate, 0, 2);
		world.setBlock(i + 2, j + 3, k + 8, PlaceDeepslate, 0, 2);
		world.setBlock(i + 3, j + 3, k + 8, PlaceDeepslate, 0, 2);
		world.setBlock(i + 4, j + 3, k + 8, PlaceDeepslate, 0, 2);
		world.setBlock(i + 5, j + 3, k + 8, PlaceDeepslate, 0, 2);
		world.setBlock(i + 6, j + 3, k + 8, PlaceDeepslate, 0, 2);
		world.setBlock(i + 7, j + 3, k + 8, PlaceDeepslate, 0, 2);
		world.setBlock(i + 8, j + 3, k + 8, PlaceDeepslate, 0, 2);
		world.setBlock(i + 9, j + 3, k + 8, PlaceDeepslate, 0, 2);
		world.setBlock(i + 10, j + 3, k + 8, PlaceDeepslate, 0, 2);
		world.setBlock(i + 11, j + 3, k + 8, PlaceDeepslate, 0, 2);
		world.setBlock(i + 12, j + 3, k + 8, PlaceDeepslate, 0, 2);
		world.setBlock(i + 13, j + 3, k + 8, PlaceDeepslate, 0, 2);
		world.setBlock(i + 14, j + 3, k + 8, PlaceDeepslate, 0, 2);
		world.setBlock(i + 15, j + 3, k + 8, PlaceDeepslate, 0, 2);
		world.setBlock(i + 16, j + 3, k + 8, PlaceDeepslate, 0, 2);
		world.setBlock(i + 17, j + 3, k + 8, PlaceDeepslate, 0, 2);
		world.setBlock(i + 18, j + 3, k + 8, PlaceDeepslate, 0, 2);
		world.setBlock(i + 19, j + 3, k + 8, PlaceDeepslate, 0, 2);
		world.setBlock(i + 0, j + 3, k + 9, PlaceDeepslate, 0, 2);
		world.setBlock(i + 1, j + 3, k + 9, PlaceDeepslate, 0, 2);
		world.setBlock(i + 2, j + 3, k + 9, PlaceDeepslate, 0, 2);
		world.setBlock(i + 3, j + 3, k + 9, PlaceDeepslate, 0, 2);
		world.setBlock(i + 4, j + 3, k + 9, PlaceDeepslate, 0, 2);
		world.setBlock(i + 5, j + 3, k + 9, PlaceDeepslate, 0, 2);
		world.setBlock(i + 6, j + 3, k + 9, PlaceDeepslate, 0, 2);
		world.setBlock(i + 7, j + 3, k + 9, PlaceDeepslate, 0, 2);
		world.setBlock(i + 8, j + 3, k + 9, PlaceDeepslate, 0, 2);
		world.setBlock(i + 9, j + 3, k + 9, PlaceDeepslate, 0, 2);
		world.setBlock(i + 10, j + 3, k + 9, PlaceDeepslate, 0, 2);
		world.setBlock(i + 11, j + 3, k + 9, PlaceDeepslate, 0, 2);
		world.setBlock(i + 12, j + 3, k + 9, PlaceDeepslate, 0, 2);
		world.setBlock(i + 13, j + 3, k + 9, PlaceDeepslate, 0, 2);
		world.setBlock(i + 14, j + 3, k + 9, PlaceDeepslate, 0, 2);
		world.setBlock(i + 15, j + 3, k + 9, PlaceDeepslate, 0, 2);
		world.setBlock(i + 16, j + 3, k + 9, PlaceDeepslate, 0, 2);
		world.setBlock(i + 17, j + 3, k + 9, PlaceDeepslate, 0, 2);
		world.setBlock(i + 18, j + 3, k + 9, PlaceDeepslate, 0, 2);
		world.setBlock(i + 19, j + 3, k + 9, PlaceDeepslate, 0, 2);
		world.setBlock(i + 20, j + 3, k + 9, PlaceDeepslate, 0, 2);
		world.setBlock(i + 0, j + 3, k + 10, PlaceDeepslate, 0, 2);
		world.setBlock(i + 1, j + 3, k + 10, PlaceDeepslate, 0, 2);
		world.setBlock(i + 2, j + 3, k + 10, PlaceDeepslate, 0, 2);
		world.setBlock(i + 3, j + 3, k + 10, PlaceDeepslate, 0, 2);
		world.setBlock(i + 4, j + 3, k + 10, PlaceDeepslate, 0, 2);
		world.setBlock(i + 5, j + 3, k + 10, PlaceDeepslate, 0, 2);
		world.setBlock(i + 6, j + 3, k + 10, PlaceDeepslate, 0, 2);
		world.setBlock(i + 7, j + 3, k + 10, PlaceDeepslate, 0, 2);
		world.setBlock(i + 8, j + 3, k + 10, PlaceDeepslate, 0, 2);
		world.setBlock(i + 9, j + 3, k + 10, PlaceDeepslate, 0, 2);
		world.setBlock(i + 10, j + 3, k + 10, PlaceDeepslate, 0, 2);
		world.setBlock(i + 11, j + 3, k + 10, PlaceDeepslate, 0, 2);
		world.setBlock(i + 12, j + 3, k + 10, PlaceDeepslate, 0, 2);
		world.setBlock(i + 13, j + 3, k + 10, PlaceDeepslate, 0, 2);
		world.setBlock(i + 14, j + 3, k + 10, PlaceDeepslate, 0, 2);
		world.setBlock(i + 15, j + 3, k + 10, PlaceDeepslate, 0, 2);
		world.setBlock(i + 16, j + 3, k + 10, PlaceDeepslate, 0, 2);
		world.setBlock(i + 17, j + 3, k + 10, PlaceDeepslate, 0, 2);
		world.setBlock(i + 18, j + 3, k + 10, PlaceDeepslate, 0, 2);
		world.setBlock(i + 19, j + 3, k + 10, PlaceDeepslate, 0, 2);
		world.setBlock(i + 20, j + 3, k + 10, PlaceDeepslate, 0, 2);
		world.setBlock(i + 21, j + 3, k + 10, PlaceDeepslate, 0, 2);
		world.setBlock(i + 0, j + 3, k + 11, PlaceDeepslate, 0, 2);
		world.setBlock(i + 1, j + 3, k + 11, PlaceDeepslate, 0, 2);
		world.setBlock(i + 2, j + 3, k + 11, PlaceDeepslate, 0, 2);
		world.setBlock(i + 3, j + 3, k + 11, PlaceDeepslate, 0, 2);
		world.setBlock(i + 4, j + 3, k + 11, PlaceDeepslate, 0, 2);
		world.setBlock(i + 5, j + 3, k + 11, PlaceDeepslate, 0, 2);
		world.setBlock(i + 6, j + 3, k + 11, PlaceDeepslate, 0, 2);
		world.setBlock(i + 7, j + 3, k + 11, PlaceDeepslate, 0, 2);
		world.setBlock(i + 8, j + 3, k + 11, PlaceDeepslate, 0, 2);
		world.setBlock(i + 9, j + 3, k + 11, PlaceDeepslate, 0, 2);
		world.setBlock(i + 10, j + 3, k + 11, PlaceDeepslate, 0, 2);
		world.setBlock(i + 11, j + 3, k + 11, PlaceDeepslate, 0, 2);
		world.setBlock(i + 12, j + 3, k + 11, PlaceDeepslate, 0, 2);
		world.setBlock(i + 13, j + 3, k + 11, PlaceDeepslate, 0, 2);
		world.setBlock(i + 14, j + 3, k + 11, PlaceDeepslate, 0, 2);
		world.setBlock(i + 15, j + 3, k + 11, PlaceDeepslate, 0, 2);
		world.setBlock(i + 16, j + 3, k + 11, PlaceDeepslate, 0, 2);
		world.setBlock(i + 17, j + 3, k + 11, PlaceDeepslate, 0, 2);
		world.setBlock(i + 18, j + 3, k + 11, PlaceDeepslate, 0, 2);
		world.setBlock(i + 19, j + 3, k + 11, PlaceDeepslate, 0, 2);
		world.setBlock(i + 20, j + 3, k + 11, PlaceDeepslate, 0, 2);
		world.setBlock(i + 21, j + 3, k + 11, PlaceDeepslate, 0, 2);
		world.setBlock(i + 0, j + 3, k + 12, PlaceDeepslate, 0, 2);
		world.setBlock(i + 1, j + 3, k + 12, PlaceDeepslate, 0, 2);
		world.setBlock(i + 2, j + 3, k + 12, PlaceDeepslate, 0, 2);
		world.setBlock(i + 3, j + 3, k + 12, PlaceDeepslate, 0, 2);
		world.setBlock(i + 4, j + 3, k + 12, PlaceDeepslate, 0, 2);
		world.setBlock(i + 5, j + 3, k + 12, PlaceDeepslate, 0, 2);
		world.setBlock(i + 6, j + 3, k + 12, PlaceDeepslate, 0, 2);
		world.setBlock(i + 7, j + 3, k + 12, PlaceDeepslate, 0, 2);
		world.setBlock(i + 8, j + 3, k + 12, PlaceDeepslate, 0, 2);
		world.setBlock(i + 9, j + 3, k + 12, PlaceDeepslate, 0, 2);
		world.setBlock(i + 10, j + 3, k + 12, PlaceDeepslate, 0, 2);
		world.setBlock(i + 11, j + 3, k + 12, PlaceDeepslate, 0, 2);
		world.setBlock(i + 12, j + 3, k + 12, PlaceDeepslate, 0, 2);
		world.setBlock(i + 13, j + 3, k + 12, PlaceDeepslate, 0, 2);
		world.setBlock(i + 14, j + 3, k + 12, PlaceDeepslate, 0, 2);
		world.setBlock(i + 15, j + 3, k + 12, PlaceDeepslate, 0, 2);
		world.setBlock(i + 16, j + 3, k + 12, PlaceDeepslate, 0, 2);
		world.setBlock(i + 17, j + 3, k + 12, PlaceDeepslate, 0, 2);
		world.setBlock(i + 18, j + 3, k + 12, PlaceDeepslate, 0, 2);
		world.setBlock(i + 19, j + 3, k + 12, PlaceDeepslate, 0, 2);
		world.setBlock(i + 20, j + 3, k + 12, PlaceDeepslate, 0, 2);
		world.setBlock(i + 21, j + 3, k + 12, PlaceDeepslate, 0, 2);
		world.setBlock(i + 0, j + 3, k + 13, PlaceDeepslate, 0, 2);
		world.setBlock(i + 1, j + 3, k + 13, PlaceDeepslate, 0, 2);
		world.setBlock(i + 2, j + 3, k + 13, PlaceDeepslate, 0, 2);
		world.setBlock(i + 3, j + 3, k + 13, PlaceDeepslate, 0, 2);
		world.setBlock(i + 4, j + 3, k + 13, PlaceDeepslate, 0, 2);
		world.setBlock(i + 5, j + 3, k + 13, PlaceDeepslate, 0, 2);
		world.setBlock(i + 6, j + 3, k + 13, PlaceDeepslate, 0, 2);
		world.setBlock(i + 7, j + 3, k + 13, PlaceDeepslate, 0, 2);
		world.setBlock(i + 8, j + 3, k + 13, PlaceDeepslate, 0, 2);
		world.setBlock(i + 9, j + 3, k + 13, PlaceDeepslate, 0, 2);
		world.setBlock(i + 10, j + 3, k + 13, PlaceDeepslate, 0, 2);
		world.setBlock(i + 11, j + 3, k + 13, PlaceDeepslate, 0, 2);
		world.setBlock(i + 12, j + 3, k + 13, PlaceDeepslate, 0, 2);
		world.setBlock(i + 13, j + 3, k + 13, PlaceDeepslate, 0, 2);
		world.setBlock(i + 14, j + 3, k + 13, PlaceDeepslate, 0, 2);
		world.setBlock(i + 15, j + 3, k + 13, PlaceDeepslate, 0, 2);
		world.setBlock(i + 16, j + 3, k + 13, PlaceDeepslate, 0, 2);
		world.setBlock(i + 17, j + 3, k + 13, PlaceDeepslate, 0, 2);
		world.setBlock(i + 18, j + 3, k + 13, PlaceDeepslate, 0, 2);
		world.setBlock(i + 19, j + 3, k + 13, PlaceDeepslate, 0, 2);
		world.setBlock(i + 20, j + 3, k + 13, PlaceDeepslate, 0, 2);
		world.setBlock(i + 21, j + 3, k + 13, PlaceDeepslate, 0, 2);
		world.setBlock(i + 0, j + 3, k + 14, PlaceDeepslate, 0, 2);
		world.setBlock(i + 1, j + 3, k + 14, PlaceDeepslate, 0, 2);
		world.setBlock(i + 2, j + 3, k + 14, PlaceDeepslate, 0, 2);
		world.setBlock(i + 3, j + 3, k + 14, PlaceDeepslate, 0, 2);
		world.setBlock(i + 4, j + 3, k + 14, PlaceDeepslate, 0, 2);
		world.setBlock(i + 5, j + 3, k + 14, PlaceDeepslate, 0, 2);
		world.setBlock(i + 6, j + 3, k + 14, PlaceDeepslate, 0, 2);
		world.setBlock(i + 7, j + 3, k + 14, PlaceDeepslate, 0, 2);
		world.setBlock(i + 8, j + 3, k + 14, PlaceDeepslate, 0, 2);
		world.setBlock(i + 9, j + 3, k + 14, PlaceDeepslate, 0, 2);
		world.setBlock(i + 10, j + 3, k + 14, PlaceDeepslate, 0, 2);
		world.setBlock(i + 11, j + 3, k + 14, PlaceDeepslate, 0, 2);
		world.setBlock(i + 12, j + 3, k + 14, PlaceDeepslate, 0, 2);
		world.setBlock(i + 13, j + 3, k + 14, PlaceDeepslate, 0, 2);
		world.setBlock(i + 14, j + 3, k + 14, PlaceDeepslate, 0, 2);
		world.setBlock(i + 15, j + 3, k + 14, PlaceDeepslate, 0, 2);
		world.setBlock(i + 16, j + 3, k + 14, PlaceDeepslate, 0, 2);
		world.setBlock(i + 17, j + 3, k + 14, PlaceDeepslate, 0, 2);
		world.setBlock(i + 18, j + 3, k + 14, PlaceDeepslate, 0, 2);
		world.setBlock(i + 19, j + 3, k + 14, PlaceDeepslate, 0, 2);
		world.setBlock(i + 20, j + 3, k + 14, PlaceDeepslate, 0, 2);
		world.setBlock(i + 21, j + 3, k + 14, PlaceDeepslate, 0, 2);
		world.setBlock(i + 0, j + 3, k + 15, PlaceDeepslate, 0, 2);
		world.setBlock(i + 1, j + 3, k + 15, PlaceDeepslate, 0, 2);
		world.setBlock(i + 2, j + 3, k + 15, PlaceDeepslate, 0, 2);
		world.setBlock(i + 3, j + 3, k + 15, PlaceDeepslate, 0, 2);
		world.setBlock(i + 4, j + 3, k + 15, PlaceDeepslate, 0, 2);
		world.setBlock(i + 5, j + 3, k + 15, PlaceDeepslate, 0, 2);
		world.setBlock(i + 6, j + 3, k + 15, PlaceDeepslate, 0, 2);
		world.setBlock(i + 7, j + 3, k + 15, PlaceDeepslate, 0, 2);
		world.setBlock(i + 8, j + 3, k + 15, PlaceDeepslate, 0, 2);
		world.setBlock(i + 9, j + 3, k + 15, PlaceDeepslate, 0, 2);
		world.setBlock(i + 10, j + 3, k + 15, PlaceDeepslate, 0, 2);
		world.setBlock(i + 11, j + 3, k + 15, PlaceDeepslate, 0, 2);
		world.setBlock(i + 12, j + 3, k + 15, PlaceDeepslate, 0, 2);
		world.setBlock(i + 13, j + 3, k + 15, PlaceDeepslate, 0, 2);
		world.setBlock(i + 14, j + 3, k + 15, PlaceDeepslate, 0, 2);
		world.setBlock(i + 15, j + 3, k + 15, PlaceDeepslate, 0, 2);
		world.setBlock(i + 16, j + 3, k + 15, PlaceDeepslate, 0, 2);
		world.setBlock(i + 17, j + 3, k + 15, PlaceDeepslate, 0, 2);
		world.setBlock(i + 18, j + 3, k + 15, PlaceDeepslate, 0, 2);
		world.setBlock(i + 19, j + 3, k + 15, PlaceDeepslate, 0, 2);
		world.setBlock(i + 20, j + 3, k + 15, PlaceDeepslate, 0, 2);
		world.setBlock(i + 21, j + 3, k + 15, PlaceDeepslate, 0, 2);
		world.setBlock(i + 0, j + 3, k + 16, PlaceDeepslate, 0, 2);
		world.setBlock(i + 1, j + 3, k + 16, PlaceDeepslate, 0, 2);
		world.setBlock(i + 2, j + 3, k + 16, PlaceDeepslate, 0, 2);
		world.setBlock(i + 3, j + 3, k + 16, PlaceDeepslate, 0, 2);
		world.setBlock(i + 4, j + 3, k + 16, PlaceDeepslate, 0, 2);
		world.setBlock(i + 5, j + 3, k + 16, PlaceDeepslate, 0, 2);
		world.setBlock(i + 6, j + 3, k + 16, PlaceDeepslate, 0, 2);
		world.setBlock(i + 7, j + 3, k + 16, PlaceDeepslate, 0, 2);
		world.setBlock(i + 8, j + 3, k + 16, PlaceDeepslate, 0, 2);
		world.setBlock(i + 9, j + 3, k + 16, PlaceDeepslate, 0, 2);
		world.setBlock(i + 10, j + 3, k + 16, PlaceDeepslate, 0, 2);
		world.setBlock(i + 11, j + 3, k + 16, PlaceDeepslate, 0, 2);
		world.setBlock(i + 12, j + 3, k + 16, PlaceDeepslate, 0, 2);
		world.setBlock(i + 13, j + 3, k + 16, PlaceDeepslate, 0, 2);
		world.setBlock(i + 14, j + 3, k + 16, PlaceDeepslate, 0, 2);
		world.setBlock(i + 15, j + 3, k + 16, PlaceDeepslate, 0, 2);
		world.setBlock(i + 16, j + 3, k + 16, PlaceDeepslate, 0, 2);
		world.setBlock(i + 17, j + 3, k + 16, PlaceDeepslate, 0, 2);
		world.setBlock(i + 18, j + 3, k + 16, PlaceDeepslate, 0, 2);
		world.setBlock(i + 19, j + 3, k + 16, PlaceDeepslate, 0, 2);
		world.setBlock(i + 20, j + 3, k + 16, PlaceDeepslate, 0, 2);
		world.setBlock(i + 21, j + 3, k + 16, PlaceDeepslate, 0, 2);
		world.setBlock(i + 0, j + 3, k + 17, PlaceDeepslate, 0, 2);
		world.setBlock(i + 1, j + 3, k + 17, PlaceDeepslate, 0, 2);
		world.setBlock(i + 2, j + 3, k + 17, PlaceDeepslate, 0, 2);
		world.setBlock(i + 3, j + 3, k + 17, PlaceDeepslate, 0, 2);
		world.setBlock(i + 4, j + 3, k + 17, PlaceDeepslate, 0, 2);
		world.setBlock(i + 5, j + 3, k + 17, PlaceDeepslate, 0, 2);
		world.setBlock(i + 6, j + 3, k + 17, PlaceDeepslate, 0, 2);
		world.setBlock(i + 7, j + 3, k + 17, PlaceDeepslate, 0, 2);
		world.setBlock(i + 8, j + 3, k + 17, PlaceDeepslate, 0, 2);
		world.setBlock(i + 9, j + 3, k + 17, PlaceDeepslate, 0, 2);
		world.setBlock(i + 10, j + 3, k + 17, PlaceDeepslate, 0, 2);
		world.setBlock(i + 11, j + 3, k + 17, PlaceDeepslate, 0, 2);
		world.setBlock(i + 12, j + 3, k + 17, PlaceDeepslate, 0, 2);
		world.setBlock(i + 13, j + 3, k + 17, PlaceDeepslate, 0, 2);
		world.setBlock(i + 14, j + 3, k + 17, PlaceDeepslate, 0, 2);
		world.setBlock(i + 15, j + 3, k + 17, PlaceDeepslate, 0, 2);
		world.setBlock(i + 16, j + 3, k + 17, PlaceDeepslate, 0, 2);
		world.setBlock(i + 17, j + 3, k + 17, PlaceDeepslate, 0, 2);
		world.setBlock(i + 18, j + 3, k + 17, PlaceDeepslate, 0, 2);
		world.setBlock(i + 19, j + 3, k + 17, PlaceDeepslate, 0, 2);
		world.setBlock(i + 20, j + 3, k + 17, PlaceDeepslate, 0, 2);
		world.setBlock(i + 21, j + 3, k + 17, PlaceDeepslate, 0, 2);
		world.setBlock(i + 1, j + 3, k + 18, PlaceDeepslate, 0, 2);
		world.setBlock(i + 2, j + 3, k + 18, PlaceDeepslate, 0, 2);
		world.setBlock(i + 3, j + 3, k + 18, PlaceDeepslate, 0, 2);
		world.setBlock(i + 4, j + 3, k + 18, PlaceDeepslate, 0, 2);
		world.setBlock(i + 5, j + 3, k + 18, PlaceDeepslate, 0, 2);
		world.setBlock(i + 6, j + 3, k + 18, PlaceDeepslate, 0, 2);
		world.setBlock(i + 7, j + 3, k + 18, PlaceDeepslate, 0, 2);
		world.setBlock(i + 8, j + 3, k + 18, PlaceDeepslate, 0, 2);
		world.setBlock(i + 9, j + 3, k + 18, PlaceDeepslate, 0, 2);
		world.setBlock(i + 10, j + 3, k + 18, PlaceDeepslate, 0, 2);
		world.setBlock(i + 11, j + 3, k + 18, PlaceDeepslate, 0, 2);
		world.setBlock(i + 12, j + 3, k + 18, PlaceDeepslate, 0, 2);
		world.setBlock(i + 13, j + 3, k + 18, PlaceDeepslate, 0, 2);
		world.setBlock(i + 14, j + 3, k + 18, PlaceDeepslate, 0, 2);
		world.setBlock(i + 15, j + 3, k + 18, PlaceDeepslate, 0, 2);
		world.setBlock(i + 16, j + 3, k + 18, PlaceDeepslate, 0, 2);
		world.setBlock(i + 17, j + 3, k + 18, PlaceDeepslate, 0, 2);
		world.setBlock(i + 18, j + 3, k + 18, PlaceDeepslate, 0, 2);
		world.setBlock(i + 19, j + 3, k + 18, PlaceDeepslate, 0, 2);
		world.setBlock(i + 20, j + 3, k + 18, PlaceDeepslate, 0, 2);
