package com.NovaCraft.world.ancient_city;

import net.minecraft.world.gen.feature.*;
import net.minecraft.block.*;
import net.minecraft.world.*;
import java.util.*;

import com.NovaCraft.registry.OtherModBlocks;
import com.NovaCraftBlocks.NovaCraftBlocks;

import net.minecraft.init.*;
import net.minecraft.tileentity.TileEntityMobSpawner;

public class AncientCityCenterPortalGen4 extends WorldGenerator
{
	public AncientCityCenterPortalGen4() {

	}
	
	private static final Block cobbled_deepslate = OtherModBlocks.cobbled_deepslate;
	private static final Block deepslate = OtherModBlocks.deepslate;
	private static final Block sculk_block = NovaCraftBlocks.sculk_block;
	private static final Block soul_lantern = Blocks.glowstone; //1
	private static final Block soul_sand = Blocks.netherrack;
	
	private static final Block polished_deepslate = OtherModBlocks.polished_deepslate;
	private static final Block deepslate_brick_slab = OtherModBlocks.deepslate_brick_slab;
	private static final Block deepslate_tile_stairs = OtherModBlocks.deepslate_tile_stairs;
	private static final Block deepslate_brick_stairs = OtherModBlocks.deepslate_brick_stairs;
	private static final Block polished_deepslate_stairs = OtherModBlocks.polished_deepslate_stairs;
	private static final Block deepslate_wall = OtherModBlocks.deepslate_wall;
	private static final Block fence_dark_oak = OtherModBlocks.fence_dark_oak;
	
	private static final Block deepslate_bricks = OtherModBlocks.deepslate_bricks;
	
	//0 -> deepslate bricks
	//1 -> cracked deepslate bricks
	//2 -> deepslate tiles
	//3 -> cracked deepslate bricks
	//4 -> chiseled deepslate bricks

	public boolean generate(final World world, final Random random, final int i, final int j, final int k) {
		
		world.setBlock(i + 43, j + 5, k + 57, Blocks.wool, 7, 2);
		world.setBlock(i + 44, j + 5, k + 57, Blocks.wool, 7, 2);
		world.setBlock(i + 45, j + 5, k + 57, deepslate_bricks, 1, 2);
		world.setBlock(i + 0, j + 5, k + 58, deepslate_bricks, 1, 2);
		world.setBlock(i + 1, j + 5, k + 58, Blocks.wool, 7, 2);
		world.setBlock(i + 2, j + 5, k + 58, Blocks.wool, 7, 2);
		world.setBlock(i + 3, j + 5, k + 58, Blocks.wool, 7, 2);
		world.setBlock(i + 10, j + 5, k + 58, Blocks.wool, 7, 2);
		world.setBlock(i + 11, j + 5, k + 58, Blocks.wool, 7, 2);
		world.setBlock(i + 12, j + 5, k + 58, deepslate_tile_stairs, 3, 2);
		world.setBlock(i + 13, j + 5, k + 58, deepslate_tile_stairs, 3, 2);
		world.setBlock(i + 14, j + 5, k + 58, deepslate_tile_stairs, 3, 2);
		world.setBlock(i + 15, j + 5, k + 58, Blocks.wool, 7, 2);
		world.setBlock(i + 16, j + 5, k + 58, Blocks.wool, 7, 2);
		world.setBlock(i + 17, j + 5, k + 58, Blocks.wool, 7, 2);
		world.setBlock(i + 18, j + 5, k + 58, Blocks.wool, 7, 2);
		world.setBlock(i + 19, j + 5, k + 58, deepslate_tile_stairs, 3, 2);
		world.setBlock(i + 20, j + 5, k + 58, deepslate_tile_stairs, 3, 2);
		world.setBlock(i + 21, j + 5, k + 58, deepslate_tile_stairs, 3, 2);
		world.setBlock(i + 22, j + 5, k + 58, Blocks.wool, 7, 2);
		world.setBlock(i + 23, j + 5, k + 58, Blocks.wool, 7, 2);
		world.setBlock(i + 24, j + 5, k + 58, deepslate_tile_stairs, 3, 2);
		world.setBlock(i + 25, j + 5, k + 58, deepslate_tile_stairs, 3, 2);
		world.setBlock(i + 26, j + 5, k + 58, deepslate_tile_stairs, 3, 2);
		world.setBlock(i + 27, j + 5, k + 58, Blocks.wool, 7, 2);
		world.setBlock(i + 28, j + 5, k + 58, Blocks.wool, 7, 2);
		world.setBlock(i + 29, j + 5, k + 58, Blocks.wool, 7, 2);
		world.setBlock(i + 30, j + 5, k + 58, Blocks.wool, 7, 2);
		world.setBlock(i + 31, j + 5, k + 58, deepslate_tile_stairs, 3, 2);
		world.setBlock(i + 32, j + 5, k + 58, deepslate_tile_stairs, 3, 2);
		world.setBlock(i + 33, j + 5, k + 58, deepslate_tile_stairs, 3, 2);
		world.setBlock(i + 34, j + 5, k + 58, Blocks.wool, 7, 2);
		world.setBlock(i + 35, j + 5, k + 58, Blocks.wool, 7, 2);
		world.setBlock(i + 42, j + 5, k + 58, Blocks.wool, 7, 2);
		world.setBlock(i + 43, j + 5, k + 58, Blocks.wool, 7, 2);
		world.setBlock(i + 44, j + 5, k + 58, Blocks.wool, 7, 2);
		world.setBlock(i + 45, j + 5, k + 58, deepslate_bricks, 0, 2);
		world.setBlock(i + 0, j + 5, k + 59, deepslate_bricks, 1, 2);
		world.setBlock(i + 1, j + 5, k + 59, Blocks.wool, 7, 2);
		world.setBlock(i + 2, j + 5, k + 59, Blocks.wool, 7, 2);
		world.setBlock(i + 3, j + 5, k + 59, deepslate_tile_stairs, 3, 2);
		world.setBlock(i + 42, j + 5, k + 59, deepslate_tile_stairs, 3, 2);
		world.setBlock(i + 43, j + 5, k + 59, Blocks.wool, 7, 2);
		world.setBlock(i + 44, j + 5, k + 59, Blocks.wool, 7, 2);
		world.setBlock(i + 45, j + 5, k + 59, deepslate_bricks, 1, 2);
		world.setBlock(i + 0, j + 5, k + 60, deepslate_bricks, 0, 2);
		world.setBlock(i + 1, j + 5, k + 60, Blocks.wool, 7, 2);
		world.setBlock(i + 2, j + 5, k + 60, Blocks.wool, 7, 2);
		world.setBlock(i + 3, j + 5, k + 60, deepslate_tile_stairs, 2, 2);
		world.setBlock(i + 42, j + 5, k + 60, deepslate_tile_stairs, 2, 2);
		world.setBlock(i + 44, j + 5, k + 60, Blocks.wool, 7, 2);
		world.setBlock(i + 45, j + 5, k + 60, deepslate_bricks, 0, 2);
		world.setBlock(i + 0, j + 5, k + 61, deepslate_tile_stairs, 4, 2);
		world.setBlock(i + 1, j + 5, k + 61, Blocks.wool, 7, 2);
		world.setBlock(i + 2, j + 5, k + 61, Blocks.wool, 7, 2);
		world.setBlock(i + 3, j + 5, k + 61, Blocks.wool, 7, 2);
		world.setBlock(i + 42, j + 5, k + 61, Blocks.wool, 7, 2);
		world.setBlock(i + 43, j + 5, k + 61, Blocks.wool, 7, 2);
		world.setBlock(i + 44, j + 5, k + 61, Blocks.wool, 7, 2);
		world.setBlock(i + 45, j + 5, k + 61, deepslate_tile_stairs, 3, 2);
		world.setBlock(i + 0, j + 5, k + 62, deepslate_tile_stairs, 4, 2);
		world.setBlock(i + 1, j + 5, k + 62, Blocks.wool, 7, 2);
		world.setBlock(i + 2, j + 5, k + 62, Blocks.wool, 7, 2);
		world.setBlock(i + 3, j + 5, k + 62, deepslate_tile_stairs, 3, 2);
		world.setBlock(i + 42, j + 5, k + 62, deepslate_tile_stairs, 3, 2);
		world.setBlock(i + 43, j + 5, k + 62, Blocks.wool, 7, 2);
		world.setBlock(i + 44, j + 5, k + 62, Blocks.wool, 7, 2);
		world.setBlock(i + 45, j + 5, k + 62, deepslate_tile_stairs, 3, 2);
		world.setBlock(i + 0, j + 5, k + 63, deepslate_tile_stairs, 4, 2);
		world.setBlock(i + 1, j + 5, k + 63, Blocks.wool, 7, 2);
		world.setBlock(i + 2, j + 5, k + 63, Blocks.wool, 7, 2);
		world.setBlock(i + 3, j + 5, k + 63, deepslate_tile_stairs, 1, 2);
		world.setBlock(i + 42, j + 5, k + 63, deepslate_tile_stairs, 0, 2);
		world.setBlock(i + 43, j + 5, k + 63, Blocks.wool, 7, 2);
		world.setBlock(i + 44, j + 5, k + 63, Blocks.wool, 7, 2);
		world.setBlock(i + 45, j + 5, k + 63, deepslate_tile_stairs, 3, 2);
		world.setBlock(i + 0, j + 5, k + 64, deepslate_tile_stairs, 4, 2);
		world.setBlock(i + 1, j + 5, k + 64, deepslate_tile_stairs, 3, 2);
		world.setBlock(i + 2, j + 5, k + 64, Blocks.wool, 7, 2);
		world.setBlock(i + 3, j + 5, k + 64, deepslate_tile_stairs, 2, 2);
		world.setBlock(i + 42, j + 5, k + 64, deepslate_tile_stairs, 0, 2);
		world.setBlock(i + 43, j + 5, k + 64, Blocks.wool, 7, 2);
		world.setBlock(i + 44, j + 5, k + 64, Blocks.wool, 7, 2);
		world.setBlock(i + 45, j + 5, k + 64, deepslate_tile_stairs, 3, 2);
		world.setBlock(i + 0, j + 5, k + 65, deepslate_tile_stairs, 4, 2);
		world.setBlock(i + 2, j + 5, k + 65, Blocks.wool, 7, 2);
		world.setBlock(i + 3, j + 5, k + 65, deepslate_tile_stairs, 3, 2);
		world.setBlock(i + 4, j + 5, k + 65, deepslate_tile_stairs, 1, 2);
		world.setBlock(i + 5, j + 5, k + 65, deepslate_tile_stairs, 2, 2);
		world.setBlock(i + 6, j + 5, k + 65, deepslate_tile_stairs, 0, 2);
		world.setBlock(i + 7, j + 5, k + 65, Blocks.wool, 7, 2);
		world.setBlock(i + 8, j + 5, k + 65, deepslate_tile_stairs, 1, 2);
		world.setBlock(i + 9, j + 5, k + 65, deepslate_tile_stairs, 0, 2);
		world.setBlock(i + 10, j + 5, k + 65, Blocks.wool, 7, 2);
		world.setBlock(i + 11, j + 5, k + 65, deepslate_tile_stairs, 1, 2);
		world.setBlock(i + 12, j + 5, k + 65, deepslate_tile_stairs, 0, 2);
		world.setBlock(i + 13, j + 5, k + 65, Blocks.wool, 7, 2);
		world.setBlock(i + 14, j + 5, k + 65, deepslate_tile_stairs, 1, 2);
		world.setBlock(i + 15, j + 5, k + 65, deepslate_tile_stairs, 0, 2);
		world.setBlock(i + 17, j + 5, k + 65, Blocks.wool, 7, 2);
		world.setBlock(i + 21, j + 5, k + 65, deepslate_tile_stairs, 6, 2);
		world.setBlock(i + 23, j + 5, k + 65, deepslate_tile_stairs, 0, 2);
		world.setBlock(i + 24, j + 5, k + 65, deepslate_tile_stairs, 1, 2);
		world.setBlock(i + 25, j + 5, k + 65, deepslate_tile_stairs, 0, 2);
		world.setBlock(i + 26, j + 5, k + 65, Blocks.wool, 7, 2);
		world.setBlock(i + 27, j + 5, k + 65, deepslate_tile_stairs, 1, 2);
		world.setBlock(i + 28, j + 5, k + 65, deepslate_tile_stairs, 0, 2);
		world.setBlock(i + 29, j + 5, k + 65, Blocks.wool, 7, 2);
		world.setBlock(i + 30, j + 5, k + 65, deepslate_tile_stairs, 1, 2);
		world.setBlock(i + 31, j + 5, k + 65, deepslate_tile_stairs, 0, 2);
		world.setBlock(i + 32, j + 5, k + 65, Blocks.wool, 7, 2);
		world.setBlock(i + 33, j + 5, k + 65, deepslate_tile_stairs, 1, 2);
		world.setBlock(i + 34, j + 5, k + 65, deepslate_tile_stairs, 0, 2);
		world.setBlock(i + 35, j + 5, k + 65, Blocks.wool, 7, 2);
		world.setBlock(i + 36, j + 5, k + 65, deepslate_tile_stairs, 1, 2);
		world.setBlock(i + 37, j + 5, k + 65, deepslate_tile_stairs, 0, 2);
		world.setBlock(i + 38, j + 5, k + 65, Blocks.wool, 7, 2);
		world.setBlock(i + 39, j + 5, k + 65, deepslate_tile_stairs, 1, 2);
		world.setBlock(i + 40, j + 5, k + 65, deepslate_tile_stairs, 2, 2);
		world.setBlock(i + 41, j + 5, k + 65, deepslate_tile_stairs, 2, 2);
		world.setBlock(i + 42, j + 5, k + 65, deepslate_tile_stairs, 0, 2);
		world.setBlock(i + 43, j + 5, k + 65, Blocks.wool, 7, 2);
		world.setBlock(i + 44, j + 5, k + 65, Blocks.wool, 7, 2);
		world.setBlock(i + 45, j + 5, k + 65, deepslate_tile_stairs, 3, 2);
		world.setBlock(i + 0, j + 5, k + 66, deepslate_bricks, 0, 2);
		world.setBlock(i + 1, j + 5, k + 66, Blocks.wool, 7, 2);
		world.setBlock(i + 2, j + 5, k + 66, Blocks.wool, 7, 2);
		world.setBlock(i + 3, j + 5, k + 66, Blocks.wool, 7, 2);
		world.setBlock(i + 5, j + 5, k + 66, Blocks.wool, 7, 2);
		world.setBlock(i + 6, j + 5, k + 66, Blocks.wool, 7, 2);
		world.setBlock(i + 7, j + 5, k + 66, Blocks.wool, 7, 2);
		world.setBlock(i + 8, j + 5, k + 66, Blocks.wool, 7, 2);
		world.setBlock(i + 9, j + 5, k + 66, Blocks.wool, 7, 2);
		world.setBlock(i + 10, j + 5, k + 66, Blocks.wool, 7, 2);
		world.setBlock(i + 11, j + 5, k + 66, Blocks.wool, 7, 2);
		world.setBlock(i + 12, j + 5, k + 66, Blocks.wool, 7, 2);
		world.setBlock(i + 13, j + 5, k + 66, Blocks.wool, 7, 2);
		world.setBlock(i + 14, j + 5, k + 66, Blocks.wool, 7, 2);
		world.setBlock(i + 15, j + 5, k + 66, Blocks.wool, 7, 2);
		world.setBlock(i + 16, j + 5, k + 66, Blocks.wool, 7, 2);
		world.setBlock(i + 24, j + 5, k + 66, Blocks.wool, 7, 2);
		world.setBlock(i + 26, j + 5, k + 66, Blocks.wool, 7, 2);
		world.setBlock(i + 27, j + 5, k + 66, Blocks.wool, 7, 2);
		world.setBlock(i + 28, j + 5, k + 66, Blocks.wool, 7, 2);
		world.setBlock(i + 29, j + 5, k + 66, Blocks.wool, 7, 2);
		world.setBlock(i + 30, j + 5, k + 66, Blocks.wool, 7, 2);
		world.setBlock(i + 31, j + 5, k + 66, Blocks.wool, 7, 2);
		world.setBlock(i + 32, j + 5, k + 66, Blocks.wool, 7, 2);
		world.setBlock(i + 33, j + 5, k + 66, Blocks.wool, 7, 2);
		world.setBlock(i + 34, j + 5, k + 66, Blocks.wool, 7, 2);
		world.setBlock(i + 35, j + 5, k + 66, Blocks.wool, 7, 2);
		world.setBlock(i + 36, j + 5, k + 66, Blocks.wool, 7, 2);
		world.setBlock(i + 37, j + 5, k + 66, Blocks.wool, 7, 2);
		world.setBlock(i + 38, j + 5, k + 66, Blocks.wool, 7, 2);
		world.setBlock(i + 39, j + 5, k + 66, Blocks.wool, 7, 2);
		world.setBlock(i + 40, j + 5, k + 66, Blocks.wool, 7, 2);
		world.setBlock(i + 41, j + 5, k + 66, Blocks.wool, 7, 2);
		world.setBlock(i + 42, j + 5, k + 66, Blocks.wool, 7, 2);
		world.setBlock(i + 43, j + 5, k + 66, Blocks.wool, 7, 2);
		world.setBlock(i + 44, j + 5, k + 66, Blocks.wool, 7, 2);
		world.setBlock(i + 45, j + 5, k + 66, deepslate_bricks, 1, 2);
		world.setBlock(i + 0, j + 5, k + 67, deepslate_bricks, 0, 2);
		world.setBlock(i + 1, j + 5, k + 67, Blocks.wool, 7, 2);
		world.setBlock(i + 2, j + 5, k + 67, Blocks.wool, 7, 2);
		world.setBlock(i + 3, j + 5, k + 67, Blocks.wool, 7, 2);
		world.setBlock(i + 5, j + 5, k + 67, Blocks.wool, 7, 2);
		world.setBlock(i + 6, j + 5, k + 67, Blocks.wool, 7, 2);
		world.setBlock(i + 7, j + 5, k + 67, Blocks.wool, 7, 2);
		world.setBlock(i + 8, j + 5, k + 67, Blocks.wool, 7, 2);
		world.setBlock(i + 9, j + 5, k + 67, Blocks.wool, 7, 2);
		world.setBlock(i + 10, j + 5, k + 67, Blocks.wool, 7, 2);
		world.setBlock(i + 11, j + 5, k + 67, Blocks.wool, 7, 2);
		world.setBlock(i + 12, j + 5, k + 67, Blocks.wool, 7, 2);
		world.setBlock(i + 13, j + 5, k + 67, Blocks.wool, 7, 2);
		world.setBlock(i + 14, j + 5, k + 67, Blocks.wool, 7, 2);
		world.setBlock(i + 15, j + 5, k + 67, Blocks.wool, 7, 2);
		world.setBlock(i + 16, j + 5, k + 67, Blocks.wool, 7, 2);
		world.setBlock(i + 17, j + 5, k + 67, Blocks.wool, 7, 2);
		world.setBlock(i + 18, j + 5, k + 67, deepslate_tile_stairs, 3, 2);
		world.setBlock(i + 24, j + 5, k + 67, Blocks.wool, 7, 2);
		world.setBlock(i + 25, j + 5, k + 67, Blocks.wool, 7, 2);
		world.setBlock(i + 26, j + 5, k + 67, Blocks.wool, 7, 2);
		world.setBlock(i + 27, j + 5, k + 67, Blocks.wool, 7, 2);
		world.setBlock(i + 28, j + 5, k + 67, Blocks.wool, 7, 2);
		world.setBlock(i + 29, j + 5, k + 67, Blocks.wool, 7, 2);
		world.setBlock(i + 30, j + 5, k + 67, Blocks.wool, 7, 2);
		world.setBlock(i + 31, j + 5, k + 67, Blocks.wool, 7, 2);
		world.setBlock(i + 32, j + 5, k + 67, Blocks.wool, 7, 2);
		world.setBlock(i + 34, j + 5, k + 67, Blocks.wool, 7, 2);
		world.setBlock(i + 35, j + 5, k + 67, Blocks.wool, 7, 2);
		world.setBlock(i + 36, j + 5, k + 67, Blocks.wool, 7, 2);
		world.setBlock(i + 37, j + 5, k + 67, Blocks.wool, 7, 2);
		world.setBlock(i + 38, j + 5, k + 67, Blocks.wool, 7, 2);
		world.setBlock(i + 39, j + 5, k + 67, Blocks.wool, 7, 2);
		world.setBlock(i + 40, j + 5, k + 67, Blocks.wool, 7, 2);
		world.setBlock(i + 41, j + 5, k + 67, Blocks.wool, 7, 2);
		world.setBlock(i + 42, j + 5, k + 67, Blocks.wool, 7, 2);
		world.setBlock(i + 43, j + 5, k + 67, Blocks.wool, 7, 2);
		world.setBlock(i + 44, j + 5, k + 67, Blocks.wool, 7, 2);
		world.setBlock(i + 45, j + 5, k + 67, deepslate_bricks, 0, 2);
		world.setBlock(i + 0, j + 5, k + 68, deepslate_bricks, 0, 2);
		world.setBlock(i + 1, j + 5, k + 68, deepslate_bricks, 0, 2);
		world.setBlock(i + 2, j + 5, k + 68, deepslate_bricks, 0, 2);
		world.setBlock(i + 3, j + 5, k + 68, deepslate_tile_stairs, 3, 2);
		world.setBlock(i + 4, j + 5, k + 68, deepslate_tile_stairs, 3, 2);
		world.setBlock(i + 5, j + 5, k + 68, deepslate_tile_stairs, 3, 2);
		world.setBlock(i + 6, j + 5, k + 68, deepslate_tile_stairs, 3, 2);
		world.setBlock(i + 7, j + 5, k + 68, deepslate_tile_stairs, 3, 2);
		world.setBlock(i + 8, j + 5, k + 68, deepslate_bricks, 1, 2);
		world.setBlock(i + 9, j + 5, k + 68, deepslate_bricks, 0, 2);
		world.setBlock(i + 10, j + 5, k + 68, deepslate_bricks, 0, 2);
		world.setBlock(i + 11, j + 5, k + 68, deepslate_bricks, 0, 2);
		world.setBlock(i + 12, j + 5, k + 68, deepslate_tile_stairs, 3, 2);
		world.setBlock(i + 13, j + 5, k + 68, deepslate_tile_stairs, 3, 2);
		world.setBlock(i + 14, j + 5, k + 68, deepslate_tile_stairs, 3, 2);
		world.setBlock(i + 15, j + 5, k + 68, deepslate_tile_stairs, 3, 2);
		world.setBlock(i + 16, j + 5, k + 68, deepslate_bricks, 1, 2);
		world.setBlock(i + 17, j + 5, k + 68, deepslate_bricks, 0, 2);
		world.setBlock(i + 18, j + 5, k + 68, deepslate_bricks, 1, 2);
		world.setBlock(i + 19, j + 5, k + 68, deepslate_bricks, 1, 2);
		world.setBlock(i + 20, j + 5, k + 68, deepslate_tile_stairs, 3, 2);
		world.setBlock(i + 24, j + 5, k + 68, deepslate_tile_stairs, 3, 2);
		world.setBlock(i + 25, j + 5, k + 68, deepslate_bricks, 1, 2);
		world.setBlock(i + 26, j + 5, k + 68, deepslate_bricks, 0, 2);
		world.setBlock(i + 27, j + 5, k + 68, deepslate_bricks, 0, 2);
		world.setBlock(i + 28, j + 5, k + 68, deepslate_bricks, 1, 2);
		world.setBlock(i + 29, j + 5, k + 68, deepslate_tile_stairs, 3, 2);
		world.setBlock(i + 30, j + 5, k + 68, deepslate_tile_stairs, 3, 2);
		world.setBlock(i + 31, j + 5, k + 68, deepslate_tile_stairs, 3, 2);
		world.setBlock(i + 32, j + 5, k + 68, deepslate_tile_stairs, 3, 2);
		world.setBlock(i + 33, j + 5, k + 68, deepslate_tile_stairs, 3, 2);
		world.setBlock(i + 34, j + 5, k + 68, deepslate_bricks, 1, 2);
		world.setBlock(i + 35, j + 5, k + 68, deepslate_bricks, 1, 2);
		world.setBlock(i + 36, j + 5, k + 68, deepslate_bricks, 1, 2);
		world.setBlock(i + 37, j + 5, k + 68, deepslate_bricks, 0, 2);
		world.setBlock(i + 38, j + 5, k + 68, deepslate_tile_stairs, 3, 2);
		world.setBlock(i + 39, j + 5, k + 68, deepslate_tile_stairs, 3, 2);
		world.setBlock(i + 40, j + 5, k + 68, deepslate_tile_stairs, 3, 2);
		world.setBlock(i + 41, j + 5, k + 68, deepslate_tile_stairs, 3, 2);
		world.setBlock(i + 42, j + 5, k + 68, deepslate_tile_stairs, 3, 2);
		world.setBlock(i + 43, j + 5, k + 68, deepslate_bricks, 0, 2);
		world.setBlock(i + 44, j + 5, k + 68, deepslate_bricks, 0, 2);
		world.setBlock(i + 45, j + 5, k + 68, deepslate_bricks, 0, 2);
		world.setBlock(i + 0, j + 6, k + 0, deepslate_bricks, 4, 2);
		world.setBlock(i + 1, j + 6, k + 0, deepslate_bricks, 4, 2);
		world.setBlock(i + 2, j + 6, k + 0, deepslate_wall, 0, 2);
		world.setBlock(i + 3, j + 6, k + 0, deepslate_bricks, 4, 2);
		world.setBlock(i + 4, j + 6, k + 0, deepslate_bricks, 4, 2);
		world.setBlock(i + 5, j + 6, k + 0, deepslate_wall, 0, 2);
		world.setBlock(i + 6, j + 6, k + 0, deepslate_bricks, 4, 2);
		world.setBlock(i + 7, j + 6, k + 0, deepslate_bricks, 4, 2);
		world.setBlock(i + 8, j + 6, k + 0, deepslate_wall, 0, 2);
		world.setBlock(i + 9, j + 6, k + 0, deepslate_bricks, 4, 2);
		world.setBlock(i + 10, j + 6, k + 0, deepslate_bricks, 4, 2);
		world.setBlock(i + 11, j + 6, k + 0, deepslate_wall, 0, 2);
		world.setBlock(i + 12, j + 6, k + 0, deepslate_bricks, 4, 2);
		world.setBlock(i + 13, j + 6, k + 0, deepslate_bricks, 4, 2);
		world.setBlock(i + 14, j + 6, k + 0, deepslate_bricks, 4, 2);
		world.setBlock(i + 15, j + 6, k + 0, deepslate_bricks, 4, 2);
		world.setBlock(i + 17, j + 6, k + 0, deepslate_bricks, 4, 2);
		world.setBlock(i + 18, j + 6, k + 0, deepslate_bricks, 4, 2);
		world.setBlock(i + 19, j + 6, k + 0, deepslate_wall, 0, 2);
		world.setBlock(i + 20, j + 6, k + 0, deepslate_bricks, 4, 2);
		world.setBlock(i + 21, j + 6, k + 0, deepslate_bricks, 4, 2);
		world.setBlock(i + 22, j + 6, k + 0, deepslate_wall, 0, 2);
		world.setBlock(i + 23, j + 6, k + 0, deepslate_bricks, 4, 2);
		world.setBlock(i + 24, j + 6, k + 0, deepslate_bricks, 4, 2);
		world.setBlock(i + 25, j + 6, k + 0, deepslate_wall, 0, 2);
		world.setBlock(i + 26, j + 6, k + 0, deepslate_bricks, 4, 2);
		world.setBlock(i + 27, j + 6, k + 0, deepslate_bricks, 4, 2);
		world.setBlock(i + 28, j + 6, k + 0, deepslate_wall, 0, 2);
		world.setBlock(i + 29, j + 6, k + 0, deepslate_bricks, 4, 2);
		world.setBlock(i + 30, j + 6, k + 0, deepslate_bricks, 4, 2);
		world.setBlock(i + 31, j + 6, k + 0, deepslate_wall, 0, 2);
		world.setBlock(i + 32, j + 6, k + 0, deepslate_bricks, 4, 2);
		world.setBlock(i + 33, j + 6, k + 0, deepslate_bricks, 4, 2);
		world.setBlock(i + 34, j + 6, k + 0, deepslate_wall, 0, 2);
		world.setBlock(i + 35, j + 6, k + 0, deepslate_bricks, 4, 2);
		world.setBlock(i + 40, j + 6, k + 0, deepslate_wall, 0, 2);
		world.setBlock(i + 41, j + 6, k + 0, deepslate_bricks, 4, 2);
		world.setBlock(i + 42, j + 6, k + 0, deepslate_bricks, 4, 2);
		world.setBlock(i + 43, j + 6, k + 0, deepslate_wall, 0, 2);
		world.setBlock(i + 44, j + 6, k + 0, deepslate_bricks, 4, 2);
		world.setBlock(i + 45, j + 6, k + 0, deepslate_bricks, 4, 2);
		world.setBlock(i + 0, j + 6, k + 1, deepslate_bricks, 4, 2);
		world.setBlock(i + 22, j + 6, k + 1, Blocks.wool, 7, 2);
		world.setBlock(i + 23, j + 6, k + 1, Blocks.wool, 7, 2);
		world.setBlock(i + 24, j + 6, k + 1, Blocks.wool, 7, 2);
		world.setBlock(i + 45, j + 6, k + 1, deepslate_bricks, 4, 2);
		world.setBlock(i + 0, j + 6, k + 2, deepslate_wall, 0, 2);
		world.setBlock(i + 22, j + 6, k + 2, Blocks.wool, 7, 2);
		world.setBlock(i + 23, j + 6, k + 2, Blocks.wool, 7, 2);
		world.setBlock(i + 24, j + 6, k + 2, Blocks.wool, 7, 2);
		world.setBlock(i + 45, j + 6, k + 2, deepslate_wall, 0, 2);
		world.setBlock(i + 0, j + 6, k + 3, deepslate_bricks, 4, 2);
		world.setBlock(i + 3, j + 6, k + 3, deepslate_tile_stairs, 0, 2);
		world.setBlock(i + 4, j + 6, k + 3, deepslate_tile_stairs, 2, 2);
		world.setBlock(i + 5, j + 6, k + 3, deepslate_bricks, 4, 2);
		world.setBlock(i + 6, j + 6, k + 3, deepslate_bricks, 4, 2);
		world.setBlock(i + 7, j + 6, k + 3, deepslate_tile_stairs, 2, 2);
		world.setBlock(i + 8, j + 6, k + 3, deepslate_bricks, 4, 2);
		world.setBlock(i + 9, j + 6, k + 3, deepslate_bricks, 4, 2);
		world.setBlock(i + 10, j + 6, k + 3, deepslate_tile_stairs, 2, 2);
		world.setBlock(i + 11, j + 6, k + 3, deepslate_bricks, 4, 2);
		world.setBlock(i + 12, j + 6, k + 3, deepslate_bricks, 4, 2);
		world.setBlock(i + 13, j + 6, k + 3, deepslate_tile_stairs, 2, 2);
		world.setBlock(i + 14, j + 6, k + 3, deepslate_bricks, 4, 2);
		world.setBlock(i + 15, j + 6, k + 3, deepslate_bricks, 4, 2);
		world.setBlock(i + 16, j + 6, k + 3, deepslate_tile_stairs, 2, 2);
		world.setBlock(i + 21, j + 6, k + 3, deepslate_bricks, 4, 2);
		world.setBlock(i + 22, j + 6, k + 3, deepslate_bricks, 4, 2);
		world.setBlock(i + 23, j + 6, k + 3, deepslate_tile_stairs, 3, 2);
		world.setBlock(i + 24, j + 6, k + 3, deepslate_bricks, 4, 2);
		world.setBlock(i + 25, j + 6, k + 3, deepslate_bricks, 4, 2);
		world.setBlock(i + 26, j + 6, k + 3, deepslate_tile_stairs, 2, 2);
		world.setBlock(i + 27, j + 6, k + 3, deepslate_bricks, 4, 2);
		world.setBlock(i + 28, j + 6, k + 3, deepslate_bricks, 4, 2);
		world.setBlock(i + 29, j + 6, k + 3, deepslate_tile_stairs, 2, 2);
		world.setBlock(i + 30, j + 6, k + 3, deepslate_bricks, 4, 2);
		world.setBlock(i + 31, j + 6, k + 3, deepslate_bricks, 4, 2);
		world.setBlock(i + 32, j + 6, k + 3, deepslate_tile_stairs, 2, 2);
		world.setBlock(i + 33, j + 6, k + 3, deepslate_bricks, 4, 2);
		world.setBlock(i + 34, j + 6, k + 3, deepslate_bricks, 4, 2);
		world.setBlock(i + 35, j + 6, k + 3, deepslate_tile_stairs, 2, 2);
		world.setBlock(i + 41, j + 6, k + 3, deepslate_tile_stairs, 2, 2);
		world.setBlock(i + 42, j + 6, k + 3, deepslate_bricks, 4, 2);
		world.setBlock(i + 45, j + 6, k + 3, deepslate_bricks, 4, 2);
		world.setBlock(i + 0, j + 6, k + 4, deepslate_bricks, 4, 2);
		world.setBlock(i + 3, j + 6, k + 4, deepslate_tile_stairs, 0, 2);
		world.setBlock(i + 42, j + 6, k + 4, deepslate_tile_stairs, 1, 2);
		world.setBlock(i + 45, j + 6, k + 4, deepslate_bricks, 4, 2);
		world.setBlock(i + 0, j + 6, k + 5, deepslate_wall, 0, 2);
		world.setBlock(i + 3, j + 6, k + 5, deepslate_bricks, 4, 2);
		world.setBlock(i + 42, j + 6, k + 5, deepslate_bricks, 4, 2);
		world.setBlock(i + 45, j + 6, k + 5, deepslate_wall, 0, 2);
		world.setBlock(i + 0, j + 6, k + 6, deepslate_bricks, 4, 2);
		world.setBlock(i + 3, j + 6, k + 6, deepslate_bricks, 4, 2);
		world.setBlock(i + 42, j + 6, k + 6, deepslate_bricks, 4, 2);
		world.setBlock(i + 0, j + 6, k + 7, deepslate_bricks, 4, 2);
		world.setBlock(i + 3, j + 6, k + 7, deepslate_tile_stairs, 0, 2);
		world.setBlock(i + 42, j + 6, k + 7, deepslate_tile_stairs, 1, 2);
		world.setBlock(i + 0, j + 6, k + 8, deepslate_wall, 0, 2);
		world.setBlock(i + 3, j + 6, k + 8, deepslate_bricks, 4, 2);
		world.setBlock(i + 42, j + 6, k + 8, deepslate_bricks, 4, 2);
		world.setBlock(i + 0, j + 6, k + 9, deepslate_bricks, 4, 2);
		world.setBlock(i + 3, j + 6, k + 9, deepslate_bricks, 4, 2);
		world.setBlock(i + 42, j + 6, k + 9, deepslate_bricks, 4, 2);
		world.setBlock(i + 0, j + 6, k + 10, deepslate_bricks, 4, 2);
		world.setBlock(i + 3, j + 6, k + 10, deepslate_tile_stairs, 0, 2);
		world.setBlock(i + 10, j + 6, k + 10, Blocks.wool, 7, 2);
		world.setBlock(i + 12, j + 6, k + 10, deepslate_tile_stairs, 2, 2);
		world.setBlock(i + 13, j + 6, k + 10, deepslate_tile_stairs, 2, 2);
		world.setBlock(i + 14, j + 6, k + 10, deepslate_tile_stairs, 2, 2);
		world.setBlock(i + 15, j + 6, k + 10, Blocks.wool, 7, 2);
		world.setBlock(i + 16, j + 6, k + 10, Blocks.wool, 7, 2);
		world.setBlock(i + 17, j + 6, k + 10, Blocks.wool, 7, 2);
		world.setBlock(i + 18, j + 6, k + 10, Blocks.wool, 7, 2);
		world.setBlock(i + 19, j + 6, k + 10, deepslate_tile_stairs, 2, 2);
		world.setBlock(i + 20, j + 6, k + 10, deepslate_tile_stairs, 2, 2);
		world.setBlock(i + 21, j + 6, k + 10, deepslate_tile_stairs, 2, 2);
		world.setBlock(i + 22, j + 6, k + 10, Blocks.wool, 7, 2);
		world.setBlock(i + 23, j + 6, k + 10, Blocks.wool, 7, 2);
		world.setBlock(i + 24, j + 6, k + 10, deepslate_tile_stairs, 2, 2);
		world.setBlock(i + 25, j + 6, k + 10, deepslate_tile_stairs, 2, 2);
		world.setBlock(i + 26, j + 6, k + 10, deepslate_tile_stairs, 2, 2);
		world.setBlock(i + 27, j + 6, k + 10, Blocks.wool, 7, 2);
		world.setBlock(i + 28, j + 6, k + 10, Blocks.wool, 7, 2);
		world.setBlock(i + 29, j + 6, k + 10, Blocks.wool, 7, 2);
		world.setBlock(i + 30, j + 6, k + 10, Blocks.wool, 7, 2);
		world.setBlock(i + 31, j + 6, k + 10, deepslate_tile_stairs, 2, 2);
		world.setBlock(i + 32, j + 6, k + 10, deepslate_tile_stairs, 2, 2);
		world.setBlock(i + 33, j + 6, k + 10, deepslate_tile_stairs, 2, 2);
		world.setBlock(i + 34, j + 6, k + 10, Blocks.wool, 7, 2);
		world.setBlock(i + 35, j + 6, k + 10, Blocks.wool, 7, 2);
		world.setBlock(i + 42, j + 6, k + 10, deepslate_tile_stairs, 1, 2);
		world.setBlock(i + 0, j + 6, k + 11, deepslate_wall, 0, 2);
		world.setBlock(i + 3, j + 6, k + 11, deepslate_bricks, 4, 2);
		world.setBlock(i + 10, j + 6, k + 11, Blocks.wool, 7, 2);
		world.setBlock(i + 35, j + 6, k + 11, Blocks.wool, 7, 2);
		world.setBlock(i + 42, j + 6, k + 11, deepslate_bricks, 4, 2);
		world.setBlock(i + 45, j + 6, k + 11, deepslate_wall, 0, 2);
		world.setBlock(i + 0, j + 6, k + 12, deepslate_bricks, 4, 2);
		world.setBlock(i + 3, j + 6, k + 12, deepslate_bricks, 4, 2);
		world.setBlock(i + 10, j + 6, k + 12, deepslate_tile_stairs, 0, 2);
		world.setBlock(i + 12, j + 6, k + 12, Blocks.wool, 7, 2);
		world.setBlock(i + 13, j + 6, k + 12, Blocks.wool, 7, 2);
		world.setBlock(i + 14, j + 6, k + 12, Blocks.wool, 7, 2);
		world.setBlock(i + 15, j + 6, k + 12, Blocks.wool, 7, 2);
		world.setBlock(i + 16, j + 6, k + 12, Blocks.wool, 7, 2);
		world.setBlock(i + 17, j + 6, k + 12, Blocks.wool, 7, 2);
		world.setBlock(i + 18, j + 6, k + 12, Blocks.wool, 7, 2);
		world.setBlock(i + 19, j + 6, k + 12, Blocks.wool, 7, 2);
		world.setBlock(i + 20, j + 6, k + 12, Blocks.wool, 7, 2);
		world.setBlock(i + 21, j + 6, k + 12, Blocks.wool, 7, 2);
		world.setBlock(i + 22, j + 6, k + 12, Blocks.wool, 7, 2);
		world.setBlock(i + 23, j + 6, k + 12, Blocks.wool, 7, 2);
		world.setBlock(i + 24, j + 6, k + 12, Blocks.wool, 7, 2);
		world.setBlock(i + 25, j + 6, k + 12, Blocks.wool, 7, 2);
		world.setBlock(i + 27, j + 6, k + 12, Blocks.wool, 7, 2);
		world.setBlock(i + 28, j + 6, k + 12, Blocks.wool, 7, 2);
		world.setBlock(i + 29, j + 6, k + 12, Blocks.wool, 7, 2);
		world.setBlock(i + 30, j + 6, k + 12, Blocks.wool, 7, 2);
		world.setBlock(i + 31, j + 6, k + 12, Blocks.wool, 7, 2);
		world.setBlock(i + 32, j + 6, k + 12, Blocks.wool, 7, 2);
		world.setBlock(i + 33, j + 6, k + 12, Blocks.wool, 7, 2);
		world.setBlock(i + 35, j + 6, k + 12, deepslate_tile_stairs, 1, 2);
		world.setBlock(i + 42, j + 6, k + 12, deepslate_bricks, 4, 2);
		world.setBlock(i + 45, j + 6, k + 12, deepslate_bricks, 4, 2);
		world.setBlock(i + 0, j + 6, k + 13, deepslate_bricks, 4, 2);
		world.setBlock(i + 3, j + 6, k + 13, deepslate_tile_stairs, 0, 2);
		world.setBlock(i + 10, j + 6, k + 13, deepslate_tile_stairs, 0, 2);
		world.setBlock(i + 12, j + 6, k + 13, Blocks.wool, 7, 2);
		world.setBlock(i + 33, j + 6, k + 13, Blocks.wool, 7, 2);
		world.setBlock(i + 35, j + 6, k + 13, deepslate_tile_stairs, 1, 2);
		world.setBlock(i + 42, j + 6, k + 13, deepslate_tile_stairs, 1, 2);
		world.setBlock(i + 45, j + 6, k + 13, deepslate_bricks, 4, 2);
		world.setBlock(i + 0, j + 6, k + 14, deepslate_bricks, 4, 2);
		world.setBlock(i + 10, j + 6, k + 14, deepslate_tile_stairs, 0, 2);
		world.setBlock(i + 12, j + 6, k + 14, Blocks.wool, 7, 2);
		world.setBlock(i + 14, j + 6, k + 14, deepslate_bricks, 0, 2);
		world.setBlock(i + 15, j + 6, k + 14, deepslate_bricks, 0, 2);
		world.setBlock(i + 16, j + 6, k + 14, deepslate_bricks, 1, 2);
		world.setBlock(i + 17, j + 6, k + 14, deepslate_bricks, 0, 2);
		world.setBlock(i + 18, j + 6, k + 14, deepslate_bricks, 0, 2);
		world.setBlock(i + 19, j + 6, k + 14, deepslate_bricks, 0, 2);
		world.setBlock(i + 20, j + 6, k + 14, deepslate_bricks, 1, 2);
		world.setBlock(i + 21, j + 6, k + 14, deepslate_bricks, 0, 2);
		world.setBlock(i + 22, j + 6, k + 14, deepslate_bricks, 1, 2);
		world.setBlock(i + 23, j + 6, k + 14, deepslate_bricks, 0, 2);
		world.setBlock(i + 24, j + 6, k + 14, deepslate_bricks, 1, 2);
		world.setBlock(i + 25, j + 6, k + 14, deepslate_bricks, 0, 2);
		world.setBlock(i + 26, j + 6, k + 14, deepslate_bricks, 0, 2);
		world.setBlock(i + 27, j + 6, k + 14, deepslate_bricks, 0, 2);
		world.setBlock(i + 33, j + 6, k + 14, Blocks.wool, 7, 2);
		world.setBlock(i + 35, j + 6, k + 14, deepslate_tile_stairs, 1, 2);
		world.setBlock(i + 42, j + 6, k + 14, deepslate_bricks, 4, 2);
		world.setBlock(i + 0, j + 6, k + 15, deepslate_bricks, 4, 2);
		world.setBlock(i + 12, j + 6, k + 15, Blocks.wool, 7, 2);
		world.setBlock(i + 14, j + 6, k + 15, deepslate_bricks, 0, 2);
		world.setBlock(i + 21, j + 6, k + 15, deepslate_bricks, 2, 2);
		world.setBlock(i + 24, j + 6, k + 15, deepslate_bricks, 2, 2);
		world.setBlock(i + 25, j + 6, k + 15, deepslate_bricks, 2, 2);
		world.setBlock(i + 26, j + 6, k + 15, deepslate_bricks, 2, 2);
		world.setBlock(i + 27, j + 6, k + 15, deepslate_bricks, 0, 2);
		world.setBlock(i + 33, j + 6, k + 15, Blocks.wool, 7, 2);
		world.setBlock(i + 35, j + 6, k + 15, Blocks.wool, 7, 2);
		world.setBlock(i + 42, j + 6, k + 15, deepslate_bricks, 4, 2);
		world.setBlock(i + 45, j + 6, k + 15, deepslate_bricks, 4, 2);
		world.setBlock(i + 0, j + 6, k + 16, deepslate_wall, 0, 2);
		world.setBlock(i + 3, j + 6, k + 16, deepslate_tile_stairs, 0, 2);
		world.setBlock(i + 10, j + 6, k + 16, Blocks.wool, 7, 2);
		world.setBlock(i + 12, j + 6, k + 16, Blocks.wool, 7, 2);
		world.setBlock(i + 14, j + 6, k + 16, deepslate_bricks, 0, 2);
		world.setBlock(i + 21, j + 6, k + 16, deepslate_bricks, 2, 2);
		world.setBlock(i + 24, j + 6, k + 16, deepslate_bricks, 2, 2);
		world.setBlock(i + 25, j + 6, k + 16, deepslate_bricks, 3, 2);
		world.setBlock(i + 26, j + 6, k + 16, deepslate_bricks, 3, 2);
		world.setBlock(i + 27, j + 6, k + 16, deepslate_bricks, 0, 2);
		world.setBlock(i + 33, j + 6, k + 16, Blocks.wool, 7, 2);
		world.setBlock(i + 35, j + 6, k + 16, Blocks.wool, 7, 2);
		world.setBlock(i + 42, j + 6, k + 16, deepslate_tile_stairs, 1, 2);
		world.setBlock(i + 45, j + 6, k + 16, deepslate_bricks, 4, 2);
		world.setBlock(i + 0, j + 6, k + 17, deepslate_bricks, 4, 2);
		world.setBlock(i + 3, j + 6, k + 17, deepslate_bricks, 4, 2);
		world.setBlock(i + 10, j + 6, k + 17, deepslate_tile_stairs, 0, 2);
		world.setBlock(i + 14, j + 6, k + 17, deepslate_bricks, 0, 2);
		world.setBlock(i + 21, j + 6, k + 17, deepslate_bricks, 2, 2);
		world.setBlock(i + 24, j + 6, k + 17, deepslate_bricks, 3, 2);
		world.setBlock(i + 25, j + 6, k + 17, deepslate_bricks, 2, 2);
		world.setBlock(i + 26, j + 6, k + 17, deepslate_bricks, 3, 2);
		world.setBlock(i + 27, j + 6, k + 17, deepslate_bricks, 0, 2);
		world.setBlock(i + 33, j + 6, k + 17, Blocks.wool, 7, 2);
		world.setBlock(i + 35, j + 6, k + 17, Blocks.wool, 7, 2);
		world.setBlock(i + 42, j + 6, k + 17, deepslate_bricks, 4, 2);
		world.setBlock(i + 45, j + 6, k + 17, deepslate_wall, 0, 2);
		world.setBlock(i + 0, j + 6, k + 18, deepslate_bricks, 4, 2);
		world.setBlock(i + 3, j + 6, k + 18, deepslate_bricks, 4, 2);
		world.setBlock(i + 10, j + 6, k + 18, deepslate_tile_stairs, 0, 2);
		world.setBlock(i + 12, j + 6, k + 18, Blocks.wool, 7, 2);
		world.setBlock(i + 14, j + 6, k + 18, deepslate_bricks, 0, 2);
		world.setBlock(i + 21, j + 6, k + 18, deepslate_bricks, 3, 2);
		world.setBlock(i + 24, j + 6, k + 18, deepslate_bricks, 3, 2);
		world.setBlock(i + 25, j + 6, k + 18, deepslate_bricks, 2, 2);
		world.setBlock(i + 26, j + 6, k + 18, deepslate_bricks, 3, 2);
		world.setBlock(i + 27, j + 6, k + 18, deepslate_bricks, 1, 2);
		world.setBlock(i + 42, j + 6, k + 18, deepslate_bricks, 4, 2);
		world.setBlock(i + 45, j + 6, k + 18, deepslate_bricks, 4, 2);
		world.setBlock(i + 0, j + 6, k + 19, deepslate_wall, 0, 2);
		world.setBlock(i + 3, j + 6, k + 19, deepslate_tile_stairs, 0, 2);
		world.setBlock(i + 10, j + 6, k + 19, deepslate_tile_stairs, 0, 2);
		world.setBlock(i + 12, j + 6, k + 19, Blocks.wool, 7, 2);
		world.setBlock(i + 14, j + 6, k + 19, deepslate_bricks, 0, 2);
		world.setBlock(i + 21, j + 6, k + 19, deepslate_bricks, 2, 2);
		world.setBlock(i + 24, j + 6, k + 19, deepslate_bricks, 2, 2);
		world.setBlock(i + 25, j + 6, k + 19, deepslate_bricks, 2, 2);
		world.setBlock(i + 26, j + 6, k + 19, deepslate_bricks, 2, 2);
		world.setBlock(i + 27, j + 6, k + 19, deepslate_bricks, 1, 2);
		world.setBlock(i + 28, j + 6, k + 19, deepslate_brick_slab, 0, 2);
		world.setBlock(i + 29, j + 6, k + 19, deepslate_brick_slab, 0, 2);
		world.setBlock(i + 30, j + 6, k + 19, deepslate_brick_slab, 0, 2);
		world.setBlock(i + 31, j + 6, k + 19, deepslate_brick_slab, 0, 2);
		world.setBlock(i + 45, j + 6, k + 19, deepslate_bricks, 4, 2);
		world.setBlock(i + 0, j + 6, k + 20, deepslate_bricks, 4, 2);
		world.setBlock(i + 10, j + 6, k + 20, Blocks.wool, 7, 2);
		world.setBlock(i + 12, j + 6, k + 20, Blocks.wool, 7, 2);
		world.setBlock(i + 14, j + 6, k + 20, deepslate_bricks, 0, 2);
		world.setBlock(i + 15, j + 6, k + 20, deepslate_bricks, 2, 2);
		world.setBlock(i + 16, j + 6, k + 20, deepslate_bricks, 2, 2);
		world.setBlock(i + 17, j + 6, k + 20, deepslate_bricks, 2, 2);
		world.setBlock(i + 18, j + 6, k + 20, deepslate_bricks, 2, 2);
		world.setBlock(i + 19, j + 6, k + 20, deepslate_bricks, 3, 2);
		world.setBlock(i + 20, j + 6, k + 20, deepslate_bricks, 2, 2);
		world.setBlock(i + 21, j + 6, k + 20, deepslate_bricks, 2, 2);
		world.setBlock(i + 22, j + 6, k + 20, deepslate_wall, 0, 2);
		world.setBlock(i + 24, j + 6, k + 20, deepslate_bricks, 2, 2);
		world.setBlock(i + 25, j + 6, k + 20, deepslate_bricks, 2, 2);
		world.setBlock(i + 26, j + 6, k + 20, deepslate_bricks, 2, 2);
		world.setBlock(i + 27, j + 6, k + 20, deepslate_bricks, 1, 2);
		world.setBlock(i + 28, j + 6, k + 20, deepslate_bricks, 1, 2);
		world.setBlock(i + 29, j + 6, k + 20, deepslate_bricks, 0, 2);
		world.setBlock(i + 30, j + 6, k + 20, deepslate_bricks, 0, 2);
		world.setBlock(i + 31, j + 6, k + 20, deepslate_bricks, 1, 2);
		world.setBlock(i + 45, j + 6, k + 20, deepslate_wall, 0, 2);
		world.setBlock(i + 0, j + 6, k + 21, deepslate_bricks, 4, 2);
		world.setBlock(i + 10, j + 6, k + 21, Blocks.wool, 7, 2);
		world.setBlock(i + 12, j + 6, k + 21, Blocks.wool, 7, 2);
		world.setBlock(i + 14, j + 6, k + 21, deepslate_bricks, 1, 2);
		world.setBlock(i + 21, j + 6, k + 21, deepslate_wall, 0, 2);
		world.setBlock(i + 24, j + 6, k + 21, deepslate_bricks, 2, 2);
		world.setBlock(i + 25, j + 6, k + 21, deepslate_bricks, 2, 2);
		world.setBlock(i + 26, j + 6, k + 21, deepslate_bricks, 3, 2);
		world.setBlock(i + 27, j + 6, k + 21, deepslate_bricks, 1, 2);
		world.setBlock(i + 28, j + 6, k + 21, deepslate_bricks, 0, 2);
		world.setBlock(i + 29, j + 6, k + 21, deepslate_bricks, 0, 2);
		world.setBlock(i + 30, j + 6, k + 21, deepslate_bricks, 0, 2);
		world.setBlock(i + 31, j + 6, k + 21, deepslate_bricks, 1, 2);
		world.setBlock(i + 33, j + 6, k + 21, Blocks.wool, 7, 2);
		world.setBlock(i + 45, j + 6, k + 21, deepslate_bricks, 4, 2);
		world.setBlock(i + 0, j + 6, k + 22, deepslate_bricks, 4, 2);
		world.setBlock(i + 3, j + 6, k + 22, deepslate_tile_stairs, 0, 2);
		world.setBlock(i + 10, j + 6, k + 22, deepslate_tile_stairs, 0, 2);
		world.setBlock(i + 12, j + 6, k + 22, Blocks.wool, 7, 2);
		world.setBlock(i + 14, j + 6, k + 22, deepslate_bricks, 0, 2);
		world.setBlock(i + 24, j + 6, k + 22, deepslate_bricks, 2, 2);
		world.setBlock(i + 25, j + 6, k + 22, deepslate_bricks, 2, 2);
		world.setBlock(i + 26, j + 6, k + 22, deepslate_bricks, 3, 2);
		world.setBlock(i + 27, j + 6, k + 22, deepslate_bricks, 0, 2);
		world.setBlock(i + 28, j + 6, k + 22, deepslate_bricks, 0, 2);
		world.setBlock(i + 29, j + 6, k + 22, deepslate_bricks, 1, 2);
		world.setBlock(i + 30, j + 6, k + 22, deepslate_bricks, 0, 2);
		world.setBlock(i + 31, j + 6, k + 22, deepslate_bricks, 0, 2);
		world.setBlock(i + 33, j + 6, k + 22, Blocks.wool, 7, 2);
		world.setBlock(i + 35, j + 6, k + 22, Blocks.wool, 7, 2);
		world.setBlock(i + 45, j + 6, k + 22, deepslate_bricks, 4, 2);
		world.setBlock(i + 0, j + 6, k + 23, deepslate_bricks, 4, 2);
		world.setBlock(i + 3, j + 6, k + 23, deepslate_bricks, 4, 2);
		world.setBlock(i + 10, j + 6, k + 23, deepslate_tile_stairs, 0, 2);
		world.setBlock(i + 12, j + 6, k + 23, Blocks.wool, 7, 2);
		world.setBlock(i + 14, j + 6, k + 23, deepslate_bricks, 0, 2);
		world.setBlock(i + 15, j + 6, k + 23, deepslate_bricks, 2, 2);
		world.setBlock(i + 16, j + 6, k + 23, deepslate_bricks, 2, 2);
		world.setBlock(i + 17, j + 6, k + 23, deepslate_bricks, 2, 2);
		world.setBlock(i + 18, j + 6, k + 23, deepslate_bricks, 2, 2);
		world.setBlock(i + 19, j + 6, k + 23, deepslate_bricks, 3, 2);
		world.setBlock(i + 20, j + 6, k + 23, deepslate_bricks, 2, 2);
		world.setBlock(i + 21, j + 6, k + 23, deepslate_bricks, 2, 2);
		world.setBlock(i + 24, j + 6, k + 23, deepslate_bricks, 2, 2);
		world.setBlock(i + 25, j + 6, k + 23, deepslate_bricks, 3, 2);
		world.setBlock(i + 26, j + 6, k + 23, deepslate_bricks, 3, 2);
		world.setBlock(i + 27, j + 6, k + 23, deepslate_bricks, 1, 2);
		world.setBlock(i + 28, j + 6, k + 23, deepslate_bricks, 1, 2);
		world.setBlock(i + 29, j + 6, k + 23, deepslate_bricks, 0, 2);
		world.setBlock(i + 30, j + 6, k + 23, deepslate_bricks, 0, 2);
		world.setBlock(i + 31, j + 6, k + 23, deepslate_bricks, 0, 2);
		world.setBlock(i + 32, j + 6, k + 23, polished_deepslate_stairs, 2, 2);
		world.setBlock(i + 33, j + 6, k + 23, Blocks.wool, 7, 2);
		world.setBlock(i + 34, j + 6, k + 23, polished_deepslate_stairs, 1, 2);
		world.setBlock(i + 35, j + 6, k + 23, Blocks.wool, 7, 2);
		world.setBlock(i + 0, j + 6, k + 24, deepslate_wall, 0, 2);
		world.setBlock(i + 3, j + 6, k + 24, deepslate_bricks, 4, 2);
		world.setBlock(i + 10, j + 6, k + 24, deepslate_tile_stairs, 0, 2);
		world.setBlock(i + 12, j + 6, k + 24, Blocks.wool, 7, 2);
		world.setBlock(i + 14, j + 6, k + 24, deepslate_bricks, 0, 2);
		world.setBlock(i + 21, j + 6, k + 24, deepslate_bricks, 2, 2);
		world.setBlock(i + 24, j + 6, k + 24, deepslate_bricks, 2, 2);
		world.setBlock(i + 25, j + 6, k + 24, deepslate_bricks, 2, 2);
		world.setBlock(i + 26, j + 6, k + 24, deepslate_bricks, 2, 2);
		world.setBlock(i + 27, j + 6, k + 24, deepslate_bricks, 1, 2);
		world.setBlock(i + 28, j + 6, k + 24, deepslate_bricks, 0, 2);
		world.setBlock(i + 29, j + 6, k + 24, deepslate_bricks, 0, 2);
		world.setBlock(i + 30, j + 6, k + 24, deepslate_bricks, 0, 2);
		world.setBlock(i + 31, j + 6, k + 24, deepslate_bricks, 0, 2);
		world.setBlock(i + 32, j + 6, k + 24, polished_deepslate_stairs, 0, 2);
		world.setBlock(i + 33, j + 6, k + 24, Blocks.wool, 7, 2);
		world.setBlock(i + 34, j + 6, k + 24, polished_deepslate_stairs, 1, 2);
		world.setBlock(i + 35, j + 6, k + 24, Blocks.wool, 7, 2);
		world.setBlock(i + 45, j + 6, k + 24, deepslate_bricks, 4, 2);
		world.setBlock(i + 0, j + 6, k + 25, deepslate_bricks, 4, 2);
		world.setBlock(i + 3, j + 6, k + 25, deepslate_tile_stairs, 0, 2);
		world.setBlock(i + 10, j + 6, k + 25, Blocks.wool, 7, 2);
		world.setBlock(i + 12, j + 6, k + 25, Blocks.wool, 7, 2);
		world.setBlock(i + 14, j + 6, k + 25, deepslate_bricks, 0, 2);
		world.setBlock(i + 21, j + 6, k + 25, deepslate_bricks, 2, 2);
		world.setBlock(i + 24, j + 6, k + 25, deepslate_bricks, 2, 2);
		world.setBlock(i + 25, j + 6, k + 25, deepslate_bricks, 3, 2);
		world.setBlock(i + 26, j + 6, k + 25, deepslate_bricks, 3, 2);
		world.setBlock(i + 27, j + 6, k + 25, deepslate_bricks, 0, 2);
		world.setBlock(i + 28, j + 6, k + 25, deepslate_bricks, 1, 2);
		world.setBlock(i + 29, j + 6, k + 25, deepslate_bricks, 1, 2);
		world.setBlock(i + 30, j + 6, k + 25, deepslate_bricks, 0, 2);
		world.setBlock(i + 31, j + 6, k + 25, deepslate_bricks, 0, 2);
		world.setBlock(i + 32, j + 6, k + 25, polished_deepslate_stairs, 3, 2);
		world.setBlock(i + 33, j + 6, k + 25, Blocks.wool, 7, 2);
		world.setBlock(i + 34, j + 6, k + 25, polished_deepslate_stairs, 1, 2);
		world.setBlock(i + 45, j + 6, k + 25, deepslate_bricks, 4, 2);
		world.setBlock(i + 0, j + 6, k + 26, deepslate_bricks, 4, 2);
		
		
		
		
		
		
		
		
		
		
		
		
		
		
		
		
		
		
		
		
		
		
		
		
		
		
		
		
		
		
		
		
		
		
		
		
		
		
		
		
		
		
		
		
		
		
		
		
		
		
		
		
		world.setBlock(i + 10, j + 6, k + 26, Blocks.wool, 7, 2);
		world.setBlock(i + 12, j + 6, k + 26, Blocks.wool, 7, 2);
		world.setBlock(i + 14, j + 6, k + 26, deepslate_bricks, 0, 2);
		world.setBlock(i + 21, j + 6, k + 26, deepslate_bricks, 3, 2);
		world.setBlock(i + 24, j + 6, k + 26, deepslate_bricks, 3, 2);
		world.setBlock(i + 25, j + 6, k + 26, deepslate_bricks, 2, 2);
		world.setBlock(i + 26, j + 6, k + 26, deepslate_bricks, 3, 2);
		world.setBlock(i + 27, j + 6, k + 26, deepslate_bricks, 0, 2);
		world.setBlock(i + 28, j + 6, k + 26, deepslate_bricks, 0, 2);
		world.setBlock(i + 29, j + 6, k + 26, deepslate_bricks, 0, 2);
		world.setBlock(i + 30, j + 6, k + 26, deepslate_bricks, 0, 2);
		world.setBlock(i + 31, j + 6, k + 26, deepslate_bricks, 0, 2);
		world.setBlock(i + 34, j + 6, k + 26, polished_deepslate, 0, 2);
		world.setBlock(i + 45, j + 6, k + 26, deepslate_wall, 0, 2);
		world.setBlock(i + 0, j + 6, k + 27, deepslate_wall, 0, 2);
		world.setBlock(i + 10, j + 6, k + 27, deepslate_tile_stairs, 0, 2);
		world.setBlock(i + 12, j + 6, k + 27, Blocks.wool, 7, 2);
		world.setBlock(i + 14, j + 6, k + 27, deepslate_bricks, 0, 2);
		world.setBlock(i + 21, j + 6, k + 27, deepslate_bricks, 2, 2);
		world.setBlock(i + 30, j + 6, k + 27, deepslate_bricks, 2, 2);
		world.setBlock(i + 31, j + 6, k + 27, deepslate_bricks, 0, 2);
		world.setBlock(i + 33, j + 6, k + 27, Blocks.wool, 7, 2);
		world.setBlock(i + 45, j + 6, k + 27, deepslate_bricks, 4, 2);
		world.setBlock(i + 0, j + 6, k + 28, deepslate_bricks, 4, 2);
		world.setBlock(i + 3, j + 6, k + 28, deepslate_tile_stairs, 0, 2);
		world.setBlock(i + 10, j + 6, k + 28, deepslate_tile_stairs, 0, 2);
		world.setBlock(i + 12, j + 6, k + 28, Blocks.wool, 7, 2);
		world.setBlock(i + 14, j + 6, k + 28, deepslate_bricks, 1, 2);
		world.setBlock(i + 21, j + 6, k + 28, deepslate_bricks, 2, 2);
		world.setBlock(i + 30, j + 6, k + 28, deepslate_bricks, 3, 2);
		world.setBlock(i + 31, j + 6, k + 28, deepslate_bricks, 1, 2);
		world.setBlock(i + 45, j + 6, k + 28, deepslate_bricks, 4, 2);
		world.setBlock(i + 0, j + 6, k + 29, deepslate_bricks, 4, 2);
		world.setBlock(i + 3, j + 6, k + 29, deepslate_bricks, 4, 2);
		world.setBlock(i + 10, j + 6, k + 29, deepslate_tile_stairs, 0, 2);
		world.setBlock(i + 12, j + 6, k + 29, Blocks.wool, 7, 2);
		world.setBlock(i + 14, j + 6, k + 29, deepslate_bricks, 0, 2);
		world.setBlock(i + 21, j + 6, k + 29, deepslate_bricks, 2, 2);
		world.setBlock(i + 26, j + 6, k + 29, deepslate_bricks, 2, 2);
		world.setBlock(i + 27, j + 6, k + 29, deepslate_bricks, 2, 2);
		world.setBlock(i + 28, j + 6, k + 29, deepslate_bricks, 2, 2);
		world.setBlock(i + 29, j + 6, k + 29, deepslate_bricks, 3, 2);
		world.setBlock(i + 30, j + 6, k + 29, deepslate_bricks, 2, 2);
		world.setBlock(i + 31, j + 6, k + 29, deepslate_bricks, 0, 2);
		world.setBlock(i + 32, j + 6, k + 29, polished_deepslate_stairs, 2, 2);
		world.setBlock(i + 33, j + 6, k + 29, Blocks.wool, 7, 2);
		world.setBlock(i + 42, j + 6, k + 29, deepslate_tile_stairs, 1, 2);
		world.setBlock(i + 45, j + 6, k + 29, deepslate_wall, 0, 2);
		world.setBlock(i + 0, j + 6, k + 30, deepslate_bricks, 4, 2);
		world.setBlock(i + 3, j + 6, k + 30, deepslate_bricks, 4, 2);
		world.setBlock(i + 10, j + 6, k + 30, Blocks.wool, 7, 2);
		world.setBlock(i + 12, j + 6, k + 30, Blocks.wool, 7, 2);
		world.setBlock(i + 14, j + 6, k + 30, deepslate_bricks, 0, 2);
		world.setBlock(i + 21, j + 6, k + 30, deepslate_bricks, 2, 2);
		world.setBlock(i + 26, j + 6, k + 30, deepslate_bricks, 2, 2);
		world.setBlock(i + 30, j + 6, k + 30, deepslate_bricks, 3, 2);
		world.setBlock(i + 31, j + 6, k + 30, deepslate_bricks, 0, 2);
		world.setBlock(i + 32, j + 6, k + 30, polished_deepslate_stairs, 0, 2);
		world.setBlock(i + 33, j + 6, k + 30, Blocks.wool, 7, 2);
		world.setBlock(i + 42, j + 6, k + 30, deepslate_bricks, 4, 2);
		world.setBlock(i + 45, j + 6, k + 30, deepslate_bricks, 4, 2);
		world.setBlock(i + 0, j + 6, k + 31, deepslate_bricks, 4, 2);
		world.setBlock(i + 3, j + 6, k + 31, deepslate_tile_stairs, 0, 2);
		world.setBlock(i + 10, j + 6, k + 31, Blocks.wool, 7, 2);
		world.setBlock(i + 12, j + 6, k + 31, Blocks.wool, 7, 2);
		world.setBlock(i + 14, j + 6, k + 31, deepslate_bricks, 0, 2);
		world.setBlock(i + 21, j + 6, k + 31, deepslate_bricks, 3, 2);
		world.setBlock(i + 26, j + 6, k + 31, deepslate_bricks, 2, 2);
		world.setBlock(i + 30, j + 6, k + 31, deepslate_bricks, 2, 2);
		world.setBlock(i + 31, j + 6, k + 31, deepslate_bricks, 0, 2);
		world.setBlock(i + 32, j + 6, k + 31, polished_deepslate_stairs, 3, 2);
		world.setBlock(i + 33, j + 6, k + 31, Blocks.wool, 7, 2);
		world.setBlock(i + 42, j + 6, k + 31, deepslate_bricks, 4, 2);
		world.setBlock(i + 45, j + 6, k + 31, deepslate_bricks, 4, 2);
		world.setBlock(i + 0, j + 6, k + 32, deepslate_wall, 0, 2);
		world.setBlock(i + 10, j + 6, k + 32, deepslate_tile_stairs, 0, 2);
		world.setBlock(i + 12, j + 6, k + 32, Blocks.wool, 7, 2);
		world.setBlock(i + 14, j + 6, k + 32, deepslate_bricks, 1, 2);
		world.setBlock(i + 15, j + 6, k + 32, deepslate_bricks, 3, 2);
		world.setBlock(i + 16, j + 6, k + 32, deepslate_bricks, 3, 2);
		world.setBlock(i + 17, j + 6, k + 32, deepslate_bricks, 3, 2);
		world.setBlock(i + 18, j + 6, k + 32, deepslate_bricks, 3, 2);
		world.setBlock(i + 19, j + 6, k + 32, deepslate_bricks, 2, 2);
		world.setBlock(i + 20, j + 6, k + 32, deepslate_bricks, 3, 2);
		world.setBlock(i + 21, j + 6, k + 32, deepslate_bricks, 2, 2);
		world.setBlock(i + 22, j + 6, k + 32, deepslate_wall, 0, 2);
		world.setBlock(i + 24, j + 6, k + 32, deepslate_bricks, 2, 2);
		world.setBlock(i + 25, j + 6, k + 32, deepslate_bricks, 2, 2);
		world.setBlock(i + 26, j + 6, k + 32, deepslate_bricks, 2, 2);
		world.setBlock(i + 27, j + 6, k + 32, Blocks.redstone_wire, 0, 2);
		world.setBlock(i + 30, j + 6, k + 32, deepslate_bricks, 3, 2);
		world.setBlock(i + 31, j + 6, k + 32, deepslate_bricks, 1, 2);
		world.setBlock(i + 42, j + 6, k + 32, deepslate_tile_stairs, 1, 2);
		world.setBlock(i + 0, j + 6, k + 33, deepslate_bricks, 4, 2);
		world.setBlock(i + 10, j + 6, k + 33, deepslate_tile_stairs, 0, 2);
		world.setBlock(i + 12, j + 6, k + 33, Blocks.wool, 7, 2);
		world.setBlock(i + 14, j + 6, k + 33, deepslate_bricks, 0, 2);
		world.setBlock(i + 21, j + 6, k + 33, deepslate_wall, 0, 2);
		world.setBlock(i + 27, j + 6, k + 33, Blocks.redstone_wire, 0, 2);
		world.setBlock(i + 30, j + 6, k + 33, deepslate_bricks, 3, 2);
		world.setBlock(i + 31, j + 6, k + 33, deepslate_bricks, 0, 2);
		world.setBlock(i + 33, j + 6, k + 33, Blocks.wool, 7, 2);
		world.setBlock(i + 35, j + 6, k + 33, fence_dark_oak, 0, 2);
		world.setBlock(i + 41, j + 6, k + 33, fence_dark_oak, 0, 2);
		world.setBlock(i + 0, j + 6, k + 34, deepslate_bricks, 4, 2);
		world.setBlock(i + 1, j + 6, k + 34, Blocks.wool, 7, 2);
		world.setBlock(i + 2, j + 6, k + 34, Blocks.wool, 7, 2);
		world.setBlock(i + 3, j + 6, k + 34, deepslate_tile_stairs, 2, 2);
		world.setBlock(i + 10, j + 6, k + 34, deepslate_tile_stairs, 0, 2);
		world.setBlock(i + 12, j + 6, k + 34, Blocks.wool, 7, 2);
		world.setBlock(i + 14, j + 6, k + 34, deepslate_bricks, 1, 2);
		world.setBlock(i + 27, j + 6, k + 34, Blocks.redstone_wire, 0, 2);
		world.setBlock(i + 30, j + 6, k + 34, deepslate_bricks, 2, 2);
		world.setBlock(i + 31, j + 6, k + 34, deepslate_bricks, 0, 2);
		world.setBlock(i + 33, j + 6, k + 34, Blocks.wool, 7, 2);
		world.setBlock(i + 0, j + 6, k + 35, deepslate_wall, 0, 2);
		world.setBlock(i + 1, j + 6, k + 35, Blocks.wool, 7, 2);
		world.setBlock(i + 2, j + 6, k + 35, Blocks.wool, 7, 2);
		world.setBlock(i + 3, j + 6, k + 35, deepslate_bricks, 4, 2);
		world.setBlock(i + 10, j + 6, k + 35, Blocks.wool, 7, 2);
		world.setBlock(i + 12, j + 6, k + 35, Blocks.wool, 7, 2);
		world.setBlock(i + 14, j + 6, k + 35, deepslate_bricks, 0, 2);
		world.setBlock(i + 27, j + 6, k + 35, Blocks.redstone_wire, 0, 2);
		world.setBlock(i + 30, j + 6, k + 35, deepslate_bricks, 2, 2);
		world.setBlock(i + 31, j + 6, k + 35, deepslate_bricks, 0, 2);
		world.setBlock(i + 33, j + 6, k + 35, Blocks.wool, 7, 2);
		world.setBlock(i + 35, j + 6, k + 35, fence_dark_oak, 0, 2);
		world.setBlock(i + 38, j + 6, k + 35, fence_dark_oak, 0, 2);
		world.setBlock(i + 41, j + 6, k + 35, fence_dark_oak, 0, 2);
		world.setBlock(i + 0, j + 6, k + 36, deepslate_bricks, 4, 2);
		world.setBlock(i + 1, j + 6, k + 36, Blocks.wool, 7, 2);
		world.setBlock(i + 2, j + 6, k + 36, Blocks.wool, 7, 2);
		world.setBlock(i + 3, j + 6, k + 36, deepslate_bricks, 4, 2);
		world.setBlock(i + 10, j + 6, k + 36, Blocks.wool, 7, 2);
		world.setBlock(i + 12, j + 6, k + 36, Blocks.wool, 7, 2);
		world.setBlock(i + 14, j + 6, k + 36, deepslate_bricks, 0, 2);
		world.setBlock(i + 15, j + 6, k + 36, deepslate_bricks, 2, 2);
		world.setBlock(i + 16, j + 6, k + 36, deepslate_bricks, 2, 2);
		world.setBlock(i + 17, j + 6, k + 36, deepslate_bricks, 3, 2);
		world.setBlock(i + 18, j + 6, k + 36, deepslate_bricks, 2, 2);
		world.setBlock(i + 20, j + 6, k + 36, deepslate_wall, 0, 2);
		world.setBlock(i + 21, j + 6, k + 36, deepslate_bricks, 3, 2);
		world.setBlock(i + 22, j + 6, k + 36, deepslate_bricks, 2, 2);
		world.setBlock(i + 23, j + 6, k + 36, deepslate_bricks, 2, 2);
		world.setBlock(i + 24, j + 6, k + 36, deepslate_bricks, 3, 2);
		world.setBlock(i + 25, j + 6, k + 36, deepslate_bricks, 2, 2);
		world.setBlock(i + 26, j + 6, k + 36, deepslate_bricks, 3, 2);
		world.setBlock(i + 27, j + 6, k + 36, Blocks.redstone_wire, 0, 2);
		world.setBlock(i + 30, j + 6, k + 36, deepslate_bricks, 2, 2);
		world.setBlock(i + 31, j + 6, k + 36, deepslate_bricks, 0, 2);
		world.setBlock(i + 42, j + 6, k + 36, deepslate_tile_stairs, 1, 2);
		world.setBlock(i + 0, j + 6, k + 37, deepslate_bricks, 4, 2);
		world.setBlock(i + 3, j + 6, k + 37, deepslate_tile_stairs, 3, 2);
		world.setBlock(i + 10, j + 6, k + 37, deepslate_tile_stairs, 0, 2);
		world.setBlock(i + 12, j + 6, k + 37, Blocks.wool, 7, 2);
		world.setBlock(i + 14, j + 6, k + 37, deepslate_bricks, 0, 2);
		world.setBlock(i + 18, j + 6, k + 37, deepslate_bricks, 3, 2);
		world.setBlock(i + 21, j + 6, k + 37, Blocks.glass_pane, 0, 2);
		world.setBlock(i + 22, j + 6, k + 37, deepslate_bricks, 3, 2);
		world.setBlock(i + 25, j + 6, k + 37, Blocks.wool, 7, 2);
		world.setBlock(i + 26, j + 6, k + 37, deepslate_bricks, 3, 2);
		world.setBlock(i + 30, j + 6, k + 37, deepslate_bricks, 2, 2);
		world.setBlock(i + 31, j + 6, k + 37, deepslate_bricks, 1, 2);
		world.setBlock(i + 32, j + 6, k + 37, polished_deepslate_stairs, 2, 2);
		world.setBlock(i + 33, j + 6, k + 37, Blocks.wool, 7, 2);
		world.setBlock(i + 34, j + 6, k + 37, polished_deepslate, 0, 2);
		world.setBlock(i + 35, j + 6, k + 37, polished_deepslate, 0, 2);
		world.setBlock(i + 42, j + 6, k + 37, deepslate_bricks, 4, 2);
		world.setBlock(i + 45, j + 6, k + 37, deepslate_bricks, 4, 2);
		world.setBlock(i + 0, j + 6, k + 38, deepslate_bricks, 4, 2);
		world.setBlock(i + 10, j + 6, k + 38, deepslate_tile_stairs, 0, 2);
		world.setBlock(i + 12, j + 6, k + 38, Blocks.wool, 7, 2);
		world.setBlock(i + 14, j + 6, k + 38, deepslate_bricks, 0, 2);
		world.setBlock(i + 18, j + 6, k + 38, deepslate_bricks, 2, 2);
		world.setBlock(i + 21, j + 6, k + 38, Blocks.glass_pane, 0, 2);
		world.setBlock(i + 23, j + 6, k + 38, Blocks.wool, 7, 2);
		world.setBlock(i + 25, j + 6, k + 38, Blocks.wool, 7, 2);
		world.setBlock(i + 26, j + 6, k + 38, deepslate_bricks, 2, 2);
		world.setBlock(i + 30, j + 6, k + 38, deepslate_bricks, 2, 2);
		world.setBlock(i + 31, j + 6, k + 38, deepslate_bricks, 1, 2);
		world.setBlock(i + 32, j + 6, k + 38, polished_deepslate_stairs, 0, 2);
		world.setBlock(i + 33, j + 6, k + 38, Blocks.wool, 7, 2);
		world.setBlock(i + 34, j + 6, k + 38, polished_deepslate, 0, 2);
		world.setBlock(i + 35, j + 6, k + 38, Blocks.redstone_lamp, 0, 2);
		world.setBlock(i + 42, j + 6, k + 38, deepslate_bricks, 4, 2);
		world.setBlock(i + 45, j + 6, k + 38, deepslate_bricks, 4, 2);
		world.setBlock(i + 0, j + 6, k + 39, deepslate_bricks, 4, 2);
		world.setBlock(i + 10, j + 6, k + 39, deepslate_tile_stairs, 0, 2);
		world.setBlock(i + 12, j + 6, k + 39, Blocks.wool, 7, 2);
		world.setBlock(i + 14, j + 6, k + 39, deepslate_bricks, 1, 2);
		world.setBlock(i + 18, j + 6, k + 39, deepslate_bricks, 3, 2);
		world.setBlock(i + 21, j + 6, k + 39, Blocks.glass_pane, 0, 2);
		world.setBlock(i + 24, j + 6, k + 39, Blocks.wool, 7, 2);
		world.setBlock(i + 26, j + 6, k + 39, deepslate_bricks, 2, 2);
		world.setBlock(i + 27, j + 6, k + 39, deepslate_bricks, 2, 2);
		world.setBlock(i + 28, j + 6, k + 39, deepslate_bricks, 3, 2);
		world.setBlock(i + 29, j + 6, k + 39, deepslate_bricks, 3, 2);
		world.setBlock(i + 30, j + 6, k + 39, deepslate_bricks, 2, 2);
		world.setBlock(i + 31, j + 6, k + 39, deepslate_bricks, 1, 2);
		world.setBlock(i + 32, j + 6, k + 39, polished_deepslate_stairs, 3, 2);
		world.setBlock(i + 34, j + 6, k + 39, polished_deepslate_stairs, 3, 2);
		world.setBlock(i + 35, j + 6, k + 39, polished_deepslate, 0, 2);
		world.setBlock(i + 42, j + 6, k + 39, deepslate_tile_stairs, 1, 2);
		world.setBlock(i + 45, j + 6, k + 39, deepslate_wall, 0, 2);
		world.setBlock(i + 0, j + 6, k + 40, deepslate_wall, 0, 2);
		world.setBlock(i + 3, j + 6, k + 40, deepslate_tile_stairs, 2, 2);
		world.setBlock(i + 10, j + 6, k + 40, Blocks.wool, 7, 2);
		world.setBlock(i + 12, j + 6, k + 40, Blocks.wool, 7, 2);
		world.setBlock(i + 14, j + 6, k + 40, deepslate_bricks, 0, 2);
		world.setBlock(i + 18, j + 6, k + 40, deepslate_bricks, 2, 2);
		world.setBlock(i + 21, j + 6, k + 40, Blocks.glass_pane, 0, 2);
		world.setBlock(i + 22, j + 6, k + 40, deepslate_bricks, 2, 2);
		world.setBlock(i + 23, j + 6, k + 40, deepslate_bricks, 2, 2);
		world.setBlock(i + 24, j + 6, k + 40, deepslate_bricks, 2, 2);
		world.setBlock(i + 25, j + 6, k + 40, deepslate_bricks, 3, 2);
		world.setBlock(i + 26, j + 6, k + 40, deepslate_bricks, 3, 2);
		world.setBlock(i + 27, j + 6, k + 40, deepslate_bricks, 2, 2);
		world.setBlock(i + 28, j + 6, k + 40, deepslate_bricks, 2, 2);
		world.setBlock(i + 29, j + 6, k + 40, deepslate_bricks, 2, 2);
		world.setBlock(i + 30, j + 6, k + 40, deepslate_bricks, 3, 2);
		world.setBlock(i + 31, j + 6, k + 40, deepslate_bricks, 0, 2);
		world.setBlock(i + 45, j + 6, k + 40, deepslate_bricks, 4, 2);
		world.setBlock(i + 0, j + 6, k + 41, deepslate_bricks, 4, 2);
		world.setBlock(i + 3, j + 6, k + 41, deepslate_bricks, 4, 2);
		world.setBlock(i + 10, j + 6, k + 41, Blocks.wool, 7, 2);
		world.setBlock(i + 12, j + 6, k + 41, Blocks.wool, 7, 2);
		world.setBlock(i + 14, j + 6, k + 41, deepslate_bricks, 0, 2);
		world.setBlock(i + 18, j + 6, k + 41, deepslate_bricks, 2, 2);
		world.setBlock(i + 21, j + 6, k + 41, Blocks.glass_pane, 0, 2);
		world.setBlock(i + 22, j + 6, k + 41, deepslate_bricks, 3, 2);
		world.setBlock(i + 23, j + 6, k + 41, deepslate_bricks, 3, 2);
		world.setBlock(i + 24, j + 6, k + 41, deepslate_bricks, 2, 2);
		world.setBlock(i + 25, j + 6, k + 41, deepslate_bricks, 3, 2);
		world.setBlock(i + 26, j + 6, k + 41, deepslate_bricks, 3, 2);
		world.setBlock(i + 27, j + 6, k + 41, deepslate_bricks, 2, 2);
		world.setBlock(i + 28, j + 6, k + 41, deepslate_bricks, 2, 2);
		world.setBlock(i + 29, j + 6, k + 41, deepslate_bricks, 2, 2);
		world.setBlock(i + 30, j + 6, k + 41, deepslate_bricks, 3, 2);
		world.setBlock(i + 31, j + 6, k + 41, deepslate_bricks, 0, 2);
		world.setBlock(i + 33, j + 6, k + 41, Blocks.wool, 7, 2);
		world.setBlock(i + 45, j + 6, k + 41, deepslate_bricks, 4, 2);
		world.setBlock(i + 0, j + 6, k + 42, deepslate_bricks, 4, 2);
		world.setBlock(i + 3, j + 6, k + 42, deepslate_bricks, 4, 2);
		world.setBlock(i + 10, j + 6, k + 42, deepslate_tile_stairs, 0, 2);
		world.setBlock(i + 12, j + 6, k + 42, Blocks.wool, 7, 2);
		world.setBlock(i + 14, j + 6, k + 42, deepslate_bricks, 1, 2);
		world.setBlock(i + 18, j + 6, k + 42, deepslate_bricks, 2, 2);
		world.setBlock(i + 21, j + 6, k + 42, Blocks.glass_pane, 0, 2);
		world.setBlock(i + 22, j + 6, k + 42, deepslate_bricks, 3, 2);
		world.setBlock(i + 23, j + 6, k + 42, deepslate_bricks, 2, 2);
		world.setBlock(i + 24, j + 6, k + 42, deepslate_bricks, 2, 2);
		world.setBlock(i + 25, j + 6, k + 42, deepslate_bricks, 2, 2);
		world.setBlock(i + 26, j + 6, k + 42, deepslate_bricks, 2, 2);
		world.setBlock(i + 27, j + 6, k + 42, deepslate_bricks, 0, 2);
		world.setBlock(i + 28, j + 6, k + 42, deepslate_bricks, 0, 2);
		world.setBlock(i + 29, j + 6, k + 42, deepslate_bricks, 0, 2);
		world.setBlock(i + 30, j + 6, k + 42, deepslate_bricks, 0, 2);
		world.setBlock(i + 31, j + 6, k + 42, deepslate_bricks, 1, 2);
		world.setBlock(i + 45, j + 6, k + 42, deepslate_wall, 0, 2);
		world.setBlock(i + 0, j + 6, k + 43, deepslate_wall, 0, 2);
		world.setBlock(i + 3, j + 6, k + 43, deepslate_tile_stairs, 3, 2);
		world.setBlock(i + 10, j + 6, k + 43, deepslate_tile_stairs, 0, 2);
		world.setBlock(i + 12, j + 6, k + 43, Blocks.wool, 7, 2);
		world.setBlock(i + 14, j + 6, k + 43, deepslate_bricks, 0, 2);
		world.setBlock(i + 18, j + 6, k + 43, deepslate_bricks, 2, 2);
		world.setBlock(i + 21, j + 6, k + 43, Blocks.glass_pane, 0, 2);
		world.setBlock(i + 22, j + 6, k + 43, deepslate_bricks, 3, 2);
		world.setBlock(i + 23, j + 6, k + 43, deepslate_bricks, 2, 2);
		world.setBlock(i + 24, j + 6, k + 43, deepslate_bricks, 2, 2);
		world.setBlock(i + 25, j + 6, k + 43, deepslate_bricks, 2, 2);
		world.setBlock(i + 26, j + 6, k + 43, deepslate_bricks, 3, 2);
		world.setBlock(i + 27, j + 6, k + 43, deepslate_bricks, 1, 2);
		world.setBlock(i + 28, j + 6, k + 43, deepslate_bricks, 0, 2);
		world.setBlock(i + 29, j + 6, k + 43, deepslate_bricks, 0, 2);
		world.setBlock(i + 30, j + 6, k + 43, deepslate_bricks, 1, 2);
		world.setBlock(i + 31, j + 6, k + 43, deepslate_bricks, 1, 2);
		world.setBlock(i + 32, j + 6, k + 43, polished_deepslate_stairs, 2, 2);
		world.setBlock(i + 33, j + 6, k + 43, Blocks.wool, 7, 2);
		world.setBlock(i + 34, j + 6, k + 43, polished_deepslate, 0, 2);
		world.setBlock(i + 45, j + 6, k + 43, deepslate_bricks, 4, 2);
		world.setBlock(i + 0, j + 6, k + 44, deepslate_bricks, 4, 2);
		world.setBlock(i + 10, j + 6, k + 44, deepslate_tile_stairs, 0, 2);
		world.setBlock(i + 12, j + 6, k + 44, Blocks.wool, 7, 2);
		world.setBlock(i + 14, j + 6, k + 44, deepslate_bricks, 0, 2);
		world.setBlock(i + 18, j + 6, k + 44, deepslate_bricks, 2, 2);
		world.setBlock(i + 21, j + 6, k + 44, Blocks.glass_pane, 0, 2);
		world.setBlock(i + 22, j + 6, k + 44, deepslate_tile_stairs, 7, 2);
		world.setBlock(i + 23, j + 6, k + 44, deepslate_tile_stairs, 7, 2);
		world.setBlock(i + 24, j + 6, k + 44, deepslate_tile_stairs, 7, 2);
		world.setBlock(i + 25, j + 6, k + 44, deepslate_tile_stairs, 7, 2);
		world.setBlock(i + 26, j + 6, k + 44, deepslate_tile_stairs, 7, 2);
		world.setBlock(i + 27, j + 6, k + 44, deepslate_bricks, 0, 2);
		world.setBlock(i + 28, j + 6, k + 44, deepslate_bricks, 0, 2);
		world.setBlock(i + 29, j + 6, k + 44, deepslate_bricks, 0, 2);
		world.setBlock(i + 30, j + 6, k + 44, deepslate_bricks, 0, 2);
		world.setBlock(i + 31, j + 6, k + 44, deepslate_bricks, 0, 2);
		world.setBlock(i + 32, j + 6, k + 44, polished_deepslate_stairs, 0, 2);
		world.setBlock(i + 33, j + 6, k + 44, Blocks.wool, 7, 2);
		world.setBlock(i + 42, j + 6, k + 44, deepslate_bricks, 4, 2);
		world.setBlock(i + 45, j + 6, k + 44, deepslate_bricks, 4, 2);
		world.setBlock(i + 0, j + 6, k + 45, deepslate_bricks, 4, 2);
		world.setBlock(i + 10, j + 6, k + 45, Blocks.wool, 7, 2);
		world.setBlock(i + 12, j + 6, k + 45, Blocks.wool, 7, 2);
		world.setBlock(i + 14, j + 6, k + 45, deepslate_bricks, 0, 2);
		world.setBlock(i + 18, j + 6, k + 45, deepslate_bricks, 2, 2);
		world.setBlock(i + 21, j + 6, k + 45, Blocks.glass_pane, 0, 2);
		world.setBlock(i + 27, j + 6, k + 45, deepslate_bricks, 0, 2);
		world.setBlock(i + 28, j + 6, k + 45, deepslate_bricks, 0, 2);
		world.setBlock(i + 29, j + 6, k + 45, deepslate_bricks, 1, 2);
		world.setBlock(i + 30, j + 6, k + 45, deepslate_bricks, 0, 2);
		world.setBlock(i + 31, j + 6, k + 45, deepslate_bricks, 0, 2);
		world.setBlock(i + 32, j + 6, k + 45, polished_deepslate_stairs, 3, 2);
		world.setBlock(i + 42, j + 6, k + 45, deepslate_bricks, 4, 2);
		world.setBlock(i + 45, j + 6, k + 45, deepslate_wall, 0, 2);
		world.setBlock(i + 0, j + 6, k + 46, deepslate_bricks, 4, 2);
		world.setBlock(i + 3, j + 6, k + 46, deepslate_tile_stairs, 2, 2);
		world.setBlock(i + 10, j + 6, k + 46, Blocks.wool, 7, 2);
		world.setBlock(i + 12, j + 6, k + 46, Blocks.wool, 7, 2);
		world.setBlock(i + 14, j + 6, k + 46, deepslate_bricks, 1, 2);
		world.setBlock(i + 18, j + 6, k + 46, deepslate_bricks, 2, 2);
		world.setBlock(i + 21, j + 6, k + 46, Blocks.glass_pane, 0, 2);
		world.setBlock(i + 27, j + 6, k + 46, deepslate_bricks, 1, 2);
		world.setBlock(i + 28, j + 6, k + 46, deepslate_bricks, 1, 2);
		world.setBlock(i + 29, j + 6, k + 46, deepslate_bricks, 0, 2);
		world.setBlock(i + 30, j + 6, k + 46, deepslate_bricks, 0, 2);
		world.setBlock(i + 31, j + 6, k + 46, deepslate_bricks, 0, 2);
		world.setBlock(i + 42, j + 6, k + 46, deepslate_tile_stairs, 1, 2);
		world.setBlock(i + 45, j + 6, k + 46, deepslate_bricks, 4, 2);
		world.setBlock(i + 0, j + 6, k + 47, deepslate_bricks, 4, 2);
		world.setBlock(i + 3, j + 6, k + 47, deepslate_bricks, 4, 2);
		world.setBlock(i + 10, j + 6, k + 47, deepslate_tile_stairs, 0, 2);
		world.setBlock(i + 12, j + 6, k + 47, Blocks.wool, 7, 2);
		world.setBlock(i + 14, j + 6, k + 47, deepslate_bricks, 0, 2);
		world.setBlock(i + 18, j + 6, k + 47, deepslate_bricks, 2, 2);
		world.setBlock(i + 20, j + 6, k + 47, deepslate_wall, 0, 2);
		world.setBlock(i + 21, j + 6, k + 47, deepslate_bricks, 2, 2);
		world.setBlock(i + 27, j + 6, k + 47, deepslate_bricks, 0, 2);
		world.setBlock(i + 28, j + 6, k + 47, deepslate_bricks, 0, 2);
		world.setBlock(i + 29, j + 6, k + 47, deepslate_bricks, 0, 2);
		world.setBlock(i + 30, j + 6, k + 47, deepslate_bricks, 0, 2);
		world.setBlock(i + 31, j + 6, k + 47, deepslate_bricks, 0, 2);
		world.setBlock(i + 33, j + 6, k + 47, Blocks.wool, 7, 2);
		world.setBlock(i + 42, j + 6, k + 47, deepslate_bricks, 4, 2);
		world.setBlock(i + 45, j + 6, k + 47, deepslate_bricks, 4, 2);
		world.setBlock(i + 0, j + 6, k + 48, deepslate_wall, 0, 2);
		world.setBlock(i + 3, j + 6, k + 48, deepslate_bricks, 4, 2);
		world.setBlock(i + 10, j + 6, k + 48, deepslate_tile_stairs, 0, 2);
		world.setBlock(i + 12, j + 6, k + 48, Blocks.wool, 7, 2);
		world.setBlock(i + 14, j + 6, k + 48, deepslate_bricks, 0, 2);
		world.setBlock(i + 18, j + 6, k + 48, Blocks.glass_pane, 0, 2);
		world.setBlock(i + 21, j + 6, k + 48, Blocks.glass_pane, 0, 2);
		world.setBlock(i + 27, j + 6, k + 48, deepslate_bricks, 0, 2);
		world.setBlock(i + 28, j + 6, k + 48, deepslate_bricks, 0, 2);
		world.setBlock(i + 29, j + 6, k + 48, deepslate_bricks, 0, 2);
		world.setBlock(i + 30, j + 6, k + 48, deepslate_bricks, 0, 2);
		world.setBlock(i + 31, j + 6, k + 48, deepslate_bricks, 0, 2);
		world.setBlock(i + 33, j + 6, k + 48, Blocks.wool, 7, 2);
		world.setBlock(i + 35, j + 6, k + 48, deepslate_tile_stairs, 1, 2);
		world.setBlock(i + 42, j + 6, k + 48, deepslate_bricks, 4, 2);
		world.setBlock(i + 45, j + 6, k + 48, deepslate_wall, 0, 2);
		world.setBlock(i + 0, j + 6, k + 49, deepslate_bricks, 4, 2);
		world.setBlock(i + 3, j + 6, k + 49, deepslate_tile_stairs, 3, 2);
		world.setBlock(i + 10, j + 6, k + 49, deepslate_tile_stairs, 0, 2);
		world.setBlock(i + 12, j + 6, k + 49, Blocks.wool, 7, 2);
		world.setBlock(i + 14, j + 6, k + 49, deepslate_bricks, 0, 2);
		world.setBlock(i + 18, j + 6, k + 49, Blocks.glass_pane, 0, 2);
		world.setBlock(i + 21, j + 6, k + 49, Blocks.glass_pane, 0, 2);
		world.setBlock(i + 27, j + 6, k + 49, deepslate_bricks, 0, 2);
		world.setBlock(i + 28, j + 6, k + 49, deepslate_brick_slab, 0, 2);
		world.setBlock(i + 29, j + 6, k + 49, deepslate_brick_slab, 0, 2);
		world.setBlock(i + 30, j + 6, k + 49, deepslate_brick_slab, 0, 2);
		world.setBlock(i + 31, j + 6, k + 49, deepslate_brick_slab, 0, 2);
		world.setBlock(i + 33, j + 6, k + 49, Blocks.wool, 7, 2);
		world.setBlock(i + 35, j + 6, k + 49, deepslate_tile_stairs, 1, 2);
		world.setBlock(i + 42, j + 6, k + 49, deepslate_tile_stairs, 1, 2);
		world.setBlock(i + 45, j + 6, k + 49, deepslate_bricks, 4, 2);
		world.setBlock(i + 0, j + 6, k + 50, deepslate_bricks, 4, 2);
		world.setBlock(i + 10, j + 6, k + 50, Blocks.wool, 7, 2);
		world.setBlock(i + 12, j + 6, k + 50, Blocks.wool, 7, 2);
		world.setBlock(i + 14, j + 6, k + 50, deepslate_bricks, 0, 2);
		world.setBlock(i + 18, j + 6, k + 50, Blocks.glass_pane, 0, 2);
		world.setBlock(i + 21, j + 6, k + 50, deepslate_bricks, 2, 2);
		world.setBlock(i + 27, j + 6, k + 50, deepslate_bricks, 0, 2);
		world.setBlock(i + 33, j + 6, k + 50, Blocks.wool, 7, 2);
		world.setBlock(i + 35, j + 6, k + 50, Blocks.wool, 7, 2);
		world.setBlock(i + 42, j + 6, k + 50, deepslate_bricks, 4, 2);
		world.setBlock(i + 45, j + 6, k + 50, deepslate_bricks, 4, 2);
		world.setBlock(i + 0, j + 6, k + 51, deepslate_wall, 0, 2);
		world.setBlock(i + 10, j + 6, k + 51, Blocks.wool, 7, 2);
		world.setBlock(i + 12, j + 6, k + 51, Blocks.wool, 7, 2);
		world.setBlock(i + 14, j + 6, k + 51, deepslate_bricks, 0, 2);
		world.setBlock(i + 18, j + 6, k + 51, Blocks.glass_pane, 0, 2);
		world.setBlock(i + 27, j + 6, k + 51, deepslate_bricks, 0, 2);
		world.setBlock(i + 33, j + 6, k + 51, Blocks.wool, 7, 2);
		world.setBlock(i + 35, j + 6, k + 51, Blocks.wool, 7, 2);
		world.setBlock(i + 42, j + 6, k + 51, deepslate_bricks, 4, 2);
		world.setBlock(i + 45, j + 6, k + 51, deepslate_wall, 0, 2);
		world.setBlock(i + 0, j + 6, k + 52, deepslate_bricks, 4, 2);
		world.setBlock(i + 3, j + 6, k + 52, deepslate_tile_stairs, 2, 2);
		world.setBlock(i + 10, j + 6, k + 52, deepslate_tile_stairs, 0, 2);
		world.setBlock(i + 12, j + 6, k + 52, Blocks.wool, 7, 2);
		world.setBlock(i + 14, j + 6, k + 52, deepslate_bricks, 0, 2);
		world.setBlock(i + 18, j + 6, k + 52, Blocks.glass_pane, 0, 2);
		world.setBlock(i + 27, j + 6, k + 52, deepslate_bricks, 0, 2);
		world.setBlock(i + 33, j + 6, k + 52, Blocks.wool, 7, 2);
		world.setBlock(i + 35, j + 6, k + 52, Blocks.wool, 7, 2);
		world.setBlock(i + 42, j + 6, k + 52, deepslate_tile_stairs, 1, 2);
		world.setBlock(i + 45, j + 6, k + 52, deepslate_bricks, 4, 2);
		world.setBlock(i + 0, j + 6, k + 53, deepslate_bricks, 4, 2);
		world.setBlock(i + 3, j + 6, k + 53, deepslate_bricks, 4, 2);
		world.setBlock(i + 10, j + 6, k + 53, deepslate_tile_stairs, 0, 2);
		world.setBlock(i + 14, j + 6, k + 53, deepslate_bricks, 0, 2);
		world.setBlock(i + 18, j + 6, k + 53, Blocks.glass_pane, 0, 2);
		world.setBlock(i + 21, j + 6, k + 53, deepslate_bricks, 2, 2);
		world.setBlock(i + 27, j + 6, k + 53, deepslate_bricks, 0, 2);
		world.setBlock(i + 33, j + 6, k + 53, Blocks.wool, 7, 2);
		world.setBlock(i + 35, j + 6, k + 53, Blocks.wool, 7, 2);
		world.setBlock(i + 42, j + 6, k + 53, deepslate_bricks, 4, 2);
		world.setBlock(i + 45, j + 6, k + 53, deepslate_bricks, 4, 2);
		world.setBlock(i + 0, j + 6, k + 54, deepslate_bricks, 4, 2);
		world.setBlock(i + 3, j + 6, k + 54, deepslate_bricks, 4, 2);
		world.setBlock(i + 10, j + 6, k + 54, deepslate_tile_stairs, 0, 2);
		world.setBlock(i + 12, j + 6, k + 54, Blocks.wool, 7, 2);
		world.setBlock(i + 14, j + 6, k + 54, deepslate_bricks, 1, 2);
		world.setBlock(i + 15, j + 6, k + 54, deepslate_bricks, 0, 2);
		world.setBlock(i + 16, j + 6, k + 54, deepslate_bricks, 1, 2);
		world.setBlock(i + 17, j + 6, k + 54, deepslate_bricks, 0, 2);
		world.setBlock(i + 18, j + 6, k + 54, deepslate_bricks, 0, 2);
		world.setBlock(i + 19, j + 6, k + 54, deepslate_bricks, 0, 2);
		world.setBlock(i + 20, j + 6, k + 54, deepslate_bricks, 0, 2);
		world.setBlock(i + 21, j + 6, k + 54, deepslate_bricks, 0, 2);
		world.setBlock(i + 22, j + 6, k + 54, deepslate_bricks, 1, 2);
		world.setBlock(i + 23, j + 6, k + 54, deepslate_bricks, 0, 2);
		world.setBlock(i + 24, j + 6, k + 54, deepslate_bricks, 0, 2);
		world.setBlock(i + 25, j + 6, k + 54, deepslate_bricks, 0, 2);
		world.setBlock(i + 26, j + 6, k + 54, deepslate_bricks, 1, 2);
		world.setBlock(i + 27, j + 6, k + 54, deepslate_bricks, 1, 2);
		world.setBlock(i + 33, j + 6, k + 54, Blocks.wool, 7, 2);
		world.setBlock(i + 35, j + 6, k + 54, deepslate_tile_stairs, 1, 2);
		world.setBlock(i + 42, j + 6, k + 54, deepslate_bricks, 4, 2);
		world.setBlock(i + 45, j + 6, k + 54, deepslate_wall, 0, 2);
		world.setBlock(i + 0, j + 6, k + 55, deepslate_bricks, 4, 2);
		world.setBlock(i + 3, j + 6, k + 55, deepslate_tile_stairs, 3, 2);
		world.setBlock(i + 10, j + 6, k + 55, deepslate_tile_stairs, 0, 2);
		world.setBlock(i + 12, j + 6, k + 55, Blocks.wool, 7, 2);
		world.setBlock(i + 33, j + 6, k + 55, Blocks.wool, 7, 2);
		world.setBlock(i + 35, j + 6, k + 55, deepslate_tile_stairs, 1, 2);
		world.setBlock(i + 42, j + 6, k + 55, deepslate_tile_stairs, 1, 2);
		world.setBlock(i + 45, j + 6, k + 55, deepslate_bricks, 4, 2);
		world.setBlock(i + 0, j + 6, k + 56, deepslate_bricks, 4, 2);
		world.setBlock(i + 3, j + 6, k + 56, deepslate_bricks, 4, 2);
		world.setBlock(i + 10, j + 6, k + 56, deepslate_tile_stairs, 0, 2);
		world.setBlock(i + 13, j + 6, k + 56, Blocks.wool, 7, 2);
		world.setBlock(i + 14, j + 6, k + 56, Blocks.wool, 7, 2);
		world.setBlock(i + 15, j + 6, k + 56, Blocks.wool, 7, 2);
		world.setBlock(i + 16, j + 6, k + 56, Blocks.wool, 7, 2);
		world.setBlock(i + 17, j + 6, k + 56, Blocks.wool, 7, 2);
		world.setBlock(i + 18, j + 6, k + 56, Blocks.wool, 7, 2);
		world.setBlock(i + 20, j + 6, k + 56, Blocks.wool, 7, 2);
		world.setBlock(i + 21, j + 6, k + 56, Blocks.wool, 7, 2);
		world.setBlock(i + 22, j + 6, k + 56, Blocks.wool, 7, 2);
		world.setBlock(i + 23, j + 6, k + 56, Blocks.wool, 7, 2);
		world.setBlock(i + 24, j + 6, k + 56, Blocks.wool, 7, 2);
		world.setBlock(i + 25, j + 6, k + 56, Blocks.wool, 7, 2);
		world.setBlock(i + 26, j + 6, k + 56, Blocks.wool, 7, 2);
		world.setBlock(i + 27, j + 6, k + 56, Blocks.wool, 7, 2);
		world.setBlock(i + 28, j + 6, k + 56, Blocks.wool, 7, 2);
		world.setBlock(i + 29, j + 6, k + 56, Blocks.wool, 7, 2);
		world.setBlock(i + 30, j + 6, k + 56, Blocks.wool, 7, 2);
		world.setBlock(i + 31, j + 6, k + 56, Blocks.wool, 7, 2);
		world.setBlock(i + 32, j + 6, k + 56, Blocks.wool, 7, 2);
		world.setBlock(i + 33, j + 6, k + 56, Blocks.wool, 7, 2);
		world.setBlock(i + 35, j + 6, k + 56, deepslate_tile_stairs, 1, 2);
		world.setBlock(i + 42, j + 6, k + 56, deepslate_bricks, 4, 2);
		world.setBlock(i + 45, j + 6, k + 56, deepslate_bricks, 4, 2);
		world.setBlock(i + 0, j + 6, k + 57, deepslate_wall, 0, 2);
		world.setBlock(i + 3, j + 6, k + 57, deepslate_bricks, 4, 2);
		world.setBlock(i + 10, j + 6, k + 57, Blocks.wool, 7, 2);
		world.setBlock(i + 35, j + 6, k + 57, Blocks.wool, 7, 2);
		world.setBlock(i + 42, j + 6, k + 57, deepslate_bricks, 4, 2);
		world.setBlock(i + 45, j + 6, k + 57, deepslate_wall, 0, 2);
		world.setBlock(i + 0, j + 6, k + 58, deepslate_bricks, 4, 2);
		world.setBlock(i + 3, j + 6, k + 58, deepslate_tile_stairs, 3, 2);
		world.setBlock(i + 10, j + 6, k + 58, Blocks.wool, 7, 2);
		world.setBlock(i + 11, j + 6, k + 58, Blocks.wool, 7, 2);
		world.setBlock(i + 12, j + 6, k + 58, deepslate_tile_stairs, 3, 2);
		world.setBlock(i + 13, j + 6, k + 58, deepslate_tile_stairs, 3, 2);
		world.setBlock(i + 14, j + 6, k + 58, deepslate_tile_stairs, 3, 2);
		world.setBlock(i + 15, j + 6, k + 58, Blocks.wool, 7, 2);
		world.setBlock(i + 16, j + 6, k + 58, Blocks.wool, 7, 2);
		world.setBlock(i + 17, j + 6, k + 58, Blocks.wool, 7, 2);
		world.setBlock(i + 18, j + 6, k + 58, Blocks.wool, 7, 2);
		world.setBlock(i + 19, j + 6, k + 58, deepslate_tile_stairs, 3, 2);
		world.setBlock(i + 20, j + 6, k + 58, deepslate_tile_stairs, 3, 2);
		world.setBlock(i + 21, j + 6, k + 58, deepslate_tile_stairs, 3, 2);
		world.setBlock(i + 22, j + 6, k + 58, Blocks.wool, 7, 2);
		world.setBlock(i + 23, j + 6, k + 58, Blocks.wool, 7, 2);
		world.setBlock(i + 24, j + 6, k + 58, deepslate_tile_stairs, 3, 2);
		world.setBlock(i + 25, j + 6, k + 58, deepslate_tile_stairs, 3, 2);
		world.setBlock(i + 26, j + 6, k + 58, deepslate_tile_stairs, 3, 2);
		world.setBlock(i + 27, j + 6, k + 58, Blocks.wool, 7, 2);
		world.setBlock(i + 28, j + 6, k + 58, Blocks.wool, 7, 2);
		world.setBlock(i + 29, j + 6, k + 58, Blocks.wool, 7, 2);
		world.setBlock(i + 30, j + 6, k + 58, Blocks.wool, 7, 2);
		world.setBlock(i + 31, j + 6, k + 58, deepslate_tile_stairs, 3, 2);
		world.setBlock(i + 32, j + 6, k + 58, deepslate_tile_stairs, 3, 2);
		world.setBlock(i + 33, j + 6, k + 58, deepslate_tile_stairs, 3, 2);
		world.setBlock(i + 34, j + 6, k + 58, Blocks.wool, 7, 2);
		world.setBlock(i + 35, j + 6, k + 58, Blocks.wool, 7, 2);
		world.setBlock(i + 42, j + 6, k + 58, deepslate_tile_stairs, 2, 2);
		world.setBlock(i + 45, j + 6, k + 58, deepslate_bricks, 4, 2);
		world.setBlock(i + 0, j + 6, k + 59, deepslate_bricks, 4, 2);
		world.setBlock(i + 3, j + 6, k + 59, deepslate_bricks, 4, 2);
		world.setBlock(i + 42, j + 6, k + 59, deepslate_bricks, 4, 2);
		world.setBlock(i + 45, j + 6, k + 59, deepslate_bricks, 4, 2);
		world.setBlock(i + 0, j + 6, k + 60, deepslate_wall, 0, 2);
		world.setBlock(i + 3, j + 6, k + 60, deepslate_bricks, 4, 2);
		world.setBlock(i + 42, j + 6, k + 60, deepslate_bricks, 4, 2);
		world.setBlock(i + 45, j + 6, k + 60, deepslate_wall, 0, 2);
		world.setBlock(i + 0, j + 6, k + 61, deepslate_bricks, 4, 2);
		world.setBlock(i + 3, j + 6, k + 61, deepslate_tile_stairs, 2, 2);
		world.setBlock(i + 42, j + 6, k + 61, deepslate_tile_stairs, 1, 2);
		world.setBlock(i + 45, j + 6, k + 61, deepslate_bricks, 4, 2);
		world.setBlock(i + 0, j + 6, k + 62, deepslate_bricks, 4, 2);
		world.setBlock(i + 2, j + 6, k + 62, deepslate_tile_stairs, 4, 2);
		world.setBlock(i + 3, j + 6, k + 62, deepslate_bricks, 4, 2);
		world.setBlock(i + 42, j + 6, k + 62, deepslate_bricks, 4, 2);
		world.setBlock(i + 45, j + 6, k + 62, deepslate_bricks, 4, 2);
		world.setBlock(i + 0, j + 6, k + 63, deepslate_wall, 0, 2);
		world.setBlock(i + 3, j + 6, k + 63, deepslate_bricks, 4, 2);
		world.setBlock(i + 42, j + 6, k + 63, deepslate_bricks, 4, 2);
		world.setBlock(i + 45, j + 6, k + 63, deepslate_wall, 0, 2);
		world.setBlock(i + 0, j + 6, k + 64, deepslate_bricks, 4, 2);
		world.setBlock(i + 3, j + 6, k + 64, deepslate_tile_stairs, 3, 2);
		world.setBlock(i + 42, j + 6, k + 64, deepslate_tile_stairs, 1, 2);
		world.setBlock(i + 45, j + 6, k + 64, deepslate_bricks, 4, 2);
		world.setBlock(i + 0, j + 6, k + 65, deepslate_bricks, 4, 2);
		world.setBlock(i + 3, j + 6, k + 65, deepslate_bricks, 4, 2);
		world.setBlock(i + 4, j + 6, k + 65, deepslate_tile_stairs, 0, 2);
		world.setBlock(i + 5, j + 6, k + 65, deepslate_bricks, 4, 2);
		world.setBlock(i + 6, j + 6, k + 65, deepslate_bricks, 4, 2);
		world.setBlock(i + 7, j + 6, k + 65, deepslate_tile_stairs, 1, 2);
		world.setBlock(i + 8, j + 6, k + 65, deepslate_bricks, 4, 2);
		world.setBlock(i + 9, j + 6, k + 65, deepslate_bricks, 4, 2);
		world.setBlock(i + 10, j + 6, k + 65, deepslate_tile_stairs, 0, 2);
		world.setBlock(i + 11, j + 6, k + 65, deepslate_bricks, 4, 2);
		world.setBlock(i + 12, j + 6, k + 65, deepslate_bricks, 4, 2);
		world.setBlock(i + 13, j + 6, k + 65, deepslate_tile_stairs, 0, 2);
		world.setBlock(i + 14, j + 6, k + 65, deepslate_bricks, 4, 2);
		world.setBlock(i + 15, j + 6, k + 65, deepslate_bricks, 4, 2);
		world.setBlock(i + 16, j + 6, k + 65, deepslate_tile_stairs, 1, 2);
		world.setBlock(i + 21, j + 6, k + 65, deepslate_bricks, 4, 2);
		world.setBlock(i + 22, j + 6, k + 65, deepslate_bricks, 4, 2);
		world.setBlock(i + 23, j + 6, k + 65, deepslate_tile_stairs, 3, 2);
		world.setBlock(i + 24, j + 6, k + 65, deepslate_bricks, 4, 2);
		world.setBlock(i + 25, j + 6, k + 65, deepslate_bricks, 4, 2);
		world.setBlock(i + 26, j + 6, k + 65, deepslate_tile_stairs, 3, 2);
		world.setBlock(i + 27, j + 6, k + 65, deepslate_bricks, 4, 2);
		world.setBlock(i + 28, j + 6, k + 65, deepslate_bricks, 4, 2);
		world.setBlock(i + 29, j + 6, k + 65, deepslate_tile_stairs, 3, 2);
		world.setBlock(i + 30, j + 6, k + 65, deepslate_bricks, 4, 2);
		world.setBlock(i + 31, j + 6, k + 65, deepslate_bricks, 4, 2);
		world.setBlock(i + 32, j + 6, k + 65, deepslate_tile_stairs, 3, 2);
		world.setBlock(i + 33, j + 6, k + 65, deepslate_bricks, 4, 2);
		world.setBlock(i + 34, j + 6, k + 65, deepslate_bricks, 4, 2);
		world.setBlock(i + 35, j + 6, k + 65, deepslate_tile_stairs, 3, 2);
		world.setBlock(i + 36, j + 6, k + 65, deepslate_bricks, 4, 2);
		world.setBlock(i + 37, j + 6, k + 65, deepslate_bricks, 4, 2);
		world.setBlock(i + 38, j + 6, k + 65, deepslate_tile_stairs, 3, 2);
		world.setBlock(i + 39, j + 6, k + 65, deepslate_bricks, 4, 2);
		world.setBlock(i + 40, j + 6, k + 65, deepslate_bricks, 4, 2);
		world.setBlock(i + 41, j + 6, k + 65, deepslate_tile_stairs, 3, 2);
		world.setBlock(i + 42, j + 6, k + 65, deepslate_bricks, 4, 2);
		world.setBlock(i + 45, j + 6, k + 65, deepslate_bricks, 4, 2);
		world.setBlock(i + 0, j + 6, k + 66, deepslate_wall, 0, 2);
		world.setBlock(i + 21, j + 6, k + 66, Blocks.wool, 7, 2);
		world.setBlock(i + 22, j + 6, k + 66, Blocks.wool, 7, 2);
		world.setBlock(i + 23, j + 6, k + 66, Blocks.wool, 7, 2);
		world.setBlock(i + 45, j + 6, k + 66, deepslate_wall, 0, 2);
		world.setBlock(i + 0, j + 6, k + 67, deepslate_bricks, 4, 2);
		world.setBlock(i + 1, j + 6, k + 67, deepslate_tile_stairs, 3, 2);
		world.setBlock(i + 21, j + 6, k + 67, Blocks.wool, 7, 2);
		world.setBlock(i + 22, j + 6, k + 67, Blocks.wool, 7, 2);
		world.setBlock(i + 23, j + 6, k + 67, Blocks.wool, 7, 2);
		world.setBlock(i + 45, j + 6, k + 67, deepslate_bricks, 4, 2);
		world.setBlock(i + 0, j + 6, k + 68, deepslate_bricks, 4, 2);
		world.setBlock(i + 1, j + 6, k + 68, deepslate_bricks, 4, 2);
		world.setBlock(i + 2, j + 6, k + 68, deepslate_wall, 0, 2);
		world.setBlock(i + 3, j + 6, k + 68, deepslate_bricks, 4, 2);
		world.setBlock(i + 4, j + 6, k + 68, deepslate_bricks, 4, 2);
		world.setBlock(i + 5, j + 6, k + 68, deepslate_wall, 0, 2);
		world.setBlock(i + 6, j + 6, k + 68, deepslate_bricks, 4, 2);
		world.setBlock(i + 7, j + 6, k + 68, deepslate_bricks, 4, 2);
		world.setBlock(i + 8, j + 6, k + 68, deepslate_wall, 0, 2);
		world.setBlock(i + 9, j + 6, k + 68, deepslate_bricks, 4, 2);
		world.setBlock(i + 10, j + 6, k + 68, deepslate_bricks, 4, 2);
		world.setBlock(i + 11, j + 6, k + 68, deepslate_wall, 0, 2);
		world.setBlock(i + 12, j + 6, k + 68, deepslate_bricks, 4, 2);
		world.setBlock(i + 13, j + 6, k + 68, deepslate_bricks, 4, 2);
		world.setBlock(i + 14, j + 6, k + 68, deepslate_bricks, 4, 2);
		world.setBlock(i + 15, j + 6, k + 68, deepslate_bricks, 4, 2);
		world.setBlock(i + 16, j + 6, k + 68, deepslate_wall, 0, 2);
		world.setBlock(i + 17, j + 6, k + 68, deepslate_bricks, 4, 2);
		world.setBlock(i + 18, j + 6, k + 68, deepslate_bricks, 4, 2);
		world.setBlock(i + 19, j + 6, k + 68, deepslate_wall, 0, 2);
		world.setBlock(i + 20, j + 6, k + 68, deepslate_bricks, 4, 2);
		world.setBlock(i + 21, j + 6, k + 68, deepslate_bricks, 4, 2);
		world.setBlock(i + 23, j + 6, k + 68, deepslate_bricks, 4, 2);
		world.setBlock(i + 24, j + 6, k + 68, deepslate_bricks, 4, 2);
		world.setBlock(i + 25, j + 6, k + 68, deepslate_wall, 0, 2);
		world.setBlock(i + 26, j + 6, k + 68, deepslate_bricks, 4, 2);
		world.setBlock(i + 27, j + 6, k + 68, deepslate_bricks, 4, 2);
		world.setBlock(i + 29, j + 6, k + 68, deepslate_bricks, 4, 2);
		world.setBlock(i + 30, j + 6, k + 68, deepslate_bricks, 4, 2);
		world.setBlock(i + 31, j + 6, k + 68, deepslate_wall, 0, 2);
		world.setBlock(i + 32, j + 6, k + 68, deepslate_bricks, 4, 2);
		world.setBlock(i + 33, j + 6, k + 68, deepslate_bricks, 4, 2);
		world.setBlock(i + 34, j + 6, k + 68, deepslate_wall, 0, 2);
		world.setBlock(i + 35, j + 6, k + 68, deepslate_bricks, 4, 2);
		world.setBlock(i + 36, j + 6, k + 68, deepslate_bricks, 4, 2);
		world.setBlock(i + 37, j + 6, k + 68, deepslate_wall, 0, 2);
		world.setBlock(i + 38, j + 6, k + 68, deepslate_bricks, 4, 2);
		world.setBlock(i + 39, j + 6, k + 68, deepslate_bricks, 4, 2);
		world.setBlock(i + 40, j + 6, k + 68, deepslate_wall, 0, 2);
		world.setBlock(i + 41, j + 6, k + 68, deepslate_bricks, 4, 2);
		world.setBlock(i + 42, j + 6, k + 68, deepslate_bricks, 4, 2);
		world.setBlock(i + 43, j + 6, k + 68, deepslate_wall, 0, 2);
		world.setBlock(i + 44, j + 6, k + 68, deepslate_bricks, 4, 2);
		world.setBlock(i + 45, j + 6, k + 68, deepslate_bricks, 4, 2);
		world.setBlock(i + 0, j + 7, k + 0, deepslate_tile_stairs, 0, 2);
		world.setBlock(i + 1, j + 7, k + 0, deepslate_tile_stairs, 2, 2);
		world.setBlock(i + 6, j + 7, k + 0, deepslate_tile_stairs, 2, 2);
		world.setBlock(i + 7, j + 7, k + 0, deepslate_tile_stairs, 2, 2);
		world.setBlock(i + 9, j + 7, k + 0, deepslate_tile_stairs, 2, 2);
		world.setBlock(i + 10, j + 7, k + 0, deepslate_tile_stairs, 2, 2);
		world.setBlock(i + 12, j + 7, k + 0, deepslate_tile_stairs, 2, 2);
		world.setBlock(i + 13, j + 7, k + 0, deepslate_tile_stairs, 2, 2);
		world.setBlock(i + 14, j + 7, k + 0, deepslate_tile_stairs, 2, 2);
		world.setBlock(i + 15, j + 7, k + 0, deepslate_tile_stairs, 2, 2);
		world.setBlock(i + 17, j + 7, k + 0, deepslate_tile_stairs, 2, 2);
		world.setBlock(i + 18, j + 7, k + 0, deepslate_tile_stairs, 2, 2);
		world.setBlock(i + 20, j + 7, k + 0, deepslate_tile_stairs, 2, 2);
		world.setBlock(i + 21, j + 7, k + 0, deepslate_tile_stairs, 2, 2);
		world.setBlock(i + 23, j + 7, k + 0, deepslate_tile_stairs, 2, 2);
		world.setBlock(i + 24, j + 7, k + 0, deepslate_tile_stairs, 2, 2);
		world.setBlock(i + 26, j + 7, k + 0, deepslate_tile_stairs, 2, 2);
		world.setBlock(i + 27, j + 7, k + 0, deepslate_tile_stairs, 2, 2);
		world.setBlock(i + 29, j + 7, k + 0, deepslate_tile_stairs, 2, 2);
		world.setBlock(i + 30, j + 7, k + 0, deepslate_tile_stairs, 2, 2);
		world.setBlock(i + 32, j + 7, k + 0, deepslate_tile_stairs, 2, 2);
		world.setBlock(i + 33, j + 7, k + 0, deepslate_tile_stairs, 2, 2);
		world.setBlock(i + 35, j + 7, k + 0, deepslate_tile_stairs, 2, 2);
		world.setBlock(i + 36, j + 7, k + 0, deepslate_tile_stairs, 2, 2);
		world.setBlock(i + 41, j + 7, k + 0, deepslate_tile_stairs, 2, 2);
		world.setBlock(i + 42, j + 7, k + 0, deepslate_tile_stairs, 2, 2);
		world.setBlock(i + 44, j + 7, k + 0, deepslate_tile_stairs, 2, 2);
		world.setBlock(i + 45, j + 7, k + 0, cobbled_deepslate, 0, 2);
		world.setBlock(i + 0, j + 7, k + 1, deepslate_tile_stairs, 0, 2);
		world.setBlock(i + 45, j + 7, k + 1, deepslate_tile_stairs, 1, 2);
		world.setBlock(i + 0, j + 7, k + 3, deepslate_tile_stairs, 0, 2);
		world.setBlock(i + 6, j + 7, k + 3, deepslate_tile_stairs, 1, 2);
		world.setBlock(i + 8, j + 7, k + 3, deepslate_tile_stairs, 0, 2);
		world.setBlock(i + 9, j + 7, k + 3, deepslate_tile_stairs, 1, 2);
		world.setBlock(i + 11, j + 7, k + 3, deepslate_tile_stairs, 0, 2);
		world.setBlock(i + 12, j + 7, k + 3, deepslate_tile_stairs, 1, 2);
		world.setBlock(i + 14, j + 7, k + 3, deepslate_tile_stairs, 0, 2);
		world.setBlock(i + 15, j + 7, k + 3, deepslate_tile_stairs, 1, 2);
		world.setBlock(i + 21, j + 7, k + 3, deepslate_tile_stairs, 0, 2);
		world.setBlock(i + 22, j + 7, k + 3, deepslate_tile_stairs, 1, 2);
		world.setBlock(i + 24, j + 7, k + 3, deepslate_tile_stairs, 0, 2);
		world.setBlock(i + 25, j + 7, k + 3, deepslate_tile_stairs, 1, 2);
		world.setBlock(i + 27, j + 7, k + 3, deepslate_tile_stairs, 0, 2);
		world.setBlock(i + 28, j + 7, k + 3, deepslate_tile_stairs, 1, 2);
		world.setBlock(i + 30, j + 7, k + 3, deepslate_tile_stairs, 0, 2);
		world.setBlock(i + 31, j + 7, k + 3, deepslate_tile_stairs, 1, 2);
		world.setBlock(i + 33, j + 7, k + 3, deepslate_tile_stairs, 0, 2);
		world.setBlock(i + 34, j + 7, k + 3, deepslate_tile_stairs, 1, 2);
		world.setBlock(i + 36, j + 7, k + 3, deepslate_tile_stairs, 1, 2);
		world.setBlock(i + 45, j + 7, k + 3, deepslate_tile_stairs, 1, 2);
		world.setBlock(i + 0, j + 7, k + 4, deepslate_tile_stairs, 0, 2);
		world.setBlock(i + 42, j + 7, k + 4, deepslate_tile_stairs, 2, 2);
		world.setBlock(i + 45, j + 7, k + 4, deepslate_tile_stairs, 1, 2);
		world.setBlock(i + 3, j + 7, k + 5, deepslate_tile_stairs, 2, 2);
		world.setBlock(i + 42, j + 7, k + 5, deepslate_tile_stairs, 2, 2);
		world.setBlock(i + 0, j + 7, k + 6, deepslate_tile_stairs, 0, 2);
		world.setBlock(i + 3, j + 7, k + 6, deepslate_tile_stairs, 3, 2);
		world.setBlock(i + 42, j + 7, k + 6, deepslate_tile_stairs, 3, 2);
		world.setBlock(i + 0, j + 7, k + 7, deepslate_tile_stairs, 0, 2);
		world.setBlock(i + 3, j + 7, k + 8, deepslate_tile_stairs, 3, 2);
		world.setBlock(i + 42, j + 7, k + 8, deepslate_tile_stairs, 2, 2);
		world.setBlock(i + 0, j + 7, k + 9, deepslate_tile_stairs, 0, 2);
		world.setBlock(i + 3, j + 7, k + 9, deepslate_tile_stairs, 3, 2);
		world.setBlock(i + 42, j + 7, k + 9, deepslate_tile_stairs, 3, 2);
		world.setBlock(i + 0, j + 7, k + 10, deepslate_tile_stairs, 0, 2);
		world.setBlock(i + 10, j + 7, k + 10, Blocks.wool, 7, 2);
		world.setBlock(i + 13, j + 7, k + 10, deepslate_tile_stairs, 2, 2);
		world.setBlock(i + 16, j + 7, k + 10, Blocks.wool, 7, 2);
		world.setBlock(i + 18, j + 7, k + 10, Blocks.wool, 7, 2);
		world.setBlock(i + 20, j + 7, k + 10, deepslate_tile_stairs, 2, 2);
		world.setBlock(i + 22, j + 7, k + 10, Blocks.wool, 7, 2);
		world.setBlock(i + 23, j + 7, k + 10, Blocks.wool, 7, 2);
		world.setBlock(i + 25, j + 7, k + 10, deepslate_tile_stairs, 2, 2);
		world.setBlock(i + 27, j + 7, k + 10, Blocks.wool, 7, 2);
		world.setBlock(i + 29, j + 7, k + 10, Blocks.wool, 7, 2);
		world.setBlock(i + 32, j + 7, k + 10, deepslate_tile_stairs, 2, 2);
		world.setBlock(i + 35, j + 7, k + 10, Blocks.wool, 7, 2);
		world.setBlock(i + 3, j + 7, k + 11, deepslate_tile_stairs, 2, 2);
		world.setBlock(i + 42, j + 7, k + 11, deepslate_tile_stairs, 2, 2);
		world.setBlock(i + 0, j + 7, k + 12, deepslate_tile_stairs, 0, 2);
		world.setBlock(i + 3, j + 7, k + 12, deepslate_tile_stairs, 3, 2);
		world.setBlock(i + 12, j + 7, k + 12, Blocks.wool, 7, 2);
		world.setBlock(i + 14, j + 7, k + 12, Blocks.wool, 7, 2);
		world.setBlock(i + 18, j + 7, k + 12, Blocks.wool, 7, 2);
		world.setBlock(i + 20, j + 7, k + 12, Blocks.wool, 7, 2);
		world.setBlock(i + 22, j + 7, k + 12, Blocks.wool, 7, 2);
		world.setBlock(i + 24, j + 7, k + 12, Blocks.wool, 7, 2);
		world.setBlock(i + 28, j + 7, k + 12, Blocks.wool, 7, 2);
		world.setBlock(i + 30, j + 7, k + 12, Blocks.wool, 7, 2);
		world.setBlock(i + 32, j + 7, k + 12, Blocks.wool, 7, 2);
		world.setBlock(i + 33, j + 7, k + 12, Blocks.wool, 7, 2);
		world.setBlock(i + 42, j + 7, k + 12, deepslate_tile_stairs, 3, 2);
		world.setBlock(i + 45, j + 7, k + 12, deepslate_tile_stairs, 1, 2);
		world.setBlock(i + 0, j + 7, k + 13, deepslate_tile_stairs, 0, 2);
		world.setBlock(i + 10, j + 7, k + 13, deepslate_tile_stairs, 0, 2);
		world.setBlock(i + 33, j + 7, k + 13, Blocks.wool, 7, 2);
		world.setBlock(i + 35, j + 7, k + 13, deepslate_tile_stairs, 1, 2);
		world.setBlock(i + 45, j + 7, k + 13, deepslate_tile_stairs, 1, 2);
		world.setBlock(i + 0, j + 7, k + 14, deepslate_tile_stairs, 0, 2);
		world.setBlock(i + 14, j + 7, k + 14, deepslate_bricks, 0, 2);
		world.setBlock(i + 15, j + 7, k + 14, deepslate_bricks, 1, 2);
		world.setBlock(i + 16, j + 7, k + 14, deepslate_bricks, 0, 2);
		world.setBlock(i + 17, j + 7, k + 14, deepslate_bricks, 0, 2);
		world.setBlock(i + 18, j + 7, k + 14, deepslate_bricks, 0, 2);
		world.setBlock(i + 19, j + 7, k + 14, deepslate_bricks, 0, 2);
		world.setBlock(i + 20, j + 7, k + 14, deepslate_bricks, 0, 2);
		world.setBlock(i + 21, j + 7, k + 14, deepslate_bricks, 0, 2);
		world.setBlock(i + 22, j + 7, k + 14, deepslate_bricks, 0, 2);
		world.setBlock(i + 23, j + 7, k + 14, deepslate_bricks, 0, 2);
		world.setBlock(i + 24, j + 7, k + 14, deepslate_bricks, 0, 2);
		world.setBlock(i + 25, j + 7, k + 14, deepslate_bricks, 0, 2);
		world.setBlock(i + 26, j + 7, k + 14, deepslate_bricks, 1, 2);
		world.setBlock(i + 27, j + 7, k + 14, deepslate_bricks, 1, 2);
		world.setBlock(i + 0, j + 7, k + 15, deepslate_tile_stairs, 0, 2);
		world.setBlock(i + 10, j + 7, k + 15, Blocks.wool, 7, 2);
		world.setBlock(i + 14, j + 7, k + 15, deepslate_bricks, 0, 2);
		world.setBlock(i + 15, j + 7, k + 15, deepslate_bricks, 1, 2);
		world.setBlock(i + 16, j + 7, k + 15, deepslate_bricks, 1, 2);
		world.setBlock(i + 17, j + 7, k + 15, deepslate_bricks, 1, 2);
		world.setBlock(i + 18, j + 7, k + 15, deepslate_bricks, 0, 2);
		world.setBlock(i + 19, j + 7, k + 15, deepslate_bricks, 1, 2);
		world.setBlock(i + 20, j + 7, k + 15, deepslate_bricks, 0, 2);
		world.setBlock(i + 21, j + 7, k + 15, deepslate_bricks, 0, 2);
		world.setBlock(i + 22, j + 7, k + 15, deepslate_bricks, 0, 2);
		world.setBlock(i + 23, j + 7, k + 15, deepslate_bricks, 0, 2);
		world.setBlock(i + 24, j + 7, k + 15, deepslate_bricks, 0, 2);
		world.setBlock(i + 25, j + 7, k + 15, deepslate_bricks, 0, 2);
		world.setBlock(i + 26, j + 7, k + 15, deepslate_bricks, 0, 2);
		world.setBlock(i + 27, j + 7, k + 15, deepslate_bricks, 0, 2);
		world.setBlock(i + 33, j + 7, k + 15, Blocks.wool, 7, 2);
		world.setBlock(i + 45, j + 7, k + 15, deepslate_tile_stairs, 1, 2);
		world.setBlock(i + 10, j + 7, k + 16, Blocks.wool, 7, 2);
		world.setBlock(i + 12, j + 7, k + 16, Blocks.wool, 7, 2);
		world.setBlock(i + 14, j + 7, k + 16, deepslate_bricks, 1, 2);
		world.setBlock(i + 15, j + 7, k + 16, deepslate_bricks, 1, 2);
		world.setBlock(i + 16, j + 7, k + 16, deepslate_bricks, 0, 2);
		world.setBlock(i + 17, j + 7, k + 16, deepslate_bricks, 1, 2);
		world.setBlock(i + 18, j + 7, k + 16, deepslate_bricks, 0, 2);
		world.setBlock(i + 19, j + 7, k + 16, deepslate_bricks, 0, 2);
		world.setBlock(i + 20, j + 7, k + 16, deepslate_bricks, 0, 2);
		world.setBlock(i + 21, j + 7, k + 16, deepslate_bricks, 0, 2);
		world.setBlock(i + 22, j + 7, k + 16, deepslate_bricks, 0, 2);
		world.setBlock(i + 23, j + 7, k + 16, deepslate_bricks, 1, 2);
		world.setBlock(i + 24, j + 7, k + 16, deepslate_bricks, 1, 2);
		world.setBlock(i + 25, j + 7, k + 16, deepslate_bricks, 1, 2);
		world.setBlock(i + 26, j + 7, k + 16, deepslate_bricks, 0, 2);
		world.setBlock(i + 27, j + 7, k + 16, deepslate_bricks, 0, 2);
		world.setBlock(i + 45, j + 7, k + 16, deepslate_tile_stairs, 1, 2);
		world.setBlock(i + 0, j + 7, k + 17, deepslate_tile_stairs, 0, 2);
		world.setBlock(i + 3, j + 7, k + 17, deepslate_tile_stairs, 2, 2);
		world.setBlock(i + 14, j + 7, k + 17, deepslate_bricks, 0, 2);
		world.setBlock(i + 15, j + 7, k + 17, deepslate_bricks, 0, 2);
		world.setBlock(i + 16, j + 7, k + 17, deepslate_bricks, 0, 2);
		world.setBlock(i + 17, j + 7, k + 17, deepslate_bricks, 1, 2);
		world.setBlock(i + 18, j + 7, k + 17, deepslate_bricks, 0, 2);
		world.setBlock(i + 19, j + 7, k + 17, deepslate_bricks, 0, 2);
		world.setBlock(i + 20, j + 7, k + 17, deepslate_bricks, 0, 2);
		world.setBlock(i + 21, j + 7, k + 17, deepslate_bricks, 0, 2);
		world.setBlock(i + 22, j + 7, k + 17, deepslate_bricks, 0, 2);
		world.setBlock(i + 23, j + 7, k + 17, deepslate_bricks, 1, 2);
		world.setBlock(i + 24, j + 7, k + 17, deepslate_bricks, 0, 2);
		world.setBlock(i + 25, j + 7, k + 17, deepslate_bricks, 1, 2);
		world.setBlock(i + 26, j + 7, k + 17, deepslate_bricks, 1, 2);
		world.setBlock(i + 27, j + 7, k + 17, deepslate_bricks, 1, 2);
		world.setBlock(i + 33, j + 7, k + 17, Blocks.wool, 7, 2);
		world.setBlock(i + 35, j + 7, k + 17, Blocks.wool, 7, 2);
		world.setBlock(i + 42, j + 7, k + 17, deepslate_tile_stairs, 2, 2);
		world.setBlock(i + 0, j + 7, k + 18, deepslate_tile_stairs, 0, 2);
		world.setBlock(i + 3, j + 7, k + 18, deepslate_tile_stairs, 3, 2);
		world.setBlock(i + 10, j + 7, k + 18, deepslate_tile_stairs, 0, 2);
		world.setBlock(i + 12, j + 7, k + 18, Blocks.wool, 7, 2);
		world.setBlock(i + 14, j + 7, k + 18, deepslate_bricks, 0, 2);
		world.setBlock(i + 15, j + 7, k + 18, deepslate_bricks, 1, 2);
		world.setBlock(i + 16, j + 7, k + 18, deepslate_bricks, 0, 2);
		world.setBlock(i + 17, j + 7, k + 18, deepslate_bricks, 0, 2);
		world.setBlock(i + 18, j + 7, k + 18, deepslate_bricks, 1, 2);
		world.setBlock(i + 19, j + 7, k + 18, deepslate_bricks, 0, 2);
		world.setBlock(i + 20, j + 7, k + 18, deepslate_bricks, 1, 2);
		world.setBlock(i + 21, j + 7, k + 18, deepslate_bricks, 0, 2);
		world.setBlock(i + 22, j + 7, k + 18, deepslate_bricks, 1, 2);
		world.setBlock(i + 23, j + 7, k + 18, deepslate_bricks, 0, 2);
		world.setBlock(i + 24, j + 7, k + 18, deepslate_bricks, 0, 2);
		world.setBlock(i + 25, j + 7, k + 18, deepslate_bricks, 0, 2);
		world.setBlock(i + 26, j + 7, k + 18, deepslate_bricks, 1, 2);
		world.setBlock(i + 27, j + 7, k + 18, deepslate_bricks, 1, 2);
		world.setBlock(i + 42, j + 7, k + 18, deepslate_tile_stairs, 3, 2);
		world.setBlock(i + 14, j + 7, k + 19, deepslate_bricks, 0, 2);
		world.setBlock(i + 15, j + 7, k + 19, deepslate_bricks, 0, 2);
		world.setBlock(i + 16, j + 7, k + 19, deepslate_bricks, 0, 2);
		world.setBlock(i + 17, j + 7, k + 19, deepslate_bricks, 1, 2);
		world.setBlock(i + 18, j + 7, k + 19, deepslate_bricks, 0, 2);
		world.setBlock(i + 19, j + 7, k + 19, deepslate_bricks, 0, 2);
		world.setBlock(i + 20, j + 7, k + 19, deepslate_bricks, 1, 2);
		world.setBlock(i + 21, j + 7, k + 19, deepslate_bricks, 0, 2);
		world.setBlock(i + 22, j + 7, k + 19, deepslate_bricks, 1, 2);
		world.setBlock(i + 23, j + 7, k + 19, deepslate_bricks, 0, 2);
		world.setBlock(i + 24, j + 7, k + 19, deepslate_bricks, 0, 2);
		world.setBlock(i + 25, j + 7, k + 19, deepslate_bricks, 0, 2);
		world.setBlock(i + 26, j + 7, k + 19, deepslate_bricks, 0, 2);
		world.setBlock(i + 27, j + 7, k + 19, deepslate_bricks, 0, 2);
		world.setBlock(i + 0, j + 7, k + 20, deepslate_tile_stairs, 0, 2);
		world.setBlock(i + 10, j + 7, k + 20, Blocks.wool, 7, 2);
		world.setBlock(i + 12, j + 7, k + 20, Blocks.wool, 7, 2);
		world.setBlock(i + 14, j + 7, k + 20, deepslate_bricks, 0, 2);
		world.setBlock(i + 15, j + 7, k + 20, deepslate_bricks, 0, 2);
		world.setBlock(i + 16, j + 7, k + 20, deepslate_bricks, 0, 2);
		world.setBlock(i + 17, j + 7, k + 20, deepslate_bricks, 0, 2);
		world.setBlock(i + 18, j + 7, k + 20, deepslate_bricks, 1, 2);
		world.setBlock(i + 19, j + 7, k + 20, deepslate_bricks, 0, 2);
		world.setBlock(i + 20, j + 7, k + 20, deepslate_bricks, 0, 2);
		world.setBlock(i + 21, j + 7, k + 20, deepslate_bricks, 1, 2);
		world.setBlock(i + 22, j + 7, k + 20, deepslate_bricks, 0, 2);
		world.setBlock(i + 23, j + 7, k + 20, deepslate_bricks, 1, 2);
		world.setBlock(i + 24, j + 7, k + 20, deepslate_bricks, 0, 2);
		world.setBlock(i + 25, j + 7, k + 20, deepslate_bricks, 0, 2);
		world.setBlock(i + 26, j + 7, k + 20, deepslate_bricks, 0, 2);
		world.setBlock(i + 27, j + 7, k + 20, deepslate_bricks, 0, 2);
		world.setBlock(i + 0, j + 7, k + 21, deepslate_tile_stairs, 0, 2);
		world.setBlock(i + 14, j + 7, k + 21, deepslate_bricks, 0, 2);
		world.setBlock(i + 15, j + 7, k + 21, deepslate_bricks, 0, 2);
		world.setBlock(i + 16, j + 7, k + 21, deepslate_bricks, 0, 2);
		world.setBlock(i + 17, j + 7, k + 21, deepslate_bricks, 0, 2);
		world.setBlock(i + 18, j + 7, k + 21, deepslate_bricks, 1, 2);
		world.setBlock(i + 19, j + 7, k + 21, deepslate_bricks, 0, 2);
		world.setBlock(i + 20, j + 7, k + 21, deepslate_bricks, 0, 2);
		world.setBlock(i + 21, j + 7, k + 21, deepslate_bricks, 1, 2);
		world.setBlock(i + 22, j + 7, k + 21, deepslate_bricks, 0, 2);
		world.setBlock(i + 23, j + 7, k + 21, deepslate_bricks, 1, 2);
		world.setBlock(i + 24, j + 7, k + 21, deepslate_bricks, 0, 2);
		world.setBlock(i + 25, j + 7, k + 21, deepslate_bricks, 0, 2);
		world.setBlock(i + 26, j + 7, k + 21, deepslate_bricks, 0, 2);
		world.setBlock(i + 27, j + 7, k + 21, deepslate_bricks, 1, 2);
		world.setBlock(i + 45, j + 7, k + 21, deepslate_tile_stairs, 1, 2);
		world.setBlock(i + 0, j + 7, k + 22, deepslate_tile_stairs, 0, 2);
		world.setBlock(i + 12, j + 7, k + 22, Blocks.wool, 7, 2);
		world.setBlock(i + 14, j + 7, k + 22, deepslate_bricks, 0, 2);
		world.setBlock(i + 15, j + 7, k + 22, deepslate_bricks, 0, 2);
		world.setBlock(i + 16, j + 7, k + 22, deepslate_bricks, 1, 2);
		world.setBlock(i + 17, j + 7, k + 22, deepslate_bricks, 0, 2);
		world.setBlock(i + 18, j + 7, k + 22, deepslate_bricks, 0, 2);
		world.setBlock(i + 19, j + 7, k + 22, deepslate_bricks, 1, 2);
		world.setBlock(i + 20, j + 7, k + 22, deepslate_bricks, 0, 2);
		world.setBlock(i + 21, j + 7, k + 22, deepslate_bricks, 1, 2);
		world.setBlock(i + 22, j + 7, k + 22, deepslate_bricks, 0, 2);
		world.setBlock(i + 23, j + 7, k + 22, deepslate_bricks, 1, 2);
		world.setBlock(i + 24, j + 7, k + 22, deepslate_bricks, 0, 2);
		world.setBlock(i + 25, j + 7, k + 22, deepslate_bricks, 0, 2);
		world.setBlock(i + 26, j + 7, k + 22, deepslate_bricks, 0, 2);
		world.setBlock(i + 27, j + 7, k + 22, deepslate_bricks, 0, 2);
		world.setBlock(i + 28, j + 7, k + 22, deepslate_brick_slab, 0, 2);
		world.setBlock(i + 29, j + 7, k + 22, deepslate_brick_slab, 0, 2);
		world.setBlock(i + 30, j + 7, k + 22, deepslate_brick_slab, 0, 2);
		world.setBlock(i + 31, j + 7, k + 22, deepslate_brick_slab, 0, 2);
		world.setBlock(i + 45, j + 7, k + 22, deepslate_tile_stairs, 1, 2);
		world.setBlock(i + 0, j + 7, k + 23, deepslate_tile_stairs, 0, 2);
		world.setBlock(i + 3, j + 7, k + 23, deepslate_tile_stairs, 2, 2);
		world.setBlock(i + 10, j + 7, k + 23, deepslate_tile_stairs, 0, 2);
		world.setBlock(i + 14, j + 7, k + 23, deepslate_bricks, 0, 2);
		world.setBlock(i + 15, j + 7, k + 23, deepslate_bricks, 1, 2);
		world.setBlock(i + 16, j + 7, k + 23, deepslate_bricks, 0, 2);
		world.setBlock(i + 17, j + 7, k + 23, deepslate_bricks, 0, 2);
		world.setBlock(i + 18, j + 7, k + 23, deepslate_bricks, 1, 2);
		world.setBlock(i + 19, j + 7, k + 23, deepslate_bricks, 1, 2);
		world.setBlock(i + 20, j + 7, k + 23, deepslate_bricks, 1, 2);
		world.setBlock(i + 21, j + 7, k + 23, deepslate_bricks, 1, 2);
		world.setBlock(i + 22, j + 7, k + 23, deepslate_bricks, 1, 2);
		world.setBlock(i + 23, j + 7, k + 23, deepslate_bricks, 1, 2);
		world.setBlock(i + 24, j + 7, k + 23, deepslate_bricks, 0, 2);
		world.setBlock(i + 25, j + 7, k + 23, deepslate_bricks, 1, 2);
		world.setBlock(i + 26, j + 7, k + 23, deepslate_bricks, 0, 2);
		world.setBlock(i + 27, j + 7, k + 23, deepslate_bricks, 0, 2);
		world.setBlock(i + 28, j + 7, k + 23, deepslate_bricks, 1, 2);
