package com.NovaCraft.world.end.endcamp;

import net.minecraft.world.gen.feature.*;
import net.minecraft.block.*;
import net.minecraft.world.*;
import java.util.*;

import com.NovaCraft.registry.OtherModBlocks;
import com.NovaCraftBlocks.NovaCraftBlocks;

import net.minecraft.init.*;

public class ChorusIslandGen extends WorldGenerator
{
	public ChorusIslandGen() {

	}
    
    public boolean generate(final World world, final Random random, final int i, final int j, final int k) {
    	
		world.setBlock(i + 12, j + 0, k + 5, Blocks.end_stone, 0, 2);
		world.setBlock(i + 7, j + 0, k + 8, Blocks.end_stone, 0, 2);
		world.setBlock(i + 9, j + 0, k + 11, Blocks.end_stone, 0, 2);
		world.setBlock(i + 8, j + 0, k + 12, Blocks.end_stone, 0, 2);
		world.setBlock(i + 12, j + 1, k + 5, Blocks.end_stone, 0, 2);
		world.setBlock(i + 7, j + 1, k + 8, Blocks.end_stone, 0, 2);
		world.setBlock(i + 8, j + 1, k + 8, Blocks.end_stone, 0, 2);
		world.setBlock(i + 12, j + 1, k + 9, Blocks.end_stone, 0, 2);
		world.setBlock(i + 11, j + 1, k + 10, Blocks.end_stone, 0, 2);
		world.setBlock(i + 15, j + 1, k + 10, Blocks.end_stone, 0, 2);
		world.setBlock(i + 3, j + 1, k + 11, Blocks.end_stone, 0, 2);
		world.setBlock(i + 9, j + 1, k + 11, Blocks.end_stone, 0, 2);
		world.setBlock(i + 8, j + 1, k + 12, Blocks.end_stone, 0, 2);
		world.setBlock(i + 11, j + 1, k + 13, Blocks.end_stone, 0, 2);
		world.setBlock(i + 13, j + 1, k + 13, Blocks.end_stone, 0, 2);
		world.setBlock(i + 9, j + 2, k + 3, Blocks.end_stone, 0, 2);
		world.setBlock(i + 9, j + 2, k + 4, Blocks.end_stone, 0, 2);
		world.setBlock(i + 11, j + 2, k + 4, Blocks.end_stone, 0, 2);
		world.setBlock(i + 9, j + 2, k + 5, Blocks.end_stone, 0, 2);
		world.setBlock(i + 11, j + 2, k + 5, Blocks.end_stone, 0, 2);
		world.setBlock(i + 12, j + 2, k + 5, Blocks.end_stone, 0, 2);
		world.setBlock(i + 7, j + 2, k + 6, Blocks.end_stone, 0, 2);
		world.setBlock(i + 8, j + 2, k + 6, Blocks.end_stone, 0, 2);
		world.setBlock(i + 10, j + 2, k + 6, Blocks.end_stone, 0, 2);
		world.setBlock(i + 13, j + 2, k + 7, Blocks.end_stone, 0, 2);
		world.setBlock(i + 5, j + 2, k + 8, Blocks.end_stone, 0, 2);
		world.setBlock(i + 8, j + 2, k + 8, Blocks.end_stone, 0, 2);
		world.setBlock(i + 10, j + 2, k + 8, Blocks.end_stone, 0, 2);
		world.setBlock(i + 14, j + 2, k + 8, Blocks.end_stone, 0, 2);
		world.setBlock(i + 4, j + 2, k + 9, Blocks.end_stone, 0, 2);
		world.setBlock(i + 9, j + 2, k + 9, Blocks.end_stone, 0, 2);
		world.setBlock(i + 11, j + 2, k + 9, Blocks.end_stone, 0, 2);
		world.setBlock(i + 14, j + 2, k + 9, Blocks.end_stone, 0, 2);
		world.setBlock(i + 3, j + 2, k + 10, Blocks.end_stone, 0, 2);
		world.setBlock(i + 12, j + 2, k + 10, Blocks.end_stone, 0, 2);
		world.setBlock(i + 13, j + 2, k + 10, Blocks.end_stone, 0, 2);
		world.setBlock(i + 14, j + 2, k + 10, Blocks.end_stone, 0, 2);
		world.setBlock(i + 15, j + 2, k + 10, Blocks.end_stone, 0, 2);
		world.setBlock(i + 16, j + 2, k + 10, Blocks.end_stone, 0, 2);
		world.setBlock(i + 3, j + 2, k + 11, Blocks.end_stone, 0, 2);
		world.setBlock(i + 4, j + 2, k + 11, Blocks.end_stone, 0, 2);
		world.setBlock(i + 9, j + 2, k + 11, Blocks.end_stone, 0, 2);
		world.setBlock(i + 12, j + 2, k + 11, Blocks.end_stone, 0, 2);
		world.setBlock(i + 13, j + 2, k + 11, Blocks.end_stone, 0, 2);
		world.setBlock(i + 16, j + 2, k + 11, Blocks.end_stone, 0, 2);
		world.setBlock(i + 7, j + 2, k + 12, Blocks.end_stone, 0, 2);
		world.setBlock(i + 8, j + 2, k + 12, Blocks.end_stone, 0, 2);
		world.setBlock(i + 16, j + 2, k + 12, Blocks.end_stone, 0, 2);
		world.setBlock(i + 6, j + 2, k + 13, Blocks.end_stone, 0, 2);
		world.setBlock(i + 7, j + 2, k + 13, Blocks.end_stone, 0, 2);
		world.setBlock(i + 11, j + 2, k + 13, Blocks.end_stone, 0, 2);
		world.setBlock(i + 13, j + 2, k + 13, Blocks.end_stone, 0, 2);
		world.setBlock(i + 14, j + 2, k + 13, Blocks.end_stone, 0, 2);
		world.setBlock(i + 13, j + 2, k + 14, Blocks.end_stone, 0, 2);
		world.setBlock(i + 11, j + 2, k + 16, Blocks.end_stone, 0, 2);
		world.setBlock(i + 10, j + 3, k + 2, Blocks.end_stone, 0, 2);
		world.setBlock(i + 9, j + 3, k + 3, Blocks.end_stone, 0, 2);
		world.setBlock(i + 10, j + 3, k + 3, Blocks.end_stone, 0, 2);
		world.setBlock(i + 11, j + 3, k + 3, Blocks.end_stone, 0, 2);
		world.setBlock(i + 8, j + 3, k + 4, Blocks.end_stone, 0, 2);
		world.setBlock(i + 9, j + 3, k + 4, Blocks.end_stone, 0, 2);
		world.setBlock(i + 10, j + 3, k + 4, Blocks.end_stone, 0, 2);
		world.setBlock(i + 11, j + 3, k + 4, Blocks.end_stone, 0, 2);
		world.setBlock(i + 12, j + 3, k + 4, Blocks.end_stone, 0, 2);
		world.setBlock(i + 7, j + 3, k + 5, Blocks.end_stone, 0, 2);
		world.setBlock(i + 8, j + 3, k + 5, Blocks.end_stone, 0, 2);
		world.setBlock(i + 9, j + 3, k + 5, Blocks.end_stone, 0, 2);
		world.setBlock(i + 10, j + 3, k + 5, Blocks.end_stone, 0, 2);
		world.setBlock(i + 11, j + 3, k + 5, Blocks.end_stone, 0, 2);
		world.setBlock(i + 12, j + 3, k + 5, Blocks.end_stone, 0, 2);
		world.setBlock(i + 13, j + 3, k + 5, Blocks.end_stone, 0, 2);
		world.setBlock(i + 6, j + 3, k + 6, Blocks.end_stone, 0, 2);
		world.setBlock(i + 7, j + 3, k + 6, Blocks.end_stone, 0, 2);
		world.setBlock(i + 8, j + 3, k + 6, Blocks.end_stone, 0, 2);
		world.setBlock(i + 9, j + 3, k + 6, Blocks.end_stone, 0, 2);
		world.setBlock(i + 10, j + 3, k + 6, Blocks.end_stone, 0, 2);
		world.setBlock(i + 11, j + 3, k + 6, Blocks.end_stone, 0, 2);
		world.setBlock(i + 12, j + 3, k + 6, Blocks.end_stone, 0, 2);
		world.setBlock(i + 13, j + 3, k + 6, Blocks.end_stone, 0, 2);
		world.setBlock(i + 14, j + 3, k + 6, Blocks.end_stone, 0, 2);
		world.setBlock(i + 5, j + 3, k + 7, Blocks.end_stone, 0, 2);
		world.setBlock(i + 6, j + 3, k + 7, Blocks.end_stone, 0, 2);
		world.setBlock(i + 7, j + 3, k + 7, Blocks.end_stone, 0, 2);
		world.setBlock(i + 8, j + 3, k + 7, Blocks.end_stone, 0, 2);
		world.setBlock(i + 9, j + 3, k + 7, Blocks.end_stone, 0, 2);
		world.setBlock(i + 10, j + 3, k + 7, Blocks.end_stone, 0, 2);
		world.setBlock(i + 11, j + 3, k + 7, Blocks.end_stone, 0, 2);
		world.setBlock(i + 12, j + 3, k + 7, Blocks.end_stone, 0, 2);
		world.setBlock(i + 13, j + 3, k + 7, Blocks.end_stone, 0, 2);
		world.setBlock(i + 14, j + 3, k + 7, Blocks.end_stone, 0, 2);
		world.setBlock(i + 15, j + 3, k + 7, Blocks.end_stone, 0, 2);
		world.setBlock(i + 4, j + 3, k + 8, Blocks.end_stone, 0, 2);
		world.setBlock(i + 5, j + 3, k + 8, Blocks.end_stone, 0, 2);
		world.setBlock(i + 6, j + 3, k + 8, Blocks.end_stone, 0, 2);
		world.setBlock(i + 7, j + 3, k + 8, Blocks.end_stone, 0, 2);
		world.setBlock(i + 8, j + 3, k + 8, Blocks.end_stone, 0, 2);
		world.setBlock(i + 9, j + 3, k + 8, Blocks.end_stone, 0, 2);
		world.setBlock(i + 10, j + 3, k + 8, Blocks.end_stone, 0, 2);
		world.setBlock(i + 11, j + 3, k + 8, Blocks.end_stone, 0, 2);
		world.setBlock(i + 12, j + 3, k + 8, Blocks.end_stone, 0, 2);
		world.setBlock(i + 13, j + 3, k + 8, Blocks.end_stone, 0, 2);
		world.setBlock(i + 14, j + 3, k + 8, Blocks.end_stone, 0, 2);
		world.setBlock(i + 15, j + 3, k + 8, Blocks.end_stone, 0, 2);
		world.setBlock(i + 16, j + 3, k + 8, Blocks.end_stone, 0, 2);
		world.setBlock(i + 3, j + 3, k + 9, Blocks.end_stone, 0, 2);
		world.setBlock(i + 4, j + 3, k + 9, Blocks.end_stone, 0, 2);
		world.setBlock(i + 5, j + 3, k + 9, Blocks.end_stone, 0, 2);
		world.setBlock(i + 6, j + 3, k + 9, Blocks.end_stone, 0, 2);
		world.setBlock(i + 7, j + 3, k + 9, Blocks.end_stone, 0, 2);
		world.setBlock(i + 8, j + 3, k + 9, Blocks.end_stone, 0, 2);
		world.setBlock(i + 9, j + 3, k + 9, Blocks.end_stone, 0, 2);
		world.setBlock(i + 10, j + 3, k + 9, Blocks.end_stone, 0, 2);
		world.setBlock(i + 11, j + 3, k + 9, Blocks.end_stone, 0, 2);
		world.setBlock(i + 12, j + 3, k + 9, Blocks.end_stone, 0, 2);
		world.setBlock(i + 13, j + 3, k + 9, Blocks.end_stone, 0, 2);
		world.setBlock(i + 14, j + 3, k + 9, Blocks.end_stone, 0, 2);
		world.setBlock(i + 15, j + 3, k + 9, Blocks.end_stone, 0, 2);
		world.setBlock(i + 16, j + 3, k + 9, Blocks.end_stone, 0, 2);
		world.setBlock(i + 17, j + 3, k + 9, Blocks.end_stone, 0, 2);
		world.setBlock(i + 2, j + 3, k + 10, Blocks.end_stone, 0, 2);
		world.setBlock(i + 3, j + 3, k + 10, Blocks.end_stone, 0, 2);
		world.setBlock(i + 4, j + 3, k + 10, Blocks.end_stone, 0, 2);
		world.setBlock(i + 5, j + 3, k + 10, Blocks.end_stone, 0, 2);
		world.setBlock(i + 6, j + 3, k + 10, Blocks.end_stone, 0, 2);
		world.setBlock(i + 7, j + 3, k + 10, Blocks.end_stone, 0, 2);
		world.setBlock(i + 8, j + 3, k + 10, Blocks.end_stone, 0, 2);
		world.setBlock(i + 9, j + 3, k + 10, Blocks.end_stone, 0, 2);
		world.setBlock(i + 10, j + 3, k + 10, Blocks.end_stone, 0, 2);
		world.setBlock(i + 11, j + 3, k + 10, Blocks.end_stone, 0, 2);
		world.setBlock(i + 12, j + 3, k + 10, Blocks.end_stone, 0, 2);
		world.setBlock(i + 13, j + 3, k + 10, Blocks.end_stone, 0, 2);
		world.setBlock(i + 14, j + 3, k + 10, Blocks.end_stone, 0, 2);
		world.setBlock(i + 15, j + 3, k + 10, Blocks.end_stone, 0, 2);
		world.setBlock(i + 16, j + 3, k + 10, Blocks.end_stone, 0, 2);
		world.setBlock(i + 17, j + 3, k + 10, Blocks.end_stone, 0, 2);
		world.setBlock(i + 18, j + 3, k + 10, Blocks.end_stone, 0, 2);
		world.setBlock(i + 3, j + 3, k + 11, Blocks.end_stone, 0, 2);
		world.setBlock(i + 4, j + 3, k + 11, Blocks.end_stone, 0, 2);
		world.setBlock(i + 5, j + 3, k + 11, Blocks.end_stone, 0, 2);
		world.setBlock(i + 6, j + 3, k + 11, Blocks.end_stone, 0, 2);
		world.setBlock(i + 7, j + 3, k + 11, Blocks.end_stone, 0, 2);
		world.setBlock(i + 8, j + 3, k + 11, Blocks.end_stone, 0, 2);
		world.setBlock(i + 9, j + 3, k + 11, Blocks.end_stone, 0, 2);
		world.setBlock(i + 10, j + 3, k + 11, Blocks.end_stone, 0, 2);
		world.setBlock(i + 11, j + 3, k + 11, Blocks.end_stone, 0, 2);
		world.setBlock(i + 12, j + 3, k + 11, Blocks.end_stone, 0, 2);
		world.setBlock(i + 13, j + 3, k + 11, Blocks.end_stone, 0, 2);
		world.setBlock(i + 14, j + 3, k + 11, Blocks.end_stone, 0, 2);
		world.setBlock(i + 15, j + 3, k + 11, Blocks.end_stone, 0, 2);
		world.setBlock(i + 16, j + 3, k + 11, Blocks.end_stone, 0, 2);
		world.setBlock(i + 17, j + 3, k + 11, Blocks.end_stone, 0, 2);
		world.setBlock(i + 4, j + 3, k + 12, Blocks.end_stone, 0, 2);
		world.setBlock(i + 5, j + 3, k + 12, Blocks.end_stone, 0, 2);
		world.setBlock(i + 6, j + 3, k + 12, Blocks.end_stone, 0, 2);
		world.setBlock(i + 7, j + 3, k + 12, Blocks.end_stone, 0, 2);
		world.setBlock(i + 8, j + 3, k + 12, Blocks.end_stone, 0, 2);
		world.setBlock(i + 9, j + 3, k + 12, Blocks.end_stone, 0, 2);
		world.setBlock(i + 10, j + 3, k + 12, Blocks.end_stone, 0, 2);
		world.setBlock(i + 11, j + 3, k + 12, Blocks.end_stone, 0, 2);
		world.setBlock(i + 12, j + 3, k + 12, Blocks.end_stone, 0, 2);
		world.setBlock(i + 13, j + 3, k + 12, Blocks.end_stone, 0, 2);
		world.setBlock(i + 14, j + 3, k + 12, Blocks.end_stone, 0, 2);
		world.setBlock(i + 15, j + 3, k + 12, Blocks.end_stone, 0, 2);
		world.setBlock(i + 16, j + 3, k + 12, Blocks.end_stone, 0, 2);
		world.setBlock(i + 5, j + 3, k + 13, Blocks.end_stone, 0, 2);
		world.setBlock(i + 6, j + 3, k + 13, Blocks.end_stone, 0, 2);
		world.setBlock(i + 7, j + 3, k + 13, Blocks.end_stone, 0, 2);
		world.setBlock(i + 8, j + 3, k + 13, Blocks.end_stone, 0, 2);
		world.setBlock(i + 9, j + 3, k + 13, Blocks.end_stone, 0, 2);
		world.setBlock(i + 10, j + 3, k + 13, Blocks.end_stone, 0, 2);
		world.setBlock(i + 11, j + 3, k + 13, Blocks.end_stone, 0, 2);
		world.setBlock(i + 12, j + 3, k + 13, Blocks.end_stone, 0, 2);
		world.setBlock(i + 13, j + 3, k + 13, Blocks.end_stone, 0, 2);
		world.setBlock(i + 14, j + 3, k + 13, Blocks.end_stone, 0, 2);
		world.setBlock(i + 15, j + 3, k + 13, Blocks.end_stone, 0, 2);
		world.setBlock(i + 6, j + 3, k + 14, Blocks.end_stone, 0, 2);
		world.setBlock(i + 7, j + 3, k + 14, Blocks.end_stone, 0, 2);
		world.setBlock(i + 8, j + 3, k + 14, Blocks.end_stone, 0, 2);
		world.setBlock(i + 9, j + 3, k + 14, Blocks.end_stone, 0, 2);
		world.setBlock(i + 10, j + 3, k + 14, Blocks.end_stone, 0, 2);
		world.setBlock(i + 11, j + 3, k + 14, Blocks.end_stone, 0, 2);
		world.setBlock(i + 12, j + 3, k + 14, Blocks.end_stone, 0, 2);
		world.setBlock(i + 13, j + 3, k + 14, Blocks.end_stone, 0, 2);
		world.setBlock(i + 14, j + 3, k + 14, Blocks.end_stone, 0, 2);
		world.setBlock(i + 7, j + 3, k + 15, Blocks.end_stone, 0, 2);
		world.setBlock(i + 8, j + 3, k + 15, Blocks.end_stone, 0, 2);
		world.setBlock(i + 9, j + 3, k + 15, Blocks.end_stone, 0, 2);
		world.setBlock(i + 10, j + 3, k + 15, Blocks.end_stone, 0, 2);
		world.setBlock(i + 11, j + 3, k + 15, Blocks.end_stone, 0, 2);
		world.setBlock(i + 12, j + 3, k + 15, Blocks.end_stone, 0, 2);
		world.setBlock(i + 13, j + 3, k + 15, Blocks.end_stone, 0, 2);
		world.setBlock(i + 8, j + 3, k + 16, Blocks.end_stone, 0, 2);
		world.setBlock(i + 9, j + 3, k + 16, Blocks.end_stone, 0, 2);
		world.setBlock(i + 10, j + 3, k + 16, Blocks.end_stone, 0, 2);
		world.setBlock(i + 11, j + 3, k + 16, Blocks.end_stone, 0, 2);
		world.setBlock(i + 12, j + 3, k + 16, Blocks.end_stone, 0, 2);
		world.setBlock(i + 9, j + 3, k + 17, Blocks.end_stone, 0, 2);
		world.setBlock(i + 10, j + 3, k + 17, Blocks.end_stone, 0, 2);
		world.setBlock(i + 11, j + 3, k + 17, Blocks.end_stone, 0, 2);
		world.setBlock(i + 10, j + 3, k + 18, Blocks.end_stone, 0, 2);
		world.setBlock(i + 10, j + 4, k + 1, Blocks.end_stone, 0, 2);
		world.setBlock(i + 9, j + 4, k + 2, Blocks.end_stone, 0, 2);
		world.setBlock(i + 10, j + 4, k + 2, Blocks.end_stone, 0, 2);
		world.setBlock(i + 11, j + 4, k + 2, Blocks.end_stone, 0, 2);
		world.setBlock(i + 8, j + 4, k + 3, Blocks.end_stone, 0, 2);
		world.setBlock(i + 9, j + 4, k + 3, Blocks.end_stone, 0, 2);
		world.setBlock(i + 10, j + 4, k + 3, Blocks.end_stone, 0, 2);
		world.setBlock(i + 11, j + 4, k + 3, Blocks.end_stone, 0, 2);
		world.setBlock(i + 12, j + 4, k + 3, Blocks.end_stone, 0, 2);
		world.setBlock(i + 7, j + 4, k + 4, Blocks.end_stone, 0, 2);
		world.setBlock(i + 8, j + 4, k + 4, Blocks.end_stone, 0, 2);
		world.setBlock(i + 9, j + 4, k + 4, Blocks.end_stone, 0, 2);
		world.setBlock(i + 10, j + 4, k + 4, Blocks.end_stone, 0, 2);
		world.setBlock(i + 11, j + 4, k + 4, Blocks.end_stone, 0, 2);
		world.setBlock(i + 12, j + 4, k + 4, Blocks.end_stone, 0, 2);
		world.setBlock(i + 13, j + 4, k + 4, Blocks.end_stone, 0, 2);
		world.setBlock(i + 6, j + 4, k + 5, Blocks.end_stone, 0, 2);
		world.setBlock(i + 7, j + 4, k + 5, Blocks.end_stone, 0, 2);
		world.setBlock(i + 8, j + 4, k + 5, Blocks.end_stone, 0, 2);
		world.setBlock(i + 9, j + 4, k + 5, Blocks.end_stone, 0, 2);
		world.setBlock(i + 10, j + 4, k + 5, Blocks.end_stone, 0, 2);
		world.setBlock(i + 11, j + 4, k + 5, Blocks.end_stone, 0, 2);
		world.setBlock(i + 12, j + 4, k + 5, Blocks.end_stone, 0, 2);
		world.setBlock(i + 13, j + 4, k + 5, Blocks.end_stone, 0, 2);
		world.setBlock(i + 14, j + 4, k + 5, Blocks.end_stone, 0, 2);
		world.setBlock(i + 5, j + 4, k + 6, Blocks.end_stone, 0, 2);
		world.setBlock(i + 6, j + 4, k + 6, Blocks.end_stone, 0, 2);
		world.setBlock(i + 7, j + 4, k + 6, Blocks.end_stone, 0, 2);
		world.setBlock(i + 8, j + 4, k + 6, Blocks.end_stone, 0, 2);
		world.setBlock(i + 9, j + 4, k + 6, Blocks.end_stone, 0, 2);
		world.setBlock(i + 10, j + 4, k + 6, Blocks.end_stone, 0, 2);
		world.setBlock(i + 11, j + 4, k + 6, Blocks.end_stone, 0, 2);
		world.setBlock(i + 12, j + 4, k + 6, Blocks.end_stone, 0, 2);
		world.setBlock(i + 13, j + 4, k + 6, Blocks.end_stone, 0, 2);
		world.setBlock(i + 14, j + 4, k + 6, Blocks.end_stone, 0, 2);
		world.setBlock(i + 15, j + 4, k + 6, Blocks.end_stone, 0, 2);
		world.setBlock(i + 4, j + 4, k + 7, Blocks.end_stone, 0, 2);
		world.setBlock(i + 5, j + 4, k + 7, Blocks.end_stone, 0, 2);
		world.setBlock(i + 6, j + 4, k + 7, Blocks.end_stone, 0, 2);
		world.setBlock(i + 7, j + 4, k + 7, Blocks.end_stone, 0, 2);
		world.setBlock(i + 8, j + 4, k + 7, Blocks.end_stone, 0, 2);
		world.setBlock(i + 9, j + 4, k + 7, Blocks.end_stone, 0, 2);
		world.setBlock(i + 10, j + 4, k + 7, Blocks.end_stone, 0, 2);
		world.setBlock(i + 11, j + 4, k + 7, Blocks.end_stone, 0, 2);
		world.setBlock(i + 12, j + 4, k + 7, Blocks.end_stone, 0, 2);
		world.setBlock(i + 13, j + 4, k + 7, Blocks.end_stone, 0, 2);
		world.setBlock(i + 14, j + 4, k + 7, Blocks.end_stone, 0, 2);
		world.setBlock(i + 15, j + 4, k + 7, Blocks.end_stone, 0, 2);
		world.setBlock(i + 16, j + 4, k + 7, Blocks.end_stone, 0, 2);
		world.setBlock(i + 3, j + 4, k + 8, Blocks.end_stone, 0, 2);
		world.setBlock(i + 4, j + 4, k + 8, Blocks.end_stone, 0, 2);
		world.setBlock(i + 5, j + 4, k + 8, Blocks.end_stone, 0, 2);
		world.setBlock(i + 6, j + 4, k + 8, Blocks.end_stone, 0, 2);
		world.setBlock(i + 7, j + 4, k + 8, Blocks.end_stone, 0, 2);
		world.setBlock(i + 8, j + 4, k + 8, Blocks.end_stone, 0, 2);
		world.setBlock(i + 9, j + 4, k + 8, Blocks.end_stone, 0, 2);
		world.setBlock(i + 10, j + 4, k + 8, Blocks.end_stone, 0, 2);
		world.setBlock(i + 11, j + 4, k + 8, Blocks.end_stone, 0, 2);
		world.setBlock(i + 12, j + 4, k + 8, Blocks.end_stone, 0, 2);
		world.setBlock(i + 13, j + 4, k + 8, Blocks.end_stone, 0, 2);
		world.setBlock(i + 14, j + 4, k + 8, Blocks.end_stone, 0, 2);
		world.setBlock(i + 15, j + 4, k + 8, Blocks.end_stone, 0, 2);
		world.setBlock(i + 16, j + 4, k + 8, Blocks.end_stone, 0, 2);
		world.setBlock(i + 17, j + 4, k + 8, Blocks.end_stone, 0, 2);
		world.setBlock(i + 2, j + 4, k + 9, Blocks.end_stone, 0, 2);
		world.setBlock(i + 3, j + 4, k + 9, Blocks.end_stone, 0, 2);
		world.setBlock(i + 4, j + 4, k + 9, Blocks.end_stone, 0, 2);
		world.setBlock(i + 5, j + 4, k + 9, Blocks.end_stone, 0, 2);
		world.setBlock(i + 6, j + 4, k + 9, Blocks.end_stone, 0, 2);
		world.setBlock(i + 7, j + 4, k + 9, Blocks.end_stone, 0, 2);
		world.setBlock(i + 8, j + 4, k + 9, Blocks.end_stone, 0, 2);
		world.setBlock(i + 9, j + 4, k + 9, Blocks.end_stone, 0, 2);
		world.setBlock(i + 10, j + 4, k + 9, Blocks.end_stone, 0, 2);
		world.setBlock(i + 11, j + 4, k + 9, Blocks.end_stone, 0, 2);
		world.setBlock(i + 12, j + 4, k + 9, Blocks.end_stone, 0, 2);
		world.setBlock(i + 13, j + 4, k + 9, Blocks.end_stone, 0, 2);
		world.setBlock(i + 14, j + 4, k + 9, Blocks.end_stone, 0, 2);
		world.setBlock(i + 15, j + 4, k + 9, Blocks.end_stone, 0, 2);
		world.setBlock(i + 16, j + 4, k + 9, Blocks.end_stone, 0, 2);
		world.setBlock(i + 17, j + 4, k + 9, Blocks.end_stone, 0, 2);
		world.setBlock(i + 18, j + 4, k + 9, Blocks.end_stone, 0, 2);
		world.setBlock(i + 1, j + 4, k + 10, Blocks.end_stone, 0, 2);
		world.setBlock(i + 2, j + 4, k + 10, Blocks.end_stone, 0, 2);
		world.setBlock(i + 3, j + 4, k + 10, Blocks.end_stone, 0, 2);
		world.setBlock(i + 4, j + 4, k + 10, Blocks.end_stone, 0, 2);
		world.setBlock(i + 5, j + 4, k + 10, Blocks.end_stone, 0, 2);
		world.setBlock(i + 6, j + 4, k + 10, Blocks.end_stone, 0, 2);
		world.setBlock(i + 7, j + 4, k + 10, Blocks.end_stone, 0, 2);
		world.setBlock(i + 8, j + 4, k + 10, Blocks.end_stone, 0, 2);
		world.setBlock(i + 9, j + 4, k + 10, Blocks.end_stone, 0, 2);
		world.setBlock(i + 10, j + 4, k + 10, Blocks.end_stone, 0, 2);
		world.setBlock(i + 11, j + 4, k + 10, Blocks.end_stone, 0, 2);
		world.setBlock(i + 12, j + 4, k + 10, Blocks.end_stone, 0, 2);
		world.setBlock(i + 13, j + 4, k + 10, Blocks.end_stone, 0, 2);
		world.setBlock(i + 14, j + 4, k + 10, Blocks.end_stone, 0, 2);
		world.setBlock(i + 15, j + 4, k + 10, Blocks.end_stone, 0, 2);
		world.setBlock(i + 16, j + 4, k + 10, Blocks.end_stone, 0, 2);
		world.setBlock(i + 17, j + 4, k + 10, Blocks.end_stone, 0, 2);
		world.setBlock(i + 18, j + 4, k + 10, Blocks.end_stone, 0, 2);
		world.setBlock(i + 19, j + 4, k + 10, Blocks.end_stone, 0, 2);
		world.setBlock(i + 2, j + 4, k + 11, Blocks.end_stone, 0, 2);
		world.setBlock(i + 3, j + 4, k + 11, Blocks.end_stone, 0, 2);
		world.setBlock(i + 4, j + 4, k + 11, Blocks.end_stone, 0, 2);
		world.setBlock(i + 5, j + 4, k + 11, Blocks.end_stone, 0, 2);
		world.setBlock(i + 6, j + 4, k + 11, Blocks.end_stone, 0, 2);
		world.setBlock(i + 7, j + 4, k + 11, Blocks.end_stone, 0, 2);
		world.setBlock(i + 8, j + 4, k + 11, Blocks.end_stone, 0, 2);
		world.setBlock(i + 9, j + 4, k + 11, Blocks.end_stone, 0, 2);
		world.setBlock(i + 10, j + 4, k + 11, Blocks.end_stone, 0, 2);
		world.setBlock(i + 11, j + 4, k + 11, Blocks.end_stone, 0, 2);
		world.setBlock(i + 12, j + 4, k + 11, Blocks.end_stone, 0, 2);
		world.setBlock(i + 13, j + 4, k + 11, Blocks.end_stone, 0, 2);
		world.setBlock(i + 14, j + 4, k + 11, Blocks.end_stone, 0, 2);
		world.setBlock(i + 15, j + 4, k + 11, Blocks.end_stone, 0, 2);
		world.setBlock(i + 16, j + 4, k + 11, Blocks.end_stone, 0, 2);
		world.setBlock(i + 17, j + 4, k + 11, Blocks.end_stone, 0, 2);
		world.setBlock(i + 18, j + 4, k + 11, Blocks.end_stone, 0, 2);
		world.setBlock(i + 3, j + 4, k + 12, Blocks.end_stone, 0, 2);
		world.setBlock(i + 4, j + 4, k + 12, Blocks.end_stone, 0, 2);
		world.setBlock(i + 5, j + 4, k + 12, Blocks.end_stone, 0, 2);
		world.setBlock(i + 6, j + 4, k + 12, Blocks.end_stone, 0, 2);
		world.setBlock(i + 7, j + 4, k + 12, Blocks.end_stone, 0, 2);
		world.setBlock(i + 8, j + 4, k + 12, Blocks.end_stone, 0, 2);
		world.setBlock(i + 9, j + 4, k + 12, Blocks.end_stone, 0, 2);
		world.setBlock(i + 10, j + 4, k + 12, Blocks.end_stone, 0, 2);
		world.setBlock(i + 11, j + 4, k + 12, Blocks.end_stone, 0, 2);
		world.setBlock(i + 12, j + 4, k + 12, Blocks.end_stone, 0, 2);
		world.setBlock(i + 13, j + 4, k + 12, Blocks.end_stone, 0, 2);
		world.setBlock(i + 14, j + 4, k + 12, Blocks.end_stone, 0, 2);
		world.setBlock(i + 15, j + 4, k + 12, Blocks.end_stone, 0, 2);
		world.setBlock(i + 16, j + 4, k + 12, Blocks.end_stone, 0, 2);
		world.setBlock(i + 17, j + 4, k + 12, Blocks.end_stone, 0, 2);
		world.setBlock(i + 4, j + 4, k + 13, Blocks.end_stone, 0, 2);
		world.setBlock(i + 5, j + 4, k + 13, Blocks.end_stone, 0, 2);
		world.setBlock(i + 6, j + 4, k + 13, Blocks.end_stone, 0, 2);
		world.setBlock(i + 7, j + 4, k + 13, Blocks.end_stone, 0, 2);
		world.setBlock(i + 8, j + 4, k + 13, Blocks.end_stone, 0, 2);
		world.setBlock(i + 9, j + 4, k + 13, Blocks.end_stone, 0, 2);
		world.setBlock(i + 10, j + 4, k + 13, Blocks.end_stone, 0, 2);
		world.setBlock(i + 11, j + 4, k + 13, Blocks.end_stone, 0, 2);
		world.setBlock(i + 12, j + 4, k + 13, Blocks.end_stone, 0, 2);
		world.setBlock(i + 13, j + 4, k + 13, Blocks.end_stone, 0, 2);
		world.setBlock(i + 14, j + 4, k + 13, Blocks.end_stone, 0, 2);
		world.setBlock(i + 15, j + 4, k + 13, Blocks.end_stone, 0, 2);
		world.setBlock(i + 16, j + 4, k + 13, Blocks.end_stone, 0, 2);
		world.setBlock(i + 5, j + 4, k + 14, Blocks.end_stone, 0, 2);
		world.setBlock(i + 6, j + 4, k + 14, Blocks.end_stone, 0, 2);
		world.setBlock(i + 7, j + 4, k + 14, Blocks.end_stone, 0, 2);
		world.setBlock(i + 8, j + 4, k + 14, Blocks.end_stone, 0, 2);
		world.setBlock(i + 9, j + 4, k + 14, Blocks.end_stone, 0, 2);
		world.setBlock(i + 10, j + 4, k + 14, Blocks.end_stone, 0, 2);
		world.setBlock(i + 11, j + 4, k + 14, Blocks.end_stone, 0, 2);
		world.setBlock(i + 12, j + 4, k + 14, Blocks.end_stone, 0, 2);
		world.setBlock(i + 13, j + 4, k + 14, Blocks.end_stone, 0, 2);
		world.setBlock(i + 14, j + 4, k + 14, Blocks.end_stone, 0, 2);
		world.setBlock(i + 15, j + 4, k + 14, Blocks.end_stone, 0, 2);
		world.setBlock(i + 6, j + 4, k + 15, Blocks.end_stone, 0, 2);
		world.setBlock(i + 7, j + 4, k + 15, Blocks.end_stone, 0, 2);
		world.setBlock(i + 8, j + 4, k + 15, Blocks.end_stone, 0, 2);
		world.setBlock(i + 9, j + 4, k + 15, Blocks.end_stone, 0, 2);
		world.setBlock(i + 10, j + 4, k + 15, Blocks.end_stone, 0, 2);
		world.setBlock(i + 11, j + 4, k + 15, Blocks.end_stone, 0, 2);
		world.setBlock(i + 12, j + 4, k + 15, Blocks.end_stone, 0, 2);
		world.setBlock(i + 13, j + 4, k + 15, Blocks.end_stone, 0, 2);
		world.setBlock(i + 14, j + 4, k + 15, Blocks.end_stone, 0, 2);
		world.setBlock(i + 7, j + 4, k + 16, Blocks.end_stone, 0, 2);
		world.setBlock(i + 8, j + 4, k + 16, Blocks.end_stone, 0, 2);
		world.setBlock(i + 9, j + 4, k + 16, Blocks.end_stone, 0, 2);
		world.setBlock(i + 10, j + 4, k + 16, Blocks.end_stone, 0, 2);
		world.setBlock(i + 11, j + 4, k + 16, Blocks.end_stone, 0, 2);
		world.setBlock(i + 12, j + 4, k + 16, Blocks.end_stone, 0, 2);
		world.setBlock(i + 13, j + 4, k + 16, Blocks.end_stone, 0, 2);
		world.setBlock(i + 8, j + 4, k + 17, Blocks.end_stone, 0, 2);
		world.setBlock(i + 9, j + 4, k + 17, Blocks.end_stone, 0, 2);
		world.setBlock(i + 10, j + 4, k + 17, Blocks.end_stone, 0, 2);
		world.setBlock(i + 11, j + 4, k + 17, Blocks.end_stone, 0, 2);
		world.setBlock(i + 12, j + 4, k + 17, Blocks.end_stone, 0, 2);
		world.setBlock(i + 9, j + 4, k + 18, Blocks.end_stone, 0, 2);
		world.setBlock(i + 10, j + 4, k + 18, Blocks.end_stone, 0, 2);
		world.setBlock(i + 11, j + 4, k + 18, Blocks.end_stone, 0, 2);
		world.setBlock(i + 10, j + 4, k + 19, Blocks.end_stone, 0, 2);
		world.setBlock(i + 10, j + 5, k + 0, OtherModBlocks.end_bricks, 0, 2);
		world.setBlock(i + 9, j + 5, k + 1, OtherModBlocks.end_bricks, 0, 2);
		world.setBlock(i + 10, j + 5, k + 1, OtherModBlocks.purpur_pillar, 0, 2);
		world.setBlock(i + 11, j + 5, k + 1, OtherModBlocks.end_bricks, 0, 2);
		world.setBlock(i + 8, j + 5, k + 2, OtherModBlocks.end_bricks, 0, 2);
		world.setBlock(i + 9, j + 5, k + 2, Blocks.end_stone, 0, 2);
		world.setBlock(i + 10, j + 5, k + 2, NovaCraftBlocks.lacuna_planks, 0, 2);
		world.setBlock(i + 11, j + 5, k + 2, Blocks.end_stone, 0, 2);
		world.setBlock(i + 12, j + 5, k + 2, OtherModBlocks.end_bricks, 0, 2);
		world.setBlock(i + 7, j + 5, k + 3, OtherModBlocks.end_bricks, 0, 2);
		world.setBlock(i + 8, j + 5, k + 3, Blocks.end_stone, 0, 2);
		world.setBlock(i + 9, j + 5, k + 3, Blocks.end_stone, 0, 2);
		world.setBlock(i + 10, j + 5, k + 3, NovaCraftBlocks.lacuna_planks, 0, 2);
		world.setBlock(i + 11, j + 5, k + 3, Blocks.end_stone, 0, 2);
		world.setBlock(i + 12, j + 5, k + 3, Blocks.end_stone, 0, 2);
		world.setBlock(i + 13, j + 5, k + 3, OtherModBlocks.end_bricks, 0, 2);
		world.setBlock(i + 6, j + 5, k + 4, OtherModBlocks.end_bricks, 0, 2);
		world.setBlock(i + 7, j + 5, k + 4, Blocks.end_stone, 0, 2);
		world.setBlock(i + 8, j + 5, k + 4, Blocks.end_stone, 0, 2);
		world.setBlock(i + 9, j + 5, k + 4, Blocks.end_stone, 0, 2);
		world.setBlock(i + 10, j + 5, k + 4, NovaCraftBlocks.lacuna_planks, 0, 2);
		world.setBlock(i + 11, j + 5, k + 4, Blocks.end_stone, 0, 2);
		world.setBlock(i + 12, j + 5, k + 4, Blocks.end_stone, 0, 2);
		world.setBlock(i + 13, j + 5, k + 4, Blocks.end_stone, 0, 2);
		world.setBlock(i + 14, j + 5, k + 4, OtherModBlocks.end_bricks, 0, 2);
		world.setBlock(i + 5, j + 5, k + 5, OtherModBlocks.end_bricks, 0, 2);
		world.setBlock(i + 6, j + 5, k + 5, Blocks.end_stone, 0, 2);
		world.setBlock(i + 7, j + 5, k + 5, Blocks.end_stone, 0, 2);
		world.setBlock(i + 8, j + 5, k + 5, Blocks.end_stone, 0, 2);
		world.setBlock(i + 9, j + 5, k + 5, Blocks.end_stone, 0, 2);
		world.setBlock(i + 10, j + 5, k + 5, NovaCraftBlocks.lacuna_planks, 0, 2);
		world.setBlock(i + 11, j + 5, k + 5, Blocks.end_stone, 0, 2);
		world.setBlock(i + 12, j + 5, k + 5, Blocks.end_stone, 0, 2);
		world.setBlock(i + 13, j + 5, k + 5, Blocks.end_stone, 0, 2);
		world.setBlock(i + 14, j + 5, k + 5, Blocks.end_stone, 0, 2);
		world.setBlock(i + 15, j + 5, k + 5, OtherModBlocks.end_bricks, 0, 2);
		world.setBlock(i + 4, j + 5, k + 6, OtherModBlocks.end_bricks, 0, 2);
		world.setBlock(i + 5, j + 5, k + 6, Blocks.end_stone, 0, 2);
		world.setBlock(i + 6, j + 5, k + 6, Blocks.end_stone, 0, 2);
		world.setBlock(i + 7, j + 5, k + 6, Blocks.end_stone, 0, 2);
		world.setBlock(i + 8, j + 5, k + 6, Blocks.end_stone, 0, 2);
		world.setBlock(i + 9, j + 5, k + 6, Blocks.end_stone, 0, 2);
		world.setBlock(i + 10, j + 5, k + 6, NovaCraftBlocks.lacuna_planks, 0, 2);
		world.setBlock(i + 11, j + 5, k + 6, Blocks.end_stone, 0, 2);
		world.setBlock(i + 12, j + 5, k + 6, Blocks.end_stone, 0, 2);
		world.setBlock(i + 13, j + 5, k + 6, Blocks.end_stone, 0, 2);
		world.setBlock(i + 14, j + 5, k + 6, Blocks.end_stone, 0, 2);
		world.setBlock(i + 15, j + 5, k + 6, Blocks.end_stone, 0, 2);
		world.setBlock(i + 16, j + 5, k + 6, OtherModBlocks.end_bricks, 0, 2);
		world.setBlock(i + 3, j + 5, k + 7, OtherModBlocks.end_bricks, 0, 2);
		world.setBlock(i + 4, j + 5, k + 7, Blocks.end_stone, 0, 2);
		world.setBlock(i + 5, j + 5, k + 7, Blocks.end_stone, 0, 2);
		world.setBlock(i + 6, j + 5, k + 7, Blocks.end_stone, 0, 2);
		world.setBlock(i + 7, j + 5, k + 7, Blocks.end_stone, 0, 2);
		world.setBlock(i + 8, j + 5, k + 7, Blocks.end_stone, 0, 2);
		world.setBlock(i + 9, j + 5, k + 7, Blocks.end_stone, 0, 2);
		world.setBlock(i + 10, j + 5, k + 7, NovaCraftBlocks.lacuna_planks, 0, 2);
		world.setBlock(i + 11, j + 5, k + 7, Blocks.end_stone, 0, 2);
		world.setBlock(i + 12, j + 5, k + 7, Blocks.end_stone, 0, 2);
		world.setBlock(i + 13, j + 5, k + 7, Blocks.end_stone, 0, 2);
		world.setBlock(i + 14, j + 5, k + 7, Blocks.end_stone, 0, 2);
		world.setBlock(i + 15, j + 5, k + 7, Blocks.end_stone, 0, 2);
		world.setBlock(i + 16, j + 5, k + 7, Blocks.end_stone, 0, 2);
		world.setBlock(i + 17, j + 5, k + 7, OtherModBlocks.end_bricks, 0, 2);
		world.setBlock(i + 2, j + 5, k + 8, OtherModBlocks.end_bricks, 0, 2);
		world.setBlock(i + 3, j + 5, k + 8, Blocks.end_stone, 0, 2);
		world.setBlock(i + 4, j + 5, k + 8, Blocks.end_stone, 0, 2);
		world.setBlock(i + 5, j + 5, k + 8, Blocks.end_stone, 0, 2);
		world.setBlock(i + 6, j + 5, k + 8, Blocks.end_stone, 0, 2);
		world.setBlock(i + 7, j + 5, k + 8, Blocks.end_stone, 0, 2);
		world.setBlock(i + 8, j + 5, k + 8, Blocks.end_stone, 0, 2);
		world.setBlock(i + 9, j + 5, k + 8, Blocks.end_stone, 0, 2);
		world.setBlock(i + 10, j + 5, k + 8, NovaCraftBlocks.lacuna_planks, 0, 2);
		world.setBlock(i + 11, j + 5, k + 8, Blocks.end_stone, 0, 2);
		world.setBlock(i + 12, j + 5, k + 8, Blocks.end_stone, 0, 2);
		world.setBlock(i + 13, j + 5, k + 8, Blocks.end_stone, 0, 2);
		world.setBlock(i + 14, j + 5, k + 8, Blocks.end_stone, 0, 2);
		world.setBlock(i + 15, j + 5, k + 8, Blocks.end_stone, 0, 2);
		world.setBlock(i + 16, j + 5, k + 8, Blocks.end_stone, 0, 2);
		world.setBlock(i + 17, j + 5, k + 8, Blocks.end_stone, 0, 2);
		world.setBlock(i + 18, j + 5, k + 8, OtherModBlocks.end_bricks, 0, 2);
		world.setBlock(i + 1, j + 5, k + 9, OtherModBlocks.end_bricks, 0, 2);
		world.setBlock(i + 2, j + 5, k + 9, Blocks.end_stone, 0, 2);
		world.setBlock(i + 3, j + 5, k + 9, Blocks.end_stone, 0, 2);
		world.setBlock(i + 4, j + 5, k + 9, Blocks.end_stone, 0, 2);
		world.setBlock(i + 5, j + 5, k + 9, Blocks.end_stone, 0, 2);
		world.setBlock(i + 6, j + 5, k + 9, Blocks.end_stone, 0, 2);
		world.setBlock(i + 7, j + 5, k + 9, Blocks.end_stone, 0, 2);
		world.setBlock(i + 8, j + 5, k + 9, Blocks.end_stone, 0, 2);
		world.setBlock(i + 9, j + 5, k + 9, Blocks.end_stone, 0, 2);
		world.setBlock(i + 10, j + 5, k + 9, NovaCraftBlocks.lacuna_planks, 0, 2);
		world.setBlock(i + 11, j + 5, k + 9, Blocks.end_stone, 0, 2);
		world.setBlock(i + 12, j + 5, k + 9, Blocks.end_stone, 0, 2);
		world.setBlock(i + 13, j + 5, k + 9, Blocks.end_stone, 0, 2);
		world.setBlock(i + 14, j + 5, k + 9, Blocks.end_stone, 0, 2);
		world.setBlock(i + 15, j + 5, k + 9, Blocks.end_stone, 0, 2);
		world.setBlock(i + 16, j + 5, k + 9, Blocks.end_stone, 0, 2);
		world.setBlock(i + 17, j + 5, k + 9, Blocks.end_stone, 0, 2);
		world.setBlock(i + 18, j + 5, k + 9, Blocks.end_stone, 0, 2);
		world.setBlock(i + 19, j + 5, k + 9, OtherModBlocks.end_bricks, 0, 2);
		world.setBlock(i + 0, j + 5, k + 10, OtherModBlocks.end_bricks, 0, 2);
		world.setBlock(i + 1, j + 5, k + 10, OtherModBlocks.purpur_pillar, 0, 2);
		world.setBlock(i + 2, j + 5, k + 10, NovaCraftBlocks.lacuna_planks, 0, 2);
		world.setBlock(i + 3, j + 5, k + 10, NovaCraftBlocks.lacuna_planks, 0, 2);
		world.setBlock(i + 4, j + 5, k + 10, NovaCraftBlocks.lacuna_planks, 0, 2);
		world.setBlock(i + 5, j + 5, k + 10, NovaCraftBlocks.lacuna_planks, 0, 2);
		world.setBlock(i + 6, j + 5, k + 10, NovaCraftBlocks.lacuna_planks, 0, 2);
		world.setBlock(i + 7, j + 5, k + 10, NovaCraftBlocks.lacuna_planks, 0, 2);
		world.setBlock(i + 8, j + 5, k + 10, NovaCraftBlocks.lacuna_planks, 0, 2);
		world.setBlock(i + 9, j + 5, k + 10, NovaCraftBlocks.lacuna_planks, 0, 2);
		world.setBlock(i + 10, j + 5, k + 10, OtherModBlocks.purpur_pillar, 0, 2);
		world.setBlock(i + 11, j + 5, k + 10, NovaCraftBlocks.lacuna_planks, 0, 2);
		world.setBlock(i + 12, j + 5, k + 10, NovaCraftBlocks.lacuna_planks, 0, 2);
		world.setBlock(i + 13, j + 5, k + 10, NovaCraftBlocks.lacuna_planks, 0, 2);
		world.setBlock(i + 14, j + 5, k + 10, NovaCraftBlocks.lacuna_planks, 0, 2);
		world.setBlock(i + 15, j + 5, k + 10, NovaCraftBlocks.lacuna_planks, 0, 2);
		world.setBlock(i + 16, j + 5, k + 10, NovaCraftBlocks.lacuna_planks, 0, 2);
		world.setBlock(i + 17, j + 5, k + 10, NovaCraftBlocks.lacuna_planks, 0, 2);
		world.setBlock(i + 18, j + 5, k + 10, NovaCraftBlocks.lacuna_planks, 0, 2);
		world.setBlock(i + 19, j + 5, k + 10, OtherModBlocks.purpur_pillar, 0, 2);
		world.setBlock(i + 20, j + 5, k + 10, OtherModBlocks.end_bricks, 0, 2);
		world.setBlock(i + 1, j + 5, k + 11, OtherModBlocks.end_bricks, 0, 2);
		world.setBlock(i + 2, j + 5, k + 11, Blocks.end_stone, 0, 2);
		world.setBlock(i + 3, j + 5, k + 11, Blocks.end_stone, 0, 2);
		world.setBlock(i + 4, j + 5, k + 11, Blocks.end_stone, 0, 2);
		world.setBlock(i + 5, j + 5, k + 11, Blocks.end_stone, 0, 2);
		world.setBlock(i + 6, j + 5, k + 11, Blocks.end_stone, 0, 2);
		world.setBlock(i + 7, j + 5, k + 11, Blocks.end_stone, 0, 2);
		world.setBlock(i + 8, j + 5, k + 11, Blocks.end_stone, 0, 2);
		world.setBlock(i + 9, j + 5, k + 11, Blocks.end_stone, 0, 2);
		world.setBlock(i + 10, j + 5, k + 11, NovaCraftBlocks.lacuna_planks, 0, 2);
		world.setBlock(i + 11, j + 5, k + 11, Blocks.end_stone, 0, 2);
		world.setBlock(i + 12, j + 5, k + 11, Blocks.end_stone, 0, 2);
		world.setBlock(i + 13, j + 5, k + 11, Blocks.end_stone, 0, 2);
		world.setBlock(i + 14, j + 5, k + 11, Blocks.end_stone, 0, 2);
		world.setBlock(i + 15, j + 5, k + 11, Blocks.end_stone, 0, 2);
		world.setBlock(i + 16, j + 5, k + 11, Blocks.end_stone, 0, 2);
		world.setBlock(i + 17, j + 5, k + 11, Blocks.end_stone, 0, 2);
		world.setBlock(i + 18, j + 5, k + 11, Blocks.end_stone, 0, 2);
		world.setBlock(i + 19, j + 5, k + 11, OtherModBlocks.end_bricks, 0, 2);
		world.setBlock(i + 2, j + 5, k + 12, OtherModBlocks.end_bricks, 0, 2);
		world.setBlock(i + 3, j + 5, k + 12, Blocks.end_stone, 0, 2);
		world.setBlock(i + 4, j + 5, k + 12, Blocks.end_stone, 0, 2);
		world.setBlock(i + 5, j + 5, k + 12, Blocks.end_stone, 0, 2);
		world.setBlock(i + 6, j + 5, k + 12, Blocks.end_stone, 0, 2);
		world.setBlock(i + 7, j + 5, k + 12, Blocks.end_stone, 0, 2);
		world.setBlock(i + 8, j + 5, k + 12, Blocks.end_stone, 0, 2);
		world.setBlock(i + 9, j + 5, k + 12, Blocks.end_stone, 0, 2);
		world.setBlock(i + 10, j + 5, k + 12, NovaCraftBlocks.lacuna_planks, 0, 2);
		world.setBlock(i + 11, j + 5, k + 12, Blocks.end_stone, 0, 2);
		world.setBlock(i + 12, j + 5, k + 12, Blocks.end_stone, 0, 2);
		world.setBlock(i + 13, j + 5, k + 12, Blocks.end_stone, 0, 2);
		world.setBlock(i + 14, j + 5, k + 12, Blocks.end_stone, 0, 2);
		world.setBlock(i + 15, j + 5, k + 12, Blocks.end_stone, 0, 2);
		world.setBlock(i + 16, j + 5, k + 12, Blocks.end_stone, 0, 2);
		world.setBlock(i + 17, j + 5, k + 12, Blocks.end_stone, 0, 2);
		world.setBlock(i + 18, j + 5, k + 12, OtherModBlocks.end_bricks, 0, 2);
		world.setBlock(i + 3, j + 5, k + 13, OtherModBlocks.end_bricks, 0, 2);
		world.setBlock(i + 4, j + 5, k + 13, Blocks.end_stone, 0, 2);
		world.setBlock(i + 5, j + 5, k + 13, Blocks.end_stone, 0, 2);
		world.setBlock(i + 6, j + 5, k + 13, Blocks.end_stone, 0, 2);
		world.setBlock(i + 7, j + 5, k + 13, Blocks.end_stone, 0, 2);
		world.setBlock(i + 8, j + 5, k + 13, Blocks.end_stone, 0, 2);
		world.setBlock(i + 9, j + 5, k + 13, Blocks.end_stone, 0, 2);
		world.setBlock(i + 10, j + 5, k + 13, NovaCraftBlocks.lacuna_planks, 0, 2);
		world.setBlock(i + 11, j + 5, k + 13, Blocks.end_stone, 0, 2);
		world.setBlock(i + 12, j + 5, k + 13, Blocks.end_stone, 0, 2);
		world.setBlock(i + 13, j + 5, k + 13, Blocks.end_stone, 0, 2);
		world.setBlock(i + 14, j + 5, k + 13, Blocks.end_stone, 0, 2);
		world.setBlock(i + 15, j + 5, k + 13, Blocks.end_stone, 0, 2);
		world.setBlock(i + 16, j + 5, k + 13, Blocks.end_stone, 0, 2);
		world.setBlock(i + 17, j + 5, k + 13, OtherModBlocks.end_bricks, 0, 2);
		world.setBlock(i + 4, j + 5, k + 14, OtherModBlocks.end_bricks, 0, 2);
		world.setBlock(i + 5, j + 5, k + 14, Blocks.end_stone, 0, 2);
		world.setBlock(i + 6, j + 5, k + 14, Blocks.end_stone, 0, 2);
		world.setBlock(i + 7, j + 5, k + 14, Blocks.end_stone, 0, 2);
		world.setBlock(i + 8, j + 5, k + 14, Blocks.end_stone, 0, 2);
		world.setBlock(i + 9, j + 5, k + 14, Blocks.end_stone, 0, 2);
		world.setBlock(i + 10, j + 5, k + 14, NovaCraftBlocks.lacuna_planks, 0, 2);
		world.setBlock(i + 11, j + 5, k + 14, Blocks.end_stone, 0, 2);
		world.setBlock(i + 12, j + 5, k + 14, Blocks.end_stone, 0, 2);
		world.setBlock(i + 13, j + 5, k + 14, Blocks.end_stone, 0, 2);
		world.setBlock(i + 14, j + 5, k + 14, Blocks.end_stone, 0, 2);
		world.setBlock(i + 15, j + 5, k + 14, Blocks.end_stone, 0, 2);
		world.setBlock(i + 16, j + 5, k + 14, OtherModBlocks.end_bricks, 0, 2);
		world.setBlock(i + 5, j + 5, k + 15, OtherModBlocks.end_bricks, 0, 2);
		world.setBlock(i + 6, j + 5, k + 15, Blocks.end_stone, 0, 2);
		world.setBlock(i + 7, j + 5, k + 15, Blocks.end_stone, 0, 2);
		world.setBlock(i + 8, j + 5, k + 15, Blocks.end_stone, 0, 2);
		world.setBlock(i + 9, j + 5, k + 15, Blocks.end_stone, 0, 2);
		world.setBlock(i + 10, j + 5, k + 15, NovaCraftBlocks.lacuna_planks, 0, 2);
		world.setBlock(i + 11, j + 5, k + 15, Blocks.end_stone, 0, 2);
		world.setBlock(i + 12, j + 5, k + 15, Blocks.end_stone, 0, 2);
		world.setBlock(i + 13, j + 5, k + 15, Blocks.end_stone, 0, 2);
		world.setBlock(i + 14, j + 5, k + 15, Blocks.end_stone, 0, 2);
		world.setBlock(i + 15, j + 5, k + 15, OtherModBlocks.end_bricks, 0, 2);
		world.setBlock(i + 6, j + 5, k + 16, OtherModBlocks.end_bricks, 0, 2);
		world.setBlock(i + 7, j + 5, k + 16, Blocks.end_stone, 0, 2);
		world.setBlock(i + 8, j + 5, k + 16, Blocks.end_stone, 0, 2);
		world.setBlock(i + 9, j + 5, k + 16, Blocks.end_stone, 0, 2);
		world.setBlock(i + 10, j + 5, k + 16, NovaCraftBlocks.lacuna_planks, 0, 2);
		world.setBlock(i + 11, j + 5, k + 16, Blocks.end_stone, 0, 2);
		world.setBlock(i + 12, j + 5, k + 16, Blocks.end_stone, 0, 2);
		world.setBlock(i + 13, j + 5, k + 16, Blocks.end_stone, 0, 2);
		world.setBlock(i + 14, j + 5, k + 16, OtherModBlocks.end_bricks, 0, 2);
		world.setBlock(i + 7, j + 5, k + 17, OtherModBlocks.end_bricks, 0, 2);
		world.setBlock(i + 8, j + 5, k + 17, Blocks.end_stone, 0, 2);
		world.setBlock(i + 9, j + 5, k + 17, Blocks.end_stone, 0, 2);
		world.setBlock(i + 10, j + 5, k + 17, NovaCraftBlocks.lacuna_planks, 0, 2);
		world.setBlock(i + 11, j + 5, k + 17, Blocks.end_stone, 0, 2);
		world.setBlock(i + 12, j + 5, k + 17, Blocks.end_stone, 0, 2);
		world.setBlock(i + 13, j + 5, k + 17, OtherModBlocks.end_bricks, 0, 2);
		world.setBlock(i + 8, j + 5, k + 18, OtherModBlocks.end_bricks, 0, 2);
		world.setBlock(i + 9, j + 5, k + 18, Blocks.end_stone, 0, 2);
		world.setBlock(i + 10, j + 5, k + 18, NovaCraftBlocks.lacuna_planks, 0, 2);
		world.setBlock(i + 11, j + 5, k + 18, Blocks.end_stone, 0, 2);
		world.setBlock(i + 12, j + 5, k + 18, OtherModBlocks.end_bricks, 0, 2);
		world.setBlock(i + 9, j + 5, k + 19, OtherModBlocks.end_bricks, 0, 2);
		world.setBlock(i + 10, j + 5, k + 19, OtherModBlocks.purpur_pillar, 0, 2);
		world.setBlock(i + 11, j + 5, k + 19, OtherModBlocks.end_bricks, 0, 2);
		world.setBlock(i + 10, j + 5, k + 20, OtherModBlocks.end_bricks, 0, 2);
		world.setBlock(i + 10, j + 6, k + 1, OtherModBlocks.end_rod, 1, 2);
		world.setBlock(i + 12, j + 6, k + 3, OtherModBlocks.chorus_flower, 0, 2);
		world.setBlock(i + 8, j + 6, k + 4, OtherModBlocks.chorus_flower, 0, 2);
		world.setBlock(i + 6, j + 6, k + 6, OtherModBlocks.chorus_flower, 0, 2);
		world.setBlock(i + 12, j + 6, k + 6, OtherModBlocks.chorus_flower, 0, 2);
		world.setBlock(i + 15, j + 6, k + 6, OtherModBlocks.chorus_flower, 0, 2);
		world.setBlock(i + 5, j + 6, k + 8, OtherModBlocks.chorus_flower, 0, 2);
		world.setBlock(i + 8, j + 6, k + 8, OtherModBlocks.chorus_flower, 0, 2);
		world.setBlock(i + 13, j + 6, k + 8, OtherModBlocks.chorus_flower, 0, 2);
		world.setBlock(i + 15, j + 6, k + 8, OtherModBlocks.chorus_flower, 0, 2);
		world.setBlock(i + 1, j + 6, k + 10, OtherModBlocks.end_rod, 1, 2);
		world.setBlock(i + 10, j + 6, k + 10, OtherModBlocks.end_rod, 1, 2);
		world.setBlock(i + 19, j + 6, k + 10, OtherModBlocks.end_rod, 1, 2);
		world.setBlock(i + 12, j + 6, k + 11, OtherModBlocks.chorus_flower, 0, 2);
		world.setBlock(i + 5, j + 6, k + 12, OtherModBlocks.chorus_flower, 0, 2);
		world.setBlock(i + 8, j + 6, k + 12, OtherModBlocks.chorus_flower, 0, 2);
		world.setBlock(i + 13, j + 6, k + 12, OtherModBlocks.chorus_flower, 0, 2);
		world.setBlock(i + 16, j + 6, k + 12, OtherModBlocks.chorus_flower, 0, 2);
		world.setBlock(i + 5, j + 6, k + 14, OtherModBlocks.chorus_flower, 0, 2);
		world.setBlock(i + 9, j + 6, k + 14, OtherModBlocks.chorus_flower, 0, 2);
		world.setBlock(i + 13, j + 6, k + 14, OtherModBlocks.chorus_flower, 0, 2);
		world.setBlock(i + 7, j + 6, k + 15, OtherModBlocks.chorus_flower, 0, 2);
		world.setBlock(i + 12, j + 6, k + 16, OtherModBlocks.chorus_flower, 0, 2);
		world.setBlock(i + 9, j + 6, k + 17, OtherModBlocks.chorus_flower, 0, 2);
		world.setBlock(i + 10, j + 6, k + 19, OtherModBlocks.end_rod, 1, 2);
    	
    	 return true;
    }

}
