package com.NovaCraft.world.end.endcamp;

import net.minecraft.world.gen.feature.*;
import net.minecraft.block.*;
import net.minecraft.world.*;
import java.util.*;

import com.NovaCraft.registry.OtherModBlocks;
import com.NovaCraftBlocks.NovaCraftBlocks;

import net.minecraft.init.*;

public class EnderSettlementShipBottomGen extends WorldGenerator
{
	public EnderSettlementShipBottomGen() {

	}
    
    public boolean generate(final World world, final Random random, final int i, final int j, final int k) {	

		world.setBlock(i + 15, j + 0, k + 14, Blocks.end_stone, 0, 2);
		world.setBlock(i + 17, j + 0, k + 19, Blocks.end_stone, 0, 2);
		world.setBlock(i + 23, j + 0, k + 20, Blocks.end_stone, 0, 2);
		world.setBlock(i + 17, j + 0, k + 23, Blocks.end_stone, 0, 2);
		world.setBlock(i + 20, j + 1, k + 9, Blocks.end_stone, 0, 2);
		world.setBlock(i + 14, j + 1, k + 14, Blocks.end_stone, 0, 2);
		world.setBlock(i + 15, j + 1, k + 14, Blocks.end_stone, 0, 2);
		world.setBlock(i + 17, j + 1, k + 14, Blocks.end_stone, 0, 2);
		world.setBlock(i + 18, j + 1, k + 14, Blocks.end_stone, 0, 2);
		world.setBlock(i + 19, j + 1, k + 15, Blocks.end_stone, 0, 2);
		world.setBlock(i + 20, j + 1, k + 15, Blocks.end_stone, 0, 2);
		world.setBlock(i + 17, j + 1, k + 19, Blocks.end_stone, 0, 2);
		world.setBlock(i + 15, j + 1, k + 20, Blocks.end_stone, 0, 2);
		world.setBlock(i + 21, j + 1, k + 20, Blocks.end_stone, 0, 2);
		world.setBlock(i + 22, j + 1, k + 20, Blocks.end_stone, 0, 2);
		world.setBlock(i + 23, j + 1, k + 20, Blocks.end_stone, 0, 2);
		world.setBlock(i + 16, j + 1, k + 22, Blocks.end_stone, 0, 2);
		world.setBlock(i + 17, j + 1, k + 23, Blocks.end_stone, 0, 2);
		world.setBlock(i + 17, j + 1, k + 24, Blocks.end_stone, 0, 2);
		world.setBlock(i + 20, j + 2, k + 9, Blocks.end_stone, 0, 2);
		world.setBlock(i + 13, j + 2, k + 11, Blocks.end_stone, 0, 2);
		world.setBlock(i + 13, j + 2, k + 12, Blocks.end_stone, 0, 2);
		world.setBlock(i + 14, j + 2, k + 13, Blocks.end_stone, 0, 2);
		world.setBlock(i + 14, j + 2, k + 14, Blocks.end_stone, 0, 2);
		world.setBlock(i + 15, j + 2, k + 14, Blocks.end_stone, 0, 2);
		world.setBlock(i + 17, j + 2, k + 14, Blocks.end_stone, 0, 2);
		world.setBlock(i + 16, j + 2, k + 15, Blocks.end_stone, 0, 2);
		world.setBlock(i + 19, j + 2, k + 15, Blocks.end_stone, 0, 2);
		world.setBlock(i + 20, j + 2, k + 15, Blocks.end_stone, 0, 2);
		world.setBlock(i + 18, j + 2, k + 17, Blocks.end_stone, 0, 2);
		world.setBlock(i + 22, j + 2, k + 18, Blocks.end_stone, 0, 2);
		world.setBlock(i + 17, j + 2, k + 19, Blocks.end_stone, 0, 2);
		world.setBlock(i + 21, j + 2, k + 19, Blocks.end_stone, 0, 2);
		world.setBlock(i + 12, j + 2, k + 20, Blocks.end_stone, 0, 2);
		world.setBlock(i + 14, j + 2, k + 20, Blocks.end_stone, 0, 2);
		world.setBlock(i + 15, j + 2, k + 20, Blocks.end_stone, 0, 2);
		world.setBlock(i + 20, j + 2, k + 20, Blocks.end_stone, 0, 2);
		world.setBlock(i + 21, j + 2, k + 20, Blocks.end_stone, 0, 2);
		world.setBlock(i + 22, j + 2, k + 20, Blocks.end_stone, 0, 2);
		world.setBlock(i + 15, j + 2, k + 21, Blocks.end_stone, 0, 2);
		world.setBlock(i + 18, j + 2, k + 21, Blocks.end_stone, 0, 2);
		world.setBlock(i + 23, j + 2, k + 21, Blocks.end_stone, 0, 2);
		world.setBlock(i + 16, j + 2, k + 22, Blocks.end_stone, 0, 2);
		world.setBlock(i + 18, j + 2, k + 22, Blocks.end_stone, 0, 2);
		world.setBlock(i + 20, j + 2, k + 22, Blocks.end_stone, 0, 2);
		world.setBlock(i + 17, j + 2, k + 23, Blocks.end_stone, 0, 2);
		world.setBlock(i + 21, j + 2, k + 23, Blocks.end_stone, 0, 2);
		world.setBlock(i + 17, j + 2, k + 24, Blocks.end_stone, 0, 2);
		world.setBlock(i + 22, j + 2, k + 24, Blocks.end_stone, 0, 2);
		world.setBlock(i + 21, j + 2, k + 25, Blocks.end_stone, 0, 2);
		world.setBlock(i + 22, j + 2, k + 25, Blocks.end_stone, 0, 2);
		world.setBlock(i + 14, j + 2, k + 26, Blocks.end_stone, 0, 2);
		world.setBlock(i + 19, j + 2, k + 26, Blocks.end_stone, 0, 2);
		world.setBlock(i + 17, j + 2, k + 27, Blocks.end_stone, 0, 2);
		world.setBlock(i + 21, j + 2, k + 27, Blocks.end_stone, 0, 2);
		world.setBlock(i + 17, j + 2, k + 28, Blocks.end_stone, 0, 2);
		world.setBlock(i + 22, j + 3, k + 5, Blocks.end_stone, 0, 2);
		world.setBlock(i + 14, j + 3, k + 6, Blocks.end_stone, 0, 2);
		world.setBlock(i + 12, j + 3, k + 8, Blocks.end_stone, 0, 2);
		world.setBlock(i + 20, j + 3, k + 8, Blocks.end_stone, 0, 2);
		world.setBlock(i + 26, j + 3, k + 8, Blocks.end_stone, 0, 2);
		world.setBlock(i + 20, j + 3, k + 9, Blocks.end_stone, 0, 2);
		world.setBlock(i + 21, j + 3, k + 9, Blocks.end_stone, 0, 2);
		world.setBlock(i + 8, j + 3, k + 10, Blocks.end_stone, 0, 2);
		world.setBlock(i + 12, j + 3, k + 10, Blocks.end_stone, 0, 2);
		world.setBlock(i + 16, j + 3, k + 10, Blocks.end_stone, 0, 2);
		world.setBlock(i + 17, j + 3, k + 10, Blocks.end_stone, 0, 2);
		world.setBlock(i + 18, j + 3, k + 10, Blocks.end_stone, 0, 2);
		world.setBlock(i + 23, j + 3, k + 10, Blocks.end_stone, 0, 2);
		world.setBlock(i + 11, j + 3, k + 11, Blocks.end_stone, 0, 2);
		world.setBlock(i + 14, j + 3, k + 11, Blocks.end_stone, 0, 2);
		world.setBlock(i + 15, j + 3, k + 11, Blocks.end_stone, 0, 2);
		world.setBlock(i + 16, j + 3, k + 11, Blocks.end_stone, 0, 2);
		world.setBlock(i + 17, j + 3, k + 11, Blocks.end_stone, 0, 2);
		world.setBlock(i + 18, j + 3, k + 11, Blocks.end_stone, 0, 2);
		world.setBlock(i + 19, j + 3, k + 11, Blocks.end_stone, 0, 2);
		world.setBlock(i + 20, j + 3, k + 11, Blocks.end_stone, 0, 2);
		world.setBlock(i + 21, j + 3, k + 11, Blocks.end_stone, 0, 2);
		world.setBlock(i + 22, j + 3, k + 11, Blocks.end_stone, 0, 2);
		world.setBlock(i + 23, j + 3, k + 11, Blocks.end_stone, 0, 2);
		world.setBlock(i + 13, j + 3, k + 12, Blocks.end_stone, 0, 2);
		world.setBlock(i + 14, j + 3, k + 12, Blocks.end_stone, 0, 2);
		world.setBlock(i + 15, j + 3, k + 12, Blocks.end_stone, 0, 2);
		world.setBlock(i + 16, j + 3, k + 12, Blocks.end_stone, 0, 2);
		world.setBlock(i + 17, j + 3, k + 12, Blocks.end_stone, 0, 2);
		world.setBlock(i + 18, j + 3, k + 12, Blocks.end_stone, 0, 2);
		world.setBlock(i + 19, j + 3, k + 12, Blocks.end_stone, 0, 2);
		world.setBlock(i + 20, j + 3, k + 12, Blocks.end_stone, 0, 2);
		world.setBlock(i + 21, j + 3, k + 12, Blocks.end_stone, 0, 2);
		world.setBlock(i + 22, j + 3, k + 12, Blocks.end_stone, 0, 2);
		world.setBlock(i + 23, j + 3, k + 12, Blocks.end_stone, 0, 2);
		world.setBlock(i + 13, j + 3, k + 13, Blocks.end_stone, 0, 2);
		world.setBlock(i + 14, j + 3, k + 13, Blocks.end_stone, 0, 2);
		world.setBlock(i + 15, j + 3, k + 13, Blocks.end_stone, 0, 2);
		world.setBlock(i + 16, j + 3, k + 13, Blocks.end_stone, 0, 2);
		world.setBlock(i + 17, j + 3, k + 13, Blocks.end_stone, 0, 2);
		world.setBlock(i + 18, j + 3, k + 13, Blocks.end_stone, 0, 2);
		world.setBlock(i + 19, j + 3, k + 13, Blocks.end_stone, 0, 2);
		world.setBlock(i + 20, j + 3, k + 13, Blocks.end_stone, 0, 2);
		world.setBlock(i + 21, j + 3, k + 13, Blocks.end_stone, 0, 2);
		world.setBlock(i + 22, j + 3, k + 13, Blocks.end_stone, 0, 2);
		world.setBlock(i + 23, j + 3, k + 13, Blocks.end_stone, 0, 2);
		world.setBlock(i + 14, j + 3, k + 14, Blocks.end_stone, 0, 2);
		world.setBlock(i + 15, j + 3, k + 14, Blocks.end_stone, 0, 2);
		world.setBlock(i + 16, j + 3, k + 14, Blocks.end_stone, 0, 2);
		world.setBlock(i + 17, j + 3, k + 14, Blocks.end_stone, 0, 2);
		world.setBlock(i + 18, j + 3, k + 14, Blocks.end_stone, 0, 2);
		world.setBlock(i + 19, j + 3, k + 14, Blocks.end_stone, 0, 2);
		world.setBlock(i + 20, j + 3, k + 14, Blocks.end_stone, 0, 2);
		world.setBlock(i + 21, j + 3, k + 14, Blocks.end_stone, 0, 2);
		world.setBlock(i + 22, j + 3, k + 14, Blocks.end_stone, 0, 2);
		world.setBlock(i + 23, j + 3, k + 14, Blocks.end_stone, 0, 2);
		world.setBlock(i + 24, j + 3, k + 14, Blocks.end_stone, 0, 2);
		world.setBlock(i + 25, j + 3, k + 14, Blocks.end_stone, 0, 2);
		world.setBlock(i + 6, j + 3, k + 15, Blocks.end_stone, 0, 2);
		world.setBlock(i + 14, j + 3, k + 15, Blocks.end_stone, 0, 2);
		world.setBlock(i + 15, j + 3, k + 15, Blocks.end_stone, 0, 2);
		world.setBlock(i + 16, j + 3, k + 15, Blocks.end_stone, 0, 2);
		world.setBlock(i + 17, j + 3, k + 15, Blocks.end_stone, 0, 2);
		world.setBlock(i + 18, j + 3, k + 15, Blocks.end_stone, 0, 2);
		world.setBlock(i + 19, j + 3, k + 15, Blocks.end_stone, 0, 2);
		world.setBlock(i + 20, j + 3, k + 15, Blocks.end_stone, 0, 2);
		world.setBlock(i + 21, j + 3, k + 15, Blocks.end_stone, 0, 2);
		world.setBlock(i + 22, j + 3, k + 15, Blocks.end_stone, 0, 2);
		world.setBlock(i + 23, j + 3, k + 15, Blocks.end_stone, 0, 2);
		world.setBlock(i + 29, j + 3, k + 15, Blocks.end_stone, 0, 2);
		world.setBlock(i + 13, j + 3, k + 16, Blocks.end_stone, 0, 2);
		world.setBlock(i + 14, j + 3, k + 16, Blocks.end_stone, 0, 2);
		world.setBlock(i + 15, j + 3, k + 16, Blocks.end_stone, 0, 2);
		world.setBlock(i + 16, j + 3, k + 16, Blocks.end_stone, 0, 2);
		world.setBlock(i + 17, j + 3, k + 16, Blocks.end_stone, 0, 2);
		world.setBlock(i + 18, j + 3, k + 16, Blocks.end_stone, 0, 2);
		world.setBlock(i + 19, j + 3, k + 16, Blocks.end_stone, 0, 2);
		world.setBlock(i + 20, j + 3, k + 16, Blocks.end_stone, 0, 2);
		world.setBlock(i + 21, j + 3, k + 16, Blocks.end_stone, 0, 2);
		world.setBlock(i + 22, j + 3, k + 16, Blocks.end_stone, 0, 2);
		world.setBlock(i + 23, j + 3, k + 16, Blocks.end_stone, 0, 2);
		world.setBlock(i + 13, j + 3, k + 17, Blocks.end_stone, 0, 2);
		world.setBlock(i + 14, j + 3, k + 17, Blocks.end_stone, 0, 2);
		world.setBlock(i + 15, j + 3, k + 17, Blocks.end_stone, 0, 2);
		world.setBlock(i + 16, j + 3, k + 17, Blocks.end_stone, 0, 2);
		world.setBlock(i + 17, j + 3, k + 17, Blocks.end_stone, 0, 2);
		world.setBlock(i + 18, j + 3, k + 17, Blocks.end_stone, 0, 2);
		world.setBlock(i + 19, j + 3, k + 17, Blocks.end_stone, 0, 2);
		world.setBlock(i + 20, j + 3, k + 17, Blocks.end_stone, 0, 2);
		world.setBlock(i + 21, j + 3, k + 17, Blocks.end_stone, 0, 2);
		world.setBlock(i + 22, j + 3, k + 17, Blocks.end_stone, 0, 2);
		world.setBlock(i + 23, j + 3, k + 17, Blocks.end_stone, 0, 2);
		world.setBlock(i + 6, j + 3, k + 18, Blocks.end_stone, 0, 2);
		world.setBlock(i + 14, j + 3, k + 18, Blocks.end_stone, 0, 2);
		world.setBlock(i + 15, j + 3, k + 18, Blocks.end_stone, 0, 2);
		world.setBlock(i + 16, j + 3, k + 18, Blocks.end_stone, 0, 2);
		world.setBlock(i + 17, j + 3, k + 18, Blocks.end_stone, 0, 2);
		world.setBlock(i + 18, j + 3, k + 18, Blocks.end_stone, 0, 2);
		world.setBlock(i + 19, j + 3, k + 18, Blocks.end_stone, 0, 2);
		world.setBlock(i + 20, j + 3, k + 18, Blocks.end_stone, 0, 2);
		world.setBlock(i + 21, j + 3, k + 18, Blocks.end_stone, 0, 2);
		world.setBlock(i + 22, j + 3, k + 18, Blocks.end_stone, 0, 2);
		world.setBlock(i + 23, j + 3, k + 18, Blocks.end_stone, 0, 2);
		world.setBlock(i + 7, j + 3, k + 19, Blocks.end_stone, 0, 2);
		world.setBlock(i + 8, j + 3, k + 19, Blocks.end_stone, 0, 2);
		world.setBlock(i + 14, j + 3, k + 19, Blocks.end_stone, 0, 2);
		world.setBlock(i + 15, j + 3, k + 19, Blocks.end_stone, 0, 2);
		world.setBlock(i + 16, j + 3, k + 19, Blocks.end_stone, 0, 2);
		world.setBlock(i + 17, j + 3, k + 19, Blocks.end_stone, 0, 2);
		world.setBlock(i + 18, j + 3, k + 19, Blocks.end_stone, 0, 2);
		world.setBlock(i + 19, j + 3, k + 19, Blocks.end_stone, 0, 2);
		world.setBlock(i + 20, j + 3, k + 19, Blocks.end_stone, 0, 2);
		world.setBlock(i + 21, j + 3, k + 19, Blocks.end_stone, 0, 2);
		world.setBlock(i + 22, j + 3, k + 19, Blocks.end_stone, 0, 2);
		world.setBlock(i + 23, j + 3, k + 19, Blocks.end_stone, 0, 2);
		world.setBlock(i + 24, j + 3, k + 19, Blocks.end_stone, 0, 2);
		world.setBlock(i + 36, j + 3, k + 19, Blocks.end_stone, 0, 2);
		world.setBlock(i + 12, j + 3, k + 20, Blocks.end_stone, 0, 2);
		world.setBlock(i + 14, j + 3, k + 20, Blocks.end_stone, 0, 2);
		world.setBlock(i + 15, j + 3, k + 20, Blocks.end_stone, 0, 2);
		world.setBlock(i + 16, j + 3, k + 20, Blocks.end_stone, 0, 2);
		world.setBlock(i + 17, j + 3, k + 20, Blocks.end_stone, 0, 2);
		world.setBlock(i + 18, j + 3, k + 20, Blocks.end_stone, 0, 2);
		world.setBlock(i + 19, j + 3, k + 20, Blocks.end_stone, 0, 2);
		world.setBlock(i + 20, j + 3, k + 20, Blocks.end_stone, 0, 2);
		world.setBlock(i + 21, j + 3, k + 20, Blocks.end_stone, 0, 2);
		world.setBlock(i + 22, j + 3, k + 20, Blocks.end_stone, 0, 2);
		world.setBlock(i + 23, j + 3, k + 20, Blocks.end_stone, 0, 2);
		world.setBlock(i + 24, j + 3, k + 20, Blocks.end_stone, 0, 2);
		world.setBlock(i + 13, j + 3, k + 21, Blocks.end_stone, 0, 2);
		world.setBlock(i + 14, j + 3, k + 21, Blocks.end_stone, 0, 2);
		world.setBlock(i + 15, j + 3, k + 21, Blocks.end_stone, 0, 2);
		world.setBlock(i + 16, j + 3, k + 21, Blocks.end_stone, 0, 2);
		world.setBlock(i + 17, j + 3, k + 21, Blocks.end_stone, 0, 2);
		world.setBlock(i + 18, j + 3, k + 21, Blocks.end_stone, 0, 2);
		world.setBlock(i + 19, j + 3, k + 21, Blocks.end_stone, 0, 2);
		world.setBlock(i + 20, j + 3, k + 21, Blocks.end_stone, 0, 2);
		world.setBlock(i + 21, j + 3, k + 21, Blocks.end_stone, 0, 2);
		world.setBlock(i + 22, j + 3, k + 21, Blocks.end_stone, 0, 2);
		world.setBlock(i + 23, j + 3, k + 21, Blocks.end_stone, 0, 2);
		world.setBlock(i + 26, j + 3, k + 21, Blocks.end_stone, 0, 2);
		world.setBlock(i + 27, j + 3, k + 21, Blocks.end_stone, 0, 2);
		world.setBlock(i + 14, j + 3, k + 22, Blocks.end_stone, 0, 2);
		world.setBlock(i + 15, j + 3, k + 22, Blocks.end_stone, 0, 2);
		world.setBlock(i + 16, j + 3, k + 22, Blocks.end_stone, 0, 2);
		world.setBlock(i + 17, j + 3, k + 22, Blocks.end_stone, 0, 2);
		world.setBlock(i + 18, j + 3, k + 22, Blocks.end_stone, 0, 2);
		world.setBlock(i + 19, j + 3, k + 22, Blocks.end_stone, 0, 2);
		world.setBlock(i + 20, j + 3, k + 22, Blocks.end_stone, 0, 2);
		world.setBlock(i + 21, j + 3, k + 22, Blocks.end_stone, 0, 2);
		world.setBlock(i + 22, j + 3, k + 22, Blocks.end_stone, 0, 2);
		world.setBlock(i + 23, j + 3, k + 22, Blocks.end_stone, 0, 2);
		world.setBlock(i + 5, j + 3, k + 23, Blocks.end_stone, 0, 2);
		world.setBlock(i + 14, j + 3, k + 23, Blocks.end_stone, 0, 2);
		world.setBlock(i + 15, j + 3, k + 23, Blocks.end_stone, 0, 2);
		world.setBlock(i + 16, j + 3, k + 23, Blocks.end_stone, 0, 2);
		world.setBlock(i + 17, j + 3, k + 23, Blocks.end_stone, 0, 2);
		world.setBlock(i + 18, j + 3, k + 23, Blocks.end_stone, 0, 2);
		world.setBlock(i + 19, j + 3, k + 23, Blocks.end_stone, 0, 2);
		world.setBlock(i + 20, j + 3, k + 23, Blocks.end_stone, 0, 2);
		world.setBlock(i + 21, j + 3, k + 23, Blocks.end_stone, 0, 2);
		world.setBlock(i + 22, j + 3, k + 23, Blocks.end_stone, 0, 2);
		world.setBlock(i + 23, j + 3, k + 23, Blocks.end_stone, 0, 2);
		world.setBlock(i + 33, j + 3, k + 23, Blocks.end_stone, 0, 2);
		world.setBlock(i + 13, j + 3, k + 24, Blocks.end_stone, 0, 2);
		world.setBlock(i + 14, j + 3, k + 24, Blocks.end_stone, 0, 2);
		world.setBlock(i + 15, j + 3, k + 24, Blocks.end_stone, 0, 2);
		world.setBlock(i + 16, j + 3, k + 24, Blocks.end_stone, 0, 2);
		world.setBlock(i + 17, j + 3, k + 24, Blocks.end_stone, 0, 2);
		world.setBlock(i + 18, j + 3, k + 24, Blocks.end_stone, 0, 2);
		world.setBlock(i + 19, j + 3, k + 24, Blocks.end_stone, 0, 2);
		world.setBlock(i + 20, j + 3, k + 24, Blocks.end_stone, 0, 2);
		world.setBlock(i + 21, j + 3, k + 24, Blocks.end_stone, 0, 2);
		world.setBlock(i + 22, j + 3, k + 24, Blocks.end_stone, 0, 2);
		world.setBlock(i + 23, j + 3, k + 24, Blocks.end_stone, 0, 2);
		world.setBlock(i + 14, j + 3, k + 25, Blocks.end_stone, 0, 2);
		world.setBlock(i + 15, j + 3, k + 25, Blocks.end_stone, 0, 2);
		world.setBlock(i + 16, j + 3, k + 25, Blocks.end_stone, 0, 2);
		world.setBlock(i + 17, j + 3, k + 25, Blocks.end_stone, 0, 2);
		world.setBlock(i + 18, j + 3, k + 25, Blocks.end_stone, 0, 2);
		world.setBlock(i + 19, j + 3, k + 25, Blocks.end_stone, 0, 2);
		world.setBlock(i + 20, j + 3, k + 25, Blocks.end_stone, 0, 2);
		world.setBlock(i + 21, j + 3, k + 25, Blocks.end_stone, 0, 2);
		world.setBlock(i + 22, j + 3, k + 25, Blocks.end_stone, 0, 2);
		world.setBlock(i + 23, j + 3, k + 25, Blocks.end_stone, 0, 2);
		world.setBlock(i + 9, j + 3, k + 26, Blocks.end_stone, 0, 2);
		world.setBlock(i + 10, j + 3, k + 26, Blocks.end_stone, 0, 2);
		world.setBlock(i + 13, j + 3, k + 26, Blocks.end_stone, 0, 2);
		world.setBlock(i + 14, j + 3, k + 26, Blocks.end_stone, 0, 2);
		world.setBlock(i + 15, j + 3, k + 26, Blocks.end_stone, 0, 2);
		world.setBlock(i + 16, j + 3, k + 26, Blocks.end_stone, 0, 2);
		world.setBlock(i + 17, j + 3, k + 26, Blocks.end_stone, 0, 2);
		world.setBlock(i + 18, j + 3, k + 26, Blocks.end_stone, 0, 2);
		world.setBlock(i + 19, j + 3, k + 26, Blocks.end_stone, 0, 2);
		world.setBlock(i + 20, j + 3, k + 26, Blocks.end_stone, 0, 2);
		world.setBlock(i + 21, j + 3, k + 26, Blocks.end_stone, 0, 2);
		world.setBlock(i + 22, j + 3, k + 26, Blocks.end_stone, 0, 2);
		world.setBlock(i + 23, j + 3, k + 26, Blocks.end_stone, 0, 2);
		world.setBlock(i + 14, j + 3, k + 27, Blocks.end_stone, 0, 2);
		world.setBlock(i + 15, j + 3, k + 27, Blocks.end_stone, 0, 2);
		world.setBlock(i + 16, j + 3, k + 27, Blocks.end_stone, 0, 2);
		world.setBlock(i + 17, j + 3, k + 27, Blocks.end_stone, 0, 2);
		world.setBlock(i + 18, j + 3, k + 27, Blocks.end_stone, 0, 2);
		world.setBlock(i + 19, j + 3, k + 27, Blocks.end_stone, 0, 2);
		world.setBlock(i + 20, j + 3, k + 27, Blocks.end_stone, 0, 2);
		world.setBlock(i + 21, j + 3, k + 27, Blocks.end_stone, 0, 2);
		world.setBlock(i + 22, j + 3, k + 27, Blocks.end_stone, 0, 2);
		world.setBlock(i + 23, j + 3, k + 27, Blocks.end_stone, 0, 2);
		world.setBlock(i + 14, j + 3, k + 28, Blocks.end_stone, 0, 2);
		world.setBlock(i + 15, j + 3, k + 28, Blocks.end_stone, 0, 2);
		world.setBlock(i + 16, j + 3, k + 28, Blocks.end_stone, 0, 2);
		world.setBlock(i + 17, j + 3, k + 28, Blocks.end_stone, 0, 2);
		world.setBlock(i + 18, j + 3, k + 28, Blocks.end_stone, 0, 2);
		world.setBlock(i + 19, j + 3, k + 28, Blocks.end_stone, 0, 2);
		world.setBlock(i + 20, j + 3, k + 28, Blocks.end_stone, 0, 2);
		world.setBlock(i + 21, j + 3, k + 28, Blocks.end_stone, 0, 2);
		world.setBlock(i + 22, j + 3, k + 28, Blocks.end_stone, 0, 2);
		world.setBlock(i + 23, j + 3, k + 28, Blocks.end_stone, 0, 2);
		world.setBlock(i + 19, j + 4, k + 0, Blocks.end_stone, 0, 2);
		world.setBlock(i + 19, j + 4, k + 1, Blocks.end_stone, 0, 2);
		world.setBlock(i + 18, j + 4, k + 2, Blocks.end_stone, 0, 2);
		world.setBlock(i + 16, j + 4, k + 4, Blocks.end_stone, 0, 2);
		world.setBlock(i + 14, j + 4, k + 5, Blocks.end_stone, 0, 2);
		world.setBlock(i + 19, j + 4, k + 5, Blocks.end_stone, 0, 2);
		world.setBlock(i + 22, j + 4, k + 5, Blocks.end_stone, 0, 2);
		world.setBlock(i + 13, j + 4, k + 6, Blocks.end_stone, 0, 2);
		world.setBlock(i + 14, j + 4, k + 6, Blocks.end_stone, 0, 2);
		world.setBlock(i + 16, j + 4, k + 6, Blocks.end_stone, 0, 2);
		world.setBlock(i + 24, j + 4, k + 6, Blocks.end_stone, 0, 2);
		world.setBlock(i + 14, j + 4, k + 7, Blocks.end_stone, 0, 2);
		world.setBlock(i + 18, j + 4, k + 7, Blocks.end_stone, 0, 2);
		world.setBlock(i + 12, j + 4, k + 8, Blocks.end_stone, 0, 2);
		world.setBlock(i + 21, j + 4, k + 8, Blocks.end_stone, 0, 2);
		world.setBlock(i + 26, j + 4, k + 8, Blocks.end_stone, 0, 2);
		world.setBlock(i + 12, j + 4, k + 9, Blocks.end_stone, 0, 2);
		world.setBlock(i + 13, j + 4, k + 9, Blocks.end_stone, 0, 2);
		world.setBlock(i + 17, j + 4, k + 9, Blocks.end_stone, 0, 2);
		world.setBlock(i + 20, j + 4, k + 9, Blocks.end_stone, 0, 2);
		world.setBlock(i + 21, j + 4, k + 9, Blocks.end_stone, 0, 2);
		world.setBlock(i + 8, j + 4, k + 10, Blocks.end_stone, 0, 2);
		world.setBlock(i + 9, j + 4, k + 10, Blocks.end_stone, 0, 2);
		world.setBlock(i + 10, j + 4, k + 10, Blocks.end_stone, 0, 2);
		world.setBlock(i + 12, j + 4, k + 10, Blocks.end_stone, 0, 2);
		world.setBlock(i + 13, j + 4, k + 10, Blocks.end_stone, 0, 2);
		world.setBlock(i + 14, j + 4, k + 10, Blocks.end_stone, 0, 2);
		world.setBlock(i + 15, j + 4, k + 10, Blocks.end_stone, 0, 2);
		world.setBlock(i + 16, j + 4, k + 10, Blocks.end_stone, 0, 2);
		world.setBlock(i + 17, j + 4, k + 10, Blocks.end_stone, 0, 2);
		world.setBlock(i + 18, j + 4, k + 10, Blocks.end_stone, 0, 2);
		world.setBlock(i + 19, j + 4, k + 10, Blocks.end_stone, 0, 2);
		world.setBlock(i + 20, j + 4, k + 10, Blocks.end_stone, 0, 2);
		world.setBlock(i + 21, j + 4, k + 10, Blocks.end_stone, 0, 2);
		world.setBlock(i + 22, j + 4, k + 10, Blocks.end_stone, 0, 2);
		world.setBlock(i + 23, j + 4, k + 10, Blocks.end_stone, 0, 2);
		world.setBlock(i + 24, j + 4, k + 10, Blocks.end_stone, 0, 2);
		world.setBlock(i + 25, j + 4, k + 10, Blocks.end_stone, 0, 2);
		world.setBlock(i + 11, j + 4, k + 11, Blocks.end_stone, 0, 2);
		world.setBlock(i + 12, j + 4, k + 11, Blocks.end_stone, 0, 2);
		world.setBlock(i + 13, j + 4, k + 11, Blocks.end_stone, 0, 2);
		world.setBlock(i + 14, j + 4, k + 11, Blocks.end_stone, 0, 2);
		world.setBlock(i + 15, j + 4, k + 11, Blocks.end_stone, 0, 2);
		world.setBlock(i + 16, j + 4, k + 11, Blocks.end_stone, 0, 2);
		world.setBlock(i + 17, j + 4, k + 11, Blocks.end_stone, 0, 2);
		world.setBlock(i + 18, j + 4, k + 11, Blocks.end_stone, 0, 2);
		world.setBlock(i + 19, j + 4, k + 11, Blocks.end_stone, 0, 2);
		world.setBlock(i + 20, j + 4, k + 11, Blocks.end_stone, 0, 2);
		world.setBlock(i + 21, j + 4, k + 11, Blocks.end_stone, 0, 2);
		world.setBlock(i + 22, j + 4, k + 11, Blocks.end_stone, 0, 2);
		world.setBlock(i + 23, j + 4, k + 11, Blocks.end_stone, 0, 2);
		world.setBlock(i + 24, j + 4, k + 11, Blocks.end_stone, 0, 2);
		world.setBlock(i + 25, j + 4, k + 11, Blocks.end_stone, 0, 2);
		world.setBlock(i + 13, j + 4, k + 12, Blocks.end_stone, 0, 2);
		world.setBlock(i + 14, j + 4, k + 12, Blocks.end_stone, 0, 2);
		world.setBlock(i + 15, j + 4, k + 12, Blocks.end_stone, 0, 2);
		world.setBlock(i + 16, j + 4, k + 12, Blocks.end_stone, 0, 2);
		world.setBlock(i + 17, j + 4, k + 12, Blocks.end_stone, 0, 2);
		world.setBlock(i + 18, j + 4, k + 12, Blocks.end_stone, 0, 2);
		world.setBlock(i + 19, j + 4, k + 12, Blocks.end_stone, 0, 2);
		world.setBlock(i + 20, j + 4, k + 12, Blocks.end_stone, 0, 2);
		world.setBlock(i + 21, j + 4, k + 12, Blocks.end_stone, 0, 2);
		world.setBlock(i + 22, j + 4, k + 12, Blocks.end_stone, 0, 2);
		world.setBlock(i + 23, j + 4, k + 12, Blocks.end_stone, 0, 2);
		world.setBlock(i + 24, j + 4, k + 12, Blocks.end_stone, 0, 2);
		world.setBlock(i + 25, j + 4, k + 12, Blocks.end_stone, 0, 2);
		world.setBlock(i + 10, j + 4, k + 13, Blocks.end_stone, 0, 2);
		world.setBlock(i + 12, j + 4, k + 13, Blocks.end_stone, 0, 2);
		world.setBlock(i + 13, j + 4, k + 13, Blocks.end_stone, 0, 2);
		world.setBlock(i + 14, j + 4, k + 13, Blocks.end_stone, 0, 2);
		world.setBlock(i + 15, j + 4, k + 13, Blocks.end_stone, 0, 2);
		world.setBlock(i + 16, j + 4, k + 13, Blocks.end_stone, 0, 2);
		world.setBlock(i + 17, j + 4, k + 13, Blocks.end_stone, 0, 2);
		world.setBlock(i + 18, j + 4, k + 13, Blocks.end_stone, 0, 2);
		world.setBlock(i + 19, j + 4, k + 13, Blocks.end_stone, 0, 2);
		world.setBlock(i + 20, j + 4, k + 13, Blocks.end_stone, 0, 2);
		world.setBlock(i + 21, j + 4, k + 13, Blocks.end_stone, 0, 2);
		world.setBlock(i + 22, j + 4, k + 13, Blocks.end_stone, 0, 2);
		world.setBlock(i + 23, j + 4, k + 13, Blocks.end_stone, 0, 2);
		world.setBlock(i + 24, j + 4, k + 13, Blocks.end_stone, 0, 2);
		world.setBlock(i + 7, j + 4, k + 14, Blocks.end_stone, 0, 2);
		world.setBlock(i + 13, j + 4, k + 14, Blocks.end_stone, 0, 2);
		world.setBlock(i + 14, j + 4, k + 14, Blocks.end_stone, 0, 2);
		world.setBlock(i + 15, j + 4, k + 14, Blocks.end_stone, 0, 2);
		world.setBlock(i + 16, j + 4, k + 14, Blocks.end_stone, 0, 2);
		world.setBlock(i + 17, j + 4, k + 14, Blocks.end_stone, 0, 2);
		world.setBlock(i + 18, j + 4, k + 14, Blocks.end_stone, 0, 2);
		world.setBlock(i + 19, j + 4, k + 14, Blocks.end_stone, 0, 2);
		world.setBlock(i + 20, j + 4, k + 14, Blocks.end_stone, 0, 2);
		world.setBlock(i + 21, j + 4, k + 14, Blocks.end_stone, 0, 2);
		world.setBlock(i + 22, j + 4, k + 14, Blocks.end_stone, 0, 2);
		world.setBlock(i + 23, j + 4, k + 14, Blocks.end_stone, 0, 2);
		world.setBlock(i + 24, j + 4, k + 14, Blocks.end_stone, 0, 2);
		world.setBlock(i + 25, j + 4, k + 14, Blocks.end_stone, 0, 2);
		world.setBlock(i + 26, j + 4, k + 14, Blocks.end_stone, 0, 2);
		world.setBlock(i + 6, j + 4, k + 15, Blocks.end_stone, 0, 2);
		world.setBlock(i + 7, j + 4, k + 15, Blocks.end_stone, 0, 2);
		world.setBlock(i + 8, j + 4, k + 15, Blocks.end_stone, 0, 2);
		world.setBlock(i + 13, j + 4, k + 15, Blocks.end_stone, 0, 2);
		world.setBlock(i + 14, j + 4, k + 15, Blocks.end_stone, 0, 2);
		world.setBlock(i + 15, j + 4, k + 15, Blocks.end_stone, 0, 2);
		world.setBlock(i + 16, j + 4, k + 15, Blocks.end_stone, 0, 2);
		world.setBlock(i + 17, j + 4, k + 15, Blocks.end_stone, 0, 2);
		world.setBlock(i + 18, j + 4, k + 15, Blocks.end_stone, 0, 2);
		world.setBlock(i + 19, j + 4, k + 15, Blocks.end_stone, 0, 2);
		world.setBlock(i + 20, j + 4, k + 15, Blocks.end_stone, 0, 2);
		world.setBlock(i + 21, j + 4, k + 15, Blocks.end_stone, 0, 2);
		world.setBlock(i + 22, j + 4, k + 15, Blocks.end_stone, 0, 2);
		world.setBlock(i + 23, j + 4, k + 15, Blocks.end_stone, 0, 2);
		world.setBlock(i + 24, j + 4, k + 15, Blocks.end_stone, 0, 2);
		world.setBlock(i + 25, j + 4, k + 15, Blocks.end_stone, 0, 2);
		world.setBlock(i + 26, j + 4, k + 15, Blocks.end_stone, 0, 2);
		world.setBlock(i + 29, j + 4, k + 15, Blocks.end_stone, 0, 2);
		world.setBlock(i + 10, j + 4, k + 16, Blocks.end_stone, 0, 2);
		world.setBlock(i + 12, j + 4, k + 16, Blocks.end_stone, 0, 2);
		world.setBlock(i + 13, j + 4, k + 16, Blocks.end_stone, 0, 2);
		world.setBlock(i + 14, j + 4, k + 16, Blocks.end_stone, 0, 2);
		world.setBlock(i + 15, j + 4, k + 16, Blocks.end_stone, 0, 2);
		world.setBlock(i + 16, j + 4, k + 16, Blocks.end_stone, 0, 2);
		world.setBlock(i + 17, j + 4, k + 16, Blocks.end_stone, 0, 2);
		world.setBlock(i + 18, j + 4, k + 16, Blocks.end_stone, 0, 2);
		world.setBlock(i + 19, j + 4, k + 16, Blocks.end_stone, 0, 2);
		world.setBlock(i + 20, j + 4, k + 16, Blocks.end_stone, 0, 2);
		world.setBlock(i + 21, j + 4, k + 16, Blocks.end_stone, 0, 2);
		world.setBlock(i + 22, j + 4, k + 16, Blocks.end_stone, 0, 2);
		world.setBlock(i + 23, j + 4, k + 16, Blocks.end_stone, 0, 2);
		world.setBlock(i + 24, j + 4, k + 16, Blocks.end_stone, 0, 2);
		world.setBlock(i + 32, j + 4, k + 16, Blocks.end_stone, 0, 2);
		world.setBlock(i + 13, j + 4, k + 17, Blocks.end_stone, 0, 2);
		world.setBlock(i + 14, j + 4, k + 17, Blocks.end_stone, 0, 2);
		world.setBlock(i + 15, j + 4, k + 17, Blocks.end_stone, 0, 2);
		world.setBlock(i + 16, j + 4, k + 17, Blocks.end_stone, 0, 2);
		world.setBlock(i + 17, j + 4, k + 17, Blocks.end_stone, 0, 2);
		world.setBlock(i + 18, j + 4, k + 17, Blocks.end_stone, 0, 2);
		world.setBlock(i + 19, j + 4, k + 17, Blocks.end_stone, 0, 2);
		world.setBlock(i + 20, j + 4, k + 17, Blocks.end_stone, 0, 2);
		world.setBlock(i + 21, j + 4, k + 17, Blocks.end_stone, 0, 2);
		world.setBlock(i + 22, j + 4, k + 17, Blocks.end_stone, 0, 2);
		world.setBlock(i + 23, j + 4, k + 17, Blocks.end_stone, 0, 2);
		world.setBlock(i + 24, j + 4, k + 17, Blocks.end_stone, 0, 2);
		world.setBlock(i + 25, j + 4, k + 17, Blocks.end_stone, 0, 2);
		world.setBlock(i + 26, j + 4, k + 17, Blocks.end_stone, 0, 2);
		world.setBlock(i + 27, j + 4, k + 17, Blocks.end_stone, 0, 2);
		world.setBlock(i + 5, j + 4, k + 18, Blocks.end_stone, 0, 2);
		world.setBlock(i + 6, j + 4, k + 18, Blocks.end_stone, 0, 2);
		world.setBlock(i + 13, j + 4, k + 18, Blocks.end_stone, 0, 2);
		world.setBlock(i + 14, j + 4, k + 18, Blocks.end_stone, 0, 2);
		world.setBlock(i + 15, j + 4, k + 18, Blocks.end_stone, 0, 2);
		world.setBlock(i + 16, j + 4, k + 18, Blocks.end_stone, 0, 2);
		world.setBlock(i + 17, j + 4, k + 18, Blocks.end_stone, 0, 2);
		world.setBlock(i + 18, j + 4, k + 18, Blocks.end_stone, 0, 2);
		world.setBlock(i + 19, j + 4, k + 18, Blocks.end_stone, 0, 2);
		world.setBlock(i + 20, j + 4, k + 18, Blocks.end_stone, 0, 2);
		world.setBlock(i + 21, j + 4, k + 18, Blocks.end_stone, 0, 2);
		world.setBlock(i + 22, j + 4, k + 18, Blocks.end_stone, 0, 2);
		world.setBlock(i + 23, j + 4, k + 18, Blocks.end_stone, 0, 2);
		world.setBlock(i + 24, j + 4, k + 18, Blocks.end_stone, 0, 2);
		world.setBlock(i + 29, j + 4, k + 18, Blocks.end_stone, 0, 2);
		world.setBlock(i + 32, j + 4, k + 18, Blocks.end_stone, 0, 2);
		world.setBlock(i + 8, j + 4, k + 19, Blocks.end_stone, 0, 2);
		world.setBlock(i + 10, j + 4, k + 19, Blocks.end_stone, 0, 2);
		world.setBlock(i + 13, j + 4, k + 19, Blocks.end_stone, 0, 2);
		world.setBlock(i + 14, j + 4, k + 19, Blocks.end_stone, 0, 2);
		world.setBlock(i + 15, j + 4, k + 19, Blocks.end_stone, 0, 2);
		world.setBlock(i + 16, j + 4, k + 19, Blocks.end_stone, 0, 2);
		world.setBlock(i + 17, j + 4, k + 19, Blocks.end_stone, 0, 2);
		world.setBlock(i + 18, j + 4, k + 19, Blocks.end_stone, 0, 2);
		world.setBlock(i + 19, j + 4, k + 19, Blocks.end_stone, 0, 2);
		world.setBlock(i + 20, j + 4, k + 19, Blocks.end_stone, 0, 2);
		world.setBlock(i + 21, j + 4, k + 19, Blocks.end_stone, 0, 2);
		world.setBlock(i + 22, j + 4, k + 19, Blocks.end_stone, 0, 2);
		world.setBlock(i + 23, j + 4, k + 19, Blocks.end_stone, 0, 2);
		world.setBlock(i + 24, j + 4, k + 19, Blocks.end_stone, 0, 2);
		world.setBlock(i + 36, j + 4, k + 19, Blocks.end_stone, 0, 2);
		world.setBlock(i + 11, j + 4, k + 20, Blocks.end_stone, 0, 2);
		world.setBlock(i + 12, j + 4, k + 20, Blocks.end_stone, 0, 2);
		world.setBlock(i + 13, j + 4, k + 20, Blocks.end_stone, 0, 2);
		world.setBlock(i + 14, j + 4, k + 20, Blocks.end_stone, 0, 2);
		world.setBlock(i + 15, j + 4, k + 20, Blocks.end_stone, 0, 2);
		world.setBlock(i + 16, j + 4, k + 20, Blocks.end_stone, 0, 2);
		world.setBlock(i + 17, j + 4, k + 20, Blocks.end_stone, 0, 2);
		world.setBlock(i + 18, j + 4, k + 20, Blocks.end_stone, 0, 2);
		world.setBlock(i + 19, j + 4, k + 20, Blocks.end_stone, 0, 2);
		world.setBlock(i + 20, j + 4, k + 20, Blocks.end_stone, 0, 2);
		world.setBlock(i + 21, j + 4, k + 20, Blocks.end_stone, 0, 2);
		world.setBlock(i + 22, j + 4, k + 20, Blocks.end_stone, 0, 2);
		world.setBlock(i + 23, j + 4, k + 20, Blocks.end_stone, 0, 2);
		world.setBlock(i + 24, j + 4, k + 20, Blocks.end_stone, 0, 2);
		world.setBlock(i + 25, j + 4, k + 20, Blocks.end_stone, 0, 2);
		world.setBlock(i + 29, j + 4, k + 20, Blocks.end_stone, 0, 2);
		world.setBlock(i + 33, j + 4, k + 20, Blocks.end_stone, 0, 2);
		world.setBlock(i + 2, j + 4, k + 21, Blocks.end_stone, 0, 2);
		world.setBlock(i + 13, j + 4, k + 21, Blocks.end_stone, 0, 2);
		world.setBlock(i + 14, j + 4, k + 21, Blocks.end_stone, 0, 2);
		world.setBlock(i + 15, j + 4, k + 21, Blocks.end_stone, 0, 2);
		world.setBlock(i + 16, j + 4, k + 21, Blocks.end_stone, 0, 2);
		world.setBlock(i + 17, j + 4, k + 21, Blocks.end_stone, 0, 2);
		world.setBlock(i + 18, j + 4, k + 21, Blocks.end_stone, 0, 2);
		world.setBlock(i + 19, j + 4, k + 21, Blocks.end_stone, 0, 2);
		world.setBlock(i + 20, j + 4, k + 21, Blocks.end_stone, 0, 2);
		world.setBlock(i + 21, j + 4, k + 21, Blocks.end_stone, 0, 2);
		world.setBlock(i + 22, j + 4, k + 21, Blocks.end_stone, 0, 2);
		world.setBlock(i + 23, j + 4, k + 21, Blocks.end_stone, 0, 2);
		world.setBlock(i + 24, j + 4, k + 21, Blocks.end_stone, 0, 2);
		world.setBlock(i + 26, j + 4, k + 21, Blocks.end_stone, 0, 2);
		world.setBlock(i + 27, j + 4, k + 21, Blocks.end_stone, 0, 2);
		world.setBlock(i + 5, j + 4, k + 22, Blocks.end_stone, 0, 2);
		world.setBlock(i + 9, j + 4, k + 22, Blocks.end_stone, 0, 2);
		world.setBlock(i + 13, j + 4, k + 22, Blocks.end_stone, 0, 2);
		world.setBlock(i + 14, j + 4, k + 22, Blocks.end_stone, 0, 2);
		world.setBlock(i + 15, j + 4, k + 22, Blocks.end_stone, 0, 2);
		world.setBlock(i + 16, j + 4, k + 22, Blocks.end_stone, 0, 2);
		world.setBlock(i + 17, j + 4, k + 22, Blocks.end_stone, 0, 2);
		world.setBlock(i + 18, j + 4, k + 22, Blocks.end_stone, 0, 2);
		world.setBlock(i + 19, j + 4, k + 22, Blocks.end_stone, 0, 2);
		world.setBlock(i + 20, j + 4, k + 22, Blocks.end_stone, 0, 2);
		world.setBlock(i + 21, j + 4, k + 22, Blocks.end_stone, 0, 2);
		world.setBlock(i + 22, j + 4, k + 22, Blocks.end_stone, 0, 2);
		world.setBlock(i + 23, j + 4, k + 22, Blocks.end_stone, 0, 2);
		world.setBlock(i + 24, j + 4, k + 22, Blocks.end_stone, 0, 2);
		world.setBlock(i + 5, j + 4, k + 23, Blocks.end_stone, 0, 2);
		world.setBlock(i + 11, j + 4, k + 23, Blocks.end_stone, 0, 2);
		world.setBlock(i + 13, j + 4, k + 23, Blocks.end_stone, 0, 2);
		world.setBlock(i + 14, j + 4, k + 23, Blocks.end_stone, 0, 2);
		world.setBlock(i + 15, j + 4, k + 23, Blocks.end_stone, 0, 2);
		world.setBlock(i + 16, j + 4, k + 23, Blocks.end_stone, 0, 2);
		world.setBlock(i + 17, j + 4, k + 23, Blocks.end_stone, 0, 2);
		world.setBlock(i + 18, j + 4, k + 23, Blocks.end_stone, 0, 2);
		world.setBlock(i + 19, j + 4, k + 23, Blocks.end_stone, 0, 2);
		world.setBlock(i + 20, j + 4, k + 23, Blocks.end_stone, 0, 2);
		world.setBlock(i + 21, j + 4, k + 23, Blocks.end_stone, 0, 2);
		world.setBlock(i + 22, j + 4, k + 23, Blocks.end_stone, 0, 2);
		world.setBlock(i + 23, j + 4, k + 23, Blocks.end_stone, 0, 2);
		world.setBlock(i + 24, j + 4, k + 23, Blocks.end_stone, 0, 2);
		world.setBlock(i + 25, j + 4, k + 23, Blocks.end_stone, 0, 2);
		world.setBlock(i + 26, j + 4, k + 23, Blocks.end_stone, 0, 2);
		world.setBlock(i + 27, j + 4, k + 23, Blocks.end_stone, 0, 2);
		world.setBlock(i + 33, j + 4, k + 23, Blocks.end_stone, 0, 2);
		world.setBlock(i + 12, j + 4, k + 24, Blocks.end_stone, 0, 2);
		world.setBlock(i + 13, j + 4, k + 24, Blocks.end_stone, 0, 2);
		world.setBlock(i + 14, j + 4, k + 24, Blocks.end_stone, 0, 2);
		world.setBlock(i + 15, j + 4, k + 24, Blocks.end_stone, 0, 2);
		world.setBlock(i + 16, j + 4, k + 24, Blocks.end_stone, 0, 2);
		world.setBlock(i + 17, j + 4, k + 24, Blocks.end_stone, 0, 2);
		world.setBlock(i + 18, j + 4, k + 24, Blocks.end_stone, 0, 2);
		world.setBlock(i + 19, j + 4, k + 24, Blocks.end_stone, 0, 2);
		world.setBlock(i + 20, j + 4, k + 24, Blocks.end_stone, 0, 2);
		world.setBlock(i + 21, j + 4, k + 24, Blocks.end_stone, 0, 2);
		world.setBlock(i + 22, j + 4, k + 24, Blocks.end_stone, 0, 2);
		world.setBlock(i + 23, j + 4, k + 24, Blocks.end_stone, 0, 2);
		world.setBlock(i + 24, j + 4, k + 24, Blocks.end_stone, 0, 2);
		world.setBlock(i + 5, j + 4, k + 25, Blocks.end_stone, 0, 2);
		world.setBlock(i + 6, j + 4, k + 25, Blocks.end_stone, 0, 2);
		world.setBlock(i + 7, j + 4, k + 25, Blocks.end_stone, 0, 2);
		world.setBlock(i + 11, j + 4, k + 25, Blocks.end_stone, 0, 2);
		world.setBlock(i + 13, j + 4, k + 25, Blocks.end_stone, 0, 2);
		world.setBlock(i + 14, j + 4, k + 25, Blocks.end_stone, 0, 2);
		world.setBlock(i + 15, j + 4, k + 25, Blocks.end_stone, 0, 2);
		world.setBlock(i + 16, j + 4, k + 25, Blocks.end_stone, 0, 2);
		world.setBlock(i + 17, j + 4, k + 25, Blocks.end_stone, 0, 2);
		world.setBlock(i + 18, j + 4, k + 25, Blocks.end_stone, 0, 2);
		world.setBlock(i + 19, j + 4, k + 25, Blocks.end_stone, 0, 2);
		world.setBlock(i + 20, j + 4, k + 25, Blocks.end_stone, 0, 2);
		world.setBlock(i + 21, j + 4, k + 25, Blocks.end_stone, 0, 2);
		world.setBlock(i + 22, j + 4, k + 25, Blocks.end_stone, 0, 2);
		world.setBlock(i + 23, j + 4, k + 25, Blocks.end_stone, 0, 2);
		world.setBlock(i + 24, j + 4, k + 25, Blocks.end_stone, 0, 2);
		world.setBlock(i + 29, j + 4, k + 25, Blocks.end_stone, 0, 2);
		world.setBlock(i + 10, j + 4, k + 26, Blocks.end_stone, 0, 2);
		world.setBlock(i + 11, j + 4, k + 26, Blocks.end_stone, 0, 2);
		world.setBlock(i + 12, j + 4, k + 26, Blocks.end_stone, 0, 2);
		world.setBlock(i + 13, j + 4, k + 26, Blocks.end_stone, 0, 2);
		world.setBlock(i + 14, j + 4, k + 26, Blocks.end_stone, 0, 2);
		world.setBlock(i + 15, j + 4, k + 26, Blocks.end_stone, 0, 2);
		world.setBlock(i + 16, j + 4, k + 26, Blocks.end_stone, 0, 2);
		world.setBlock(i + 17, j + 4, k + 26, Blocks.end_stone, 0, 2);
		world.setBlock(i + 18, j + 4, k + 26, Blocks.end_stone, 0, 2);
		world.setBlock(i + 19, j + 4, k + 26, Blocks.end_stone, 0, 2);
		world.setBlock(i + 20, j + 4, k + 26, Blocks.end_stone, 0, 2);
		world.setBlock(i + 21, j + 4, k + 26, Blocks.end_stone, 0, 2);
		world.setBlock(i + 22, j + 4, k + 26, Blocks.end_stone, 0, 2);
		world.setBlock(i + 23, j + 4, k + 26, Blocks.end_stone, 0, 2);
		world.setBlock(i + 24, j + 4, k + 26, Blocks.end_stone, 0, 2);
		world.setBlock(i + 25, j + 4, k + 26, Blocks.end_stone, 0, 2);
		world.setBlock(i + 29, j + 4, k + 26, Blocks.end_stone, 0, 2);
		world.setBlock(i + 30, j + 4, k + 26, Blocks.end_stone, 0, 2);
		world.setBlock(i + 10, j + 4, k + 27, Blocks.end_stone, 0, 2);
		world.setBlock(i + 13, j + 4, k + 27, Blocks.end_stone, 0, 2);
		world.setBlock(i + 14, j + 4, k + 27, Blocks.end_stone, 0, 2);
		world.setBlock(i + 15, j + 4, k + 27, Blocks.end_stone, 0, 2);
		world.setBlock(i + 16, j + 4, k + 27, Blocks.end_stone, 0, 2);
		world.setBlock(i + 17, j + 4, k + 27, Blocks.end_stone, 0, 2);
		world.setBlock(i + 18, j + 4, k + 27, Blocks.end_stone, 0, 2);
		world.setBlock(i + 19, j + 4, k + 27, Blocks.end_stone, 0, 2);
		world.setBlock(i + 20, j + 4, k + 27, Blocks.end_stone, 0, 2);
		world.setBlock(i + 21, j + 4, k + 27, Blocks.end_stone, 0, 2);
		world.setBlock(i + 22, j + 4, k + 27, Blocks.end_stone, 0, 2);
		world.setBlock(i + 23, j + 4, k + 27, Blocks.end_stone, 0, 2);
		world.setBlock(i + 24, j + 4, k + 27, Blocks.end_stone, 0, 2);
		world.setBlock(i + 25, j + 4, k + 27, Blocks.end_stone, 0, 2);
		world.setBlock(i + 26, j + 4, k + 27, Blocks.end_stone, 0, 2);
		world.setBlock(i + 27, j + 4, k + 27, Blocks.end_stone, 0, 2);
		world.setBlock(i + 13, j + 4, k + 28, Blocks.end_stone, 0, 2);
		world.setBlock(i + 14, j + 4, k + 28, Blocks.end_stone, 0, 2);
		world.setBlock(i + 15, j + 4, k + 28, Blocks.end_stone, 0, 2);
		world.setBlock(i + 16, j + 4, k + 28, Blocks.end_stone, 0, 2);
		world.setBlock(i + 17, j + 4, k + 28, Blocks.end_stone, 0, 2);
		world.setBlock(i + 18, j + 4, k + 28, Blocks.end_stone, 0, 2);
		world.setBlock(i + 19, j + 4, k + 28, Blocks.end_stone, 0, 2);
		world.setBlock(i + 20, j + 4, k + 28, Blocks.end_stone, 0, 2);
		world.setBlock(i + 21, j + 4, k + 28, Blocks.end_stone, 0, 2);
		world.setBlock(i + 22, j + 4, k + 28, Blocks.end_stone, 0, 2);
		world.setBlock(i + 23, j + 4, k + 28, Blocks.end_stone, 0, 2);
		world.setBlock(i + 24, j + 4, k + 28, Blocks.end_stone, 0, 2);
		world.setBlock(i + 28, j + 4, k + 28, Blocks.end_stone, 0, 2);
		world.setBlock(i + 12, j + 4, k + 29, Blocks.end_stone, 0, 2);
		world.setBlock(i + 13, j + 4, k + 29, Blocks.end_stone, 0, 2);
		world.setBlock(i + 14, j + 4, k + 29, Blocks.end_stone, 0, 2);
		world.setBlock(i + 15, j + 4, k + 29, Blocks.end_stone, 0, 2);
		world.setBlock(i + 16, j + 4, k + 29, Blocks.end_stone, 0, 2);
		world.setBlock(i + 17, j + 4, k + 29, Blocks.end_stone, 0, 2);
		world.setBlock(i + 18, j + 4, k + 29, Blocks.end_stone, 0, 2);
		world.setBlock(i + 19, j + 4, k + 29, Blocks.end_stone, 0, 2);
		world.setBlock(i + 20, j + 4, k + 29, Blocks.end_stone, 0, 2);
		world.setBlock(i + 21, j + 4, k + 29, Blocks.end_stone, 0, 2);
		world.setBlock(i + 22, j + 4, k + 29, Blocks.end_stone, 0, 2);
		world.setBlock(i + 23, j + 4, k + 29, Blocks.end_stone, 0, 2);
		world.setBlock(i + 24, j + 4, k + 29, Blocks.end_stone, 0, 2);
		world.setBlock(i + 29, j + 4, k + 29, Blocks.end_stone, 0, 2);
		world.setBlock(i + 21, j + 4, k + 30, Blocks.end_stone, 0, 2);
		world.setBlock(i + 24, j + 4, k + 30, Blocks.end_stone, 0, 2);
		world.setBlock(i + 25, j + 4, k + 30, Blocks.end_stone, 0, 2);
		world.setBlock(i + 10, j + 4, k + 31, Blocks.end_stone, 0, 2);
		world.setBlock(i + 24, j + 4, k + 31, Blocks.end_stone, 0, 2);
		world.setBlock(i + 19, j + 5, k + 1, Blocks.end_stone, 0, 2);
		world.setBlock(i + 18, j + 5, k + 2, Blocks.end_stone, 0, 2);
		world.setBlock(i + 20, j + 5, k + 2, Blocks.end_stone, 0, 2);
		world.setBlock(i + 21, j + 5, k + 2, Blocks.end_stone, 0, 2);
		world.setBlock(i + 16, j + 5, k + 4, Blocks.end_stone, 0, 2);
		world.setBlock(i + 18, j + 5, k + 4, Blocks.end_stone, 0, 2);
		world.setBlock(i + 19, j + 5, k + 4, Blocks.end_stone, 0, 2);
		world.setBlock(i + 15, j + 5, k + 5, Blocks.end_stone, 0, 2);
		world.setBlock(i + 16, j + 5, k + 5, Blocks.end_stone, 0, 2);
		world.setBlock(i + 19, j + 5, k + 5, Blocks.end_stone, 0, 2);
		world.setBlock(i + 20, j + 5, k + 5, Blocks.end_stone, 0, 2);
		world.setBlock(i + 22, j + 5, k + 5, Blocks.end_stone, 0, 2);
		world.setBlock(i + 14, j + 5, k + 6, Blocks.end_stone, 0, 2);
		world.setBlock(i + 15, j + 5, k + 6, Blocks.end_stone, 0, 2);
		world.setBlock(i + 16, j + 5, k + 6, Blocks.end_stone, 0, 2);
		world.setBlock(i + 17, j + 5, k + 6, Blocks.end_stone, 0, 2);
		world.setBlock(i + 24, j + 5, k + 6, Blocks.end_stone, 0, 2);
		world.setBlock(i + 17, j + 5, k + 7, Blocks.end_stone, 0, 2);
		world.setBlock(i + 18, j + 5, k + 7, Blocks.end_stone, 0, 2);
		world.setBlock(i + 22, j + 5, k + 7, Blocks.end_stone, 0, 2);
		world.setBlock(i + 12, j + 5, k + 8, Blocks.end_stone, 0, 2);
		world.setBlock(i + 15, j + 5, k + 8, Blocks.end_stone, 0, 2);
		world.setBlock(i + 19, j + 5, k + 8, Blocks.end_stone, 0, 2);
		world.setBlock(i + 20, j + 5, k + 8, Blocks.end_stone, 0, 2);
		world.setBlock(i + 21, j + 5, k + 8, Blocks.end_stone, 0, 2);
		world.setBlock(i + 23, j + 5, k + 8, Blocks.end_stone, 0, 2);
		world.setBlock(i + 26, j + 5, k + 8, Blocks.end_stone, 0, 2);
		world.setBlock(i + 11, j + 5, k + 9, Blocks.end_stone, 0, 2);
		world.setBlock(i + 12, j + 5, k + 9, Blocks.end_stone, 0, 2);
		world.setBlock(i + 13, j + 5, k + 9, Blocks.end_stone, 0, 2);
		world.setBlock(i + 14, j + 5, k + 9, Blocks.end_stone, 0, 2);
		world.setBlock(i + 15, j + 5, k + 9, Blocks.end_stone, 0, 2);
		world.setBlock(i + 16, j + 5, k + 9, Blocks.end_stone, 0, 2);
		world.setBlock(i + 17, j + 5, k + 9, Blocks.end_stone, 0, 2);
		world.setBlock(i + 18, j + 5, k + 9, Blocks.end_stone, 0, 2);
		world.setBlock(i + 19, j + 5, k + 9, Blocks.end_stone, 0, 2);
		world.setBlock(i + 20, j + 5, k + 9, Blocks.end_stone, 0, 2);
		world.setBlock(i + 21, j + 5, k + 9, Blocks.end_stone, 0, 2);
		world.setBlock(i + 22, j + 5, k + 9, Blocks.end_stone, 0, 2);
		world.setBlock(i + 23, j + 5, k + 9, Blocks.end_stone, 0, 2);
		world.setBlock(i + 24, j + 5, k + 9, Blocks.end_stone, 0, 2);
		world.setBlock(i + 25, j + 5, k + 9, Blocks.end_stone, 0, 2);
		world.setBlock(i + 26, j + 5, k + 9, Blocks.end_stone, 0, 2);
		world.setBlock(i + 8, j + 5, k + 10, Blocks.end_stone, 0, 2);
		world.setBlock(i + 9, j + 5, k + 10, Blocks.end_stone, 0, 2);
		world.setBlock(i + 10, j + 5, k + 10, Blocks.end_stone, 0, 2);
		world.setBlock(i + 11, j + 5, k + 10, Blocks.end_stone, 0, 2);
		world.setBlock(i + 12, j + 5, k + 10, Blocks.end_stone, 0, 2);
		world.setBlock(i + 13, j + 5, k + 10, Blocks.end_stone, 0, 2);
		world.setBlock(i + 14, j + 5, k + 10, Blocks.end_stone, 0, 2);
		world.setBlock(i + 15, j + 5, k + 10, Blocks.end_stone, 0, 2);
		world.setBlock(i + 16, j + 5, k + 10, Blocks.end_stone, 0, 2);
		world.setBlock(i + 17, j + 5, k + 10, Blocks.end_stone, 0, 2);
		world.setBlock(i + 18, j + 5, k + 10, Blocks.end_stone, 0, 2);
		world.setBlock(i + 19, j + 5, k + 10, Blocks.end_stone, 0, 2);
		world.setBlock(i + 20, j + 5, k + 10, Blocks.end_stone, 0, 2);
		world.setBlock(i + 21, j + 5, k + 10, Blocks.end_stone, 0, 2);
		world.setBlock(i + 22, j + 5, k + 10, Blocks.end_stone, 0, 2);
		world.setBlock(i + 23, j + 5, k + 10, Blocks.end_stone, 0, 2);
		world.setBlock(i + 24, j + 5, k + 10, Blocks.end_stone, 0, 2);
		world.setBlock(i + 25, j + 5, k + 10, Blocks.end_stone, 0, 2);
		world.setBlock(i + 26, j + 5, k + 10, Blocks.end_stone, 0, 2);
		world.setBlock(i + 9, j + 5, k + 11, Blocks.end_stone, 0, 2);
		world.setBlock(i + 11, j + 5, k + 11, Blocks.end_stone, 0, 2);
		world.setBlock(i + 12, j + 5, k + 11, Blocks.end_stone, 0, 2);
		world.setBlock(i + 13, j + 5, k + 11, Blocks.end_stone, 0, 2);
		world.setBlock(i + 14, j + 5, k + 11, Blocks.end_stone, 0, 2);
		world.setBlock(i + 15, j + 5, k + 11, Blocks.end_stone, 0, 2);
		world.setBlock(i + 16, j + 5, k + 11, Blocks.end_stone, 0, 2);
		world.setBlock(i + 17, j + 5, k + 11, Blocks.end_stone, 0, 2);
		world.setBlock(i + 18, j + 5, k + 11, Blocks.end_stone, 0, 2);
		world.setBlock(i + 19, j + 5, k + 11, Blocks.end_stone, 0, 2);
		world.setBlock(i + 20, j + 5, k + 11, Blocks.end_stone, 0, 2);
		world.setBlock(i + 21, j + 5, k + 11, Blocks.end_stone, 0, 2);
		world.setBlock(i + 22, j + 5, k + 11, Blocks.end_stone, 0, 2);
		world.setBlock(i + 23, j + 5, k + 11, Blocks.end_stone, 0, 2);
		world.setBlock(i + 24, j + 5, k + 11, Blocks.end_stone, 0, 2);
		world.setBlock(i + 25, j + 5, k + 11, Blocks.end_stone, 0, 2);
		world.setBlock(i + 30, j + 5, k + 11, Blocks.end_stone, 0, 2);
		world.setBlock(i + 8, j + 5, k + 12, Blocks.end_stone, 0, 2);
		world.setBlock(i + 12, j + 5, k + 12, Blocks.end_stone, 0, 2);
		world.setBlock(i + 13, j + 5, k + 12, Blocks.end_stone, 0, 2);
		world.setBlock(i + 14, j + 5, k + 12, Blocks.end_stone, 0, 2);
		world.setBlock(i + 15, j + 5, k + 12, Blocks.end_stone, 0, 2);
		world.setBlock(i + 16, j + 5, k + 12, Blocks.end_stone, 0, 2);
		world.setBlock(i + 17, j + 5, k + 12, Blocks.end_stone, 0, 2);
		world.setBlock(i + 18, j + 5, k + 12, Blocks.end_stone, 0, 2);
		world.setBlock(i + 19, j + 5, k + 12, Blocks.end_stone, 0, 2);
		world.setBlock(i + 20, j + 5, k + 12, Blocks.end_stone, 0, 2);
		world.setBlock(i + 21, j + 5, k + 12, Blocks.end_stone, 0, 2);
		world.setBlock(i + 22, j + 5, k + 12, Blocks.end_stone, 0, 2);
		world.setBlock(i + 23, j + 5, k + 12, Blocks.end_stone, 0, 2);
		world.setBlock(i + 24, j + 5, k + 12, Blocks.end_stone, 0, 2);
		world.setBlock(i + 25, j + 5, k + 12, Blocks.end_stone, 0, 2);
		world.setBlock(i + 10, j + 5, k + 13, Blocks.end_stone, 0, 2);
		world.setBlock(i + 12, j + 5, k + 13, Blocks.end_stone, 0, 2);
		world.setBlock(i + 13, j + 5, k + 13, Blocks.end_stone, 0, 2);
		world.setBlock(i + 14, j + 5, k + 13, Blocks.end_stone, 0, 2);
		world.setBlock(i + 15, j + 5, k + 13, Blocks.end_stone, 0, 2);
		world.setBlock(i + 16, j + 5, k + 13, Blocks.end_stone, 0, 2);
		world.setBlock(i + 17, j + 5, k + 13, Blocks.end_stone, 0, 2);
		world.setBlock(i + 18, j + 5, k + 13, Blocks.end_stone, 0, 2);
		world.setBlock(i + 19, j + 5, k + 13, Blocks.end_stone, 0, 2);
		world.setBlock(i + 20, j + 5, k + 13, Blocks.end_stone, 0, 2);
		world.setBlock(i + 21, j + 5, k + 13, Blocks.end_stone, 0, 2);
		world.setBlock(i + 22, j + 5, k + 13, Blocks.end_stone, 0, 2);
		world.setBlock(i + 23, j + 5, k + 13, Blocks.end_stone, 0, 2);
		world.setBlock(i + 24, j + 5, k + 13, Blocks.end_stone, 0, 2);
		world.setBlock(i + 25, j + 5, k + 13, Blocks.end_stone, 0, 2);
		world.setBlock(i + 27, j + 5, k + 13, Blocks.end_stone, 0, 2);
		world.setBlock(i + 28, j + 5, k + 13, Blocks.end_stone, 0, 2);
		world.setBlock(i + 29, j + 5, k + 13, Blocks.end_stone, 0, 2);
		world.setBlock(i + 30, j + 5, k + 13, Blocks.end_stone, 0, 2);
		world.setBlock(i + 6, j + 5, k + 14, Blocks.end_stone, 0, 2);
		world.setBlock(i + 7, j + 5, k + 14, Blocks.end_stone, 0, 2);
		world.setBlock(i + 11, j + 5, k + 14, Blocks.end_stone, 0, 2);
		world.setBlock(i + 12, j + 5, k + 14, Blocks.end_stone, 0, 2);
		world.setBlock(i + 13, j + 5, k + 14, Blocks.end_stone, 0, 2);
		world.setBlock(i + 14, j + 5, k + 14, Blocks.end_stone, 0, 2);
		world.setBlock(i + 15, j + 5, k + 14, Blocks.end_stone, 0, 2);
		world.setBlock(i + 16, j + 5, k + 14, Blocks.end_stone, 0, 2);
		world.setBlock(i + 17, j + 5, k + 14, Blocks.end_stone, 0, 2);
		world.setBlock(i + 18, j + 5, k + 14, Blocks.end_stone, 0, 2);
		world.setBlock(i + 19, j + 5, k + 14, Blocks.end_stone, 0, 2);
		world.setBlock(i + 20, j + 5, k + 14, Blocks.end_stone, 0, 2);
		world.setBlock(i + 21, j + 5, k + 14, Blocks.end_stone, 0, 2);
		world.setBlock(i + 22, j + 5, k + 14, Blocks.end_stone, 0, 2);
		world.setBlock(i + 23, j + 5, k + 14, Blocks.end_stone, 0, 2);
		world.setBlock(i + 24, j + 5, k + 14, Blocks.end_stone, 0, 2);
		world.setBlock(i + 25, j + 5, k + 14, Blocks.end_stone, 0, 2);
		world.setBlock(i + 32, j + 5, k + 14, Blocks.end_stone, 0, 2);
		world.setBlock(i + 33, j + 5, k + 14, Blocks.end_stone, 0, 2);
		world.setBlock(i + 6, j + 5, k + 15, Blocks.end_stone, 0, 2);
		world.setBlock(i + 8, j + 5, k + 15, Blocks.end_stone, 0, 2);
		world.setBlock(i + 12, j + 5, k + 15, Blocks.end_stone, 0, 2);
		world.setBlock(i + 13, j + 5, k + 15, Blocks.end_stone, 0, 2);
		world.setBlock(i + 14, j + 5, k + 15, Blocks.end_stone, 0, 2);
		world.setBlock(i + 15, j + 5, k + 15, Blocks.end_stone, 0, 2);
		world.setBlock(i + 16, j + 5, k + 15, Blocks.end_stone, 0, 2);
		world.setBlock(i + 17, j + 5, k + 15, Blocks.end_stone, 0, 2);
		world.setBlock(i + 18, j + 5, k + 15, Blocks.end_stone, 0, 2);
		world.setBlock(i + 19, j + 5, k + 15, Blocks.end_stone, 0, 2);
		world.setBlock(i + 20, j + 5, k + 15, Blocks.end_stone, 0, 2);
		world.setBlock(i + 21, j + 5, k + 15, Blocks.end_stone, 0, 2);
		world.setBlock(i + 22, j + 5, k + 15, Blocks.end_stone, 0, 2);
		world.setBlock(i + 23, j + 5, k + 15, Blocks.end_stone, 0, 2);
		world.setBlock(i + 24, j + 5, k + 15, Blocks.end_stone, 0, 2);
		world.setBlock(i + 25, j + 5, k + 15, Blocks.end_stone, 0, 2);
		world.setBlock(i + 26, j + 5, k + 15, Blocks.end_stone, 0, 2);
		world.setBlock(i + 27, j + 5, k + 15, Blocks.end_stone, 0, 2);
		world.setBlock(i + 29, j + 5, k + 15, Blocks.end_stone, 0, 2);
		world.setBlock(i + 30, j + 5, k + 15, Blocks.end_stone, 0, 2);
		world.setBlock(i + 31, j + 5, k + 15, Blocks.end_stone, 0, 2);
		world.setBlock(i + 4, j + 5, k + 16, Blocks.end_stone, 0, 2);
		world.setBlock(i + 5, j + 5, k + 16, Blocks.end_stone, 0, 2);
		world.setBlock(i + 9, j + 5, k + 16, Blocks.end_stone, 0, 2);
		world.setBlock(i + 10, j + 5, k + 16, Blocks.end_stone, 0, 2);
		world.setBlock(i + 12, j + 5, k + 16, Blocks.end_stone, 0, 2);
		world.setBlock(i + 13, j + 5, k + 16, Blocks.end_stone, 0, 2);
		world.setBlock(i + 14, j + 5, k + 16, Blocks.end_stone, 0, 2);
		world.setBlock(i + 15, j + 5, k + 16, Blocks.end_stone, 0, 2);
		world.setBlock(i + 16, j + 5, k + 16, Blocks.end_stone, 0, 2);
		world.setBlock(i + 17, j + 5, k + 16, Blocks.end_stone, 0, 2);
		world.setBlock(i + 18, j + 5, k + 16, Blocks.end_stone, 0, 2);
		world.setBlock(i + 19, j + 5, k + 16, Blocks.end_stone, 0, 2);
		world.setBlock(i + 20, j + 5, k + 16, Blocks.end_stone, 0, 2);
		world.setBlock(i + 21, j + 5, k + 16, Blocks.end_stone, 0, 2);
		world.setBlock(i + 22, j + 5, k + 16, Blocks.end_stone, 0, 2);
		world.setBlock(i + 23, j + 5, k + 16, Blocks.end_stone, 0, 2);
		world.setBlock(i + 24, j + 5, k + 16, Blocks.end_stone, 0, 2);
		world.setBlock(i + 25, j + 5, k + 16, Blocks.end_stone, 0, 2);
		world.setBlock(i + 28, j + 5, k + 16, Blocks.end_stone, 0, 2);
		world.setBlock(i + 30, j + 5, k + 16, Blocks.end_stone, 0, 2);
		world.setBlock(i + 31, j + 5, k + 16, Blocks.end_stone, 0, 2);
		world.setBlock(i + 32, j + 5, k + 16, Blocks.end_stone, 0, 2);
		world.setBlock(i + 2, j + 5, k + 17, Blocks.end_stone, 0, 2);
		world.setBlock(i + 6, j + 5, k + 17, Blocks.end_stone, 0, 2);
		world.setBlock(i + 9, j + 5, k + 17, Blocks.end_stone, 0, 2);
		world.setBlock(i + 11, j + 5, k + 17, Blocks.end_stone, 0, 2);
		world.setBlock(i + 12, j + 5, k + 17, Blocks.end_stone, 0, 2);
		world.setBlock(i + 13, j + 5, k + 17, Blocks.end_stone, 0, 2);
		world.setBlock(i + 14, j + 5, k + 17, Blocks.end_stone, 0, 2);
		world.setBlock(i + 15, j + 5, k + 17, Blocks.end_stone, 0, 2);
		world.setBlock(i + 16, j + 5, k + 17, Blocks.end_stone, 0, 2);
		world.setBlock(i + 17, j + 5, k + 17, Blocks.end_stone, 0, 2);
		world.setBlock(i + 18, j + 5, k + 17, Blocks.end_stone, 0, 2);
		world.setBlock(i + 19, j + 5, k + 17, Blocks.end_stone, 0, 2);
		world.setBlock(i + 20, j + 5, k + 17, Blocks.end_stone, 0, 2);
		world.setBlock(i + 21, j + 5, k + 17, Blocks.end_stone, 0, 2);
		world.setBlock(i + 22, j + 5, k + 17, Blocks.end_stone, 0, 2);
		world.setBlock(i + 23, j + 5, k + 17, Blocks.end_stone, 0, 2);
		world.setBlock(i + 24, j + 5, k + 17, Blocks.end_stone, 0, 2);
		world.setBlock(i + 25, j + 5, k + 17, Blocks.end_stone, 0, 2);
		world.setBlock(i + 27, j + 5, k + 17, Blocks.end_stone, 0, 2);
		world.setBlock(i + 5, j + 5, k + 18, Blocks.end_stone, 0, 2);
		world.setBlock(i + 6, j + 5, k + 18, Blocks.end_stone, 0, 2);
		world.setBlock(i + 7, j + 5, k + 18, Blocks.end_stone, 0, 2);
		world.setBlock(i + 8, j + 5, k + 18, Blocks.end_stone, 0, 2);
		world.setBlock(i + 9, j + 5, k + 18, Blocks.end_stone, 0, 2);
		world.setBlock(i + 12, j + 5, k + 18, Blocks.end_stone, 0, 2);
		world.setBlock(i + 13, j + 5, k + 18, Blocks.end_stone, 0, 2);
		world.setBlock(i + 14, j + 5, k + 18, Blocks.end_stone, 0, 2);
		world.setBlock(i + 15, j + 5, k + 18, Blocks.end_stone, 0, 2);
		world.setBlock(i + 16, j + 5, k + 18, Blocks.end_stone, 0, 2);
		world.setBlock(i + 17, j + 5, k + 18, Blocks.end_stone, 0, 2);
		world.setBlock(i + 18, j + 5, k + 18, Blocks.end_stone, 0, 2);
		world.setBlock(i + 19, j + 5, k + 18, Blocks.end_stone, 0, 2);
		world.setBlock(i + 20, j + 5, k + 18, Blocks.end_stone, 0, 2);
		world.setBlock(i + 21, j + 5, k + 18, Blocks.end_stone, 0, 2);
		world.setBlock(i + 22, j + 5, k + 18, Blocks.end_stone, 0, 2);
		world.setBlock(i + 23, j + 5, k + 18, Blocks.end_stone, 0, 2);
		world.setBlock(i + 24, j + 5, k + 18, Blocks.end_stone, 0, 2);
		world.setBlock(i + 25, j + 5, k + 18, Blocks.end_stone, 0, 2);
		world.setBlock(i + 29, j + 5, k + 18, Blocks.end_stone, 0, 2);
		world.setBlock(i + 31, j + 5, k + 18, Blocks.end_stone, 0, 2);
		world.setBlock(i + 32, j + 5, k + 18, Blocks.end_stone, 0, 2);
		world.setBlock(i + 33, j + 5, k + 18, Blocks.end_stone, 0, 2);
		world.setBlock(i + 34, j + 5, k + 18, Blocks.end_stone, 0, 2);
		world.setBlock(i + 2, j + 5, k + 19, Blocks.end_stone, 0, 2);
		world.setBlock(i + 3, j + 5, k + 19, Blocks.end_stone, 0, 2);
		world.setBlock(i + 5, j + 5, k + 19, Blocks.end_stone, 0, 2);
		world.setBlock(i + 7, j + 5, k + 19, Blocks.end_stone, 0, 2);
		world.setBlock(i + 8, j + 5, k + 19, Blocks.end_stone, 0, 2);
		world.setBlock(i + 10, j + 5, k + 19, Blocks.end_stone, 0, 2);
		world.setBlock(i + 11, j + 5, k + 19, Blocks.end_stone, 0, 2);
		world.setBlock(i + 12, j + 5, k + 19, Blocks.end_stone, 0, 2);
		world.setBlock(i + 13, j + 5, k + 19, Blocks.end_stone, 0, 2);
		world.setBlock(i + 14, j + 5, k + 19, Blocks.end_stone, 0, 2);
		world.setBlock(i + 15, j + 5, k + 19, Blocks.end_stone, 0, 2);
		world.setBlock(i + 16, j + 5, k + 19, Blocks.end_stone, 0, 2);
		world.setBlock(i + 17, j + 5, k + 19, Blocks.end_stone, 0, 2);
		world.setBlock(i + 18, j + 5, k + 19, Blocks.end_stone, 0, 2);
		world.setBlock(i + 19, j + 5, k + 19, Blocks.end_stone, 0, 2);
		world.setBlock(i + 20, j + 5, k + 19, Blocks.end_stone, 0, 2);
		world.setBlock(i + 21, j + 5, k + 19, Blocks.end_stone, 0, 2);
		world.setBlock(i + 22, j + 5, k + 19, Blocks.end_stone, 0, 2);
		world.setBlock(i + 23, j + 5, k + 19, Blocks.end_stone, 0, 2);
		world.setBlock(i + 24, j + 5, k + 19, Blocks.end_stone, 0, 2);
		world.setBlock(i + 25, j + 5, k + 19, Blocks.end_stone, 0, 2);
		world.setBlock(i + 26, j + 5, k + 19, Blocks.end_stone, 0, 2);
		world.setBlock(i + 27, j + 5, k + 19, Blocks.end_stone, 0, 2);
		world.setBlock(i + 30, j + 5, k + 19, Blocks.end_stone, 0, 2);
		world.setBlock(i + 31, j + 5, k + 19, Blocks.end_stone, 0, 2);
		world.setBlock(i + 36, j + 5, k + 19, Blocks.end_stone, 0, 2);
		world.setBlock(i + 1, j + 5, k + 20, Blocks.end_stone, 0, 2);
		world.setBlock(i + 3, j + 5, k + 20, Blocks.end_stone, 0, 2);
		world.setBlock(i + 12, j + 5, k + 20, Blocks.end_stone, 0, 2);
		world.setBlock(i + 13, j + 5, k + 20, Blocks.end_stone, 0, 2);
		world.setBlock(i + 14, j + 5, k + 20, Blocks.end_stone, 0, 2);
		world.setBlock(i + 15, j + 5, k + 20, Blocks.end_stone, 0, 2);
		world.setBlock(i + 16, j + 5, k + 20, Blocks.end_stone, 0, 2);
		world.setBlock(i + 17, j + 5, k + 20, Blocks.end_stone, 0, 2);
		world.setBlock(i + 18, j + 5, k + 20, Blocks.end_stone, 0, 2);
		world.setBlock(i + 19, j + 5, k + 20, Blocks.end_stone, 0, 2);
		world.setBlock(i + 20, j + 5, k + 20, Blocks.end_stone, 0, 2);
		world.setBlock(i + 21, j + 5, k + 20, Blocks.end_stone, 0, 2);
		world.setBlock(i + 22, j + 5, k + 20, Blocks.end_stone, 0, 2);
		world.setBlock(i + 23, j + 5, k + 20, Blocks.end_stone, 0, 2);
		world.setBlock(i + 24, j + 5, k + 20, Blocks.end_stone, 0, 2);
		world.setBlock(i + 25, j + 5, k + 20, Blocks.end_stone, 0, 2);
		world.setBlock(i + 27, j + 5, k + 20, Blocks.end_stone, 0, 2);
		world.setBlock(i + 29, j + 5, k + 20, Blocks.end_stone, 0, 2);
		world.setBlock(i + 33, j + 5, k + 20, Blocks.end_stone, 0, 2);
		world.setBlock(i + 35, j + 5, k + 20, Blocks.end_stone, 0, 2);
		world.setBlock(i + 36, j + 5, k + 20, Blocks.end_stone, 0, 2);
		world.setBlock(i + 2, j + 5, k + 21, Blocks.end_stone, 0, 2);
		world.setBlock(i + 3, j + 5, k + 21, Blocks.end_stone, 0, 2);
		world.setBlock(i + 8, j + 5, k + 21, Blocks.end_stone, 0, 2);
		world.setBlock(i + 12, j + 5, k + 21, Blocks.end_stone, 0, 2);
		world.setBlock(i + 13, j + 5, k + 21, Blocks.end_stone, 0, 2);
		world.setBlock(i + 14, j + 5, k + 21, Blocks.end_stone, 0, 2);
		world.setBlock(i + 15, j + 5, k + 21, Blocks.end_stone, 0, 2);
		world.setBlock(i + 16, j + 5, k + 21, Blocks.end_stone, 0, 2);
		world.setBlock(i + 17, j + 5, k + 21, Blocks.end_stone, 0, 2);
		world.setBlock(i + 18, j + 5, k + 21, Blocks.end_stone, 0, 2);
		world.setBlock(i + 19, j + 5, k + 21, Blocks.end_stone, 0, 2);
		world.setBlock(i + 20, j + 5, k + 21, Blocks.end_stone, 0, 2);
		world.setBlock(i + 21, j + 5, k + 21, Blocks.end_stone, 0, 2);
		world.setBlock(i + 22, j + 5, k + 21, Blocks.end_stone, 0, 2);
		world.setBlock(i + 23, j + 5, k + 21, Blocks.end_stone, 0, 2);
		world.setBlock(i + 24, j + 5, k + 21, Blocks.end_stone, 0, 2);
		world.setBlock(i + 25, j + 5, k + 21, Blocks.end_stone, 0, 2);
		world.setBlock(i + 26, j + 5, k + 21, Blocks.end_stone, 0, 2);
		world.setBlock(i + 27, j + 5, k + 21, Blocks.end_stone, 0, 2);
		world.setBlock(i + 31, j + 5, k + 21, Blocks.end_stone, 0, 2);
		world.setBlock(i + 32, j + 5, k + 21, Blocks.end_stone, 0, 2);
		world.setBlock(i + 33, j + 5, k + 21, Blocks.end_stone, 0, 2);
		world.setBlock(i + 34, j + 5, k + 21, Blocks.end_stone, 0, 2);
		world.setBlock(i + 35, j + 5, k + 21, Blocks.end_stone, 0, 2);
		world.setBlock(i + 37, j + 5, k + 21, Blocks.end_stone, 0, 2);
		world.setBlock(i + 3, j + 5, k + 22, Blocks.end_stone, 0, 2);
		world.setBlock(i + 5, j + 5, k + 22, Blocks.end_stone, 0, 2);
		world.setBlock(i + 7, j + 5, k + 22, Blocks.end_stone, 0, 2);
		world.setBlock(i + 9, j + 5, k + 22, Blocks.end_stone, 0, 2);
		world.setBlock(i + 12, j + 5, k + 22, Blocks.end_stone, 0, 2);
		world.setBlock(i + 13, j + 5, k + 22, Blocks.end_stone, 0, 2);
		world.setBlock(i + 14, j + 5, k + 22, Blocks.end_stone, 0, 2);
		world.setBlock(i + 15, j + 5, k + 22, Blocks.end_stone, 0, 2);
		world.setBlock(i + 16, j + 5, k + 22, Blocks.end_stone, 0, 2);
		world.setBlock(i + 17, j + 5, k + 22, Blocks.end_stone, 0, 2);
		world.setBlock(i + 18, j + 5, k + 22, Blocks.end_stone, 0, 2);
		world.setBlock(i + 19, j + 5, k + 22, Blocks.end_stone, 0, 2);
		world.setBlock(i + 20, j + 5, k + 22, Blocks.end_stone, 0, 2);
		world.setBlock(i + 21, j + 5, k + 22, Blocks.end_stone, 0, 2);
		world.setBlock(i + 22, j + 5, k + 22, Blocks.end_stone, 0, 2);
		world.setBlock(i + 23, j + 5, k + 22, Blocks.end_stone, 0, 2);
		world.setBlock(i + 24, j + 5, k + 22, Blocks.end_stone, 0, 2);
		world.setBlock(i + 25, j + 5, k + 22, Blocks.end_stone, 0, 2);
		world.setBlock(i + 29, j + 5, k + 22, Blocks.end_stone, 0, 2);
		world.setBlock(i + 33, j + 5, k + 22, Blocks.end_stone, 0, 2);
		world.setBlock(i + 34, j + 5, k + 22, Blocks.end_stone, 0, 2);
		world.setBlock(i + 4, j + 5, k + 23, Blocks.end_stone, 0, 2);
		world.setBlock(i + 5, j + 5, k + 23, Blocks.end_stone, 0, 2);
		world.setBlock(i + 11, j + 5, k + 23, Blocks.end_stone, 0, 2);
		world.setBlock(i + 12, j + 5, k + 23, Blocks.end_stone, 0, 2);
		world.setBlock(i + 13, j + 5, k + 23, Blocks.end_stone, 0, 2);
		world.setBlock(i + 14, j + 5, k + 23, Blocks.end_stone, 0, 2);
		world.setBlock(i + 15, j + 5, k + 23, Blocks.end_stone, 0, 2);
		world.setBlock(i + 16, j + 5, k + 23, Blocks.end_stone, 0, 2);
		world.setBlock(i + 17, j + 5, k + 23, Blocks.end_stone, 0, 2);
		world.setBlock(i + 18, j + 5, k + 23, Blocks.end_stone, 0, 2);
		world.setBlock(i + 19, j + 5, k + 23, Blocks.end_stone, 0, 2);
		world.setBlock(i + 20, j + 5, k + 23, Blocks.end_stone, 0, 2);
		world.setBlock(i + 21, j + 5, k + 23, Blocks.end_stone, 0, 2);
		world.setBlock(i + 22, j + 5, k + 23, Blocks.end_stone, 0, 2);
		world.setBlock(i + 23, j + 5, k + 23, Blocks.end_stone, 0, 2);
		world.setBlock(i + 24, j + 5, k + 23, Blocks.end_stone, 0, 2);
		world.setBlock(i + 25, j + 5, k + 23, Blocks.end_stone, 0, 2);
		world.setBlock(i + 26, j + 5, k + 23, Blocks.end_stone, 0, 2);
		world.setBlock(i + 31, j + 5, k + 23, Blocks.end_stone, 0, 2);
		world.setBlock(i + 33, j + 5, k + 23, Blocks.end_stone, 0, 2);
		world.setBlock(i + 5, j + 5, k + 24, Blocks.end_stone, 0, 2);
		world.setBlock(i + 11, j + 5, k + 24, Blocks.end_stone, 0, 2);
		world.setBlock(i + 12, j + 5, k + 24, Blocks.end_stone, 0, 2);
		world.setBlock(i + 13, j + 5, k + 24, Blocks.end_stone, 0, 2);
		world.setBlock(i + 14, j + 5, k + 24, Blocks.end_stone, 0, 2);
		world.setBlock(i + 15, j + 5, k + 24, Blocks.end_stone, 0, 2);
		world.setBlock(i + 16, j + 5, k + 24, Blocks.end_stone, 0, 2);
		world.setBlock(i + 17, j + 5, k + 24, Blocks.end_stone, 0, 2);
		world.setBlock(i + 18, j + 5, k + 24, Blocks.end_stone, 0, 2);
		world.setBlock(i + 19, j + 5, k + 24, Blocks.end_stone, 0, 2);
		world.setBlock(i + 20, j + 5, k + 24, Blocks.end_stone, 0, 2);
		world.setBlock(i + 21, j + 5, k + 24, Blocks.end_stone, 0, 2);
		world.setBlock(i + 22, j + 5, k + 24, Blocks.end_stone, 0, 2);
		world.setBlock(i + 23, j + 5, k + 24, Blocks.end_stone, 0, 2);
		world.setBlock(i + 24, j + 5, k + 24, Blocks.end_stone, 0, 2);
		world.setBlock(i + 25, j + 5, k + 24, Blocks.end_stone, 0, 2);
		world.setBlock(i + 28, j + 5, k + 24, Blocks.end_stone, 0, 2);
		world.setBlock(i + 31, j + 5, k + 24, Blocks.end_stone, 0, 2);
		world.setBlock(i + 6, j + 5, k + 25, Blocks.end_stone, 0, 2);
		world.setBlock(i + 7, j + 5, k + 25, Blocks.end_stone, 0, 2);
		world.setBlock(i + 9, j + 5, k + 25, Blocks.end_stone, 0, 2);
		world.setBlock(i + 11, j + 5, k + 25, Blocks.end_stone, 0, 2);
		world.setBlock(i + 12, j + 5, k + 25, Blocks.end_stone, 0, 2);
		world.setBlock(i + 13, j + 5, k + 25, Blocks.end_stone, 0, 2);
		world.setBlock(i + 14, j + 5, k + 25, Blocks.end_stone, 0, 2);
		world.setBlock(i + 15, j + 5, k + 25, Blocks.end_stone, 0, 2);
		world.setBlock(i + 16, j + 5, k + 25, Blocks.end_stone, 0, 2);
		world.setBlock(i + 17, j + 5, k + 25, Blocks.end_stone, 0, 2);
		world.setBlock(i + 18, j + 5, k + 25, Blocks.end_stone, 0, 2);
		world.setBlock(i + 19, j + 5, k + 25, Blocks.end_stone, 0, 2);
		world.setBlock(i + 20, j + 5, k + 25, Blocks.end_stone, 0, 2);
		world.setBlock(i + 21, j + 5, k + 25, Blocks.end_stone, 0, 2);
		world.setBlock(i + 22, j + 5, k + 25, Blocks.end_stone, 0, 2);
		world.setBlock(i + 23, j + 5, k + 25, Blocks.end_stone, 0, 2);
		world.setBlock(i + 24, j + 5, k + 25, Blocks.end_stone, 0, 2);
		world.setBlock(i + 25, j + 5, k + 25, Blocks.end_stone, 0, 2);
		world.setBlock(i + 27, j + 5, k + 25, Blocks.end_stone, 0, 2);
		world.setBlock(i + 29, j + 5, k + 25, Blocks.end_stone, 0, 2);
		world.setBlock(i + 8, j + 5, k + 26, Blocks.end_stone, 0, 2);
		world.setBlock(i + 9, j + 5, k + 26, Blocks.end_stone, 0, 2);
		world.setBlock(i + 10, j + 5, k + 26, Blocks.end_stone, 0, 2);
		world.setBlock(i + 11, j + 5, k + 26, Blocks.end_stone, 0, 2);
		world.setBlock(i + 12, j + 5, k + 26, Blocks.end_stone, 0, 2);
		world.setBlock(i + 13, j + 5, k + 26, Blocks.end_stone, 0, 2);
		world.setBlock(i + 14, j + 5, k + 26, Blocks.end_stone, 0, 2);
		world.setBlock(i + 15, j + 5, k + 26, Blocks.end_stone, 0, 2);
		world.setBlock(i + 16, j + 5, k + 26, Blocks.end_stone, 0, 2);
		world.setBlock(i + 17, j + 5, k + 26, Blocks.end_stone, 0, 2);
		world.setBlock(i + 18, j + 5, k + 26, Blocks.end_stone, 0, 2);
		world.setBlock(i + 19, j + 5, k + 26, Blocks.end_stone, 0, 2);
		world.setBlock(i + 20, j + 5, k + 26, Blocks.end_stone, 0, 2);
		world.setBlock(i + 21, j + 5, k + 26, Blocks.end_stone, 0, 2);
		world.setBlock(i + 22, j + 5, k + 26, Blocks.end_stone, 0, 2);
		world.setBlock(i + 23, j + 5, k + 26, Blocks.end_stone, 0, 2);
		world.setBlock(i + 24, j + 5, k + 26, Blocks.end_stone, 0, 2);
		world.setBlock(i + 25, j + 5, k + 26, Blocks.end_stone, 0, 2);
		world.setBlock(i + 27, j + 5, k + 26, Blocks.end_stone, 0, 2);
		world.setBlock(i + 29, j + 5, k + 26, Blocks.end_stone, 0, 2);
		world.setBlock(i + 30, j + 5, k + 26, Blocks.end_stone, 0, 2);
		world.setBlock(i + 10, j + 5, k + 27, Blocks.end_stone, 0, 2);
		world.setBlock(i + 11, j + 5, k + 27, Blocks.end_stone, 0, 2);
		world.setBlock(i + 12, j + 5, k + 27, Blocks.end_stone, 0, 2);
		world.setBlock(i + 13, j + 5, k + 27, Blocks.end_stone, 0, 2);
		world.setBlock(i + 14, j + 5, k + 27, Blocks.end_stone, 0, 2);
		world.setBlock(i + 15, j + 5, k + 27, Blocks.end_stone, 0, 2);
		world.setBlock(i + 16, j + 5, k + 27, Blocks.end_stone, 0, 2);
		world.setBlock(i + 17, j + 5, k + 27, Blocks.end_stone, 0, 2);
		world.setBlock(i + 18, j + 5, k + 27, Blocks.end_stone, 0, 2);
		world.setBlock(i + 19, j + 5, k + 27, Blocks.end_stone, 0, 2);
		world.setBlock(i + 20, j + 5, k + 27, Blocks.end_stone, 0, 2);
		world.setBlock(i + 21, j + 5, k + 27, Blocks.end_stone, 0, 2);
		world.setBlock(i + 22, j + 5, k + 27, Blocks.end_stone, 0, 2);
		world.setBlock(i + 23, j + 5, k + 27, Blocks.end_stone, 0, 2);
		world.setBlock(i + 24, j + 5, k + 27, Blocks.end_stone, 0, 2);
		world.setBlock(i + 25, j + 5, k + 27, Blocks.end_stone, 0, 2);
		world.setBlock(i + 26, j + 5, k + 27, Blocks.end_stone, 0, 2);
		world.setBlock(i + 27, j + 5, k + 27, Blocks.end_stone, 0, 2);
		world.setBlock(i + 28, j + 5, k + 27, Blocks.end_stone, 0, 2);
		world.setBlock(i + 29, j + 5, k + 27, Blocks.end_stone, 0, 2);
		world.setBlock(i + 11, j + 5, k + 28, Blocks.end_stone, 0, 2);
		world.setBlock(i + 12, j + 5, k + 28, Blocks.end_stone, 0, 2);
		world.setBlock(i + 13, j + 5, k + 28, Blocks.end_stone, 0, 2);
		world.setBlock(i + 14, j + 5, k + 28, Blocks.end_stone, 0, 2);
		world.setBlock(i + 15, j + 5, k + 28, Blocks.end_stone, 0, 2);
		world.setBlock(i + 16, j + 5, k + 28, Blocks.end_stone, 0, 2);
		world.setBlock(i + 17, j + 5, k + 28, Blocks.end_stone, 0, 2);
		world.setBlock(i + 18, j + 5, k + 28, Blocks.end_stone, 0, 2);
		world.setBlock(i + 19, j + 5, k + 28, Blocks.end_stone, 0, 2);
		world.setBlock(i + 20, j + 5, k + 28, Blocks.end_stone, 0, 2);
		world.setBlock(i + 21, j + 5, k + 28, Blocks.end_stone, 0, 2);
		world.setBlock(i + 22, j + 5, k + 28, Blocks.end_stone, 0, 2);
		world.setBlock(i + 23, j + 5, k + 28, Blocks.end_stone, 0, 2);
		world.setBlock(i + 24, j + 5, k + 28, Blocks.end_stone, 0, 2);
		world.setBlock(i + 25, j + 5, k + 28, Blocks.end_stone, 0, 2);
		world.setBlock(i + 28, j + 5, k + 28, Blocks.end_stone, 0, 2);
		world.setBlock(i + 10, j + 5, k + 29, Blocks.end_stone, 0, 2);
		world.setBlock(i + 11, j + 5, k + 29, Blocks.end_stone, 0, 2);
		world.setBlock(i + 12, j + 5, k + 29, Blocks.end_stone, 0, 2);
		world.setBlock(i + 13, j + 5, k + 29, Blocks.end_stone, 0, 2);
		world.setBlock(i + 14, j + 5, k + 29, Blocks.end_stone, 0, 2);
		world.setBlock(i + 15, j + 5, k + 29, Blocks.end_stone, 0, 2);
		world.setBlock(i + 16, j + 5, k + 29, Blocks.end_stone, 0, 2);
		world.setBlock(i + 17, j + 5, k + 29, Blocks.end_stone, 0, 2);
		world.setBlock(i + 18, j + 5, k + 29, Blocks.end_stone, 0, 2);
		world.setBlock(i + 19, j + 5, k + 29, Blocks.end_stone, 0, 2);
		world.setBlock(i + 20, j + 5, k + 29, Blocks.end_stone, 0, 2);
		world.setBlock(i + 21, j + 5, k + 29, Blocks.end_stone, 0, 2);
		world.setBlock(i + 22, j + 5, k + 29, Blocks.end_stone, 0, 2);
		world.setBlock(i + 23, j + 5, k + 29, Blocks.end_stone, 0, 2);
		world.setBlock(i + 24, j + 5, k + 29, Blocks.end_stone, 0, 2);
		world.setBlock(i + 25, j + 5, k + 29, Blocks.end_stone, 0, 2);
		world.setBlock(i + 26, j + 5, k + 29, Blocks.end_stone, 0, 2);
		world.setBlock(i + 29, j + 5, k + 29, Blocks.end_stone, 0, 2);
		world.setBlock(i + 12, j + 5, k + 30, Blocks.end_stone, 0, 2);
		world.setBlock(i + 13, j + 5, k + 30, Blocks.end_stone, 0, 2);
		world.setBlock(i + 14, j + 5, k + 30, Blocks.end_stone, 0, 2);
		world.setBlock(i + 15, j + 5, k + 30, Blocks.end_stone, 0, 2);
		world.setBlock(i + 16, j + 5, k + 30, Blocks.end_stone, 0, 2);
		world.setBlock(i + 17, j + 5, k + 30, Blocks.end_stone, 0, 2);
		world.setBlock(i + 18, j + 5, k + 30, Blocks.end_stone, 0, 2);
		world.setBlock(i + 19, j + 5, k + 30, Blocks.end_stone, 0, 2);
		world.setBlock(i + 20, j + 5, k + 30, Blocks.end_stone, 0, 2);
		world.setBlock(i + 21, j + 5, k + 30, Blocks.end_stone, 0, 2);
		world.setBlock(i + 22, j + 5, k + 30, Blocks.end_stone, 0, 2);
		world.setBlock(i + 23, j + 5, k + 30, Blocks.end_stone, 0, 2);
		world.setBlock(i + 24, j + 5, k + 30, Blocks.end_stone, 0, 2);
		world.setBlock(i + 25, j + 5, k + 30, Blocks.end_stone, 0, 2);
		world.setBlock(i + 26, j + 5, k + 30, Blocks.end_stone, 0, 2);
		world.setBlock(i + 10, j + 5, k + 31, Blocks.end_stone, 0, 2);
		world.setBlock(i + 11, j + 5, k + 31, Blocks.end_stone, 0, 2);
		world.setBlock(i + 18, j + 5, k + 31, Blocks.end_stone, 0, 2);
		world.setBlock(i + 20, j + 5, k + 31, Blocks.end_stone, 0, 2);
		world.setBlock(i + 24, j + 5, k + 31, Blocks.end_stone, 0, 2);
		world.setBlock(i + 25, j + 5, k + 31, Blocks.end_stone, 0, 2);
		world.setBlock(i + 26, j + 5, k + 31, Blocks.end_stone, 0, 2);
		world.setBlock(i + 26, j + 5, k + 32, Blocks.end_stone, 0, 2);
		world.setBlock(i + 19, j + 6, k + 0, Blocks.end_stone, 0, 2);
		world.setBlock(i + 18, j + 6, k + 1, Blocks.end_stone, 0, 2);
		world.setBlock(i + 19, j + 6, k + 1, Blocks.end_stone, 0, 2);
		world.setBlock(i + 20, j + 6, k + 1, Blocks.end_stone, 0, 2);
		world.setBlock(i + 17, j + 6, k + 2, Blocks.end_stone, 0, 2);
		world.setBlock(i + 18, j + 6, k + 2, Blocks.end_stone, 0, 2);
		world.setBlock(i + 19, j + 6, k + 2, Blocks.end_stone, 0, 2);
		world.setBlock(i + 20, j + 6, k + 2, Blocks.end_stone, 0, 2);
		world.setBlock(i + 21, j + 6, k + 2, Blocks.end_stone, 0, 2);
		world.setBlock(i + 16, j + 6, k + 3, Blocks.end_stone, 0, 2);
		world.setBlock(i + 17, j + 6, k + 3, Blocks.end_stone, 0, 2);
		world.setBlock(i + 18, j + 6, k + 3, Blocks.end_stone, 0, 2);
		world.setBlock(i + 19, j + 6, k + 3, Blocks.end_stone, 0, 2);
		world.setBlock(i + 20, j + 6, k + 3, Blocks.end_stone, 0, 2);
		world.setBlock(i + 21, j + 6, k + 3, Blocks.end_stone, 0, 2);
		world.setBlock(i + 22, j + 6, k + 3, Blocks.end_stone, 0, 2);
		world.setBlock(i + 15, j + 6, k + 4, Blocks.end_stone, 0, 2);
		world.setBlock(i + 16, j + 6, k + 4, Blocks.end_stone, 0, 2);
		world.setBlock(i + 17, j + 6, k + 4, Blocks.end_stone, 0, 2);
		world.setBlock(i + 18, j + 6, k + 4, Blocks.end_stone, 0, 2);
		world.setBlock(i + 19, j + 6, k + 4, Blocks.end_stone, 0, 2);
		world.setBlock(i + 20, j + 6, k + 4, Blocks.end_stone, 0, 2);
		world.setBlock(i + 21, j + 6, k + 4, Blocks.end_stone, 0, 2);
		world.setBlock(i + 22, j + 6, k + 4, Blocks.end_stone, 0, 2);
		world.setBlock(i + 23, j + 6, k + 4, Blocks.end_stone, 0, 2);
		world.setBlock(i + 14, j + 6, k + 5, Blocks.end_stone, 0, 2);
		world.setBlock(i + 15, j + 6, k + 5, Blocks.end_stone, 0, 2);
		world.setBlock(i + 16, j + 6, k + 5, Blocks.end_stone, 0, 2);
		world.setBlock(i + 17, j + 6, k + 5, Blocks.end_stone, 0, 2);
		world.setBlock(i + 18, j + 6, k + 5, Blocks.end_stone, 0, 2);
		world.setBlock(i + 19, j + 6, k + 5, Blocks.end_stone, 0, 2);
		world.setBlock(i + 20, j + 6, k + 5, Blocks.end_stone, 0, 2);
		world.setBlock(i + 21, j + 6, k + 5, Blocks.end_stone, 0, 2);
		world.setBlock(i + 22, j + 6, k + 5, Blocks.end_stone, 0, 2);
		world.setBlock(i + 23, j + 6, k + 5, Blocks.end_stone, 0, 2);
		world.setBlock(i + 24, j + 6, k + 5, Blocks.end_stone, 0, 2);
		world.setBlock(i + 13, j + 6, k + 6, Blocks.end_stone, 0, 2);
		world.setBlock(i + 14, j + 6, k + 6, Blocks.end_stone, 0, 2);
		world.setBlock(i + 15, j + 6, k + 6, Blocks.end_stone, 0, 2);
		world.setBlock(i + 16, j + 6, k + 6, Blocks.end_stone, 0, 2);
		world.setBlock(i + 17, j + 6, k + 6, Blocks.end_stone, 0, 2);
		world.setBlock(i + 18, j + 6, k + 6, Blocks.end_stone, 0, 2);
		world.setBlock(i + 19, j + 6, k + 6, Blocks.end_stone, 0, 2);
		world.setBlock(i + 20, j + 6, k + 6, Blocks.end_stone, 0, 2);
		world.setBlock(i + 21, j + 6, k + 6, Blocks.end_stone, 0, 2);
		world.setBlock(i + 22, j + 6, k + 6, Blocks.end_stone, 0, 2);
		world.setBlock(i + 23, j + 6, k + 6, Blocks.end_stone, 0, 2);
		world.setBlock(i + 24, j + 6, k + 6, Blocks.end_stone, 0, 2);
		world.setBlock(i + 25, j + 6, k + 6, Blocks.end_stone, 0, 2);
		world.setBlock(i + 12, j + 6, k + 7, Blocks.end_stone, 0, 2);
		world.setBlock(i + 13, j + 6, k + 7, Blocks.end_stone, 0, 2);
		world.setBlock(i + 14, j + 6, k + 7, Blocks.end_stone, 0, 2);
		world.setBlock(i + 15, j + 6, k + 7, Blocks.end_stone, 0, 2);
		world.setBlock(i + 16, j + 6, k + 7, Blocks.end_stone, 0, 2);
		world.setBlock(i + 17, j + 6, k + 7, Blocks.end_stone, 0, 2);
		world.setBlock(i + 18, j + 6, k + 7, Blocks.end_stone, 0, 2);
		world.setBlock(i + 19, j + 6, k + 7, Blocks.end_stone, 0, 2);
		world.setBlock(i + 20, j + 6, k + 7, Blocks.end_stone, 0, 2);
		world.setBlock(i + 21, j + 6, k + 7, Blocks.end_stone, 0, 2);
		world.setBlock(i + 22, j + 6, k + 7, Blocks.end_stone, 0, 2);
		world.setBlock(i + 23, j + 6, k + 7, Blocks.end_stone, 0, 2);
		world.setBlock(i + 24, j + 6, k + 7, Blocks.end_stone, 0, 2);
		world.setBlock(i + 25, j + 6, k + 7, Blocks.end_stone, 0, 2);
		world.setBlock(i + 26, j + 6, k + 7, Blocks.end_stone, 0, 2);
		world.setBlock(i + 11, j + 6, k + 8, Blocks.end_stone, 0, 2);
		world.setBlock(i + 12, j + 6, k + 8, Blocks.end_stone, 0, 2);
		world.setBlock(i + 13, j + 6, k + 8, Blocks.end_stone, 0, 2);
		world.setBlock(i + 14, j + 6, k + 8, Blocks.end_stone, 0, 2);
		world.setBlock(i + 15, j + 6, k + 8, Blocks.end_stone, 0, 2);
		world.setBlock(i + 16, j + 6, k + 8, Blocks.end_stone, 0, 2);
		world.setBlock(i + 17, j + 6, k + 8, Blocks.end_stone, 0, 2);
		world.setBlock(i + 18, j + 6, k + 8, Blocks.end_stone, 0, 2);
		world.setBlock(i + 19, j + 6, k + 8, Blocks.end_stone, 0, 2);
		world.setBlock(i + 20, j + 6, k + 8, Blocks.end_stone, 0, 2);
		world.setBlock(i + 21, j + 6, k + 8, Blocks.end_stone, 0, 2);
		world.setBlock(i + 22, j + 6, k + 8, Blocks.end_stone, 0, 2);
		world.setBlock(i + 23, j + 6, k + 8, Blocks.end_stone, 0, 2);
		world.setBlock(i + 24, j + 6, k + 8, Blocks.end_stone, 0, 2);
		world.setBlock(i + 25, j + 6, k + 8, Blocks.end_stone, 0, 2);
		world.setBlock(i + 26, j + 6, k + 8, Blocks.end_stone, 0, 2);
		world.setBlock(i + 27, j + 6, k + 8, Blocks.end_stone, 0, 2);
		world.setBlock(i + 10, j + 6, k + 9, Blocks.end_stone, 0, 2);
		world.setBlock(i + 11, j + 6, k + 9, Blocks.end_stone, 0, 2);
		world.setBlock(i + 12, j + 6, k + 9, Blocks.end_stone, 0, 2);
		world.setBlock(i + 13, j + 6, k + 9, Blocks.end_stone, 0, 2);
		world.setBlock(i + 14, j + 6, k + 9, Blocks.end_stone, 0, 2);
		world.setBlock(i + 15, j + 6, k + 9, Blocks.end_stone, 0, 2);
		world.setBlock(i + 16, j + 6, k + 9, Blocks.end_stone, 0, 2);
		world.setBlock(i + 17, j + 6, k + 9, Blocks.end_stone, 0, 2);
		world.setBlock(i + 18, j + 6, k + 9, Blocks.end_stone, 0, 2);
		world.setBlock(i + 19, j + 6, k + 9, Blocks.end_stone, 0, 2);
		world.setBlock(i + 20, j + 6, k + 9, Blocks.end_stone, 0, 2);
		world.setBlock(i + 21, j + 6, k + 9, Blocks.end_stone, 0, 2);
		world.setBlock(i + 22, j + 6, k + 9, Blocks.end_stone, 0, 2);
		world.setBlock(i + 23, j + 6, k + 9, Blocks.end_stone, 0, 2);
		world.setBlock(i + 24, j + 6, k + 9, Blocks.end_stone, 0, 2);
		world.setBlock(i + 25, j + 6, k + 9, Blocks.end_stone, 0, 2);
		world.setBlock(i + 26, j + 6, k + 9, Blocks.end_stone, 0, 2);
		world.setBlock(i + 27, j + 6, k + 9, Blocks.end_stone, 0, 2);
		world.setBlock(i + 28, j + 6, k + 9, Blocks.end_stone, 0, 2);
		world.setBlock(i + 9, j + 6, k + 10, Blocks.end_stone, 0, 2);
		world.setBlock(i + 10, j + 6, k + 10, Blocks.end_stone, 0, 2);
		world.setBlock(i + 11, j + 6, k + 10, Blocks.end_stone, 0, 2);
		world.setBlock(i + 12, j + 6, k + 10, Blocks.end_stone, 0, 2);
		world.setBlock(i + 13, j + 6, k + 10, Blocks.end_stone, 0, 2);
		world.setBlock(i + 14, j + 6, k + 10, Blocks.end_stone, 0, 2);
		world.setBlock(i + 15, j + 6, k + 10, Blocks.end_stone, 0, 2);
		world.setBlock(i + 16, j + 6, k + 10, Blocks.end_stone, 0, 2);
		world.setBlock(i + 17, j + 6, k + 10, Blocks.end_stone, 0, 2);
		world.setBlock(i + 18, j + 6, k + 10, Blocks.end_stone, 0, 2);
		world.setBlock(i + 19, j + 6, k + 10, Blocks.end_stone, 0, 2);
		world.setBlock(i + 20, j + 6, k + 10, Blocks.end_stone, 0, 2);
		world.setBlock(i + 21, j + 6, k + 10, Blocks.end_stone, 0, 2);
		world.setBlock(i + 22, j + 6, k + 10, Blocks.end_stone, 0, 2);
		world.setBlock(i + 23, j + 6, k + 10, Blocks.end_stone, 0, 2);
		world.setBlock(i + 24, j + 6, k + 10, Blocks.end_stone, 0, 2);
		world.setBlock(i + 25, j + 6, k + 10, Blocks.end_stone, 0, 2);
		world.setBlock(i + 26, j + 6, k + 10, Blocks.end_stone, 0, 2);
		world.setBlock(i + 27, j + 6, k + 10, Blocks.end_stone, 0, 2);
		world.setBlock(i + 28, j + 6, k + 10, Blocks.end_stone, 0, 2);
		world.setBlock(i + 29, j + 6, k + 10, Blocks.end_stone, 0, 2);
		world.setBlock(i + 8, j + 6, k + 11, Blocks.end_stone, 0, 2);
		world.setBlock(i + 9, j + 6, k + 11, Blocks.end_stone, 0, 2);
		world.setBlock(i + 10, j + 6, k + 11, Blocks.end_stone, 0, 2);
		world.setBlock(i + 11, j + 6, k + 11, Blocks.end_stone, 0, 2);
		world.setBlock(i + 12, j + 6, k + 11, Blocks.end_stone, 0, 2);
		world.setBlock(i + 13, j + 6, k + 11, Blocks.end_stone, 0, 2);
		world.setBlock(i + 14, j + 6, k + 11, Blocks.end_stone, 0, 2);
		world.setBlock(i + 15, j + 6, k + 11, Blocks.end_stone, 0, 2);
		world.setBlock(i + 16, j + 6, k + 11, Blocks.end_stone, 0, 2);
		world.setBlock(i + 17, j + 6, k + 11, Blocks.end_stone, 0, 2);
		world.setBlock(i + 18, j + 6, k + 11, Blocks.end_stone, 0, 2);
		world.setBlock(i + 19, j + 6, k + 11, Blocks.end_stone, 0, 2);
		world.setBlock(i + 20, j + 6, k + 11, Blocks.end_stone, 0, 2);
		world.setBlock(i + 21, j + 6, k + 11, Blocks.end_stone, 0, 2);
		world.setBlock(i + 22, j + 6, k + 11, Blocks.end_stone, 0, 2);
		world.setBlock(i + 23, j + 6, k + 11, Blocks.end_stone, 0, 2);
		world.setBlock(i + 24, j + 6, k + 11, Blocks.end_stone, 0, 2);
		world.setBlock(i + 25, j + 6, k + 11, Blocks.end_stone, 0, 2);
		world.setBlock(i + 26, j + 6, k + 11, Blocks.end_stone, 0, 2);
		world.setBlock(i + 27, j + 6, k + 11, Blocks.end_stone, 0, 2);
		world.setBlock(i + 28, j + 6, k + 11, Blocks.end_stone, 0, 2);
		world.setBlock(i + 29, j + 6, k + 11, Blocks.end_stone, 0, 2);
		world.setBlock(i + 30, j + 6, k + 11, Blocks.end_stone, 0, 2);
		world.setBlock(i + 7, j + 6, k + 12, Blocks.end_stone, 0, 2);
		world.setBlock(i + 8, j + 6, k + 12, Blocks.end_stone, 0, 2);
		world.setBlock(i + 9, j + 6, k + 12, Blocks.end_stone, 0, 2);
		world.setBlock(i + 10, j + 6, k + 12, Blocks.end_stone, 0, 2);
		world.setBlock(i + 11, j + 6, k + 12, Blocks.end_stone, 0, 2);
		world.setBlock(i + 12, j + 6, k + 12, Blocks.end_stone, 0, 2);
		world.setBlock(i + 13, j + 6, k + 12, Blocks.end_stone, 0, 2);
		world.setBlock(i + 14, j + 6, k + 12, Blocks.end_stone, 0, 2);
		world.setBlock(i + 15, j + 6, k + 12, Blocks.end_stone, 0, 2);
		world.setBlock(i + 16, j + 6, k + 12, Blocks.end_stone, 0, 2);
		world.setBlock(i + 17, j + 6, k + 12, Blocks.end_stone, 0, 2);
		world.setBlock(i + 18, j + 6, k + 12, Blocks.end_stone, 0, 2);
		world.setBlock(i + 19, j + 6, k + 12, Blocks.end_stone, 0, 2);
		world.setBlock(i + 20, j + 6, k + 12, Blocks.end_stone, 0, 2);
		world.setBlock(i + 21, j + 6, k + 12, Blocks.end_stone, 0, 2);
		world.setBlock(i + 22, j + 6, k + 12, Blocks.end_stone, 0, 2);
		world.setBlock(i + 23, j + 6, k + 12, Blocks.end_stone, 0, 2);
		world.setBlock(i + 24, j + 6, k + 12, Blocks.end_stone, 0, 2);
		world.setBlock(i + 25, j + 6, k + 12, Blocks.end_stone, 0, 2);
		world.setBlock(i + 26, j + 6, k + 12, Blocks.end_stone, 0, 2);
		world.setBlock(i + 27, j + 6, k + 12, Blocks.end_stone, 0, 2);
		world.setBlock(i + 28, j + 6, k + 12, Blocks.end_stone, 0, 2);
		world.setBlock(i + 29, j + 6, k + 12, Blocks.end_stone, 0, 2);
		world.setBlock(i + 30, j + 6, k + 12, Blocks.end_stone, 0, 2);
		world.setBlock(i + 31, j + 6, k + 12, Blocks.end_stone, 0, 2);
		world.setBlock(i + 6, j + 6, k + 13, Blocks.end_stone, 0, 2);
		world.setBlock(i + 7, j + 6, k + 13, Blocks.end_stone, 0, 2);
		world.setBlock(i + 8, j + 6, k + 13, Blocks.end_stone, 0, 2);
		world.setBlock(i + 9, j + 6, k + 13, Blocks.end_stone, 0, 2);
		world.setBlock(i + 10, j + 6, k + 13, Blocks.end_stone, 0, 2);
		world.setBlock(i + 11, j + 6, k + 13, Blocks.end_stone, 0, 2);
		world.setBlock(i + 12, j + 6, k + 13, Blocks.end_stone, 0, 2);
		world.setBlock(i + 13, j + 6, k + 13, Blocks.end_stone, 0, 2);
		world.setBlock(i + 14, j + 6, k + 13, Blocks.end_stone, 0, 2);
		world.setBlock(i + 15, j + 6, k + 13, Blocks.end_stone, 0, 2);
		world.setBlock(i + 16, j + 6, k + 13, Blocks.end_stone, 0, 2);
		world.setBlock(i + 17, j + 6, k + 13, Blocks.end_stone, 0, 2);
		world.setBlock(i + 18, j + 6, k + 13, Blocks.end_stone, 0, 2);
		world.setBlock(i + 19, j + 6, k + 13, Blocks.end_stone, 0, 2);
		world.setBlock(i + 20, j + 6, k + 13, Blocks.end_stone, 0, 2);
		world.setBlock(i + 21, j + 6, k + 13, Blocks.end_stone, 0, 2);
		world.setBlock(i + 22, j + 6, k + 13, Blocks.end_stone, 0, 2);
		world.setBlock(i + 23, j + 6, k + 13, Blocks.end_stone, 0, 2);
		world.setBlock(i + 24, j + 6, k + 13, Blocks.end_stone, 0, 2);
		world.setBlock(i + 25, j + 6, k + 13, Blocks.end_stone, 0, 2);
		world.setBlock(i + 26, j + 6, k + 13, Blocks.end_stone, 0, 2);
		world.setBlock(i + 27, j + 6, k + 13, Blocks.end_stone, 0, 2);
		world.setBlock(i + 28, j + 6, k + 13, Blocks.end_stone, 0, 2);
		world.setBlock(i + 29, j + 6, k + 13, Blocks.end_stone, 0, 2);
		world.setBlock(i + 30, j + 6, k + 13, Blocks.end_stone, 0, 2);
		world.setBlock(i + 31, j + 6, k + 13, Blocks.end_stone, 0, 2);
		world.setBlock(i + 32, j + 6, k + 13, Blocks.end_stone, 0, 2);
		world.setBlock(i + 5, j + 6, k + 14, Blocks.end_stone, 0, 2);
		world.setBlock(i + 6, j + 6, k + 14, Blocks.end_stone, 0, 2);
		world.setBlock(i + 7, j + 6, k + 14, Blocks.end_stone, 0, 2);
		world.setBlock(i + 8, j + 6, k + 14, Blocks.end_stone, 0, 2);
		world.setBlock(i + 9, j + 6, k + 14, Blocks.end_stone, 0, 2);
		world.setBlock(i + 10, j + 6, k + 14, Blocks.end_stone, 0, 2);
		world.setBlock(i + 11, j + 6, k + 14, Blocks.end_stone, 0, 2);
		world.setBlock(i + 12, j + 6, k + 14, Blocks.end_stone, 0, 2);
		world.setBlock(i + 13, j + 6, k + 14, Blocks.end_stone, 0, 2);
		world.setBlock(i + 14, j + 6, k + 14, Blocks.end_stone, 0, 2);
		world.setBlock(i + 15, j + 6, k + 14, Blocks.end_stone, 0, 2);
		world.setBlock(i + 16, j + 6, k + 14, Blocks.end_stone, 0, 2);
		world.setBlock(i + 17, j + 6, k + 14, Blocks.end_stone, 0, 2);
		world.setBlock(i + 18, j + 6, k + 14, Blocks.end_stone, 0, 2);
		world.setBlock(i + 19, j + 6, k + 14, Blocks.end_stone, 0, 2);
		world.setBlock(i + 20, j + 6, k + 14, Blocks.end_stone, 0, 2);
		world.setBlock(i + 21, j + 6, k + 14, Blocks.end_stone, 0, 2);
		world.setBlock(i + 22, j + 6, k + 14, Blocks.end_stone, 0, 2);
		world.setBlock(i + 23, j + 6, k + 14, Blocks.end_stone, 0, 2);
		world.setBlock(i + 24, j + 6, k + 14, Blocks.end_stone, 0, 2);
		world.setBlock(i + 25, j + 6, k + 14, Blocks.end_stone, 0, 2);
		world.setBlock(i + 26, j + 6, k + 14, Blocks.end_stone, 0, 2);
		world.setBlock(i + 27, j + 6, k + 14, Blocks.end_stone, 0, 2);
		world.setBlock(i + 28, j + 6, k + 14, Blocks.end_stone, 0, 2);
		world.setBlock(i + 29, j + 6, k + 14, Blocks.end_stone, 0, 2);
		world.setBlock(i + 30, j + 6, k + 14, Blocks.end_stone, 0, 2);
		world.setBlock(i + 31, j + 6, k + 14, Blocks.end_stone, 0, 2);
		world.setBlock(i + 32, j + 6, k + 14, Blocks.end_stone, 0, 2);
		world.setBlock(i + 33, j + 6, k + 14, Blocks.end_stone, 0, 2);
		world.setBlock(i + 4, j + 6, k + 15, Blocks.end_stone, 0, 2);
		world.setBlock(i + 5, j + 6, k + 15, Blocks.end_stone, 0, 2);
		world.setBlock(i + 6, j + 6, k + 15, Blocks.end_stone, 0, 2);
		world.setBlock(i + 7, j + 6, k + 15, Blocks.end_stone, 0, 2);
		world.setBlock(i + 8, j + 6, k + 15, Blocks.end_stone, 0, 2);
		world.setBlock(i + 9, j + 6, k + 15, Blocks.end_stone, 0, 2);
		world.setBlock(i + 10, j + 6, k + 15, Blocks.end_stone, 0, 2);
		world.setBlock(i + 11, j + 6, k + 15, Blocks.end_stone, 0, 2);
		world.setBlock(i + 12, j + 6, k + 15, Blocks.end_stone, 0, 2);
		world.setBlock(i + 13, j + 6, k + 15, Blocks.end_stone, 0, 2);
		world.setBlock(i + 14, j + 6, k + 15, Blocks.end_stone, 0, 2);
		world.setBlock(i + 15, j + 6, k + 15, Blocks.end_stone, 0, 2);
		world.setBlock(i + 16, j + 6, k + 15, Blocks.end_stone, 0, 2);
		world.setBlock(i + 17, j + 6, k + 15, Blocks.end_stone, 0, 2);
		world.setBlock(i + 18, j + 6, k + 15, Blocks.end_stone, 0, 2);
		world.setBlock(i + 19, j + 6, k + 15, Blocks.end_stone, 0, 2);
		world.setBlock(i + 20, j + 6, k + 15, Blocks.end_stone, 0, 2);
		world.setBlock(i + 21, j + 6, k + 15, Blocks.end_stone, 0, 2);
		world.setBlock(i + 22, j + 6, k + 15, Blocks.end_stone, 0, 2);
		world.setBlock(i + 23, j + 6, k + 15, Blocks.end_stone, 0, 2);
		world.setBlock(i + 24, j + 6, k + 15, Blocks.end_stone, 0, 2);
		world.setBlock(i + 25, j + 6, k + 15, Blocks.end_stone, 0, 2);
		world.setBlock(i + 26, j + 6, k + 15, Blocks.end_stone, 0, 2);
		world.setBlock(i + 27, j + 6, k + 15, Blocks.end_stone, 0, 2);
		world.setBlock(i + 28, j + 6, k + 15, Blocks.end_stone, 0, 2);
		world.setBlock(i + 29, j + 6, k + 15, Blocks.end_stone, 0, 2);
		world.setBlock(i + 30, j + 6, k + 15, Blocks.end_stone, 0, 2);
		world.setBlock(i + 31, j + 6, k + 15, Blocks.end_stone, 0, 2);
		world.setBlock(i + 32, j + 6, k + 15, Blocks.end_stone, 0, 2);
		world.setBlock(i + 33, j + 6, k + 15, Blocks.end_stone, 0, 2);
		world.setBlock(i + 34, j + 6, k + 15, Blocks.end_stone, 0, 2);
		world.setBlock(i + 3, j + 6, k + 16, Blocks.end_stone, 0, 2);
		world.setBlock(i + 4, j + 6, k + 16, Blocks.end_stone, 0, 2);
		world.setBlock(i + 5, j + 6, k + 16, Blocks.end_stone, 0, 2);
		world.setBlock(i + 6, j + 6, k + 16, Blocks.end_stone, 0, 2);
		world.setBlock(i + 7, j + 6, k + 16, Blocks.end_stone, 0, 2);
		world.setBlock(i + 8, j + 6, k + 16, Blocks.end_stone, 0, 2);
		world.setBlock(i + 9, j + 6, k + 16, Blocks.end_stone, 0, 2);
		world.setBlock(i + 10, j + 6, k + 16, Blocks.end_stone, 0, 2);
		world.setBlock(i + 11, j + 6, k + 16, Blocks.end_stone, 0, 2);
		world.setBlock(i + 12, j + 6, k + 16, Blocks.end_stone, 0, 2);
		world.setBlock(i + 13, j + 6, k + 16, Blocks.end_stone, 0, 2);
		world.setBlock(i + 14, j + 6, k + 16, Blocks.end_stone, 0, 2);
		world.setBlock(i + 15, j + 6, k + 16, Blocks.end_stone, 0, 2);
		world.setBlock(i + 16, j + 6, k + 16, Blocks.end_stone, 0, 2);
		world.setBlock(i + 17, j + 6, k + 16, Blocks.end_stone, 0, 2);
		world.setBlock(i + 18, j + 6, k + 16, Blocks.end_stone, 0, 2);
		world.setBlock(i + 19, j + 6, k + 16, Blocks.end_stone, 0, 2);
		world.setBlock(i + 20, j + 6, k + 16, Blocks.end_stone, 0, 2);
		world.setBlock(i + 21, j + 6, k + 16, Blocks.end_stone, 0, 2);
		world.setBlock(i + 22, j + 6, k + 16, Blocks.end_stone, 0, 2);
		world.setBlock(i + 23, j + 6, k + 16, Blocks.end_stone, 0, 2);
		world.setBlock(i + 24, j + 6, k + 16, Blocks.end_stone, 0, 2);
		world.setBlock(i + 25, j + 6, k + 16, Blocks.end_stone, 0, 2);
		world.setBlock(i + 26, j + 6, k + 16, Blocks.end_stone, 0, 2);
		world.setBlock(i + 27, j + 6, k + 16, Blocks.end_stone, 0, 2);
		world.setBlock(i + 28, j + 6, k + 16, Blocks.end_stone, 0, 2);
		world.setBlock(i + 29, j + 6, k + 16, Blocks.end_stone, 0, 2);
		world.setBlock(i + 30, j + 6, k + 16, Blocks.end_stone, 0, 2);
		world.setBlock(i + 31, j + 6, k + 16, Blocks.end_stone, 0, 2);
		world.setBlock(i + 32, j + 6, k + 16, Blocks.end_stone, 0, 2);
		world.setBlock(i + 33, j + 6, k + 16, Blocks.end_stone, 0, 2);
		world.setBlock(i + 34, j + 6, k + 16, Blocks.end_stone, 0, 2);
		world.setBlock(i + 35, j + 6, k + 16, Blocks.end_stone, 0, 2);
		world.setBlock(i + 2, j + 6, k + 17, Blocks.end_stone, 0, 2);
		world.setBlock(i + 3, j + 6, k + 17, Blocks.end_stone, 0, 2);
		world.setBlock(i + 4, j + 6, k + 17, Blocks.end_stone, 0, 2);
		world.setBlock(i + 5, j + 6, k + 17, Blocks.end_stone, 0, 2);
		world.setBlock(i + 6, j + 6, k + 17, Blocks.end_stone, 0, 2);
		world.setBlock(i + 7, j + 6, k + 17, Blocks.end_stone, 0, 2);
		world.setBlock(i + 8, j + 6, k + 17, Blocks.end_stone, 0, 2);
		world.setBlock(i + 9, j + 6, k + 17, Blocks.end_stone, 0, 2);
		world.setBlock(i + 10, j + 6, k + 17, Blocks.end_stone, 0, 2);
		world.setBlock(i + 11, j + 6, k + 17, Blocks.end_stone, 0, 2);
		world.setBlock(i + 12, j + 6, k + 17, Blocks.end_stone, 0, 2);
		world.setBlock(i + 13, j + 6, k + 17, Blocks.end_stone, 0, 2);
		world.setBlock(i + 14, j + 6, k + 17, Blocks.end_stone, 0, 2);
		world.setBlock(i + 15, j + 6, k + 17, Blocks.end_stone, 0, 2);
		world.setBlock(i + 16, j + 6, k + 17, Blocks.end_stone, 0, 2);
		world.setBlock(i + 17, j + 6, k + 17, Blocks.end_stone, 0, 2);
		world.setBlock(i + 18, j + 6, k + 17, Blocks.end_stone, 0, 2);
		world.setBlock(i + 19, j + 6, k + 17, Blocks.end_stone, 0, 2);
		world.setBlock(i + 20, j + 6, k + 17, Blocks.end_stone, 0, 2);
		world.setBlock(i + 21, j + 6, k + 17, Blocks.end_stone, 0, 2);
		world.setBlock(i + 22, j + 6, k + 17, Blocks.end_stone, 0, 2);
		world.setBlock(i + 23, j + 6, k + 17, Blocks.end_stone, 0, 2);
		world.setBlock(i + 24, j + 6, k + 17, Blocks.end_stone, 0, 2);
		world.setBlock(i + 25, j + 6, k + 17, Blocks.end_stone, 0, 2);
		world.setBlock(i + 26, j + 6, k + 17, Blocks.end_stone, 0, 2);
		world.setBlock(i + 27, j + 6, k + 17, Blocks.end_stone, 0, 2);
		world.setBlock(i + 28, j + 6, k + 17, Blocks.end_stone, 0, 2);
		world.setBlock(i + 29, j + 6, k + 17, Blocks.end_stone, 0, 2);
		world.setBlock(i + 30, j + 6, k + 17, Blocks.end_stone, 0, 2);
		world.setBlock(i + 31, j + 6, k + 17, Blocks.end_stone, 0, 2);
		world.setBlock(i + 32, j + 6, k + 17, Blocks.end_stone, 0, 2);
		world.setBlock(i + 33, j + 6, k + 17, Blocks.end_stone, 0, 2);
		world.setBlock(i + 34, j + 6, k + 17, Blocks.end_stone, 0, 2);
		world.setBlock(i + 35, j + 6, k + 17, Blocks.end_stone, 0, 2);
		world.setBlock(i + 36, j + 6, k + 17, Blocks.end_stone, 0, 2);
		world.setBlock(i + 1, j + 6, k + 18, Blocks.end_stone, 0, 2);
		world.setBlock(i + 2, j + 6, k + 18, Blocks.end_stone, 0, 2);
		world.setBlock(i + 3, j + 6, k + 18, Blocks.end_stone, 0, 2);
		world.setBlock(i + 4, j + 6, k + 18, Blocks.end_stone, 0, 2);
		world.setBlock(i + 5, j + 6, k + 18, Blocks.end_stone, 0, 2);
		world.setBlock(i + 6, j + 6, k + 18, Blocks.end_stone, 0, 2);
		world.setBlock(i + 7, j + 6, k + 18, Blocks.end_stone, 0, 2);
		world.setBlock(i + 8, j + 6, k + 18, Blocks.end_stone, 0, 2);
		world.setBlock(i + 9, j + 6, k + 18, Blocks.end_stone, 0, 2);
		world.setBlock(i + 10, j + 6, k + 18, Blocks.end_stone, 0, 2);
		world.setBlock(i + 11, j + 6, k + 18, Blocks.end_stone, 0, 2);
		world.setBlock(i + 12, j + 6, k + 18, Blocks.end_stone, 0, 2);
		world.setBlock(i + 13, j + 6, k + 18, Blocks.end_stone, 0, 2);
		world.setBlock(i + 14, j + 6, k + 18, Blocks.end_stone, 0, 2);
		world.setBlock(i + 15, j + 6, k + 18, Blocks.end_stone, 0, 2);
		world.setBlock(i + 16, j + 6, k + 18, Blocks.end_stone, 0, 2);
		world.setBlock(i + 17, j + 6, k + 18, Blocks.end_stone, 0, 2);
		world.setBlock(i + 18, j + 6, k + 18, Blocks.end_stone, 0, 2);
		world.setBlock(i + 19, j + 6, k + 18, Blocks.end_stone, 0, 2);
		world.setBlock(i + 20, j + 6, k + 18, Blocks.end_stone, 0, 2);
		world.setBlock(i + 21, j + 6, k + 18, Blocks.end_stone, 0, 2);
		world.setBlock(i + 22, j + 6, k + 18, Blocks.end_stone, 0, 2);
		world.setBlock(i + 23, j + 6, k + 18, Blocks.end_stone, 0, 2);
		world.setBlock(i + 24, j + 6, k + 18, Blocks.end_stone, 0, 2);
		world.setBlock(i + 25, j + 6, k + 18, Blocks.end_stone, 0, 2);
		world.setBlock(i + 26, j + 6, k + 18, Blocks.end_stone, 0, 2);
		world.setBlock(i + 27, j + 6, k + 18, Blocks.end_stone, 0, 2);
		world.setBlock(i + 28, j + 6, k + 18, Blocks.end_stone, 0, 2);
		world.setBlock(i + 29, j + 6, k + 18, Blocks.end_stone, 0, 2);
		world.setBlock(i + 30, j + 6, k + 18, Blocks.end_stone, 0, 2);
		world.setBlock(i + 31, j + 6, k + 18, Blocks.end_stone, 0, 2);
		world.setBlock(i + 32, j + 6, k + 18, Blocks.end_stone, 0, 2);
		world.setBlock(i + 33, j + 6, k + 18, Blocks.end_stone, 0, 2);
		world.setBlock(i + 34, j + 6, k + 18, Blocks.end_stone, 0, 2);
		world.setBlock(i + 35, j + 6, k + 18, Blocks.end_stone, 0, 2);
		world.setBlock(i + 36, j + 6, k + 18, Blocks.end_stone, 0, 2);
		world.setBlock(i + 37, j + 6, k + 18, Blocks.end_stone, 0, 2);
		world.setBlock(i + 0, j + 6, k + 19, Blocks.end_stone, 0, 2);
		world.setBlock(i + 1, j + 6, k + 19, Blocks.end_stone, 0, 2);
		world.setBlock(i + 2, j + 6, k + 19, Blocks.end_stone, 0, 2);
		world.setBlock(i + 3, j + 6, k + 19, Blocks.end_stone, 0, 2);
		world.setBlock(i + 4, j + 6, k + 19, Blocks.end_stone, 0, 2);
		world.setBlock(i + 5, j + 6, k + 19, Blocks.end_stone, 0, 2);
		world.setBlock(i + 6, j + 6, k + 19, Blocks.end_stone, 0, 2);
		world.setBlock(i + 7, j + 6, k + 19, Blocks.end_stone, 0, 2);
		world.setBlock(i + 8, j + 6, k + 19, Blocks.end_stone, 0, 2);
		world.setBlock(i + 9, j + 6, k + 19, Blocks.end_stone, 0, 2);
		world.setBlock(i + 10, j + 6, k + 19, Blocks.end_stone, 0, 2);
		world.setBlock(i + 11, j + 6, k + 19, Blocks.end_stone, 0, 2);
		world.setBlock(i + 12, j + 6, k + 19, Blocks.end_stone, 0, 2);
		world.setBlock(i + 13, j + 6, k + 19, Blocks.end_stone, 0, 2);
		world.setBlock(i + 14, j + 6, k + 19, Blocks.end_stone, 0, 2);
		world.setBlock(i + 15, j + 6, k + 19, Blocks.end_stone, 0, 2);
		world.setBlock(i + 16, j + 6, k + 19, Blocks.end_stone, 0, 2);
		world.setBlock(i + 17, j + 6, k + 19, Blocks.end_stone, 0, 2);
		world.setBlock(i + 18, j + 6, k + 19, Blocks.end_stone, 0, 2);
		world.setBlock(i + 19, j + 6, k + 19, Blocks.end_stone, 0, 2);
		world.setBlock(i + 20, j + 6, k + 19, Blocks.end_stone, 0, 2);
		world.setBlock(i + 21, j + 6, k + 19, Blocks.end_stone, 0, 2);
		world.setBlock(i + 22, j + 6, k + 19, Blocks.end_stone, 0, 2);
		world.setBlock(i + 23, j + 6, k + 19, Blocks.end_stone, 0, 2);
		world.setBlock(i + 24, j + 6, k + 19, Blocks.end_stone, 0, 2);
		world.setBlock(i + 25, j + 6, k + 19, Blocks.end_stone, 0, 2);
		world.setBlock(i + 26, j + 6, k + 19, Blocks.end_stone, 0, 2);
		world.setBlock(i + 27, j + 6, k + 19, Blocks.end_stone, 0, 2);
		world.setBlock(i + 28, j + 6, k + 19, Blocks.end_stone, 0, 2);
		world.setBlock(i + 29, j + 6, k + 19, Blocks.end_stone, 0, 2);
		world.setBlock(i + 30, j + 6, k + 19, Blocks.end_stone, 0, 2);
		world.setBlock(i + 31, j + 6, k + 19, Blocks.end_stone, 0, 2);
		world.setBlock(i + 32, j + 6, k + 19, Blocks.end_stone, 0, 2);
		world.setBlock(i + 33, j + 6, k + 19, Blocks.end_stone, 0, 2);
		world.setBlock(i + 34, j + 6, k + 19, Blocks.end_stone, 0, 2);
		world.setBlock(i + 35, j + 6, k + 19, Blocks.end_stone, 0, 2);
		world.setBlock(i + 36, j + 6, k + 19, Blocks.end_stone, 0, 2);
		world.setBlock(i + 37, j + 6, k + 19, Blocks.end_stone, 0, 2);
		world.setBlock(i + 38, j + 6, k + 19, Blocks.end_stone, 0, 2);
		world.setBlock(i + 0, j + 6, k + 20, Blocks.end_stone, 0, 2);
		world.setBlock(i + 1, j + 6, k + 20, Blocks.end_stone, 0, 2);
		world.setBlock(i + 2, j + 6, k + 20, Blocks.end_stone, 0, 2);
		world.setBlock(i + 3, j + 6, k + 20, Blocks.end_stone, 0, 2);
		world.setBlock(i + 4, j + 6, k + 20, Blocks.end_stone, 0, 2);
		world.setBlock(i + 5, j + 6, k + 20, Blocks.end_stone, 0, 2);
		world.setBlock(i + 6, j + 6, k + 20, Blocks.end_stone, 0, 2);
		world.setBlock(i + 7, j + 6, k + 20, Blocks.end_stone, 0, 2);
		world.setBlock(i + 8, j + 6, k + 20, Blocks.end_stone, 0, 2);
		world.setBlock(i + 9, j + 6, k + 20, Blocks.end_stone, 0, 2);
		world.setBlock(i + 10, j + 6, k + 20, Blocks.end_stone, 0, 2);
		world.setBlock(i + 11, j + 6, k + 20, Blocks.end_stone, 0, 2);
		world.setBlock(i + 12, j + 6, k + 20, Blocks.end_stone, 0, 2);
		world.setBlock(i + 13, j + 6, k + 20, Blocks.end_stone, 0, 2);
		world.setBlock(i + 14, j + 6, k + 20, Blocks.end_stone, 0, 2);
		world.setBlock(i + 15, j + 6, k + 20, Blocks.end_stone, 0, 2);
		world.setBlock(i + 16, j + 6, k + 20, Blocks.end_stone, 0, 2);
		world.setBlock(i + 17, j + 6, k + 20, Blocks.end_stone, 0, 2);
		world.setBlock(i + 18, j + 6, k + 20, Blocks.end_stone, 0, 2);
		world.setBlock(i + 19, j + 6, k + 20, Blocks.end_stone, 0, 2);
		world.setBlock(i + 20, j + 6, k + 20, Blocks.end_stone, 0, 2);
		world.setBlock(i + 21, j + 6, k + 20, Blocks.end_stone, 0, 2);
		world.setBlock(i + 22, j + 6, k + 20, Blocks.end_stone, 0, 2);
		world.setBlock(i + 23, j + 6, k + 20, Blocks.end_stone, 0, 2);
		world.setBlock(i + 24, j + 6, k + 20, Blocks.end_stone, 0, 2);
		world.setBlock(i + 25, j + 6, k + 20, Blocks.end_stone, 0, 2);
		world.setBlock(i + 26, j + 6, k + 20, Blocks.end_stone, 0, 2);
		world.setBlock(i + 27, j + 6, k + 20, Blocks.end_stone, 0, 2);
		world.setBlock(i + 28, j + 6, k + 20, Blocks.end_stone, 0, 2);
		world.setBlock(i + 29, j + 6, k + 20, Blocks.end_stone, 0, 2);
		world.setBlock(i + 30, j + 6, k + 20, Blocks.end_stone, 0, 2);
		world.setBlock(i + 31, j + 6, k + 20, Blocks.end_stone, 0, 2);
		world.setBlock(i + 32, j + 6, k + 20, Blocks.end_stone, 0, 2);
		world.setBlock(i + 33, j + 6, k + 20, Blocks.end_stone, 0, 2);
		world.setBlock(i + 34, j + 6, k + 20, Blocks.end_stone, 0, 2);
		world.setBlock(i + 35, j + 6, k + 20, Blocks.end_stone, 0, 2);
		world.setBlock(i + 36, j + 6, k + 20, Blocks.end_stone, 0, 2);
		world.setBlock(i + 37, j + 6, k + 20, Blocks.end_stone, 0, 2);
		world.setBlock(i + 38, j + 6, k + 20, Blocks.end_stone, 0, 2);
		world.setBlock(i + 39, j + 6, k + 20, Blocks.end_stone, 0, 2);
		world.setBlock(i + 1, j + 6, k + 21, Blocks.end_stone, 0, 2);
		world.setBlock(i + 2, j + 6, k + 21, Blocks.end_stone, 0, 2);
		world.setBlock(i + 3, j + 6, k + 21, Blocks.end_stone, 0, 2);
		world.setBlock(i + 4, j + 6, k + 21, Blocks.end_stone, 0, 2);
		world.setBlock(i + 5, j + 6, k + 21, Blocks.end_stone, 0, 2);
		world.setBlock(i + 6, j + 6, k + 21, Blocks.end_stone, 0, 2);
		world.setBlock(i + 7, j + 6, k + 21, Blocks.end_stone, 0, 2);
		world.setBlock(i + 8, j + 6, k + 21, Blocks.end_stone, 0, 2);
		world.setBlock(i + 9, j + 6, k + 21, Blocks.end_stone, 0, 2);
		world.setBlock(i + 10, j + 6, k + 21, Blocks.end_stone, 0, 2);
		world.setBlock(i + 11, j + 6, k + 21, Blocks.end_stone, 0, 2);
		world.setBlock(i + 12, j + 6, k + 21, Blocks.end_stone, 0, 2);
		world.setBlock(i + 13, j + 6, k + 21, Blocks.end_stone, 0, 2);
		world.setBlock(i + 14, j + 6, k + 21, Blocks.end_stone, 0, 2);
		world.setBlock(i + 15, j + 6, k + 21, Blocks.end_stone, 0, 2);
		world.setBlock(i + 16, j + 6, k + 21, Blocks.end_stone, 0, 2);
		world.setBlock(i + 17, j + 6, k + 21, Blocks.end_stone, 0, 2);
		world.setBlock(i + 18, j + 6, k + 21, Blocks.end_stone, 0, 2);
		world.setBlock(i + 19, j + 6, k + 21, Blocks.end_stone, 0, 2);
		world.setBlock(i + 20, j + 6, k + 21, Blocks.end_stone, 0, 2);
