package com.NovaCraft.world.end.endcamp;

import java.util.Random;

import com.NovaCraft.registry.OtherModBlocks;
import com.NovaCraftBlocks.NovaCraftBlocks;

import net.minecraft.block.Block;
import net.minecraft.init.Blocks;
import net.minecraft.world.World;
import net.minecraft.world.gen.feature.WorldGenerator;

public class EnderCampTreasureTowerPart2Gen extends WorldGenerator
{
	public EnderCampTreasureTowerPart2Gen() {

	}
	
	public boolean generate(final World world, final Random random, final int i, final int j, final int k) {
		
		world.setBlock(i + 10, j + 5, k + 16, Blocks.end_stone, 0, 2);
		world.setBlock(i + 11, j + 5, k + 16, Blocks.end_stone, 0, 2);
		world.setBlock(i + 12, j + 5, k + 16, NovaCraftBlocks.nullstone_tiles, 0, 2);
		world.setBlock(i + 13, j + 5, k + 16, NovaCraftBlocks.lacuna_planks, 0, 2);
		world.setBlock(i + 14, j + 5, k + 16, NovaCraftBlocks.lacuna_planks, 0, 2);
		world.setBlock(i + 15, j + 5, k + 16, NovaCraftBlocks.lacuna_planks, 0, 2);
		world.setBlock(i + 16, j + 5, k + 16, NovaCraftBlocks.lacuna_planks, 0, 2);
		world.setBlock(i + 17, j + 5, k + 16, NovaCraftBlocks.lacuna_planks, 0, 2);
		world.setBlock(i + 18, j + 5, k + 16, NovaCraftBlocks.lacuna_planks, 0, 2);
		world.setBlock(i + 19, j + 5, k + 16, NovaCraftBlocks.lacuna_planks, 0, 2);
		world.setBlock(i + 20, j + 5, k + 16, NovaCraftBlocks.nullstone_tiles, 0, 2);
		world.setBlock(i + 21, j + 5, k + 16, Blocks.end_stone, 0, 2);
		world.setBlock(i + 22, j + 5, k + 16, Blocks.end_stone, 0, 2);
		world.setBlock(i + 23, j + 5, k + 16, Blocks.end_stone, 0, 2);
		world.setBlock(i + 24, j + 5, k + 16, Blocks.end_stone, 0, 2);
		world.setBlock(i + 25, j + 5, k + 16, Blocks.end_stone, 0, 2);
		world.setBlock(i + 26, j + 5, k + 16, OtherModBlocks.end_bricks, 0, 2);
		world.setBlock(i + 0, j + 5, k + 17, OtherModBlocks.end_bricks, 0, 2);
		world.setBlock(i + 1, j + 5, k + 17, Blocks.end_stone, 0, 2);
		world.setBlock(i + 2, j + 5, k + 17, Blocks.end_stone, 0, 2);
		world.setBlock(i + 3, j + 5, k + 17, NovaCraftBlocks.lacuna_planks, 0, 2);
		world.setBlock(i + 4, j + 5, k + 17, NovaCraftBlocks.lacuna_planks, 0, 2);
		world.setBlock(i + 5, j + 5, k + 17, Blocks.end_stone, 0, 2);
		world.setBlock(i + 6, j + 5, k + 17, Blocks.end_stone, 0, 2);
		world.setBlock(i + 7, j + 5, k + 17, Blocks.end_stone, 0, 2);
		world.setBlock(i + 8, j + 5, k + 17, Blocks.end_stone, 0, 2);
		world.setBlock(i + 9, j + 5, k + 17, Blocks.end_stone, 0, 2);
		world.setBlock(i + 10, j + 5, k + 17, Blocks.end_stone, 0, 2);
		world.setBlock(i + 11, j + 5, k + 17, NovaCraftBlocks.nullstone_tiles, 0, 2);
		world.setBlock(i + 12, j + 5, k + 17, NovaCraftBlocks.lacuna_planks, 0, 2);
		world.setBlock(i + 13, j + 5, k + 17, NovaCraftBlocks.lacuna_planks, 0, 2);
		world.setBlock(i + 14, j + 5, k + 17, NovaCraftBlocks.lacuna_planks, 0, 2);
		world.setBlock(i + 15, j + 5, k + 17, NovaCraftBlocks.lacuna_planks, 0, 2);
		world.setBlock(i + 16, j + 5, k + 17, OtherModBlocks.purpur_pillar, 0, 2);
		world.setBlock(i + 17, j + 5, k + 17, NovaCraftBlocks.lacuna_planks, 0, 2);
		world.setBlock(i + 18, j + 5, k + 17, NovaCraftBlocks.lacuna_planks, 0, 2);
		world.setBlock(i + 19, j + 5, k + 17, NovaCraftBlocks.lacuna_planks, 0, 2);
		world.setBlock(i + 20, j + 5, k + 17, NovaCraftBlocks.lacuna_planks, 0, 2);
		world.setBlock(i + 21, j + 5, k + 17, NovaCraftBlocks.nullstone_tiles, 0, 2);
		world.setBlock(i + 22, j + 5, k + 17, Blocks.end_stone, 0, 2);
		world.setBlock(i + 23, j + 5, k + 17, Blocks.end_stone, 0, 2);
		world.setBlock(i + 24, j + 5, k + 17, Blocks.end_stone, 0, 2);
		world.setBlock(i + 25, j + 5, k + 17, Blocks.end_stone, 0, 2);
		world.setBlock(i + 26, j + 5, k + 17, OtherModBlocks.end_bricks, 0, 2);
		world.setBlock(i + 0, j + 5, k + 18, OtherModBlocks.end_bricks, 0, 2);
		world.setBlock(i + 1, j + 5, k + 18, Blocks.end_stone, 0, 2);
		world.setBlock(i + 2, j + 5, k + 18, NovaCraftBlocks.lacuna_planks, 0, 2);
		world.setBlock(i + 3, j + 5, k + 18, NovaCraftBlocks.lacuna_planks, 0, 2);
		world.setBlock(i + 4, j + 5, k + 18, NovaCraftBlocks.lacuna_planks, 0, 2);
		world.setBlock(i + 5, j + 5, k + 18, NovaCraftBlocks.lacuna_planks, 0, 2);
		world.setBlock(i + 6, j + 5, k + 18, Blocks.end_stone, 0, 2);
		world.setBlock(i + 7, j + 5, k + 18, Blocks.end_stone, 0, 2);
		world.setBlock(i + 8, j + 5, k + 18, Blocks.end_stone, 0, 2);
		world.setBlock(i + 9, j + 5, k + 18, Blocks.end_stone, 0, 2);
		world.setBlock(i + 10, j + 5, k + 18, Blocks.end_stone, 0, 2);
		world.setBlock(i + 11, j + 5, k + 18, NovaCraftBlocks.nullstone_tiles, 0, 2);
		world.setBlock(i + 12, j + 5, k + 18, NovaCraftBlocks.lacuna_planks, 0, 2);
		world.setBlock(i + 13, j + 5, k + 18, NovaCraftBlocks.lacuna_planks, 0, 2);
		world.setBlock(i + 14, j + 5, k + 18, NovaCraftBlocks.lacuna_planks, 0, 2);
		world.setBlock(i + 15, j + 5, k + 18, OtherModBlocks.purpur_pillar, 0, 2);
		world.setBlock(i + 16, j + 5, k + 18, NovaCraftBlocks.living_ender, 0, 2);
		world.setBlock(i + 17, j + 5, k + 18, OtherModBlocks.purpur_pillar, 0, 2);
		world.setBlock(i + 18, j + 5, k + 18, NovaCraftBlocks.lacuna_planks, 0, 2);
		world.setBlock(i + 19, j + 5, k + 18, NovaCraftBlocks.lacuna_planks, 0, 2);
		world.setBlock(i + 20, j + 5, k + 18, NovaCraftBlocks.lacuna_planks, 0, 2);
		world.setBlock(i + 21, j + 5, k + 18, NovaCraftBlocks.lacuna_planks, 0, 2);
		world.setBlock(i + 22, j + 5, k + 18, NovaCraftBlocks.nullstone_tiles, 0, 2);
		world.setBlock(i + 23, j + 5, k + 18, Blocks.end_stone, 0, 2);
		world.setBlock(i + 24, j + 5, k + 18, Blocks.end_stone, 0, 2);
		world.setBlock(i + 25, j + 5, k + 18, Blocks.end_stone, 0, 2);
		world.setBlock(i + 26, j + 5, k + 18, OtherModBlocks.end_bricks, 0, 2);
		world.setBlock(i + 0, j + 5, k + 19, OtherModBlocks.end_bricks, 0, 2);
		world.setBlock(i + 1, j + 5, k + 19, Blocks.end_stone, 0, 2);
		world.setBlock(i + 2, j + 5, k + 19, NovaCraftBlocks.lacuna_planks, 0, 2);
		world.setBlock(i + 3, j + 5, k + 19, NovaCraftBlocks.lacuna_planks, 0, 2);
		world.setBlock(i + 4, j + 5, k + 19, NovaCraftBlocks.lacuna_planks, 0, 2);
		world.setBlock(i + 5, j + 5, k + 19, NovaCraftBlocks.lacuna_planks, 0, 2);
		world.setBlock(i + 6, j + 5, k + 19, Blocks.end_stone, 0, 2);
		world.setBlock(i + 7, j + 5, k + 19, Blocks.end_stone, 0, 2);
		world.setBlock(i + 8, j + 5, k + 19, Blocks.end_stone, 0, 2);
		world.setBlock(i + 9, j + 5, k + 19, Blocks.end_stone, 0, 2);
		world.setBlock(i + 10, j + 5, k + 19, Blocks.end_stone, 0, 2);
		world.setBlock(i + 11, j + 5, k + 19, NovaCraftBlocks.nullstone_tiles, 0, 2);
		world.setBlock(i + 12, j + 5, k + 19, NovaCraftBlocks.lacuna_planks, 0, 2);
		world.setBlock(i + 13, j + 5, k + 19, NovaCraftBlocks.lacuna_planks, 0, 2);
		world.setBlock(i + 14, j + 5, k + 19, NovaCraftBlocks.lacuna_planks, 0, 2);
		world.setBlock(i + 15, j + 5, k + 19, NovaCraftBlocks.lacuna_planks, 0, 2);
		world.setBlock(i + 16, j + 5, k + 19, OtherModBlocks.purpur_pillar, 0, 2);
		world.setBlock(i + 17, j + 5, k + 19, NovaCraftBlocks.lacuna_planks, 0, 2);
		world.setBlock(i + 18, j + 5, k + 19, NovaCraftBlocks.lacuna_planks, 0, 2);
		world.setBlock(i + 19, j + 5, k + 19, NovaCraftBlocks.lacuna_planks, 0, 2);
		world.setBlock(i + 20, j + 5, k + 19, NovaCraftBlocks.lacuna_planks, 0, 2);
		world.setBlock(i + 21, j + 5, k + 19, NovaCraftBlocks.nullstone_tiles, 0, 2);
		world.setBlock(i + 22, j + 5, k + 19, Blocks.end_stone, 0, 2);
		world.setBlock(i + 23, j + 5, k + 19, Blocks.end_stone, 0, 2);
		world.setBlock(i + 24, j + 5, k + 19, Blocks.end_stone, 0, 2);
		world.setBlock(i + 25, j + 5, k + 19, Blocks.end_stone, 0, 2);
		world.setBlock(i + 26, j + 5, k + 19, OtherModBlocks.end_bricks, 0, 2);
		world.setBlock(i + 0, j + 5, k + 20, OtherModBlocks.end_bricks, 0, 2);
		world.setBlock(i + 1, j + 5, k + 20, Blocks.end_stone, 0, 2);
		world.setBlock(i + 2, j + 5, k + 20, Blocks.end_stone, 0, 2);
		world.setBlock(i + 3, j + 5, k + 20, NovaCraftBlocks.lacuna_planks, 0, 2);
		world.setBlock(i + 4, j + 5, k + 20, NovaCraftBlocks.lacuna_planks, 0, 2);
		world.setBlock(i + 5, j + 5, k + 20, Blocks.end_stone, 0, 2);
		world.setBlock(i + 6, j + 5, k + 20, Blocks.end_stone, 0, 2);
		world.setBlock(i + 7, j + 5, k + 20, Blocks.end_stone, 0, 2);
		world.setBlock(i + 8, j + 5, k + 20, Blocks.end_stone, 0, 2);
		world.setBlock(i + 9, j + 5, k + 20, Blocks.end_stone, 0, 2);
		world.setBlock(i + 10, j + 5, k + 20, Blocks.end_stone, 0, 2);
		world.setBlock(i + 11, j + 5, k + 20, Blocks.end_stone, 0, 2);
		world.setBlock(i + 12, j + 5, k + 20, NovaCraftBlocks.nullstone_tiles, 0, 2);
		world.setBlock(i + 13, j + 5, k + 20, NovaCraftBlocks.lacuna_planks, 0, 2);
		world.setBlock(i + 14, j + 5, k + 20, NovaCraftBlocks.lacuna_planks, 0, 2);
		world.setBlock(i + 15, j + 5, k + 20, NovaCraftBlocks.lacuna_planks, 0, 2);
		world.setBlock(i + 16, j + 5, k + 20, NovaCraftBlocks.lacuna_planks, 0, 2);
		world.setBlock(i + 17, j + 5, k + 20, NovaCraftBlocks.lacuna_planks, 0, 2);
		world.setBlock(i + 18, j + 5, k + 20, NovaCraftBlocks.lacuna_planks, 0, 2);
		world.setBlock(i + 19, j + 5, k + 20, NovaCraftBlocks.lacuna_planks, 0, 2);
		world.setBlock(i + 20, j + 5, k + 20, NovaCraftBlocks.nullstone_tiles, 0, 2);
		world.setBlock(i + 21, j + 5, k + 20, Blocks.end_stone, 0, 2);
		world.setBlock(i + 22, j + 5, k + 20, Blocks.end_stone, 0, 2);
		world.setBlock(i + 23, j + 5, k + 20, Blocks.end_stone, 0, 2);
		world.setBlock(i + 24, j + 5, k + 20, Blocks.end_stone, 0, 2);
		world.setBlock(i + 25, j + 5, k + 20, Blocks.end_stone, 0, 2);
		world.setBlock(i + 26, j + 5, k + 20, OtherModBlocks.end_bricks, 0, 2);
		world.setBlock(i + 1, j + 5, k + 21, OtherModBlocks.end_bricks, 0, 2);
		world.setBlock(i + 2, j + 5, k + 21, Blocks.end_stone, 0, 2);
		world.setBlock(i + 3, j + 5, k + 21, Blocks.end_stone, 0, 2);
		world.setBlock(i + 4, j + 5, k + 21, Blocks.end_stone, 0, 2);
		world.setBlock(i + 5, j + 5, k + 21, Blocks.end_stone, 0, 2);
		world.setBlock(i + 6, j + 5, k + 21, Blocks.end_stone, 0, 2);
		world.setBlock(i + 7, j + 5, k + 21, Blocks.end_stone, 0, 2);
		world.setBlock(i + 8, j + 5, k + 21, Blocks.end_stone, 0, 2);
		world.setBlock(i + 9, j + 5, k + 21, Blocks.end_stone, 0, 2);
		world.setBlock(i + 10, j + 5, k + 21, Blocks.end_stone, 0, 2);
		world.setBlock(i + 11, j + 5, k + 21, Blocks.end_stone, 0, 2);
		world.setBlock(i + 12, j + 5, k + 21, Blocks.end_stone, 0, 2);
		world.setBlock(i + 13, j + 5, k + 21, NovaCraftBlocks.nullstone_tiles, 0, 2);
		world.setBlock(i + 14, j + 5, k + 21, NovaCraftBlocks.lacuna_planks, 0, 2);
		world.setBlock(i + 15, j + 5, k + 21, NovaCraftBlocks.lacuna_planks, 0, 2);
		world.setBlock(i + 16, j + 5, k + 21, NovaCraftBlocks.lacuna_planks, 0, 2);
		world.setBlock(i + 17, j + 5, k + 21, NovaCraftBlocks.lacuna_planks, 0, 2);
		world.setBlock(i + 18, j + 5, k + 21, NovaCraftBlocks.lacuna_planks, 0, 2);
		world.setBlock(i + 19, j + 5, k + 21, NovaCraftBlocks.nullstone_tiles, 0, 2);
		world.setBlock(i + 20, j + 5, k + 21, Blocks.end_stone, 0, 2);
		world.setBlock(i + 21, j + 5, k + 21, Blocks.end_stone, 0, 2);
		world.setBlock(i + 22, j + 5, k + 21, Blocks.end_stone, 0, 2);
		world.setBlock(i + 23, j + 5, k + 21, Blocks.end_stone, 0, 2);
		world.setBlock(i + 24, j + 5, k + 21, Blocks.end_stone, 0, 2);
		world.setBlock(i + 25, j + 5, k + 21, Blocks.end_stone, 0, 2);
		world.setBlock(i + 26, j + 5, k + 21, OtherModBlocks.end_bricks, 0, 2);
		world.setBlock(i + 2, j + 5, k + 22, OtherModBlocks.end_bricks, 0, 2);
		world.setBlock(i + 3, j + 5, k + 22, Blocks.end_stone, 0, 2);
		world.setBlock(i + 4, j + 5, k + 22, Blocks.end_stone, 0, 2);
		world.setBlock(i + 5, j + 5, k + 22, Blocks.end_stone, 0, 2);
		world.setBlock(i + 6, j + 5, k + 22, Blocks.end_stone, 0, 2);
		world.setBlock(i + 7, j + 5, k + 22, Blocks.end_stone, 0, 2);
		world.setBlock(i + 8, j + 5, k + 22, Blocks.end_stone, 0, 2);
		world.setBlock(i + 9, j + 5, k + 22, Blocks.end_stone, 0, 2);
		world.setBlock(i + 10, j + 5, k + 22, Blocks.end_stone, 0, 2);
		world.setBlock(i + 11, j + 5, k + 22, Blocks.end_stone, 0, 2);
		world.setBlock(i + 12, j + 5, k + 22, Blocks.end_stone, 0, 2);
		world.setBlock(i + 13, j + 5, k + 22, Blocks.end_stone, 0, 2);
		world.setBlock(i + 14, j + 5, k + 22, NovaCraftBlocks.nullstone_tiles, 0, 2);
		world.setBlock(i + 15, j + 5, k + 22, NovaCraftBlocks.lacuna_planks, 0, 2);
		world.setBlock(i + 16, j + 5, k + 22, NovaCraftBlocks.lacuna_planks, 0, 2);
		world.setBlock(i + 17, j + 5, k + 22, NovaCraftBlocks.lacuna_planks, 0, 2);
		world.setBlock(i + 18, j + 5, k + 22, NovaCraftBlocks.nullstone_tiles, 0, 2);
		world.setBlock(i + 19, j + 5, k + 22, Blocks.end_stone, 0, 2);
		world.setBlock(i + 20, j + 5, k + 22, Blocks.end_stone, 0, 2);
		world.setBlock(i + 21, j + 5, k + 22, Blocks.end_stone, 0, 2);
		world.setBlock(i + 22, j + 5, k + 22, Blocks.end_stone, 0, 2);
		world.setBlock(i + 23, j + 5, k + 22, Blocks.end_stone, 0, 2);
		world.setBlock(i + 24, j + 5, k + 22, Blocks.end_stone, 0, 2);
		world.setBlock(i + 25, j + 5, k + 22, Blocks.end_stone, 0, 2);
		world.setBlock(i + 26, j + 5, k + 22, OtherModBlocks.end_bricks, 0, 2);
		world.setBlock(i + 3, j + 5, k + 23, OtherModBlocks.end_bricks, 0, 2);
		world.setBlock(i + 4, j + 5, k + 23, Blocks.end_stone, 0, 2);
		world.setBlock(i + 5, j + 5, k + 23, Blocks.end_stone, 0, 2);
		world.setBlock(i + 6, j + 5, k + 23, Blocks.end_stone, 0, 2);
		world.setBlock(i + 7, j + 5, k + 23, Blocks.end_stone, 0, 2);
		world.setBlock(i + 8, j + 5, k + 23, Blocks.end_stone, 0, 2);
		world.setBlock(i + 9, j + 5, k + 23, Blocks.end_stone, 0, 2);
		world.setBlock(i + 10, j + 5, k + 23, Blocks.end_stone, 0, 2);
		world.setBlock(i + 11, j + 5, k + 23, Blocks.end_stone, 0, 2);
		world.setBlock(i + 12, j + 5, k + 23, Blocks.end_stone, 0, 2);
		world.setBlock(i + 13, j + 5, k + 23, Blocks.end_stone, 0, 2);
		world.setBlock(i + 14, j + 5, k + 23, Blocks.end_stone, 0, 2);
		world.setBlock(i + 15, j + 5, k + 23, NovaCraftBlocks.nullstone_tiles, 0, 2);
		world.setBlock(i + 16, j + 5, k + 23, NovaCraftBlocks.nullstone_tiles, 0, 2);
		world.setBlock(i + 17, j + 5, k + 23, NovaCraftBlocks.nullstone_tiles, 0, 2);
		world.setBlock(i + 18, j + 5, k + 23, Blocks.end_stone, 0, 2);
		world.setBlock(i + 19, j + 5, k + 23, Blocks.end_stone, 0, 2);
		world.setBlock(i + 20, j + 5, k + 23, Blocks.end_stone, 0, 2);
		world.setBlock(i + 21, j + 5, k + 23, Blocks.end_stone, 0, 2);
		world.setBlock(i + 22, j + 5, k + 23, Blocks.end_stone, 0, 2);
		world.setBlock(i + 23, j + 5, k + 23, Blocks.end_stone, 0, 2);
		world.setBlock(i + 24, j + 5, k + 23, Blocks.end_stone, 0, 2);
		world.setBlock(i + 25, j + 5, k + 23, Blocks.end_stone, 0, 2);
		world.setBlock(i + 26, j + 5, k + 23, OtherModBlocks.end_bricks, 0, 2);
		world.setBlock(i + 4, j + 5, k + 24, OtherModBlocks.end_bricks, 0, 2);
		world.setBlock(i + 5, j + 5, k + 24, Blocks.end_stone, 0, 2);
		world.setBlock(i + 6, j + 5, k + 24, Blocks.end_stone, 0, 2);
		world.setBlock(i + 7, j + 5, k + 24, Blocks.end_stone, 0, 2);
		world.setBlock(i + 8, j + 5, k + 24, Blocks.end_stone, 0, 2);
		world.setBlock(i + 9, j + 5, k + 24, Blocks.end_stone, 0, 2);
		world.setBlock(i + 10, j + 5, k + 24, Blocks.end_stone, 0, 2);
		world.setBlock(i + 11, j + 5, k + 24, Blocks.end_stone, 0, 2);
		world.setBlock(i + 12, j + 5, k + 24, Blocks.end_stone, 0, 2);
		world.setBlock(i + 13, j + 5, k + 24, Blocks.end_stone, 0, 2);
		world.setBlock(i + 14, j + 5, k + 24, Blocks.end_stone, 0, 2);
		world.setBlock(i + 15, j + 5, k + 24, Blocks.end_stone, 0, 2);
		world.setBlock(i + 16, j + 5, k + 24, Blocks.end_stone, 0, 2);
		world.setBlock(i + 17, j + 5, k + 24, Blocks.end_stone, 0, 2);
		world.setBlock(i + 18, j + 5, k + 24, Blocks.end_stone, 0, 2);
		world.setBlock(i + 19, j + 5, k + 24, Blocks.end_stone, 0, 2);
		world.setBlock(i + 20, j + 5, k + 24, Blocks.end_stone, 0, 2);
		world.setBlock(i + 21, j + 5, k + 24, Blocks.end_stone, 0, 2);
		world.setBlock(i + 22, j + 5, k + 24, Blocks.end_stone, 0, 2);
		world.setBlock(i + 23, j + 5, k + 24, Blocks.end_stone, 0, 2);
		world.setBlock(i + 24, j + 5, k + 24, Blocks.end_stone, 0, 2);
		world.setBlock(i + 25, j + 5, k + 24, Blocks.end_stone, 0, 2);
		world.setBlock(i + 26, j + 5, k + 24, OtherModBlocks.end_bricks, 0, 2);
		world.setBlock(i + 5, j + 5, k + 25, OtherModBlocks.end_bricks, 0, 2);
		world.setBlock(i + 6, j + 5, k + 25, Blocks.end_stone, 0, 2);
		world.setBlock(i + 7, j + 5, k + 25, Blocks.end_stone, 0, 2);
		world.setBlock(i + 8, j + 5, k + 25, Blocks.end_stone, 0, 2);
		world.setBlock(i + 9, j + 5, k + 25, Blocks.end_stone, 0, 2);
		world.setBlock(i + 10, j + 5, k + 25, Blocks.end_stone, 0, 2);
		world.setBlock(i + 11, j + 5, k + 25, Blocks.end_stone, 0, 2);
		world.setBlock(i + 12, j + 5, k + 25, Blocks.end_stone, 0, 2);
		world.setBlock(i + 13, j + 5, k + 25, Blocks.end_stone, 0, 2);
		world.setBlock(i + 14, j + 5, k + 25, Blocks.end_stone, 0, 2);
		world.setBlock(i + 15, j + 5, k + 25, Blocks.end_stone, 0, 2);
		world.setBlock(i + 16, j + 5, k + 25, Blocks.end_stone, 0, 2);
		world.setBlock(i + 17, j + 5, k + 25, Blocks.end_stone, 0, 2);
		world.setBlock(i + 18, j + 5, k + 25, Blocks.end_stone, 0, 2);
		world.setBlock(i + 19, j + 5, k + 25, Blocks.end_stone, 0, 2);
		world.setBlock(i + 20, j + 5, k + 25, Blocks.end_stone, 0, 2);
		world.setBlock(i + 21, j + 5, k + 25, Blocks.end_stone, 0, 2);
		world.setBlock(i + 22, j + 5, k + 25, Blocks.end_stone, 0, 2);
		world.setBlock(i + 23, j + 5, k + 25, Blocks.end_stone, 0, 2);
		world.setBlock(i + 24, j + 5, k + 25, Blocks.end_stone, 0, 2);
		world.setBlock(i + 25, j + 5, k + 25, Blocks.end_stone, 0, 2);
		world.setBlock(i + 26, j + 5, k + 25, OtherModBlocks.end_bricks, 0, 2);
		world.setBlock(i + 6, j + 5, k + 26, OtherModBlocks.end_bricks, 0, 2);
		world.setBlock(i + 7, j + 5, k + 26, Blocks.end_stone, 0, 2);
		world.setBlock(i + 8, j + 5, k + 26, Blocks.end_stone, 0, 2);
		world.setBlock(i + 9, j + 5, k + 26, Blocks.end_stone, 0, 2);
		world.setBlock(i + 10, j + 5, k + 26, Blocks.end_stone, 0, 2);
		world.setBlock(i + 11, j + 5, k + 26, Blocks.end_stone, 0, 2);
		world.setBlock(i + 12, j + 5, k + 26, Blocks.end_stone, 0, 2);
		world.setBlock(i + 13, j + 5, k + 26, Blocks.end_stone, 0, 2);
		world.setBlock(i + 14, j + 5, k + 26, Blocks.end_stone, 0, 2);
		world.setBlock(i + 15, j + 5, k + 26, Blocks.end_stone, 0, 2);
		world.setBlock(i + 16, j + 5, k + 26, Blocks.end_stone, 0, 2);
		world.setBlock(i + 17, j + 5, k + 26, Blocks.end_stone, 0, 2);
		world.setBlock(i + 18, j + 5, k + 26, Blocks.end_stone, 0, 2);
		world.setBlock(i + 19, j + 5, k + 26, Blocks.end_stone, 0, 2);
		world.setBlock(i + 20, j + 5, k + 26, Blocks.end_stone, 0, 2);
		world.setBlock(i + 21, j + 5, k + 26, Blocks.end_stone, 0, 2);
		world.setBlock(i + 22, j + 5, k + 26, Blocks.end_stone, 0, 2);
		world.setBlock(i + 23, j + 5, k + 26, Blocks.end_stone, 0, 2);
		world.setBlock(i + 24, j + 5, k + 26, Blocks.end_stone, 0, 2);
		world.setBlock(i + 25, j + 5, k + 26, Blocks.end_stone, 0, 2);
		world.setBlock(i + 26, j + 5, k + 26, OtherModBlocks.end_bricks, 0, 2);
		world.setBlock(i + 7, j + 5, k + 27, OtherModBlocks.end_bricks, 0, 2);
		world.setBlock(i + 8, j + 5, k + 27, Blocks.end_stone, 0, 2);
		world.setBlock(i + 9, j + 5, k + 27, Blocks.end_stone, 0, 2);
		world.setBlock(i + 10, j + 5, k + 27, Blocks.end_stone, 0, 2);
		world.setBlock(i + 11, j + 5, k + 27, Blocks.end_stone, 0, 2);
		world.setBlock(i + 12, j + 5, k + 27, Blocks.end_stone, 0, 2);
		world.setBlock(i + 13, j + 5, k + 27, Blocks.end_stone, 0, 2);
		world.setBlock(i + 14, j + 5, k + 27, Blocks.end_stone, 0, 2);
		world.setBlock(i + 15, j + 5, k + 27, Blocks.end_stone, 0, 2);
		world.setBlock(i + 16, j + 5, k + 27, Blocks.end_stone, 0, 2);
		world.setBlock(i + 17, j + 5, k + 27, Blocks.end_stone, 0, 2);
		world.setBlock(i + 18, j + 5, k + 27, Blocks.end_stone, 0, 2);
		world.setBlock(i + 19, j + 5, k + 27, Blocks.end_stone, 0, 2);
		world.setBlock(i + 20, j + 5, k + 27, Blocks.end_stone, 0, 2);
		world.setBlock(i + 21, j + 5, k + 27, Blocks.end_stone, 0, 2);
		world.setBlock(i + 22, j + 5, k + 27, Blocks.end_stone, 0, 2);
		world.setBlock(i + 23, j + 5, k + 27, Blocks.end_stone, 0, 2);
		world.setBlock(i + 24, j + 5, k + 27, Blocks.end_stone, 0, 2);
		world.setBlock(i + 25, j + 5, k + 27, Blocks.end_stone, 0, 2);
		world.setBlock(i + 26, j + 5, k + 27, OtherModBlocks.end_bricks, 0, 2);
		world.setBlock(i + 8, j + 5, k + 28, OtherModBlocks.end_bricks, 0, 2);
		world.setBlock(i + 9, j + 5, k + 28, Blocks.end_stone, 0, 2);
		world.setBlock(i + 10, j + 5, k + 28, Blocks.end_stone, 0, 2);
		world.setBlock(i + 11, j + 5, k + 28, Blocks.end_stone, 0, 2);
		world.setBlock(i + 12, j + 5, k + 28, Blocks.end_stone, 0, 2);
		world.setBlock(i + 13, j + 5, k + 28, Blocks.end_stone, 0, 2);
		world.setBlock(i + 14, j + 5, k + 28, Blocks.end_stone, 0, 2);
		world.setBlock(i + 15, j + 5, k + 28, Blocks.end_stone, 0, 2);
		world.setBlock(i + 16, j + 5, k + 28, Blocks.end_stone, 0, 2);
		world.setBlock(i + 17, j + 5, k + 28, Blocks.end_stone, 0, 2);
		world.setBlock(i + 18, j + 5, k + 28, Blocks.end_stone, 0, 2);
		world.setBlock(i + 19, j + 5, k + 28, Blocks.end_stone, 0, 2);
		world.setBlock(i + 20, j + 5, k + 28, Blocks.end_stone, 0, 2);
		world.setBlock(i + 21, j + 5, k + 28, Blocks.end_stone, 0, 2);
		world.setBlock(i + 22, j + 5, k + 28, Blocks.end_stone, 0, 2);
		world.setBlock(i + 23, j + 5, k + 28, Blocks.end_stone, 0, 2);
		world.setBlock(i + 24, j + 5, k + 28, Blocks.end_stone, 0, 2);
		world.setBlock(i + 25, j + 5, k + 28, Blocks.end_stone, 0, 2);
		world.setBlock(i + 26, j + 5, k + 28, OtherModBlocks.end_bricks, 0, 2);
		world.setBlock(i + 9, j + 5, k + 29, OtherModBlocks.end_bricks, 0, 2);
		world.setBlock(i + 10, j + 5, k + 29, Blocks.end_stone, 0, 2);
		world.setBlock(i + 11, j + 5, k + 29, Blocks.end_stone, 0, 2);
		world.setBlock(i + 12, j + 5, k + 29, Blocks.end_stone, 0, 2);
		world.setBlock(i + 13, j + 5, k + 29, Blocks.end_stone, 0, 2);
		world.setBlock(i + 14, j + 5, k + 29, Blocks.end_stone, 0, 2);
		world.setBlock(i + 15, j + 5, k + 29, Blocks.end_stone, 0, 2);
		world.setBlock(i + 16, j + 5, k + 29, Blocks.end_stone, 0, 2);
		world.setBlock(i + 17, j + 5, k + 29, Blocks.end_stone, 0, 2);
		world.setBlock(i + 18, j + 5, k + 29, Blocks.end_stone, 0, 2);
		world.setBlock(i + 19, j + 5, k + 29, Blocks.end_stone, 0, 2);
		world.setBlock(i + 20, j + 5, k + 29, Blocks.end_stone, 0, 2);
		world.setBlock(i + 21, j + 5, k + 29, Blocks.end_stone, 0, 2);
		world.setBlock(i + 22, j + 5, k + 29, Blocks.end_stone, 0, 2);
		world.setBlock(i + 23, j + 5, k + 29, Blocks.end_stone, 0, 2);
		world.setBlock(i + 24, j + 5, k + 29, Blocks.end_stone, 0, 2);
		world.setBlock(i + 25, j + 5, k + 29, OtherModBlocks.end_bricks, 0, 2);
		world.setBlock(i + 10, j + 5, k + 30, OtherModBlocks.end_bricks, 0, 2);
		world.setBlock(i + 11, j + 5, k + 30, Blocks.end_stone, 0, 2);
		world.setBlock(i + 12, j + 5, k + 30, Blocks.end_stone, 0, 2);
		world.setBlock(i + 13, j + 5, k + 30, Blocks.end_stone, 0, 2);
		world.setBlock(i + 14, j + 5, k + 30, Blocks.end_stone, 0, 2);
		world.setBlock(i + 15, j + 5, k + 30, Blocks.end_stone, 0, 2);
		world.setBlock(i + 16, j + 5, k + 30, Blocks.end_stone, 0, 2);
		world.setBlock(i + 17, j + 5, k + 30, Blocks.end_stone, 0, 2);
		world.setBlock(i + 18, j + 5, k + 30, Blocks.end_stone, 0, 2);
		world.setBlock(i + 19, j + 5, k + 30, Blocks.end_stone, 0, 2);
		world.setBlock(i + 20, j + 5, k + 30, Blocks.end_stone, 0, 2);
		world.setBlock(i + 21, j + 5, k + 30, Blocks.end_stone, 0, 2);
		world.setBlock(i + 22, j + 5, k + 30, Blocks.end_stone, 0, 2);
		world.setBlock(i + 23, j + 5, k + 30, Blocks.end_stone, 0, 2);
		world.setBlock(i + 24, j + 5, k + 30, OtherModBlocks.end_bricks, 0, 2);
		world.setBlock(i + 10, j + 5, k + 31, OtherModBlocks.end_bricks, 0, 2);
		world.setBlock(i + 11, j + 5, k + 31, Blocks.end_stone, 0, 2);
		world.setBlock(i + 12, j + 5, k + 31, Blocks.end_stone, 0, 2);
		world.setBlock(i + 13, j + 5, k + 31, Blocks.end_stone, 0, 2);
		world.setBlock(i + 14, j + 5, k + 31, Blocks.end_stone, 0, 2);
		world.setBlock(i + 15, j + 5, k + 31, Blocks.end_stone, 0, 2);
		world.setBlock(i + 16, j + 5, k + 31, Blocks.end_stone, 0, 2);
		world.setBlock(i + 17, j + 5, k + 31, Blocks.end_stone, 0, 2);
		world.setBlock(i + 18, j + 5, k + 31, Blocks.end_stone, 0, 2);
		world.setBlock(i + 19, j + 5, k + 31, Blocks.end_stone, 0, 2);
		world.setBlock(i + 20, j + 5, k + 31, Blocks.end_stone, 0, 2);
		world.setBlock(i + 21, j + 5, k + 31, Blocks.end_stone, 0, 2);
		world.setBlock(i + 22, j + 5, k + 31, Blocks.end_stone, 0, 2);
		world.setBlock(i + 23, j + 5, k + 31, OtherModBlocks.end_bricks, 0, 2);
		world.setBlock(i + 10, j + 5, k + 32, OtherModBlocks.end_bricks, 0, 2);
		world.setBlock(i + 11, j + 5, k + 32, Blocks.end_stone, 0, 2);
		world.setBlock(i + 12, j + 5, k + 32, Blocks.end_stone, 0, 2);
		world.setBlock(i + 13, j + 5, k + 32, Blocks.end_stone, 0, 2);
		world.setBlock(i + 14, j + 5, k + 32, Blocks.end_stone, 0, 2);
		world.setBlock(i + 15, j + 5, k + 32, Blocks.end_stone, 0, 2);
		world.setBlock(i + 16, j + 5, k + 32, Blocks.end_stone, 0, 2);
		world.setBlock(i + 17, j + 5, k + 32, Blocks.end_stone, 0, 2);
		world.setBlock(i + 18, j + 5, k + 32, Blocks.end_stone, 0, 2);
		world.setBlock(i + 19, j + 5, k + 32, Blocks.end_stone, 0, 2);
		world.setBlock(i + 20, j + 5, k + 32, Blocks.end_stone, 0, 2);
		world.setBlock(i + 21, j + 5, k + 32, Blocks.end_stone, 0, 2);
		world.setBlock(i + 22, j + 5, k + 32, OtherModBlocks.end_bricks, 0, 2);
		world.setBlock(i + 10, j + 5, k + 33, OtherModBlocks.end_bricks, 0, 2);
		world.setBlock(i + 11, j + 5, k + 33, Blocks.end_stone, 0, 2);
		world.setBlock(i + 12, j + 5, k + 33, Blocks.end_stone, 0, 2);
		world.setBlock(i + 13, j + 5, k + 33, Blocks.end_stone, 0, 2);
		world.setBlock(i + 14, j + 5, k + 33, Blocks.end_stone, 0, 2);
		world.setBlock(i + 15, j + 5, k + 33, Blocks.end_stone, 0, 2);
		world.setBlock(i + 16, j + 5, k + 33, Blocks.end_stone, 0, 2);
		world.setBlock(i + 17, j + 5, k + 33, Blocks.end_stone, 0, 2);
		world.setBlock(i + 18, j + 5, k + 33, Blocks.end_stone, 0, 2);
		world.setBlock(i + 19, j + 5, k + 33, Blocks.end_stone, 0, 2);
		world.setBlock(i + 20, j + 5, k + 33, Blocks.end_stone, 0, 2);
		world.setBlock(i + 21, j + 5, k + 33, OtherModBlocks.end_bricks, 0, 2);
		world.setBlock(i + 11, j + 5, k + 34, OtherModBlocks.end_bricks, 0, 2);
		world.setBlock(i + 12, j + 5, k + 34, OtherModBlocks.end_bricks, 0, 2);
		world.setBlock(i + 13, j + 5, k + 34, OtherModBlocks.end_bricks, 0, 2);
		world.setBlock(i + 14, j + 5, k + 34, OtherModBlocks.end_bricks, 0, 2);
		world.setBlock(i + 15, j + 5, k + 34, OtherModBlocks.end_bricks, 0, 2);
		world.setBlock(i + 16, j + 5, k + 34, OtherModBlocks.end_bricks, 0, 2);
		world.setBlock(i + 17, j + 5, k + 34, OtherModBlocks.end_bricks, 0, 2);
		world.setBlock(i + 18, j + 5, k + 34, OtherModBlocks.end_bricks, 0, 2);
		world.setBlock(i + 19, j + 5, k + 34, OtherModBlocks.end_bricks, 0, 2);
		world.setBlock(i + 20, j + 5, k + 34, OtherModBlocks.end_bricks, 0, 2);
		world.setBlock(i + 13, j + 6, k + 1, NovaCraftBlocks.lacuna_stairs, 0, 2);
		world.setBlock(i + 14, j + 6, k + 1, NovaCraftBlocks.lacuna_stairs, 2, 2);
		world.setBlock(i + 15, j + 6, k + 1, NovaCraftBlocks.lacuna_stairs, 1, 2);
		world.setBlock(i + 17, j + 6, k + 1, NovaCraftBlocks.lacuna_stairs, 0, 2);
		world.setBlock(i + 18, j + 6, k + 1, NovaCraftBlocks.lacuna_stairs, 2, 2);
		world.setBlock(i + 19, j + 6, k + 1, NovaCraftBlocks.lacuna_stairs, 1, 2);
		world.setBlock(i + 13, j + 6, k + 2, NovaCraftBlocks.lacuna_stairs, 0, 2);
		world.setBlock(i + 14, j + 6, k + 2, OtherModBlocks.obsidian_special, 2, 2);
		world.setBlock(i + 15, j + 6, k + 2, NovaCraftBlocks.lacuna_stairs, 1, 2);
		world.setBlock(i + 17, j + 6, k + 2, NovaCraftBlocks.lacuna_stairs, 0, 2);
		world.setBlock(i + 18, j + 6, k + 2, OtherModBlocks.obsidian_special, 2, 2);
		world.setBlock(i + 19, j + 6, k + 2, NovaCraftBlocks.lacuna_stairs, 1, 2);
		world.setBlock(i + 13, j + 6, k + 3, NovaCraftBlocks.lacuna_stairs, 3, 2);
		world.setBlock(i + 14, j + 6, k + 3, NovaCraftBlocks.lacuna_stairs, 3, 2);
		world.setBlock(i + 15, j + 6, k + 3, NovaCraftBlocks.lacuna_stairs, 1, 2);
		world.setBlock(i + 17, j + 6, k + 3, NovaCraftBlocks.lacuna_stairs, 0, 2);
		world.setBlock(i + 18, j + 6, k + 3, NovaCraftBlocks.lacuna_stairs, 3, 2);
		world.setBlock(i + 19, j + 6, k + 3, NovaCraftBlocks.lacuna_stairs, 3, 2);
		world.setBlock(i + 16, j + 6, k + 6, OtherModBlocks.purpur_pillar, 0, 2);
		world.setBlock(i + 22, j + 6, k + 9, OtherModBlocks.purpur_pillar, 0, 2);
		world.setBlock(i + 10, j + 6, k + 11, OtherModBlocks.purpur_pillar, 0, 2);
		world.setBlock(i + 16, j + 6, k + 11, NovaCraftBlocks.lacuna_stairs, 6, 2);
		world.setBlock(i + 15, j + 6, k + 12, OtherModBlocks.obsidian_special, 0, 2);
		world.setBlock(i + 16, j + 6, k + 12, OtherModBlocks.obsidian_special, 0, 2);
		world.setBlock(i + 17, j + 6, k + 12, OtherModBlocks.obsidian_special, 0, 2);
		world.setBlock(i + 14, j + 6, k + 13, OtherModBlocks.obsidian_special, 0, 2);
		world.setBlock(i + 18, j + 6, k + 13, OtherModBlocks.obsidian_special, 0, 2);
		world.setBlock(i + 13, j + 6, k + 14, OtherModBlocks.obsidian_special, 0, 2);
		world.setBlock(i + 19, j + 6, k + 14, OtherModBlocks.obsidian_special, 0, 2);
		world.setBlock(i + 12, j + 6, k + 15, OtherModBlocks.obsidian_special, 0, 2);
		world.setBlock(i + 20, j + 6, k + 15, OtherModBlocks.obsidian_special, 0, 2);
		world.setBlock(i + 11, j + 6, k + 16, OtherModBlocks.obsidian_special, 0, 2);
		world.setBlock(i + 21, j + 6, k + 16, OtherModBlocks.obsidian_special, 0, 2);
		world.setBlock(i + 2, j + 6, k + 17, OtherModBlocks.purpur_pillar, 0, 2);
		world.setBlock(i + 5, j + 6, k + 17, OtherModBlocks.purpur_pillar, 0, 2);
		world.setBlock(i + 10, j + 6, k + 17, OtherModBlocks.obsidian_special, 0, 2);
		world.setBlock(i + 16, j + 6, k + 17, OtherModBlocks.end_rod, 1, 2);
		world.setBlock(i + 22, j + 6, k + 17, OtherModBlocks.obsidian_special, 0, 2);
		world.setBlock(i + 3, j + 6, k + 18, Blocks.pumpkin, 3, 2);
		world.setBlock(i + 4, j + 6, k + 18, Blocks.pumpkin, 3, 2);
		world.setBlock(i + 9, j + 6, k + 18, NovaCraftBlocks.lacuna_stairs, 4, 2);
		world.setBlock(i + 10, j + 6, k + 18, OtherModBlocks.obsidian_special, 0, 2);
		world.setBlock(i + 15, j + 6, k + 18, OtherModBlocks.end_rod, 1, 2);
		world.setBlock(i + 16, j + 6, k + 18, NovaCraftBlocks.dark_lotus, 0, 2);
		world.setBlock(i + 17, j + 6, k + 18, OtherModBlocks.end_rod, 1, 2);
		world.setBlock(i + 3, j + 6, k + 19, Blocks.pumpkin, 3, 2);
		world.setBlock(i + 4, j + 6, k + 19, Blocks.pumpkin, 3, 2);
		world.setBlock(i + 10, j + 6, k + 19, OtherModBlocks.obsidian_special, 0, 2);
		world.setBlock(i + 16, j + 6, k + 19, OtherModBlocks.end_rod, 1, 2);
		world.setBlock(i + 22, j + 6, k + 19, OtherModBlocks.obsidian_special, 0, 2);
		world.setBlock(i + 2, j + 6, k + 20, OtherModBlocks.purpur_pillar, 0, 2);
		world.setBlock(i + 5, j + 6, k + 20, OtherModBlocks.purpur_pillar, 0, 2);
		world.setBlock(i + 11, j + 6, k + 20, OtherModBlocks.obsidian_special, 0, 2);
		world.setBlock(i + 21, j + 6, k + 20, OtherModBlocks.obsidian_special, 0, 2);
		world.setBlock(i + 12, j + 6, k + 21, OtherModBlocks.obsidian_special, 0, 2);
		world.setBlock(i + 20, j + 6, k + 21, OtherModBlocks.obsidian_special, 0, 2);
		world.setBlock(i + 13, j + 6, k + 22, OtherModBlocks.obsidian_special, 0, 2);
		world.setBlock(i + 19, j + 6, k + 22, OtherModBlocks.obsidian_special, 0, 2);
		world.setBlock(i + 8, j + 6, k + 23, OtherModBlocks.purpur_pillar, 0, 2);
		world.setBlock(i + 14, j + 6, k + 23, OtherModBlocks.obsidian_special, 0, 2);
		world.setBlock(i + 18, j + 6, k + 23, OtherModBlocks.obsidian_special, 0, 2);
		world.setBlock(i + 15, j + 6, k + 24, OtherModBlocks.obsidian_special, 0, 2);
		world.setBlock(i + 16, j + 6, k + 24, OtherModBlocks.obsidian_special, 0, 2);
		world.setBlock(i + 17, j + 6, k + 24, OtherModBlocks.obsidian_special, 0, 2);
		world.setBlock(i + 16, j + 6, k + 25, NovaCraftBlocks.lacuna_stairs, 7, 2);
		world.setBlock(i + 21, j + 6, k + 26, OtherModBlocks.purpur_pillar, 0, 2);
		world.setBlock(i + 14, j + 6, k + 29, OtherModBlocks.purpur_pillar, 0, 2);
		world.setBlock(i + 13, j + 6, k + 31, NovaCraftBlocks.lacuna_stairs, 2, 2);
		world.setBlock(i + 14, j + 6, k + 31, NovaCraftBlocks.lacuna_stairs, 2, 2);
		world.setBlock(i + 15, j + 6, k + 31, NovaCraftBlocks.lacuna_stairs, 1, 2);
		world.setBlock(i + 17, j + 6, k + 31, NovaCraftBlocks.lacuna_stairs, 2, 2);
		world.setBlock(i + 18, j + 6, k + 31, NovaCraftBlocks.lacuna_stairs, 2, 2);
		world.setBlock(i + 19, j + 6, k + 31, NovaCraftBlocks.lacuna_stairs, 2, 2);
		world.setBlock(i + 13, j + 6, k + 32, NovaCraftBlocks.lacuna_stairs, 0, 2);
		world.setBlock(i + 14, j + 6, k + 32, OtherModBlocks.obsidian_special, 2, 2);
		world.setBlock(i + 15, j + 6, k + 32, NovaCraftBlocks.lacuna_stairs, 1, 2);
		world.setBlock(i + 17, j + 6, k + 32, NovaCraftBlocks.lacuna_stairs, 0, 2);
		world.setBlock(i + 18, j + 6, k + 32, OtherModBlocks.obsidian_special, 2, 2);
		world.setBlock(i + 19, j + 6, k + 32, NovaCraftBlocks.lacuna_stairs, 1, 2);
		world.setBlock(i + 13, j + 6, k + 33, NovaCraftBlocks.lacuna_stairs, 0, 2);
		world.setBlock(i + 14, j + 6, k + 33, NovaCraftBlocks.lacuna_stairs, 3, 2);
		world.setBlock(i + 15, j + 6, k + 33, NovaCraftBlocks.lacuna_stairs, 3, 2);
		world.setBlock(i + 17, j + 6, k + 33, NovaCraftBlocks.lacuna_stairs, 3, 2);
		world.setBlock(i + 18, j + 6, k + 33, NovaCraftBlocks.lacuna_stairs, 3, 2);
		world.setBlock(i + 19, j + 6, k + 33, NovaCraftBlocks.lacuna_stairs, 1, 2);
		world.setBlock(i + 14, j + 7, k + 2, OtherModBlocks.obsidian_special, 2, 2);
		world.setBlock(i + 18, j + 7, k + 2, OtherModBlocks.obsidian_special, 2, 2);
		world.setBlock(i + 16, j + 7, k + 6, OtherModBlocks.end_rod, 1, 2);
		world.setBlock(i + 22, j + 7, k + 9, OtherModBlocks.end_rod, 1, 2);
		world.setBlock(i + 10, j + 7, k + 11, OtherModBlocks.end_rod, 1, 2);
		world.setBlock(i + 15, j + 7, k + 12, OtherModBlocks.obsidian_special, 1, 2);
		world.setBlock(i + 16, j + 7, k + 12, Blocks.iron_bars, 0, 2);
		world.setBlock(i + 17, j + 7, k + 12, OtherModBlocks.obsidian_special, 1, 2);
		world.setBlock(i + 14, j + 7, k + 13, Blocks.obsidian, 0, 2);
		world.setBlock(i + 18, j + 7, k + 13, Blocks.obsidian, 0, 2);
		world.setBlock(i + 13, j + 7, k + 14, Blocks.obsidian, 0, 2);
		world.setBlock(i + 19, j + 7, k + 14, Blocks.obsidian, 0, 2);
		world.setBlock(i + 12, j + 7, k + 15, Blocks.obsidian, 0, 2);
		world.setBlock(i + 20, j + 7, k + 15, Blocks.obsidian, 0, 2);
		world.setBlock(i + 11, j + 7, k + 16, OtherModBlocks.obsidian_special, 1, 2);
		world.setBlock(i + 21, j + 7, k + 16, OtherModBlocks.obsidian_special, 1, 2);
		world.setBlock(i + 2, j + 7, k + 17, OtherModBlocks.end_rod, 1, 2);
		world.setBlock(i + 5, j + 7, k + 17, OtherModBlocks.end_rod, 1, 2);
		world.setBlock(i + 10, j + 7, k + 17, Blocks.obsidian, 0, 2);
		world.setBlock(i + 22, j + 7, k + 17, Blocks.obsidian, 0, 2);
		world.setBlock(i + 10, j + 7, k + 18, Blocks.iron_bars, 0, 2);
		world.setBlock(i + 3, j + 7, k + 19, Blocks.lit_pumpkin, 3, 2);
		world.setBlock(i + 10, j + 7, k + 19, Blocks.obsidian, 0, 2);
		world.setBlock(i + 22, j + 7, k + 19, Blocks.obsidian, 0, 2);
		world.setBlock(i + 2, j + 7, k + 20, OtherModBlocks.end_rod, 1, 2);
		world.setBlock(i + 5, j + 7, k + 20, OtherModBlocks.end_rod, 1, 2);
		world.setBlock(i + 11, j + 7, k + 20, OtherModBlocks.obsidian_special, 1, 2);
		world.setBlock(i + 21, j + 7, k + 20, OtherModBlocks.obsidian_special, 1, 2);
		world.setBlock(i + 12, j + 7, k + 21, Blocks.obsidian, 0, 2);
		world.setBlock(i + 20, j + 7, k + 21, Blocks.obsidian, 0, 2);
		world.setBlock(i + 13, j + 7, k + 22, Blocks.obsidian, 0, 2);
		world.setBlock(i + 19, j + 7, k + 22, Blocks.obsidian, 0, 2);
		world.setBlock(i + 8, j + 7, k + 23, OtherModBlocks.end_rod, 1, 2);
		world.setBlock(i + 14, j + 7, k + 23, Blocks.obsidian, 0, 2);
		world.setBlock(i + 18, j + 7, k + 23, Blocks.obsidian, 0, 2);
		world.setBlock(i + 15, j + 7, k + 24, OtherModBlocks.obsidian_special, 1, 2);
		world.setBlock(i + 16, j + 7, k + 24, Blocks.iron_bars, 0, 2);
		world.setBlock(i + 17, j + 7, k + 24, OtherModBlocks.obsidian_special, 1, 2);
		world.setBlock(i + 21, j + 7, k + 26, OtherModBlocks.end_rod, 1, 2);
		world.setBlock(i + 14, j + 7, k + 29, OtherModBlocks.end_rod, 1, 2);
		world.setBlock(i + 14, j + 7, k + 32, OtherModBlocks.obsidian_special, 2, 2);
		world.setBlock(i + 18, j + 7, k + 32, OtherModBlocks.obsidian_special, 2, 2);
		world.setBlock(i + 14, j + 8, k + 2, OtherModBlocks.obsidian_special, 2, 2);
		world.setBlock(i + 18, j + 8, k + 2, OtherModBlocks.obsidian_special, 2, 2);
		world.setBlock(i + 15, j + 8, k + 12, OtherModBlocks.obsidian_special, 1, 2);
		world.setBlock(i + 16, j + 8, k + 12, Blocks.iron_bars, 0, 2);
		world.setBlock(i + 17, j + 8, k + 12, OtherModBlocks.obsidian_special, 1, 2);
		world.setBlock(i + 14, j + 8, k + 13, Blocks.obsidian, 0, 2);
		world.setBlock(i + 18, j + 8, k + 13, Blocks.obsidian, 0, 2);
		world.setBlock(i + 13, j + 8, k + 14, Blocks.obsidian, 0, 2);
		world.setBlock(i + 19, j + 8, k + 14, Blocks.obsidian, 0, 2);
		world.setBlock(i + 12, j + 8, k + 15, Blocks.obsidian, 0, 2);
		world.setBlock(i + 20, j + 8, k + 15, Blocks.obsidian, 0, 2);
		world.setBlock(i + 11, j + 8, k + 16, OtherModBlocks.obsidian_special, 1, 2);
		world.setBlock(i + 21, j + 8, k + 16, OtherModBlocks.obsidian_special, 1, 2);
		world.setBlock(i + 10, j + 8, k + 17, Blocks.obsidian, 0, 2);
		world.setBlock(i + 22, j + 8, k + 17, Blocks.obsidian, 0, 2);
		world.setBlock(i + 10, j + 8, k + 18, Blocks.iron_bars, 0, 2);
		world.setBlock(i + 10, j + 8, k + 19, Blocks.obsidian, 0, 2);
		world.setBlock(i + 22, j + 8, k + 19, Blocks.obsidian, 0, 2);
		world.setBlock(i + 11, j + 8, k + 20, OtherModBlocks.obsidian_special, 1, 2);
		world.setBlock(i + 21, j + 8, k + 20, OtherModBlocks.obsidian_special, 1, 2);
		world.setBlock(i + 12, j + 8, k + 21, Blocks.obsidian, 0, 2);
		world.setBlock(i + 20, j + 8, k + 21, Blocks.obsidian, 0, 2);
		world.setBlock(i + 13, j + 8, k + 22, Blocks.obsidian, 0, 2);
		world.setBlock(i + 19, j + 8, k + 22, Blocks.obsidian, 0, 2);
		world.setBlock(i + 14, j + 8, k + 23, Blocks.obsidian, 0, 2);
		world.setBlock(i + 18, j + 8, k + 23, Blocks.obsidian, 0, 2);
		world.setBlock(i + 15, j + 8, k + 24, OtherModBlocks.obsidian_special, 1, 2);
		world.setBlock(i + 16, j + 8, k + 24, Blocks.iron_bars, 0, 2);
		world.setBlock(i + 17, j + 8, k + 24, OtherModBlocks.obsidian_special, 1, 2);
		world.setBlock(i + 14, j + 8, k + 32, OtherModBlocks.obsidian_special, 2, 2);
		world.setBlock(i + 18, j + 8, k + 32, OtherModBlocks.obsidian_special, 2, 2);
		world.setBlock(i + 14, j + 9, k + 2, OtherModBlocks.obsidian_special, 2, 2);
		world.setBlock(i + 18, j + 9, k + 2, OtherModBlocks.obsidian_special, 2, 2);
		world.setBlock(i + 16, j + 9, k + 11, OtherModBlocks.end_rod, 0, 2);
		world.setBlock(i + 15, j + 9, k + 12, OtherModBlocks.obsidian_special, 0, 2);
		world.setBlock(i + 16, j + 9, k + 12, OtherModBlocks.obsidian_special, 0, 2);
		world.setBlock(i + 17, j + 9, k + 12, OtherModBlocks.obsidian_special, 0, 2);
		world.setBlock(i + 14, j + 9, k + 13, Blocks.obsidian, 0, 2);
		world.setBlock(i + 16, j + 9, k + 13, NovaCraftBlocks.lacuna_planks, 0, 2);
		world.setBlock(i + 17, j + 9, k + 13, NovaCraftBlocks.lacuna_planks, 0, 2);
		world.setBlock(i + 18, j + 9, k + 13, Blocks.obsidian, 0, 2);
		world.setBlock(i + 13, j + 9, k + 14, Blocks.obsidian, 0, 2);
		world.setBlock(i + 17, j + 9, k + 14, NovaCraftBlocks.lacuna_planks, 0, 2);
		world.setBlock(i + 18, j + 9, k + 14, NovaCraftBlocks.lacuna_planks, 0, 2);
		world.setBlock(i + 19, j + 9, k + 14, Blocks.obsidian, 0, 2);
		world.setBlock(i + 12, j + 9, k + 15, Blocks.obsidian, 0, 2);
		world.setBlock(i + 18, j + 9, k + 15, NovaCraftBlocks.lacuna_planks, 0, 2);
		world.setBlock(i + 19, j + 9, k + 15, NovaCraftBlocks.lacuna_planks, 0, 2);
		world.setBlock(i + 20, j + 9, k + 15, Blocks.obsidian, 0, 2);
		world.setBlock(i + 11, j + 9, k + 16, OtherModBlocks.obsidian_special, 0, 2);
		world.setBlock(i + 21, j + 9, k + 16, OtherModBlocks.obsidian_special, 0, 2);
		world.setBlock(i + 10, j + 9, k + 17, Blocks.obsidian, 0, 2);
		world.setBlock(i + 22, j + 9, k + 17, Blocks.obsidian, 0, 2);
		world.setBlock(i + 9, j + 9, k + 18, OtherModBlocks.end_rod, 0, 2);
		world.setBlock(i + 10, j + 9, k + 18, OtherModBlocks.obsidian_special, 0, 2);
		world.setBlock(i + 11, j + 9, k + 18, NovaCraftBlocks.lacuna_planks, 0, 2);
		world.setBlock(i + 22, j + 9, k + 18, Blocks.obsidian, 0, 2);
		world.setBlock(i + 23, j + 9, k + 18, OtherModBlocks.end_rod, 0, 2);
		world.setBlock(i + 10, j + 9, k + 19, Blocks.obsidian, 0, 2);
		world.setBlock(i + 11, j + 9, k + 19, NovaCraftBlocks.lacuna_planks, 0, 2);
		world.setBlock(i + 12, j + 9, k + 19, NovaCraftBlocks.lacuna_planks, 0, 2);
		world.setBlock(i + 22, j + 9, k + 19, Blocks.obsidian, 0, 2);
		world.setBlock(i + 11, j + 9, k + 20, OtherModBlocks.obsidian_special, 0, 2);
		world.setBlock(i + 12, j + 9, k + 20, NovaCraftBlocks.lacuna_planks, 0, 2);
		world.setBlock(i + 13, j + 9, k + 20, NovaCraftBlocks.lacuna_planks, 0, 2);
		world.setBlock(i + 21, j + 9, k + 20, OtherModBlocks.obsidian_special, 0, 2);
		world.setBlock(i + 12, j + 9, k + 21, Blocks.obsidian, 0, 2);
		world.setBlock(i + 13, j + 9, k + 21, NovaCraftBlocks.lacuna_planks, 0, 2);
		world.setBlock(i + 14, j + 9, k + 21, NovaCraftBlocks.lacuna_planks, 0, 2);
		world.setBlock(i + 20, j + 9, k + 21, Blocks.obsidian, 0, 2);
		world.setBlock(i + 13, j + 9, k + 22, Blocks.obsidian, 0, 2);
		world.setBlock(i + 14, j + 9, k + 22, NovaCraftBlocks.lacuna_planks, 0, 2);
		world.setBlock(i + 15, j + 9, k + 22, NovaCraftBlocks.lacuna_planks, 0, 2);
		world.setBlock(i + 19, j + 9, k + 22, Blocks.obsidian, 0, 2);
		world.setBlock(i + 14, j + 9, k + 23, Blocks.obsidian, 0, 2);
		world.setBlock(i + 15, j + 9, k + 23, NovaCraftBlocks.lacuna_planks, 0, 2);
		world.setBlock(i + 16, j + 9, k + 23, NovaCraftBlocks.lacuna_planks, 0, 2);
		world.setBlock(i + 18, j + 9, k + 23, Blocks.obsidian, 0, 2);
		world.setBlock(i + 15, j + 9, k + 24, OtherModBlocks.obsidian_special, 0, 2);
		world.setBlock(i + 16, j + 9, k + 24, OtherModBlocks.obsidian_special, 0, 2);
		world.setBlock(i + 17, j + 9, k + 24, OtherModBlocks.obsidian_special, 0, 2);
		world.setBlock(i + 16, j + 9, k + 25, OtherModBlocks.end_rod, 0, 2);
		world.setBlock(i + 14, j + 9, k + 32, OtherModBlocks.obsidian_special, 2, 2);
		world.setBlock(i + 18, j + 9, k + 32, OtherModBlocks.obsidian_special, 2, 2);
		world.setBlock(i + 14, j + 10, k + 2, OtherModBlocks.obsidian_special, 2, 2);
		world.setBlock(i + 18, j + 10, k + 2, OtherModBlocks.obsidian_special, 2, 2);
		world.setBlock(i + 16, j + 10, k + 11, OtherModBlocks.obsidian_special, 1, 2);
		world.setBlock(i + 15, j + 10, k + 12, Blocks.obsidian, 0, 2);
		world.setBlock(i + 16, j + 10, k + 12, Blocks.obsidian, 0, 2);
		world.setBlock(i + 17, j + 10, k + 12, Blocks.obsidian, 0, 2);
		world.setBlock(i + 14, j + 10, k + 13, Blocks.obsidian, 0, 2);
		world.setBlock(i + 15, j + 10, k + 13, NovaCraftBlocks.lacuna_planks, 0, 2);
		world.setBlock(i + 16, j + 10, k + 13, NovaCraftBlocks.lacuna_planks, 0, 2);
		world.setBlock(i + 17, j + 10, k + 13, NovaCraftBlocks.lacuna_planks, 0, 2);
		world.setBlock(i + 18, j + 10, k + 13, Blocks.obsidian, 0, 2);
		world.setBlock(i + 13, j + 10, k + 14, Blocks.obsidian, 0, 2);
		world.setBlock(i + 14, j + 10, k + 14, NovaCraftBlocks.lacuna_slab, 0, 2);
		world.setBlock(i + 15, j + 10, k + 14, NovaCraftBlocks.lacuna_planks, 0, 2);
		world.setBlock(i + 16, j + 10, k + 14, NovaCraftBlocks.lacuna_planks, 0, 2);
		world.setBlock(i + 17, j + 10, k + 14, NovaCraftBlocks.lacuna_planks, 0, 2);
		world.setBlock(i + 18, j + 10, k + 14, NovaCraftBlocks.lacuna_planks, 0, 2);
		world.setBlock(i + 19, j + 10, k + 14, Blocks.obsidian, 0, 2);
		world.setBlock(i + 12, j + 10, k + 15, Blocks.obsidian, 0, 2);
		world.setBlock(i + 15, j + 10, k + 15, NovaCraftBlocks.lacuna_slab, 0, 2);
		world.setBlock(i + 16, j + 10, k + 15, NovaCraftBlocks.lacuna_planks, 0, 2);
		world.setBlock(i + 17, j + 10, k + 15, NovaCraftBlocks.lacuna_planks, 0, 2);
		world.setBlock(i + 18, j + 10, k + 15, NovaCraftBlocks.lacuna_planks, 0, 2);
		world.setBlock(i + 19, j + 10, k + 15, NovaCraftBlocks.lacuna_planks, 0, 2);
		world.setBlock(i + 20, j + 10, k + 15, Blocks.obsidian, 0, 2);
		world.setBlock(i + 11, j + 10, k + 16, Blocks.obsidian, 0, 2);
		world.setBlock(i + 12, j + 10, k + 16, NovaCraftBlocks.lacuna_slab, 0, 2);
		world.setBlock(i + 16, j + 10, k + 16, NovaCraftBlocks.lacuna_slab, 0, 2);
		world.setBlock(i + 17, j + 10, k + 16, NovaCraftBlocks.lacuna_slab, 0, 2);
		world.setBlock(i + 18, j + 10, k + 16, NovaCraftBlocks.lacuna_slab, 0, 2);
		world.setBlock(i + 19, j + 10, k + 16, NovaCraftBlocks.lacuna_slab, 0, 2);
		world.setBlock(i + 20, j + 10, k + 16, NovaCraftBlocks.lacuna_slab, 0, 2);
		world.setBlock(i + 21, j + 10, k + 16, Blocks.obsidian, 0, 2);
		world.setBlock(i + 10, j + 10, k + 17, Blocks.obsidian, 0, 2);
		world.setBlock(i + 11, j + 10, k + 17, NovaCraftBlocks.lacuna_planks, 0, 2);
		world.setBlock(i + 12, j + 10, k + 17, NovaCraftBlocks.lacuna_planks, 0, 2);
		world.setBlock(i + 13, j + 10, k + 17, NovaCraftBlocks.lacuna_slab, 0, 2);
		world.setBlock(i + 22, j + 10, k + 17, Blocks.obsidian, 0, 2);
		world.setBlock(i + 9, j + 10, k + 18, OtherModBlocks.obsidian_special, 1, 2);
		world.setBlock(i + 10, j + 10, k + 18, Blocks.obsidian, 0, 2);
		world.setBlock(i + 11, j + 10, k + 18, NovaCraftBlocks.lacuna_planks, 0, 2);
		world.setBlock(i + 12, j + 10, k + 18, NovaCraftBlocks.lacuna_planks, 0, 2);
		world.setBlock(i + 13, j + 10, k + 18, NovaCraftBlocks.lacuna_planks, 0, 2);
		world.setBlock(i + 14, j + 10, k + 18, NovaCraftBlocks.lacuna_slab, 0, 2);
		world.setBlock(i + 22, j + 10, k + 18, Blocks.obsidian, 0, 2);
		world.setBlock(i + 23, j + 10, k + 18, OtherModBlocks.obsidian_special, 1, 2);
		world.setBlock(i + 10, j + 10, k + 19, Blocks.obsidian, 0, 2);
		world.setBlock(i + 11, j + 10, k + 19, NovaCraftBlocks.lacuna_planks, 0, 2);
		world.setBlock(i + 12, j + 10, k + 19, NovaCraftBlocks.lacuna_planks, 0, 2);
		world.setBlock(i + 13, j + 10, k + 19, NovaCraftBlocks.lacuna_planks, 0, 2);
		world.setBlock(i + 14, j + 10, k + 19, NovaCraftBlocks.lacuna_planks, 0, 2);
		world.setBlock(i + 15, j + 10, k + 19, NovaCraftBlocks.lacuna_slab, 0, 2);
		world.setBlock(i + 22, j + 10, k + 19, Blocks.obsidian, 0, 2);
		world.setBlock(i + 11, j + 10, k + 20, Blocks.obsidian, 0, 2);
		world.setBlock(i + 12, j + 10, k + 20, NovaCraftBlocks.lacuna_planks, 0, 2);
		world.setBlock(i + 13, j + 10, k + 20, NovaCraftBlocks.lacuna_planks, 0, 2);
		world.setBlock(i + 14, j + 10, k + 20, NovaCraftBlocks.lacuna_planks, 0, 2);
		world.setBlock(i + 15, j + 10, k + 20, NovaCraftBlocks.lacuna_planks, 0, 2);
		world.setBlock(i + 16, j + 10, k + 20, NovaCraftBlocks.lacuna_slab, 0, 2);
		world.setBlock(i + 21, j + 10, k + 20, Blocks.obsidian, 0, 2);
		world.setBlock(i + 12, j + 10, k + 21, Blocks.obsidian, 0, 2);
		world.setBlock(i + 13, j + 10, k + 21, NovaCraftBlocks.lacuna_planks, 0, 2);
		world.setBlock(i + 14, j + 10, k + 21, NovaCraftBlocks.lacuna_planks, 0, 2);
		world.setBlock(i + 15, j + 10, k + 21, NovaCraftBlocks.lacuna_planks, 0, 2);
		world.setBlock(i + 16, j + 10, k + 21, NovaCraftBlocks.lacuna_planks, 0, 2);
		world.setBlock(i + 17, j + 10, k + 21, NovaCraftBlocks.lacuna_slab, 0, 2);
		world.setBlock(i + 20, j + 10, k + 21, Blocks.obsidian, 0, 2);
		world.setBlock(i + 13, j + 10, k + 22, Blocks.obsidian, 0, 2);
		world.setBlock(i + 14, j + 10, k + 22, NovaCraftBlocks.lacuna_planks, 0, 2);
		world.setBlock(i + 15, j + 10, k + 22, NovaCraftBlocks.lacuna_planks, 0, 2);
		world.setBlock(i + 16, j + 10, k + 22, NovaCraftBlocks.lacuna_planks, 0, 2);
		world.setBlock(i + 17, j + 10, k + 22, NovaCraftBlocks.lacuna_planks, 0, 2);
		world.setBlock(i + 18, j + 10, k + 22, NovaCraftBlocks.lacuna_slab, 0, 2);
		world.setBlock(i + 19, j + 10, k + 22, Blocks.obsidian, 0, 2);
		world.setBlock(i + 14, j + 10, k + 23, Blocks.obsidian, 0, 2);
		world.setBlock(i + 15, j + 10, k + 23, NovaCraftBlocks.lacuna_planks, 0, 2);
		world.setBlock(i + 16, j + 10, k + 23, NovaCraftBlocks.lacuna_planks, 0, 2);
		world.setBlock(i + 17, j + 10, k + 23, NovaCraftBlocks.lacuna_planks, 0, 2);
		world.setBlock(i + 18, j + 10, k + 23, Blocks.obsidian, 0, 2);
		world.setBlock(i + 15, j + 10, k + 24, Blocks.obsidian, 0, 2);
		world.setBlock(i + 16, j + 10, k + 24, Blocks.obsidian, 0, 2);
		world.setBlock(i + 17, j + 10, k + 24, Blocks.obsidian, 0, 2);
		world.setBlock(i + 16, j + 10, k + 25, OtherModBlocks.obsidian_special, 1, 2);
		world.setBlock(i + 14, j + 10, k + 32, OtherModBlocks.obsidian_special, 2, 2);
		world.setBlock(i + 18, j + 10, k + 32, OtherModBlocks.obsidian_special, 2, 2);
		world.setBlock(i + 14, j + 11, k + 2, OtherModBlocks.obsidian_special, 2, 2);
		world.setBlock(i + 18, j + 11, k + 2, OtherModBlocks.obsidian_special, 2, 2);
		world.setBlock(i + 15, j + 11, k + 12, Blocks.obsidian, 0, 2);
		world.setBlock(i + 16, j + 11, k + 12, Blocks.obsidian, 0, 2);
		world.setBlock(i + 17, j + 11, k + 12, Blocks.obsidian, 0, 2);
		world.setBlock(i + 14, j + 11, k + 13, Blocks.obsidian, 0, 2);
		world.setBlock(i + 15, j + 11, k + 13, OtherModBlocks.purpur_pillar, 0, 2);
		world.setBlock(i + 16, j + 11, k + 13, OtherModBlocks.purpur_pillar, 0, 2);
		world.setBlock(i + 17, j + 11, k + 13, OtherModBlocks.purpur_pillar, 0, 2);
		world.setBlock(i + 18, j + 11, k + 13, Blocks.obsidian, 0, 2);
		world.setBlock(i + 13, j + 11, k + 14, Blocks.obsidian, 0, 2);
		world.setBlock(i + 15, j + 11, k + 14, Blocks.cobblestone, 0, 2);
		world.setBlock(i + 16, j + 11, k + 14, Blocks.cobblestone, 0, 2);
		world.setBlock(i + 17, j + 11, k + 14, OtherModBlocks.purpur_pillar, 0, 2);
		world.setBlock(i + 18, j + 11, k + 14, OtherModBlocks.purpur_pillar, 0, 2);
		world.setBlock(i + 19, j + 11, k + 14, Blocks.obsidian, 0, 2);
		world.setBlock(i + 12, j + 11, k + 15, Blocks.obsidian, 0, 2);
		world.setBlock(i + 16, j + 11, k + 15, Blocks.cobblestone, 0, 2);
		world.setBlock(i + 17, j + 11, k + 15, Blocks.iron_ore, 0, 2);
		world.setBlock(i + 18, j + 11, k + 15, OtherModBlocks.purpur_pillar, 0, 2);
		world.setBlock(i + 19, j + 11, k + 15, Blocks.coal_ore, 0, 2);
		world.setBlock(i + 20, j + 11, k + 15, Blocks.obsidian, 0, 2);
		world.setBlock(i + 11, j + 11, k + 16, Blocks.obsidian, 0, 2);
		world.setBlock(i + 21, j + 11, k + 16, Blocks.obsidian, 0, 2);
		world.setBlock(i + 10, j + 11, k + 17, Blocks.obsidian, 0, 2);
		world.setBlock(i + 11, j + 11, k + 17, Blocks.netherrack, 0, 2);
		world.setBlock(i + 12, j + 11, k + 17, Blocks.netherrack, 0, 2);
		world.setBlock(i + 22, j + 11, k + 17, Blocks.obsidian, 0, 2);
		world.setBlock(i + 10, j + 11, k + 18, Blocks.obsidian, 0, 2);
		world.setBlock(i + 11, j + 11, k + 18, Blocks.netherrack, 0, 2);
		world.setBlock(i + 12, j + 11, k + 18, Blocks.netherrack, 0, 2);
		world.setBlock(i + 13, j + 11, k + 18, Blocks.soul_sand, 0, 2);
		world.setBlock(i + 22, j + 11, k + 18, Blocks.obsidian, 0, 2);
		world.setBlock(i + 10, j + 11, k + 19, Blocks.obsidian, 0, 2);
		world.setBlock(i + 11, j + 11, k + 19, Blocks.netherrack, 0, 2);
		world.setBlock(i + 12, j + 11, k + 19, Blocks.netherrack, 0, 2);
		world.setBlock(i + 13, j + 11, k + 19, Blocks.netherrack, 0, 2);
		world.setBlock(i + 14, j + 11, k + 19, Blocks.quartz_ore, 0, 2);
		world.setBlock(i + 22, j + 11, k + 19, Blocks.obsidian, 0, 2);
		world.setBlock(i + 11, j + 11, k + 20, Blocks.obsidian, 0, 2);
		world.setBlock(i + 12, j + 11, k + 20, Blocks.netherrack, 0, 2);
		world.setBlock(i + 13, j + 11, k + 20, Blocks.soul_sand, 0, 2);
		world.setBlock(i + 14, j + 11, k + 20, Blocks.soul_sand, 0, 2);
		world.setBlock(i + 21, j + 11, k + 20, Blocks.obsidian, 0, 2);
		world.setBlock(i + 12, j + 11, k + 21, Blocks.obsidian, 0, 2);
		world.setBlock(i + 13, j + 11, k + 21, NovaCraftBlocks.grimstone, 0, 2);
		world.setBlock(i + 14, j + 11, k + 21, NovaCraftBlocks.grimstone, 0, 2);
		world.setBlock(i + 20, j + 11, k + 21, Blocks.obsidian, 0, 2);
		world.setBlock(i + 13, j + 11, k + 22, Blocks.obsidian, 0, 2);
		world.setBlock(i + 14, j + 11, k + 22, NovaCraftBlocks.grimstone, 0, 2);
		world.setBlock(i + 15, j + 11, k + 22, NovaCraftBlocks.cobbled_grimstone, 0, 2);
		world.setBlock(i + 19, j + 11, k + 22, Blocks.obsidian, 0, 2);
		world.setBlock(i + 14, j + 11, k + 23, Blocks.obsidian, 0, 2);
		world.setBlock(i + 15, j + 11, k + 23, NovaCraftBlocks.nullstone, 0, 2);
		world.setBlock(i + 16, j + 11, k + 23, NovaCraftBlocks.nullstone_diamond, 0, 2);
		world.setBlock(i + 17, j + 11, k + 23, NovaCraftBlocks.nullstone, 0, 2);
		world.setBlock(i + 18, j + 11, k + 23, Blocks.obsidian, 0, 2);
		world.setBlock(i + 15, j + 11, k + 24, Blocks.obsidian, 0, 2);
		world.setBlock(i + 16, j + 11, k + 24, Blocks.obsidian, 0, 2);
		world.setBlock(i + 17, j + 11, k + 24, Blocks.obsidian, 0, 2);
		world.setBlock(i + 14, j + 11, k + 32, OtherModBlocks.obsidian_special, 2, 2);
		world.setBlock(i + 18, j + 11, k + 32, OtherModBlocks.obsidian_special, 2, 2);
		world.setBlock(i + 14, j + 12, k + 2, OtherModBlocks.obsidian_special, 2, 2);
		world.setBlock(i + 18, j + 12, k + 2, OtherModBlocks.obsidian_special, 2, 2);
		world.setBlock(i + 15, j + 12, k + 12, Blocks.obsidian, 0, 2);
		world.setBlock(i + 16, j + 12, k + 12, Blocks.obsidian, 0, 2);
		world.setBlock(i + 17, j + 12, k + 12, Blocks.obsidian, 0, 2);
		world.setBlock(i + 14, j + 12, k + 13, Blocks.obsidian, 0, 2);
		world.setBlock(i + 15, j + 12, k + 13, Blocks.brown_mushroom, 0, 2);
		world.setBlock(i + 16, j + 12, k + 13, Blocks.gold_ore, 0, 2);
		world.setBlock(i + 17, j + 12, k + 13, Blocks.cobblestone, 0, 2);
		world.setBlock(i + 18, j + 12, k + 13, Blocks.obsidian, 0, 2);
		world.setBlock(i + 13, j + 12, k + 14, Blocks.obsidian, 0, 2);
		world.setBlock(i + 17, j + 12, k + 14, Blocks.gravel, 0, 2);
		world.setBlock(i + 18, j + 12, k + 14, Blocks.cobblestone, 0, 2);
		world.setBlock(i + 19, j + 12, k + 14, Blocks.obsidian, 0, 2);
		world.setBlock(i + 12, j + 12, k + 15, Blocks.obsidian, 0, 2);
		world.setBlock(i + 18, j + 12, k + 15, Blocks.gravel, 0, 2);
		world.setBlock(i + 20, j + 12, k + 15, Blocks.obsidian, 0, 2);
		world.setBlock(i + 11, j + 12, k + 16, Blocks.obsidian, 0, 2);
		world.setBlock(i + 21, j + 12, k + 16, Blocks.obsidian, 0, 2);
		world.setBlock(i + 10, j + 12, k + 17, Blocks.obsidian, 0, 2);
		world.setBlock(i + 11, j + 12, k + 17, Blocks.glowstone, 0, 2);
		world.setBlock(i + 22, j + 12, k + 17, Blocks.obsidian, 0, 2);
		world.setBlock(i + 10, j + 12, k + 18, Blocks.obsidian, 0, 2);
		world.setBlock(i + 11, j + 12, k + 18, Blocks.netherrack, 0, 2);
		world.setBlock(i + 12, j + 12, k + 18, Blocks.quartz_ore, 0, 2);
		world.setBlock(i + 22, j + 12, k + 18, Blocks.obsidian, 0, 2);
		world.setBlock(i + 10, j + 12, k + 19, Blocks.obsidian, 0, 2);
		world.setBlock(i + 11, j + 12, k + 19, Blocks.netherrack, 0, 2);
		world.setBlock(i + 12, j + 12, k + 19, Blocks.lava, 0, 2);
		world.setBlock(i + 13, j + 12, k + 19, Blocks.netherrack, 0, 2);
		world.setBlock(i + 22, j + 12, k + 19, Blocks.obsidian, 0, 2);
		world.setBlock(i + 11, j + 12, k + 20, Blocks.obsidian, 0, 2);
		world.setBlock(i + 12, j + 12, k + 20, Blocks.netherrack, 0, 2);
		world.setBlock(i + 13, j + 12, k + 20, Blocks.nether_wart, 3, 2);
		world.setBlock(i + 21, j + 12, k + 20, Blocks.obsidian, 0, 2);
		world.setBlock(i + 12, j + 12, k + 21, Blocks.obsidian, 0, 2);
		world.setBlock(i + 13, j + 12, k + 21, NovaCraftBlocks.grimstone, 0, 2);
		world.setBlock(i + 20, j + 12, k + 21, Blocks.obsidian, 0, 2);
		world.setBlock(i + 13, j + 12, k + 22, Blocks.obsidian, 0, 2);
		world.setBlock(i + 14, j + 12, k + 22, NovaCraftBlocks.grimstone_emerald, 0, 2);
		world.setBlock(i + 19, j + 12, k + 22, Blocks.obsidian, 0, 2);
		world.setBlock(i + 14, j + 12, k + 23, Blocks.obsidian, 0, 2);
		world.setBlock(i + 15, j + 12, k + 23, NovaCraftBlocks.nullstone, 0, 2);
		world.setBlock(i + 16, j + 12, k + 23, NovaCraftBlocks.cobbled_nullstone, 0, 2);
		world.setBlock(i + 18, j + 12, k + 23, Blocks.obsidian, 0, 2);
		world.setBlock(i + 15, j + 12, k + 24, Blocks.obsidian, 0, 2);
		world.setBlock(i + 16, j + 12, k + 24, Blocks.obsidian, 0, 2);
		world.setBlock(i + 17, j + 12, k + 24, Blocks.obsidian, 0, 2);
		world.setBlock(i + 14, j + 12, k + 32, OtherModBlocks.obsidian_special, 2, 2);
		world.setBlock(i + 18, j + 12, k + 32, OtherModBlocks.obsidian_special, 2, 2);
		world.setBlock(i + 14, j + 13, k + 2, OtherModBlocks.obsidian_special, 2, 2);
		world.setBlock(i + 18, j + 13, k + 2, OtherModBlocks.obsidian_special, 2, 2);
		world.setBlock(i + 16, j + 13, k + 11, NovaCraftBlocks.lacuna_stairs, 6, 2);
		world.setBlock(i + 15, j + 13, k + 12, OtherModBlocks.obsidian_special, 0, 2);
		world.setBlock(i + 16, j + 13, k + 12, OtherModBlocks.obsidian_special, 0, 2);
		world.setBlock(i + 17, j + 13, k + 12, OtherModBlocks.obsidian_special, 0, 2);
		world.setBlock(i + 14, j + 13, k + 13, Blocks.obsidian, 0, 2);
		world.setBlock(i + 17, j + 13, k + 13, Blocks.redstone_ore, 0, 2);
		world.setBlock(i + 18, j + 13, k + 13, Blocks.obsidian, 0, 2);
		world.setBlock(i + 13, j + 13, k + 14, Blocks.obsidian, 0, 2);
		world.setBlock(i + 18, j + 13, k + 14, OtherModBlocks.purpur_pillar, 0, 2);
		world.setBlock(i + 19, j + 13, k + 14, Blocks.obsidian, 0, 2);
		world.setBlock(i + 12, j + 13, k + 15, Blocks.obsidian, 0, 2);
		world.setBlock(i + 20, j + 13, k + 15, Blocks.obsidian, 0, 2);
		world.setBlock(i + 11, j + 13, k + 16, Blocks.obsidian, 0, 2);
		world.setBlock(i + 21, j + 13, k + 16, Blocks.obsidian, 0, 2);
		world.setBlock(i + 10, j + 13, k + 17, OtherModBlocks.obsidian_special, 0, 2);
		world.setBlock(i + 22, j + 13, k + 17, Blocks.obsidian, 0, 2);
		world.setBlock(i + 9, j + 13, k + 18, NovaCraftBlocks.lacuna_stairs, 4, 2);
		world.setBlock(i + 10, j + 13, k + 18, OtherModBlocks.obsidian_special, 0, 2);
		world.setBlock(i + 11, j + 13, k + 18, Blocks.netherrack, 0, 2);
		world.setBlock(i + 22, j + 13, k + 18, Blocks.obsidian, 0, 2);
		world.setBlock(i + 10, j + 13, k + 19, OtherModBlocks.obsidian_special, 0, 2);
		world.setBlock(i + 11, j + 13, k + 19, Blocks.netherrack, 0, 2);
		world.setBlock(i + 22, j + 13, k + 19, Blocks.obsidian, 0, 2);
		world.setBlock(i + 11, j + 13, k + 20, Blocks.obsidian, 0, 2);
		world.setBlock(i + 12, j + 13, k + 20, Blocks.glowstone, 0, 2);
		world.setBlock(i + 21, j + 13, k + 20, Blocks.obsidian, 0, 2);
		world.setBlock(i + 12, j + 13, k + 21, Blocks.obsidian, 0, 2);
		world.setBlock(i + 13, j + 13, k + 21, NovaCraftBlocks.grimstone_lapis, 0, 2);
		world.setBlock(i + 20, j + 13, k + 21, Blocks.obsidian, 0, 2);
		world.setBlock(i + 13, j + 13, k + 22, Blocks.obsidian, 0, 2);
		world.setBlock(i + 14, j + 13, k + 22, NovaCraftBlocks.cobbled_grimstone, 0, 2);
		world.setBlock(i + 19, j + 13, k + 22, Blocks.obsidian, 0, 2);
		world.setBlock(i + 14, j + 13, k + 23, Blocks.obsidian, 0, 2);
		world.setBlock(i + 15, j + 13, k + 23, NovaCraftBlocks.cobbled_nullstone, 0, 2);
		world.setBlock(i + 16, j + 13, k + 23, NovaCraftBlocks.nullstone_stalagmite, 0, 2);
		world.setBlock(i + 18, j + 13, k + 23, Blocks.obsidian, 0, 2);
		world.setBlock(i + 15, j + 13, k + 24, Blocks.obsidian, 0, 2);
		world.setBlock(i + 16, j + 13, k + 24, Blocks.obsidian, 0, 2);
		world.setBlock(i + 17, j + 13, k + 24, Blocks.obsidian, 0, 2);
		world.setBlock(i + 14, j + 13, k + 32, OtherModBlocks.obsidian_special, 2, 2);
		world.setBlock(i + 18, j + 13, k + 32, OtherModBlocks.obsidian_special, 2, 2);
		world.setBlock(i + 14, j + 14, k + 2, OtherModBlocks.obsidian_special, 2, 2);
		world.setBlock(i + 18, j + 14, k + 2, OtherModBlocks.obsidian_special, 2, 2);
		world.setBlock(i + 15, j + 14, k + 12, OtherModBlocks.obsidian_special, 1, 2);
		world.setBlock(i + 16, j + 14, k + 12, Blocks.iron_bars, 0, 2);
		world.setBlock(i + 17, j + 14, k + 12, OtherModBlocks.obsidian_special, 1, 2);
		world.setBlock(i + 14, j + 14, k + 13, Blocks.obsidian, 0, 2);
		world.setBlock(i + 18, j + 14, k + 13, Blocks.obsidian, 0, 2);
		world.setBlock(i + 13, j + 14, k + 14, Blocks.obsidian, 0, 2);
		world.setBlock(i + 18, j + 14, k + 14, Blocks.red_mushroom, 0, 2);
		world.setBlock(i + 19, j + 14, k + 14, Blocks.obsidian, 0, 2);
		world.setBlock(i + 12, j + 14, k + 15, Blocks.obsidian, 0, 2);
		world.setBlock(i + 20, j + 14, k + 15, Blocks.obsidian, 0, 2);
		world.setBlock(i + 11, j + 14, k + 16, Blocks.obsidian, 0, 2);
		world.setBlock(i + 21, j + 14, k + 16, Blocks.obsidian, 0, 2);
		world.setBlock(i + 10, j + 14, k + 17, OtherModBlocks.obsidian_special, 1, 2);
		world.setBlock(i + 22, j + 14, k + 17, OtherModBlocks.obsidian_special, 0, 2);
		world.setBlock(i + 10, j + 14, k + 18, Blocks.iron_bars, 0, 2);
		world.setBlock(i + 22, j + 14, k + 18, OtherModBlocks.obsidian_special, 0, 2);
		world.setBlock(i + 23, j + 14, k + 18, NovaCraftBlocks.lacuna_stairs, 5, 2);
		world.setBlock(i + 10, j + 14, k + 19, OtherModBlocks.obsidian_special, 1, 2);
		world.setBlock(i + 11, j + 14, k + 19, NovaCraftBlocks.ion_mushroom, 0, 2);
		world.setBlock(i + 22, j + 14, k + 19, OtherModBlocks.obsidian_special, 0, 2);
		world.setBlock(i + 11, j + 14, k + 20, Blocks.obsidian, 0, 2);
		world.setBlock(i + 21, j + 14, k + 20, Blocks.obsidian, 0, 2);
		world.setBlock(i + 12, j + 14, k + 21, Blocks.obsidian, 0, 2);
		world.setBlock(i + 20, j + 14, k + 21, Blocks.obsidian, 0, 2);
		world.setBlock(i + 13, j + 14, k + 22, Blocks.obsidian, 0, 2);
		world.setBlock(i + 19, j + 14, k + 22, Blocks.obsidian, 0, 2);
		world.setBlock(i + 14, j + 14, k + 23, Blocks.obsidian, 0, 2);
		world.setBlock(i + 18, j + 14, k + 23, Blocks.obsidian, 0, 2);
		world.setBlock(i + 15, j + 14, k + 24, Blocks.obsidian, 0, 2);
		world.setBlock(i + 16, j + 14, k + 24, Blocks.obsidian, 0, 2);
		world.setBlock(i + 17, j + 14, k + 24, Blocks.obsidian, 0, 2);
		world.setBlock(i + 14, j + 14, k + 32, OtherModBlocks.obsidian_special, 2, 2);
		world.setBlock(i + 18, j + 14, k + 32, OtherModBlocks.obsidian_special, 2, 2);
		world.setBlock(i + 14, j + 15, k + 2, OtherModBlocks.obsidian_special, 2, 2);
		world.setBlock(i + 18, j + 15, k + 2, OtherModBlocks.obsidian_special, 2, 2);
		world.setBlock(i + 15, j + 15, k + 12, OtherModBlocks.obsidian_special, 1, 2);
		world.setBlock(i + 16, j + 15, k + 12, Blocks.iron_bars, 0, 2);
		world.setBlock(i + 17, j + 15, k + 12, OtherModBlocks.obsidian_special, 1, 2);
		world.setBlock(i + 14, j + 15, k + 13, Blocks.obsidian, 0, 2);
		world.setBlock(i + 18, j + 15, k + 13, Blocks.obsidian, 0, 2);
		world.setBlock(i + 13, j + 15, k + 14, Blocks.obsidian, 0, 2);
		world.setBlock(i + 19, j + 15, k + 14, Blocks.obsidian, 0, 2);
		world.setBlock(i + 12, j + 15, k + 15, Blocks.obsidian, 0, 2);
		world.setBlock(i + 20, j + 15, k + 15, Blocks.obsidian, 0, 2);
		world.setBlock(i + 11, j + 15, k + 16, Blocks.obsidian, 0, 2);
		world.setBlock(i + 21, j + 15, k + 16, Blocks.obsidian, 0, 2);
		world.setBlock(i + 10, j + 15, k + 17, OtherModBlocks.obsidian_special, 1, 2);
		world.setBlock(i + 22, j + 15, k + 17, OtherModBlocks.obsidian_special, 1, 2);
		world.setBlock(i + 10, j + 15, k + 18, Blocks.iron_bars, 0, 2);
		world.setBlock(i + 22, j + 15, k + 18, Blocks.iron_bars, 0, 2);
		world.setBlock(i + 10, j + 15, k + 19, OtherModBlocks.obsidian_special, 1, 2);
		world.setBlock(i + 22, j + 15, k + 19, OtherModBlocks.obsidian_special, 1, 2);
		world.setBlock(i + 11, j + 15, k + 20, Blocks.obsidian, 0, 2);
		world.setBlock(i + 21, j + 15, k + 20, Blocks.obsidian, 0, 2);
		world.setBlock(i + 12, j + 15, k + 21, Blocks.obsidian, 0, 2);
		world.setBlock(i + 20, j + 15, k + 21, Blocks.obsidian, 0, 2);
		world.setBlock(i + 13, j + 15, k + 22, Blocks.obsidian, 0, 2);
		world.setBlock(i + 19, j + 15, k + 22, Blocks.obsidian, 0, 2);
		world.setBlock(i + 14, j + 15, k + 23, Blocks.obsidian, 0, 2);
		world.setBlock(i + 18, j + 15, k + 23, Blocks.obsidian, 0, 2);
		world.setBlock(i + 15, j + 15, k + 24, Blocks.obsidian, 0, 2);
		world.setBlock(i + 16, j + 15, k + 24, Blocks.obsidian, 0, 2);
		world.setBlock(i + 17, j + 15, k + 24, Blocks.obsidian, 0, 2);
		world.setBlock(i + 14, j + 15, k + 32, OtherModBlocks.obsidian_special, 2, 2);
		world.setBlock(i + 18, j + 15, k + 32, OtherModBlocks.obsidian_special, 2, 2);
		world.setBlock(i + 14, j + 16, k + 2, OtherModBlocks.obsidian_special, 2, 2);
		world.setBlock(i + 18, j + 16, k + 2, OtherModBlocks.obsidian_special, 2, 2);
		world.setBlock(i + 16, j + 16, k + 11, OtherModBlocks.end_rod, 0, 2);
		world.setBlock(i + 15, j + 16, k + 12, Blocks.obsidian, 0, 2);
		world.setBlock(i + 16, j + 16, k + 12, OtherModBlocks.obsidian_special, 0, 2);
		world.setBlock(i + 17, j + 16, k + 12, Blocks.obsidian, 0, 2);
		world.setBlock(i + 14, j + 16, k + 13, Blocks.obsidian, 0, 2);
		world.setBlock(i + 15, j + 16, k + 13, NovaCraftBlocks.lacuna_planks, 0, 2);
		world.setBlock(i + 16, j + 16, k + 13, NovaCraftBlocks.lacuna_planks, 0, 2);
		world.setBlock(i + 17, j + 16, k + 13, NovaCraftBlocks.lacuna_planks, 0, 2);
		world.setBlock(i + 18, j + 16, k + 13, Blocks.obsidian, 0, 2);
		world.setBlock(i + 13, j + 16, k + 14, Blocks.obsidian, 0, 2);
		world.setBlock(i + 14, j + 16, k + 14, NovaCraftBlocks.lacuna_planks, 0, 2);
		world.setBlock(i + 15, j + 16, k + 14, NovaCraftBlocks.lacuna_planks, 0, 2);
		world.setBlock(i + 16, j + 16, k + 14, NovaCraftBlocks.lacuna_planks, 0, 2);
		world.setBlock(i + 19, j + 16, k + 14, Blocks.obsidian, 0, 2);
		world.setBlock(i + 12, j + 16, k + 15, Blocks.obsidian, 0, 2);
		world.setBlock(i + 13, j + 16, k + 15, NovaCraftBlocks.lacuna_planks, 0, 2);
		world.setBlock(i + 14, j + 16, k + 15, NovaCraftBlocks.lacuna_planks, 0, 2);
		world.setBlock(i + 15, j + 16, k + 15, NovaCraftBlocks.lacuna_planks, 0, 2);
		world.setBlock(i + 16, j + 16, k + 15, NovaCraftBlocks.lacuna_planks, 0, 2);
		world.setBlock(i + 20, j + 16, k + 15, Blocks.obsidian, 0, 2);
		world.setBlock(i + 11, j + 16, k + 16, Blocks.obsidian, 0, 2);
		world.setBlock(i + 12, j + 16, k + 16, NovaCraftBlocks.lacuna_planks, 0, 2);
		world.setBlock(i + 13, j + 16, k + 16, NovaCraftBlocks.lacuna_planks, 0, 2);
		world.setBlock(i + 14, j + 16, k + 16, NovaCraftBlocks.lacuna_planks, 0, 2);
		world.setBlock(i + 21, j + 16, k + 16, Blocks.obsidian, 0, 2);
		world.setBlock(i + 10, j + 16, k + 17, Blocks.obsidian, 0, 2);
		world.setBlock(i + 11, j + 16, k + 17, NovaCraftBlocks.lacuna_planks, 0, 2);
		world.setBlock(i + 12, j + 16, k + 17, NovaCraftBlocks.lacuna_planks, 0, 2);
		world.setBlock(i + 13, j + 16, k + 17, NovaCraftBlocks.lacuna_planks, 0, 2);
		world.setBlock(i + 22, j + 16, k + 17, OtherModBlocks.obsidian_special, 1, 2);
		world.setBlock(i + 9, j + 16, k + 18, OtherModBlocks.end_rod, 0, 2);
		world.setBlock(i + 10, j + 16, k + 18, OtherModBlocks.obsidian_special, 0, 2);
		world.setBlock(i + 11, j + 16, k + 18, NovaCraftBlocks.lacuna_planks, 0, 2);
		world.setBlock(i + 12, j + 16, k + 18, NovaCraftBlocks.lacuna_planks, 0, 2);
		world.setBlock(i + 22, j + 16, k + 18, Blocks.iron_bars, 0, 2);
		world.setBlock(i + 10, j + 16, k + 19, Blocks.obsidian, 0, 2);
		world.setBlock(i + 11, j + 16, k + 19, NovaCraftBlocks.lacuna_planks, 0, 2);
		world.setBlock(i + 22, j + 16, k + 19, OtherModBlocks.obsidian_special, 1, 2);
		world.setBlock(i + 11, j + 16, k + 20, Blocks.obsidian, 0, 2);
		world.setBlock(i + 21, j + 16, k + 20, Blocks.obsidian, 0, 2);
		world.setBlock(i + 12, j + 16, k + 21, Blocks.obsidian, 0, 2);
		world.setBlock(i + 20, j + 16, k + 21, Blocks.obsidian, 0, 2);
		world.setBlock(i + 13, j + 16, k + 22, Blocks.obsidian, 0, 2);
		world.setBlock(i + 19, j + 16, k + 22, Blocks.obsidian, 0, 2);
		world.setBlock(i + 14, j + 16, k + 23, Blocks.obsidian, 0, 2);
		world.setBlock(i + 18, j + 16, k + 23, Blocks.obsidian, 0, 2);
		world.setBlock(i + 15, j + 16, k + 24, Blocks.obsidian, 0, 2);
		world.setBlock(i + 16, j + 16, k + 24, Blocks.obsidian, 0, 2);
		world.setBlock(i + 17, j + 16, k + 24, Blocks.obsidian, 0, 2);
		world.setBlock(i + 14, j + 16, k + 32, OtherModBlocks.obsidian_special, 2, 2);
		world.setBlock(i + 18, j + 16, k + 32, OtherModBlocks.obsidian_special, 2, 2);
		world.setBlock(i + 14, j + 17, k + 2, OtherModBlocks.obsidian_special, 2, 2);
		world.setBlock(i + 18, j + 17, k + 2, OtherModBlocks.obsidian_special, 2, 2);
		world.setBlock(i + 16, j + 17, k + 11, OtherModBlocks.obsidian_special, 1, 2);
		world.setBlock(i + 15, j + 17, k + 12, Blocks.obsidian, 0, 2);
		world.setBlock(i + 16, j + 17, k + 12, Blocks.obsidian, 0, 2);
		world.setBlock(i + 17, j + 17, k + 12, Blocks.obsidian, 0, 2);
		world.setBlock(i + 14, j + 17, k + 13, Blocks.obsidian, 0, 2);
		world.setBlock(i + 15, j + 17, k + 13, NovaCraftBlocks.lacuna_planks, 0, 2);
		world.setBlock(i + 16, j + 17, k + 13, NovaCraftBlocks.lacuna_planks, 0, 2);
		world.setBlock(i + 17, j + 17, k + 13, NovaCraftBlocks.lacuna_planks, 0, 2);
		world.setBlock(i + 18, j + 17, k + 13, Blocks.obsidian, 0, 2);
		world.setBlock(i + 13, j + 17, k + 14, Blocks.obsidian, 0, 2);
		world.setBlock(i + 14, j + 17, k + 14, NovaCraftBlocks.lacuna_planks, 0, 2);
		world.setBlock(i + 15, j + 17, k + 14, NovaCraftBlocks.lacuna_planks, 0, 2);
		world.setBlock(i + 16, j + 17, k + 14, NovaCraftBlocks.lacuna_planks, 0, 2);
		world.setBlock(i + 17, j + 17, k + 14, NovaCraftBlocks.lacuna_slab, 0, 2);
		world.setBlock(i + 19, j + 17, k + 14, Blocks.obsidian, 0, 2);
		world.setBlock(i + 12, j + 17, k + 15, Blocks.obsidian, 0, 2);
		world.setBlock(i + 13, j + 17, k + 15, NovaCraftBlocks.lacuna_planks, 0, 2);
		world.setBlock(i + 14, j + 17, k + 15, NovaCraftBlocks.lacuna_planks, 0, 2);
		world.setBlock(i + 15, j + 17, k + 15, NovaCraftBlocks.lacuna_planks, 0, 2);
		world.setBlock(i + 16, j + 17, k + 15, NovaCraftBlocks.lacuna_planks, 0, 2);
		world.setBlock(i + 17, j + 17, k + 15, NovaCraftBlocks.lacuna_slab, 0, 2);
		world.setBlock(i + 20, j + 17, k + 15, Blocks.obsidian, 0, 2);
		world.setBlock(i + 11, j + 17, k + 16, Blocks.obsidian, 0, 2);
		world.setBlock(i + 12, j + 17, k + 16, NovaCraftBlocks.nullstone_tiles, 0, 2);
		world.setBlock(i + 13, j + 17, k + 16, NovaCraftBlocks.lacuna_planks, 0, 2);
		world.setBlock(i + 14, j + 17, k + 16, NovaCraftBlocks.lacuna_planks, 0, 2);
		world.setBlock(i + 15, j + 17, k + 16, NovaCraftBlocks.lacuna_planks, 0, 2);
		world.setBlock(i + 16, j + 17, k + 16, NovaCraftBlocks.lacuna_slab, 0, 2);
		world.setBlock(i + 21, j + 17, k + 16, Blocks.obsidian, 0, 2);
		world.setBlock(i + 10, j + 17, k + 17, Blocks.obsidian, 0, 2);
		world.setBlock(i + 11, j + 17, k + 17, NovaCraftBlocks.lacuna_planks, 0, 2);
		world.setBlock(i + 12, j + 17, k + 17, NovaCraftBlocks.lacuna_planks, 0, 2);
		world.setBlock(i + 13, j + 17, k + 17, NovaCraftBlocks.lacuna_planks, 0, 2);
		world.setBlock(i + 14, j + 17, k + 17, NovaCraftBlocks.lacuna_planks, 0, 2);
		world.setBlock(i + 15, j + 17, k + 17, NovaCraftBlocks.lacuna_slab, 0, 2);
		world.setBlock(i + 22, j + 17, k + 17, OtherModBlocks.obsidian_special, 0, 2);
		world.setBlock(i + 9, j + 17, k + 18, OtherModBlocks.obsidian_special, 1, 2);
		world.setBlock(i + 10, j + 17, k + 18, Blocks.obsidian, 0, 2);
		world.setBlock(i + 11, j + 17, k + 18, NovaCraftBlocks.lacuna_planks, 0, 2);
		world.setBlock(i + 12, j + 17, k + 18, NovaCraftBlocks.lacuna_planks, 0, 2);
		world.setBlock(i + 13, j + 17, k + 18, NovaCraftBlocks.lacuna_planks, 0, 2);
		world.setBlock(i + 14, j + 17, k + 18, NovaCraftBlocks.lacuna_slab, 0, 2);
		world.setBlock(i + 22, j + 17, k + 18, OtherModBlocks.obsidian_special, 0, 2);
		world.setBlock(i + 23, j + 17, k + 18, OtherModBlocks.end_rod, 0, 2);
		world.setBlock(i + 10, j + 17, k + 19, Blocks.obsidian, 0, 2);
		world.setBlock(i + 11, j + 17, k + 19, NovaCraftBlocks.lacuna_planks, 0, 2);
		world.setBlock(i + 12, j + 17, k + 19, NovaCraftBlocks.lacuna_planks, 0, 2);
		world.setBlock(i + 13, j + 17, k + 19, NovaCraftBlocks.lacuna_slab, 0, 2);
		world.setBlock(i + 22, j + 17, k + 19, OtherModBlocks.obsidian_special, 0, 2);
		world.setBlock(i + 11, j + 17, k + 20, Blocks.obsidian, 0, 2);
		world.setBlock(i + 12, j + 17, k + 20, NovaCraftBlocks.lacuna_slab, 0, 2);
		world.setBlock(i + 21, j + 17, k + 20, Blocks.obsidian, 0, 2);
		world.setBlock(i + 12, j + 17, k + 21, Blocks.obsidian, 0, 2);
		world.setBlock(i + 20, j + 17, k + 21, Blocks.obsidian, 0, 2);
		world.setBlock(i + 13, j + 17, k + 22, Blocks.obsidian, 0, 2);
		world.setBlock(i + 19, j + 17, k + 22, Blocks.obsidian, 0, 2);
		world.setBlock(i + 14, j + 17, k + 23, Blocks.obsidian, 0, 2);
		world.setBlock(i + 18, j + 17, k + 23, Blocks.obsidian, 0, 2);
		world.setBlock(i + 15, j + 17, k + 24, Blocks.obsidian, 0, 2);
		world.setBlock(i + 16, j + 17, k + 24, Blocks.obsidian, 0, 2);
		world.setBlock(i + 17, j + 17, k + 24, Blocks.obsidian, 0, 2);
		world.setBlock(i + 14, j + 17, k + 32, OtherModBlocks.obsidian_special, 2, 2);
		world.setBlock(i + 18, j + 17, k + 32, OtherModBlocks.obsidian_special, 2, 2);
		world.setBlock(i + 14, j + 18, k + 2, OtherModBlocks.obsidian_special, 2, 2);
		world.setBlock(i + 18, j + 18, k + 2, OtherModBlocks.obsidian_special, 2, 2);
		world.setBlock(i + 15, j + 18, k + 12, Blocks.obsidian, 0, 2);
		world.setBlock(i + 16, j + 18, k + 12, Blocks.obsidian, 0, 2);
		world.setBlock(i + 17, j + 18, k + 12, Blocks.obsidian, 0, 2);
		world.setBlock(i + 14, j + 18, k + 13, Blocks.obsidian, 0, 2);
		world.setBlock(i + 15, j + 18, k + 13, Blocks.sand, 0, 2);
		world.setBlock(i + 16, j + 18, k + 13, Blocks.sand, 0, 2);
		world.setBlock(i + 17, j + 18, k + 13, Blocks.sand, 0, 2);
		world.setBlock(i + 18, j + 18, k + 13, Blocks.obsidian, 0, 2);
		world.setBlock(i + 13, j + 18, k + 14, Blocks.obsidian, 0, 2);
		world.setBlock(i + 14, j + 18, k + 14, Blocks.clay, 0, 2);
		world.setBlock(i + 15, j + 18, k + 14, Blocks.sand, 0, 2);
		world.setBlock(i + 16, j + 18, k + 14, Blocks.sand, 0, 2);
		world.setBlock(i + 19, j + 18, k + 14, Blocks.obsidian, 0, 2);
		world.setBlock(i + 12, j + 18, k + 15, Blocks.obsidian, 0, 2);
		world.setBlock(i + 13, j + 18, k + 15, Blocks.dirt, 0, 2);
		world.setBlock(i + 14, j + 18, k + 15, Blocks.dirt, 0, 2);
		world.setBlock(i + 15, j + 18, k + 15, Blocks.sand, 0, 2);
		world.setBlock(i + 16, j + 18, k + 15, Blocks.sand, 0, 2);
		world.setBlock(i + 20, j + 18, k + 15, Blocks.obsidian, 0, 2);
		world.setBlock(i + 11, j + 18, k + 16, Blocks.obsidian, 0, 2);
		world.setBlock(i + 12, j + 18, k + 16, Blocks.dirt, 0, 2);
		world.setBlock(i + 13, j + 18, k + 16, Blocks.dirt, 0, 2);
		world.setBlock(i + 14, j + 18, k + 16, Blocks.grass, 0, 2);
		world.setBlock(i + 15, j + 18, k + 16, Blocks.sand, 0, 2);
		world.setBlock(i + 21, j + 18, k + 16, Blocks.obsidian, 0, 2);
		world.setBlock(i + 10, j + 18, k + 17, Blocks.obsidian, 0, 2);
		world.setBlock(i + 11, j + 18, k + 17, Blocks.dirt, 0, 2);
		world.setBlock(i + 12, j + 18, k + 17, Blocks.dirt, 0, 2);
		world.setBlock(i + 13, j + 18, k + 17, Blocks.grass, 0, 2);
		world.setBlock(i + 22, j + 18, k + 17, Blocks.obsidian, 0, 2);
		world.setBlock(i + 10, j + 18, k + 18, Blocks.obsidian, 0, 2);
		world.setBlock(i + 11, j + 18, k + 18, Blocks.dirt, 0, 2);
		world.setBlock(i + 12, j + 18, k + 18, Blocks.grass, 0, 2);
		world.setBlock(i + 22, j + 18, k + 18, Blocks.obsidian, 0, 2);
		world.setBlock(i + 23, j + 18, k + 18, OtherModBlocks.obsidian_special, 1, 2);
		world.setBlock(i + 10, j + 18, k + 19, Blocks.obsidian, 0, 2);
		world.setBlock(i + 11, j + 18, k + 19, Blocks.grass, 0, 2);
		world.setBlock(i + 22, j + 18, k + 19, Blocks.obsidian, 0, 2);
		world.setBlock(i + 11, j + 18, k + 20, Blocks.obsidian, 0, 2);
		world.setBlock(i + 21, j + 18, k + 20, Blocks.obsidian, 0, 2);
		world.setBlock(i + 12, j + 18, k + 21, Blocks.obsidian, 0, 2);
		world.setBlock(i + 20, j + 18, k + 21, Blocks.obsidian, 0, 2);
		world.setBlock(i + 13, j + 18, k + 22, Blocks.obsidian, 0, 2);
		world.setBlock(i + 19, j + 18, k + 22, Blocks.obsidian, 0, 2);
		world.setBlock(i + 14, j + 18, k + 23, Blocks.obsidian, 0, 2);
		world.setBlock(i + 18, j + 18, k + 23, Blocks.obsidian, 0, 2);
		world.setBlock(i + 15, j + 18, k + 24, Blocks.obsidian, 0, 2);
		world.setBlock(i + 16, j + 18, k + 24, Blocks.obsidian, 0, 2);
		world.setBlock(i + 17, j + 18, k + 24, Blocks.obsidian, 0, 2);
		world.setBlock(i + 14, j + 18, k + 32, OtherModBlocks.obsidian_special, 2, 2);
		world.setBlock(i + 18, j + 18, k + 32, OtherModBlocks.obsidian_special, 2, 2);
		world.setBlock(i + 14, j + 19, k + 2, Blocks.obsidian, 0, 2);
		world.setBlock(i + 15, j + 19, k + 2, Blocks.obsidian, 0, 2);
		world.setBlock(i + 16, j + 19, k + 2, Blocks.obsidian, 0, 2);
		world.setBlock(i + 17, j + 19, k + 2, Blocks.obsidian, 0, 2);
		world.setBlock(i + 18, j + 19, k + 2, Blocks.obsidian, 0, 2);
		world.setBlock(i + 14, j + 19, k + 3, Blocks.obsidian, 0, 2);
		world.setBlock(i + 15, j + 19, k + 3, Blocks.obsidian, 0, 2);
		world.setBlock(i + 16, j + 19, k + 3, Blocks.obsidian, 0, 2);
		world.setBlock(i + 17, j + 19, k + 3, Blocks.obsidian, 0, 2);
		world.setBlock(i + 18, j + 19, k + 3, Blocks.obsidian, 0, 2);
		world.setBlock(i + 14, j + 19, k + 4, Blocks.obsidian, 0, 2);
		world.setBlock(i + 15, j + 19, k + 4, Blocks.obsidian, 0, 2);
		world.setBlock(i + 16, j + 19, k + 4, Blocks.obsidian, 0, 2);
		world.setBlock(i + 17, j + 19, k + 4, Blocks.obsidian, 0, 2);
		world.setBlock(i + 18, j + 19, k + 4, Blocks.obsidian, 0, 2);
		world.setBlock(i + 14, j + 19, k + 5, Blocks.obsidian, 0, 2);
		world.setBlock(i + 15, j + 19, k + 5, Blocks.obsidian, 0, 2);
		world.setBlock(i + 16, j + 19, k + 5, Blocks.obsidian, 0, 2);
		world.setBlock(i + 17, j + 19, k + 5, Blocks.obsidian, 0, 2);
		world.setBlock(i + 18, j + 19, k + 5, Blocks.obsidian, 0, 2);
		world.setBlock(i + 15, j + 19, k + 6, Blocks.obsidian, 0, 2);
		world.setBlock(i + 16, j + 19, k + 6, Blocks.obsidian, 0, 2);
		world.setBlock(i + 17, j + 19, k + 6, Blocks.obsidian, 0, 2);
		world.setBlock(i + 16, j + 19, k + 7, Blocks.obsidian, 0, 2);
		world.setBlock(i + 16, j + 19, k + 8, Blocks.obsidian, 0, 2);
		world.setBlock(i + 16, j + 19, k + 9, Blocks.obsidian, 0, 2);
		world.setBlock(i + 16, j + 19, k + 10, Blocks.obsidian, 0, 2);
		world.setBlock(i + 16, j + 19, k + 11, OtherModBlocks.obsidian_special, 0, 2);
		world.setBlock(i + 15, j + 19, k + 12, Blocks.obsidian, 0, 2);
		world.setBlock(i + 16, j + 19, k + 12, OtherModBlocks.obsidian_special, 0, 2);
		world.setBlock(i + 17, j + 19, k + 12, Blocks.obsidian, 0, 2);
		world.setBlock(i + 14, j + 19, k + 13, Blocks.obsidian, 0, 2);
		world.setBlock(i + 15, j + 19, k + 13, Blocks.water, 0, 2);
		world.setBlock(i + 16, j + 19, k + 13, Blocks.sand, 0, 2);
		world.setBlock(i + 17, j + 19, k + 13, Blocks.sand, 0, 2);
		world.setBlock(i + 18, j + 19, k + 13, Blocks.obsidian, 0, 2);
		world.setBlock(i + 13, j + 19, k + 14, Blocks.obsidian, 0, 2);
		world.setBlock(i + 14, j + 19, k + 14, Blocks.water, 0, 2);
		world.setBlock(i + 15, j + 19, k + 14, Blocks.clay, 0, 2);
		world.setBlock(i + 16, j + 19, k + 14, Blocks.sand, 0, 2);
		world.setBlock(i + 19, j + 19, k + 14, Blocks.obsidian, 0, 2);
		world.setBlock(i + 12, j + 19, k + 15, Blocks.obsidian, 0, 2);
		world.setBlock(i + 13, j + 19, k + 15, Blocks.grass, 0, 2);
		world.setBlock(i + 14, j + 19, k + 15, Blocks.grass, 0, 2);
		world.setBlock(i + 15, j + 19, k + 15, Blocks.clay, 0, 2);
		world.setBlock(i + 20, j + 19, k + 15, Blocks.obsidian, 0, 2);
		world.setBlock(i + 11, j + 19, k + 16, Blocks.obsidian, 0, 2);
		world.setBlock(i + 12, j + 19, k + 16, Blocks.grass, 0, 2);
		world.setBlock(i + 13, j + 19, k + 16, Blocks.grass, 0, 2);
		world.setBlock(i + 14, j + 19, k + 16, Blocks.tallgrass, 1, 2);
		world.setBlock(i + 21, j + 19, k + 16, Blocks.obsidian, 0, 2);
		world.setBlock(i + 10, j + 19, k + 17, Blocks.obsidian, 0, 2);
		world.setBlock(i + 11, j + 19, k + 17, Blocks.dirt, 0, 2);
		world.setBlock(i + 12, j + 19, k + 17, Blocks.grass, 0, 2);
		world.setBlock(i + 13, j + 19, k + 17, Blocks.tallgrass, 1, 2);
		world.setBlock(i + 22, j + 19, k + 17, Blocks.obsidian, 0, 2);
		world.setBlock(i + 10, j + 19, k + 18, Blocks.obsidian, 0, 2);
		world.setBlock(i + 11, j + 19, k + 18, Blocks.grass, 0, 2);
		world.setBlock(i + 12, j + 19, k + 18, Blocks.double_plant, 4, 2);
		world.setBlock(i + 22, j + 19, k + 18, Blocks.obsidian, 0, 2);
		world.setBlock(i + 10, j + 19, k + 19, Blocks.obsidian, 0, 2);
		world.setBlock(i + 11, j + 19, k + 19, Blocks.red_flower, 5, 2);
		world.setBlock(i + 22, j + 19, k + 19, Blocks.obsidian, 0, 2);
		world.setBlock(i + 11, j + 19, k + 20, Blocks.obsidian, 0, 2);
		world.setBlock(i + 21, j + 19, k + 20, Blocks.obsidian, 0, 2);
		world.setBlock(i + 12, j + 19, k + 21, Blocks.obsidian, 0, 2);
		world.setBlock(i + 20, j + 19, k + 21, Blocks.obsidian, 0, 2);
		world.setBlock(i + 13, j + 19, k + 22, Blocks.obsidian, 0, 2);
		world.setBlock(i + 19, j + 19, k + 22, Blocks.obsidian, 0, 2);
		world.setBlock(i + 14, j + 19, k + 23, Blocks.obsidian, 0, 2);
		world.setBlock(i + 18, j + 19, k + 23, Blocks.obsidian, 0, 2);
		world.setBlock(i + 15, j + 19, k + 24, Blocks.obsidian, 0, 2);
		world.setBlock(i + 16, j + 19, k + 24, OtherModBlocks.obsidian_special, 0, 2);
		world.setBlock(i + 17, j + 19, k + 24, Blocks.obsidian, 0, 2);
		world.setBlock(i + 16, j + 19, k + 25, Blocks.obsidian, 0, 2);
		world.setBlock(i + 16, j + 19, k + 26, Blocks.obsidian, 0, 2);
		world.setBlock(i + 16, j + 19, k + 27, Blocks.obsidian, 0, 2);
		world.setBlock(i + 14, j + 19, k + 28, Blocks.obsidian, 0, 2);
		world.setBlock(i + 15, j + 19, k + 28, Blocks.obsidian, 0, 2);
		world.setBlock(i + 16, j + 19, k + 28, Blocks.obsidian, 0, 2);
		world.setBlock(i + 17, j + 19, k + 28, Blocks.obsidian, 0, 2);
		world.setBlock(i + 18, j + 19, k + 28, Blocks.obsidian, 0, 2);
		world.setBlock(i + 14, j + 19, k + 29, Blocks.obsidian, 0, 2);
		world.setBlock(i + 15, j + 19, k + 29, Blocks.obsidian, 0, 2);
		world.setBlock(i + 16, j + 19, k + 29, Blocks.obsidian, 0, 2);
		world.setBlock(i + 17, j + 19, k + 29, Blocks.obsidian, 0, 2);
		world.setBlock(i + 18, j + 19, k + 29, Blocks.obsidian, 0, 2);
		world.setBlock(i + 14, j + 19, k + 30, Blocks.obsidian, 0, 2);
		world.setBlock(i + 15, j + 19, k + 30, Blocks.obsidian, 0, 2);
		world.setBlock(i + 16, j + 19, k + 30, Blocks.obsidian, 0, 2);
		world.setBlock(i + 17, j + 19, k + 30, Blocks.obsidian, 0, 2);
		world.setBlock(i + 18, j + 19, k + 30, Blocks.obsidian, 0, 2);
		world.setBlock(i + 14, j + 19, k + 31, Blocks.obsidian, 0, 2);
		world.setBlock(i + 15, j + 19, k + 31, Blocks.obsidian, 0, 2);
		world.setBlock(i + 16, j + 19, k + 31, Blocks.obsidian, 0, 2);
		world.setBlock(i + 17, j + 19, k + 31, Blocks.obsidian, 0, 2);
		world.setBlock(i + 18, j + 19, k + 31, Blocks.obsidian, 0, 2);
		world.setBlock(i + 14, j + 19, k + 32, Blocks.obsidian, 0, 2);
		world.setBlock(i + 15, j + 19, k + 32, Blocks.obsidian, 0, 2);
		world.setBlock(i + 16, j + 19, k + 32, Blocks.obsidian, 0, 2);
		world.setBlock(i + 17, j + 19, k + 32, Blocks.obsidian, 0, 2);
		world.setBlock(i + 18, j + 19, k + 32, Blocks.obsidian, 0, 2);
		world.setBlock(i + 15, j + 19, k + 33, Blocks.obsidian, 0, 2);
		world.setBlock(i + 16, j + 19, k + 33, Blocks.obsidian, 0, 2);
		world.setBlock(i + 17, j + 19, k + 33, Blocks.obsidian, 0, 2);
		world.setBlock(i + 14, j + 20, k + 1, Blocks.obsidian, 0, 2);
		world.setBlock(i + 15, j + 20, k + 1, Blocks.obsidian, 0, 2);
		world.setBlock(i + 16, j + 20, k + 1, Blocks.obsidian, 0, 2);
		world.setBlock(i + 17, j + 20, k + 1, Blocks.obsidian, 0, 2);
		world.setBlock(i + 18, j + 20, k + 1, Blocks.obsidian, 0, 2);
		world.setBlock(i + 13, j + 20, k + 2, Blocks.obsidian, 0, 2);
		world.setBlock(i + 14, j + 20, k + 2, NovaCraftBlocks.frontierslate, 0, 2);
		world.setBlock(i + 15, j + 20, k + 2, Blocks.end_stone, 0, 2);
		world.setBlock(i + 16, j + 20, k + 2, Blocks.end_stone, 0, 2);
		world.setBlock(i + 17, j + 20, k + 2, Blocks.end_stone, 0, 2);
		world.setBlock(i + 18, j + 20, k + 2, Blocks.end_stone, 0, 2);
		world.setBlock(i + 19, j + 20, k + 2, Blocks.obsidian, 0, 2);
		world.setBlock(i + 13, j + 20, k + 3, Blocks.obsidian, 0, 2);
		world.setBlock(i + 14, j + 20, k + 3, NovaCraftBlocks.frontierslate, 0, 2);
		world.setBlock(i + 15, j + 20, k + 3, NovaCraftBlocks.frontierslate, 0, 2);
		world.setBlock(i + 16, j + 20, k + 3, Blocks.end_stone, 0, 2);
		world.setBlock(i + 17, j + 20, k + 3, Blocks.end_stone, 0, 2);
		world.setBlock(i + 18, j + 20, k + 3, Blocks.end_stone, 0, 2);
		world.setBlock(i + 19, j + 20, k + 3, Blocks.obsidian, 0, 2);
		world.setBlock(i + 13, j + 20, k + 4, Blocks.obsidian, 0, 2);
		world.setBlock(i + 14, j + 20, k + 4, NovaCraftBlocks.frontierslate, 0, 2);
		world.setBlock(i + 17, j + 20, k + 4, NovaCraftBlocks.xancium_ore, 0, 2);
		world.setBlock(i + 18, j + 20, k + 4, Blocks.end_stone, 0, 2);
		world.setBlock(i + 19, j + 20, k + 4, Blocks.obsidian, 0, 2);
		world.setBlock(i + 13, j + 20, k + 5, Blocks.obsidian, 0, 2);
		world.setBlock(i + 18, j + 20, k + 5, Blocks.end_stone, 0, 2);
		world.setBlock(i + 19, j + 20, k + 5, Blocks.obsidian, 0, 2);
		world.setBlock(i + 14, j + 20, k + 6, Blocks.obsidian, 0, 2);
		world.setBlock(i + 17, j + 20, k + 6, Blocks.chest, 4, 2);
		world.setBlock(i + 18, j + 20, k + 6, Blocks.obsidian, 0, 2);
		world.setBlock(i + 15, j + 20, k + 7, Blocks.obsidian, 0, 2);
		world.setBlock(i + 17, j + 20, k + 7, Blocks.obsidian, 0, 2);
		world.setBlock(i + 15, j + 20, k + 8, Blocks.obsidian, 0, 2);
		world.setBlock(i + 17, j + 20, k + 8, Blocks.obsidian, 0, 2);
		world.setBlock(i + 14, j + 20, k + 9, NovaCraftBlocks.lacuna_stairs, 4, 2);
		world.setBlock(i + 15, j + 20, k + 9, Blocks.obsidian, 0, 2);
		world.setBlock(i + 17, j + 20, k + 9, Blocks.obsidian, 0, 2);
		world.setBlock(i + 18, j + 20, k + 9, NovaCraftBlocks.lacuna_stairs, 5, 2);
		world.setBlock(i + 15, j + 20, k + 10, Blocks.obsidian, 0, 2);
		world.setBlock(i + 17, j + 20, k + 10, Blocks.obsidian, 0, 2);
		world.setBlock(i + 15, j + 20, k + 11, Blocks.obsidian, 0, 2);
		world.setBlock(i + 17, j + 20, k + 11, Blocks.obsidian, 0, 2);
		world.setBlock(i + 15, j + 20, k + 12, OtherModBlocks.obsidian_special, 0, 2);
		world.setBlock(i + 16, j + 20, k + 12, Blocks.iron_bars, 0, 2);
		world.setBlock(i + 17, j + 20, k + 12, OtherModBlocks.obsidian_special, 0, 2);
		world.setBlock(i + 14, j + 20, k + 13, Blocks.obsidian, 0, 2);
		world.setBlock(i + 18, j + 20, k + 13, Blocks.obsidian, 0, 2);
		world.setBlock(i + 13, j + 20, k + 14, Blocks.obsidian, 0, 2);
		world.setBlock(i + 16, j + 20, k + 14, Blocks.cactus, 0, 2);
		world.setBlock(i + 19, j + 20, k + 14, Blocks.obsidian, 0, 2);
		world.setBlock(i + 12, j + 20, k + 15, Blocks.obsidian, 0, 2);
		world.setBlock(i + 13, j + 20, k + 15, Blocks.tallgrass, 1, 2);
		world.setBlock(i + 14, j + 20, k + 15, Blocks.tallgrass, 1, 2);
		world.setBlock(i + 20, j + 20, k + 15, Blocks.obsidian, 0, 2);
		world.setBlock(i + 11, j + 20, k + 16, Blocks.obsidian, 0, 2);
		world.setBlock(i + 13, j + 20, k + 16, Blocks.tallgrass, 1, 2);
		world.setBlock(i + 21, j + 20, k + 16, Blocks.obsidian, 0, 2);
		world.setBlock(i + 10, j + 20, k + 17, Blocks.obsidian, 0, 2);
		world.setBlock(i + 11, j + 20, k + 17, Blocks.log, 0, 2);
		world.setBlock(i + 12, j + 20, k + 17, Blocks.yellow_flower, 0, 2);
		world.setBlock(i + 22, j + 20, k + 17, Blocks.obsidian, 0, 2);
		world.setBlock(i + 10, j + 20, k + 18, Blocks.obsidian, 0, 2);
		world.setBlock(i + 12, j + 20, k + 18, Blocks.double_plant, 11, 2);
		world.setBlock(i + 22, j + 20, k + 18, Blocks.obsidian, 0, 2);
		world.setBlock(i + 10, j + 20, k + 19, Blocks.obsidian, 0, 2);
		world.setBlock(i + 22, j + 20, k + 19, Blocks.obsidian, 0, 2);
		world.setBlock(i + 11, j + 20, k + 20, Blocks.obsidian, 0, 2);
		world.setBlock(i + 21, j + 20, k + 20, Blocks.obsidian, 0, 2);
		world.setBlock(i + 12, j + 20, k + 21, Blocks.obsidian, 0, 2);
		world.setBlock(i + 20, j + 20, k + 21, Blocks.obsidian, 0, 2);
		world.setBlock(i + 13, j + 20, k + 22, Blocks.obsidian, 0, 2);
		world.setBlock(i + 19, j + 20, k + 22, Blocks.obsidian, 0, 2);
		world.setBlock(i + 14, j + 20, k + 23, Blocks.obsidian, 0, 2);
		world.setBlock(i + 18, j + 20, k + 23, Blocks.obsidian, 0, 2);
		world.setBlock(i + 15, j + 20, k + 24, OtherModBlocks.obsidian_special, 0, 2);
		world.setBlock(i + 16, j + 20, k + 24, Blocks.iron_bars, 0, 2);
		world.setBlock(i + 17, j + 20, k + 24, OtherModBlocks.obsidian_special, 0, 2);
		world.setBlock(i + 15, j + 20, k + 25, Blocks.obsidian, 0, 2);
		world.setBlock(i + 17, j + 20, k + 25, Blocks.obsidian, 0, 2);
		world.setBlock(i + 15, j + 20, k + 26, Blocks.obsidian, 0, 2);
		world.setBlock(i + 17, j + 20, k + 26, Blocks.obsidian, 0, 2);
		world.setBlock(i + 15, j + 20, k + 27, Blocks.obsidian, 0, 2);
		world.setBlock(i + 17, j + 20, k + 27, Blocks.obsidian, 0, 2);
		world.setBlock(i + 14, j + 20, k + 28, Blocks.obsidian, 0, 2);
		world.setBlock(i + 15, j + 20, k + 28, Blocks.chest, 5, 2);
		world.setBlock(i + 18, j + 20, k + 28, Blocks.obsidian, 0, 2);
		world.setBlock(i + 14, j + 20, k + 29, Blocks.obsidian, 0, 2);
		world.setBlock(i + 18, j + 20, k + 29, Blocks.obsidian, 0, 2);
		world.setBlock(i + 13, j + 20, k + 30, NovaCraftBlocks.lacuna_stairs, 4, 2);
		world.setBlock(i + 14, j + 20, k + 30, Blocks.obsidian, 0, 2);
		world.setBlock(i + 18, j + 20, k + 30, Blocks.obsidian, 0, 2);
		world.setBlock(i + 19, j + 20, k + 30, NovaCraftBlocks.lacuna_stairs, 5, 2);
		world.setBlock(i + 14, j + 20, k + 31, Blocks.obsidian, 0, 2);
		world.setBlock(i + 16, j + 20, k + 31, Blocks.cobblestone, 0, 2);
		world.setBlock(i + 17, j + 20, k + 31, Blocks.mossy_cobblestone, 0, 2);
		world.setBlock(i + 18, j + 20, k + 31, Blocks.obsidian, 0, 2);
		world.setBlock(i + 14, j + 20, k + 32, Blocks.obsidian, 0, 2);
		world.setBlock(i + 15, j + 20, k + 32, Blocks.mossy_cobblestone, 0, 2);
		world.setBlock(i + 16, j + 20, k + 32, Blocks.cobblestone, 0, 2);
		world.setBlock(i + 17, j + 20, k + 32, Blocks.cobblestone, 0, 2);
		world.setBlock(i + 18, j + 20, k + 32, Blocks.obsidian, 0, 2);
		world.setBlock(i + 15, j + 20, k + 33, Blocks.obsidian, 0, 2);
		world.setBlock(i + 16, j + 20, k + 33, Blocks.obsidian, 0, 2);
		world.setBlock(i + 17, j + 20, k + 33, Blocks.obsidian, 0, 2);
		world.setBlock(i + 14, j + 21, k + 1, Blocks.obsidian, 0, 2);
		world.setBlock(i + 15, j + 21, k + 1, Blocks.obsidian, 0, 2);
		world.setBlock(i + 16, j + 21, k + 1, Blocks.obsidian, 0, 2);
		world.setBlock(i + 17, j + 21, k + 1, Blocks.obsidian, 0, 2);
		world.setBlock(i + 18, j + 21, k + 1, Blocks.obsidian, 0, 2);
		world.setBlock(i + 13, j + 21, k + 2, Blocks.obsidian, 0, 2);
		world.setBlock(i + 14, j + 21, k + 2, NovaCraftBlocks.frontierslate, 0, 2);
		world.setBlock(i + 15, j + 21, k + 2, NovaCraftBlocks.frontierslate, 0, 2);
		world.setBlock(i + 16, j + 21, k + 2, NovaCraftBlocks.xancium_ore, 0, 2);
		world.setBlock(i + 17, j + 21, k + 2, NovaCraftBlocks.xancium_ore, 0, 2);
		world.setBlock(i + 18, j + 21, k + 2, Blocks.end_stone, 0, 2);
		world.setBlock(i + 19, j + 21, k + 2, Blocks.obsidian, 0, 2);
		world.setBlock(i + 13, j + 21, k + 3, Blocks.obsidian, 0, 2);
		world.setBlock(i + 14, j + 21, k + 3, NovaCraftBlocks.frontierslate_klangite_ore, 0, 2);
		world.setBlock(i + 17, j + 21, k + 3, NovaCraftBlocks.xancium_ore, 0, 2);
		world.setBlock(i + 18, j + 21, k + 3, Blocks.end_stone, 0, 2);
		world.setBlock(i + 19, j + 21, k + 3, Blocks.obsidian, 0, 2);
		world.setBlock(i + 13, j + 21, k + 4, Blocks.obsidian, 0, 2);
		world.setBlock(i + 18, j + 21, k + 4, NovaCraftBlocks.xancium_ore, 0, 2);
		world.setBlock(i + 19, j + 21, k + 4, Blocks.obsidian, 0, 2);
		world.setBlock(i + 13, j + 21, k + 5, Blocks.obsidian, 0, 2);
		world.setBlock(i + 19, j + 21, k + 5, Blocks.obsidian, 0, 2);
		world.setBlock(i + 14, j + 21, k + 6, Blocks.obsidian, 0, 2);
		world.setBlock(i + 18, j + 21, k + 6, Blocks.obsidian, 0, 2);
		world.setBlock(i + 15, j + 21, k + 7, Blocks.obsidian, 0, 2);
		world.setBlock(i + 17, j + 21, k + 7, Blocks.obsidian, 0, 2);
		world.setBlock(i + 15, j + 21, k + 8, Blocks.obsidian, 0, 2);
		world.setBlock(i + 17, j + 21, k + 8, Blocks.obsidian, 0, 2);
		world.setBlock(i + 15, j + 21, k + 9, Blocks.iron_bars, 0, 2);
		world.setBlock(i + 17, j + 21, k + 9, Blocks.iron_bars, 0, 2);
		world.setBlock(i + 15, j + 21, k + 10, Blocks.obsidian, 0, 2);
		world.setBlock(i + 17, j + 21, k + 10, Blocks.obsidian, 0, 2);
		world.setBlock(i + 15, j + 21, k + 11, Blocks.obsidian, 0, 2);
		world.setBlock(i + 17, j + 21, k + 11, Blocks.obsidian, 0, 2);
		world.setBlock(i + 15, j + 21, k + 12, OtherModBlocks.obsidian_special, 0, 2);
		world.setBlock(i + 16, j + 21, k + 12, Blocks.iron_bars, 0, 2);
		world.setBlock(i + 17, j + 21, k + 12, OtherModBlocks.obsidian_special, 0, 2);
		world.setBlock(i + 14, j + 21, k + 13, Blocks.obsidian, 0, 2);
		world.setBlock(i + 18, j + 21, k + 13, Blocks.obsidian, 0, 2);
		world.setBlock(i + 13, j + 21, k + 14, Blocks.obsidian, 0, 2);
		world.setBlock(i + 16, j + 21, k + 14, Blocks.cactus, 0, 2);
		world.setBlock(i + 19, j + 21, k + 14, Blocks.obsidian, 0, 2);
		world.setBlock(i + 12, j + 21, k + 15, Blocks.obsidian, 0, 2);
		world.setBlock(i + 20, j + 21, k + 15, Blocks.obsidian, 0, 2);
		world.setBlock(i + 11, j + 21, k + 16, Blocks.obsidian, 0, 2);
		world.setBlock(i + 21, j + 21, k + 16, Blocks.obsidian, 0, 2);
		world.setBlock(i + 10, j + 21, k + 17, Blocks.obsidian, 0, 2);
		world.setBlock(i + 11, j + 21, k + 17, Blocks.log, 0, 2);
		world.setBlock(i + 22, j + 21, k + 17, Blocks.obsidian, 0, 2);
		world.setBlock(i + 10, j + 21, k + 18, Blocks.obsidian, 0, 2);
		world.setBlock(i + 22, j + 21, k + 18, Blocks.obsidian, 0, 2);
		world.setBlock(i + 10, j + 21, k + 19, Blocks.obsidian, 0, 2);
		world.setBlock(i + 22, j + 21, k + 19, Blocks.obsidian, 0, 2);
		world.setBlock(i + 11, j + 21, k + 20, Blocks.obsidian, 0, 2);
		world.setBlock(i + 21, j + 21, k + 20, Blocks.obsidian, 0, 2);
		world.setBlock(i + 12, j + 21, k + 21, Blocks.obsidian, 0, 2);
		world.setBlock(i + 20, j + 21, k + 21, Blocks.obsidian, 0, 2);
		world.setBlock(i + 13, j + 21, k + 22, Blocks.obsidian, 0, 2);
		world.setBlock(i + 19, j + 21, k + 22, Blocks.obsidian, 0, 2);
		world.setBlock(i + 14, j + 21, k + 23, Blocks.obsidian, 0, 2);
		world.setBlock(i + 18, j + 21, k + 23, Blocks.obsidian, 0, 2);
		world.setBlock(i + 15, j + 21, k + 24, OtherModBlocks.obsidian_special, 0, 2);
		world.setBlock(i + 16, j + 21, k + 24, Blocks.iron_bars, 0, 2);
		world.setBlock(i + 17, j + 21, k + 24, OtherModBlocks.obsidian_special, 0, 2);
		world.setBlock(i + 15, j + 21, k + 25, Blocks.obsidian, 0, 2);
		world.setBlock(i + 17, j + 21, k + 25, Blocks.obsidian, 0, 2);
		world.setBlock(i + 15, j + 21, k + 26, Blocks.obsidian, 0, 2);
		world.setBlock(i + 17, j + 21, k + 26, Blocks.obsidian, 0, 2);
		world.setBlock(i + 15, j + 21, k + 27, Blocks.obsidian, 0, 2);
		world.setBlock(i + 17, j + 21, k + 27, Blocks.obsidian, 0, 2);
		world.setBlock(i + 14, j + 21, k + 28, Blocks.obsidian, 0, 2);
		world.setBlock(i + 18, j + 21, k + 28, Blocks.obsidian, 0, 2);
		world.setBlock(i + 14, j + 21, k + 29, Blocks.obsidian, 0, 2);
		world.setBlock(i + 18, j + 21, k + 29, Blocks.obsidian, 0, 2);
		world.setBlock(i + 14, j + 21, k + 30, Blocks.iron_bars, 0, 2);
		world.setBlock(i + 18, j + 21, k + 30, Blocks.iron_bars, 0, 2);
		world.setBlock(i + 14, j + 21, k + 31, Blocks.obsidian, 0, 2);
		world.setBlock(i + 18, j + 21, k + 31, Blocks.obsidian, 0, 2);
		world.setBlock(i + 14, j + 21, k + 32, Blocks.obsidian, 0, 2);
		world.setBlock(i + 16, j + 21, k + 32, Blocks.mob_spawner, 0, 2);
		world.setBlock(i + 17, j + 21, k + 32, Blocks.mossy_cobblestone, 0, 2);
		world.setBlock(i + 18, j + 21, k + 32, Blocks.obsidian, 0, 2);
		world.setBlock(i + 15, j + 21, k + 33, Blocks.obsidian, 0, 2);
		world.setBlock(i + 16, j + 21, k + 33, Blocks.obsidian, 0, 2);
		world.setBlock(i + 17, j + 21, k + 33, Blocks.obsidian, 0, 2);
		world.setBlock(i + 14, j + 22, k + 1, Blocks.obsidian, 0, 2);
		world.setBlock(i + 15, j + 22, k + 1, Blocks.obsidian, 0, 2);
		world.setBlock(i + 16, j + 22, k + 1, Blocks.obsidian, 0, 2);
		world.setBlock(i + 17, j + 22, k + 1, Blocks.obsidian, 0, 2);
		world.setBlock(i + 18, j + 22, k + 1, Blocks.obsidian, 0, 2);
		world.setBlock(i + 13, j + 22, k + 2, Blocks.obsidian, 0, 2);
		world.setBlock(i + 14, j + 22, k + 2, NovaCraftBlocks.frontierslate, 0, 2);
		world.setBlock(i + 17, j + 22, k + 2, NovaCraftBlocks.xancium_ore, 0, 2);
		world.setBlock(i + 18, j + 22, k + 2, Blocks.end_stone, 0, 2);
		world.setBlock(i + 19, j + 22, k + 2, Blocks.obsidian, 0, 2);
		world.setBlock(i + 13, j + 22, k + 3, Blocks.obsidian, 0, 2);
		world.setBlock(i + 18, j + 22, k + 3, NovaCraftBlocks.xancium_ore, 0, 2);
		world.setBlock(i + 19, j + 22, k + 3, Blocks.obsidian, 0, 2);
		world.setBlock(i + 13, j + 22, k + 4, Blocks.obsidian, 0, 2);
		world.setBlock(i + 16, j + 22, k + 4, OtherModBlocks.end_rod, 0, 2);
		world.setBlock(i + 19, j + 22, k + 4, Blocks.obsidian, 0, 2);
		world.setBlock(i + 13, j + 22, k + 5, Blocks.obsidian, 0, 2);
		world.setBlock(i + 19, j + 22, k + 5, Blocks.obsidian, 0, 2);
		world.setBlock(i + 14, j + 22, k + 6, Blocks.obsidian, 0, 2);
		world.setBlock(i + 18, j + 22, k + 6, Blocks.obsidian, 0, 2);
		world.setBlock(i + 15, j + 22, k + 7, Blocks.obsidian, 0, 2);
		world.setBlock(i + 17, j + 22, k + 7, Blocks.obsidian, 0, 2);
		world.setBlock(i + 15, j + 22, k + 8, Blocks.obsidian, 0, 2);
		world.setBlock(i + 17, j + 22, k + 8, Blocks.obsidian, 0, 2);
		world.setBlock(i + 15, j + 22, k + 9, Blocks.obsidian, 0, 2);
		world.setBlock(i + 17, j + 22, k + 9, Blocks.obsidian, 0, 2);
		world.setBlock(i + 15, j + 22, k + 10, Blocks.obsidian, 0, 2);
		world.setBlock(i + 17, j + 22, k + 10, Blocks.obsidian, 0, 2);
		world.setBlock(i + 15, j + 22, k + 11, Blocks.obsidian, 0, 2);
		world.setBlock(i + 17, j + 22, k + 11, Blocks.obsidian, 0, 2);
		world.setBlock(i + 15, j + 22, k + 12, OtherModBlocks.obsidian_special, 0, 2);
		world.setBlock(i + 16, j + 22, k + 12, Blocks.iron_bars, 0, 2);
		world.setBlock(i + 17, j + 22, k + 12, OtherModBlocks.obsidian_special, 0, 2);
		world.setBlock(i + 14, j + 22, k + 13, Blocks.obsidian, 0, 2);
		world.setBlock(i + 18, j + 22, k + 13, Blocks.obsidian, 0, 2);
		world.setBlock(i + 13, j + 22, k + 14, Blocks.obsidian, 0, 2);
		world.setBlock(i + 16, j + 22, k + 14, Blocks.cactus, 0, 2);
		world.setBlock(i + 19, j + 22, k + 14, Blocks.obsidian, 0, 2);
		world.setBlock(i + 12, j + 22, k + 15, Blocks.obsidian, 0, 2);
		world.setBlock(i + 20, j + 22, k + 15, Blocks.obsidian, 0, 2);
		world.setBlock(i + 11, j + 22, k + 16, Blocks.obsidian, 0, 2);
		world.setBlock(i + 12, j + 22, k + 16, Blocks.leaves, 0, 2);
		world.setBlock(i + 21, j + 22, k + 16, Blocks.obsidian, 0, 2);
		world.setBlock(i + 10, j + 22, k + 17, Blocks.obsidian, 0, 2);
		world.setBlock(i + 11, j + 22, k + 17, Blocks.log, 0, 2);
		world.setBlock(i + 12, j + 22, k + 17, Blocks.leaves, 0, 2);
		world.setBlock(i + 22, j + 22, k + 17, Blocks.obsidian, 0, 2);
		world.setBlock(i + 10, j + 22, k + 18, Blocks.obsidian, 0, 2);
		world.setBlock(i + 11, j + 22, k + 18, Blocks.leaves, 0, 2);
		world.setBlock(i + 12, j + 22, k + 18, Blocks.leaves, 0, 2);
		world.setBlock(i + 22, j + 22, k + 18, Blocks.obsidian, 0, 2);
		world.setBlock(i + 10, j + 22, k + 19, Blocks.obsidian, 0, 2);
		world.setBlock(i + 22, j + 22, k + 19, Blocks.obsidian, 0, 2);
		world.setBlock(i + 11, j + 22, k + 20, Blocks.obsidian, 0, 2);
		world.setBlock(i + 21, j + 22, k + 20, Blocks.obsidian, 0, 2);
		world.setBlock(i + 12, j + 22, k + 21, Blocks.obsidian, 0, 2);
		world.setBlock(i + 20, j + 22, k + 21, Blocks.obsidian, 0, 2);
		world.setBlock(i + 13, j + 22, k + 22, Blocks.obsidian, 0, 2);
		world.setBlock(i + 19, j + 22, k + 22, Blocks.obsidian, 0, 2);
		world.setBlock(i + 14, j + 22, k + 23, Blocks.obsidian, 0, 2);
		world.setBlock(i + 18, j + 22, k + 23, Blocks.obsidian, 0, 2);
		world.setBlock(i + 15, j + 22, k + 24, OtherModBlocks.obsidian_special, 0, 2);
