package com.NovaCraft.world.end.endcamp;

import net.minecraft.world.gen.feature.*;
import net.minecraft.block.*;
import net.minecraft.world.*;
import java.util.*;

import com.NovaCraft.registry.OtherModBlocks;
import com.NovaCraftBlocks.NovaCraftBlocks;

import net.minecraft.init.*;

public class EnderCampCenterGen extends WorldGenerator
{
	public EnderCampCenterGen() {

	}
    
    public boolean generate(final World world, final Random random, final int i, final int j, final int k) {	
    		
			world.setBlock(i + 10, j + 0, k + 5, Blocks.end_stone, 0, 2);			
			world.setBlock(i + 9, j + 0, k + 6, Blocks.end_stone, 0, 2);
			world.setBlock(i + 10, j + 0, k + 6, Blocks.end_stone, 0, 2);
			world.setBlock(i + 11, j + 0, k + 6, Blocks.end_stone, 0, 2);			
			world.setBlock(i + 8, j + 0, k + 7, Blocks.end_stone, 0, 2);		
			world.setBlock(i + 10, j + 0, k + 7, Blocks.end_stone, 0, 2);
			world.setBlock(i + 12, j + 0, k + 7, Blocks.end_stone, 0, 2);			
			world.setBlock(i + 7, j + 0, k + 8, Blocks.end_stone, 0, 2);
			world.setBlock(i + 10, j + 0, k + 8, Blocks.end_stone, 0, 2);
			world.setBlock(i + 13, j + 0, k + 8, Blocks.end_stone, 0, 2);
			world.setBlock(i + 6, j + 0, k + 9, Blocks.end_stone, 0, 2);
			world.setBlock(i + 10, j + 0, k + 9, Blocks.end_stone, 0, 2);
			world.setBlock(i + 14, j + 0, k + 9, Blocks.end_stone, 0, 2);
			world.setBlock(i + 5, j + 0, k + 10, Blocks.end_stone, 0, 2);
			world.setBlock(i + 6, j + 0, k + 10, Blocks.end_stone, 0, 2);
			world.setBlock(i + 7, j + 0, k + 10, Blocks.end_stone, 0, 2);
			world.setBlock(i + 8, j + 0, k + 10, Blocks.end_stone, 0, 2);
			world.setBlock(i + 9, j + 0, k + 10, Blocks.end_stone, 0, 2);
			world.setBlock(i + 10, j + 0, k + 10, Blocks.end_stone, 0, 2);
			world.setBlock(i + 11, j + 0, k + 10, Blocks.end_stone, 0, 2);
			world.setBlock(i + 12, j + 0, k + 10, Blocks.end_stone, 0, 2);
			world.setBlock(i + 13, j + 0, k + 10, Blocks.end_stone, 0, 2);
			world.setBlock(i + 14, j + 0, k + 10, Blocks.end_stone, 0, 2);
			world.setBlock(i + 15, j + 0, k + 10, Blocks.end_stone, 0, 2);
			world.setBlock(i + 6, j + 0, k + 11, Blocks.end_stone, 0, 2);
			world.setBlock(i + 10, j + 0, k + 11, Blocks.end_stone, 0, 2);
			world.setBlock(i + 14, j + 0, k + 11, Blocks.end_stone, 0, 2);
			world.setBlock(i + 7, j + 0, k + 12, Blocks.end_stone, 0, 2);
			world.setBlock(i + 10, j + 0, k + 12, Blocks.end_stone, 0, 2);
			world.setBlock(i + 13, j + 0, k + 12, Blocks.end_stone, 0, 2);
			world.setBlock(i + 8, j + 0, k + 13, Blocks.end_stone, 0, 2);
			world.setBlock(i + 10, j + 0, k + 13, Blocks.end_stone, 0, 2);
			world.setBlock(i + 12, j + 0, k + 13, Blocks.end_stone, 0, 2);
			world.setBlock(i + 9, j + 0, k + 14, Blocks.end_stone, 0, 2);
			world.setBlock(i + 10, j + 0, k + 14, Blocks.end_stone, 0, 2);
			world.setBlock(i + 11, j + 0, k + 14, Blocks.end_stone, 0, 2);
			world.setBlock(i + 10, j + 0, k + 15, Blocks.end_stone, 0, 2);
			world.setBlock(i + 10, j + 1, k + 3, Blocks.end_stone, 0, 2);
			world.setBlock(i + 9, j + 1, k + 4, Blocks.end_stone, 0, 2);
			world.setBlock(i + 10, j + 1, k + 4, Blocks.end_stone, 0, 2);
			world.setBlock(i + 11, j + 1, k + 4, Blocks.end_stone, 0, 2);
			world.setBlock(i + 8, j + 1, k + 5, Blocks.end_stone, 0, 2);
			world.setBlock(i + 9, j + 1, k + 5, Blocks.end_stone, 0, 2);
			world.setBlock(i + 10, j + 1, k + 5, Blocks.end_stone, 0, 2);
			world.setBlock(i + 11, j + 1, k + 5, Blocks.end_stone, 0, 2);
			world.setBlock(i + 12, j + 1, k + 5, Blocks.end_stone, 0, 2);
			world.setBlock(i + 7, j + 1, k + 6, Blocks.end_stone, 0, 2);
			world.setBlock(i + 8, j + 1, k + 6, Blocks.end_stone, 0, 2);
			world.setBlock(i + 9, j + 1, k + 6, Blocks.end_stone, 0, 2);
			world.setBlock(i + 10, j + 1, k + 6, Blocks.end_stone, 0, 2);
			world.setBlock(i + 11, j + 1, k + 6, Blocks.end_stone, 0, 2);
			world.setBlock(i + 12, j + 1, k + 6, Blocks.end_stone, 0, 2);
			world.setBlock(i + 13, j + 1, k + 6, Blocks.end_stone, 0, 2);
			world.setBlock(i + 6, j + 1, k + 7, Blocks.end_stone, 0, 2);
			world.setBlock(i + 7, j + 1, k + 7, Blocks.end_stone, 0, 2);
			world.setBlock(i + 8, j + 1, k + 7, Blocks.end_stone, 0, 2);
			world.setBlock(i + 9, j + 1, k + 7, Blocks.end_stone, 0, 2);
			world.setBlock(i + 10, j + 1, k + 7, Blocks.end_stone, 0, 2);
			world.setBlock(i + 11, j + 1, k + 7, Blocks.end_stone, 0, 2);
			world.setBlock(i + 12, j + 1, k + 7, Blocks.end_stone, 0, 2);
			world.setBlock(i + 13, j + 1, k + 7, Blocks.end_stone, 0, 2);
			world.setBlock(i + 14, j + 1, k + 7, Blocks.end_stone, 0, 2);
			world.setBlock(i + 5, j + 1, k + 8, Blocks.end_stone, 0, 2);
			world.setBlock(i + 6, j + 1, k + 8, Blocks.end_stone, 0, 2);
			world.setBlock(i + 7, j + 1, k + 8, Blocks.end_stone, 0, 2);
			world.setBlock(i + 8, j + 1, k + 8, Blocks.end_stone, 0, 2);
			world.setBlock(i + 9, j + 1, k + 8, Blocks.end_stone, 0, 2);
			world.setBlock(i + 10, j + 1, k + 8, Blocks.end_stone, 0, 2);
			world.setBlock(i + 11, j + 1, k + 8, Blocks.end_stone, 0, 2);
			world.setBlock(i + 12, j + 1, k + 8, Blocks.end_stone, 0, 2);
			world.setBlock(i + 13, j + 1, k + 8, Blocks.end_stone, 0, 2);
			world.setBlock(i + 14, j + 1, k + 8, Blocks.end_stone, 0, 2);
			world.setBlock(i + 15, j + 1, k + 8, Blocks.end_stone, 0, 2);
			world.setBlock(i + 4, j + 1, k + 9, Blocks.end_stone, 0, 2);
			world.setBlock(i + 5, j + 1, k + 9, Blocks.end_stone, 0, 2);
			world.setBlock(i + 6, j + 1, k + 9, Blocks.end_stone, 0, 2);
			world.setBlock(i + 7, j + 1, k + 9, Blocks.end_stone, 0, 2);
			world.setBlock(i + 8, j + 1, k + 9, Blocks.end_stone, 0, 2);
			world.setBlock(i + 9, j + 1, k + 9, Blocks.end_stone, 0, 2);
			world.setBlock(i + 10, j + 1, k + 9, Blocks.end_stone, 0, 2);
			world.setBlock(i + 11, j + 1, k + 9, Blocks.end_stone, 0, 2);
			world.setBlock(i + 12, j + 1, k + 9, Blocks.end_stone, 0, 2);
			world.setBlock(i + 13, j + 1, k + 9, Blocks.end_stone, 0, 2);
			world.setBlock(i + 14, j + 1, k + 9, Blocks.end_stone, 0, 2);
			world.setBlock(i + 15, j + 1, k + 9, Blocks.end_stone, 0, 2);
			world.setBlock(i + 16, j + 1, k + 9, Blocks.end_stone, 0, 2);
			world.setBlock(i + 3, j + 1, k + 10, Blocks.end_stone, 0, 2);
			world.setBlock(i + 4, j + 1, k + 10, Blocks.end_stone, 0, 2);
			world.setBlock(i + 5, j + 1, k + 10, Blocks.end_stone, 0, 2);
			world.setBlock(i + 6, j + 1, k + 10, Blocks.end_stone, 0, 2);
			world.setBlock(i + 7, j + 1, k + 10, Blocks.end_stone, 0, 2);
			world.setBlock(i + 8, j + 1, k + 10, Blocks.end_stone, 0, 2);
			world.setBlock(i + 9, j + 1, k + 10, Blocks.end_stone, 0, 2);
			world.setBlock(i + 10, j + 1, k + 10, Blocks.end_stone, 0, 2);
			world.setBlock(i + 11, j + 1, k + 10, Blocks.end_stone, 0, 2);
			world.setBlock(i + 12, j + 1, k + 10, Blocks.end_stone, 0, 2);
			world.setBlock(i + 13, j + 1, k + 10, Blocks.end_stone, 0, 2);
			world.setBlock(i + 14, j + 1, k + 10, Blocks.end_stone, 0, 2);
			world.setBlock(i + 15, j + 1, k + 10, Blocks.end_stone, 0, 2);
			world.setBlock(i + 16, j + 1, k + 10, Blocks.end_stone, 0, 2);
			world.setBlock(i + 17, j + 1, k + 10, Blocks.end_stone, 0, 2);
			world.setBlock(i + 4, j + 1, k + 11, Blocks.end_stone, 0, 2);
			world.setBlock(i + 5, j + 1, k + 11, Blocks.end_stone, 0, 2);
			world.setBlock(i + 6, j + 1, k + 11, Blocks.end_stone, 0, 2);
			world.setBlock(i + 7, j + 1, k + 11, Blocks.end_stone, 0, 2);
			world.setBlock(i + 8, j + 1, k + 11, Blocks.end_stone, 0, 2);
			world.setBlock(i + 9, j + 1, k + 11, Blocks.end_stone, 0, 2);
			world.setBlock(i + 10, j + 1, k + 11, Blocks.end_stone, 0, 2);
			world.setBlock(i + 11, j + 1, k + 11, Blocks.end_stone, 0, 2);
			world.setBlock(i + 12, j + 1, k + 11, Blocks.end_stone, 0, 2);
			world.setBlock(i + 13, j + 1, k + 11, Blocks.end_stone, 0, 2);
			world.setBlock(i + 14, j + 1, k + 11, Blocks.end_stone, 0, 2);
			world.setBlock(i + 15, j + 1, k + 11, Blocks.end_stone, 0, 2);
			world.setBlock(i + 16, j + 1, k + 11, Blocks.end_stone, 0, 2);
			world.setBlock(i + 5, j + 1, k + 12, Blocks.end_stone, 0, 2);
			world.setBlock(i + 6, j + 1, k + 12, Blocks.end_stone, 0, 2);
			world.setBlock(i + 7, j + 1, k + 12, Blocks.end_stone, 0, 2);
			world.setBlock(i + 8, j + 1, k + 12, Blocks.end_stone, 0, 2);
			world.setBlock(i + 9, j + 1, k + 12, Blocks.end_stone, 0, 2);
			world.setBlock(i + 10, j + 1, k + 12, Blocks.end_stone, 0, 2);
			world.setBlock(i + 11, j + 1, k + 12, Blocks.end_stone, 0, 2);
			world.setBlock(i + 12, j + 1, k + 12, Blocks.end_stone, 0, 2);
			world.setBlock(i + 13, j + 1, k + 12, Blocks.end_stone, 0, 2);
			world.setBlock(i + 14, j + 1, k + 12, Blocks.end_stone, 0, 2);
			world.setBlock(i + 15, j + 1, k + 12, Blocks.end_stone, 0, 2);
			world.setBlock(i + 6, j + 1, k + 13, Blocks.end_stone, 0, 2);
			world.setBlock(i + 7, j + 1, k + 13, Blocks.end_stone, 0, 2);
			world.setBlock(i + 8, j + 1, k + 13, Blocks.end_stone, 0, 2);
			world.setBlock(i + 9, j + 1, k + 13, Blocks.end_stone, 0, 2);
			world.setBlock(i + 10, j + 1, k + 13, Blocks.end_stone, 0, 2);
			world.setBlock(i + 11, j + 1, k + 13, Blocks.end_stone, 0, 2);
			world.setBlock(i + 12, j + 1, k + 13, Blocks.end_stone, 0, 2);
			world.setBlock(i + 13, j + 1, k + 13, Blocks.end_stone, 0, 2);
			world.setBlock(i + 14, j + 1, k + 13, Blocks.end_stone, 0, 2);
			world.setBlock(i + 7, j + 1, k + 14, Blocks.end_stone, 0, 2);
			world.setBlock(i + 8, j + 1, k + 14, Blocks.end_stone, 0, 2);
			world.setBlock(i + 9, j + 1, k + 14, Blocks.end_stone, 0, 2);
			world.setBlock(i + 10, j + 1, k + 14, Blocks.end_stone, 0, 2);
			world.setBlock(i + 11, j + 1, k + 14, Blocks.end_stone, 0, 2);
			world.setBlock(i + 12, j + 1, k + 14, Blocks.end_stone, 0, 2);
			world.setBlock(i + 13, j + 1, k + 14, Blocks.end_stone, 0, 2);
			world.setBlock(i + 8, j + 1, k + 15, Blocks.end_stone, 0, 2);
			world.setBlock(i + 9, j + 1, k + 15, Blocks.end_stone, 0, 2);
			world.setBlock(i + 10, j + 1, k + 15, Blocks.end_stone, 0, 2);
			world.setBlock(i + 11, j + 1, k + 15, Blocks.end_stone, 0, 2);
			world.setBlock(i + 12, j + 1, k + 15, Blocks.end_stone, 0, 2);
			world.setBlock(i + 9, j + 1, k + 16, Blocks.end_stone, 0, 2);
			world.setBlock(i + 10, j + 1, k + 16, Blocks.end_stone, 0, 2);
			world.setBlock(i + 11, j + 1, k + 16, Blocks.end_stone, 0, 2);
			world.setBlock(i + 10, j + 1, k + 17, Blocks.end_stone, 0, 2);
			world.setBlock(i + 10, j + 2, k + 1, Blocks.end_stone, 0, 2);
			world.setBlock(i + 9, j + 2, k + 2, Blocks.end_stone, 0, 2);
			world.setBlock(i + 10, j + 2, k + 2, Blocks.end_stone, 0, 2);
			world.setBlock(i + 11, j + 2, k + 2, Blocks.end_stone, 0, 2);
			world.setBlock(i + 8, j + 2, k + 3, Blocks.end_stone, 0, 2);
			world.setBlock(i + 9, j + 2, k + 3, Blocks.end_stone, 0, 2);
			world.setBlock(i + 10, j + 2, k + 3, Blocks.end_stone, 0, 2);
			world.setBlock(i + 11, j + 2, k + 3, Blocks.end_stone, 0, 2);
			world.setBlock(i + 12, j + 2, k + 3, Blocks.end_stone, 0, 2);
			world.setBlock(i + 7, j + 2, k + 4, Blocks.end_stone, 0, 2);
			world.setBlock(i + 8, j + 2, k + 4, Blocks.end_stone, 0, 2);
			world.setBlock(i + 9, j + 2, k + 4, Blocks.end_stone, 0, 2);
			world.setBlock(i + 10, j + 2, k + 4, Blocks.end_stone, 0, 2);
			world.setBlock(i + 11, j + 2, k + 4, Blocks.end_stone, 0, 2);
			world.setBlock(i + 12, j + 2, k + 4, Blocks.end_stone, 0, 2);
			world.setBlock(i + 13, j + 2, k + 4, Blocks.end_stone, 0, 2);
			world.setBlock(i + 6, j + 2, k + 5, Blocks.end_stone, 0, 2);
			world.setBlock(i + 7, j + 2, k + 5, Blocks.end_stone, 0, 2);
			world.setBlock(i + 8, j + 2, k + 5, Blocks.end_stone, 0, 2);
			world.setBlock(i + 9, j + 2, k + 5, Blocks.end_stone, 0, 2);
			world.setBlock(i + 10, j + 2, k + 5, Blocks.end_stone, 0, 2);
			world.setBlock(i + 11, j + 2, k + 5, Blocks.end_stone, 0, 2);
			world.setBlock(i + 12, j + 2, k + 5, Blocks.end_stone, 0, 2);
			world.setBlock(i + 13, j + 2, k + 5, Blocks.end_stone, 0, 2);
			world.setBlock(i + 14, j + 2, k + 5, Blocks.end_stone, 0, 2);
			world.setBlock(i + 5, j + 2, k + 6, Blocks.end_stone, 0, 2);
			world.setBlock(i + 6, j + 2, k + 6, Blocks.end_stone, 0, 2);
			world.setBlock(i + 7, j + 2, k + 6, Blocks.end_stone, 0, 2);
			world.setBlock(i + 8, j + 2, k + 6, Blocks.end_stone, 0, 2);
			world.setBlock(i + 9, j + 2, k + 6, Blocks.end_stone, 0, 2);
			world.setBlock(i + 10, j + 2, k + 6, Blocks.end_stone, 0, 2);
			world.setBlock(i + 11, j + 2, k + 6, Blocks.end_stone, 0, 2);
			world.setBlock(i + 12, j + 2, k + 6, Blocks.end_stone, 0, 2);
			world.setBlock(i + 13, j + 2, k + 6, Blocks.end_stone, 0, 2);
			world.setBlock(i + 14, j + 2, k + 6, Blocks.end_stone, 0, 2);
			world.setBlock(i + 15, j + 2, k + 6, Blocks.end_stone, 0, 2);
			world.setBlock(i + 4, j + 2, k + 7, Blocks.end_stone, 0, 2);
			world.setBlock(i + 5, j + 2, k + 7, Blocks.end_stone, 0, 2);
			world.setBlock(i + 6, j + 2, k + 7, Blocks.end_stone, 0, 2);
			world.setBlock(i + 7, j + 2, k + 7, Blocks.end_stone, 0, 2);
			world.setBlock(i + 8, j + 2, k + 7, Blocks.end_stone, 0, 2);
			world.setBlock(i + 9, j + 2, k + 7, Blocks.end_stone, 0, 2);
			world.setBlock(i + 10, j + 2, k + 7, Blocks.end_stone, 0, 2);
			world.setBlock(i + 11, j + 2, k + 7, Blocks.end_stone, 0, 2);
			world.setBlock(i + 12, j + 2, k + 7, Blocks.end_stone, 0, 2);
			world.setBlock(i + 13, j + 2, k + 7, Blocks.end_stone, 0, 2);
			world.setBlock(i + 14, j + 2, k + 7, Blocks.end_stone, 0, 2);
			world.setBlock(i + 15, j + 2, k + 7, Blocks.end_stone, 0, 2);
			world.setBlock(i + 16, j + 2, k + 7, Blocks.end_stone, 0, 2);
			world.setBlock(i + 3, j + 2, k + 8, Blocks.end_stone, 0, 2);
			world.setBlock(i + 4, j + 2, k + 8, Blocks.end_stone, 0, 2);
			world.setBlock(i + 5, j + 2, k + 8, Blocks.end_stone, 0, 2);
			world.setBlock(i + 6, j + 2, k + 8, Blocks.end_stone, 0, 2);
			world.setBlock(i + 7, j + 2, k + 8, Blocks.end_stone, 0, 2);
			world.setBlock(i + 8, j + 2, k + 8, Blocks.end_stone, 0, 2);
			world.setBlock(i + 9, j + 2, k + 8, Blocks.end_stone, 0, 2);
			world.setBlock(i + 10, j + 2, k + 8, Blocks.end_stone, 0, 2);
			world.setBlock(i + 11, j + 2, k + 8, Blocks.end_stone, 0, 2);
			world.setBlock(i + 12, j + 2, k + 8, Blocks.end_stone, 0, 2);
			world.setBlock(i + 13, j + 2, k + 8, Blocks.end_stone, 0, 2);
			world.setBlock(i + 14, j + 2, k + 8, Blocks.end_stone, 0, 2);
			world.setBlock(i + 15, j + 2, k + 8, Blocks.end_stone, 0, 2);
			world.setBlock(i + 16, j + 2, k + 8, Blocks.end_stone, 0, 2);
			world.setBlock(i + 17, j + 2, k + 8, Blocks.end_stone, 0, 2);
			world.setBlock(i + 2, j + 2, k + 9, Blocks.end_stone, 0, 2);
			world.setBlock(i + 3, j + 2, k + 9, Blocks.end_stone, 0, 2);
			world.setBlock(i + 4, j + 2, k + 9, Blocks.end_stone, 0, 2);
			world.setBlock(i + 5, j + 2, k + 9, Blocks.end_stone, 0, 2);
			world.setBlock(i + 6, j + 2, k + 9, Blocks.end_stone, 0, 2);
			world.setBlock(i + 7, j + 2, k + 9, Blocks.end_stone, 0, 2);
			world.setBlock(i + 8, j + 2, k + 9, Blocks.end_stone, 0, 2);
			world.setBlock(i + 9, j + 2, k + 9, Blocks.end_stone, 0, 2);
			world.setBlock(i + 10, j + 2, k + 9, Blocks.end_stone, 0, 2);
			world.setBlock(i + 11, j + 2, k + 9, Blocks.end_stone, 0, 2);
			world.setBlock(i + 12, j + 2, k + 9, Blocks.end_stone, 0, 2);
			world.setBlock(i + 13, j + 2, k + 9, Blocks.end_stone, 0, 2);
			world.setBlock(i + 14, j + 2, k + 9, Blocks.end_stone, 0, 2);
			world.setBlock(i + 15, j + 2, k + 9, Blocks.end_stone, 0, 2);
			world.setBlock(i + 16, j + 2, k + 9, Blocks.end_stone, 0, 2);
			world.setBlock(i + 17, j + 2, k + 9, Blocks.end_stone, 0, 2);
			world.setBlock(i + 18, j + 2, k + 9, Blocks.end_stone, 0, 2);
			world.setBlock(i + 1, j + 2, k + 10, Blocks.end_stone, 0, 2);
			world.setBlock(i + 2, j + 2, k + 10, Blocks.end_stone, 0, 2);
			world.setBlock(i + 3, j + 2, k + 10, Blocks.end_stone, 0, 2);
			world.setBlock(i + 4, j + 2, k + 10, Blocks.end_stone, 0, 2);
			world.setBlock(i + 5, j + 2, k + 10, Blocks.end_stone, 0, 2);
			world.setBlock(i + 6, j + 2, k + 10, Blocks.end_stone, 0, 2);
			world.setBlock(i + 7, j + 2, k + 10, Blocks.end_stone, 0, 2);
			world.setBlock(i + 8, j + 2, k + 10, Blocks.end_stone, 0, 2);
			world.setBlock(i + 9, j + 2, k + 10, Blocks.end_stone, 0, 2);
			world.setBlock(i + 10, j + 2, k + 10, Blocks.end_stone, 0, 2);
			world.setBlock(i + 11, j + 2, k + 10, Blocks.end_stone, 0, 2);
			world.setBlock(i + 12, j + 2, k + 10, Blocks.end_stone, 0, 2);
			world.setBlock(i + 13, j + 2, k + 10, Blocks.end_stone, 0, 2);
			world.setBlock(i + 14, j + 2, k + 10, Blocks.end_stone, 0, 2);
			world.setBlock(i + 15, j + 2, k + 10, Blocks.end_stone, 0, 2);
			world.setBlock(i + 16, j + 2, k + 10, Blocks.end_stone, 0, 2);
			world.setBlock(i + 17, j + 2, k + 10, Blocks.end_stone, 0, 2);
			world.setBlock(i + 18, j + 2, k + 10, Blocks.end_stone, 0, 2);
			world.setBlock(i + 19, j + 2, k + 10, Blocks.end_stone, 0, 2);
			world.setBlock(i + 2, j + 2, k + 11, Blocks.end_stone, 0, 2);
			world.setBlock(i + 3, j + 2, k + 11, Blocks.end_stone, 0, 2);
			world.setBlock(i + 4, j + 2, k + 11, Blocks.end_stone, 0, 2);
			world.setBlock(i + 5, j + 2, k + 11, Blocks.end_stone, 0, 2);
			world.setBlock(i + 6, j + 2, k + 11, Blocks.end_stone, 0, 2);
			world.setBlock(i + 7, j + 2, k + 11, Blocks.end_stone, 0, 2);
			world.setBlock(i + 8, j + 2, k + 11, Blocks.end_stone, 0, 2);
			world.setBlock(i + 9, j + 2, k + 11, Blocks.end_stone, 0, 2);
			world.setBlock(i + 10, j + 2, k + 11, Blocks.end_stone, 0, 2);
			world.setBlock(i + 11, j + 2, k + 11, Blocks.end_stone, 0, 2);
			world.setBlock(i + 12, j + 2, k + 11, Blocks.end_stone, 0, 2);
			world.setBlock(i + 13, j + 2, k + 11, Blocks.end_stone, 0, 2);
			world.setBlock(i + 14, j + 2, k + 11, Blocks.end_stone, 0, 2);
			world.setBlock(i + 15, j + 2, k + 11, Blocks.end_stone, 0, 2);
			world.setBlock(i + 16, j + 2, k + 11, Blocks.end_stone, 0, 2);
			world.setBlock(i + 17, j + 2, k + 11, Blocks.end_stone, 0, 2);
			world.setBlock(i + 18, j + 2, k + 11, Blocks.end_stone, 0, 2);
			world.setBlock(i + 3, j + 2, k + 12, Blocks.end_stone, 0, 2);
			world.setBlock(i + 4, j + 2, k + 12, Blocks.end_stone, 0, 2);
			world.setBlock(i + 5, j + 2, k + 12, Blocks.end_stone, 0, 2);
			world.setBlock(i + 6, j + 2, k + 12, Blocks.end_stone, 0, 2);
			world.setBlock(i + 7, j + 2, k + 12, Blocks.end_stone, 0, 2);
			world.setBlock(i + 8, j + 2, k + 12, Blocks.end_stone, 0, 2);
			world.setBlock(i + 9, j + 2, k + 12, Blocks.end_stone, 0, 2);
			world.setBlock(i + 10, j + 2, k + 12, Blocks.end_stone, 0, 2);
			world.setBlock(i + 11, j + 2, k + 12, Blocks.end_stone, 0, 2);
			world.setBlock(i + 12, j + 2, k + 12, Blocks.end_stone, 0, 2);
			world.setBlock(i + 13, j + 2, k + 12, Blocks.end_stone, 0, 2);
			world.setBlock(i + 14, j + 2, k + 12, Blocks.end_stone, 0, 2);
			world.setBlock(i + 15, j + 2, k + 12, Blocks.end_stone, 0, 2);
			world.setBlock(i + 16, j + 2, k + 12, Blocks.end_stone, 0, 2);
			world.setBlock(i + 17, j + 2, k + 12, Blocks.end_stone, 0, 2);
			world.setBlock(i + 4, j + 2, k + 13, Blocks.end_stone, 0, 2);
			world.setBlock(i + 5, j + 2, k + 13, Blocks.end_stone, 0, 2);
			world.setBlock(i + 6, j + 2, k + 13, Blocks.end_stone, 0, 2);
			world.setBlock(i + 7, j + 2, k + 13, Blocks.end_stone, 0, 2);
			world.setBlock(i + 8, j + 2, k + 13, Blocks.end_stone, 0, 2);
			world.setBlock(i + 9, j + 2, k + 13, Blocks.end_stone, 0, 2);
			world.setBlock(i + 10, j + 2, k + 13, Blocks.end_stone, 0, 2);
			world.setBlock(i + 11, j + 2, k + 13, Blocks.end_stone, 0, 2);
			world.setBlock(i + 12, j + 2, k + 13, Blocks.end_stone, 0, 2);
			world.setBlock(i + 13, j + 2, k + 13, Blocks.end_stone, 0, 2);
			world.setBlock(i + 14, j + 2, k + 13, Blocks.end_stone, 0, 2);
			world.setBlock(i + 15, j + 2, k + 13, Blocks.end_stone, 0, 2);
			world.setBlock(i + 16, j + 2, k + 13, Blocks.end_stone, 0, 2);
			world.setBlock(i + 5, j + 2, k + 14, Blocks.end_stone, 0, 2);
			world.setBlock(i + 6, j + 2, k + 14, Blocks.end_stone, 0, 2);
			world.setBlock(i + 7, j + 2, k + 14, Blocks.end_stone, 0, 2);
			world.setBlock(i + 8, j + 2, k + 14, Blocks.end_stone, 0, 2);
			world.setBlock(i + 9, j + 2, k + 14, Blocks.end_stone, 0, 2);
			world.setBlock(i + 10, j + 2, k + 14, Blocks.end_stone, 0, 2);
			world.setBlock(i + 11, j + 2, k + 14, Blocks.end_stone, 0, 2);
			world.setBlock(i + 12, j + 2, k + 14, Blocks.end_stone, 0, 2);
			world.setBlock(i + 13, j + 2, k + 14, Blocks.end_stone, 0, 2);
			world.setBlock(i + 14, j + 2, k + 14, Blocks.end_stone, 0, 2);
			world.setBlock(i + 15, j + 2, k + 14, Blocks.end_stone, 0, 2);
			world.setBlock(i + 6, j + 2, k + 15, Blocks.end_stone, 0, 2);
			world.setBlock(i + 7, j + 2, k + 15, Blocks.end_stone, 0, 2);
			world.setBlock(i + 8, j + 2, k + 15, Blocks.end_stone, 0, 2);
			world.setBlock(i + 9, j + 2, k + 15, Blocks.end_stone, 0, 2);
			world.setBlock(i + 10, j + 2, k + 15, Blocks.end_stone, 0, 2);
			world.setBlock(i + 11, j + 2, k + 15, Blocks.end_stone, 0, 2);
			world.setBlock(i + 12, j + 2, k + 15, Blocks.end_stone, 0, 2);
			world.setBlock(i + 13, j + 2, k + 15, Blocks.end_stone, 0, 2);
			world.setBlock(i + 14, j + 2, k + 15, Blocks.end_stone, 0, 2);
			world.setBlock(i + 7, j + 2, k + 16, Blocks.end_stone, 0, 2);
			world.setBlock(i + 8, j + 2, k + 16, Blocks.end_stone, 0, 2);
			world.setBlock(i + 9, j + 2, k + 16, Blocks.end_stone, 0, 2);
			world.setBlock(i + 10, j + 2, k + 16, Blocks.end_stone, 0, 2);
			world.setBlock(i + 11, j + 2, k + 16, Blocks.end_stone, 0, 2);
			world.setBlock(i + 12, j + 2, k + 16, Blocks.end_stone, 0, 2);
			world.setBlock(i + 13, j + 2, k + 16, Blocks.end_stone, 0, 2);
			world.setBlock(i + 8, j + 2, k + 17, Blocks.end_stone, 0, 2);
			world.setBlock(i + 9, j + 2, k + 17, Blocks.end_stone, 0, 2);
			world.setBlock(i + 10, j + 2, k + 17, Blocks.end_stone, 0, 2);
			world.setBlock(i + 11, j + 2, k + 17, Blocks.end_stone, 0, 2);
			world.setBlock(i + 12, j + 2, k + 17, Blocks.end_stone, 0, 2);
			world.setBlock(i + 9, j + 2, k + 18, Blocks.end_stone, 0, 2);
			world.setBlock(i + 10, j + 2, k + 18, Blocks.end_stone, 0, 2);
			world.setBlock(i + 11, j + 2, k + 18, Blocks.end_stone, 0, 2);
			world.setBlock(i + 10, j + 2, k + 19, Blocks.end_stone, 0, 2);
			world.setBlock(i + 10, j + 3, k + 0, OtherModBlocks.end_bricks, 0, 2);
			world.setBlock(i + 9, j + 3, k + 1, OtherModBlocks.end_bricks, 0, 2);
			world.setBlock(i + 10, j + 3, k + 1, Blocks.end_stone, 0, 2);
			world.setBlock(i + 11, j + 3, k + 1, OtherModBlocks.end_bricks, 0, 2);
			world.setBlock(i + 8, j + 3, k + 2, OtherModBlocks.end_bricks, 0, 2);
			world.setBlock(i + 9, j + 3, k + 2, Blocks.end_stone, 0, 2);
			world.setBlock(i + 10, j + 3, k + 2, Blocks.end_stone, 0, 2);
			world.setBlock(i + 11, j + 3, k + 2, Blocks.end_stone, 0, 2);
			world.setBlock(i + 12, j + 3, k + 2, OtherModBlocks.end_bricks, 0, 2);
			world.setBlock(i + 7, j + 3, k + 3, OtherModBlocks.end_bricks, 0, 2);
			world.setBlock(i + 8, j + 3, k + 3, Blocks.end_stone, 0, 2);
			world.setBlock(i + 9, j + 3, k + 3, Blocks.end_stone, 0, 2);
			world.setBlock(i + 10, j + 3, k + 3, Blocks.end_stone, 0, 2);
			world.setBlock(i + 11, j + 3, k + 3, Blocks.end_stone, 0, 2);
			world.setBlock(i + 12, j + 3, k + 3, Blocks.end_stone, 0, 2);
			world.setBlock(i + 13, j + 3, k + 3, OtherModBlocks.end_bricks, 0, 2);
			world.setBlock(i + 6, j + 3, k + 4, OtherModBlocks.end_bricks, 0, 2);
			world.setBlock(i + 7, j + 3, k + 4, Blocks.end_stone, 0, 2);
			world.setBlock(i + 8, j + 3, k + 4, Blocks.end_stone, 0, 2);
			world.setBlock(i + 9, j + 3, k + 4, Blocks.end_stone, 0, 2);
			world.setBlock(i + 10, j + 3, k + 4, Blocks.end_stone, 0, 2);
			world.setBlock(i + 11, j + 3, k + 4, Blocks.end_stone, 0, 2);
			world.setBlock(i + 12, j + 3, k + 4, Blocks.end_stone, 0, 2);
			world.setBlock(i + 13, j + 3, k + 4, Blocks.end_stone, 0, 2);
			world.setBlock(i + 14, j + 3, k + 4, OtherModBlocks.end_bricks, 0, 2);
			world.setBlock(i + 5, j + 3, k + 5, OtherModBlocks.end_bricks, 0, 2);
			world.setBlock(i + 6, j + 3, k + 5, Blocks.end_stone, 0, 2);
			world.setBlock(i + 7, j + 3, k + 5, Blocks.end_stone, 0, 2);
			world.setBlock(i + 8, j + 3, k + 5, Blocks.end_stone, 0, 2);
			world.setBlock(i + 9, j + 3, k + 5, Blocks.end_stone, 0, 2);
			world.setBlock(i + 10, j + 3, k + 5, Blocks.end_stone, 0, 2);
			world.setBlock(i + 11, j + 3, k + 5, Blocks.end_stone, 0, 2);
			world.setBlock(i + 12, j + 3, k + 5, Blocks.end_stone, 0, 2);
			world.setBlock(i + 13, j + 3, k + 5, Blocks.end_stone, 0, 2);
			world.setBlock(i + 14, j + 3, k + 5, Blocks.end_stone, 0, 2);
			world.setBlock(i + 15, j + 3, k + 5, OtherModBlocks.end_bricks, 0, 2);
			world.setBlock(i + 4, j + 3, k + 6, OtherModBlocks.end_bricks, 0, 2);
			world.setBlock(i + 5, j + 3, k + 6, Blocks.end_stone, 0, 2);
			world.setBlock(i + 6, j + 3, k + 6, Blocks.end_stone, 0, 2);
			world.setBlock(i + 7, j + 3, k + 6, Blocks.end_stone, 0, 2);
			world.setBlock(i + 8, j + 3, k + 6, Blocks.end_stone, 0, 2);
			world.setBlock(i + 9, j + 3, k + 6, Blocks.end_stone, 0, 2);
			world.setBlock(i + 10, j + 3, k + 6, Blocks.end_stone, 0, 2);
			world.setBlock(i + 11, j + 3, k + 6, Blocks.end_stone, 0, 2);
			world.setBlock(i + 12, j + 3, k + 6, Blocks.end_stone, 0, 2);
			world.setBlock(i + 13, j + 3, k + 6, Blocks.end_stone, 0, 2);
			world.setBlock(i + 14, j + 3, k + 6, Blocks.end_stone, 0, 2);
			world.setBlock(i + 15, j + 3, k + 6, Blocks.end_stone, 0, 2);
			world.setBlock(i + 16, j + 3, k + 6, OtherModBlocks.end_bricks, 0, 2);
			world.setBlock(i + 3, j + 3, k + 7, OtherModBlocks.end_bricks, 0, 2);
			world.setBlock(i + 4, j + 3, k + 7, Blocks.end_stone, 0, 2);
			world.setBlock(i + 5, j + 3, k + 7, Blocks.end_stone, 0, 2);
			world.setBlock(i + 6, j + 3, k + 7, Blocks.end_stone, 0, 2);
			world.setBlock(i + 7, j + 3, k + 7, Blocks.end_stone, 0, 2);
			world.setBlock(i + 8, j + 3, k + 7, Blocks.end_stone, 0, 2);
			world.setBlock(i + 9, j + 3, k + 7, Blocks.end_stone, 0, 2);
			world.setBlock(i + 10, j + 3, k + 7, Blocks.end_stone, 0, 2);
			world.setBlock(i + 11, j + 3, k + 7, Blocks.end_stone, 0, 2);
			world.setBlock(i + 12, j + 3, k + 7, Blocks.end_stone, 0, 2);
			world.setBlock(i + 13, j + 3, k + 7, Blocks.end_stone, 0, 2);
			world.setBlock(i + 14, j + 3, k + 7, Blocks.end_stone, 0, 2);
			world.setBlock(i + 15, j + 3, k + 7, Blocks.end_stone, 0, 2);
			world.setBlock(i + 16, j + 3, k + 7, Blocks.end_stone, 0, 2);
			world.setBlock(i + 17, j + 3, k + 7, OtherModBlocks.end_bricks, 0, 2);
			world.setBlock(i + 2, j + 3, k + 8, OtherModBlocks.end_bricks, 0, 2);
			world.setBlock(i + 3, j + 3, k + 8, Blocks.end_stone, 0, 2);
			world.setBlock(i + 4, j + 3, k + 8, Blocks.end_stone, 0, 2);
			world.setBlock(i + 5, j + 3, k + 8, Blocks.end_stone, 0, 2);
			world.setBlock(i + 6, j + 3, k + 8, Blocks.end_stone, 0, 2);
			world.setBlock(i + 7, j + 3, k + 8, Blocks.end_stone, 0, 2);
			world.setBlock(i + 8, j + 3, k + 8, NovaCraftBlocks.frontierslate_bricks, 0, 2);
			world.setBlock(i + 9, j + 3, k + 8, NovaCraftBlocks.frontierslate_bricks, 0, 2);
			world.setBlock(i + 10, j + 3, k + 8, NovaCraftBlocks.frontierslate_bricks, 0, 2);
			world.setBlock(i + 11, j + 3, k + 8, NovaCraftBlocks.frontierslate_bricks, 0, 2);
			world.setBlock(i + 12, j + 3, k + 8, NovaCraftBlocks.frontierslate_bricks, 0, 2);
			world.setBlock(i + 13, j + 3, k + 8, Blocks.end_stone, 0, 2);
			world.setBlock(i + 14, j + 3, k + 8, Blocks.end_stone, 0, 2);
			world.setBlock(i + 15, j + 3, k + 8, Blocks.end_stone, 0, 2);
			world.setBlock(i + 16, j + 3, k + 8, Blocks.end_stone, 0, 2);
			world.setBlock(i + 17, j + 3, k + 8, Blocks.end_stone, 0, 2);
			world.setBlock(i + 18, j + 3, k + 8, OtherModBlocks.end_bricks, 0, 2);
			world.setBlock(i + 1, j + 3, k + 9, OtherModBlocks.end_bricks, 0, 2);
			world.setBlock(i + 2, j + 3, k + 9, Blocks.end_stone, 0, 2);
			world.setBlock(i + 3, j + 3, k + 9, Blocks.end_stone, 0, 2);
			world.setBlock(i + 4, j + 3, k + 9, Blocks.end_stone, 0, 2);
			world.setBlock(i + 5, j + 3, k + 9, Blocks.end_stone, 0, 2);
			world.setBlock(i + 6, j + 3, k + 9, Blocks.end_stone, 0, 2);
			world.setBlock(i + 7, j + 3, k + 9, Blocks.end_stone, 0, 2);
			world.setBlock(i + 8, j + 3, k + 9, NovaCraftBlocks.frontierslate_bricks, 0, 2);
			world.setBlock(i + 9, j + 3, k + 9, Blocks.netherrack, 0, 2);
			world.setBlock(i + 10, j + 3, k + 9, Blocks.end_stone, 0, 2);
			world.setBlock(i + 11, j + 3, k + 9, Blocks.netherrack, 0, 2);
			world.setBlock(i + 12, j + 3, k + 9, NovaCraftBlocks.frontierslate_bricks, 0, 2);
			world.setBlock(i + 13, j + 3, k + 9, Blocks.end_stone, 0, 2);
			world.setBlock(i + 14, j + 3, k + 9, Blocks.end_stone, 0, 2);
			world.setBlock(i + 15, j + 3, k + 9, Blocks.end_stone, 0, 2);
			world.setBlock(i + 16, j + 3, k + 9, Blocks.end_stone, 0, 2);
			world.setBlock(i + 17, j + 3, k + 9, Blocks.end_stone, 0, 2);
			world.setBlock(i + 18, j + 3, k + 9, Blocks.end_stone, 0, 2);
			world.setBlock(i + 19, j + 3, k + 9, OtherModBlocks.end_bricks, 0, 2);
			world.setBlock(i + 0, j + 3, k + 10, OtherModBlocks.end_bricks, 0, 2);
			world.setBlock(i + 1, j + 3, k + 10, Blocks.end_stone, 0, 2);
			world.setBlock(i + 2, j + 3, k + 10, Blocks.end_stone, 0, 2);
			world.setBlock(i + 3, j + 3, k + 10, Blocks.end_stone, 0, 2);
			world.setBlock(i + 4, j + 3, k + 10, Blocks.end_stone, 0, 2);
			world.setBlock(i + 5, j + 3, k + 10, Blocks.end_stone, 0, 2);
			world.setBlock(i + 6, j + 3, k + 10, Blocks.end_stone, 0, 2);
			world.setBlock(i + 7, j + 3, k + 10, Blocks.end_stone, 0, 2);
			world.setBlock(i + 8, j + 3, k + 10, NovaCraftBlocks.frontierslate_bricks, 0, 2);
			world.setBlock(i + 9, j + 3, k + 10, Blocks.end_stone, 0, 2);
			world.setBlock(i + 10, j + 3, k + 10, Blocks.end_stone, 0, 2);
			world.setBlock(i + 11, j + 3, k + 10, Blocks.end_stone, 0, 2);
			world.setBlock(i + 12, j + 3, k + 10, NovaCraftBlocks.frontierslate_bricks, 0, 2);
			world.setBlock(i + 13, j + 3, k + 10, Blocks.end_stone, 0, 2);
			world.setBlock(i + 14, j + 3, k + 10, Blocks.end_stone, 0, 2);
			world.setBlock(i + 15, j + 3, k + 10, Blocks.end_stone, 0, 2);
			world.setBlock(i + 16, j + 3, k + 10, Blocks.end_stone, 0, 2);
			world.setBlock(i + 17, j + 3, k + 10, Blocks.end_stone, 0, 2);
			world.setBlock(i + 18, j + 3, k + 10, Blocks.end_stone, 0, 2);
			world.setBlock(i + 19, j + 3, k + 10, Blocks.end_stone, 0, 2);
			world.setBlock(i + 20, j + 3, k + 10, OtherModBlocks.end_bricks, 0, 2);
			world.setBlock(i + 1, j + 3, k + 11, OtherModBlocks.end_bricks, 0, 2);
			world.setBlock(i + 2, j + 3, k + 11, Blocks.end_stone, 0, 2);
			world.setBlock(i + 3, j + 3, k + 11, Blocks.end_stone, 0, 2);
			world.setBlock(i + 4, j + 3, k + 11, Blocks.end_stone, 0, 2);
			world.setBlock(i + 5, j + 3, k + 11, Blocks.end_stone, 0, 2);
			world.setBlock(i + 6, j + 3, k + 11, Blocks.end_stone, 0, 2);
			world.setBlock(i + 7, j + 3, k + 11, Blocks.end_stone, 0, 2);
			world.setBlock(i + 8, j + 3, k + 11, NovaCraftBlocks.frontierslate_bricks, 0, 2);
			world.setBlock(i + 9, j + 3, k + 11, Blocks.netherrack, 0, 2);
			world.setBlock(i + 10, j + 3, k + 11, Blocks.end_stone, 0, 2);
			world.setBlock(i + 11, j + 3, k + 11, Blocks.netherrack, 0, 2);
			world.setBlock(i + 12, j + 3, k + 11, NovaCraftBlocks.frontierslate_bricks, 0, 2);
			world.setBlock(i + 13, j + 3, k + 11, Blocks.end_stone, 0, 2);
			world.setBlock(i + 14, j + 3, k + 11, Blocks.end_stone, 0, 2);
			world.setBlock(i + 15, j + 3, k + 11, Blocks.end_stone, 0, 2);
			world.setBlock(i + 16, j + 3, k + 11, Blocks.end_stone, 0, 2);
			world.setBlock(i + 17, j + 3, k + 11, Blocks.end_stone, 0, 2);
			world.setBlock(i + 18, j + 3, k + 11, Blocks.end_stone, 0, 2);
			world.setBlock(i + 19, j + 3, k + 11, OtherModBlocks.end_bricks, 0, 2);
			world.setBlock(i + 2, j + 3, k + 12, OtherModBlocks.end_bricks, 0, 2);
			world.setBlock(i + 3, j + 3, k + 12, Blocks.end_stone, 0, 2);
			world.setBlock(i + 4, j + 3, k + 12, Blocks.end_stone, 0, 2);
			world.setBlock(i + 5, j + 3, k + 12, Blocks.end_stone, 0, 2);
			world.setBlock(i + 6, j + 3, k + 12, Blocks.end_stone, 0, 2);
			world.setBlock(i + 7, j + 3, k + 12, Blocks.end_stone, 0, 2);
			world.setBlock(i + 8, j + 3, k + 12, NovaCraftBlocks.frontierslate_bricks, 0, 2);
			world.setBlock(i + 9, j + 3, k + 12, NovaCraftBlocks.frontierslate_bricks, 0, 2);
			world.setBlock(i + 10, j + 3, k + 12, NovaCraftBlocks.frontierslate_bricks, 0, 2);
			world.setBlock(i + 11, j + 3, k + 12, NovaCraftBlocks.frontierslate_bricks, 0, 2);
			world.setBlock(i + 12, j + 3, k + 12, NovaCraftBlocks.frontierslate_bricks, 0, 2);
			world.setBlock(i + 13, j + 3, k + 12, Blocks.end_stone, 0, 2);
			world.setBlock(i + 14, j + 3, k + 12, Blocks.end_stone, 0, 2);
			world.setBlock(i + 15, j + 3, k + 12, Blocks.end_stone, 0, 2);
			world.setBlock(i + 16, j + 3, k + 12, Blocks.end_stone, 0, 2);
			world.setBlock(i + 17, j + 3, k + 12, Blocks.end_stone, 0, 2);
			world.setBlock(i + 18, j + 3, k + 12, OtherModBlocks.end_bricks, 0, 2);
			world.setBlock(i + 3, j + 3, k + 13, OtherModBlocks.end_bricks, 0, 2);
			world.setBlock(i + 4, j + 3, k + 13, Blocks.end_stone, 0, 2);
			world.setBlock(i + 5, j + 3, k + 13, Blocks.end_stone, 0, 2);
			world.setBlock(i + 6, j + 3, k + 13, Blocks.end_stone, 0, 2);
			world.setBlock(i + 7, j + 3, k + 13, Blocks.end_stone, 0, 2);
			world.setBlock(i + 8, j + 3, k + 13, Blocks.end_stone, 0, 2);
			world.setBlock(i + 9, j + 3, k + 13, Blocks.end_stone, 0, 2);
			world.setBlock(i + 10, j + 3, k + 13, Blocks.end_stone, 0, 2);
			world.setBlock(i + 11, j + 3, k + 13, Blocks.end_stone, 0, 2);
			world.setBlock(i + 12, j + 3, k + 13, Blocks.end_stone, 0, 2);
			world.setBlock(i + 13, j + 3, k + 13, Blocks.end_stone, 0, 2);
			world.setBlock(i + 14, j + 3, k + 13, Blocks.end_stone, 0, 2);
			world.setBlock(i + 15, j + 3, k + 13, Blocks.end_stone, 0, 2);
			world.setBlock(i + 16, j + 3, k + 13, Blocks.end_stone, 0, 2);
			world.setBlock(i + 17, j + 3, k + 13, OtherModBlocks.end_bricks, 0, 2);
			world.setBlock(i + 4, j + 3, k + 14, OtherModBlocks.end_bricks, 0, 2);
			world.setBlock(i + 5, j + 3, k + 14, Blocks.end_stone, 0, 2);
			world.setBlock(i + 6, j + 3, k + 14, Blocks.end_stone, 0, 2);
			world.setBlock(i + 7, j + 3, k + 14, Blocks.end_stone, 0, 2);
			world.setBlock(i + 8, j + 3, k + 14, Blocks.end_stone, 0, 2);
			world.setBlock(i + 9, j + 3, k + 14, Blocks.end_stone, 0, 2);
			world.setBlock(i + 10, j + 3, k + 14, Blocks.end_stone, 0, 2);
			world.setBlock(i + 11, j + 3, k + 14, Blocks.end_stone, 0, 2);
			world.setBlock(i + 12, j + 3, k + 14, Blocks.end_stone, 0, 2);
			world.setBlock(i + 13, j + 3, k + 14, Blocks.end_stone, 0, 2);
			world.setBlock(i + 14, j + 3, k + 14, Blocks.end_stone, 0, 2);
			world.setBlock(i + 15, j + 3, k + 14, Blocks.end_stone, 0, 2);
			world.setBlock(i + 16, j + 3, k + 14, OtherModBlocks.end_bricks, 0, 2);
			world.setBlock(i + 5, j + 3, k + 15, OtherModBlocks.end_bricks, 0, 2);
			world.setBlock(i + 6, j + 3, k + 15, Blocks.end_stone, 0, 2);
			world.setBlock(i + 7, j + 3, k + 15, Blocks.end_stone, 0, 2);
			world.setBlock(i + 8, j + 3, k + 15, Blocks.end_stone, 0, 2);
			world.setBlock(i + 9, j + 3, k + 15, Blocks.end_stone, 0, 2);
			world.setBlock(i + 10, j + 3, k + 15, Blocks.end_stone, 0, 2);
			world.setBlock(i + 11, j + 3, k + 15, Blocks.end_stone, 0, 2);
			world.setBlock(i + 12, j + 3, k + 15, Blocks.end_stone, 0, 2);
			world.setBlock(i + 13, j + 3, k + 15, Blocks.end_stone, 0, 2);
			world.setBlock(i + 14, j + 3, k + 15, Blocks.end_stone, 0, 2);
			world.setBlock(i + 15, j + 3, k + 15, OtherModBlocks.end_bricks, 0, 2);
			world.setBlock(i + 6, j + 3, k + 16, OtherModBlocks.end_bricks, 0, 2);
			world.setBlock(i + 7, j + 3, k + 16, Blocks.end_stone, 0, 2);
			world.setBlock(i + 8, j + 3, k + 16, Blocks.end_stone, 0, 2);
			world.setBlock(i + 9, j + 3, k + 16, Blocks.end_stone, 0, 2);
			world.setBlock(i + 10, j + 3, k + 16, Blocks.end_stone, 0, 2);
			world.setBlock(i + 11, j + 3, k + 16, Blocks.end_stone, 0, 2);
			world.setBlock(i + 12, j + 3, k + 16, Blocks.end_stone, 0, 2);
			world.setBlock(i + 13, j + 3, k + 16, Blocks.end_stone, 0, 2);
			world.setBlock(i + 14, j + 3, k + 16, OtherModBlocks.end_bricks, 0, 2);
			world.setBlock(i + 7, j + 3, k + 17, OtherModBlocks.end_bricks, 0, 2);
			world.setBlock(i + 8, j + 3, k + 17, Blocks.end_stone, 0, 2);
			world.setBlock(i + 9, j + 3, k + 17, Blocks.end_stone, 0, 2);
			world.setBlock(i + 10, j + 3, k + 17, Blocks.end_stone, 0, 2);
			world.setBlock(i + 11, j + 3, k + 17, Blocks.end_stone, 0, 2);
			world.setBlock(i + 12, j + 3, k + 17, Blocks.end_stone, 0, 2);
			world.setBlock(i + 13, j + 3, k + 17, OtherModBlocks.end_bricks, 0, 2);
			world.setBlock(i + 8, j + 3, k + 18, OtherModBlocks.end_bricks, 0, 2);
			world.setBlock(i + 9, j + 3, k + 18, Blocks.end_stone, 0, 2);
			world.setBlock(i + 10, j + 3, k + 18, Blocks.end_stone, 0, 2);
			world.setBlock(i + 11, j + 3, k + 18, Blocks.end_stone, 0, 2);
			world.setBlock(i + 12, j + 3, k + 18, OtherModBlocks.end_bricks, 0, 2);
			world.setBlock(i + 9, j + 3, k + 19, OtherModBlocks.end_bricks, 0, 2);
			world.setBlock(i + 10, j + 3, k + 19, Blocks.end_stone, 0, 2);
			world.setBlock(i + 11, j + 3, k + 19, OtherModBlocks.end_bricks, 0, 2);
			world.setBlock(i + 10, j + 3, k + 20, OtherModBlocks.end_bricks, 0, 2);
			world.setBlock(i + 7, j + 4, k + 4, NovaCraftBlocks.frontierslate_bricks, 0, 2);
			world.setBlock(i + 13, j + 4, k + 4, NovaCraftBlocks.frontierslate_bricks, 0, 2);
			world.setBlock(i + 4, j + 4, k + 7, NovaCraftBlocks.frontierslate_bricks, 0, 2);
			world.setBlock(i + 7, j + 4, k + 7, NovaCraftBlocks.frontierslate_brick_slab, 5, 2);
			world.setBlock(i + 8, j + 4, k + 7, NovaCraftBlocks.frontierslate_brick_slab, 5, 2);
			world.setBlock(i + 9, j + 4, k + 7, NovaCraftBlocks.frontierslate_brick_slab, 5, 2);
			world.setBlock(i + 11, j + 4, k + 7, NovaCraftBlocks.frontierslate_brick_slab, 5, 2);
			world.setBlock(i + 12, j + 4, k + 7, NovaCraftBlocks.frontierslate_brick_slab, 5, 2);
			world.setBlock(i + 13, j + 4, k + 7, NovaCraftBlocks.frontierslate_brick_slab, 5, 2);
			world.setBlock(i + 16, j + 4, k + 7, NovaCraftBlocks.frontierslate_bricks, 0, 2);
			world.setBlock(i + 7, j + 4, k + 8, NovaCraftBlocks.frontierslate_brick_slab, 5, 2);
			world.setBlock(i + 8, j + 4, k + 8, NovaCraftBlocks.frontierslate, 0, 2);
			world.setBlock(i + 12, j + 4, k + 8, NovaCraftBlocks.frontierslate, 0, 2);
			world.setBlock(i + 13, j + 4, k + 8, NovaCraftBlocks.frontierslate_brick_slab, 5, 2);
			world.setBlock(i + 7, j + 4, k + 9, NovaCraftBlocks.frontierslate_brick_slab, 5, 2);
			world.setBlock(i + 9, j + 4, k + 9, Blocks.fire, 15, 2);
			world.setBlock(i + 10, j + 4, k + 9, NovaCraftBlocks.frontierslate, 0, 2);
			world.setBlock(i + 11, j + 4, k + 9, Blocks.fire, 15, 2);
			world.setBlock(i + 13, j + 4, k + 9, NovaCraftBlocks.frontierslate_brick_slab, 5, 2);
			world.setBlock(i + 9, j + 4, k + 10, NovaCraftBlocks.frontierslate, 0, 2);
			world.setBlock(i + 10, j + 4, k + 10, NovaCraftBlocks.frontierslate_bricks, 3, 2);
			world.setBlock(i + 11, j + 4, k + 10, NovaCraftBlocks.frontierslate, 0, 2);
			world.setBlock(i + 7, j + 4, k + 11, NovaCraftBlocks.frontierslate_brick_slab, 5, 2);
			world.setBlock(i + 9, j + 4, k + 11, Blocks.fire, 15, 2);
			world.setBlock(i + 10, j + 4, k + 11, NovaCraftBlocks.frontierslate, 0, 2);
			world.setBlock(i + 11, j + 4, k + 11, Blocks.fire, 15, 2);
			world.setBlock(i + 13, j + 4, k + 11, NovaCraftBlocks.frontierslate_brick_slab, 5, 2);
			world.setBlock(i + 7, j + 4, k + 12, NovaCraftBlocks.frontierslate_brick_slab, 5, 2);
			world.setBlock(i + 8, j + 4, k + 12, NovaCraftBlocks.frontierslate, 0, 2);
			world.setBlock(i + 12, j + 4, k + 12, NovaCraftBlocks.frontierslate, 0, 2);
			world.setBlock(i + 13, j + 4, k + 12, NovaCraftBlocks.frontierslate_brick_slab, 5, 2);
			world.setBlock(i + 4, j + 4, k + 13, NovaCraftBlocks.frontierslate_bricks, 0, 2);
			world.setBlock(i + 7, j + 4, k + 13, NovaCraftBlocks.frontierslate_brick_slab, 5, 2);
			world.setBlock(i + 8, j + 4, k + 13, NovaCraftBlocks.frontierslate_brick_slab, 5, 2);
			world.setBlock(i + 9, j + 4, k + 13, NovaCraftBlocks.frontierslate_brick_slab, 5, 2);
			world.setBlock(i + 11, j + 4, k + 13, NovaCraftBlocks.frontierslate_brick_slab, 5, 2);
			world.setBlock(i + 12, j + 4, k + 13, NovaCraftBlocks.frontierslate_brick_slab, 5, 2);
			world.setBlock(i + 13, j + 4, k + 13, NovaCraftBlocks.frontierslate_brick_slab, 5, 2);
			world.setBlock(i + 16, j + 4, k + 13, NovaCraftBlocks.frontierslate_bricks, 0, 2);
			world.setBlock(i + 7, j + 4, k + 16, NovaCraftBlocks.frontierslate_bricks, 0, 2);
			world.setBlock(i + 13, j + 4, k + 16, NovaCraftBlocks.frontierslate_bricks, 0, 2);
			world.setBlock(i + 7, j + 5, k + 4, NovaCraftBlocks.frontierslate_bricks, 0, 2);
			world.setBlock(i + 13, j + 5, k + 4, NovaCraftBlocks.frontierslate_bricks, 0, 2);
			world.setBlock(i + 4, j + 5, k + 7, NovaCraftBlocks.frontierslate_bricks, 0, 2);
			world.setBlock(i + 16, j + 5, k + 7, NovaCraftBlocks.frontierslate_bricks, 0, 2);
			world.setBlock(i + 8, j + 5, k + 8, NovaCraftBlocks.frontierslate, 0, 2);
			world.setBlock(i + 9, j + 5, k + 8, NovaCraftBlocks.frontierslate_brick_stairs, 1, 2);
			world.setBlock(i + 11, j + 5, k + 8, NovaCraftBlocks.frontierslate_brick_stairs, 0, 2);
			world.setBlock(i + 12, j + 5, k + 8, NovaCraftBlocks.frontierslate, 0, 2);
			world.setBlock(i + 8, j + 5, k + 9, NovaCraftBlocks.frontierslate_brick_stairs, 3, 2);
			world.setBlock(i + 9, j + 5, k + 9, NovaCraftBlocks.frontierslate_brick_slab, 5, 2);
			world.setBlock(i + 11, j + 5, k + 9, NovaCraftBlocks.frontierslate_brick_slab, 5, 2);
			world.setBlock(i + 12, j + 5, k + 9, NovaCraftBlocks.frontierslate_brick_stairs, 3, 2);
			world.setBlock(i + 10, j + 5, k + 10, NovaCraftBlocks.carved_frontierslate_bricks, 0, 2);
			world.setBlock(i + 8, j + 5, k + 11, NovaCraftBlocks.frontierslate_brick_stairs, 2, 2);
			world.setBlock(i + 9, j + 5, k + 11, NovaCraftBlocks.frontierslate_brick_slab, 5, 2);
			world.setBlock(i + 11, j + 5, k + 11, NovaCraftBlocks.frontierslate_brick_slab, 5, 2);
			world.setBlock(i + 12, j + 5, k + 11, NovaCraftBlocks.frontierslate_brick_stairs, 2, 2);
			world.setBlock(i + 8, j + 5, k + 12, NovaCraftBlocks.frontierslate, 0, 2);
			world.setBlock(i + 9, j + 5, k + 12, NovaCraftBlocks.frontierslate_brick_stairs, 1, 2);
			world.setBlock(i + 11, j + 5, k + 12, NovaCraftBlocks.frontierslate_brick_stairs, 0, 2);
			world.setBlock(i + 12, j + 5, k + 12, NovaCraftBlocks.frontierslate, 0, 2);
			world.setBlock(i + 4, j + 5, k + 13, NovaCraftBlocks.frontierslate_bricks, 0, 2);
			world.setBlock(i + 16, j + 5, k + 13, NovaCraftBlocks.frontierslate_bricks, 0, 2);
			world.setBlock(i + 7, j + 5, k + 16, NovaCraftBlocks.frontierslate_bricks, 0, 2);
			world.setBlock(i + 13, j + 5, k + 16, NovaCraftBlocks.frontierslate_bricks, 0, 2);
			world.setBlock(i + 7, j + 6, k + 4, NovaCraftBlocks.frontierslate_bricks, 0, 2);
			world.setBlock(i + 8, j + 6, k + 4, NovaCraftBlocks.frontierslate_brick_stairs, 5, 2);
			world.setBlock(i + 12, j + 6, k + 4, NovaCraftBlocks.frontierslate_brick_stairs, 4, 2);
			world.setBlock(i + 13, j + 6, k + 4, NovaCraftBlocks.frontierslate_bricks, 0, 2);
			world.setBlock(i + 4, j + 6, k + 7, NovaCraftBlocks.frontierslate_bricks, 0, 2);
			world.setBlock(i + 16, j + 6, k + 7, NovaCraftBlocks.frontierslate_bricks, 0, 2);
			world.setBlock(i + 4, j + 6, k + 8, NovaCraftBlocks.frontierslate_brick_stairs, 7, 2);
			world.setBlock(i + 8, j + 6, k + 8, NovaCraftBlocks.frontierslate, 0, 2);
			world.setBlock(i + 12, j + 6, k + 8, NovaCraftBlocks.frontierslate, 0, 2);
			world.setBlock(i + 16, j + 6, k + 8, NovaCraftBlocks.frontierslate_brick_stairs, 7, 2);
			world.setBlock(i + 4, j + 6, k + 12, NovaCraftBlocks.frontierslate_brick_stairs, 6, 2);
			world.setBlock(i + 8, j + 6, k + 12, NovaCraftBlocks.frontierslate, 0, 2);
			world.setBlock(i + 12, j + 6, k + 12, NovaCraftBlocks.frontierslate, 0, 2);
			world.setBlock(i + 16, j + 6, k + 12, NovaCraftBlocks.frontierslate_brick_stairs, 6, 2);
			world.setBlock(i + 4, j + 6, k + 13, NovaCraftBlocks.frontierslate_bricks, 0, 2);
			world.setBlock(i + 16, j + 6, k + 13, NovaCraftBlocks.frontierslate_bricks, 0, 2);
			world.setBlock(i + 7, j + 6, k + 16, NovaCraftBlocks.frontierslate_bricks, 0, 2);
			world.setBlock(i + 8, j + 6, k + 16, NovaCraftBlocks.frontierslate_brick_stairs, 5, 2);
			world.setBlock(i + 12, j + 6, k + 16, NovaCraftBlocks.frontierslate_brick_stairs, 4, 2);
			world.setBlock(i + 13, j + 6, k + 16, NovaCraftBlocks.frontierslate_bricks, 0, 2);
			world.setBlock(i + 7, j + 7, k + 4, NovaCraftBlocks.frontierslate_brick_stairs, 0, 2);
			world.setBlock(i + 8, j + 7, k + 4, NovaCraftBlocks.frontierslate_bricks, 0, 2);
			world.setBlock(i + 9, j + 7, k + 4, NovaCraftBlocks.frontierslate_brick_stairs, 5, 2);
			world.setBlock(i + 10, j + 7, k + 4, OtherModBlocks.end_rod, 0, 2);
			world.setBlock(i + 11, j + 7, k + 4, NovaCraftBlocks.frontierslate_brick_stairs, 4, 2);
			world.setBlock(i + 12, j + 7, k + 4, NovaCraftBlocks.frontierslate_bricks, 0, 2);
			world.setBlock(i + 13, j + 7, k + 4, NovaCraftBlocks.frontierslate_brick_stairs, 1, 2);
			world.setBlock(i + 4, j + 7, k + 7, NovaCraftBlocks.frontierslate_brick_stairs, 2, 2);
			world.setBlock(i + 16, j + 7, k + 7, NovaCraftBlocks.frontierslate_brick_stairs, 2, 2);
			world.setBlock(i + 4, j + 7, k + 8, NovaCraftBlocks.frontierslate_bricks, 0, 2);
			world.setBlock(i + 8, j + 7, k + 8, OtherModBlocks.end_rod, 1, 2);
			world.setBlock(i + 12, j + 7, k + 8, OtherModBlocks.end_rod, 1, 2);
			world.setBlock(i + 16, j + 7, k + 8, NovaCraftBlocks.frontierslate_bricks, 0, 2);
			world.setBlock(i + 4, j + 7, k + 9, NovaCraftBlocks.frontierslate_brick_stairs, 7, 2);
			world.setBlock(i + 16, j + 7, k + 9, NovaCraftBlocks.frontierslate_brick_stairs, 7, 2);
			world.setBlock(i + 4, j + 7, k + 10, OtherModBlocks.end_rod, 0, 2);
			world.setBlock(i + 16, j + 7, k + 10, OtherModBlocks.end_rod, 0, 2);
			world.setBlock(i + 4, j + 7, k + 11, NovaCraftBlocks.frontierslate_brick_stairs, 6, 2);
			world.setBlock(i + 16, j + 7, k + 11, NovaCraftBlocks.frontierslate_brick_stairs, 6, 2);
			world.setBlock(i + 4, j + 7, k + 12, NovaCraftBlocks.frontierslate_bricks, 0, 2);
			world.setBlock(i + 8, j + 7, k + 12, OtherModBlocks.end_rod, 1, 2);
			world.setBlock(i + 12, j + 7, k + 12, OtherModBlocks.end_rod, 1, 2);
			world.setBlock(i + 16, j + 7, k + 12, NovaCraftBlocks.frontierslate_bricks, 0, 2);
			world.setBlock(i + 4, j + 7, k + 13, NovaCraftBlocks.frontierslate_brick_stairs, 3, 2);
			world.setBlock(i + 16, j + 7, k + 13, NovaCraftBlocks.frontierslate_brick_stairs, 3, 2);
			world.setBlock(i + 7, j + 7, k + 16, NovaCraftBlocks.frontierslate_brick_stairs, 0, 2);
			world.setBlock(i + 8, j + 7, k + 16, NovaCraftBlocks.frontierslate_bricks, 0, 2);
			world.setBlock(i + 9, j + 7, k + 16, NovaCraftBlocks.frontierslate_brick_stairs, 5, 2);
			world.setBlock(i + 10, j + 7, k + 16, OtherModBlocks.end_rod, 0, 2);
			world.setBlock(i + 11, j + 7, k + 16, NovaCraftBlocks.frontierslate_brick_stairs, 4, 2);
			world.setBlock(i + 12, j + 7, k + 16, NovaCraftBlocks.frontierslate_bricks, 0, 2);
			world.setBlock(i + 13, j + 7, k + 16, NovaCraftBlocks.frontierslate_brick_stairs, 1, 2);
			world.setBlock(i + 8, j + 8, k + 4, NovaCraftBlocks.frontierslate_brick_stairs, 0, 2);
			world.setBlock(i + 9, j + 8, k + 4, NovaCraftBlocks.frontierslate_bricks, 0, 2);
			world.setBlock(i + 10, j + 8, k + 4, NovaCraftBlocks.frontierslate_bricks, 0, 2);
			world.setBlock(i + 11, j + 8, k + 4, NovaCraftBlocks.frontierslate_bricks, 0, 2);
			world.setBlock(i + 12, j + 8, k + 4, NovaCraftBlocks.frontierslate_brick_stairs, 1, 2);
			world.setBlock(i + 4, j + 8, k + 8, NovaCraftBlocks.frontierslate_brick_stairs, 2, 2);
			world.setBlock(i + 16, j + 8, k + 8, NovaCraftBlocks.frontierslate_brick_stairs, 2, 2);
			world.setBlock(i + 4, j + 8, k + 9, NovaCraftBlocks.frontierslate_bricks, 0, 2);
			world.setBlock(i + 16, j + 8, k + 9, NovaCraftBlocks.frontierslate_bricks, 0, 2);
			world.setBlock(i + 4, j + 8, k + 10, NovaCraftBlocks.frontierslate_bricks, 0, 2);
			world.setBlock(i + 16, j + 8, k + 10, NovaCraftBlocks.frontierslate_bricks, 0, 2);
			world.setBlock(i + 4, j + 8, k + 11, NovaCraftBlocks.frontierslate_bricks, 0, 2);
			world.setBlock(i + 16, j + 8, k + 11, NovaCraftBlocks.frontierslate_bricks, 0, 2);
			world.setBlock(i + 4, j + 8, k + 12, NovaCraftBlocks.frontierslate_brick_stairs, 3, 2);
			world.setBlock(i + 16, j + 8, k + 12, NovaCraftBlocks.frontierslate_brick_stairs, 3, 2);
			world.setBlock(i + 8, j + 8, k + 16, NovaCraftBlocks.frontierslate_brick_stairs, 0, 2);
			world.setBlock(i + 9, j + 8, k + 16, NovaCraftBlocks.frontierslate_bricks, 0, 2);
			world.setBlock(i + 10, j + 8, k + 16, NovaCraftBlocks.frontierslate_bricks, 0, 2);
			world.setBlock(i + 11, j + 8, k + 16, NovaCraftBlocks.frontierslate_bricks, 0, 2);
			world.setBlock(i + 12, j + 8, k + 16, NovaCraftBlocks.frontierslate_brick_stairs, 1, 2);
			world.setBlock(i + 9, j + 9, k + 4, NovaCraftBlocks.frontierslate_brick_stairs, 0, 2);
			world.setBlock(i + 10, j + 9, k + 4, NovaCraftBlocks.frontierslate_bricks, 0, 2);
			world.setBlock(i + 11, j + 9, k + 4, NovaCraftBlocks.frontierslate_brick_stairs, 1, 2);
			world.setBlock(i + 4, j + 9, k + 9, NovaCraftBlocks.frontierslate_brick_stairs, 2, 2);
			world.setBlock(i + 16, j + 9, k + 9, NovaCraftBlocks.frontierslate_brick_stairs, 2, 2);
			world.setBlock(i + 4, j + 9, k + 10, NovaCraftBlocks.frontierslate_bricks, 0, 2);
			world.setBlock(i + 16, j + 9, k + 10, NovaCraftBlocks.frontierslate_bricks, 0, 2);
			world.setBlock(i + 4, j + 9, k + 11, NovaCraftBlocks.frontierslate_brick_stairs, 3, 2);
			world.setBlock(i + 16, j + 9, k + 11, NovaCraftBlocks.frontierslate_brick_stairs, 3, 2);
			world.setBlock(i + 9, j + 9, k + 16, NovaCraftBlocks.frontierslate_brick_stairs, 0, 2);
			world.setBlock(i + 10, j + 9, k + 16, NovaCraftBlocks.frontierslate_bricks, 0, 2);
			world.setBlock(i + 11, j + 9, k + 16, NovaCraftBlocks.frontierslate_brick_stairs, 1, 2);
			world.setBlock(i + 10, j + 10, k + 4, NovaCraftBlocks.frontierslate_brick_slab, 5, 2);
			world.setBlock(i + 4, j + 10, k + 10, NovaCraftBlocks.frontierslate_brick_slab, 5, 2);
			world.setBlock(i + 16, j + 10, k + 10, NovaCraftBlocks.frontierslate_brick_slab, 5, 2);
			world.setBlock(i + 10, j + 10, k + 16, NovaCraftBlocks.frontierslate_brick_slab, 5, 2);
    		
    		
        	
        return true;
    }
    
}
