package com.NovaCraft.world.end.endcamp;

import net.minecraft.world.gen.feature.*;
import net.minecraft.block.*;
import net.minecraft.world.*;
import java.util.*;

import com.NovaCraft.registry.OtherModBlocks;
import com.NovaCraftBlocks.NovaCraftBlocks;

import net.minecraft.init.*;

public class EnderSettlementShipGen extends WorldGenerator
{
	public EnderSettlementShipGen() {

	}
    
    public boolean generate(final World world, final Random random, final int i, final int j, final int k) {	
    
		world.setBlock(i + 9, j + 3, k + 8, OtherModBlocks.purpur_pillar, 8, 2);
		world.setBlock(i + 9, j + 3, k + 9, OtherModBlocks.purpur_pillar, 8, 2);
		world.setBlock(i + 9, j + 3, k + 10, OtherModBlocks.purpur_pillar, 8, 2);
		world.setBlock(i + 9, j + 3, k + 11, OtherModBlocks.purpur_pillar, 8, 2);
		world.setBlock(i + 9, j + 3, k + 12, OtherModBlocks.purpur_pillar, 8, 2);
		world.setBlock(i + 9, j + 3, k + 13, OtherModBlocks.purpur_pillar, 8, 2);
		world.setBlock(i + 9, j + 3, k + 14, OtherModBlocks.purpur_pillar, 8, 2);
		world.setBlock(i + 9, j + 3, k + 15, OtherModBlocks.purpur_pillar, 8, 2);
		world.setBlock(i + 9, j + 3, k + 16, OtherModBlocks.purpur_pillar, 8, 2);
		world.setBlock(i + 9, j + 3, k + 17, OtherModBlocks.purpur_pillar, 8, 2);
		world.setBlock(i + 9, j + 3, k + 18, OtherModBlocks.purpur_pillar, 8, 2);
		world.setBlock(i + 9, j + 3, k + 19, OtherModBlocks.purpur_pillar, 8, 2);
		world.setBlock(i + 9, j + 3, k + 20, OtherModBlocks.purpur_pillar, 8, 2);
		world.setBlock(i + 8, j + 4, k + 7,  OtherModBlocks.purpur_block, 0, 2);
		world.setBlock(i + 9, j + 4, k + 7, OtherModBlocks.purpur_pillar, 8, 2);
		world.setBlock(i + 10, j + 4, k + 7, OtherModBlocks.purpur_block, 0, 2);
		world.setBlock(i + 8, j + 4, k + 8, OtherModBlocks.purpur_block, 0, 2);
		world.setBlock(i + 9, j + 4, k + 8, OtherModBlocks.purpur_pillar, 8, 2);
		world.setBlock(i + 10, j + 4, k + 8, OtherModBlocks.purpur_block, 0, 2);
		world.setBlock(i + 8, j + 4, k + 9, OtherModBlocks.purpur_block, 0, 2);
		world.setBlock(i + 9, j + 4, k + 9, OtherModBlocks.purpur_block, 0, 2);
		world.setBlock(i + 10, j + 4, k + 9, OtherModBlocks.purpur_block, 0, 2);
		world.setBlock(i + 7, j + 4, k + 10, OtherModBlocks.purpur_stairs, 4, 2);
		world.setBlock(i + 8, j + 4, k + 10, OtherModBlocks.purpur_block, 0, 2);
		world.setBlock(i + 10, j + 4, k + 10, OtherModBlocks.purpur_block, 0, 2);
		world.setBlock(i + 11, j + 4, k + 10, OtherModBlocks.purpur_stairs, 5, 2);
		world.setBlock(i + 8, j + 4, k + 11, OtherModBlocks.purpur_block, 0, 2);
		world.setBlock(i + 9, j + 4, k + 11, OtherModBlocks.purpur_block, 0, 2);
		world.setBlock(i + 10, j + 4, k + 11, OtherModBlocks.purpur_block, 0, 2);
		world.setBlock(i + 8, j + 4, k + 12, OtherModBlocks.purpur_block, 0, 2);
		world.setBlock(i + 9, j + 4, k + 12, OtherModBlocks.purpur_block, 0, 2);
		world.setBlock(i + 10, j + 4, k + 12, OtherModBlocks.purpur_block, 0, 2);
		world.setBlock(i + 9, j + 4, k + 13, OtherModBlocks.purpur_block, 0, 2);
		world.setBlock(i + 10, j + 4, k + 13, OtherModBlocks.purpur_block, 0, 2);
		world.setBlock(i + 7, j + 4, k + 14, OtherModBlocks.purpur_stairs, 4, 2);
		world.setBlock(i + 8, j + 4, k + 14, OtherModBlocks.purpur_block, 0, 2);
		world.setBlock(i + 9, j + 4, k + 14, OtherModBlocks.purpur_block, 0, 2);
		world.setBlock(i + 10, j + 4, k + 14, OtherModBlocks.purpur_block, 0, 2);
		world.setBlock(i + 8, j + 4, k + 15, OtherModBlocks.purpur_block, 0, 2);
		world.setBlock(i + 9, j + 4, k + 15, OtherModBlocks.purpur_block, 0, 2);
		world.setBlock(i + 10, j + 4, k + 15, OtherModBlocks.purpur_block, 0, 2);
		world.setBlock(i + 8, j + 4, k + 16, OtherModBlocks.purpur_block, 0, 2);
		world.setBlock(i + 9, j + 4, k + 16, OtherModBlocks.purpur_block, 0, 2);
		world.setBlock(i + 10, j + 4, k + 16, OtherModBlocks.purpur_block, 0, 2);
		world.setBlock(i + 8, j + 4, k + 17, OtherModBlocks.purpur_block, 0, 2);
		world.setBlock(i + 9, j + 4, k + 17, OtherModBlocks.purpur_block, 0, 2);
		world.setBlock(i + 10, j + 4, k + 17, OtherModBlocks.purpur_block, 0, 2);
		world.setBlock(i + 7, j + 4, k + 18, OtherModBlocks.purpur_stairs, 4, 2);
		world.setBlock(i + 8, j + 4, k + 18, OtherModBlocks.purpur_block, 0, 2);
		world.setBlock(i + 9, j + 4, k + 18, OtherModBlocks.purpur_block, 0, 2);
		world.setBlock(i + 10, j + 4, k + 18, OtherModBlocks.purpur_block, 0, 2);
		world.setBlock(i + 11, j + 4, k + 18, OtherModBlocks.purpur_stairs, 5, 2);
		world.setBlock(i + 9, j + 4, k + 19, OtherModBlocks.purpur_block, 0, 2);
		world.setBlock(i + 10, j + 4, k + 19, OtherModBlocks.purpur_block, 0, 2);
		world.setBlock(i + 9, j + 4, k + 20, OtherModBlocks.purpur_pillar, 8, 2);
		world.setBlock(i + 9, j + 4, k + 21, OtherModBlocks.purpur_pillar, 8, 2);
		world.setBlock(i + 9, j + 4, k + 22, OtherModBlocks.purpur_pillar, 8, 2);
		world.setBlock(i + 9, j + 4, k + 23, OtherModBlocks.purpur_pillar, 8, 2);
		world.setBlock(i + 6, j + 5, k + 6, OtherModBlocks.purpur_stairs, 4, 2);
		world.setBlock(i + 7, j + 5, k + 6, OtherModBlocks.purpur_block, 0, 2);
		world.setBlock(i + 8, j + 5, k + 6, OtherModBlocks.purpur_block, 0, 2);
		world.setBlock(i + 9, j + 5, k + 6, OtherModBlocks.purpur_pillar, 8, 2);
		world.setBlock(i + 10, j + 5, k + 6, OtherModBlocks.purpur_block, 0, 2);
		world.setBlock(i + 11, j + 5, k + 6, OtherModBlocks.purpur_block, 0, 2);
		world.setBlock(i + 12, j + 5, k + 6, OtherModBlocks.purpur_stairs, 5, 2);
		world.setBlock(i + 7, j + 5, k + 7, OtherModBlocks.purpur_block, 0, 2);
		world.setBlock(i + 8, j + 5, k + 7, Blocks.obsidian, 0, 2);
		world.setBlock(i + 9, j + 5, k + 7, OtherModBlocks.purpur_pillar, 8, 2);
		world.setBlock(i + 7, j + 5, k + 8, OtherModBlocks.purpur_block, 0, 2);
		world.setBlock(i + 8, j + 5, k + 8, Blocks.obsidian, 0, 2);
		world.setBlock(i + 9, j + 5, k + 8, OtherModBlocks.purpur_pillar, 8, 2);
		world.setBlock(i + 10, j + 5, k + 8, Blocks.obsidian, 0, 2);
		world.setBlock(i + 11, j + 5, k + 8, OtherModBlocks.purpur_block, 0, 2);
		world.setBlock(i + 7, j + 5, k + 9, OtherModBlocks.purpur_block, 0, 2);
		world.setBlock(i + 8, j + 5, k + 9, Blocks.obsidian, 0, 2);
		world.setBlock(i + 9, j + 5, k + 9, OtherModBlocks.purpur_pillar, 8, 2);
		world.setBlock(i + 10, j + 5, k + 9, Blocks.obsidian, 0, 2);
		world.setBlock(i + 11, j + 5, k + 9, OtherModBlocks.purpur_block, 0, 2);
		world.setBlock(i + 6, j + 5, k + 10, OtherModBlocks.purpur_stairs, 4, 2);
		world.setBlock(i + 7, j + 5, k + 10, OtherModBlocks.purpur_block, 0, 2);
		world.setBlock(i + 8, j + 5, k + 10, Blocks.obsidian, 0, 2);
		world.setBlock(i + 9, j + 5, k + 10, OtherModBlocks.purpur_pillar, 8, 2);
		world.setBlock(i + 10, j + 5, k + 10, Blocks.obsidian, 0, 2);
		world.setBlock(i + 11, j + 5, k + 10, OtherModBlocks.purpur_block, 0, 2);
		world.setBlock(i + 12, j + 5, k + 10, OtherModBlocks.purpur_stairs, 5, 2);
		world.setBlock(i + 7, j + 5, k + 11, OtherModBlocks.purpur_block, 0, 2);
		world.setBlock(i + 8, j + 5, k + 11, Blocks.obsidian, 0, 2);
		world.setBlock(i + 9, j + 5, k + 11, OtherModBlocks.purpur_pillar, 8, 2);
		world.setBlock(i + 10, j + 5, k + 11, Blocks.obsidian, 0, 2);
		world.setBlock(i + 11, j + 5, k + 11, OtherModBlocks.purpur_block, 0, 2);
		world.setBlock(i + 7, j + 5, k + 12, OtherModBlocks.purpur_block, 0, 2);
		world.setBlock(i + 8, j + 5, k + 12, Blocks.obsidian, 0, 2);
		world.setBlock(i + 9, j + 5, k + 12, OtherModBlocks.purpur_pillar, 8, 2);
		world.setBlock(i + 10, j + 5, k + 12, Blocks.obsidian, 0, 2);
		world.setBlock(i + 11, j + 5, k + 12, OtherModBlocks.purpur_block, 0, 2);
		world.setBlock(i + 7, j + 5, k + 13, OtherModBlocks.purpur_block, 0, 2);
		world.setBlock(i + 8, j + 5, k + 13, Blocks.obsidian, 0, 2);
		world.setBlock(i + 9, j + 5, k + 13, OtherModBlocks.purpur_pillar, 8, 2);
		world.setBlock(i + 10, j + 5, k + 13, Blocks.obsidian, 0, 2);
		world.setBlock(i + 11, j + 5, k + 13, OtherModBlocks.purpur_block, 0, 2);
		world.setBlock(i + 6, j + 5, k + 14, OtherModBlocks.purpur_stairs, 4, 2);
		world.setBlock(i + 8, j + 5, k + 14, Blocks.obsidian, 0, 2);
		world.setBlock(i + 9, j + 5, k + 14, OtherModBlocks.purpur_pillar, 8, 2);
		world.setBlock(i + 10, j + 5, k + 14, Blocks.obsidian, 0, 2);
		world.setBlock(i + 11, j + 5, k + 14, OtherModBlocks.purpur_block, 0, 2);
		world.setBlock(i + 12, j + 5, k + 14, OtherModBlocks.purpur_stairs, 5, 2);
		world.setBlock(i + 7, j + 5, k + 15, OtherModBlocks.purpur_block, 0, 2);
		world.setBlock(i + 8, j + 5, k + 15, Blocks.obsidian, 0, 2);
		world.setBlock(i + 9, j + 5, k + 15, OtherModBlocks.purpur_pillar, 8, 2);
		world.setBlock(i + 10, j + 5, k + 15, Blocks.obsidian, 0, 2);
		world.setBlock(i + 11, j + 5, k + 15, OtherModBlocks.purpur_block, 0, 2);
		world.setBlock(i + 7, j + 5, k + 16, OtherModBlocks.purpur_block, 0, 2);
		world.setBlock(i + 8, j + 5, k + 16, Blocks.obsidian, 0, 2);
		world.setBlock(i + 9, j + 5, k + 16, OtherModBlocks.purpur_pillar, 8, 2);
		world.setBlock(i + 10, j + 5, k + 16, Blocks.obsidian, 0, 2);
		world.setBlock(i + 11, j + 5, k + 16, OtherModBlocks.purpur_block, 0, 2);
		world.setBlock(i + 7, j + 5, k + 17, OtherModBlocks.purpur_block, 0, 2);
		world.setBlock(i + 8, j + 5, k + 17, Blocks.obsidian, 0, 2);
		world.setBlock(i + 9, j + 5, k + 17, OtherModBlocks.purpur_pillar, 0, 2);
		world.setBlock(i + 10, j + 5, k + 17, Blocks.obsidian, 0, 2);
		world.setBlock(i + 11, j + 5, k + 17, OtherModBlocks.purpur_block, 0, 2);
		world.setBlock(i + 6, j + 5, k + 18, OtherModBlocks.purpur_stairs, 4, 2);
		world.setBlock(i + 7, j + 5, k + 18, OtherModBlocks.purpur_block, 0, 2);
		world.setBlock(i + 8, j + 5, k + 18, Blocks.obsidian, 0, 2);
		world.setBlock(i + 9, j + 5, k + 18, OtherModBlocks.purpur_pillar, 8, 2);
		world.setBlock(i + 10, j + 5, k + 18, Blocks.obsidian, 0, 2);
		world.setBlock(i + 11, j + 5, k + 18, OtherModBlocks.purpur_block, 0, 2);
		world.setBlock(i + 12, j + 5, k + 18, OtherModBlocks.purpur_stairs, 5, 2);
		world.setBlock(i + 7, j + 5, k + 19, OtherModBlocks.purpur_block, 0, 2);
		world.setBlock(i + 8, j + 5, k + 19, Blocks.obsidian, 0, 2);
		world.setBlock(i + 9, j + 5, k + 19, OtherModBlocks.purpur_pillar, 8, 2);
		world.setBlock(i + 10, j + 5, k + 19, Blocks.obsidian, 0, 2);
		world.setBlock(i + 11, j + 5, k + 19, OtherModBlocks.purpur_block, 0, 2);
		world.setBlock(i + 7, j + 5, k + 20, OtherModBlocks.purpur_block, 0, 2);
		world.setBlock(i + 9, j + 5, k + 20, OtherModBlocks.purpur_pillar, 8, 2);
		world.setBlock(i + 10, j + 5, k + 20, OtherModBlocks.purpur_block, 0, 2);
		world.setBlock(i + 11, j + 5, k + 20, OtherModBlocks.purpur_block, 0, 2);
		world.setBlock(i + 7, j + 5, k + 21, OtherModBlocks.purpur_block, 0, 2);
		world.setBlock(i + 8, j + 5, k + 21, OtherModBlocks.purpur_block, 0, 2);
		world.setBlock(i + 9, j + 5, k + 21, OtherModBlocks.purpur_pillar, 8, 2);
		world.setBlock(i + 10, j + 5, k + 21, OtherModBlocks.purpur_block, 0, 2);
		world.setBlock(i + 11, j + 5, k + 21, OtherModBlocks.purpur_block, 0, 2);
		world.setBlock(i + 8, j + 5, k + 22, OtherModBlocks.purpur_block, 0, 2);
		world.setBlock(i + 10, j + 5, k + 22, OtherModBlocks.purpur_block, 0, 2);
		world.setBlock(i + 8, j + 5, k + 23, OtherModBlocks.purpur_block, 0, 2);
		world.setBlock(i + 9, j + 5, k + 23, OtherModBlocks.purpur_pillar, 8, 2);
		world.setBlock(i + 10, j + 5, k + 23, OtherModBlocks.purpur_block, 0, 2);
		world.setBlock(i + 9, j + 5, k + 24, OtherModBlocks.purpur_pillar, 8, 2);
		world.setBlock(i + 9, j + 5, k + 25, OtherModBlocks.purpur_pillar, 8, 2);
		world.setBlock(i + 5, j + 6, k + 6, OtherModBlocks.purpur_stairs, 4, 2);
		world.setBlock(i + 6, j + 6, k + 6, OtherModBlocks.purpur_block, 0, 2);
		world.setBlock(i + 7, j + 6, k + 6, OtherModBlocks.purpur_block, 0, 2);
		world.setBlock(i + 9, j + 6, k + 6, OtherModBlocks.purpur_block, 0, 2);
		world.setBlock(i + 10, j + 6, k + 6, OtherModBlocks.purpur_block, 0, 2);
		world.setBlock(i + 11, j + 6, k + 6, OtherModBlocks.purpur_block, 0, 2);
		world.setBlock(i + 12, j + 6, k + 6, OtherModBlocks.purpur_block, 0, 2);
		world.setBlock(i + 13, j + 6, k + 6, OtherModBlocks.purpur_stairs, 5, 2);
		world.setBlock(i + 6, j + 6, k + 7, OtherModBlocks.purpur_block, 0, 2);
		world.setBlock(i + 12, j + 6, k + 7, OtherModBlocks.purpur_block, 0, 2);
		world.setBlock(i + 6, j + 6, k + 8, OtherModBlocks.purpur_block, 0, 2);
		world.setBlock(i + 7, j + 6, k + 8, OtherModBlocks.purpur_block, 0, 2);
		world.setBlock(i + 12, j + 6, k + 8, OtherModBlocks.purpur_block, 0, 2);
		world.setBlock(i + 6, j + 6, k + 9, OtherModBlocks.purpur_block, 0, 2);
		world.setBlock(i + 12, j + 6, k + 9, OtherModBlocks.purpur_block, 0, 2);
		world.setBlock(i + 5, j + 6, k + 10, OtherModBlocks.purpur_stairs, 4, 2);
		world.setBlock(i + 7, j + 6, k + 10, OtherModBlocks.purpur_block, 0, 2);
		world.setBlock(i + 12, j + 6, k + 10, OtherModBlocks.purpur_block, 0, 2);
		world.setBlock(i + 13, j + 6, k + 10, OtherModBlocks.purpur_stairs, 5, 2);
		world.setBlock(i + 6, j + 6, k + 11, OtherModBlocks.purpur_block, 0, 2);
		world.setBlock(i + 7, j + 6, k + 11, OtherModBlocks.purpur_block, 0, 2);
		world.setBlock(i + 12, j + 6, k + 11, OtherModBlocks.purpur_block, 0, 2);
		world.setBlock(i + 6, j + 6, k + 12, OtherModBlocks.purpur_block, 0, 2);
		world.setBlock(i + 7, j + 6, k + 12, OtherModBlocks.purpur_block, 0, 2);
		world.setBlock(i + 12, j + 6, k + 12, OtherModBlocks.purpur_block, 0, 2);
		world.setBlock(i + 6, j + 6, k + 13, OtherModBlocks.purpur_block, 0, 2);
		world.setBlock(i + 7, j + 6, k + 13, OtherModBlocks.purpur_block, 0, 2);
		world.setBlock(i + 5, j + 6, k + 14, OtherModBlocks.purpur_stairs, 4, 2);
		world.setBlock(i + 6, j + 6, k + 14, OtherModBlocks.purpur_block, 0, 2);
		world.setBlock(i + 7, j + 6, k + 14, OtherModBlocks.purpur_block, 0, 2);
		world.setBlock(i + 12, j + 6, k + 14, OtherModBlocks.purpur_block, 0, 2);
		world.setBlock(i + 13, j + 6, k + 14, OtherModBlocks.purpur_stairs, 5, 2);
		world.setBlock(i + 6, j + 6, k + 15, OtherModBlocks.purpur_block, 0, 2);
		world.setBlock(i + 7, j + 6, k + 15, OtherModBlocks.purpur_block, 0, 2);
		world.setBlock(i + 12, j + 6, k + 15, OtherModBlocks.purpur_block, 0, 2);
		world.setBlock(i + 6, j + 6, k + 16, OtherModBlocks.purpur_block, 0, 2);
		world.setBlock(i + 7, j + 6, k + 16, OtherModBlocks.purpur_stairs, 3, 2);
		world.setBlock(i + 12, j + 6, k + 16, OtherModBlocks.purpur_block, 0, 2);
		world.setBlock(i + 6, j + 6, k + 17, OtherModBlocks.purpur_block, 0, 2);
		world.setBlock(i + 9, j + 6, k + 17, OtherModBlocks.purpur_pillar, 0, 2);
		world.setBlock(i + 12, j + 6, k + 17, OtherModBlocks.purpur_block, 0, 2);
		world.setBlock(i + 5, j + 6, k + 18, OtherModBlocks.purpur_stairs, 4, 2);
		world.setBlock(i + 6, j + 6, k + 18, OtherModBlocks.purpur_block, 0, 2);
		world.setBlock(i + 12, j + 6, k + 18, OtherModBlocks.purpur_block, 0, 2);
		world.setBlock(i + 12, j + 6, k + 19, OtherModBlocks.purpur_block, 0, 2);
		world.setBlock(i + 6, j + 6, k + 20, OtherModBlocks.purpur_block, 0, 2);
		world.setBlock(i + 12, j + 6, k + 20, OtherModBlocks.purpur_block, 0, 2);
		world.setBlock(i + 6, j + 6, k + 21, OtherModBlocks.purpur_block, 0, 2);
		world.setBlock(i + 12, j + 6, k + 21, OtherModBlocks.purpur_block, 0, 2);
		world.setBlock(i + 7, j + 6, k + 22, OtherModBlocks.purpur_block, 0, 2);
		world.setBlock(i + 11, j + 6, k + 22, OtherModBlocks.purpur_block, 0, 2);
		world.setBlock(i + 7, j + 6, k + 23, OtherModBlocks.purpur_block, 0, 2);
		world.setBlock(i + 8, j + 6, k + 23, OtherModBlocks.purpur_block, 0, 2);
		world.setBlock(i + 9, j + 6, k + 23, OtherModBlocks.purpur_block, 0, 2);
		world.setBlock(i + 10, j + 6, k + 23, OtherModBlocks.purpur_block, 0, 2);
		world.setBlock(i + 11, j + 6, k + 23, OtherModBlocks.purpur_block, 0, 2);
		world.setBlock(i + 8, j + 6, k + 24, OtherModBlocks.purpur_block, 0, 2);
		world.setBlock(i + 9, j + 6, k + 24, OtherModBlocks.purpur_block, 0, 2);
		world.setBlock(i + 10, j + 6, k + 24, OtherModBlocks.purpur_block, 0, 2);
		world.setBlock(i + 9, j + 6, k + 25, OtherModBlocks.purpur_pillar, 8, 2);
		world.setBlock(i + 9, j + 6, k + 26, OtherModBlocks.purpur_pillar, 8, 2);
		world.setBlock(i + 5, j + 7, k + 5, OtherModBlocks.purpur_stairs, 6, 2);
		world.setBlock(i + 9, j + 7, k + 5, OtherModBlocks.purpur_stairs, 6, 2);
		world.setBlock(i + 13, j + 7, k + 5, OtherModBlocks.purpur_stairs, 6, 2);
		world.setBlock(i + 5, j + 7, k + 6, OtherModBlocks.purpur_block, 0, 2);
		world.setBlock(i + 6, j + 7, k + 6, OtherModBlocks.purpur_block, 0, 2);
		world.setBlock(i + 7, j + 7, k + 6, OtherModBlocks.purpur_block, 0, 2);
		world.setBlock(i + 8, j + 7, k + 6, OtherModBlocks.purpur_block, 0, 2);
		world.setBlock(i + 9, j + 7, k + 6, OtherModBlocks.purpur_block, 0, 2);
		world.setBlock(i + 10, j + 7, k + 6, OtherModBlocks.purpur_block, 0, 2);
		world.setBlock(i + 11, j + 7, k + 6, OtherModBlocks.purpur_block, 0, 2);
		world.setBlock(i + 12, j + 7, k + 6, OtherModBlocks.purpur_block, 0, 2);
		world.setBlock(i + 13, j + 7, k + 6, OtherModBlocks.purpur_block, 0, 2);
		world.setBlock(i + 5, j + 7, k + 7, OtherModBlocks.purpur_block, 0, 2);
		world.setBlock(i + 6, j + 7, k + 7, OtherModBlocks.purpur_block, 0, 2);
		world.setBlock(i + 7, j + 7, k + 7, OtherModBlocks.purpur_block, 0, 2);
		world.setBlock(i + 13, j + 7, k + 7, OtherModBlocks.purpur_block, 0, 2);
		world.setBlock(i + 5, j + 7, k + 8, OtherModBlocks.purpur_block, 0, 2);
		world.setBlock(i + 6, j + 7, k + 8, OtherModBlocks.purpur_block, 0, 2);
		world.setBlock(i + 7, j + 7, k + 8, OtherModBlocks.purpur_block, 0, 2);
		world.setBlock(i + 13, j + 7, k + 8, OtherModBlocks.purpur_block, 0, 2);
		world.setBlock(i + 5, j + 7, k + 9, OtherModBlocks.purpur_block, 0, 2);
		world.setBlock(i + 6, j + 7, k + 9, OtherModBlocks.purpur_block, 0, 2);
		world.setBlock(i + 7, j + 7, k + 9, OtherModBlocks.purpur_block, 0, 2);
		world.setBlock(i + 13, j + 7, k + 9, OtherModBlocks.purpur_block, 0, 2);
		world.setBlock(i + 6, j + 7, k + 10, OtherModBlocks.purpur_block, 0, 2);
		world.setBlock(i + 7, j + 7, k + 10, OtherModBlocks.purpur_block, 0, 2);
		world.setBlock(i + 13, j + 7, k + 10, OtherModBlocks.purpur_block, 0, 2);
		world.setBlock(i + 5, j + 7, k + 11, OtherModBlocks.purpur_block, 0, 2);
		world.setBlock(i + 6, j + 7, k + 11, OtherModBlocks.purpur_block, 0, 2);
		world.setBlock(i + 7, j + 7, k + 11, OtherModBlocks.purpur_block, 0, 2);
		world.setBlock(i + 13, j + 7, k + 11, OtherModBlocks.purpur_block, 0, 2);
		world.setBlock(i + 5, j + 7, k + 12, OtherModBlocks.purpur_block, 0, 2);
		world.setBlock(i + 6, j + 7, k + 12, OtherModBlocks.purpur_stairs, 3, 2);
		world.setBlock(i + 7, j + 7, k + 12, OtherModBlocks.purpur_stairs, 3, 2);
		world.setBlock(i + 13, j + 7, k + 12, OtherModBlocks.purpur_block, 0, 2);
		world.setBlock(i + 5, j + 7, k + 13, OtherModBlocks.purpur_block, 0, 2);
		world.setBlock(i + 13, j + 7, k + 13, OtherModBlocks.purpur_block, 0, 2);
		world.setBlock(i + 5, j + 7, k + 14, OtherModBlocks.purpur_block, 0, 2);
		world.setBlock(i + 13, j + 7, k + 14, OtherModBlocks.purpur_block, 0, 2);
		world.setBlock(i + 5, j + 7, k + 15, OtherModBlocks.purpur_block, 0, 2);
		world.setBlock(i + 13, j + 7, k + 15, OtherModBlocks.purpur_block, 0, 2);
		world.setBlock(i + 5, j + 7, k + 16, OtherModBlocks.purpur_block, 0, 2);
		world.setBlock(i + 13, j + 7, k + 16, OtherModBlocks.purpur_block, 0, 2);
		world.setBlock(i + 5, j + 7, k + 17, OtherModBlocks.purpur_block, 0, 2);
		world.setBlock(i + 9, j + 7, k + 17, OtherModBlocks.purpur_pillar, 0, 2);
		world.setBlock(i + 13, j + 7, k + 17, OtherModBlocks.purpur_block, 0, 2);
		world.setBlock(i + 5, j + 7, k + 18, OtherModBlocks.purpur_block, 0, 2);
		world.setBlock(i + 13, j + 7, k + 18, OtherModBlocks.purpur_block, 0, 2);
		world.setBlock(i + 5, j + 7, k + 19, OtherModBlocks.purpur_block, 0, 2);
		world.setBlock(i + 13, j + 7, k + 19, OtherModBlocks.purpur_block, 0, 2);
		world.setBlock(i + 5, j + 7, k + 20, OtherModBlocks.purpur_block, 0, 2);
		world.setBlock(i + 13, j + 7, k + 20, OtherModBlocks.purpur_block, 0, 2);
		world.setBlock(i + 6, j + 7, k + 21, OtherModBlocks.purpur_block, 0, 2);
		world.setBlock(i + 12, j + 7, k + 21, OtherModBlocks.purpur_block, 0, 2);
		world.setBlock(i + 6, j + 7, k + 22, OtherModBlocks.purpur_block, 0, 2);
		world.setBlock(i + 7, j + 7, k + 23, OtherModBlocks.purpur_block, 0, 2);
		world.setBlock(i + 11, j + 7, k + 23, OtherModBlocks.purpur_block, 0, 2);
		world.setBlock(i + 7, j + 7, k + 24, OtherModBlocks.purpur_block, 0, 2);
		world.setBlock(i + 8, j + 7, k + 24, Blocks.chest, 2, 2);
		world.setBlock(i + 10, j + 7, k + 24, Blocks.chest, 2, 2);
		world.setBlock(i + 11, j + 7, k + 24, OtherModBlocks.purpur_block, 0, 2);
		world.setBlock(i + 8, j + 7, k + 25, OtherModBlocks.purpur_block, 0, 2);
		world.setBlock(i + 9, j + 7, k + 25, OtherModBlocks.purpur_block, 0, 2);
		world.setBlock(i + 10, j + 7, k + 25, OtherModBlocks.purpur_block, 0, 2);
		world.setBlock(i + 9, j + 7, k + 26, OtherModBlocks.purpur_block, 0, 2);
		world.setBlock(i + 4, j + 8, k + 4, OtherModBlocks.purpur_stairs, 6, 2);
		world.setBlock(i + 5, j + 8, k + 4, OtherModBlocks.purpur_stairs, 6, 2);
		world.setBlock(i + 6, j + 8, k + 4, OtherModBlocks.purpur_stairs, 6, 2);
		world.setBlock(i + 7, j + 8, k + 4, OtherModBlocks.purpur_stairs, 6, 2);
		world.setBlock(i + 8, j + 8, k + 4, OtherModBlocks.purpur_stairs, 6, 2);
		world.setBlock(i + 9, j + 8, k + 4, OtherModBlocks.purpur_stairs, 2, 2);
		world.setBlock(i + 11, j + 8, k + 4, OtherModBlocks.purpur_stairs, 6, 2);
		world.setBlock(i + 12, j + 8, k + 4, OtherModBlocks.purpur_stairs, 2, 2);
		world.setBlock(i + 13, j + 8, k + 4, OtherModBlocks.purpur_stairs, 6, 2);
		world.setBlock(i + 14, j + 8, k + 4, OtherModBlocks.purpur_stairs, 5, 2);
		world.setBlock(i + 4, j + 8, k + 5, OtherModBlocks.purpur_stairs, 4, 2);
		world.setBlock(i + 5, j + 8, k + 5, OtherModBlocks.purpur_block, 0, 2);
		world.setBlock(i + 6, j + 8, k + 5, OtherModBlocks.purpur_block, 0, 2);
		world.setBlock(i + 7, j + 8, k + 5, OtherModBlocks.purpur_block, 0, 2);
		world.setBlock(i + 9, j + 8, k + 5, OtherModBlocks.purpur_block, 0, 2);
		world.setBlock(i + 10, j + 8, k + 5, OtherModBlocks.purpur_block, 0, 2);
		world.setBlock(i + 11, j + 8, k + 5, OtherModBlocks.purpur_block, 0, 2);
		world.setBlock(i + 12, j + 8, k + 5, OtherModBlocks.purpur_block, 0, 2);
		world.setBlock(i + 13, j + 8, k + 5, OtherModBlocks.purpur_block, 0, 2);
		world.setBlock(i + 14, j + 8, k + 5, OtherModBlocks.purpur_stairs, 5, 2);
		world.setBlock(i + 4, j + 8, k + 6, OtherModBlocks.purpur_stairs, 0, 2);
		world.setBlock(i + 5, j + 8, k + 6, OtherModBlocks.purpur_block, 0, 2);
		world.setBlock(i + 6, j + 8, k + 6, OtherModBlocks.purpur_block, 0, 2);
		world.setBlock(i + 7, j + 8, k + 6, OtherModBlocks.purpur_block, 0, 2);
		world.setBlock(i + 8, j + 8, k + 6, OtherModBlocks.purpur_block, 0, 2);
		world.setBlock(i + 9, j + 8, k + 6, OtherModBlocks.purpur_block, 0, 2);
		world.setBlock(i + 10, j + 8, k + 6, OtherModBlocks.purpur_block, 0, 2);
		world.setBlock(i + 11, j + 8, k + 6, OtherModBlocks.purpur_block, 0, 2);
		world.setBlock(i + 12, j + 8, k + 6, OtherModBlocks.purpur_block, 0, 2);
		world.setBlock(i + 13, j + 8, k + 6, OtherModBlocks.purpur_block, 0, 2);
		world.setBlock(i + 14, j + 8, k + 6, OtherModBlocks.purpur_stairs, 1, 2);
		world.setBlock(i + 4, j + 8, k + 7, OtherModBlocks.purpur_stairs, 4, 2);
		world.setBlock(i + 5, j + 8, k + 7, OtherModBlocks.purpur_block, 0, 2);
		world.setBlock(i + 6, j + 8, k + 7, OtherModBlocks.purpur_block, 0, 2);
		world.setBlock(i + 7, j + 8, k + 7, OtherModBlocks.purpur_block, 0, 2);
		world.setBlock(i + 8, j + 8, k + 7, OtherModBlocks.purpur_block, 0, 2);
		world.setBlock(i + 9, j + 8, k + 7, OtherModBlocks.purpur_block, 0, 2);
		world.setBlock(i + 10, j + 8, k + 7, OtherModBlocks.purpur_block, 0, 2);
		world.setBlock(i + 11, j + 8, k + 7, OtherModBlocks.purpur_block, 0, 2);
		world.setBlock(i + 12, j + 8, k + 7, OtherModBlocks.purpur_block, 0, 2);
		world.setBlock(i + 14, j + 8, k + 7, OtherModBlocks.purpur_stairs, 5, 2);
		world.setBlock(i + 4, j + 8, k + 8, OtherModBlocks.purpur_stairs, 4, 2);
		world.setBlock(i + 5, j + 8, k + 8, OtherModBlocks.purpur_block, 0, 2);
		world.setBlock(i + 6, j + 8, k + 8, OtherModBlocks.purpur_block, 0, 2);
		world.setBlock(i + 8, j + 8, k + 8, OtherModBlocks.purpur_block, 0, 2);
		world.setBlock(i + 9, j + 8, k + 8, OtherModBlocks.purpur_block, 0, 2);
		world.setBlock(i + 10, j + 8, k + 8, OtherModBlocks.purpur_block, 0, 2);
		world.setBlock(i + 11, j + 8, k + 8, OtherModBlocks.purpur_block, 0, 2);
		world.setBlock(i + 12, j + 8, k + 8, OtherModBlocks.purpur_block, 0, 2);
		world.setBlock(i + 13, j + 8, k + 8, OtherModBlocks.purpur_block, 0, 2);
		world.setBlock(i + 14, j + 8, k + 8, OtherModBlocks.purpur_stairs, 5, 2);
		world.setBlock(i + 4, j + 8, k + 9, OtherModBlocks.purpur_stairs, 0, 2);
		world.setBlock(i + 5, j + 8, k + 9, OtherModBlocks.purpur_block, 0, 2);
		world.setBlock(i + 7, j + 8, k + 9, OtherModBlocks.purpur_block, 0, 2);
		world.setBlock(i + 8, j + 8, k + 9, OtherModBlocks.purpur_block, 0, 2);
		world.setBlock(i + 9, j + 8, k + 9, OtherModBlocks.purpur_block, 0, 2);
		world.setBlock(i + 10, j + 8, k + 9, OtherModBlocks.purpur_block, 0, 2);
		world.setBlock(i + 11, j + 8, k + 9, OtherModBlocks.purpur_block, 0, 2);
		world.setBlock(i + 12, j + 8, k + 9, OtherModBlocks.purpur_block, 0, 2);
		world.setBlock(i + 13, j + 8, k + 9, OtherModBlocks.purpur_block, 0, 2);
		world.setBlock(i + 14, j + 8, k + 9, OtherModBlocks.purpur_stairs, 1, 2);
		world.setBlock(i + 4, j + 8, k + 10, OtherModBlocks.purpur_stairs, 4, 2);
		world.setBlock(i + 5, j + 8, k + 10, OtherModBlocks.purpur_block, 0, 2);
		world.setBlock(i + 6, j + 8, k + 10, OtherModBlocks.purpur_block, 0, 2);
		world.setBlock(i + 7, j + 8, k + 10, OtherModBlocks.purpur_block, 0, 2);
		world.setBlock(i + 8, j + 8, k + 10, OtherModBlocks.purpur_block, 0, 2);
		world.setBlock(i + 9, j + 8, k + 10, OtherModBlocks.purpur_block, 0, 2);
		world.setBlock(i + 10, j + 8, k + 10, OtherModBlocks.purpur_block, 0, 2);
		world.setBlock(i + 11, j + 8, k + 10, OtherModBlocks.purpur_block, 0, 2);
		world.setBlock(i + 12, j + 8, k + 10, OtherModBlocks.purpur_block, 0, 2);
		world.setBlock(i + 13, j + 8, k + 10, OtherModBlocks.purpur_block, 0, 2);
		world.setBlock(i + 4, j + 8, k + 11, OtherModBlocks.purpur_stairs, 7, 2);
		world.setBlock(i + 5, j + 8, k + 11, OtherModBlocks.purpur_block, 0, 2);
		world.setBlock(i + 6, j + 8, k + 11, OtherModBlocks.purpur_stairs, 3, 2);
		world.setBlock(i + 7, j + 8, k + 11, OtherModBlocks.purpur_stairs, 3, 2);
		world.setBlock(i + 8, j + 8, k + 11, OtherModBlocks.purpur_block, 0, 2);
		world.setBlock(i + 9, j + 8, k + 11, OtherModBlocks.purpur_block, 0, 2);
		world.setBlock(i + 10, j + 8, k + 11, OtherModBlocks.purpur_block, 0, 2);
		world.setBlock(i + 11, j + 8, k + 11, OtherModBlocks.purpur_block, 0, 2);
		world.setBlock(i + 12, j + 8, k + 11, OtherModBlocks.purpur_block, 0, 2);
		world.setBlock(i + 13, j + 8, k + 11, OtherModBlocks.purpur_block, 0, 2);
		world.setBlock(i + 14, j + 8, k + 11, OtherModBlocks.purpur_stairs, 7, 2);
		world.setBlock(i + 5, j + 8, k + 12, OtherModBlocks.purpur_block, 0, 2);
		world.setBlock(i + 5, j + 8, k + 13, OtherModBlocks.purpur_block, 0, 2);
		world.setBlock(i + 13, j + 8, k + 13, OtherModBlocks.purpur_block, 0, 2);
		world.setBlock(i + 5, j + 8, k + 14, OtherModBlocks.purpur_block, 0, 2);
		world.setBlock(i + 13, j + 8, k + 14, OtherModBlocks.purpur_block, 0, 2);
		world.setBlock(i + 4, j + 8, k + 15, OtherModBlocks.purpur_stairs, 4, 2);
		world.setBlock(i + 5, j + 8, k + 15, OtherModBlocks.purpur_block, 0, 2);
		world.setBlock(i + 13, j + 8, k + 15, OtherModBlocks.purpur_block, 0, 2);
		world.setBlock(i + 14, j + 8, k + 15, OtherModBlocks.purpur_stairs, 5, 2);
		world.setBlock(i + 5, j + 8, k + 16, OtherModBlocks.purpur_block, 0, 2);
		world.setBlock(i + 13, j + 8, k + 16, OtherModBlocks.purpur_block, 0, 2);
		world.setBlock(i + 5, j + 8, k + 17, OtherModBlocks.purpur_block, 0, 2);
		world.setBlock(i + 9, j + 8, k + 17, OtherModBlocks.purpur_pillar, 0, 2);
		world.setBlock(i + 13, j + 8, k + 17, OtherModBlocks.purpur_block, 0, 2);
		world.setBlock(i + 4, j + 8, k + 18, OtherModBlocks.purpur_stairs, 4, 2);
		world.setBlock(i + 5, j + 8, k + 18, OtherModBlocks.purpur_block, 0, 2);
		world.setBlock(i + 13, j + 8, k + 18, OtherModBlocks.purpur_block, 0, 2);
		world.setBlock(i + 14, j + 8, k + 18, OtherModBlocks.purpur_stairs, 5, 2);
		world.setBlock(i + 5, j + 8, k + 19, OtherModBlocks.purpur_block, 0, 2);
		world.setBlock(i + 5, j + 8, k + 20, OtherModBlocks.purpur_block, 0, 2);
		world.setBlock(i + 13, j + 8, k + 20, OtherModBlocks.purpur_block, 0, 2);
		world.setBlock(i + 6, j + 8, k + 21, OtherModBlocks.purpur_block, 0, 2);
		world.setBlock(i + 12, j + 8, k + 21, OtherModBlocks.purpur_block, 0, 2);
		world.setBlock(i + 6, j + 8, k + 22, OtherModBlocks.purpur_block, 0, 2);
		world.setBlock(i + 12, j + 8, k + 22, OtherModBlocks.purpur_block, 0, 2);
		world.setBlock(i + 7, j + 8, k + 23, OtherModBlocks.purpur_block, 0, 2);
		world.setBlock(i + 11, j + 8, k + 23, OtherModBlocks.purpur_block, 0, 2);
		world.setBlock(i + 7, j + 8, k + 24, OtherModBlocks.purpur_block, 0, 2);
		world.setBlock(i + 11, j + 8, k + 24, OtherModBlocks.purpur_block, 0, 2);
		world.setBlock(i + 8, j + 8, k + 25, OtherModBlocks.purpur_block, 0, 2);
		world.setBlock(i + 9, j + 8, k + 25, OtherModBlocks.purpur_block, 0, 2);
		world.setBlock(i + 10, j + 8, k + 25, OtherModBlocks.purpur_block, 0, 2);
		world.setBlock(i + 9, j + 8, k + 26, OtherModBlocks.purpur_pillar, 8, 2);
		world.setBlock(i + 9, j + 8, k + 27, OtherModBlocks.purpur_pillar, 8, 2);
		world.setBlock(i + 4, j + 9, k + 4, OtherModBlocks.end_rod, 1, 2);
		world.setBlock(i + 14, j + 9, k + 4, OtherModBlocks.end_rod, 1, 2);
		world.setBlock(i + 5, j + 9, k + 5, OtherModBlocks.purpur_pillar, 0, 2);
		world.setBlock(i + 6, j + 9, k + 5, OtherModBlocks.end_bricks, 0, 2);
		world.setBlock(i + 7, j + 9, k + 5, OtherModBlocks.end_bricks, 0, 2);
		world.setBlock(i + 8, j + 9, k + 5, OtherModBlocks.end_bricks, 0, 2);
		world.setBlock(i + 9, j + 9, k + 5, OtherModBlocks.purpur_pillar, 0, 2);
		world.setBlock(i + 10, j + 9, k + 5, OtherModBlocks.end_bricks, 0, 2);
		world.setBlock(i + 12, j + 9, k + 5, OtherModBlocks.end_bricks, 0, 2);
		world.setBlock(i + 13, j + 9, k + 5, OtherModBlocks.purpur_pillar, 0, 2);
		world.setBlock(i + 5, j + 9, k + 6, OtherModBlocks.end_bricks, 0, 2);
		world.setBlock(i + 9, j + 9, k + 6, OtherModBlocks.purpur_pillar, 0, 2);
		world.setBlock(i + 5, j + 9, k + 7, OtherModBlocks.end_bricks, 0, 2);
		world.setBlock(i + 13, j + 9, k + 7, OtherModBlocks.end_bricks, 0, 2);
		world.setBlock(i + 5, j + 9, k + 8, OtherModBlocks.end_bricks, 0, 2);
		world.setBlock(i + 13, j + 9, k + 8, OtherModBlocks.end_bricks, 0, 2);
		world.setBlock(i + 5, j + 9, k + 9, OtherModBlocks.end_bricks, 0, 2);
		world.setBlock(i + 13, j + 9, k + 9, OtherModBlocks.end_bricks, 0, 2);
		world.setBlock(i + 5, j + 9, k + 10, OtherModBlocks.purpur_pillar, 0, 2);
		world.setBlock(i + 8, j + 9, k + 10, OtherModBlocks.purpur_block, 0, 2);
		world.setBlock(i + 9, j + 9, k + 10, OtherModBlocks.purpur_block, 0, 2);
		world.setBlock(i + 12, j + 9, k + 10, OtherModBlocks.purpur_block, 0, 2);
		world.setBlock(i + 13, j + 9, k + 10, OtherModBlocks.purpur_pillar, 0, 2);
		world.setBlock(i + 5, j + 9, k + 11, OtherModBlocks.purpur_block, 0, 2);
		world.setBlock(i + 8, j + 9, k + 11, OtherModBlocks.purpur_block, 0, 2);
		world.setBlock(i + 9, j + 9, k + 11, OtherModBlocks.purpur_block, 0, 2);
		world.setBlock(i + 10, j + 9, k + 11, OtherModBlocks.purpur_stairs, 2, 2);
		world.setBlock(i + 12, j + 9, k + 11, OtherModBlocks.purpur_block, 0, 2);
		world.setBlock(i + 13, j + 9, k + 11, OtherModBlocks.purpur_block, 0, 2);
		world.setBlock(i + 5, j + 9, k + 12, OtherModBlocks.purpur_block, 0, 2);
		world.setBlock(i + 8, j + 9, k + 12, OtherModBlocks.purpur_block, 0, 2);
		world.setBlock(i + 9, j + 9, k + 12, OtherModBlocks.purpur_block, 0, 2);
		world.setBlock(i + 10, j + 9, k + 12, OtherModBlocks.purpur_block, 0, 2);
		world.setBlock(i + 11, j + 9, k + 12, OtherModBlocks.purpur_block, 0, 2);
		world.setBlock(i + 12, j + 9, k + 12, OtherModBlocks.purpur_block, 0, 2);
		world.setBlock(i + 13, j + 9, k + 12, OtherModBlocks.purpur_block, 0, 2);
		world.setBlock(i + 5, j + 9, k + 13, OtherModBlocks.purpur_block, 0, 2);
		world.setBlock(i + 13, j + 9, k + 13, OtherModBlocks.purpur_block, 0, 2);
		world.setBlock(i + 5, j + 9, k + 14, OtherModBlocks.purpur_block, 0, 2);
		world.setBlock(i + 13, j + 9, k + 14, OtherModBlocks.purpur_block, 0, 2);
		world.setBlock(i + 5, j + 9, k + 16, OtherModBlocks.purpur_block, 0, 2);
		world.setBlock(i + 13, j + 9, k + 16, OtherModBlocks.purpur_block, 0, 2);
		world.setBlock(i + 5, j + 9, k + 17, OtherModBlocks.purpur_block, 0, 2);
		world.setBlock(i + 9, j + 9, k + 17, OtherModBlocks.purpur_pillar, 0, 2);
		world.setBlock(i + 5, j + 9, k + 19, OtherModBlocks.purpur_block, 0, 2);
		world.setBlock(i + 13, j + 9, k + 19, OtherModBlocks.purpur_block, 0, 2);
		world.setBlock(i + 5, j + 9, k + 20, OtherModBlocks.purpur_block, 0, 2);
		world.setBlock(i + 13, j + 9, k + 20, OtherModBlocks.purpur_block, 0, 2);
		world.setBlock(i + 6, j + 9, k + 21, OtherModBlocks.purpur_block, 0, 2);
		world.setBlock(i + 12, j + 9, k + 21, OtherModBlocks.purpur_block, 0, 2);
		world.setBlock(i + 6, j + 9, k + 22, OtherModBlocks.purpur_block, 0, 2);
		world.setBlock(i + 12, j + 9, k + 22, OtherModBlocks.purpur_block, 0, 2);
		world.setBlock(i + 7, j + 9, k + 23, OtherModBlocks.purpur_block, 0, 2);
		world.setBlock(i + 11, j + 9, k + 23, OtherModBlocks.purpur_block, 0, 2);
		world.setBlock(i + 7, j + 9, k + 24, OtherModBlocks.purpur_block, 0, 2);
		world.setBlock(i + 11, j + 9, k + 24, OtherModBlocks.purpur_block, 0, 2);
		world.setBlock(i + 8, j + 9, k + 25, OtherModBlocks.purpur_block, 0, 2);
		world.setBlock(i + 9, j + 9, k + 25, OtherModBlocks.end_rod, 2, 2);
		world.setBlock(i + 10, j + 9, k + 25, OtherModBlocks.purpur_block, 0, 2);
		world.setBlock(i + 9, j + 9, k + 26, OtherModBlocks.purpur_block, 0, 2);
		world.setBlock(i + 9, j + 9, k + 27, OtherModBlocks.purpur_pillar, 8, 2);
		world.setBlock(i + 9, j + 9, k + 28, OtherModBlocks.purpur_pillar, 8, 2);
		world.setBlock(i + 5, j + 10, k + 5, OtherModBlocks.purpur_pillar, 0, 2);
		world.setBlock(i + 6, j + 10, k + 5, OtherModBlocks.end_bricks, 0, 2);
		world.setBlock(i + 8, j + 10, k + 5, OtherModBlocks.end_bricks, 0, 2);
		world.setBlock(i + 9, j + 10, k + 5, OtherModBlocks.purpur_pillar, 0, 2);
		world.setBlock(i + 10, j + 10, k + 5, OtherModBlocks.end_bricks, 0, 2);
		world.setBlock(i + 11, j + 10, k + 5, Blocks.stained_glass, 2, 2);
		world.setBlock(i + 12, j + 10, k + 5, OtherModBlocks.end_bricks, 0, 2);;
		world.setBlock(i + 5, j + 10, k + 6, OtherModBlocks.end_bricks, 0, 2);
		world.setBlock(i + 9, j + 10, k + 6, Blocks.brewing_stand, 5, 2);
		world.setBlock(i + 13, j + 10, k + 6, OtherModBlocks.end_bricks, 0, 2);
		world.setBlock(i + 5, j + 10, k + 7, Blocks.stained_glass, 2, 2);
		world.setBlock(i + 13, j + 10, k + 7, Blocks.stained_glass, 2, 2);
		world.setBlock(i + 5, j + 10, k + 8, Blocks.stained_glass, 2, 2);
		world.setBlock(i + 5, j + 10, k + 9, OtherModBlocks.end_bricks, 0, 2);
		world.setBlock(i + 13, j + 10, k + 9, OtherModBlocks.end_bricks, 0, 2);
		world.setBlock(i + 5, j + 10, k + 10, OtherModBlocks.purpur_pillar, 0, 2);
		world.setBlock(i + 8, j + 10, k + 10, OtherModBlocks.purpur_block, 0, 2);
		world.setBlock(i + 9, j + 10, k + 10, OtherModBlocks.purpur_block, 0, 2);
		world.setBlock(i + 12, j + 10, k + 10, OtherModBlocks.purpur_block, 0, 2);
		world.setBlock(i + 13, j + 10, k + 10, OtherModBlocks.purpur_pillar, 0, 2);
		world.setBlock(i + 5, j + 10, k + 11, OtherModBlocks.purpur_block, 0, 2);
		world.setBlock(i + 8, j + 10, k + 11, OtherModBlocks.purpur_block, 0, 2);
		world.setBlock(i + 9, j + 10, k + 11, OtherModBlocks.purpur_block, 0, 2);
		world.setBlock(i + 12, j + 10, k + 11, OtherModBlocks.purpur_block, 0, 2);
		world.setBlock(i + 13, j + 10, k + 11, OtherModBlocks.purpur_block, 0, 2);
		world.setBlock(i + 5, j + 10, k + 12, OtherModBlocks.purpur_block, 0, 2);
		world.setBlock(i + 8, j + 10, k + 12, OtherModBlocks.purpur_block, 0, 2);
		world.setBlock(i + 9, j + 10, k + 12, OtherModBlocks.purpur_block, 0, 2);
		world.setBlock(i + 10, j + 10, k + 12, OtherModBlocks.purpur_stairs, 2, 2);
		world.setBlock(i + 11, j + 10, k + 12, OtherModBlocks.purpur_stairs, 2, 2);
		world.setBlock(i + 12, j + 10, k + 12, OtherModBlocks.purpur_block, 0, 2);
		world.setBlock(i + 13, j + 10, k + 12, OtherModBlocks.purpur_block, 0, 2);
		world.setBlock(i + 5, j + 10, k + 13, OtherModBlocks.purpur_block, 0, 2);
		world.setBlock(i + 6, j + 10, k + 13, OtherModBlocks.purpur_block, 0, 2);
		world.setBlock(i + 8, j + 10, k + 13, OtherModBlocks.purpur_block, 0, 2);
		world.setBlock(i + 9, j + 10, k + 13, OtherModBlocks.purpur_block, 0, 2);
		world.setBlock(i + 10, j + 10, k + 13, OtherModBlocks.purpur_block, 0, 2);
		world.setBlock(i + 11, j + 10, k + 13, OtherModBlocks.purpur_block, 0, 2);
		world.setBlock(i + 12, j + 10, k + 13, OtherModBlocks.purpur_block, 0, 2);
		world.setBlock(i + 13, j + 10, k + 13, OtherModBlocks.purpur_block, 0, 2);
		world.setBlock(i + 5, j + 10, k + 14, OtherModBlocks.purpur_block, 0, 2);
		world.setBlock(i + 6, j + 10, k + 14, OtherModBlocks.purpur_block, 0, 2);
		world.setBlock(i + 7, j + 10, k + 14, OtherModBlocks.purpur_block, 0, 2);
		world.setBlock(i + 8, j + 10, k + 14, OtherModBlocks.purpur_block, 0, 2);
		world.setBlock(i + 9, j + 10, k + 14, OtherModBlocks.purpur_block, 0, 2);
		world.setBlock(i + 10, j + 10, k + 14, OtherModBlocks.purpur_block, 0, 2);
		world.setBlock(i + 11, j + 10, k + 14, OtherModBlocks.purpur_block, 0, 2);
		world.setBlock(i + 12, j + 10, k + 14, OtherModBlocks.purpur_block, 0, 2);
		world.setBlock(i + 13, j + 10, k + 14, OtherModBlocks.purpur_block, 0, 2);
		world.setBlock(i + 5, j + 10, k + 15, OtherModBlocks.purpur_block, 0, 2);
		world.setBlock(i + 6, j + 10, k + 15, OtherModBlocks.purpur_block, 0, 2);
		world.setBlock(i + 7, j + 10, k + 15, OtherModBlocks.purpur_block, 0, 2);
		world.setBlock(i + 8, j + 10, k + 15, OtherModBlocks.purpur_block, 0, 2);
		world.setBlock(i + 9, j + 10, k + 15, OtherModBlocks.purpur_block, 0, 2);
		world.setBlock(i + 10, j + 10, k + 15, OtherModBlocks.purpur_block, 0, 2);
		world.setBlock(i + 11, j + 10, k + 15, OtherModBlocks.purpur_block, 0, 2);
		world.setBlock(i + 12, j + 10, k + 15, OtherModBlocks.purpur_block, 0, 2);
		world.setBlock(i + 13, j + 10, k + 15, OtherModBlocks.purpur_block, 0, 2);
		world.setBlock(i + 5, j + 10, k + 16, OtherModBlocks.purpur_block, 0, 2);
		world.setBlock(i + 6, j + 10, k + 16, OtherModBlocks.purpur_block, 0, 2);
		world.setBlock(i + 7, j + 10, k + 16, OtherModBlocks.purpur_block, 0, 2);
		world.setBlock(i + 8, j + 10, k + 16, OtherModBlocks.purpur_block, 0, 2);
		world.setBlock(i + 9, j + 10, k + 16, OtherModBlocks.purpur_block, 0, 2);
		world.setBlock(i + 10, j + 10, k + 16, OtherModBlocks.purpur_block, 0, 2);
		world.setBlock(i + 11, j + 10, k + 16, OtherModBlocks.purpur_block, 0, 2);
		world.setBlock(i + 12, j + 10, k + 16, OtherModBlocks.purpur_block, 0, 2);
		world.setBlock(i + 5, j + 10, k + 17, OtherModBlocks.purpur_block, 0, 2);
		world.setBlock(i + 6, j + 10, k + 17, OtherModBlocks.purpur_block, 0, 2);
		world.setBlock(i + 7, j + 10, k + 17, OtherModBlocks.purpur_block, 0, 2);
		world.setBlock(i + 8, j + 10, k + 17, OtherModBlocks.purpur_block, 0, 2);
		world.setBlock(i + 9, j + 10, k + 17, OtherModBlocks.purpur_pillar, 0, 2);
		world.setBlock(i + 10, j + 10, k + 17, OtherModBlocks.purpur_block, 0, 2);
		world.setBlock(i + 11, j + 10, k + 17, OtherModBlocks.purpur_block, 0, 2);
		world.setBlock(i + 12, j + 10, k + 17, OtherModBlocks.purpur_block, 0, 2);
		world.setBlock(i + 5, j + 10, k + 18, OtherModBlocks.purpur_block, 0, 2);
		world.setBlock(i + 6, j + 10, k + 18, OtherModBlocks.purpur_block, 0, 2);
		world.setBlock(i + 7, j + 10, k + 18, OtherModBlocks.purpur_block, 0, 2);
		world.setBlock(i + 8, j + 10, k + 18, OtherModBlocks.purpur_block, 0, 2);
		world.setBlock(i + 9, j + 10, k + 18, Blocks.stained_glass, 2, 2);
		world.setBlock(i + 10, j + 10, k + 18, OtherModBlocks.purpur_block, 0, 2);
		world.setBlock(i + 12, j + 10, k + 18, OtherModBlocks.purpur_block, 0, 2);
		world.setBlock(i + 13, j + 10, k + 18, OtherModBlocks.purpur_block, 0, 2);
		world.setBlock(i + 5, j + 10, k + 19, OtherModBlocks.purpur_block, 0, 2);
		world.setBlock(i + 6, j + 10, k + 19, OtherModBlocks.purpur_block, 0, 2);
		world.setBlock(i + 7, j + 10, k + 19, OtherModBlocks.purpur_block, 0, 2);
		world.setBlock(i + 8, j + 10, k + 19, OtherModBlocks.purpur_block, 0, 2);
		world.setBlock(i + 9, j + 10, k + 19, OtherModBlocks.purpur_pillar, 8, 2);
		world.setBlock(i + 10, j + 10, k + 19, OtherModBlocks.purpur_block, 0, 2);
		world.setBlock(i + 11, j + 10, k + 19, OtherModBlocks.purpur_block, 0, 2);
		world.setBlock(i + 12, j + 10, k + 19, OtherModBlocks.purpur_block, 0, 2);
		world.setBlock(i + 13, j + 10, k + 19, OtherModBlocks.purpur_block, 0, 2);
		world.setBlock(i + 5, j + 10, k + 20, OtherModBlocks.purpur_block, 0, 2);
		world.setBlock(i + 6, j + 10, k + 20, OtherModBlocks.purpur_block, 0, 2);
		world.setBlock(i + 7, j + 10, k + 20, OtherModBlocks.purpur_block, 0, 2);
		world.setBlock(i + 8, j + 10, k + 20, OtherModBlocks.purpur_block, 0, 2);
		world.setBlock(i + 9, j + 10, k + 20, OtherModBlocks.purpur_block, 0, 2);
		world.setBlock(i + 10, j + 10, k + 20, OtherModBlocks.purpur_block, 0, 2);
		world.setBlock(i + 12, j + 10, k + 20, OtherModBlocks.purpur_block, 0, 2);
		world.setBlock(i + 13, j + 10, k + 20, OtherModBlocks.purpur_block, 0, 2);
		world.setBlock(i + 5, j + 10, k + 21, OtherModBlocks.purpur_block, 0, 2);
		world.setBlock(i + 6, j + 10, k + 21, OtherModBlocks.purpur_block, 0, 2);
		world.setBlock(i + 7, j + 10, k + 21, OtherModBlocks.purpur_block, 0, 2);
		world.setBlock(i + 8, j + 10, k + 21, OtherModBlocks.purpur_block, 0, 2);
		world.setBlock(i + 9, j + 10, k + 21, OtherModBlocks.purpur_block, 0, 2);
		world.setBlock(i + 10, j + 10, k + 21, OtherModBlocks.purpur_block, 0, 2);
		world.setBlock(i + 11, j + 10, k + 21, OtherModBlocks.purpur_block, 0, 2);
		world.setBlock(i + 12, j + 10, k + 21, OtherModBlocks.purpur_block, 0, 2);
		world.setBlock(i + 13, j + 10, k + 21, OtherModBlocks.purpur_block, 0, 2);
		world.setBlock(i + 6, j + 10, k + 22, OtherModBlocks.purpur_block, 0, 2);
		world.setBlock(i + 7, j + 10, k + 22, OtherModBlocks.purpur_block, 0, 2);
		world.setBlock(i + 8, j + 10, k + 22, OtherModBlocks.purpur_block, 0, 2);
		world.setBlock(i + 9, j + 10, k + 22, OtherModBlocks.purpur_block, 0, 2);
		world.setBlock(i + 10, j + 10, k + 22, OtherModBlocks.purpur_block, 0, 2);
		world.setBlock(i + 11, j + 10, k + 22, OtherModBlocks.purpur_block, 0, 2);
		world.setBlock(i + 12, j + 10, k + 22, OtherModBlocks.purpur_block, 0, 2);
		world.setBlock(i + 6, j + 10, k + 23, OtherModBlocks.purpur_block, 0, 2);
		world.setBlock(i + 7, j + 10, k + 23, OtherModBlocks.purpur_block, 0, 2);
		world.setBlock(i + 8, j + 10, k + 23, OtherModBlocks.purpur_block, 0, 2);
		world.setBlock(i + 9, j + 10, k + 23, OtherModBlocks.purpur_block, 0, 2);
		world.setBlock(i + 10, j + 10, k + 23, OtherModBlocks.purpur_block, 0, 2);
		world.setBlock(i + 11, j + 10, k + 23, OtherModBlocks.purpur_block, 0, 2);
		world.setBlock(i + 12, j + 10, k + 23, OtherModBlocks.purpur_block, 0, 2);
		world.setBlock(i + 7, j + 10, k + 24, OtherModBlocks.purpur_block, 0, 2);
		world.setBlock(i + 9, j + 10, k + 24, OtherModBlocks.purpur_block, 0, 2);
		world.setBlock(i + 10, j + 10, k + 24, OtherModBlocks.purpur_block, 0, 2);
		world.setBlock(i + 11, j + 10, k + 24, OtherModBlocks.purpur_block, 0, 2);
		world.setBlock(i + 7, j + 10, k + 25, OtherModBlocks.purpur_block, 0, 2);
		world.setBlock(i + 8, j + 10, k + 25, OtherModBlocks.purpur_block, 0, 2);
		world.setBlock(i + 9, j + 10, k + 25, OtherModBlocks.purpur_block, 0, 2);
		world.setBlock(i + 10, j + 10, k + 25, OtherModBlocks.purpur_block, 0, 2);
		world.setBlock(i + 11, j + 10, k + 25, OtherModBlocks.purpur_block, 0, 2);
		world.setBlock(i + 8, j + 10, k + 26, OtherModBlocks.purpur_block, 0, 2);
		world.setBlock(i + 9, j + 10, k + 26, OtherModBlocks.purpur_block, 0, 2);
		world.setBlock(i + 10, j + 10, k + 26, OtherModBlocks.purpur_block, 0, 2);
		world.setBlock(i + 9, j + 10, k + 27, OtherModBlocks.purpur_pillar, 8, 2);
		world.setBlock(i + 9, j + 10, k + 28, OtherModBlocks.purpur_pillar, 8, 2);
		world.setBlock(i + 9, j + 10, k + 29, OtherModBlocks.purpur_pillar, 8, 2);
		world.setBlock(i + 9, j + 10, k + 30, OtherModBlocks.purpur_pillar, 8, 2);
		world.setBlock(i + 5, j + 11, k + 5, OtherModBlocks.purpur_pillar, 0, 2);
		world.setBlock(i + 6, j + 11, k + 5, OtherModBlocks.end_bricks, 0, 2);
		world.setBlock(i + 7, j + 11, k + 5, OtherModBlocks.end_bricks, 0, 2);
		world.setBlock(i + 8, j + 11, k + 5, OtherModBlocks.end_bricks, 0, 2);
		world.setBlock(i + 9, j + 11, k + 5, OtherModBlocks.purpur_pillar, 0, 2);
		world.setBlock(i + 10, j + 11, k + 5, OtherModBlocks.end_bricks, 0, 2);
		world.setBlock(i + 12, j + 11, k + 5, OtherModBlocks.end_bricks, 0, 2);
		world.setBlock(i + 13, j + 11, k + 5, OtherModBlocks.purpur_pillar, 0, 2);
		world.setBlock(i + 14, j + 11, k + 5, Blocks.air, 0, 2);
		world.setBlock(i + 15, j + 11, k + 5, Blocks.air, 0, 2);
		world.setBlock(i + 16, j + 11, k + 5, Blocks.air, 0, 2);
		world.setBlock(i + 0, j + 11, k + 6, Blocks.air, 0, 2);
		world.setBlock(i + 1, j + 11, k + 6, Blocks.air, 0, 2);
		world.setBlock(i + 2, j + 11, k + 6, Blocks.air, 0, 2);
		world.setBlock(i + 3, j + 11, k + 6, Blocks.air, 0, 2);
		world.setBlock(i + 4, j + 11, k + 6, Blocks.air, 0, 2);
		world.setBlock(i + 5, j + 11, k + 6, OtherModBlocks.end_bricks, 0, 2);
		world.setBlock(i + 6, j + 11, k + 6, Blocks.air, 0, 2);
		world.setBlock(i + 7, j + 11, k + 6, Blocks.air, 0, 2);
		world.setBlock(i + 8, j + 11, k + 6, Blocks.air, 0, 2);
		world.setBlock(i + 9, j + 11, k + 6, Blocks.air, 0, 2);
		world.setBlock(i + 10, j + 11, k + 6, Blocks.air, 0, 2);
		world.setBlock(i + 11, j + 11, k + 6, Blocks.air, 0, 2);
		world.setBlock(i + 12, j + 11, k + 6, Blocks.air, 0, 2);
		world.setBlock(i + 13, j + 11, k + 6, OtherModBlocks.end_bricks, 0, 2);
		world.setBlock(i + 14, j + 11, k + 6, Blocks.air, 0, 2);
		world.setBlock(i + 15, j + 11, k + 6, Blocks.air, 0, 2);
		world.setBlock(i + 16, j + 11, k + 6, Blocks.air, 0, 2);
		world.setBlock(i + 0, j + 11, k + 7, Blocks.air, 0, 2);
		world.setBlock(i + 1, j + 11, k + 7, Blocks.air, 0, 2);
		world.setBlock(i + 2, j + 11, k + 7, Blocks.air, 0, 2);
		world.setBlock(i + 3, j + 11, k + 7, Blocks.air, 0, 2);
		world.setBlock(i + 4, j + 11, k + 7, Blocks.air, 0, 2);
		world.setBlock(i + 5, j + 11, k + 7, OtherModBlocks.end_bricks, 0, 2);
		world.setBlock(i + 6, j + 11, k + 7, Blocks.air, 0, 2);
		world.setBlock(i + 7, j + 11, k + 7, Blocks.air, 0, 2);
		world.setBlock(i + 8, j + 11, k + 7, Blocks.air, 0, 2);
		world.setBlock(i + 9, j + 11, k + 7, Blocks.air, 0, 2);
		world.setBlock(i + 10, j + 11, k + 7, Blocks.air, 0, 2);
		world.setBlock(i + 11, j + 11, k + 7, Blocks.air, 0, 2);
		world.setBlock(i + 12, j + 11, k + 7, Blocks.air, 0, 2);
		world.setBlock(i + 13, j + 11, k + 7, OtherModBlocks.end_bricks, 0, 2);
		world.setBlock(i + 14, j + 11, k + 7, Blocks.air, 0, 2);
		world.setBlock(i + 15, j + 11, k + 7, Blocks.air, 0, 2);
		world.setBlock(i + 16, j + 11, k + 7, Blocks.air, 0, 2);
		world.setBlock(i + 0, j + 11, k + 8, Blocks.air, 0, 2);
		world.setBlock(i + 1, j + 11, k + 8, Blocks.air, 0, 2);
		world.setBlock(i + 2, j + 11, k + 8, Blocks.air, 0, 2);
		world.setBlock(i + 3, j + 11, k + 8, Blocks.air, 0, 2);
		world.setBlock(i + 4, j + 11, k + 8, Blocks.air, 0, 2);
		world.setBlock(i + 5, j + 11, k + 8, OtherModBlocks.end_bricks, 0, 2);
		world.setBlock(i + 6, j + 11, k + 8, Blocks.air, 0, 2);
		world.setBlock(i + 7, j + 11, k + 8, Blocks.air, 0, 2);
		world.setBlock(i + 8, j + 11, k + 8, Blocks.air, 0, 2);
		world.setBlock(i + 9, j + 11, k + 8, Blocks.air, 0, 2);
		world.setBlock(i + 10, j + 11, k + 8, Blocks.air, 0, 2);
		world.setBlock(i + 11, j + 11, k + 8, Blocks.air, 0, 2);
		world.setBlock(i + 12, j + 11, k + 8, Blocks.air, 0, 2);
		world.setBlock(i + 13, j + 11, k + 8, OtherModBlocks.end_bricks, 0, 2);
		world.setBlock(i + 14, j + 11, k + 8, Blocks.air, 0, 2);
		world.setBlock(i + 15, j + 11, k + 8, Blocks.air, 0, 2);
		world.setBlock(i + 16, j + 11, k + 8, Blocks.air, 0, 2);
		world.setBlock(i + 0, j + 11, k + 9, Blocks.air, 0, 2);
		world.setBlock(i + 1, j + 11, k + 9, Blocks.air, 0, 2);
		world.setBlock(i + 2, j + 11, k + 9, Blocks.air, 0, 2);
		world.setBlock(i + 3, j + 11, k + 9, Blocks.air, 0, 2);
		world.setBlock(i + 4, j + 11, k + 9, Blocks.air, 0, 2);
		world.setBlock(i + 5, j + 11, k + 9, OtherModBlocks.end_bricks, 0, 2);
		world.setBlock(i + 6, j + 11, k + 9, Blocks.air, 0, 2);
		world.setBlock(i + 7, j + 11, k + 9, Blocks.air, 0, 2);
		world.setBlock(i + 8, j + 11, k + 9, Blocks.air, 0, 2);
		world.setBlock(i + 9, j + 11, k + 9, Blocks.air, 0, 2);
		world.setBlock(i + 10, j + 11, k + 9, Blocks.air, 0, 2);
		world.setBlock(i + 11, j + 11, k + 9, Blocks.air, 0, 2);
		world.setBlock(i + 12, j + 11, k + 9, Blocks.air, 0, 2);
		world.setBlock(i + 13, j + 11, k + 9, OtherModBlocks.end_bricks, 0, 2);
		world.setBlock(i + 14, j + 11, k + 9, Blocks.air, 0, 2);
		world.setBlock(i + 15, j + 11, k + 9, Blocks.air, 0, 2);
		world.setBlock(i + 16, j + 11, k + 9, Blocks.air, 0, 2);
		world.setBlock(i + 0, j + 11, k + 10, Blocks.air, 0, 2);
		world.setBlock(i + 1, j + 11, k + 10, Blocks.air, 0, 2);
		world.setBlock(i + 2, j + 11, k + 10, Blocks.air, 0, 2);
		world.setBlock(i + 3, j + 11, k + 10, Blocks.air, 0, 2);
		world.setBlock(i + 4, j + 11, k + 10, Blocks.air, 0, 2);
		world.setBlock(i + 5, j + 11, k + 10, OtherModBlocks.purpur_pillar, 0, 2);
		world.setBlock(i + 6, j + 11, k + 10, OtherModBlocks.purpur_stairs, 6, 2);
		world.setBlock(i + 7, j + 11, k + 10, OtherModBlocks.purpur_stairs, 6, 2);
		world.setBlock(i + 8, j + 11, k + 10, OtherModBlocks.purpur_block, 0, 2);
		world.setBlock(i + 9, j + 11, k + 10, OtherModBlocks.purpur_block, 0, 2);
		world.setBlock(i + 10, j + 11, k + 10, Blocks.air, 0, 2);
		world.setBlock(i + 11, j + 11, k + 10, Blocks.air, 0, 2);
		world.setBlock(i + 12, j + 11, k + 10, OtherModBlocks.purpur_block, 0, 2);
		world.setBlock(i + 13, j + 11, k + 10, OtherModBlocks.purpur_pillar, 0, 2);
		world.setBlock(i + 14, j + 11, k + 10, Blocks.air, 0, 2);
		world.setBlock(i + 15, j + 11, k + 10, Blocks.air, 0, 2);
		world.setBlock(i + 16, j + 11, k + 10, Blocks.air, 0, 2);
		world.setBlock(i + 0, j + 11, k + 11, Blocks.air, 0, 2);
		world.setBlock(i + 1, j + 11, k + 11, Blocks.air, 0, 2);
		world.setBlock(i + 2, j + 11, k + 11, Blocks.air, 0, 2);
		world.setBlock(i + 3, j + 11, k + 11, Blocks.air, 0, 2);
		world.setBlock(i + 4, j + 11, k + 11, Blocks.air, 0, 2);
		world.setBlock(i + 5, j + 11, k + 11, OtherModBlocks.purpur_block, 0, 2);
		world.setBlock(i + 6, j + 11, k + 11, OtherModBlocks.purpur_block, 0, 2);
		world.setBlock(i + 7, j + 11, k + 11, OtherModBlocks.purpur_block, 0, 2);
		world.setBlock(i + 8, j + 11, k + 11, Blocks.air, 0, 2);
		world.setBlock(i + 9, j + 11, k + 11, Blocks.air, 0, 2);
		world.setBlock(i + 10, j + 11, k + 11, Blocks.air, 0, 2);
		world.setBlock(i + 11, j + 11, k + 11, Blocks.air, 0, 2);
		world.setBlock(i + 12, j + 11, k + 11, Blocks.air, 0, 2);
		world.setBlock(i + 13, j + 11, k + 11, OtherModBlocks.purpur_block, 0, 2);
		world.setBlock(i + 14, j + 11, k + 11, Blocks.air, 0, 2);
		world.setBlock(i + 15, j + 11, k + 11, Blocks.air, 0, 2);
		world.setBlock(i + 16, j + 11, k + 11, Blocks.air, 0, 2);
		world.setBlock(i + 0, j + 11, k + 12, Blocks.air, 0, 2);
		world.setBlock(i + 1, j + 11, k + 12, Blocks.air, 0, 2);
		world.setBlock(i + 2, j + 11, k + 12, Blocks.air, 0, 2);
		world.setBlock(i + 3, j + 11, k + 12, Blocks.air, 0, 2);
		world.setBlock(i + 4, j + 11, k + 12, Blocks.air, 0, 2);
		world.setBlock(i + 5, j + 11, k + 12, OtherModBlocks.purpur_block, 0, 2);
		world.setBlock(i + 6, j + 11, k + 12, OtherModBlocks.purpur_stairs, 3, 2);
		world.setBlock(i + 7, j + 11, k + 12, OtherModBlocks.purpur_stairs, 3, 2);
		world.setBlock(i + 8, j + 11, k + 12, Blocks.air, 0, 2);
		world.setBlock(i + 9, j + 11, k + 12, Blocks.air, 0, 2);
		world.setBlock(i + 10, j + 11, k + 12, Blocks.air, 0, 2);
		world.setBlock(i + 11, j + 11, k + 12, Blocks.air, 0, 2);
		world.setBlock(i + 12, j + 11, k + 12, Blocks.air, 0, 2);
		world.setBlock(i + 13, j + 11, k + 12, OtherModBlocks.purpur_block, 0, 2);
		world.setBlock(i + 14, j + 11, k + 12, Blocks.air, 0, 2);
		world.setBlock(i + 15, j + 11, k + 12, Blocks.air, 0, 2);
		world.setBlock(i + 16, j + 11, k + 12, Blocks.air, 0, 2);
		world.setBlock(i + 0, j + 11, k + 13, Blocks.air, 0, 2);
		world.setBlock(i + 1, j + 11, k + 13, Blocks.air, 0, 2);
		world.setBlock(i + 2, j + 11, k + 13, Blocks.air, 0, 2);
		world.setBlock(i + 3, j + 11, k + 13, Blocks.air, 0, 2);
		world.setBlock(i + 4, j + 11, k + 13, Blocks.air, 0, 2);
		world.setBlock(i + 5, j + 11, k + 13, OtherModBlocks.purpur_stairs, 0, 2);
		world.setBlock(i + 6, j + 11, k + 13, Blocks.air, 0, 2);
		world.setBlock(i + 7, j + 11, k + 13, Blocks.air, 0, 2);
		world.setBlock(i + 8, j + 11, k + 13, Blocks.air, 0, 2);
		world.setBlock(i + 9, j + 11, k + 13, Blocks.air, 0, 2);
		world.setBlock(i + 10, j + 11, k + 13, Blocks.air, 0, 2);
		world.setBlock(i + 11, j + 11, k + 13, Blocks.air, 0, 2);
		world.setBlock(i + 12, j + 11, k + 13, Blocks.air, 0, 2);
		world.setBlock(i + 13, j + 11, k + 13, OtherModBlocks.purpur_stairs, 1, 2);
		world.setBlock(i + 14, j + 11, k + 13, Blocks.air, 0, 2);
		world.setBlock(i + 15, j + 11, k + 13, Blocks.air, 0, 2);
		world.setBlock(i + 16, j + 11, k + 13, Blocks.air, 0, 2);
		world.setBlock(i + 0, j + 11, k + 14, Blocks.air, 0, 2);
		world.setBlock(i + 1, j + 11, k + 14, Blocks.air, 0, 2);
		world.setBlock(i + 2, j + 11, k + 14, Blocks.air, 0, 2);
		world.setBlock(i + 3, j + 11, k + 14, Blocks.air, 0, 2);
		world.setBlock(i + 4, j + 11, k + 14, Blocks.air, 0, 2);
		world.setBlock(i + 5, j + 11, k + 14, OtherModBlocks.purpur_stairs, 0, 2);
		world.setBlock(i + 6, j + 11, k + 14, Blocks.air, 0, 2);
		world.setBlock(i + 7, j + 11, k + 14, Blocks.air, 0, 2);
		world.setBlock(i + 8, j + 11, k + 14, Blocks.air, 0, 2);
		world.setBlock(i + 9, j + 11, k + 14, Blocks.air, 0, 2);
		world.setBlock(i + 10, j + 11, k + 14, Blocks.air, 0, 2);
		world.setBlock(i + 11, j + 11, k + 14, Blocks.air, 0, 2);
		world.setBlock(i + 12, j + 11, k + 14, Blocks.air, 0, 2);
		world.setBlock(i + 13, j + 11, k + 14, OtherModBlocks.purpur_stairs, 1, 2);
		world.setBlock(i + 14, j + 11, k + 14, Blocks.air, 0, 2);
		world.setBlock(i + 15, j + 11, k + 14, Blocks.air, 0, 2);
		world.setBlock(i + 16, j + 11, k + 14, Blocks.air, 0, 2);
		world.setBlock(i + 0, j + 11, k + 15, Blocks.air, 0, 2);
		world.setBlock(i + 1, j + 11, k + 15, Blocks.air, 0, 2);
		world.setBlock(i + 2, j + 11, k + 15, Blocks.air, 0, 2);
		world.setBlock(i + 3, j + 11, k + 15, Blocks.air, 0, 2);
		world.setBlock(i + 4, j + 11, k + 15, Blocks.air, 0, 2);
		world.setBlock(i + 5, j + 11, k + 15, OtherModBlocks.purpur_block, 0, 2);
		world.setBlock(i + 6, j + 11, k + 15, Blocks.air, 0, 2);
		world.setBlock(i + 7, j + 11, k + 15, Blocks.air, 0, 2);
		world.setBlock(i + 8, j + 11, k + 15, Blocks.air, 0, 2);
		world.setBlock(i + 9, j + 11, k + 15, Blocks.air, 0, 2);
		world.setBlock(i + 10, j + 11, k + 15, Blocks.air, 0, 2);
		world.setBlock(i + 11, j + 11, k + 15, Blocks.air, 0, 2);
		world.setBlock(i + 12, j + 11, k + 15, Blocks.air, 0, 2);
		world.setBlock(i + 13, j + 11, k + 15, OtherModBlocks.purpur_block, 0, 2);
		world.setBlock(i + 14, j + 11, k + 15, Blocks.air, 0, 2);
		world.setBlock(i + 15, j + 11, k + 15, Blocks.air, 0, 2);
		world.setBlock(i + 16, j + 11, k + 15, Blocks.air, 0, 2);
		world.setBlock(i + 0, j + 11, k + 16, Blocks.air, 0, 2);
		world.setBlock(i + 1, j + 11, k + 16, Blocks.air, 0, 2);
		world.setBlock(i + 2, j + 11, k + 16, Blocks.air, 0, 2);
		world.setBlock(i + 3, j + 11, k + 16, Blocks.air, 0, 2);
		world.setBlock(i + 4, j + 11, k + 16, Blocks.air, 0, 2);
		world.setBlock(i + 5, j + 11, k + 16, OtherModBlocks.purpur_stairs, 0, 2);
		world.setBlock(i + 6, j + 11, k + 16, Blocks.air, 0, 2);
		world.setBlock(i + 7, j + 11, k + 16, Blocks.air, 0, 2);
		world.setBlock(i + 8, j + 11, k + 16, Blocks.air, 0, 2);
		world.setBlock(i + 10, j + 11, k + 16, Blocks.air, 0, 2);
		world.setBlock(i + 11, j + 11, k + 16, Blocks.air, 0, 2);
		world.setBlock(i + 12, j + 11, k + 16, Blocks.air, 0, 2);
		world.setBlock(i + 13, j + 11, k + 16, OtherModBlocks.purpur_stairs, 1, 2);
		world.setBlock(i + 14, j + 11, k + 16, Blocks.air, 0, 2);
		world.setBlock(i + 15, j + 11, k + 16, Blocks.air, 0, 2);
		world.setBlock(i + 16, j + 11, k + 16, Blocks.air, 0, 2);
		world.setBlock(i + 0, j + 11, k + 17, Blocks.air, 0, 2);
		world.setBlock(i + 1, j + 11, k + 17, Blocks.air, 0, 2);
		world.setBlock(i + 2, j + 11, k + 17, Blocks.air, 0, 2);
		world.setBlock(i + 3, j + 11, k + 17, Blocks.air, 0, 2);
		world.setBlock(i + 4, j + 11, k + 17, Blocks.air, 0, 2);
		world.setBlock(i + 5, j + 11, k + 17, OtherModBlocks.purpur_stairs, 0, 2);
		world.setBlock(i + 6, j + 11, k + 17, Blocks.air, 0, 2);
		world.setBlock(i + 7, j + 11, k + 17, Blocks.air, 0, 2);
		world.setBlock(i + 8, j + 11, k + 17, Blocks.air, 0, 2);
		world.setBlock(i + 9, j + 11, k + 17, OtherModBlocks.purpur_pillar, 0, 2);
		world.setBlock(i + 10, j + 11, k + 17, Blocks.air, 0, 2);
		world.setBlock(i + 11, j + 11, k + 17, Blocks.air, 0, 2);
		world.setBlock(i + 12, j + 11, k + 17, Blocks.air, 0, 2);
		world.setBlock(i + 13, j + 11, k + 17, OtherModBlocks.purpur_stairs, 1, 2);
		world.setBlock(i + 5, j + 11, k + 18, OtherModBlocks.purpur_block, 0, 2);
		world.setBlock(i + 13, j + 11, k + 18, OtherModBlocks.purpur_block, 0, 2);
		world.setBlock(i + 14, j + 11, k + 18, Blocks.air, 0, 2);
		world.setBlock(i + 15, j + 11, k + 18, Blocks.air, 0, 2);
		world.setBlock(i + 16, j + 11, k + 18, Blocks.air, 0, 2);
		world.setBlock(i + 0, j + 11, k + 19, Blocks.air, 0, 2);
		world.setBlock(i + 1, j + 11, k + 19, Blocks.air, 0, 2);
		world.setBlock(i + 2, j + 11, k + 19, Blocks.air, 0, 2);
		world.setBlock(i + 3, j + 11, k + 19, Blocks.air, 0, 2);
		world.setBlock(i + 4, j + 11, k + 19, Blocks.air, 0, 2);
		world.setBlock(i + 5, j + 11, k + 19, OtherModBlocks.purpur_stairs, 0, 2);
		world.setBlock(i + 6, j + 11, k + 19, Blocks.air, 0, 2);
		world.setBlock(i + 7, j + 11, k + 19, Blocks.air, 0, 2);
		world.setBlock(i + 8, j + 11, k + 19, Blocks.air, 0, 2);
		world.setBlock(i + 9, j + 11, k + 19, OtherModBlocks.purpur_stairs, 2, 2);
		world.setBlock(i + 10, j + 11, k + 19, Blocks.air, 0, 2);
		world.setBlock(i + 11, j + 11, k + 19, Blocks.air, 0, 2);
		world.setBlock(i + 12, j + 11, k + 19, Blocks.air, 0, 2);
		world.setBlock(i + 13, j + 11, k + 19, OtherModBlocks.purpur_stairs, 1, 2);
		world.setBlock(i + 5, j + 11, k + 20, OtherModBlocks.purpur_stairs, 0, 2);
		world.setBlock(i + 6, j + 11, k + 20, Blocks.air, 0, 2);
		world.setBlock(i + 7, j + 11, k + 20, Blocks.air, 0, 2);
		world.setBlock(i + 8, j + 11, k + 20, Blocks.air, 0, 2);
		world.setBlock(i + 9, j + 11, k + 20, OtherModBlocks.purpur_pillar, 8, 2);
		world.setBlock(i + 10, j + 11, k + 20, Blocks.air, 0, 2);
		world.setBlock(i + 11, j + 11, k + 20, Blocks.air, 0, 2);
		world.setBlock(i + 12, j + 11, k + 20, Blocks.air, 0, 2);
		world.setBlock(i + 13, j + 11, k + 20, OtherModBlocks.purpur_stairs, 1, 2);
		world.setBlock(i + 14, j + 11, k + 20, Blocks.air, 0, 2);
		world.setBlock(i + 15, j + 11, k + 20, Blocks.air, 0, 2);
		world.setBlock(i + 16, j + 11, k + 20, Blocks.air, 0, 2);
		world.setBlock(i + 0, j + 11, k + 21, Blocks.air, 0, 2);
		world.setBlock(i + 1, j + 11, k + 21, Blocks.air, 0, 2);
		world.setBlock(i + 2, j + 11, k + 21, Blocks.air, 0, 2);
		world.setBlock(i + 3, j + 11, k + 21, Blocks.air, 0, 2);
		world.setBlock(i + 4, j + 11, k + 21, Blocks.air, 0, 2);
		world.setBlock(i + 5, j + 11, k + 21, OtherModBlocks.purpur_block, 0, 2);
		world.setBlock(i + 6, j + 11, k + 21, OtherModBlocks.purpur_stairs, 3, 2);
		world.setBlock(i + 7, j + 11, k + 21, Blocks.air, 0, 2);
		world.setBlock(i + 8, j + 11, k + 21, Blocks.air, 0, 2);
		world.setBlock(i + 10, j + 11, k + 21, Blocks.air, 0, 2);
		world.setBlock(i + 11, j + 11, k + 21, Blocks.air, 0, 2);
		world.setBlock(i + 12, j + 11, k + 21, OtherModBlocks.purpur_stairs, 3, 2);
		world.setBlock(i + 13, j + 11, k + 21, OtherModBlocks.purpur_block, 0, 2);
		world.setBlock(i + 6, j + 11, k + 22, OtherModBlocks.purpur_stairs, 0, 2);
		world.setBlock(i + 7, j + 11, k + 22, Blocks.air, 0, 2);
		world.setBlock(i + 8, j + 11, k + 22, Blocks.air, 0, 2);
		world.setBlock(i + 9, j + 11, k + 22, Blocks.air, 0, 2);
		world.setBlock(i + 10, j + 11, k + 22, Blocks.air, 0, 2);
		world.setBlock(i + 11, j + 11, k + 22, Blocks.air, 0, 2);
		world.setBlock(i + 12, j + 11, k + 22, OtherModBlocks.purpur_stairs, 1, 2);
		world.setBlock(i + 6, j + 11, k + 23, OtherModBlocks.purpur_block, 0, 2);
		world.setBlock(i + 7, j + 11, k + 23, OtherModBlocks.purpur_stairs, 3, 2);
		world.setBlock(i + 8, j + 11, k + 23, Blocks.air, 0, 2);
		world.setBlock(i + 9, j + 11, k + 23, Blocks.air, 0, 2);
		world.setBlock(i + 10, j + 11, k + 23, Blocks.air, 0, 2);
		world.setBlock(i + 11, j + 11, k + 23, OtherModBlocks.purpur_stairs, 3, 2);
		world.setBlock(i + 12, j + 11, k + 23, OtherModBlocks.purpur_block, 0, 2);
		world.setBlock(i + 7, j + 11, k + 24, OtherModBlocks.purpur_stairs, 0, 2);
		world.setBlock(i + 8, j + 11, k + 24, Blocks.air, 0, 2);
		world.setBlock(i + 9, j + 11, k + 24, Blocks.air, 0, 2);
		world.setBlock(i + 10, j + 11, k + 24, Blocks.air, 0, 2);
		world.setBlock(i + 11, j + 11, k + 24, OtherModBlocks.purpur_stairs, 1, 2);
		world.setBlock(i + 7, j + 11, k + 25, OtherModBlocks.purpur_block, 0, 2);
		world.setBlock(i + 8, j + 11, k + 25, Blocks.air, 0, 2);
		world.setBlock(i + 9, j + 11, k + 25, Blocks.air, 0, 2);
		world.setBlock(i + 10, j + 11, k + 25, Blocks.air, 0, 2);
		world.setBlock(i + 11, j + 11, k + 25, OtherModBlocks.purpur_block, 0, 2);
		world.setBlock(i + 8, j + 11, k + 26, OtherModBlocks.purpur_block, 0, 2);
		world.setBlock(i + 9, j + 11, k + 26, Blocks.air, 0, 2);
		world.setBlock(i + 10, j + 11, k + 26, OtherModBlocks.purpur_block, 0, 2);
		world.setBlock(i + 9, j + 11, k + 27, OtherModBlocks.purpur_block, 0, 2);
		world.setBlock(i + 9, j + 11, k + 30, OtherModBlocks.purpur_stairs, 2, 2);
		//world.setBlock(i + 9, j + 11, k + 31, Block.getBlockById(144), 3, 2); ender dragon head here
		world.setBlock(i + 3, j + 12, k + 3, OtherModBlocks.purpur_stairs, 4, 2);
		world.setBlock(i + 4, j + 12, k + 3, OtherModBlocks.purpur_stairs, 6, 2);
		world.setBlock(i + 5, j + 12, k + 3, OtherModBlocks.purpur_stairs, 2, 2);
		world.setBlock(i + 6, j + 12, k + 3, OtherModBlocks.purpur_stairs, 2, 2);
		world.setBlock(i + 7, j + 12, k + 3, OtherModBlocks.purpur_stairs, 6, 2);
		world.setBlock(i + 8, j + 12, k + 3, OtherModBlocks.purpur_stairs, 6, 2);
		world.setBlock(i + 9, j + 12, k + 3, OtherModBlocks.purpur_stairs, 2, 2);
		world.setBlock(i + 10, j + 12, k + 3, OtherModBlocks.purpur_stairs, 6, 2);
		world.setBlock(i + 11, j + 12, k + 3, OtherModBlocks.purpur_stairs, 6, 2);
		world.setBlock(i + 12, j + 12, k + 3, OtherModBlocks.purpur_stairs, 2, 2);
		world.setBlock(i + 13, j + 12, k + 3, OtherModBlocks.purpur_stairs, 2, 2);
		world.setBlock(i + 15, j + 12, k + 3, OtherModBlocks.purpur_stairs, 6, 2);
		world.setBlock(i + 16, j + 12, k + 3, Blocks.air, 0, 2);
		world.setBlock(i + 0, j + 12, k + 4, Blocks.air, 0, 2);
		world.setBlock(i + 1, j + 12, k + 4, Blocks.air, 0, 2);
		world.setBlock(i + 2, j + 12, k + 4, Blocks.air, 0, 2);
		world.setBlock(i + 3, j + 12, k + 4, OtherModBlocks.purpur_stairs, 4, 2);
		world.setBlock(i + 4, j + 12, k + 4, OtherModBlocks.purpur_block, 0, 2);
		world.setBlock(i + 5, j + 12, k + 4, OtherModBlocks.purpur_block, 0, 2);
		world.setBlock(i + 6, j + 12, k + 4, OtherModBlocks.purpur_block, 0, 2);
		world.setBlock(i + 7, j + 12, k + 4, OtherModBlocks.purpur_block, 0, 2);
		world.setBlock(i + 8, j + 12, k + 4, OtherModBlocks.purpur_block, 0, 2);
		world.setBlock(i + 9, j + 12, k + 4, OtherModBlocks.purpur_block, 0, 2);
		world.setBlock(i + 10, j + 12, k + 4, OtherModBlocks.purpur_block, 0, 2);
		world.setBlock(i + 11, j + 12, k + 4, OtherModBlocks.purpur_block, 0, 2);
		world.setBlock(i + 12, j + 12, k + 4, OtherModBlocks.purpur_block, 0, 2);
		world.setBlock(i + 13, j + 12, k + 4, OtherModBlocks.purpur_block, 0, 2);
		world.setBlock(i + 14, j + 12, k + 4, OtherModBlocks.purpur_block, 0, 2);
		world.setBlock(i + 15, j + 12, k + 4, OtherModBlocks.purpur_stairs, 5, 2);
		world.setBlock(i + 16, j + 12, k + 4, Blocks.air, 0, 2);
		world.setBlock(i + 0, j + 12, k + 5, Blocks.air, 0, 2);
		world.setBlock(i + 1, j + 12, k + 5, Blocks.air, 0, 2);
		world.setBlock(i + 2, j + 12, k + 5, Blocks.air, 0, 2);
		world.setBlock(i + 3, j + 12, k + 5, OtherModBlocks.purpur_stairs, 0, 2);
		world.setBlock(i + 4, j + 12, k + 5, OtherModBlocks.purpur_block, 0, 2);
		world.setBlock(i + 5, j + 12, k + 5, OtherModBlocks.purpur_block, 0, 2);
		world.setBlock(i + 6, j + 12, k + 5, OtherModBlocks.purpur_block, 0, 2);
		world.setBlock(i + 7, j + 12, k + 5, OtherModBlocks.purpur_block, 0, 2);
		world.setBlock(i + 8, j + 12, k + 5, OtherModBlocks.purpur_block, 0, 2);
		world.setBlock(i + 9, j + 12, k + 5, OtherModBlocks.purpur_block, 0, 2);
		world.setBlock(i + 10, j + 12, k + 5, OtherModBlocks.purpur_block, 0, 2);
		world.setBlock(i + 11, j + 12, k + 5, OtherModBlocks.purpur_block, 0, 2);
		world.setBlock(i + 12, j + 12, k + 5, OtherModBlocks.purpur_block, 0, 2);
		world.setBlock(i + 13, j + 12, k + 5, OtherModBlocks.purpur_block, 0, 2);
		world.setBlock(i + 14, j + 12, k + 5, OtherModBlocks.purpur_block, 0, 2);
		world.setBlock(i + 15, j + 12, k + 5, OtherModBlocks.purpur_stairs, 1, 2);
		world.setBlock(i + 16, j + 12, k + 5, Blocks.air, 0, 2);
		world.setBlock(i + 0, j + 12, k + 6, Blocks.air, 0, 2);
		world.setBlock(i + 1, j + 12, k + 6, Blocks.air, 0, 2);
		world.setBlock(i + 2, j + 12, k + 6, Blocks.air, 0, 2);
		world.setBlock(i + 3, j + 12, k + 6, OtherModBlocks.purpur_stairs, 0, 2);
		world.setBlock(i + 4, j + 12, k + 6, OtherModBlocks.purpur_block, 0, 2);
		world.setBlock(i + 5, j + 12, k + 6, OtherModBlocks.purpur_block, 0, 2);
		world.setBlock(i + 6, j + 12, k + 6, OtherModBlocks.purpur_block, 0, 2);
		world.setBlock(i + 7, j + 12, k + 6, OtherModBlocks.purpur_block, 0, 2);
		world.setBlock(i + 8, j + 12, k + 6, OtherModBlocks.purpur_block, 0, 2);
		world.setBlock(i + 9, j + 12, k + 6, OtherModBlocks.purpur_block, 0, 2);
		world.setBlock(i + 10, j + 12, k + 6, OtherModBlocks.purpur_block, 0, 2);
		world.setBlock(i + 11, j + 12, k + 6, OtherModBlocks.purpur_block, 0, 2);
		world.setBlock(i + 12, j + 12, k + 6, OtherModBlocks.purpur_block, 0, 2);
		world.setBlock(i + 13, j + 12, k + 6, OtherModBlocks.purpur_block, 0, 2);
		world.setBlock(i + 14, j + 12, k + 6, OtherModBlocks.purpur_block, 0, 2);
		world.setBlock(i + 15, j + 12, k + 6, OtherModBlocks.purpur_stairs, 1, 2);
		world.setBlock(i + 16, j + 12, k + 6, Blocks.air, 0, 2);
		world.setBlock(i + 0, j + 12, k + 7, Blocks.air, 0, 2);
		world.setBlock(i + 1, j + 12, k + 7, Blocks.air, 0, 2);
		world.setBlock(i + 2, j + 12, k + 7, Blocks.air, 0, 2);
		world.setBlock(i + 3, j + 12, k + 7, OtherModBlocks.purpur_stairs, 4, 2);
		world.setBlock(i + 4, j + 12, k + 7, OtherModBlocks.purpur_block, 0, 2);
		world.setBlock(i + 5, j + 12, k + 7, OtherModBlocks.purpur_block, 0, 2);
		world.setBlock(i + 6, j + 12, k + 7, OtherModBlocks.purpur_block, 0, 2);
		world.setBlock(i + 7, j + 12, k + 7, OtherModBlocks.purpur_block, 0, 2);
		world.setBlock(i + 8, j + 12, k + 7, OtherModBlocks.purpur_block, 0, 2);
		world.setBlock(i + 9, j + 12, k + 7, OtherModBlocks.purpur_block, 0, 2);
		world.setBlock(i + 10, j + 12, k + 7, OtherModBlocks.purpur_block, 0, 2);
		world.setBlock(i + 11, j + 12, k + 7, OtherModBlocks.purpur_block, 0, 2);
		world.setBlock(i + 12, j + 12, k + 7, OtherModBlocks.purpur_block, 0, 2);
		world.setBlock(i + 13, j + 12, k + 7, OtherModBlocks.purpur_block, 0, 2);
		world.setBlock(i + 14, j + 12, k + 7, OtherModBlocks.purpur_block, 0, 2);
		world.setBlock(i + 15, j + 12, k + 7, OtherModBlocks.purpur_stairs, 5, 2);
		world.setBlock(i + 16, j + 12, k + 7, Blocks.air, 0, 2);
		world.setBlock(i + 0, j + 12, k + 8, Blocks.air, 0, 2);
		world.setBlock(i + 1, j + 12, k + 8, Blocks.air, 0, 2);
		world.setBlock(i + 2, j + 12, k + 8, Blocks.air, 0, 2);
		world.setBlock(i + 3, j + 12, k + 8, OtherModBlocks.purpur_stairs, 4, 2);
		world.setBlock(i + 4, j + 12, k + 8, OtherModBlocks.purpur_block, 0, 2);
		world.setBlock(i + 5, j + 12, k + 8, OtherModBlocks.purpur_block, 0, 2);
		world.setBlock(i + 6, j + 12, k + 8, OtherModBlocks.purpur_block, 0, 2);
		world.setBlock(i + 7, j + 12, k + 8, OtherModBlocks.purpur_block, 0, 2);
		world.setBlock(i + 8, j + 12, k + 8, OtherModBlocks.purpur_block, 0, 2);
		world.setBlock(i + 9, j + 12, k + 8, OtherModBlocks.purpur_block, 0, 2);
		world.setBlock(i + 10, j + 12, k + 8, OtherModBlocks.purpur_block, 0, 2);
		world.setBlock(i + 11, j + 12, k + 8, OtherModBlocks.purpur_block, 0, 2);
		world.setBlock(i + 12, j + 12, k + 8, OtherModBlocks.purpur_block, 0, 2);
		world.setBlock(i + 13, j + 12, k + 8, OtherModBlocks.purpur_block, 0, 2);
		world.setBlock(i + 14, j + 12, k + 8, OtherModBlocks.purpur_block, 0, 2);
		world.setBlock(i + 15, j + 12, k + 8, OtherModBlocks.purpur_stairs, 5, 2);
		world.setBlock(i + 3, j + 12, k + 9, OtherModBlocks.purpur_stairs, 0, 2);
		world.setBlock(i + 4, j + 12, k + 9, OtherModBlocks.purpur_block, 0, 2);
		world.setBlock(i + 5, j + 12, k + 9, OtherModBlocks.purpur_block, 0, 2);
		world.setBlock(i + 6, j + 12, k + 9, OtherModBlocks.purpur_block, 0, 2);
		world.setBlock(i + 7, j + 12, k + 9, OtherModBlocks.purpur_block, 0, 2);
		world.setBlock(i + 8, j + 12, k + 9, OtherModBlocks.purpur_block, 0, 2);
		world.setBlock(i + 9, j + 12, k + 9, OtherModBlocks.purpur_block, 0, 2);
		world.setBlock(i + 10, j + 12, k + 9, OtherModBlocks.purpur_block, 0, 2);
		world.setBlock(i + 11, j + 12, k + 9, OtherModBlocks.purpur_block, 0, 2);
		world.setBlock(i + 12, j + 12, k + 9, OtherModBlocks.purpur_block, 0, 2);
		world.setBlock(i + 13, j + 12, k + 9, OtherModBlocks.purpur_block, 0, 2);
		world.setBlock(i + 14, j + 12, k + 9, OtherModBlocks.purpur_block, 0, 2);
		world.setBlock(i + 15, j + 12, k + 9, OtherModBlocks.purpur_stairs, 1, 2);
		world.setBlock(i + 3, j + 12, k + 10, OtherModBlocks.purpur_stairs, 0, 2);
		world.setBlock(i + 4, j + 12, k + 10, OtherModBlocks.purpur_block, 0, 2);
		world.setBlock(i + 6, j + 12, k + 10, OtherModBlocks.purpur_block, 0, 2);
		world.setBlock(i + 7, j + 12, k + 10, OtherModBlocks.purpur_block, 0, 2);
		world.setBlock(i + 8, j + 12, k + 10, OtherModBlocks.purpur_block, 0, 2);
		world.setBlock(i + 9, j + 12, k + 10, OtherModBlocks.purpur_block, 0, 2);
		world.setBlock(i + 10, j + 12, k + 10, OtherModBlocks.purpur_block, 0, 2);
		world.setBlock(i + 11, j + 12, k + 10, OtherModBlocks.purpur_block, 0, 2);
		world.setBlock(i + 12, j + 12, k + 10, OtherModBlocks.purpur_block, 0, 2);
		world.setBlock(i + 13, j + 12, k + 10, OtherModBlocks.purpur_block, 0, 2);
		world.setBlock(i + 14, j + 12, k + 10, OtherModBlocks.purpur_block, 0, 2);
		world.setBlock(i + 15, j + 12, k + 10, OtherModBlocks.purpur_stairs, 1, 2);
		world.setBlock(i + 3, j + 12, k + 11, OtherModBlocks.purpur_stairs, 4, 2);
		world.setBlock(i + 4, j + 12, k + 11, OtherModBlocks.purpur_block, 0, 2);
		world.setBlock(i + 5, j + 12, k + 11, OtherModBlocks.purpur_block, 0, 2);
		world.setBlock(i + 6, j + 12, k + 11, OtherModBlocks.purpur_stairs, 3, 2);
		world.setBlock(i + 7, j + 12, k + 11, OtherModBlocks.purpur_stairs, 3, 2);
		world.setBlock(i + 8, j + 12, k + 11, OtherModBlocks.purpur_block, 0, 2);
		world.setBlock(i + 9, j + 12, k + 11, OtherModBlocks.purpur_block, 0, 2);
		world.setBlock(i + 12, j + 12, k + 11, OtherModBlocks.purpur_block, 0, 2);
		world.setBlock(i + 13, j + 12, k + 11, OtherModBlocks.purpur_block, 0, 2);
		world.setBlock(i + 14, j + 12, k + 11, OtherModBlocks.purpur_block, 0, 2);
		world.setBlock(i + 15, j + 12, k + 11, OtherModBlocks.purpur_stairs, 5, 2);
		world.setBlock(i + 3, j + 12, k + 12, OtherModBlocks.purpur_stairs, 7, 2);
		world.setBlock(i + 12, j + 12, k + 12, OtherModBlocks.purpur_stairs, 7, 2);
		world.setBlock(i + 13, j + 12, k + 12, OtherModBlocks.purpur_stairs, 7, 2);
		world.setBlock(i + 14, j + 12, k + 12, OtherModBlocks.purpur_stairs, 7, 2);
		world.setBlock(i + 15, j + 12, k + 12, OtherModBlocks.purpur_stairs, 5, 2);
		world.setBlock(i + 9, j + 12, k + 16, Blocks.ladder, 2, 2);
		world.setBlock(i + 9, j + 12, k + 17, OtherModBlocks.purpur_pillar, 0, 2);
		world.setBlock(i + 5, j + 12, k + 21, OtherModBlocks.end_rod, 1, 2);
		world.setBlock(i + 9, j + 12, k + 21, OtherModBlocks.purpur_stairs, 2, 2);
		world.setBlock(i + 13, j + 12, k + 21, OtherModBlocks.end_rod, 1, 2);
		world.setBlock(i + 9, j + 12, k + 22, OtherModBlocks.purpur_pillar, 8, 2);
		world.setBlock(i + 9, j + 12, k + 23, OtherModBlocks.purpur_pillar, 8, 2);
		world.setBlock(i + 9, j + 12, k + 27, OtherModBlocks.end_rod, 1, 2);
		world.setBlock(i + 4, j + 13, k + 4, OtherModBlocks.purpur_block, 0, 2);
		world.setBlock(i + 5, j + 13, k + 4, OtherModBlocks.purpur_stairs, 2, 2);
		world.setBlock(i + 6, j + 13, k + 4, OtherModBlocks.purpur_stairs, 2, 2);
		world.setBlock(i + 8, j + 13, k + 4, OtherModBlocks.purpur_stairs, 2, 2);
		world.setBlock(i + 9, j + 13, k + 4, OtherModBlocks.purpur_stairs, 2, 2);
		world.setBlock(i + 10, j + 13, k + 4, OtherModBlocks.purpur_stairs, 2, 2);
		world.setBlock(i + 11, j + 13, k + 4, OtherModBlocks.purpur_block, 0, 2);
		world.setBlock(i + 12, j + 13, k + 4, OtherModBlocks.purpur_stairs, 2, 2);
		world.setBlock(i + 13, j + 13, k + 4, OtherModBlocks.purpur_stairs, 2, 2);
		world.setBlock(i + 14, j + 13, k + 4, OtherModBlocks.purpur_block, 0, 2);
		world.setBlock(i + 4, j + 13, k + 5, OtherModBlocks.purpur_stairs, 0, 2);
		world.setBlock(i + 7, j + 13, k + 5, OtherModBlocks.purpur_stairs, 0, 2);
		world.setBlock(i + 8, j + 13, k + 5, OtherModBlocks.purpur_stairs, 3, 2);
		world.setBlock(i + 9, j + 13, k + 5, OtherModBlocks.purpur_stairs, 3, 2);
		world.setBlock(i + 10, j + 13, k + 5, OtherModBlocks.purpur_stairs, 3, 2);
		world.setBlock(i + 11, j + 13, k + 5, OtherModBlocks.purpur_stairs, 1, 2);
		world.setBlock(i + 14, j + 13, k + 5, OtherModBlocks.purpur_stairs, 1, 2);
		world.setBlock(i + 4, j + 13, k + 6, OtherModBlocks.purpur_stairs, 0, 2);
		world.setBlock(i + 14, j + 13, k + 6, OtherModBlocks.purpur_stairs, 1, 2);
		world.setBlock(i + 4, j + 13, k + 7, OtherModBlocks.purpur_stairs, 0, 2);
		world.setBlock(i + 14, j + 13, k + 7, OtherModBlocks.purpur_stairs, 1, 2);
		world.setBlock(i + 4, j + 13, k + 8, OtherModBlocks.purpur_stairs, 0, 2);
		world.setBlock(i + 14, j + 13, k + 8, OtherModBlocks.purpur_stairs, 1, 2);
		world.setBlock(i + 4, j + 13, k + 9, OtherModBlocks.purpur_stairs, 0, 2);
		world.setBlock(i + 11, j + 13, k + 9, OtherModBlocks.purpur_pillar, 0, 2);
		world.setBlock(i + 4, j + 13, k + 10, OtherModBlocks.purpur_stairs, 0, 2);
		world.setBlock(i + 9, j + 13, k + 10, OtherModBlocks.purpur_stairs, 1, 2);
		world.setBlock(i + 10, j + 13, k + 10, OtherModBlocks.purpur_stairs, 3, 2);
		world.setBlock(i + 11, j + 13, k + 10, OtherModBlocks.purpur_stairs, 3, 2);
		world.setBlock(i + 12, j + 13, k + 10, OtherModBlocks.purpur_stairs, 0, 2);
		world.setBlock(i + 14, j + 13, k + 10, OtherModBlocks.purpur_stairs, 1, 2);
		world.setBlock(i + 4, j + 13, k + 11, OtherModBlocks.purpur_block, 0, 2);
		world.setBlock(i + 5, j + 13, k + 11, OtherModBlocks.purpur_block, 0, 2);
		world.setBlock(i + 8, j + 13, k + 11, OtherModBlocks.purpur_block, 0, 2);
		world.setBlock(i + 9, j + 13, k + 11, OtherModBlocks.purpur_block, 0, 2);
		world.setBlock(i + 12, j + 13, k + 11, OtherModBlocks.purpur_block, 0, 2);
		world.setBlock(i + 14, j + 13, k + 11, OtherModBlocks.purpur_block, 0, 2);
		world.setBlock(i + 9, j + 13, k + 16, Blocks.ladder, 2, 2);
		world.setBlock(i + 9, j + 13, k + 17, OtherModBlocks.purpur_pillar, 0, 2);
		world.setBlock(i + 9, j + 13, k + 23, OtherModBlocks.purpur_stairs, 2, 2);
		world.setBlock(i + 9, j + 13, k + 24, OtherModBlocks.purpur_pillar, 8, 2);
		world.setBlock(i + 9, j + 13, k + 25, OtherModBlocks.purpur_pillar, 8, 2);
		world.setBlock(i + 9, j + 14, k + 16, Blocks.ladder, 2, 2);
		world.setBlock(i + 9, j + 14, k + 17, OtherModBlocks.purpur_pillar, 0, 2);
		world.setBlock(i + 9, j + 14, k + 25, OtherModBlocks.purpur_stairs, 2, 2);
		world.setBlock(i + 9, j + 14, k + 26, OtherModBlocks.purpur_pillar, 8, 2);
		world.setBlock(i + 9, j + 14, k + 27, OtherModBlocks.purpur_pillar, 8, 2);
		world.setBlock(i + 9, j + 15, k + 16, Blocks.ladder, 2, 2);
		world.setBlock(i + 9, j + 15, k + 17, OtherModBlocks.purpur_pillar, 0, 2);
		world.setBlock(i + 9, j + 15, k + 27, OtherModBlocks.purpur_stairs, 2, 2);
		world.setBlock(i + 9, j + 15, k + 28, OtherModBlocks.purpur_pillar, 8, 2);
		world.setBlock(i + 9, j + 15, k + 29, OtherModBlocks.purpur_pillar, 8, 2);
		world.setBlock(i + 9, j + 15, k + 30, OtherModBlocks.purpur_slab, 8, 2);
		world.setBlock(i + 9, j + 16, k + 16, Blocks.ladder, 2, 2);
		world.setBlock(i + 9, j + 16, k + 17, OtherModBlocks.purpur_pillar, 0, 2);
		world.setBlock(i + 9, j + 17, k + 16, Blocks.ladder, 2, 2);
		world.setBlock(i + 9, j + 17, k + 17, OtherModBlocks.purpur_pillar, 0, 2);
		world.setBlock(i + 9, j + 18, k + 16, Blocks.ladder, 2, 2);
		world.setBlock(i + 9, j + 18, k + 17, OtherModBlocks.purpur_pillar, 0, 2);
		world.setBlock(i + 9, j + 19, k + 16, Blocks.ladder, 2, 2);
		world.setBlock(i + 9, j + 19, k + 17, OtherModBlocks.purpur_pillar, 0, 2);
		world.setBlock(i + 9, j + 20, k + 16, Blocks.ladder, 2, 2);
		world.setBlock(i + 9, j + 20, k + 17, OtherModBlocks.purpur_pillar, 0, 2);
		world.setBlock(i + 9, j + 21, k + 16, Blocks.ladder, 2, 2);
		world.setBlock(i + 9, j + 21, k + 17, OtherModBlocks.purpur_pillar, 0, 2);
		world.setBlock(i + 9, j + 22, k + 16, Blocks.ladder, 2, 2);
		world.setBlock(i + 9, j + 22, k + 17, OtherModBlocks.purpur_pillar, 0, 2);
		world.setBlock(i + 8, j + 23, k + 16, OtherModBlocks.purpur_slab, 8, 2);
		world.setBlock(i + 9, j + 23, k + 16, Blocks.ladder, 2, 2);
		world.setBlock(i + 10, j + 23, k + 16, OtherModBlocks.purpur_slab, 8, 2);
		world.setBlock(i + 8, j + 23, k + 17, OtherModBlocks.purpur_slab, 8, 2);
		world.setBlock(i + 9, j + 23, k + 17, OtherModBlocks.purpur_pillar, 0, 2);
		world.setBlock(i + 10, j + 23, k + 17, OtherModBlocks.purpur_slab, 8, 2);
		world.setBlock(i + 8, j + 23, k + 18, OtherModBlocks.purpur_slab, 8, 2);
		world.setBlock(i + 10, j + 23, k + 18, OtherModBlocks.purpur_slab, 8, 2);
		world.setBlock(i + 7, j + 24, k + 15, OtherModBlocks.purpur_stairs, 6, 2);
		world.setBlock(i + 8, j + 24, k + 15, OtherModBlocks.purpur_stairs, 6, 2);
		world.setBlock(i + 9, j + 24, k + 15, OtherModBlocks.purpur_stairs, 6, 2);
		world.setBlock(i + 10, j + 24, k + 15, OtherModBlocks.purpur_stairs, 6, 2);
		world.setBlock(i + 11, j + 24, k + 15, OtherModBlocks.purpur_stairs, 5, 2);
		world.setBlock(i + 7, j + 24, k + 16, OtherModBlocks.purpur_stairs, 4, 2);
		world.setBlock(i + 9, j + 24, k + 16, Blocks.ladder, 2, 2);
		world.setBlock(i + 11, j + 24, k + 16, OtherModBlocks.purpur_stairs, 5, 2);
		world.setBlock(i + 9, j + 24, k + 17, OtherModBlocks.purpur_pillar, 0, 2);
		world.setBlock(i + 11, j + 24, k + 17, OtherModBlocks.purpur_stairs, 5, 2);
		world.setBlock(i + 7, j + 24, k + 18, OtherModBlocks.purpur_stairs, 4, 2);
		world.setBlock(i + 11, j + 24, k + 18, OtherModBlocks.purpur_stairs, 5, 2);
		world.setBlock(i + 7, j + 24, k + 19, OtherModBlocks.purpur_stairs, 4, 2);
		world.setBlock(i + 8, j + 24, k + 19, OtherModBlocks.purpur_stairs, 7, 2);
		world.setBlock(i + 9, j + 24, k + 19, OtherModBlocks.purpur_stairs, 7, 2);
		world.setBlock(i + 10, j + 24, k + 19, OtherModBlocks.purpur_stairs, 7, 2);
		world.setBlock(i + 11, j + 24, k + 19, OtherModBlocks.purpur_stairs, 7, 2);
		world.setBlock(i + 9, j + 25, k + 17, OtherModBlocks.purpur_pillar, 0, 2);

		
    	return true;
    }
    
}
