package com.NovaCraft.world.end.endcamp;

import net.minecraft.world.gen.feature.*;
import net.minecraft.block.*;
import net.minecraft.world.*;
import java.util.*;

import com.NovaCraft.registry.OtherModBlocks;
import com.NovaCraftBlocks.NovaCraftBlocks;

import net.minecraft.init.*;

public class EnderSettlementSmallEndTowerGen extends WorldGenerator
{
	public EnderSettlementSmallEndTowerGen() {

	}
    
    public boolean generate(final World world, final Random random, final int i, final int j, final int k) {	
    	
		world.setBlock(i + 12, j + 0, k + 11, Blocks.end_stone, 0, 2);
		world.setBlock(i + 9, j + 1, k + 2, Blocks.end_stone, 0, 2);
		world.setBlock(i + 5, j + 1, k + 8, Blocks.end_stone, 0, 2);
		world.setBlock(i + 7, j + 1, k + 9, Blocks.end_stone, 0, 2);
		world.setBlock(i + 12, j + 1, k + 11, Blocks.end_stone, 0, 2);
		world.setBlock(i + 10, j + 1, k + 14, Blocks.end_stone, 0, 2);
		world.setBlock(i + 8, j + 2, k + 2, Blocks.end_stone, 0, 2);
		world.setBlock(i + 9, j + 2, k + 2, Blocks.end_stone, 0, 2);
		world.setBlock(i + 6, j + 2, k + 3, Blocks.end_stone, 0, 2);
		world.setBlock(i + 7, j + 2, k + 3, Blocks.end_stone, 0, 2);
		world.setBlock(i + 8, j + 2, k + 3, Blocks.end_stone, 0, 2);
		world.setBlock(i + 8, j + 2, k + 4, Blocks.end_stone, 0, 2);
		world.setBlock(i + 9, j + 2, k + 4, Blocks.end_stone, 0, 2);
		world.setBlock(i + 11, j + 2, k + 4, Blocks.end_stone, 0, 2);
		world.setBlock(i + 7, j + 2, k + 5, Blocks.end_stone, 0, 2);
		world.setBlock(i + 9, j + 2, k + 5, Blocks.end_stone, 0, 2);
		world.setBlock(i + 10, j + 2, k + 5, Blocks.end_stone, 0, 2);
		world.setBlock(i + 11, j + 2, k + 5, Blocks.end_stone, 0, 2);
		world.setBlock(i + 7, j + 2, k + 6, Blocks.end_stone, 0, 2);
		world.setBlock(i + 8, j + 2, k + 6, Blocks.end_stone, 0, 2);
		world.setBlock(i + 9, j + 2, k + 6, Blocks.end_stone, 0, 2);
		world.setBlock(i + 12, j + 2, k + 6, Blocks.end_stone, 0, 2);
		world.setBlock(i + 13, j + 2, k + 7, Blocks.end_stone, 0, 2);
		world.setBlock(i + 5, j + 2, k + 8, Blocks.end_stone, 0, 2);
		world.setBlock(i + 6, j + 2, k + 8, Blocks.end_stone, 0, 2);
		world.setBlock(i + 9, j + 2, k + 8, Blocks.end_stone, 0, 2);
		world.setBlock(i + 10, j + 2, k + 8, Blocks.end_stone, 0, 2);
		world.setBlock(i + 7, j + 2, k + 9, Blocks.end_stone, 0, 2);
		world.setBlock(i + 9, j + 2, k + 9, Blocks.end_stone, 0, 2);
		world.setBlock(i + 11, j + 2, k + 9, Blocks.end_stone, 0, 2);
		world.setBlock(i + 13, j + 2, k + 9, Blocks.end_stone, 0, 2);
		world.setBlock(i + 14, j + 2, k + 9, Blocks.end_stone, 0, 2);
		world.setBlock(i + 12, j + 2, k + 10, Blocks.end_stone, 0, 2);
		world.setBlock(i + 8, j + 2, k + 11, Blocks.end_stone, 0, 2);
		world.setBlock(i + 12, j + 2, k + 11, Blocks.end_stone, 0, 2);
		world.setBlock(i + 13, j + 2, k + 11, Blocks.end_stone, 0, 2);
		world.setBlock(i + 8, j + 2, k + 12, Blocks.end_stone, 0, 2);
		world.setBlock(i + 9, j + 2, k + 12, Blocks.end_stone, 0, 2);
		world.setBlock(i + 10, j + 2, k + 12, Blocks.end_stone, 0, 2);
		world.setBlock(i + 7, j + 2, k + 13, Blocks.end_stone, 0, 2);
		world.setBlock(i + 7, j + 2, k + 14, Blocks.end_stone, 0, 2);
		world.setBlock(i + 10, j + 2, k + 14, Blocks.end_stone, 0, 2);
		world.setBlock(i + 9, j + 2, k + 15, Blocks.end_stone, 0, 2);
		world.setBlock(i + 10, j + 2, k + 15, Blocks.end_stone, 0, 2);
		world.setBlock(i + 9, j + 3, k + 1, Blocks.end_stone, 0, 2);
		world.setBlock(i + 8, j + 3, k + 2, Blocks.end_stone, 0, 2);
		world.setBlock(i + 9, j + 3, k + 2, Blocks.end_stone, 0, 2);
		world.setBlock(i + 10, j + 3, k + 2, Blocks.end_stone, 0, 2);
		world.setBlock(i + 7, j + 3, k + 3, Blocks.end_stone, 0, 2);
		world.setBlock(i + 8, j + 3, k + 3, Blocks.end_stone, 0, 2);
		world.setBlock(i + 9, j + 3, k + 3, Blocks.end_stone, 0, 2);
		world.setBlock(i + 10, j + 3, k + 3, Blocks.end_stone, 0, 2);
		world.setBlock(i + 11, j + 3, k + 3, Blocks.end_stone, 0, 2);
		world.setBlock(i + 6, j + 3, k + 4, Blocks.end_stone, 0, 2);
		world.setBlock(i + 7, j + 3, k + 4, Blocks.end_stone, 0, 2);
		world.setBlock(i + 8, j + 3, k + 4, Blocks.end_stone, 0, 2);
		world.setBlock(i + 9, j + 3, k + 4, Blocks.end_stone, 0, 2);
		world.setBlock(i + 10, j + 3, k + 4, Blocks.end_stone, 0, 2);
		world.setBlock(i + 11, j + 3, k + 4, Blocks.end_stone, 0, 2);
		world.setBlock(i + 12, j + 3, k + 4, Blocks.end_stone, 0, 2);
		world.setBlock(i + 5, j + 3, k + 5, Blocks.end_stone, 0, 2);
		world.setBlock(i + 6, j + 3, k + 5, Blocks.end_stone, 0, 2);
		world.setBlock(i + 7, j + 3, k + 5, Blocks.end_stone, 0, 2);
		world.setBlock(i + 8, j + 3, k + 5, Blocks.end_stone, 0, 2);
		world.setBlock(i + 9, j + 3, k + 5, Blocks.end_stone, 0, 2);
		world.setBlock(i + 10, j + 3, k + 5, Blocks.end_stone, 0, 2);
		world.setBlock(i + 11, j + 3, k + 5, Blocks.end_stone, 0, 2);
		world.setBlock(i + 12, j + 3, k + 5, Blocks.end_stone, 0, 2);
		world.setBlock(i + 13, j + 3, k + 5, Blocks.end_stone, 0, 2);
		world.setBlock(i + 5, j + 3, k + 6, Blocks.end_stone, 0, 2);
		world.setBlock(i + 6, j + 3, k + 6, Blocks.end_stone, 0, 2);
		world.setBlock(i + 7, j + 3, k + 6, Blocks.end_stone, 0, 2);
		world.setBlock(i + 8, j + 3, k + 6, Blocks.end_stone, 0, 2);
		world.setBlock(i + 9, j + 3, k + 6, Blocks.end_stone, 0, 2);
		world.setBlock(i + 10, j + 3, k + 6, Blocks.end_stone, 0, 2);
		world.setBlock(i + 11, j + 3, k + 6, Blocks.end_stone, 0, 2);
		world.setBlock(i + 12, j + 3, k + 6, Blocks.end_stone, 0, 2);
		world.setBlock(i + 13, j + 3, k + 6, Blocks.end_stone, 0, 2);
		world.setBlock(i + 4, j + 3, k + 7, Blocks.end_stone, 0, 2);
		world.setBlock(i + 5, j + 3, k + 7, Blocks.end_stone, 0, 2);
		world.setBlock(i + 6, j + 3, k + 7, Blocks.end_stone, 0, 2);
		world.setBlock(i + 7, j + 3, k + 7, Blocks.end_stone, 0, 2);
		world.setBlock(i + 8, j + 3, k + 7, Blocks.end_stone, 0, 2);
		world.setBlock(i + 9, j + 3, k + 7, Blocks.end_stone, 0, 2);
		world.setBlock(i + 10, j + 3, k + 7, Blocks.end_stone, 0, 2);
		world.setBlock(i + 11, j + 3, k + 7, Blocks.end_stone, 0, 2);
		world.setBlock(i + 12, j + 3, k + 7, Blocks.end_stone, 0, 2);
		world.setBlock(i + 13, j + 3, k + 7, Blocks.end_stone, 0, 2);
		world.setBlock(i + 14, j + 3, k + 7, Blocks.end_stone, 0, 2);
		world.setBlock(i + 3, j + 3, k + 8, Blocks.end_stone, 0, 2);
		world.setBlock(i + 5, j + 3, k + 8, Blocks.end_stone, 0, 2);
		world.setBlock(i + 6, j + 3, k + 8, Blocks.end_stone, 0, 2);
		world.setBlock(i + 7, j + 3, k + 8, Blocks.end_stone, 0, 2);
		world.setBlock(i + 8, j + 3, k + 8, Blocks.end_stone, 0, 2);
		world.setBlock(i + 9, j + 3, k + 8, Blocks.end_stone, 0, 2);
		world.setBlock(i + 10, j + 3, k + 8, Blocks.end_stone, 0, 2);
		world.setBlock(i + 11, j + 3, k + 8, Blocks.end_stone, 0, 2);
		world.setBlock(i + 12, j + 3, k + 8, Blocks.end_stone, 0, 2);
		world.setBlock(i + 13, j + 3, k + 8, Blocks.end_stone, 0, 2);
		world.setBlock(i + 14, j + 3, k + 8, Blocks.end_stone, 0, 2);
		world.setBlock(i + 15, j + 3, k + 8, Blocks.end_stone, 0, 2);
		world.setBlock(i + 2, j + 3, k + 9, Blocks.end_stone, 0, 2);
		world.setBlock(i + 5, j + 3, k + 9, Blocks.end_stone, 0, 2);
		world.setBlock(i + 6, j + 3, k + 9, Blocks.end_stone, 0, 2);
		world.setBlock(i + 7, j + 3, k + 9, Blocks.end_stone, 0, 2);
		world.setBlock(i + 8, j + 3, k + 9, Blocks.end_stone, 0, 2);
		world.setBlock(i + 9, j + 3, k + 9, Blocks.end_stone, 0, 2);
		world.setBlock(i + 10, j + 3, k + 9, Blocks.end_stone, 0, 2);
		world.setBlock(i + 11, j + 3, k + 9, Blocks.end_stone, 0, 2);
		world.setBlock(i + 12, j + 3, k + 9, Blocks.end_stone, 0, 2);
		world.setBlock(i + 13, j + 3, k + 9, Blocks.end_stone, 0, 2);
		world.setBlock(i + 14, j + 3, k + 9, Blocks.end_stone, 0, 2);
		world.setBlock(i + 15, j + 3, k + 9, Blocks.end_stone, 0, 2);
		world.setBlock(i + 16, j + 3, k + 9, Blocks.end_stone, 0, 2);
		world.setBlock(i + 3, j + 3, k + 10, Blocks.end_stone, 0, 2);
		world.setBlock(i + 5, j + 3, k + 10, Blocks.end_stone, 0, 2);
		world.setBlock(i + 6, j + 3, k + 10, Blocks.end_stone, 0, 2);
		world.setBlock(i + 7, j + 3, k + 10, Blocks.end_stone, 0, 2);
		world.setBlock(i + 8, j + 3, k + 10, Blocks.end_stone, 0, 2);
		world.setBlock(i + 9, j + 3, k + 10, Blocks.end_stone, 0, 2);
		world.setBlock(i + 10, j + 3, k + 10, Blocks.end_stone, 0, 2);
		world.setBlock(i + 11, j + 3, k + 10, Blocks.end_stone, 0, 2);
		world.setBlock(i + 12, j + 3, k + 10, Blocks.end_stone, 0, 2);
		world.setBlock(i + 13, j + 3, k + 10, Blocks.end_stone, 0, 2);
		world.setBlock(i + 14, j + 3, k + 10, Blocks.end_stone, 0, 2);
		world.setBlock(i + 15, j + 3, k + 10, Blocks.end_stone, 0, 2);
		world.setBlock(i + 4, j + 3, k + 11, Blocks.end_stone, 0, 2);
		world.setBlock(i + 5, j + 3, k + 11, Blocks.end_stone, 0, 2);
		world.setBlock(i + 6, j + 3, k + 11, Blocks.end_stone, 0, 2);
		world.setBlock(i + 7, j + 3, k + 11, Blocks.end_stone, 0, 2);
		world.setBlock(i + 8, j + 3, k + 11, Blocks.end_stone, 0, 2);
		world.setBlock(i + 9, j + 3, k + 11, Blocks.end_stone, 0, 2);
		world.setBlock(i + 10, j + 3, k + 11, Blocks.end_stone, 0, 2);
		world.setBlock(i + 11, j + 3, k + 11, Blocks.end_stone, 0, 2);
		world.setBlock(i + 12, j + 3, k + 11, Blocks.end_stone, 0, 2);
		world.setBlock(i + 13, j + 3, k + 11, Blocks.end_stone, 0, 2);
		world.setBlock(i + 14, j + 3, k + 11, Blocks.end_stone, 0, 2);
		world.setBlock(i + 5, j + 3, k + 12, Blocks.end_stone, 0, 2);
		world.setBlock(i + 6, j + 3, k + 12, Blocks.end_stone, 0, 2);
		world.setBlock(i + 7, j + 3, k + 12, Blocks.end_stone, 0, 2);
		world.setBlock(i + 8, j + 3, k + 12, Blocks.end_stone, 0, 2);
		world.setBlock(i + 9, j + 3, k + 12, Blocks.end_stone, 0, 2);
		world.setBlock(i + 10, j + 3, k + 12, Blocks.end_stone, 0, 2);
		world.setBlock(i + 11, j + 3, k + 12, Blocks.end_stone, 0, 2);
		world.setBlock(i + 12, j + 3, k + 12, Blocks.end_stone, 0, 2);
		world.setBlock(i + 13, j + 3, k + 12, Blocks.end_stone, 0, 2);
		world.setBlock(i + 14, j + 3, k + 12, Blocks.end_stone, 0, 2);
		world.setBlock(i + 5, j + 3, k + 13, Blocks.end_stone, 0, 2);
		world.setBlock(i + 6, j + 3, k + 13, Blocks.end_stone, 0, 2);
		world.setBlock(i + 7, j + 3, k + 13, Blocks.end_stone, 0, 2);
		world.setBlock(i + 8, j + 3, k + 13, Blocks.end_stone, 0, 2);
		world.setBlock(i + 9, j + 3, k + 13, Blocks.end_stone, 0, 2);
		world.setBlock(i + 10, j + 3, k + 13, Blocks.end_stone, 0, 2);
		world.setBlock(i + 11, j + 3, k + 13, Blocks.end_stone, 0, 2);
		world.setBlock(i + 12, j + 3, k + 13, Blocks.end_stone, 0, 2);
		world.setBlock(i + 13, j + 3, k + 13, Blocks.end_stone, 0, 2);
		world.setBlock(i + 6, j + 3, k + 14, Blocks.end_stone, 0, 2);
		world.setBlock(i + 7, j + 3, k + 14, Blocks.end_stone, 0, 2);
		world.setBlock(i + 8, j + 3, k + 14, Blocks.end_stone, 0, 2);
		world.setBlock(i + 9, j + 3, k + 14, Blocks.end_stone, 0, 2);
		world.setBlock(i + 10, j + 3, k + 14, Blocks.end_stone, 0, 2);
		world.setBlock(i + 11, j + 3, k + 14, Blocks.end_stone, 0, 2);
		world.setBlock(i + 12, j + 3, k + 14, Blocks.end_stone, 0, 2);
		world.setBlock(i + 7, j + 3, k + 15, Blocks.end_stone, 0, 2);
		world.setBlock(i + 8, j + 3, k + 15, Blocks.end_stone, 0, 2);
		world.setBlock(i + 9, j + 3, k + 15, Blocks.end_stone, 0, 2);
		world.setBlock(i + 10, j + 3, k + 15, Blocks.end_stone, 0, 2);
		world.setBlock(i + 11, j + 3, k + 15, Blocks.end_stone, 0, 2);
		world.setBlock(i + 8, j + 3, k + 16, Blocks.end_stone, 0, 2);
		world.setBlock(i + 9, j + 3, k + 16, Blocks.end_stone, 0, 2);
		world.setBlock(i + 10, j + 3, k + 16, Blocks.end_stone, 0, 2);
		world.setBlock(i + 9, j + 3, k + 17, Blocks.end_stone, 0, 2);
		world.setBlock(i + 9, j + 4, k + 1, Blocks.end_stone, 0, 2);
		world.setBlock(i + 8, j + 4, k + 2, Blocks.end_stone, 0, 2);
		world.setBlock(i + 9, j + 4, k + 2, Blocks.end_stone, 0, 2);
		world.setBlock(i + 10, j + 4, k + 2, Blocks.end_stone, 0, 2);
		world.setBlock(i + 7, j + 4, k + 3, Blocks.end_stone, 0, 2);
		world.setBlock(i + 8, j + 4, k + 3, Blocks.end_stone, 0, 2);
		world.setBlock(i + 9, j + 4, k + 3, Blocks.end_stone, 0, 2);
		world.setBlock(i + 10, j + 4, k + 3, Blocks.end_stone, 0, 2);
		world.setBlock(i + 11, j + 4, k + 3, Blocks.end_stone, 0, 2);
		world.setBlock(i + 6, j + 4, k + 4, Blocks.end_stone, 0, 2);
		world.setBlock(i + 7, j + 4, k + 4, Blocks.end_stone, 0, 2);
		world.setBlock(i + 8, j + 4, k + 4, Blocks.end_stone, 0, 2);
		world.setBlock(i + 9, j + 4, k + 4, Blocks.end_stone, 0, 2);
		world.setBlock(i + 10, j + 4, k + 4, Blocks.end_stone, 0, 2);
		world.setBlock(i + 11, j + 4, k + 4, Blocks.end_stone, 0, 2);
		world.setBlock(i + 12, j + 4, k + 4, Blocks.end_stone, 0, 2);
		world.setBlock(i + 5, j + 4, k + 5, Blocks.end_stone, 0, 2);
		world.setBlock(i + 6, j + 4, k + 5, Blocks.end_stone, 0, 2);
		world.setBlock(i + 7, j + 4, k + 5, Blocks.end_stone, 0, 2);
		world.setBlock(i + 8, j + 4, k + 5, Blocks.end_stone, 0, 2);
		world.setBlock(i + 9, j + 4, k + 5, Blocks.end_stone, 0, 2);
		world.setBlock(i + 10, j + 4, k + 5, Blocks.end_stone, 0, 2);
		world.setBlock(i + 11, j + 4, k + 5, Blocks.end_stone, 0, 2);
		world.setBlock(i + 12, j + 4, k + 5, Blocks.end_stone, 0, 2);
		world.setBlock(i + 13, j + 4, k + 5, Blocks.end_stone, 0, 2);
		world.setBlock(i + 4, j + 4, k + 6, Blocks.end_stone, 0, 2);
		world.setBlock(i + 5, j + 4, k + 6, Blocks.end_stone, 0, 2);
		world.setBlock(i + 6, j + 4, k + 6, Blocks.end_stone, 0, 2);
		world.setBlock(i + 7, j + 4, k + 6, Blocks.end_stone, 0, 2);
		world.setBlock(i + 8, j + 4, k + 6, Blocks.end_stone, 0, 2);
		world.setBlock(i + 9, j + 4, k + 6, Blocks.end_stone, 0, 2);
		world.setBlock(i + 10, j + 4, k + 6, Blocks.end_stone, 0, 2);
		world.setBlock(i + 11, j + 4, k + 6, Blocks.end_stone, 0, 2);
		world.setBlock(i + 12, j + 4, k + 6, Blocks.end_stone, 0, 2);
		world.setBlock(i + 13, j + 4, k + 6, Blocks.end_stone, 0, 2);
		world.setBlock(i + 14, j + 4, k + 6, Blocks.end_stone, 0, 2);
		world.setBlock(i + 3, j + 4, k + 7, Blocks.end_stone, 0, 2);
		world.setBlock(i + 4, j + 4, k + 7, Blocks.end_stone, 0, 2);
		world.setBlock(i + 5, j + 4, k + 7, Blocks.end_stone, 0, 2);
		world.setBlock(i + 6, j + 4, k + 7, Blocks.end_stone, 0, 2);
		world.setBlock(i + 7, j + 4, k + 7, Blocks.end_stone, 0, 2);
		world.setBlock(i + 8, j + 4, k + 7, Blocks.end_stone, 0, 2);
		world.setBlock(i + 9, j + 4, k + 7, Blocks.end_stone, 0, 2);
		world.setBlock(i + 10, j + 4, k + 7, Blocks.end_stone, 0, 2);
		world.setBlock(i + 11, j + 4, k + 7, Blocks.end_stone, 0, 2);
		world.setBlock(i + 12, j + 4, k + 7, Blocks.end_stone, 0, 2);
		world.setBlock(i + 13, j + 4, k + 7, Blocks.end_stone, 0, 2);
		world.setBlock(i + 14, j + 4, k + 7, Blocks.end_stone, 0, 2);
		world.setBlock(i + 15, j + 4, k + 7, Blocks.end_stone, 0, 2);
		world.setBlock(i + 2, j + 4, k + 8, Blocks.end_stone, 0, 2);
		world.setBlock(i + 3, j + 4, k + 8, Blocks.end_stone, 0, 2);
		world.setBlock(i + 4, j + 4, k + 8, Blocks.end_stone, 0, 2);
		world.setBlock(i + 5, j + 4, k + 8, Blocks.end_stone, 0, 2);
		world.setBlock(i + 6, j + 4, k + 8, Blocks.end_stone, 0, 2);
		world.setBlock(i + 7, j + 4, k + 8, Blocks.end_stone, 0, 2);
		world.setBlock(i + 8, j + 4, k + 8, Blocks.end_stone, 0, 2);
		world.setBlock(i + 9, j + 4, k + 8, Blocks.end_stone, 0, 2);
		world.setBlock(i + 10, j + 4, k + 8, Blocks.end_stone, 0, 2);
		world.setBlock(i + 11, j + 4, k + 8, Blocks.end_stone, 0, 2);
		world.setBlock(i + 12, j + 4, k + 8, Blocks.end_stone, 0, 2);
		world.setBlock(i + 13, j + 4, k + 8, Blocks.end_stone, 0, 2);
		world.setBlock(i + 14, j + 4, k + 8, Blocks.end_stone, 0, 2);
		world.setBlock(i + 15, j + 4, k + 8, Blocks.end_stone, 0, 2);
		world.setBlock(i + 16, j + 4, k + 8, Blocks.end_stone, 0, 2);
		world.setBlock(i + 1, j + 4, k + 9, Blocks.end_stone, 0, 2);
		world.setBlock(i + 2, j + 4, k + 9, Blocks.end_stone, 0, 2);
		world.setBlock(i + 3, j + 4, k + 9, Blocks.end_stone, 0, 2);
		world.setBlock(i + 4, j + 4, k + 9, Blocks.end_stone, 0, 2);
		world.setBlock(i + 5, j + 4, k + 9, Blocks.end_stone, 0, 2);
		world.setBlock(i + 6, j + 4, k + 9, Blocks.end_stone, 0, 2);
		world.setBlock(i + 7, j + 4, k + 9, Blocks.end_stone, 0, 2);
		world.setBlock(i + 8, j + 4, k + 9, Blocks.end_stone, 0, 2);
		world.setBlock(i + 9, j + 4, k + 9, Blocks.end_stone, 0, 2);
		world.setBlock(i + 10, j + 4, k + 9, Blocks.end_stone, 0, 2);
		world.setBlock(i + 11, j + 4, k + 9, Blocks.end_stone, 0, 2);
		world.setBlock(i + 12, j + 4, k + 9, Blocks.end_stone, 0, 2);
		world.setBlock(i + 13, j + 4, k + 9, Blocks.end_stone, 0, 2);
		world.setBlock(i + 14, j + 4, k + 9, Blocks.end_stone, 0, 2);
		world.setBlock(i + 15, j + 4, k + 9, Blocks.end_stone, 0, 2);
		world.setBlock(i + 16, j + 4, k + 9, Blocks.end_stone, 0, 2);
		world.setBlock(i + 17, j + 4, k + 9, Blocks.end_stone, 0, 2);
		world.setBlock(i + 2, j + 4, k + 10, Blocks.end_stone, 0, 2);
		world.setBlock(i + 3, j + 4, k + 10, Blocks.end_stone, 0, 2);
		world.setBlock(i + 4, j + 4, k + 10, Blocks.end_stone, 0, 2);
		world.setBlock(i + 5, j + 4, k + 10, Blocks.end_stone, 0, 2);
		world.setBlock(i + 6, j + 4, k + 10, Blocks.end_stone, 0, 2);
		world.setBlock(i + 7, j + 4, k + 10, Blocks.end_stone, 0, 2);
		world.setBlock(i + 8, j + 4, k + 10, Blocks.end_stone, 0, 2);
		world.setBlock(i + 9, j + 4, k + 10, Blocks.end_stone, 0, 2);
		world.setBlock(i + 10, j + 4, k + 10, Blocks.end_stone, 0, 2);
		world.setBlock(i + 11, j + 4, k + 10, Blocks.end_stone, 0, 2);
		world.setBlock(i + 12, j + 4, k + 10, Blocks.end_stone, 0, 2);
		world.setBlock(i + 13, j + 4, k + 10, Blocks.end_stone, 0, 2);
		world.setBlock(i + 14, j + 4, k + 10, Blocks.end_stone, 0, 2);
		world.setBlock(i + 15, j + 4, k + 10, Blocks.end_stone, 0, 2);
		world.setBlock(i + 16, j + 4, k + 10, Blocks.end_stone, 0, 2);
		world.setBlock(i + 3, j + 4, k + 11, Blocks.end_stone, 0, 2);
		world.setBlock(i + 4, j + 4, k + 11, Blocks.end_stone, 0, 2);
		world.setBlock(i + 5, j + 4, k + 11, Blocks.end_stone, 0, 2);
		world.setBlock(i + 6, j + 4, k + 11, Blocks.end_stone, 0, 2);
		world.setBlock(i + 7, j + 4, k + 11, Blocks.end_stone, 0, 2);
		world.setBlock(i + 8, j + 4, k + 11, Blocks.end_stone, 0, 2);
		world.setBlock(i + 9, j + 4, k + 11, Blocks.end_stone, 0, 2);
		world.setBlock(i + 10, j + 4, k + 11, Blocks.end_stone, 0, 2);
		world.setBlock(i + 11, j + 4, k + 11, Blocks.end_stone, 0, 2);
		world.setBlock(i + 12, j + 4, k + 11, Blocks.end_stone, 0, 2);
		world.setBlock(i + 13, j + 4, k + 11, Blocks.end_stone, 0, 2);
		world.setBlock(i + 14, j + 4, k + 11, Blocks.end_stone, 0, 2);
		world.setBlock(i + 15, j + 4, k + 11, Blocks.end_stone, 0, 2);
		world.setBlock(i + 4, j + 4, k + 12, Blocks.end_stone, 0, 2);
		world.setBlock(i + 5, j + 4, k + 12, Blocks.end_stone, 0, 2);
		world.setBlock(i + 6, j + 4, k + 12, Blocks.end_stone, 0, 2);
		world.setBlock(i + 7, j + 4, k + 12, Blocks.end_stone, 0, 2);
		world.setBlock(i + 8, j + 4, k + 12, Blocks.end_stone, 0, 2);
		world.setBlock(i + 9, j + 4, k + 12, Blocks.end_stone, 0, 2);
		world.setBlock(i + 10, j + 4, k + 12, Blocks.end_stone, 0, 2);
		world.setBlock(i + 11, j + 4, k + 12, Blocks.end_stone, 0, 2);
		world.setBlock(i + 12, j + 4, k + 12, Blocks.end_stone, 0, 2);
		world.setBlock(i + 13, j + 4, k + 12, Blocks.end_stone, 0, 2);
		world.setBlock(i + 14, j + 4, k + 12, Blocks.end_stone, 0, 2);
		world.setBlock(i + 5, j + 4, k + 13, Blocks.end_stone, 0, 2);
		world.setBlock(i + 6, j + 4, k + 13, Blocks.end_stone, 0, 2);
		world.setBlock(i + 7, j + 4, k + 13, Blocks.end_stone, 0, 2);
		world.setBlock(i + 8, j + 4, k + 13, Blocks.end_stone, 0, 2);
		world.setBlock(i + 9, j + 4, k + 13, Blocks.end_stone, 0, 2);
		world.setBlock(i + 10, j + 4, k + 13, Blocks.end_stone, 0, 2);
		world.setBlock(i + 11, j + 4, k + 13, Blocks.end_stone, 0, 2);
		world.setBlock(i + 12, j + 4, k + 13, Blocks.end_stone, 0, 2);
		world.setBlock(i + 13, j + 4, k + 13, Blocks.end_stone, 0, 2);
		world.setBlock(i + 6, j + 4, k + 14, Blocks.end_stone, 0, 2);
		world.setBlock(i + 7, j + 4, k + 14, Blocks.end_stone, 0, 2);
		world.setBlock(i + 8, j + 4, k + 14, Blocks.end_stone, 0, 2);
		world.setBlock(i + 9, j + 4, k + 14, Blocks.end_stone, 0, 2);
		world.setBlock(i + 10, j + 4, k + 14, Blocks.end_stone, 0, 2);
		world.setBlock(i + 11, j + 4, k + 14, Blocks.end_stone, 0, 2);
		world.setBlock(i + 12, j + 4, k + 14, Blocks.end_stone, 0, 2);
		world.setBlock(i + 7, j + 4, k + 15, Blocks.end_stone, 0, 2);
		world.setBlock(i + 8, j + 4, k + 15, Blocks.end_stone, 0, 2);
		world.setBlock(i + 9, j + 4, k + 15, Blocks.end_stone, 0, 2);
		world.setBlock(i + 10, j + 4, k + 15, Blocks.end_stone, 0, 2);
		world.setBlock(i + 11, j + 4, k + 15, Blocks.end_stone, 0, 2);
		world.setBlock(i + 8, j + 4, k + 16, Blocks.end_stone, 0, 2);
		world.setBlock(i + 9, j + 4, k + 16, Blocks.end_stone, 0, 2);
		world.setBlock(i + 10, j + 4, k + 16, Blocks.end_stone, 0, 2);
		world.setBlock(i + 9, j + 4, k + 17, Blocks.end_stone, 0, 2);
		world.setBlock(i + 9, j + 5, k + 0, OtherModBlocks.end_bricks, 0, 2);
		world.setBlock(i + 8, j + 5, k + 1, OtherModBlocks.end_bricks, 0, 2);
		world.setBlock(i + 9, j + 5, k + 1, Blocks.end_stone, 0, 2);
		world.setBlock(i + 10, j + 5, k + 1, OtherModBlocks.end_bricks, 0, 2);
		world.setBlock(i + 7, j + 5, k + 2, OtherModBlocks.end_bricks, 0, 2);
		world.setBlock(i + 8, j + 5, k + 2, Blocks.end_stone, 0, 2);
		world.setBlock(i + 9, j + 5, k + 2, Blocks.end_stone, 0, 2);
		world.setBlock(i + 10, j + 5, k + 2, Blocks.end_stone, 0, 2);
		world.setBlock(i + 11, j + 5, k + 2, OtherModBlocks.end_bricks, 0, 2);
		world.setBlock(i + 6, j + 5, k + 3, OtherModBlocks.end_bricks, 0, 2);
		world.setBlock(i + 7, j + 5, k + 3, Blocks.end_stone, 0, 2);
		world.setBlock(i + 8, j + 5, k + 3, Blocks.end_stone, 0, 2);
		world.setBlock(i + 9, j + 5, k + 3, Blocks.end_stone, 0, 2);
		world.setBlock(i + 10, j + 5, k + 3, Blocks.end_stone, 0, 2);
		world.setBlock(i + 11, j + 5, k + 3, Blocks.end_stone, 0, 2);
		world.setBlock(i + 12, j + 5, k + 3, OtherModBlocks.end_bricks, 0, 2);
		world.setBlock(i + 5, j + 5, k + 4, OtherModBlocks.end_bricks, 0, 2);
		world.setBlock(i + 6, j + 5, k + 4, Blocks.end_stone, 0, 2);
		world.setBlock(i + 7, j + 5, k + 4, Blocks.end_stone, 0, 2);
		world.setBlock(i + 8, j + 5, k + 4, Blocks.end_stone, 0, 2);
		world.setBlock(i + 9, j + 5, k + 4, Blocks.end_stone, 0, 2);
		world.setBlock(i + 10, j + 5, k + 4, Blocks.end_stone, 0, 2);
		world.setBlock(i + 11, j + 5, k + 4, Blocks.end_stone, 0, 2);
		world.setBlock(i + 12, j + 5, k + 4, Blocks.end_stone, 0, 2);
		world.setBlock(i + 13, j + 5, k + 4, OtherModBlocks.end_bricks, 0, 2);
		world.setBlock(i + 4, j + 5, k + 5, OtherModBlocks.end_bricks, 0, 2);
		world.setBlock(i + 5, j + 5, k + 5, Blocks.end_stone, 0, 2);
		world.setBlock(i + 6, j + 5, k + 5, Blocks.end_stone, 0, 2);
		world.setBlock(i + 7, j + 5, k + 5, Blocks.obsidian, 0, 2);
		world.setBlock(i + 8, j + 5, k + 5, Blocks.obsidian, 0, 2);
		world.setBlock(i + 9, j + 5, k + 5, Blocks.obsidian, 0, 2);
		world.setBlock(i + 10, j + 5, k + 5, Blocks.obsidian, 0, 2);
		world.setBlock(i + 11, j + 5, k + 5, Blocks.obsidian, 0, 2);
		world.setBlock(i + 12, j + 5, k + 5, Blocks.end_stone, 0, 2);
		world.setBlock(i + 13, j + 5, k + 5, Blocks.end_stone, 0, 2);
		world.setBlock(i + 14, j + 5, k + 5, OtherModBlocks.end_bricks, 0, 2);
		world.setBlock(i + 3, j + 5, k + 6, OtherModBlocks.end_bricks, 0, 2);
		world.setBlock(i + 4, j + 5, k + 6, Blocks.end_stone, 0, 2);
		world.setBlock(i + 5, j + 5, k + 6, Blocks.end_stone, 0, 2);
		world.setBlock(i + 6, j + 5, k + 6, Blocks.obsidian, 0, 2);
		world.setBlock(i + 7, j + 5, k + 6, Blocks.obsidian, 0, 2);
		world.setBlock(i + 8, j + 5, k + 6, NovaCraftBlocks.lacuna_planks, 0, 2);
		world.setBlock(i + 9, j + 5, k + 6, NovaCraftBlocks.lacuna_planks, 0, 2);
		world.setBlock(i + 10, j + 5, k + 6, NovaCraftBlocks.lacuna_planks, 0, 2);
		world.setBlock(i + 11, j + 5, k + 6, Blocks.obsidian, 0, 2);
		world.setBlock(i + 12, j + 5, k + 6, Blocks.obsidian, 0, 2);
		world.setBlock(i + 13, j + 5, k + 6, Blocks.end_stone, 0, 2);
		world.setBlock(i + 14, j + 5, k + 6, Blocks.end_stone, 0, 2);
		world.setBlock(i + 15, j + 5, k + 6, OtherModBlocks.end_bricks, 0, 2);
		world.setBlock(i + 2, j + 5, k + 7, OtherModBlocks.end_bricks, 0, 2);
		world.setBlock(i + 3, j + 5, k + 7, Blocks.end_stone, 0, 2);
		world.setBlock(i + 4, j + 5, k + 7, Blocks.end_stone, 0, 2);
		world.setBlock(i + 5, j + 5, k + 7, Blocks.obsidian, 0, 2);
		world.setBlock(i + 6, j + 5, k + 7, Blocks.obsidian, 0, 2);
		world.setBlock(i + 7, j + 5, k + 7, NovaCraftBlocks.lacuna_planks, 0, 2);
		world.setBlock(i + 8, j + 5, k + 7, NovaCraftBlocks.lacuna_planks, 0, 2);
		world.setBlock(i + 9, j + 5, k + 7, NovaCraftBlocks.lacuna_planks, 0, 2);
		world.setBlock(i + 10, j + 5, k + 7, NovaCraftBlocks.lacuna_planks, 0, 2);
		world.setBlock(i + 11, j + 5, k + 7, NovaCraftBlocks.lacuna_planks, 0, 2);
		world.setBlock(i + 12, j + 5, k + 7, Blocks.obsidian, 0, 2);
		world.setBlock(i + 13, j + 5, k + 7, Blocks.obsidian, 0, 2);
		world.setBlock(i + 14, j + 5, k + 7, Blocks.end_stone, 0, 2);
		world.setBlock(i + 15, j + 5, k + 7, Blocks.end_stone, 0, 2);
		world.setBlock(i + 16, j + 5, k + 7, OtherModBlocks.end_bricks, 0, 2);
		world.setBlock(i + 1, j + 5, k + 8, OtherModBlocks.end_bricks, 0, 2);
		world.setBlock(i + 2, j + 5, k + 8, Blocks.end_stone, 0, 2);
		world.setBlock(i + 3, j + 5, k + 8, Blocks.end_stone, 0, 2);
		world.setBlock(i + 4, j + 5, k + 8, Blocks.end_stone, 0, 2);
		world.setBlock(i + 5, j + 5, k + 8, Blocks.obsidian, 0, 2);
		world.setBlock(i + 6, j + 5, k + 8, NovaCraftBlocks.lacuna_planks, 0, 2);
		world.setBlock(i + 7, j + 5, k + 8, NovaCraftBlocks.lacuna_planks, 0, 2);
		world.setBlock(i + 8, j + 5, k + 8, NovaCraftBlocks.lacuna_planks, 0, 2);
		world.setBlock(i + 9, j + 5, k + 8, Blocks.obsidian, 0, 2);
		world.setBlock(i + 10, j + 5, k + 8, NovaCraftBlocks.lacuna_planks, 0, 2);
		world.setBlock(i + 11, j + 5, k + 8, NovaCraftBlocks.lacuna_planks, 0, 2);
		world.setBlock(i + 12, j + 5, k + 8, NovaCraftBlocks.lacuna_planks, 0, 2);
		world.setBlock(i + 13, j + 5, k + 8, Blocks.obsidian, 0, 2);
		world.setBlock(i + 14, j + 5, k + 8, Blocks.end_stone, 0, 2);
		world.setBlock(i + 15, j + 5, k + 8, Blocks.end_stone, 0, 2);
		world.setBlock(i + 16, j + 5, k + 8, Blocks.end_stone, 0, 2);
		world.setBlock(i + 17, j + 5, k + 8, OtherModBlocks.end_bricks, 0, 2);
		world.setBlock(i + 0, j + 5, k + 9, OtherModBlocks.end_bricks, 0, 2);
		world.setBlock(i + 1, j + 5, k + 9, Blocks.end_stone, 0, 2);
		world.setBlock(i + 2, j + 5, k + 9, Blocks.end_stone, 0, 2);
		world.setBlock(i + 3, j + 5, k + 9, Blocks.end_stone, 0, 2);
		world.setBlock(i + 4, j + 5, k + 9, Blocks.end_stone, 0, 2);
		world.setBlock(i + 5, j + 5, k + 9, Blocks.obsidian, 0, 2);
		world.setBlock(i + 6, j + 5, k + 9, NovaCraftBlocks.lacuna_planks, 0, 2);
		world.setBlock(i + 7, j + 5, k + 9, NovaCraftBlocks.lacuna_planks, 0, 2);
		world.setBlock(i + 8, j + 5, k + 9, Blocks.obsidian, 0, 2);
		world.setBlock(i + 9, j + 5, k + 9, NovaCraftBlocks.lacuna_planks, 0, 2);
		world.setBlock(i + 10, j + 5, k + 9, Blocks.obsidian, 0, 2);
		world.setBlock(i + 11, j + 5, k + 9, NovaCraftBlocks.lacuna_planks, 0, 2);
		world.setBlock(i + 12, j + 5, k + 9, NovaCraftBlocks.lacuna_planks, 0, 2);
		world.setBlock(i + 13, j + 5, k + 9, Blocks.obsidian, 0, 2);
		world.setBlock(i + 14, j + 5, k + 9, Blocks.end_stone, 0, 2);
		world.setBlock(i + 15, j + 5, k + 9, Blocks.end_stone, 0, 2);
		world.setBlock(i + 16, j + 5, k + 9, Blocks.end_stone, 0, 2);
		world.setBlock(i + 17, j + 5, k + 9, Blocks.end_stone, 0, 2);
		world.setBlock(i + 18, j + 5, k + 9, OtherModBlocks.end_bricks, 0, 2);
		world.setBlock(i + 1, j + 5, k + 10, OtherModBlocks.end_bricks, 0, 2);
		world.setBlock(i + 2, j + 5, k + 10, Blocks.end_stone, 0, 2);
		world.setBlock(i + 3, j + 5, k + 10, Blocks.end_stone, 0, 2);
		world.setBlock(i + 4, j + 5, k + 10, Blocks.end_stone, 0, 2);
		world.setBlock(i + 5, j + 5, k + 10, Blocks.obsidian, 0, 2);
		world.setBlock(i + 6, j + 5, k + 10, NovaCraftBlocks.lacuna_planks, 0, 2);
		world.setBlock(i + 7, j + 5, k + 10, NovaCraftBlocks.lacuna_planks, 0, 2);
		world.setBlock(i + 8, j + 5, k + 10, NovaCraftBlocks.lacuna_planks, 0, 2);
		world.setBlock(i + 9, j + 5, k + 10, Blocks.obsidian, 0, 2);
		world.setBlock(i + 10, j + 5, k + 10, NovaCraftBlocks.lacuna_planks, 0, 2);
		world.setBlock(i + 11, j + 5, k + 10, NovaCraftBlocks.lacuna_planks, 0, 2);
		world.setBlock(i + 12, j + 5, k + 10, NovaCraftBlocks.lacuna_planks, 0, 2);
		world.setBlock(i + 13, j + 5, k + 10, Blocks.obsidian, 0, 2);
		world.setBlock(i + 14, j + 5, k + 10, Blocks.end_stone, 0, 2);
		world.setBlock(i + 15, j + 5, k + 10, Blocks.end_stone, 0, 2);
		world.setBlock(i + 16, j + 5, k + 10, Blocks.end_stone, 0, 2);
		world.setBlock(i + 17, j + 5, k + 10, OtherModBlocks.end_bricks, 0, 2);
		world.setBlock(i + 2, j + 5, k + 11, OtherModBlocks.end_bricks, 0, 2);
		world.setBlock(i + 3, j + 5, k + 11, Blocks.end_stone, 0, 2);
		world.setBlock(i + 4, j + 5, k + 11, Blocks.end_stone, 0, 2);
		world.setBlock(i + 5, j + 5, k + 11, Blocks.obsidian, 0, 2);
		world.setBlock(i + 6, j + 5, k + 11, Blocks.obsidian, 0, 2);
		world.setBlock(i + 7, j + 5, k + 11, NovaCraftBlocks.lacuna_planks, 0, 2);
		world.setBlock(i + 8, j + 5, k + 11, NovaCraftBlocks.lacuna_planks, 0, 2);
		world.setBlock(i + 9, j + 5, k + 11, NovaCraftBlocks.lacuna_planks, 0, 2);
		world.setBlock(i + 10, j + 5, k + 11, NovaCraftBlocks.lacuna_planks, 0, 2);
		world.setBlock(i + 11, j + 5, k + 11, NovaCraftBlocks.lacuna_planks, 0, 2);
		world.setBlock(i + 12, j + 5, k + 11, Blocks.obsidian, 0, 2);
		world.setBlock(i + 13, j + 5, k + 11, Blocks.obsidian, 0, 2);
		world.setBlock(i + 14, j + 5, k + 11, Blocks.end_stone, 0, 2);
		world.setBlock(i + 15, j + 5, k + 11, Blocks.end_stone, 0, 2);
		world.setBlock(i + 16, j + 5, k + 11, OtherModBlocks.end_bricks, 0, 2);
		world.setBlock(i + 3, j + 5, k + 12, OtherModBlocks.end_bricks, 0, 2);
		world.setBlock(i + 4, j + 5, k + 12, Blocks.end_stone, 0, 2);
		world.setBlock(i + 5, j + 5, k + 12, Blocks.end_stone, 0, 2);
		world.setBlock(i + 6, j + 5, k + 12, Blocks.obsidian, 0, 2);
		world.setBlock(i + 7, j + 5, k + 12, Blocks.obsidian, 0, 2);
		world.setBlock(i + 8, j + 5, k + 12, NovaCraftBlocks.lacuna_planks, 0, 2);
		world.setBlock(i + 9, j + 5, k + 12, NovaCraftBlocks.lacuna_planks, 0, 2);
		world.setBlock(i + 10, j + 5, k + 12, NovaCraftBlocks.lacuna_planks, 0, 2);
		world.setBlock(i + 11, j + 5, k + 12, Blocks.obsidian, 0, 2);
		world.setBlock(i + 12, j + 5, k + 12, Blocks.obsidian, 0, 2);
		world.setBlock(i + 13, j + 5, k + 12, Blocks.end_stone, 0, 2);
		world.setBlock(i + 14, j + 5, k + 12, Blocks.end_stone, 0, 2);
		world.setBlock(i + 15, j + 5, k + 12, OtherModBlocks.end_bricks, 0, 2);
		world.setBlock(i + 4, j + 5, k + 13, OtherModBlocks.end_bricks, 0, 2);
		world.setBlock(i + 5, j + 5, k + 13, Blocks.end_stone, 0, 2);
		world.setBlock(i + 6, j + 5, k + 13, Blocks.end_stone, 0, 2);
		world.setBlock(i + 7, j + 5, k + 13, Blocks.obsidian, 0, 2);
		world.setBlock(i + 8, j + 5, k + 13, Blocks.obsidian, 0, 2);
		world.setBlock(i + 9, j + 5, k + 13, Blocks.obsidian, 0, 2);
		world.setBlock(i + 10, j + 5, k + 13, Blocks.obsidian, 0, 2);
		world.setBlock(i + 11, j + 5, k + 13, Blocks.obsidian, 0, 2);
		world.setBlock(i + 12, j + 5, k + 13, Blocks.end_stone, 0, 2);
		world.setBlock(i + 13, j + 5, k + 13, Blocks.end_stone, 0, 2);
		world.setBlock(i + 14, j + 5, k + 13, OtherModBlocks.end_bricks, 0, 2);
		world.setBlock(i + 5, j + 5, k + 14, OtherModBlocks.end_bricks, 0, 2);
		world.setBlock(i + 6, j + 5, k + 14, Blocks.end_stone, 0, 2);
		world.setBlock(i + 7, j + 5, k + 14, Blocks.end_stone, 0, 2);
		world.setBlock(i + 8, j + 5, k + 14, Blocks.end_stone, 0, 2);
		world.setBlock(i + 9, j + 5, k + 14, Blocks.end_stone, 0, 2);
		world.setBlock(i + 10, j + 5, k + 14, Blocks.end_stone, 0, 2);
		world.setBlock(i + 11, j + 5, k + 14, Blocks.end_stone, 0, 2);
		world.setBlock(i + 12, j + 5, k + 14, Blocks.end_stone, 0, 2);
		world.setBlock(i + 13, j + 5, k + 14, OtherModBlocks.end_bricks, 0, 2);
		world.setBlock(i + 6, j + 5, k + 15, OtherModBlocks.end_bricks, 0, 2);
		world.setBlock(i + 7, j + 5, k + 15, Blocks.end_stone, 0, 2);
		world.setBlock(i + 8, j + 5, k + 15, Blocks.end_stone, 0, 2);
		world.setBlock(i + 9, j + 5, k + 15, Blocks.end_stone, 0, 2);
		world.setBlock(i + 10, j + 5, k + 15, Blocks.end_stone, 0, 2);
		world.setBlock(i + 11, j + 5, k + 15, Blocks.end_stone, 0, 2);
		world.setBlock(i + 12, j + 5, k + 15, OtherModBlocks.end_bricks, 0, 2);
		world.setBlock(i + 7, j + 5, k + 16, OtherModBlocks.end_bricks, 0, 2);
		world.setBlock(i + 8, j + 5, k + 16, Blocks.end_stone, 0, 2);
		world.setBlock(i + 9, j + 5, k + 16, Blocks.end_stone, 0, 2);
		world.setBlock(i + 10, j + 5, k + 16, Blocks.end_stone, 0, 2);
		world.setBlock(i + 11, j + 5, k + 16, OtherModBlocks.end_bricks, 0, 2);
		world.setBlock(i + 8, j + 5, k + 17, OtherModBlocks.end_bricks, 0, 2);
		world.setBlock(i + 9, j + 5, k + 17, Blocks.end_stone, 0, 2);
		world.setBlock(i + 10, j + 5, k + 17, OtherModBlocks.end_bricks, 0, 2);
		world.setBlock(i + 9, j + 5, k + 18, OtherModBlocks.end_bricks, 0, 2);
		world.setBlock(i + 7, j + 6, k + 5, OtherModBlocks.purpur_block, 0, 2);
		world.setBlock(i + 8, j + 6, k + 5, OtherModBlocks.purpur_pillar, 0, 2);
		world.setBlock(i + 10, j + 6, k + 5, OtherModBlocks.purpur_pillar, 0, 2);
		world.setBlock(i + 11, j + 6, k + 5, OtherModBlocks.purpur_block, 0, 2);
		world.setBlock(i + 6, j + 6, k + 6, OtherModBlocks.purpur_block, 0, 2);
		world.setBlock(i + 12, j + 6, k + 6, OtherModBlocks.purpur_block, 0, 2);
		world.setBlock(i + 5, j + 6, k + 7, OtherModBlocks.purpur_block, 0, 2);
		world.setBlock(i + 13, j + 6, k + 7, OtherModBlocks.purpur_block, 0, 2);
		world.setBlock(i + 4, j + 6, k + 8, OtherModBlocks.end_brick_stairs, 4, 2);
		world.setBlock(i + 5, j + 6, k + 8, OtherModBlocks.purpur_pillar, 0, 2);
		world.setBlock(i + 13, j + 6, k + 8, OtherModBlocks.purpur_pillar, 0, 2);
		world.setBlock(i + 14, j + 6, k + 8, OtherModBlocks.end_brick_stairs, 5, 2);
		world.setBlock(i + 5, j + 6, k + 9, OtherModBlocks.purpur_block, 0, 2);
		world.setBlock(i + 13, j + 6, k + 9, OtherModBlocks.purpur_block, 0, 2);
		world.setBlock(i + 4, j + 6, k + 10, OtherModBlocks.end_brick_stairs, 4, 2);
		world.setBlock(i + 5, j + 6, k + 10, OtherModBlocks.purpur_pillar, 0, 2);
		world.setBlock(i + 13, j + 6, k + 10, OtherModBlocks.purpur_pillar, 0, 2);
		world.setBlock(i + 14, j + 6, k + 10, OtherModBlocks.end_brick_stairs, 5, 2);
		world.setBlock(i + 5, j + 6, k + 11, OtherModBlocks.purpur_block, 0, 2);
		world.setBlock(i + 13, j + 6, k + 11, OtherModBlocks.purpur_block, 0, 2);
		world.setBlock(i + 6, j + 6, k + 12, OtherModBlocks.purpur_block, 0, 2);
		world.setBlock(i + 12, j + 6, k + 12, OtherModBlocks.purpur_block, 0, 2);
		world.setBlock(i + 7, j + 6, k + 13, OtherModBlocks.purpur_block, 0, 2);
		world.setBlock(i + 8, j + 6, k + 13, OtherModBlocks.purpur_pillar, 0, 2);
		world.setBlock(i + 9, j + 6, k + 13, OtherModBlocks.purpur_block, 0, 2);
		world.setBlock(i + 10, j + 6, k + 13, OtherModBlocks.purpur_pillar, 0, 2);
		world.setBlock(i + 11, j + 6, k + 13, OtherModBlocks.purpur_block, 0, 2);
		world.setBlock(i + 8, j + 6, k + 14, OtherModBlocks.end_brick_stairs, 7, 2);
		world.setBlock(i + 10, j + 6, k + 14, OtherModBlocks.end_brick_stairs, 7, 2);
		world.setBlock(i + 8, j + 7, k + 4, OtherModBlocks.end_brick_stairs, 6, 2);
		world.setBlock(i + 10, j + 7, k + 4, OtherModBlocks.end_brick_stairs, 6, 2);
		world.setBlock(i + 7, j + 7, k + 5, OtherModBlocks.purpur_block, 0, 2);
		world.setBlock(i + 8, j + 7, k + 5, OtherModBlocks.purpur_pillar, 0, 2);
		world.setBlock(i + 10, j + 7, k + 5, OtherModBlocks.purpur_pillar, 0, 2);
		world.setBlock(i + 11, j + 7, k + 5, OtherModBlocks.purpur_block, 0, 2);
		world.setBlock(i + 6, j + 7, k + 6, OtherModBlocks.purpur_block, 0, 2);
		world.setBlock(i + 12, j + 7, k + 6, OtherModBlocks.purpur_block, 0, 2);
		world.setBlock(i + 5, j + 7, k + 7, OtherModBlocks.purpur_block, 0, 2);
		world.setBlock(i + 13, j + 7, k + 7, OtherModBlocks.purpur_block, 0, 2);
		world.setBlock(i + 5, j + 7, k + 8, NovaCraftBlocks.inked_vacuum_glass, 0, 2);
		world.setBlock(i + 13, j + 7, k + 8, NovaCraftBlocks.inked_vacuum_glass, 0, 2);
		world.setBlock(i + 5, j + 7, k + 9, OtherModBlocks.purpur_block, 0, 2);
		world.setBlock(i + 13, j + 7, k + 9, OtherModBlocks.purpur_block, 0, 2);
		world.setBlock(i + 5, j + 7, k + 10, NovaCraftBlocks.inked_vacuum_glass, 0, 2);
		world.setBlock(i + 13, j + 7, k + 10, NovaCraftBlocks.inked_vacuum_glass, 0, 2);
		world.setBlock(i + 5, j + 7, k + 11, OtherModBlocks.purpur_block, 0, 2);
		world.setBlock(i + 13, j + 7, k + 11, OtherModBlocks.purpur_block, 0, 2);
		world.setBlock(i + 6, j + 7, k + 12, OtherModBlocks.purpur_block, 0, 2);
		world.setBlock(i + 12, j + 7, k + 12, OtherModBlocks.purpur_block, 0, 2);
		world.setBlock(i + 7, j + 7, k + 13, OtherModBlocks.purpur_block, 0, 2);
		world.setBlock(i + 8, j + 7, k + 13, NovaCraftBlocks.inked_vacuum_glass, 0, 2);
		world.setBlock(i + 9, j + 7, k + 13, OtherModBlocks.purpur_block, 0, 2);
		world.setBlock(i + 10, j + 7, k + 13, NovaCraftBlocks.inked_vacuum_glass, 0, 2);
		world.setBlock(i + 11, j + 7, k + 13, OtherModBlocks.purpur_block, 0, 2);
		world.setBlock(i + 7, j + 8, k + 5, OtherModBlocks.purpur_block, 0, 2);
		world.setBlock(i + 8, j + 8, k + 5, NovaCraftBlocks.inked_vacuum_glass, 0, 2);
		world.setBlock(i + 10, j + 8, k + 5, NovaCraftBlocks.inked_vacuum_glass, 0, 2);
		world.setBlock(i + 11, j + 8, k + 5, OtherModBlocks.purpur_block, 0, 2);
		world.setBlock(i + 6, j + 8, k + 6, OtherModBlocks.purpur_block, 0, 2);
		world.setBlock(i + 12, j + 8, k + 6, OtherModBlocks.purpur_block, 0, 2);
		world.setBlock(i + 5, j + 8, k + 7, OtherModBlocks.purpur_block, 0, 2);
		world.setBlock(i + 12, j + 8, k + 7, OtherModBlocks.purpur_slab, 8, 2);
		world.setBlock(i + 13, j + 8, k + 7, OtherModBlocks.purpur_block, 0, 2);
		world.setBlock(i + 5, j + 8, k + 8, OtherModBlocks.purpur_pillar, 0, 2);
		world.setBlock(i + 13, j + 8, k + 8, OtherModBlocks.purpur_pillar, 0, 2);
		world.setBlock(i + 5, j + 8, k + 9, OtherModBlocks.purpur_block, 0, 2);
		world.setBlock(i + 13, j + 8, k + 9, OtherModBlocks.purpur_block, 0, 2);
		world.setBlock(i + 14, j + 8, k + 9, OtherModBlocks.end_brick_stairs, 5, 2);
		world.setBlock(i + 5, j + 8, k + 10, OtherModBlocks.purpur_pillar, 0, 2);
		world.setBlock(i + 13, j + 8, k + 10, OtherModBlocks.purpur_pillar, 0, 2);
		world.setBlock(i + 5, j + 8, k + 11, OtherModBlocks.purpur_block, 0, 2);
		world.setBlock(i + 12, j + 8, k + 11, OtherModBlocks.purpur_slab, 0, 2);
		world.setBlock(i + 13, j + 8, k + 11, OtherModBlocks.purpur_block, 0, 2);
		world.setBlock(i + 6, j + 8, k + 12, OtherModBlocks.purpur_block, 0, 2);
		world.setBlock(i + 12, j + 8, k + 12, OtherModBlocks.purpur_block, 0, 2);
		world.setBlock(i + 7, j + 8, k + 13, OtherModBlocks.purpur_block, 0, 2);
		world.setBlock(i + 8, j + 8, k + 13, OtherModBlocks.purpur_pillar, 0, 2);
		world.setBlock(i + 9, j + 8, k + 13, OtherModBlocks.purpur_block, 0, 2);
		world.setBlock(i + 10, j + 8, k + 13, OtherModBlocks.purpur_pillar, 0, 2);
		world.setBlock(i + 11, j + 8, k + 13, OtherModBlocks.purpur_block, 0, 2);
		world.setBlock(i + 7, j + 9, k + 5, OtherModBlocks.purpur_block, 0, 2);
		world.setBlock(i + 8, j + 9, k + 5, OtherModBlocks.purpur_pillar, 0, 2);
		world.setBlock(i + 9, j + 9, k + 5, OtherModBlocks.purpur_block, 0, 2);
		world.setBlock(i + 10, j + 9, k + 5, OtherModBlocks.purpur_pillar, 0, 2);
		world.setBlock(i + 11, j + 9, k + 5, OtherModBlocks.purpur_block, 0, 2);
		world.setBlock(i + 6, j + 9, k + 6, OtherModBlocks.purpur_block, 0, 2);
		world.setBlock(i + 7, j + 9, k + 6, OtherModBlocks.purpur_slab, 0, 2);
		world.setBlock(i + 12, j + 9, k + 6, OtherModBlocks.purpur_block, 0, 2);
		world.setBlock(i + 5, j + 9, k + 7, OtherModBlocks.purpur_block, 0, 2);
		world.setBlock(i + 12, j + 9, k + 7, Blocks.chest, 4, 2);
		world.setBlock(i + 13, j + 9, k + 7, OtherModBlocks.purpur_block, 0, 2);
		world.setBlock(i + 5, j + 9, k + 8, OtherModBlocks.purpur_pillar, 0, 2);
		world.setBlock(i + 13, j + 9, k + 8, OtherModBlocks.purpur_pillar, 0, 2);
		world.setBlock(i + 5, j + 9, k + 9, OtherModBlocks.purpur_block, 0, 2);
		world.setBlock(i + 9, j + 9, k + 9, OtherModBlocks.purpur_pillar, 0, 2);
		world.setBlock(i + 13, j + 9, k + 9, NovaCraftBlocks.inked_vacuum_glass, 0, 2);
		world.setBlock(i + 5, j + 9, k + 10, OtherModBlocks.purpur_pillar, 0, 2);
		world.setBlock(i + 13, j + 9, k + 10, OtherModBlocks.purpur_pillar, 0, 2);
		world.setBlock(i + 5, j + 9, k + 11, OtherModBlocks.purpur_block, 0, 2);
		world.setBlock(i + 13, j + 9, k + 11, OtherModBlocks.purpur_block, 0, 2);
		world.setBlock(i + 6, j + 9, k + 12, OtherModBlocks.purpur_block, 0, 2);
		world.setBlock(i + 12, j + 9, k + 12, OtherModBlocks.purpur_block, 0, 2);
		world.setBlock(i + 7, j + 9, k + 13, OtherModBlocks.purpur_block, 0, 2);
		world.setBlock(i + 8, j + 9, k + 13, OtherModBlocks.purpur_pillar, 0, 2);
		world.setBlock(i + 9, j + 9, k + 13, OtherModBlocks.purpur_block, 0, 2);
		world.setBlock(i + 10, j + 9, k + 13, OtherModBlocks.purpur_pillar, 0, 2);
		world.setBlock(i + 11, j + 9, k + 13, OtherModBlocks.purpur_block, 0, 2);
		world.setBlock(i + 9, j + 9, k + 14, OtherModBlocks.end_brick_stairs, 7, 2);
		world.setBlock(i + 7, j + 10, k + 5, OtherModBlocks.purpur_block, 0, 2);
		world.setBlock(i + 8, j + 10, k + 5, OtherModBlocks.purpur_pillar, 0, 2);
		world.setBlock(i + 9, j + 10, k + 5, OtherModBlocks.purpur_block, 0, 2);
		world.setBlock(i + 10, j + 10, k + 5, OtherModBlocks.purpur_pillar, 0, 2);
		world.setBlock(i + 11, j + 10, k + 5, OtherModBlocks.purpur_block, 0, 2);
		world.setBlock(i + 6, j + 10, k + 6, OtherModBlocks.purpur_block, 0, 2);
		world.setBlock(i + 12, j + 10, k + 6, OtherModBlocks.purpur_block, 0, 2);
		world.setBlock(i + 5, j + 10, k + 7, OtherModBlocks.purpur_block, 0, 2);
		world.setBlock(i + 13, j + 10, k + 7, OtherModBlocks.purpur_block, 0, 2);
		world.setBlock(i + 5, j + 10, k + 8, OtherModBlocks.purpur_pillar, 0, 2);
		world.setBlock(i + 13, j + 10, k + 8, OtherModBlocks.purpur_pillar, 0, 2);
		world.setBlock(i + 4, j + 10, k + 9, OtherModBlocks.end_brick_stairs, 4, 2);
		world.setBlock(i + 5, j + 10, k + 9, OtherModBlocks.purpur_block, 0, 2);
		world.setBlock(i + 9, j + 10, k + 9, Blocks.chest, 4, 2);
		world.setBlock(i + 13, j + 10, k + 9, OtherModBlocks.purpur_block, 0, 2);
		world.setBlock(i + 5, j + 10, k + 10, OtherModBlocks.purpur_pillar, 0, 2);
		world.setBlock(i + 13, j + 10, k + 10, OtherModBlocks.purpur_pillar, 0, 2);
		world.setBlock(i + 5, j + 10, k + 11, OtherModBlocks.purpur_block, 0, 2);
		world.setBlock(i + 6, j + 10, k + 11, OtherModBlocks.purpur_block, 0, 2);
		world.setBlock(i + 13, j + 10, k + 11, OtherModBlocks.purpur_block, 0, 2);
		world.setBlock(i + 6, j + 10, k + 12, OtherModBlocks.purpur_block, 0, 2);
		world.setBlock(i + 12, j + 10, k + 12, OtherModBlocks.purpur_block, 0, 2);
		world.setBlock(i + 7, j + 10, k + 13, OtherModBlocks.purpur_block, 0, 2);
		world.setBlock(i + 8, j + 10, k + 13, OtherModBlocks.purpur_pillar, 0, 2);
		world.setBlock(i + 9, j + 10, k + 13, NovaCraftBlocks.inked_vacuum_glass, 0, 2);
		world.setBlock(i + 10, j + 10, k + 13, OtherModBlocks.purpur_pillar, 0, 2);
		world.setBlock(i + 11, j + 10, k + 13, OtherModBlocks.purpur_block, 0, 2);
		world.setBlock(i + 9, j + 11, k + 4, OtherModBlocks.end_brick_stairs, 6, 2);
		world.setBlock(i + 7, j + 11, k + 5, OtherModBlocks.purpur_block, 0, 2);
		world.setBlock(i + 8, j + 11, k + 5, OtherModBlocks.purpur_pillar, 0, 2);
		world.setBlock(i + 9, j + 11, k + 5, OtherModBlocks.purpur_block, 0, 2);
		world.setBlock(i + 10, j + 11, k + 5, OtherModBlocks.purpur_pillar, 0, 2);
		world.setBlock(i + 11, j + 11, k + 5, OtherModBlocks.purpur_block, 0, 2);
		world.setBlock(i + 6, j + 11, k + 6, OtherModBlocks.purpur_block, 0, 2);
		world.setBlock(i + 12, j + 11, k + 6, OtherModBlocks.purpur_block, 0, 2);
		world.setBlock(i + 5, j + 11, k + 7, OtherModBlocks.purpur_block, 0, 2);
		world.setBlock(i + 13, j + 11, k + 7, OtherModBlocks.purpur_block, 0, 2);
		world.setBlock(i + 5, j + 11, k + 8, OtherModBlocks.purpur_pillar, 0, 2);
		world.setBlock(i + 6, j + 11, k + 8, OtherModBlocks.purpur_slab, 0, 2);
		world.setBlock(i + 13, j + 11, k + 8, OtherModBlocks.purpur_pillar, 0, 2);
		world.setBlock(i + 5, j + 11, k + 9, NovaCraftBlocks.inked_vacuum_glass, 0, 2);
		world.setBlock(i + 13, j + 11, k + 9, OtherModBlocks.purpur_block, 0, 2);
		world.setBlock(i + 5, j + 11, k + 10, OtherModBlocks.purpur_pillar, 0, 2);
		world.setBlock(i + 10, j + 11, k + 10, OtherModBlocks.end_rod, 0, 2);
		world.setBlock(i + 13, j + 11, k + 10, OtherModBlocks.purpur_pillar, 0, 2);
		world.setBlock(i + 5, j + 11, k + 11, OtherModBlocks.purpur_block, 0, 2);
		world.setBlock(i + 6, j + 11, k + 11, Blocks.chest, 5, 2);
		world.setBlock(i + 13, j + 11, k + 11, OtherModBlocks.purpur_block, 0, 2);
		world.setBlock(i + 6, j + 11, k + 12, OtherModBlocks.purpur_block, 0, 2);
		world.setBlock(i + 11, j + 11, k + 12, OtherModBlocks.purpur_slab, 8, 2);
		world.setBlock(i + 12, j + 11, k + 12, OtherModBlocks.purpur_block, 0, 2);
		world.setBlock(i + 7, j + 11, k + 13, OtherModBlocks.purpur_block, 0, 2);
		world.setBlock(i + 8, j + 11, k + 13, OtherModBlocks.purpur_pillar, 0, 2);
		world.setBlock(i + 9, j + 11, k + 13, OtherModBlocks.purpur_block, 0, 2);
		world.setBlock(i + 10, j + 11, k + 13, OtherModBlocks.purpur_pillar, 0, 2);
		world.setBlock(i + 11, j + 11, k + 13, OtherModBlocks.purpur_block, 0, 2);
		world.setBlock(i + 7, j + 12, k + 5, OtherModBlocks.purpur_block, 0, 2);
		world.setBlock(i + 8, j + 12, k + 5, OtherModBlocks.purpur_pillar, 0, 2);
		world.setBlock(i + 9, j + 12, k + 5, NovaCraftBlocks.inked_vacuum_glass, 0, 2);
		world.setBlock(i + 10, j + 12, k + 5, OtherModBlocks.purpur_pillar, 0, 2);
		world.setBlock(i + 11, j + 12, k + 5, OtherModBlocks.purpur_block, 0, 2);
		world.setBlock(i + 6, j + 12, k + 6, OtherModBlocks.purpur_block, 0, 2);
		world.setBlock(i + 12, j + 12, k + 6, OtherModBlocks.purpur_block, 0, 2);
		world.setBlock(i + 5, j + 12, k + 7, OtherModBlocks.purpur_block, 0, 2);
		world.setBlock(i + 13, j + 12, k + 7, OtherModBlocks.purpur_block, 0, 2);
		world.setBlock(i + 5, j + 12, k + 8, OtherModBlocks.purpur_pillar, 0, 2);
		world.setBlock(i + 13, j + 12, k + 8, OtherModBlocks.purpur_pillar, 0, 2);
		world.setBlock(i + 5, j + 12, k + 9, OtherModBlocks.purpur_block, 0, 2);
		world.setBlock(i + 12, j + 12, k + 9, OtherModBlocks.purpur_slab, 0, 2);
		world.setBlock(i + 13, j + 12, k + 9, OtherModBlocks.purpur_block, 0, 2);
		world.setBlock(i + 14, j + 12, k + 9, OtherModBlocks.end_brick_stairs, 5, 2);
		world.setBlock(i + 5, j + 12, k + 10, OtherModBlocks.purpur_pillar, 0, 2);
		world.setBlock(i + 6, j + 12, k + 10, OtherModBlocks.purpur_slab, 8, 2);
		world.setBlock(i + 10, j + 12, k + 10, OtherModBlocks.purpur_pillar, 0, 2);
		world.setBlock(i + 13, j + 12, k + 10, OtherModBlocks.purpur_pillar, 0, 2);
		world.setBlock(i + 5, j + 12, k + 11, OtherModBlocks.purpur_block, 0, 2);
		world.setBlock(i + 13, j + 12, k + 11, OtherModBlocks.purpur_block, 0, 2);
		world.setBlock(i + 6, j + 12, k + 12, OtherModBlocks.purpur_block, 0, 2);
		world.setBlock(i + 8, j + 12, k + 12, OtherModBlocks.purpur_slab, 0, 2);
		world.setBlock(i + 12, j + 12, k + 12, OtherModBlocks.purpur_block, 0, 2);
		world.setBlock(i + 7, j + 12, k + 13, OtherModBlocks.purpur_block, 0, 2);
		world.setBlock(i + 8, j + 12, k + 13, OtherModBlocks.purpur_pillar, 0, 2);
		world.setBlock(i + 9, j + 12, k + 13, OtherModBlocks.purpur_block, 0, 2);
		world.setBlock(i + 10, j + 12, k + 13, OtherModBlocks.purpur_pillar, 0, 2);
		world.setBlock(i + 11, j + 12, k + 13, OtherModBlocks.purpur_block, 0, 2);
		world.setBlock(i + 9, j + 12, k + 14, OtherModBlocks.end_brick_stairs, 7, 2);
		world.setBlock(i + 9, j + 13, k + 4, OtherModBlocks.end_brick_stairs, 6, 2);
		world.setBlock(i + 7, j + 13, k + 5, OtherModBlocks.purpur_block, 0, 2);
		world.setBlock(i + 8, j + 13, k + 5, OtherModBlocks.purpur_pillar, 0, 2);
		world.setBlock(i + 9, j + 13, k + 5, OtherModBlocks.purpur_block, 0, 2);
		world.setBlock(i + 10, j + 13, k + 5, OtherModBlocks.purpur_pillar, 0, 2);
		world.setBlock(i + 11, j + 13, k + 5, OtherModBlocks.purpur_block, 0, 2);
		world.setBlock(i + 6, j + 13, k + 6, OtherModBlocks.purpur_block, 0, 2);
		world.setBlock(i + 7, j + 13, k + 6, OtherModBlocks.purpur_slab, 0, 2);
		world.setBlock(i + 11, j + 13, k + 6, OtherModBlocks.purpur_slab, 0, 2);
		world.setBlock(i + 12, j + 13, k + 6, OtherModBlocks.purpur_block, 0, 2);
		world.setBlock(i + 5, j + 13, k + 7, OtherModBlocks.purpur_block, 0, 2);
		world.setBlock(i + 6, j + 13, k + 7, OtherModBlocks.end_rod, 5, 2);
		world.setBlock(i + 12, j + 13, k + 7, OtherModBlocks.end_rod, 4, 2);
		world.setBlock(i + 13, j + 13, k + 7, OtherModBlocks.purpur_block, 0, 2);
		world.setBlock(i + 5, j + 13, k + 8, OtherModBlocks.purpur_pillar, 0, 2);
		world.setBlock(i + 13, j + 13, k + 8, OtherModBlocks.purpur_pillar, 0, 2);
		world.setBlock(i + 4, j + 13, k + 9, OtherModBlocks.end_brick_stairs, 4, 2);
		world.setBlock(i + 5, j + 13, k + 9, OtherModBlocks.purpur_block, 0, 2);
		world.setBlock(i + 13, j + 13, k + 9, NovaCraftBlocks.inked_vacuum_glass, 0, 2);
		world.setBlock(i + 5, j + 13, k + 10, OtherModBlocks.purpur_pillar, 0, 2);
		world.setBlock(i + 10, j + 13, k + 10, Blocks.chest, 2, 2);
		world.setBlock(i + 13, j + 13, k + 10, OtherModBlocks.purpur_pillar, 0, 2);
		world.setBlock(i + 5, j + 13, k + 11, OtherModBlocks.purpur_block, 0, 2);
		world.setBlock(i + 13, j + 13, k + 11, OtherModBlocks.purpur_block, 0, 2);
		world.setBlock(i + 6, j + 13, k + 12, OtherModBlocks.purpur_block, 0, 2);
		world.setBlock(i + 7, j + 13, k + 12, OtherModBlocks.end_rod, 2, 2);
		world.setBlock(i + 12, j + 13, k + 12, OtherModBlocks.purpur_block, 0, 2);
		world.setBlock(i + 7, j + 13, k + 13, OtherModBlocks.purpur_block, 0, 2);
		world.setBlock(i + 8, j + 13, k + 13, OtherModBlocks.purpur_pillar, 0, 2);
		world.setBlock(i + 9, j + 13, k + 13, NovaCraftBlocks.inked_vacuum_glass, 0, 2);
		world.setBlock(i + 10, j + 13, k + 13, OtherModBlocks.purpur_pillar, 0, 2);
		world.setBlock(i + 11, j + 13, k + 13, OtherModBlocks.purpur_block, 0, 2);
		world.setBlock(i + 7, j + 14, k + 5, OtherModBlocks.purpur_block, 0, 2);
		world.setBlock(i + 8, j + 14, k + 5, OtherModBlocks.purpur_pillar, 0, 2);
		world.setBlock(i + 9, j + 14, k + 5, NovaCraftBlocks.inked_vacuum_glass, 0, 2);
		world.setBlock(i + 10, j + 14, k + 5, OtherModBlocks.purpur_pillar, 0, 2);
		world.setBlock(i + 11, j + 14, k + 5, OtherModBlocks.purpur_block, 0, 2);
		world.setBlock(i + 6, j + 14, k + 6, OtherModBlocks.purpur_block, 0, 2);
		world.setBlock(i + 12, j + 14, k + 6, OtherModBlocks.purpur_block, 0, 2);
		world.setBlock(i + 5, j + 14, k + 7, OtherModBlocks.purpur_block, 0, 2);
		world.setBlock(i + 13, j + 14, k + 7, OtherModBlocks.purpur_block, 0, 2);
		world.setBlock(i + 5, j + 14, k + 8, OtherModBlocks.purpur_pillar, 0, 2);
		world.setBlock(i + 13, j + 14, k + 8, OtherModBlocks.purpur_pillar, 0, 2);
		world.setBlock(i + 5, j + 14, k + 9, NovaCraftBlocks.inked_vacuum_glass, 0, 2);
		world.setBlock(i + 13, j + 14, k + 9, OtherModBlocks.purpur_block, 0, 2);
		world.setBlock(i + 5, j + 14, k + 10, OtherModBlocks.purpur_pillar, 0, 2);
		world.setBlock(i + 13, j + 14, k + 10, OtherModBlocks.purpur_pillar, 0, 2);
		world.setBlock(i + 5, j + 14, k + 11, OtherModBlocks.purpur_block, 0, 2);
		world.setBlock(i + 13, j + 14, k + 11, OtherModBlocks.purpur_block, 0, 2);
		world.setBlock(i + 6, j + 14, k + 12, OtherModBlocks.purpur_block, 0, 2);
		world.setBlock(i + 12, j + 14, k + 12, OtherModBlocks.purpur_block, 0, 2);
		world.setBlock(i + 7, j + 14, k + 13, OtherModBlocks.purpur_block, 0, 2);
		world.setBlock(i + 8, j + 14, k + 13, OtherModBlocks.purpur_pillar, 0, 2);
		world.setBlock(i + 9, j + 14, k + 13, OtherModBlocks.purpur_block, 0, 2);
		world.setBlock(i + 10, j + 14, k + 13, OtherModBlocks.purpur_pillar, 0, 2);
		world.setBlock(i + 11, j + 14, k + 13, OtherModBlocks.purpur_block, 0, 2);
		world.setBlock(i + 8, j + 15, k + 4, OtherModBlocks.end_brick_stairs, 6, 2);
		world.setBlock(i + 9, j + 15, k + 4, OtherModBlocks.end_brick_stairs, 6, 2);
		world.setBlock(i + 10, j + 15, k + 4, OtherModBlocks.end_brick_stairs, 6, 2);
		world.setBlock(i + 7, j + 15, k + 5, OtherModBlocks.purpur_block, 0, 2);
		world.setBlock(i + 8, j + 15, k + 5, OtherModBlocks.purpur_pillar, 0, 2);
		world.setBlock(i + 9, j + 15, k + 5, OtherModBlocks.purpur_block, 0, 2);
		world.setBlock(i + 10, j + 15, k + 5, OtherModBlocks.purpur_pillar, 0, 2);
		world.setBlock(i + 11, j + 15, k + 5, OtherModBlocks.purpur_block, 0, 2);
		world.setBlock(i + 6, j + 15, k + 6, OtherModBlocks.purpur_block, 0, 2);
		world.setBlock(i + 7, j + 15, k + 6, OtherModBlocks.end_brick_stairs, 5, 2);
		world.setBlock(i + 11, j + 15, k + 6, OtherModBlocks.end_brick_stairs, 4, 2);
		world.setBlock(i + 12, j + 15, k + 6, OtherModBlocks.purpur_block, 0, 2);
		world.setBlock(i + 5, j + 15, k + 7, OtherModBlocks.purpur_block, 0, 2);
		world.setBlock(i + 6, j + 15, k + 7, OtherModBlocks.end_brick_stairs, 7, 2);
		world.setBlock(i + 12, j + 15, k + 7, OtherModBlocks.end_brick_stairs, 7, 2);
		world.setBlock(i + 13, j + 15, k + 7, OtherModBlocks.purpur_block, 0, 2);
		world.setBlock(i + 4, j + 15, k + 8, OtherModBlocks.end_brick_stairs, 4, 2);
		world.setBlock(i + 5, j + 15, k + 8, OtherModBlocks.purpur_pillar, 0, 2);
		world.setBlock(i + 13, j + 15, k + 8, OtherModBlocks.purpur_pillar, 0, 2);
		world.setBlock(i + 14, j + 15, k + 8, OtherModBlocks.end_brick_stairs, 5, 2);
		world.setBlock(i + 4, j + 15, k + 9, OtherModBlocks.end_brick_stairs, 4, 2);
		world.setBlock(i + 5, j + 15, k + 9, OtherModBlocks.purpur_block, 0, 2);
		world.setBlock(i + 13, j + 15, k + 9, OtherModBlocks.purpur_block, 0, 2);
		world.setBlock(i + 14, j + 15, k + 9, OtherModBlocks.end_brick_stairs, 5, 2);
		world.setBlock(i + 4, j + 15, k + 10, OtherModBlocks.end_brick_stairs, 4, 2);
		world.setBlock(i + 5, j + 15, k + 10, OtherModBlocks.purpur_pillar, 0, 2);
		world.setBlock(i + 13, j + 15, k + 10, OtherModBlocks.purpur_pillar, 0, 2);
		world.setBlock(i + 14, j + 15, k + 10, OtherModBlocks.end_brick_stairs, 5, 2);
		world.setBlock(i + 5, j + 15, k + 11, OtherModBlocks.purpur_block, 0, 2);
		world.setBlock(i + 6, j + 15, k + 11, OtherModBlocks.end_brick_stairs, 6, 2);
		world.setBlock(i + 12, j + 15, k + 11, OtherModBlocks.end_brick_stairs, 6, 2);
		world.setBlock(i + 13, j + 15, k + 11, OtherModBlocks.purpur_block, 0, 2);
		world.setBlock(i + 6, j + 15, k + 12, OtherModBlocks.purpur_block, 0, 2);
		world.setBlock(i + 7, j + 15, k + 12, OtherModBlocks.end_brick_stairs, 5, 2);
		world.setBlock(i + 11, j + 15, k + 12, OtherModBlocks.end_brick_stairs, 4, 2);
		world.setBlock(i + 12, j + 15, k + 12, OtherModBlocks.purpur_block, 0, 2);
		world.setBlock(i + 7, j + 15, k + 13, OtherModBlocks.purpur_block, 0, 2);
		world.setBlock(i + 8, j + 15, k + 13, OtherModBlocks.purpur_pillar, 0, 2);
		world.setBlock(i + 9, j + 15, k + 13, OtherModBlocks.purpur_block, 0, 2);
		world.setBlock(i + 10, j + 15, k + 13, OtherModBlocks.purpur_pillar, 0, 2);
		world.setBlock(i + 11, j + 15, k + 13, OtherModBlocks.purpur_block, 0, 2);
		world.setBlock(i + 8, j + 15, k + 14, OtherModBlocks.end_brick_stairs, 7, 2);
		world.setBlock(i + 9, j + 15, k + 14, OtherModBlocks.end_brick_stairs, 7, 2);
		world.setBlock(i + 10, j + 15, k + 14, OtherModBlocks.end_brick_stairs, 7, 2);
		world.setBlock(i + 7, j + 16, k + 5, OtherModBlocks.purpur_slab, 0, 2);
		world.setBlock(i + 8, j + 16, k + 5, OtherModBlocks.end_brick_slab, 0, 2);
		world.setBlock(i + 9, j + 16, k + 5, OtherModBlocks.end_brick_slab, 0, 2);
		world.setBlock(i + 10, j + 16, k + 5, OtherModBlocks.end_brick_slab, 0, 2);
		world.setBlock(i + 11, j + 16, k + 5, OtherModBlocks.purpur_slab, 0, 2);
		world.setBlock(i + 6, j + 16, k + 6, OtherModBlocks.purpur_slab, 0, 2);
		world.setBlock(i + 7, j + 16, k + 6, OtherModBlocks.purpur_block, 0, 2);
		world.setBlock(i + 8, j + 16, k + 6, OtherModBlocks.end_bricks, 0, 2);
		world.setBlock(i + 9, j + 16, k + 6, OtherModBlocks.end_bricks, 0, 2);
		world.setBlock(i + 10, j + 16, k + 6, OtherModBlocks.end_bricks, 0, 2);
		world.setBlock(i + 11, j + 16, k + 6, OtherModBlocks.purpur_block, 0, 2);
		world.setBlock(i + 12, j + 16, k + 6, OtherModBlocks.purpur_slab, 0, 2);
		world.setBlock(i + 5, j + 16, k + 7, OtherModBlocks.purpur_slab, 0, 2);
		world.setBlock(i + 6, j + 16, k + 7, OtherModBlocks.purpur_block, 0, 2);
		world.setBlock(i + 7, j + 16, k + 7, OtherModBlocks.end_bricks, 0, 2);
		world.setBlock(i + 11, j + 16, k + 7, OtherModBlocks.end_bricks, 0, 2);
		world.setBlock(i + 12, j + 16, k + 7, OtherModBlocks.purpur_block, 0, 2);
		world.setBlock(i + 13, j + 16, k + 7, OtherModBlocks.purpur_slab, 0, 2);
		world.setBlock(i + 5, j + 16, k + 8, OtherModBlocks.end_brick_slab, 0, 2);
		world.setBlock(i + 6, j + 16, k + 8, OtherModBlocks.end_bricks, 0, 2);
		world.setBlock(i + 12, j + 16, k + 8, OtherModBlocks.end_bricks, 0, 2);
		world.setBlock(i + 13, j + 16, k + 8, OtherModBlocks.end_brick_slab, 0, 2);
		world.setBlock(i + 5, j + 16, k + 9, OtherModBlocks.end_brick_slab, 0, 2);
		world.setBlock(i + 6, j + 16, k + 9, OtherModBlocks.end_bricks, 0, 2);
		world.setBlock(i + 12, j + 16, k + 9, OtherModBlocks.end_bricks, 0, 2);
		world.setBlock(i + 13, j + 16, k + 9, OtherModBlocks.end_brick_slab, 0, 2);
		world.setBlock(i + 5, j + 16, k + 10, OtherModBlocks.end_brick_slab, 0, 2);
		world.setBlock(i + 6, j + 16, k + 10, OtherModBlocks.end_bricks, 0, 2);
		world.setBlock(i + 12, j + 16, k + 10, OtherModBlocks.end_bricks, 0, 2);
		world.setBlock(i + 13, j + 16, k + 10, OtherModBlocks.end_brick_slab, 0, 2);
		world.setBlock(i + 5, j + 16, k + 11, OtherModBlocks.purpur_slab, 0, 2);
		world.setBlock(i + 6, j + 16, k + 11, OtherModBlocks.purpur_block, 0, 2);
		world.setBlock(i + 7, j + 16, k + 11, OtherModBlocks.end_bricks, 0, 2);
		world.setBlock(i + 11, j + 16, k + 11, OtherModBlocks.end_bricks, 0, 2);
		world.setBlock(i + 12, j + 16, k + 11, OtherModBlocks.purpur_block, 0, 2);
		world.setBlock(i + 13, j + 16, k + 11, OtherModBlocks.purpur_slab, 0, 2);
		world.setBlock(i + 6, j + 16, k + 12, OtherModBlocks.purpur_slab, 0, 2);
		world.setBlock(i + 7, j + 16, k + 12, OtherModBlocks.purpur_block, 0, 2);
		world.setBlock(i + 8, j + 16, k + 12, OtherModBlocks.end_bricks, 0, 2);
		world.setBlock(i + 9, j + 16, k + 12, OtherModBlocks.end_bricks, 0, 2);
		world.setBlock(i + 10, j + 16, k + 12, OtherModBlocks.end_bricks, 0, 2);
		world.setBlock(i + 11, j + 16, k + 12, OtherModBlocks.purpur_block, 0, 2);
		world.setBlock(i + 12, j + 16, k + 12, OtherModBlocks.purpur_slab, 0, 2);
		world.setBlock(i + 7, j + 16, k + 13, OtherModBlocks.purpur_slab, 0, 2);
		world.setBlock(i + 8, j + 16, k + 13, OtherModBlocks.end_brick_slab, 0, 2);
		world.setBlock(i + 9, j + 16, k + 13, OtherModBlocks.end_brick_slab, 0, 2);
		world.setBlock(i + 10, j + 16, k + 13, OtherModBlocks.end_brick_slab, 0, 2);
		world.setBlock(i + 11, j + 16, k + 13, OtherModBlocks.purpur_slab, 0, 2);
		world.setBlock(i + 7, j + 17, k + 7, OtherModBlocks.purpur_block, 0, 2);
		world.setBlock(i + 8, j + 17, k + 7, OtherModBlocks.end_brick_slab, 0, 2);
		world.setBlock(i + 10, j + 17, k + 7, OtherModBlocks.end_brick_slab, 0, 2);
		world.setBlock(i + 11, j + 17, k + 7, OtherModBlocks.purpur_block, 0, 2);
		world.setBlock(i + 7, j + 17, k + 8, OtherModBlocks.end_brick_slab, 0, 2);
		world.setBlock(i + 11, j + 17, k + 8, OtherModBlocks.end_brick_slab, 0, 2);
		world.setBlock(i + 7, j + 17, k + 10, OtherModBlocks.end_brick_slab, 0, 2);
		world.setBlock(i + 11, j + 17, k + 10, OtherModBlocks.end_brick_slab, 0, 2);
		world.setBlock(i + 7, j + 17, k + 11, OtherModBlocks.purpur_block, 0, 2);
		world.setBlock(i + 8, j + 17, k + 11, OtherModBlocks.end_brick_slab, 0, 2);
		world.setBlock(i + 10, j + 17, k + 11, OtherModBlocks.end_brick_slab, 0, 2);
		world.setBlock(i + 11, j + 17, k + 11, OtherModBlocks.purpur_block, 0, 2);
		world.setBlock(i + 7, j + 18, k + 7, OtherModBlocks.end_rod, 1, 2);
		world.setBlock(i + 11, j + 18, k + 7, OtherModBlocks.end_rod, 1, 2);
		world.setBlock(i + 7, j + 18, k + 11, OtherModBlocks.end_rod, 1, 2);
		world.setBlock(i + 11, j + 18, k + 11, OtherModBlocks.end_rod, 1, 2);
		
		return true;
    }

}
