package com.NovaCraft.world.end.endcamp;

import java.util.Random;

import com.NovaCraft.registry.OtherModBlocks;
import com.NovaCraftBlocks.NovaCraftBlocks;
import com.NovaCraftBlocks.sculk.BlockSculkEndstone;

import net.minecraft.block.Block;
import net.minecraft.init.Blocks;
import net.minecraft.world.World;
import net.minecraft.world.gen.feature.WorldGenerator;

public class EnderCampTreasureTowerPart1Gen extends WorldGenerator
{
	public EnderCampTreasureTowerPart1Gen() {

	}
	
	public boolean generate(final World world, final Random random, final int i, final int j, final int k) {
		
		
		world.setBlock(i + 16, j + 0, k + 3, Blocks.end_stone, 0, 2);
		world.setBlock(i + 14, j + 0, k + 14, Blocks.end_stone, 0, 2);
		world.setBlock(i + 17, j + 0, k + 16, Blocks.end_stone, 0, 2);
		world.setBlock(i + 12, j + 0, k + 21, Blocks.end_stone, 0, 2);
		world.setBlock(i + 18, j + 0, k + 31, Blocks.end_stone, 0, 2);
		world.setBlock(i + 16, j + 1, k + 3, Blocks.end_stone, 0, 2);
		world.setBlock(i + 12, j + 1, k + 5, Blocks.end_stone, 0, 2);
		world.setBlock(i + 14, j + 1, k + 6, Blocks.end_stone, 0, 2);
		world.setBlock(i + 15, j + 1, k + 6, Blocks.end_stone, 0, 2);
		world.setBlock(i + 15, j + 1, k + 10, Blocks.end_stone, 0, 2);
		world.setBlock(i + 14, j + 1, k + 14, Blocks.end_stone, 0, 2);
		world.setBlock(i + 4, j + 1, k + 16, Blocks.end_stone, 0, 2);
		world.setBlock(i + 16, j + 1, k + 16, Blocks.end_stone, 0, 2);
		world.setBlock(i + 17, j + 1, k + 16, Blocks.end_stone, 0, 2);
		world.setBlock(i + 13, j + 1, k + 18, Blocks.end_stone, 0, 2);
		world.setBlock(i + 4, j + 1, k + 20, Blocks.end_stone, 0, 2);
		world.setBlock(i + 12, j + 1, k + 20, Blocks.end_stone, 0, 2);
		world.setBlock(i + 12, j + 1, k + 21, Blocks.end_stone, 0, 2);
		world.setBlock(i + 14, j + 1, k + 21, Blocks.end_stone, 0, 2);
		world.setBlock(i + 18, j + 1, k + 22, Blocks.end_stone, 0, 2);
		world.setBlock(i + 14, j + 1, k + 24, Blocks.end_stone, 0, 2);
		world.setBlock(i + 18, j + 1, k + 25, Blocks.end_stone, 0, 2);
		world.setBlock(i + 21, j + 1, k + 29, Blocks.end_stone, 0, 2);
		world.setBlock(i + 16, j + 1, k + 30, Blocks.end_stone, 0, 2);
		world.setBlock(i + 18, j + 1, k + 30, Blocks.end_stone, 0, 2);
		world.setBlock(i + 18, j + 1, k + 31, Blocks.end_stone, 0, 2);
		world.setBlock(i + 16, j + 1, k + 32, Blocks.end_stone, 0, 2);
		world.setBlock(i + 19, j + 1, k + 32, Blocks.end_stone, 0, 2);
		world.setBlock(i + 13, j + 2, k + 3, Blocks.end_stone, 0, 2);
		world.setBlock(i + 14, j + 2, k + 3, Blocks.end_stone, 0, 2);
		world.setBlock(i + 15, j + 2, k + 3, Blocks.end_stone, 0, 2);
		world.setBlock(i + 16, j + 2, k + 3, Blocks.end_stone, 0, 2);
		world.setBlock(i + 16, j + 2, k + 4, Blocks.end_stone, 0, 2);
		world.setBlock(i + 17, j + 2, k + 4, Blocks.end_stone, 0, 2);
		world.setBlock(i + 12, j + 2, k + 5, Blocks.end_stone, 0, 2);
		world.setBlock(i + 18, j + 2, k + 5, Blocks.end_stone, 0, 2);
		world.setBlock(i + 13, j + 2, k + 6, Blocks.end_stone, 0, 2);
		world.setBlock(i + 14, j + 2, k + 6, Blocks.end_stone, 0, 2);
		world.setBlock(i + 15, j + 2, k + 6, Blocks.end_stone, 0, 2);
		world.setBlock(i + 17, j + 2, k + 6, Blocks.end_stone, 0, 2);
		world.setBlock(i + 18, j + 2, k + 6, Blocks.end_stone, 0, 2);
		world.setBlock(i + 13, j + 2, k + 7, Blocks.end_stone, 0, 2);
		world.setBlock(i + 14, j + 2, k + 7, Blocks.end_stone, 0, 2);
		world.setBlock(i + 19, j + 2, k + 7, Blocks.end_stone, 0, 2);
		world.setBlock(i + 14, j + 2, k + 8, Blocks.end_stone, 0, 2);
		world.setBlock(i + 15, j + 2, k + 8, Blocks.end_stone, 0, 2);
		world.setBlock(i + 16, j + 2, k + 8, Blocks.end_stone, 0, 2);
		world.setBlock(i + 20, j + 2, k + 8, Blocks.end_stone, 0, 2);
		world.setBlock(i + 11, j + 2, k + 9, Blocks.end_stone, 0, 2);
		world.setBlock(i + 15, j + 2, k + 9, Blocks.end_stone, 0, 2);
		world.setBlock(i + 16, j + 2, k + 9, Blocks.end_stone, 0, 2);
		world.setBlock(i + 21, j + 2, k + 9, Blocks.end_stone, 0, 2);
		world.setBlock(i + 15, j + 2, k + 10, Blocks.end_stone, 0, 2);
		world.setBlock(i + 17, j + 2, k + 10, Blocks.end_stone, 0, 2);
		world.setBlock(i + 22, j + 2, k + 10, Blocks.end_stone, 0, 2);
		world.setBlock(i + 23, j + 2, k + 10, Blocks.end_stone, 0, 2);
		world.setBlock(i + 24, j + 2, k + 10, Blocks.end_stone, 0, 2);
		world.setBlock(i + 12, j + 2, k + 11, Blocks.end_stone, 0, 2);
		world.setBlock(i + 14, j + 2, k + 11, Blocks.end_stone, 0, 2);
		world.setBlock(i + 15, j + 2, k + 11, Blocks.end_stone, 0, 2);
		world.setBlock(i + 19, j + 2, k + 11, Blocks.end_stone, 0, 2);
		world.setBlock(i + 16, j + 2, k + 12, Blocks.end_stone, 0, 2);
		world.setBlock(i + 7, j + 2, k + 13, Blocks.end_stone, 0, 2);
		world.setBlock(i + 15, j + 2, k + 13, Blocks.end_stone, 0, 2);
		world.setBlock(i + 21, j + 2, k + 13, Blocks.end_stone, 0, 2);
		world.setBlock(i + 23, j + 2, k + 13, Blocks.end_stone, 0, 2);
		world.setBlock(i + 24, j + 2, k + 13, Blocks.end_stone, 0, 2);
		world.setBlock(i + 10, j + 2, k + 14, Blocks.end_stone, 0, 2);
		world.setBlock(i + 11, j + 2, k + 14, Blocks.end_stone, 0, 2);
		world.setBlock(i + 14, j + 2, k + 14, Blocks.end_stone, 0, 2);
		world.setBlock(i + 22, j + 2, k + 14, Blocks.end_stone, 0, 2);
		world.setBlock(i + 6, j + 2, k + 15, Blocks.end_stone, 0, 2);
		world.setBlock(i + 11, j + 2, k + 15, Blocks.end_stone, 0, 2);
		world.setBlock(i + 15, j + 2, k + 15, Blocks.end_stone, 0, 2);
		world.setBlock(i + 20, j + 2, k + 15, Blocks.end_stone, 0, 2);
		world.setBlock(i + 21, j + 2, k + 15, Blocks.end_stone, 0, 2);
		world.setBlock(i + 23, j + 2, k + 15, Blocks.end_stone, 0, 2);
		world.setBlock(i + 24, j + 2, k + 15, Blocks.end_stone, 0, 2);
		world.setBlock(i + 4, j + 2, k + 16, Blocks.end_stone, 0, 2);
		world.setBlock(i + 7, j + 2, k + 16, Blocks.end_stone, 0, 2);
		world.setBlock(i + 14, j + 2, k + 16, Blocks.end_stone, 0, 2);
		world.setBlock(i + 17, j + 2, k + 16, Blocks.end_stone, 0, 2);
		world.setBlock(i + 7, j + 2, k + 17, Blocks.end_stone, 0, 2);
		world.setBlock(i + 10, j + 2, k + 17, Blocks.end_stone, 0, 2);
		world.setBlock(i + 20, j + 2, k + 17, Blocks.end_stone, 0, 2);
		world.setBlock(i + 3, j + 2, k + 18, Blocks.end_stone, 0, 2);
		world.setBlock(i + 4, j + 2, k + 18, Blocks.end_stone, 0, 2);
		world.setBlock(i + 7, j + 2, k + 18, Blocks.end_stone, 0, 2);
		world.setBlock(i + 13, j + 2, k + 18, Blocks.end_stone, 0, 2);
		world.setBlock(i + 17, j + 2, k + 18, Blocks.end_stone, 0, 2);
		world.setBlock(i + 22, j + 2, k + 18, Blocks.end_stone, 0, 2);
		world.setBlock(i + 23, j + 2, k + 18, Blocks.end_stone, 0, 2);
		world.setBlock(i + 8, j + 2, k + 19, Blocks.end_stone, 0, 2);
		world.setBlock(i + 9, j + 2, k + 19, Blocks.end_stone, 0, 2);
		world.setBlock(i + 14, j + 2, k + 19, Blocks.end_stone, 0, 2);
		world.setBlock(i + 17, j + 2, k + 19, Blocks.end_stone, 0, 2);
		world.setBlock(i + 18, j + 2, k + 19, Blocks.end_stone, 0, 2);
		world.setBlock(i + 4, j + 2, k + 20, Blocks.end_stone, 0, 2);
		world.setBlock(i + 8, j + 2, k + 20, Blocks.end_stone, 0, 2);
		world.setBlock(i + 10, j + 2, k + 20, Blocks.end_stone, 0, 2);
		world.setBlock(i + 12, j + 2, k + 20, Blocks.end_stone, 0, 2);
		world.setBlock(i + 16, j + 2, k + 20, Blocks.end_stone, 0, 2);
		world.setBlock(i + 17, j + 2, k + 20, Blocks.end_stone, 0, 2);
		world.setBlock(i + 21, j + 2, k + 20, Blocks.end_stone, 0, 2);
		world.setBlock(i + 23, j + 2, k + 20, Blocks.end_stone, 0, 2);
		world.setBlock(i + 5, j + 2, k + 21, Blocks.end_stone, 0, 2);
		world.setBlock(i + 8, j + 2, k + 21, Blocks.end_stone, 0, 2);
		world.setBlock(i + 11, j + 2, k + 21, Blocks.end_stone, 0, 2);
		world.setBlock(i + 12, j + 2, k + 21, Blocks.end_stone, 0, 2);
		world.setBlock(i + 14, j + 2, k + 21, Blocks.end_stone, 0, 2);
		world.setBlock(i + 16, j + 2, k + 21, Blocks.end_stone, 0, 2);
		world.setBlock(i + 21, j + 2, k + 21, Blocks.end_stone, 0, 2);
		world.setBlock(i + 23, j + 2, k + 21, Blocks.end_stone, 0, 2);
		world.setBlock(i + 8, j + 2, k + 22, Blocks.end_stone, 0, 2);
		world.setBlock(i + 9, j + 2, k + 22, Blocks.end_stone, 0, 2);
		world.setBlock(i + 12, j + 2, k + 22, Blocks.end_stone, 0, 2);
		world.setBlock(i + 14, j + 2, k + 22, Blocks.end_stone, 0, 2);
		world.setBlock(i + 16, j + 2, k + 22, Blocks.end_stone, 0, 2);
		world.setBlock(i + 17, j + 2, k + 22, Blocks.end_stone, 0, 2);
		world.setBlock(i + 18, j + 2, k + 22, Blocks.end_stone, 0, 2);
		world.setBlock(i + 5, j + 2, k + 23, Blocks.end_stone, 0, 2);
		world.setBlock(i + 6, j + 2, k + 23, Blocks.end_stone, 0, 2);
		world.setBlock(i + 9, j + 2, k + 23, Blocks.end_stone, 0, 2);
		world.setBlock(i + 14, j + 2, k + 23, Blocks.end_stone, 0, 2);
		world.setBlock(i + 18, j + 2, k + 23, Blocks.end_stone, 0, 2);
		world.setBlock(i + 19, j + 2, k + 23, Blocks.end_stone, 0, 2);
		world.setBlock(i + 21, j + 2, k + 23, Blocks.end_stone, 0, 2);
		world.setBlock(i + 22, j + 2, k + 23, Blocks.end_stone, 0, 2);
		world.setBlock(i + 9, j + 2, k + 24, Blocks.end_stone, 0, 2);
		world.setBlock(i + 10, j + 2, k + 24, Blocks.end_stone, 0, 2);
		world.setBlock(i + 14, j + 2, k + 24, Blocks.end_stone, 0, 2);
		world.setBlock(i + 17, j + 2, k + 24, Blocks.end_stone, 0, 2);
		world.setBlock(i + 21, j + 2, k + 24, Blocks.end_stone, 0, 2);
		world.setBlock(i + 7, j + 2, k + 25, Blocks.end_stone, 0, 2);
		world.setBlock(i + 11, j + 2, k + 25, Blocks.end_stone, 0, 2);
		world.setBlock(i + 12, j + 2, k + 25, Blocks.end_stone, 0, 2);
		world.setBlock(i + 16, j + 2, k + 25, Blocks.end_stone, 0, 2);
		world.setBlock(i + 17, j + 2, k + 25, Blocks.end_stone, 0, 2);
		world.setBlock(i + 18, j + 2, k + 25, Blocks.end_stone, 0, 2);
		world.setBlock(i + 21, j + 2, k + 25, Blocks.end_stone, 0, 2);
		world.setBlock(i + 13, j + 2, k + 26, Blocks.end_stone, 0, 2);
		world.setBlock(i + 14, j + 2, k + 26, Blocks.end_stone, 0, 2);
		world.setBlock(i + 16, j + 2, k + 26, Blocks.end_stone, 0, 2);
		world.setBlock(i + 18, j + 2, k + 26, Blocks.end_stone, 0, 2);
		world.setBlock(i + 22, j + 2, k + 26, Blocks.end_stone, 0, 2);
		world.setBlock(i + 10, j + 2, k + 27, Blocks.end_stone, 0, 2);
		world.setBlock(i + 11, j + 2, k + 27, Blocks.end_stone, 0, 2);
		world.setBlock(i + 15, j + 2, k + 27, Blocks.end_stone, 0, 2);
		world.setBlock(i + 17, j + 2, k + 27, Blocks.end_stone, 0, 2);
		world.setBlock(i + 22, j + 2, k + 27, Blocks.end_stone, 0, 2);
		world.setBlock(i + 12, j + 2, k + 28, Blocks.end_stone, 0, 2);
		world.setBlock(i + 15, j + 2, k + 28, Blocks.end_stone, 0, 2);
		world.setBlock(i + 21, j + 2, k + 28, Blocks.end_stone, 0, 2);
		world.setBlock(i + 16, j + 2, k + 29, Blocks.end_stone, 0, 2);
		world.setBlock(i + 21, j + 2, k + 29, Blocks.end_stone, 0, 2);
		world.setBlock(i + 12, j + 2, k + 30, Blocks.end_stone, 0, 2);
		world.setBlock(i + 15, j + 2, k + 30, Blocks.end_stone, 0, 2);
		world.setBlock(i + 16, j + 2, k + 30, Blocks.end_stone, 0, 2);
		world.setBlock(i + 18, j + 2, k + 30, Blocks.end_stone, 0, 2);
		world.setBlock(i + 21, j + 2, k + 30, Blocks.end_stone, 0, 2);
		world.setBlock(i + 20, j + 2, k + 31, Blocks.end_stone, 0, 2);
		world.setBlock(i + 15, j + 2, k + 32, Blocks.end_stone, 0, 2);
		world.setBlock(i + 16, j + 2, k + 32, Blocks.end_stone, 0, 2);
		world.setBlock(i + 18, j + 2, k + 32, Blocks.end_stone, 0, 2);
		world.setBlock(i + 19, j + 2, k + 32, Blocks.end_stone, 0, 2);
		world.setBlock(i + 20, j + 2, k + 32, Blocks.end_stone, 0, 2);
		world.setBlock(i + 20, j + 2, k + 33, Blocks.end_stone, 0, 2);
		world.setBlock(i + 12, j + 3, k + 2, Blocks.end_stone, 0, 2);
		world.setBlock(i + 13, j + 3, k + 2, Blocks.end_stone, 0, 2);
		world.setBlock(i + 14, j + 3, k + 2, Blocks.end_stone, 0, 2);
		world.setBlock(i + 15, j + 3, k + 2, Blocks.end_stone, 0, 2);
		world.setBlock(i + 16, j + 3, k + 2, Blocks.end_stone, 0, 2);
		world.setBlock(i + 17, j + 3, k + 2, Blocks.end_stone, 0, 2);
		world.setBlock(i + 18, j + 3, k + 2, Blocks.end_stone, 0, 2);
		world.setBlock(i + 19, j + 3, k + 2, Blocks.end_stone, 0, 2);
		world.setBlock(i + 20, j + 3, k + 2, Blocks.end_stone, 0, 2);
		world.setBlock(i + 12, j + 3, k + 3, Blocks.end_stone, 0, 2);
		world.setBlock(i + 13, j + 3, k + 3, Blocks.end_stone, 0, 2);
		world.setBlock(i + 14, j + 3, k + 3, Blocks.end_stone, 0, 2);
		world.setBlock(i + 15, j + 3, k + 3, Blocks.end_stone, 0, 2);
		world.setBlock(i + 16, j + 3, k + 3, Blocks.end_stone, 0, 2);
		world.setBlock(i + 17, j + 3, k + 3, Blocks.end_stone, 0, 2);
		world.setBlock(i + 18, j + 3, k + 3, Blocks.end_stone, 0, 2);
		world.setBlock(i + 19, j + 3, k + 3, Blocks.end_stone, 0, 2);
		world.setBlock(i + 20, j + 3, k + 3, Blocks.end_stone, 0, 2);
		world.setBlock(i + 12, j + 3, k + 4, Blocks.end_stone, 0, 2);
		world.setBlock(i + 13, j + 3, k + 4, Blocks.end_stone, 0, 2);
		world.setBlock(i + 14, j + 3, k + 4, Blocks.end_stone, 0, 2);
		world.setBlock(i + 15, j + 3, k + 4, Blocks.end_stone, 0, 2);
		world.setBlock(i + 16, j + 3, k + 4, Blocks.end_stone, 0, 2);
		world.setBlock(i + 17, j + 3, k + 4, Blocks.end_stone, 0, 2);
		world.setBlock(i + 18, j + 3, k + 4, Blocks.end_stone, 0, 2);
		world.setBlock(i + 19, j + 3, k + 4, Blocks.end_stone, 0, 2);
		world.setBlock(i + 20, j + 3, k + 4, Blocks.end_stone, 0, 2);
		world.setBlock(i + 12, j + 3, k + 5, Blocks.end_stone, 0, 2);
		world.setBlock(i + 13, j + 3, k + 5, Blocks.end_stone, 0, 2);
		world.setBlock(i + 14, j + 3, k + 5, Blocks.end_stone, 0, 2);
		world.setBlock(i + 15, j + 3, k + 5, Blocks.end_stone, 0, 2);
		world.setBlock(i + 16, j + 3, k + 5, Blocks.end_stone, 0, 2);
		world.setBlock(i + 17, j + 3, k + 5, Blocks.end_stone, 0, 2);
		world.setBlock(i + 18, j + 3, k + 5, Blocks.end_stone, 0, 2);
		world.setBlock(i + 19, j + 3, k + 5, Blocks.end_stone, 0, 2);
		world.setBlock(i + 20, j + 3, k + 5, Blocks.end_stone, 0, 2);
		world.setBlock(i + 12, j + 3, k + 6, Blocks.end_stone, 0, 2);
		world.setBlock(i + 13, j + 3, k + 6, Blocks.end_stone, 0, 2);
		world.setBlock(i + 14, j + 3, k + 6, Blocks.end_stone, 0, 2);
		world.setBlock(i + 15, j + 3, k + 6, Blocks.end_stone, 0, 2);
		world.setBlock(i + 16, j + 3, k + 6, Blocks.end_stone, 0, 2);
		world.setBlock(i + 17, j + 3, k + 6, Blocks.end_stone, 0, 2);
		world.setBlock(i + 18, j + 3, k + 6, Blocks.end_stone, 0, 2);
		world.setBlock(i + 19, j + 3, k + 6, Blocks.end_stone, 0, 2);
		world.setBlock(i + 20, j + 3, k + 6, Blocks.end_stone, 0, 2);
		world.setBlock(i + 21, j + 3, k + 6, Blocks.end_stone, 0, 2);
		world.setBlock(i + 12, j + 3, k + 7, Blocks.end_stone, 0, 2);
		world.setBlock(i + 13, j + 3, k + 7, Blocks.end_stone, 0, 2);
		world.setBlock(i + 14, j + 3, k + 7, Blocks.end_stone, 0, 2);
		world.setBlock(i + 15, j + 3, k + 7, Blocks.end_stone, 0, 2);
		world.setBlock(i + 16, j + 3, k + 7, Blocks.end_stone, 0, 2);
		world.setBlock(i + 17, j + 3, k + 7, Blocks.end_stone, 0, 2);
		world.setBlock(i + 18, j + 3, k + 7, Blocks.end_stone, 0, 2);
		world.setBlock(i + 19, j + 3, k + 7, Blocks.end_stone, 0, 2);
		world.setBlock(i + 20, j + 3, k + 7, Blocks.end_stone, 0, 2);
		world.setBlock(i + 21, j + 3, k + 7, Blocks.end_stone, 0, 2);
		world.setBlock(i + 22, j + 3, k + 7, Blocks.end_stone, 0, 2);
		world.setBlock(i + 11, j + 3, k + 8, Blocks.end_stone, 0, 2);
		world.setBlock(i + 12, j + 3, k + 8, Blocks.end_stone, 0, 2);
		world.setBlock(i + 13, j + 3, k + 8, Blocks.end_stone, 0, 2);
		world.setBlock(i + 14, j + 3, k + 8, Blocks.end_stone, 0, 2);
		world.setBlock(i + 15, j + 3, k + 8, Blocks.end_stone, 0, 2);
		world.setBlock(i + 16, j + 3, k + 8, Blocks.end_stone, 0, 2);
		world.setBlock(i + 17, j + 3, k + 8, Blocks.end_stone, 0, 2);
		world.setBlock(i + 18, j + 3, k + 8, Blocks.end_stone, 0, 2);
		world.setBlock(i + 19, j + 3, k + 8, Blocks.end_stone, 0, 2);
		world.setBlock(i + 20, j + 3, k + 8, Blocks.end_stone, 0, 2);
		world.setBlock(i + 21, j + 3, k + 8, Blocks.end_stone, 0, 2);
		world.setBlock(i + 22, j + 3, k + 8, Blocks.end_stone, 0, 2);
		world.setBlock(i + 23, j + 3, k + 8, Blocks.end_stone, 0, 2);
		world.setBlock(i + 10, j + 3, k + 9, Blocks.end_stone, 0, 2);
		world.setBlock(i + 11, j + 3, k + 9, Blocks.end_stone, 0, 2);
		world.setBlock(i + 12, j + 3, k + 9, Blocks.end_stone, 0, 2);
		world.setBlock(i + 13, j + 3, k + 9, Blocks.end_stone, 0, 2);
		world.setBlock(i + 14, j + 3, k + 9, Blocks.end_stone, 0, 2);
		world.setBlock(i + 15, j + 3, k + 9, Blocks.end_stone, 0, 2);
		world.setBlock(i + 16, j + 3, k + 9, Blocks.end_stone, 0, 2);
		world.setBlock(i + 17, j + 3, k + 9, Blocks.end_stone, 0, 2);
		world.setBlock(i + 18, j + 3, k + 9, Blocks.end_stone, 0, 2);
		world.setBlock(i + 19, j + 3, k + 9, Blocks.end_stone, 0, 2);
		world.setBlock(i + 20, j + 3, k + 9, Blocks.end_stone, 0, 2);
		world.setBlock(i + 21, j + 3, k + 9, Blocks.end_stone, 0, 2);
		world.setBlock(i + 22, j + 3, k + 9, Blocks.end_stone, 0, 2);
		world.setBlock(i + 23, j + 3, k + 9, Blocks.end_stone, 0, 2);
		world.setBlock(i + 24, j + 3, k + 9, Blocks.end_stone, 0, 2);
		world.setBlock(i + 9, j + 3, k + 10, Blocks.end_stone, 0, 2);
		world.setBlock(i + 10, j + 3, k + 10, Blocks.end_stone, 0, 2);
		world.setBlock(i + 11, j + 3, k + 10, Blocks.end_stone, 0, 2);
		world.setBlock(i + 12, j + 3, k + 10, Blocks.end_stone, 0, 2);
		world.setBlock(i + 13, j + 3, k + 10, Blocks.end_stone, 0, 2);
		world.setBlock(i + 14, j + 3, k + 10, Blocks.end_stone, 0, 2);
		world.setBlock(i + 15, j + 3, k + 10, Blocks.end_stone, 0, 2);
		world.setBlock(i + 16, j + 3, k + 10, Blocks.end_stone, 0, 2);
		world.setBlock(i + 17, j + 3, k + 10, Blocks.end_stone, 0, 2);
		world.setBlock(i + 18, j + 3, k + 10, Blocks.end_stone, 0, 2);
		world.setBlock(i + 19, j + 3, k + 10, Blocks.end_stone, 0, 2);
		world.setBlock(i + 20, j + 3, k + 10, Blocks.end_stone, 0, 2);
		world.setBlock(i + 21, j + 3, k + 10, Blocks.end_stone, 0, 2);
		world.setBlock(i + 22, j + 3, k + 10, Blocks.end_stone, 0, 2);
		world.setBlock(i + 23, j + 3, k + 10, Blocks.end_stone, 0, 2);
		world.setBlock(i + 24, j + 3, k + 10, Blocks.end_stone, 0, 2);
		world.setBlock(i + 8, j + 3, k + 11, Blocks.end_stone, 0, 2);
		world.setBlock(i + 9, j + 3, k + 11, Blocks.end_stone, 0, 2);
		world.setBlock(i + 10, j + 3, k + 11, Blocks.end_stone, 0, 2);
		world.setBlock(i + 11, j + 3, k + 11, Blocks.end_stone, 0, 2);
		world.setBlock(i + 12, j + 3, k + 11, Blocks.end_stone, 0, 2);
		world.setBlock(i + 13, j + 3, k + 11, Blocks.end_stone, 0, 2);
		world.setBlock(i + 14, j + 3, k + 11, Blocks.end_stone, 0, 2);
		world.setBlock(i + 15, j + 3, k + 11, Blocks.end_stone, 0, 2);
		world.setBlock(i + 16, j + 3, k + 11, Blocks.end_stone, 0, 2);
		world.setBlock(i + 17, j + 3, k + 11, Blocks.end_stone, 0, 2);
		world.setBlock(i + 18, j + 3, k + 11, Blocks.end_stone, 0, 2);
		world.setBlock(i + 19, j + 3, k + 11, Blocks.end_stone, 0, 2);
		world.setBlock(i + 20, j + 3, k + 11, Blocks.end_stone, 0, 2);
		world.setBlock(i + 21, j + 3, k + 11, Blocks.end_stone, 0, 2);
		world.setBlock(i + 22, j + 3, k + 11, Blocks.end_stone, 0, 2);
		world.setBlock(i + 23, j + 3, k + 11, Blocks.end_stone, 0, 2);
		world.setBlock(i + 24, j + 3, k + 11, Blocks.end_stone, 0, 2);
		world.setBlock(i + 7, j + 3, k + 12, Blocks.end_stone, 0, 2);
		world.setBlock(i + 8, j + 3, k + 12, Blocks.end_stone, 0, 2);
		world.setBlock(i + 9, j + 3, k + 12, Blocks.end_stone, 0, 2);
		world.setBlock(i + 10, j + 3, k + 12, Blocks.end_stone, 0, 2);
		world.setBlock(i + 11, j + 3, k + 12, Blocks.end_stone, 0, 2);
		world.setBlock(i + 12, j + 3, k + 12, Blocks.end_stone, 0, 2);
		world.setBlock(i + 13, j + 3, k + 12, Blocks.end_stone, 0, 2);
		world.setBlock(i + 14, j + 3, k + 12, Blocks.end_stone, 0, 2);
		world.setBlock(i + 15, j + 3, k + 12, Blocks.end_stone, 0, 2);
		world.setBlock(i + 16, j + 3, k + 12, Blocks.end_stone, 0, 2);
		world.setBlock(i + 17, j + 3, k + 12, Blocks.end_stone, 0, 2);
		world.setBlock(i + 18, j + 3, k + 12, Blocks.end_stone, 0, 2);
		world.setBlock(i + 19, j + 3, k + 12, Blocks.end_stone, 0, 2);
		world.setBlock(i + 20, j + 3, k + 12, Blocks.end_stone, 0, 2);
		world.setBlock(i + 21, j + 3, k + 12, Blocks.end_stone, 0, 2);
		world.setBlock(i + 22, j + 3, k + 12, Blocks.end_stone, 0, 2);
		world.setBlock(i + 23, j + 3, k + 12, Blocks.end_stone, 0, 2);
		world.setBlock(i + 24, j + 3, k + 12, Blocks.end_stone, 0, 2);
		world.setBlock(i + 6, j + 3, k + 13, Blocks.end_stone, 0, 2);
		world.setBlock(i + 7, j + 3, k + 13, Blocks.end_stone, 0, 2);
		world.setBlock(i + 8, j + 3, k + 13, Blocks.end_stone, 0, 2);
		world.setBlock(i + 9, j + 3, k + 13, Blocks.end_stone, 0, 2);
		world.setBlock(i + 10, j + 3, k + 13, Blocks.end_stone, 0, 2);
		world.setBlock(i + 11, j + 3, k + 13, Blocks.end_stone, 0, 2);
		world.setBlock(i + 12, j + 3, k + 13, Blocks.end_stone, 0, 2);
		world.setBlock(i + 13, j + 3, k + 13, Blocks.end_stone, 0, 2);
		world.setBlock(i + 14, j + 3, k + 13, Blocks.end_stone, 0, 2);
		world.setBlock(i + 15, j + 3, k + 13, Blocks.end_stone, 0, 2);
		world.setBlock(i + 16, j + 3, k + 13, Blocks.end_stone, 0, 2);
		world.setBlock(i + 17, j + 3, k + 13, Blocks.end_stone, 0, 2);
		world.setBlock(i + 18, j + 3, k + 13, Blocks.end_stone, 0, 2);
		world.setBlock(i + 19, j + 3, k + 13, Blocks.end_stone, 0, 2);
		world.setBlock(i + 20, j + 3, k + 13, Blocks.end_stone, 0, 2);
		world.setBlock(i + 21, j + 3, k + 13, Blocks.end_stone, 0, 2);
		world.setBlock(i + 22, j + 3, k + 13, Blocks.end_stone, 0, 2);
		world.setBlock(i + 23, j + 3, k + 13, Blocks.end_stone, 0, 2);
		world.setBlock(i + 24, j + 3, k + 13, Blocks.end_stone, 0, 2);
		world.setBlock(i + 5, j + 3, k + 14, Blocks.end_stone, 0, 2);
		world.setBlock(i + 6, j + 3, k + 14, Blocks.end_stone, 0, 2);
		world.setBlock(i + 7, j + 3, k + 14, Blocks.end_stone, 0, 2);
		world.setBlock(i + 8, j + 3, k + 14, Blocks.end_stone, 0, 2);
		world.setBlock(i + 9, j + 3, k + 14, Blocks.end_stone, 0, 2);
		world.setBlock(i + 10, j + 3, k + 14, Blocks.end_stone, 0, 2);
		world.setBlock(i + 11, j + 3, k + 14, Blocks.end_stone, 0, 2);
		world.setBlock(i + 12, j + 3, k + 14, Blocks.end_stone, 0, 2);
		world.setBlock(i + 13, j + 3, k + 14, Blocks.end_stone, 0, 2);
		world.setBlock(i + 14, j + 3, k + 14, Blocks.end_stone, 0, 2);
		world.setBlock(i + 15, j + 3, k + 14, Blocks.end_stone, 0, 2);
		world.setBlock(i + 16, j + 3, k + 14, Blocks.end_stone, 0, 2);
		world.setBlock(i + 17, j + 3, k + 14, Blocks.end_stone, 0, 2);
		world.setBlock(i + 18, j + 3, k + 14, Blocks.end_stone, 0, 2);
		world.setBlock(i + 19, j + 3, k + 14, Blocks.end_stone, 0, 2);
		world.setBlock(i + 20, j + 3, k + 14, Blocks.end_stone, 0, 2);
		world.setBlock(i + 21, j + 3, k + 14, Blocks.end_stone, 0, 2);
		world.setBlock(i + 22, j + 3, k + 14, Blocks.end_stone, 0, 2);
		world.setBlock(i + 23, j + 3, k + 14, Blocks.end_stone, 0, 2);
		world.setBlock(i + 24, j + 3, k + 14, Blocks.end_stone, 0, 2);
		world.setBlock(i + 4, j + 3, k + 15, Blocks.end_stone, 0, 2);
		world.setBlock(i + 5, j + 3, k + 15, Blocks.end_stone, 0, 2);
		world.setBlock(i + 6, j + 3, k + 15, Blocks.end_stone, 0, 2);
		world.setBlock(i + 7, j + 3, k + 15, Blocks.end_stone, 0, 2);
		world.setBlock(i + 8, j + 3, k + 15, Blocks.end_stone, 0, 2);
		world.setBlock(i + 9, j + 3, k + 15, Blocks.end_stone, 0, 2);
		world.setBlock(i + 10, j + 3, k + 15, Blocks.end_stone, 0, 2);
		world.setBlock(i + 11, j + 3, k + 15, Blocks.end_stone, 0, 2);
		world.setBlock(i + 12, j + 3, k + 15, Blocks.end_stone, 0, 2);
		world.setBlock(i + 13, j + 3, k + 15, Blocks.end_stone, 0, 2);
		world.setBlock(i + 14, j + 3, k + 15, Blocks.end_stone, 0, 2);
		world.setBlock(i + 15, j + 3, k + 15, Blocks.end_stone, 0, 2);
		world.setBlock(i + 16, j + 3, k + 15, Blocks.end_stone, 0, 2);
		world.setBlock(i + 17, j + 3, k + 15, Blocks.end_stone, 0, 2);
		world.setBlock(i + 18, j + 3, k + 15, Blocks.end_stone, 0, 2);
		world.setBlock(i + 19, j + 3, k + 15, Blocks.end_stone, 0, 2);
		world.setBlock(i + 20, j + 3, k + 15, Blocks.end_stone, 0, 2);
		world.setBlock(i + 21, j + 3, k + 15, Blocks.end_stone, 0, 2);
		world.setBlock(i + 22, j + 3, k + 15, Blocks.end_stone, 0, 2);
		world.setBlock(i + 23, j + 3, k + 15, Blocks.end_stone, 0, 2);
		world.setBlock(i + 24, j + 3, k + 15, Blocks.end_stone, 0, 2);
		world.setBlock(i + 3, j + 3, k + 16, Blocks.end_stone, 0, 2);
		world.setBlock(i + 4, j + 3, k + 16, Blocks.end_stone, 0, 2);
		world.setBlock(i + 5, j + 3, k + 16, Blocks.end_stone, 0, 2);
		world.setBlock(i + 6, j + 3, k + 16, Blocks.end_stone, 0, 2);
		world.setBlock(i + 7, j + 3, k + 16, Blocks.end_stone, 0, 2);
		world.setBlock(i + 8, j + 3, k + 16, Blocks.end_stone, 0, 2);
		world.setBlock(i + 9, j + 3, k + 16, Blocks.end_stone, 0, 2);
		world.setBlock(i + 10, j + 3, k + 16, Blocks.end_stone, 0, 2);
		world.setBlock(i + 11, j + 3, k + 16, Blocks.end_stone, 0, 2);
		world.setBlock(i + 12, j + 3, k + 16, Blocks.end_stone, 0, 2);
		world.setBlock(i + 13, j + 3, k + 16, Blocks.end_stone, 0, 2);
		world.setBlock(i + 14, j + 3, k + 16, Blocks.end_stone, 0, 2);
		world.setBlock(i + 15, j + 3, k + 16, Blocks.end_stone, 0, 2);
		world.setBlock(i + 16, j + 3, k + 16, Blocks.end_stone, 0, 2);
		world.setBlock(i + 17, j + 3, k + 16, Blocks.end_stone, 0, 2);
		world.setBlock(i + 18, j + 3, k + 16, Blocks.end_stone, 0, 2);
		world.setBlock(i + 19, j + 3, k + 16, Blocks.end_stone, 0, 2);
		world.setBlock(i + 20, j + 3, k + 16, Blocks.end_stone, 0, 2);
		world.setBlock(i + 21, j + 3, k + 16, Blocks.end_stone, 0, 2);
		world.setBlock(i + 22, j + 3, k + 16, Blocks.end_stone, 0, 2);
		world.setBlock(i + 23, j + 3, k + 16, Blocks.end_stone, 0, 2);
		world.setBlock(i + 24, j + 3, k + 16, Blocks.end_stone, 0, 2);
		world.setBlock(i + 2, j + 3, k + 17, Blocks.end_stone, 0, 2);
		world.setBlock(i + 3, j + 3, k + 17, Blocks.end_stone, 0, 2);
		world.setBlock(i + 4, j + 3, k + 17, Blocks.end_stone, 0, 2);
		world.setBlock(i + 5, j + 3, k + 17, Blocks.end_stone, 0, 2);
		world.setBlock(i + 6, j + 3, k + 17, Blocks.end_stone, 0, 2);
		world.setBlock(i + 7, j + 3, k + 17, Blocks.end_stone, 0, 2);
		world.setBlock(i + 8, j + 3, k + 17, Blocks.end_stone, 0, 2);
		world.setBlock(i + 9, j + 3, k + 17, Blocks.end_stone, 0, 2);
		world.setBlock(i + 10, j + 3, k + 17, Blocks.end_stone, 0, 2);
		world.setBlock(i + 11, j + 3, k + 17, Blocks.end_stone, 0, 2);
		world.setBlock(i + 12, j + 3, k + 17, Blocks.end_stone, 0, 2);
		world.setBlock(i + 13, j + 3, k + 17, Blocks.end_stone, 0, 2);
		world.setBlock(i + 14, j + 3, k + 17, Blocks.end_stone, 0, 2);
		world.setBlock(i + 15, j + 3, k + 17, Blocks.end_stone, 0, 2);
		world.setBlock(i + 16, j + 3, k + 17, Blocks.end_stone, 0, 2);
		world.setBlock(i + 17, j + 3, k + 17, Blocks.end_stone, 0, 2);
		world.setBlock(i + 18, j + 3, k + 17, Blocks.end_stone, 0, 2);
		world.setBlock(i + 19, j + 3, k + 17, Blocks.end_stone, 0, 2);
		world.setBlock(i + 20, j + 3, k + 17, Blocks.end_stone, 0, 2);
		world.setBlock(i + 21, j + 3, k + 17, Blocks.end_stone, 0, 2);
		world.setBlock(i + 22, j + 3, k + 17, Blocks.end_stone, 0, 2);
		world.setBlock(i + 23, j + 3, k + 17, Blocks.end_stone, 0, 2);
		world.setBlock(i + 24, j + 3, k + 17, Blocks.end_stone, 0, 2);
		world.setBlock(i + 2, j + 3, k + 18, Blocks.end_stone, 0, 2);
		world.setBlock(i + 3, j + 3, k + 18, Blocks.end_stone, 0, 2);
		world.setBlock(i + 4, j + 3, k + 18, Blocks.end_stone, 0, 2);
		world.setBlock(i + 5, j + 3, k + 18, Blocks.end_stone, 0, 2);
		world.setBlock(i + 6, j + 3, k + 18, Blocks.end_stone, 0, 2);
		world.setBlock(i + 7, j + 3, k + 18, Blocks.end_stone, 0, 2);
		world.setBlock(i + 8, j + 3, k + 18, Blocks.end_stone, 0, 2);
		world.setBlock(i + 9, j + 3, k + 18, Blocks.end_stone, 0, 2);
		world.setBlock(i + 10, j + 3, k + 18, Blocks.end_stone, 0, 2);
		world.setBlock(i + 11, j + 3, k + 18, Blocks.end_stone, 0, 2);
		world.setBlock(i + 12, j + 3, k + 18, Blocks.end_stone, 0, 2);
		world.setBlock(i + 13, j + 3, k + 18, Blocks.end_stone, 0, 2);
		world.setBlock(i + 14, j + 3, k + 18, Blocks.end_stone, 0, 2);
		world.setBlock(i + 15, j + 3, k + 18, Blocks.end_stone, 0, 2);
		world.setBlock(i + 16, j + 3, k + 18, Blocks.end_stone, 0, 2);
		world.setBlock(i + 17, j + 3, k + 18, Blocks.end_stone, 0, 2);
		world.setBlock(i + 18, j + 3, k + 18, Blocks.end_stone, 0, 2);
		world.setBlock(i + 19, j + 3, k + 18, Blocks.end_stone, 0, 2);
		world.setBlock(i + 20, j + 3, k + 18, Blocks.end_stone, 0, 2);
		world.setBlock(i + 21, j + 3, k + 18, Blocks.end_stone, 0, 2);
		world.setBlock(i + 22, j + 3, k + 18, Blocks.end_stone, 0, 2);
		world.setBlock(i + 23, j + 3, k + 18, Blocks.end_stone, 0, 2);
		world.setBlock(i + 24, j + 3, k + 18, Blocks.end_stone, 0, 2);
		world.setBlock(i + 2, j + 3, k + 19, Blocks.end_stone, 0, 2);
		world.setBlock(i + 3, j + 3, k + 19, Blocks.end_stone, 0, 2);
		world.setBlock(i + 4, j + 3, k + 19, Blocks.end_stone, 0, 2);
		world.setBlock(i + 5, j + 3, k + 19, Blocks.end_stone, 0, 2);
		world.setBlock(i + 6, j + 3, k + 19, Blocks.end_stone, 0, 2);
		world.setBlock(i + 7, j + 3, k + 19, Blocks.end_stone, 0, 2);
		world.setBlock(i + 8, j + 3, k + 19, Blocks.end_stone, 0, 2);
		world.setBlock(i + 9, j + 3, k + 19, Blocks.end_stone, 0, 2);
		world.setBlock(i + 10, j + 3, k + 19, Blocks.end_stone, 0, 2);
		world.setBlock(i + 11, j + 3, k + 19, Blocks.end_stone, 0, 2);
		world.setBlock(i + 12, j + 3, k + 19, Blocks.end_stone, 0, 2);
		world.setBlock(i + 13, j + 3, k + 19, Blocks.end_stone, 0, 2);
		world.setBlock(i + 14, j + 3, k + 19, Blocks.end_stone, 0, 2);
		world.setBlock(i + 15, j + 3, k + 19, Blocks.end_stone, 0, 2);
		world.setBlock(i + 16, j + 3, k + 19, Blocks.end_stone, 0, 2);
		world.setBlock(i + 17, j + 3, k + 19, Blocks.end_stone, 0, 2);
		world.setBlock(i + 18, j + 3, k + 19, Blocks.end_stone, 0, 2);
		world.setBlock(i + 19, j + 3, k + 19, Blocks.end_stone, 0, 2);
		world.setBlock(i + 20, j + 3, k + 19, Blocks.end_stone, 0, 2);
		world.setBlock(i + 21, j + 3, k + 19, Blocks.end_stone, 0, 2);
		world.setBlock(i + 22, j + 3, k + 19, Blocks.end_stone, 0, 2);
		world.setBlock(i + 23, j + 3, k + 19, Blocks.end_stone, 0, 2);
		world.setBlock(i + 24, j + 3, k + 19, Blocks.end_stone, 0, 2);
		world.setBlock(i + 2, j + 3, k + 20, Blocks.end_stone, 0, 2);
		world.setBlock(i + 3, j + 3, k + 20, Blocks.end_stone, 0, 2);
		world.setBlock(i + 4, j + 3, k + 20, Blocks.end_stone, 0, 2);
		world.setBlock(i + 5, j + 3, k + 20, Blocks.end_stone, 0, 2);
		world.setBlock(i + 6, j + 3, k + 20, Blocks.end_stone, 0, 2);
		world.setBlock(i + 7, j + 3, k + 20, Blocks.end_stone, 0, 2);
		world.setBlock(i + 8, j + 3, k + 20, Blocks.end_stone, 0, 2);
		world.setBlock(i + 9, j + 3, k + 20, Blocks.end_stone, 0, 2);
		world.setBlock(i + 10, j + 3, k + 20, Blocks.end_stone, 0, 2);
		world.setBlock(i + 11, j + 3, k + 20, Blocks.end_stone, 0, 2);
		world.setBlock(i + 12, j + 3, k + 20, Blocks.end_stone, 0, 2);
		world.setBlock(i + 13, j + 3, k + 20, Blocks.end_stone, 0, 2);
		world.setBlock(i + 14, j + 3, k + 20, Blocks.end_stone, 0, 2);
		world.setBlock(i + 15, j + 3, k + 20, Blocks.end_stone, 0, 2);
		world.setBlock(i + 16, j + 3, k + 20, Blocks.end_stone, 0, 2);
		world.setBlock(i + 17, j + 3, k + 20, Blocks.end_stone, 0, 2);
		world.setBlock(i + 18, j + 3, k + 20, Blocks.end_stone, 0, 2);
		world.setBlock(i + 19, j + 3, k + 20, Blocks.end_stone, 0, 2);
		world.setBlock(i + 20, j + 3, k + 20, Blocks.end_stone, 0, 2);
		world.setBlock(i + 21, j + 3, k + 20, Blocks.end_stone, 0, 2);
		world.setBlock(i + 22, j + 3, k + 20, Blocks.end_stone, 0, 2);
		world.setBlock(i + 23, j + 3, k + 20, Blocks.end_stone, 0, 2);
		world.setBlock(i + 24, j + 3, k + 20, Blocks.end_stone, 0, 2);
		world.setBlock(i + 3, j + 3, k + 21, Blocks.end_stone, 0, 2);
		world.setBlock(i + 4, j + 3, k + 21, Blocks.end_stone, 0, 2);
		world.setBlock(i + 5, j + 3, k + 21, Blocks.end_stone, 0, 2);
		world.setBlock(i + 6, j + 3, k + 21, Blocks.end_stone, 0, 2);
		world.setBlock(i + 7, j + 3, k + 21, Blocks.end_stone, 0, 2);
		world.setBlock(i + 8, j + 3, k + 21, Blocks.end_stone, 0, 2);
		world.setBlock(i + 9, j + 3, k + 21, Blocks.end_stone, 0, 2);
		world.setBlock(i + 10, j + 3, k + 21, Blocks.end_stone, 0, 2);
		world.setBlock(i + 11, j + 3, k + 21, Blocks.end_stone, 0, 2);
		world.setBlock(i + 12, j + 3, k + 21, Blocks.end_stone, 0, 2);
		world.setBlock(i + 13, j + 3, k + 21, Blocks.end_stone, 0, 2);
		world.setBlock(i + 14, j + 3, k + 21, Blocks.end_stone, 0, 2);
		world.setBlock(i + 15, j + 3, k + 21, Blocks.end_stone, 0, 2);
		world.setBlock(i + 16, j + 3, k + 21, Blocks.end_stone, 0, 2);
		world.setBlock(i + 17, j + 3, k + 21, Blocks.end_stone, 0, 2);
		world.setBlock(i + 18, j + 3, k + 21, Blocks.end_stone, 0, 2);
		world.setBlock(i + 19, j + 3, k + 21, Blocks.end_stone, 0, 2);
		world.setBlock(i + 20, j + 3, k + 21, Blocks.end_stone, 0, 2);
		world.setBlock(i + 21, j + 3, k + 21, Blocks.end_stone, 0, 2);
		world.setBlock(i + 22, j + 3, k + 21, Blocks.end_stone, 0, 2);
		world.setBlock(i + 23, j + 3, k + 21, Blocks.end_stone, 0, 2);
		world.setBlock(i + 24, j + 3, k + 21, Blocks.end_stone, 0, 2);
		world.setBlock(i + 4, j + 3, k + 22, Blocks.end_stone, 0, 2);
		world.setBlock(i + 5, j + 3, k + 22, Blocks.end_stone, 0, 2);
		world.setBlock(i + 6, j + 3, k + 22, Blocks.end_stone, 0, 2);
		world.setBlock(i + 7, j + 3, k + 22, Blocks.end_stone, 0, 2);
		world.setBlock(i + 8, j + 3, k + 22, Blocks.end_stone, 0, 2);
		world.setBlock(i + 9, j + 3, k + 22, Blocks.end_stone, 0, 2);
		world.setBlock(i + 10, j + 3, k + 22, Blocks.end_stone, 0, 2);
		world.setBlock(i + 11, j + 3, k + 22, Blocks.end_stone, 0, 2);
		world.setBlock(i + 12, j + 3, k + 22, Blocks.end_stone, 0, 2);
		world.setBlock(i + 13, j + 3, k + 22, Blocks.end_stone, 0, 2);
		world.setBlock(i + 14, j + 3, k + 22, Blocks.end_stone, 0, 2);
		world.setBlock(i + 15, j + 3, k + 22, Blocks.end_stone, 0, 2);
		world.setBlock(i + 16, j + 3, k + 22, Blocks.end_stone, 0, 2);
		world.setBlock(i + 17, j + 3, k + 22, Blocks.end_stone, 0, 2);
		world.setBlock(i + 18, j + 3, k + 22, Blocks.end_stone, 0, 2);
		world.setBlock(i + 19, j + 3, k + 22, Blocks.end_stone, 0, 2);
		world.setBlock(i + 20, j + 3, k + 22, Blocks.end_stone, 0, 2);
		world.setBlock(i + 21, j + 3, k + 22, Blocks.end_stone, 0, 2);
		world.setBlock(i + 22, j + 3, k + 22, Blocks.end_stone, 0, 2);
		world.setBlock(i + 23, j + 3, k + 22, Blocks.end_stone, 0, 2);
		world.setBlock(i + 24, j + 3, k + 22, Blocks.end_stone, 0, 2);
		world.setBlock(i + 5, j + 3, k + 23, Blocks.end_stone, 0, 2);
		world.setBlock(i + 6, j + 3, k + 23, Blocks.end_stone, 0, 2);
		world.setBlock(i + 7, j + 3, k + 23, Blocks.end_stone, 0, 2);
		world.setBlock(i + 8, j + 3, k + 23, Blocks.end_stone, 0, 2);
		world.setBlock(i + 9, j + 3, k + 23, Blocks.end_stone, 0, 2);
		world.setBlock(i + 10, j + 3, k + 23, Blocks.end_stone, 0, 2);
		world.setBlock(i + 11, j + 3, k + 23, Blocks.end_stone, 0, 2);
		world.setBlock(i + 12, j + 3, k + 23, Blocks.end_stone, 0, 2);
		world.setBlock(i + 13, j + 3, k + 23, Blocks.end_stone, 0, 2);
		world.setBlock(i + 14, j + 3, k + 23, Blocks.end_stone, 0, 2);
		world.setBlock(i + 15, j + 3, k + 23, Blocks.end_stone, 0, 2);
		world.setBlock(i + 16, j + 3, k + 23, Blocks.end_stone, 0, 2);
		world.setBlock(i + 17, j + 3, k + 23, Blocks.end_stone, 0, 2);
		world.setBlock(i + 18, j + 3, k + 23, Blocks.end_stone, 0, 2);
		world.setBlock(i + 19, j + 3, k + 23, Blocks.end_stone, 0, 2);
		world.setBlock(i + 20, j + 3, k + 23, Blocks.end_stone, 0, 2);
		world.setBlock(i + 21, j + 3, k + 23, Blocks.end_stone, 0, 2);
		world.setBlock(i + 22, j + 3, k + 23, Blocks.end_stone, 0, 2);
		world.setBlock(i + 23, j + 3, k + 23, Blocks.end_stone, 0, 2);
		world.setBlock(i + 24, j + 3, k + 23, Blocks.end_stone, 0, 2);
		world.setBlock(i + 6, j + 3, k + 24, Blocks.end_stone, 0, 2);
		world.setBlock(i + 7, j + 3, k + 24, Blocks.end_stone, 0, 2);
		world.setBlock(i + 8, j + 3, k + 24, Blocks.end_stone, 0, 2);
		world.setBlock(i + 9, j + 3, k + 24, Blocks.end_stone, 0, 2);
		world.setBlock(i + 10, j + 3, k + 24, Blocks.end_stone, 0, 2);
		world.setBlock(i + 11, j + 3, k + 24, Blocks.end_stone, 0, 2);
		world.setBlock(i + 12, j + 3, k + 24, Blocks.end_stone, 0, 2);
		world.setBlock(i + 13, j + 3, k + 24, Blocks.end_stone, 0, 2);
		world.setBlock(i + 14, j + 3, k + 24, Blocks.end_stone, 0, 2);
		world.setBlock(i + 15, j + 3, k + 24, Blocks.end_stone, 0, 2);
		world.setBlock(i + 16, j + 3, k + 24, Blocks.end_stone, 0, 2);
		world.setBlock(i + 17, j + 3, k + 24, Blocks.end_stone, 0, 2);
		world.setBlock(i + 18, j + 3, k + 24, Blocks.end_stone, 0, 2);
		world.setBlock(i + 19, j + 3, k + 24, Blocks.end_stone, 0, 2);
		world.setBlock(i + 20, j + 3, k + 24, Blocks.end_stone, 0, 2);
		world.setBlock(i + 21, j + 3, k + 24, Blocks.end_stone, 0, 2);
		world.setBlock(i + 22, j + 3, k + 24, Blocks.end_stone, 0, 2);
		world.setBlock(i + 23, j + 3, k + 24, Blocks.end_stone, 0, 2);
		world.setBlock(i + 24, j + 3, k + 24, Blocks.end_stone, 0, 2);
		world.setBlock(i + 7, j + 3, k + 25, Blocks.end_stone, 0, 2);
		world.setBlock(i + 8, j + 3, k + 25, Blocks.end_stone, 0, 2);
		world.setBlock(i + 9, j + 3, k + 25, Blocks.end_stone, 0, 2);
		world.setBlock(i + 10, j + 3, k + 25, Blocks.end_stone, 0, 2);
		world.setBlock(i + 11, j + 3, k + 25, Blocks.end_stone, 0, 2);
		world.setBlock(i + 12, j + 3, k + 25, Blocks.end_stone, 0, 2);
		world.setBlock(i + 13, j + 3, k + 25, Blocks.end_stone, 0, 2);
		world.setBlock(i + 14, j + 3, k + 25, Blocks.end_stone, 0, 2);
		world.setBlock(i + 15, j + 3, k + 25, Blocks.end_stone, 0, 2);
		world.setBlock(i + 16, j + 3, k + 25, Blocks.end_stone, 0, 2);
		world.setBlock(i + 17, j + 3, k + 25, Blocks.end_stone, 0, 2);
		world.setBlock(i + 18, j + 3, k + 25, Blocks.end_stone, 0, 2);
		world.setBlock(i + 19, j + 3, k + 25, Blocks.end_stone, 0, 2);
		world.setBlock(i + 20, j + 3, k + 25, Blocks.end_stone, 0, 2);
		world.setBlock(i + 21, j + 3, k + 25, Blocks.end_stone, 0, 2);
		world.setBlock(i + 22, j + 3, k + 25, Blocks.end_stone, 0, 2);
		world.setBlock(i + 23, j + 3, k + 25, Blocks.end_stone, 0, 2);
		world.setBlock(i + 24, j + 3, k + 25, Blocks.end_stone, 0, 2);
		world.setBlock(i + 8, j + 3, k + 26, Blocks.end_stone, 0, 2);
		world.setBlock(i + 9, j + 3, k + 26, Blocks.end_stone, 0, 2);
		world.setBlock(i + 10, j + 3, k + 26, Blocks.end_stone, 0, 2);
		world.setBlock(i + 11, j + 3, k + 26, Blocks.end_stone, 0, 2);
		world.setBlock(i + 12, j + 3, k + 26, Blocks.end_stone, 0, 2);
		world.setBlock(i + 13, j + 3, k + 26, Blocks.end_stone, 0, 2);
		world.setBlock(i + 14, j + 3, k + 26, Blocks.end_stone, 0, 2);
		world.setBlock(i + 15, j + 3, k + 26, Blocks.end_stone, 0, 2);
		world.setBlock(i + 16, j + 3, k + 26, Blocks.end_stone, 0, 2);
		world.setBlock(i + 17, j + 3, k + 26, Blocks.end_stone, 0, 2);
		world.setBlock(i + 18, j + 3, k + 26, Blocks.end_stone, 0, 2);
		world.setBlock(i + 19, j + 3, k + 26, Blocks.end_stone, 0, 2);
		world.setBlock(i + 20, j + 3, k + 26, Blocks.end_stone, 0, 2);
		world.setBlock(i + 21, j + 3, k + 26, Blocks.end_stone, 0, 2);
		world.setBlock(i + 22, j + 3, k + 26, Blocks.end_stone, 0, 2);
		world.setBlock(i + 23, j + 3, k + 26, Blocks.end_stone, 0, 2);
		world.setBlock(i + 24, j + 3, k + 26, Blocks.end_stone, 0, 2);
		world.setBlock(i + 9, j + 3, k + 27, Blocks.end_stone, 0, 2);
		world.setBlock(i + 10, j + 3, k + 27, Blocks.end_stone, 0, 2);
		world.setBlock(i + 11, j + 3, k + 27, Blocks.end_stone, 0, 2);
		world.setBlock(i + 12, j + 3, k + 27, Blocks.end_stone, 0, 2);
		world.setBlock(i + 13, j + 3, k + 27, Blocks.end_stone, 0, 2);
		world.setBlock(i + 14, j + 3, k + 27, Blocks.end_stone, 0, 2);
		world.setBlock(i + 15, j + 3, k + 27, Blocks.end_stone, 0, 2);
		world.setBlock(i + 16, j + 3, k + 27, Blocks.end_stone, 0, 2);
		world.setBlock(i + 17, j + 3, k + 27, Blocks.end_stone, 0, 2);
		world.setBlock(i + 18, j + 3, k + 27, Blocks.end_stone, 0, 2);
		world.setBlock(i + 19, j + 3, k + 27, Blocks.end_stone, 0, 2);
		world.setBlock(i + 20, j + 3, k + 27, Blocks.end_stone, 0, 2);
		world.setBlock(i + 21, j + 3, k + 27, Blocks.end_stone, 0, 2);
		world.setBlock(i + 22, j + 3, k + 27, Blocks.end_stone, 0, 2);
		world.setBlock(i + 23, j + 3, k + 27, Blocks.end_stone, 0, 2);
		world.setBlock(i + 24, j + 3, k + 27, Blocks.end_stone, 0, 2);
		world.setBlock(i + 10, j + 3, k + 28, Blocks.end_stone, 0, 2);
		world.setBlock(i + 11, j + 3, k + 28, Blocks.end_stone, 0, 2);
		world.setBlock(i + 12, j + 3, k + 28, Blocks.end_stone, 0, 2);
		world.setBlock(i + 13, j + 3, k + 28, Blocks.end_stone, 0, 2);
		world.setBlock(i + 14, j + 3, k + 28, Blocks.end_stone, 0, 2);
		world.setBlock(i + 15, j + 3, k + 28, Blocks.end_stone, 0, 2);
		world.setBlock(i + 16, j + 3, k + 28, Blocks.end_stone, 0, 2);
		world.setBlock(i + 17, j + 3, k + 28, Blocks.end_stone, 0, 2);
		world.setBlock(i + 18, j + 3, k + 28, Blocks.end_stone, 0, 2);
		world.setBlock(i + 19, j + 3, k + 28, Blocks.end_stone, 0, 2);
		world.setBlock(i + 20, j + 3, k + 28, Blocks.end_stone, 0, 2);
		world.setBlock(i + 21, j + 3, k + 28, Blocks.end_stone, 0, 2);
		world.setBlock(i + 22, j + 3, k + 28, Blocks.end_stone, 0, 2);
		world.setBlock(i + 23, j + 3, k + 28, Blocks.end_stone, 0, 2);
		world.setBlock(i + 24, j + 3, k + 28, Blocks.end_stone, 0, 2);
		world.setBlock(i + 11, j + 3, k + 29, Blocks.end_stone, 0, 2);
		world.setBlock(i + 12, j + 3, k + 29, Blocks.end_stone, 0, 2);
		world.setBlock(i + 13, j + 3, k + 29, Blocks.end_stone, 0, 2);
		world.setBlock(i + 14, j + 3, k + 29, Blocks.end_stone, 0, 2);
		world.setBlock(i + 15, j + 3, k + 29, Blocks.end_stone, 0, 2);
		world.setBlock(i + 16, j + 3, k + 29, Blocks.end_stone, 0, 2);
		world.setBlock(i + 17, j + 3, k + 29, Blocks.end_stone, 0, 2);
		world.setBlock(i + 18, j + 3, k + 29, Blocks.end_stone, 0, 2);
		world.setBlock(i + 19, j + 3, k + 29, Blocks.end_stone, 0, 2);
		world.setBlock(i + 20, j + 3, k + 29, Blocks.end_stone, 0, 2);
		world.setBlock(i + 21, j + 3, k + 29, Blocks.end_stone, 0, 2);
		world.setBlock(i + 22, j + 3, k + 29, Blocks.end_stone, 0, 2);
		world.setBlock(i + 23, j + 3, k + 29, Blocks.end_stone, 0, 2);
		world.setBlock(i + 12, j + 3, k + 30, Blocks.end_stone, 0, 2);
		world.setBlock(i + 13, j + 3, k + 30, Blocks.end_stone, 0, 2);
		world.setBlock(i + 14, j + 3, k + 30, Blocks.end_stone, 0, 2);
		world.setBlock(i + 15, j + 3, k + 30, Blocks.end_stone, 0, 2);
		world.setBlock(i + 16, j + 3, k + 30, Blocks.end_stone, 0, 2);
		world.setBlock(i + 17, j + 3, k + 30, Blocks.end_stone, 0, 2);
		world.setBlock(i + 18, j + 3, k + 30, Blocks.end_stone, 0, 2);
		world.setBlock(i + 19, j + 3, k + 30, Blocks.end_stone, 0, 2);
		world.setBlock(i + 20, j + 3, k + 30, Blocks.end_stone, 0, 2);
		world.setBlock(i + 21, j + 3, k + 30, Blocks.end_stone, 0, 2);
		world.setBlock(i + 22, j + 3, k + 30, Blocks.end_stone, 0, 2);
		world.setBlock(i + 12, j + 3, k + 31, Blocks.end_stone, 0, 2);
		world.setBlock(i + 13, j + 3, k + 31, Blocks.end_stone, 0, 2);
		world.setBlock(i + 14, j + 3, k + 31, Blocks.end_stone, 0, 2);
		world.setBlock(i + 15, j + 3, k + 31, Blocks.end_stone, 0, 2);
		world.setBlock(i + 16, j + 3, k + 31, Blocks.end_stone, 0, 2);
		world.setBlock(i + 17, j + 3, k + 31, Blocks.end_stone, 0, 2);
		world.setBlock(i + 18, j + 3, k + 31, Blocks.end_stone, 0, 2);
		world.setBlock(i + 19, j + 3, k + 31, Blocks.end_stone, 0, 2);
		world.setBlock(i + 20, j + 3, k + 31, Blocks.end_stone, 0, 2);
		world.setBlock(i + 21, j + 3, k + 31, Blocks.end_stone, 0, 2);
		world.setBlock(i + 12, j + 3, k + 32, Blocks.end_stone, 0, 2);
		world.setBlock(i + 13, j + 3, k + 32, Blocks.end_stone, 0, 2);
		world.setBlock(i + 14, j + 3, k + 32, Blocks.end_stone, 0, 2);
		world.setBlock(i + 15, j + 3, k + 32, Blocks.end_stone, 0, 2);
		world.setBlock(i + 16, j + 3, k + 32, Blocks.end_stone, 0, 2);
		world.setBlock(i + 17, j + 3, k + 32, Blocks.end_stone, 0, 2);
		world.setBlock(i + 18, j + 3, k + 32, Blocks.end_stone, 0, 2);
		world.setBlock(i + 19, j + 3, k + 32, Blocks.end_stone, 0, 2);
		world.setBlock(i + 20, j + 3, k + 32, Blocks.end_stone, 0, 2);
		world.setBlock(i + 11, j + 4, k + 1, Blocks.end_stone, 0, 2);
		world.setBlock(i + 12, j + 4, k + 1, Blocks.end_stone, 0, 2);
		world.setBlock(i + 13, j + 4, k + 1, Blocks.end_stone, 0, 2);
		world.setBlock(i + 14, j + 4, k + 1, Blocks.end_stone, 0, 2);
		world.setBlock(i + 15, j + 4, k + 1, Blocks.end_stone, 0, 2);
		world.setBlock(i + 16, j + 4, k + 1, Blocks.end_stone, 0, 2);
		world.setBlock(i + 17, j + 4, k + 1, Blocks.end_stone, 0, 2);
		world.setBlock(i + 18, j + 4, k + 1, Blocks.end_stone, 0, 2);
		world.setBlock(i + 19, j + 4, k + 1, Blocks.end_stone, 0, 2);
		world.setBlock(i + 20, j + 4, k + 1, Blocks.end_stone, 0, 2);
		world.setBlock(i + 21, j + 4, k + 1, Blocks.end_stone, 0, 2);
		world.setBlock(i + 11, j + 4, k + 2, Blocks.end_stone, 0, 2);
		world.setBlock(i + 12, j + 4, k + 2, Blocks.end_stone, 0, 2);
		world.setBlock(i + 13, j + 4, k + 2, Blocks.end_stone, 0, 2);
		world.setBlock(i + 14, j + 4, k + 2, Blocks.end_stone, 0, 2);
		world.setBlock(i + 15, j + 4, k + 2, Blocks.end_stone, 0, 2);
		world.setBlock(i + 16, j + 4, k + 2, Blocks.end_stone, 0, 2);
		world.setBlock(i + 17, j + 4, k + 2, Blocks.end_stone, 0, 2);
		world.setBlock(i + 18, j + 4, k + 2, Blocks.end_stone, 0, 2);
		world.setBlock(i + 19, j + 4, k + 2, Blocks.end_stone, 0, 2);
		world.setBlock(i + 20, j + 4, k + 2, Blocks.end_stone, 0, 2);
		world.setBlock(i + 21, j + 4, k + 2, Blocks.end_stone, 0, 2);
		world.setBlock(i + 11, j + 4, k + 3, Blocks.end_stone, 0, 2);
		world.setBlock(i + 12, j + 4, k + 3, Blocks.end_stone, 0, 2);
		world.setBlock(i + 13, j + 4, k + 3, Blocks.end_stone, 0, 2);
		world.setBlock(i + 14, j + 4, k + 3, Blocks.end_stone, 0, 2);
		world.setBlock(i + 15, j + 4, k + 3, Blocks.end_stone, 0, 2);
		world.setBlock(i + 16, j + 4, k + 3, Blocks.end_stone, 0, 2);
		world.setBlock(i + 17, j + 4, k + 3, Blocks.end_stone, 0, 2);
		world.setBlock(i + 18, j + 4, k + 3, Blocks.end_stone, 0, 2);
		world.setBlock(i + 19, j + 4, k + 3, Blocks.end_stone, 0, 2);
		world.setBlock(i + 20, j + 4, k + 3, Blocks.end_stone, 0, 2);
		world.setBlock(i + 21, j + 4, k + 3, Blocks.end_stone, 0, 2);
		world.setBlock(i + 11, j + 4, k + 4, Blocks.end_stone, 0, 2);
		world.setBlock(i + 12, j + 4, k + 4, Blocks.end_stone, 0, 2);
		world.setBlock(i + 13, j + 4, k + 4, Blocks.end_stone, 0, 2);
		world.setBlock(i + 14, j + 4, k + 4, Blocks.end_stone, 0, 2);
		world.setBlock(i + 15, j + 4, k + 4, Blocks.end_stone, 0, 2);
		world.setBlock(i + 16, j + 4, k + 4, Blocks.end_stone, 0, 2);
		world.setBlock(i + 17, j + 4, k + 4, Blocks.end_stone, 0, 2);
		world.setBlock(i + 18, j + 4, k + 4, Blocks.end_stone, 0, 2);
		world.setBlock(i + 19, j + 4, k + 4, Blocks.end_stone, 0, 2);
		world.setBlock(i + 20, j + 4, k + 4, Blocks.end_stone, 0, 2);
		world.setBlock(i + 21, j + 4, k + 4, Blocks.end_stone, 0, 2);
		world.setBlock(i + 11, j + 4, k + 5, Blocks.end_stone, 0, 2);
		world.setBlock(i + 12, j + 4, k + 5, Blocks.end_stone, 0, 2);
		world.setBlock(i + 13, j + 4, k + 5, Blocks.end_stone, 0, 2);
		world.setBlock(i + 14, j + 4, k + 5, Blocks.end_stone, 0, 2);
		world.setBlock(i + 15, j + 4, k + 5, Blocks.end_stone, 0, 2);
		world.setBlock(i + 16, j + 4, k + 5, Blocks.end_stone, 0, 2);
		world.setBlock(i + 17, j + 4, k + 5, Blocks.end_stone, 0, 2);
		world.setBlock(i + 18, j + 4, k + 5, Blocks.end_stone, 0, 2);
		world.setBlock(i + 19, j + 4, k + 5, Blocks.end_stone, 0, 2);
		world.setBlock(i + 20, j + 4, k + 5, Blocks.end_stone, 0, 2);
		world.setBlock(i + 21, j + 4, k + 5, Blocks.end_stone, 0, 2);
		world.setBlock(i + 11, j + 4, k + 6, Blocks.end_stone, 0, 2);
		world.setBlock(i + 12, j + 4, k + 6, Blocks.end_stone, 0, 2);
		world.setBlock(i + 13, j + 4, k + 6, Blocks.end_stone, 0, 2);
		world.setBlock(i + 14, j + 4, k + 6, Blocks.end_stone, 0, 2);
		world.setBlock(i + 15, j + 4, k + 6, Blocks.end_stone, 0, 2);
		world.setBlock(i + 16, j + 4, k + 6, Blocks.end_stone, 0, 2);
		world.setBlock(i + 17, j + 4, k + 6, Blocks.end_stone, 0, 2);
		world.setBlock(i + 18, j + 4, k + 6, Blocks.end_stone, 0, 2);
		world.setBlock(i + 19, j + 4, k + 6, Blocks.end_stone, 0, 2);
		world.setBlock(i + 20, j + 4, k + 6, Blocks.end_stone, 0, 2);
		world.setBlock(i + 21, j + 4, k + 6, Blocks.end_stone, 0, 2);
		world.setBlock(i + 22, j + 4, k + 6, Blocks.end_stone, 0, 2);
		world.setBlock(i + 11, j + 4, k + 7, Blocks.end_stone, 0, 2);
		world.setBlock(i + 12, j + 4, k + 7, Blocks.end_stone, 0, 2);
		world.setBlock(i + 13, j + 4, k + 7, Blocks.end_stone, 0, 2);
		world.setBlock(i + 14, j + 4, k + 7, Blocks.end_stone, 0, 2);
		world.setBlock(i + 15, j + 4, k + 7, Blocks.end_stone, 0, 2);
		world.setBlock(i + 16, j + 4, k + 7, Blocks.end_stone, 0, 2);
		world.setBlock(i + 17, j + 4, k + 7, Blocks.end_stone, 0, 2);
		world.setBlock(i + 18, j + 4, k + 7, Blocks.end_stone, 0, 2);
		world.setBlock(i + 19, j + 4, k + 7, Blocks.end_stone, 0, 2);
		world.setBlock(i + 20, j + 4, k + 7, Blocks.end_stone, 0, 2);
		world.setBlock(i + 21, j + 4, k + 7, Blocks.end_stone, 0, 2);
		world.setBlock(i + 22, j + 4, k + 7, Blocks.end_stone, 0, 2);
		world.setBlock(i + 23, j + 4, k + 7, Blocks.end_stone, 0, 2);
		world.setBlock(i + 10, j + 4, k + 8, Blocks.end_stone, 0, 2);
		world.setBlock(i + 11, j + 4, k + 8, Blocks.end_stone, 0, 2);
		world.setBlock(i + 12, j + 4, k + 8, Blocks.end_stone, 0, 2);
		world.setBlock(i + 13, j + 4, k + 8, Blocks.end_stone, 0, 2);
		world.setBlock(i + 14, j + 4, k + 8, Blocks.end_stone, 0, 2);
		world.setBlock(i + 15, j + 4, k + 8, Blocks.end_stone, 0, 2);
		world.setBlock(i + 16, j + 4, k + 8, Blocks.end_stone, 0, 2);
		world.setBlock(i + 17, j + 4, k + 8, Blocks.end_stone, 0, 2);
		world.setBlock(i + 18, j + 4, k + 8, Blocks.end_stone, 0, 2);
		world.setBlock(i + 19, j + 4, k + 8, Blocks.end_stone, 0, 2);
		world.setBlock(i + 20, j + 4, k + 8, Blocks.end_stone, 0, 2);
		world.setBlock(i + 21, j + 4, k + 8, Blocks.end_stone, 0, 2);
		world.setBlock(i + 22, j + 4, k + 8, Blocks.end_stone, 0, 2);
		world.setBlock(i + 23, j + 4, k + 8, Blocks.end_stone, 0, 2);
		world.setBlock(i + 24, j + 4, k + 8, Blocks.end_stone, 0, 2);
		world.setBlock(i + 9, j + 4, k + 9, Blocks.end_stone, 0, 2);
		world.setBlock(i + 10, j + 4, k + 9, Blocks.end_stone, 0, 2);
		world.setBlock(i + 11, j + 4, k + 9, Blocks.end_stone, 0, 2);
		world.setBlock(i + 12, j + 4, k + 9, Blocks.end_stone, 0, 2);
		world.setBlock(i + 13, j + 4, k + 9, Blocks.end_stone, 0, 2);
		world.setBlock(i + 14, j + 4, k + 9, Blocks.end_stone, 0, 2);
		world.setBlock(i + 15, j + 4, k + 9, Blocks.end_stone, 0, 2);
		world.setBlock(i + 16, j + 4, k + 9, Blocks.end_stone, 0, 2);
		world.setBlock(i + 17, j + 4, k + 9, Blocks.end_stone, 0, 2);
		world.setBlock(i + 18, j + 4, k + 9, Blocks.end_stone, 0, 2);
		world.setBlock(i + 19, j + 4, k + 9, Blocks.end_stone, 0, 2);
		world.setBlock(i + 20, j + 4, k + 9, Blocks.end_stone, 0, 2);
		world.setBlock(i + 21, j + 4, k + 9, Blocks.end_stone, 0, 2);
		world.setBlock(i + 22, j + 4, k + 9, Blocks.end_stone, 0, 2);
		world.setBlock(i + 23, j + 4, k + 9, Blocks.end_stone, 0, 2);
		world.setBlock(i + 24, j + 4, k + 9, Blocks.end_stone, 0, 2);
		world.setBlock(i + 25, j + 4, k + 9, Blocks.end_stone, 0, 2);
		world.setBlock(i + 8, j + 4, k + 10, Blocks.end_stone, 0, 2);
		world.setBlock(i + 9, j + 4, k + 10, Blocks.end_stone, 0, 2);
		world.setBlock(i + 10, j + 4, k + 10, Blocks.end_stone, 0, 2);
		world.setBlock(i + 11, j + 4, k + 10, Blocks.end_stone, 0, 2);
		world.setBlock(i + 12, j + 4, k + 10, Blocks.end_stone, 0, 2);
		world.setBlock(i + 13, j + 4, k + 10, Blocks.end_stone, 0, 2);
		world.setBlock(i + 14, j + 4, k + 10, Blocks.end_stone, 0, 2);
		world.setBlock(i + 15, j + 4, k + 10, Blocks.end_stone, 0, 2);
		world.setBlock(i + 16, j + 4, k + 10, Blocks.end_stone, 0, 2);
		world.setBlock(i + 17, j + 4, k + 10, Blocks.end_stone, 0, 2);
		world.setBlock(i + 18, j + 4, k + 10, Blocks.end_stone, 0, 2);
		world.setBlock(i + 19, j + 4, k + 10, Blocks.end_stone, 0, 2);
		world.setBlock(i + 20, j + 4, k + 10, Blocks.end_stone, 0, 2);
		world.setBlock(i + 21, j + 4, k + 10, Blocks.end_stone, 0, 2);
		world.setBlock(i + 22, j + 4, k + 10, Blocks.end_stone, 0, 2);
		world.setBlock(i + 23, j + 4, k + 10, Blocks.end_stone, 0, 2);
		world.setBlock(i + 24, j + 4, k + 10, Blocks.end_stone, 0, 2);
		world.setBlock(i + 25, j + 4, k + 10, Blocks.end_stone, 0, 2);
		world.setBlock(i + 7, j + 4, k + 11, Blocks.end_stone, 0, 2);
		world.setBlock(i + 8, j + 4, k + 11, Blocks.end_stone, 0, 2);
		world.setBlock(i + 9, j + 4, k + 11, Blocks.end_stone, 0, 2);
		world.setBlock(i + 10, j + 4, k + 11, Blocks.end_stone, 0, 2);
		world.setBlock(i + 11, j + 4, k + 11, Blocks.end_stone, 0, 2);
		world.setBlock(i + 12, j + 4, k + 11, Blocks.end_stone, 0, 2);
		world.setBlock(i + 13, j + 4, k + 11, Blocks.end_stone, 0, 2);
		world.setBlock(i + 14, j + 4, k + 11, Blocks.end_stone, 0, 2);
		world.setBlock(i + 15, j + 4, k + 11, Blocks.end_stone, 0, 2);
		world.setBlock(i + 16, j + 4, k + 11, Blocks.end_stone, 0, 2);
		world.setBlock(i + 17, j + 4, k + 11, Blocks.end_stone, 0, 2);
		world.setBlock(i + 18, j + 4, k + 11, Blocks.end_stone, 0, 2);
		world.setBlock(i + 19, j + 4, k + 11, Blocks.end_stone, 0, 2);
		world.setBlock(i + 20, j + 4, k + 11, Blocks.end_stone, 0, 2);
		world.setBlock(i + 21, j + 4, k + 11, Blocks.end_stone, 0, 2);
		world.setBlock(i + 22, j + 4, k + 11, Blocks.end_stone, 0, 2);
		world.setBlock(i + 23, j + 4, k + 11, Blocks.end_stone, 0, 2);
		world.setBlock(i + 24, j + 4, k + 11, Blocks.end_stone, 0, 2);
		world.setBlock(i + 25, j + 4, k + 11, Blocks.end_stone, 0, 2);
		world.setBlock(i + 6, j + 4, k + 12, Blocks.end_stone, 0, 2);
		world.setBlock(i + 7, j + 4, k + 12, Blocks.end_stone, 0, 2);
		world.setBlock(i + 8, j + 4, k + 12, Blocks.end_stone, 0, 2);
		world.setBlock(i + 9, j + 4, k + 12, Blocks.end_stone, 0, 2);
		world.setBlock(i + 10, j + 4, k + 12, Blocks.end_stone, 0, 2);
		world.setBlock(i + 11, j + 4, k + 12, Blocks.end_stone, 0, 2);
		world.setBlock(i + 12, j + 4, k + 12, Blocks.end_stone, 0, 2);
		world.setBlock(i + 13, j + 4, k + 12, Blocks.end_stone, 0, 2);
		world.setBlock(i + 14, j + 4, k + 12, Blocks.end_stone, 0, 2);
		world.setBlock(i + 15, j + 4, k + 12, Blocks.end_stone, 0, 2);
		world.setBlock(i + 16, j + 4, k + 12, Blocks.end_stone, 0, 2);
		world.setBlock(i + 17, j + 4, k + 12, Blocks.end_stone, 0, 2);
		world.setBlock(i + 18, j + 4, k + 12, Blocks.end_stone, 0, 2);
		world.setBlock(i + 19, j + 4, k + 12, Blocks.end_stone, 0, 2);
		world.setBlock(i + 20, j + 4, k + 12, Blocks.end_stone, 0, 2);
		world.setBlock(i + 21, j + 4, k + 12, Blocks.end_stone, 0, 2);
		world.setBlock(i + 22, j + 4, k + 12, Blocks.end_stone, 0, 2);
		world.setBlock(i + 23, j + 4, k + 12, Blocks.end_stone, 0, 2);
		world.setBlock(i + 24, j + 4, k + 12, Blocks.end_stone, 0, 2);
		world.setBlock(i + 25, j + 4, k + 12, Blocks.end_stone, 0, 2);
		world.setBlock(i + 5, j + 4, k + 13, Blocks.end_stone, 0, 2);
		world.setBlock(i + 6, j + 4, k + 13, Blocks.end_stone, 0, 2);
		world.setBlock(i + 7, j + 4, k + 13, Blocks.end_stone, 0, 2);
		world.setBlock(i + 8, j + 4, k + 13, Blocks.end_stone, 0, 2);
		world.setBlock(i + 9, j + 4, k + 13, Blocks.end_stone, 0, 2);
		world.setBlock(i + 10, j + 4, k + 13, Blocks.end_stone, 0, 2);
		world.setBlock(i + 11, j + 4, k + 13, Blocks.end_stone, 0, 2);
		world.setBlock(i + 12, j + 4, k + 13, Blocks.end_stone, 0, 2);
		world.setBlock(i + 13, j + 4, k + 13, Blocks.end_stone, 0, 2);
		world.setBlock(i + 14, j + 4, k + 13, Blocks.end_stone, 0, 2);
		world.setBlock(i + 15, j + 4, k + 13, Blocks.end_stone, 0, 2);
		world.setBlock(i + 16, j + 4, k + 13, Blocks.end_stone, 0, 2);
		world.setBlock(i + 17, j + 4, k + 13, Blocks.end_stone, 0, 2);
		world.setBlock(i + 18, j + 4, k + 13, Blocks.end_stone, 0, 2);
		world.setBlock(i + 19, j + 4, k + 13, Blocks.end_stone, 0, 2);
		world.setBlock(i + 20, j + 4, k + 13, Blocks.end_stone, 0, 2);
		world.setBlock(i + 21, j + 4, k + 13, Blocks.end_stone, 0, 2);
		world.setBlock(i + 22, j + 4, k + 13, Blocks.end_stone, 0, 2);
		world.setBlock(i + 23, j + 4, k + 13, Blocks.end_stone, 0, 2);
		world.setBlock(i + 24, j + 4, k + 13, Blocks.end_stone, 0, 2);
		world.setBlock(i + 25, j + 4, k + 13, Blocks.end_stone, 0, 2);
		world.setBlock(i + 4, j + 4, k + 14, Blocks.end_stone, 0, 2);
		world.setBlock(i + 5, j + 4, k + 14, Blocks.end_stone, 0, 2);
		world.setBlock(i + 6, j + 4, k + 14, Blocks.end_stone, 0, 2);
		world.setBlock(i + 7, j + 4, k + 14, Blocks.end_stone, 0, 2);
		world.setBlock(i + 8, j + 4, k + 14, Blocks.end_stone, 0, 2);
		world.setBlock(i + 9, j + 4, k + 14, Blocks.end_stone, 0, 2);
		world.setBlock(i + 10, j + 4, k + 14, Blocks.end_stone, 0, 2);
		world.setBlock(i + 11, j + 4, k + 14, Blocks.end_stone, 0, 2);
		world.setBlock(i + 12, j + 4, k + 14, Blocks.end_stone, 0, 2);
		world.setBlock(i + 13, j + 4, k + 14, Blocks.end_stone, 0, 2);
		world.setBlock(i + 14, j + 4, k + 14, Blocks.end_stone, 0, 2);
		world.setBlock(i + 15, j + 4, k + 14, Blocks.end_stone, 0, 2);
		world.setBlock(i + 16, j + 4, k + 14, Blocks.end_stone, 0, 2);
		world.setBlock(i + 17, j + 4, k + 14, Blocks.end_stone, 0, 2);
		world.setBlock(i + 18, j + 4, k + 14, Blocks.end_stone, 0, 2);
		world.setBlock(i + 19, j + 4, k + 14, Blocks.end_stone, 0, 2);
		world.setBlock(i + 20, j + 4, k + 14, Blocks.end_stone, 0, 2);
		world.setBlock(i + 21, j + 4, k + 14, Blocks.end_stone, 0, 2);
		world.setBlock(i + 22, j + 4, k + 14, Blocks.end_stone, 0, 2);
		world.setBlock(i + 23, j + 4, k + 14, Blocks.end_stone, 0, 2);
		world.setBlock(i + 24, j + 4, k + 14, Blocks.end_stone, 0, 2);
		world.setBlock(i + 25, j + 4, k + 14, Blocks.end_stone, 0, 2);
		world.setBlock(i + 3, j + 4, k + 15, Blocks.end_stone, 0, 2);
		world.setBlock(i + 4, j + 4, k + 15, Blocks.end_stone, 0, 2);
		world.setBlock(i + 5, j + 4, k + 15, Blocks.end_stone, 0, 2);
		world.setBlock(i + 6, j + 4, k + 15, Blocks.end_stone, 0, 2);
		world.setBlock(i + 7, j + 4, k + 15, Blocks.end_stone, 0, 2);
		world.setBlock(i + 8, j + 4, k + 15, Blocks.end_stone, 0, 2);
		world.setBlock(i + 9, j + 4, k + 15, Blocks.end_stone, 0, 2);
		world.setBlock(i + 10, j + 4, k + 15, Blocks.end_stone, 0, 2);
		world.setBlock(i + 11, j + 4, k + 15, Blocks.end_stone, 0, 2);
		world.setBlock(i + 12, j + 4, k + 15, Blocks.end_stone, 0, 2);
		world.setBlock(i + 13, j + 4, k + 15, Blocks.end_stone, 0, 2);
		world.setBlock(i + 14, j + 4, k + 15, Blocks.end_stone, 0, 2);
		world.setBlock(i + 15, j + 4, k + 15, Blocks.end_stone, 0, 2);
		world.setBlock(i + 16, j + 4, k + 15, Blocks.end_stone, 0, 2);
		world.setBlock(i + 17, j + 4, k + 15, Blocks.end_stone, 0, 2);
		world.setBlock(i + 18, j + 4, k + 15, Blocks.end_stone, 0, 2);
		world.setBlock(i + 19, j + 4, k + 15, Blocks.end_stone, 0, 2);
		world.setBlock(i + 20, j + 4, k + 15, Blocks.end_stone, 0, 2);
		world.setBlock(i + 21, j + 4, k + 15, Blocks.end_stone, 0, 2);
		world.setBlock(i + 22, j + 4, k + 15, Blocks.end_stone, 0, 2);
		world.setBlock(i + 23, j + 4, k + 15, Blocks.end_stone, 0, 2);
		world.setBlock(i + 24, j + 4, k + 15, Blocks.end_stone, 0, 2);
		world.setBlock(i + 25, j + 4, k + 15, Blocks.end_stone, 0, 2);
		world.setBlock(i + 2, j + 4, k + 16, Blocks.end_stone, 0, 2);
		world.setBlock(i + 3, j + 4, k + 16, Blocks.end_stone, 0, 2);
		world.setBlock(i + 4, j + 4, k + 16, Blocks.end_stone, 0, 2);
		world.setBlock(i + 5, j + 4, k + 16, Blocks.end_stone, 0, 2);
		world.setBlock(i + 6, j + 4, k + 16, Blocks.end_stone, 0, 2);
		world.setBlock(i + 7, j + 4, k + 16, Blocks.end_stone, 0, 2);
		world.setBlock(i + 8, j + 4, k + 16, Blocks.end_stone, 0, 2);
		world.setBlock(i + 9, j + 4, k + 16, Blocks.end_stone, 0, 2);
		world.setBlock(i + 10, j + 4, k + 16, Blocks.end_stone, 0, 2);
		world.setBlock(i + 11, j + 4, k + 16, Blocks.end_stone, 0, 2);
		world.setBlock(i + 12, j + 4, k + 16, Blocks.end_stone, 0, 2);
		world.setBlock(i + 13, j + 4, k + 16, Blocks.end_stone, 0, 2);
		world.setBlock(i + 14, j + 4, k + 16, Blocks.end_stone, 0, 2);
		world.setBlock(i + 15, j + 4, k + 16, Blocks.end_stone, 0, 2);
		world.setBlock(i + 16, j + 4, k + 16, Blocks.end_stone, 0, 2);
		world.setBlock(i + 17, j + 4, k + 16, Blocks.end_stone, 0, 2);
		world.setBlock(i + 18, j + 4, k + 16, Blocks.end_stone, 0, 2);
		world.setBlock(i + 19, j + 4, k + 16, Blocks.end_stone, 0, 2);
		world.setBlock(i + 20, j + 4, k + 16, Blocks.end_stone, 0, 2);
		world.setBlock(i + 21, j + 4, k + 16, Blocks.end_stone, 0, 2);
		world.setBlock(i + 22, j + 4, k + 16, Blocks.end_stone, 0, 2);
		world.setBlock(i + 23, j + 4, k + 16, Blocks.end_stone, 0, 2);
		world.setBlock(i + 24, j + 4, k + 16, Blocks.end_stone, 0, 2);
		world.setBlock(i + 25, j + 4, k + 16, Blocks.end_stone, 0, 2);
		world.setBlock(i + 1, j + 4, k + 17, Blocks.end_stone, 0, 2);
		world.setBlock(i + 2, j + 4, k + 17, Blocks.end_stone, 0, 2);
		world.setBlock(i + 3, j + 4, k + 17, Blocks.end_stone, 0, 2);
		world.setBlock(i + 4, j + 4, k + 17, Blocks.end_stone, 0, 2);
		world.setBlock(i + 5, j + 4, k + 17, Blocks.end_stone, 0, 2);
		world.setBlock(i + 6, j + 4, k + 17, Blocks.end_stone, 0, 2);
		world.setBlock(i + 7, j + 4, k + 17, Blocks.end_stone, 0, 2);
		world.setBlock(i + 8, j + 4, k + 17, Blocks.end_stone, 0, 2);
		world.setBlock(i + 9, j + 4, k + 17, Blocks.end_stone, 0, 2);
		world.setBlock(i + 10, j + 4, k + 17, Blocks.end_stone, 0, 2);
		world.setBlock(i + 11, j + 4, k + 17, Blocks.end_stone, 0, 2);
		world.setBlock(i + 12, j + 4, k + 17, Blocks.end_stone, 0, 2);
		world.setBlock(i + 13, j + 4, k + 17, Blocks.end_stone, 0, 2);
		world.setBlock(i + 14, j + 4, k + 17, Blocks.end_stone, 0, 2);
		world.setBlock(i + 15, j + 4, k + 17, Blocks.end_stone, 0, 2);
		world.setBlock(i + 16, j + 4, k + 17, Blocks.end_stone, 0, 2);
		world.setBlock(i + 17, j + 4, k + 17, Blocks.end_stone, 0, 2);
		world.setBlock(i + 18, j + 4, k + 17, Blocks.end_stone, 0, 2);
		world.setBlock(i + 19, j + 4, k + 17, Blocks.end_stone, 0, 2);
		world.setBlock(i + 20, j + 4, k + 17, Blocks.end_stone, 0, 2);
		world.setBlock(i + 21, j + 4, k + 17, Blocks.end_stone, 0, 2);
		world.setBlock(i + 22, j + 4, k + 17, Blocks.end_stone, 0, 2);
		world.setBlock(i + 23, j + 4, k + 17, Blocks.end_stone, 0, 2);
		world.setBlock(i + 24, j + 4, k + 17, Blocks.end_stone, 0, 2);
		world.setBlock(i + 25, j + 4, k + 17, Blocks.end_stone, 0, 2);
		world.setBlock(i + 1, j + 4, k + 18, Blocks.end_stone, 0, 2);
		world.setBlock(i + 2, j + 4, k + 18, Blocks.end_stone, 0, 2);
		world.setBlock(i + 3, j + 4, k + 18, Blocks.end_stone, 0, 2);
		world.setBlock(i + 4, j + 4, k + 18, Blocks.end_stone, 0, 2);
		world.setBlock(i + 5, j + 4, k + 18, Blocks.end_stone, 0, 2);
		world.setBlock(i + 6, j + 4, k + 18, Blocks.end_stone, 0, 2);
		world.setBlock(i + 7, j + 4, k + 18, Blocks.end_stone, 0, 2);
		world.setBlock(i + 8, j + 4, k + 18, Blocks.end_stone, 0, 2);
		world.setBlock(i + 9, j + 4, k + 18, Blocks.end_stone, 0, 2);
		world.setBlock(i + 10, j + 4, k + 18, Blocks.end_stone, 0, 2);
		world.setBlock(i + 11, j + 4, k + 18, Blocks.end_stone, 0, 2);
		world.setBlock(i + 12, j + 4, k + 18, Blocks.end_stone, 0, 2);
		world.setBlock(i + 13, j + 4, k + 18, Blocks.end_stone, 0, 2);
		world.setBlock(i + 14, j + 4, k + 18, Blocks.end_stone, 0, 2);
		world.setBlock(i + 15, j + 4, k + 18, Blocks.end_stone, 0, 2);
		world.setBlock(i + 16, j + 4, k + 18, Blocks.end_stone, 0, 2);
		world.setBlock(i + 17, j + 4, k + 18, Blocks.end_stone, 0, 2);
		world.setBlock(i + 18, j + 4, k + 18, Blocks.end_stone, 0, 2);
		world.setBlock(i + 19, j + 4, k + 18, Blocks.end_stone, 0, 2);
		world.setBlock(i + 20, j + 4, k + 18, Blocks.end_stone, 0, 2);
		world.setBlock(i + 21, j + 4, k + 18, Blocks.end_stone, 0, 2);
		world.setBlock(i + 22, j + 4, k + 18, Blocks.end_stone, 0, 2);
		world.setBlock(i + 23, j + 4, k + 18, Blocks.end_stone, 0, 2);
		world.setBlock(i + 24, j + 4, k + 18, Blocks.end_stone, 0, 2);
		world.setBlock(i + 25, j + 4, k + 18, Blocks.end_stone, 0, 2);
		world.setBlock(i + 1, j + 4, k + 19, Blocks.end_stone, 0, 2);
		world.setBlock(i + 2, j + 4, k + 19, Blocks.end_stone, 0, 2);
		world.setBlock(i + 3, j + 4, k + 19, Blocks.end_stone, 0, 2);
		world.setBlock(i + 4, j + 4, k + 19, Blocks.end_stone, 0, 2);
		world.setBlock(i + 5, j + 4, k + 19, Blocks.end_stone, 0, 2);
		world.setBlock(i + 6, j + 4, k + 19, Blocks.end_stone, 0, 2);
		world.setBlock(i + 7, j + 4, k + 19, Blocks.end_stone, 0, 2);
		world.setBlock(i + 8, j + 4, k + 19, Blocks.end_stone, 0, 2);
		world.setBlock(i + 9, j + 4, k + 19, Blocks.end_stone, 0, 2);
		world.setBlock(i + 10, j + 4, k + 19, Blocks.end_stone, 0, 2);
		world.setBlock(i + 11, j + 4, k + 19, Blocks.end_stone, 0, 2);
		world.setBlock(i + 12, j + 4, k + 19, Blocks.end_stone, 0, 2);
		world.setBlock(i + 13, j + 4, k + 19, Blocks.end_stone, 0, 2);
		world.setBlock(i + 14, j + 4, k + 19, Blocks.end_stone, 0, 2);
		world.setBlock(i + 15, j + 4, k + 19, Blocks.end_stone, 0, 2);
		world.setBlock(i + 16, j + 4, k + 19, Blocks.end_stone, 0, 2);
		world.setBlock(i + 17, j + 4, k + 19, Blocks.end_stone, 0, 2);
		world.setBlock(i + 18, j + 4, k + 19, Blocks.end_stone, 0, 2);
		world.setBlock(i + 19, j + 4, k + 19, Blocks.end_stone, 0, 2);
		world.setBlock(i + 20, j + 4, k + 19, Blocks.end_stone, 0, 2);
		world.setBlock(i + 21, j + 4, k + 19, Blocks.end_stone, 0, 2);
		world.setBlock(i + 22, j + 4, k + 19, Blocks.end_stone, 0, 2);
		world.setBlock(i + 23, j + 4, k + 19, Blocks.end_stone, 0, 2);
		world.setBlock(i + 24, j + 4, k + 19, Blocks.end_stone, 0, 2);
		world.setBlock(i + 25, j + 4, k + 19, Blocks.end_stone, 0, 2);
		world.setBlock(i + 1, j + 4, k + 20, Blocks.end_stone, 0, 2);
		world.setBlock(i + 2, j + 4, k + 20, Blocks.end_stone, 0, 2);
		world.setBlock(i + 3, j + 4, k + 20, Blocks.end_stone, 0, 2);
		world.setBlock(i + 4, j + 4, k + 20, Blocks.end_stone, 0, 2);
		world.setBlock(i + 5, j + 4, k + 20, Blocks.end_stone, 0, 2);
		world.setBlock(i + 6, j + 4, k + 20, Blocks.end_stone, 0, 2);
		world.setBlock(i + 7, j + 4, k + 20, Blocks.end_stone, 0, 2);
		world.setBlock(i + 8, j + 4, k + 20, Blocks.end_stone, 0, 2);
		world.setBlock(i + 9, j + 4, k + 20, Blocks.end_stone, 0, 2);
		world.setBlock(i + 10, j + 4, k + 20, Blocks.end_stone, 0, 2);
		world.setBlock(i + 11, j + 4, k + 20, Blocks.end_stone, 0, 2);
		world.setBlock(i + 12, j + 4, k + 20, Blocks.end_stone, 0, 2);
		world.setBlock(i + 13, j + 4, k + 20, Blocks.end_stone, 0, 2);
		world.setBlock(i + 14, j + 4, k + 20, Blocks.end_stone, 0, 2);
		world.setBlock(i + 15, j + 4, k + 20, Blocks.end_stone, 0, 2);
		world.setBlock(i + 16, j + 4, k + 20, Blocks.end_stone, 0, 2);
		world.setBlock(i + 17, j + 4, k + 20, Blocks.end_stone, 0, 2);
		world.setBlock(i + 18, j + 4, k + 20, Blocks.end_stone, 0, 2);
		world.setBlock(i + 19, j + 4, k + 20, Blocks.end_stone, 0, 2);
		world.setBlock(i + 20, j + 4, k + 20, Blocks.end_stone, 0, 2);
		world.setBlock(i + 21, j + 4, k + 20, Blocks.end_stone, 0, 2);
		world.setBlock(i + 22, j + 4, k + 20, Blocks.end_stone, 0, 2);
		world.setBlock(i + 23, j + 4, k + 20, Blocks.end_stone, 0, 2);
		world.setBlock(i + 24, j + 4, k + 20, Blocks.end_stone, 0, 2);
		world.setBlock(i + 25, j + 4, k + 20, Blocks.end_stone, 0, 2);
		world.setBlock(i + 2, j + 4, k + 21, Blocks.end_stone, 0, 2);
		world.setBlock(i + 3, j + 4, k + 21, Blocks.end_stone, 0, 2);
		world.setBlock(i + 4, j + 4, k + 21, Blocks.end_stone, 0, 2);
		world.setBlock(i + 5, j + 4, k + 21, Blocks.end_stone, 0, 2);
		world.setBlock(i + 6, j + 4, k + 21, Blocks.end_stone, 0, 2);
		world.setBlock(i + 7, j + 4, k + 21, Blocks.end_stone, 0, 2);
		world.setBlock(i + 8, j + 4, k + 21, Blocks.end_stone, 0, 2);
		world.setBlock(i + 9, j + 4, k + 21, Blocks.end_stone, 0, 2);
		world.setBlock(i + 10, j + 4, k + 21, Blocks.end_stone, 0, 2);
		world.setBlock(i + 11, j + 4, k + 21, Blocks.end_stone, 0, 2);
		world.setBlock(i + 12, j + 4, k + 21, Blocks.end_stone, 0, 2);
		world.setBlock(i + 13, j + 4, k + 21, Blocks.end_stone, 0, 2);
		world.setBlock(i + 14, j + 4, k + 21, Blocks.end_stone, 0, 2);
		world.setBlock(i + 15, j + 4, k + 21, Blocks.end_stone, 0, 2);
		world.setBlock(i + 16, j + 4, k + 21, Blocks.end_stone, 0, 2);
		world.setBlock(i + 17, j + 4, k + 21, Blocks.end_stone, 0, 2);
		world.setBlock(i + 18, j + 4, k + 21, Blocks.end_stone, 0, 2);
		world.setBlock(i + 19, j + 4, k + 21, Blocks.end_stone, 0, 2);
		world.setBlock(i + 20, j + 4, k + 21, Blocks.end_stone, 0, 2);
		world.setBlock(i + 21, j + 4, k + 21, Blocks.end_stone, 0, 2);
		world.setBlock(i + 22, j + 4, k + 21, Blocks.end_stone, 0, 2);
		world.setBlock(i + 23, j + 4, k + 21, Blocks.end_stone, 0, 2);
		world.setBlock(i + 24, j + 4, k + 21, Blocks.end_stone, 0, 2);
		world.setBlock(i + 25, j + 4, k + 21, Blocks.end_stone, 0, 2);
		world.setBlock(i + 3, j + 4, k + 22, Blocks.end_stone, 0, 2);
		world.setBlock(i + 4, j + 4, k + 22, Blocks.end_stone, 0, 2);
		world.setBlock(i + 5, j + 4, k + 22, Blocks.end_stone, 0, 2);
		world.setBlock(i + 6, j + 4, k + 22, Blocks.end_stone, 0, 2);
		world.setBlock(i + 7, j + 4, k + 22, Blocks.end_stone, 0, 2);
		world.setBlock(i + 8, j + 4, k + 22, Blocks.end_stone, 0, 2);
		world.setBlock(i + 9, j + 4, k + 22, Blocks.end_stone, 0, 2);
		world.setBlock(i + 10, j + 4, k + 22, Blocks.end_stone, 0, 2);
		world.setBlock(i + 11, j + 4, k + 22, Blocks.end_stone, 0, 2);
		world.setBlock(i + 12, j + 4, k + 22, Blocks.end_stone, 0, 2);
		world.setBlock(i + 13, j + 4, k + 22, Blocks.end_stone, 0, 2);
		world.setBlock(i + 14, j + 4, k + 22, Blocks.end_stone, 0, 2);
		world.setBlock(i + 15, j + 4, k + 22, Blocks.end_stone, 0, 2);
		world.setBlock(i + 16, j + 4, k + 22, Blocks.end_stone, 0, 2);
		world.setBlock(i + 17, j + 4, k + 22, Blocks.end_stone, 0, 2);
		world.setBlock(i + 18, j + 4, k + 22, Blocks.end_stone, 0, 2);
		world.setBlock(i + 19, j + 4, k + 22, Blocks.end_stone, 0, 2);
		world.setBlock(i + 20, j + 4, k + 22, Blocks.end_stone, 0, 2);
		world.setBlock(i + 21, j + 4, k + 22, Blocks.end_stone, 0, 2);
		world.setBlock(i + 22, j + 4, k + 22, Blocks.end_stone, 0, 2);
		world.setBlock(i + 23, j + 4, k + 22, Blocks.end_stone, 0, 2);
		world.setBlock(i + 24, j + 4, k + 22, Blocks.end_stone, 0, 2);
		world.setBlock(i + 25, j + 4, k + 22, Blocks.end_stone, 0, 2);
		world.setBlock(i + 4, j + 4, k + 23, Blocks.end_stone, 0, 2);
		world.setBlock(i + 5, j + 4, k + 23, Blocks.end_stone, 0, 2);
		world.setBlock(i + 6, j + 4, k + 23, Blocks.end_stone, 0, 2);
		world.setBlock(i + 7, j + 4, k + 23, Blocks.end_stone, 0, 2);
		world.setBlock(i + 8, j + 4, k + 23, Blocks.end_stone, 0, 2);
		world.setBlock(i + 9, j + 4, k + 23, Blocks.end_stone, 0, 2);
		world.setBlock(i + 10, j + 4, k + 23, Blocks.end_stone, 0, 2);
		world.setBlock(i + 11, j + 4, k + 23, Blocks.end_stone, 0, 2);
		world.setBlock(i + 12, j + 4, k + 23, Blocks.end_stone, 0, 2);
		world.setBlock(i + 13, j + 4, k + 23, Blocks.end_stone, 0, 2);
		world.setBlock(i + 14, j + 4, k + 23, Blocks.end_stone, 0, 2);
		world.setBlock(i + 15, j + 4, k + 23, Blocks.end_stone, 0, 2);
		world.setBlock(i + 16, j + 4, k + 23, Blocks.end_stone, 0, 2);
		world.setBlock(i + 17, j + 4, k + 23, Blocks.end_stone, 0, 2);
		world.setBlock(i + 18, j + 4, k + 23, Blocks.end_stone, 0, 2);
		world.setBlock(i + 19, j + 4, k + 23, Blocks.end_stone, 0, 2);
		world.setBlock(i + 20, j + 4, k + 23, Blocks.end_stone, 0, 2);
		world.setBlock(i + 21, j + 4, k + 23, Blocks.end_stone, 0, 2);
		world.setBlock(i + 22, j + 4, k + 23, Blocks.end_stone, 0, 2);
		world.setBlock(i + 23, j + 4, k + 23, Blocks.end_stone, 0, 2);
		world.setBlock(i + 24, j + 4, k + 23, Blocks.end_stone, 0, 2);
		world.setBlock(i + 25, j + 4, k + 23, Blocks.end_stone, 0, 2);
		world.setBlock(i + 5, j + 4, k + 24, Blocks.end_stone, 0, 2);
		world.setBlock(i + 6, j + 4, k + 24, Blocks.end_stone, 0, 2);
		world.setBlock(i + 7, j + 4, k + 24, Blocks.end_stone, 0, 2);
		world.setBlock(i + 8, j + 4, k + 24, Blocks.end_stone, 0, 2);
		world.setBlock(i + 9, j + 4, k + 24, Blocks.end_stone, 0, 2);
		world.setBlock(i + 10, j + 4, k + 24, Blocks.end_stone, 0, 2);
		world.setBlock(i + 11, j + 4, k + 24, Blocks.end_stone, 0, 2);
		world.setBlock(i + 12, j + 4, k + 24, Blocks.end_stone, 0, 2);
		world.setBlock(i + 13, j + 4, k + 24, Blocks.end_stone, 0, 2);
		world.setBlock(i + 14, j + 4, k + 24, Blocks.end_stone, 0, 2);
		world.setBlock(i + 15, j + 4, k + 24, Blocks.end_stone, 0, 2);
		world.setBlock(i + 16, j + 4, k + 24, Blocks.end_stone, 0, 2);
		world.setBlock(i + 17, j + 4, k + 24, Blocks.end_stone, 0, 2);
		world.setBlock(i + 18, j + 4, k + 24, Blocks.end_stone, 0, 2);
		world.setBlock(i + 19, j + 4, k + 24, Blocks.end_stone, 0, 2);
		world.setBlock(i + 20, j + 4, k + 24, Blocks.end_stone, 0, 2);
		world.setBlock(i + 21, j + 4, k + 24, Blocks.end_stone, 0, 2);
		world.setBlock(i + 22, j + 4, k + 24, Blocks.end_stone, 0, 2);
		world.setBlock(i + 23, j + 4, k + 24, Blocks.end_stone, 0, 2);
		world.setBlock(i + 24, j + 4, k + 24, Blocks.end_stone, 0, 2);
		world.setBlock(i + 25, j + 4, k + 24, Blocks.end_stone, 0, 2);
		world.setBlock(i + 6, j + 4, k + 25, Blocks.end_stone, 0, 2);
		world.setBlock(i + 7, j + 4, k + 25, Blocks.end_stone, 0, 2);
		world.setBlock(i + 8, j + 4, k + 25, Blocks.end_stone, 0, 2);
		world.setBlock(i + 9, j + 4, k + 25, Blocks.end_stone, 0, 2);
		world.setBlock(i + 10, j + 4, k + 25, Blocks.end_stone, 0, 2);
		world.setBlock(i + 11, j + 4, k + 25, Blocks.end_stone, 0, 2);
		world.setBlock(i + 12, j + 4, k + 25, Blocks.end_stone, 0, 2);
		world.setBlock(i + 13, j + 4, k + 25, Blocks.end_stone, 0, 2);
		world.setBlock(i + 14, j + 4, k + 25, Blocks.end_stone, 0, 2);
		world.setBlock(i + 15, j + 4, k + 25, Blocks.end_stone, 0, 2);
		world.setBlock(i + 16, j + 4, k + 25, Blocks.end_stone, 0, 2);
		world.setBlock(i + 17, j + 4, k + 25, Blocks.end_stone, 0, 2);
		world.setBlock(i + 18, j + 4, k + 25, Blocks.end_stone, 0, 2);
		world.setBlock(i + 19, j + 4, k + 25, Blocks.end_stone, 0, 2);
		world.setBlock(i + 20, j + 4, k + 25, Blocks.end_stone, 0, 2);
		world.setBlock(i + 21, j + 4, k + 25, Blocks.end_stone, 0, 2);
		world.setBlock(i + 22, j + 4, k + 25, Blocks.end_stone, 0, 2);
		world.setBlock(i + 23, j + 4, k + 25, Blocks.end_stone, 0, 2);
		world.setBlock(i + 24, j + 4, k + 25, Blocks.end_stone, 0, 2);
		world.setBlock(i + 25, j + 4, k + 25, Blocks.end_stone, 0, 2);
		world.setBlock(i + 7, j + 4, k + 26, Blocks.end_stone, 0, 2);
		world.setBlock(i + 8, j + 4, k + 26, Blocks.end_stone, 0, 2);
		world.setBlock(i + 9, j + 4, k + 26, Blocks.end_stone, 0, 2);
		world.setBlock(i + 10, j + 4, k + 26, Blocks.end_stone, 0, 2);
		world.setBlock(i + 11, j + 4, k + 26, Blocks.end_stone, 0, 2);
		world.setBlock(i + 12, j + 4, k + 26, Blocks.end_stone, 0, 2);
		world.setBlock(i + 13, j + 4, k + 26, Blocks.end_stone, 0, 2);
		world.setBlock(i + 14, j + 4, k + 26, Blocks.end_stone, 0, 2);
		world.setBlock(i + 15, j + 4, k + 26, Blocks.end_stone, 0, 2);
		world.setBlock(i + 16, j + 4, k + 26, Blocks.end_stone, 0, 2);
		world.setBlock(i + 17, j + 4, k + 26, Blocks.end_stone, 0, 2);
		world.setBlock(i + 18, j + 4, k + 26, Blocks.end_stone, 0, 2);
		world.setBlock(i + 19, j + 4, k + 26, Blocks.end_stone, 0, 2);
		world.setBlock(i + 20, j + 4, k + 26, Blocks.end_stone, 0, 2);
		world.setBlock(i + 21, j + 4, k + 26, Blocks.end_stone, 0, 2);
		world.setBlock(i + 22, j + 4, k + 26, Blocks.end_stone, 0, 2);
		world.setBlock(i + 23, j + 4, k + 26, Blocks.end_stone, 0, 2);
		world.setBlock(i + 24, j + 4, k + 26, Blocks.end_stone, 0, 2);
		world.setBlock(i + 25, j + 4, k + 26, Blocks.end_stone, 0, 2);
		world.setBlock(i + 8, j + 4, k + 27, Blocks.end_stone, 0, 2);
		world.setBlock(i + 9, j + 4, k + 27, Blocks.end_stone, 0, 2);
		world.setBlock(i + 10, j + 4, k + 27, Blocks.end_stone, 0, 2);
		world.setBlock(i + 11, j + 4, k + 27, Blocks.end_stone, 0, 2);
		world.setBlock(i + 12, j + 4, k + 27, Blocks.end_stone, 0, 2);
		world.setBlock(i + 13, j + 4, k + 27, Blocks.end_stone, 0, 2);
		world.setBlock(i + 14, j + 4, k + 27, Blocks.end_stone, 0, 2);
		world.setBlock(i + 15, j + 4, k + 27, Blocks.end_stone, 0, 2);
		world.setBlock(i + 16, j + 4, k + 27, Blocks.end_stone, 0, 2);
		world.setBlock(i + 17, j + 4, k + 27, Blocks.end_stone, 0, 2);
		world.setBlock(i + 18, j + 4, k + 27, Blocks.end_stone, 0, 2);
		world.setBlock(i + 19, j + 4, k + 27, Blocks.end_stone, 0, 2);
		world.setBlock(i + 20, j + 4, k + 27, Blocks.end_stone, 0, 2);
		world.setBlock(i + 21, j + 4, k + 27, Blocks.end_stone, 0, 2);
		world.setBlock(i + 22, j + 4, k + 27, Blocks.end_stone, 0, 2);
		world.setBlock(i + 23, j + 4, k + 27, Blocks.end_stone, 0, 2);
		world.setBlock(i + 24, j + 4, k + 27, Blocks.end_stone, 0, 2);
		world.setBlock(i + 25, j + 4, k + 27, Blocks.end_stone, 0, 2);
		world.setBlock(i + 9, j + 4, k + 28, Blocks.end_stone, 0, 2);
		world.setBlock(i + 10, j + 4, k + 28, Blocks.end_stone, 0, 2);
		world.setBlock(i + 11, j + 4, k + 28, Blocks.end_stone, 0, 2);
		world.setBlock(i + 12, j + 4, k + 28, Blocks.end_stone, 0, 2);
		world.setBlock(i + 13, j + 4, k + 28, Blocks.end_stone, 0, 2);
		world.setBlock(i + 14, j + 4, k + 28, Blocks.end_stone, 0, 2);
		world.setBlock(i + 15, j + 4, k + 28, Blocks.end_stone, 0, 2);
		world.setBlock(i + 16, j + 4, k + 28, Blocks.end_stone, 0, 2);
		world.setBlock(i + 17, j + 4, k + 28, Blocks.end_stone, 0, 2);
		world.setBlock(i + 18, j + 4, k + 28, Blocks.end_stone, 0, 2);
		world.setBlock(i + 19, j + 4, k + 28, Blocks.end_stone, 0, 2);
		world.setBlock(i + 20, j + 4, k + 28, Blocks.end_stone, 0, 2);
		world.setBlock(i + 21, j + 4, k + 28, Blocks.end_stone, 0, 2);
		world.setBlock(i + 22, j + 4, k + 28, Blocks.end_stone, 0, 2);
		world.setBlock(i + 23, j + 4, k + 28, Blocks.end_stone, 0, 2);
		world.setBlock(i + 24, j + 4, k + 28, Blocks.end_stone, 0, 2);
		world.setBlock(i + 25, j + 4, k + 28, Blocks.end_stone, 0, 2);
		world.setBlock(i + 10, j + 4, k + 29, Blocks.end_stone, 0, 2);
		world.setBlock(i + 11, j + 4, k + 29, Blocks.end_stone, 0, 2);
		world.setBlock(i + 12, j + 4, k + 29, Blocks.end_stone, 0, 2);
		world.setBlock(i + 13, j + 4, k + 29, Blocks.end_stone, 0, 2);
		world.setBlock(i + 14, j + 4, k + 29, Blocks.end_stone, 0, 2);
		world.setBlock(i + 15, j + 4, k + 29, Blocks.end_stone, 0, 2);
		world.setBlock(i + 16, j + 4, k + 29, Blocks.end_stone, 0, 2);
		world.setBlock(i + 17, j + 4, k + 29, Blocks.end_stone, 0, 2);
		world.setBlock(i + 18, j + 4, k + 29, Blocks.end_stone, 0, 2);
		world.setBlock(i + 19, j + 4, k + 29, Blocks.end_stone, 0, 2);
		world.setBlock(i + 20, j + 4, k + 29, Blocks.end_stone, 0, 2);
		world.setBlock(i + 21, j + 4, k + 29, Blocks.end_stone, 0, 2);
		world.setBlock(i + 22, j + 4, k + 29, Blocks.end_stone, 0, 2);
		world.setBlock(i + 23, j + 4, k + 29, Blocks.end_stone, 0, 2);
		world.setBlock(i + 24, j + 4, k + 29, Blocks.end_stone, 0, 2);
		world.setBlock(i + 11, j + 4, k + 30, Blocks.end_stone, 0, 2);
		world.setBlock(i + 12, j + 4, k + 30, Blocks.end_stone, 0, 2);
		world.setBlock(i + 13, j + 4, k + 30, Blocks.end_stone, 0, 2);
		world.setBlock(i + 14, j + 4, k + 30, Blocks.end_stone, 0, 2);
		world.setBlock(i + 15, j + 4, k + 30, Blocks.end_stone, 0, 2);
		world.setBlock(i + 16, j + 4, k + 30, Blocks.end_stone, 0, 2);
		world.setBlock(i + 17, j + 4, k + 30, Blocks.end_stone, 0, 2);
		world.setBlock(i + 18, j + 4, k + 30, Blocks.end_stone, 0, 2);
		world.setBlock(i + 19, j + 4, k + 30, Blocks.end_stone, 0, 2);
		world.setBlock(i + 20, j + 4, k + 30, Blocks.end_stone, 0, 2);
		world.setBlock(i + 21, j + 4, k + 30, Blocks.end_stone, 0, 2);
		world.setBlock(i + 22, j + 4, k + 30, Blocks.end_stone, 0, 2);
		world.setBlock(i + 23, j + 4, k + 30, Blocks.end_stone, 0, 2);
		world.setBlock(i + 11, j + 4, k + 31, Blocks.end_stone, 0, 2);
		world.setBlock(i + 12, j + 4, k + 31, Blocks.end_stone, 0, 2);
		world.setBlock(i + 13, j + 4, k + 31, Blocks.end_stone, 0, 2);
		world.setBlock(i + 14, j + 4, k + 31, Blocks.end_stone, 0, 2);
		world.setBlock(i + 15, j + 4, k + 31, Blocks.end_stone, 0, 2);
		world.setBlock(i + 16, j + 4, k + 31, Blocks.end_stone, 0, 2);
		world.setBlock(i + 17, j + 4, k + 31, Blocks.end_stone, 0, 2);
		world.setBlock(i + 18, j + 4, k + 31, Blocks.end_stone, 0, 2);
		world.setBlock(i + 19, j + 4, k + 31, Blocks.end_stone, 0, 2);
		world.setBlock(i + 20, j + 4, k + 31, Blocks.end_stone, 0, 2);
		world.setBlock(i + 21, j + 4, k + 31, Blocks.end_stone, 0, 2);
		world.setBlock(i + 22, j + 4, k + 31, Blocks.end_stone, 0, 2);
		world.setBlock(i + 11, j + 4, k + 32, Blocks.end_stone, 0, 2);
		world.setBlock(i + 12, j + 4, k + 32, Blocks.end_stone, 0, 2);
		world.setBlock(i + 13, j + 4, k + 32, Blocks.end_stone, 0, 2);
		world.setBlock(i + 14, j + 4, k + 32, Blocks.end_stone, 0, 2);
		world.setBlock(i + 15, j + 4, k + 32, Blocks.end_stone, 0, 2);
		world.setBlock(i + 16, j + 4, k + 32, Blocks.end_stone, 0, 2);
		world.setBlock(i + 17, j + 4, k + 32, Blocks.end_stone, 0, 2);
		world.setBlock(i + 18, j + 4, k + 32, Blocks.end_stone, 0, 2);
		world.setBlock(i + 19, j + 4, k + 32, Blocks.end_stone, 0, 2);
		world.setBlock(i + 20, j + 4, k + 32, Blocks.end_stone, 0, 2);
		world.setBlock(i + 21, j + 4, k + 32, Blocks.end_stone, 0, 2);
		world.setBlock(i + 11, j + 4, k + 33, Blocks.end_stone, 0, 2);
		world.setBlock(i + 12, j + 4, k + 33, Blocks.end_stone, 0, 2);
		world.setBlock(i + 13, j + 4, k + 33, Blocks.end_stone, 0, 2);
		world.setBlock(i + 14, j + 4, k + 33, Blocks.end_stone, 0, 2);
		world.setBlock(i + 15, j + 4, k + 33, Blocks.end_stone, 0, 2);
		world.setBlock(i + 16, j + 4, k + 33, Blocks.end_stone, 0, 2);
		world.setBlock(i + 17, j + 4, k + 33, Blocks.end_stone, 0, 2);
		world.setBlock(i + 18, j + 4, k + 33, Blocks.end_stone, 0, 2);
		world.setBlock(i + 19, j + 4, k + 33, Blocks.end_stone, 0, 2);
		world.setBlock(i + 20, j + 4, k + 33, Blocks.end_stone, 0, 2);
		world.setBlock(i + 11, j + 5, k + 0, OtherModBlocks.end_bricks, 0, 2);
		world.setBlock(i + 12, j + 5, k + 0, OtherModBlocks.end_bricks, 0, 2);
		world.setBlock(i + 13, j + 5, k + 0, OtherModBlocks.end_bricks, 0, 2);
		world.setBlock(i + 14, j + 5, k + 0, OtherModBlocks.end_bricks, 0, 2);
		world.setBlock(i + 15, j + 5, k + 0, OtherModBlocks.end_bricks, 0, 2);
		world.setBlock(i + 16, j + 5, k + 0, OtherModBlocks.end_bricks, 0, 2);
		world.setBlock(i + 17, j + 5, k + 0, OtherModBlocks.end_bricks, 0, 2);
		world.setBlock(i + 18, j + 5, k + 0, OtherModBlocks.end_bricks, 0, 2);
		world.setBlock(i + 19, j + 5, k + 0, OtherModBlocks.end_bricks, 0, 2);
		world.setBlock(i + 20, j + 5, k + 0, OtherModBlocks.end_bricks, 0, 2);
		world.setBlock(i + 21, j + 5, k + 0, OtherModBlocks.end_bricks, 0, 2);
		world.setBlock(i + 10, j + 5, k + 1, OtherModBlocks.end_bricks, 0, 2);
		world.setBlock(i + 11, j + 5, k + 1, Blocks.end_stone, 0, 2);
		world.setBlock(i + 12, j + 5, k + 1, Blocks.end_stone, 0, 2);
		world.setBlock(i + 13, j + 5, k + 1, Blocks.end_stone, 0, 2);
		world.setBlock(i + 14, j + 5, k + 1, Blocks.end_stone, 0, 2);
		world.setBlock(i + 15, j + 5, k + 1, Blocks.end_stone, 0, 2);
		world.setBlock(i + 16, j + 5, k + 1, Blocks.end_stone, 0, 2);
		world.setBlock(i + 17, j + 5, k + 1, Blocks.end_stone, 0, 2);
		world.setBlock(i + 18, j + 5, k + 1, Blocks.end_stone, 0, 2);
		world.setBlock(i + 19, j + 5, k + 1, Blocks.end_stone, 0, 2);
		world.setBlock(i + 20, j + 5, k + 1, Blocks.end_stone, 0, 2);
		world.setBlock(i + 21, j + 5, k + 1, Blocks.end_stone, 0, 2);
		world.setBlock(i + 22, j + 5, k + 1, OtherModBlocks.end_bricks, 0, 2);
		world.setBlock(i + 10, j + 5, k + 2, OtherModBlocks.end_bricks, 0, 2);
		world.setBlock(i + 11, j + 5, k + 2, Blocks.end_stone, 0, 2);
		world.setBlock(i + 12, j + 5, k + 2, Blocks.end_stone, 0, 2);
		world.setBlock(i + 13, j + 5, k + 2, Blocks.end_stone, 0, 2);
		world.setBlock(i + 14, j + 5, k + 2, Blocks.end_stone, 0, 2);
		world.setBlock(i + 15, j + 5, k + 2, Blocks.end_stone, 0, 2);
		world.setBlock(i + 16, j + 5, k + 2, Blocks.end_stone, 0, 2);
		world.setBlock(i + 17, j + 5, k + 2, Blocks.end_stone, 0, 2);
		world.setBlock(i + 18, j + 5, k + 2, Blocks.end_stone, 0, 2);
		world.setBlock(i + 19, j + 5, k + 2, Blocks.end_stone, 0, 2);
		world.setBlock(i + 20, j + 5, k + 2, Blocks.end_stone, 0, 2);
		world.setBlock(i + 21, j + 5, k + 2, Blocks.end_stone, 0, 2);
		world.setBlock(i + 22, j + 5, k + 2, OtherModBlocks.end_bricks, 0, 2);
		world.setBlock(i + 10, j + 5, k + 3, OtherModBlocks.end_bricks, 0, 2);
		world.setBlock(i + 11, j + 5, k + 3, Blocks.end_stone, 0, 2);
		world.setBlock(i + 12, j + 5, k + 3, Blocks.end_stone, 0, 2);
		world.setBlock(i + 13, j + 5, k + 3, Blocks.end_stone, 0, 2);
		world.setBlock(i + 14, j + 5, k + 3, Blocks.end_stone, 0, 2);
		world.setBlock(i + 15, j + 5, k + 3, Blocks.end_stone, 0, 2);
		world.setBlock(i + 16, j + 5, k + 3, Blocks.end_stone, 0, 2);
		world.setBlock(i + 17, j + 5, k + 3, Blocks.end_stone, 0, 2);
		world.setBlock(i + 18, j + 5, k + 3, Blocks.end_stone, 0, 2);
		world.setBlock(i + 19, j + 5, k + 3, Blocks.end_stone, 0, 2);
		world.setBlock(i + 20, j + 5, k + 3, Blocks.end_stone, 0, 2);
		world.setBlock(i + 21, j + 5, k + 3, Blocks.end_stone, 0, 2);
		world.setBlock(i + 22, j + 5, k + 3, OtherModBlocks.end_bricks, 0, 2);
		world.setBlock(i + 10, j + 5, k + 4, OtherModBlocks.end_bricks, 0, 2);
		world.setBlock(i + 11, j + 5, k + 4, Blocks.end_stone, 0, 2);
		world.setBlock(i + 12, j + 5, k + 4, Blocks.end_stone, 0, 2);
		world.setBlock(i + 13, j + 5, k + 4, Blocks.end_stone, 0, 2);
		world.setBlock(i + 14, j + 5, k + 4, Blocks.end_stone, 0, 2);
		world.setBlock(i + 15, j + 5, k + 4, Blocks.end_stone, 0, 2);
		world.setBlock(i + 16, j + 5, k + 4, Blocks.end_stone, 0, 2);
		world.setBlock(i + 17, j + 5, k + 4, Blocks.end_stone, 0, 2);
		world.setBlock(i + 18, j + 5, k + 4, Blocks.end_stone, 0, 2);
		world.setBlock(i + 19, j + 5, k + 4, Blocks.end_stone, 0, 2);
		world.setBlock(i + 20, j + 5, k + 4, Blocks.end_stone, 0, 2);
		world.setBlock(i + 21, j + 5, k + 4, Blocks.end_stone, 0, 2);
		world.setBlock(i + 22, j + 5, k + 4, OtherModBlocks.end_bricks, 0, 2);
		world.setBlock(i + 10, j + 5, k + 5, OtherModBlocks.end_bricks, 0, 2);
		world.setBlock(i + 11, j + 5, k + 5, Blocks.end_stone, 0, 2);
		world.setBlock(i + 12, j + 5, k + 5, Blocks.end_stone, 0, 2);
		world.setBlock(i + 13, j + 5, k + 5, Blocks.end_stone, 0, 2);
		world.setBlock(i + 14, j + 5, k + 5, Blocks.end_stone, 0, 2);
		world.setBlock(i + 15, j + 5, k + 5, Blocks.end_stone, 0, 2);
		world.setBlock(i + 16, j + 5, k + 5, Blocks.end_stone, 0, 2);
		world.setBlock(i + 17, j + 5, k + 5, Blocks.end_stone, 0, 2);
		world.setBlock(i + 18, j + 5, k + 5, Blocks.end_stone, 0, 2);
		world.setBlock(i + 19, j + 5, k + 5, Blocks.end_stone, 0, 2);
		world.setBlock(i + 20, j + 5, k + 5, Blocks.end_stone, 0, 2);
		world.setBlock(i + 21, j + 5, k + 5, Blocks.end_stone, 0, 2);
		world.setBlock(i + 22, j + 5, k + 5, OtherModBlocks.end_bricks, 0, 2);
		world.setBlock(i + 10, j + 5, k + 6, OtherModBlocks.end_bricks, 0, 2);
		world.setBlock(i + 11, j + 5, k + 6, Blocks.end_stone, 0, 2);
		world.setBlock(i + 12, j + 5, k + 6, Blocks.end_stone, 0, 2);
		world.setBlock(i + 13, j + 5, k + 6, Blocks.end_stone, 0, 2);
		world.setBlock(i + 14, j + 5, k + 6, Blocks.end_stone, 0, 2);
		world.setBlock(i + 15, j + 5, k + 6, Blocks.end_stone, 0, 2);
		world.setBlock(i + 16, j + 5, k + 6, Blocks.end_stone, 0, 2);
		world.setBlock(i + 17, j + 5, k + 6, Blocks.end_stone, 0, 2);
		world.setBlock(i + 18, j + 5, k + 6, Blocks.end_stone, 0, 2);
		world.setBlock(i + 19, j + 5, k + 6, Blocks.end_stone, 0, 2);
		world.setBlock(i + 20, j + 5, k + 6, Blocks.end_stone, 0, 2);
		world.setBlock(i + 21, j + 5, k + 6, Blocks.end_stone, 0, 2);
		world.setBlock(i + 22, j + 5, k + 6, Blocks.end_stone, 0, 2);
		world.setBlock(i + 23, j + 5, k + 6, OtherModBlocks.end_bricks, 0, 2);
		world.setBlock(i + 10, j + 5, k + 7, OtherModBlocks.end_bricks, 0, 2);
		world.setBlock(i + 11, j + 5, k + 7, Blocks.end_stone, 0, 2);
		world.setBlock(i + 12, j + 5, k + 7, Blocks.end_stone, 0, 2);
		world.setBlock(i + 13, j + 5, k + 7, Blocks.end_stone, 0, 2);
		world.setBlock(i + 14, j + 5, k + 7, Blocks.end_stone, 0, 2);
		world.setBlock(i + 15, j + 5, k + 7, Blocks.end_stone, 0, 2);
		world.setBlock(i + 16, j + 5, k + 7, Blocks.end_stone, 0, 2);
		world.setBlock(i + 17, j + 5, k + 7, Blocks.end_stone, 0, 2);
		world.setBlock(i + 18, j + 5, k + 7, Blocks.end_stone, 0, 2);
		world.setBlock(i + 19, j + 5, k + 7, Blocks.end_stone, 0, 2);
		world.setBlock(i + 20, j + 5, k + 7, Blocks.end_stone, 0, 2);
		world.setBlock(i + 21, j + 5, k + 7, Blocks.end_stone, 0, 2);
		world.setBlock(i + 22, j + 5, k + 7, Blocks.end_stone, 0, 2);
		world.setBlock(i + 23, j + 5, k + 7, Blocks.end_stone, 0, 2);
		world.setBlock(i + 24, j + 5, k + 7, OtherModBlocks.end_bricks, 0, 2);
		world.setBlock(i + 9, j + 5, k + 8, OtherModBlocks.end_bricks, 0, 2);
		world.setBlock(i + 10, j + 5, k + 8, Blocks.end_stone, 0, 2);
		world.setBlock(i + 11, j + 5, k + 8, Blocks.end_stone, 0, 2);
		world.setBlock(i + 12, j + 5, k + 8, Blocks.end_stone, 0, 2);
		world.setBlock(i + 13, j + 5, k + 8, Blocks.end_stone, 0, 2);
		world.setBlock(i + 14, j + 5, k + 8, Blocks.end_stone, 0, 2);
		world.setBlock(i + 15, j + 5, k + 8, Blocks.end_stone, 0, 2);
		world.setBlock(i + 16, j + 5, k + 8, Blocks.end_stone, 0, 2);
		world.setBlock(i + 17, j + 5, k + 8, Blocks.end_stone, 0, 2);
		world.setBlock(i + 18, j + 5, k + 8, Blocks.end_stone, 0, 2);
		world.setBlock(i + 19, j + 5, k + 8, Blocks.end_stone, 0, 2);
		world.setBlock(i + 20, j + 5, k + 8, Blocks.end_stone, 0, 2);
		world.setBlock(i + 21, j + 5, k + 8, Blocks.end_stone, 0, 2);
		world.setBlock(i + 22, j + 5, k + 8, Blocks.end_stone, 0, 2);
		world.setBlock(i + 23, j + 5, k + 8, Blocks.end_stone, 0, 2);
		world.setBlock(i + 24, j + 5, k + 8, Blocks.end_stone, 0, 2);
		world.setBlock(i + 25, j + 5, k + 8, OtherModBlocks.end_bricks, 0, 2);
		world.setBlock(i + 8, j + 5, k + 9, OtherModBlocks.end_bricks, 0, 2);
		world.setBlock(i + 9, j + 5, k + 9, Blocks.end_stone, 0, 2);
		world.setBlock(i + 10, j + 5, k + 9, Blocks.end_stone, 0, 2);
		world.setBlock(i + 11, j + 5, k + 9, Blocks.end_stone, 0, 2);
		world.setBlock(i + 12, j + 5, k + 9, Blocks.end_stone, 0, 2);
		world.setBlock(i + 13, j + 5, k + 9, Blocks.end_stone, 0, 2);
		world.setBlock(i + 14, j + 5, k + 9, Blocks.end_stone, 0, 2);
		world.setBlock(i + 15, j + 5, k + 9, Blocks.end_stone, 0, 2);
		world.setBlock(i + 16, j + 5, k + 9, Blocks.end_stone, 0, 2);
		world.setBlock(i + 17, j + 5, k + 9, Blocks.end_stone, 0, 2);
		world.setBlock(i + 18, j + 5, k + 9, Blocks.end_stone, 0, 2);
		world.setBlock(i + 19, j + 5, k + 9, Blocks.end_stone, 0, 2);
		world.setBlock(i + 20, j + 5, k + 9, Blocks.end_stone, 0, 2);
		world.setBlock(i + 21, j + 5, k + 9, Blocks.end_stone, 0, 2);
		world.setBlock(i + 22, j + 5, k + 9, Blocks.end_stone, 0, 2);
		world.setBlock(i + 23, j + 5, k + 9, Blocks.end_stone, 0, 2);
		world.setBlock(i + 24, j + 5, k + 9, Blocks.end_stone, 0, 2);
		world.setBlock(i + 25, j + 5, k + 9, Blocks.end_stone, 0, 2);
		world.setBlock(i + 26, j + 5, k + 9, OtherModBlocks.end_bricks, 0, 2);
		world.setBlock(i + 7, j + 5, k + 10, OtherModBlocks.end_bricks, 0, 2);
		world.setBlock(i + 8, j + 5, k + 10, Blocks.end_stone, 0, 2);
		world.setBlock(i + 9, j + 5, k + 10, Blocks.end_stone, 0, 2);
		world.setBlock(i + 10, j + 5, k + 10, Blocks.end_stone, 0, 2);
		world.setBlock(i + 11, j + 5, k + 10, Blocks.end_stone, 0, 2);
		world.setBlock(i + 12, j + 5, k + 10, Blocks.end_stone, 0, 2);
		world.setBlock(i + 13, j + 5, k + 10, Blocks.end_stone, 0, 2);
		world.setBlock(i + 14, j + 5, k + 10, Blocks.end_stone, 0, 2);
		world.setBlock(i + 15, j + 5, k + 10, Blocks.end_stone, 0, 2);
		world.setBlock(i + 16, j + 5, k + 10, Blocks.end_stone, 0, 2);
		world.setBlock(i + 17, j + 5, k + 10, Blocks.end_stone, 0, 2);
		world.setBlock(i + 18, j + 5, k + 10, Blocks.end_stone, 0, 2);
		world.setBlock(i + 19, j + 5, k + 10, Blocks.end_stone, 0, 2);
		world.setBlock(i + 20, j + 5, k + 10, Blocks.end_stone, 0, 2);
		world.setBlock(i + 21, j + 5, k + 10, Blocks.end_stone, 0, 2);
		world.setBlock(i + 22, j + 5, k + 10, Blocks.end_stone, 0, 2);
		world.setBlock(i + 23, j + 5, k + 10, Blocks.end_stone, 0, 2);
		world.setBlock(i + 24, j + 5, k + 10, Blocks.end_stone, 0, 2);
		world.setBlock(i + 25, j + 5, k + 10, Blocks.end_stone, 0, 2);
		world.setBlock(i + 26, j + 5, k + 10, OtherModBlocks.end_bricks, 0, 2);
		world.setBlock(i + 6, j + 5, k + 11, OtherModBlocks.end_bricks, 0, 2);
		world.setBlock(i + 7, j + 5, k + 11, Blocks.end_stone, 0, 2);
		world.setBlock(i + 8, j + 5, k + 11, Blocks.end_stone, 0, 2);
		world.setBlock(i + 9, j + 5, k + 11, Blocks.end_stone, 0, 2);
		world.setBlock(i + 10, j + 5, k + 11, Blocks.end_stone, 0, 2);
		world.setBlock(i + 11, j + 5, k + 11, Blocks.end_stone, 0, 2);
		world.setBlock(i + 12, j + 5, k + 11, Blocks.end_stone, 0, 2);
		world.setBlock(i + 13, j + 5, k + 11, Blocks.end_stone, 0, 2);
		world.setBlock(i + 14, j + 5, k + 11, Blocks.end_stone, 0, 2);
		world.setBlock(i + 15, j + 5, k + 11, Blocks.end_stone, 0, 2);
		world.setBlock(i + 16, j + 5, k + 11, Blocks.end_stone, 0, 2);
		world.setBlock(i + 17, j + 5, k + 11, Blocks.end_stone, 0, 2);
		world.setBlock(i + 18, j + 5, k + 11, Blocks.end_stone, 0, 2);
		world.setBlock(i + 19, j + 5, k + 11, Blocks.end_stone, 0, 2);
		world.setBlock(i + 20, j + 5, k + 11, Blocks.end_stone, 0, 2);
		world.setBlock(i + 21, j + 5, k + 11, Blocks.end_stone, 0, 2);
		world.setBlock(i + 22, j + 5, k + 11, Blocks.end_stone, 0, 2);
		world.setBlock(i + 23, j + 5, k + 11, Blocks.end_stone, 0, 2);
		world.setBlock(i + 24, j + 5, k + 11, Blocks.end_stone, 0, 2);
		world.setBlock(i + 25, j + 5, k + 11, Blocks.end_stone, 0, 2);
		world.setBlock(i + 26, j + 5, k + 11, OtherModBlocks.end_bricks, 0, 2);
		world.setBlock(i + 5, j + 5, k + 12, OtherModBlocks.end_bricks, 0, 2);
		world.setBlock(i + 6, j + 5, k + 12, Blocks.end_stone, 0, 2);
		world.setBlock(i + 7, j + 5, k + 12, Blocks.end_stone, 0, 2);
		world.setBlock(i + 8, j + 5, k + 12, Blocks.end_stone, 0, 2);
		world.setBlock(i + 9, j + 5, k + 12, Blocks.end_stone, 0, 2);
		world.setBlock(i + 10, j + 5, k + 12, Blocks.end_stone, 0, 2);
		world.setBlock(i + 11, j + 5, k + 12, Blocks.end_stone, 0, 2);
		world.setBlock(i + 12, j + 5, k + 12, Blocks.end_stone, 0, 2);
		world.setBlock(i + 13, j + 5, k + 12, Blocks.end_stone, 0, 2);
		world.setBlock(i + 14, j + 5, k + 12, Blocks.end_stone, 0, 2);
		world.setBlock(i + 15, j + 5, k + 12, Blocks.end_stone, 0, 2);
		world.setBlock(i + 16, j + 5, k + 12, Blocks.end_stone, 0, 2);
		world.setBlock(i + 17, j + 5, k + 12, Blocks.end_stone, 0, 2);
		world.setBlock(i + 18, j + 5, k + 12, Blocks.end_stone, 0, 2);
		world.setBlock(i + 19, j + 5, k + 12, Blocks.end_stone, 0, 2);
		world.setBlock(i + 20, j + 5, k + 12, Blocks.end_stone, 0, 2);
		world.setBlock(i + 21, j + 5, k + 12, Blocks.end_stone, 0, 2);
		world.setBlock(i + 22, j + 5, k + 12, Blocks.end_stone, 0, 2);
		world.setBlock(i + 23, j + 5, k + 12, Blocks.end_stone, 0, 2);
		world.setBlock(i + 24, j + 5, k + 12, Blocks.end_stone, 0, 2);
		world.setBlock(i + 25, j + 5, k + 12, Blocks.end_stone, 0, 2);
		world.setBlock(i + 26, j + 5, k + 12, OtherModBlocks.end_bricks, 0, 2);
		world.setBlock(i + 4, j + 5, k + 13, OtherModBlocks.end_bricks, 0, 2);
		world.setBlock(i + 5, j + 5, k + 13, Blocks.end_stone, 0, 2);
		world.setBlock(i + 6, j + 5, k + 13, Blocks.end_stone, 0, 2);
		world.setBlock(i + 7, j + 5, k + 13, Blocks.end_stone, 0, 2);
		world.setBlock(i + 8, j + 5, k + 13, Blocks.end_stone, 0, 2);
		world.setBlock(i + 9, j + 5, k + 13, Blocks.end_stone, 0, 2);
		world.setBlock(i + 10, j + 5, k + 13, Blocks.end_stone, 0, 2);
		world.setBlock(i + 11, j + 5, k + 13, Blocks.end_stone, 0, 2);
		world.setBlock(i + 12, j + 5, k + 13, Blocks.end_stone, 0, 2);
		world.setBlock(i + 13, j + 5, k + 13, Blocks.end_stone, 0, 2);
		world.setBlock(i + 14, j + 5, k + 13, Blocks.end_stone, 0, 2);
		world.setBlock(i + 15, j + 5, k + 13, NovaCraftBlocks.nullstone_tiles, 0, 2);
		world.setBlock(i + 16, j + 5, k + 13, NovaCraftBlocks.nullstone_tiles, 0, 2);
		world.setBlock(i + 17, j + 5, k + 13, NovaCraftBlocks.nullstone_tiles, 0, 2);
		world.setBlock(i + 18, j + 5, k + 13, Blocks.end_stone, 0, 2);
		world.setBlock(i + 19, j + 5, k + 13, Blocks.end_stone, 0, 2);
		world.setBlock(i + 20, j + 5, k + 13, Blocks.end_stone, 0, 2);
		world.setBlock(i + 21, j + 5, k + 13, Blocks.end_stone, 0, 2);
		world.setBlock(i + 22, j + 5, k + 13, Blocks.end_stone, 0, 2);
		world.setBlock(i + 23, j + 5, k + 13, Blocks.end_stone, 0, 2);
		world.setBlock(i + 24, j + 5, k + 13, Blocks.end_stone, 0, 2);
		world.setBlock(i + 25, j + 5, k + 13, Blocks.end_stone, 0, 2);
		world.setBlock(i + 26, j + 5, k + 13, OtherModBlocks.end_bricks, 0, 2);
		world.setBlock(i + 3, j + 5, k + 14, OtherModBlocks.end_bricks, 0, 2);
		world.setBlock(i + 4, j + 5, k + 14, Blocks.end_stone, 0, 2);
		world.setBlock(i + 5, j + 5, k + 14, Blocks.end_stone, 0, 2);
		world.setBlock(i + 6, j + 5, k + 14, Blocks.end_stone, 0, 2);
		world.setBlock(i + 7, j + 5, k + 14, Blocks.end_stone, 0, 2);
		world.setBlock(i + 8, j + 5, k + 14, Blocks.end_stone, 0, 2);
		world.setBlock(i + 9, j + 5, k + 14, Blocks.end_stone, 0, 2);
		world.setBlock(i + 10, j + 5, k + 14, Blocks.end_stone, 0, 2);
		world.setBlock(i + 11, j + 5, k + 14, Blocks.end_stone, 0, 2);
		world.setBlock(i + 12, j + 5, k + 14, Blocks.end_stone, 0, 2);
		world.setBlock(i + 13, j + 5, k + 14, Blocks.end_stone, 0, 2);
		world.setBlock(i + 14, j + 5, k + 14, NovaCraftBlocks.nullstone_tiles, 0, 2);
		world.setBlock(i + 15, j + 5, k + 14, NovaCraftBlocks.lacuna_planks, 0, 2);
		world.setBlock(i + 16, j + 5, k + 14, NovaCraftBlocks.lacuna_planks, 0, 2);
		world.setBlock(i + 17, j + 5, k + 14, NovaCraftBlocks.lacuna_planks, 0, 2);
		world.setBlock(i + 18, j + 5, k + 14, NovaCraftBlocks.nullstone_tiles, 0, 2);
		world.setBlock(i + 19, j + 5, k + 14, Blocks.end_stone, 0, 2);
		world.setBlock(i + 20, j + 5, k + 14, Blocks.end_stone, 0, 2);
		world.setBlock(i + 21, j + 5, k + 14, Blocks.end_stone, 0, 2);
		world.setBlock(i + 22, j + 5, k + 14, Blocks.end_stone, 0, 2);
		world.setBlock(i + 23, j + 5, k + 14, Blocks.end_stone, 0, 2);
		world.setBlock(i + 24, j + 5, k + 14, Blocks.end_stone, 0, 2);
		world.setBlock(i + 25, j + 5, k + 14, Blocks.end_stone, 0, 2);
		world.setBlock(i + 26, j + 5, k + 14, OtherModBlocks.end_bricks, 0, 2);
		world.setBlock(i + 2, j + 5, k + 15, OtherModBlocks.end_bricks, 0, 2);
		world.setBlock(i + 3, j + 5, k + 15, Blocks.end_stone, 0, 2);
		world.setBlock(i + 4, j + 5, k + 15, Blocks.end_stone, 0, 2);
		world.setBlock(i + 5, j + 5, k + 15, Blocks.end_stone, 0, 2);
		world.setBlock(i + 6, j + 5, k + 15, Blocks.end_stone, 0, 2);
		world.setBlock(i + 7, j + 5, k + 15, Blocks.end_stone, 0, 2);
		world.setBlock(i + 8, j + 5, k + 15, Blocks.end_stone, 0, 2);
		world.setBlock(i + 9, j + 5, k + 15, Blocks.end_stone, 0, 2);
		world.setBlock(i + 10, j + 5, k + 15, Blocks.end_stone, 0, 2);
		world.setBlock(i + 11, j + 5, k + 15, Blocks.end_stone, 0, 2);
		world.setBlock(i + 12, j + 5, k + 15, Blocks.end_stone, 0, 2);
		world.setBlock(i + 13, j + 5, k + 15, NovaCraftBlocks.nullstone_tiles, 0, 2);
		world.setBlock(i + 14, j + 5, k + 15, NovaCraftBlocks.lacuna_planks, 0, 2);
		world.setBlock(i + 15, j + 5, k + 15, NovaCraftBlocks.lacuna_planks, 0, 2);
		world.setBlock(i + 16, j + 5, k + 15, NovaCraftBlocks.lacuna_planks, 0, 2);
		world.setBlock(i + 17, j + 5, k + 15, NovaCraftBlocks.lacuna_planks, 0, 2);
		world.setBlock(i + 18, j + 5, k + 15, NovaCraftBlocks.lacuna_planks, 0, 2);
		world.setBlock(i + 19, j + 5, k + 15, NovaCraftBlocks.nullstone_tiles, 0, 2);
		world.setBlock(i + 20, j + 5, k + 15, Blocks.end_stone, 0, 2);
		world.setBlock(i + 21, j + 5, k + 15, Blocks.end_stone, 0, 2);
		world.setBlock(i + 22, j + 5, k + 15, Blocks.end_stone, 0, 2);
		world.setBlock(i + 23, j + 5, k + 15, Blocks.end_stone, 0, 2);
		world.setBlock(i + 24, j + 5, k + 15, Blocks.end_stone, 0, 2);
		world.setBlock(i + 25, j + 5, k + 15, Blocks.end_stone, 0, 2);
		world.setBlock(i + 26, j + 5, k + 15, OtherModBlocks.end_bricks, 0, 2);
		world.setBlock(i + 1, j + 5, k + 16, OtherModBlocks.end_bricks, 0, 2);
