package com.NovaCraft.world.mansion;

import com.NovaCraft.config.Configs;
import cpw.mods.fml.common.Loader;
import cpw.mods.fml.common.registry.GameRegistry;
import net.minecraft.block.Block;
import net.minecraft.init.Blocks;
import net.minecraft.world.World;
import net.minecraft.world.gen.feature.WorldGenerator;

import java.util.Random;

public class MansionBasementStairsFloor1Gen extends WorldGenerator
{
    public MansionBasementStairsFloor1Gen() {

    }

    private Block PlaceDarkOakFence;

    private Block determineIfDarkOakFenceExists(World world, int x, int y, int z) {
        Block existingBlock = world.getBlock(x, y, z);
        if (Configs.enableDarkOakFenceInAncientCity && Loader.isModLoaded("etfuturum")) {
            try {
                Block fence_dark_oak = GameRegistry.findBlock("etfuturum", "fence_dark_oak");
                if (fence_dark_oak != null && (existingBlock == null || existingBlock != fence_dark_oak)) {
                    return fence_dark_oak;
                }
            } catch (Exception ex) {
                if (Configs.enableDebugMode) {
                    System.out.println("Missing Dark Oak Fence from Et Futurum Requiem, using regular fence instead...");
                }
                return Blocks.fence;
            }
        }

        return Blocks.fence;
    }

    @Override
    public boolean generate(final World world, final Random random, final int i, final int j, final int k) {
        PlaceDarkOakFence = determineIfDarkOakFenceExists(world, i + 15, j + 2, k + 3);
        
        world.setBlock(i + 0, j + 0, k + 0, Blocks.planks, 2, 2);
        world.setBlock(i + 1, j + 0, k + 0, Blocks.planks, 2, 2);
        world.setBlock(i + 2, j + 0, k + 0, Blocks.planks, 2, 2);
        world.setBlock(i + 3, j + 0, k + 0, Blocks.planks, 2, 2);
        world.setBlock(i + 4, j + 0, k + 0, Blocks.planks, 2, 2);
        world.setBlock(i + 5, j + 0, k + 0, Blocks.planks, 2, 2);
        world.setBlock(i + 6, j + 0, k + 0, Blocks.planks, 2, 2);
        world.setBlock(i + 7, j + 0, k + 0, Blocks.planks, 2, 2);
        world.setBlock(i + 8, j + 0, k + 0, Blocks.planks, 2, 2);
        world.setBlock(i + 9, j + 0, k + 0, Blocks.planks, 2, 2);
        world.setBlock(i + 10, j + 0, k + 0, Blocks.planks, 2, 2);
        world.setBlock(i + 11, j + 0, k + 0, Blocks.planks, 2, 2);
        world.setBlock(i + 12, j + 0, k + 0, Blocks.planks, 2, 2);
        world.setBlock(i + 13, j + 0, k + 0, Blocks.planks, 2, 2);
        world.setBlock(i + 14, j + 0, k + 0, Blocks.planks, 2, 2);
        world.setBlock(i + 15, j + 0, k + 0, Blocks.planks, 2, 2);
        world.setBlock(i + 16, j + 0, k + 0, Blocks.planks, 2, 2);
        world.setBlock(i + 0, j + 0, k + 1, Blocks.planks, 2, 2);
        world.setBlock(i + 1, j + 0, k + 1, Blocks.planks, 2, 2);
        world.setBlock(i + 2, j + 0, k + 1, Blocks.planks, 2, 2);
        world.setBlock(i + 3, j + 0, k + 1, Blocks.planks, 2, 2);
        world.setBlock(i + 4, j + 0, k + 1, Blocks.planks, 2, 2);
        world.setBlock(i + 5, j + 0, k + 1, Blocks.planks, 2, 2);
        world.setBlock(i + 6, j + 0, k + 1, Blocks.planks, 2, 2);
        world.setBlock(i + 7, j + 0, k + 1, Blocks.planks, 2, 2);
        world.setBlock(i + 8, j + 0, k + 1, Blocks.planks, 2, 2);
        world.setBlock(i + 9, j + 0, k + 1, Blocks.planks, 2, 2);
        world.setBlock(i + 10, j + 0, k + 1, Blocks.planks, 2, 2);
        world.setBlock(i + 11, j + 0, k + 1, Blocks.planks, 2, 2);
        world.setBlock(i + 12, j + 0, k + 1, Blocks.planks, 2, 2);
        world.setBlock(i + 13, j + 0, k + 1, Blocks.dark_oak_stairs, 3, 2);
        world.setBlock(i + 14, j + 0, k + 1, Blocks.planks, 2, 2);
        world.setBlock(i + 15, j + 0, k + 1, Blocks.planks, 2, 2);
        world.setBlock(i + 16, j + 0, k + 1, Blocks.planks, 2, 2);
        world.setBlock(i + 0, j + 0, k + 2, Blocks.planks, 2, 2);
        world.setBlock(i + 1, j + 0, k + 2, Blocks.planks, 2, 2);
        world.setBlock(i + 2, j + 0, k + 2, Blocks.planks, 2, 2);
        world.setBlock(i + 3, j + 0, k + 2, Blocks.planks, 2, 2);
        world.setBlock(i + 4, j + 0, k + 2, Blocks.planks, 2, 2);
        world.setBlock(i + 5, j + 0, k + 2, Blocks.planks, 2, 2);
        world.setBlock(i + 6, j + 0, k + 2, Blocks.planks, 2, 2);
        world.setBlock(i + 7, j + 0, k + 2, Blocks.planks, 2, 2);
        world.setBlock(i + 8, j + 0, k + 2, Blocks.planks, 2, 2);
        world.setBlock(i + 9, j + 0, k + 2, Blocks.planks, 2, 2);
        world.setBlock(i + 10, j + 0, k + 2, Blocks.planks, 2, 2);
        world.setBlock(i + 11, j + 0, k + 2, Blocks.planks, 2, 2);
        world.setBlock(i + 12, j + 0, k + 2, Blocks.planks, 2, 2);
        world.setBlock(i + 13, j + 0, k + 2, Blocks.air, 0, 2);
        world.setBlock(i + 14, j + 0, k + 2, Blocks.planks, 2, 2);
        world.setBlock(i + 15, j + 0, k + 2, Blocks.planks, 2, 2);
        world.setBlock(i + 16, j + 0, k + 2, Blocks.planks, 2, 2);
        world.setBlock(i + 0, j + 0, k + 3, Blocks.planks, 2, 2);
        world.setBlock(i + 1, j + 0, k + 3, Blocks.planks, 2, 2);
        world.setBlock(i + 2, j + 0, k + 3, Blocks.planks, 2, 2);
        world.setBlock(i + 3, j + 0, k + 3, Blocks.planks, 2, 2);
        world.setBlock(i + 4, j + 0, k + 3, Blocks.planks, 2, 2);
        world.setBlock(i + 5, j + 0, k + 3, Blocks.planks, 2, 2);
        world.setBlock(i + 6, j + 0, k + 3, Blocks.planks, 2, 2);
        world.setBlock(i + 7, j + 0, k + 3, Blocks.planks, 2, 2);
        world.setBlock(i + 8, j + 0, k + 3, Blocks.planks, 2, 2);
        world.setBlock(i + 9, j + 0, k + 3, Blocks.planks, 2, 2);
        world.setBlock(i + 10, j + 0, k + 3, Blocks.planks, 2, 2);
        world.setBlock(i + 11, j + 0, k + 3, Blocks.planks, 2, 2);
        world.setBlock(i + 12, j + 0, k + 3, Blocks.planks, 2, 2);
        world.setBlock(i + 13, j + 0, k + 3, Blocks.air, 0, 2);
        world.setBlock(i + 14, j + 0, k + 3, Blocks.planks, 2, 2);
        world.setBlock(i + 15, j + 0, k + 3, Blocks.planks, 2, 2);
        world.setBlock(i + 16, j + 0, k + 3, Blocks.planks, 2, 2);
        world.setBlock(i + 0, j + 0, k + 4, Blocks.planks, 2, 2);
        world.setBlock(i + 1, j + 0, k + 4, Blocks.planks, 2, 2);
        world.setBlock(i + 2, j + 0, k + 4, Blocks.planks, 2, 2);
        world.setBlock(i + 3, j + 0, k + 4, Blocks.planks, 2, 2);
        world.setBlock(i + 4, j + 0, k + 4, Blocks.planks, 2, 2);
        world.setBlock(i + 5, j + 0, k + 4, Blocks.planks, 2, 2);
        world.setBlock(i + 6, j + 0, k + 4, Blocks.planks, 2, 2);
        world.setBlock(i + 7, j + 0, k + 4, Blocks.planks, 2, 2);
        world.setBlock(i + 8, j + 0, k + 4, Blocks.planks, 2, 2);
        world.setBlock(i + 9, j + 0, k + 4, Blocks.planks, 2, 2);
        world.setBlock(i + 10, j + 0, k + 4, Blocks.planks, 2, 2);
        world.setBlock(i + 11, j + 0, k + 4, Blocks.planks, 2, 2);
        world.setBlock(i + 12, j + 0, k + 4, Blocks.planks, 2, 2);
        world.setBlock(i + 13, j + 0, k + 4, Blocks.air, 0, 2);
        world.setBlock(i + 14, j + 0, k + 4, Blocks.planks, 2, 2);
        world.setBlock(i + 15, j + 0, k + 4, Blocks.planks, 2, 2);
        world.setBlock(i + 16, j + 0, k + 4, Blocks.planks, 2, 2);
        world.setBlock(i + 0, j + 0, k + 5, Blocks.planks, 2, 2);
        world.setBlock(i + 1, j + 0, k + 5, Blocks.planks, 2, 2);
        world.setBlock(i + 2, j + 0, k + 5, Blocks.planks, 2, 2);
        world.setBlock(i + 3, j + 0, k + 5, Blocks.planks, 2, 2);
        world.setBlock(i + 4, j + 0, k + 5, Blocks.planks, 2, 2);
        world.setBlock(i + 5, j + 0, k + 5, Blocks.planks, 2, 2);
        world.setBlock(i + 6, j + 0, k + 5, Blocks.planks, 2, 2);
        world.setBlock(i + 7, j + 0, k + 5, Blocks.planks, 2, 2);
        world.setBlock(i + 8, j + 0, k + 5, Blocks.planks, 2, 2);
        world.setBlock(i + 9, j + 0, k + 5, Blocks.planks, 2, 2);
        world.setBlock(i + 10, j + 0, k + 5, Blocks.planks, 2, 2);
        world.setBlock(i + 11, j + 0, k + 5, Blocks.planks, 2, 2);
        world.setBlock(i + 12, j + 0, k + 5, Blocks.planks, 2, 2);
        world.setBlock(i + 13, j + 0, k + 5, Blocks.air, 0, 2);
        world.setBlock(i + 14, j + 0, k + 5, Blocks.planks, 2, 2);
        world.setBlock(i + 15, j + 0, k + 5, Blocks.planks, 2, 2);
        world.setBlock(i + 16, j + 0, k + 5, Blocks.planks, 2, 2);
        world.setBlock(i + 0, j + 0, k + 6, Blocks.planks, 2, 2);
        world.setBlock(i + 1, j + 0, k + 6, Blocks.planks, 2, 2);
        world.setBlock(i + 2, j + 0, k + 6, Blocks.planks, 2, 2);
        world.setBlock(i + 3, j + 0, k + 6, Blocks.planks, 2, 2);
        world.setBlock(i + 4, j + 0, k + 6, Blocks.planks, 2, 2);
        world.setBlock(i + 5, j + 0, k + 6, Blocks.planks, 2, 2);
        world.setBlock(i + 6, j + 0, k + 6, Blocks.planks, 2, 2);
        world.setBlock(i + 7, j + 0, k + 6, Blocks.planks, 2, 2);
        world.setBlock(i + 8, j + 0, k + 6, Blocks.planks, 2, 2);
        world.setBlock(i + 9, j + 0, k + 6, Blocks.planks, 2, 2);
        world.setBlock(i + 10, j + 0, k + 6, Blocks.planks, 2, 2);
        world.setBlock(i + 11, j + 0, k + 6, Blocks.planks, 2, 2);
        world.setBlock(i + 12, j + 0, k + 6, Blocks.planks, 2, 2);
        world.setBlock(i + 13, j + 0, k + 6, Blocks.planks, 2, 2);
        world.setBlock(i + 14, j + 0, k + 6, Blocks.planks, 2, 2);
        world.setBlock(i + 15, j + 0, k + 6, Blocks.planks, 2, 2);
        world.setBlock(i + 16, j + 0, k + 6, Blocks.planks, 2, 2);
        world.setBlock(i + 0, j + 0, k + 7, Blocks.planks, 2, 2);
        world.setBlock(i + 1, j + 0, k + 7, Blocks.planks, 2, 2);
        world.setBlock(i + 2, j + 0, k + 7, Blocks.planks, 2, 2);
        world.setBlock(i + 3, j + 0, k + 7, Blocks.planks, 2, 2);
        world.setBlock(i + 4, j + 0, k + 7, Blocks.planks, 2, 2);
        world.setBlock(i + 5, j + 0, k + 7, Blocks.planks, 2, 2);
        world.setBlock(i + 6, j + 0, k + 7, Blocks.planks, 2, 2);
        world.setBlock(i + 7, j + 0, k + 7, Blocks.planks, 2, 2);
        world.setBlock(i + 8, j + 0, k + 7, Blocks.planks, 2, 2);
        world.setBlock(i + 9, j + 0, k + 7, Blocks.planks, 2, 2);
        world.setBlock(i + 10, j + 0, k + 7, Blocks.planks, 2, 2);
        world.setBlock(i + 11, j + 0, k + 7, Blocks.planks, 2, 2);
        world.setBlock(i + 12, j + 0, k + 7, Blocks.planks, 2, 2);
        world.setBlock(i + 13, j + 0, k + 7, Blocks.planks, 2, 2);
        world.setBlock(i + 14, j + 0, k + 7, Blocks.planks, 2, 2);
        world.setBlock(i + 15, j + 0, k + 7, Blocks.planks, 2, 2);
        world.setBlock(i + 16, j + 0, k + 7, Blocks.planks, 2, 2);
        world.setBlock(i + 0, j + 0, k + 8, Blocks.planks, 2, 2);
        world.setBlock(i + 1, j + 0, k + 8, Blocks.planks, 2, 2);
        world.setBlock(i + 2, j + 0, k + 8, Blocks.planks, 2, 2);
        world.setBlock(i + 3, j + 0, k + 8, Blocks.planks, 2, 2);
        world.setBlock(i + 4, j + 0, k + 8, Blocks.planks, 2, 2);
        world.setBlock(i + 5, j + 0, k + 8, Blocks.planks, 2, 2);
        world.setBlock(i + 6, j + 0, k + 8, Blocks.planks, 2, 2);
        world.setBlock(i + 7, j + 0, k + 8, Blocks.planks, 2, 2);
        world.setBlock(i + 8, j + 0, k + 8, Blocks.planks, 2, 2);
        world.setBlock(i + 9, j + 0, k + 8, Blocks.planks, 2, 2);
        world.setBlock(i + 10, j + 0, k + 8, Blocks.planks, 2, 2);
        world.setBlock(i + 11, j + 0, k + 8, Blocks.planks, 2, 2);
        world.setBlock(i + 12, j + 0, k + 8, Blocks.planks, 2, 2);
        world.setBlock(i + 13, j + 0, k + 8, Blocks.planks, 2, 2);
        world.setBlock(i + 14, j + 0, k + 8, Blocks.planks, 2, 2);
        world.setBlock(i + 15, j + 0, k + 8, Blocks.planks, 2, 2);
        world.setBlock(i + 16, j + 0, k + 8, Blocks.planks, 2, 2);
        world.setBlock(i + 0, j + 1, k + 0, Blocks.planks, 5, 2);
        world.setBlock(i + 1, j + 1, k + 0, Blocks.planks, 5, 2);
        world.setBlock(i + 2, j + 1, k + 0, Blocks.planks, 5, 2);
        world.setBlock(i + 3, j + 1, k + 0, Blocks.planks, 5, 2);
        world.setBlock(i + 4, j + 1, k + 0, Blocks.planks, 5, 2);
        world.setBlock(i + 5, j + 1, k + 0, Blocks.planks, 5, 2);
        world.setBlock(i + 6, j + 1, k + 0, Blocks.planks, 5, 2);
        world.setBlock(i + 7, j + 1, k + 0, Blocks.planks, 5, 2);
        world.setBlock(i + 8, j + 1, k + 0, Blocks.planks, 5, 2);
        world.setBlock(i + 9, j + 1, k + 0, Blocks.planks, 5, 2);
        world.setBlock(i + 10, j + 1, k + 0, Blocks.planks, 5, 2);
        world.setBlock(i + 11, j + 1, k + 0, Blocks.planks, 5, 2);
        world.setBlock(i + 12, j + 1, k + 0, Blocks.planks, 5, 2);
        world.setBlock(i + 13, j + 1, k + 0, Blocks.planks, 5, 2);
        world.setBlock(i + 14, j + 1, k + 0, Blocks.planks, 5, 2);
        world.setBlock(i + 15, j + 1, k + 0, Blocks.planks, 5, 2);
        world.setBlock(i + 16, j + 1, k + 0, Blocks.planks, 5, 2);
        world.setBlock(i + 0, j + 1, k + 1, Blocks.planks, 5, 2);
        world.setBlock(i + 1, j + 1, k + 1, Blocks.hay_block, 0, 2);
        world.setBlock(i + 2, j + 1, k + 1, Blocks.hay_block, 0, 2);
        world.setBlock(i + 3, j + 1, k + 1, Blocks.hay_block, 0, 2);
        world.setBlock(i + 4, j + 1, k + 1, Blocks.air, 0, 2);
        world.setBlock(i + 5, j + 1, k + 1, Blocks.air, 0, 2);
        world.setBlock(i + 6, j + 1, k + 1, Blocks.pumpkin, 0, 2);
        world.setBlock(i + 7, j + 1, k + 1, Blocks.pumpkin, 0, 2);
        world.setBlock(i + 8, j + 1, k + 1, Blocks.pumpkin, 0, 2);
        world.setBlock(i + 9, j + 1, k + 1, Blocks.pumpkin, 0, 2);
        world.setBlock(i + 10, j + 1, k + 1, Blocks.pumpkin, 0, 2);
        world.setBlock(i + 11, j + 1, k + 1, Blocks.pumpkin, 0, 2);
        world.setBlock(i + 12, j + 1, k + 1, Blocks.air, 0, 2);
        world.setBlock(i + 13, j + 1, k + 1, Blocks.air, 0, 2);
        world.setBlock(i + 14, j + 1, k + 1, Blocks.dark_oak_stairs, 0, 2);
        world.setBlock(i + 15, j + 1, k + 1, Blocks.planks, 5, 2);
        world.setBlock(i + 16, j + 1, k + 1, Blocks.planks, 5, 2);
        world.setBlock(i + 0, j + 1, k + 2, Blocks.planks, 5, 2);
        world.setBlock(i + 1, j + 1, k + 2, Blocks.hay_block, 0, 2);
        world.setBlock(i + 2, j + 1, k + 2, Blocks.hay_block, 0, 2);
        world.setBlock(i + 3, j + 1, k + 2, Blocks.air, 0, 2);
        world.setBlock(i + 4, j + 1, k + 2, Blocks.air, 0, 2);
        world.setBlock(i + 5, j + 1, k + 2, Blocks.air, 0, 2);
        world.setBlock(i + 6, j + 1, k + 2, Blocks.air, 0, 2);
        world.setBlock(i + 7, j + 1, k + 2, Blocks.pumpkin, 0, 2);
        world.setBlock(i + 8, j + 1, k + 2, Blocks.pumpkin, 0, 2);
        world.setBlock(i + 9, j + 1, k + 2, Blocks.pumpkin, 0, 2);
        world.setBlock(i + 10, j + 1, k + 2, Blocks.pumpkin, 0, 2);
        world.setBlock(i + 11, j + 1, k + 2, Blocks.air, 0, 2);
        world.setBlock(i + 12, j + 1, k + 2, Blocks.air, 0, 2);
        world.setBlock(i + 13, j + 1, k + 2, Blocks.air, 0, 2);
        world.setBlock(i + 14, j + 1, k + 2, Blocks.air, 0, 2);
        world.setBlock(i + 15, j + 1, k + 2, Blocks.planks, 5, 2);
        world.setBlock(i + 16, j + 1, k + 2, Blocks.planks, 5, 2);
        world.setBlock(i + 0, j + 1, k + 3, Blocks.planks, 5, 2);
        world.setBlock(i + 1, j + 1, k + 3, Blocks.hay_block, 0, 2);
        world.setBlock(i + 2, j + 1, k + 3, Blocks.hay_block, 0, 2);
        world.setBlock(i + 3, j + 1, k + 3, Blocks.air, 0, 2);
        world.setBlock(i + 4, j + 1, k + 3, Blocks.air, 0, 2);
        world.setBlock(i + 5, j + 1, k + 3, Blocks.air, 0, 2);
        world.setBlock(i + 6, j + 1, k + 3, Blocks.air, 0, 2);
        world.setBlock(i + 7, j + 1, k + 3, Blocks.air, 0, 2);
        world.setBlock(i + 8, j + 1, k + 3, Blocks.air, 0, 2);
        world.setBlock(i + 9, j + 1, k + 3, Blocks.air, 0, 2);
        world.setBlock(i + 10, j + 1, k + 3, Blocks.air, 0, 2);
        world.setBlock(i + 11, j + 1, k + 3, Blocks.air, 0, 2);
        world.setBlock(i + 12, j + 1, k + 3, Blocks.air, 0, 2);
        world.setBlock(i + 13, j + 1, k + 3, Blocks.air, 0, 2);
        world.setBlock(i + 14, j + 1, k + 3, Blocks.air, 0, 2);
        world.setBlock(i + 15, j + 1, k + 3, Blocks.air, 0, 2);
        world.setBlock(i + 16, j + 1, k + 3, Blocks.planks, 5, 2);
        world.setBlock(i + 0, j + 1, k + 4, Blocks.planks, 5, 2);
        world.setBlock(i + 1, j + 1, k + 4, Blocks.air, 0, 2);
        world.setBlock(i + 2, j + 1, k + 4, Blocks.air, 0, 2);
        world.setBlock(i + 3, j + 1, k + 4, Blocks.air, 0, 2);
        world.setBlock(i + 4, j + 1, k + 4, Blocks.air, 0, 2);
        world.setBlock(i + 5, j + 1, k + 4, Blocks.air, 0, 2);
        world.setBlock(i + 6, j + 1, k + 4, Blocks.air, 0, 2);
        world.setBlock(i + 7, j + 1, k + 4, Blocks.air, 0, 2);
        world.setBlock(i + 8, j + 1, k + 4, Blocks.air, 0, 2);
        world.setBlock(i + 9, j + 1, k + 4, Blocks.air, 0, 2);
        world.setBlock(i + 10, j + 1, k + 4, Blocks.air, 0, 2);
        world.setBlock(i + 11, j + 1, k + 4, Blocks.air, 0, 2);
        world.setBlock(i + 12, j + 1, k + 4, Blocks.air, 0, 2);
        world.setBlock(i + 13, j + 1, k + 4, Blocks.air, 0, 2);
        world.setBlock(i + 14, j + 1, k + 4, Blocks.air, 0, 2);
        world.setBlock(i + 15, j + 1, k + 4, Blocks.air, 0, 2);
        world.setBlock(i + 16, j + 1, k + 4, Blocks.planks, 5, 2);
        world.setBlock(i + 0, j + 1, k + 5, Blocks.planks, 5, 2);
        world.setBlock(i + 1, j + 1, k + 5, Blocks.hay_block, 0, 2);
        world.setBlock(i + 2, j + 1, k + 5, Blocks.hay_block, 0, 2);
        world.setBlock(i + 3, j + 1, k + 5, Blocks.air, 0, 2);
        world.setBlock(i + 4, j + 1, k + 5, Blocks.air, 0, 2);
        world.setBlock(i + 5, j + 1, k + 5, Blocks.air, 0, 2);
        world.setBlock(i + 6, j + 1, k + 5, Blocks.air, 0, 2);
        world.setBlock(i + 7, j + 1, k + 5, Blocks.air, 0, 2);
        world.setBlock(i + 8, j + 1, k + 5, Blocks.air, 0, 2);
        world.setBlock(i + 9, j + 1, k + 5, Blocks.air, 0, 2);
        world.setBlock(i + 10, j + 1, k + 5, Blocks.air, 0, 2);
        world.setBlock(i + 11, j + 1, k + 5, Blocks.melon_block, 0, 2);
        world.setBlock(i + 12, j + 1, k + 5, Blocks.air, 0, 2);
        world.setBlock(i + 13, j + 1, k + 5, Blocks.air, 0, 2);
        world.setBlock(i + 14, j + 1, k + 5, Blocks.air, 0, 2);
        world.setBlock(i + 15, j + 1, k + 5, Blocks.air, 0, 2);
        world.setBlock(i + 16, j + 1, k + 5, Blocks.planks, 5, 2);
        world.setBlock(i + 0, j + 1, k + 6, Blocks.planks, 5, 2);
        world.setBlock(i + 1, j + 1, k + 6, Blocks.hay_block, 0, 2);
        world.setBlock(i + 2, j + 1, k + 6, Blocks.hay_block, 0, 2);
        world.setBlock(i + 3, j + 1, k + 6, Blocks.hay_block, 0, 2);
        world.setBlock(i + 4, j + 1, k + 6, Blocks.air, 0, 2);
        world.setBlock(i + 5, j + 1, k + 6, Blocks.air, 0, 2);
        world.setBlock(i + 6, j + 1, k + 6, Blocks.air, 0, 2);
        world.setBlock(i + 7, j + 1, k + 6, Blocks.air, 0, 2);
        world.setBlock(i + 8, j + 1, k + 6, Blocks.melon_block, 0, 2);
        world.setBlock(i + 9, j + 1, k + 6, Blocks.melon_block, 0, 2);
        world.setBlock(i + 10, j + 1, k + 6, Blocks.melon_block, 0, 2);
        world.setBlock(i + 11, j + 1, k + 6, Blocks.melon_block, 0, 2);
        world.setBlock(i + 12, j + 1, k + 6, Blocks.melon_block, 0, 2);
        world.setBlock(i + 13, j + 1, k + 6, Blocks.air, 0, 2);
        world.setBlock(i + 14, j + 1, k + 6, Blocks.air, 0, 2);
        world.setBlock(i + 15, j + 1, k + 6, Blocks.air, 0, 2);
        world.setBlock(i + 16, j + 1, k + 6, Blocks.planks, 5, 2);
        world.setBlock(i + 0, j + 1, k + 7, Blocks.planks, 5, 2);
        world.setBlock(i + 1, j + 1, k + 7, Blocks.hay_block, 0, 2);
        world.setBlock(i + 2, j + 1, k + 7, Blocks.hay_block, 0, 2);
        world.setBlock(i + 3, j + 1, k + 7, Blocks.hay_block, 0, 2);
        world.setBlock(i + 4, j + 1, k + 7, Blocks.hay_block, 0, 2);
        world.setBlock(i + 5, j + 1, k + 7, Blocks.air, 0, 2);
        world.setBlock(i + 6, j + 1, k + 7, Blocks.air, 0, 2);
        world.setBlock(i + 7, j + 1, k + 7, Blocks.melon_block, 0, 2);
        world.setBlock(i + 8, j + 1, k + 7, Blocks.melon_block, 0, 2);
        world.setBlock(i + 9, j + 1, k + 7, Blocks.melon_block, 0, 2);
        world.setBlock(i + 10, j + 1, k + 7, Blocks.melon_block, 0, 2);
        world.setBlock(i + 11, j + 1, k + 7, Blocks.melon_block, 0, 2);
        world.setBlock(i + 12, j + 1, k + 7, Blocks.melon_block, 0, 2);
        world.setBlock(i + 13, j + 1, k + 7, Blocks.melon_block, 0, 2);
        world.setBlock(i + 14, j + 1, k + 7, Blocks.air, 0, 2);
        world.setBlock(i + 15, j + 1, k + 7, Blocks.air, 0, 2);
        world.setBlock(i + 16, j + 1, k + 7, Blocks.planks, 5, 2);
        world.setBlock(i + 0, j + 1, k + 8, Blocks.planks, 5, 2);
        world.setBlock(i + 1, j + 1, k + 8, Blocks.planks, 5, 2);
        world.setBlock(i + 2, j + 1, k + 8, Blocks.planks, 5, 2);
        world.setBlock(i + 3, j + 1, k + 8, Blocks.planks, 5, 2);
        world.setBlock(i + 4, j + 1, k + 8, Blocks.planks, 5, 2);
        world.setBlock(i + 5, j + 1, k + 8, Blocks.planks, 5, 2);
        world.setBlock(i + 6, j + 1, k + 8, Blocks.planks, 5, 2);
        world.setBlock(i + 7, j + 1, k + 8, Blocks.planks, 5, 2);
        world.setBlock(i + 8, j + 1, k + 8, Blocks.planks, 5, 2);
        world.setBlock(i + 9, j + 1, k + 8, Blocks.planks, 5, 2);
        world.setBlock(i + 10, j + 1, k + 8, Blocks.planks, 5, 2);
        world.setBlock(i + 11, j + 1, k + 8, Blocks.planks, 5, 2);
        world.setBlock(i + 12, j + 1, k + 8, Blocks.planks, 5, 2);
        world.setBlock(i + 13, j + 1, k + 8, Blocks.planks, 5, 2);
        world.setBlock(i + 14, j + 1, k + 8, Blocks.planks, 5, 2);
        world.setBlock(i + 15, j + 1, k + 8, Blocks.planks, 5, 2);
        world.setBlock(i + 16, j + 1, k + 8, Blocks.planks, 5, 2);
        world.setBlock(i + 0, j + 2, k + 0, Blocks.planks, 5, 2);
        world.setBlock(i + 1, j + 2, k + 0, Blocks.planks, 5, 2);
        world.setBlock(i + 2, j + 2, k + 0, Blocks.planks, 5, 2);
        world.setBlock(i + 3, j + 2, k + 0, Blocks.planks, 5, 2);
        world.setBlock(i + 4, j + 2, k + 0, Blocks.planks, 5, 2);
        world.setBlock(i + 5, j + 2, k + 0, Blocks.planks, 5, 2);
        world.setBlock(i + 6, j + 2, k + 0, Blocks.planks, 5, 2);
        world.setBlock(i + 7, j + 2, k + 0, Blocks.planks, 5, 2);
        world.setBlock(i + 8, j + 2, k + 0, Blocks.planks, 5, 2);
        world.setBlock(i + 9, j + 2, k + 0, Blocks.planks, 5, 2);
        world.setBlock(i + 10, j + 2, k + 0, Blocks.planks, 5, 2);
        world.setBlock(i + 11, j + 2, k + 0, Blocks.planks, 5, 2);
        world.setBlock(i + 12, j + 2, k + 0, Blocks.log2, 9, 2);
        world.setBlock(i + 13, j + 2, k + 0, Blocks.planks, 5, 2);
        world.setBlock(i + 14, j + 2, k + 0, Blocks.planks, 5, 2);
        world.setBlock(i + 15, j + 2, k + 0, Blocks.planks, 5, 2);
        world.setBlock(i + 16, j + 2, k + 0, Blocks.planks, 5, 2);
        world.setBlock(i + 0, j + 2, k + 1, Blocks.planks, 5, 2);
        world.setBlock(i + 1, j + 2, k + 1, Blocks.hay_block, 0, 2);
        world.setBlock(i + 2, j + 2, k + 1, Blocks.hay_block, 0, 2);
        world.setBlock(i + 3, j + 2, k + 1, Blocks.air, 0, 2);
        world.setBlock(i + 4, j + 2, k + 1, Blocks.air, 0, 2);
        world.setBlock(i + 5, j + 2, k + 1, Blocks.air, 0, 2);
        world.setBlock(i + 6, j + 2, k + 1, Blocks.air, 0, 2);
        world.setBlock(i + 7, j + 2, k + 1, Blocks.pumpkin, 0, 2);
        world.setBlock(i + 8, j + 2, k + 1, Blocks.pumpkin, 0, 2);
        world.setBlock(i + 9, j + 2, k + 1, Blocks.pumpkin, 0, 2);
        world.setBlock(i + 10, j + 2, k + 1, Blocks.pumpkin, 0, 2);
        world.setBlock(i + 11, j + 2, k + 1, Blocks.air, 0, 2);
        world.setBlock(i + 12, j + 2, k + 1, Blocks.air, 0, 2);
        world.setBlock(i + 13, j + 2, k + 1, Blocks.air, 0, 2);
        world.setBlock(i + 14, j + 2, k + 1, Blocks.air, 0, 2);
        world.setBlock(i + 15, j + 2, k + 1, Blocks.dark_oak_stairs, 0, 2);
        world.setBlock(i + 16, j + 2, k + 1, Blocks.planks, 5, 2);
        world.setBlock(i + 0, j + 2, k + 2, Blocks.planks, 5, 2);
        world.setBlock(i + 1, j + 2, k + 2, Blocks.hay_block, 0, 2);
        world.setBlock(i + 2, j + 2, k + 2, Blocks.air, 0, 2);
        world.setBlock(i + 3, j + 2, k + 2, Blocks.air, 0, 2);
        world.setBlock(i + 4, j + 2, k + 2, Blocks.air, 0, 2);
        world.setBlock(i + 5, j + 2, k + 2, Blocks.air, 0, 2);
        world.setBlock(i + 6, j + 2, k + 2, Blocks.air, 0, 2);
        world.setBlock(i + 7, j + 2, k + 2, Blocks.air, 0, 2);
        world.setBlock(i + 8, j + 2, k + 2, Blocks.pumpkin, 0, 2);
        world.setBlock(i + 9, j + 2, k + 2, Blocks.pumpkin, 0, 2);
        world.setBlock(i + 10, j + 2, k + 2, Blocks.air, 0, 2);
        world.setBlock(i + 11, j + 2, k + 2, Blocks.air, 0, 2);
        world.setBlock(i + 12, j + 2, k + 2, Blocks.air, 0, 2);
        world.setBlock(i + 13, j + 2, k + 2, Blocks.air, 0, 2);
        world.setBlock(i + 14, j + 2, k + 2, Blocks.air, 0, 2);
        world.setBlock(i + 15, j + 2, k + 2, Blocks.planks, 5, 2);
        world.setBlock(i + 16, j + 2, k + 2, Blocks.planks, 5, 2);
        world.setBlock(i + 0, j + 2, k + 3, Blocks.planks, 5, 2);
        world.setBlock(i + 1, j + 2, k + 3, Blocks.hay_block, 0, 2);
        world.setBlock(i + 2, j + 2, k + 3, Blocks.air, 0, 2);
        world.setBlock(i + 3, j + 2, k + 3, Blocks.air, 0, 2);
        world.setBlock(i + 4, j + 2, k + 3, Blocks.air, 0, 2);
        world.setBlock(i + 5, j + 2, k + 3, Blocks.air, 0, 2);
        world.setBlock(i + 6, j + 2, k + 3, Blocks.air, 0, 2);
        world.setBlock(i + 7, j + 2, k + 3, Blocks.air, 0, 2);
        world.setBlock(i + 8, j + 2, k + 3, Blocks.air, 0, 2);
        world.setBlock(i + 9, j + 2, k + 3, Blocks.air, 0, 2);
        world.setBlock(i + 10, j + 2, k + 3, Blocks.air, 0, 2);
        world.setBlock(i + 11, j + 2, k + 3, Blocks.air, 0, 2);
        world.setBlock(i + 12, j + 2, k + 3, Blocks.air, 0, 2);
        world.setBlock(i + 13, j + 2, k + 3, Blocks.air, 0, 2);
        world.setBlock(i + 14, j + 2, k + 3, Blocks.air, 0, 2);
        world.setBlock(i + 15, j + 2, k + 3, PlaceDarkOakFence, 0, 2);
        world.setBlock(i + 16, j + 2, k + 3, Blocks.planks, 5, 2);
        world.setBlock(i + 0, j + 2, k + 4, Blocks.log2, 5, 2);
        world.setBlock(i + 1, j + 2, k + 4, Blocks.air, 0, 2);
        world.setBlock(i + 2, j + 2, k + 4, Blocks.air, 0, 2);
        world.setBlock(i + 3, j + 2, k + 4, Blocks.air, 0, 2);
        world.setBlock(i + 4, j + 2, k + 4, Blocks.air, 0, 2);
        world.setBlock(i + 5, j + 2, k + 4, Blocks.air, 0, 2);
        world.setBlock(i + 6, j + 2, k + 4, Blocks.air, 0, 2);
        world.setBlock(i + 7, j + 2, k + 4, Blocks.air, 0, 2);
        world.setBlock(i + 8, j + 2, k + 4, Blocks.air, 0, 2);
        world.setBlock(i + 9, j + 2, k + 4, Blocks.air, 0, 2);
        world.setBlock(i + 10, j + 2, k + 4, Blocks.air, 0, 2);
        world.setBlock(i + 11, j + 2, k + 4, Blocks.air, 0, 2);
        world.setBlock(i + 12, j + 2, k + 4, Blocks.air, 0, 2);
        world.setBlock(i + 13, j + 2, k + 4, Blocks.air, 0, 2);
        world.setBlock(i + 14, j + 2, k + 4, Blocks.air, 0, 2);
        world.setBlock(i + 15, j + 2, k + 4, Blocks.air, 0, 2);
        world.setBlock(i + 16, j + 2, k + 4, Blocks.log2, 5, 2);
        world.setBlock(i + 0, j + 2, k + 5, Blocks.planks, 5, 2);
        world.setBlock(i + 1, j + 2, k + 5, Blocks.hay_block, 0, 2);
        world.setBlock(i + 2, j + 2, k + 5, Blocks.air, 0, 2);
        world.setBlock(i + 3, j + 2, k + 5, Blocks.air, 0, 2);
        world.setBlock(i + 4, j + 2, k + 5, Blocks.air, 0, 2);
        world.setBlock(i + 5, j + 2, k + 5, Blocks.air, 0, 2);
        world.setBlock(i + 6, j + 2, k + 5, Blocks.air, 0, 2);
        world.setBlock(i + 7, j + 2, k + 5, Blocks.air, 0, 2);
        world.setBlock(i + 8, j + 2, k + 5, Blocks.air, 0, 2);
        world.setBlock(i + 9, j + 2, k + 5, Blocks.air, 0, 2);
        world.setBlock(i + 10, j + 2, k + 5, Blocks.air, 0, 2);
        world.setBlock(i + 11, j + 2, k + 5, Blocks.air, 0, 2);
        world.setBlock(i + 12, j + 2, k + 5, Blocks.air, 0, 2);
        world.setBlock(i + 13, j + 2, k + 5, Blocks.air, 0, 2);
        world.setBlock(i + 14, j + 2, k + 5, Blocks.air, 0, 2);
        world.setBlock(i + 15, j + 2, k + 5, Blocks.air, 0, 2);
        world.setBlock(i + 16, j + 2, k + 5, Blocks.planks, 5, 2);
        world.setBlock(i + 0, j + 2, k + 6, Blocks.planks, 5, 2);
        world.setBlock(i + 1, j + 2, k + 6, Blocks.hay_block, 0, 2);
        world.setBlock(i + 2, j + 2, k + 6, Blocks.hay_block, 0, 2);
        world.setBlock(i + 3, j + 2, k + 6, Blocks.air, 0, 2);
        world.setBlock(i + 4, j + 2, k + 6, Blocks.air, 0, 2);
        world.setBlock(i + 5, j + 2, k + 6, Blocks.air, 0, 2);
        world.setBlock(i + 6, j + 2, k + 6, Blocks.air, 0, 2);
        world.setBlock(i + 7, j + 2, k + 6, Blocks.air, 0, 2);
        world.setBlock(i + 8, j + 2, k + 6, Blocks.air, 0, 2);
        world.setBlock(i + 9, j + 2, k + 6, Blocks.air, 0, 2);
        world.setBlock(i + 10, j + 2, k + 6, Blocks.air, 0, 2);
        world.setBlock(i + 11, j + 2, k + 6, Blocks.melon_block, 0, 2);
        world.setBlock(i + 12, j + 2, k + 6, Blocks.air, 0, 2);
        world.setBlock(i + 13, j + 2, k + 6, Blocks.air, 0, 2);
        world.setBlock(i + 14, j + 2, k + 6, Blocks.air, 0, 2);
        world.setBlock(i + 15, j + 2, k + 6, Blocks.air, 0, 2);
        world.setBlock(i + 16, j + 2, k + 6, Blocks.planks, 5, 2);
        world.setBlock(i + 0, j + 2, k + 7, Blocks.planks, 5, 2);
        world.setBlock(i + 1, j + 2, k + 7, Blocks.hay_block, 0, 2);
        world.setBlock(i + 2, j + 2, k + 7, Blocks.hay_block, 0, 2);
        world.setBlock(i + 3, j + 2, k + 7, Blocks.hay_block, 0, 2);
        world.setBlock(i + 4, j + 2, k + 7, Blocks.air, 0, 2);
        world.setBlock(i + 5, j + 2, k + 7, Blocks.air, 0, 2);
        world.setBlock(i + 6, j + 2, k + 7, Blocks.air, 0, 2);
        world.setBlock(i + 7, j + 2, k + 7, Blocks.air, 0, 2);
        world.setBlock(i + 8, j + 2, k + 7, Blocks.melon_block, 0, 2);
        world.setBlock(i + 9, j + 2, k + 7, Blocks.melon_block, 0, 2);
        world.setBlock(i + 10, j + 2, k + 7, Blocks.melon_block, 0, 2);
        world.setBlock(i + 11, j + 2, k + 7, Blocks.melon_block, 0, 2);
        world.setBlock(i + 12, j + 2, k + 7, Blocks.melon_block, 0, 2);
        world.setBlock(i + 13, j + 2, k + 7, Blocks.air, 0, 2);
        world.setBlock(i + 14, j + 2, k + 7, Blocks.air, 0, 2);
        world.setBlock(i + 15, j + 2, k + 7, Blocks.air, 0, 2);
        world.setBlock(i + 16, j + 2, k + 7, Blocks.planks, 5, 2);
        world.setBlock(i + 0, j + 2, k + 8, Blocks.planks, 5, 2);
        world.setBlock(i + 1, j + 2, k + 8, Blocks.planks, 5, 2);
        world.setBlock(i + 2, j + 2, k + 8, Blocks.planks, 5, 2);
        world.setBlock(i + 3, j + 2, k + 8, Blocks.planks, 5, 2);
        world.setBlock(i + 4, j + 2, k + 8, Blocks.log2, 9, 2);
        world.setBlock(i + 5, j + 2, k + 8, Blocks.planks, 5, 2);
        world.setBlock(i + 6, j + 2, k + 8, Blocks.planks, 5, 2);
        world.setBlock(i + 7, j + 2, k + 8, Blocks.planks, 5, 2);
        world.setBlock(i + 8, j + 2, k + 8, Blocks.planks, 5, 2);
        world.setBlock(i + 9, j + 2, k + 8, Blocks.planks, 5, 2);
        world.setBlock(i + 10, j + 2, k + 8, Blocks.planks, 5, 2);
        world.setBlock(i + 11, j + 2, k + 8, Blocks.planks, 5, 2);
        world.setBlock(i + 12, j + 2, k + 8, Blocks.log2, 9, 2);
        world.setBlock(i + 13, j + 2, k + 8, Blocks.planks, 5, 2);
        world.setBlock(i + 14, j + 2, k + 8, Blocks.planks, 5, 2);
        world.setBlock(i + 15, j + 2, k + 8, Blocks.planks, 5, 2);
        world.setBlock(i + 16, j + 2, k + 8, Blocks.planks, 5, 2);
        world.setBlock(i + 0, j + 3, k + 0, Blocks.planks, 5, 2);
        world.setBlock(i + 1, j + 3, k + 0, Blocks.planks, 5, 2);
        world.setBlock(i + 2, j + 3, k + 0, Blocks.planks, 5, 2);
        world.setBlock(i + 3, j + 3, k + 0, Blocks.planks, 5, 2);
        world.setBlock(i + 4, j + 3, k + 0, Blocks.planks, 5, 2);
        world.setBlock(i + 5, j + 3, k + 0, Blocks.planks, 5, 2);
        world.setBlock(i + 6, j + 3, k + 0, Blocks.planks, 5, 2);
        world.setBlock(i + 7, j + 3, k + 0, Blocks.planks, 5, 2);
        world.setBlock(i + 8, j + 3, k + 0, Blocks.planks, 5, 2);
        world.setBlock(i + 9, j + 3, k + 0, Blocks.planks, 5, 2);
        world.setBlock(i + 10, j + 3, k + 0, Blocks.planks, 5, 2);
        world.setBlock(i + 11, j + 3, k + 0, Blocks.planks, 5, 2);
        world.setBlock(i + 12, j + 3, k + 0, Blocks.log2, 9, 2);
        world.setBlock(i + 13, j + 3, k + 0, Blocks.planks, 5, 2);
        world.setBlock(i + 14, j + 3, k + 0, Blocks.planks, 5, 2);
        world.setBlock(i + 15, j + 3, k + 0, Blocks.planks, 5, 2);
        world.setBlock(i + 16, j + 3, k + 0, Blocks.planks, 5, 2);
        world.setBlock(i + 0, j + 3, k + 1, Blocks.planks, 5, 2);
        world.setBlock(i + 1, j + 3, k + 1, Blocks.hay_block, 0, 2);
        world.setBlock(i + 2, j + 3, k + 1, Blocks.hay_block, 0, 2);
        world.setBlock(i + 3, j + 3, k + 1, Blocks.air, 0, 2);
        world.setBlock(i + 4, j + 3, k + 1, Blocks.air, 0, 2);
        world.setBlock(i + 5, j + 3, k + 1, Blocks.air, 0, 2);
        world.setBlock(i + 6, j + 3, k + 1, Blocks.air, 0, 2);
        world.setBlock(i + 7, j + 3, k + 1, Blocks.air, 0, 2);
        world.setBlock(i + 8, j + 3, k + 1, Blocks.pumpkin, 0, 2);
        world.setBlock(i + 9, j + 3, k + 1, Blocks.pumpkin, 0, 2);
        world.setBlock(i + 10, j + 3, k + 1, Blocks.pumpkin, 0, 2);
        world.setBlock(i + 11, j + 3, k + 1, Blocks.air, 0, 2);
        world.setBlock(i + 12, j + 3, k + 1, Blocks.air, 0, 2);
        world.setBlock(i + 13, j + 3, k + 1, Blocks.air, 0, 2);
        world.setBlock(i + 14, j + 3, k + 1, Blocks.air, 0, 2);
        world.setBlock(i + 15, j + 3, k + 1, Blocks.air, 0, 2);
        world.setBlock(i + 16, j + 3, k + 1, Blocks.planks, 5, 2);
        world.setBlock(i + 0, j + 3, k + 2, Blocks.planks, 5, 2);
        world.setBlock(i + 1, j + 3, k + 2, Blocks.hay_block, 0, 2);
        world.setBlock(i + 2, j + 3, k + 2, Blocks.air, 0, 2);
        world.setBlock(i + 3, j + 3, k + 2, Blocks.air, 0, 2);
        world.setBlock(i + 4, j + 3, k + 2, Blocks.air, 0, 2);
        world.setBlock(i + 5, j + 3, k + 2, Blocks.air, 0, 2);
        world.setBlock(i + 6, j + 3, k + 2, Blocks.air, 0, 2);
        world.setBlock(i + 7, j + 3, k + 2, Blocks.air, 0, 2);
        world.setBlock(i + 8, j + 3, k + 2, Blocks.air, 0, 2);
        world.setBlock(i + 9, j + 3, k + 2, Blocks.pumpkin, 0, 2);
        world.setBlock(i + 10, j + 3, k + 2, Blocks.air, 0, 2);
        world.setBlock(i + 11, j + 3, k + 2, Blocks.air, 0, 2);
        world.setBlock(i + 12, j + 3, k + 2, Blocks.air, 0, 2);
        world.setBlock(i + 13, j + 3, k + 2, Blocks.air, 0, 2);
        world.setBlock(i + 14, j + 3, k + 2, Blocks.air, 0, 2);
        world.setBlock(i + 15, j + 3, k + 2, Blocks.dark_oak_stairs, 2, 2);
        world.setBlock(i + 16, j + 3, k + 2, Blocks.planks, 5, 2);
        world.setBlock(i + 0, j + 3, k + 3, Blocks.planks, 5, 2);
        world.setBlock(i + 1, j + 3, k + 3, Blocks.hay_block, 0, 2);
        world.setBlock(i + 2, j + 3, k + 3, Blocks.air, 0, 2);
        world.setBlock(i + 3, j + 3, k + 3, Blocks.air, 0, 2);
        world.setBlock(i + 4, j + 3, k + 3, Blocks.air, 0, 2);
        world.setBlock(i + 5, j + 3, k + 3, Blocks.air, 0, 2);
        world.setBlock(i + 6, j + 3, k + 3, Blocks.air, 0, 2);
        world.setBlock(i + 7, j + 3, k + 3, Blocks.air, 0, 2);
        world.setBlock(i + 8, j + 3, k + 3, Blocks.air, 0, 2);
        world.setBlock(i + 9, j + 3, k + 3, Blocks.air, 0, 2);
        world.setBlock(i + 10, j + 3, k + 3, Blocks.air, 0, 2);
        world.setBlock(i + 11, j + 3, k + 3, Blocks.air, 0, 2);
        world.setBlock(i + 12, j + 3, k + 3, Blocks.air, 0, 2);
        world.setBlock(i + 13, j + 3, k + 3, Blocks.air, 0, 2);
        world.setBlock(i + 14, j + 3, k + 3, Blocks.air, 0, 2);
        world.setBlock(i + 15, j + 3, k + 3, Blocks.planks, 5, 2);
        world.setBlock(i + 16, j + 3, k + 3, Blocks.planks, 5, 2);
        world.setBlock(i + 0, j + 3, k + 4, Blocks.log2, 5, 2);
        world.setBlock(i + 1, j + 3, k + 4, Blocks.air, 0, 2);
        world.setBlock(i + 2, j + 3, k + 4, Blocks.air, 0, 2);
        world.setBlock(i + 3, j + 3, k + 4, Blocks.air, 0, 2);
        world.setBlock(i + 4, j + 3, k + 4, Blocks.air, 0, 2);
        world.setBlock(i + 5, j + 3, k + 4, Blocks.air, 0, 2);
        world.setBlock(i + 6, j + 3, k + 4, Blocks.air, 0, 2);
        world.setBlock(i + 7, j + 3, k + 4, Blocks.air, 0, 2);
        world.setBlock(i + 8, j + 3, k + 4, Blocks.air, 0, 2);
        world.setBlock(i + 9, j + 3, k + 4, Blocks.air, 0, 2);
        world.setBlock(i + 10, j + 3, k + 4, Blocks.air, 0, 2);
        world.setBlock(i + 11, j + 3, k + 4, Blocks.air, 0, 2);
        world.setBlock(i + 12, j + 3, k + 4, Blocks.air, 0, 2);
        world.setBlock(i + 13, j + 3, k + 4, Blocks.air, 0, 2);
        world.setBlock(i + 14, j + 3, k + 4, Blocks.air, 0, 2);
        world.setBlock(i + 15, j + 3, k + 4, PlaceDarkOakFence, 0, 2);
        world.setBlock(i + 16, j + 3, k + 4, Blocks.log2, 5, 2);
        world.setBlock(i + 0, j + 3, k + 5, Blocks.planks, 5, 2);
        world.setBlock(i + 1, j + 3, k + 5, Blocks.air, 0, 2);
        world.setBlock(i + 2, j + 3, k + 5, Blocks.air, 0, 2);
        world.setBlock(i + 3, j + 3, k + 5, Blocks.air, 0, 2);
        world.setBlock(i + 4, j + 3, k + 5, Blocks.air, 0, 2);
        world.setBlock(i + 5, j + 3, k + 5, Blocks.air, 0, 2);
        world.setBlock(i + 6, j + 3, k + 5, Blocks.air, 0, 2);
        world.setBlock(i + 7, j + 3, k + 5, Blocks.air, 0, 2);
        world.setBlock(i + 8, j + 3, k + 5, Blocks.air, 0, 2);
        world.setBlock(i + 9, j + 3, k + 5, Blocks.air, 0, 2);
        world.setBlock(i + 10, j + 3, k + 5, Blocks.air, 0, 2);
        world.setBlock(i + 11, j + 3, k + 5, Blocks.air, 0, 2);
        world.setBlock(i + 12, j + 3, k + 5, Blocks.air, 0, 2);
        world.setBlock(i + 13, j + 3, k + 5, Blocks.air, 0, 2);
        world.setBlock(i + 14, j + 3, k + 5, Blocks.air, 0, 2);
        world.setBlock(i + 15, j + 3, k + 5, Blocks.air, 0, 2);
        world.setBlock(i + 16, j + 3, k + 5, Blocks.planks, 5, 2);
        world.setBlock(i + 0, j + 3, k + 6, Blocks.planks, 5, 2);
        world.setBlock(i + 1, j + 3, k + 6, Blocks.hay_block, 0, 2);
        world.setBlock(i + 2, j + 3, k + 6, Blocks.air, 0, 2);
        world.setBlock(i + 3, j + 3, k + 6, Blocks.air, 0, 2);
        world.setBlock(i + 4, j + 3, k + 6, Blocks.air, 0, 2);
        world.setBlock(i + 5, j + 3, k + 6, Blocks.air, 0, 2);
        world.setBlock(i + 6, j + 3, k + 6, Blocks.air, 0, 2);
        world.setBlock(i + 7, j + 3, k + 6, Blocks.air, 0, 2);
        world.setBlock(i + 8, j + 3, k + 6, Blocks.air, 0, 2);
        world.setBlock(i + 9, j + 3, k + 6, Blocks.air, 0, 2);
        world.setBlock(i + 10, j + 3, k + 6, Blocks.air, 0, 2);
        world.setBlock(i + 11, j + 3, k + 6, Blocks.air, 0, 2);
        world.setBlock(i + 12, j + 3, k + 6, Blocks.air, 0, 2);
        world.setBlock(i + 13, j + 3, k + 6, Blocks.air, 0, 2);
        world.setBlock(i + 14, j + 3, k + 6, Blocks.air, 0, 2);
        world.setBlock(i + 15, j + 3, k + 6, Blocks.air, 0, 2);
        world.setBlock(i + 16, j + 3, k + 6, Blocks.planks, 5, 2);
        world.setBlock(i + 0, j + 3, k + 7, Blocks.planks, 5, 2);
        world.setBlock(i + 1, j + 3, k + 7, Blocks.hay_block, 0, 2);
        world.setBlock(i + 2, j + 3, k + 7, Blocks.hay_block, 0, 2);
        world.setBlock(i + 3, j + 3, k + 7, Blocks.air, 0, 2);
        world.setBlock(i + 4, j + 3, k + 7, Blocks.air, 0, 2);
        world.setBlock(i + 5, j + 3, k + 7, Blocks.air, 0, 2);
        world.setBlock(i + 6, j + 3, k + 7, Blocks.air, 0, 2);
        world.setBlock(i + 7, j + 3, k + 7, Blocks.air, 0, 2);
        world.setBlock(i + 8, j + 3, k + 7, Blocks.air, 0, 2);
        world.setBlock(i + 9, j + 3, k + 7, Blocks.melon_block, 0, 2);
        world.setBlock(i + 10, j + 3, k + 7, Blocks.melon_block, 0, 2);
        world.setBlock(i + 11, j + 3, k + 7, Blocks.melon_block, 0, 2);
        world.setBlock(i + 12, j + 3, k + 7, Blocks.air, 0, 2);
        world.setBlock(i + 13, j + 3, k + 7, Blocks.air, 0, 2);
        world.setBlock(i + 14, j + 3, k + 7, Blocks.air, 0, 2);
        world.setBlock(i + 15, j + 3, k + 7, Blocks.air, 0, 2);
        world.setBlock(i + 16, j + 3, k + 7, Blocks.planks, 5, 2);
        world.setBlock(i + 0, j + 3, k + 8, Blocks.planks, 5, 2);
        world.setBlock(i + 1, j + 3, k + 8, Blocks.planks, 5, 2);
        world.setBlock(i + 2, j + 3, k + 8, Blocks.planks, 5, 2);
        world.setBlock(i + 3, j + 3, k + 8, Blocks.planks, 5, 2);
        world.setBlock(i + 4, j + 3, k + 8, Blocks.log2, 9, 2);
        world.setBlock(i + 5, j + 3, k + 8, Blocks.planks, 5, 2);
        world.setBlock(i + 6, j + 3, k + 8, Blocks.planks, 5, 2);
        world.setBlock(i + 7, j + 3, k + 8, Blocks.planks, 5, 2);
        world.setBlock(i + 8, j + 3, k + 8, Blocks.planks, 5, 2);
        world.setBlock(i + 9, j + 3, k + 8, Blocks.planks, 5, 2);
        world.setBlock(i + 10, j + 3, k + 8, Blocks.planks, 5, 2);
        world.setBlock(i + 11, j + 3, k + 8, Blocks.planks, 5, 2);
        world.setBlock(i + 12, j + 3, k + 8, Blocks.log2, 9, 2);
        world.setBlock(i + 13, j + 3, k + 8, Blocks.planks, 5, 2);
        world.setBlock(i + 14, j + 3, k + 8, Blocks.planks, 5, 2);
        world.setBlock(i + 15, j + 3, k + 8, Blocks.planks, 5, 2);
        world.setBlock(i + 16, j + 3, k + 8, Blocks.planks, 5, 2);
        world.setBlock(i + 0, j + 4, k + 0, Blocks.planks, 5, 2);
        world.setBlock(i + 1, j + 4, k + 0, Blocks.planks, 5, 2);
        world.setBlock(i + 2, j + 4, k + 0, Blocks.planks, 5, 2);
        world.setBlock(i + 3, j + 4, k + 0, Blocks.planks, 5, 2);
        world.setBlock(i + 4, j + 4, k + 0, Blocks.planks, 5, 2);
        world.setBlock(i + 5, j + 4, k + 0, Blocks.planks, 5, 2);
        world.setBlock(i + 6, j + 4, k + 0, Blocks.planks, 5, 2);
        world.setBlock(i + 7, j + 4, k + 0, Blocks.planks, 5, 2);
        world.setBlock(i + 8, j + 4, k + 0, Blocks.planks, 5, 2);
        world.setBlock(i + 9, j + 4, k + 0, Blocks.planks, 5, 2);
        world.setBlock(i + 10, j + 4, k + 0, Blocks.log2, 9, 2);
        world.setBlock(i + 11, j + 4, k + 0, Blocks.log2, 9, 2);
        world.setBlock(i + 12, j + 4, k + 0, Blocks.planks, 5, 2);
        world.setBlock(i + 13, j + 4, k + 0, Blocks.log2, 9, 2);
        world.setBlock(i + 14, j + 4, k + 0, Blocks.log2, 9, 2);
        world.setBlock(i + 15, j + 4, k + 0, Blocks.planks, 5, 2);
        world.setBlock(i + 16, j + 4, k + 0, Blocks.planks, 5, 2);
        world.setBlock(i + 0, j + 4, k + 1, Blocks.planks, 5, 2);
        world.setBlock(i + 1, j + 4, k + 1, Blocks.hay_block, 0, 2);
        world.setBlock(i + 2, j + 4, k + 1, Blocks.air, 0, 2);
        world.setBlock(i + 3, j + 4, k + 1, Blocks.air, 0, 2);
        world.setBlock(i + 4, j + 4, k + 1, Blocks.air, 0, 2);
        world.setBlock(i + 5, j + 4, k + 1, Blocks.air, 0, 2);
        world.setBlock(i + 6, j + 4, k + 1, Blocks.air, 0, 2);
        world.setBlock(i + 7, j + 4, k + 1, Blocks.air, 0, 2);
        world.setBlock(i + 8, j + 4, k + 1, Blocks.pumpkin, 0, 2);
        world.setBlock(i + 9, j + 4, k + 1, Blocks.pumpkin, 0, 2);
        world.setBlock(i + 10, j + 4, k + 1, Blocks.air, 0, 2);
        world.setBlock(i + 11, j + 4, k + 1, Blocks.air, 0, 2);
        world.setBlock(i + 12, j + 4, k + 1, Blocks.air, 0, 2);
        world.setBlock(i + 13, j + 4, k + 1, Blocks.air, 0, 2);
        world.setBlock(i + 14, j + 4, k + 1, Blocks.air, 0, 2);
        world.setBlock(i + 15, j + 4, k + 1, Blocks.air, 0, 2);
        world.setBlock(i + 16, j + 4, k + 1, Blocks.planks, 5, 2);
        world.setBlock(i + 0, j + 4, k + 2, Blocks.log2, 5, 2);
        world.setBlock(i + 1, j + 4, k + 2, Blocks.hay_block, 0, 2);
        world.setBlock(i + 2, j + 4, k + 2, Blocks.air, 0, 2);
        world.setBlock(i + 3, j + 4, k + 2, Blocks.air, 0, 2);
        world.setBlock(i + 4, j + 4, k + 2, Blocks.air, 0, 2);
        world.setBlock(i + 5, j + 4, k + 2, Blocks.air, 0, 2);
        world.setBlock(i + 6, j + 4, k + 2, Blocks.air, 0, 2);
        world.setBlock(i + 7, j + 4, k + 2, Blocks.air, 0, 2);
        world.setBlock(i + 8, j + 4, k + 2, Blocks.air, 0, 2);
        world.setBlock(i + 9, j + 4, k + 2, Blocks.air, 0, 2);
        world.setBlock(i + 10, j + 4, k + 2, Blocks.air, 0, 2);
        world.setBlock(i + 11, j + 4, k + 2, Blocks.air, 0, 2);
        world.setBlock(i + 12, j + 4, k + 2, Blocks.air, 0, 2);
        world.setBlock(i + 13, j + 4, k + 2, Blocks.air, 0, 2);
        world.setBlock(i + 14, j + 4, k + 2, Blocks.air, 0, 2);
        world.setBlock(i + 15, j + 4, k + 2, Blocks.air, 0, 2);
        world.setBlock(i + 16, j + 4, k + 2, Blocks.log2, 5, 2);
        world.setBlock(i + 0, j + 4, k + 3, Blocks.log2, 5, 2);
        world.setBlock(i + 1, j + 4, k + 3, Blocks.air, 0, 2);
        world.setBlock(i + 2, j + 4, k + 3, Blocks.air, 0, 2);
        world.setBlock(i + 3, j + 4, k + 3, Blocks.air, 0, 2);
        world.setBlock(i + 4, j + 4, k + 3, Blocks.air, 0, 2);
        world.setBlock(i + 5, j + 4, k + 3, Blocks.air, 0, 2);
        world.setBlock(i + 6, j + 4, k + 3, Blocks.air, 0, 2);
        world.setBlock(i + 7, j + 4, k + 3, Blocks.air, 0, 2);
        world.setBlock(i + 8, j + 4, k + 3, Blocks.air, 0, 2);
        world.setBlock(i + 9, j + 4, k + 3, Blocks.air, 0, 2);
        world.setBlock(i + 10, j + 4, k + 3, Blocks.air, 0, 2);
        world.setBlock(i + 11, j + 4, k + 3, Blocks.air, 0, 2);
        world.setBlock(i + 12, j + 4, k + 3, Blocks.air, 0, 2);
        world.setBlock(i + 13, j + 4, k + 3, Blocks.air, 0, 2);
        world.setBlock(i + 14, j + 4, k + 3, Blocks.air, 0, 2);
        world.setBlock(i + 15, j + 4, k + 3, Blocks.dark_oak_stairs, 2, 2);
        world.setBlock(i + 16, j + 4, k + 3, Blocks.log2, 5, 2);
        world.setBlock(i + 0, j + 4, k + 4, Blocks.planks, 5, 2);
        world.setBlock(i + 1, j + 4, k + 4, Blocks.air, 0, 2);
        world.setBlock(i + 2, j + 4, k + 4, Blocks.air, 0, 2);
        world.setBlock(i + 3, j + 4, k + 4, Blocks.air, 0, 2);
        world.setBlock(i + 4, j + 4, k + 4, Blocks.air, 0, 2);
        world.setBlock(i + 5, j + 4, k + 4, Blocks.air, 0, 2);
        world.setBlock(i + 6, j + 4, k + 4, Blocks.air, 0, 2);
        world.setBlock(i + 7, j + 4, k + 4, Blocks.air, 0, 2);
        world.setBlock(i + 8, j + 4, k + 4, Blocks.air, 0, 2);
        world.setBlock(i + 9, j + 4, k + 4, Blocks.air, 0, 2);
        world.setBlock(i + 10, j + 4, k + 4, Blocks.air, 0, 2);
        world.setBlock(i + 11, j + 4, k + 4, Blocks.air, 0, 2);
        world.setBlock(i + 12, j + 4, k + 4, Blocks.air, 0, 2);
        world.setBlock(i + 13, j + 4, k + 4, Blocks.air, 0, 2);
        world.setBlock(i + 14, j + 4, k + 4, Blocks.air, 0, 2);
        world.setBlock(i + 15, j + 4, k + 4, Blocks.planks, 5, 2);
        world.setBlock(i + 16, j + 4, k + 4, Blocks.planks, 5, 2);
        world.setBlock(i + 0, j + 4, k + 5, Blocks.log2, 5, 2);
        world.setBlock(i + 1, j + 4, k + 5, Blocks.air, 0, 2);
        world.setBlock(i + 2, j + 4, k + 5, Blocks.air, 0, 2);
        world.setBlock(i + 3, j + 4, k + 5, Blocks.air, 0, 2);
        world.setBlock(i + 4, j + 4, k + 5, Blocks.air, 0, 2);
        world.setBlock(i + 5, j + 4, k + 5, Blocks.air, 0, 2);
        world.setBlock(i + 6, j + 4, k + 5, Blocks.air, 0, 2);
        world.setBlock(i + 7, j + 4, k + 5, Blocks.air, 0, 2);
        world.setBlock(i + 8, j + 4, k + 5, Blocks.air, 0, 2);
        world.setBlock(i + 9, j + 4, k + 5, Blocks.air, 0, 2);
        world.setBlock(i + 10, j + 4, k + 5, Blocks.air, 0, 2);
        world.setBlock(i + 11, j + 4, k + 5, Blocks.air, 0, 2);
        world.setBlock(i + 12, j + 4, k + 5, Blocks.air, 0, 2);
        world.setBlock(i + 13, j + 4, k + 5, Blocks.air, 0, 2);
        world.setBlock(i + 14, j + 4, k + 5, Blocks.air, 0, 2);
        world.setBlock(i + 15, j + 4, k + 5, PlaceDarkOakFence, 0, 2);
        world.setBlock(i + 16, j + 4, k + 5, Blocks.log2, 5, 2);
        world.setBlock(i + 0, j + 4, k + 6, Blocks.log2, 5, 2);
        world.setBlock(i + 1, j + 4, k + 6, Blocks.hay_block, 0, 2);
        world.setBlock(i + 2, j + 4, k + 6, Blocks.air, 0, 2);
        world.setBlock(i + 3, j + 4, k + 6, Blocks.air, 0, 2);
        world.setBlock(i + 4, j + 4, k + 6, Blocks.air, 0, 2);
        world.setBlock(i + 5, j + 4, k + 6, Blocks.air, 0, 2);
        world.setBlock(i + 6, j + 4, k + 6, Blocks.air, 0, 2);
        world.setBlock(i + 7, j + 4, k + 6, Blocks.air, 0, 2);
        world.setBlock(i + 8, j + 4, k + 6, Blocks.air, 0, 2);
        world.setBlock(i + 9, j + 4, k + 6, Blocks.air, 0, 2);
        world.setBlock(i + 10, j + 4, k + 6, Blocks.air, 0, 2);
        world.setBlock(i + 11, j + 4, k + 6, Blocks.air, 0, 2);
        world.setBlock(i + 12, j + 4, k + 6, Blocks.air, 0, 2);
        world.setBlock(i + 13, j + 4, k + 6, Blocks.air, 0, 2);
        world.setBlock(i + 14, j + 4, k + 6, Blocks.air, 0, 2);
        world.setBlock(i + 15, j + 4, k + 6, Blocks.air, 0, 2);
        world.setBlock(i + 16, j + 4, k + 6, Blocks.log2, 5, 2);
        world.setBlock(i + 0, j + 4, k + 7, Blocks.planks, 5, 2);
        world.setBlock(i + 1, j + 4, k + 7, Blocks.hay_block, 0, 2);
        world.setBlock(i + 2, j + 4, k + 7, Blocks.air, 0, 2);
        world.setBlock(i + 3, j + 4, k + 7, Blocks.air, 0, 2);
        world.setBlock(i + 4, j + 4, k + 7, Blocks.air, 0, 2);
        world.setBlock(i + 5, j + 4, k + 7, Blocks.air, 0, 2);
        world.setBlock(i + 6, j + 4, k + 7, Blocks.air, 0, 2);
        world.setBlock(i + 7, j + 4, k + 7, Blocks.air, 0, 2);
        world.setBlock(i + 8, j + 4, k + 7, Blocks.air, 0, 2);
        world.setBlock(i + 9, j + 4, k + 7, Blocks.melon_block, 0, 2);
        world.setBlock(i + 10, j + 4, k + 7, Blocks.melon_block, 0, 2);
        world.setBlock(i + 11, j + 4, k + 7, Blocks.air, 0, 2);
        world.setBlock(i + 12, j + 4, k + 7, Blocks.air, 0, 2);
        world.setBlock(i + 13, j + 4, k + 7, Blocks.air, 0, 2);
        world.setBlock(i + 14, j + 4, k + 7, Blocks.air, 0, 2);
        world.setBlock(i + 15, j + 4, k + 7, Blocks.air, 0, 2);
        world.setBlock(i + 16, j + 4, k + 7, Blocks.planks, 5, 2);
        world.setBlock(i + 0, j + 4, k + 8, Blocks.planks, 5, 2);
        world.setBlock(i + 1, j + 4, k + 8, Blocks.planks, 5, 2);
        world.setBlock(i + 2, j + 4, k + 8, Blocks.log2, 9, 2);
        world.setBlock(i + 3, j + 4, k + 8, Blocks.log2, 9, 2);
        world.setBlock(i + 4, j + 4, k + 8, Blocks.planks, 5, 2);
        world.setBlock(i + 5, j + 4, k + 8, Blocks.log2, 9, 2);
        world.setBlock(i + 6, j + 4, k + 8, Blocks.log2, 9, 2);
        world.setBlock(i + 7, j + 4, k + 8, Blocks.planks, 5, 2);
        world.setBlock(i + 8, j + 4, k + 8, Blocks.planks, 5, 2);
        world.setBlock(i + 9, j + 4, k + 8, Blocks.planks, 5, 2);
        world.setBlock(i + 10, j + 4, k + 8, Blocks.log2, 9, 2);
        world.setBlock(i + 11, j + 4, k + 8, Blocks.log2, 9, 2);
        world.setBlock(i + 12, j + 4, k + 8, Blocks.planks, 5, 2);
        world.setBlock(i + 13, j + 4, k + 8, Blocks.log2, 9, 2);
        world.setBlock(i + 14, j + 4, k + 8, Blocks.log2, 9, 2);
        world.setBlock(i + 15, j + 4, k + 8, Blocks.planks, 5, 2);
        world.setBlock(i + 16, j + 4, k + 8, Blocks.planks, 5, 2);
        world.setBlock(i + 0, j + 5, k + 0, Blocks.planks, 5, 2);
        world.setBlock(i + 1, j + 5, k + 0, Blocks.planks, 5, 2);
        world.setBlock(i + 2, j + 5, k + 0, Blocks.planks, 5, 2);
        world.setBlock(i + 3, j + 5, k + 0, Blocks.planks, 5, 2);
        world.setBlock(i + 4, j + 5, k + 0, Blocks.planks, 5, 2);
        world.setBlock(i + 5, j + 5, k + 0, Blocks.planks, 5, 2);
        world.setBlock(i + 6, j + 5, k + 0, Blocks.planks, 5, 2);
        world.setBlock(i + 7, j + 5, k + 0, Blocks.planks, 5, 2);
        world.setBlock(i + 8, j + 5, k + 0, Blocks.planks, 5, 2);
        world.setBlock(i + 9, j + 5, k + 0, Blocks.planks, 5, 2);
        world.setBlock(i + 10, j + 5, k + 0, Blocks.planks, 5, 2);
        world.setBlock(i + 11, j + 5, k + 0, Blocks.planks, 5, 2);
        world.setBlock(i + 12, j + 5, k + 0, Blocks.log2, 9, 2);
        world.setBlock(i + 13, j + 5, k + 0, Blocks.planks, 5, 2);
        world.setBlock(i + 14, j + 5, k + 0, Blocks.planks, 5, 2);
        world.setBlock(i + 15, j + 5, k + 0, Blocks.planks, 5, 2);
        world.setBlock(i + 16, j + 5, k + 0, Blocks.planks, 5, 2);
        world.setBlock(i + 0, j + 5, k + 1, Blocks.planks, 5, 2);
        world.setBlock(i + 1, j + 5, k + 1, Blocks.hay_block, 0, 2);
        world.setBlock(i + 2, j + 5, k + 1, Blocks.air, 0, 2);
        world.setBlock(i + 3, j + 5, k + 1, Blocks.air, 0, 2);
        world.setBlock(i + 4, j + 5, k + 1, Blocks.air, 0, 2);
        world.setBlock(i + 5, j + 5, k + 1, Blocks.air, 0, 2);
        world.setBlock(i + 6, j + 5, k + 1, Blocks.air, 0, 2);
        world.setBlock(i + 7, j + 5, k + 1, Blocks.air, 0, 2);
        world.setBlock(i + 8, j + 5, k + 1, Blocks.air, 0, 2);
        world.setBlock(i + 9, j + 5, k + 1, Blocks.pumpkin, 0, 2);
        world.setBlock(i + 10, j + 5, k + 1, Blocks.air, 0, 2);
        world.setBlock(i + 11, j + 5, k + 1, Blocks.air, 0, 2);
        world.setBlock(i + 12, j + 5, k + 1, Blocks.air, 0, 2);
        world.setBlock(i + 13, j + 5, k + 1, Blocks.air, 0, 2);
        world.setBlock(i + 14, j + 5, k + 1, Blocks.air, 0, 2);
        world.setBlock(i + 15, j + 5, k + 1, Blocks.air, 0, 2);
        world.setBlock(i + 16, j + 5, k + 1, Blocks.planks, 5, 2);
        world.setBlock(i + 0, j + 5, k + 2, Blocks.planks, 5, 2);
        world.setBlock(i + 1, j + 5, k + 2, Blocks.air, 0, 2);
        world.setBlock(i + 2, j + 5, k + 2, Blocks.air, 0, 2);
        world.setBlock(i + 3, j + 5, k + 2, Blocks.air, 0, 2);
        world.setBlock(i + 4, j + 5, k + 2, Blocks.air, 0, 2);
        world.setBlock(i + 5, j + 5, k + 2, Blocks.air, 0, 2);
        world.setBlock(i + 6, j + 5, k + 2, Blocks.air, 0, 2);
        world.setBlock(i + 7, j + 5, k + 2, Blocks.air, 0, 2);
        world.setBlock(i + 8, j + 5, k + 2, Blocks.air, 0, 2);
        world.setBlock(i + 9, j + 5, k + 2, Blocks.air, 0, 2);
        world.setBlock(i + 10, j + 5, k + 2, Blocks.air, 0, 2);
        world.setBlock(i + 11, j + 5, k + 2, Blocks.air, 0, 2);
        world.setBlock(i + 12, j + 5, k + 2, Blocks.air, 0, 2);
        world.setBlock(i + 13, j + 5, k + 2, Blocks.air, 0, 2);
        world.setBlock(i + 14, j + 5, k + 2, Blocks.air, 0, 2);
        world.setBlock(i + 15, j + 5, k + 2, Blocks.air, 0, 2);
        world.setBlock(i + 16, j + 5, k + 2, Blocks.planks, 5, 2);
        world.setBlock(i + 0, j + 5, k + 3, Blocks.planks, 5, 2);
        world.setBlock(i + 1, j + 5, k + 3, Blocks.air, 0, 2);
        world.setBlock(i + 2, j + 5, k + 3, Blocks.air, 0, 2);
        world.setBlock(i + 3, j + 5, k + 3, Blocks.air, 0, 2);
        world.setBlock(i + 4, j + 5, k + 3, Blocks.air, 0, 2);
        world.setBlock(i + 5, j + 5, k + 3, Blocks.air, 0, 2);
        world.setBlock(i + 6, j + 5, k + 3, Blocks.air, 0, 2);
        world.setBlock(i + 7, j + 5, k + 3, Blocks.air, 0, 2);
        world.setBlock(i + 8, j + 5, k + 3, Blocks.air, 0, 2);
        world.setBlock(i + 9, j + 5, k + 3, Blocks.air, 0, 2);
        world.setBlock(i + 10, j + 5, k + 3, Blocks.air, 0, 2);
        world.setBlock(i + 11, j + 5, k + 3, Blocks.air, 0, 2);
        world.setBlock(i + 12, j + 5, k + 3, Blocks.air, 0, 2);
        world.setBlock(i + 13, j + 5, k + 3, Blocks.air, 0, 2);
        world.setBlock(i + 14, j + 5, k + 3, Blocks.air, 0, 2);
        world.setBlock(i + 15, j + 5, k + 3, Blocks.air, 0, 2);
        world.setBlock(i + 16, j + 5, k + 3, Blocks.planks, 5, 2);
        world.setBlock(i + 0, j + 5, k + 4, Blocks.log2, 5, 2);
        world.setBlock(i + 1, j + 5, k + 4, Blocks.air, 0, 2);
        world.setBlock(i + 2, j + 5, k + 4, Blocks.air, 0, 2);
        world.setBlock(i + 3, j + 5, k + 4, Blocks.air, 0, 2);
        world.setBlock(i + 4, j + 5, k + 4, Blocks.air, 0, 2);
        world.setBlock(i + 5, j + 5, k + 4, Blocks.air, 0, 2);
        world.setBlock(i + 6, j + 5, k + 4, Blocks.air, 0, 2);
        world.setBlock(i + 7, j + 5, k + 4, Blocks.air, 0, 2);
        world.setBlock(i + 8, j + 5, k + 4, Blocks.air, 0, 2);
        world.setBlock(i + 9, j + 5, k + 4, Blocks.air, 0, 2);
        world.setBlock(i + 10, j + 5, k + 4, Blocks.air, 0, 2);
        world.setBlock(i + 11, j + 5, k + 4, Blocks.air, 0, 2);
        world.setBlock(i + 12, j + 5, k + 4, Blocks.air, 0, 2);
        world.setBlock(i + 13, j + 5, k + 4, Blocks.air, 0, 2);
        world.setBlock(i + 14, j + 5, k + 4, Blocks.air, 0, 2);
        world.setBlock(i + 15, j + 5, k + 4, Blocks.dark_oak_stairs, 2, 2);
        world.setBlock(i + 16, j + 5, k + 4, Blocks.log2, 5, 2);
        world.setBlock(i + 0, j + 5, k + 5, Blocks.planks, 5, 2);
        world.setBlock(i + 1, j + 5, k + 5, Blocks.air, 0, 2);
        world.setBlock(i + 2, j + 5, k + 5, Blocks.air, 0, 2);
        world.setBlock(i + 3, j + 5, k + 5, Blocks.air, 0, 2);
        world.setBlock(i + 4, j + 5, k + 5, Blocks.air, 0, 2);
        world.setBlock(i + 5, j + 5, k + 5, Blocks.air, 0, 2);
        world.setBlock(i + 6, j + 5, k + 5, Blocks.air, 0, 2);
        world.setBlock(i + 7, j + 5, k + 5, Blocks.air, 0, 2);
        world.setBlock(i + 8, j + 5, k + 5, Blocks.air, 0, 2);
        world.setBlock(i + 9, j + 5, k + 5, Blocks.air, 0, 2);
        world.setBlock(i + 10, j + 5, k + 5, Blocks.air, 0, 2);
        world.setBlock(i + 11, j + 5, k + 5, Blocks.air, 0, 2);
        world.setBlock(i + 12, j + 5, k + 5, Blocks.air, 0, 2);
        world.setBlock(i + 13, j + 5, k + 5, Blocks.air, 0, 2);
        world.setBlock(i + 14, j + 5, k + 5, Blocks.air, 0, 2);
        world.setBlock(i + 15, j + 5, k + 5, Blocks.planks, 5, 2);
        world.setBlock(i + 16, j + 5, k + 5, Blocks.planks, 5, 2);
        world.setBlock(i + 0, j + 5, k + 6, Blocks.planks, 5, 2);
        world.setBlock(i + 1, j + 5, k + 6, Blocks.air, 0, 2);
        world.setBlock(i + 2, j + 5, k + 6, Blocks.air, 0, 2);
        world.setBlock(i + 3, j + 5, k + 6, Blocks.air, 0, 2);
        world.setBlock(i + 4, j + 5, k + 6, Blocks.air, 0, 2);
        world.setBlock(i + 5, j + 5, k + 6, Blocks.air, 0, 2);
        world.setBlock(i + 6, j + 5, k + 6, Blocks.air, 0, 2);
        world.setBlock(i + 7, j + 5, k + 6, Blocks.air, 0, 2);
        world.setBlock(i + 8, j + 5, k + 6, Blocks.air, 0, 2);
        world.setBlock(i + 9, j + 5, k + 6, Blocks.air, 0, 2);
        world.setBlock(i + 10, j + 5, k + 6, Blocks.air, 0, 2);
        world.setBlock(i + 11, j + 5, k + 6, Blocks.air, 0, 2);
        world.setBlock(i + 12, j + 5, k + 6, Blocks.air, 0, 2);
        world.setBlock(i + 13, j + 5, k + 6, Blocks.air, 0, 2);
        world.setBlock(i + 14, j + 5, k + 6, Blocks.air, 0, 2);
        world.setBlock(i + 15, j + 5, k + 6, PlaceDarkOakFence, 0, 2);
        world.setBlock(i + 16, j + 5, k + 6, Blocks.planks, 5, 2);
        world.setBlock(i + 0, j + 5, k + 7, Blocks.planks, 5, 2);
        world.setBlock(i + 1, j + 5, k + 7, Blocks.air, 0, 2);
        world.setBlock(i + 2, j + 5, k + 7, Blocks.air, 0, 2);
        world.setBlock(i + 3, j + 5, k + 7, Blocks.air, 0, 2);
        world.setBlock(i + 4, j + 5, k + 7, Blocks.air, 0, 2);
        world.setBlock(i + 5, j + 5, k + 7, Blocks.air, 0, 2);
        world.setBlock(i + 6, j + 5, k + 7, Blocks.air, 0, 2);
        world.setBlock(i + 7, j + 5, k + 7, Blocks.air, 0, 2);
        world.setBlock(i + 8, j + 5, k + 7, Blocks.air, 0, 2);
        world.setBlock(i + 9, j + 5, k + 7, Blocks.air, 0, 2);
        world.setBlock(i + 10, j + 5, k + 7, Blocks.air, 0, 2);
        world.setBlock(i + 11, j + 5, k + 7, Blocks.air, 0, 2);
        world.setBlock(i + 12, j + 5, k + 7, Blocks.air, 0, 2);
        world.setBlock(i + 13, j + 5, k + 7, Blocks.air, 0, 2);
        world.setBlock(i + 14, j + 5, k + 7, Blocks.air, 0, 2);
        world.setBlock(i + 15, j + 5, k + 7, Blocks.air, 0, 2);
        world.setBlock(i + 16, j + 5, k + 7, Blocks.planks, 5, 2);
        world.setBlock(i + 0, j + 5, k + 8, Blocks.planks, 5, 2);
        world.setBlock(i + 1, j + 5, k + 8, Blocks.planks, 5, 2);
        world.setBlock(i + 2, j + 5, k + 8, Blocks.planks, 5, 2);
        world.setBlock(i + 3, j + 5, k + 8, Blocks.planks, 5, 2);
        world.setBlock(i + 4, j + 5, k + 8, Blocks.log2, 9, 2);
        world.setBlock(i + 5, j + 5, k + 8, Blocks.planks, 5, 2);
        world.setBlock(i + 6, j + 5, k + 8, Blocks.planks, 5, 2);
        world.setBlock(i + 7, j + 5, k + 8, Blocks.planks, 5, 2);
        world.setBlock(i + 8, j + 5, k + 8, Blocks.planks, 5, 2);
        world.setBlock(i + 9, j + 5, k + 8, Blocks.planks, 5, 2);
        world.setBlock(i + 10, j + 5, k + 8, Blocks.planks, 5, 2);
        world.setBlock(i + 11, j + 5, k + 8, Blocks.planks, 5, 2);
        world.setBlock(i + 12, j + 5, k + 8, Blocks.log2, 9, 2);
        world.setBlock(i + 13, j + 5, k + 8, Blocks.planks, 5, 2);
        world.setBlock(i + 14, j + 5, k + 8, Blocks.planks, 5, 2);
        world.setBlock(i + 15, j + 5, k + 8, Blocks.planks, 5, 2);
        world.setBlock(i + 16, j + 5, k + 8, Blocks.planks, 5, 2);
        world.setBlock(i + 0, j + 6, k + 0, Blocks.planks, 5, 2);
        world.setBlock(i + 1, j + 6, k + 0, Blocks.planks, 5, 2);
        world.setBlock(i + 2, j + 6, k + 0, Blocks.planks, 5, 2);
        world.setBlock(i + 3, j + 6, k + 0, Blocks.planks, 5, 2);
        world.setBlock(i + 4, j + 6, k + 0, Blocks.planks, 5, 2);
        world.setBlock(i + 5, j + 6, k + 0, Blocks.planks, 5, 2);
        world.setBlock(i + 6, j + 6, k + 0, Blocks.planks, 5, 2);
        world.setBlock(i + 7, j + 6, k + 0, Blocks.planks, 5, 2);
        world.setBlock(i + 8, j + 6, k + 0, Blocks.planks, 5, 2);
        world.setBlock(i + 9, j + 6, k + 0, Blocks.planks, 5, 2);
        world.setBlock(i + 10, j + 6, k + 0, Blocks.planks, 5, 2);
        world.setBlock(i + 11, j + 6, k + 0, Blocks.planks, 5, 2);
        world.setBlock(i + 12, j + 6, k + 0, Blocks.log2, 9, 2);
        world.setBlock(i + 13, j + 6, k + 0, Blocks.planks, 5, 2);
        world.setBlock(i + 14, j + 6, k + 0, Blocks.planks, 5, 2);
        world.setBlock(i + 15, j + 6, k + 0, Blocks.planks, 5, 2);
        world.setBlock(i + 16, j + 6, k + 0, Blocks.planks, 5, 2);
        world.setBlock(i + 0, j + 6, k + 1, Blocks.planks, 5, 2);
        world.setBlock(i + 1, j + 6, k + 1, Blocks.air, 0, 2);
        world.setBlock(i + 2, j + 6, k + 1, Blocks.air, 0, 2);
        world.setBlock(i + 3, j + 6, k + 1, Blocks.air, 0, 2);
        world.setBlock(i + 4, j + 6, k + 1, Blocks.air, 0, 2);
        world.setBlock(i + 5, j + 6, k + 1, Blocks.air, 0, 2);
        world.setBlock(i + 6, j + 6, k + 1, Blocks.air, 0, 2);
        world.setBlock(i + 7, j + 6, k + 1, Blocks.air, 0, 2);
        world.setBlock(i + 8, j + 6, k + 1, Blocks.air, 0, 2);
        world.setBlock(i + 9, j + 6, k + 1, Blocks.air, 0, 2);
        world.setBlock(i + 10, j + 6, k + 1, Blocks.air, 0, 2);
        world.setBlock(i + 11, j + 6, k + 1, Blocks.air, 0, 2);
        world.setBlock(i + 12, j + 6, k + 1, Blocks.air, 0, 2);
        world.setBlock(i + 13, j + 6, k + 1, Blocks.air, 0, 2);
        world.setBlock(i + 14, j + 6, k + 1, Blocks.air, 0, 2);
        world.setBlock(i + 15, j + 6, k + 1, Blocks.air, 0, 2);
        world.setBlock(i + 16, j + 6, k + 1, Blocks.planks, 5, 2);
        world.setBlock(i + 0, j + 6, k + 2, Blocks.planks, 5, 2);
        world.setBlock(i + 1, j + 6, k + 2, Blocks.air, 0, 2);
        world.setBlock(i + 2, j + 6, k + 2, Blocks.air, 0, 2);
        world.setBlock(i + 3, j + 6, k + 2, Blocks.air, 0, 2);
        world.setBlock(i + 4, j + 6, k + 2, Blocks.air, 0, 2);
        world.setBlock(i + 5, j + 6, k + 2, Blocks.air, 0, 2);
        world.setBlock(i + 6, j + 6, k + 2, Blocks.air, 0, 2);
        world.setBlock(i + 7, j + 6, k + 2, Blocks.air, 0, 2);
        world.setBlock(i + 8, j + 6, k + 2, Blocks.air, 0, 2);
        world.setBlock(i + 9, j + 6, k + 2, Blocks.air, 0, 2);
        world.setBlock(i + 10, j + 6, k + 2, Blocks.air, 0, 2);
        world.setBlock(i + 11, j + 6, k + 2, Blocks.air, 0, 2);
        world.setBlock(i + 12, j + 6, k + 2, Blocks.air, 0, 2);
        world.setBlock(i + 13, j + 6, k + 2, Blocks.air, 0, 2);
        world.setBlock(i + 14, j + 6, k + 2, Blocks.air, 0, 2);
        world.setBlock(i + 15, j + 6, k + 2, Blocks.air, 0, 2);
        world.setBlock(i + 16, j + 6, k + 2, Blocks.planks, 5, 2);
        world.setBlock(i + 0, j + 6, k + 3, Blocks.planks, 5, 2);
        world.setBlock(i + 1, j + 6, k + 3, Blocks.air, 0, 2);
        world.setBlock(i + 2, j + 6, k + 3, Blocks.air, 0, 2);
        world.setBlock(i + 3, j + 6, k + 3, Blocks.air, 0, 2);
        world.setBlock(i + 4, j + 6, k + 3, Blocks.air, 0, 2);
        world.setBlock(i + 5, j + 6, k + 3, Blocks.air, 0, 2);
        world.setBlock(i + 6, j + 6, k + 3, Blocks.air, 0, 2);
        world.setBlock(i + 7, j + 6, k + 3, Blocks.air, 0, 2);
        world.setBlock(i + 8, j + 6, k + 3, Blocks.air, 0, 2);
        world.setBlock(i + 9, j + 6, k + 3, Blocks.air, 0, 2);
        world.setBlock(i + 10, j + 6, k + 3, Blocks.air, 0, 2);
        world.setBlock(i + 11, j + 6, k + 3, Blocks.air, 0, 2);
        world.setBlock(i + 12, j + 6, k + 3, Blocks.air, 0, 2);
        world.setBlock(i + 13, j + 6, k + 3, Blocks.air, 0, 2);
        world.setBlock(i + 14, j + 6, k + 3, Blocks.air, 0, 2);
        world.setBlock(i + 15, j + 6, k + 3, Blocks.air, 0, 2);
        world.setBlock(i + 16, j + 6, k + 3, Blocks.planks, 5, 2);
        world.setBlock(i + 0, j + 6, k + 4, Blocks.log2, 5, 2);
        world.setBlock(i + 1, j + 6, k + 4, Blocks.air, 0, 2);
        world.setBlock(i + 2, j + 6, k + 4, Blocks.air, 0, 2);
        world.setBlock(i + 3, j + 6, k + 4, Blocks.air, 0, 2);
        world.setBlock(i + 4, j + 6, k + 4, Blocks.air, 0, 2);
        world.setBlock(i + 5, j + 6, k + 4, Blocks.air, 0, 2);
        world.setBlock(i + 6, j + 6, k + 4, Blocks.air, 0, 2);
        world.setBlock(i + 7, j + 6, k + 4, Blocks.air, 0, 2);
        world.setBlock(i + 8, j + 6, k + 4, Blocks.air, 0, 2);
        world.setBlock(i + 9, j + 6, k + 4, Blocks.air, 0, 2);
        world.setBlock(i + 10, j + 6, k + 4, Blocks.air, 0, 2);
        world.setBlock(i + 11, j + 6, k + 4, Blocks.air, 0, 2);
        world.setBlock(i + 12, j + 6, k + 4, Blocks.air, 0, 2);
        world.setBlock(i + 13, j + 6, k + 4, Blocks.air, 0, 2);
        world.setBlock(i + 14, j + 6, k + 4, Blocks.air, 0, 2);
        world.setBlock(i + 15, j + 6, k + 4, Blocks.air, 0, 2);
        world.setBlock(i + 16, j + 6, k + 4, Blocks.log2, 5, 2);
        world.setBlock(i + 0, j + 6, k + 5, Blocks.planks, 5, 2);
        world.setBlock(i + 1, j + 6, k + 5, Blocks.air, 0, 2);
        world.setBlock(i + 2, j + 6, k + 5, Blocks.air, 0, 2);
        world.setBlock(i + 3, j + 6, k + 5, Blocks.air, 0, 2);
        world.setBlock(i + 4, j + 6, k + 5, Blocks.air, 0, 2);
        world.setBlock(i + 5, j + 6, k + 5, Blocks.air, 0, 2);
        world.setBlock(i + 6, j + 6, k + 5, Blocks.air, 0, 2);
        world.setBlock(i + 7, j + 6, k + 5, Blocks.air, 0, 2);
        world.setBlock(i + 8, j + 6, k + 5, Blocks.air, 0, 2);
        world.setBlock(i + 9, j + 6, k + 5, Blocks.air, 0, 2);
        world.setBlock(i + 10, j + 6, k + 5, Blocks.air, 0, 2);
        world.setBlock(i + 11, j + 6, k + 5, Blocks.air, 0, 2);
        world.setBlock(i + 12, j + 6, k + 5, Blocks.air, 0, 2);
        world.setBlock(i + 13, j + 6, k + 5, Blocks.air, 0, 2);
        world.setBlock(i + 14, j + 6, k + 5, Blocks.air, 0, 2);
        world.setBlock(i + 15, j + 6, k + 5, Blocks.dark_oak_stairs, 2, 2);
        world.setBlock(i + 16, j + 6, k + 5, Blocks.planks, 5, 2);
        world.setBlock(i + 0, j + 6, k + 6, Blocks.planks, 5, 2);
        world.setBlock(i + 1, j + 6, k + 6, Blocks.air, 0, 2);
        world.setBlock(i + 2, j + 6, k + 6, Blocks.air, 0, 2);
        world.setBlock(i + 3, j + 6, k + 6, Blocks.air, 0, 2);
        world.setBlock(i + 4, j + 6, k + 6, Blocks.air, 0, 2);
        world.setBlock(i + 5, j + 6, k + 6, Blocks.air, 0, 2);
        world.setBlock(i + 6, j + 6, k + 6, Blocks.air, 0, 2);
        world.setBlock(i + 7, j + 6, k + 6, Blocks.air, 0, 2);
        world.setBlock(i + 8, j + 6, k + 6, Blocks.air, 0, 2);
        world.setBlock(i + 9, j + 6, k + 6, Blocks.air, 0, 2);
        world.setBlock(i + 10, j + 6, k + 6, Blocks.air, 0, 2);
        world.setBlock(i + 11, j + 6, k + 6, Blocks.air, 0, 2);
        world.setBlock(i + 12, j + 6, k + 6, Blocks.air, 0, 2);
        world.setBlock(i + 13, j + 6, k + 6, Blocks.air, 0, 2);
        world.setBlock(i + 14, j + 6, k + 6, Blocks.air, 0, 2);
        world.setBlock(i + 15, j + 6, k + 6, Blocks.planks, 5, 2);
        world.setBlock(i + 16, j + 6, k + 6, Blocks.planks, 5, 2);
        world.setBlock(i + 0, j + 6, k + 7, Blocks.planks, 5, 2);
        world.setBlock(i + 1, j + 6, k + 7, Blocks.air, 0, 2);
        world.setBlock(i + 2, j + 6, k + 7, Blocks.air, 0, 2);
        world.setBlock(i + 3, j + 6, k + 7, Blocks.air, 0, 2);
        world.setBlock(i + 4, j + 6, k + 7, Blocks.air, 0, 2);
        world.setBlock(i + 5, j + 6, k + 7, Blocks.air, 0, 2);
        world.setBlock(i + 6, j + 6, k + 7, Blocks.air, 0, 2);
        world.setBlock(i + 7, j + 6, k + 7, Blocks.air, 0, 2);
        world.setBlock(i + 8, j + 6, k + 7, Blocks.air, 0, 2);
        world.setBlock(i + 9, j + 6, k + 7, Blocks.air, 0, 2);
        world.setBlock(i + 10, j + 6, k + 7, Blocks.air, 0, 2);
        world.setBlock(i + 11, j + 6, k + 7, Blocks.air, 0, 2);
        world.setBlock(i + 12, j + 6, k + 7, Blocks.air, 0, 2);
        world.setBlock(i + 13, j + 6, k + 7, Blocks.air, 0, 2);
        world.setBlock(i + 14, j + 6, k + 7, Blocks.air, 0, 2);
        world.setBlock(i + 15, j + 6, k + 7, PlaceDarkOakFence, 0, 2);
        world.setBlock(i + 16, j + 6, k + 7, Blocks.planks, 5, 2);
        world.setBlock(i + 0, j + 6, k + 8, Blocks.planks, 5, 2);
        world.setBlock(i + 1, j + 6, k + 8, Blocks.planks, 5, 2);
        world.setBlock(i + 2, j + 6, k + 8, Blocks.planks, 5, 2);
        world.setBlock(i + 3, j + 6, k + 8, Blocks.planks, 5, 2);
        world.setBlock(i + 4, j + 6, k + 8, Blocks.log2, 9, 2);
        world.setBlock(i + 5, j + 6, k + 8, Blocks.planks, 5, 2);
        world.setBlock(i + 6, j + 6, k + 8, Blocks.planks, 5, 2);
        world.setBlock(i + 7, j + 6, k + 8, Blocks.planks, 5, 2);
        world.setBlock(i + 8, j + 6, k + 8, Blocks.planks, 5, 2);
        world.setBlock(i + 9, j + 6, k + 8, Blocks.planks, 5, 2);
        world.setBlock(i + 10, j + 6, k + 8, Blocks.planks, 5, 2);
        world.setBlock(i + 11, j + 6, k + 8, Blocks.planks, 5, 2);
        world.setBlock(i + 12, j + 6, k + 8, Blocks.log2, 9, 2);
        world.setBlock(i + 13, j + 6, k + 8, Blocks.planks, 5, 2);
        world.setBlock(i + 14, j + 6, k + 8, Blocks.planks, 5, 2);
        world.setBlock(i + 15, j + 6, k + 8, Blocks.planks, 5, 2);
        world.setBlock(i + 16, j + 6, k + 8, Blocks.planks, 5, 2);
        world.setBlock(i + 0, j + 7, k + 0, Blocks.planks, 5, 2);
        world.setBlock(i + 1, j + 7, k + 0, Blocks.planks, 5, 2);
        world.setBlock(i + 2, j + 7, k + 0, Blocks.planks, 5, 2);
        world.setBlock(i + 3, j + 7, k + 0, Blocks.planks, 5, 2);
        world.setBlock(i + 4, j + 7, k + 0, Blocks.planks, 5, 2);
        world.setBlock(i + 5, j + 7, k + 0, Blocks.planks, 5, 2);
        world.setBlock(i + 6, j + 7, k + 0, Blocks.planks, 5, 2);
        world.setBlock(i + 7, j + 7, k + 0, Blocks.planks, 5, 2);
        world.setBlock(i + 8, j + 7, k + 0, Blocks.planks, 5, 2);
        world.setBlock(i + 9, j + 7, k + 0, Blocks.planks, 5, 2);
        world.setBlock(i + 10, j + 7, k + 0, Blocks.planks, 5, 2);
        world.setBlock(i + 11, j + 7, k + 0, Blocks.planks, 5, 2);
        world.setBlock(i + 12, j + 7, k + 0, Blocks.planks, 5, 2);
        world.setBlock(i + 13, j + 7, k + 0, Blocks.planks, 5, 2);
        world.setBlock(i + 14, j + 7, k + 0, Blocks.planks, 5, 2);
        world.setBlock(i + 15, j + 7, k + 0, Blocks.planks, 5, 2);
        world.setBlock(i + 16, j + 7, k + 0, Blocks.planks, 5, 2);
        world.setBlock(i + 0, j + 7, k + 1, Blocks.planks, 5, 2);
        world.setBlock(i + 1, j + 7, k + 1, Blocks.air, 0, 2);
        world.setBlock(i + 2, j + 7, k + 1, Blocks.air, 0, 2);
        world.setBlock(i + 3, j + 7, k + 1, Blocks.air, 0, 2);
        world.setBlock(i + 4, j + 7, k + 1, Blocks.air, 0, 2);
        world.setBlock(i + 5, j + 7, k + 1, Blocks.air, 0, 2);
        world.setBlock(i + 6, j + 7, k + 1, Blocks.air, 0, 2);
        world.setBlock(i + 7, j + 7, k + 1, Blocks.air, 0, 2);
        world.setBlock(i + 8, j + 7, k + 1, Blocks.air, 0, 2);
        world.setBlock(i + 9, j + 7, k + 1, Blocks.air, 0, 2);
        world.setBlock(i + 10, j + 7, k + 1, Blocks.air, 0, 2);
        world.setBlock(i + 11, j + 7, k + 1, Blocks.air, 0, 2);
        world.setBlock(i + 12, j + 7, k + 1, Blocks.air, 0, 2);
        world.setBlock(i + 13, j + 7, k + 1, Blocks.air, 0, 2);
        world.setBlock(i + 14, j + 7, k + 1, Blocks.air, 0, 2);
        world.setBlock(i + 15, j + 7, k + 1, Blocks.air, 0, 2);
        world.setBlock(i + 16, j + 7, k + 1, Blocks.planks, 5, 2);
        world.setBlock(i + 0, j + 7, k + 2, Blocks.planks, 5, 2);
        world.setBlock(i + 1, j + 7, k + 2, Blocks.air, 0, 2);
        world.setBlock(i + 2, j + 7, k + 2, Blocks.air, 0, 2);
        world.setBlock(i + 3, j + 7, k + 2, Blocks.air, 0, 2);
        world.setBlock(i + 4, j + 7, k + 2, Blocks.air, 0, 2);
        world.setBlock(i + 5, j + 7, k + 2, Blocks.air, 0, 2);
        world.setBlock(i + 6, j + 7, k + 2, Blocks.air, 0, 2);
        world.setBlock(i + 7, j + 7, k + 2, Blocks.air, 0, 2);
        world.setBlock(i + 8, j + 7, k + 2, Blocks.air, 0, 2);
        world.setBlock(i + 9, j + 7, k + 2, Blocks.air, 0, 2);
        world.setBlock(i + 10, j + 7, k + 2, Blocks.air, 0, 2);
        world.setBlock(i + 11, j + 7, k + 2, Blocks.air, 0, 2);
        world.setBlock(i + 12, j + 7, k + 2, Blocks.air, 0, 2);
        world.setBlock(i + 13, j + 7, k + 2, Blocks.air, 0, 2);
        world.setBlock(i + 14, j + 7, k + 2, Blocks.air, 0, 2);
        world.setBlock(i + 15, j + 7, k + 2, Blocks.air, 0, 2);
        world.setBlock(i + 16, j + 7, k + 2, Blocks.planks, 5, 2);
        world.setBlock(i + 0, j + 7, k + 3, Blocks.planks, 5, 2);
        world.setBlock(i + 1, j + 7, k + 3, Blocks.air, 0, 2);
        world.setBlock(i + 2, j + 7, k + 3, Blocks.air, 0, 2);
        world.setBlock(i + 3, j + 7, k + 3, Blocks.air, 0, 2);
        world.setBlock(i + 4, j + 7, k + 3, Blocks.air, 0, 2);
        world.setBlock(i + 5, j + 7, k + 3, Blocks.air, 0, 2);
        world.setBlock(i + 6, j + 7, k + 3, Blocks.air, 0, 2);
        world.setBlock(i + 7, j + 7, k + 3, Blocks.air, 0, 2);
        world.setBlock(i + 8, j + 7, k + 3, Blocks.air, 0, 2);
        world.setBlock(i + 9, j + 7, k + 3, Blocks.air, 0, 2);
        world.setBlock(i + 10, j + 7, k + 3, Blocks.air, 0, 2);
        world.setBlock(i + 11, j + 7, k + 3, Blocks.air, 0, 2);
        world.setBlock(i + 12, j + 7, k + 3, Blocks.air, 0, 2);
        world.setBlock(i + 13, j + 7, k + 3, Blocks.air, 0, 2);
        world.setBlock(i + 14, j + 7, k + 3, Blocks.air, 0, 2);
        world.setBlock(i + 15, j + 7, k + 3, Blocks.air, 0, 2);
        world.setBlock(i + 16, j + 7, k + 3, Blocks.planks, 5, 2);
        world.setBlock(i + 0, j + 7, k + 4, Blocks.planks, 5, 2);
        world.setBlock(i + 1, j + 7, k + 4, Blocks.air, 0, 2);
        world.setBlock(i + 2, j + 7, k + 4, Blocks.air, 0, 2);
        world.setBlock(i + 3, j + 7, k + 4, Blocks.air, 0, 2);
        world.setBlock(i + 4, j + 7, k + 4, Blocks.air, 0, 2);
        world.setBlock(i + 5, j + 7, k + 4, Blocks.air, 0, 2);
        world.setBlock(i + 6, j + 7, k + 4, Blocks.air, 0, 2);
        world.setBlock(i + 7, j + 7, k + 4, Blocks.air, 0, 2);
        world.setBlock(i + 8, j + 7, k + 4, Blocks.air, 0, 2);
        world.setBlock(i + 9, j + 7, k + 4, Blocks.air, 0, 2);
        world.setBlock(i + 10, j + 7, k + 4, Blocks.air, 0, 2);
        world.setBlock(i + 11, j + 7, k + 4, Blocks.air, 0, 2);
        world.setBlock(i + 12, j + 7, k + 4, Blocks.air, 0, 2);
        world.setBlock(i + 13, j + 7, k + 4, Blocks.air, 0, 2);
        world.setBlock(i + 14, j + 7, k + 4, Blocks.air, 0, 2);
        world.setBlock(i + 15, j + 7, k + 4, Blocks.air, 0, 2);
        world.setBlock(i + 16, j + 7, k + 4, Blocks.planks, 5, 2);
        world.setBlock(i + 0, j + 7, k + 5, Blocks.planks, 5, 2);
        world.setBlock(i + 1, j + 7, k + 5, Blocks.air, 0, 2);
        world.setBlock(i + 2, j + 7, k + 5, Blocks.air, 0, 2);
        world.setBlock(i + 3, j + 7, k + 5, Blocks.air, 0, 2);
        world.setBlock(i + 4, j + 7, k + 5, Blocks.air, 0, 2);
        world.setBlock(i + 5, j + 7, k + 5, Blocks.air, 0, 2);
        world.setBlock(i + 6, j + 7, k + 5, Blocks.air, 0, 2);
        world.setBlock(i + 7, j + 7, k + 5, Blocks.air, 0, 2);
        world.setBlock(i + 8, j + 7, k + 5, Blocks.air, 0, 2);
        world.setBlock(i + 9, j + 7, k + 5, Blocks.air, 0, 2);
        world.setBlock(i + 10, j + 7, k + 5, Blocks.air, 0, 2);
        world.setBlock(i + 11, j + 7, k + 5, Blocks.air, 0, 2);
        world.setBlock(i + 12, j + 7, k + 5, Blocks.air, 0, 2);
        world.setBlock(i + 13, j + 7, k + 5, Blocks.air, 0, 2);
        world.setBlock(i + 14, j + 7, k + 5, Blocks.air, 0, 2);
        world.setBlock(i + 15, j + 7, k + 5, Blocks.air, 0, 2);
        world.setBlock(i + 16, j + 7, k + 5, Blocks.planks, 5, 2);
        world.setBlock(i + 0, j + 7, k + 6, Blocks.planks, 5, 2);
        world.setBlock(i + 1, j + 7, k + 6, Blocks.air, 0, 2);
        world.setBlock(i + 2, j + 7, k + 6, Blocks.air, 0, 2);
        world.setBlock(i + 3, j + 7, k + 6, Blocks.air, 0, 2);
        world.setBlock(i + 4, j + 7, k + 6, Blocks.air, 0, 2);
        world.setBlock(i + 5, j + 7, k + 6, Blocks.air, 0, 2);
        world.setBlock(i + 6, j + 7, k + 6, Blocks.air, 0, 2);
        world.setBlock(i + 7, j + 7, k + 6, Blocks.air, 0, 2);
        world.setBlock(i + 8, j + 7, k + 6, Blocks.air, 0, 2);
        world.setBlock(i + 9, j + 7, k + 6, Blocks.air, 0, 2);
        world.setBlock(i + 10, j + 7, k + 6, Blocks.air, 0, 2);
        world.setBlock(i + 11, j + 7, k + 6, Blocks.air, 0, 2);
        world.setBlock(i + 12, j + 7, k + 6, Blocks.air, 0, 2);
        world.setBlock(i + 13, j + 7, k + 6, Blocks.air, 0, 2);
        world.setBlock(i + 14, j + 7, k + 6, Blocks.air, 0, 2);
        world.setBlock(i + 15, j + 7, k + 6, Blocks.dark_oak_stairs, 2, 2);
        world.setBlock(i + 16, j + 7, k + 6, Blocks.planks, 5, 2);
        world.setBlock(i + 0, j + 7, k + 7, Blocks.planks, 5, 2);
        world.setBlock(i + 1, j + 7, k + 7, Blocks.air, 0, 2);
        world.setBlock(i + 2, j + 7, k + 7, Blocks.air, 0, 2);
        world.setBlock(i + 3, j + 7, k + 7, Blocks.air, 0, 2);
        world.setBlock(i + 4, j + 7, k + 7, Blocks.air, 0, 2);
        world.setBlock(i + 5, j + 7, k + 7, Blocks.air, 0, 2);
        world.setBlock(i + 6, j + 7, k + 7, Blocks.air, 0, 2);
        world.setBlock(i + 7, j + 7, k + 7, Blocks.air, 0, 2);
        world.setBlock(i + 8, j + 7, k + 7, Blocks.air, 0, 2);
        world.setBlock(i + 9, j + 7, k + 7, Blocks.air, 0, 2);
        world.setBlock(i + 10, j + 7, k + 7, Blocks.air, 0, 2);
        world.setBlock(i + 11, j + 7, k + 7, Blocks.air, 0, 2);
        world.setBlock(i + 12, j + 7, k + 7, Blocks.air, 0, 2);
        world.setBlock(i + 13, j + 7, k + 7, Blocks.air, 0, 2);
        world.setBlock(i + 14, j + 7, k + 7, Blocks.air, 0, 2);
        world.setBlock(i + 15, j + 7, k + 7, Blocks.planks, 5, 2);
        world.setBlock(i + 16, j + 7, k + 7, Blocks.planks, 5, 2);
        world.setBlock(i + 0, j + 7, k + 8, Blocks.planks, 5, 2);
        world.setBlock(i + 1, j + 7, k + 8, Blocks.planks, 5, 2);
        world.setBlock(i + 2, j + 7, k + 8, Blocks.planks, 5, 2);
        world.setBlock(i + 3, j + 7, k + 8, Blocks.planks, 5, 2);
        world.setBlock(i + 4, j + 7, k + 8, Blocks.planks, 5, 2);
        world.setBlock(i + 5, j + 7, k + 8, Blocks.planks, 5, 2);
        world.setBlock(i + 6, j + 7, k + 8, Blocks.planks, 5, 2);
        world.setBlock(i + 7, j + 7, k + 8, Blocks.planks, 5, 2);
        world.setBlock(i + 8, j + 7, k + 8, Blocks.planks, 5, 2);
        world.setBlock(i + 9, j + 7, k + 8, Blocks.planks, 5, 2);
        world.setBlock(i + 10, j + 7, k + 8, Blocks.planks, 5, 2);
        world.setBlock(i + 11, j + 7, k + 8, Blocks.planks, 5, 2);
        world.setBlock(i + 12, j + 7, k + 8, Blocks.planks, 5, 2);
        world.setBlock(i + 13, j + 7, k + 8, Blocks.planks, 5, 2);
        world.setBlock(i + 14, j + 7, k + 8, Blocks.planks, 5, 2);
        world.setBlock(i + 15, j + 7, k + 8, Blocks.planks, 5, 2);
        world.setBlock(i + 16, j + 7, k + 8, Blocks.planks, 5, 2);

        return true;
    }
}
