package com.NovaCraft.world.mansion;


import com.NovaCraft.Items.NovaCraftItems;
import com.NovaCraftBlocks.NovaCraftBlocks;
import net.minecraft.block.Block;
import net.minecraft.init.Blocks;
import net.minecraft.init.Items;
import net.minecraft.item.ItemStack;
import net.minecraft.tileentity.TileEntity;
import net.minecraft.tileentity.TileEntityChest;
import net.minecraft.world.World;
import net.minecraft.world.gen.feature.WorldGenerator;

import java.util.Random;

public class MansionBasementStairsGen extends WorldGenerator {

    public MansionBasementStairsGen() {

    }

    @Override
    public boolean generate(final World world, final Random random, final int i, final int j, final int k) {

        world.setBlock(i, j, k, placeStoneBricks(random), 0, 2);
        world.setBlock(i + 1, j, k, placeStoneBricks(random), 0, 2);
        world.setBlock(i + 2, j, k, placeStoneBricks(random), 0, 2);
        world.setBlock(i + 3, j, k, placeStoneBricks(random), 0, 2);
        world.setBlock(i + 4, j, k, placeStoneBricks(random), 0, 2);
        world.setBlock(i, j, k + 1, placeStoneBricks(random), 0, 2);
        world.setBlock(i + 1, j, k + 1, placeStoneBricks(random), 0, 2);
        world.setBlock(i + 2, j, k + 1, placeStoneBricks(random), 0, 2);
        world.setBlock(i + 3, j, k + 1, placeStoneBricks(random), 0, 2);
        world.setBlock(i + 4, j, k + 1, placeStoneBricks(random), 0, 2);
        world.setBlock(i, j, k + 2, placeStoneBricks(random), 0, 2);
        world.setBlock(i + 1, j, k + 2, placeStoneBricks(random), 0, 2);
        world.setBlock(i + 2, j, k + 2, placeStoneBricks(random), 0, 2);
        world.setBlock(i + 3, j, k + 2, placeStoneBricks(random), 0, 2);
        world.setBlock(i + 4, j, k + 2, placeStoneBricks(random), 0, 2);
        world.setBlock(i, j, k + 3, placeStoneBricks(random), 0, 2);
        world.setBlock(i + 1, j, k + 3, placeStoneBricks(random), 0, 2);
        world.setBlock(i + 2, j, k + 3, placeStoneBricks(random), 0, 2);
        world.setBlock(i + 3, j, k + 3, placeStoneBricks(random), 0, 2);
        world.setBlock(i + 4, j, k + 3, placeStoneBricks(random), 0, 2);
        world.setBlock(i, j, k + 4, placeStoneBricks(random), 0, 2);
        world.setBlock(i + 1, j, k + 4, placeStoneBricks(random), 0, 2);
        world.setBlock(i + 2, j, k + 4, placeStoneBricks(random), 0, 2);
        world.setBlock(i + 3, j, k + 4, placeStoneBricks(random), 0, 2);
        world.setBlock(i + 4, j, k + 4, placeStoneBricks(random), 0, 2);
        world.setBlock(i, j, k + 5, placeStoneBricks(random), 0, 2);
        world.setBlock(i + 1, j, k + 5, placeStoneBricks(random), 0, 2);
        world.setBlock(i + 2, j, k + 5, placeStoneBricks(random), 0, 2);
        world.setBlock(i + 3, j, k + 5, placeStoneBricks(random), 0, 2);
        world.setBlock(i + 4, j, k + 5, placeStoneBricks(random), 0, 2);
        world.setBlock(i, j, k + 6, placeStoneBricks(random), 0, 2);
        world.setBlock(i + 1, j, k + 6, placeStoneBricks(random), 0, 2);
        world.setBlock(i + 2, j, k + 6, placeStoneBricks(random), 0, 2);
        world.setBlock(i + 3, j, k + 6, placeStoneBricks(random), 0, 2);
        world.setBlock(i + 4, j, k + 6, placeStoneBricks(random), 0, 2);
        world.setBlock(i, j, k + 7, placeStoneBricks(random), 0, 2);
        world.setBlock(i + 1, j, k + 7, placeStoneBricks(random), 0, 2);
        world.setBlock(i + 2, j, k + 7, placeStoneBricks(random), 0, 2);
        world.setBlock(i + 3, j, k + 7, placeStoneBricks(random), 0, 2);
        world.setBlock(i + 4, j, k + 7, placeStoneBricks(random), 0, 2);
        world.setBlock(i, j + 1, k, placeStoneBricks(random), 0, 2);
        world.setBlock(i + 1, j + 1, k, placeStoneBricks(random), 0, 2);
        world.setBlock(i + 2, j + 1, k, placeStoneBricks(random), 0, 2);
        world.setBlock(i + 3, j + 1, k, placeStoneBricks(random), 0, 2);
        world.setBlock(i + 4, j + 1, k, placeStoneBricks(random), 0, 2);
        world.setBlock(i, j + 1, k + 1, placeStoneBricks(random), 0, 2);
        world.setBlock(i + 1, j + 1, k + 1, placeStoneBricks(random), 0, 2);
        world.setBlock(i + 2, j + 1, k + 1, placeStoneBricks(random), 0, 2);
        world.setBlock(i + 3, j + 1, k + 1, placeStoneBricks(random), 0, 2);
        world.setBlock(i + 4, j + 1, k + 1, placeStoneBricks(random), 0, 2);
        world.setBlock(i, j + 1, k + 2, placeStoneBricks(random), 0, 2);
        world.setBlock(i + 1, j + 1, k + 2, placeStoneBricks(random), 0, 2);
        world.setBlock(i + 2, j + 1, k + 2, NovaCraftBlocks.luminant_log, 0, 2);
        world.setBlock(i + 4, j + 1, k + 2, placeStoneBricks(random), 0, 2);
        world.setBlock(i, j + 1, k + 3, Blocks.air, 0, 2);
        world.setBlock(i + 1, j + 1, k + 3, NovaCraftBlocks.luminant_stairs, 3, 2);
        world.setBlock(i + 2, j + 1, k + 3, NovaCraftBlocks.luminant_log, 0, 2);
        world.setBlock(i + 3, j + 1, k + 3, Blocks.air, 0, 2);
        world.setBlock(i + 4, j + 1, k + 3, Blocks.air, 0, 2);
        world.setBlock(i, j + 1, k + 4, Blocks.air, 0, 2);
        world.setBlock(i + 1, j + 1, k + 4, Blocks.air, 0, 2);
        world.setBlock(i + 2, j + 1, k + 4, Blocks.air, 0, 2);
        world.setBlock(i + 3, j + 1, k + 4, Blocks.air, 0, 2);
        world.setBlock(i + 4, j + 1, k + 4, Blocks.air, 0, 2);
        world.setBlock(i, j + 1, k + 5, placeStoneBricks(random), 0, 2);
        world.setBlock(i + 1, j + 1, k + 5, Blocks.air, 0, 2);
        world.setBlock(i + 2, j + 1, k + 5, Blocks.air, 0, 2);
        world.setBlock(i + 3, j + 1, k + 5, Blocks.air, 0, 2);
        world.setBlock(i + 4, j + 1, k + 5, placeStoneBricks(random), 0, 2);
        world.setBlock(i, j + 1, k + 6, placeStoneBricks(random), 0, 2);
        world.setBlock(i + 1, j + 1, k + 6, Blocks.air, 0, 2);
        world.setBlock(i + 2, j + 1, k + 6, Blocks.air, 0, 2);
        world.setBlock(i + 3, j + 1, k + 6, Blocks.air, 0, 2);
        world.setBlock(i + 4, j + 1, k + 6, placeStoneBricks(random), 0, 2);
        world.setBlock(i, j + 1, k + 7, placeStoneBricks(random), 0, 2);
        world.setBlock(i + 1, j + 1, k + 7, placeStoneBricks(random), 0, 2);
        world.setBlock(i + 2, j + 1, k + 7, placeStoneBricks(random), 0, 2);
        world.setBlock(i + 3, j + 1, k + 7, placeStoneBricks(random), 0, 2);
        world.setBlock(i + 4, j + 1, k + 7, placeStoneBricks(random), 0, 2);
        world.setBlock(i, j + 2, k, placeStoneBricks(random), 0, 2);
        world.setBlock(i + 1, j + 2, k, placeStoneBricks(random), 0, 2);
        world.setBlock(i + 2, j + 2, k, placeStoneBricks(random), 0, 2);
        world.setBlock(i + 3, j + 2, k, placeStoneBricks(random), 0, 2);
        world.setBlock(i + 4, j + 2, k, placeStoneBricks(random), 0, 2);
        world.setBlock(i, j + 2, k + 1, placeStoneBricks(random), 0, 2);
        world.setBlock(i + 1, j + 2, k + 1, placeStoneBricks(random), 0, 2);
        world.setBlock(i + 2, j + 2, k + 1, placeStoneBricks(random), 0, 2);
        world.setBlock(i + 3, j + 2, k + 1, placeStoneBricks(random), 0, 2);
        world.setBlock(i + 4, j + 2, k + 1, placeStoneBricks(random), 0, 2);
        world.setBlock(i, j + 2, k + 2, placeStoneBricks(random), 0, 2);
        world.setBlock(i + 1, j + 2, k + 2, NovaCraftBlocks.luminant_stairs, 3, 2);
        world.setBlock(i + 2, j + 2, k + 2, NovaCraftBlocks.luminant_log, 0, 2);
        world.setBlock(i + 3, j + 2, k + 2, Blocks.air, 0, 2);
        world.setBlock(i + 4, j + 2, k + 2, placeStoneBricks(random), 0, 2);
        world.setBlock(i, j + 2, k + 3, Blocks.air, 0, 2);
        world.setBlock(i + 1, j + 2, k + 3, Blocks.air, 0, 2);
        world.setBlock(i + 2, j + 2, k + 3, NovaCraftBlocks.luminant_log, 0, 2);
        world.setBlock(i + 3, j + 2, k + 3, Blocks.air, 0, 2);
        world.setBlock(i + 4, j + 2, k + 3, Blocks.air, 0, 2);
        world.setBlock(i, j + 2, k + 4, Blocks.air, 0, 2);
        world.setBlock(i + 1, j + 2, k + 4, Blocks.air, 0, 2);
        world.setBlock(i + 2, j + 2, k + 4, Blocks.air, 0, 2);
        world.setBlock(i + 3, j + 2, k + 4, Blocks.air, 0, 2);
        world.setBlock(i + 4, j + 2, k + 4, Blocks.air, 0, 2);
        world.setBlock(i, j + 2, k + 5, placeStoneBricks(random), 0, 2);
        world.setBlock(i + 1, j + 2, k + 5, Blocks.air, 0, 2);
        world.setBlock(i + 2, j + 2, k + 5, Blocks.air, 0, 2);
        world.setBlock(i + 3, j + 2, k + 5, Blocks.air, 0, 2);
        world.setBlock(i + 4, j + 2, k + 5, placeStoneBricks(random), 0, 2);
        world.setBlock(i, j + 2, k + 6, placeStoneBricks(random), 0, 2);
        world.setBlock(i + 1, j + 2, k + 6, Blocks.air, 0, 2);
        world.setBlock(i + 3, j + 2, k + 6, Blocks.air, 0, 2);
        world.setBlock(i + 4, j + 2, k + 6, placeStoneBricks(random), 0, 2);
        world.setBlock(i, j + 2, k + 7, placeStoneBricks(random), 0, 2);
        world.setBlock(i + 1, j + 2, k + 7, placeStoneBricks(random), 0, 2);
        world.setBlock(i + 2, j + 2, k + 7, placeStoneBricks(random), 0, 2);
        world.setBlock(i + 3, j + 2, k + 7, placeStoneBricks(random), 0, 2);
        world.setBlock(i + 4, j + 2, k + 7, placeStoneBricks(random), 0, 2);
        world.setBlock(i, j + 3, k, placeStoneBricks(random), 0, 2);
        world.setBlock(i + 1, j + 3, k, placeStoneBricks(random), 0, 2);
        world.setBlock(i + 2, j + 3, k, placeStoneBricks(random), 0, 2);
        world.setBlock(i + 3, j + 3, k, placeStoneBricks(random), 0, 2);
        world.setBlock(i + 4, j + 3, k, placeStoneBricks(random), 0, 2);
        world.setBlock(i, j + 3, k + 1, placeStoneBricks(random), 0, 2);
        world.setBlock(i + 1, j + 3, k + 1, NovaCraftBlocks.luminant_stairs, 3, 2);
        world.setBlock(i + 2, j + 3, k + 1, placeStoneBricks(random), 0, 2);
        world.setBlock(i + 3, j + 3, k + 1, placeStoneBricks(random), 0, 2);
        world.setBlock(i + 4, j + 3, k + 1, placeStoneBricks(random), 0, 2);
        world.setBlock(i, j + 3, k + 2, placeStoneBricks(random), 0, 2);
        world.setBlock(i + 1, j + 3, k + 2, Blocks.air, 0, 2);
        world.setBlock(i + 2, j + 3, k + 2, NovaCraftBlocks.luminant_log, 0, 2);
        world.setBlock(i + 3, j + 3, k + 2, Blocks.air, 0, 2);
        world.setBlock(i + 4, j + 3, k + 2, placeStoneBricks(random), 0, 2);
        world.setBlock(i, j + 3, k + 3, Blocks.air, 0, 2);
        world.setBlock(i + 1, j + 3, k + 3, Blocks.air, 0, 2);
        world.setBlock(i + 2, j + 3, k + 3, NovaCraftBlocks.luminant_log, 0, 2);
        world.setBlock(i + 3, j + 3, k + 3, Blocks.air, 0, 2);
        world.setBlock(i + 4, j + 3, k + 3, Blocks.air, 0, 2);
        world.setBlock(i, j + 3, k + 4, Blocks.air, 0, 2);
        world.setBlock(i + 1, j + 3, k + 4, Blocks.air, 0, 2);
        world.setBlock(i + 2, j + 3, k + 4, placeStoneBrickStairs(random), 7, 2);
        world.setBlock(i + 3, j + 3, k + 4, Blocks.air, 0, 2);
        world.setBlock(i + 4, j + 3, k + 4, Blocks.air, 0, 2);
        world.setBlock(i, j + 3, k + 5, placeStoneBricks(random), 0, 2);
        world.setBlock(i + 1, j + 3, k + 5, Blocks.air, 0, 2);
        world.setBlock(i + 2, j + 3, k + 5, Blocks.air, 0, 2);
        world.setBlock(i + 3, j + 3, k + 5, Blocks.air, 0, 2);
        world.setBlock(i + 4, j + 3, k + 5, placeStoneBricks(random), 0, 2);
        world.setBlock(i, j + 3, k + 6, placeStoneBricks(random), 0, 2);
        world.setBlock(i + 1, j + 3, k + 6, Blocks.air, 0, 2);
        world.setBlock(i + 2, j + 3, k + 6, Blocks.air, 0, 2);
        world.setBlock(i + 3, j + 3, k + 6, Blocks.air, 0, 2);
        world.setBlock(i + 4, j + 3, k + 6, placeStoneBricks(random), 0, 2);
        world.setBlock(i, j + 3, k + 7, placeStoneBricks(random), 0, 2);
        world.setBlock(i + 1, j + 3, k + 7, placeStoneBricks(random), 0, 2);
        world.setBlock(i + 2, j + 3, k + 7, placeStoneBricks(random), 0, 2);
        world.setBlock(i + 3, j + 3, k + 7, placeStoneBricks(random), 0, 2);
        world.setBlock(i + 4, j + 3, k + 7, placeStoneBricks(random), 0, 2);
        world.setBlock(i, j + 4, k, placeStoneBricks(random), 0, 2);
        world.setBlock(i + 1, j + 4, k, placeStoneBricks(random), 0, 2);
        world.setBlock(i + 2, j + 4, k, placeStoneBricks(random), 0, 2);
        world.setBlock(i + 3, j + 4, k, placeStoneBricks(random), 0, 2);
        world.setBlock(i + 4, j + 4, k, placeStoneBricks(random), 0, 2);
        world.setBlock(i, j + 4, k + 1, placeStoneBricks(random), 0, 2);
        world.setBlock(i + 1, j + 4, k + 1, Blocks.air, 0, 2);
        world.setBlock(i + 2, j + 4, k + 1, NovaCraftBlocks.luminant_stairs, 0, 2);
        world.setBlock(i + 3, j + 4, k + 1, placeStoneBricks(random), 0, 2);
        world.setBlock(i + 4, j + 4, k + 1, placeStoneBricks(random), 0, 2);
        world.setBlock(i, j + 4, k + 2, placeStoneBricks(random), 0, 2);
        world.setBlock(i + 1, j + 4, k + 2, Blocks.air, 0, 2);
        world.setBlock(i + 2, j + 4, k + 2, NovaCraftBlocks.luminant_log, 0, 2);
        world.setBlock(i + 3, j + 4, k + 2, Blocks.air, 0, 2);
        world.setBlock(i + 4, j + 4, k + 2, placeStoneBricks(random), 0, 2);
        world.setBlock(i, j + 4, k + 3, placeStoneBrickStairs(random), 7, 2);
        world.setBlock(i + 1, j + 4, k + 3, Blocks.air, 0, 2);
        world.setBlock(i + 2, j + 4, k + 3, NovaCraftBlocks.luminant_log, 0, 2);
        world.setBlock(i + 3, j + 4, k + 3, Blocks.air, 0, 2);
        world.setBlock(i + 4, j + 4, k + 3, placeStoneBrickStairs(random), 7, 2);
        world.setBlock(i, j + 4, k + 4, placeStoneBrickStairs(random), 6, 2);
        world.setBlock(i + 1, j + 4, k + 4, Blocks.air, 0, 2);
        world.setBlock(i + 2, j + 4, k + 4, NovaCraftBlocks.luminant_log, 0, 2);
        world.setBlock(i + 3, j + 4, k + 4, Blocks.air, 0, 2);
        world.setBlock(i + 4, j + 4, k + 4, placeStoneBrickStairs(random), 6, 2);
        world.setBlock(i, j + 4, k + 5, placeStoneBricks(random), 0, 2);
        world.setBlock(i + 1, j + 4, k + 5, Blocks.air, 0, 2);
        world.setBlock(i + 2, j + 4, k + 5, placeStoneBrickStairs(random), 7, 2);
        world.setBlock(i + 3, j + 4, k + 5, Blocks.air, 0, 2);
        world.setBlock(i + 4, j + 4, k + 5, placeStoneBricks(random), 0, 2);
        world.setBlock(i, j + 4, k + 6, placeStoneBricks(random), 0, 2);
        world.setBlock(i + 1, j + 4, k + 6, Blocks.air, 0, 2);
        world.setBlock(i + 2, j + 4, k + 6, placeStoneBrickStairs(random), 6, 2);
        world.setBlock(i + 3, j + 4, k + 6, Blocks.air, 0, 2);
        world.setBlock(i + 4, j + 4, k + 6, placeStoneBricks(random), 0, 2);
        world.setBlock(i, j + 4, k + 7, placeStoneBricks(random), 0, 2);
        world.setBlock(i + 1, j + 4, k + 7, placeStoneBricks(random), 0, 2);
        world.setBlock(i + 2, j + 4, k + 7, placeStoneBricks(random), 0, 2);
        world.setBlock(i + 3, j + 4, k + 7, placeStoneBricks(random), 0, 2);
        world.setBlock(i + 4, j + 4, k + 7, placeStoneBricks(random), 0, 2);
        world.setBlock(i, j + 5, k, placeStoneBricks(random), 0, 2);
        world.setBlock(i + 1, j + 5, k, placeStoneBricks(random), 0, 2);
        world.setBlock(i + 2, j + 5, k, placeStoneBricks(random), 0, 2);
        world.setBlock(i + 3, j + 5, k, placeStoneBricks(random), 0, 2);
        world.setBlock(i + 4, j + 5, k, placeStoneBricks(random), 0, 2);
        world.setBlock(i, j + 5, k + 1, placeStoneBricks(random), 0, 2);
        world.setBlock(i + 1, j + 5, k + 1, Blocks.air, 0, 2);
        world.setBlock(i + 2, j + 5, k + 1, Blocks.air, 0, 2);
        world.setBlock(i + 3, j + 5, k + 1, NovaCraftBlocks.luminant_stairs, 0, 2);
        world.setBlock(i + 4, j + 5, k + 1, placeStoneBricks(random), 0, 2);
        world.setBlock(i, j + 5, k + 2, placeStoneBricks(random), 0, 2);
        world.setBlock(i + 1, j + 5, k + 2, Blocks.air, 0, 2);
        world.setBlock(i + 2, j + 5, k + 2, NovaCraftBlocks.luminant_log, 0, 2);
        world.setBlock(i + 3, j + 5, k + 2, placeStoneBricks(random), 0, 2);
        world.setBlock(i + 4, j + 5, k + 2, placeStoneBricks(random), 0, 2);
        world.setBlock(i, j + 5, k + 3, placeStoneBricks(random), 0, 2);
        world.setBlock(i + 1, j + 5, k + 3, placeStoneBrickStairs(random), 4, 2);
        world.setBlock(i + 2, j + 5, k + 3, NovaCraftBlocks.luminant_log, 0, 2);
        world.setBlock(i + 3, j + 5, k + 3, placeStoneBrickStairs(random), 5, 2);
        world.setBlock(i + 4, j + 5, k + 3, placeStoneBricks(random), 0, 2);
        world.setBlock(i, j + 5, k + 4, placeStoneBricks(random), 0, 2);
        world.setBlock(i + 1, j + 5, k + 4, placeStoneBrickStairs(random), 4, 2);
        world.setBlock(i + 2, j + 5, k + 4, NovaCraftBlocks.luminant_log, 0, 2);
        world.setBlock(i + 3, j + 5, k + 4, placeStoneBrickStairs(random), 5, 2);
        world.setBlock(i + 4, j + 5, k + 4, placeStoneBricks(random), 0, 2);
        world.setBlock(i, j + 5, k + 5, placeStoneBricks(random), 0, 2);
        world.setBlock(i + 1, j + 5, k + 5, placeStoneBrickStairs(random), 4, 2);
        world.setBlock(i + 2, j + 5, k + 5, NovaCraftBlocks.luminant_log, 0, 2);
        world.setBlock(i + 3, j + 5, k + 5, placeStoneBrickStairs(random), 5, 2);
        world.setBlock(i + 4, j + 5, k + 5, placeStoneBricks(random), 0, 2);
        world.setBlock(i, j + 5, k + 6, placeStoneBricks(random), 0, 2);
        world.setBlock(i + 1, j + 5, k + 6, Blocks.air, 0, 2);
        world.setBlock(i + 2, j + 5, k + 6, Blocks.air, 0, 2);
        world.setBlock(i + 3, j + 5, k + 6, Blocks.air, 0, 2);
        world.setBlock(i + 4, j + 5, k + 6, placeStoneBricks(random), 0, 2);
        world.setBlock(i, j + 5, k + 7, placeStoneBricks(random), 0, 2);
        world.setBlock(i + 1, j + 5, k + 7, placeStoneBricks(random), 0, 2);
        world.setBlock(i + 2, j + 5, k + 7, placeStoneBricks(random), 0, 2);
        world.setBlock(i + 3, j + 5, k + 7, placeStoneBricks(random), 0, 2);
        world.setBlock(i + 4, j + 5, k + 7, placeStoneBricks(random), 0, 2);
        world.setBlock(i, j + 6, k, placeStoneBricks(random), 0, 2);
        world.setBlock(i + 1, j + 6, k, placeStoneBricks(random), 0, 2);
        world.setBlock(i + 2, j + 6, k, placeStoneBricks(random), 0, 2);
        world.setBlock(i + 3, j + 6, k, placeStoneBricks(random), 0, 2);
        world.setBlock(i + 4, j + 6, k, placeStoneBricks(random), 0, 2);
        world.setBlock(i, j + 6, k + 1, placeStoneBricks(random), 0, 2);
        world.setBlock(i + 1, j + 6, k + 1, Blocks.air, 0, 2);
        world.setBlock(i + 2, j + 6, k + 1, Blocks.air, 0, 2);
        world.setBlock(i + 3, j + 6, k + 1, Blocks.air, 0, 2);
        world.setBlock(i + 4, j + 6, k + 1, placeStoneBricks(random), 0, 2);
        world.setBlock(i, j + 6, k + 2, placeStoneBricks(random), 0, 2);
        world.setBlock(i + 1, j + 6, k + 2, Blocks.air, 0, 2);
        world.setBlock(i + 2, j + 6, k + 2, NovaCraftBlocks.luminant_log, 0, 2);
        world.setBlock(i + 3, j + 6, k + 2, NovaCraftBlocks.luminant_stairs, 2, 2);
        world.setBlock(i + 4, j + 6, k + 2, placeStoneBricks(random), 0, 2);
        world.setBlock(i, j + 6, k + 3, placeStoneBricks(random), 0, 2);
        world.setBlock(i + 1, j + 6, k + 3, Blocks.air, 0, 2);
        world.setBlock(i + 2, j + 6, k + 3, NovaCraftBlocks.luminant_log, 0, 2);
        world.setBlock(i + 3, j + 6, k + 3, placeStoneBricks(random), 0, 2);
        world.setBlock(i + 4, j + 6, k + 3, placeStoneBricks(random), 0, 2);
        world.setBlock(i, j + 6, k + 4, placeStoneBricks(random), 0, 2);
        world.setBlock(i + 1, j + 6, k + 4, Blocks.air, 0, 2);
        world.setBlock(i + 2, j + 6, k + 4, NovaCraftBlocks.luminant_log, 0, 2);
        world.setBlock(i + 3, j + 6, k + 4, Blocks.air, 0, 2);
        world.setBlock(i + 4, j + 6, k + 4, placeStoneBricks(random), 0, 2);
        world.setBlock(i, j + 6, k + 5, placeStoneBricks(random), 0, 2);
        world.setBlock(i + 1, j + 6, k + 5, Blocks.air, 0, 2);
        world.setBlock(i + 2, j + 6, k + 5, NovaCraftBlocks.luminant_log, 0, 2);
        world.setBlock(i + 3, j + 6, k + 5, Blocks.air, 0, 2);
        world.setBlock(i + 4, j + 6, k + 5, placeStoneBricks(random), 0, 2);
        world.setBlock(i, j + 6, k + 6, placeStoneBricks(random), 0, 2);
        world.setBlock(i + 1, j + 6, k + 6, Blocks.air, 0, 2);
        world.setBlock(i + 2, j + 6, k + 6, Blocks.air, 0, 2);
        world.setBlock(i + 3, j + 6, k + 6, Blocks.air, 0, 2);
        world.setBlock(i + 4, j + 6, k + 6, placeStoneBricks(random), 0, 2);
        world.setBlock(i, j + 6, k + 7, placeStoneBricks(random), 0, 2);
        world.setBlock(i + 1, j + 6, k + 7, placeStoneBricks(random), 0, 2);
        world.setBlock(i + 2, j + 6, k + 7, placeStoneBricks(random), 0, 2);
        world.setBlock(i + 3, j + 6, k + 7, placeStoneBricks(random), 0, 2);
        world.setBlock(i + 4, j + 6, k + 7, placeStoneBricks(random), 0, 2);
        world.setBlock(i, j + 7, k, placeStoneBricks(random), 0, 2);
        world.setBlock(i + 1, j + 7, k, placeStoneBricks(random), 0, 2);
        world.setBlock(i + 2, j + 7, k, placeStoneBricks(random), 0, 2);
        world.setBlock(i + 3, j + 7, k, placeStoneBricks(random), 0, 2);
        world.setBlock(i + 4, j + 7, k, placeStoneBricks(random), 0, 2);
        world.setBlock(i, j + 7, k + 1, placeStoneBricks(random), 0, 2);
        world.setBlock(i + 1, j + 7, k + 1, Blocks.air, 0, 2);
        world.setBlock(i + 2, j + 7, k + 1, Blocks.air, 0, 2);
        world.setBlock(i + 3, j + 7, k + 1, Blocks.air, 0, 2);
        world.setBlock(i + 4, j + 7, k + 1, placeStoneBricks(random), 0, 2);
        world.setBlock(i, j + 7, k + 2, placeStoneBricks(random), 0, 2);
        world.setBlock(i + 1, j + 7, k + 2, Blocks.air, 0, 2);
        world.setBlock(i + 2, j + 7, k + 2, NovaCraftBlocks.luminant_log, 0, 2);
        world.setBlock(i + 3, j + 7, k + 2, Blocks.air, 0, 2);
        world.setBlock(i + 4, j + 7, k + 2, placeStoneBricks(random), 0, 2);
        world.setBlock(i, j + 7, k + 3, placeStoneBricks(random), 0, 2);
        world.setBlock(i + 1, j + 7, k + 3, Blocks.air, 0, 2);
        world.setBlock(i + 2, j + 7, k + 3, NovaCraftBlocks.luminant_log, 0, 2);
        world.setBlock(i + 3, j + 7, k + 3, NovaCraftBlocks.luminant_stairs, 2, 2);
        world.setBlock(i + 4, j + 7, k + 3, placeStoneBricks(random), 0, 2);
        world.setBlock(i, j + 7, k + 4, placeStoneBricks(random), 0, 2);
        world.setBlock(i + 1, j + 7, k + 4, Blocks.air, 0, 2);
        world.setBlock(i + 2, j + 7, k + 4, NovaCraftBlocks.luminant_log, 0, 2);
        world.setBlock(i + 3, j + 7, k + 4, placeStoneBricks(random), 0, 2);
        world.setBlock(i + 4, j + 7, k + 4, placeStoneBricks(random), 0, 2);
        world.setBlock(i, j + 7, k + 5, placeStoneBricks(random), 0, 2);
        world.setBlock(i + 1, j + 7, k + 5, Blocks.air, 0, 2);
        world.setBlock(i + 2, j + 7, k + 5, NovaCraftBlocks.luminant_log, 0, 2);
        world.setBlock(i + 3, j + 7, k + 5, Blocks.air, 0, 2);
        world.setBlock(i + 4, j + 7, k + 5, placeStoneBricks(random), 0, 2);
        world.setBlock(i, j + 7, k + 6, placeStoneBricks(random), 0, 2);
        world.setBlock(i + 1, j + 7, k + 6, Blocks.air, 0, 2);
        world.setBlock(i + 2, j + 7, k + 6, Blocks.air, 0, 2);
        world.setBlock(i + 3, j + 7, k + 6, Blocks.air, 0, 2);
        world.setBlock(i + 4, j + 7, k + 6, placeStoneBricks(random), 0, 2);
        world.setBlock(i, j + 7, k + 7, placeStoneBricks(random), 0, 2);
        world.setBlock(i + 1, j + 7, k + 7, placeStoneBricks(random), 0, 2);
        world.setBlock(i + 2, j + 7, k + 7, placeStoneBricks(random), 0, 2);
        world.setBlock(i + 3, j + 7, k + 7, placeStoneBricks(random), 0, 2);
        world.setBlock(i + 4, j + 7, k + 7, placeStoneBricks(random), 0, 2);
        world.setBlock(i, j + 8, k, placeStoneBricks(random), 0, 2);
        world.setBlock(i + 1, j + 8, k, placeStoneBricks(random), 0, 2);
        world.setBlock(i + 2, j + 8, k, placeStoneBricks(random), 0, 2);
        world.setBlock(i + 3, j + 8, k, placeStoneBricks(random), 0, 2);
        world.setBlock(i + 4, j + 8, k, placeStoneBricks(random), 0, 2);
        world.setBlock(i, j + 8, k + 1, placeStoneBricks(random), 0, 2);
        world.setBlock(i + 1, j + 8, k + 1, Blocks.air, 0, 2);
        world.setBlock(i + 2, j + 8, k + 1, Blocks.air, 0, 2);
        world.setBlock(i + 3, j + 8, k + 1, Blocks.air, 0, 2);
        world.setBlock(i + 4, j + 8, k + 1, placeStoneBricks(random), 0, 2);
        world.setBlock(i, j + 8, k + 2, placeStoneBricks(random), 0, 2);
        world.setBlock(i + 1, j + 8, k + 2, Blocks.air, 0, 2);
        world.setBlock(i + 2, j + 8, k + 2, NovaCraftBlocks.luminant_log, 0, 2);
        world.setBlock(i + 3, j + 8, k + 2, Blocks.air, 0, 2);
        world.setBlock(i + 4, j + 8, k + 2, placeStoneBricks(random), 0, 2);
        world.setBlock(i, j + 8, k + 3, placeStoneBricks(random), 0, 2);
        world.setBlock(i + 1, j + 8, k + 3, Blocks.air, 0, 2);
        world.setBlock(i + 2, j + 8, k + 3, NovaCraftBlocks.luminant_log, 0, 2);
        world.setBlock(i + 3, j + 8, k + 3, Blocks.air, 0, 2);
        world.setBlock(i + 4, j + 8, k + 3, placeStoneBricks(random), 0, 2);
        world.setBlock(i, j + 8, k + 4, placeStoneBricks(random), 0, 2);
        world.setBlock(i + 1, j + 8, k + 4, Blocks.air, 0, 2);
        world.setBlock(i + 2, j + 8, k + 4, NovaCraftBlocks.luminant_log, 0, 2);
        world.setBlock(i + 3, j + 8, k + 4, NovaCraftBlocks.luminant_stairs, 2, 2);
        world.setBlock(i + 4, j + 8, k + 4, placeStoneBricks(random), 0, 2);
        world.setBlock(i, j + 8, k + 5, placeStoneBricks(random), 0, 2);
        world.setBlock(i + 1, j + 8, k + 5, Blocks.air, 0, 2);
        world.setBlock(i + 2, j + 8, k + 5, NovaCraftBlocks.luminant_log, 0, 2);
        world.setBlock(i + 3, j + 8, k + 5, placeStoneBricks(random), 0, 2);
        world.setBlock(i + 4, j + 8, k + 5, placeStoneBricks(random), 0, 2);
        world.setBlock(i, j + 8, k + 6, placeStoneBricks(random), 0, 2);
        world.setBlock(i + 1, j + 8, k + 6, Blocks.air, 0, 2);
        world.setBlock(i + 2, j + 8, k + 6, Blocks.air, 0, 2);
        world.setBlock(i + 3, j + 8, k + 6, Blocks.air, 0, 2);
        world.setBlock(i + 4, j + 8, k + 6, placeStoneBricks(random), 0, 2);
        world.setBlock(i, j + 8, k + 7, placeStoneBricks(random), 0, 2);
        world.setBlock(i + 1, j + 8, k + 7, placeStoneBricks(random), 0, 2);
        world.setBlock(i + 2, j + 8, k + 7, placeStoneBricks(random), 0, 2);
        world.setBlock(i + 3, j + 8, k + 7, placeStoneBricks(random), 0, 2);
        world.setBlock(i + 4, j + 8, k + 7, placeStoneBricks(random), 0, 2);
        world.setBlock(i, j + 9, k, placeStoneBricks(random), 0, 2);
        world.setBlock(i + 1, j + 9, k, placeStoneBricks(random), 0, 2);
        world.setBlock(i + 2, j + 9, k, placeStoneBricks(random), 0, 2);
        world.setBlock(i + 3, j + 9, k, placeStoneBricks(random), 0, 2);
        world.setBlock(i + 4, j + 9, k, placeStoneBricks(random), 0, 2);
        world.setBlock(i, j + 9, k + 1, placeStoneBricks(random), 0, 2);
        world.setBlock(i + 1, j + 9, k + 1, Blocks.air, 0, 2);
        world.setBlock(i + 2, j + 9, k + 1, Blocks.air, 0, 2);
        world.setBlock(i + 3, j + 9, k + 1, Blocks.air, 0, 2);
        world.setBlock(i + 4, j + 9, k + 1, placeStoneBricks(random), 0, 2);
        world.setBlock(i, j + 9, k + 2, placeStoneBricks(random), 0, 2);
        world.setBlock(i + 1, j + 9, k + 2, Blocks.air, 0, 2);
        world.setBlock(i + 2, j + 9, k + 2, NovaCraftBlocks.luminant_log, 0, 2);
        world.setBlock(i + 3, j + 9, k + 2, Blocks.air, 0, 2);
        world.setBlock(i + 4, j + 9, k + 2, placeStoneBricks(random), 0, 2);
        world.setBlock(i, j + 9, k + 3, placeStoneBricks(random), 0, 2);
        world.setBlock(i + 1, j + 9, k + 3, Blocks.air, 0, 2);
        world.setBlock(i + 2, j + 9, k + 3, NovaCraftBlocks.luminant_log, 0, 2);
        world.setBlock(i + 3, j + 9, k + 3, Blocks.air, 0, 2);
        world.setBlock(i + 4, j + 9, k + 3, placeStoneBricks(random), 0, 2);
        world.setBlock(i, j + 9, k + 4, placeStoneBricks(random), 0, 2);
        world.setBlock(i + 1, j + 9, k + 4, Blocks.air, 0, 2);
        world.setBlock(i + 2, j + 9, k + 4, NovaCraftBlocks.luminant_log, 0, 2);
        world.setBlock(i + 3, j + 9, k + 4, Blocks.air, 0, 2);
        world.setBlock(i + 4, j + 9, k + 4, placeStoneBricks(random), 0, 2);
        world.setBlock(i, j + 9, k + 5, placeStoneBricks(random), 0, 2);
        world.setBlock(i + 1, j + 9, k + 5, Blocks.air, 0, 2);
        world.setBlock(i + 2, j + 9, k + 5, NovaCraftBlocks.luminant_log, 0, 2);
        world.setBlock(i + 3, j + 9, k + 5, NovaCraftBlocks.luminant_stairs, 2, 2);
        world.setBlock(i + 4, j + 9, k + 5, placeStoneBricks(random), 0, 2);
        world.setBlock(i, j + 9, k + 6, placeStoneBricks(random), 0, 2);
        world.setBlock(i + 1, j + 9, k + 6, Blocks.air, 0, 2);
        world.setBlock(i + 2, j + 9, k + 6, Blocks.air, 0, 2);
        world.setBlock(i + 3, j + 9, k + 6, placeStoneBricks(random), 0, 2);
        world.setBlock(i + 4, j + 9, k + 6, placeStoneBricks(random), 0, 2);
        world.setBlock(i, j + 9, k + 7, placeStoneBricks(random), 0, 2);
        world.setBlock(i + 1, j + 9, k + 7, placeStoneBricks(random), 0, 2);
        world.setBlock(i + 2, j + 9, k + 7, placeStoneBricks(random), 0, 2);
        world.setBlock(i + 3, j + 9, k + 7, placeStoneBricks(random), 0, 2);
        world.setBlock(i + 4, j + 9, k + 7, placeStoneBricks(random), 0, 2);
        world.setBlock(i, j + 10, k, placeStoneBricks(random), 0, 2);
        world.setBlock(i + 1, j + 10, k, placeStoneBricks(random), 0, 2);
        world.setBlock(i + 2, j + 10, k, placeStoneBricks(random), 0, 2);
        world.setBlock(i + 3, j + 10, k, placeStoneBricks(random), 0, 2);
        world.setBlock(i + 4, j + 10, k, placeStoneBricks(random), 0, 2);
        world.setBlock(i, j + 10, k + 1, placeStoneBricks(random), 0, 2);
        world.setBlock(i + 1, j + 10, k + 1, Blocks.air, 0, 2);
        world.setBlock(i + 2, j + 10, k + 1, Blocks.air, 0, 2);
        world.setBlock(i + 3, j + 10, k + 1, Blocks.air, 0, 2);
        world.setBlock(i + 4, j + 10, k + 1, placeStoneBricks(random), 0, 2);
        world.setBlock(i, j + 10, k + 2, placeStoneBricks(random), 0, 2);
        world.setBlock(i + 1, j + 10, k + 2, Blocks.air, 0, 2);
        world.setBlock(i + 2, j + 10, k + 2, NovaCraftBlocks.luminant_log, 0, 2);
        world.setBlock(i + 3, j + 10, k + 2, Blocks.air, 0, 2);
        world.setBlock(i + 4, j + 10, k + 2, placeStoneBricks(random), 0, 2);
        world.setBlock(i, j + 10, k + 3, placeStoneBricks(random), 0, 2);
        world.setBlock(i + 1, j + 10, k + 3, Blocks.air, 0, 2);
        world.setBlock(i + 2, j + 10, k + 3, NovaCraftBlocks.luminant_log, 0, 2);
        world.setBlock(i + 4, j + 10, k + 3, placeStoneBricks(random), 0, 2);
        world.setBlock(i, j + 10, k + 4, placeStoneBricks(random), 0, 2);
        world.setBlock(i + 1, j + 10, k + 4, Blocks.air, 0, 2);
        world.setBlock(i + 2, j + 10, k + 4, NovaCraftBlocks.luminant_log, 0, 2);
        world.setBlock(i + 3, j + 10, k + 4, Blocks.air, 0, 2);
        world.setBlock(i + 4, j + 10, k + 4, placeStoneBricks(random), 0, 2);
        world.setBlock(i, j + 10, k + 5, placeStoneBricks(random), 0, 2);
        world.setBlock(i + 1, j + 10, k + 5, Blocks.air, 0, 2);
        world.setBlock(i + 2, j + 10, k + 5, NovaCraftBlocks.luminant_log, 0, 2);
        world.setBlock(i + 3, j + 10, k + 5, Blocks.air, 0, 2);
        world.setBlock(i + 4, j + 10, k + 5, placeStoneBricks(random), 0, 2);
        world.setBlock(i, j + 10, k + 6, placeStoneBricks(random), 0, 2);
        world.setBlock(i + 1, j + 10, k + 6, Blocks.air, 0, 2);
        world.setBlock(i + 2, j + 10, k + 6, placeStoneBricks(random), 0, 2);
        world.setBlock(i + 3, j + 10, k + 6, NovaCraftBlocks.luminant_stairs, 2, 2);
        world.setBlock(i + 4, j + 10, k + 6, placeStoneBricks(random), 0, 2);
        world.setBlock(i, j + 10, k + 7, placeStoneBricks(random), 0, 2);
        world.setBlock(i + 1, j + 10, k + 7, placeStoneBricks(random), 0, 2);
        world.setBlock(i + 2, j + 10, k + 7, placeStoneBricks(random), 0, 2);
        world.setBlock(i + 3, j + 10, k + 7, placeStoneBricks(random), 0, 2);
        world.setBlock(i + 4, j + 10, k + 7, placeStoneBricks(random), 0, 2);
        world.setBlock(i, j + 11, k, placeStoneBricks(random), 0, 2);
        world.setBlock(i + 1, j + 11, k, placeStoneBricks(random), 0, 2);
        world.setBlock(i + 2, j + 11, k, placeStoneBricks(random), 0, 2);
        world.setBlock(i + 3, j + 11, k, placeStoneBricks(random), 0, 2);
        world.setBlock(i + 4, j + 11, k, placeStoneBricks(random), 0, 2);
        world.setBlock(i, j + 11, k + 1, placeStoneBricks(random), 0, 2);
        world.setBlock(i + 1, j + 11, k + 1, Blocks.air, 0, 2);
        world.setBlock(i + 2, j + 11, k + 1, Blocks.air, 0, 2);
        world.setBlock(i + 3, j + 11, k + 1, Blocks.air, 0, 2);
        world.setBlock(i + 4, j + 11, k + 1, placeStoneBricks(random), 0, 2);
        world.setBlock(i, j + 11, k + 2, placeStoneBricks(random), 0, 2);
        world.setBlock(i + 1, j + 11, k + 2, Blocks.air, 0, 2);
        world.setBlock(i + 2, j + 11, k + 2, NovaCraftBlocks.luminant_log, 0, 2);
        world.setBlock(i + 3, j + 11, k + 2, Blocks.air, 0, 2);
        world.setBlock(i + 4, j + 11, k + 2, placeStoneBricks(random), 0, 2);
        world.setBlock(i, j + 11, k + 3, placeStoneBricks(random), 0, 2);
        world.setBlock(i + 1, j + 11, k + 3, Blocks.air, 0, 2);
        world.setBlock(i + 2, j + 11, k + 3, NovaCraftBlocks.luminant_log, 0, 2);
        world.setBlock(i + 3, j + 11, k + 3, Blocks.air, 0, 2);
        world.setBlock(i + 4, j + 11, k + 3, placeStoneBricks(random), 0, 2);
        world.setBlock(i, j + 11, k + 4, placeStoneBricks(random), 0, 2);
        world.setBlock(i + 1, j + 11, k + 4, Blocks.air, 0, 2);
        world.setBlock(i + 2, j + 11, k + 4, NovaCraftBlocks.luminant_log, 0, 2);
        world.setBlock(i + 3, j + 11, k + 4, Blocks.air, 0, 2);
        world.setBlock(i + 4, j + 11, k + 4, placeStoneBricks(random), 0, 2);
        world.setBlock(i, j + 11, k + 5, placeStoneBricks(random), 0, 2);
        world.setBlock(i + 1, j + 11, k + 5, Blocks.air, 0, 2);
        world.setBlock(i + 2, j + 11, k + 5, NovaCraftBlocks.luminant_log, 0, 2);
        world.setBlock(i + 3, j + 11, k + 5, Blocks.air, 0, 2);
        world.setBlock(i + 4, j + 11, k + 5, placeStoneBricks(random), 0, 2);
        world.setBlock(i, j + 11, k + 6, placeStoneBricks(random), 0, 2);
        world.setBlock(i + 1, j + 11, k + 6, placeStoneBricks(random), 0, 2);
        world.setBlock(i + 2, j + 11, k + 6, NovaCraftBlocks.luminant_stairs, 1, 2);
        world.setBlock(i + 3, j + 11, k + 6, Blocks.air, 0, 2);
        world.setBlock(i + 4, j + 11, k + 6, placeStoneBricks(random), 0, 2);
        world.setBlock(i, j + 11, k + 7, placeStoneBricks(random), 0, 2);
        world.setBlock(i + 1, j + 11, k + 7, placeStoneBricks(random), 0, 2);
        world.setBlock(i + 2, j + 11, k + 7, placeStoneBricks(random), 0, 2);
        world.setBlock(i + 3, j + 11, k + 7, placeStoneBricks(random), 0, 2);
        world.setBlock(i + 4, j + 11, k + 7, placeStoneBricks(random), 0, 2);
        world.setBlock(i, j + 12, k, placeStoneBricks(random), 0, 2);
        world.setBlock(i + 1, j + 12, k, placeStoneBricks(random), 0, 2);
        world.setBlock(i + 2, j + 12, k, placeStoneBricks(random), 0, 2);
        world.setBlock(i + 3, j + 12, k, placeStoneBricks(random), 0, 2);
        world.setBlock(i + 4, j + 12, k, placeStoneBricks(random), 0, 2);
        world.setBlock(i, j + 12, k + 1, placeStoneBricks(random), 0, 2);
        world.setBlock(i + 1, j + 12, k + 1, Blocks.air, 0, 2);
        world.setBlock(i + 2, j + 12, k + 1, Blocks.air, 0, 2);
        world.setBlock(i + 3, j + 12, k + 1, Blocks.air, 0, 2);
        world.setBlock(i + 4, j + 12, k + 1, placeStoneBricks(random), 0, 2);
        world.setBlock(i, j + 12, k + 2, placeStoneBricks(random), 0, 2);
        world.setBlock(i + 1, j + 12, k + 2, Blocks.air, 0, 2);
        world.setBlock(i + 2, j + 12, k + 2, NovaCraftBlocks.luminant_log, 0, 2);
        world.setBlock(i + 3, j + 12, k + 2, Blocks.air, 0, 2);
        world.setBlock(i + 4, j + 12, k + 2, placeStoneBricks(random), 0, 2);
        world.setBlock(i, j + 12, k + 3, placeStoneBricks(random), 0, 2);
        world.setBlock(i + 1, j + 12, k + 3, Blocks.air, 0, 2);
        world.setBlock(i + 2, j + 12, k + 3, NovaCraftBlocks.luminant_log, 0, 2);
        world.setBlock(i + 3, j + 12, k + 3, Blocks.air, 0, 2);
        world.setBlock(i + 4, j + 12, k + 3, placeStoneBricks(random), 0, 2);
        world.setBlock(i, j + 12, k + 4, placeStoneBricks(random), 0, 2);
        world.setBlock(i + 1, j + 12, k + 4, Blocks.air, 0, 2);
        world.setBlock(i + 2, j + 12, k + 4, NovaCraftBlocks.luminant_log, 0, 2);
        world.setBlock(i + 3, j + 12, k + 4, Blocks.air, 0, 2);
        world.setBlock(i + 4, j + 12, k + 4, placeStoneBricks(random), 0, 2);
        world.setBlock(i, j + 12, k + 5, placeStoneBricks(random), 0, 2);
        world.setBlock(i + 1, j + 12, k + 5, placeStoneBricks(random), 0, 2);
        world.setBlock(i + 2, j + 12, k + 5, NovaCraftBlocks.luminant_log, 0, 2);
        world.setBlock(i + 3, j + 12, k + 5, Blocks.air, 0, 2);
        world.setBlock(i + 4, j + 12, k + 5, placeStoneBricks(random), 0, 2);
        world.setBlock(i, j + 12, k + 6, placeStoneBricks(random), 0, 2);
        world.setBlock(i + 1, j + 12, k + 6, NovaCraftBlocks.luminant_stairs, 1, 2);
        world.setBlock(i + 2, j + 12, k + 6, Blocks.air, 0, 2);
        world.setBlock(i + 3, j + 12, k + 6, Blocks.air, 0, 2);
        world.setBlock(i + 4, j + 12, k + 6, placeStoneBricks(random), 0, 2);
        world.setBlock(i, j + 12, k + 7, placeStoneBricks(random), 0, 2);
        world.setBlock(i + 1, j + 12, k + 7, placeStoneBricks(random), 0, 2);
        world.setBlock(i + 2, j + 12, k + 7, placeStoneBricks(random), 0, 2);
        world.setBlock(i + 3, j + 12, k + 7, placeStoneBricks(random), 0, 2);
        world.setBlock(i + 4, j + 12, k + 7, placeStoneBricks(random), 0, 2);
        world.setBlock(i, j + 13, k, placeStoneBricks(random), 0, 2);
        world.setBlock(i + 1, j + 13, k, placeStoneBricks(random), 0, 2);
        world.setBlock(i + 2, j + 13, k, placeStoneBricks(random), 0, 2);
        world.setBlock(i + 3, j + 13, k, placeStoneBricks(random), 0, 2);
        world.setBlock(i + 4, j + 13, k, placeStoneBricks(random), 0, 2);
        world.setBlock(i, j + 13, k + 1, placeStoneBricks(random), 0, 2);
        world.setBlock(i + 1, j + 13, k + 1, Blocks.air, 0, 2);
        world.setBlock(i + 2, j + 13, k + 1, Blocks.air, 0, 2);
        world.setBlock(i + 3, j + 13, k + 1, Blocks.air, 0, 2);
        world.setBlock(i + 4, j + 13, k + 1, placeStoneBricks(random), 0, 2);
        world.setBlock(i, j + 13, k + 2, placeStoneBricks(random), 0, 2);
        world.setBlock(i + 1, j + 13, k + 2, Blocks.air, 0, 2);
        world.setBlock(i + 2, j + 13, k + 2, NovaCraftBlocks.luminant_log, 0, 2);
        world.setBlock(i + 3, j + 13, k + 2, Blocks.air, 0, 2);
        world.setBlock(i + 4, j + 13, k + 2, placeStoneBricks(random), 0, 2);
        world.setBlock(i, j + 13, k + 3, placeStoneBricks(random), 0, 2);
        world.setBlock(i + 1, j + 13, k + 3, Blocks.air, 0, 2);
        world.setBlock(i + 2, j + 13, k + 3, NovaCraftBlocks.luminant_log, 0, 2);
        world.setBlock(i + 3, j + 13, k + 3, Blocks.air, 0, 2);
        world.setBlock(i + 4, j + 13, k + 3, placeStoneBricks(random), 0, 2);
        world.setBlock(i, j + 13, k + 4, placeStoneBricks(random), 0, 2);
        world.setBlock(i + 1, j + 13, k + 4, placeStoneBricks(random), 0, 2);
        world.setBlock(i + 2, j + 13, k + 4, NovaCraftBlocks.luminant_log, 0, 2);
        world.setBlock(i + 3, j + 13, k + 4, Blocks.air, 0, 2);
        world.setBlock(i + 4, j + 13, k + 4, placeStoneBricks(random), 0, 2);
        world.setBlock(i, j + 13, k + 5, placeStoneBricks(random), 0, 2);
        world.setBlock(i + 1, j + 13, k + 5, NovaCraftBlocks.luminant_stairs, 3, 2);
        world.setBlock(i + 2, j + 13, k + 5, NovaCraftBlocks.luminant_log, 0, 2);
        world.setBlock(i + 3, j + 13, k + 5, Blocks.air, 0, 2);
        world.setBlock(i + 4, j + 13, k + 5, placeStoneBricks(random), 0, 2);
        world.setBlock(i, j + 13, k + 6, placeStoneBricks(random), 0, 2);
        world.setBlock(i + 1, j + 13, k + 6, Blocks.air, 0, 2);
        world.setBlock(i + 2, j + 13, k + 6, Blocks.air, 0, 2);
        world.setBlock(i + 3, j + 13, k + 6, Blocks.air, 0, 2);
        world.setBlock(i + 4, j + 13, k + 6, placeStoneBricks(random), 0, 2);
        world.setBlock(i, j + 13, k + 7, placeStoneBricks(random), 0, 2);
        world.setBlock(i + 1, j + 13, k + 7, placeStoneBricks(random), 0, 2);
        world.setBlock(i + 2, j + 13, k + 7, placeStoneBricks(random), 0, 2);
        world.setBlock(i + 3, j + 13, k + 7, placeStoneBricks(random), 0, 2);
        world.setBlock(i + 4, j + 13, k + 7, placeStoneBricks(random), 0, 2);
        world.setBlock(i, j + 14, k, placeStoneBricks(random), 0, 2);
        world.setBlock(i + 1, j + 14, k, placeStoneBricks(random), 0, 2);
        world.setBlock(i + 2, j + 14, k, placeStoneBricks(random), 0, 2);
        world.setBlock(i + 3, j + 14, k, placeStoneBricks(random), 0, 2);
        world.setBlock(i + 4, j + 14, k, placeStoneBricks(random), 0, 2);
        world.setBlock(i, j + 14, k + 1, placeStoneBricks(random), 0, 2);
        world.setBlock(i + 1, j + 14, k + 1, Blocks.air, 0, 2);
        world.setBlock(i + 2, j + 14, k + 1, Blocks.air, 0, 2);
        world.setBlock(i + 3, j + 14, k + 1, Blocks.air, 0, 2);
        world.setBlock(i + 4, j + 14, k + 1, placeStoneBricks(random), 0, 2);
        world.setBlock(i, j + 14, k + 2, placeStoneBricks(random), 0, 2);
        world.setBlock(i + 1, j + 14, k + 2, Blocks.air, 0, 2);
        world.setBlock(i + 2, j + 14, k + 2, NovaCraftBlocks.luminant_log, 0, 2);
        world.setBlock(i + 3, j + 14, k + 2, Blocks.air, 0, 2);
        world.setBlock(i + 4, j + 14, k + 2, placeStoneBricks(random), 0, 2);
        world.setBlock(i, j + 14, k + 3, placeStoneBricks(random), 0, 2);
        world.setBlock(i + 1, j + 14, k + 3, placeStoneBricks(random), 0, 2);
        world.setBlock(i + 2, j + 14, k + 3, NovaCraftBlocks.luminant_log, 0, 2);
        world.setBlock(i + 3, j + 14, k + 3, Blocks.air, 0, 2);
        world.setBlock(i + 4, j + 14, k + 3, placeStoneBricks(random), 0, 2);
        world.setBlock(i, j + 14, k + 4, placeStoneBricks(random), 0, 2);
        world.setBlock(i + 1, j + 14, k + 4, NovaCraftBlocks.luminant_stairs, 3, 2);
        world.setBlock(i + 2, j + 14, k + 4, NovaCraftBlocks.luminant_log, 0, 2);
        world.setBlock(i + 3, j + 14, k + 4, Blocks.air, 0, 2);
        world.setBlock(i + 4, j + 14, k + 4, placeStoneBricks(random), 0, 2);
        world.setBlock(i, j + 14, k + 5, placeStoneBricks(random), 0, 2);
        world.setBlock(i + 1, j + 14, k + 5, Blocks.air, 0, 2);
        world.setBlock(i + 2, j + 14, k + 5, NovaCraftBlocks.luminant_log, 0, 2);
        world.setBlock(i + 3, j + 14, k + 5, Blocks.air, 0, 2);
        world.setBlock(i + 4, j + 14, k + 5, placeStoneBricks(random), 0, 2);
        world.setBlock(i, j + 14, k + 6, placeStoneBricks(random), 0, 2);
        world.setBlock(i + 1, j + 14, k + 6, Blocks.air, 0, 2);
        world.setBlock(i + 3, j + 14, k + 6, Blocks.air, 0, 2);
        world.setBlock(i + 4, j + 14, k + 6, placeStoneBricks(random), 0, 2);
        world.setBlock(i, j + 14, k + 7, placeStoneBricks(random), 0, 2);
        world.setBlock(i + 1, j + 14, k + 7, placeStoneBricks(random), 0, 2);
        world.setBlock(i + 2, j + 14, k + 7, placeStoneBricks(random), 0, 2);
        world.setBlock(i + 3, j + 14, k + 7, placeStoneBricks(random), 0, 2);
        world.setBlock(i + 4, j + 14, k + 7, placeStoneBricks(random), 0, 2);
        world.setBlock(i, j + 15, k, placeStoneBricks(random), 0, 2);
        world.setBlock(i + 1, j + 15, k, placeStoneBricks(random), 0, 2);
        world.setBlock(i + 2, j + 15, k, placeStoneBricks(random), 0, 2);
        world.setBlock(i + 3, j + 15, k, placeStoneBricks(random), 0, 2);
        world.setBlock(i + 4, j + 15, k, placeStoneBricks(random), 0, 2);
        world.setBlock(i, j + 15, k + 1, placeStoneBricks(random), 0, 2);
        world.setBlock(i + 1, j + 15, k + 1, Blocks.air, 0, 2);
        world.setBlock(i + 2, j + 15, k + 1, Blocks.air, 0, 2);
        world.setBlock(i + 3, j + 15, k + 1, Blocks.air, 0, 2);
        world.setBlock(i + 4, j + 15, k + 1, placeStoneBricks(random), 0, 2);
        world.setBlock(i, j + 15, k + 2, placeStoneBricks(random), 0, 2);
        world.setBlock(i + 1, j + 15, k + 2, placeStoneBricks(random), 0, 2);
        world.setBlock(i + 2, j + 15, k + 2, NovaCraftBlocks.luminant_log, 0, 2);
        world.setBlock(i + 3, j + 15, k + 2, Blocks.air, 0, 2);
        world.setBlock(i + 4, j + 15, k + 2, placeStoneBricks(random), 0, 2);
        world.setBlock(i, j + 15, k + 3, placeStoneBricks(random), 0, 2);
        world.setBlock(i + 1, j + 15, k + 3, NovaCraftBlocks.luminant_stairs, 3, 2);
        world.setBlock(i + 2, j + 15, k + 3, NovaCraftBlocks.luminant_log, 0, 2);
        world.setBlock(i + 3, j + 15, k + 3, Blocks.air, 0, 2);
        world.setBlock(i + 4, j + 15, k + 3, placeStoneBricks(random), 0, 2);
        world.setBlock(i, j + 15, k + 4, placeStoneBricks(random), 0, 2);
        world.setBlock(i + 1, j + 15, k + 4, Blocks.air, 0, 2);
        world.setBlock(i + 2, j + 15, k + 4, NovaCraftBlocks.luminant_log, 0, 2);
        world.setBlock(i + 3, j + 15, k + 4, Blocks.air, 0, 2);
        world.setBlock(i + 4, j + 15, k + 4, placeStoneBricks(random), 0, 2);
        world.setBlock(i, j + 15, k + 5, placeStoneBricks(random), 0, 2);
        world.setBlock(i + 1, j + 15, k + 5, Blocks.air, 0, 2);
        world.setBlock(i + 2, j + 15, k + 5, NovaCraftBlocks.luminant_log, 0, 2);
        world.setBlock(i + 3, j + 15, k + 5, Blocks.air, 0, 2);
        world.setBlock(i + 4, j + 15, k + 5, placeStoneBricks(random), 0, 2);
        world.setBlock(i, j + 15, k + 6, placeStoneBricks(random), 0, 2);
        world.setBlock(i + 1, j + 15, k + 6, Blocks.air, 0, 2);
        world.setBlock(i + 2, j + 15, k + 6, Blocks.air, 0, 2);
        world.setBlock(i + 3, j + 15, k + 6, Blocks.air, 0, 2);
        world.setBlock(i + 4, j + 15, k + 6, placeStoneBricks(random), 0, 2);
        world.setBlock(i, j + 15, k + 7, placeStoneBricks(random), 0, 2);
        world.setBlock(i + 1, j + 15, k + 7, placeStoneBricks(random), 0, 2);
        world.setBlock(i + 2, j + 15, k + 7, placeStoneBricks(random), 0, 2);
        world.setBlock(i + 3, j + 15, k + 7, placeStoneBricks(random), 0, 2);
        world.setBlock(i + 4, j + 15, k + 7, placeStoneBricks(random), 0, 2);
        world.setBlock(i, j + 16, k, placeStoneBricks(random), 0, 2);
        world.setBlock(i + 1, j + 16, k, placeStoneBricks(random), 0, 2);
        world.setBlock(i + 2, j + 16, k, placeStoneBricks(random), 0, 2);
        world.setBlock(i + 3, j + 16, k, placeStoneBricks(random), 0, 2);
        world.setBlock(i + 4, j + 16, k, placeStoneBricks(random), 0, 2);
        world.setBlock(i, j + 16, k + 1, placeStoneBricks(random), 0, 2);
        world.setBlock(i + 1, j + 16, k + 1, placeStoneBricks(random), 0, 2);
        world.setBlock(i + 2, j + 16, k + 1, Blocks.air, 0, 2);
        world.setBlock(i + 3, j + 16, k + 1, Blocks.air, 0, 2);
        world.setBlock(i + 4, j + 16, k + 1, placeStoneBricks(random), 0, 2);
        world.setBlock(i, j + 16, k + 2, placeStoneBricks(random), 0, 2);
        world.setBlock(i + 1, j + 16, k + 2, NovaCraftBlocks.luminant_stairs, 3, 2);
        world.setBlock(i + 2, j + 16, k + 2, NovaCraftBlocks.luminant_log, 0, 2);
        world.setBlock(i + 3, j + 16, k + 2, Blocks.air, 0, 2);
        world.setBlock(i + 4, j + 16, k + 2, placeStoneBricks(random), 0, 2);
        world.setBlock(i, j + 16, k + 3, placeStoneBricks(random), 0, 2);
        world.setBlock(i + 1, j + 16, k + 3, Blocks.air, 0, 2);
        world.setBlock(i + 2, j + 16, k + 3, NovaCraftBlocks.luminant_log, 0, 2);
        world.setBlock(i + 3, j + 16, k + 3, Blocks.air, 0, 2);
        world.setBlock(i + 4, j + 16, k + 3, placeStoneBricks(random), 0, 2);
        world.setBlock(i, j + 16, k + 4, placeStoneBricks(random), 0, 2);
        world.setBlock(i + 1, j + 16, k + 4, Blocks.air, 0, 2);
        world.setBlock(i + 2, j + 16, k + 4, NovaCraftBlocks.luminant_log, 0, 2);
        world.setBlock(i + 3, j + 16, k + 4, Blocks.air, 0, 2);
        world.setBlock(i + 4, j + 16, k + 4, placeStoneBricks(random), 0, 2);
        world.setBlock(i, j + 16, k + 5, placeStoneBricks(random), 0, 2);
        world.setBlock(i + 1, j + 16, k + 5, Blocks.air, 0, 2);
        world.setBlock(i + 2, j + 16, k + 5, NovaCraftBlocks.luminant_log, 0, 2);
        world.setBlock(i + 3, j + 16, k + 5, Blocks.air, 0, 2);
        world.setBlock(i + 4, j + 16, k + 5, placeStoneBricks(random), 0, 2);
        world.setBlock(i, j + 16, k + 6, placeStoneBricks(random), 0, 2);
        world.setBlock(i + 1, j + 16, k + 6, Blocks.air, 0, 2);
        world.setBlock(i + 2, j + 16, k + 6, Blocks.air, 0, 2);
        world.setBlock(i + 3, j + 16, k + 6, Blocks.air, 0, 2);
        world.setBlock(i + 4, j + 16, k + 6, placeStoneBricks(random), 0, 2);
        world.setBlock(i, j + 16, k + 7, placeStoneBricks(random), 0, 2);
        world.setBlock(i + 1, j + 16, k + 7, placeStoneBricks(random), 0, 2);
        world.setBlock(i + 2, j + 16, k + 7, placeStoneBricks(random), 0, 2);
        world.setBlock(i + 3, j + 16, k + 7, placeStoneBricks(random), 0, 2);
        world.setBlock(i + 4, j + 16, k + 7, placeStoneBricks(random), 0, 2);
        world.setBlock(i, j + 17, k, placeStoneBricks(random), 0, 2);
        world.setBlock(i + 1, j + 17, k, placeStoneBricks(random), 0, 2);
        world.setBlock(i + 2, j + 17, k, placeStoneBricks(random), 0, 2);
        world.setBlock(i + 3, j + 17, k, placeStoneBricks(random), 0, 2);
        world.setBlock(i + 4, j + 17, k, placeStoneBricks(random), 0, 2);
        world.setBlock(i, j + 17, k + 1, placeStoneBricks(random), 0, 2);
        world.setBlock(i + 1, j + 17, k + 1, NovaCraftBlocks.luminant_stairs, 3, 2);
        world.setBlock(i + 2, j + 17, k + 1, placeStoneBricks(random), 0, 2);
        world.setBlock(i + 3, j + 17, k + 1, Blocks.air, 0, 2);
        world.setBlock(i + 4, j + 17, k + 1, placeStoneBricks(random), 0, 2);
        world.setBlock(i, j + 17, k + 2, placeStoneBricks(random), 0, 2);
        world.setBlock(i + 1, j + 17, k + 2, Blocks.air, 0, 2);
        world.setBlock(i + 2, j + 17, k + 2, NovaCraftBlocks.luminant_log, 0, 2);
        world.setBlock(i + 3, j + 17, k + 2, Blocks.air, 0, 2);
        world.setBlock(i + 4, j + 17, k + 2, placeStoneBricks(random), 0, 2);
        world.setBlock(i, j + 17, k + 3, placeStoneBricks(random), 0, 2);
        world.setBlock(i + 1, j + 17, k + 3, Blocks.air, 0, 2);
        world.setBlock(i + 2, j + 17, k + 3, NovaCraftBlocks.luminant_log, 0, 2);
        world.setBlock(i + 3, j + 17, k + 3, Blocks.air, 0, 2);
        world.setBlock(i + 4, j + 17, k + 3, placeStoneBricks(random), 0, 2);
        world.setBlock(i, j + 17, k + 4, placeStoneBricks(random), 0, 2);
        world.setBlock(i + 1, j + 17, k + 4, Blocks.air, 0, 2);
        world.setBlock(i + 2, j + 17, k + 4, NovaCraftBlocks.luminant_log, 0, 2);
        world.setBlock(i + 3, j + 17, k + 4, Blocks.air, 0, 2);
        world.setBlock(i + 4, j + 17, k + 4, placeStoneBricks(random), 0, 2);
        world.setBlock(i, j + 17, k + 5, placeStoneBricks(random), 0, 2);
        world.setBlock(i + 1, j + 17, k + 5, Blocks.air, 0, 2);
        world.setBlock(i + 2, j + 17, k + 5, NovaCraftBlocks.luminant_log, 0, 2);
        world.setBlock(i + 3, j + 17, k + 5, Blocks.air, 0, 2);
        world.setBlock(i + 4, j + 17, k + 5, placeStoneBricks(random), 0, 2);
        world.setBlock(i, j + 17, k + 6, placeStoneBricks(random), 0, 2);
        world.setBlock(i + 1, j + 17, k + 6, Blocks.air, 0, 2);
        world.setBlock(i + 2, j + 17, k + 6, Blocks.air, 0, 2);
        world.setBlock(i + 3, j + 17, k + 6, Blocks.air, 0, 2);
        world.setBlock(i + 4, j + 17, k + 6, placeStoneBricks(random), 0, 2);
        world.setBlock(i, j + 17, k + 7, placeStoneBricks(random), 0, 2);
        world.setBlock(i + 1, j + 17, k + 7, placeStoneBricks(random), 0, 2);
        world.setBlock(i + 2, j + 17, k + 7, placeStoneBricks(random), 0, 2);
        world.setBlock(i + 3, j + 17, k + 7, placeStoneBricks(random), 0, 2);
        world.setBlock(i + 4, j + 17, k + 7, placeStoneBricks(random), 0, 2);
        world.setBlock(i, j + 18, k, placeStoneBricks(random), 0, 2);
        world.setBlock(i + 1, j + 18, k, placeStoneBricks(random), 0, 2);
        world.setBlock(i + 2, j + 18, k, placeStoneBricks(random), 0, 2);
        world.setBlock(i + 3, j + 18, k, placeStoneBricks(random), 0, 2);
        world.setBlock(i + 4, j + 18, k, placeStoneBricks(random), 0, 2);
        world.setBlock(i, j + 18, k + 1, placeStoneBricks(random), 0, 2);
        world.setBlock(i + 1, j + 18, k + 1, Blocks.air, 0, 2);
        world.setBlock(i + 2, j + 18, k + 1, NovaCraftBlocks.luminant_stairs, 0, 2);
        world.setBlock(i + 3, j + 18, k + 1, placeStoneBricks(random), 0, 2);
        world.setBlock(i + 4, j + 18, k + 1, placeStoneBricks(random), 0, 2);
        world.setBlock(i, j + 18, k + 2, placeStoneBricks(random), 0, 2);
        world.setBlock(i + 1, j + 18, k + 2, Blocks.air, 0, 2);
        world.setBlock(i + 2, j + 18, k + 2, NovaCraftBlocks.luminant_log, 0, 2);
        world.setBlock(i + 3, j + 18, k + 2, Blocks.air, 0, 2);
        world.setBlock(i + 4, j + 18, k + 2, placeStoneBricks(random), 0, 2);
        world.setBlock(i, j + 18, k + 3, placeStoneBricks(random), 0, 2);
        world.setBlock(i + 1, j + 18, k + 3, Blocks.air, 0, 2);
        world.setBlock(i + 2, j + 18, k + 3, NovaCraftBlocks.luminant_log, 0, 2);
        world.setBlock(i + 3, j + 18, k + 3, Blocks.air, 0, 2);
        world.setBlock(i + 4, j + 18, k + 3, placeStoneBricks(random), 0, 2);
        world.setBlock(i, j + 18, k + 4, placeStoneBricks(random), 0, 2);
        world.setBlock(i + 1, j + 18, k + 4, Blocks.air, 0, 2);
        world.setBlock(i + 2, j + 18, k + 4, NovaCraftBlocks.luminant_log, 0, 2);
        world.setBlock(i + 3, j + 18, k + 4, Blocks.air, 0, 2);
        world.setBlock(i + 4, j + 18, k + 4, placeStoneBricks(random), 0, 2);
        world.setBlock(i, j + 18, k + 5, placeStoneBricks(random), 0, 2);
        world.setBlock(i + 1, j + 18, k + 5, Blocks.air, 0, 2);
        world.setBlock(i + 2, j + 18, k + 5, NovaCraftBlocks.luminant_log, 0, 2);
        world.setBlock(i + 3, j + 18, k + 5, Blocks.air, 0, 2);
        world.setBlock(i + 4, j + 18, k + 5, placeStoneBricks(random), 0, 2);
        world.setBlock(i, j + 18, k + 6, placeStoneBricks(random), 0, 2);
        world.setBlock(i + 1, j + 18, k + 6, Blocks.air, 0, 2);
        world.setBlock(i + 2, j + 18, k + 6, Blocks.air, 0, 2);
        world.setBlock(i + 3, j + 18, k + 6, Blocks.air, 0, 2);
        world.setBlock(i + 4, j + 18, k + 6, placeStoneBricks(random), 0, 2);
        world.setBlock(i, j + 18, k + 7, placeStoneBricks(random), 0, 2);
        world.setBlock(i + 1, j + 18, k + 7, placeStoneBricks(random), 0, 2);
        world.setBlock(i + 2, j + 18, k + 7, placeStoneBricks(random), 0, 2);
        world.setBlock(i + 3, j + 18, k + 7, placeStoneBricks(random), 0, 2);
        world.setBlock(i + 4, j + 18, k + 7, placeStoneBricks(random), 0, 2);
        world.setBlock(i, j + 19, k, placeStoneBricks(random), 0, 2);
        world.setBlock(i + 1, j + 19, k, placeStoneBricks(random), 0, 2);
        world.setBlock(i + 2, j + 19, k, placeStoneBricks(random), 0, 2);
        world.setBlock(i + 3, j + 19, k, placeStoneBricks(random), 0, 2);
        world.setBlock(i + 4, j + 19, k, placeStoneBricks(random), 0, 2);
        world.setBlock(i, j + 19, k + 1, placeStoneBricks(random), 0, 2);
        world.setBlock(i + 1, j + 19, k + 1, Blocks.air, 0, 2);
        world.setBlock(i + 2, j + 19, k + 1, Blocks.air, 0, 2);
        world.setBlock(i + 3, j + 19, k + 1, NovaCraftBlocks.luminant_stairs, 0, 2);
        world.setBlock(i + 4, j + 19, k + 1, placeStoneBricks(random), 0, 2);
        world.setBlock(i, j + 19, k + 2, placeStoneBricks(random), 0, 2);
        world.setBlock(i + 1, j + 19, k + 2, Blocks.air, 0, 2);
        world.setBlock(i + 2, j + 19, k + 2, NovaCraftBlocks.luminant_log, 0, 2);
        world.setBlock(i + 3, j + 19, k + 2, placeStoneBricks(random), 0, 2);
        world.setBlock(i + 4, j + 19, k + 2, placeStoneBricks(random), 0, 2);
        world.setBlock(i, j + 19, k + 3, placeStoneBricks(random), 0, 2);
        world.setBlock(i + 2, j + 19, k + 3, NovaCraftBlocks.luminant_log, 0, 2);
        world.setBlock(i + 3, j + 19, k + 3, Blocks.air, 0, 2);
        world.setBlock(i + 4, j + 19, k + 3, placeStoneBricks(random), 0, 2);
        world.setBlock(i, j + 19, k + 4, placeStoneBricks(random), 0, 2);
        world.setBlock(i + 1, j + 19, k + 4, Blocks.air, 0, 2);
        world.setBlock(i + 2, j + 19, k + 4, NovaCraftBlocks.luminant_log, 0, 2);
        world.setBlock(i + 3, j + 19, k + 4, Blocks.air, 0, 2);
        world.setBlock(i + 4, j + 19, k + 4, placeStoneBricks(random), 0, 2);
        world.setBlock(i, j + 19, k + 5, placeStoneBricks(random), 0, 2);
        world.setBlock(i + 1, j + 19, k + 5, Blocks.air, 0, 2);
        world.setBlock(i + 2, j + 19, k + 5, NovaCraftBlocks.luminant_log, 0, 2);
        world.setBlock(i + 3, j + 19, k + 5, Blocks.air, 0, 2);
        world.setBlock(i + 4, j + 19, k + 5, placeStoneBricks(random), 0, 2);
        world.setBlock(i, j + 19, k + 6, placeStoneBricks(random), 0, 2);
        world.setBlock(i + 1, j + 19, k + 6, Blocks.air, 0, 2);
        world.setBlock(i + 2, j + 19, k + 6, Blocks.air, 0, 2);
        world.setBlock(i + 3, j + 19, k + 6, Blocks.air, 0, 2);
        world.setBlock(i + 4, j + 19, k + 6, placeStoneBricks(random), 0, 2);
        world.setBlock(i, j + 19, k + 7, placeStoneBricks(random), 0, 2);
        world.setBlock(i + 1, j + 19, k + 7, placeStoneBricks(random), 0, 2);
        world.setBlock(i + 2, j + 19, k + 7, placeStoneBricks(random), 0, 2);
        world.setBlock(i + 3, j + 19, k + 7, placeStoneBricks(random), 0, 2);
        world.setBlock(i + 4, j + 19, k + 7, placeStoneBricks(random), 0, 2);
        world.setBlock(i, j + 20, k, placeStoneBricks(random), 0, 2);
        world.setBlock(i + 1, j + 20, k, placeStoneBricks(random), 0, 2);
        world.setBlock(i + 2, j + 20, k, placeStoneBricks(random), 0, 2);
        world.setBlock(i + 3, j + 20, k, placeStoneBricks(random), 0, 2);
        world.setBlock(i + 4, j + 20, k, placeStoneBricks(random), 0, 2);
        world.setBlock(i, j + 20, k + 1, placeStoneBricks(random), 0, 2);
        world.setBlock(i + 1, j + 20, k + 1, Blocks.air, 0, 2);
        world.setBlock(i + 2, j + 20, k + 1, Blocks.air, 0, 2);
        world.setBlock(i + 3, j + 20, k + 1, Blocks.air, 0, 2);
        world.setBlock(i + 4, j + 20, k + 1, placeStoneBricks(random), 0, 2);
        world.setBlock(i, j + 20, k + 2, placeStoneBricks(random), 0, 2);
        world.setBlock(i + 1, j + 20, k + 2, Blocks.air, 0, 2);
        world.setBlock(i + 2, j + 20, k + 2, NovaCraftBlocks.luminant_log, 0, 2);
        world.setBlock(i + 3, j + 20, k + 2, NovaCraftBlocks.luminant_stairs, 2, 2);
        world.setBlock(i + 4, j + 20, k + 2, placeStoneBricks(random), 0, 2);
        world.setBlock(i, j + 20, k + 3, placeStoneBricks(random), 0, 2);
        world.setBlock(i + 1, j + 20, k + 3, Blocks.air, 0, 2);
        world.setBlock(i + 2, j + 20, k + 3, NovaCraftBlocks.luminant_log, 0, 2);
        world.setBlock(i + 3, j + 20, k + 3, placeStoneBricks(random), 0, 2);
        world.setBlock(i + 4, j + 20, k + 3, placeStoneBricks(random), 0, 2);
        world.setBlock(i, j + 20, k + 4, placeStoneBricks(random), 0, 2);
        world.setBlock(i + 1, j + 20, k + 4, Blocks.air, 0, 2);
        world.setBlock(i + 2, j + 20, k + 4, NovaCraftBlocks.luminant_log, 0, 2);
        world.setBlock(i + 3, j + 20, k + 4, Blocks.air, 0, 2);
        world.setBlock(i + 4, j + 20, k + 4, placeStoneBricks(random), 0, 2);
        world.setBlock(i, j + 20, k + 5, placeStoneBricks(random), 0, 2);
        world.setBlock(i + 1, j + 20, k + 5, Blocks.air, 0, 2);
        world.setBlock(i + 2, j + 20, k + 5, NovaCraftBlocks.luminant_log, 0, 2);
        world.setBlock(i + 3, j + 20, k + 5, Blocks.air, 0, 2);
        world.setBlock(i + 4, j + 20, k + 5, placeStoneBricks(random), 0, 2);
        world.setBlock(i, j + 20, k + 6, placeStoneBricks(random), 0, 2);
        world.setBlock(i + 1, j + 20, k + 6, Blocks.air, 0, 2);
        world.setBlock(i + 2, j + 20, k + 6, Blocks.air, 0, 2);
        world.setBlock(i + 3, j + 20, k + 6, Blocks.air, 0, 2);
        world.setBlock(i + 4, j + 20, k + 6, placeStoneBricks(random), 0, 2);
        world.setBlock(i, j + 20, k + 7, placeStoneBricks(random), 0, 2);
        world.setBlock(i + 1, j + 20, k + 7, placeStoneBricks(random), 0, 2);
        world.setBlock(i + 2, j + 20, k + 7, placeStoneBricks(random), 0, 2);
        world.setBlock(i + 3, j + 20, k + 7, placeStoneBricks(random), 0, 2);
        world.setBlock(i + 4, j + 20, k + 7, placeStoneBricks(random), 0, 2);
        world.setBlock(i, j + 21, k, placeStoneBricks(random), 0, 2);
        world.setBlock(i + 1, j + 21, k, placeStoneBricks(random), 0, 2);
        world.setBlock(i + 2, j + 21, k, placeStoneBricks(random), 0, 2);
        world.setBlock(i + 3, j + 21, k, placeStoneBricks(random), 0, 2);
        world.setBlock(i + 4, j + 21, k, placeStoneBricks(random), 0, 2);
        world.setBlock(i, j + 21, k + 1, placeStoneBricks(random), 0, 2);
        world.setBlock(i + 1, j + 21, k + 1, Blocks.air, 0, 2);
        world.setBlock(i + 2, j + 21, k + 1, Blocks.air, 0, 2);
        world.setBlock(i + 3, j + 21, k + 1, Blocks.air, 0, 2);
        world.setBlock(i + 4, j + 21, k + 1, placeStoneBricks(random), 0, 2);
        world.setBlock(i, j + 21, k + 2, placeStoneBricks(random), 0, 2);
        world.setBlock(i + 1, j + 21, k + 2, Blocks.air, 0, 2);
        world.setBlock(i + 2, j + 21, k + 2, NovaCraftBlocks.luminant_log, 0, 2);
        world.setBlock(i + 3, j + 21, k + 2, Blocks.air, 0, 2);
        world.setBlock(i + 4, j + 21, k + 2, placeStoneBricks(random), 0, 2);
        world.setBlock(i, j + 21, k + 3, placeStoneBricks(random), 0, 2);
        world.setBlock(i + 1, j + 21, k + 3, Blocks.air, 0, 2);
        world.setBlock(i + 2, j + 21, k + 3, NovaCraftBlocks.luminant_log, 0, 2);
        world.setBlock(i + 3, j + 21, k + 3, NovaCraftBlocks.luminant_stairs, 2, 2);
        world.setBlock(i + 4, j + 21, k + 3, placeStoneBricks(random), 0, 2);
        world.setBlock(i, j + 21, k + 4, placeStoneBricks(random), 0, 2);
        world.setBlock(i + 1, j + 21, k + 4, Blocks.air, 0, 2);
        world.setBlock(i + 2, j + 21, k + 4, NovaCraftBlocks.luminant_log, 0, 2);
        world.setBlock(i + 3, j + 21, k + 4, placeStoneBricks(random), 0, 2);
        world.setBlock(i + 4, j + 21, k + 4, placeStoneBricks(random), 0, 2);
        world.setBlock(i, j + 21, k + 5, placeStoneBricks(random), 0, 2);
        world.setBlock(i + 1, j + 21, k + 5, Blocks.air, 0, 2);
        world.setBlock(i + 2, j + 21, k + 5, NovaCraftBlocks.luminant_log, 0, 2);
        world.setBlock(i + 3, j + 21, k + 5, Blocks.air, 0, 2);
        world.setBlock(i + 4, j + 21, k + 5, placeStoneBricks(random), 0, 2);
        world.setBlock(i, j + 21, k + 6, placeStoneBricks(random), 0, 2);
        world.setBlock(i + 1, j + 21, k + 6, Blocks.air, 0, 2);
        world.setBlock(i + 2, j + 21, k + 6, Blocks.air, 0, 2);
        world.setBlock(i + 3, j + 21, k + 6, Blocks.air, 0, 2);
        world.setBlock(i + 4, j + 21, k + 6, placeStoneBricks(random), 0, 2);
        world.setBlock(i, j + 21, k + 7, placeStoneBricks(random), 0, 2);
        world.setBlock(i + 1, j + 21, k + 7, placeStoneBricks(random), 0, 2);
        world.setBlock(i + 2, j + 21, k + 7, placeStoneBricks(random), 0, 2);
        world.setBlock(i + 3, j + 21, k + 7, placeStoneBricks(random), 0, 2);
        world.setBlock(i + 4, j + 21, k + 7, placeStoneBricks(random), 0, 2);
        world.setBlock(i, j + 22, k, placeStoneBricks(random), 0, 2);
        world.setBlock(i + 1, j + 22, k, placeStoneBricks(random), 0, 2);
        world.setBlock(i + 2, j + 22, k, placeStoneBricks(random), 0, 2);
        world.setBlock(i + 3, j + 22, k, placeStoneBricks(random), 0, 2);
        world.setBlock(i + 4, j + 22, k, placeStoneBricks(random), 0, 2);
        world.setBlock(i, j + 22, k + 1, placeStoneBricks(random), 0, 2);
        world.setBlock(i + 1, j + 22, k + 1, Blocks.air, 0, 2);
        world.setBlock(i + 2, j + 22, k + 1, Blocks.air, 0, 2);
        world.setBlock(i + 3, j + 22, k + 1, Blocks.air, 0, 2);
        world.setBlock(i + 4, j + 22, k + 1, placeStoneBricks(random), 0, 2);
        world.setBlock(i, j + 22, k + 2, placeStoneBricks(random), 0, 2);
        world.setBlock(i + 1, j + 22, k + 2, Blocks.air, 0, 2);
        world.setBlock(i + 2, j + 22, k + 2, NovaCraftBlocks.luminant_log, 0, 2);
        world.setBlock(i + 3, j + 22, k + 2, Blocks.air, 0, 2);
        world.setBlock(i + 4, j + 22, k + 2, placeStoneBricks(random), 0, 2);
        world.setBlock(i, j + 22, k + 3, placeStoneBricks(random), 0, 2);
        world.setBlock(i + 1, j + 22, k + 3, Blocks.air, 0, 2);
        world.setBlock(i + 2, j + 22, k + 3, NovaCraftBlocks.luminant_log, 0, 2);
        world.setBlock(i + 3, j + 22, k + 3, Blocks.air, 0, 2);
        world.setBlock(i + 4, j + 22, k + 3, placeStoneBricks(random), 0, 2);
        world.setBlock(i, j + 22, k + 4, placeStoneBricks(random), 0, 2);
        world.setBlock(i + 1, j + 22, k + 4, Blocks.air, 0, 2);
        world.setBlock(i + 2, j + 22, k + 4, NovaCraftBlocks.luminant_log, 0, 2);
        world.setBlock(i + 3, j + 22, k + 4, NovaCraftBlocks.luminant_stairs, 2, 2);
        world.setBlock(i + 4, j + 22, k + 4, placeStoneBricks(random), 0, 2);
        world.setBlock(i, j + 22, k + 5, placeStoneBricks(random), 0, 2);
        world.setBlock(i + 1, j + 22, k + 5, Blocks.air, 0, 2);
        world.setBlock(i + 2, j + 22, k + 5, NovaCraftBlocks.luminant_log, 0, 2);
        world.setBlock(i + 3, j + 22, k + 5, placeStoneBricks(random), 0, 2);
        world.setBlock(i + 4, j + 22, k + 5, placeStoneBricks(random), 0, 2);
        world.setBlock(i, j + 22, k + 6, placeStoneBricks(random), 0, 2);
        world.setBlock(i + 1, j + 22, k + 6, Blocks.air, 0, 2);
        world.setBlock(i + 2, j + 22, k + 6, Blocks.air, 0, 2);
        world.setBlock(i + 3, j + 22, k + 6, Blocks.air, 0, 2);
        world.setBlock(i + 4, j + 22, k + 6, placeStoneBricks(random), 0, 2);
        world.setBlock(i, j + 22, k + 7, placeStoneBricks(random), 0, 2);
        world.setBlock(i + 1, j + 22, k + 7, placeStoneBricks(random), 0, 2);
        world.setBlock(i + 2, j + 22, k + 7, placeStoneBricks(random), 0, 2);
        world.setBlock(i + 3, j + 22, k + 7, placeStoneBricks(random), 0, 2);
        world.setBlock(i + 4, j + 22, k + 7, placeStoneBricks(random), 0, 2);
        world.setBlock(i, j + 23, k, placeStoneBricks(random), 0, 2);
        world.setBlock(i + 1, j + 23, k, placeStoneBricks(random), 0, 2);
        world.setBlock(i + 2, j + 23, k, placeStoneBricks(random), 0, 2);
        world.setBlock(i + 3, j + 23, k, placeStoneBricks(random), 0, 2);
        world.setBlock(i + 4, j + 23, k, placeStoneBricks(random), 0, 2);
        world.setBlock(i, j + 23, k + 1, placeStoneBricks(random), 0, 2);
        world.setBlock(i + 1, j + 23, k + 1, Blocks.air, 0, 2);
        world.setBlock(i + 2, j + 23, k + 1, Blocks.air, 0, 2);
        world.setBlock(i + 3, j + 23, k + 1, Blocks.air, 0, 2);
        world.setBlock(i + 4, j + 23, k + 1, placeStoneBricks(random), 0, 2);
        world.setBlock(i, j + 23, k + 2, placeStoneBricks(random), 0, 2);
        world.setBlock(i + 1, j + 23, k + 2, Blocks.air, 0, 2);
        world.setBlock(i + 2, j + 23, k + 2, NovaCraftBlocks.luminant_log, 0, 2);
        world.setBlock(i + 3, j + 23, k + 2, Blocks.air, 0, 2);
        world.setBlock(i + 4, j + 23, k + 2, placeStoneBricks(random), 0, 2);
        world.setBlock(i, j + 23, k + 3, placeStoneBricks(random), 0, 2);
        world.setBlock(i + 1, j + 23, k + 3, Blocks.air, 0, 2);
        world.setBlock(i + 2, j + 23, k + 3, NovaCraftBlocks.luminant_log, 0, 2);
        world.setBlock(i + 3, j + 23, k + 3, Blocks.air, 0, 2);
        world.setBlock(i + 4, j + 23, k + 3, placeStoneBricks(random), 0, 2);
        world.setBlock(i, j + 23, k + 4, placeStoneBricks(random), 0, 2);
        world.setBlock(i + 1, j + 23, k + 4, Blocks.air, 0, 2);
        world.setBlock(i + 2, j + 23, k + 4, NovaCraftBlocks.luminant_log, 0, 2);
        world.setBlock(i + 3, j + 23, k + 4, Blocks.air, 0, 2);
        world.setBlock(i + 4, j + 23, k + 4, placeStoneBricks(random), 0, 2);
        world.setBlock(i, j + 23, k + 5, placeStoneBricks(random), 0, 2);
        world.setBlock(i + 1, j + 23, k + 5, Blocks.air, 0, 2);
        world.setBlock(i + 2, j + 23, k + 5, NovaCraftBlocks.luminant_log, 0, 2);
        world.setBlock(i + 3, j + 23, k + 5, NovaCraftBlocks.luminant_stairs, 2, 2);
        world.setBlock(i + 4, j + 23, k + 5, placeStoneBricks(random), 0, 2);
        world.setBlock(i, j + 23, k + 6, placeStoneBricks(random), 0, 2);
        world.setBlock(i + 1, j + 23, k + 6, Blocks.air, 0, 2);
        world.setBlock(i + 2, j + 23, k + 6, Blocks.air, 0, 2);
        world.setBlock(i + 3, j + 23, k + 6, placeStoneBricks(random), 0, 2);
        world.setBlock(i + 4, j + 23, k + 6, placeStoneBricks(random), 0, 2);
        world.setBlock(i, j + 23, k + 7, placeStoneBricks(random), 0, 2);
        world.setBlock(i + 1, j + 23, k + 7, placeStoneBricks(random), 0, 2);
        world.setBlock(i + 2, j + 23, k + 7, placeStoneBricks(random), 0, 2);
        world.setBlock(i + 3, j + 23, k + 7, placeStoneBricks(random), 0, 2);
        world.setBlock(i + 4, j + 23, k + 7, placeStoneBricks(random), 0, 2);
        world.setBlock(i, j + 24, k, placeStoneBricks(random), 0, 2);
        world.setBlock(i + 1, j + 24, k, placeStoneBricks(random), 0, 2);
        world.setBlock(i + 2, j + 24, k, placeStoneBricks(random), 0, 2);
        world.setBlock(i + 3, j + 24, k, placeStoneBricks(random), 0, 2);
        world.setBlock(i + 4, j + 24, k, placeStoneBricks(random), 0, 2);
        world.setBlock(i, j + 24, k + 1, placeStoneBricks(random), 0, 2);
        world.setBlock(i + 1, j + 24, k + 1, Blocks.air, 0, 2);
        world.setBlock(i + 2, j + 24, k + 1, Blocks.air, 0, 2);
        world.setBlock(i + 3, j + 24, k + 1, Blocks.air, 0, 2);
        world.setBlock(i + 4, j + 24, k + 1, placeStoneBricks(random), 0, 2);
        world.setBlock(i, j + 24, k + 2, placeStoneBricks(random), 0, 2);
        world.setBlock(i + 1, j + 24, k + 2, Blocks.air, 0, 2);
        world.setBlock(i + 2, j + 24, k + 2, NovaCraftBlocks.luminant_log, 0, 2);
        world.setBlock(i + 3, j + 24, k + 2, Blocks.air, 0, 2);
        world.setBlock(i + 4, j + 24, k + 2, placeStoneBricks(random), 0, 2);
        world.setBlock(i, j + 24, k + 3, placeStoneBricks(random), 0, 2);
        world.setBlock(i + 1, j + 24, k + 3, Blocks.air, 0, 2);
        world.setBlock(i + 2, j + 24, k + 3, NovaCraftBlocks.luminant_log, 0, 2);
        world.setBlock(i + 3, j + 24, k + 3, Blocks.air, 0, 2);
        world.setBlock(i + 4, j + 24, k + 3, placeStoneBricks(random), 0, 2);
        world.setBlock(i, j + 24, k + 4, placeStoneBricks(random), 0, 2);
        world.setBlock(i + 1, j + 24, k + 4, Blocks.air, 0, 2);
        world.setBlock(i + 2, j + 24, k + 4, NovaCraftBlocks.luminant_log, 0, 2);
        world.setBlock(i + 3, j + 24, k + 4, Blocks.air, 0, 2);
        world.setBlock(i + 4, j + 24, k + 4, placeStoneBricks(random), 0, 2);
        world.setBlock(i, j + 24, k + 5, placeStoneBricks(random), 0, 2);
        world.setBlock(i + 1, j + 24, k + 5, Blocks.air, 0, 2);
        world.setBlock(i + 2, j + 24, k + 5, NovaCraftBlocks.luminant_log, 0, 2);
        world.setBlock(i + 3, j + 24, k + 5, Blocks.air, 0, 2);
        world.setBlock(i + 4, j + 24, k + 5, placeStoneBricks(random), 0, 2);
        world.setBlock(i, j + 24, k + 6, placeStoneBricks(random), 0, 2);
        world.setBlock(i + 1, j + 24, k + 6, Blocks.air, 0, 2);
        world.setBlock(i + 2, j + 24, k + 6, placeStoneBricks(random), 0, 2);
        world.setBlock(i + 3, j + 24, k + 6, NovaCraftBlocks.luminant_stairs, 2, 2);
        world.setBlock(i + 4, j + 24, k + 6, placeStoneBricks(random), 0, 2);
        world.setBlock(i, j + 24, k + 7, placeStoneBricks(random), 0, 2);
        world.setBlock(i + 1, j + 24, k + 7, placeStoneBricks(random), 0, 2);
        world.setBlock(i + 2, j + 24, k + 7, placeStoneBricks(random), 0, 2);
        world.setBlock(i + 3, j + 24, k + 7, placeStoneBricks(random), 0, 2);
        world.setBlock(i + 4, j + 24, k + 7, placeStoneBricks(random), 0, 2);
        world.setBlock(i, j + 25, k, placeStoneBricks(random), 0, 2);
        world.setBlock(i + 1, j + 25, k, placeStoneBricks(random), 0, 2);
        world.setBlock(i + 2, j + 25, k, placeStoneBricks(random), 0, 2);
        world.setBlock(i + 3, j + 25, k, placeStoneBricks(random), 0, 2);
        world.setBlock(i + 4, j + 25, k, placeStoneBricks(random), 0, 2);
        world.setBlock(i, j + 25, k + 1, placeStoneBricks(random), 0, 2);
        world.setBlock(i + 1, j + 25, k + 1, Blocks.air, 0, 2);
        world.setBlock(i + 2, j + 25, k + 1, Blocks.air, 0, 2);
        world.setBlock(i + 3, j + 25, k + 1, Blocks.air, 0, 2);
        world.setBlock(i + 4, j + 25, k + 1, placeStoneBricks(random), 0, 2);
        world.setBlock(i, j + 25, k + 2, placeStoneBricks(random), 0, 2);
        world.setBlock(i + 1, j + 25, k + 2, Blocks.air, 0, 2);
        world.setBlock(i + 2, j + 25, k + 2, NovaCraftBlocks.luminant_log, 0, 2);
        world.setBlock(i + 3, j + 25, k + 2, Blocks.air, 0, 2);
        world.setBlock(i + 4, j + 25, k + 2, placeStoneBricks(random), 0, 2);
        world.setBlock(i, j + 25, k + 3, placeStoneBricks(random), 0, 2);
        world.setBlock(i + 1, j + 25, k + 3, Blocks.air, 0, 2);
        world.setBlock(i + 2, j + 25, k + 3, NovaCraftBlocks.luminant_log, 0, 2);
        world.setBlock(i + 4, j + 25, k + 3, placeStoneBricks(random), 0, 2);
        world.setBlock(i, j + 25, k + 4, placeStoneBricks(random), 0, 2);
        world.setBlock(i + 1, j + 25, k + 4, Blocks.air, 0, 2);
        world.setBlock(i + 2, j + 25, k + 4, NovaCraftBlocks.luminant_log, 0, 2);
        world.setBlock(i + 3, j + 25, k + 4, Blocks.air, 0, 2);
        world.setBlock(i + 4, j + 25, k + 4, placeStoneBricks(random), 0, 2);
        world.setBlock(i, j + 25, k + 5, placeStoneBricks(random), 0, 2);
        world.setBlock(i + 1, j + 25, k + 5, Blocks.air, 0, 2);
        world.setBlock(i + 2, j + 25, k + 5, NovaCraftBlocks.luminant_log, 0, 2);
        world.setBlock(i + 3, j + 25, k + 5, Blocks.air, 0, 2);
        world.setBlock(i + 4, j + 25, k + 5, placeStoneBricks(random), 0, 2);
        world.setBlock(i, j + 25, k + 6, placeStoneBricks(random), 0, 2);
        world.setBlock(i + 1, j + 25, k + 6, placeStoneBricks(random), 0, 2);
        world.setBlock(i + 2, j + 25, k + 6, NovaCraftBlocks.luminant_stairs, 1, 2);
        world.setBlock(i + 3, j + 25, k + 6, Blocks.air, 0, 2);
        world.setBlock(i + 4, j + 25, k + 6, placeStoneBricks(random), 0, 2);
        world.setBlock(i, j + 25, k + 7, placeStoneBricks(random), 0, 2);
        world.setBlock(i + 1, j + 25, k + 7, placeStoneBricks(random), 0, 2);
        world.setBlock(i + 2, j + 25, k + 7, placeStoneBricks(random), 0, 2);
        world.setBlock(i + 3, j + 25, k + 7, placeStoneBricks(random), 0, 2);
        world.setBlock(i + 4, j + 25, k + 7, placeStoneBricks(random), 0, 2);
        world.setBlock(i, j + 26, k, placeStoneBricks(random), 0, 2);
        world.setBlock(i + 1, j + 26, k, placeStoneBricks(random), 0, 2);
        world.setBlock(i + 2, j + 26, k, placeStoneBricks(random), 0, 2);
        world.setBlock(i + 3, j + 26, k, placeStoneBricks(random), 0, 2);
        world.setBlock(i + 4, j + 26, k, placeStoneBricks(random), 0, 2);
        world.setBlock(i, j + 26, k + 1, placeStoneBricks(random), 0, 2);
        world.setBlock(i + 1, j + 26, k + 1, Blocks.air, 0, 2);
        world.setBlock(i + 2, j + 26, k + 1, Blocks.air, 0, 2);
        world.setBlock(i + 3, j + 26, k + 1, Blocks.air, 0, 2);
        world.setBlock(i + 4, j + 26, k + 1, placeStoneBricks(random), 0, 2);
        world.setBlock(i, j + 26, k + 2, placeStoneBricks(random), 0, 2);
        world.setBlock(i + 1, j + 26, k + 2, Blocks.air, 0, 2);
        world.setBlock(i + 2, j + 26, k + 2, NovaCraftBlocks.luminant_log, 0, 2);
        world.setBlock(i + 3, j + 26, k + 2, Blocks.air, 0, 2);
        world.setBlock(i + 4, j + 26, k + 2, placeStoneBricks(random), 0, 2);
        world.setBlock(i, j + 26, k + 3, placeStoneBricks(random), 0, 2);
        world.setBlock(i + 1, j + 26, k + 3, Blocks.air, 0, 2);
        world.setBlock(i + 2, j + 26, k + 3, NovaCraftBlocks.luminant_log, 0, 2);
        world.setBlock(i + 3, j + 26, k + 3, Blocks.air, 0, 2);
        world.setBlock(i + 4, j + 26, k + 3, placeStoneBricks(random), 0, 2);
        world.setBlock(i, j + 26, k + 4, placeStoneBricks(random), 0, 2);
        world.setBlock(i + 1, j + 26, k + 4, Blocks.air, 0, 2);
        world.setBlock(i + 2, j + 26, k + 4, NovaCraftBlocks.luminant_log, 0, 2);
        world.setBlock(i + 3, j + 26, k + 4, Blocks.air, 0, 2);
        world.setBlock(i + 4, j + 26, k + 4, placeStoneBricks(random), 0, 2);
        world.setBlock(i, j + 26, k + 5, placeStoneBricks(random), 0, 2);
        world.setBlock(i + 1, j + 26, k + 5, placeStoneBricks(random), 0, 2);
        world.setBlock(i + 2, j + 26, k + 5, NovaCraftBlocks.luminant_log, 0, 2);
        world.setBlock(i + 3, j + 26, k + 5, Blocks.air, 0, 2);
        world.setBlock(i + 4, j + 26, k + 5, placeStoneBricks(random), 0, 2);
        world.setBlock(i, j + 26, k + 6, placeStoneBricks(random), 0, 2);
        world.setBlock(i + 1, j + 26, k + 6, NovaCraftBlocks.luminant_stairs, 1, 2);
        world.setBlock(i + 2, j + 26, k + 6, Blocks.air, 0, 2);
        world.setBlock(i + 3, j + 26, k + 6, Blocks.air, 0, 2);
        world.setBlock(i + 4, j + 26, k + 6, placeStoneBricks(random), 0, 2);
        world.setBlock(i, j + 26, k + 7, placeStoneBricks(random), 0, 2);
        world.setBlock(i + 1, j + 26, k + 7, placeStoneBricks(random), 0, 2);
        world.setBlock(i + 2, j + 26, k + 7, placeStoneBricks(random), 0, 2);
        world.setBlock(i + 3, j + 26, k + 7, placeStoneBricks(random), 0, 2);
        world.setBlock(i + 4, j + 26, k + 7, placeStoneBricks(random), 0, 2);
        world.setBlock(i, j + 27, k, placeStoneBricks(random), 0, 2);
        world.setBlock(i + 1, j + 27, k, placeStoneBricks(random), 0, 2);
        world.setBlock(i + 2, j + 27, k, placeStoneBricks(random), 0, 2);
        world.setBlock(i + 3, j + 27, k, placeStoneBricks(random), 0, 2);
        world.setBlock(i + 4, j + 27, k, placeStoneBricks(random), 0, 2);
        world.setBlock(i, j + 27, k + 1, placeStoneBricks(random), 0, 2);
        world.setBlock(i + 1, j + 27, k + 1, Blocks.air, 0, 2);
        world.setBlock(i + 2, j + 27, k + 1, Blocks.air, 0, 2);
        world.setBlock(i + 3, j + 27, k + 1, Blocks.air, 0, 2);
        world.setBlock(i + 4, j + 27, k + 1, placeStoneBricks(random), 0, 2);
        world.setBlock(i, j + 27, k + 2, placeStoneBricks(random), 0, 2);
        world.setBlock(i + 1, j + 27, k + 2, Blocks.air, 0, 2);
        world.setBlock(i + 2, j + 27, k + 2, NovaCraftBlocks.luminant_log, 0, 2);
        world.setBlock(i + 3, j + 27, k + 2, Blocks.air, 0, 2);
        world.setBlock(i + 4, j + 27, k + 2, placeStoneBricks(random), 0, 2);
        world.setBlock(i, j + 27, k + 3, placeStoneBricks(random), 0, 2);
        world.setBlock(i + 1, j + 27, k + 3, Blocks.air, 0, 2);
        world.setBlock(i + 2, j + 27, k + 3, NovaCraftBlocks.luminant_log, 0, 2);
        world.setBlock(i + 3, j + 27, k + 3, Blocks.air, 0, 2);
        world.setBlock(i + 4, j + 27, k + 3, placeStoneBricks(random), 0, 2);
        world.setBlock(i, j + 27, k + 4, placeStoneBricks(random), 0, 2);
        world.setBlock(i + 1, j + 27, k + 4, placeStoneBricks(random), 0, 2);
        world.setBlock(i + 2, j + 27, k + 4, NovaCraftBlocks.luminant_log, 0, 2);
        world.setBlock(i + 3, j + 27, k + 4, Blocks.air, 0, 2);
        world.setBlock(i + 4, j + 27, k + 4, placeStoneBricks(random), 0, 2);
        world.setBlock(i, j + 27, k + 5, placeStoneBricks(random), 0, 2);
        world.setBlock(i + 1, j + 27, k + 5, NovaCraftBlocks.luminant_stairs, 3, 2);
        world.setBlock(i + 2, j + 27, k + 5, NovaCraftBlocks.luminant_log, 0, 2);
        world.setBlock(i + 3, j + 27, k + 5, Blocks.air, 0, 2);
        world.setBlock(i + 4, j + 27, k + 5, placeStoneBricks(random), 0, 2);
        world.setBlock(i, j + 27, k + 6, placeStoneBricks(random), 0, 2);
        world.setBlock(i + 1, j + 27, k + 6, Blocks.air, 0, 2);
        world.setBlock(i + 2, j + 27, k + 6, Blocks.air, 0, 2);
        world.setBlock(i + 3, j + 27, k + 6, Blocks.air, 0, 2);
        world.setBlock(i + 4, j + 27, k + 6, placeStoneBricks(random), 0, 2);
        world.setBlock(i, j + 27, k + 7, placeStoneBricks(random), 0, 2);
        world.setBlock(i + 1, j + 27, k + 7, placeStoneBricks(random), 0, 2);
        world.setBlock(i + 2, j + 27, k + 7, placeStoneBricks(random), 0, 2);
        world.setBlock(i + 3, j + 27, k + 7, placeStoneBricks(random), 0, 2);
        world.setBlock(i + 4, j + 27, k + 7, placeStoneBricks(random), 0, 2);
        world.setBlock(i, j + 28, k, placeStoneBricks(random), 0, 2);
        world.setBlock(i + 1, j + 28, k, placeStoneBricks(random), 0, 2);
        world.setBlock(i + 2, j + 28, k, placeStoneBricks(random), 0, 2);
        world.setBlock(i + 3, j + 28, k, placeStoneBricks(random), 0, 2);
        world.setBlock(i + 4, j + 28, k, placeStoneBricks(random), 0, 2);
        world.setBlock(i, j + 28, k + 1, placeStoneBricks(random), 0, 2);
        world.setBlock(i + 1, j + 28, k + 1, Blocks.air, 0, 2);
        world.setBlock(i + 2, j + 28, k + 1, Blocks.air, 0, 2);
        world.setBlock(i + 3, j + 28, k + 1, Blocks.air, 0, 2);
        world.setBlock(i + 4, j + 28, k + 1, placeStoneBricks(random), 0, 2);
        world.setBlock(i, j + 28, k + 2, placeStoneBricks(random), 0, 2);
        world.setBlock(i + 1, j + 28, k + 2, Blocks.air, 0, 2);
        world.setBlock(i + 2, j + 28, k + 2, NovaCraftBlocks.luminant_log, 0, 2);
        world.setBlock(i + 3, j + 28, k + 2, Blocks.air, 0, 2);
        world.setBlock(i + 4, j + 28, k + 2, placeStoneBricks(random), 0, 2);
        world.setBlock(i, j + 28, k + 3, placeStoneBricks(random), 0, 2);
        world.setBlock(i + 1, j + 28, k + 3, placeStoneBricks(random), 0, 2);
        world.setBlock(i + 2, j + 28, k + 3, NovaCraftBlocks.luminant_log, 0, 2);
        world.setBlock(i + 3, j + 28, k + 3, Blocks.air, 0, 2);
        world.setBlock(i + 4, j + 28, k + 3, placeStoneBricks(random), 0, 2);
        world.setBlock(i, j + 28, k + 4, placeStoneBricks(random), 0, 2);
        world.setBlock(i + 1, j + 28, k + 4, NovaCraftBlocks.luminant_stairs, 3, 2);
        world.setBlock(i + 2, j + 28, k + 4, NovaCraftBlocks.luminant_log, 0, 2);
        world.setBlock(i + 3, j + 28, k + 4, Blocks.air, 0, 2);
        world.setBlock(i + 4, j + 28, k + 4, placeStoneBricks(random), 0, 2);
        world.setBlock(i, j + 28, k + 5, placeStoneBricks(random), 0, 2);
        world.setBlock(i + 1, j + 28, k + 5, Blocks.air, 0, 2);
        world.setBlock(i + 2, j + 28, k + 5, NovaCraftBlocks.luminant_log, 0, 2);
        world.setBlock(i + 3, j + 28, k + 5, Blocks.air, 0, 2);
        world.setBlock(i + 4, j + 28, k + 5, placeStoneBricks(random), 0, 2);
        world.setBlock(i, j + 28, k + 6, placeStoneBricks(random), 0, 2);
        world.setBlock(i + 1, j + 28, k + 6, Blocks.air, 0, 2);
        world.setBlock(i + 2, j + 28, k + 6, Blocks.air, 0, 2);
        world.setBlock(i + 3, j + 28, k + 6, Blocks.air, 0, 2);
        world.setBlock(i + 4, j + 28, k + 6, placeStoneBricks(random), 0, 2);
        world.setBlock(i, j + 28, k + 7, placeStoneBricks(random), 0, 2);
        world.setBlock(i + 1, j + 28, k + 7, placeStoneBricks(random), 0, 2);
        world.setBlock(i + 2, j + 28, k + 7, placeStoneBricks(random), 0, 2);
        world.setBlock(i + 3, j + 28, k + 7, placeStoneBricks(random), 0, 2);
        world.setBlock(i + 4, j + 28, k + 7, placeStoneBricks(random), 0, 2);
        world.setBlock(i, j + 29, k, placeStoneBricks(random), 0, 2);
        world.setBlock(i + 1, j + 29, k, placeStoneBricks(random), 0, 2);
        world.setBlock(i + 2, j + 29, k, placeStoneBricks(random), 0, 2);
        world.setBlock(i + 3, j + 29, k, placeStoneBricks(random), 0, 2);
        world.setBlock(i + 4, j + 29, k, placeStoneBricks(random), 0, 2);
        world.setBlock(i, j + 29, k + 1, placeStoneBricks(random), 0, 2);
        world.setBlock(i + 1, j + 29, k + 1, Blocks.air, 0, 2);
        world.setBlock(i + 2, j + 29, k + 1, Blocks.air, 0, 2);
        world.setBlock(i + 3, j + 29, k + 1, Blocks.air, 0, 2);
        world.setBlock(i + 4, j + 29, k + 1, placeStoneBricks(random), 0, 2);
        world.setBlock(i, j + 29, k + 2, placeStoneBricks(random), 0, 2);
        world.setBlock(i + 1, j + 29, k + 2, placeStoneBricks(random), 0, 2);
        world.setBlock(i + 2, j + 29, k + 2, NovaCraftBlocks.luminant_log, 0, 2);
        world.setBlock(i + 3, j + 29, k + 2, Blocks.air, 0, 2);
        world.setBlock(i + 4, j + 29, k + 2, placeStoneBricks(random), 0, 2);
        world.setBlock(i, j + 29, k + 3, placeStoneBricks(random), 0, 2);
        world.setBlock(i + 1, j + 29, k + 3, NovaCraftBlocks.luminant_stairs, 3, 2);
        world.setBlock(i + 2, j + 29, k + 3, NovaCraftBlocks.luminant_log, 0, 2);
        world.setBlock(i + 3, j + 29, k + 3, Blocks.air, 0, 2);
        world.setBlock(i + 4, j + 29, k + 3, placeStoneBricks(random), 0, 2);
        world.setBlock(i, j + 29, k + 4, placeStoneBricks(random), 0, 2);
        world.setBlock(i + 1, j + 29, k + 4, Blocks.air, 0, 2);
        world.setBlock(i + 2, j + 29, k + 4, NovaCraftBlocks.luminant_log, 0, 2);
        world.setBlock(i + 3, j + 29, k + 4, Blocks.air, 0, 2);
        world.setBlock(i + 4, j + 29, k + 4, placeStoneBricks(random), 0, 2);
        world.setBlock(i, j + 29, k + 5, placeStoneBricks(random), 0, 2);
        world.setBlock(i + 1, j + 29, k + 5, Blocks.air, 0, 2);
        world.setBlock(i + 2, j + 29, k + 5, NovaCraftBlocks.luminant_log, 0, 2);
        world.setBlock(i + 3, j + 29, k + 5, Blocks.air, 0, 2);
        world.setBlock(i + 4, j + 29, k + 5, placeStoneBricks(random), 0, 2);
        world.setBlock(i, j + 29, k + 6, placeStoneBricks(random), 0, 2);
        world.setBlock(i + 1, j + 29, k + 6, Blocks.air, 0, 2);
        world.setBlock(i + 3, j + 29, k + 6, Blocks.air, 0, 2);
        world.setBlock(i + 4, j + 29, k + 6, placeStoneBricks(random), 0, 2);
        world.setBlock(i, j + 29, k + 7, placeStoneBricks(random), 0, 2);
        world.setBlock(i + 1, j + 29, k + 7, placeStoneBricks(random), 0, 2);
        world.setBlock(i + 2, j + 29, k + 7, placeStoneBricks(random), 0, 2);
        world.setBlock(i + 3, j + 29, k + 7, placeStoneBricks(random), 0, 2);
        world.setBlock(i + 4, j + 29, k + 7, placeStoneBricks(random), 0, 2);
        world.setBlock(i, j + 30, k, placeStoneBricks(random), 0, 2);
        world.setBlock(i + 1, j + 30, k, placeStoneBricks(random), 0, 2);
        world.setBlock(i + 2, j + 30, k, placeStoneBricks(random), 0, 2);
        world.setBlock(i + 3, j + 30, k, placeStoneBricks(random), 0, 2);
        world.setBlock(i + 4, j + 30, k, placeStoneBricks(random), 0, 2);
        world.setBlock(i, j + 30, k + 1, placeStoneBricks(random), 0, 2);
        world.setBlock(i + 1, j + 30, k + 1, placeStoneBricks(random), 0, 2);
        world.setBlock(i + 2, j + 30, k + 1, Blocks.air, 0, 2);
        world.setBlock(i + 3, j + 30, k + 1, Blocks.air, 0, 2);
        world.setBlock(i + 4, j + 30, k + 1, placeStoneBricks(random), 0, 2);
        world.setBlock(i, j + 30, k + 2, placeStoneBricks(random), 0, 2);
        world.setBlock(i + 1, j + 30, k + 2, NovaCraftBlocks.luminant_stairs, 3, 2);
        world.setBlock(i + 2, j + 30, k + 2, NovaCraftBlocks.luminant_log, 0, 2);
        world.setBlock(i + 3, j + 30, k + 2, Blocks.air, 0, 2);
        world.setBlock(i + 4, j + 30, k + 2, placeStoneBricks(random), 0, 2);
        world.setBlock(i, j + 30, k + 3, placeStoneBricks(random), 0, 2);
        world.setBlock(i + 1, j + 30, k + 3, Blocks.air, 0, 2);
        world.setBlock(i + 2, j + 30, k + 3, NovaCraftBlocks.luminant_log, 0, 2);
        world.setBlock(i + 3, j + 30, k + 3, Blocks.air, 0, 2);
        world.setBlock(i + 4, j + 30, k + 3, placeStoneBricks(random), 0, 2);
        world.setBlock(i, j + 30, k + 4, placeStoneBricks(random), 0, 2);
        world.setBlock(i + 1, j + 30, k + 4, Blocks.air, 0, 2);
        world.setBlock(i + 2, j + 30, k + 4, NovaCraftBlocks.luminant_log, 0, 2);
        world.setBlock(i + 3, j + 30, k + 4, Blocks.air, 0, 2);
        world.setBlock(i + 4, j + 30, k + 4, placeStoneBricks(random), 0, 2);
        world.setBlock(i, j + 30, k + 5, placeStoneBricks(random), 0, 2);
        world.setBlock(i + 1, j + 30, k + 5, Blocks.air, 0, 2);
        world.setBlock(i + 2, j + 30, k + 5, NovaCraftBlocks.luminant_log, 0, 2);
        world.setBlock(i + 3, j + 30, k + 5, Blocks.air, 0, 2);
        world.setBlock(i + 4, j + 30, k + 5, placeStoneBricks(random), 0, 2);
        world.setBlock(i, j + 30, k + 6, placeStoneBricks(random), 0, 2);
        world.setBlock(i + 1, j + 30, k + 6, Blocks.air, 0, 2);
        world.setBlock(i + 2, j + 30, k + 6, Blocks.air, 0, 2);
        world.setBlock(i + 3, j + 30, k + 6, Blocks.air, 0, 2);
        world.setBlock(i + 4, j + 30, k + 6, placeStoneBricks(random), 0, 2);
        world.setBlock(i, j + 30, k + 7, placeStoneBricks(random), 0, 2);
        world.setBlock(i + 1, j + 30, k + 7, placeStoneBricks(random), 0, 2);
        world.setBlock(i + 2, j + 30, k + 7, placeStoneBricks(random), 0, 2);
        world.setBlock(i + 3, j + 30, k + 7, placeStoneBricks(random), 0, 2);
        world.setBlock(i + 4, j + 30, k + 7, placeStoneBricks(random), 0, 2);
        world.setBlock(i + 2, j + 2, k + 6, NovaCraftBlocks.vanite_torch, 4, 2);
        world.setBlock(i + 3, j + 10, k + 3, NovaCraftBlocks.vanite_torch, 2, 2);
        world.setBlock(i + 2, j + 14, k + 6, NovaCraftBlocks.vanite_torch, 4, 2);
        world.setBlock(i + 1, j + 19, k + 3, NovaCraftBlocks.vanite_torch, 1, 2);
        world.setBlock(i + 3, j + 25, k + 3, NovaCraftBlocks.vanite_torch, 2, 2);
        world.setBlock(i + 2, j + 29, k + 6, NovaCraftBlocks.vanite_torch, 4, 2);

        this.setBlockAndNotifyAdequately(world, i + 3, j + 1, k + 2, Blocks.chest, 3);
        TileEntity tile = world.getTileEntity(i + 3, j + 1, k + 2);
        if (tile instanceof TileEntityChest) {
            TileEntityChest chest = (TileEntityChest) tile;

            for (int slot = 0; slot < 3 + random.nextInt(20); slot++) {
                chest.setInventorySlotContents(random.nextInt(chest.getSizeInventory()), this.getFoodLoot(random));
            }
        }

        return true;
    }

    private Block placeStoneBricks(Random random) {
        if (random.nextDouble() < 0.12) {
            return NovaCraftBlocks.grimstone_bricks;
        } else {
            return Blocks.stonebrick;
        }
    }

    private Block placeStoneBrickStairs(Random random) {
        if (random.nextDouble() < 0.12) {
            return NovaCraftBlocks.grimstone_brick_stairs;
        } else {
            return Blocks.stone_brick_stairs;
        }
    }

    private ItemStack getFoodLoot(Random random) {
        int item = random.nextInt(10);
        switch (item) {
            case 0:
                return new ItemStack(Items.chicken, random.nextInt(3) + 5);
            case 1:
                return new ItemStack(Items.porkchop, random.nextInt(2) + 3);
            case 2:
                return new ItemStack(Items.potato, random.nextInt(8) + 10);
            case 3:
                return new ItemStack(Items.carrot, random.nextInt(12) + 12);
            case 4:
                return new ItemStack(Items.beef, random.nextInt(5) + 9);
            case 5:
                return new ItemStack(Items.mushroom_stew, 1);
            case 6:
                return new ItemStack(NovaCraftItems.raw_chevon, random.nextInt(2) + 3);
            case 7:
                return new ItemStack(NovaCraftItems.raw_glow_squid, random.nextInt(4) + 3);
            default: {
                return new ItemStack(Items.wheat, random.nextInt(14) + 22);
            }
        }
    }
}
