package com.NovaCraft.world.mansion;

import com.NovaCraft.Items.NovaCraftItems;
import com.NovaCraft.config.Configs;
import com.NovaCraft.config.ConfigsCompact;
import com.NovaCraftBlocks.NovaCraftBlocks;
import cpw.mods.fml.common.Loader;
import cpw.mods.fml.common.registry.GameRegistry;
import net.minecraft.block.Block;
import net.minecraft.init.Blocks;
import net.minecraft.init.Items;
import net.minecraft.item.ItemStack;
import net.minecraft.tileentity.TileEntity;
import net.minecraft.tileentity.TileEntityChest;
import net.minecraft.world.World;
import net.minecraft.world.gen.feature.WorldGenerator;

import java.util.Random;

public class MansionFloor3Gen2 extends WorldGenerator {

    public MansionFloor3Gen2() {

    }

    private Block PlaceDarkOakFence;
    private Block PlaceBirchFence;

    private Block determineIfDarkOakFenceExists(World world, int x, int y, int z) {
        Block existingBlock = world.getBlock(x, y, z);
        if (ConfigsCompact.enableDarkOakFence && Loader.isModLoaded("etfuturum")) {
            try {
                Block fence_dark_oak = GameRegistry.findBlock("etfuturum", "fence_dark_oak");
                if (fence_dark_oak != null && (existingBlock == null || existingBlock != fence_dark_oak)) {
                    return fence_dark_oak;
                }
            } catch (Exception ex) {
                if (Configs.enableDebugMode) {
                    System.out.println("Missing Dark Oak Fence from Et Futurum Requiem, using regular fence instead...");
                }
                return Blocks.fence;
            }
        }

        return Blocks.fence;
    }

    private Block determineIfBirchFenceExists(World world, int x, int y, int z) {
        Block existingBlock = world.getBlock(x, y, z);
        if (ConfigsCompact.enableDarkOakFence && Loader.isModLoaded("etfuturum")) {
            try {
                Block fence_birch = GameRegistry.findBlock("etfuturum", "fence_birch");
                if (fence_birch != null && (existingBlock == null || existingBlock != fence_birch)) {
                    return fence_birch;
                }
            } catch (Exception ex) {
                if (Configs.enableDebugMode) {
                    System.out.println("Missing Birch Fence from Et Futurum Requiem, using regular fence instead...");
                }
                return Blocks.fence;
            }
        }

        return Blocks.fence;
    }

    @Override
    public boolean generate(final World world, final Random random, final int i, final int j, final int k) {
        PlaceDarkOakFence = determineIfDarkOakFenceExists(world, i + 1, j + 4, k + 16);
        PlaceBirchFence = determineIfBirchFenceExists(world, i + 33, j + 4, k + 51);

        world.setBlock(i + 2, j + 4, k + 14, Blocks.glass_pane, 0, 2);
        world.setBlock(i + 18, j + 4, k + 14, Blocks.glass_pane, 0, 2);
        world.setBlock(i + 2, j + 4, k + 15, Blocks.glass_pane, 0, 2);
        world.setBlock(i + 18, j + 4, k + 15, Blocks.glass_pane, 0, 2);
        world.setBlock(i + 1, j + 4, k + 16, PlaceDarkOakFence, 0, 2);
        world.setBlock(i + 2, j + 4, k + 16, Blocks.log2, 5, 2);
        world.setBlock(i + 18, j + 4, k + 16, Blocks.log2, 5, 2);
        world.setBlock(i + 19, j + 4, k + 16, PlaceDarkOakFence, 0, 2);
        world.setBlock(i + 2, j + 4, k + 17, Blocks.planks, 5, 2);
        world.setBlock(i + 18, j + 4, k + 17, Blocks.planks, 5, 2);
        world.setBlock(i + 20, j + 4, k + 17, PlaceDarkOakFence, 0, 2);
        world.setBlock(i + 24, j + 4, k + 17, PlaceDarkOakFence, 0, 2);
        world.setBlock(i + 26, j + 4, k + 17, Blocks.cobblestone, 0, 2);
        world.setBlock(i + 27, j + 4, k + 17, Blocks.cobblestone_wall, 0, 2);
        world.setBlock(i + 2, j + 4, k + 18, Blocks.planks, 5, 2);
        world.setBlock(i + 3, j + 4, k + 18, Blocks.planks, 5, 2);
        world.setBlock(i + 4, j + 4, k + 18, Blocks.planks, 5, 2);
        world.setBlock(i + 5, j + 4, k + 18, Blocks.planks, 5, 2);
        world.setBlock(i + 6, j + 4, k + 18, Blocks.planks, 5, 2);
        world.setBlock(i + 7, j + 4, k + 18, Blocks.planks, 5, 2);
        world.setBlock(i + 8, j + 4, k + 18, Blocks.planks, 5, 2);
        world.setBlock(i + 9, j + 4, k + 18, Blocks.planks, 5, 2);
        world.setBlock(i + 10, j + 4, k + 18, Blocks.planks, 5, 2);
        world.setBlock(i + 11, j + 4, k + 18, Blocks.planks, 5, 2);
        world.setBlock(i + 12, j + 4, k + 18, Blocks.planks, 5, 2);
        world.setBlock(i + 13, j + 4, k + 18, Blocks.planks, 5, 2);
        world.setBlock(i + 14, j + 4, k + 18, Blocks.log2, 9, 2);
        world.setBlock(i + 15, j + 4, k + 18, Blocks.planks, 5, 2);
        world.setBlock(i + 16, j + 4, k + 18, Blocks.planks, 5, 2);
        world.setBlock(i + 17, j + 4, k + 18, Blocks.planks, 5, 2);
        world.setBlock(i + 18, j + 4, k + 18, Blocks.planks, 5, 2);
        world.setBlock(i + 19, j + 4, k + 18, Blocks.planks, 5, 2);
        world.setBlock(i + 20, j + 4, k + 18, Blocks.log2, 9, 2);
        world.setBlock(i + 21, j + 4, k + 18, Blocks.glass_pane, 0, 2);
        world.setBlock(i + 22, j + 4, k + 18, Blocks.glass_pane, 0, 2);
        world.setBlock(i + 23, j + 4, k + 18, Blocks.glass_pane, 0, 2);
        world.setBlock(i + 24, j + 4, k + 18, Blocks.log2, 9, 2);
        world.setBlock(i + 25, j + 4, k + 18, Blocks.planks, 5, 2);
        world.setBlock(i + 26, j + 4, k + 18, Blocks.cobblestone, 0, 2);
        world.setBlock(i + 27, j + 4, k + 18, Blocks.cobblestone, 0, 2);
        world.setBlock(i + 2, j + 4, k + 19, Blocks.planks, 5, 2);
        world.setBlock(i + 10, j + 4, k + 19, Blocks.planks, 5, 2);
        world.setBlock(i + 18, j + 4, k + 19, Blocks.planks, 5, 2);
        world.setBlock(i + 26, j + 4, k + 19, Blocks.planks, 5, 2);
        world.setBlock(i + 1, j + 4, k + 20, PlaceDarkOakFence, 0, 2);
        world.setBlock(i + 2, j + 4, k + 20, Blocks.log2, 5, 2);
        world.setBlock(i + 10, j + 4, k + 20, Blocks.torch, 5, 2);
        world.setBlock(i + 18, j + 4, k + 20, Blocks.torch, 5, 2);
        world.setBlock(i + 26, j + 4, k + 20, Blocks.log2, 5, 2);
        world.setBlock(i + 27, j + 4, k + 20, PlaceDarkOakFence, 0, 2);
        world.setBlock(i + 2, j + 4, k + 21, Blocks.glass_pane, 0, 2);
        world.setBlock(i + 26, j + 4, k + 21, Blocks.glass_pane, 0, 2);
        world.setBlock(i + 2, j + 4, k + 22, Blocks.glass_pane, 0, 2);
        world.setBlock(i + 26, j + 4, k + 22, Blocks.glass_pane, 0, 2);
        world.setBlock(i + 2, j + 4, k + 23, Blocks.glass_pane, 0, 2);
        world.setBlock(i + 26, j + 4, k + 23, Blocks.glass_pane, 0, 2);
        world.setBlock(i + 1, j + 4, k + 24, PlaceDarkOakFence, 0, 2);
        world.setBlock(i + 2, j + 4, k + 24, Blocks.log2, 5, 2);
        world.setBlock(i + 10, j + 4, k + 24, Blocks.torch, 5, 2);
        world.setBlock(i + 18, j + 4, k + 24, Blocks.torch, 5, 2);
        world.setBlock(i + 26, j + 4, k + 24, Blocks.log2, 5, 2);
        world.setBlock(i + 27, j + 4, k + 24, PlaceDarkOakFence, 0, 2);
        world.setBlock(i + 2, j + 4, k + 25, Blocks.planks, 5, 2);
        world.setBlock(i + 10, j + 4, k + 25, Blocks.planks, 5, 2);
        world.setBlock(i + 18, j + 4, k + 25, Blocks.planks, 5, 2);
        world.setBlock(i + 26, j + 4, k + 25, Blocks.planks, 5, 2);
        world.setBlock(i + 2, j + 4, k + 26, Blocks.planks, 5, 2);
        world.setBlock(i + 3, j + 4, k + 26, Blocks.planks, 5, 2);
        world.setBlock(i + 4, j + 4, k + 26, Blocks.torch, 5, 2);
        world.setBlock(i + 8, j + 4, k + 26, Blocks.torch, 5, 2);
        world.setBlock(i + 9, j + 4, k + 26, Blocks.planks, 5, 2);
        world.setBlock(i + 10, j + 4, k + 26, Blocks.planks, 5, 2);
        world.setBlock(i + 11, j + 4, k + 26, Blocks.planks, 5, 2);
        world.setBlock(i + 12, j + 4, k + 26, Blocks.planks, 5, 2);
        world.setBlock(i + 13, j + 4, k + 26, Blocks.planks, 5, 2);
        world.setBlock(i + 14, j + 4, k + 26, Blocks.planks, 5, 2);
        world.setBlock(i + 15, j + 4, k + 26, Blocks.planks, 5, 2);
        world.setBlock(i + 16, j + 4, k + 26, Blocks.planks, 5, 2);
        world.setBlock(i + 17, j + 4, k + 26, Blocks.planks, 5, 2);
        world.setBlock(i + 18, j + 4, k + 26, Blocks.planks, 5, 2);
        world.setBlock(i + 26, j + 4, k + 26, Blocks.planks, 5, 2);
        world.setBlock(i + 2, j + 4, k + 27, Blocks.planks, 5, 2);
        world.setBlock(i + 10, j + 4, k + 27, Blocks.planks, 5, 2);
        world.setBlock(i + 18, j + 4, k + 27, Blocks.planks, 5, 2);
        world.setBlock(i + 26, j + 4, k + 27, Blocks.planks, 5, 2);
        world.setBlock(i + 1, j + 4, k + 28, PlaceDarkOakFence, 0, 2);
        world.setBlock(i + 2, j + 4, k + 28, Blocks.log2, 5, 2);
        world.setBlock(i + 10, j + 4, k + 28, Blocks.planks, 5, 2);
        world.setBlock(i + 18, j + 4, k + 28, Blocks.planks, 5, 2);
        world.setBlock(i + 26, j + 4, k + 28, Blocks.log2, 5, 2);
        world.setBlock(i + 27, j + 4, k + 28, PlaceDarkOakFence, 0, 2);
        world.setBlock(i + 2, j + 4, k + 29, Blocks.glass_pane, 0, 2);
        world.setBlock(i + 10, j + 4, k + 29, Blocks.planks, 5, 2);
        world.setBlock(i + 18, j + 4, k + 29, Blocks.planks, 5, 2);
        world.setBlock(i + 26, j + 4, k + 29, Blocks.glass_pane, 0, 2);
        world.setBlock(i + 2, j + 4, k + 30, Blocks.glass_pane, 0, 2);
        world.setBlock(i + 10, j + 4, k + 30, Blocks.log2, 5, 2);
        world.setBlock(i + 18, j + 4, k + 30, Blocks.log2, 5, 2);
        world.setBlock(i + 26, j + 4, k + 30, Blocks.glass_pane, 0, 2);
        world.setBlock(i + 2, j + 4, k + 31, Blocks.glass_pane, 0, 2);
        world.setBlock(i + 10, j + 4, k + 31, Blocks.planks, 5, 2);
        world.setBlock(i + 18, j + 4, k + 31, Blocks.planks, 5, 2);
        world.setBlock(i + 26, j + 4, k + 31, Blocks.glass_pane, 0, 2);
        world.setBlock(i + 1, j + 4, k + 32, PlaceDarkOakFence, 0, 2);
        world.setBlock(i + 2, j + 4, k + 32, Blocks.log2, 5, 2);
        world.setBlock(i + 10, j + 4, k + 32, Blocks.planks, 5, 2);
        world.setBlock(i + 18, j + 4, k + 32, Blocks.planks, 5, 2);
        world.setBlock(i + 26, j + 4, k + 32, Blocks.log2, 5, 2);
        world.setBlock(i + 27, j + 4, k + 32, PlaceDarkOakFence, 0, 2);
        world.setBlock(i + 2, j + 4, k + 33, Blocks.planks, 5, 2);
        world.setBlock(i + 10, j + 4, k + 33, Blocks.planks, 5, 2);
        world.setBlock(i + 18, j + 4, k + 33, Blocks.planks, 5, 2);
        world.setBlock(i + 19, j + 4, k + 33, Blocks.planks, 5, 2);
        world.setBlock(i + 20, j + 4, k + 33, Blocks.wool, 8, 2);
        world.setBlock(i + 21, j + 4, k + 33, Blocks.wool, 8, 2);
        world.setBlock(i + 22, j + 4, k + 33, Blocks.wool, 8, 2);
        world.setBlock(i + 23, j + 4, k + 33, Blocks.wool, 8, 2);
        world.setBlock(i + 24, j + 4, k + 33, Blocks.wool, 8, 2);
        world.setBlock(i + 25, j + 4, k + 33, Blocks.planks, 5, 2);
        world.setBlock(i + 26, j + 4, k + 33, Blocks.planks, 5, 2);
        world.setBlock(i + 2, j + 4, k + 34, Blocks.planks, 5, 2);
        world.setBlock(i + 3, j + 4, k + 34, Blocks.planks, 5, 2);
        world.setBlock(i + 4, j + 4, k + 34, Blocks.torch, 5, 2);
        world.setBlock(i + 8, j + 4, k + 34, Blocks.torch, 5, 2);
        world.setBlock(i + 9, j + 4, k + 34, Blocks.planks, 5, 2);
        world.setBlock(i + 10, j + 4, k + 34, Blocks.planks, 5, 2);
        world.setBlock(i + 11, j + 4, k + 34, Blocks.planks, 5, 2);
        world.setBlock(i + 12, j + 4, k + 34, Blocks.planks, 5, 2);
        world.setBlock(i + 13, j + 4, k + 34, Blocks.planks, 5, 2);
        world.setBlock(i + 14, j + 4, k + 34, Blocks.log2, 9, 2);
        world.setBlock(i + 15, j + 4, k + 34, Blocks.planks, 5, 2);
        world.setBlock(i + 16, j + 4, k + 34, Blocks.planks, 5, 2);
        world.setBlock(i + 17, j + 4, k + 34, Blocks.planks, 5, 2);
        world.setBlock(i + 18, j + 4, k + 34, Blocks.planks, 5, 2);
        world.setBlock(i + 19, j + 4, k + 34, Blocks.planks, 5, 2);
        world.setBlock(i + 20, j + 4, k + 34, Blocks.planks, 5, 2);
        world.setBlock(i + 21, j + 4, k + 34, Blocks.planks, 5, 2);
        world.setBlock(i + 22, j + 4, k + 34, Blocks.log2, 9, 2);
        world.setBlock(i + 23, j + 4, k + 34, Blocks.planks, 5, 2);
        world.setBlock(i + 24, j + 4, k + 34, Blocks.planks, 5, 2);
        world.setBlock(i + 25, j + 4, k + 34, Blocks.planks, 5, 2);
        world.setBlock(i + 26, j + 4, k + 34, Blocks.planks, 5, 2);
        world.setBlock(i + 2, j + 4, k + 35, Blocks.planks, 5, 2);
        world.setBlock(i + 10, j + 4, k + 35, Blocks.planks, 5, 2);
        world.setBlock(i + 18, j + 4, k + 35, Blocks.fence, 0, 2);
        world.setBlock(i + 26, j + 4, k + 35, Blocks.planks, 5, 2);
        world.setBlock(i + 1, j + 4, k + 36, PlaceDarkOakFence, 0, 2);
        world.setBlock(i + 2, j + 4, k + 36, Blocks.log2, 5, 2);
        world.setBlock(i + 10, j + 4, k + 36, Blocks.planks, 5, 2);
        world.setBlock(i + 26, j + 4, k + 36, Blocks.log2, 5, 2);
        world.setBlock(i + 27, j + 4, k + 36, PlaceDarkOakFence, 0, 2);
        world.setBlock(i + 2, j + 4, k + 37, Blocks.glass_pane, 0, 2);
        world.setBlock(i + 10, j + 4, k + 37, Blocks.planks, 5, 2);
        world.setBlock(i + 26, j + 4, k + 37, Blocks.glass_pane, 0, 2);
        world.setBlock(i + 2, j + 4, k + 38, Blocks.glass_pane, 0, 2);
        world.setBlock(i + 10, j + 4, k + 38, Blocks.planks, 5, 2);
        world.setBlock(i + 26, j + 4, k + 38, Blocks.glass_pane, 0, 2);
        world.setBlock(i + 2, j + 4, k + 39, Blocks.glass_pane, 0, 2);
        world.setBlock(i + 10, j + 4, k + 39, Blocks.planks, 5, 2);
        world.setBlock(i + 26, j + 4, k + 39, Blocks.glass_pane, 0, 2);
        world.setBlock(i + 1, j + 4, k + 40, PlaceDarkOakFence, 0, 2);
        world.setBlock(i + 2, j + 4, k + 40, Blocks.log2, 5, 2);
        world.setBlock(i + 10, j + 4, k + 40, Blocks.planks, 5, 2);
        world.setBlock(i + 26, j + 4, k + 40, Blocks.log2, 5, 2);
        world.setBlock(i + 27, j + 4, k + 40, PlaceDarkOakFence, 0, 2);
        world.setBlock(i + 2, j + 4, k + 41, Blocks.planks, 5, 2);
        world.setBlock(i + 10, j + 4, k + 41, Blocks.planks, 5, 2);
        world.setBlock(i + 26, j + 4, k + 41, Blocks.planks, 5, 2);
        world.setBlock(i + 2, j + 4, k + 42, Blocks.planks, 5, 2);
        world.setBlock(i + 3, j + 4, k + 42, Blocks.planks, 5, 2);
        world.setBlock(i + 4, j + 4, k + 42, Blocks.torch, 5, 2);
        world.setBlock(i + 8, j + 4, k + 42, Blocks.torch, 5, 2);
        world.setBlock(i + 9, j + 4, k + 42, Blocks.planks, 5, 2);
        world.setBlock(i + 10, j + 4, k + 42, Blocks.planks, 5, 2);
        world.setBlock(i + 11, j + 4, k + 42, Blocks.fence, 0, 2);
        world.setBlock(i + 25, j + 4, k + 42, Blocks.fence, 0, 2);
        world.setBlock(i + 26, j + 4, k + 42, Blocks.planks, 5, 2);
        world.setBlock(i + 2, j + 4, k + 43, Blocks.planks, 5, 2);
        world.setBlock(i + 10, j + 4, k + 43, Blocks.planks, 5, 2);
        world.setBlock(i + 26, j + 4, k + 43, Blocks.planks, 5, 2);
        world.setBlock(i + 27, j + 4, k + 43, Blocks.cobblestone_wall, 0, 2);
        world.setBlock(i + 1, j + 4, k + 44, PlaceDarkOakFence, 0, 2);
        world.setBlock(i + 2, j + 4, k + 44, Blocks.log2, 5, 2);
        world.setBlock(i + 10, j + 4, k + 44, Blocks.planks, 5, 2);
        world.setBlock(i + 26, j + 4, k + 44, Blocks.planks, 5, 2);
        world.setBlock(i + 27, j + 4, k + 44, Blocks.cobblestone, 0, 2);
        world.setBlock(i + 34, j + 4, k + 44, Blocks.cobblestone, 0, 2);
        world.setBlock(i + 35, j + 4, k + 44, Blocks.cobblestone_wall, 0, 2);
        world.setBlock(i + 2, j + 4, k + 45, Blocks.glass_pane, 0, 2);
        world.setBlock(i + 10, j + 4, k + 45, Blocks.planks, 5, 2);
        world.setBlock(i + 26, j + 4, k + 45, Blocks.log2, 5, 2);
        world.setBlock(i + 27, j + 4, k + 45, Blocks.planks, 5, 2);
        world.setBlock(i + 28, j + 4, k + 45, Blocks.planks, 5, 2);
        world.setBlock(i + 29, j + 4, k + 45, Blocks.planks, 5, 2);
        world.setBlock(i + 30, j + 4, k + 45, Blocks.planks, 5, 2);
        world.setBlock(i + 31, j + 4, k + 45, Blocks.planks, 5, 2);
        world.setBlock(i + 32, j + 4, k + 45, Blocks.planks, 5, 2);
        world.setBlock(i + 33, j + 4, k + 45, Blocks.planks, 5, 2);
        world.setBlock(i + 34, j + 4, k + 45, Blocks.planks, 5, 2);
        world.setBlock(i + 35, j + 4, k + 45, Blocks.cobblestone, 0, 2);
        world.setBlock(i + 2, j + 4, k + 46, Blocks.glass_pane, 0, 2);
        world.setBlock(i + 10, j + 4, k + 46, Blocks.log2, 5, 2);
        world.setBlock(i + 26, j + 4, k + 46, Blocks.planks, 5, 2);
        world.setBlock(i + 31, j + 4, k + 46, Blocks.planks, 5, 2);
        world.setBlock(i + 34, j + 4, k + 46, Blocks.planks, 5, 2);
        world.setBlock(i + 2, j + 4, k + 47, Blocks.glass_pane, 0, 2);
        world.setBlock(i + 10, j + 4, k + 47, Blocks.planks, 5, 2);
        world.setBlock(i + 26, j + 4, k + 47, Blocks.planks, 5, 2);
        world.setBlock(i + 31, j + 4, k + 47, Blocks.planks, 5, 2);
        world.setBlock(i + 34, j + 4, k + 47, Blocks.planks, 5, 2);
        world.setBlock(i + 1, j + 4, k + 48, PlaceDarkOakFence, 0, 2);
        world.setBlock(i + 2, j + 4, k + 48, Blocks.log2, 5, 2);
        world.setBlock(i + 10, j + 4, k + 48, Blocks.planks, 5, 2);
        world.setBlock(i + 25, j + 4, k + 48, Blocks.fence, 0, 2);
        world.setBlock(i + 26, j + 4, k + 48, Blocks.planks, 5, 2);
        world.setBlock(i + 27, j + 4, k + 48, Blocks.torch, 5, 2);
        world.setBlock(i + 31, j + 4, k + 48, Blocks.log2, 1, 2);
        world.setBlock(i + 32, j + 4, k + 48, Blocks.log2, 1, 2);
        world.setBlock(i + 34, j + 4, k + 48, Blocks.planks, 5, 2);
        world.setBlock(i + 2, j + 4, k + 49, Blocks.planks, 5, 2);
        world.setBlock(i + 10, j + 4, k + 49, Blocks.planks, 5, 2);
        world.setBlock(i + 18, j + 4, k + 49, Blocks.fence, 0, 2);
        world.setBlock(i + 26, j + 4, k + 49, Blocks.planks, 5, 2);
        world.setBlock(i + 30, j + 4, k + 49, Blocks.planks, 5, 2);
        world.setBlock(i + 34, j + 4, k + 49, Blocks.planks, 5, 2);
        world.setBlock(i + 2, j + 4, k + 50, Blocks.planks, 5, 2);
        world.setBlock(i + 3, j + 4, k + 50, Blocks.planks, 5, 2);
        world.setBlock(i + 4, j + 4, k + 50, Blocks.torch, 5, 2);
        world.setBlock(i + 8, j + 4, k + 50, Blocks.torch, 5, 2);
        world.setBlock(i + 9, j + 4, k + 50, Blocks.planks, 5, 2);
        world.setBlock(i + 10, j + 4, k + 50, Blocks.planks, 5, 2);
        world.setBlock(i + 11, j + 4, k + 50, Blocks.planks, 5, 2);
        world.setBlock(i + 12, j + 4, k + 50, Blocks.planks, 5, 2);
        world.setBlock(i + 13, j + 4, k + 50, Blocks.planks, 5, 2);
        world.setBlock(i + 14, j + 4, k + 50, Blocks.log2, 9, 2);
        world.setBlock(i + 15, j + 4, k + 50, Blocks.planks, 5, 2);
        world.setBlock(i + 16, j + 4, k + 50, Blocks.planks, 5, 2);
        world.setBlock(i + 17, j + 4, k + 50, Blocks.planks, 5, 2);
        world.setBlock(i + 18, j + 4, k + 50, Blocks.planks, 5, 2);
        world.setBlock(i + 19, j + 4, k + 50, Blocks.planks, 5, 2);
        world.setBlock(i + 20, j + 4, k + 50, Blocks.planks, 5, 2);
        world.setBlock(i + 21, j + 4, k + 50, Blocks.planks, 5, 2);
        world.setBlock(i + 22, j + 4, k + 50, Blocks.log2, 9, 2);
        world.setBlock(i + 23, j + 4, k + 50, Blocks.planks, 5, 2);
        world.setBlock(i + 24, j + 4, k + 50, Blocks.planks, 5, 2);
        world.setBlock(i + 25, j + 4, k + 50, Blocks.planks, 5, 2);
        world.setBlock(i + 26, j + 4, k + 50, Blocks.planks, 5, 2);
        world.setBlock(i + 27, j + 4, k + 50, Blocks.planks, 5, 2);
        world.setBlock(i + 28, j + 4, k + 50, Blocks.planks, 5, 2);
        world.setBlock(i + 29, j + 4, k + 50, Blocks.planks, 5, 2);
        world.setBlock(i + 30, j + 4, k + 50, Blocks.planks, 5, 2);
        world.setBlock(i + 31, j + 4, k + 50, Blocks.planks, 5, 2);
        world.setBlock(i + 32, j + 4, k + 50, Blocks.planks, 5, 2);
        world.setBlock(i + 33, j + 4, k + 50, Blocks.planks, 5, 2);
        world.setBlock(i + 34, j + 4, k + 50, Blocks.planks, 5, 2);
        world.setBlock(i + 2, j + 4, k + 51, Blocks.planks, 5, 2);
        world.setBlock(i + 10, j + 4, k + 51, Blocks.planks, 5, 2);
        world.setBlock(i + 18, j + 4, k + 51, Blocks.planks, 5, 2);
        world.setBlock(i + 26, j + 4, k + 51, Blocks.planks, 5, 2);
        world.setBlock(i + 32, j + 4, k + 51, Blocks.planks, 2, 2);
        world.setBlock(i + 33, j + 4, k + 51, PlaceBirchFence, 0, 2);
        world.setBlock(i + 34, j + 4, k + 51, Blocks.planks, 5, 2);
        world.setBlock(i + 1, j + 4, k + 52, PlaceDarkOakFence, 0, 2);
        world.setBlock(i + 2, j + 4, k + 52, Blocks.log2, 5, 2);
        world.setBlock(i + 10, j + 4, k + 52, Blocks.torch, 5, 2);
        world.setBlock(i + 18, j + 4, k + 52, Blocks.torch, 5, 2);
        world.setBlock(i + 25, j + 4, k + 52, Blocks.torch, 5, 2);
        world.setBlock(i + 26, j + 4, k + 52, Blocks.planks, 5, 2);
        world.setBlock(i + 27, j + 4, k + 52, Blocks.torch, 5, 2);
        world.setBlock(i + 34, j + 4, k + 52, Blocks.log2, 5, 2);
        world.setBlock(i + 35, j + 4, k + 52, PlaceDarkOakFence, 0, 2);
        world.setBlock(i + 2, j + 4, k + 53, Blocks.glass_pane, 0, 2);
        world.setBlock(i + 26, j + 4, k + 53, Blocks.planks, 5, 2);
        world.setBlock(i + 34, j + 4, k + 53, Blocks.glass_pane, 0, 2);
        world.setBlock(i + 2, j + 4, k + 54, Blocks.glass_pane, 0, 2);
        world.setBlock(i + 26, j + 4, k + 54, Blocks.planks, 5, 2);
        world.setBlock(i + 34, j + 4, k + 54, Blocks.glass_pane, 0, 2);
        world.setBlock(i + 2, j + 4, k + 55, Blocks.glass_pane, 0, 2);
        world.setBlock(i + 26, j + 4, k + 55, Blocks.planks, 5, 2);
        world.setBlock(i + 34, j + 4, k + 55, Blocks.glass_pane, 0, 2);
        world.setBlock(i + 1, j + 4, k + 56, PlaceDarkOakFence, 0, 2);
        world.setBlock(i + 2, j + 4, k + 56, Blocks.log2, 5, 2);
        world.setBlock(i + 10, j + 4, k + 56, Blocks.torch, 5, 2);
        world.setBlock(i + 18, j + 4, k + 56, Blocks.torch, 5, 2);
        world.setBlock(i + 25, j + 4, k + 56, Blocks.torch, 5, 2);
        world.setBlock(i + 26, j + 4, k + 56, Blocks.planks, 5, 2);
        world.setBlock(i + 27, j + 4, k + 56, Blocks.torch, 5, 2);
        world.setBlock(i + 34, j + 4, k + 56, Blocks.log2, 5, 2);
        world.setBlock(i + 35, j + 4, k + 56, PlaceDarkOakFence, 0, 2);
        world.setBlock(i + 2, j + 4, k + 57, Blocks.planks, 5, 2);
        world.setBlock(i + 10, j + 4, k + 57, Blocks.planks, 5, 2);
        world.setBlock(i + 18, j + 4, k + 57, Blocks.planks, 5, 2);
        world.setBlock(i + 26, j + 4, k + 57, Blocks.planks, 5, 2);
        world.setBlock(i + 31, j + 4, k + 57, Blocks.ladder, 4, 2);
        world.setBlock(i + 32, j + 4, k + 57, Blocks.planks, 2, 2);
        world.setBlock(i + 33, j + 4, k + 57, PlaceBirchFence, 0, 2);
        world.setBlock(i + 34, j + 4, k + 57, Blocks.planks, 5, 2);
        world.setBlock(i + 2, j + 4, k + 58, Blocks.planks, 5, 2);
        world.setBlock(i + 3, j + 4, k + 58, Blocks.planks, 5, 2);
        world.setBlock(i + 4, j + 4, k + 58, Blocks.planks, 5, 2);
        world.setBlock(i + 5, j + 4, k + 58, Blocks.planks, 5, 2);
        world.setBlock(i + 6, j + 4, k + 58, Blocks.planks, 5, 2);
        world.setBlock(i + 7, j + 4, k + 58, Blocks.planks, 5, 2);
        world.setBlock(i + 8, j + 4, k + 58, Blocks.planks, 5, 2);
        world.setBlock(i + 9, j + 4, k + 58, Blocks.planks, 5, 2);
        world.setBlock(i + 10, j + 4, k + 58, Blocks.planks, 5, 2);
        world.setBlock(i + 11, j + 4, k + 58, Blocks.planks, 5, 2);
        world.setBlock(i + 12, j + 4, k + 58, Blocks.planks, 5, 2);
        world.setBlock(i + 13, j + 4, k + 58, Blocks.planks, 5, 2);
        world.setBlock(i + 14, j + 4, k + 58, Blocks.log2, 9, 2);
        world.setBlock(i + 15, j + 4, k + 58, Blocks.planks, 5, 2);
        world.setBlock(i + 16, j + 4, k + 58, Blocks.planks, 5, 2);
        world.setBlock(i + 17, j + 4, k + 58, Blocks.planks, 5, 2);
        world.setBlock(i + 18, j + 4, k + 58, Blocks.planks, 5, 2);
        world.setBlock(i + 19, j + 4, k + 58, Blocks.planks, 5, 2);
        world.setBlock(i + 20, j + 4, k + 58, Blocks.planks, 5, 2);
        world.setBlock(i + 21, j + 4, k + 58, Blocks.planks, 5, 2);
        world.setBlock(i + 22, j + 4, k + 58, Blocks.planks, 5, 2);
        world.setBlock(i + 23, j + 4, k + 58, Blocks.planks, 5, 2);
        world.setBlock(i + 24, j + 4, k + 58, Blocks.planks, 5, 2);
        world.setBlock(i + 25, j + 4, k + 58, Blocks.planks, 5, 2);
        world.setBlock(i + 26, j + 4, k + 58, Blocks.planks, 5, 2);
        world.setBlock(i + 27, j + 4, k + 58, Blocks.planks, 5, 2);
        world.setBlock(i + 28, j + 4, k + 58, Blocks.log2, 9, 2);
        world.setBlock(i + 29, j + 4, k + 58, Blocks.glass_pane, 0, 2);
        world.setBlock(i + 30, j + 4, k + 58, Blocks.glass_pane, 0, 2);
        world.setBlock(i + 31, j + 4, k + 58, Blocks.glass_pane, 0, 2);
        world.setBlock(i + 32, j + 4, k + 58, Blocks.log2, 9, 2);
        world.setBlock(i + 33, j + 4, k + 58, Blocks.planks, 5, 2);
        world.setBlock(i + 34, j + 4, k + 58, Blocks.cobblestone, 0, 2);
        world.setBlock(i + 35, j + 4, k + 58, Blocks.cobblestone, 0, 2);
        world.setBlock(i + 2, j + 4, k + 59, Blocks.planks, 5, 2);
        world.setBlock(i + 10, j + 4, k + 59, Blocks.planks, 5, 2);
        world.setBlock(i + 26, j + 4, k + 59, Blocks.planks, 5, 2);
        world.setBlock(i + 28, j + 4, k + 59, PlaceDarkOakFence, 0, 2);
        world.setBlock(i + 32, j + 4, k + 59, PlaceDarkOakFence, 0, 2);
        world.setBlock(i + 34, j + 4, k + 59, Blocks.cobblestone, 0, 2);
        world.setBlock(i + 35, j + 4, k + 59, Blocks.cobblestone_wall, 0, 2);
        world.setBlock(i + 1, j + 4, k + 60, PlaceDarkOakFence, 0, 2);
        world.setBlock(i + 2, j + 4, k + 60, Blocks.log2, 5, 2);
        world.setBlock(i + 10, j + 4, k + 60, Blocks.planks, 5, 2);
        world.setBlock(i + 26, j + 4, k + 60, Blocks.log2, 5, 2);
        world.setBlock(i + 27, j + 4, k + 60, PlaceDarkOakFence, 0, 2);
        world.setBlock(i + 2, j + 4, k + 61, Blocks.glass_pane, 0, 2);
        world.setBlock(i + 10, j + 4, k + 61, Blocks.planks, 5, 2);
        world.setBlock(i + 26, j + 4, k + 61, Blocks.glass_pane, 0, 2);
        world.setBlock(i + 2, j + 4, k + 62, Blocks.glass_pane, 0, 2);
        world.setBlock(i + 10, j + 4, k + 62, Blocks.log2, 5, 2);
        world.setBlock(i + 26, j + 4, k + 62, Blocks.glass_pane, 0, 2);
        world.setBlock(i + 2, j + 4, k + 63, Blocks.glass_pane, 0, 2);
        world.setBlock(i + 10, j + 4, k + 63, Blocks.planks, 5, 2);
        world.setBlock(i + 26, j + 4, k + 63, Blocks.glass_pane, 0, 2);
        world.setBlock(i + 1, j + 4, k + 64, PlaceDarkOakFence, 0, 2);
        world.setBlock(i + 2, j + 4, k + 64, Blocks.log2, 5, 2);
        world.setBlock(i + 10, j + 4, k + 64, Blocks.planks, 5, 2);
        world.setBlock(i + 26, j + 4, k + 64, Blocks.log2, 5, 2);
        world.setBlock(i + 27, j + 4, k + 64, PlaceDarkOakFence, 0, 2);
        world.setBlock(i + 2, j + 4, k + 65, Blocks.planks, 5, 2);
        world.setBlock(i + 10, j + 4, k + 65, Blocks.planks, 5, 2);
        world.setBlock(i + 26, j + 4, k + 65, Blocks.planks, 5, 2);
        world.setBlock(i + 2, j + 4, k + 66, Blocks.planks, 5, 2);
        world.setBlock(i + 10, j + 4, k + 66, Blocks.planks, 5, 2);
        world.setBlock(i + 26, j + 4, k + 66, Blocks.planks, 5, 2);
        world.setBlock(i + 2, j + 4, k + 67, Blocks.planks, 5, 2);
        world.setBlock(i + 10, j + 4, k + 67, Blocks.planks, 5, 2);
        world.setBlock(i + 26, j + 4, k + 67, Blocks.planks, 5, 2);
        world.setBlock(i + 1, j + 4, k + 68, PlaceDarkOakFence, 0, 2);
        world.setBlock(i + 2, j + 4, k + 68, Blocks.log2, 5, 2);
        world.setBlock(i + 10, j + 4, k + 68, Blocks.planks, 5, 2);
        world.setBlock(i + 26, j + 4, k + 68, Blocks.log2, 5, 2);
        world.setBlock(i + 27, j + 4, k + 68, PlaceDarkOakFence, 0, 2);
        world.setBlock(i + 2, j + 4, k + 69, Blocks.glass_pane, 0, 2);
        world.setBlock(i + 10, j + 4, k + 69, Blocks.planks, 5, 2);
        world.setBlock(i + 26, j + 4, k + 69, Blocks.glass_pane, 0, 2);
        world.setBlock(i + 2, j + 4, k + 70, Blocks.glass_pane, 0, 2);
        world.setBlock(i + 10, j + 4, k + 70, Blocks.log2, 5, 2);
        world.setBlock(i + 26, j + 4, k + 70, Blocks.glass_pane, 0, 2);
        world.setBlock(i + 2, j + 4, k + 71, Blocks.glass_pane, 0, 2);
        world.setBlock(i + 10, j + 4, k + 71, Blocks.planks, 5, 2);
        world.setBlock(i + 26, j + 4, k + 71, Blocks.glass_pane, 0, 2);
        world.setBlock(i + 1, j + 4, k + 72, PlaceDarkOakFence, 0, 2);
        world.setBlock(i + 2, j + 4, k + 72, Blocks.log2, 5, 2);
        world.setBlock(i + 10, j + 4, k + 72, Blocks.planks, 5, 2);
        world.setBlock(i + 26, j + 4, k + 72, Blocks.log2, 5, 2);
        world.setBlock(i + 27, j + 4, k + 72, PlaceDarkOakFence, 0, 2);
        world.setBlock(i + 2, j + 4, k + 73, Blocks.planks, 5, 2);
        world.setBlock(i + 10, j + 4, k + 73, Blocks.planks, 5, 2);
        world.setBlock(i + 26, j + 4, k + 73, Blocks.planks, 5, 2);
        world.setBlock(i + 1, j + 4, k + 74, Blocks.cobblestone, 0, 2);
        world.setBlock(i + 2, j + 4, k + 74, Blocks.cobblestone, 0, 2);
        world.setBlock(i + 3, j + 4, k + 74, Blocks.planks, 5, 2);
        world.setBlock(i + 4, j + 4, k + 74, Blocks.log2, 9, 2);
        world.setBlock(i + 5, j + 4, k + 74, Blocks.glass_pane, 0, 2);
        world.setBlock(i + 6, j + 4, k + 74, Blocks.glass_pane, 0, 2);
        world.setBlock(i + 7, j + 4, k + 74, Blocks.glass_pane, 0, 2);
        world.setBlock(i + 8, j + 4, k + 74, Blocks.log2, 9, 2);
        world.setBlock(i + 9, j + 4, k + 74, Blocks.planks, 5, 2);
        world.setBlock(i + 10, j + 4, k + 74, Blocks.planks, 5, 2);
        world.setBlock(i + 11, j + 4, k + 74, Blocks.planks, 5, 2);
        world.setBlock(i + 12, j + 4, k + 74, Blocks.log2, 9, 2);
        world.setBlock(i + 13, j + 4, k + 74, Blocks.glass_pane, 0, 2);
        world.setBlock(i + 14, j + 4, k + 74, Blocks.glass_pane, 0, 2);
        world.setBlock(i + 15, j + 4, k + 74, Blocks.glass_pane, 0, 2);
        world.setBlock(i + 16, j + 4, k + 74, Blocks.log2, 9, 2);
        world.setBlock(i + 17, j + 4, k + 74, Blocks.planks, 5, 2);
        world.setBlock(i + 18, j + 4, k + 74, Blocks.planks, 5, 2);
        world.setBlock(i + 19, j + 4, k + 74, Blocks.planks, 5, 2);
        world.setBlock(i + 20, j + 4, k + 74, Blocks.log2, 9, 2);
        world.setBlock(i + 21, j + 4, k + 74, Blocks.glass_pane, 0, 2);
        world.setBlock(i + 22, j + 4, k + 74, Blocks.glass_pane, 0, 2);
        world.setBlock(i + 23, j + 4, k + 74, Blocks.glass_pane, 0, 2);
        world.setBlock(i + 24, j + 4, k + 74, Blocks.log2, 9, 2);
        world.setBlock(i + 25, j + 4, k + 74, Blocks.planks, 5, 2);
        world.setBlock(i + 26, j + 4, k + 74, Blocks.cobblestone, 0, 2);
        world.setBlock(i + 27, j + 4, k + 74, Blocks.cobblestone, 0, 2);
        world.setBlock(i + 1, j + 4, k + 75, Blocks.cobblestone_wall, 0, 2);
        world.setBlock(i + 2, j + 4, k + 75, Blocks.cobblestone, 0, 2);
        world.setBlock(i + 4, j + 4, k + 75, PlaceDarkOakFence, 0, 2);
        world.setBlock(i + 8, j + 4, k + 75, PlaceDarkOakFence, 0, 2);
        world.setBlock(i + 12, j + 4, k + 75, PlaceDarkOakFence, 0, 2);
        world.setBlock(i + 16, j + 4, k + 75, PlaceDarkOakFence, 0, 2);
        world.setBlock(i + 20, j + 4, k + 75, PlaceDarkOakFence, 0, 2);
        world.setBlock(i + 24, j + 4, k + 75, PlaceDarkOakFence, 0, 2);
        world.setBlock(i + 26, j + 4, k + 75, Blocks.cobblestone, 0, 2);
        world.setBlock(i + 27, j + 4, k + 75, Blocks.cobblestone_wall, 0, 2);
        world.setBlock(i + 1, j + 5, k + 1, Blocks.cobblestone_wall, 0, 2);
        world.setBlock(i + 2, j + 5, k + 1, Blocks.cobblestone, 0, 2);
        world.setBlock(i + 4, j + 5, k + 1, Blocks.log2, 5, 2);
        world.setBlock(i + 5, j + 5, k + 1, Blocks.log2, 5, 2);
        world.setBlock(i + 6, j + 5, k + 1, Blocks.log2, 5, 2);
        world.setBlock(i + 7, j + 5, k + 1, Blocks.log2, 5, 2);
        world.setBlock(i + 8, j + 5, k + 1, Blocks.log2, 5, 2);
        world.setBlock(i + 12, j + 5, k + 1, Blocks.log2, 5, 2);
        world.setBlock(i + 13, j + 5, k + 1, Blocks.log2, 5, 2);
        world.setBlock(i + 14, j + 5, k + 1, Blocks.log2, 5, 2);
        world.setBlock(i + 15, j + 5, k + 1, Blocks.log2, 5, 2);
        world.setBlock(i + 16, j + 5, k + 1, Blocks.log2, 5, 2);
        world.setBlock(i + 18, j + 5, k + 1, Blocks.cobblestone, 0, 2);
        world.setBlock(i + 19, j + 5, k + 1, Blocks.cobblestone_wall, 0, 2);
        world.setBlock(i + 1, j + 5, k + 2, Blocks.cobblestone, 0, 2);
        world.setBlock(i + 2, j + 5, k + 2, Blocks.cobblestone, 0, 2);
        world.setBlock(i + 3, j + 5, k + 2, Blocks.planks, 5, 2);
        world.setBlock(i + 4, j + 5, k + 2, Blocks.log2, 9, 2);
        world.setBlock(i + 5, j + 5, k + 2, Blocks.log2, 9, 2);
        world.setBlock(i + 6, j + 5, k + 2, Blocks.log2, 9, 2);
        world.setBlock(i + 7, j + 5, k + 2, Blocks.log2, 9, 2);
        world.setBlock(i + 8, j + 5, k + 2, Blocks.log2, 9, 2);
        world.setBlock(i + 9, j + 5, k + 2, Blocks.planks, 5, 2);
        world.setBlock(i + 10, j + 5, k + 2, Blocks.planks, 5, 2);
        world.setBlock(i + 11, j + 5, k + 2, Blocks.planks, 5, 2);
        world.setBlock(i + 12, j + 5, k + 2, Blocks.log2, 9, 2);
        world.setBlock(i + 13, j + 5, k + 2, Blocks.log2, 9, 2);
        world.setBlock(i + 14, j + 5, k + 2, Blocks.log2, 9, 2);
        world.setBlock(i + 15, j + 5, k + 2, Blocks.log2, 9, 2);
        world.setBlock(i + 16, j + 5, k + 2, Blocks.log2, 9, 2);
        world.setBlock(i + 17, j + 5, k + 2, Blocks.planks, 5, 2);
        world.setBlock(i + 18, j + 5, k + 2, Blocks.cobblestone, 0, 2);
        world.setBlock(i + 19, j + 5, k + 2, Blocks.cobblestone, 0, 2);
        world.setBlock(i + 2, j + 5, k + 3, Blocks.planks, 5, 2);
        world.setBlock(i + 18, j + 5, k + 3, Blocks.planks, 5, 2);
        world.setBlock(i + 1, j + 5, k + 4, Blocks.log2, 9, 2);
        world.setBlock(i + 2, j + 5, k + 4, Blocks.log2, 5, 2);
        world.setBlock(i + 18, j + 5, k + 4, Blocks.log2, 5, 2);
        world.setBlock(i + 19, j + 5, k + 4, Blocks.log2, 9, 2);
        world.setBlock(i + 1, j + 5, k + 5, Blocks.log2, 9, 2);
        world.setBlock(i + 2, j + 5, k + 5, Blocks.log2, 5, 2);
        world.setBlock(i + 18, j + 5, k + 5, Blocks.log2, 5, 2);
        world.setBlock(i + 19, j + 5, k + 5, Blocks.log2, 9, 2);
        world.setBlock(i + 1, j + 5, k + 6, Blocks.log2, 9, 2);
        world.setBlock(i + 2, j + 5, k + 6, Blocks.log2, 5, 2);
        world.setBlock(i + 18, j + 5, k + 6, Blocks.log2, 5, 2);
        world.setBlock(i + 19, j + 5, k + 6, Blocks.log2, 9, 2);
        world.setBlock(i + 1, j + 5, k + 7, Blocks.log2, 9, 2);
        world.setBlock(i + 2, j + 5, k + 7, Blocks.log2, 5, 2);
        world.setBlock(i + 18, j + 5, k + 7, Blocks.log2, 5, 2);
        world.setBlock(i + 19, j + 5, k + 7, Blocks.log2, 9, 2);
        world.setBlock(i + 1, j + 5, k + 8, Blocks.log2, 9, 2);
        world.setBlock(i + 2, j + 5, k + 8, Blocks.log2, 5, 2);
        world.setBlock(i + 18, j + 5, k + 8, Blocks.log2, 5, 2);
        world.setBlock(i + 19, j + 5, k + 8, Blocks.log2, 9, 2);
        world.setBlock(i + 2, j + 5, k + 9, Blocks.planks, 5, 2);
        world.setBlock(i + 18, j + 5, k + 9, Blocks.planks, 5, 2);
        world.setBlock(i + 2, j + 5, k + 10, Blocks.planks, 5, 2);
        world.setBlock(i + 18, j + 5, k + 10, Blocks.planks, 5, 2);
        world.setBlock(i + 2, j + 5, k + 11, Blocks.planks, 5, 2);
        world.setBlock(i + 18, j + 5, k + 11, Blocks.planks, 5, 2);
        world.setBlock(i + 1, j + 5, k + 12, Blocks.log2, 9, 2);
        world.setBlock(i + 2, j + 5, k + 12, Blocks.log2, 5, 2);
        world.setBlock(i + 18, j + 5, k + 12, Blocks.log2, 5, 2);
        world.setBlock(i + 19, j + 5, k + 12, Blocks.log2, 9, 2);
        world.setBlock(i + 1, j + 5, k + 13, Blocks.log2, 9, 2);
        world.setBlock(i + 2, j + 5, k + 13, Blocks.log2, 5, 2);
        world.setBlock(i + 18, j + 5, k + 13, Blocks.log2, 5, 2);
        world.setBlock(i + 19, j + 5, k + 13, Blocks.log2, 9, 2);
        world.setBlock(i + 1, j + 5, k + 14, Blocks.log2, 9, 2);
        world.setBlock(i + 2, j + 5, k + 14, Blocks.log2, 5, 2);
        world.setBlock(i + 18, j + 5, k + 14, Blocks.log2, 5, 2);
        world.setBlock(i + 19, j + 5, k + 14, Blocks.log2, 9, 2);
        world.setBlock(i + 1, j + 5, k + 15, Blocks.log2, 9, 2);
        world.setBlock(i + 2, j + 5, k + 15, Blocks.log2, 5, 2);
        world.setBlock(i + 18, j + 5, k + 15, Blocks.log2, 5, 2);
        world.setBlock(i + 19, j + 5, k + 15, Blocks.log2, 9, 2);
        world.setBlock(i + 1, j + 5, k + 16, Blocks.log2, 9, 2);
        world.setBlock(i + 2, j + 5, k + 16, Blocks.log2, 5, 2);
        world.setBlock(i + 18, j + 5, k + 16, Blocks.log2, 5, 2);
        world.setBlock(i + 19, j + 5, k + 16, Blocks.log2, 9, 2);
        world.setBlock(i + 2, j + 5, k + 17, Blocks.planks, 5, 2);
        world.setBlock(i + 18, j + 5, k + 17, Blocks.planks, 5, 2);
        world.setBlock(i + 20, j + 5, k + 17, Blocks.log2, 5, 2);
        world.setBlock(i + 21, j + 5, k + 17, Blocks.log2, 5, 2);
        world.setBlock(i + 22, j + 5, k + 17, Blocks.log2, 5, 2);
        world.setBlock(i + 23, j + 5, k + 17, Blocks.log2, 5, 2);
        world.setBlock(i + 24, j + 5, k + 17, Blocks.log2, 5, 2);
        world.setBlock(i + 26, j + 5, k + 17, Blocks.cobblestone, 0, 2);
        world.setBlock(i + 27, j + 5, k + 17, Blocks.cobblestone_wall, 0, 2);
        world.setBlock(i + 2, j + 5, k + 18, Blocks.planks, 5, 2);
        world.setBlock(i + 3, j + 5, k + 18, Blocks.planks, 5, 2);
        world.setBlock(i + 4, j + 5, k + 18, Blocks.planks, 5, 2);
        world.setBlock(i + 5, j + 5, k + 18, Blocks.planks, 5, 2);
        world.setBlock(i + 6, j + 5, k + 18, Blocks.planks, 5, 2);
        world.setBlock(i + 7, j + 5, k + 18, Blocks.planks, 5, 2);
        world.setBlock(i + 8, j + 5, k + 18, Blocks.planks, 5, 2);
        world.setBlock(i + 9, j + 5, k + 18, Blocks.planks, 5, 2);
        world.setBlock(i + 10, j + 5, k + 18, Blocks.planks, 5, 2);
        world.setBlock(i + 11, j + 5, k + 18, Blocks.planks, 5, 2);
        world.setBlock(i + 12, j + 5, k + 18, Blocks.planks, 5, 2);
        world.setBlock(i + 13, j + 5, k + 18, Blocks.planks, 5, 2);
        world.setBlock(i + 14, j + 5, k + 18, Blocks.log2, 9, 2);
        world.setBlock(i + 15, j + 5, k + 18, Blocks.planks, 5, 2);
        world.setBlock(i + 16, j + 5, k + 18, Blocks.planks, 5, 2);
        world.setBlock(i + 17, j + 5, k + 18, Blocks.planks, 5, 2);
        world.setBlock(i + 18, j + 5, k + 18, Blocks.planks, 5, 2);
        world.setBlock(i + 19, j + 5, k + 18, Blocks.planks, 5, 2);
        world.setBlock(i + 20, j + 5, k + 18, Blocks.log2, 9, 2);
        world.setBlock(i + 21, j + 5, k + 18, Blocks.log2, 9, 2);
        world.setBlock(i + 22, j + 5, k + 18, Blocks.log2, 9, 2);
        world.setBlock(i + 23, j + 5, k + 18, Blocks.log2, 9, 2);
        world.setBlock(i + 24, j + 5, k + 18, Blocks.log2, 9, 2);
        world.setBlock(i + 25, j + 5, k + 18, Blocks.planks, 5, 2);
        world.setBlock(i + 26, j + 5, k + 18, Blocks.cobblestone, 0, 2);
        world.setBlock(i + 27, j + 5, k + 18, Blocks.cobblestone, 0, 2);
        world.setBlock(i + 2, j + 5, k + 19, Blocks.planks, 5, 2);
        world.setBlock(i + 10, j + 5, k + 19, Blocks.planks, 5, 2);
        world.setBlock(i + 18, j + 5, k + 19, Blocks.planks, 5, 2);
        world.setBlock(i + 26, j + 5, k + 19, Blocks.planks, 5, 2);
        world.setBlock(i + 1, j + 5, k + 20, Blocks.log2, 9, 2);
        world.setBlock(i + 2, j + 5, k + 20, Blocks.log2, 5, 2);
        world.setBlock(i + 26, j + 5, k + 20, Blocks.log2, 5, 2);
        world.setBlock(i + 27, j + 5, k + 20, Blocks.log2, 9, 2);
        world.setBlock(i + 1, j + 5, k + 21, Blocks.log2, 9, 2);
        world.setBlock(i + 2, j + 5, k + 21, Blocks.log2, 5, 2);
        world.setBlock(i + 26, j + 5, k + 21, Blocks.log2, 5, 2);
        world.setBlock(i + 27, j + 5, k + 21, Blocks.log2, 9, 2);
        world.setBlock(i + 1, j + 5, k + 22, Blocks.log2, 9, 2);
        world.setBlock(i + 2, j + 5, k + 22, Blocks.log2, 5, 2);
        world.setBlock(i + 26, j + 5, k + 22, Blocks.log2, 5, 2);
        world.setBlock(i + 27, j + 5, k + 22, Blocks.log2, 9, 2);
        world.setBlock(i + 1, j + 5, k + 23, Blocks.log2, 9, 2);
        world.setBlock(i + 2, j + 5, k + 23, Blocks.log2, 5, 2);
        world.setBlock(i + 26, j + 5, k + 23, Blocks.log2, 5, 2);
        world.setBlock(i + 27, j + 5, k + 23, Blocks.log2, 9, 2);
        world.setBlock(i + 1, j + 5, k + 24, Blocks.log2, 9, 2);
        world.setBlock(i + 2, j + 5, k + 24, Blocks.log2, 5, 2);
        world.setBlock(i + 26, j + 5, k + 24, Blocks.log2, 5, 2);
        world.setBlock(i + 27, j + 5, k + 24, Blocks.log2, 9, 2);
        world.setBlock(i + 2, j + 5, k + 25, Blocks.planks, 5, 2);
        world.setBlock(i + 10, j + 5, k + 25, Blocks.planks, 5, 2);
        world.setBlock(i + 18, j + 5, k + 25, Blocks.planks, 5, 2);
        world.setBlock(i + 26, j + 5, k + 25, Blocks.planks, 5, 2);
        world.setBlock(i + 2, j + 5, k + 26, Blocks.planks, 5, 2);
        world.setBlock(i + 3, j + 5, k + 26, Blocks.planks, 5, 2);
        world.setBlock(i + 9, j + 5, k + 26, Blocks.planks, 5, 2);
        world.setBlock(i + 10, j + 5, k + 26, Blocks.planks, 5, 2);
        world.setBlock(i + 11, j + 5, k + 26, Blocks.planks, 5, 2);
        world.setBlock(i + 12, j + 5, k + 26, Blocks.planks, 5, 2);
        world.setBlock(i + 13, j + 5, k + 26, Blocks.planks, 5, 2);
        world.setBlock(i + 14, j + 5, k + 26, Blocks.planks, 5, 2);
        world.setBlock(i + 15, j + 5, k + 26, Blocks.planks, 5, 2);
        world.setBlock(i + 16, j + 5, k + 26, Blocks.planks, 5, 2);
        world.setBlock(i + 17, j + 5, k + 26, Blocks.planks, 5, 2);
        world.setBlock(i + 18, j + 5, k + 26, Blocks.planks, 5, 2);
        world.setBlock(i + 26, j + 5, k + 26, Blocks.planks, 5, 2);
        world.setBlock(i + 2, j + 5, k + 27, Blocks.planks, 5, 2);
        world.setBlock(i + 10, j + 5, k + 27, Blocks.planks, 5, 2);
        world.setBlock(i + 18, j + 5, k + 27, Blocks.planks, 5, 2);
        world.setBlock(i + 26, j + 5, k + 27, Blocks.planks, 5, 2);
        world.setBlock(i + 1, j + 5, k + 28, Blocks.log2, 9, 2);
        world.setBlock(i + 2, j + 5, k + 28, Blocks.log2, 5, 2);
        world.setBlock(i + 10, j + 5, k + 28, Blocks.planks, 5, 2);
        world.setBlock(i + 18, j + 5, k + 28, Blocks.planks, 5, 2);
        world.setBlock(i + 26, j + 5, k + 28, Blocks.log2, 5, 2);
        world.setBlock(i + 27, j + 5, k + 28, Blocks.log2, 9, 2);
        world.setBlock(i + 1, j + 5, k + 29, Blocks.log2, 9, 2);
        world.setBlock(i + 2, j + 5, k + 29, Blocks.log2, 5, 2);
        world.setBlock(i + 10, j + 5, k + 29, Blocks.planks, 5, 2);
        world.setBlock(i + 11, j + 5, k + 29, Blocks.dark_oak_stairs, 2, 2);
        world.setBlock(i + 17, j + 5, k + 29, Blocks.dark_oak_stairs, 2, 2);
        world.setBlock(i + 18, j + 5, k + 29, Blocks.planks, 5, 2);
        world.setBlock(i + 26, j + 5, k + 29, Blocks.log2, 5, 2);
        world.setBlock(i + 27, j + 5, k + 29, Blocks.log2, 9, 2);
        world.setBlock(i + 1, j + 5, k + 30, Blocks.log2, 9, 2);
        world.setBlock(i + 2, j + 5, k + 30, Blocks.log2, 5, 2);
        world.setBlock(i + 10, j + 5, k + 30, Blocks.log2, 5, 2);
        world.setBlock(i + 11, j + 5, k + 30, Blocks.planks, 5, 2);
        world.setBlock(i + 17, j + 5, k + 30, Blocks.planks, 5, 2);
        world.setBlock(i + 18, j + 5, k + 30, Blocks.log2, 5, 2);
        world.setBlock(i + 26, j + 5, k + 30, Blocks.log2, 5, 2);
        world.setBlock(i + 27, j + 5, k + 30, Blocks.log2, 9, 2);
        world.setBlock(i + 1, j + 5, k + 31, Blocks.log2, 9, 2);
        world.setBlock(i + 2, j + 5, k + 31, Blocks.log2, 5, 2);
        world.setBlock(i + 10, j + 5, k + 31, Blocks.planks, 5, 2);
        world.setBlock(i + 11, j + 5, k + 31, Blocks.dark_oak_stairs, 3, 2);
        world.setBlock(i + 17, j + 5, k + 31, Blocks.dark_oak_stairs, 3, 2);
        world.setBlock(i + 18, j + 5, k + 31, Blocks.planks, 5, 2);
        world.setBlock(i + 26, j + 5, k + 31, Blocks.log2, 5, 2);
        world.setBlock(i + 27, j + 5, k + 31, Blocks.log2, 9, 2);
        world.setBlock(i + 1, j + 5, k + 32, Blocks.log2, 9, 2);
        world.setBlock(i + 2, j + 5, k + 32, Blocks.log2, 5, 2);
        world.setBlock(i + 10, j + 5, k + 32, Blocks.planks, 5, 2);
        world.setBlock(i + 18, j + 5, k + 32, Blocks.planks, 5, 2);
        world.setBlock(i + 26, j + 5, k + 32, Blocks.log2, 5, 2);
        world.setBlock(i + 27, j + 5, k + 32, Blocks.log2, 9, 2);
        world.setBlock(i + 2, j + 5, k + 33, Blocks.planks, 5, 2);
        world.setBlock(i + 10, j + 5, k + 33, Blocks.planks, 5, 2);
        world.setBlock(i + 18, j + 5, k + 33, Blocks.planks, 5, 2);
        world.setBlock(i + 19, j + 5, k + 33, Blocks.planks, 5, 2);
        world.setBlock(i + 20, j + 5, k + 33, Blocks.wool, 8, 2);
        world.setBlock(i + 21, j + 5, k + 33, Blocks.wool, 8, 2);
        world.setBlock(i + 22, j + 5, k + 33, Blocks.wool, 8, 2);
        world.setBlock(i + 23, j + 5, k + 33, Blocks.wool, 8, 2);
        world.setBlock(i + 24, j + 5, k + 33, Blocks.wool, 8, 2);
        world.setBlock(i + 25, j + 5, k + 33, Blocks.planks, 5, 2);
        world.setBlock(i + 26, j + 5, k + 33, Blocks.planks, 5, 2);
        world.setBlock(i + 2, j + 5, k + 34, Blocks.planks, 5, 2);
        world.setBlock(i + 3, j + 5, k + 34, Blocks.planks, 5, 2);
        world.setBlock(i + 9, j + 5, k + 34, Blocks.planks, 5, 2);
        world.setBlock(i + 10, j + 5, k + 34, Blocks.planks, 5, 2);
        world.setBlock(i + 11, j + 5, k + 34, Blocks.planks, 5, 2);
        world.setBlock(i + 12, j + 5, k + 34, Blocks.planks, 5, 2);
        world.setBlock(i + 13, j + 5, k + 34, Blocks.planks, 5, 2);
        world.setBlock(i + 14, j + 5, k + 34, Blocks.log2, 9, 2);
        world.setBlock(i + 15, j + 5, k + 34, Blocks.planks, 5, 2);
        world.setBlock(i + 16, j + 5, k + 34, Blocks.planks, 5, 2);
        world.setBlock(i + 17, j + 5, k + 34, Blocks.planks, 5, 2);
        world.setBlock(i + 18, j + 5, k + 34, Blocks.planks, 5, 2);
        world.setBlock(i + 19, j + 5, k + 34, Blocks.planks, 5, 2);
        world.setBlock(i + 20, j + 5, k + 34, Blocks.planks, 5, 2);
        world.setBlock(i + 21, j + 5, k + 34, Blocks.planks, 5, 2);
        world.setBlock(i + 22, j + 5, k + 34, Blocks.log2, 9, 2);
        world.setBlock(i + 23, j + 5, k + 34, Blocks.planks, 5, 2);
        world.setBlock(i + 24, j + 5, k + 34, Blocks.planks, 5, 2);
        world.setBlock(i + 25, j + 5, k + 34, Blocks.planks, 5, 2);
        world.setBlock(i + 26, j + 5, k + 34, Blocks.planks, 5, 2);
        world.setBlock(i + 2, j + 5, k + 35, Blocks.planks, 5, 2);
        world.setBlock(i + 10, j + 5, k + 35, Blocks.planks, 5, 2);
        world.setBlock(i + 18, j + 5, k + 35, Blocks.torch, 5, 2);
        world.setBlock(i + 26, j + 5, k + 35, Blocks.planks, 5, 2);
        world.setBlock(i + 1, j + 5, k + 36, Blocks.log2, 9, 2);
        world.setBlock(i + 2, j + 5, k + 36, Blocks.log2, 5, 2);
        world.setBlock(i + 10, j + 5, k + 36, Blocks.planks, 5, 2);
        world.setBlock(i + 26, j + 5, k + 36, Blocks.log2, 5, 2);
        world.setBlock(i + 27, j + 5, k + 36, Blocks.log2, 9, 2);
        world.setBlock(i + 1, j + 5, k + 37, Blocks.log2, 9, 2);
        world.setBlock(i + 2, j + 5, k + 37, Blocks.log2, 5, 2);
        world.setBlock(i + 10, j + 5, k + 37, Blocks.planks, 5, 2);
        world.setBlock(i + 26, j + 5, k + 37, Blocks.log2, 5, 2);
        world.setBlock(i + 27, j + 5, k + 37, Blocks.log2, 9, 2);
        world.setBlock(i + 1, j + 5, k + 38, Blocks.log2, 9, 2);
        world.setBlock(i + 2, j + 5, k + 38, Blocks.log2, 5, 2);
        world.setBlock(i + 10, j + 5, k + 38, Blocks.planks, 5, 2);
        world.setBlock(i + 26, j + 5, k + 38, Blocks.log2, 5, 2);
        world.setBlock(i + 27, j + 5, k + 38, Blocks.log2, 9, 2);
        world.setBlock(i + 1, j + 5, k + 39, Blocks.log2, 9, 2);
        world.setBlock(i + 2, j + 5, k + 39, Blocks.log2, 5, 2);
        world.setBlock(i + 10, j + 5, k + 39, Blocks.planks, 5, 2);
        world.setBlock(i + 26, j + 5, k + 39, Blocks.log2, 5, 2);
        world.setBlock(i + 27, j + 5, k + 39, Blocks.log2, 9, 2);
        world.setBlock(i + 1, j + 5, k + 40, Blocks.log2, 9, 2);
        world.setBlock(i + 2, j + 5, k + 40, Blocks.log2, 5, 2);
        world.setBlock(i + 10, j + 5, k + 40, Blocks.planks, 5, 2);
        world.setBlock(i + 26, j + 5, k + 40, Blocks.log2, 5, 2);
        world.setBlock(i + 27, j + 5, k + 40, Blocks.log2, 9, 2);
        world.setBlock(i + 2, j + 5, k + 41, Blocks.planks, 5, 2);
        world.setBlock(i + 10, j + 5, k + 41, Blocks.planks, 5, 2);
        world.setBlock(i + 26, j + 5, k + 41, Blocks.planks, 5, 2);
        world.setBlock(i + 2, j + 5, k + 42, Blocks.planks, 5, 2);
        world.setBlock(i + 3, j + 5, k + 42, Blocks.planks, 5, 2);
        world.setBlock(i + 9, j + 5, k + 42, Blocks.planks, 5, 2);
        world.setBlock(i + 10, j + 5, k + 42, Blocks.planks, 5, 2);
        world.setBlock(i + 11, j + 5, k + 42, Blocks.torch, 5, 2);
        world.setBlock(i + 25, j + 5, k + 42, Blocks.torch, 5, 2);
        world.setBlock(i + 26, j + 5, k + 42, Blocks.planks, 5, 2);
        world.setBlock(i + 2, j + 5, k + 43, Blocks.planks, 5, 2);
        world.setBlock(i + 10, j + 5, k + 43, Blocks.planks, 5, 2);
        world.setBlock(i + 26, j + 5, k + 43, Blocks.planks, 5, 2);
        world.setBlock(i + 27, j + 5, k + 43, Blocks.cobblestone_wall, 0, 2);
        world.setBlock(i + 1, j + 5, k + 44, Blocks.log2, 9, 2);
        world.setBlock(i + 2, j + 5, k + 44, Blocks.log2, 5, 2);
        world.setBlock(i + 10, j + 5, k + 44, Blocks.planks, 5, 2);
        world.setBlock(i + 26, j + 5, k + 44, Blocks.planks, 5, 2);
        world.setBlock(i + 27, j + 5, k + 44, Blocks.cobblestone, 0, 2);
        world.setBlock(i + 34, j + 5, k + 44, Blocks.cobblestone, 0, 2);
        world.setBlock(i + 35, j + 5, k + 44, Blocks.cobblestone_wall, 0, 2);
        world.setBlock(i + 1, j + 5, k + 45, Blocks.log2, 9, 2);
        world.setBlock(i + 2, j + 5, k + 45, Blocks.log2, 5, 2);
        world.setBlock(i + 10, j + 5, k + 45, Blocks.planks, 5, 2);
        world.setBlock(i + 26, j + 5, k + 45, Blocks.log2, 5, 2);
        world.setBlock(i + 27, j + 5, k + 45, Blocks.planks, 5, 2);
        world.setBlock(i + 28, j + 5, k + 45, Blocks.planks, 5, 2);
        world.setBlock(i + 29, j + 5, k + 45, Blocks.planks, 5, 2);
        world.setBlock(i + 30, j + 5, k + 45, Blocks.planks, 5, 2);
        world.setBlock(i + 31, j + 5, k + 45, Blocks.planks, 5, 2);
        world.setBlock(i + 32, j + 5, k + 45, Blocks.planks, 5, 2);
        world.setBlock(i + 33, j + 5, k + 45, Blocks.planks, 5, 2);
        world.setBlock(i + 34, j + 5, k + 45, Blocks.planks, 5, 2);
        world.setBlock(i + 35, j + 5, k + 45, Blocks.cobblestone, 0, 2);
        world.setBlock(i + 1, j + 5, k + 46, Blocks.log2, 9, 2);
        world.setBlock(i + 2, j + 5, k + 46, Blocks.log2, 5, 2);
        world.setBlock(i + 10, j + 5, k + 46, Blocks.log2, 5, 2);
        world.setBlock(i + 26, j + 5, k + 46, Blocks.planks, 5, 2);
        world.setBlock(i + 31, j + 5, k + 46, Blocks.planks, 5, 2);
        world.setBlock(i + 34, j + 5, k + 46, Blocks.planks, 5, 2);
        world.setBlock(i + 1, j + 5, k + 47, Blocks.log2, 9, 2);
        world.setBlock(i + 2, j + 5, k + 47, Blocks.log2, 5, 2);
        world.setBlock(i + 10, j + 5, k + 47, Blocks.planks, 5, 2);
        world.setBlock(i + 26, j + 5, k + 47, Blocks.planks, 5, 2);
        world.setBlock(i + 31, j + 5, k + 47, Blocks.planks, 5, 2);
        world.setBlock(i + 34, j + 5, k + 47, Blocks.planks, 5, 2);
        world.setBlock(i + 1, j + 5, k + 48, Blocks.log2, 9, 2);
        world.setBlock(i + 2, j + 5, k + 48, Blocks.log2, 5, 2);
        world.setBlock(i + 10, j + 5, k + 48, Blocks.planks, 5, 2);
        world.setBlock(i + 25, j + 5, k + 48, Blocks.torch, 5, 2);
        world.setBlock(i + 26, j + 5, k + 48, Blocks.planks, 5, 2);
        world.setBlock(i + 31, j + 5, k + 48, Blocks.log2, 1, 2);
        world.setBlock(i + 32, j + 5, k + 48, Blocks.log2, 1, 2);
        world.setBlock(i + 34, j + 5, k + 48, Blocks.planks, 5, 2);
        world.setBlock(i + 2, j + 5, k + 49, Blocks.planks, 5, 2);
        world.setBlock(i + 10, j + 5, k + 49, Blocks.planks, 5, 2);
        world.setBlock(i + 18, j + 5, k + 49, Blocks.torch, 5, 2);
        world.setBlock(i + 26, j + 5, k + 49, Blocks.planks, 5, 2);
        world.setBlock(i + 30, j + 5, k + 49, Blocks.planks, 5, 2);
        world.setBlock(i + 34, j + 5, k + 49, Blocks.planks, 5, 2);
        world.setBlock(i + 2, j + 5, k + 50, Blocks.planks, 5, 2);
        world.setBlock(i + 3, j + 5, k + 50, Blocks.planks, 5, 2);
        world.setBlock(i + 9, j + 5, k + 50, Blocks.planks, 5, 2);
        world.setBlock(i + 10, j + 5, k + 50, Blocks.planks, 5, 2);
        world.setBlock(i + 11, j + 5, k + 50, Blocks.planks, 5, 2);
        world.setBlock(i + 12, j + 5, k + 50, Blocks.planks, 5, 2);
        world.setBlock(i + 13, j + 5, k + 50, Blocks.planks, 5, 2);
        world.setBlock(i + 14, j + 5, k + 50, Blocks.log2, 9, 2);
        world.setBlock(i + 15, j + 5, k + 50, Blocks.planks, 5, 2);
        world.setBlock(i + 16, j + 5, k + 50, Blocks.planks, 5, 2);
        world.setBlock(i + 17, j + 5, k + 50, Blocks.planks, 5, 2);
        world.setBlock(i + 18, j + 5, k + 50, Blocks.planks, 5, 2);
        world.setBlock(i + 19, j + 5, k + 50, Blocks.planks, 5, 2);
        world.setBlock(i + 20, j + 5, k + 50, Blocks.planks, 5, 2);
        world.setBlock(i + 21, j + 5, k + 50, Blocks.planks, 5, 2);
        world.setBlock(i + 22, j + 5, k + 50, Blocks.log2, 9, 2);
        world.setBlock(i + 23, j + 5, k + 50, Blocks.planks, 5, 2);
        world.setBlock(i + 24, j + 5, k + 50, Blocks.planks, 5, 2);
        world.setBlock(i + 25, j + 5, k + 50, Blocks.planks, 5, 2);
        world.setBlock(i + 26, j + 5, k + 50, Blocks.planks, 5, 2);
        world.setBlock(i + 27, j + 5, k + 50, Blocks.planks, 5, 2);
        world.setBlock(i + 28, j + 5, k + 50, Blocks.planks, 5, 2);
        world.setBlock(i + 29, j + 5, k + 50, Blocks.planks, 5, 2);
        world.setBlock(i + 30, j + 5, k + 50, Blocks.planks, 5, 2);
        world.setBlock(i + 31, j + 5, k + 50, Blocks.planks, 5, 2);
        world.setBlock(i + 32, j + 5, k + 50, Blocks.planks, 5, 2);
        world.setBlock(i + 33, j + 5, k + 50, Blocks.planks, 5, 2);
        world.setBlock(i + 34, j + 5, k + 50, Blocks.planks, 5, 2);
        world.setBlock(i + 2, j + 5, k + 51, Blocks.planks, 5, 2);
        world.setBlock(i + 10, j + 5, k + 51, Blocks.planks, 5, 2);
        world.setBlock(i + 18, j + 5, k + 51, Blocks.planks, 5, 2);
        world.setBlock(i + 26, j + 5, k + 51, Blocks.planks, 5, 2);
        world.setBlock(i + 33, j + 5, k + 51, Blocks.planks, 2, 2);
        world.setBlock(i + 34, j + 5, k + 51, Blocks.planks, 5, 2);
        world.setBlock(i + 1, j + 5, k + 52, Blocks.log2, 9, 2);
        world.setBlock(i + 2, j + 5, k + 52, Blocks.log2, 5, 2);
        world.setBlock(i + 26, j + 5, k + 52, Blocks.planks, 5, 2);
        world.setBlock(i + 33, j + 5, k + 52, Blocks.wooden_slab, 10, 2);
        world.setBlock(i + 34, j + 5, k + 52, Blocks.log2, 5, 2);
        world.setBlock(i + 35, j + 5, k + 52, Blocks.log2, 9, 2);
        world.setBlock(i + 1, j + 5, k + 53, Blocks.log2, 9, 2);
        world.setBlock(i + 2, j + 5, k + 53, Blocks.log2, 5, 2);
        world.setBlock(i + 26, j + 5, k + 53, Blocks.planks, 5, 2);
        world.setBlock(i + 34, j + 5, k + 53, Blocks.log2, 5, 2);
        world.setBlock(i + 35, j + 5, k + 53, Blocks.log2, 9, 2);
        world.setBlock(i + 1, j + 5, k + 54, Blocks.log2, 9, 2);
        world.setBlock(i + 2, j + 5, k + 54, Blocks.log2, 5, 2);
        world.setBlock(i + 26, j + 5, k + 54, Blocks.planks, 5, 2);
        world.setBlock(i + 34, j + 5, k + 54, Blocks.log2, 5, 2);
        world.setBlock(i + 35, j + 5, k + 54, Blocks.log2, 9, 2);
        world.setBlock(i + 1, j + 5, k + 55, Blocks.log2, 9, 2);
        world.setBlock(i + 2, j + 5, k + 55, Blocks.log2, 5, 2);
        world.setBlock(i + 26, j + 5, k + 55, Blocks.planks, 5, 2);
        world.setBlock(i + 34, j + 5, k + 55, Blocks.log2, 5, 2);
        world.setBlock(i + 35, j + 5, k + 55, Blocks.log2, 9, 2);
        world.setBlock(i + 1, j + 5, k + 56, Blocks.log2, 9, 2);
        world.setBlock(i + 2, j + 5, k + 56, Blocks.log2, 5, 2);
        world.setBlock(i + 26, j + 5, k + 56, Blocks.planks, 5, 2);
        world.setBlock(i + 33, j + 5, k + 56, Blocks.wooden_slab, 10, 2);
        world.setBlock(i + 34, j + 5, k + 56, Blocks.log2, 5, 2);
        world.setBlock(i + 35, j + 5, k + 56, Blocks.log2, 9, 2);
        world.setBlock(i + 2, j + 5, k + 57, Blocks.planks, 5, 2);
        world.setBlock(i + 10, j + 5, k + 57, Blocks.planks, 5, 2);
        world.setBlock(i + 18, j + 5, k + 57, Blocks.planks, 5, 2);
        world.setBlock(i + 26, j + 5, k + 57, Blocks.planks, 5, 2);
        world.setBlock(i + 33, j + 5, k + 57, Blocks.planks, 2, 2);
        world.setBlock(i + 34, j + 5, k + 57, Blocks.planks, 5, 2);
        world.setBlock(i + 2, j + 5, k + 58, Blocks.planks, 5, 2);
        world.setBlock(i + 3, j + 5, k + 58, Blocks.planks, 5, 2);
        world.setBlock(i + 4, j + 5, k + 58, Blocks.planks, 5, 2);
        world.setBlock(i + 5, j + 5, k + 58, Blocks.planks, 5, 2);
        world.setBlock(i + 6, j + 5, k + 58, Blocks.planks, 5, 2);
        world.setBlock(i + 7, j + 5, k + 58, Blocks.planks, 5, 2);
        world.setBlock(i + 8, j + 5, k + 58, Blocks.planks, 5, 2);
        world.setBlock(i + 9, j + 5, k + 58, Blocks.planks, 5, 2);
        world.setBlock(i + 10, j + 5, k + 58, Blocks.planks, 5, 2);
        world.setBlock(i + 11, j + 5, k + 58, Blocks.planks, 5, 2);
        world.setBlock(i + 12, j + 5, k + 58, Blocks.planks, 5, 2);
        world.setBlock(i + 13, j + 5, k + 58, Blocks.planks, 5, 2);
        world.setBlock(i + 14, j + 5, k + 58, Blocks.log2, 9, 2);
        world.setBlock(i + 15, j + 5, k + 58, Blocks.planks, 5, 2);
        world.setBlock(i + 16, j + 5, k + 58, Blocks.planks, 5, 2);
        world.setBlock(i + 17, j + 5, k + 58, Blocks.planks, 5, 2);
        world.setBlock(i + 18, j + 5, k + 58, Blocks.planks, 5, 2);
        world.setBlock(i + 19, j + 5, k + 58, Blocks.planks, 5, 2);
        world.setBlock(i + 20, j + 5, k + 58, Blocks.planks, 5, 2);
        world.setBlock(i + 21, j + 5, k + 58, Blocks.planks, 5, 2);
        world.setBlock(i + 22, j + 5, k + 58, Blocks.planks, 5, 2);
        world.setBlock(i + 23, j + 5, k + 58, Blocks.planks, 5, 2);
        world.setBlock(i + 24, j + 5, k + 58, Blocks.planks, 5, 2);
        world.setBlock(i + 25, j + 5, k + 58, Blocks.planks, 5, 2);
        world.setBlock(i + 26, j + 5, k + 58, Blocks.planks, 5, 2);
        world.setBlock(i + 27, j + 5, k + 58, Blocks.planks, 5, 2);
        world.setBlock(i + 28, j + 5, k + 58, Blocks.log2, 9, 2);
        world.setBlock(i + 29, j + 5, k + 58, Blocks.log2, 9, 2);
        world.setBlock(i + 30, j + 5, k + 58, Blocks.log2, 9, 2);
        world.setBlock(i + 31, j + 5, k + 58, Blocks.log2, 9, 2);
        world.setBlock(i + 32, j + 5, k + 58, Blocks.log2, 9, 2);
        world.setBlock(i + 33, j + 5, k + 58, Blocks.planks, 5, 2);
        world.setBlock(i + 34, j + 5, k + 58, Blocks.cobblestone, 0, 2);
        world.setBlock(i + 35, j + 5, k + 58, Blocks.cobblestone, 0, 2);
        world.setBlock(i + 2, j + 5, k + 59, Blocks.planks, 5, 2);
        world.setBlock(i + 10, j + 5, k + 59, Blocks.planks, 5, 2);
        world.setBlock(i + 26, j + 5, k + 59, Blocks.planks, 5, 2);
        world.setBlock(i + 28, j + 5, k + 59, Blocks.log2, 5, 2);
        world.setBlock(i + 29, j + 5, k + 59, Blocks.log2, 5, 2);
        world.setBlock(i + 30, j + 5, k + 59, Blocks.log2, 5, 2);
        world.setBlock(i + 31, j + 5, k + 59, Blocks.log2, 5, 2);
        world.setBlock(i + 32, j + 5, k + 59, Blocks.log2, 5, 2);
        world.setBlock(i + 34, j + 5, k + 59, Blocks.cobblestone, 0, 2);
        world.setBlock(i + 35, j + 5, k + 59, Blocks.cobblestone_wall, 0, 2);
        world.setBlock(i + 1, j + 5, k + 60, Blocks.log2, 9, 2);
        world.setBlock(i + 2, j + 5, k + 60, Blocks.log2, 5, 2);
        world.setBlock(i + 10, j + 5, k + 60, Blocks.planks, 5, 2);
        world.setBlock(i + 26, j + 5, k + 60, Blocks.log2, 5, 2);
        world.setBlock(i + 27, j + 5, k + 60, Blocks.log2, 9, 2);
        world.setBlock(i + 1, j + 5, k + 61, Blocks.log2, 9, 2);
        world.setBlock(i + 2, j + 5, k + 61, Blocks.log2, 5, 2);
        world.setBlock(i + 10, j + 5, k + 61, Blocks.planks, 5, 2);
        world.setBlock(i + 26, j + 5, k + 61, Blocks.log2, 5, 2);
        world.setBlock(i + 27, j + 5, k + 61, Blocks.log2, 9, 2);
        world.setBlock(i + 1, j + 5, k + 62, Blocks.log2, 9, 2);
        world.setBlock(i + 2, j + 5, k + 62, Blocks.log2, 5, 2);
        world.setBlock(i + 10, j + 5, k + 62, Blocks.log2, 5, 2);
        world.setBlock(i + 26, j + 5, k + 62, Blocks.log2, 5, 2);
        world.setBlock(i + 27, j + 5, k + 62, Blocks.log2, 9, 2);
        world.setBlock(i + 1, j + 5, k + 63, Blocks.log2, 9, 2);
        world.setBlock(i + 2, j + 5, k + 63, Blocks.log2, 5, 2);
        world.setBlock(i + 10, j + 5, k + 63, Blocks.planks, 5, 2);
        world.setBlock(i + 26, j + 5, k + 63, Blocks.log2, 5, 2);
        world.setBlock(i + 27, j + 5, k + 63, Blocks.log2, 9, 2);
        world.setBlock(i + 1, j + 5, k + 64, Blocks.log2, 9, 2);
        world.setBlock(i + 2, j + 5, k + 64, Blocks.log2, 5, 2);
        world.setBlock(i + 10, j + 5, k + 64, Blocks.planks, 5, 2);
        world.setBlock(i + 26, j + 5, k + 64, Blocks.log2, 5, 2);
        world.setBlock(i + 27, j + 5, k + 64, Blocks.log2, 9, 2);
        world.setBlock(i + 2, j + 5, k + 65, Blocks.planks, 5, 2);
        world.setBlock(i + 10, j + 5, k + 65, Blocks.planks, 5, 2);
        world.setBlock(i + 26, j + 5, k + 65, Blocks.planks, 5, 2);
        world.setBlock(i + 2, j + 5, k + 66, Blocks.planks, 5, 2);
        world.setBlock(i + 10, j + 5, k + 66, Blocks.planks, 5, 2);
        world.setBlock(i + 26, j + 5, k + 66, Blocks.planks, 5, 2);
        world.setBlock(i + 2, j + 5, k + 67, Blocks.planks, 5, 2);
        world.setBlock(i + 10, j + 5, k + 67, Blocks.planks, 5, 2);
        world.setBlock(i + 26, j + 5, k + 67, Blocks.planks, 5, 2);
        world.setBlock(i + 1, j + 5, k + 68, Blocks.log2, 9, 2);
        world.setBlock(i + 2, j + 5, k + 68, Blocks.log2, 5, 2);
        world.setBlock(i + 10, j + 5, k + 68, Blocks.planks, 5, 2);
        world.setBlock(i + 26, j + 5, k + 68, Blocks.log2, 5, 2);
        world.setBlock(i + 27, j + 5, k + 68, Blocks.log2, 9, 2);
        world.setBlock(i + 1, j + 5, k + 69, Blocks.log2, 9, 2);
        world.setBlock(i + 2, j + 5, k + 69, Blocks.log2, 5, 2);
        world.setBlock(i + 10, j + 5, k + 69, Blocks.planks, 5, 2);
        world.setBlock(i + 26, j + 5, k + 69, Blocks.log2, 5, 2);
        world.setBlock(i + 27, j + 5, k + 69, Blocks.log2, 9, 2);
        world.setBlock(i + 1, j + 5, k + 70, Blocks.log2, 9, 2);
        world.setBlock(i + 2, j + 5, k + 70, Blocks.log2, 5, 2);
        world.setBlock(i + 10, j + 5, k + 70, Blocks.log2, 5, 2);
        world.setBlock(i + 26, j + 5, k + 70, Blocks.log2, 5, 2);
        world.setBlock(i + 27, j + 5, k + 70, Blocks.log2, 9, 2);
        world.setBlock(i + 1, j + 5, k + 71, Blocks.log2, 9, 2);
        world.setBlock(i + 2, j + 5, k + 71, Blocks.log2, 5, 2);
        world.setBlock(i + 10, j + 5, k + 71, Blocks.planks, 5, 2);
        world.setBlock(i + 26, j + 5, k + 71, Blocks.log2, 5, 2);
        world.setBlock(i + 27, j + 5, k + 71, Blocks.log2, 9, 2);
        world.setBlock(i + 1, j + 5, k + 72, Blocks.log2, 9, 2);
        world.setBlock(i + 2, j + 5, k + 72, Blocks.log2, 5, 2);
        world.setBlock(i + 10, j + 5, k + 72, Blocks.planks, 5, 2);
        world.setBlock(i + 26, j + 5, k + 72, Blocks.log2, 5, 2);
        world.setBlock(i + 27, j + 5, k + 72, Blocks.log2, 9, 2);
        world.setBlock(i + 2, j + 5, k + 73, Blocks.planks, 5, 2);
        world.setBlock(i + 5, j + 5, k + 73, Blocks.stone_stairs, 4, 2);
        world.setBlock(i + 6, j + 5, k + 73, Blocks.cobblestone, 0, 2);
        world.setBlock(i + 7, j + 5, k + 73, Blocks.stone_stairs, 5, 2);
        world.setBlock(i + 10, j + 5, k + 73, Blocks.planks, 5, 2);
        world.setBlock(i + 26, j + 5, k + 73, Blocks.planks, 5, 2);
        world.setBlock(i + 1, j + 5, k + 74, Blocks.cobblestone, 0, 2);
        world.setBlock(i + 2, j + 5, k + 74, Blocks.cobblestone, 0, 2);
        world.setBlock(i + 3, j + 5, k + 74, Blocks.planks, 5, 2);
        world.setBlock(i + 4, j + 5, k + 74, Blocks.log2, 9, 2);
        world.setBlock(i + 5, j + 5, k + 74, Blocks.log2, 9, 2);
        world.setBlock(i + 6, j + 5, k + 74, Blocks.log2, 9, 2);
        world.setBlock(i + 7, j + 5, k + 74, Blocks.log2, 9, 2);
        world.setBlock(i + 8, j + 5, k + 74, Blocks.log2, 9, 2);
        world.setBlock(i + 9, j + 5, k + 74, Blocks.planks, 5, 2);
        world.setBlock(i + 10, j + 5, k + 74, Blocks.planks, 5, 2);
        world.setBlock(i + 11, j + 5, k + 74, Blocks.planks, 5, 2);
        world.setBlock(i + 12, j + 5, k + 74, Blocks.log2, 9, 2);
        world.setBlock(i + 13, j + 5, k + 74, Blocks.log2, 9, 2);
        world.setBlock(i + 14, j + 5, k + 74, Blocks.log2, 9, 2);
        world.setBlock(i + 15, j + 5, k + 74, Blocks.log2, 9, 2);
        world.setBlock(i + 16, j + 5, k + 74, Blocks.log2, 9, 2);
        world.setBlock(i + 17, j + 5, k + 74, Blocks.planks, 5, 2);
        world.setBlock(i + 18, j + 5, k + 74, Blocks.planks, 5, 2);
        world.setBlock(i + 19, j + 5, k + 74, Blocks.planks, 5, 2);
        world.setBlock(i + 20, j + 5, k + 74, Blocks.log2, 9, 2);
        world.setBlock(i + 21, j + 5, k + 74, Blocks.log2, 9, 2);
        world.setBlock(i + 22, j + 5, k + 74, Blocks.log2, 9, 2);
        world.setBlock(i + 23, j + 5, k + 74, Blocks.log2, 9, 2);
        world.setBlock(i + 24, j + 5, k + 74, Blocks.log2, 9, 2);
        world.setBlock(i + 25, j + 5, k + 74, Blocks.planks, 5, 2);
        world.setBlock(i + 26, j + 5, k + 74, Blocks.cobblestone, 0, 2);
        world.setBlock(i + 27, j + 5, k + 74, Blocks.cobblestone, 0, 2);
        world.setBlock(i + 1, j + 5, k + 75, Blocks.cobblestone_wall, 0, 2);
        world.setBlock(i + 2, j + 5, k + 75, Blocks.cobblestone, 0, 2);
        world.setBlock(i + 4, j + 5, k + 75, Blocks.log2, 5, 2);
        world.setBlock(i + 5, j + 5, k + 75, Blocks.log2, 5, 2);
        world.setBlock(i + 6, j + 5, k + 75, Blocks.log2, 5, 2);
        world.setBlock(i + 7, j + 5, k + 75, Blocks.log2, 5, 2);
        world.setBlock(i + 8, j + 5, k + 75, Blocks.log2, 5, 2);
        world.setBlock(i + 12, j + 5, k + 75, Blocks.log2, 5, 2);
        world.setBlock(i + 13, j + 5, k + 75, Blocks.log2, 5, 2);
        world.setBlock(i + 14, j + 5, k + 75, Blocks.log2, 5, 2);
        world.setBlock(i + 15, j + 5, k + 75, Blocks.log2, 5, 2);
        world.setBlock(i + 16, j + 5, k + 75, Blocks.log2, 5, 2);
        world.setBlock(i + 20, j + 5, k + 75, Blocks.log2, 5, 2);
        world.setBlock(i + 21, j + 5, k + 75, Blocks.log2, 5, 2);
        world.setBlock(i + 22, j + 5, k + 75, Blocks.log2, 5, 2);
        world.setBlock(i + 23, j + 5, k + 75, Blocks.log2, 5, 2);
        world.setBlock(i + 24, j + 5, k + 75, Blocks.log2, 5, 2);
        world.setBlock(i + 26, j + 5, k + 75, Blocks.cobblestone, 0, 2);
        world.setBlock(i + 27, j + 5, k + 75, Blocks.cobblestone_wall, 0, 2);
        world.setBlock(i + 1, j + 6, k + 1, Blocks.cobblestone_wall, 0, 2);
        world.setBlock(i + 2, j + 6, k + 1, Blocks.cobblestone, 0, 2);
        world.setBlock(i + 3, j + 6, k + 1, Blocks.stone_stairs, 6, 2);
        world.setBlock(i + 4, j + 6, k + 1, Blocks.stone_stairs, 5, 2);
        world.setBlock(i + 8, j + 6, k + 1, Blocks.stone_stairs, 4, 2);
        world.setBlock(i + 9, j + 6, k + 1, Blocks.stone_stairs, 6, 2);
        world.setBlock(i + 10, j + 6, k + 1, Blocks.stone_stairs, 6, 2);
        world.setBlock(i + 11, j + 6, k + 1, Blocks.stone_stairs, 6, 2);
        world.setBlock(i + 12, j + 6, k + 1, Blocks.stone_stairs, 5, 2);
        world.setBlock(i + 16, j + 6, k + 1, Blocks.stone_stairs, 4, 2);
        world.setBlock(i + 17, j + 6, k + 1, Blocks.stone_stairs, 6, 2);
        world.setBlock(i + 18, j + 6, k + 1, Blocks.cobblestone, 0, 2);
        world.setBlock(i + 19, j + 6, k + 1, Blocks.cobblestone_wall, 0, 2);
        world.setBlock(i + 1, j + 6, k + 2, Blocks.cobblestone, 0, 2);
        world.setBlock(i + 2, j + 6, k + 2, Blocks.cobblestone, 0, 2);
        world.setBlock(i + 3, j + 6, k + 2, Blocks.planks, 5, 2);
        world.setBlock(i + 4, j + 6, k + 2, Blocks.planks, 5, 2);
        world.setBlock(i + 5, j + 6, k + 2, Blocks.planks, 5, 2);
        world.setBlock(i + 6, j + 6, k + 2, Blocks.planks, 5, 2);
        world.setBlock(i + 7, j + 6, k + 2, Blocks.planks, 5, 2);
        world.setBlock(i + 8, j + 6, k + 2, Blocks.planks, 5, 2);
        world.setBlock(i + 9, j + 6, k + 2, Blocks.planks, 5, 2);
        world.setBlock(i + 10, j + 6, k + 2, Blocks.planks, 5, 2);
        world.setBlock(i + 11, j + 6, k + 2, Blocks.planks, 5, 2);
        world.setBlock(i + 12, j + 6, k + 2, Blocks.planks, 5, 2);
        world.setBlock(i + 13, j + 6, k + 2, Blocks.planks, 5, 2);
        world.setBlock(i + 14, j + 6, k + 2, Blocks.planks, 5, 2);
        world.setBlock(i + 15, j + 6, k + 2, Blocks.planks, 5, 2);
        world.setBlock(i + 16, j + 6, k + 2, Blocks.planks, 5, 2);
        world.setBlock(i + 17, j + 6, k + 2, Blocks.planks, 5, 2);
        world.setBlock(i + 18, j + 6, k + 2, Blocks.cobblestone, 0, 2);
        world.setBlock(i + 19, j + 6, k + 2, Blocks.cobblestone, 0, 2);
        world.setBlock(i + 1, j + 6, k + 3, Blocks.stone_stairs, 4, 2);
        world.setBlock(i + 2, j + 6, k + 3, Blocks.planks, 5, 2);
        world.setBlock(i + 18, j + 6, k + 3, Blocks.planks, 5, 2);
        world.setBlock(i + 19, j + 6, k + 3, Blocks.stone_stairs, 5, 2);
        world.setBlock(i + 1, j + 6, k + 4, Blocks.stone_stairs, 7, 2);
        world.setBlock(i + 2, j + 6, k + 4, Blocks.planks, 5, 2);
        world.setBlock(i + 18, j + 6, k + 4, Blocks.planks, 5, 2);
        world.setBlock(i + 19, j + 6, k + 4, Blocks.stone_stairs, 7, 2);
        world.setBlock(i + 2, j + 6, k + 5, Blocks.planks, 5, 2);
        world.setBlock(i + 10, j + 6, k + 5, Blocks.fence, 0, 2);
        world.setBlock(i + 18, j + 6, k + 5, Blocks.planks, 5, 2);
        world.setBlock(i + 2, j + 6, k + 6, Blocks.planks, 5, 2);
        world.setBlock(i + 9, j + 6, k + 6, Blocks.fence, 0, 2);
        world.setBlock(i + 10, j + 6, k + 6, Blocks.fence, 0, 2);
        world.setBlock(i + 11, j + 6, k + 6, Blocks.fence, 0, 2);
        world.setBlock(i + 18, j + 6, k + 6, Blocks.planks, 5, 2);
        world.setBlock(i + 2, j + 6, k + 7, Blocks.planks, 5, 2);
        world.setBlock(i + 10, j + 6, k + 7, Blocks.fence, 0, 2);
        world.setBlock(i + 18, j + 6, k + 7, Blocks.planks, 5, 2);
        world.setBlock(i + 1, j + 6, k + 8, Blocks.stone_stairs, 6, 2);
        world.setBlock(i + 2, j + 6, k + 8, Blocks.planks, 5, 2);
        world.setBlock(i + 18, j + 6, k + 8, Blocks.planks, 5, 2);
        world.setBlock(i + 19, j + 6, k + 8, Blocks.stone_stairs, 6, 2);
        world.setBlock(i + 1, j + 6, k + 9, Blocks.stone_stairs, 4, 2);
        world.setBlock(i + 2, j + 6, k + 9, Blocks.planks, 5, 2);
        world.setBlock(i + 18, j + 6, k + 9, Blocks.planks, 5, 2);
        world.setBlock(i + 19, j + 6, k + 9, Blocks.stone_stairs, 5, 2);
        world.setBlock(i + 1, j + 6, k + 10, Blocks.stone_stairs, 4, 2);
        world.setBlock(i + 2, j + 6, k + 10, Blocks.planks, 5, 2);
        world.setBlock(i + 18, j + 6, k + 10, Blocks.planks, 5, 2);
        world.setBlock(i + 19, j + 6, k + 10, Blocks.stone_stairs, 5, 2);
        world.setBlock(i + 1, j + 6, k + 11, Blocks.stone_stairs, 4, 2);
        world.setBlock(i + 2, j + 6, k + 11, Blocks.planks, 5, 2);
        world.setBlock(i + 18, j + 6, k + 11, Blocks.planks, 5, 2);
        world.setBlock(i + 19, j + 6, k + 11, Blocks.stone_stairs, 5, 2);
        world.setBlock(i + 1, j + 6, k + 12, Blocks.stone_stairs, 7, 2);
        world.setBlock(i + 2, j + 6, k + 12, Blocks.planks, 5, 2);
        world.setBlock(i + 18, j + 6, k + 12, Blocks.planks, 5, 2);
        world.setBlock(i + 19, j + 6, k + 12, Blocks.stone_stairs, 7, 2);
        world.setBlock(i + 2, j + 6, k + 13, Blocks.planks, 5, 2);
        world.setBlock(i + 10, j + 6, k + 13, Blocks.fence, 0, 2);
        world.setBlock(i + 18, j + 6, k + 13, Blocks.planks, 5, 2);
        world.setBlock(i + 2, j + 6, k + 14, Blocks.planks, 5, 2);
        world.setBlock(i + 9, j + 6, k + 14, Blocks.fence, 0, 2);
        world.setBlock(i + 10, j + 6, k + 14, Blocks.fence, 0, 2);
        world.setBlock(i + 11, j + 6, k + 14, Blocks.fence, 0, 2);
        world.setBlock(i + 18, j + 6, k + 14, Blocks.planks, 5, 2);
        world.setBlock(i + 2, j + 6, k + 15, Blocks.planks, 5, 2);
        world.setBlock(i + 10, j + 6, k + 15, Blocks.fence, 0, 2);
        world.setBlock(i + 18, j + 6, k + 15, Blocks.planks, 5, 2);
        world.setBlock(i + 1, j + 6, k + 16, Blocks.stone_stairs, 6, 2);
        world.setBlock(i + 2, j + 6, k + 16, Blocks.planks, 5, 2);
        world.setBlock(i + 18, j + 6, k + 16, Blocks.planks, 5, 2);
        world.setBlock(i + 19, j + 6, k + 16, Blocks.stone_stairs, 6, 2);
        world.setBlock(i + 1, j + 6, k + 17, Blocks.stone_stairs, 4, 2);
        world.setBlock(i + 2, j + 6, k + 17, Blocks.planks, 5, 2);
        world.setBlock(i + 18, j + 6, k + 17, Blocks.planks, 5, 2);
        world.setBlock(i + 19, j + 6, k + 17, Blocks.stone_stairs, 6, 2);
        world.setBlock(i + 20, j + 6, k + 17, Blocks.stone_stairs, 5, 2);
        world.setBlock(i + 24, j + 6, k + 17, Blocks.stone_stairs, 4, 2);
        world.setBlock(i + 25, j + 6, k + 17, Blocks.stone_stairs, 6, 2);
        world.setBlock(i + 26, j + 6, k + 17, Blocks.cobblestone, 0, 2);
        world.setBlock(i + 27, j + 6, k + 17, Blocks.cobblestone_wall, 0, 2);
        world.setBlock(i + 1, j + 6, k + 18, Blocks.stone_stairs, 4, 2);
        world.setBlock(i + 2, j + 6, k + 18, Blocks.planks, 5, 2);
        world.setBlock(i + 3, j + 6, k + 18, Blocks.planks, 5, 2);
        world.setBlock(i + 4, j + 6, k + 18, Blocks.planks, 5, 2);
        world.setBlock(i + 5, j + 6, k + 18, Blocks.planks, 5, 2);
        world.setBlock(i + 6, j + 6, k + 18, Blocks.planks, 5, 2);
        world.setBlock(i + 7, j + 6, k + 18, Blocks.planks, 5, 2);
        world.setBlock(i + 8, j + 6, k + 18, Blocks.planks, 5, 2);
        world.setBlock(i + 9, j + 6, k + 18, Blocks.planks, 5, 2);
        world.setBlock(i + 10, j + 6, k + 18, Blocks.planks, 5, 2);
        world.setBlock(i + 11, j + 6, k + 18, Blocks.planks, 5, 2);
        world.setBlock(i + 12, j + 6, k + 18, Blocks.planks, 5, 2);
        world.setBlock(i + 13, j + 6, k + 18, Blocks.planks, 5, 2);
        world.setBlock(i + 14, j + 6, k + 18, Blocks.planks, 5, 2);
        world.setBlock(i + 15, j + 6, k + 18, Blocks.planks, 5, 2);
        world.setBlock(i + 16, j + 6, k + 18, Blocks.planks, 5, 2);
        world.setBlock(i + 17, j + 6, k + 18, Blocks.planks, 5, 2);
        world.setBlock(i + 18, j + 6, k + 18, Blocks.planks, 5, 2);
        world.setBlock(i + 19, j + 6, k + 18, Blocks.planks, 5, 2);
        world.setBlock(i + 20, j + 6, k + 18, Blocks.planks, 5, 2);
        world.setBlock(i + 21, j + 6, k + 18, Blocks.planks, 5, 2);
        world.setBlock(i + 22, j + 6, k + 18, Blocks.planks, 5, 2);
        world.setBlock(i + 23, j + 6, k + 18, Blocks.planks, 5, 2);
        world.setBlock(i + 24, j + 6, k + 18, Blocks.planks, 5, 2);
        world.setBlock(i + 25, j + 6, k + 18, Blocks.planks, 5, 2);
        world.setBlock(i + 26, j + 6, k + 18, Blocks.cobblestone, 0, 2);
        world.setBlock(i + 27, j + 6, k + 18, Blocks.cobblestone, 0, 2);
        world.setBlock(i + 1, j + 6, k + 19, Blocks.stone_stairs, 4, 2);
        world.setBlock(i + 2, j + 6, k + 19, Blocks.planks, 5, 2);
        world.setBlock(i + 10, j + 6, k + 19, Blocks.planks, 5, 2);
        world.setBlock(i + 18, j + 6, k + 19, Blocks.planks, 5, 2);
        world.setBlock(i + 26, j + 6, k + 19, Blocks.planks, 5, 2);
        world.setBlock(i + 27, j + 6, k + 19, Blocks.stone_stairs, 5, 2);
        world.setBlock(i + 1, j + 6, k + 20, Blocks.stone_stairs, 7, 2);
        world.setBlock(i + 2, j + 6, k + 20, Blocks.planks, 5, 2);
        world.setBlock(i + 26, j + 6, k + 20, Blocks.planks, 5, 2);
        world.setBlock(i + 27, j + 6, k + 20, Blocks.stone_stairs, 7, 2);
        world.setBlock(i + 2, j + 6, k + 21, Blocks.planks, 5, 2);
        world.setBlock(i + 26, j + 6, k + 21, Blocks.planks, 5, 2);
        world.setBlock(i + 2, j + 6, k + 22, Blocks.planks, 5, 2);
        world.setBlock(i + 26, j + 6, k + 22, Blocks.planks, 5, 2);
        world.setBlock(i + 2, j + 6, k + 23, Blocks.planks, 5, 2);
        world.setBlock(i + 26, j + 6, k + 23, Blocks.planks, 5, 2);
        world.setBlock(i + 1, j + 6, k + 24, Blocks.stone_stairs, 6, 2);
        world.setBlock(i + 2, j + 6, k + 24, Blocks.planks, 5, 2);
        world.setBlock(i + 26, j + 6, k + 24, Blocks.planks, 5, 2);
        world.setBlock(i + 27, j + 6, k + 24, Blocks.stone_stairs, 6, 2);
        world.setBlock(i + 1, j + 6, k + 25, Blocks.stone_stairs, 4, 2);
        world.setBlock(i + 2, j + 6, k + 25, Blocks.planks, 5, 2);
        world.setBlock(i + 10, j + 6, k + 25, Blocks.planks, 5, 2);
        world.setBlock(i + 18, j + 6, k + 25, Blocks.planks, 5, 2);
        world.setBlock(i + 26, j + 6, k + 25, Blocks.planks, 5, 2);
        world.setBlock(i + 27, j + 6, k + 25, Blocks.stone_stairs, 5, 2);
        world.setBlock(i + 1, j + 6, k + 26, Blocks.stone_stairs, 4, 2);
        world.setBlock(i + 2, j + 6, k + 26, Blocks.planks, 5, 2);
        world.setBlock(i + 3, j + 6, k + 26, Blocks.planks, 5, 2);
        world.setBlock(i + 9, j + 6, k + 26, Blocks.planks, 5, 2);
        world.setBlock(i + 10, j + 6, k + 26, Blocks.planks, 5, 2);
        world.setBlock(i + 11, j + 6, k + 26, Blocks.planks, 5, 2);
        world.setBlock(i + 12, j + 6, k + 26, Blocks.planks, 5, 2);
        world.setBlock(i + 13, j + 6, k + 26, Blocks.planks, 5, 2);
        world.setBlock(i + 14, j + 6, k + 26, Blocks.planks, 5, 2);
        world.setBlock(i + 15, j + 6, k + 26, Blocks.planks, 5, 2);
        world.setBlock(i + 16, j + 6, k + 26, Blocks.planks, 5, 2);
        world.setBlock(i + 17, j + 6, k + 26, Blocks.planks, 5, 2);
        world.setBlock(i + 18, j + 6, k + 26, Blocks.planks, 5, 2);
        world.setBlock(i + 26, j + 6, k + 26, Blocks.planks, 5, 2);
        world.setBlock(i + 27, j + 6, k + 26, Blocks.stone_stairs, 5, 2);
        world.setBlock(i + 1, j + 6, k + 27, Blocks.stone_stairs, 4, 2);
        world.setBlock(i + 2, j + 6, k + 27, Blocks.planks, 5, 2);
        world.setBlock(i + 10, j + 6, k + 27, Blocks.planks, 5, 2);
        world.setBlock(i + 18, j + 6, k + 27, Blocks.planks, 5, 2);
        world.setBlock(i + 26, j + 6, k + 27, Blocks.planks, 5, 2);
        world.setBlock(i + 27, j + 6, k + 27, Blocks.stone_stairs, 5, 2);
        world.setBlock(i + 1, j + 6, k + 28, Blocks.stone_stairs, 7, 2);
        world.setBlock(i + 2, j + 6, k + 28, Blocks.planks, 5, 2);
        world.setBlock(i + 10, j + 6, k + 28, Blocks.planks, 5, 2);
        world.setBlock(i + 18, j + 6, k + 28, Blocks.planks, 5, 2);
        world.setBlock(i + 26, j + 6, k + 28, Blocks.planks, 5, 2);
        world.setBlock(i + 27, j + 6, k + 28, Blocks.stone_stairs, 7, 2);
        world.setBlock(i + 2, j + 6, k + 29, Blocks.planks, 5, 2);
        world.setBlock(i + 10, j + 6, k + 29, Blocks.planks, 5, 2);
        world.setBlock(i + 18, j + 6, k + 29, Blocks.planks, 5, 2);
        world.setBlock(i + 26, j + 6, k + 29, Blocks.planks, 5, 2);
        world.setBlock(i + 2, j + 6, k + 30, Blocks.planks, 5, 2);
        world.setBlock(i + 10, j + 6, k + 30, Blocks.planks, 5, 2);
        world.setBlock(i + 11, j + 6, k + 30, Blocks.planks, 5, 2);
        world.setBlock(i + 12, j + 6, k + 30, PlaceDarkOakFence, 0, 2);
        world.setBlock(i + 16, j + 6, k + 30, PlaceDarkOakFence, 0, 2);
        world.setBlock(i + 17, j + 6, k + 30, Blocks.planks, 5, 2);
        world.setBlock(i + 18, j + 6, k + 30, Blocks.planks, 5, 2);
        world.setBlock(i + 26, j + 6, k + 30, Blocks.planks, 5, 2);
        world.setBlock(i + 2, j + 6, k + 31, Blocks.planks, 5, 2);
        world.setBlock(i + 10, j + 6, k + 31, Blocks.planks, 5, 2);
        world.setBlock(i + 18, j + 6, k + 31, Blocks.planks, 5, 2);
        world.setBlock(i + 26, j + 6, k + 31, Blocks.planks, 5, 2);
        world.setBlock(i + 1, j + 6, k + 32, Blocks.stone_stairs, 6, 2);
        world.setBlock(i + 2, j + 6, k + 32, Blocks.planks, 5, 2);
        world.setBlock(i + 10, j + 6, k + 32, Blocks.planks, 5, 2);
        world.setBlock(i + 18, j + 6, k + 32, Blocks.planks, 5, 2);
        world.setBlock(i + 26, j + 6, k + 32, Blocks.planks, 5, 2);
        world.setBlock(i + 27, j + 6, k + 32, Blocks.stone_stairs, 6, 2);
        world.setBlock(i + 1, j + 6, k + 33, Blocks.stone_stairs, 4, 2);
        world.setBlock(i + 2, j + 6, k + 33, Blocks.planks, 5, 2);
        world.setBlock(i + 10, j + 6, k + 33, Blocks.planks, 5, 2);
        world.setBlock(i + 18, j + 6, k + 33, Blocks.planks, 5, 2);
        world.setBlock(i + 19, j + 6, k + 33, Blocks.planks, 5, 2);
        world.setBlock(i + 20, j + 6, k + 33, Blocks.wool, 8, 2);
        world.setBlock(i + 21, j + 6, k + 33, Blocks.wool, 8, 2);
        world.setBlock(i + 22, j + 6, k + 33, Blocks.wool, 8, 2);
        world.setBlock(i + 23, j + 6, k + 33, Blocks.wool, 8, 2);
        world.setBlock(i + 24, j + 6, k + 33, Blocks.wool, 8, 2);
        world.setBlock(i + 25, j + 6, k + 33, Blocks.planks, 5, 2);
        world.setBlock(i + 26, j + 6, k + 33, Blocks.planks, 5, 2);
        world.setBlock(i + 27, j + 6, k + 33, Blocks.stone_stairs, 5, 2);
        world.setBlock(i + 1, j + 6, k + 34, Blocks.stone_stairs, 4, 2);
        world.setBlock(i + 2, j + 6, k + 34, Blocks.planks, 5, 2);
        world.setBlock(i + 3, j + 6, k + 34, Blocks.planks, 5, 2);
        world.setBlock(i + 9, j + 6, k + 34, Blocks.planks, 5, 2);
        world.setBlock(i + 10, j + 6, k + 34, Blocks.planks, 5, 2);
        world.setBlock(i + 11, j + 6, k + 34, Blocks.planks, 5, 2);
        world.setBlock(i + 12, j + 6, k + 34, Blocks.planks, 5, 2);
        world.setBlock(i + 13, j + 6, k + 34, Blocks.planks, 5, 2);
        world.setBlock(i + 14, j + 6, k + 34, Blocks.planks, 5, 2);
        world.setBlock(i + 15, j + 6, k + 34, Blocks.planks, 5, 2);
        world.setBlock(i + 16, j + 6, k + 34, Blocks.planks, 5, 2);
        world.setBlock(i + 17, j + 6, k + 34, Blocks.planks, 5, 2);
        world.setBlock(i + 18, j + 6, k + 34, Blocks.planks, 5, 2);
        world.setBlock(i + 19, j + 6, k + 34, Blocks.planks, 5, 2);
        world.setBlock(i + 20, j + 6, k + 34, Blocks.planks, 5, 2);
        world.setBlock(i + 21, j + 6, k + 34, Blocks.planks, 5, 2);
        world.setBlock(i + 22, j + 6, k + 34, Blocks.planks, 5, 2);
        world.setBlock(i + 23, j + 6, k + 34, Blocks.planks, 5, 2);
        world.setBlock(i + 24, j + 6, k + 34, Blocks.planks, 5, 2);
        world.setBlock(i + 25, j + 6, k + 34, Blocks.planks, 5, 2);
        world.setBlock(i + 26, j + 6, k + 34, Blocks.planks, 5, 2);
        world.setBlock(i + 27, j + 6, k + 34, Blocks.stone_stairs, 5, 2);
        world.setBlock(i + 1, j + 6, k + 35, Blocks.stone_stairs, 4, 2);
        world.setBlock(i + 2, j + 6, k + 35, Blocks.planks, 5, 2);
        world.setBlock(i + 10, j + 6, k + 35, Blocks.planks, 5, 2);
        world.setBlock(i + 26, j + 6, k + 35, Blocks.planks, 5, 2);
        world.setBlock(i + 27, j + 6, k + 35, Blocks.stone_stairs, 5, 2);
        world.setBlock(i + 1, j + 6, k + 36, Blocks.stone_stairs, 7, 2);
        world.setBlock(i + 2, j + 6, k + 36, Blocks.planks, 5, 2);
        world.setBlock(i + 10, j + 6, k + 36, Blocks.planks, 5, 2);
        world.setBlock(i + 26, j + 6, k + 36, Blocks.planks, 5, 2);
        world.setBlock(i + 27, j + 6, k + 36, Blocks.stone_stairs, 7, 2);
        world.setBlock(i + 2, j + 6, k + 37, Blocks.planks, 5, 2);
        world.setBlock(i + 10, j + 6, k + 37, Blocks.planks, 5, 2);
        world.setBlock(i + 26, j + 6, k + 37, Blocks.planks, 5, 2);
        world.setBlock(i + 2, j + 6, k + 38, Blocks.planks, 5, 2);
        world.setBlock(i + 10, j + 6, k + 38, Blocks.planks, 5, 2);
        world.setBlock(i + 26, j + 6, k + 38, Blocks.planks, 5, 2);
        world.setBlock(i + 2, j + 6, k + 39, Blocks.planks, 5, 2);
        world.setBlock(i + 10, j + 6, k + 39, Blocks.planks, 5, 2);
        world.setBlock(i + 26, j + 6, k + 39, Blocks.planks, 5, 2);
        world.setBlock(i + 1, j + 6, k + 40, Blocks.stone_stairs, 6, 2);
        world.setBlock(i + 2, j + 6, k + 40, Blocks.planks, 5, 2);
        world.setBlock(i + 10, j + 6, k + 40, Blocks.planks, 5, 2);
        world.setBlock(i + 26, j + 6, k + 40, Blocks.planks, 5, 2);
        world.setBlock(i + 27, j + 6, k + 40, Blocks.stone_stairs, 6, 2);
        world.setBlock(i + 1, j + 6, k + 41, Blocks.stone_stairs, 4, 2);
        world.setBlock(i + 2, j + 6, k + 41, Blocks.planks, 5, 2);
        world.setBlock(i + 10, j + 6, k + 41, Blocks.planks, 5, 2);
        world.setBlock(i + 18, j + 6, k + 41, Blocks.fence, 0, 2);
        world.setBlock(i + 26, j + 6, k + 41, Blocks.planks, 5, 2);
        world.setBlock(i + 27, j + 6, k + 41, Blocks.stone_stairs, 5, 2);
        world.setBlock(i + 1, j + 6, k + 42, Blocks.stone_stairs, 4, 2);
        world.setBlock(i + 2, j + 6, k + 42, Blocks.planks, 5, 2);
        world.setBlock(i + 3, j + 6, k + 42, Blocks.planks, 5, 2);
        world.setBlock(i + 9, j + 6, k + 42, Blocks.planks, 5, 2);
        world.setBlock(i + 10, j + 6, k + 42, Blocks.planks, 5, 2);
        world.setBlock(i + 17, j + 6, k + 42, Blocks.fence, 0, 2);
        world.setBlock(i + 18, j + 6, k + 42, Blocks.fence, 0, 2);
        world.setBlock(i + 19, j + 6, k + 42, Blocks.fence, 0, 2);
        world.setBlock(i + 26, j + 6, k + 42, Blocks.planks, 5, 2);
        world.setBlock(i + 27, j + 6, k + 42, Blocks.stone_stairs, 5, 2);
        world.setBlock(i + 1, j + 6, k + 43, Blocks.stone_stairs, 4, 2);
        world.setBlock(i + 2, j + 6, k + 43, Blocks.planks, 5, 2);
        world.setBlock(i + 10, j + 6, k + 43, Blocks.planks, 5, 2);
        world.setBlock(i + 18, j + 6, k + 43, Blocks.fence, 0, 2);
        world.setBlock(i + 26, j + 6, k + 43, Blocks.planks, 5, 2);
        world.setBlock(i + 27, j + 6, k + 43, Blocks.cobblestone, 0, 2);
        world.setBlock(i + 1, j + 6, k + 44, Blocks.stone_stairs, 7, 2);
        world.setBlock(i + 2, j + 6, k + 44, Blocks.planks, 5, 2);
        world.setBlock(i + 10, j + 6, k + 44, Blocks.planks, 5, 2);
        world.setBlock(i + 26, j + 6, k + 44, Blocks.planks, 5, 2);
        world.setBlock(i + 27, j + 6, k + 44, Blocks.cobblestone, 0, 2);
        world.setBlock(i + 28, j + 6, k + 44, Blocks.stone_stairs, 6, 2);
        world.setBlock(i + 29, j + 6, k + 44, Blocks.stone_stairs, 5, 2);
        world.setBlock(i + 32, j + 6, k + 44, Blocks.stone_stairs, 4, 2);
        world.setBlock(i + 33, j + 6, k + 44, Blocks.stone_stairs, 6, 2);
        world.setBlock(i + 34, j + 6, k + 44, Blocks.cobblestone, 0, 2);
        world.setBlock(i + 35, j + 6, k + 44, Blocks.cobblestone_wall, 0, 2);
        world.setBlock(i + 2, j + 6, k + 45, Blocks.planks, 5, 2);
        world.setBlock(i + 10, j + 6, k + 45, Blocks.planks, 5, 2);
        world.setBlock(i + 26, j + 6, k + 45, Blocks.planks, 5, 2);
        world.setBlock(i + 27, j + 6, k + 45, Blocks.planks, 5, 2);
        world.setBlock(i + 28, j + 6, k + 45, Blocks.planks, 5, 2);
        world.setBlock(i + 29, j + 6, k + 45, Blocks.planks, 5, 2);
        world.setBlock(i + 30, j + 6, k + 45, Blocks.planks, 5, 2);
        world.setBlock(i + 31, j + 6, k + 45, Blocks.planks, 5, 2);
        world.setBlock(i + 32, j + 6, k + 45, Blocks.planks, 5, 2);
        world.setBlock(i + 33, j + 6, k + 45, Blocks.planks, 5, 2);
        world.setBlock(i + 34, j + 6, k + 45, Blocks.planks, 5, 2);
        world.setBlock(i + 35, j + 6, k + 45, Blocks.cobblestone, 0, 2);
        world.setBlock(i + 2, j + 6, k + 46, Blocks.planks, 5, 2);
        world.setBlock(i + 10, j + 6, k + 46, Blocks.planks, 5, 2);
        world.setBlock(i + 26, j + 6, k + 46, Blocks.planks, 5, 2);
        world.setBlock(i + 31, j + 6, k + 46, Blocks.planks, 5, 2);
        world.setBlock(i + 34, j + 6, k + 46, Blocks.planks, 5, 2);
        world.setBlock(i + 35, j + 6, k + 46, Blocks.stone_stairs, 5, 2);
        world.setBlock(i + 2, j + 6, k + 47, Blocks.planks, 5, 2);
        world.setBlock(i + 10, j + 6, k + 47, Blocks.planks, 5, 2);
        world.setBlock(i + 26, j + 6, k + 47, Blocks.planks, 5, 2);
        world.setBlock(i + 31, j + 6, k + 47, Blocks.planks, 5, 2);
        world.setBlock(i + 34, j + 6, k + 47, Blocks.planks, 5, 2);
        world.setBlock(i + 35, j + 6, k + 47, Blocks.stone_stairs, 5, 2);
        world.setBlock(i + 1, j + 6, k + 48, Blocks.stone_stairs, 6, 2);
        world.setBlock(i + 2, j + 6, k + 48, Blocks.planks, 5, 2);
        world.setBlock(i + 10, j + 6, k + 48, Blocks.planks, 5, 2);
        world.setBlock(i + 26, j + 6, k + 48, Blocks.planks, 5, 2);
        world.setBlock(i + 31, j + 6, k + 48, Blocks.log2, 1, 2);
        world.setBlock(i + 32, j + 6, k + 48, Blocks.log2, 1, 2);
        world.setBlock(i + 34, j + 6, k + 48, Blocks.planks, 5, 2);
        world.setBlock(i + 1, j + 6, k + 49, Blocks.stone_stairs, 4, 2);
        world.setBlock(i + 2, j + 6, k + 49, Blocks.planks, 5, 2);
        world.setBlock(i + 10, j + 6, k + 49, Blocks.planks, 5, 2);
        world.setBlock(i + 26, j + 6, k + 49, Blocks.planks, 5, 2);
        world.setBlock(i + 30, j + 6, k + 49, Blocks.planks, 5, 2);
        world.setBlock(i + 34, j + 6, k + 49, Blocks.planks, 5, 2);
        world.setBlock(i + 1, j + 6, k + 50, Blocks.stone_stairs, 4, 2);
        world.setBlock(i + 2, j + 6, k + 50, Blocks.planks, 5, 2);
        world.setBlock(i + 3, j + 6, k + 50, Blocks.planks, 5, 2);
        world.setBlock(i + 9, j + 6, k + 50, Blocks.planks, 5, 2);
        world.setBlock(i + 10, j + 6, k + 50, Blocks.planks, 5, 2);
        world.setBlock(i + 11, j + 6, k + 50, Blocks.planks, 5, 2);
        world.setBlock(i + 12, j + 6, k + 50, Blocks.planks, 5, 2);
        world.setBlock(i + 13, j + 6, k + 50, Blocks.planks, 5, 2);
        world.setBlock(i + 14, j + 6, k + 50, Blocks.planks, 5, 2);
        world.setBlock(i + 15, j + 6, k + 50, Blocks.planks, 5, 2);
        world.setBlock(i + 16, j + 6, k + 50, Blocks.planks, 5, 2);
        world.setBlock(i + 17, j + 6, k + 50, Blocks.planks, 5, 2);
        world.setBlock(i + 18, j + 6, k + 50, Blocks.planks, 5, 2);
        world.setBlock(i + 19, j + 6, k + 50, Blocks.planks, 5, 2);
        world.setBlock(i + 20, j + 6, k + 50, Blocks.planks, 5, 2);
        world.setBlock(i + 21, j + 6, k + 50, Blocks.planks, 5, 2);
        world.setBlock(i + 22, j + 6, k + 50, Blocks.planks, 5, 2);
        world.setBlock(i + 23, j + 6, k + 50, Blocks.planks, 5, 2);
        world.setBlock(i + 24, j + 6, k + 50, Blocks.planks, 5, 2);
        world.setBlock(i + 25, j + 6, k + 50, Blocks.planks, 5, 2);
        world.setBlock(i + 26, j + 6, k + 50, Blocks.planks, 5, 2);
        world.setBlock(i + 27, j + 6, k + 50, Blocks.planks, 5, 2);
        world.setBlock(i + 28, j + 6, k + 50, Blocks.planks, 5, 2);
        world.setBlock(i + 29, j + 6, k + 50, Blocks.planks, 5, 2);
        world.setBlock(i + 30, j + 6, k + 50, Blocks.planks, 5, 2);
        world.setBlock(i + 31, j + 6, k + 50, Blocks.planks, 5, 2);
        world.setBlock(i + 32, j + 6, k + 50, Blocks.planks, 5, 2);
        world.setBlock(i + 33, j + 6, k + 50, Blocks.planks, 5, 2);
        world.setBlock(i + 34, j + 6, k + 50, Blocks.planks, 5, 2);
        world.setBlock(i + 1, j + 6, k + 51, Blocks.stone_stairs, 4, 2);
        world.setBlock(i + 2, j + 6, k + 51, Blocks.planks, 5, 2);
        world.setBlock(i + 10, j + 6, k + 51, Blocks.planks, 5, 2);
        world.setBlock(i + 18, j + 6, k + 51, Blocks.planks, 5, 2);
        world.setBlock(i + 26, j + 6, k + 51, Blocks.planks, 5, 2);
        world.setBlock(i + 34, j + 6, k + 51, Blocks.planks, 5, 2);
        world.setBlock(i + 35, j + 6, k + 51, Blocks.stone_stairs, 5, 2);
        world.setBlock(i + 1, j + 6, k + 52, Blocks.stone_stairs, 7, 2);
        world.setBlock(i + 2, j + 6, k + 52, Blocks.planks, 5, 2);
        world.setBlock(i + 26, j + 6, k + 52, Blocks.planks, 5, 2);
        world.setBlock(i + 33, j + 6, k + 52, Blocks.wooden_slab, 2, 2);
        world.setBlock(i + 34, j + 6, k + 52, Blocks.planks, 5, 2);
        world.setBlock(i + 35, j + 6, k + 52, Blocks.stone_stairs, 7, 2);
        world.setBlock(i + 2, j + 6, k + 53, Blocks.planks, 5, 2);
        world.setBlock(i + 26, j + 6, k + 53, Blocks.planks, 5, 2);
        world.setBlock(i + 33, j + 6, k + 53, Blocks.birch_stairs, 2, 2);
        world.setBlock(i + 34, j + 6, k + 53, Blocks.planks, 5, 2);
        world.setBlock(i + 2, j + 6, k + 54, Blocks.planks, 5, 2);
        world.setBlock(i + 26, j + 6, k + 54, Blocks.planks, 5, 2);
        world.setBlock(i + 33, j + 6, k + 54, Blocks.planks, 2, 2);
        world.setBlock(i + 34, j + 6, k + 54, Blocks.planks, 5, 2);
        world.setBlock(i + 2, j + 6, k + 55, Blocks.planks, 5, 2);
        world.setBlock(i + 26, j + 6, k + 55, Blocks.planks, 5, 2);
        world.setBlock(i + 33, j + 6, k + 55, Blocks.birch_stairs, 3, 2);
        world.setBlock(i + 34, j + 6, k + 55, Blocks.planks, 5, 2);
        world.setBlock(i + 1, j + 6, k + 56, Blocks.stone_stairs, 6, 2);
        world.setBlock(i + 2, j + 6, k + 56, Blocks.planks, 5, 2);
        world.setBlock(i + 26, j + 6, k + 56, Blocks.planks, 5, 2);
        world.setBlock(i + 33, j + 6, k + 56, Blocks.wooden_slab, 2, 2);
        world.setBlock(i + 34, j + 6, k + 56, Blocks.planks, 5, 2);
        world.setBlock(i + 35, j + 6, k + 56, Blocks.stone_stairs, 6, 2);
        world.setBlock(i + 1, j + 6, k + 57, Blocks.stone_stairs, 4, 2);
        world.setBlock(i + 2, j + 6, k + 57, Blocks.planks, 5, 2);
        world.setBlock(i + 10, j + 6, k + 57, Blocks.planks, 5, 2);
        world.setBlock(i + 18, j + 6, k + 57, Blocks.planks, 5, 2);
        world.setBlock(i + 26, j + 6, k + 57, Blocks.planks, 5, 2);
        world.setBlock(i + 34, j + 6, k + 57, Blocks.planks, 5, 2);
        world.setBlock(i + 35, j + 6, k + 57, Blocks.stone_stairs, 5, 2);
        world.setBlock(i + 1, j + 6, k + 58, Blocks.stone_stairs, 4, 2);
        world.setBlock(i + 2, j + 6, k + 58, Blocks.planks, 5, 2);
        world.setBlock(i + 3, j + 6, k + 58, Blocks.planks, 5, 2);
        world.setBlock(i + 4, j + 6, k + 58, Blocks.planks, 5, 2);
        world.setBlock(i + 5, j + 6, k + 58, Blocks.planks, 5, 2);
        world.setBlock(i + 6, j + 6, k + 58, Blocks.planks, 5, 2);
        world.setBlock(i + 7, j + 6, k + 58, Blocks.planks, 5, 2);
        world.setBlock(i + 8, j + 6, k + 58, Blocks.planks, 5, 2);
        world.setBlock(i + 9, j + 6, k + 58, Blocks.planks, 5, 2);
        world.setBlock(i + 10, j + 6, k + 58, Blocks.planks, 5, 2);
        world.setBlock(i + 11, j + 6, k + 58, Blocks.planks, 5, 2);
        world.setBlock(i + 12, j + 6, k + 58, Blocks.planks, 5, 2);
        world.setBlock(i + 13, j + 6, k + 58, Blocks.planks, 5, 2);
        world.setBlock(i + 14, j + 6, k + 58, Blocks.planks, 5, 2);
        world.setBlock(i + 15, j + 6, k + 58, Blocks.planks, 5, 2);
        world.setBlock(i + 16, j + 6, k + 58, Blocks.planks, 5, 2);
        world.setBlock(i + 17, j + 6, k + 58, Blocks.planks, 5, 2);
        world.setBlock(i + 18, j + 6, k + 58, Blocks.planks, 5, 2);
        world.setBlock(i + 19, j + 6, k + 58, Blocks.planks, 5, 2);
        world.setBlock(i + 20, j + 6, k + 58, Blocks.planks, 5, 2);
        world.setBlock(i + 21, j + 6, k + 58, Blocks.planks, 5, 2);
        world.setBlock(i + 22, j + 6, k + 58, Blocks.planks, 5, 2);
        world.setBlock(i + 23, j + 6, k + 58, Blocks.planks, 5, 2);
        world.setBlock(i + 24, j + 6, k + 58, Blocks.planks, 5, 2);
        world.setBlock(i + 25, j + 6, k + 58, Blocks.planks, 5, 2);
        world.setBlock(i + 26, j + 6, k + 58, Blocks.planks, 5, 2);
        world.setBlock(i + 27, j + 6, k + 58, Blocks.planks, 5, 2);
        world.setBlock(i + 28, j + 6, k + 58, Blocks.planks, 5, 2);
        world.setBlock(i + 29, j + 6, k + 58, Blocks.planks, 5, 2);
        world.setBlock(i + 30, j + 6, k + 58, Blocks.planks, 5, 2);
        world.setBlock(i + 31, j + 6, k + 58, Blocks.planks, 5, 2);
        world.setBlock(i + 32, j + 6, k + 58, Blocks.planks, 5, 2);
        world.setBlock(i + 33, j + 6, k + 58, Blocks.planks, 5, 2);
        world.setBlock(i + 34, j + 6, k + 58, Blocks.cobblestone, 0, 2);
        world.setBlock(i + 35, j + 6, k + 58, Blocks.cobblestone, 0, 2);
        world.setBlock(i + 1, j + 6, k + 59, Blocks.stone_stairs, 4, 2);
        world.setBlock(i + 2, j + 6, k + 59, Blocks.planks, 5, 2);
        world.setBlock(i + 10, j + 6, k + 59, Blocks.planks, 5, 2);
        world.setBlock(i + 26, j + 6, k + 59, Blocks.planks, 5, 2);
        world.setBlock(i + 27, j + 6, k + 59, Blocks.stone_stairs, 5, 2);
        world.setBlock(i + 28, j + 6, k + 59, Blocks.stone_stairs, 5, 2);
        world.setBlock(i + 32, j + 6, k + 59, Blocks.stone_stairs, 4, 2);
        world.setBlock(i + 33, j + 6, k + 59, Blocks.stone_stairs, 7, 2);
        world.setBlock(i + 34, j + 6, k + 59, Blocks.cobblestone, 0, 2);
        world.setBlock(i + 35, j + 6, k + 59, Blocks.cobblestone_wall, 0, 2);
        world.setBlock(i + 1, j + 6, k + 60, Blocks.stone_stairs, 7, 2);
        world.setBlock(i + 2, j + 6, k + 60, Blocks.planks, 5, 2);
        world.setBlock(i + 10, j + 6, k + 60, Blocks.planks, 5, 2);
        world.setBlock(i + 26, j + 6, k + 60, Blocks.planks, 5, 2);
        world.setBlock(i + 27, j + 6, k + 60, Blocks.stone_stairs, 7, 2);
        world.setBlock(i + 2, j + 6, k + 61, Blocks.planks, 5, 2);
        world.setBlock(i + 10, j + 6, k + 61, Blocks.planks, 5, 2);
        world.setBlock(i + 18, j + 6, k + 61, Blocks.fence, 0, 2);
        world.setBlock(i + 26, j + 6, k + 61, Blocks.planks, 5, 2);
        world.setBlock(i + 2, j + 6, k + 62, Blocks.planks, 5, 2);
        world.setBlock(i + 10, j + 6, k + 62, Blocks.planks, 5, 2);
        world.setBlock(i + 17, j + 6, k + 62, Blocks.fence, 0, 2);
        world.setBlock(i + 18, j + 6, k + 62, Blocks.fence, 0, 2);
        world.setBlock(i + 19, j + 6, k + 62, Blocks.fence, 0, 2);
        world.setBlock(i + 26, j + 6, k + 62, Blocks.planks, 5, 2);
        world.setBlock(i + 2, j + 6, k + 63, Blocks.planks, 5, 2);
        world.setBlock(i + 10, j + 6, k + 63, Blocks.planks, 5, 2);
        world.setBlock(i + 18, j + 6, k + 63, Blocks.fence, 0, 2);
        world.setBlock(i + 26, j + 6, k + 63, Blocks.planks, 5, 2);
        world.setBlock(i + 1, j + 6, k + 64, Blocks.stone_stairs, 6, 2);
        world.setBlock(i + 2, j + 6, k + 64, Blocks.planks, 5, 2);
        world.setBlock(i + 10, j + 6, k + 64, Blocks.planks, 5, 2);
        world.setBlock(i + 26, j + 6, k + 64, Blocks.planks, 5, 2);
        world.setBlock(i + 27, j + 6, k + 64, Blocks.stone_stairs, 6, 2);
