package com.NovaCraft.world.mansion;

import net.minecraft.init.Blocks;
import net.minecraft.world.World;
import net.minecraft.world.gen.feature.WorldGenerator;

import java.util.Random;

public class MansionFloor3Gen3 extends WorldGenerator {

    public MansionFloor3Gen3() {

    }

    @Override
    public boolean generate(final World world, final Random random, final int i, final int j, final int k) {

        world.setBlock(i + 16, j + 8, k + 50, Blocks.log2, 9, 2);
        world.setBlock(i + 17, j + 8, k + 50, Blocks.log2, 9, 2);
        world.setBlock(i + 18, j + 8, k + 50, Blocks.log2, 9, 2);
        world.setBlock(i + 19, j + 8, k + 50, Blocks.log2, 9, 2);
        world.setBlock(i + 20, j + 8, k + 50, Blocks.log2, 9, 2);
        world.setBlock(i + 21, j + 8, k + 50, Blocks.log2, 9, 2);
        world.setBlock(i + 22, j + 8, k + 50, Blocks.log2, 9, 2);
        world.setBlock(i + 23, j + 8, k + 50, Blocks.log2, 9, 2);
        world.setBlock(i + 24, j + 8, k + 50, Blocks.log2, 9, 2);
        world.setBlock(i + 25, j + 8, k + 50, Blocks.log2, 9, 2);
        world.setBlock(i + 26, j + 8, k + 50, Blocks.log2, 9, 2);
        world.setBlock(i + 27, j + 8, k + 50, Blocks.planks, 5, 2);
        world.setBlock(i + 28, j + 8, k + 50, Blocks.planks, 5, 2);
        world.setBlock(i + 29, j + 8, k + 50, Blocks.planks, 5, 2);
        world.setBlock(i + 30, j + 8, k + 50, Blocks.planks, 5, 2);
        world.setBlock(i + 31, j + 8, k + 50, Blocks.planks, 5, 2);
        world.setBlock(i + 32, j + 8, k + 50, Blocks.planks, 5, 2);
        world.setBlock(i + 33, j + 8, k + 50, Blocks.planks, 5, 2);
        world.setBlock(i + 34, j + 8, k + 50, Blocks.planks, 5, 2);
        world.setBlock(i + 35, j + 8, k + 50, Blocks.planks, 5, 2);
        world.setBlock(i + 36, j + 8, k + 50, Blocks.dark_oak_stairs, 1, 2);
        world.setBlock(i, j + 8, k + 51, Blocks.dark_oak_stairs, 0, 2);
        world.setBlock(i + 1, j + 8, k + 51, Blocks.planks, 5, 2);
        world.setBlock(i + 2, j + 8, k + 51, Blocks.planks, 5, 2);
        world.setBlock(i + 10, j + 8, k + 51, Blocks.planks, 5, 2);
        world.setBlock(i + 18, j + 8, k + 51, Blocks.planks, 5, 2);
        world.setBlock(i + 26, j + 8, k + 51, Blocks.log2, 5, 2);
        world.setBlock(i + 27, j + 8, k + 51, Blocks.birch_stairs, 7, 2);
        world.setBlock(i + 28, j + 8, k + 51, Blocks.birch_stairs, 7, 2);
        world.setBlock(i + 29, j + 8, k + 51, Blocks.birch_stairs, 7, 2);
        world.setBlock(i + 30, j + 8, k + 51, Blocks.birch_stairs, 7, 2);
        world.setBlock(i + 31, j + 8, k + 51, Blocks.birch_stairs, 7, 2);
        world.setBlock(i + 32, j + 8, k + 51, Blocks.birch_stairs, 7, 2);
        world.setBlock(i + 33, j + 8, k + 51, Blocks.birch_stairs, 4, 2);
        world.setBlock(i + 34, j + 8, k + 51, Blocks.planks, 5, 2);
        world.setBlock(i + 35, j + 8, k + 51, Blocks.planks, 5, 2);
        world.setBlock(i + 36, j + 8, k + 51, Blocks.dark_oak_stairs, 1, 2);
        world.setBlock(i, j + 8, k + 52, Blocks.dark_oak_stairs, 0, 2);
        world.setBlock(i + 1, j + 8, k + 52, Blocks.planks, 5, 2);
        world.setBlock(i + 2, j + 8, k + 52, Blocks.planks, 5, 2);
        world.setBlock(i + 26, j + 8, k + 52, Blocks.log2, 5, 2);
        world.setBlock(i + 27, j + 8, k + 52, Blocks.birch_stairs, 5, 2);
        world.setBlock(i + 33, j + 8, k + 52, Blocks.birch_stairs, 4, 2);
        world.setBlock(i + 34, j + 8, k + 52, Blocks.planks, 5, 2);
        world.setBlock(i + 35, j + 8, k + 52, Blocks.planks, 5, 2);
        world.setBlock(i + 36, j + 8, k + 52, Blocks.dark_oak_stairs, 1, 2);
        world.setBlock(i, j + 8, k + 53, Blocks.dark_oak_stairs, 0, 2);
        world.setBlock(i + 1, j + 8, k + 53, Blocks.planks, 5, 2);
        world.setBlock(i + 2, j + 8, k + 53, Blocks.planks, 5, 2);
        world.setBlock(i + 26, j + 8, k + 53, Blocks.log2, 5, 2);
        world.setBlock(i + 27, j + 8, k + 53, Blocks.birch_stairs, 5, 2);
        world.setBlock(i + 33, j + 8, k + 53, Blocks.birch_stairs, 4, 2);
        world.setBlock(i + 34, j + 8, k + 53, Blocks.planks, 5, 2);
        world.setBlock(i + 35, j + 8, k + 53, Blocks.planks, 5, 2);
        world.setBlock(i + 36, j + 8, k + 53, Blocks.dark_oak_stairs, 1, 2);
        world.setBlock(i, j + 8, k + 54, Blocks.dark_oak_stairs, 0, 2);
        world.setBlock(i + 1, j + 8, k + 54, Blocks.planks, 5, 2);
        world.setBlock(i + 2, j + 8, k + 54, Blocks.planks, 5, 2);
        world.setBlock(i + 26, j + 8, k + 54, Blocks.log2, 5, 2);
        world.setBlock(i + 27, j + 8, k + 54, Blocks.birch_stairs, 5, 2);
        world.setBlock(i + 33, j + 8, k + 54, Blocks.birch_stairs, 4, 2);
        world.setBlock(i + 34, j + 8, k + 54, Blocks.planks, 5, 2);
        world.setBlock(i + 35, j + 8, k + 54, Blocks.planks, 5, 2);
        world.setBlock(i + 36, j + 8, k + 54, Blocks.dark_oak_stairs, 1, 2);
        world.setBlock(i, j + 8, k + 55, Blocks.dark_oak_stairs, 0, 2);
        world.setBlock(i + 1, j + 8, k + 55, Blocks.planks, 5, 2);
        world.setBlock(i + 2, j + 8, k + 55, Blocks.planks, 5, 2);
        world.setBlock(i + 26, j + 8, k + 55, Blocks.log2, 5, 2);
        world.setBlock(i + 27, j + 8, k + 55, Blocks.birch_stairs, 5, 2);
        world.setBlock(i + 33, j + 8, k + 55, Blocks.birch_stairs, 4, 2);
        world.setBlock(i + 34, j + 8, k + 55, Blocks.planks, 5, 2);
        world.setBlock(i + 35, j + 8, k + 55, Blocks.planks, 5, 2);
        world.setBlock(i + 36, j + 8, k + 55, Blocks.dark_oak_stairs, 1, 2);
        world.setBlock(i, j + 8, k + 56, Blocks.dark_oak_stairs, 0, 2);
        world.setBlock(i + 1, j + 8, k + 56, Blocks.planks, 5, 2);
        world.setBlock(i + 2, j + 8, k + 56, Blocks.planks, 5, 2);
        world.setBlock(i + 26, j + 8, k + 56, Blocks.log2, 5, 2);
        world.setBlock(i + 27, j + 8, k + 56, Blocks.birch_stairs, 5, 2);
        world.setBlock(i + 33, j + 8, k + 56, Blocks.birch_stairs, 4, 2);
        world.setBlock(i + 34, j + 8, k + 56, Blocks.planks, 5, 2);
        world.setBlock(i + 35, j + 8, k + 56, Blocks.planks, 5, 2);
        world.setBlock(i + 36, j + 8, k + 56, Blocks.dark_oak_stairs, 1, 2);
        world.setBlock(i, j + 8, k + 57, Blocks.dark_oak_stairs, 0, 2);
        world.setBlock(i + 1, j + 8, k + 57, Blocks.planks, 5, 2);
        world.setBlock(i + 2, j + 8, k + 57, Blocks.planks, 5, 2);
        world.setBlock(i + 10, j + 8, k + 57, Blocks.planks, 5, 2);
        world.setBlock(i + 18, j + 8, k + 57, Blocks.planks, 5, 2);
        world.setBlock(i + 26, j + 8, k + 57, Blocks.log2, 5, 2);
        world.setBlock(i + 27, j + 8, k + 57, Blocks.birch_stairs, 5, 2);
        world.setBlock(i + 28, j + 8, k + 57, Blocks.birch_stairs, 6, 2);
        world.setBlock(i + 29, j + 8, k + 57, Blocks.birch_stairs, 6, 2);
        world.setBlock(i + 30, j + 8, k + 57, Blocks.birch_stairs, 6, 2);
        world.setBlock(i + 31, j + 8, k + 57, Blocks.birch_stairs, 6, 2);
        world.setBlock(i + 32, j + 8, k + 57, Blocks.birch_stairs, 6, 2);
        world.setBlock(i + 33, j + 8, k + 57, Blocks.birch_stairs, 6, 2);
        world.setBlock(i + 34, j + 8, k + 57, Blocks.planks, 5, 2);
        world.setBlock(i + 35, j + 8, k + 57, Blocks.planks, 5, 2);
        world.setBlock(i + 36, j + 8, k + 57, Blocks.dark_oak_stairs, 1, 2);
        world.setBlock(i, j + 8, k + 58, Blocks.dark_oak_stairs, 0, 2);
        world.setBlock(i + 1, j + 8, k + 58, Blocks.planks, 5, 2);
        world.setBlock(i + 2, j + 8, k + 58, Blocks.planks, 5, 2);
        world.setBlock(i + 3, j + 8, k + 58, Blocks.log2, 9, 2);
        world.setBlock(i + 4, j + 8, k + 58, Blocks.log2, 9, 2);
        world.setBlock(i + 5, j + 8, k + 58, Blocks.log2, 9, 2);
        world.setBlock(i + 6, j + 8, k + 58, Blocks.log2, 9, 2);
        world.setBlock(i + 7, j + 8, k + 58, Blocks.log2, 9, 2);
        world.setBlock(i + 8, j + 8, k + 58, Blocks.log2, 9, 2);
        world.setBlock(i + 9, j + 8, k + 58, Blocks.log2, 9, 2);
        world.setBlock(i + 10, j + 8, k + 58, Blocks.log2, 9, 2);
        world.setBlock(i + 11, j + 8, k + 58, Blocks.log2, 9, 2);
        world.setBlock(i + 12, j + 8, k + 58, Blocks.log2, 9, 2);
        world.setBlock(i + 13, j + 8, k + 58, Blocks.log2, 9, 2);
        world.setBlock(i + 14, j + 8, k + 58, Blocks.log2, 9, 2);
        world.setBlock(i + 15, j + 8, k + 58, Blocks.log2, 9, 2);
        world.setBlock(i + 16, j + 8, k + 58, Blocks.log2, 9, 2);
        world.setBlock(i + 17, j + 8, k + 58, Blocks.log2, 9, 2);
        world.setBlock(i + 18, j + 8, k + 58, Blocks.log2, 9, 2);
        world.setBlock(i + 19, j + 8, k + 58, Blocks.log2, 9, 2);
        world.setBlock(i + 20, j + 8, k + 58, Blocks.log2, 9, 2);
        world.setBlock(i + 21, j + 8, k + 58, Blocks.log2, 9, 2);
        world.setBlock(i + 22, j + 8, k + 58, Blocks.log2, 9, 2);
        world.setBlock(i + 23, j + 8, k + 58, Blocks.log2, 9, 2);
        world.setBlock(i + 24, j + 8, k + 58, Blocks.log2, 9, 2);
        world.setBlock(i + 25, j + 8, k + 58, Blocks.log2, 9, 2);
        world.setBlock(i + 26, j + 8, k + 58, Blocks.log2, 5, 2);
        world.setBlock(i + 27, j + 8, k + 58, Blocks.planks, 5, 2);
        world.setBlock(i + 28, j + 8, k + 58, Blocks.planks, 5, 2);
        world.setBlock(i + 29, j + 8, k + 58, Blocks.planks, 5, 2);
        world.setBlock(i + 30, j + 8, k + 58, Blocks.planks, 5, 2);
        world.setBlock(i + 31, j + 8, k + 58, Blocks.planks, 5, 2);
        world.setBlock(i + 32, j + 8, k + 58, Blocks.planks, 5, 2);
        world.setBlock(i + 33, j + 8, k + 58, Blocks.planks, 5, 2);
        world.setBlock(i + 34, j + 8, k + 58, Blocks.planks, 5, 2);
        world.setBlock(i + 35, j + 8, k + 58, Blocks.planks, 5, 2);
        world.setBlock(i + 36, j + 8, k + 58, Blocks.dark_oak_stairs, 1, 2);
        world.setBlock(i, j + 8, k + 59, Blocks.dark_oak_stairs, 0, 2);
        world.setBlock(i + 1, j + 8, k + 59, Blocks.planks, 5, 2);
        world.setBlock(i + 2, j + 8, k + 59, Blocks.planks, 5, 2);
        world.setBlock(i + 10, j + 8, k + 59, Blocks.log2, 5, 2);
        world.setBlock(i + 26, j + 8, k + 59, Blocks.planks, 5, 2);
        world.setBlock(i + 27, j + 8, k + 59, Blocks.planks, 5, 2);
        world.setBlock(i + 28, j + 8, k + 59, Blocks.planks, 5, 2);
        world.setBlock(i + 29, j + 8, k + 59, Blocks.planks, 5, 2);
        world.setBlock(i + 30, j + 8, k + 59, Blocks.planks, 5, 2);
        world.setBlock(i + 31, j + 8, k + 59, Blocks.planks, 5, 2);
        world.setBlock(i + 32, j + 8, k + 59, Blocks.planks, 5, 2);
        world.setBlock(i + 33, j + 8, k + 59, Blocks.planks, 5, 2);
        world.setBlock(i + 34, j + 8, k + 59, Blocks.planks, 5, 2);
        world.setBlock(i + 35, j + 8, k + 59, Blocks.planks, 5, 2);
        world.setBlock(i + 36, j + 8, k + 59, Blocks.dark_oak_stairs, 1, 2);
        world.setBlock(i, j + 8, k + 60, Blocks.dark_oak_stairs, 0, 2);
        world.setBlock(i + 1, j + 8, k + 60, Blocks.planks, 5, 2);
        world.setBlock(i + 2, j + 8, k + 60, Blocks.planks, 5, 2);
        world.setBlock(i + 10, j + 8, k + 60, Blocks.log2, 5, 2);
        world.setBlock(i + 26, j + 8, k + 60, Blocks.planks, 5, 2);
        world.setBlock(i + 27, j + 8, k + 60, Blocks.planks, 5, 2);
        world.setBlock(i + 28, j + 8, k + 60, Blocks.dark_oak_stairs, 1, 2);
        world.setBlock(i + 29, j + 8, k + 60, Blocks.dark_oak_stairs, 3, 2);
        world.setBlock(i + 30, j + 8, k + 60, Blocks.dark_oak_stairs, 3, 2);
        world.setBlock(i + 31, j + 8, k + 60, Blocks.dark_oak_stairs, 3, 2);
        world.setBlock(i + 32, j + 8, k + 60, Blocks.dark_oak_stairs, 3, 2);
        world.setBlock(i + 33, j + 8, k + 60, Blocks.dark_oak_stairs, 3, 2);
        world.setBlock(i + 34, j + 8, k + 60, Blocks.dark_oak_stairs, 3, 2);
        world.setBlock(i + 35, j + 8, k + 60, Blocks.dark_oak_stairs, 3, 2);
        world.setBlock(i + 36, j + 8, k + 60, Blocks.dark_oak_stairs, 3, 2);
        world.setBlock(i, j + 8, k + 61, Blocks.dark_oak_stairs, 0, 2);
        world.setBlock(i + 1, j + 8, k + 61, Blocks.planks, 5, 2);
        world.setBlock(i + 2, j + 8, k + 61, Blocks.planks, 5, 2);
        world.setBlock(i + 10, j + 8, k + 61, Blocks.log2, 5, 2);
        world.setBlock(i + 26, j + 8, k + 61, Blocks.planks, 5, 2);
        world.setBlock(i + 27, j + 8, k + 61, Blocks.planks, 5, 2);
        world.setBlock(i + 28, j + 8, k + 61, Blocks.dark_oak_stairs, 1, 2);
        world.setBlock(i, j + 8, k + 62, Blocks.dark_oak_stairs, 0, 2);
        world.setBlock(i + 1, j + 8, k + 62, Blocks.planks, 5, 2);
        world.setBlock(i + 2, j + 8, k + 62, Blocks.planks, 5, 2);
        world.setBlock(i + 10, j + 8, k + 62, Blocks.log2, 5, 2);
        world.setBlock(i + 18, j + 8, k + 62, Blocks.fence, 0, 2);
        world.setBlock(i + 26, j + 8, k + 62, Blocks.planks, 5, 2);
        world.setBlock(i + 27, j + 8, k + 62, Blocks.planks, 5, 2);
        world.setBlock(i + 28, j + 8, k + 62, Blocks.dark_oak_stairs, 1, 2);
        world.setBlock(i, j + 8, k + 63, Blocks.dark_oak_stairs, 0, 2);
        world.setBlock(i + 1, j + 8, k + 63, Blocks.planks, 5, 2);
        world.setBlock(i + 2, j + 8, k + 63, Blocks.planks, 5, 2);
        world.setBlock(i + 10, j + 8, k + 63, Blocks.log2, 5, 2);
        world.setBlock(i + 26, j + 8, k + 63, Blocks.planks, 5, 2);
        world.setBlock(i + 27, j + 8, k + 63, Blocks.planks, 5, 2);
        world.setBlock(i + 28, j + 8, k + 63, Blocks.dark_oak_stairs, 1, 2);
        world.setBlock(i, j + 8, k + 64, Blocks.dark_oak_stairs, 0, 2);
        world.setBlock(i + 1, j + 8, k + 64, Blocks.planks, 5, 2);
        world.setBlock(i + 2, j + 8, k + 64, Blocks.planks, 5, 2);
        world.setBlock(i + 10, j + 8, k + 64, Blocks.log2, 5, 2);
        world.setBlock(i + 26, j + 8, k + 64, Blocks.planks, 5, 2);
        world.setBlock(i + 27, j + 8, k + 64, Blocks.planks, 5, 2);
        world.setBlock(i + 28, j + 8, k + 64, Blocks.dark_oak_stairs, 1, 2);
        world.setBlock(i, j + 8, k + 65, Blocks.dark_oak_stairs, 0, 2);
        world.setBlock(i + 1, j + 8, k + 65, Blocks.planks, 5, 2);
        world.setBlock(i + 2, j + 8, k + 65, Blocks.planks, 5, 2);
        world.setBlock(i + 10, j + 8, k + 65, Blocks.log2, 5, 2);
        world.setBlock(i + 26, j + 8, k + 65, Blocks.planks, 5, 2);
        world.setBlock(i + 27, j + 8, k + 65, Blocks.planks, 5, 2);
        world.setBlock(i + 28, j + 8, k + 65, Blocks.dark_oak_stairs, 1, 2);
        world.setBlock(i, j + 8, k + 66, Blocks.dark_oak_stairs, 0, 2);
        world.setBlock(i + 1, j + 8, k + 66, Blocks.planks, 5, 2);
        world.setBlock(i + 2, j + 8, k + 66, Blocks.planks, 5, 2);
        world.setBlock(i + 10, j + 8, k + 66, Blocks.log2, 5, 2);
        world.setBlock(i + 26, j + 8, k + 66, Blocks.planks, 5, 2);
        world.setBlock(i + 27, j + 8, k + 66, Blocks.planks, 5, 2);
        world.setBlock(i + 28, j + 8, k + 66, Blocks.dark_oak_stairs, 1, 2);
        world.setBlock(i, j + 8, k + 67, Blocks.dark_oak_stairs, 0, 2);
        world.setBlock(i + 1, j + 8, k + 67, Blocks.planks, 5, 2);
        world.setBlock(i + 2, j + 8, k + 67, Blocks.planks, 5, 2);
        world.setBlock(i + 10, j + 8, k + 67, Blocks.log2, 5, 2);
        world.setBlock(i + 26, j + 8, k + 67, Blocks.planks, 5, 2);
        world.setBlock(i + 27, j + 8, k + 67, Blocks.planks, 5, 2);
        world.setBlock(i + 28, j + 8, k + 67, Blocks.dark_oak_stairs, 1, 2);
        world.setBlock(i, j + 8, k + 68, Blocks.dark_oak_stairs, 0, 2);
        world.setBlock(i + 1, j + 8, k + 68, Blocks.planks, 5, 2);
        world.setBlock(i + 2, j + 8, k + 68, Blocks.planks, 5, 2);
        world.setBlock(i + 10, j + 8, k + 68, Blocks.log2, 5, 2);
        world.setBlock(i + 26, j + 8, k + 68, Blocks.planks, 5, 2);
        world.setBlock(i + 27, j + 8, k + 68, Blocks.planks, 5, 2);
        world.setBlock(i + 28, j + 8, k + 68, Blocks.dark_oak_stairs, 1, 2);
        world.setBlock(i, j + 8, k + 69, Blocks.dark_oak_stairs, 0, 2);
        world.setBlock(i + 1, j + 8, k + 69, Blocks.planks, 5, 2);
        world.setBlock(i + 2, j + 8, k + 69, Blocks.planks, 5, 2);
        world.setBlock(i + 10, j + 8, k + 69, Blocks.log2, 5, 2);
        world.setBlock(i + 26, j + 8, k + 69, Blocks.planks, 5, 2);
        world.setBlock(i + 27, j + 8, k + 69, Blocks.planks, 5, 2);
        world.setBlock(i + 28, j + 8, k + 69, Blocks.dark_oak_stairs, 1, 2);
        world.setBlock(i, j + 8, k + 70, Blocks.dark_oak_stairs, 0, 2);
        world.setBlock(i + 1, j + 8, k + 70, Blocks.planks, 5, 2);
        world.setBlock(i + 2, j + 8, k + 70, Blocks.planks, 5, 2);
        world.setBlock(i + 10, j + 8, k + 70, Blocks.log2, 5, 2);
        world.setBlock(i + 18, j + 8, k + 70, Blocks.fence, 0, 2);
        world.setBlock(i + 26, j + 8, k + 70, Blocks.planks, 5, 2);
        world.setBlock(i + 27, j + 8, k + 70, Blocks.planks, 5, 2);
        world.setBlock(i + 28, j + 8, k + 70, Blocks.dark_oak_stairs, 1, 2);
        world.setBlock(i, j + 8, k + 71, Blocks.dark_oak_stairs, 0, 2);
        world.setBlock(i + 1, j + 8, k + 71, Blocks.planks, 5, 2);
        world.setBlock(i + 2, j + 8, k + 71, Blocks.planks, 5, 2);
        world.setBlock(i + 10, j + 8, k + 71, Blocks.log2, 5, 2);
        world.setBlock(i + 26, j + 8, k + 71, Blocks.planks, 5, 2);
        world.setBlock(i + 27, j + 8, k + 71, Blocks.planks, 5, 2);
        world.setBlock(i + 28, j + 8, k + 71, Blocks.dark_oak_stairs, 1, 2);
        world.setBlock(i, j + 8, k + 72, Blocks.dark_oak_stairs, 0, 2);
        world.setBlock(i + 1, j + 8, k + 72, Blocks.planks, 5, 2);
        world.setBlock(i + 2, j + 8, k + 72, Blocks.planks, 5, 2);
        world.setBlock(i + 5, j + 8, k + 72, Blocks.stone_stairs, 4, 2);
        world.setBlock(i + 6, j + 8, k + 72, Blocks.cobblestone, 0, 2);
        world.setBlock(i + 7, j + 8, k + 72, Blocks.stone_stairs, 5, 2);
        world.setBlock(i + 10, j + 8, k + 72, Blocks.log2, 5, 2);
        world.setBlock(i + 26, j + 8, k + 72, Blocks.planks, 5, 2);
        world.setBlock(i + 27, j + 8, k + 72, Blocks.planks, 5, 2);
        world.setBlock(i + 28, j + 8, k + 72, Blocks.dark_oak_stairs, 1, 2);
        world.setBlock(i, j + 8, k + 73, Blocks.dark_oak_stairs, 0, 2);
        world.setBlock(i + 1, j + 8, k + 73, Blocks.planks, 5, 2);
        world.setBlock(i + 2, j + 8, k + 73, Blocks.planks, 5, 2);
        world.setBlock(i + 4, j + 8, k + 73, Blocks.cobblestone, 0, 2);
        world.setBlock(i + 5, j + 8, k + 73, Blocks.cobblestone, 0, 2);
        world.setBlock(i + 6, j + 8, k + 73, Blocks.cobblestone, 0, 2);
        world.setBlock(i + 7, j + 8, k + 73, Blocks.cobblestone, 0, 2);
        world.setBlock(i + 8, j + 8, k + 73, Blocks.cobblestone, 0, 2);
        world.setBlock(i + 10, j + 8, k + 73, Blocks.log2, 5, 2);
        world.setBlock(i + 26, j + 8, k + 73, Blocks.planks, 5, 2);
        world.setBlock(i + 27, j + 8, k + 73, Blocks.planks, 5, 2);
        world.setBlock(i + 28, j + 8, k + 73, Blocks.dark_oak_stairs, 1, 2);
        world.setBlock(i, j + 8, k + 74, Blocks.dark_oak_stairs, 0, 2);
        world.setBlock(i + 1, j + 8, k + 74, Blocks.planks, 5, 2);
        world.setBlock(i + 2, j + 8, k + 74, Blocks.planks, 5, 2);
        world.setBlock(i + 3, j + 8, k + 74, Blocks.planks, 5, 2);
        world.setBlock(i + 4, j + 8, k + 74, Blocks.planks, 5, 2);
        world.setBlock(i + 5, j + 8, k + 74, Blocks.planks, 5, 2);
        world.setBlock(i + 6, j + 8, k + 74, Blocks.planks, 5, 2);
        world.setBlock(i + 7, j + 8, k + 74, Blocks.planks, 5, 2);
        world.setBlock(i + 8, j + 8, k + 74, Blocks.planks, 5, 2);
        world.setBlock(i + 9, j + 8, k + 74, Blocks.planks, 5, 2);
        world.setBlock(i + 10, j + 8, k + 74, Blocks.log2, 5, 2);
        world.setBlock(i + 11, j + 8, k + 74, Blocks.planks, 5, 2);
        world.setBlock(i + 12, j + 8, k + 74, Blocks.planks, 5, 2);
        world.setBlock(i + 13, j + 8, k + 74, Blocks.planks, 5, 2);
        world.setBlock(i + 14, j + 8, k + 74, Blocks.planks, 5, 2);
        world.setBlock(i + 15, j + 8, k + 74, Blocks.planks, 5, 2);
        world.setBlock(i + 16, j + 8, k + 74, Blocks.planks, 5, 2);
        world.setBlock(i + 17, j + 8, k + 74, Blocks.planks, 5, 2);
        world.setBlock(i + 18, j + 8, k + 74, Blocks.planks, 5, 2);
        world.setBlock(i + 19, j + 8, k + 74, Blocks.planks, 5, 2);
        world.setBlock(i + 20, j + 8, k + 74, Blocks.planks, 5, 2);
        world.setBlock(i + 21, j + 8, k + 74, Blocks.planks, 5, 2);
        world.setBlock(i + 22, j + 8, k + 74, Blocks.planks, 5, 2);
        world.setBlock(i + 23, j + 8, k + 74, Blocks.planks, 5, 2);
        world.setBlock(i + 24, j + 8, k + 74, Blocks.planks, 5, 2);
        world.setBlock(i + 25, j + 8, k + 74, Blocks.planks, 5, 2);
        world.setBlock(i + 26, j + 8, k + 74, Blocks.planks, 5, 2);
        world.setBlock(i + 27, j + 8, k + 74, Blocks.planks, 5, 2);
        world.setBlock(i + 28, j + 8, k + 74, Blocks.dark_oak_stairs, 1, 2);
        world.setBlock(i, j + 8, k + 75, Blocks.dark_oak_stairs, 0, 2);
        world.setBlock(i + 1, j + 8, k + 75, Blocks.planks, 5, 2);
        world.setBlock(i + 2, j + 8, k + 75, Blocks.planks, 5, 2);
        world.setBlock(i + 3, j + 8, k + 75, Blocks.planks, 5, 2);
        world.setBlock(i + 4, j + 8, k + 75, Blocks.planks, 5, 2);
        world.setBlock(i + 5, j + 8, k + 75, Blocks.planks, 5, 2);
        world.setBlock(i + 6, j + 8, k + 75, Blocks.planks, 5, 2);
        world.setBlock(i + 7, j + 8, k + 75, Blocks.planks, 5, 2);
        world.setBlock(i + 8, j + 8, k + 75, Blocks.planks, 5, 2);
        world.setBlock(i + 9, j + 8, k + 75, Blocks.planks, 5, 2);
        world.setBlock(i + 10, j + 8, k + 75, Blocks.planks, 5, 2);
        world.setBlock(i + 11, j + 8, k + 75, Blocks.planks, 5, 2);
        world.setBlock(i + 12, j + 8, k + 75, Blocks.planks, 5, 2);
        world.setBlock(i + 13, j + 8, k + 75, Blocks.planks, 5, 2);
        world.setBlock(i + 14, j + 8, k + 75, Blocks.planks, 5, 2);
        world.setBlock(i + 15, j + 8, k + 75, Blocks.planks, 5, 2);
        world.setBlock(i + 16, j + 8, k + 75, Blocks.planks, 5, 2);
        world.setBlock(i + 17, j + 8, k + 75, Blocks.planks, 5, 2);
        world.setBlock(i + 18, j + 8, k + 75, Blocks.planks, 5, 2);
        world.setBlock(i + 19, j + 8, k + 75, Blocks.planks, 5, 2);
        world.setBlock(i + 20, j + 8, k + 75, Blocks.planks, 5, 2);
        world.setBlock(i + 21, j + 8, k + 75, Blocks.planks, 5, 2);
        world.setBlock(i + 22, j + 8, k + 75, Blocks.planks, 5, 2);
        world.setBlock(i + 23, j + 8, k + 75, Blocks.planks, 5, 2);
        world.setBlock(i + 24, j + 8, k + 75, Blocks.planks, 5, 2);
        world.setBlock(i + 25, j + 8, k + 75, Blocks.planks, 5, 2);
        world.setBlock(i + 26, j + 8, k + 75, Blocks.planks, 5, 2);
        world.setBlock(i + 27, j + 8, k + 75, Blocks.planks, 5, 2);
        world.setBlock(i + 28, j + 8, k + 75, Blocks.dark_oak_stairs, 1, 2);
        world.setBlock(i, j + 8, k + 76, Blocks.dark_oak_stairs, 0, 2);
        world.setBlock(i + 1, j + 8, k + 76, Blocks.dark_oak_stairs, 3, 2);
        world.setBlock(i + 2, j + 8, k + 76, Blocks.dark_oak_stairs, 3, 2);
        world.setBlock(i + 3, j + 8, k + 76, Blocks.dark_oak_stairs, 3, 2);
        world.setBlock(i + 4, j + 8, k + 76, Blocks.dark_oak_stairs, 3, 2);
        world.setBlock(i + 5, j + 8, k + 76, Blocks.dark_oak_stairs, 3, 2);
        world.setBlock(i + 6, j + 8, k + 76, Blocks.dark_oak_stairs, 3, 2);
        world.setBlock(i + 7, j + 8, k + 76, Blocks.dark_oak_stairs, 3, 2);
        world.setBlock(i + 8, j + 8, k + 76, Blocks.dark_oak_stairs, 3, 2);
        world.setBlock(i + 9, j + 8, k + 76, Blocks.dark_oak_stairs, 3, 2);
        world.setBlock(i + 10, j + 8, k + 76, Blocks.dark_oak_stairs, 3, 2);
        world.setBlock(i + 11, j + 8, k + 76, Blocks.dark_oak_stairs, 3, 2);
        world.setBlock(i + 12, j + 8, k + 76, Blocks.dark_oak_stairs, 3, 2);
        world.setBlock(i + 13, j + 8, k + 76, Blocks.dark_oak_stairs, 3, 2);
        world.setBlock(i + 14, j + 8, k + 76, Blocks.dark_oak_stairs, 3, 2);
        world.setBlock(i + 15, j + 8, k + 76, Blocks.dark_oak_stairs, 3, 2);
        world.setBlock(i + 16, j + 8, k + 76, Blocks.dark_oak_stairs, 3, 2);
        world.setBlock(i + 17, j + 8, k + 76, Blocks.dark_oak_stairs, 3, 2);
        world.setBlock(i + 18, j + 8, k + 76, Blocks.dark_oak_stairs, 3, 2);
        world.setBlock(i + 19, j + 8, k + 76, Blocks.dark_oak_stairs, 3, 2);
        world.setBlock(i + 20, j + 8, k + 76, Blocks.dark_oak_stairs, 3, 2);
        world.setBlock(i + 21, j + 8, k + 76, Blocks.dark_oak_stairs, 3, 2);
        world.setBlock(i + 22, j + 8, k + 76, Blocks.dark_oak_stairs, 3, 2);
        world.setBlock(i + 23, j + 8, k + 76, Blocks.dark_oak_stairs, 3, 2);
        world.setBlock(i + 24, j + 8, k + 76, Blocks.dark_oak_stairs, 3, 2);
        world.setBlock(i + 25, j + 8, k + 76, Blocks.dark_oak_stairs, 3, 2);
        world.setBlock(i + 26, j + 8, k + 76, Blocks.dark_oak_stairs, 3, 2);
        world.setBlock(i + 27, j + 8, k + 76, Blocks.dark_oak_stairs, 3, 2);
        world.setBlock(i + 28, j + 8, k + 76, Blocks.dark_oak_stairs, 3, 2);
        world.setBlock(i + 1, j + 9, k + 1, Blocks.dark_oak_stairs, 2, 2);
        world.setBlock(i + 2, j + 9, k + 1, Blocks.dark_oak_stairs, 2, 2);
        world.setBlock(i + 3, j + 9, k + 1, Blocks.dark_oak_stairs, 2, 2);
        world.setBlock(i + 4, j + 9, k + 1, Blocks.dark_oak_stairs, 2, 2);
        world.setBlock(i + 5, j + 9, k + 1, Blocks.dark_oak_stairs, 2, 2);
        world.setBlock(i + 6, j + 9, k + 1, Blocks.dark_oak_stairs, 2, 2);
        world.setBlock(i + 7, j + 9, k + 1, Blocks.dark_oak_stairs, 2, 2);
        world.setBlock(i + 8, j + 9, k + 1, Blocks.dark_oak_stairs, 2, 2);
        world.setBlock(i + 9, j + 9, k + 1, Blocks.dark_oak_stairs, 2, 2);
        world.setBlock(i + 10, j + 9, k + 1, Blocks.dark_oak_stairs, 2, 2);
        world.setBlock(i + 11, j + 9, k + 1, Blocks.dark_oak_stairs, 2, 2);
        world.setBlock(i + 12, j + 9, k + 1, Blocks.dark_oak_stairs, 2, 2);
        world.setBlock(i + 13, j + 9, k + 1, Blocks.dark_oak_stairs, 2, 2);
        world.setBlock(i + 14, j + 9, k + 1, Blocks.dark_oak_stairs, 2, 2);
        world.setBlock(i + 15, j + 9, k + 1, Blocks.dark_oak_stairs, 2, 2);
        world.setBlock(i + 16, j + 9, k + 1, Blocks.dark_oak_stairs, 2, 2);
        world.setBlock(i + 17, j + 9, k + 1, Blocks.dark_oak_stairs, 2, 2);
        world.setBlock(i + 18, j + 9, k + 1, Blocks.dark_oak_stairs, 2, 2);
        world.setBlock(i + 19, j + 9, k + 1, Blocks.dark_oak_stairs, 1, 2);
        world.setBlock(i + 1, j + 9, k + 2, Blocks.dark_oak_stairs, 0, 2);
        world.setBlock(i + 2, j + 9, k + 2, Blocks.planks, 5, 2);
        world.setBlock(i + 3, j + 9, k + 2, Blocks.planks, 5, 2);
        world.setBlock(i + 4, j + 9, k + 2, Blocks.planks, 5, 2);
        world.setBlock(i + 5, j + 9, k + 2, Blocks.planks, 5, 2);
        world.setBlock(i + 6, j + 9, k + 2, Blocks.planks, 5, 2);
        world.setBlock(i + 7, j + 9, k + 2, Blocks.planks, 5, 2);
        world.setBlock(i + 8, j + 9, k + 2, Blocks.planks, 5, 2);
        world.setBlock(i + 9, j + 9, k + 2, Blocks.planks, 5, 2);
        world.setBlock(i + 10, j + 9, k + 2, Blocks.planks, 5, 2);
        world.setBlock(i + 11, j + 9, k + 2, Blocks.planks, 5, 2);
        world.setBlock(i + 12, j + 9, k + 2, Blocks.planks, 5, 2);
        world.setBlock(i + 13, j + 9, k + 2, Blocks.planks, 5, 2);
        world.setBlock(i + 14, j + 9, k + 2, Blocks.planks, 5, 2);
        world.setBlock(i + 15, j + 9, k + 2, Blocks.planks, 5, 2);
        world.setBlock(i + 16, j + 9, k + 2, Blocks.planks, 5, 2);
        world.setBlock(i + 17, j + 9, k + 2, Blocks.planks, 5, 2);
        world.setBlock(i + 18, j + 9, k + 2, Blocks.planks, 5, 2);
        world.setBlock(i + 19, j + 9, k + 2, Blocks.dark_oak_stairs, 1, 2);
        world.setBlock(i + 1, j + 9, k + 3, Blocks.dark_oak_stairs, 0, 2);
        world.setBlock(i + 2, j + 9, k + 3, Blocks.planks, 5, 2);
        world.setBlock(i + 18, j + 9, k + 3, Blocks.planks, 5, 2);
        world.setBlock(i + 19, j + 9, k + 3, Blocks.dark_oak_stairs, 1, 2);
        world.setBlock(i + 1, j + 9, k + 4, Blocks.dark_oak_stairs, 0, 2);
        world.setBlock(i + 2, j + 9, k + 4, Blocks.planks, 5, 2);
        world.setBlock(i + 18, j + 9, k + 4, Blocks.planks, 5, 2);
        world.setBlock(i + 19, j + 9, k + 4, Blocks.dark_oak_stairs, 1, 2);
        world.setBlock(i + 1, j + 9, k + 5, Blocks.dark_oak_stairs, 0, 2);
        world.setBlock(i + 2, j + 9, k + 5, Blocks.planks, 5, 2);
        world.setBlock(i + 18, j + 9, k + 5, Blocks.planks, 5, 2);
        world.setBlock(i + 19, j + 9, k + 5, Blocks.dark_oak_stairs, 1, 2);
        world.setBlock(i + 1, j + 9, k + 6, Blocks.dark_oak_stairs, 0, 2);
        world.setBlock(i + 2, j + 9, k + 6, Blocks.planks, 5, 2);
        world.setBlock(i + 10, j + 9, k + 6, Blocks.fence, 0, 2);
        world.setBlock(i + 18, j + 9, k + 6, Blocks.planks, 5, 2);
        world.setBlock(i + 19, j + 9, k + 6, Blocks.dark_oak_stairs, 1, 2);
        world.setBlock(i + 1, j + 9, k + 7, Blocks.dark_oak_stairs, 0, 2);
        world.setBlock(i + 2, j + 9, k + 7, Blocks.planks, 5, 2);
        world.setBlock(i + 18, j + 9, k + 7, Blocks.planks, 5, 2);
        world.setBlock(i + 19, j + 9, k + 7, Blocks.dark_oak_stairs, 1, 2);
        world.setBlock(i + 1, j + 9, k + 8, Blocks.dark_oak_stairs, 0, 2);
        world.setBlock(i + 2, j + 9, k + 8, Blocks.planks, 5, 2);
        world.setBlock(i + 18, j + 9, k + 8, Blocks.planks, 5, 2);
        world.setBlock(i + 19, j + 9, k + 8, Blocks.dark_oak_stairs, 1, 2);
        world.setBlock(i + 1, j + 9, k + 9, Blocks.dark_oak_stairs, 0, 2);
        world.setBlock(i + 2, j + 9, k + 9, Blocks.planks, 5, 2);
        world.setBlock(i + 18, j + 9, k + 9, Blocks.planks, 5, 2);
        world.setBlock(i + 19, j + 9, k + 9, Blocks.dark_oak_stairs, 1, 2);
        world.setBlock(i + 1, j + 9, k + 10, Blocks.dark_oak_stairs, 0, 2);
        world.setBlock(i + 2, j + 9, k + 10, Blocks.planks, 5, 2);
        world.setBlock(i + 18, j + 9, k + 10, Blocks.planks, 5, 2);
        world.setBlock(i + 19, j + 9, k + 10, Blocks.dark_oak_stairs, 1, 2);
        world.setBlock(i + 1, j + 9, k + 11, Blocks.dark_oak_stairs, 0, 2);
        world.setBlock(i + 2, j + 9, k + 11, Blocks.planks, 5, 2);
        world.setBlock(i + 18, j + 9, k + 11, Blocks.planks, 5, 2);
        world.setBlock(i + 19, j + 9, k + 11, Blocks.dark_oak_stairs, 1, 2);
        world.setBlock(i + 1, j + 9, k + 12, Blocks.dark_oak_stairs, 0, 2);
        world.setBlock(i + 2, j + 9, k + 12, Blocks.planks, 5, 2);
        world.setBlock(i + 18, j + 9, k + 12, Blocks.planks, 5, 2);
        world.setBlock(i + 19, j + 9, k + 12, Blocks.dark_oak_stairs, 1, 2);
        world.setBlock(i + 1, j + 9, k + 13, Blocks.dark_oak_stairs, 0, 2);
        world.setBlock(i + 2, j + 9, k + 13, Blocks.planks, 5, 2);
        world.setBlock(i + 18, j + 9, k + 13, Blocks.planks, 5, 2);
        world.setBlock(i + 19, j + 9, k + 13, Blocks.dark_oak_stairs, 1, 2);
        world.setBlock(i + 1, j + 9, k + 14, Blocks.dark_oak_stairs, 0, 2);
        world.setBlock(i + 2, j + 9, k + 14, Blocks.planks, 5, 2);
        world.setBlock(i + 10, j + 9, k + 14, Blocks.fence, 0, 2);
        world.setBlock(i + 18, j + 9, k + 14, Blocks.planks, 5, 2);
        world.setBlock(i + 19, j + 9, k + 14, Blocks.dark_oak_stairs, 1, 2);
        world.setBlock(i + 1, j + 9, k + 15, Blocks.dark_oak_stairs, 0, 2);
        world.setBlock(i + 2, j + 9, k + 15, Blocks.planks, 5, 2);
        world.setBlock(i + 18, j + 9, k + 15, Blocks.planks, 5, 2);
        world.setBlock(i + 19, j + 9, k + 15, Blocks.dark_oak_stairs, 1, 2);
        world.setBlock(i + 1, j + 9, k + 16, Blocks.dark_oak_stairs, 0, 2);
        world.setBlock(i + 2, j + 9, k + 16, Blocks.planks, 5, 2);
        world.setBlock(i + 18, j + 9, k + 16, Blocks.planks, 5, 2);
        world.setBlock(i + 19, j + 9, k + 16, Blocks.dark_oak_stairs, 1, 2);
        world.setBlock(i + 1, j + 9, k + 17, Blocks.dark_oak_stairs, 0, 2);
        world.setBlock(i + 2, j + 9, k + 17, Blocks.planks, 5, 2);
        world.setBlock(i + 18, j + 9, k + 17, Blocks.planks, 5, 2);
        world.setBlock(i + 19, j + 9, k + 17, Blocks.dark_oak_stairs, 2, 2);
        world.setBlock(i + 20, j + 9, k + 17, Blocks.dark_oak_stairs, 2, 2);
        world.setBlock(i + 21, j + 9, k + 17, Blocks.dark_oak_stairs, 2, 2);
        world.setBlock(i + 22, j + 9, k + 17, Blocks.dark_oak_stairs, 2, 2);
        world.setBlock(i + 23, j + 9, k + 17, Blocks.dark_oak_stairs, 2, 2);
        world.setBlock(i + 24, j + 9, k + 17, Blocks.dark_oak_stairs, 2, 2);
        world.setBlock(i + 25, j + 9, k + 17, Blocks.dark_oak_stairs, 2, 2);
        world.setBlock(i + 26, j + 9, k + 17, Blocks.dark_oak_stairs, 2, 2);
        world.setBlock(i + 27, j + 9, k + 17, Blocks.dark_oak_stairs, 1, 2);
        world.setBlock(i + 1, j + 9, k + 18, Blocks.dark_oak_stairs, 0, 2);
        world.setBlock(i + 2, j + 9, k + 18, Blocks.planks, 5, 2);
        world.setBlock(i + 3, j + 9, k + 18, Blocks.planks, 5, 2);
        world.setBlock(i + 4, j + 9, k + 18, Blocks.planks, 5, 2);
        world.setBlock(i + 5, j + 9, k + 18, Blocks.planks, 5, 2);
        world.setBlock(i + 6, j + 9, k + 18, Blocks.planks, 5, 2);
        world.setBlock(i + 7, j + 9, k + 18, Blocks.planks, 5, 2);
        world.setBlock(i + 8, j + 9, k + 18, Blocks.planks, 5, 2);
        world.setBlock(i + 9, j + 9, k + 18, Blocks.planks, 5, 2);
        world.setBlock(i + 10, j + 9, k + 18, Blocks.planks, 5, 2);
        world.setBlock(i + 11, j + 9, k + 18, Blocks.planks, 5, 2);
        world.setBlock(i + 12, j + 9, k + 18, Blocks.planks, 5, 2);
        world.setBlock(i + 13, j + 9, k + 18, Blocks.planks, 5, 2);
        world.setBlock(i + 14, j + 9, k + 18, Blocks.planks, 5, 2);
        world.setBlock(i + 15, j + 9, k + 18, Blocks.planks, 5, 2);
        world.setBlock(i + 16, j + 9, k + 18, Blocks.planks, 5, 2);
        world.setBlock(i + 17, j + 9, k + 18, Blocks.planks, 5, 2);
        world.setBlock(i + 18, j + 9, k + 18, Blocks.planks, 5, 2);
        world.setBlock(i + 19, j + 9, k + 18, Blocks.planks, 5, 2);
        world.setBlock(i + 20, j + 9, k + 18, Blocks.planks, 5, 2);
        world.setBlock(i + 21, j + 9, k + 18, Blocks.planks, 5, 2);
        world.setBlock(i + 22, j + 9, k + 18, Blocks.planks, 5, 2);
        world.setBlock(i + 23, j + 9, k + 18, Blocks.planks, 5, 2);
        world.setBlock(i + 24, j + 9, k + 18, Blocks.planks, 5, 2);
        world.setBlock(i + 25, j + 9, k + 18, Blocks.planks, 5, 2);
        world.setBlock(i + 26, j + 9, k + 18, Blocks.planks, 5, 2);
        world.setBlock(i + 27, j + 9, k + 18, Blocks.dark_oak_stairs, 1, 2);
        world.setBlock(i + 1, j + 9, k + 19, Blocks.dark_oak_stairs, 0, 2);
        world.setBlock(i + 2, j + 9, k + 19, Blocks.planks, 5, 2);
        world.setBlock(i + 3, j + 9, k + 19, Blocks.dark_oak_stairs, 5, 2);
        world.setBlock(i + 10, j + 9, k + 19, Blocks.planks, 5, 2);
        world.setBlock(i + 18, j + 9, k + 19, Blocks.planks, 5, 2);
        world.setBlock(i + 26, j + 9, k + 19, Blocks.planks, 5, 2);
        world.setBlock(i + 27, j + 9, k + 19, Blocks.dark_oak_stairs, 1, 2);
        world.setBlock(i + 1, j + 9, k + 20, Blocks.dark_oak_stairs, 0, 2);
        world.setBlock(i + 2, j + 9, k + 20, Blocks.planks, 5, 2);
        world.setBlock(i + 3, j + 9, k + 20, Blocks.dark_oak_stairs, 5, 2);
        world.setBlock(i + 10, j + 9, k + 20, Blocks.dark_oak_stairs, 7, 2);
        world.setBlock(i + 18, j + 9, k + 20, Blocks.dark_oak_stairs, 7, 2);
        world.setBlock(i + 26, j + 9, k + 20, Blocks.planks, 5, 2);
        world.setBlock(i + 27, j + 9, k + 20, Blocks.dark_oak_stairs, 1, 2);
        world.setBlock(i + 1, j + 9, k + 21, Blocks.dark_oak_stairs, 0, 2);
        world.setBlock(i + 2, j + 9, k + 21, Blocks.planks, 5, 2);
        world.setBlock(i + 3, j + 9, k + 21, Blocks.dark_oak_stairs, 5, 2);
        world.setBlock(i + 26, j + 9, k + 21, Blocks.planks, 5, 2);
        world.setBlock(i + 27, j + 9, k + 21, Blocks.dark_oak_stairs, 1, 2);
        world.setBlock(i + 1, j + 9, k + 22, Blocks.dark_oak_stairs, 0, 2);
        world.setBlock(i + 2, j + 9, k + 22, Blocks.planks, 5, 2);
        world.setBlock(i + 3, j + 9, k + 22, Blocks.dark_oak_stairs, 5, 2);
        world.setBlock(i + 26, j + 9, k + 22, Blocks.planks, 5, 2);
        world.setBlock(i + 27, j + 9, k + 22, Blocks.dark_oak_stairs, 1, 2);
        world.setBlock(i + 1, j + 9, k + 23, Blocks.dark_oak_stairs, 0, 2);
        world.setBlock(i + 2, j + 9, k + 23, Blocks.planks, 5, 2);
        world.setBlock(i + 3, j + 9, k + 23, Blocks.dark_oak_stairs, 5, 2);
        world.setBlock(i + 26, j + 9, k + 23, Blocks.planks, 5, 2);
        world.setBlock(i + 27, j + 9, k + 23, Blocks.dark_oak_stairs, 1, 2);
        world.setBlock(i + 1, j + 9, k + 24, Blocks.dark_oak_stairs, 0, 2);
        world.setBlock(i + 2, j + 9, k + 24, Blocks.planks, 5, 2);
        world.setBlock(i + 10, j + 9, k + 24, Blocks.dark_oak_stairs, 6, 2);
        world.setBlock(i + 18, j + 9, k + 24, Blocks.dark_oak_stairs, 6, 2);
        world.setBlock(i + 26, j + 9, k + 24, Blocks.planks, 5, 2);
        world.setBlock(i + 27, j + 9, k + 24, Blocks.dark_oak_stairs, 1, 2);
        world.setBlock(i + 1, j + 9, k + 25, Blocks.dark_oak_stairs, 0, 2);
        world.setBlock(i + 2, j + 9, k + 25, Blocks.planks, 5, 2);
        world.setBlock(i + 10, j + 9, k + 25, Blocks.planks, 5, 2);
        world.setBlock(i + 18, j + 9, k + 25, Blocks.planks, 5, 2);
        world.setBlock(i + 26, j + 9, k + 25, Blocks.planks, 5, 2);
        world.setBlock(i + 27, j + 9, k + 25, Blocks.dark_oak_stairs, 1, 2);
        world.setBlock(i + 1, j + 9, k + 26, Blocks.dark_oak_stairs, 0, 2);
        world.setBlock(i + 2, j + 9, k + 26, Blocks.planks, 5, 2);
        world.setBlock(i + 3, j + 9, k + 26, Blocks.planks, 5, 2);
        world.setBlock(i + 4, j + 9, k + 26, Blocks.dark_oak_stairs, 5, 2);
        world.setBlock(i + 8, j + 9, k + 26, Blocks.dark_oak_stairs, 4, 2);
        world.setBlock(i + 9, j + 9, k + 26, Blocks.planks, 5, 2);
        world.setBlock(i + 10, j + 9, k + 26, Blocks.planks, 5, 2);
        world.setBlock(i + 11, j + 9, k + 26, Blocks.planks, 5, 2);
        world.setBlock(i + 12, j + 9, k + 26, Blocks.planks, 5, 2);
        world.setBlock(i + 13, j + 9, k + 26, Blocks.planks, 5, 2);
        world.setBlock(i + 14, j + 9, k + 26, Blocks.planks, 5, 2);
        world.setBlock(i + 15, j + 9, k + 26, Blocks.planks, 5, 2);
        world.setBlock(i + 16, j + 9, k + 26, Blocks.planks, 5, 2);
        world.setBlock(i + 17, j + 9, k + 26, Blocks.planks, 5, 2);
        world.setBlock(i + 18, j + 9, k + 26, Blocks.planks, 5, 2);
        world.setBlock(i + 26, j + 9, k + 26, Blocks.planks, 5, 2);
        world.setBlock(i + 27, j + 9, k + 26, Blocks.dark_oak_stairs, 1, 2);
        world.setBlock(i + 1, j + 9, k + 27, Blocks.dark_oak_stairs, 0, 2);
        world.setBlock(i + 2, j + 9, k + 27, Blocks.planks, 5, 2);
        world.setBlock(i + 3, j + 9, k + 27, Blocks.dark_oak_stairs, 5, 2);
        world.setBlock(i + 10, j + 9, k + 27, Blocks.planks, 5, 2);
        world.setBlock(i + 18, j + 9, k + 27, Blocks.planks, 5, 2);
        world.setBlock(i + 26, j + 9, k + 27, Blocks.planks, 5, 2);
        world.setBlock(i + 27, j + 9, k + 27, Blocks.dark_oak_stairs, 1, 2);
        world.setBlock(i + 1, j + 9, k + 28, Blocks.dark_oak_stairs, 0, 2);
        world.setBlock(i + 2, j + 9, k + 28, Blocks.planks, 5, 2);
        world.setBlock(i + 3, j + 9, k + 28, Blocks.dark_oak_stairs, 5, 2);
        world.setBlock(i + 10, j + 9, k + 28, Blocks.planks, 5, 2);
        world.setBlock(i + 18, j + 9, k + 28, Blocks.planks, 5, 2);
        world.setBlock(i + 26, j + 9, k + 28, Blocks.planks, 5, 2);
        world.setBlock(i + 27, j + 9, k + 28, Blocks.dark_oak_stairs, 1, 2);
        world.setBlock(i + 1, j + 9, k + 29, Blocks.dark_oak_stairs, 0, 2);
        world.setBlock(i + 2, j + 9, k + 29, Blocks.planks, 5, 2);
        world.setBlock(i + 3, j + 9, k + 29, Blocks.dark_oak_stairs, 5, 2);
        world.setBlock(i + 10, j + 9, k + 29, Blocks.planks, 5, 2);
        world.setBlock(i + 18, j + 9, k + 29, Blocks.planks, 5, 2);
        world.setBlock(i + 26, j + 9, k + 29, Blocks.planks, 5, 2);
        world.setBlock(i + 27, j + 9, k + 29, Blocks.dark_oak_stairs, 1, 2);
        world.setBlock(i + 1, j + 9, k + 30, Blocks.dark_oak_stairs, 0, 2);
        world.setBlock(i + 2, j + 9, k + 30, Blocks.planks, 5, 2);
        world.setBlock(i + 3, j + 9, k + 30, Blocks.dark_oak_stairs, 5, 2);
        world.setBlock(i + 10, j + 9, k + 30, Blocks.planks, 5, 2);
        world.setBlock(i + 11, j + 9, k + 30, Blocks.planks, 5, 2);
        world.setBlock(i + 17, j + 9, k + 30, Blocks.planks, 5, 2);
        world.setBlock(i + 18, j + 9, k + 30, Blocks.planks, 5, 2);
        world.setBlock(i + 26, j + 9, k + 30, Blocks.planks, 5, 2);
        world.setBlock(i + 27, j + 9, k + 30, Blocks.dark_oak_stairs, 1, 2);
        world.setBlock(i + 1, j + 9, k + 31, Blocks.dark_oak_stairs, 0, 2);
        world.setBlock(i + 2, j + 9, k + 31, Blocks.planks, 5, 2);
        world.setBlock(i + 3, j + 9, k + 31, Blocks.dark_oak_stairs, 5, 2);
        world.setBlock(i + 10, j + 9, k + 31, Blocks.planks, 5, 2);
        world.setBlock(i + 18, j + 9, k + 31, Blocks.planks, 5, 2);
        world.setBlock(i + 26, j + 9, k + 31, Blocks.planks, 5, 2);
        world.setBlock(i + 27, j + 9, k + 31, Blocks.dark_oak_stairs, 1, 2);
        world.setBlock(i + 1, j + 9, k + 32, Blocks.dark_oak_stairs, 0, 2);
        world.setBlock(i + 2, j + 9, k + 32, Blocks.planks, 5, 2);
        world.setBlock(i + 10, j + 9, k + 32, Blocks.planks, 5, 2);
        world.setBlock(i + 18, j + 9, k + 32, Blocks.planks, 5, 2);
        world.setBlock(i + 26, j + 9, k + 32, Blocks.planks, 5, 2);
        world.setBlock(i + 27, j + 9, k + 32, Blocks.dark_oak_stairs, 1, 2);
        world.setBlock(i + 1, j + 9, k + 33, Blocks.dark_oak_stairs, 0, 2);
        world.setBlock(i + 2, j + 9, k + 33, Blocks.planks, 5, 2);
        world.setBlock(i + 10, j + 9, k + 33, Blocks.planks, 5, 2);
        world.setBlock(i + 18, j + 9, k + 33, Blocks.planks, 5, 2);
        world.setBlock(i + 26, j + 9, k + 33, Blocks.planks, 5, 2);
        world.setBlock(i + 27, j + 9, k + 33, Blocks.dark_oak_stairs, 1, 2);
        world.setBlock(i + 1, j + 9, k + 34, Blocks.dark_oak_stairs, 0, 2);
        world.setBlock(i + 2, j + 9, k + 34, Blocks.planks, 5, 2);
        world.setBlock(i + 3, j + 9, k + 34, Blocks.planks, 5, 2);
        world.setBlock(i + 4, j + 9, k + 34, Blocks.dark_oak_stairs, 5, 2);
        world.setBlock(i + 8, j + 9, k + 34, Blocks.dark_oak_stairs, 4, 2);
        world.setBlock(i + 9, j + 9, k + 34, Blocks.planks, 5, 2);
        world.setBlock(i + 10, j + 9, k + 34, Blocks.planks, 5, 2);
        world.setBlock(i + 11, j + 9, k + 34, Blocks.planks, 5, 2);
        world.setBlock(i + 12, j + 9, k + 34, Blocks.planks, 5, 2);
        world.setBlock(i + 13, j + 9, k + 34, Blocks.planks, 5, 2);
        world.setBlock(i + 14, j + 9, k + 34, Blocks.planks, 5, 2);
        world.setBlock(i + 15, j + 9, k + 34, Blocks.planks, 5, 2);
        world.setBlock(i + 16, j + 9, k + 34, Blocks.planks, 5, 2);
        world.setBlock(i + 17, j + 9, k + 34, Blocks.planks, 5, 2);
        world.setBlock(i + 18, j + 9, k + 34, Blocks.planks, 5, 2);
        world.setBlock(i + 19, j + 9, k + 34, Blocks.planks, 5, 2);
        world.setBlock(i + 20, j + 9, k + 34, Blocks.planks, 5, 2);
        world.setBlock(i + 21, j + 9, k + 34, Blocks.planks, 5, 2);
        world.setBlock(i + 22, j + 9, k + 34, Blocks.planks, 5, 2);
        world.setBlock(i + 23, j + 9, k + 34, Blocks.planks, 5, 2);
        world.setBlock(i + 24, j + 9, k + 34, Blocks.planks, 5, 2);
        world.setBlock(i + 25, j + 9, k + 34, Blocks.planks, 5, 2);
        world.setBlock(i + 26, j + 9, k + 34, Blocks.planks, 5, 2);
        world.setBlock(i + 27, j + 9, k + 34, Blocks.dark_oak_stairs, 1, 2);
        world.setBlock(i + 1, j + 9, k + 35, Blocks.dark_oak_stairs, 0, 2);
        world.setBlock(i + 2, j + 9, k + 35, Blocks.planks, 5, 2);
        world.setBlock(i + 3, j + 9, k + 35, Blocks.dark_oak_stairs, 5, 2);
        world.setBlock(i + 10, j + 9, k + 35, Blocks.planks, 5, 2);
        world.setBlock(i + 26, j + 9, k + 35, Blocks.planks, 5, 2);
        world.setBlock(i + 27, j + 9, k + 35, Blocks.dark_oak_stairs, 1, 2);
        world.setBlock(i + 1, j + 9, k + 36, Blocks.dark_oak_stairs, 0, 2);
        world.setBlock(i + 2, j + 9, k + 36, Blocks.planks, 5, 2);
        world.setBlock(i + 3, j + 9, k + 36, Blocks.dark_oak_stairs, 5, 2);
        world.setBlock(i + 10, j + 9, k + 36, Blocks.planks, 5, 2);
        world.setBlock(i + 26, j + 9, k + 36, Blocks.planks, 5, 2);
        world.setBlock(i + 27, j + 9, k + 36, Blocks.dark_oak_stairs, 1, 2);
        world.setBlock(i + 1, j + 9, k + 37, Blocks.dark_oak_stairs, 0, 2);
        world.setBlock(i + 2, j + 9, k + 37, Blocks.planks, 5, 2);
        world.setBlock(i + 3, j + 9, k + 37, Blocks.dark_oak_stairs, 5, 2);
        world.setBlock(i + 10, j + 9, k + 37, Blocks.planks, 5, 2);
        world.setBlock(i + 26, j + 9, k + 37, Blocks.planks, 5, 2);
        world.setBlock(i + 27, j + 9, k + 37, Blocks.dark_oak_stairs, 1, 2);
        world.setBlock(i + 1, j + 9, k + 38, Blocks.dark_oak_stairs, 0, 2);
        world.setBlock(i + 2, j + 9, k + 38, Blocks.planks, 5, 2);
        world.setBlock(i + 3, j + 9, k + 38, Blocks.dark_oak_stairs, 5, 2);
        world.setBlock(i + 10, j + 9, k + 38, Blocks.planks, 5, 2);
        world.setBlock(i + 26, j + 9, k + 38, Blocks.planks, 5, 2);
        world.setBlock(i + 27, j + 9, k + 38, Blocks.dark_oak_stairs, 1, 2);
        world.setBlock(i + 1, j + 9, k + 39, Blocks.dark_oak_stairs, 0, 2);
        world.setBlock(i + 2, j + 9, k + 39, Blocks.planks, 5, 2);
        world.setBlock(i + 3, j + 9, k + 39, Blocks.dark_oak_stairs, 5, 2);
        world.setBlock(i + 10, j + 9, k + 39, Blocks.planks, 5, 2);
        world.setBlock(i + 26, j + 9, k + 39, Blocks.planks, 5, 2);
        world.setBlock(i + 27, j + 9, k + 39, Blocks.dark_oak_stairs, 1, 2);
        world.setBlock(i + 1, j + 9, k + 40, Blocks.dark_oak_stairs, 0, 2);
        world.setBlock(i + 2, j + 9, k + 40, Blocks.planks, 5, 2);
        world.setBlock(i + 10, j + 9, k + 40, Blocks.planks, 5, 2);
        world.setBlock(i + 26, j + 9, k + 40, Blocks.planks, 5, 2);
        world.setBlock(i + 27, j + 9, k + 40, Blocks.dark_oak_stairs, 1, 2);
        world.setBlock(i + 1, j + 9, k + 41, Blocks.dark_oak_stairs, 0, 2);
        world.setBlock(i + 2, j + 9, k + 41, Blocks.planks, 5, 2);
        world.setBlock(i + 10, j + 9, k + 41, Blocks.planks, 5, 2);
        world.setBlock(i + 26, j + 9, k + 41, Blocks.planks, 5, 2);
        world.setBlock(i + 27, j + 9, k + 41, Blocks.dark_oak_stairs, 1, 2);
        world.setBlock(i + 1, j + 9, k + 42, Blocks.dark_oak_stairs, 0, 2);
        world.setBlock(i + 2, j + 9, k + 42, Blocks.planks, 5, 2);
        world.setBlock(i + 3, j + 9, k + 42, Blocks.planks, 5, 2);
        world.setBlock(i + 4, j + 9, k + 42, Blocks.dark_oak_stairs, 5, 2);
        world.setBlock(i + 8, j + 9, k + 42, Blocks.dark_oak_stairs, 4, 2);
        world.setBlock(i + 9, j + 9, k + 42, Blocks.planks, 5, 2);
        world.setBlock(i + 10, j + 9, k + 42, Blocks.planks, 5, 2);
        world.setBlock(i + 18, j + 9, k + 42, Blocks.fence, 0, 2);
        world.setBlock(i + 26, j + 9, k + 42, Blocks.planks, 5, 2);
        world.setBlock(i + 27, j + 9, k + 42, Blocks.dark_oak_stairs, 1, 2);
        world.setBlock(i + 1, j + 9, k + 43, Blocks.dark_oak_stairs, 0, 2);
        world.setBlock(i + 2, j + 9, k + 43, Blocks.planks, 5, 2);
        world.setBlock(i + 3, j + 9, k + 43, Blocks.dark_oak_stairs, 5, 2);
        world.setBlock(i + 10, j + 9, k + 43, Blocks.planks, 5, 2);
        world.setBlock(i + 26, j + 9, k + 43, Blocks.planks, 5, 2);
        world.setBlock(i + 27, j + 9, k + 43, Blocks.dark_oak_stairs, 1, 2);
        world.setBlock(i + 1, j + 9, k + 44, Blocks.dark_oak_stairs, 0, 2);
        world.setBlock(i + 2, j + 9, k + 44, Blocks.planks, 5, 2);
        world.setBlock(i + 3, j + 9, k + 44, Blocks.dark_oak_stairs, 5, 2);
        world.setBlock(i + 10, j + 9, k + 44, Blocks.planks, 5, 2);
        world.setBlock(i + 26, j + 9, k + 44, Blocks.planks, 5, 2);
        world.setBlock(i + 27, j + 9, k + 44, Blocks.dark_oak_stairs, 1, 2);
        world.setBlock(i + 1, j + 9, k + 45, Blocks.dark_oak_stairs, 0, 2);
        world.setBlock(i + 2, j + 9, k + 45, Blocks.planks, 5, 2);
        world.setBlock(i + 3, j + 9, k + 45, Blocks.dark_oak_stairs, 5, 2);
        world.setBlock(i + 10, j + 9, k + 45, Blocks.planks, 5, 2);
        world.setBlock(i + 26, j + 9, k + 45, Blocks.planks, 5, 2);
        world.setBlock(i + 27, j + 9, k + 45, Blocks.dark_oak_stairs, 1, 2);
        world.setBlock(i + 28, j + 9, k + 45, Blocks.dark_oak_stairs, 2, 2);
        world.setBlock(i + 29, j + 9, k + 45, Blocks.dark_oak_stairs, 2, 2);
        world.setBlock(i + 30, j + 9, k + 45, Blocks.dark_oak_stairs, 2, 2);
        world.setBlock(i + 31, j + 9, k + 45, Blocks.dark_oak_stairs, 2, 2);
        world.setBlock(i + 32, j + 9, k + 45, Blocks.dark_oak_stairs, 2, 2);
        world.setBlock(i + 33, j + 9, k + 45, Blocks.dark_oak_stairs, 2, 2);
        world.setBlock(i + 34, j + 9, k + 45, Blocks.dark_oak_stairs, 2, 2);
        world.setBlock(i + 35, j + 9, k + 45, Blocks.dark_oak_stairs, 1, 2);
        world.setBlock(i + 1, j + 9, k + 46, Blocks.dark_oak_stairs, 0, 2);
        world.setBlock(i + 2, j + 9, k + 46, Blocks.planks, 5, 2);
        world.setBlock(i + 3, j + 9, k + 46, Blocks.dark_oak_stairs, 5, 2);
        world.setBlock(i + 10, j + 9, k + 46, Blocks.planks, 5, 2);
        world.setBlock(i + 26, j + 9, k + 46, Blocks.planks, 5, 2);
        world.setBlock(i + 27, j + 9, k + 46, Blocks.planks, 5, 2);
        world.setBlock(i + 28, j + 9, k + 46, Blocks.planks, 5, 2);
        world.setBlock(i + 31, j + 9, k + 46, Blocks.planks, 5, 2);
        world.setBlock(i + 34, j + 9, k + 46, Blocks.planks, 5, 2);
        world.setBlock(i + 35, j + 9, k + 46, Blocks.dark_oak_stairs, 1, 2);
        world.setBlock(i + 1, j + 9, k + 47, Blocks.dark_oak_stairs, 0, 2);
        world.setBlock(i + 2, j + 9, k + 47, Blocks.planks, 5, 2);
        world.setBlock(i + 3, j + 9, k + 47, Blocks.dark_oak_stairs, 5, 2);
        world.setBlock(i + 10, j + 9, k + 47, Blocks.planks, 5, 2);
        world.setBlock(i + 26, j + 9, k + 47, Blocks.planks, 5, 2);
        world.setBlock(i + 27, j + 9, k + 47, Blocks.planks, 5, 2);
        world.setBlock(i + 28, j + 9, k + 47, Blocks.planks, 5, 2);
        world.setBlock(i + 31, j + 9, k + 47, Blocks.planks, 5, 2);
        world.setBlock(i + 34, j + 9, k + 47, Blocks.planks, 5, 2);
        world.setBlock(i + 35, j + 9, k + 47, Blocks.dark_oak_stairs, 1, 2);
        world.setBlock(i + 1, j + 9, k + 48, Blocks.dark_oak_stairs, 0, 2);
        world.setBlock(i + 2, j + 9, k + 48, Blocks.planks, 5, 2);
        world.setBlock(i + 10, j + 9, k + 48, Blocks.planks, 5, 2);
        world.setBlock(i + 26, j + 9, k + 48, Blocks.planks, 5, 2);
        world.setBlock(i + 27, j + 9, k + 48, Blocks.planks, 5, 2);
        world.setBlock(i + 28, j + 9, k + 48, Blocks.planks, 5, 2);
        world.setBlock(i + 31, j + 9, k + 48, Blocks.log2, 1, 2);
        world.setBlock(i + 32, j + 9, k + 48, Blocks.log2, 1, 2);
        world.setBlock(i + 34, j + 9, k + 48, Blocks.planks, 5, 2);
        world.setBlock(i + 35, j + 9, k + 48, Blocks.dark_oak_stairs, 1, 2);
        world.setBlock(i + 1, j + 9, k + 49, Blocks.dark_oak_stairs, 0, 2);
        world.setBlock(i + 2, j + 9, k + 49, Blocks.planks, 5, 2);
        world.setBlock(i + 10, j + 9, k + 49, Blocks.planks, 5, 2);
        world.setBlock(i + 26, j + 9, k + 49, Blocks.planks, 5, 2);
        world.setBlock(i + 27, j + 9, k + 49, Blocks.planks, 5, 2);
        world.setBlock(i + 28, j + 9, k + 49, Blocks.planks, 5, 2);
        world.setBlock(i + 29, j + 9, k + 49, Blocks.planks, 5, 2);
        world.setBlock(i + 30, j + 9, k + 49, Blocks.planks, 5, 2);
        world.setBlock(i + 31, j + 9, k + 49, Blocks.planks, 5, 2);
        world.setBlock(i + 32, j + 9, k + 49, Blocks.planks, 5, 2);
        world.setBlock(i + 33, j + 9, k + 49, Blocks.planks, 5, 2);
        world.setBlock(i + 34, j + 9, k + 49, Blocks.planks, 5, 2);
        world.setBlock(i + 35, j + 9, k + 49, Blocks.dark_oak_stairs, 1, 2);
        world.setBlock(i + 1, j + 9, k + 50, Blocks.dark_oak_stairs, 0, 2);
        world.setBlock(i + 2, j + 9, k + 50, Blocks.planks, 5, 2);
        world.setBlock(i + 3, j + 9, k + 50, Blocks.planks, 5, 2);
        world.setBlock(i + 4, j + 9, k + 50, Blocks.dark_oak_stairs, 5, 2);
        world.setBlock(i + 8, j + 9, k + 50, Blocks.dark_oak_stairs, 4, 2);
        world.setBlock(i + 9, j + 9, k + 50, Blocks.planks, 5, 2);
        world.setBlock(i + 10, j + 9, k + 50, Blocks.planks, 5, 2);
        world.setBlock(i + 11, j + 9, k + 50, Blocks.planks, 5, 2);
        world.setBlock(i + 12, j + 9, k + 50, Blocks.planks, 5, 2);
        world.setBlock(i + 13, j + 9, k + 50, Blocks.planks, 5, 2);
        world.setBlock(i + 14, j + 9, k + 50, Blocks.planks, 5, 2);
        world.setBlock(i + 15, j + 9, k + 50, Blocks.planks, 5, 2);
        world.setBlock(i + 16, j + 9, k + 50, Blocks.planks, 5, 2);
        world.setBlock(i + 17, j + 9, k + 50, Blocks.planks, 5, 2);
        world.setBlock(i + 18, j + 9, k + 50, Blocks.planks, 5, 2);
        world.setBlock(i + 19, j + 9, k + 50, Blocks.planks, 5, 2);
        world.setBlock(i + 20, j + 9, k + 50, Blocks.planks, 5, 2);
        world.setBlock(i + 21, j + 9, k + 50, Blocks.planks, 5, 2);
        world.setBlock(i + 22, j + 9, k + 50, Blocks.planks, 5, 2);
        world.setBlock(i + 23, j + 9, k + 50, Blocks.planks, 5, 2);
        world.setBlock(i + 24, j + 9, k + 50, Blocks.planks, 5, 2);
        world.setBlock(i + 25, j + 9, k + 50, Blocks.planks, 5, 2);
        world.setBlock(i + 26, j + 9, k + 50, Blocks.planks, 5, 2);
        world.setBlock(i + 27, j + 9, k + 50, Blocks.planks, 5, 2);
        world.setBlock(i + 28, j + 9, k + 50, Blocks.planks, 5, 2);
        world.setBlock(i + 29, j + 9, k + 50, Blocks.planks, 5, 2);
        world.setBlock(i + 30, j + 9, k + 50, Blocks.planks, 5, 2);
        world.setBlock(i + 31, j + 9, k + 50, Blocks.planks, 5, 2);
        world.setBlock(i + 32, j + 9, k + 50, Blocks.planks, 5, 2);
        world.setBlock(i + 33, j + 9, k + 50, Blocks.planks, 5, 2);
        world.setBlock(i + 34, j + 9, k + 50, Blocks.planks, 5, 2);
        world.setBlock(i + 35, j + 9, k + 50, Blocks.dark_oak_stairs, 1, 2);
        world.setBlock(i + 1, j + 9, k + 51, Blocks.dark_oak_stairs, 0, 2);
        world.setBlock(i + 2, j + 9, k + 51, Blocks.planks, 5, 2);
        world.setBlock(i + 3, j + 9, k + 51, Blocks.dark_oak_stairs, 5, 2);
        world.setBlock(i + 10, j + 9, k + 51, Blocks.planks, 5, 2);
        world.setBlock(i + 18, j + 9, k + 51, Blocks.planks, 5, 2);
        world.setBlock(i + 25, j + 9, k + 51, Blocks.dark_oak_stairs, 7, 2);
        world.setBlock(i + 26, j + 9, k + 51, Blocks.planks, 5, 2);
        world.setBlock(i + 27, j + 9, k + 51, Blocks.planks, 2, 2);
        world.setBlock(i + 28, j + 9, k + 51, Blocks.planks, 2, 2);
        world.setBlock(i + 29, j + 9, k + 51, Blocks.planks, 2, 2);
        world.setBlock(i + 30, j + 9, k + 51, Blocks.planks, 2, 2);
        world.setBlock(i + 31, j + 9, k + 51, Blocks.planks, 2, 2);
        world.setBlock(i + 32, j + 9, k + 51, Blocks.planks, 2, 2);
        world.setBlock(i + 33, j + 9, k + 51, Blocks.planks, 2, 2);
        world.setBlock(i + 34, j + 9, k + 51, Blocks.planks, 5, 2);
        world.setBlock(i + 35, j + 9, k + 51, Blocks.dark_oak_stairs, 1, 2);
        world.setBlock(i + 1, j + 9, k + 52, Blocks.dark_oak_stairs, 0, 2);
        world.setBlock(i + 2, j + 9, k + 52, Blocks.planks, 5, 2);
        world.setBlock(i + 3, j + 9, k + 52, Blocks.dark_oak_stairs, 5, 2);
        world.setBlock(i + 10, j + 9, k + 52, Blocks.dark_oak_stairs, 7, 2);
        world.setBlock(i + 18, j + 9, k + 52, Blocks.dark_oak_stairs, 7, 2);
        world.setBlock(i + 26, j + 9, k + 52, Blocks.planks, 5, 2);
        world.setBlock(i + 27, j + 9, k + 52, Blocks.planks, 2, 2);
        world.setBlock(i + 30, j + 9, k + 52, Blocks.birch_stairs, 7, 2);
        world.setBlock(i + 33, j + 9, k + 52, Blocks.planks, 2, 2);
        world.setBlock(i + 34, j + 9, k + 52, Blocks.planks, 5, 2);
        world.setBlock(i + 35, j + 9, k + 52, Blocks.dark_oak_stairs, 1, 2);
        world.setBlock(i + 1, j + 9, k + 53, Blocks.dark_oak_stairs, 0, 2);
        world.setBlock(i + 2, j + 9, k + 53, Blocks.planks, 5, 2);
        world.setBlock(i + 3, j + 9, k + 53, Blocks.dark_oak_stairs, 5, 2);
        world.setBlock(i + 26, j + 9, k + 53, Blocks.planks, 5, 2);
        world.setBlock(i + 27, j + 9, k + 53, Blocks.planks, 2, 2);
        world.setBlock(i + 30, j + 9, k + 53, Blocks.wooden_slab, 10, 2);
        world.setBlock(i + 33, j + 9, k + 53, Blocks.planks, 2, 2);
        world.setBlock(i + 34, j + 9, k + 53, Blocks.planks, 5, 2);
        world.setBlock(i + 35, j + 9, k + 53, Blocks.dark_oak_stairs, 1, 2);
        world.setBlock(i + 1, j + 9, k + 54, Blocks.dark_oak_stairs, 0, 2);
        world.setBlock(i + 2, j + 9, k + 54, Blocks.planks, 5, 2);
        world.setBlock(i + 3, j + 9, k + 54, Blocks.dark_oak_stairs, 5, 2);
        world.setBlock(i + 26, j + 9, k + 54, Blocks.planks, 5, 2);
        world.setBlock(i + 27, j + 9, k + 54, Blocks.planks, 2, 2);
        world.setBlock(i + 28, j + 9, k + 54, Blocks.birch_stairs, 5, 2);
        world.setBlock(i + 29, j + 9, k + 54, Blocks.wooden_slab, 10, 2);
        world.setBlock(i + 30, j + 9, k + 54, Blocks.wooden_slab, 10, 2);
        world.setBlock(i + 31, j + 9, k + 54, Blocks.wooden_slab, 10, 2);
        world.setBlock(i + 32, j + 9, k + 54, Blocks.birch_stairs, 4, 2);
        world.setBlock(i + 33, j + 9, k + 54, Blocks.planks, 2, 2);
        world.setBlock(i + 34, j + 9, k + 54, Blocks.planks, 5, 2);
        world.setBlock(i + 35, j + 9, k + 54, Blocks.dark_oak_stairs, 1, 2);
        world.setBlock(i + 1, j + 9, k + 55, Blocks.dark_oak_stairs, 0, 2);
        world.setBlock(i + 2, j + 9, k + 55, Blocks.planks, 5, 2);
        world.setBlock(i + 3, j + 9, k + 55, Blocks.dark_oak_stairs, 5, 2);
        world.setBlock(i + 26, j + 9, k + 55, Blocks.planks, 5, 2);
        world.setBlock(i + 27, j + 9, k + 55, Blocks.planks, 2, 2);
        world.setBlock(i + 30, j + 9, k + 55, Blocks.wooden_slab, 10, 2);
        world.setBlock(i + 33, j + 9, k + 55, Blocks.planks, 2, 2);
        world.setBlock(i + 34, j + 9, k + 55, Blocks.planks, 5, 2);
        world.setBlock(i + 35, j + 9, k + 55, Blocks.dark_oak_stairs, 1, 2);
        world.setBlock(i + 1, j + 9, k + 56, Blocks.dark_oak_stairs, 0, 2);
        world.setBlock(i + 2, j + 9, k + 56, Blocks.planks, 5, 2);
        world.setBlock(i + 3, j + 9, k + 56, Blocks.dark_oak_stairs, 5, 2);
        world.setBlock(i + 10, j + 9, k + 56, Blocks.dark_oak_stairs, 6, 2);
        world.setBlock(i + 18, j + 9, k + 56, Blocks.dark_oak_stairs, 6, 2);
        world.setBlock(i + 26, j + 9, k + 56, Blocks.planks, 5, 2);
        world.setBlock(i + 27, j + 9, k + 56, Blocks.planks, 2, 2);
        world.setBlock(i + 30, j + 9, k + 56, Blocks.birch_stairs, 6, 2);
        world.setBlock(i + 33, j + 9, k + 56, Blocks.planks, 2, 2);
        world.setBlock(i + 34, j + 9, k + 56, Blocks.planks, 5, 2);
        world.setBlock(i + 35, j + 9, k + 56, Blocks.dark_oak_stairs, 1, 2);
        world.setBlock(i + 1, j + 9, k + 57, Blocks.dark_oak_stairs, 0, 2);
        world.setBlock(i + 2, j + 9, k + 57, Blocks.planks, 5, 2);
        world.setBlock(i + 3, j + 9, k + 57, Blocks.dark_oak_stairs, 5, 2);
        world.setBlock(i + 10, j + 9, k + 57, Blocks.planks, 5, 2);
        world.setBlock(i + 18, j + 9, k + 57, Blocks.planks, 5, 2);
        world.setBlock(i + 25, j + 9, k + 57, Blocks.dark_oak_stairs, 4, 2);
        world.setBlock(i + 26, j + 9, k + 57, Blocks.planks, 5, 2);
        world.setBlock(i + 27, j + 9, k + 57, Blocks.planks, 2, 2);
        world.setBlock(i + 28, j + 9, k + 57, Blocks.planks, 2, 2);
        world.setBlock(i + 29, j + 9, k + 57, Blocks.planks, 2, 2);
        world.setBlock(i + 30, j + 9, k + 57, Blocks.planks, 2, 2);
        world.setBlock(i + 31, j + 9, k + 57, Blocks.planks, 2, 2);
        world.setBlock(i + 32, j + 9, k + 57, Blocks.planks, 2, 2);
        world.setBlock(i + 33, j + 9, k + 57, Blocks.planks, 2, 2);
        world.setBlock(i + 34, j + 9, k + 57, Blocks.planks, 5, 2);
        world.setBlock(i + 35, j + 9, k + 57, Blocks.dark_oak_stairs, 1, 2);
        world.setBlock(i + 1, j + 9, k + 58, Blocks.dark_oak_stairs, 0, 2);
        world.setBlock(i + 2, j + 9, k + 58, Blocks.planks, 5, 2);
        world.setBlock(i + 3, j + 9, k + 58, Blocks.planks, 5, 2);
        world.setBlock(i + 4, j + 9, k + 58, Blocks.planks, 5, 2);
        world.setBlock(i + 5, j + 9, k + 58, Blocks.planks, 5, 2);
        world.setBlock(i + 6, j + 9, k + 58, Blocks.planks, 5, 2);
        world.setBlock(i + 7, j + 9, k + 58, Blocks.planks, 5, 2);
        world.setBlock(i + 8, j + 9, k + 58, Blocks.planks, 5, 2);
        world.setBlock(i + 9, j + 9, k + 58, Blocks.planks, 5, 2);
        world.setBlock(i + 10, j + 9, k + 58, Blocks.planks, 5, 2);
        world.setBlock(i + 11, j + 9, k + 58, Blocks.planks, 5, 2);
        world.setBlock(i + 12, j + 9, k + 58, Blocks.planks, 5, 2);
        world.setBlock(i + 13, j + 9, k + 58, Blocks.planks, 5, 2);
        world.setBlock(i + 14, j + 9, k + 58, Blocks.planks, 5, 2);
        world.setBlock(i + 15, j + 9, k + 58, Blocks.planks, 5, 2);
        world.setBlock(i + 16, j + 9, k + 58, Blocks.planks, 5, 2);
        world.setBlock(i + 17, j + 9, k + 58, Blocks.planks, 5, 2);
        world.setBlock(i + 18, j + 9, k + 58, Blocks.planks, 5, 2);
        world.setBlock(i + 19, j + 9, k + 58, Blocks.planks, 5, 2);
        world.setBlock(i + 20, j + 9, k + 58, Blocks.planks, 5, 2);
        world.setBlock(i + 21, j + 9, k + 58, Blocks.planks, 5, 2);
        world.setBlock(i + 22, j + 9, k + 58, Blocks.planks, 5, 2);
        world.setBlock(i + 23, j + 9, k + 58, Blocks.planks, 5, 2);
        world.setBlock(i + 24, j + 9, k + 58, Blocks.planks, 5, 2);
        world.setBlock(i + 25, j + 9, k + 58, Blocks.planks, 5, 2);
        world.setBlock(i + 26, j + 9, k + 58, Blocks.planks, 5, 2);
        world.setBlock(i + 27, j + 9, k + 58, Blocks.planks, 5, 2);
        world.setBlock(i + 28, j + 9, k + 58, Blocks.planks, 5, 2);
        world.setBlock(i + 29, j + 9, k + 58, Blocks.planks, 5, 2);
        world.setBlock(i + 30, j + 9, k + 58, Blocks.planks, 5, 2);
        world.setBlock(i + 31, j + 9, k + 58, Blocks.planks, 5, 2);
        world.setBlock(i + 32, j + 9, k + 58, Blocks.planks, 5, 2);
        world.setBlock(i + 33, j + 9, k + 58, Blocks.planks, 5, 2);
        world.setBlock(i + 34, j + 9, k + 58, Blocks.planks, 5, 2);
        world.setBlock(i + 35, j + 9, k + 58, Blocks.dark_oak_stairs, 1, 2);
        world.setBlock(i + 1, j + 9, k + 59, Blocks.dark_oak_stairs, 0, 2);
        world.setBlock(i + 2, j + 9, k + 59, Blocks.planks, 5, 2);
        world.setBlock(i + 10, j + 9, k + 59, Blocks.planks, 5, 2);
        world.setBlock(i + 26, j + 9, k + 59, Blocks.planks, 5, 2);
        world.setBlock(i + 27, j + 9, k + 59, Blocks.dark_oak_stairs, 1, 2);
        world.setBlock(i + 28, j + 9, k + 59, Blocks.dark_oak_stairs, 3, 2);
        world.setBlock(i + 29, j + 9, k + 59, Blocks.dark_oak_stairs, 3, 2);
        world.setBlock(i + 30, j + 9, k + 59, Blocks.dark_oak_stairs, 3, 2);
        world.setBlock(i + 31, j + 9, k + 59, Blocks.dark_oak_stairs, 3, 2);
        world.setBlock(i + 32, j + 9, k + 59, Blocks.dark_oak_stairs, 3, 2);
        world.setBlock(i + 33, j + 9, k + 59, Blocks.dark_oak_stairs, 3, 2);
        world.setBlock(i + 34, j + 9, k + 59, Blocks.dark_oak_stairs, 3, 2);
        world.setBlock(i + 35, j + 9, k + 59, Blocks.dark_oak_stairs, 3, 2);
        world.setBlock(i + 1, j + 9, k + 60, Blocks.dark_oak_stairs, 0, 2);
        world.setBlock(i + 2, j + 9, k + 60, Blocks.planks, 5, 2);
        world.setBlock(i + 10, j + 9, k + 60, Blocks.planks, 5, 2);
        world.setBlock(i + 26, j + 9, k + 60, Blocks.planks, 5, 2);
        world.setBlock(i + 27, j + 9, k + 60, Blocks.dark_oak_stairs, 1, 2);
        world.setBlock(i + 1, j + 9, k + 61, Blocks.dark_oak_stairs, 0, 2);
        world.setBlock(i + 2, j + 9, k + 61, Blocks.planks, 5, 2);
        world.setBlock(i + 10, j + 9, k + 61, Blocks.planks, 5, 2);
        world.setBlock(i + 26, j + 9, k + 61, Blocks.planks, 5, 2);
        world.setBlock(i + 27, j + 9, k + 61, Blocks.dark_oak_stairs, 1, 2);
        world.setBlock(i + 1, j + 9, k + 62, Blocks.dark_oak_stairs, 0, 2);
        world.setBlock(i + 2, j + 9, k + 62, Blocks.planks, 5, 2);
        world.setBlock(i + 10, j + 9, k + 62, Blocks.planks, 5, 2);
        world.setBlock(i + 18, j + 9, k + 62, Blocks.fence, 0, 2);
        world.setBlock(i + 26, j + 9, k + 62, Blocks.planks, 5, 2);
        world.setBlock(i + 27, j + 9, k + 62, Blocks.dark_oak_stairs, 1, 2);
        world.setBlock(i + 1, j + 9, k + 63, Blocks.dark_oak_stairs, 0, 2);
        world.setBlock(i + 2, j + 9, k + 63, Blocks.planks, 5, 2);
        world.setBlock(i + 10, j + 9, k + 63, Blocks.planks, 5, 2);
        world.setBlock(i + 26, j + 9, k + 63, Blocks.planks, 5, 2);
        world.setBlock(i + 27, j + 9, k + 63, Blocks.dark_oak_stairs, 1, 2);
        world.setBlock(i + 1, j + 9, k + 64, Blocks.dark_oak_stairs, 0, 2);
        world.setBlock(i + 2, j + 9, k + 64, Blocks.planks, 5, 2);
        world.setBlock(i + 10, j + 9, k + 64, Blocks.planks, 5, 2);
        world.setBlock(i + 26, j + 9, k + 64, Blocks.planks, 5, 2);
        world.setBlock(i + 27, j + 9, k + 64, Blocks.dark_oak_stairs, 1, 2);
        world.setBlock(i + 1, j + 9, k + 65, Blocks.dark_oak_stairs, 0, 2);
        world.setBlock(i + 2, j + 9, k + 65, Blocks.planks, 5, 2);
        world.setBlock(i + 10, j + 9, k + 65, Blocks.planks, 5, 2);
        world.setBlock(i + 26, j + 9, k + 65, Blocks.planks, 5, 2);
        world.setBlock(i + 27, j + 9, k + 65, Blocks.dark_oak_stairs, 1, 2);
        world.setBlock(i + 1, j + 9, k + 66, Blocks.dark_oak_stairs, 0, 2);
        world.setBlock(i + 2, j + 9, k + 66, Blocks.planks, 5, 2);
        world.setBlock(i + 10, j + 9, k + 66, Blocks.planks, 5, 2);
        world.setBlock(i + 26, j + 9, k + 66, Blocks.planks, 5, 2);
        world.setBlock(i + 27, j + 9, k + 66, Blocks.dark_oak_stairs, 1, 2);
        world.setBlock(i + 1, j + 9, k + 67, Blocks.dark_oak_stairs, 0, 2);
        world.setBlock(i + 2, j + 9, k + 67, Blocks.planks, 5, 2);
        world.setBlock(i + 10, j + 9, k + 67, Blocks.planks, 5, 2);
        world.setBlock(i + 26, j + 9, k + 67, Blocks.planks, 5, 2);
        world.setBlock(i + 27, j + 9, k + 67, Blocks.dark_oak_stairs, 1, 2);
        world.setBlock(i + 1, j + 9, k + 68, Blocks.dark_oak_stairs, 0, 2);
        world.setBlock(i + 2, j + 9, k + 68, Blocks.planks, 5, 2);
        world.setBlock(i + 10, j + 9, k + 68, Blocks.planks, 5, 2);
        world.setBlock(i + 26, j + 9, k + 68, Blocks.planks, 5, 2);
        world.setBlock(i + 27, j + 9, k + 68, Blocks.dark_oak_stairs, 1, 2);
        world.setBlock(i + 1, j + 9, k + 69, Blocks.dark_oak_stairs, 0, 2);
        world.setBlock(i + 2, j + 9, k + 69, Blocks.planks, 5, 2);
        world.setBlock(i + 10, j + 9, k + 69, Blocks.planks, 5, 2);
        world.setBlock(i + 26, j + 9, k + 69, Blocks.planks, 5, 2);
        world.setBlock(i + 27, j + 9, k + 69, Blocks.dark_oak_stairs, 1, 2);
        world.setBlock(i + 1, j + 9, k + 70, Blocks.dark_oak_stairs, 0, 2);
        world.setBlock(i + 2, j + 9, k + 70, Blocks.planks, 5, 2);
        world.setBlock(i + 10, j + 9, k + 70, Blocks.planks, 5, 2);
        world.setBlock(i + 18, j + 9, k + 70, Blocks.fence, 0, 2);
        world.setBlock(i + 26, j + 9, k + 70, Blocks.planks, 5, 2);
        world.setBlock(i + 27, j + 9, k + 70, Blocks.dark_oak_stairs, 1, 2);
        world.setBlock(i + 1, j + 9, k + 71, Blocks.dark_oak_stairs, 0, 2);
        world.setBlock(i + 2, j + 9, k + 71, Blocks.planks, 5, 2);
        world.setBlock(i + 6, j + 9, k + 71, Blocks.stone_stairs, 6, 2);
        world.setBlock(i + 10, j + 9, k + 71, Blocks.planks, 5, 2);
        world.setBlock(i + 26, j + 9, k + 71, Blocks.planks, 5, 2);
        world.setBlock(i + 27, j + 9, k + 71, Blocks.dark_oak_stairs, 1, 2);
        world.setBlock(i + 1, j + 9, k + 72, Blocks.dark_oak_stairs, 0, 2);
        world.setBlock(i + 2, j + 9, k + 72, Blocks.planks, 5, 2);
        world.setBlock(i + 5, j + 9, k + 72, Blocks.cobblestone, 0, 2);
        world.setBlock(i + 6, j + 9, k + 72, Blocks.cobblestone, 0, 2);
        world.setBlock(i + 7, j + 9, k + 72, Blocks.cobblestone, 0, 2);
        world.setBlock(i + 10, j + 9, k + 72, Blocks.planks, 5, 2);
        world.setBlock(i + 26, j + 9, k + 72, Blocks.planks, 5, 2);
        world.setBlock(i + 27, j + 9, k + 72, Blocks.dark_oak_stairs, 1, 2);
        world.setBlock(i + 1, j + 9, k + 73, Blocks.dark_oak_stairs, 0, 2);
        world.setBlock(i + 2, j + 9, k + 73, Blocks.planks, 5, 2);
        world.setBlock(i + 4, j + 9, k + 73, Blocks.cobblestone, 0, 2);
        world.setBlock(i + 5, j + 9, k + 73, Blocks.cobblestone, 0, 2);
        world.setBlock(i + 6, j + 9, k + 73, Blocks.cobblestone, 0, 2);
        world.setBlock(i + 7, j + 9, k + 73, Blocks.cobblestone, 0, 2);
        world.setBlock(i + 8, j + 9, k + 73, Blocks.cobblestone, 0, 2);
        world.setBlock(i + 10, j + 9, k + 73, Blocks.planks, 5, 2);
        world.setBlock(i + 26, j + 9, k + 73, Blocks.planks, 5, 2);
        world.setBlock(i + 27, j + 9, k + 73, Blocks.dark_oak_stairs, 1, 2);
        world.setBlock(i + 1, j + 9, k + 74, Blocks.dark_oak_stairs, 0, 2);
        world.setBlock(i + 2, j + 9, k + 74, Blocks.planks, 5, 2);
        world.setBlock(i + 3, j + 9, k + 74, Blocks.planks, 5, 2);
        world.setBlock(i + 4, j + 9, k + 74, Blocks.planks, 5, 2);
        world.setBlock(i + 5, j + 9, k + 74, Blocks.planks, 5, 2);
        world.setBlock(i + 6, j + 9, k + 74, Blocks.planks, 5, 2);
        world.setBlock(i + 7, j + 9, k + 74, Blocks.planks, 5, 2);
        world.setBlock(i + 8, j + 9, k + 74, Blocks.planks, 5, 2);
        world.setBlock(i + 9, j + 9, k + 74, Blocks.planks, 5, 2);
        world.setBlock(i + 10, j + 9, k + 74, Blocks.planks, 5, 2);
        world.setBlock(i + 11, j + 9, k + 74, Blocks.planks, 5, 2);
        world.setBlock(i + 12, j + 9, k + 74, Blocks.planks, 5, 2);
        world.setBlock(i + 13, j + 9, k + 74, Blocks.planks, 5, 2);
        world.setBlock(i + 14, j + 9, k + 74, Blocks.planks, 5, 2);
        world.setBlock(i + 15, j + 9, k + 74, Blocks.planks, 5, 2);
        world.setBlock(i + 16, j + 9, k + 74, Blocks.planks, 5, 2);
        world.setBlock(i + 17, j + 9, k + 74, Blocks.planks, 5, 2);
        world.setBlock(i + 18, j + 9, k + 74, Blocks.planks, 5, 2);
        world.setBlock(i + 19, j + 9, k + 74, Blocks.planks, 5, 2);
        world.setBlock(i + 20, j + 9, k + 74, Blocks.planks, 5, 2);
        world.setBlock(i + 21, j + 9, k + 74, Blocks.planks, 5, 2);
        world.setBlock(i + 22, j + 9, k + 74, Blocks.planks, 5, 2);
        world.setBlock(i + 23, j + 9, k + 74, Blocks.planks, 5, 2);
        world.setBlock(i + 24, j + 9, k + 74, Blocks.planks, 5, 2);
        world.setBlock(i + 25, j + 9, k + 74, Blocks.planks, 5, 2);
        world.setBlock(i + 26, j + 9, k + 74, Blocks.planks, 5, 2);
        world.setBlock(i + 27, j + 9, k + 74, Blocks.dark_oak_stairs, 1, 2);
        world.setBlock(i + 1, j + 9, k + 75, Blocks.dark_oak_stairs, 0, 2);
        world.setBlock(i + 2, j + 9, k + 75, Blocks.dark_oak_stairs, 3, 2);
        world.setBlock(i + 3, j + 9, k + 75, Blocks.dark_oak_stairs, 3, 2);
        world.setBlock(i + 4, j + 9, k + 75, Blocks.dark_oak_stairs, 3, 2);
        world.setBlock(i + 5, j + 9, k + 75, Blocks.dark_oak_stairs, 3, 2);
        world.setBlock(i + 6, j + 9, k + 75, Blocks.dark_oak_stairs, 3, 2);
        world.setBlock(i + 7, j + 9, k + 75, Blocks.dark_oak_stairs, 3, 2);
        world.setBlock(i + 8, j + 9, k + 75, Blocks.dark_oak_stairs, 3, 2);
        world.setBlock(i + 9, j + 9, k + 75, Blocks.dark_oak_stairs, 3, 2);
        world.setBlock(i + 10, j + 9, k + 75, Blocks.dark_oak_stairs, 3, 2);
        world.setBlock(i + 11, j + 9, k + 75, Blocks.dark_oak_stairs, 3, 2);
        world.setBlock(i + 12, j + 9, k + 75, Blocks.dark_oak_stairs, 3, 2);
        world.setBlock(i + 13, j + 9, k + 75, Blocks.dark_oak_stairs, 3, 2);
        world.setBlock(i + 14, j + 9, k + 75, Blocks.dark_oak_stairs, 3, 2);
        world.setBlock(i + 15, j + 9, k + 75, Blocks.dark_oak_stairs, 3, 2);
        world.setBlock(i + 16, j + 9, k + 75, Blocks.dark_oak_stairs, 3, 2);
        world.setBlock(i + 17, j + 9, k + 75, Blocks.dark_oak_stairs, 3, 2);
        world.setBlock(i + 18, j + 9, k + 75, Blocks.dark_oak_stairs, 3, 2);
        world.setBlock(i + 19, j + 9, k + 75, Blocks.dark_oak_stairs, 3, 2);
        world.setBlock(i + 20, j + 9, k + 75, Blocks.dark_oak_stairs, 3, 2);
        world.setBlock(i + 21, j + 9, k + 75, Blocks.dark_oak_stairs, 3, 2);
        world.setBlock(i + 22, j + 9, k + 75, Blocks.dark_oak_stairs, 3, 2);
        world.setBlock(i + 23, j + 9, k + 75, Blocks.dark_oak_stairs, 3, 2);
        world.setBlock(i + 24, j + 9, k + 75, Blocks.dark_oak_stairs, 3, 2);
        world.setBlock(i + 25, j + 9, k + 75, Blocks.dark_oak_stairs, 3, 2);
        world.setBlock(i + 26, j + 9, k + 75, Blocks.dark_oak_stairs, 3, 2);
        world.setBlock(i + 27, j + 9, k + 75, Blocks.dark_oak_stairs, 3, 2);
        world.setBlock(i + 2, j + 10, k + 2, Blocks.dark_oak_stairs, 2, 2);
        world.setBlock(i + 3, j + 10, k + 2, Blocks.dark_oak_stairs, 2, 2);
        world.setBlock(i + 4, j + 10, k + 2, Blocks.dark_oak_stairs, 2, 2);
        world.setBlock(i + 5, j + 10, k + 2, Blocks.dark_oak_stairs, 2, 2);
        world.setBlock(i + 6, j + 10, k + 2, Blocks.dark_oak_stairs, 2, 2);
        world.setBlock(i + 7, j + 10, k + 2, Blocks.dark_oak_stairs, 2, 2);
        world.setBlock(i + 8, j + 10, k + 2, Blocks.dark_oak_stairs, 2, 2);
        world.setBlock(i + 9, j + 10, k + 2, Blocks.dark_oak_stairs, 2, 2);
        world.setBlock(i + 10, j + 10, k + 2, Blocks.dark_oak_stairs, 2, 2);
        world.setBlock(i + 11, j + 10, k + 2, Blocks.dark_oak_stairs, 2, 2);
        world.setBlock(i + 12, j + 10, k + 2, Blocks.dark_oak_stairs, 2, 2);
        world.setBlock(i + 13, j + 10, k + 2, Blocks.dark_oak_stairs, 2, 2);
        world.setBlock(i + 14, j + 10, k + 2, Blocks.dark_oak_stairs, 2, 2);
        world.setBlock(i + 15, j + 10, k + 2, Blocks.dark_oak_stairs, 2, 2);
        world.setBlock(i + 16, j + 10, k + 2, Blocks.dark_oak_stairs, 2, 2);
        world.setBlock(i + 17, j + 10, k + 2, Blocks.dark_oak_stairs, 2, 2);
        world.setBlock(i + 18, j + 10, k + 2, Blocks.dark_oak_stairs, 1, 2);
        world.setBlock(i + 2, j + 10, k + 3, Blocks.dark_oak_stairs, 0, 2);
        world.setBlock(i + 3, j + 10, k + 3, Blocks.planks, 5, 2);
        world.setBlock(i + 4, j + 10, k + 3, Blocks.planks, 5, 2);
        world.setBlock(i + 5, j + 10, k + 3, Blocks.planks, 5, 2);
        world.setBlock(i + 6, j + 10, k + 3, Blocks.planks, 5, 2);
        world.setBlock(i + 7, j + 10, k + 3, Blocks.planks, 5, 2);
        world.setBlock(i + 8, j + 10, k + 3, Blocks.planks, 5, 2);
        world.setBlock(i + 9, j + 10, k + 3, Blocks.planks, 5, 2);
        world.setBlock(i + 10, j + 10, k + 3, Blocks.planks, 5, 2);
        world.setBlock(i + 11, j + 10, k + 3, Blocks.planks, 5, 2);
        world.setBlock(i + 12, j + 10, k + 3, Blocks.planks, 5, 2);
        world.setBlock(i + 13, j + 10, k + 3, Blocks.planks, 5, 2);
        world.setBlock(i + 14, j + 10, k + 3, Blocks.planks, 5, 2);
        world.setBlock(i + 15, j + 10, k + 3, Blocks.planks, 5, 2);
        world.setBlock(i + 16, j + 10, k + 3, Blocks.planks, 5, 2);
        world.setBlock(i + 17, j + 10, k + 3, Blocks.planks, 5, 2);
        world.setBlock(i + 18, j + 10, k + 3, Blocks.dark_oak_stairs, 1, 2);
        world.setBlock(i + 2, j + 10, k + 4, Blocks.dark_oak_stairs, 0, 2);
        world.setBlock(i + 3, j + 10, k + 4, Blocks.planks, 5, 2);
        world.setBlock(i + 4, j + 10, k + 4, Blocks.planks, 5, 2);
        world.setBlock(i + 5, j + 10, k + 4, Blocks.planks, 5, 2);
        world.setBlock(i + 6, j + 10, k + 4, Blocks.planks, 5, 2);
        world.setBlock(i + 7, j + 10, k + 4, Blocks.planks, 5, 2);
        world.setBlock(i + 8, j + 10, k + 4, Blocks.planks, 5, 2);
        world.setBlock(i + 9, j + 10, k + 4, Blocks.planks, 5, 2);
        world.setBlock(i + 10, j + 10, k + 4, Blocks.planks, 5, 2);
        world.setBlock(i + 11, j + 10, k + 4, Blocks.planks, 5, 2);
        world.setBlock(i + 12, j + 10, k + 4, Blocks.planks, 5, 2);
        world.setBlock(i + 13, j + 10, k + 4, Blocks.planks, 5, 2);
        world.setBlock(i + 14, j + 10, k + 4, Blocks.planks, 5, 2);
        world.setBlock(i + 15, j + 10, k + 4, Blocks.planks, 5, 2);
        world.setBlock(i + 16, j + 10, k + 4, Blocks.planks, 5, 2);
        world.setBlock(i + 17, j + 10, k + 4, Blocks.planks, 5, 2);
        world.setBlock(i + 18, j + 10, k + 4, Blocks.dark_oak_stairs, 1, 2);
        world.setBlock(i + 2, j + 10, k + 5, Blocks.dark_oak_stairs, 0, 2);
        world.setBlock(i + 3, j + 10, k + 5, Blocks.planks, 5, 2);
        world.setBlock(i + 4, j + 10, k + 5, Blocks.planks, 5, 2);
        world.setBlock(i + 5, j + 10, k + 5, Blocks.planks, 5, 2);
        world.setBlock(i + 6, j + 10, k + 5, Blocks.planks, 5, 2);
        world.setBlock(i + 7, j + 10, k + 5, Blocks.planks, 5, 2);
        world.setBlock(i + 8, j + 10, k + 5, Blocks.planks, 5, 2);
        world.setBlock(i + 9, j + 10, k + 5, Blocks.planks, 5, 2);
        world.setBlock(i + 10, j + 10, k + 5, Blocks.planks, 5, 2);
        world.setBlock(i + 11, j + 10, k + 5, Blocks.planks, 5, 2);
        world.setBlock(i + 12, j + 10, k + 5, Blocks.planks, 5, 2);
        world.setBlock(i + 13, j + 10, k + 5, Blocks.planks, 5, 2);
        world.setBlock(i + 14, j + 10, k + 5, Blocks.planks, 5, 2);
        world.setBlock(i + 15, j + 10, k + 5, Blocks.planks, 5, 2);
        world.setBlock(i + 16, j + 10, k + 5, Blocks.planks, 5, 2);
        world.setBlock(i + 17, j + 10, k + 5, Blocks.planks, 5, 2);
        world.setBlock(i + 18, j + 10, k + 5, Blocks.dark_oak_stairs, 1, 2);
        world.setBlock(i + 2, j + 10, k + 6, Blocks.dark_oak_stairs, 0, 2);
        world.setBlock(i + 3, j + 10, k + 6, Blocks.planks, 5, 2);
        world.setBlock(i + 4, j + 10, k + 6, Blocks.planks, 5, 2);
        world.setBlock(i + 5, j + 10, k + 6, Blocks.planks, 5, 2);
        world.setBlock(i + 6, j + 10, k + 6, Blocks.planks, 5, 2);
        world.setBlock(i + 7, j + 10, k + 6, Blocks.planks, 5, 2);
        world.setBlock(i + 8, j + 10, k + 6, Blocks.planks, 5, 2);
        world.setBlock(i + 9, j + 10, k + 6, Blocks.planks, 5, 2);
        world.setBlock(i + 10, j + 10, k + 6, Blocks.planks, 5, 2);
        world.setBlock(i + 11, j + 10, k + 6, Blocks.planks, 5, 2);
        world.setBlock(i + 12, j + 10, k + 6, Blocks.planks, 5, 2);
        world.setBlock(i + 13, j + 10, k + 6, Blocks.planks, 5, 2);
        world.setBlock(i + 14, j + 10, k + 6, Blocks.planks, 5, 2);
        world.setBlock(i + 15, j + 10, k + 6, Blocks.planks, 5, 2);
        world.setBlock(i + 16, j + 10, k + 6, Blocks.planks, 5, 2);
        world.setBlock(i + 17, j + 10, k + 6, Blocks.planks, 5, 2);
        world.setBlock(i + 18, j + 10, k + 6, Blocks.dark_oak_stairs, 1, 2);
        world.setBlock(i + 2, j + 10, k + 7, Blocks.dark_oak_stairs, 0, 2);
        world.setBlock(i + 3, j + 10, k + 7, Blocks.planks, 5, 2);
        world.setBlock(i + 4, j + 10, k + 7, Blocks.planks, 5, 2);
        world.setBlock(i + 5, j + 10, k + 7, Blocks.planks, 5, 2);
        world.setBlock(i + 6, j + 10, k + 7, Blocks.planks, 5, 2);
        world.setBlock(i + 7, j + 10, k + 7, Blocks.planks, 5, 2);
        world.setBlock(i + 8, j + 10, k + 7, Blocks.planks, 5, 2);
        world.setBlock(i + 9, j + 10, k + 7, Blocks.planks, 5, 2);
        world.setBlock(i + 10, j + 10, k + 7, Blocks.planks, 5, 2);
        world.setBlock(i + 11, j + 10, k + 7, Blocks.planks, 5, 2);
        world.setBlock(i + 12, j + 10, k + 7, Blocks.planks, 5, 2);
        world.setBlock(i + 13, j + 10, k + 7, Blocks.planks, 5, 2);
        world.setBlock(i + 14, j + 10, k + 7, Blocks.planks, 5, 2);
        world.setBlock(i + 15, j + 10, k + 7, Blocks.planks, 5, 2);
        world.setBlock(i + 16, j + 10, k + 7, Blocks.planks, 5, 2);
        world.setBlock(i + 17, j + 10, k + 7, Blocks.planks, 5, 2);
        world.setBlock(i + 18, j + 10, k + 7, Blocks.dark_oak_stairs, 1, 2);
        world.setBlock(i + 2, j + 10, k + 8, Blocks.dark_oak_stairs, 0, 2);
        world.setBlock(i + 3, j + 10, k + 8, Blocks.planks, 5, 2);
        world.setBlock(i + 4, j + 10, k + 8, Blocks.planks, 5, 2);
        world.setBlock(i + 5, j + 10, k + 8, Blocks.planks, 5, 2);
        world.setBlock(i + 6, j + 10, k + 8, Blocks.planks, 5, 2);
        world.setBlock(i + 7, j + 10, k + 8, Blocks.planks, 5, 2);
        world.setBlock(i + 8, j + 10, k + 8, Blocks.planks, 5, 2);
        world.setBlock(i + 9, j + 10, k + 8, Blocks.planks, 5, 2);
        world.setBlock(i + 10, j + 10, k + 8, Blocks.planks, 5, 2);
        world.setBlock(i + 11, j + 10, k + 8, Blocks.planks, 5, 2);
        world.setBlock(i + 12, j + 10, k + 8, Blocks.planks, 5, 2);
        world.setBlock(i + 13, j + 10, k + 8, Blocks.planks, 5, 2);
        world.setBlock(i + 14, j + 10, k + 8, Blocks.planks, 5, 2);
        world.setBlock(i + 15, j + 10, k + 8, Blocks.planks, 5, 2);
        world.setBlock(i + 16, j + 10, k + 8, Blocks.planks, 5, 2);
        world.setBlock(i + 17, j + 10, k + 8, Blocks.planks, 5, 2);
        world.setBlock(i + 18, j + 10, k + 8, Blocks.dark_oak_stairs, 1, 2);
        world.setBlock(i + 2, j + 10, k + 9, Blocks.dark_oak_stairs, 0, 2);
        world.setBlock(i + 3, j + 10, k + 9, Blocks.planks, 5, 2);
        world.setBlock(i + 4, j + 10, k + 9, Blocks.planks, 5, 2);
        world.setBlock(i + 5, j + 10, k + 9, Blocks.planks, 5, 2);
        world.setBlock(i + 6, j + 10, k + 9, Blocks.planks, 5, 2);
        world.setBlock(i + 7, j + 10, k + 9, Blocks.planks, 5, 2);
        world.setBlock(i + 8, j + 10, k + 9, Blocks.planks, 5, 2);
        world.setBlock(i + 9, j + 10, k + 9, Blocks.planks, 5, 2);
        world.setBlock(i + 10, j + 10, k + 9, Blocks.planks, 5, 2);
        world.setBlock(i + 11, j + 10, k + 9, Blocks.planks, 5, 2);
        world.setBlock(i + 12, j + 10, k + 9, Blocks.planks, 5, 2);
        world.setBlock(i + 13, j + 10, k + 9, Blocks.planks, 5, 2);
        world.setBlock(i + 14, j + 10, k + 9, Blocks.planks, 5, 2);
        world.setBlock(i + 15, j + 10, k + 9, Blocks.planks, 5, 2);
        world.setBlock(i + 16, j + 10, k + 9, Blocks.planks, 5, 2);
        world.setBlock(i + 17, j + 10, k + 9, Blocks.planks, 5, 2);
        world.setBlock(i + 18, j + 10, k + 9, Blocks.dark_oak_stairs, 1, 2);
        world.setBlock(i + 2, j + 10, k + 10, Blocks.dark_oak_stairs, 0, 2);
        world.setBlock(i + 3, j + 10, k + 10, Blocks.planks, 5, 2);
        world.setBlock(i + 4, j + 10, k + 10, Blocks.planks, 5, 2);
        world.setBlock(i + 5, j + 10, k + 10, Blocks.planks, 5, 2);
        world.setBlock(i + 6, j + 10, k + 10, Blocks.planks, 5, 2);
        world.setBlock(i + 7, j + 10, k + 10, Blocks.planks, 5, 2);
        world.setBlock(i + 8, j + 10, k + 10, Blocks.planks, 5, 2);
        world.setBlock(i + 9, j + 10, k + 10, Blocks.planks, 5, 2);
        world.setBlock(i + 10, j + 10, k + 10, Blocks.planks, 5, 2);
        world.setBlock(i + 11, j + 10, k + 10, Blocks.planks, 5, 2);
        world.setBlock(i + 12, j + 10, k + 10, Blocks.planks, 5, 2);
        world.setBlock(i + 13, j + 10, k + 10, Blocks.planks, 5, 2);
        world.setBlock(i + 14, j + 10, k + 10, Blocks.planks, 5, 2);
        world.setBlock(i + 15, j + 10, k + 10, Blocks.planks, 5, 2);
        world.setBlock(i + 16, j + 10, k + 10, Blocks.planks, 5, 2);
        world.setBlock(i + 17, j + 10, k + 10, Blocks.planks, 5, 2);
        world.setBlock(i + 18, j + 10, k + 10, Blocks.dark_oak_stairs, 1, 2);
        world.setBlock(i + 2, j + 10, k + 11, Blocks.dark_oak_stairs, 0, 2);
        world.setBlock(i + 3, j + 10, k + 11, Blocks.planks, 5, 2);
        world.setBlock(i + 4, j + 10, k + 11, Blocks.planks, 5, 2);
        world.setBlock(i + 5, j + 10, k + 11, Blocks.planks, 5, 2);
        world.setBlock(i + 6, j + 10, k + 11, Blocks.planks, 5, 2);
        world.setBlock(i + 7, j + 10, k + 11, Blocks.planks, 5, 2);
        world.setBlock(i + 8, j + 10, k + 11, Blocks.planks, 5, 2);
        world.setBlock(i + 9, j + 10, k + 11, Blocks.planks, 5, 2);
        world.setBlock(i + 10, j + 10, k + 11, Blocks.planks, 5, 2);
        world.setBlock(i + 11, j + 10, k + 11, Blocks.planks, 5, 2);
        world.setBlock(i + 12, j + 10, k + 11, Blocks.planks, 5, 2);
        world.setBlock(i + 13, j + 10, k + 11, Blocks.planks, 5, 2);
        world.setBlock(i + 14, j + 10, k + 11, Blocks.planks, 5, 2);
        world.setBlock(i + 15, j + 10, k + 11, Blocks.planks, 5, 2);
        world.setBlock(i + 16, j + 10, k + 11, Blocks.planks, 5, 2);
        world.setBlock(i + 17, j + 10, k + 11, Blocks.planks, 5, 2);
        world.setBlock(i + 18, j + 10, k + 11, Blocks.dark_oak_stairs, 1, 2);
        world.setBlock(i + 2, j + 10, k + 12, Blocks.dark_oak_stairs, 0, 2);
        world.setBlock(i + 3, j + 10, k + 12, Blocks.planks, 5, 2);
        world.setBlock(i + 4, j + 10, k + 12, Blocks.planks, 5, 2);
        world.setBlock(i + 5, j + 10, k + 12, Blocks.planks, 5, 2);
        world.setBlock(i + 6, j + 10, k + 12, Blocks.planks, 5, 2);
        world.setBlock(i + 7, j + 10, k + 12, Blocks.planks, 5, 2);
        world.setBlock(i + 8, j + 10, k + 12, Blocks.planks, 5, 2);
        world.setBlock(i + 9, j + 10, k + 12, Blocks.planks, 5, 2);
        world.setBlock(i + 10, j + 10, k + 12, Blocks.planks, 5, 2);
        world.setBlock(i + 11, j + 10, k + 12, Blocks.planks, 5, 2);
        world.setBlock(i + 12, j + 10, k + 12, Blocks.planks, 5, 2);
        world.setBlock(i + 13, j + 10, k + 12, Blocks.planks, 5, 2);
        world.setBlock(i + 14, j + 10, k + 12, Blocks.planks, 5, 2);
        world.setBlock(i + 15, j + 10, k + 12, Blocks.planks, 5, 2);
        world.setBlock(i + 16, j + 10, k + 12, Blocks.planks, 5, 2);
        world.setBlock(i + 17, j + 10, k + 12, Blocks.planks, 5, 2);
        world.setBlock(i + 18, j + 10, k + 12, Blocks.dark_oak_stairs, 1, 2);
        world.setBlock(i + 2, j + 10, k + 13, Blocks.dark_oak_stairs, 0, 2);
        world.setBlock(i + 3, j + 10, k + 13, Blocks.planks, 5, 2);
        world.setBlock(i + 4, j + 10, k + 13, Blocks.planks, 5, 2);
        world.setBlock(i + 5, j + 10, k + 13, Blocks.planks, 5, 2);
        world.setBlock(i + 6, j + 10, k + 13, Blocks.planks, 5, 2);
        world.setBlock(i + 7, j + 10, k + 13, Blocks.planks, 5, 2);
        world.setBlock(i + 8, j + 10, k + 13, Blocks.planks, 5, 2);
        world.setBlock(i + 9, j + 10, k + 13, Blocks.planks, 5, 2);
        world.setBlock(i + 10, j + 10, k + 13, Blocks.planks, 5, 2);
        world.setBlock(i + 11, j + 10, k + 13, Blocks.planks, 5, 2);
        world.setBlock(i + 12, j + 10, k + 13, Blocks.planks, 5, 2);
        world.setBlock(i + 13, j + 10, k + 13, Blocks.planks, 5, 2);
        world.setBlock(i + 14, j + 10, k + 13, Blocks.planks, 5, 2);
        world.setBlock(i + 15, j + 10, k + 13, Blocks.planks, 5, 2);
        world.setBlock(i + 16, j + 10, k + 13, Blocks.planks, 5, 2);
        world.setBlock(i + 17, j + 10, k + 13, Blocks.planks, 5, 2);
        world.setBlock(i + 18, j + 10, k + 13, Blocks.dark_oak_stairs, 1, 2);
        world.setBlock(i + 2, j + 10, k + 14, Blocks.dark_oak_stairs, 0, 2);
        world.setBlock(i + 3, j + 10, k + 14, Blocks.planks, 5, 2);
        world.setBlock(i + 4, j + 10, k + 14, Blocks.planks, 5, 2);
        world.setBlock(i + 5, j + 10, k + 14, Blocks.planks, 5, 2);
        world.setBlock(i + 6, j + 10, k + 14, Blocks.planks, 5, 2);
        world.setBlock(i + 7, j + 10, k + 14, Blocks.planks, 5, 2);
        world.setBlock(i + 8, j + 10, k + 14, Blocks.planks, 5, 2);
        world.setBlock(i + 9, j + 10, k + 14, Blocks.planks, 5, 2);
        world.setBlock(i + 10, j + 10, k + 14, Blocks.planks, 5, 2);
        world.setBlock(i + 11, j + 10, k + 14, Blocks.planks, 5, 2);
        world.setBlock(i + 12, j + 10, k + 14, Blocks.planks, 5, 2);
        world.setBlock(i + 13, j + 10, k + 14, Blocks.planks, 5, 2);
        world.setBlock(i + 14, j + 10, k + 14, Blocks.planks, 5, 2);
        world.setBlock(i + 15, j + 10, k + 14, Blocks.planks, 5, 2);
        world.setBlock(i + 16, j + 10, k + 14, Blocks.planks, 5, 2);
        world.setBlock(i + 17, j + 10, k + 14, Blocks.planks, 5, 2);
        world.setBlock(i + 18, j + 10, k + 14, Blocks.dark_oak_stairs, 1, 2);
        world.setBlock(i + 2, j + 10, k + 15, Blocks.dark_oak_stairs, 0, 2);
        world.setBlock(i + 3, j + 10, k + 15, Blocks.planks, 5, 2);
        world.setBlock(i + 4, j + 10, k + 15, Blocks.planks, 5, 2);
        world.setBlock(i + 5, j + 10, k + 15, Blocks.planks, 5, 2);
        world.setBlock(i + 6, j + 10, k + 15, Blocks.planks, 5, 2);
        world.setBlock(i + 7, j + 10, k + 15, Blocks.planks, 5, 2);
        world.setBlock(i + 8, j + 10, k + 15, Blocks.planks, 5, 2);
        world.setBlock(i + 9, j + 10, k + 15, Blocks.planks, 5, 2);
        world.setBlock(i + 10, j + 10, k + 15, Blocks.planks, 5, 2);
        world.setBlock(i + 11, j + 10, k + 15, Blocks.planks, 5, 2);
        world.setBlock(i + 12, j + 10, k + 15, Blocks.planks, 5, 2);
        world.setBlock(i + 13, j + 10, k + 15, Blocks.planks, 5, 2);
        world.setBlock(i + 14, j + 10, k + 15, Blocks.planks, 5, 2);
        world.setBlock(i + 15, j + 10, k + 15, Blocks.planks, 5, 2);
        world.setBlock(i + 16, j + 10, k + 15, Blocks.planks, 5, 2);
        world.setBlock(i + 17, j + 10, k + 15, Blocks.planks, 5, 2);
        world.setBlock(i + 18, j + 10, k + 15, Blocks.dark_oak_stairs, 1, 2);
        world.setBlock(i + 2, j + 10, k + 16, Blocks.dark_oak_stairs, 0, 2);
        world.setBlock(i + 3, j + 10, k + 16, Blocks.planks, 5, 2);
        world.setBlock(i + 4, j + 10, k + 16, Blocks.planks, 5, 2);
        world.setBlock(i + 5, j + 10, k + 16, Blocks.planks, 5, 2);
        world.setBlock(i + 6, j + 10, k + 16, Blocks.planks, 5, 2);
        world.setBlock(i + 7, j + 10, k + 16, Blocks.planks, 5, 2);
        world.setBlock(i + 8, j + 10, k + 16, Blocks.planks, 5, 2);
        world.setBlock(i + 9, j + 10, k + 16, Blocks.planks, 5, 2);
        world.setBlock(i + 10, j + 10, k + 16, Blocks.planks, 5, 2);
        world.setBlock(i + 11, j + 10, k + 16, Blocks.planks, 5, 2);
        world.setBlock(i + 12, j + 10, k + 16, Blocks.planks, 5, 2);
        world.setBlock(i + 13, j + 10, k + 16, Blocks.planks, 5, 2);
        world.setBlock(i + 14, j + 10, k + 16, Blocks.planks, 5, 2);
        world.setBlock(i + 15, j + 10, k + 16, Blocks.planks, 5, 2);
        world.setBlock(i + 16, j + 10, k + 16, Blocks.planks, 5, 2);
        world.setBlock(i + 17, j + 10, k + 16, Blocks.planks, 5, 2);
        world.setBlock(i + 18, j + 10, k + 16, Blocks.dark_oak_stairs, 1, 2);
        world.setBlock(i + 2, j + 10, k + 17, Blocks.dark_oak_stairs, 0, 2);
        world.setBlock(i + 3, j + 10, k + 17, Blocks.planks, 5, 2);
        world.setBlock(i + 4, j + 10, k + 17, Blocks.planks, 5, 2);
        world.setBlock(i + 5, j + 10, k + 17, Blocks.planks, 5, 2);
        world.setBlock(i + 6, j + 10, k + 17, Blocks.planks, 5, 2);
        world.setBlock(i + 7, j + 10, k + 17, Blocks.planks, 5, 2);
        world.setBlock(i + 8, j + 10, k + 17, Blocks.planks, 5, 2);
        world.setBlock(i + 9, j + 10, k + 17, Blocks.planks, 5, 2);
        world.setBlock(i + 10, j + 10, k + 17, Blocks.planks, 5, 2);
        world.setBlock(i + 11, j + 10, k + 17, Blocks.planks, 5, 2);
        world.setBlock(i + 12, j + 10, k + 17, Blocks.planks, 5, 2);
        world.setBlock(i + 13, j + 10, k + 17, Blocks.planks, 5, 2);
        world.setBlock(i + 14, j + 10, k + 17, Blocks.planks, 5, 2);
        world.setBlock(i + 15, j + 10, k + 17, Blocks.planks, 5, 2);
        world.setBlock(i + 16, j + 10, k + 17, Blocks.planks, 5, 2);
        world.setBlock(i + 17, j + 10, k + 17, Blocks.planks, 5, 2);
        world.setBlock(i + 18, j + 10, k + 17, Blocks.dark_oak_stairs, 1, 2);
        world.setBlock(i + 2, j + 10, k + 18, Blocks.dark_oak_stairs, 0, 2);
        world.setBlock(i + 3, j + 10, k + 18, Blocks.planks, 5, 2);
        world.setBlock(i + 4, j + 10, k + 18, Blocks.planks, 5, 2);
        world.setBlock(i + 5, j + 10, k + 18, Blocks.planks, 5, 2);
        world.setBlock(i + 6, j + 10, k + 18, Blocks.planks, 5, 2);
        world.setBlock(i + 7, j + 10, k + 18, Blocks.planks, 5, 2);
        world.setBlock(i + 8, j + 10, k + 18, Blocks.planks, 5, 2);
        world.setBlock(i + 9, j + 10, k + 18, Blocks.planks, 5, 2);
        world.setBlock(i + 10, j + 10, k + 18, Blocks.planks, 5, 2);
        world.setBlock(i + 11, j + 10, k + 18, Blocks.planks, 5, 2);
        world.setBlock(i + 12, j + 10, k + 18, Blocks.planks, 5, 2);
        world.setBlock(i + 13, j + 10, k + 18, Blocks.planks, 5, 2);
        world.setBlock(i + 14, j + 10, k + 18, Blocks.planks, 5, 2);
        world.setBlock(i + 15, j + 10, k + 18, Blocks.planks, 5, 2);
        world.setBlock(i + 16, j + 10, k + 18, Blocks.planks, 5, 2);
        world.setBlock(i + 17, j + 10, k + 18, Blocks.planks, 5, 2);
        world.setBlock(i + 18, j + 10, k + 18, Blocks.dark_oak_stairs, 2, 2);
        world.setBlock(i + 19, j + 10, k + 18, Blocks.dark_oak_stairs, 2, 2);
        world.setBlock(i + 20, j + 10, k + 18, Blocks.dark_oak_stairs, 2, 2);
        world.setBlock(i + 21, j + 10, k + 18, Blocks.dark_oak_stairs, 2, 2);
        world.setBlock(i + 22, j + 10, k + 18, Blocks.dark_oak_stairs, 2, 2);
        world.setBlock(i + 23, j + 10, k + 18, Blocks.dark_oak_stairs, 2, 2);
        world.setBlock(i + 24, j + 10, k + 18, Blocks.dark_oak_stairs, 2, 2);
        world.setBlock(i + 25, j + 10, k + 18, Blocks.dark_oak_stairs, 2, 2);
        world.setBlock(i + 26, j + 10, k + 18, Blocks.dark_oak_stairs, 1, 2);
        world.setBlock(i + 2, j + 10, k + 19, Blocks.dark_oak_stairs, 0, 2);
        world.setBlock(i + 3, j + 10, k + 19, Blocks.planks, 5, 2);
        world.setBlock(i + 4, j + 10, k + 19, Blocks.planks, 5, 2);
        world.setBlock(i + 5, j + 10, k + 19, Blocks.planks, 5, 2);
        world.setBlock(i + 6, j + 10, k + 19, Blocks.planks, 5, 2);
        world.setBlock(i + 7, j + 10, k + 19, Blocks.planks, 5, 2);
        world.setBlock(i + 8, j + 10, k + 19, Blocks.planks, 5, 2);
        world.setBlock(i + 9, j + 10, k + 19, Blocks.planks, 5, 2);
        world.setBlock(i + 10, j + 10, k + 19, Blocks.planks, 5, 2);
        world.setBlock(i + 11, j + 10, k + 19, Blocks.planks, 5, 2);
        world.setBlock(i + 12, j + 10, k + 19, Blocks.planks, 5, 2);
        world.setBlock(i + 13, j + 10, k + 19, Blocks.planks, 5, 2);
        world.setBlock(i + 14, j + 10, k + 19, Blocks.planks, 5, 2);
        world.setBlock(i + 15, j + 10, k + 19, Blocks.planks, 5, 2);
        world.setBlock(i + 16, j + 10, k + 19, Blocks.planks, 5, 2);
        world.setBlock(i + 17, j + 10, k + 19, Blocks.planks, 5, 2);
        world.setBlock(i + 18, j + 10, k + 19, Blocks.planks, 5, 2);
        world.setBlock(i + 19, j + 10, k + 19, Blocks.planks, 5, 2);
        world.setBlock(i + 20, j + 10, k + 19, Blocks.planks, 5, 2);
        world.setBlock(i + 21, j + 10, k + 19, Blocks.planks, 5, 2);
        world.setBlock(i + 22, j + 10, k + 19, Blocks.planks, 5, 2);
        world.setBlock(i + 23, j + 10, k + 19, Blocks.planks, 5, 2);
        world.setBlock(i + 24, j + 10, k + 19, Blocks.planks, 5, 2);
        world.setBlock(i + 25, j + 10, k + 19, Blocks.planks, 5, 2);
        world.setBlock(i + 26, j + 10, k + 19, Blocks.dark_oak_stairs, 1, 2);
        world.setBlock(i + 2, j + 10, k + 20, Blocks.dark_oak_stairs, 0, 2);
        world.setBlock(i + 3, j + 10, k + 20, Blocks.planks, 5, 2);
        world.setBlock(i + 4, j + 10, k + 20, Blocks.planks, 5, 2);
        world.setBlock(i + 5, j + 10, k + 20, Blocks.planks, 5, 2);
        world.setBlock(i + 6, j + 10, k + 20, Blocks.planks, 5, 2);
        world.setBlock(i + 7, j + 10, k + 20, Blocks.planks, 5, 2);
        world.setBlock(i + 8, j + 10, k + 20, Blocks.planks, 5, 2);
        world.setBlock(i + 9, j + 10, k + 20, Blocks.planks, 5, 2);
        world.setBlock(i + 10, j + 10, k + 20, Blocks.planks, 5, 2);
        world.setBlock(i + 11, j + 10, k + 20, Blocks.planks, 5, 2);
        world.setBlock(i + 12, j + 10, k + 20, Blocks.planks, 5, 2);
        world.setBlock(i + 13, j + 10, k + 20, Blocks.planks, 5, 2);
        world.setBlock(i + 14, j + 10, k + 20, Blocks.planks, 5, 2);
        world.setBlock(i + 15, j + 10, k + 20, Blocks.planks, 5, 2);
        world.setBlock(i + 16, j + 10, k + 20, Blocks.planks, 5, 2);
        world.setBlock(i + 17, j + 10, k + 20, Blocks.planks, 5, 2);
        world.setBlock(i + 18, j + 10, k + 20, Blocks.planks, 5, 2);
        world.setBlock(i + 19, j + 10, k + 20, Blocks.planks, 5, 2);
        world.setBlock(i + 20, j + 10, k + 20, Blocks.planks, 5, 2);
        world.setBlock(i + 21, j + 10, k + 20, Blocks.planks, 5, 2);
        world.setBlock(i + 22, j + 10, k + 20, Blocks.planks, 5, 2);
        world.setBlock(i + 23, j + 10, k + 20, Blocks.planks, 5, 2);
        world.setBlock(i + 24, j + 10, k + 20, Blocks.planks, 5, 2);
        world.setBlock(i + 25, j + 10, k + 20, Blocks.planks, 5, 2);
        world.setBlock(i + 26, j + 10, k + 20, Blocks.dark_oak_stairs, 1, 2);
        world.setBlock(i + 2, j + 10, k + 21, Blocks.dark_oak_stairs, 0, 2);
        world.setBlock(i + 3, j + 10, k + 21, Blocks.planks, 5, 2);
        world.setBlock(i + 4, j + 10, k + 21, Blocks.planks, 5, 2);
        world.setBlock(i + 5, j + 10, k + 21, Blocks.planks, 5, 2);
        world.setBlock(i + 6, j + 10, k + 21, Blocks.planks, 5, 2);
        world.setBlock(i + 7, j + 10, k + 21, Blocks.planks, 5, 2);
        world.setBlock(i + 8, j + 10, k + 21, Blocks.planks, 5, 2);
        world.setBlock(i + 9, j + 10, k + 21, Blocks.planks, 5, 2);
        world.setBlock(i + 10, j + 10, k + 21, Blocks.planks, 5, 2);
        world.setBlock(i + 11, j + 10, k + 21, Blocks.planks, 5, 2);
        world.setBlock(i + 12, j + 10, k + 21, Blocks.planks, 5, 2);
        world.setBlock(i + 13, j + 10, k + 21, Blocks.planks, 5, 2);
        world.setBlock(i + 14, j + 10, k + 21, Blocks.planks, 5, 2);
        world.setBlock(i + 15, j + 10, k + 21, Blocks.planks, 5, 2);
        world.setBlock(i + 16, j + 10, k + 21, Blocks.planks, 5, 2);
        world.setBlock(i + 17, j + 10, k + 21, Blocks.planks, 5, 2);
        world.setBlock(i + 18, j + 10, k + 21, Blocks.planks, 5, 2);
        world.setBlock(i + 19, j + 10, k + 21, Blocks.planks, 5, 2);
        world.setBlock(i + 20, j + 10, k + 21, Blocks.planks, 5, 2);
        world.setBlock(i + 21, j + 10, k + 21, Blocks.planks, 5, 2);
        world.setBlock(i + 22, j + 10, k + 21, Blocks.planks, 5, 2);
        world.setBlock(i + 23, j + 10, k + 21, Blocks.planks, 5, 2);
        world.setBlock(i + 24, j + 10, k + 21, Blocks.planks, 5, 2);
        world.setBlock(i + 25, j + 10, k + 21, Blocks.planks, 5, 2);
        world.setBlock(i + 26, j + 10, k + 21, Blocks.dark_oak_stairs, 1, 2);
        world.setBlock(i + 2, j + 10, k + 22, Blocks.dark_oak_stairs, 0, 2);
        world.setBlock(i + 3, j + 10, k + 22, Blocks.planks, 5, 2);
        world.setBlock(i + 4, j + 10, k + 22, Blocks.planks, 5, 2);
        world.setBlock(i + 5, j + 10, k + 22, Blocks.planks, 5, 2);
