package com.NovaCraft.world.mansion;

import com.NovaCraftBlocks.NovaCraftBlocks;
import cpw.mods.fml.common.registry.GameRegistry;
import net.minecraft.block.Block;
import net.minecraft.init.Blocks;
import net.minecraft.init.Items;
import net.minecraft.item.ItemStack;
import net.minecraft.nbt.NBTTagCompound;
import net.minecraft.nbt.NBTTagFloat;
import net.minecraft.nbt.NBTTagList;
import net.minecraft.tileentity.TileEntityChest;
import net.minecraft.tileentity.TileEntityMobSpawner;
import net.minecraft.util.WeightedRandomChestContent;
import net.minecraft.world.World;
import net.minecraft.world.gen.feature.WorldGenerator;
import net.minecraftforge.common.ChestGenHooks;

import java.util.Random;

import static net.minecraftforge.common.ChestGenHooks.DUNGEON_CHEST;

public class MansionSealedOffRoomGen extends WorldGenerator {

    public MansionSealedOffRoomGen() {

    }

    @Override
    public boolean generate(final World world, final Random random, final int i, final int j, final int k) {

        world.setBlock(i + 8, j, k, NovaCraftBlocks.cobbled_grimstone, 0, 2);
        world.setBlock(i + 9, j, k, NovaCraftBlocks.cobbled_grimstone, 0, 2);
        world.setBlock(i + 10, j, k, NovaCraftBlocks.cobbled_grimstone, 0, 2);
        world.setBlock(i + 11, j, k, NovaCraftBlocks.cobbled_grimstone, 0, 2);
        world.setBlock(i + 12, j, k, NovaCraftBlocks.cobbled_grimstone, 0, 2);
        world.setBlock(i + 13, j, k, NovaCraftBlocks.cobbled_grimstone, 0, 2);
        world.setBlock(i + 14, j, k, NovaCraftBlocks.cobbled_grimstone, 0, 2);
        world.setBlock(i + 15, j, k, NovaCraftBlocks.cobbled_grimstone, 0, 2);
        world.setBlock(i + 16, j, k, NovaCraftBlocks.cobbled_grimstone, 0, 2);
        world.setBlock(i + 8, j, k + 1, NovaCraftBlocks.cobbled_grimstone, 0, 2);
        world.setBlock(i + 9, j, k + 1, placeStoneBricks(random), 0, 2);
        world.setBlock(i + 10, j, k + 1, placeStoneBricks(random), 0, 2);
        world.setBlock(i + 11, j, k + 1, placeStoneBricks(random), 0, 2);
        world.setBlock(i + 12, j, k + 1, placeStoneBricks(random), 0, 2);
        world.setBlock(i + 13, j, k + 1, placeStoneBricks(random), 0, 2);
        world.setBlock(i + 14, j, k + 1, placeStoneBricks(random), 0, 2);
        world.setBlock(i + 15, j, k + 1, placeStoneBricks(random), 0, 2);
        world.setBlock(i + 16, j, k + 1, NovaCraftBlocks.cobbled_grimstone, 0, 2);
        world.setBlock(i + 8, j, k + 2, NovaCraftBlocks.cobbled_grimstone, 0, 2);
        world.setBlock(i + 9, j, k + 2, placeStoneBricks(random), 0, 2);
        world.setBlock(i + 10, j, k + 2, placeStoneBricks(random), 0, 2);
        world.setBlock(i + 11, j, k + 2, placeStoneBricks(random), 0, 2);
        world.setBlock(i + 12, j, k + 2, placeStoneBricks(random), 0, 2);
        world.setBlock(i + 13, j, k + 2, NovaCraftBlocks.sculk_block, 0, 2);
        world.setBlock(i + 14, j, k + 2, placeStoneBricks(random), 0, 2);
        world.setBlock(i + 15, j, k + 2, placeStoneBricks(random), 0, 2);
        world.setBlock(i + 16, j, k + 2, NovaCraftBlocks.cobbled_grimstone, 0, 2);
        world.setBlock(i + 8, j, k + 3, NovaCraftBlocks.cobbled_grimstone, 0, 2);
        world.setBlock(i + 9, j, k + 3, placeStoneBricks(random), 0, 2);
        world.setBlock(i + 10, j, k + 3, placeStoneBricks(random), 0, 2);
        world.setBlock(i + 11, j, k + 3, placeStoneBricks(random), 0, 2);
        world.setBlock(i + 12, j, k + 3, placeStoneBricks(random), 0, 2);
        world.setBlock(i + 13, j, k + 3, placeStoneBricks(random), 0, 2);
        world.setBlock(i + 14, j, k + 3, placeStoneBricks(random), 0, 2);
        world.setBlock(i + 15, j, k + 3, placeStoneBricks(random), 0, 2);
        world.setBlock(i + 16, j, k + 3, NovaCraftBlocks.cobbled_grimstone, 0, 2);
        world.setBlock(i + 8, j, k + 4, NovaCraftBlocks.cobbled_grimstone, 0, 2);
        world.setBlock(i + 9, j, k + 4, placeStoneBricks(random), 0, 2);
        world.setBlock(i + 10, j, k + 4, placeStoneBricks(random), 0, 2);
        world.setBlock(i + 11, j, k + 4, placeStoneBricks(random), 0, 2);
        world.setBlock(i + 12, j, k + 4, placeStoneBricks(random), 0, 2);
        world.setBlock(i + 13, j, k + 4, placeStoneBricks(random), 0, 2);
        world.setBlock(i + 14, j, k + 4, placeStoneBricks(random), 0, 2);
        world.setBlock(i + 15, j, k + 4, NovaCraftBlocks.sculk_block, 0, 2);
        world.setBlock(i + 16, j, k + 4, NovaCraftBlocks.cobbled_grimstone, 0, 2);
        world.setBlock(i + 8, j, k + 5, NovaCraftBlocks.cobbled_grimstone, 0, 2);
        world.setBlock(i + 9, j, k + 5, placeStoneBricks(random), 0, 2);
        world.setBlock(i + 10, j, k + 5, placeStoneBricks(random), 0, 2);
        world.setBlock(i + 11, j, k + 5, placeStoneBricks(random), 0, 2);
        world.setBlock(i + 12, j, k + 5, placeStoneBricks(random), 0, 2);
        world.setBlock(i + 13, j, k + 5, placeStoneBricks(random), 0, 2);
        world.setBlock(i + 14, j, k + 5, placeStoneBricks(random), 0, 2);
        world.setBlock(i + 15, j, k + 5, placeStoneBricks(random), 0, 2);
        world.setBlock(i + 16, j, k + 5, NovaCraftBlocks.cobbled_grimstone, 0, 2);
        world.setBlock(i + 8, j, k + 6, NovaCraftBlocks.cobbled_grimstone, 0, 2);
        world.setBlock(i + 9, j, k + 6, placeStoneBricks(random), 0, 2);
        world.setBlock(i + 10, j, k + 6, NovaCraftBlocks.sculk_block, 0, 2);
        world.setBlock(i + 11, j, k + 6, placeStoneBricks(random), 0, 2);
        world.setBlock(i + 12, j, k + 6, placeStoneBricks(random), 0, 2);
        world.setBlock(i + 13, j, k + 6, NovaCraftBlocks.sculk_block, 0, 2);
        world.setBlock(i + 14, j, k + 6, placeStoneBricks(random), 0, 2);
        world.setBlock(i + 15, j, k + 6, placeStoneBricks(random), 0, 2);
        world.setBlock(i + 16, j, k + 6, NovaCraftBlocks.cobbled_grimstone, 0, 2);
        world.setBlock(i + 8, j, k + 7, NovaCraftBlocks.cobbled_grimstone, 0, 2);
        world.setBlock(i + 9, j, k + 7, placeStoneBricks(random), 0, 2);
        world.setBlock(i + 10, j, k + 7, placeStoneBricks(random), 0, 2);
        world.setBlock(i + 11, j, k + 7, placeStoneBricks(random), 0, 2);
        world.setBlock(i + 12, j, k + 7, placeStoneBricks(random), 0, 2);
        world.setBlock(i + 13, j, k + 7, placeStoneBricks(random), 0, 2);
        world.setBlock(i + 14, j, k + 7, placeStoneBricks(random), 0, 2);
        world.setBlock(i + 15, j, k + 7, placeStoneBricks(random), 0, 2);
        world.setBlock(i + 16, j, k + 7, NovaCraftBlocks.cobbled_grimstone, 0, 2);
        world.setBlock(i + 1, j, k + 8, NovaCraftBlocks.cobbled_grimstone, 0, 2);
        world.setBlock(i + 2, j, k + 8, NovaCraftBlocks.cobbled_grimstone, 0, 2);
        world.setBlock(i + 3, j, k + 8, NovaCraftBlocks.cobbled_grimstone, 0, 2);
        world.setBlock(i + 4, j, k + 8, NovaCraftBlocks.cobbled_grimstone, 0, 2);
        world.setBlock(i + 5, j, k + 8, NovaCraftBlocks.cobbled_grimstone, 0, 2);
        world.setBlock(i + 6, j, k + 8, NovaCraftBlocks.cobbled_grimstone, 0, 2);
        world.setBlock(i + 7, j, k + 8, NovaCraftBlocks.cobbled_grimstone, 0, 2);
        world.setBlock(i + 8, j, k + 8, NovaCraftBlocks.cobbled_grimstone, 0, 2);
        world.setBlock(i + 9, j, k + 8, placeStoneBricks(random), 0, 2);
        world.setBlock(i + 10, j, k + 8, placeStoneBricks(random), 0, 2);
        world.setBlock(i + 11, j, k + 8, placeStoneBricks(random), 0, 2);
        world.setBlock(i + 12, j, k + 8, placeStoneBricks(random), 0, 2);
        world.setBlock(i + 13, j, k + 8, placeStoneBricks(random), 0, 2);
        world.setBlock(i + 14, j, k + 8, placeStoneBricks(random), 0, 2);
        world.setBlock(i + 15, j, k + 8, placeStoneBricks(random), 0, 2);
        world.setBlock(i + 16, j, k + 8, NovaCraftBlocks.cobbled_grimstone, 0, 2);
        world.setBlock(i + 17, j, k + 8, NovaCraftBlocks.cobbled_grimstone, 0, 2);
        world.setBlock(i + 1, j, k + 9, NovaCraftBlocks.cobbled_grimstone, 0, 2);
        world.setBlock(i + 2, j, k + 9, placeStoneBricks(random), 0, 2);
        world.setBlock(i + 3, j, k + 9, placeStoneBricks(random), 0, 2);
        world.setBlock(i + 4, j, k + 9, placeStoneBricks(random), 0, 2);
        world.setBlock(i + 5, j, k + 9, placeStoneBricks(random), 0, 2);
        world.setBlock(i + 6, j, k + 9, placeStoneBricks(random), 0, 2);
        world.setBlock(i + 7, j, k + 9, placeStoneBricks(random), 0, 2);
        world.setBlock(i + 8, j, k + 9, placeStoneBricks(random), 0, 2);
        world.setBlock(i + 9, j, k + 9, placeStoneBricks(random), 0, 2);
        world.setBlock(i + 10, j, k + 9, placeStoneBricks(random), 0, 2);
        world.setBlock(i + 11, j, k + 9, placeStoneBricks(random), 0, 2);
        world.setBlock(i + 12, j, k + 9, placeStoneBricks(random), 0, 2);
        world.setBlock(i + 13, j, k + 9, placeStoneBricks(random), 0, 2);
        world.setBlock(i + 14, j, k + 9, placeStoneBricks(random), 0, 2);
        world.setBlock(i + 15, j, k + 9, placeStoneBricks(random), 0, 2);
        world.setBlock(i + 16, j, k + 9, placeStoneBricks(random), 0, 2);
        world.setBlock(i + 17, j, k + 9, NovaCraftBlocks.cobbled_grimstone, 0, 2);
        world.setBlock(i + 1, j, k + 10, NovaCraftBlocks.cobbled_grimstone, 0, 2);
        world.setBlock(i + 2, j, k + 10, placeStoneBricks(random), 0, 2);
        world.setBlock(i + 3, j, k + 10, placeStoneBricks(random), 0, 2);
        world.setBlock(i + 4, j, k + 10, placeStoneBricks(random), 0, 2);
        world.setBlock(i + 5, j, k + 10, placeStoneBricks(random), 0, 2);
        world.setBlock(i + 6, j, k + 10, placeStoneBricks(random), 0, 2);
        world.setBlock(i + 7, j, k + 10, placeStoneBricks(random), 0, 2);
        world.setBlock(i + 8, j, k + 10, placeStoneBricks(random), 0, 2);
        world.setBlock(i + 9, j, k + 10, placeStoneBricks(random), 0, 2);
        world.setBlock(i + 10, j, k + 10, placeStoneBricks(random), 0, 2);
        world.setBlock(i + 11, j, k + 10, placeStoneBricks(random), 0, 2);
        world.setBlock(i + 12, j, k + 10, placeStoneBricks(random), 0, 2);
        world.setBlock(i + 13, j, k + 10, placeStoneBricks(random), 0, 2);
        world.setBlock(i + 14, j, k + 10, placeStoneBricks(random), 0, 2);
        world.setBlock(i + 15, j, k + 10, placeStoneBricks(random), 0, 2);
        world.setBlock(i + 16, j, k + 10, placeStoneBricks(random), 0, 2);
        world.setBlock(i + 17, j, k + 10, NovaCraftBlocks.cobbled_grimstone, 0, 2);
        world.setBlock(i + 1, j, k + 11, NovaCraftBlocks.cobbled_grimstone, 0, 2);
        world.setBlock(i + 2, j, k + 11, placeStoneBricks(random), 0, 2);
        world.setBlock(i + 3, j, k + 11, placeStoneBricks(random), 0, 2);
        world.setBlock(i + 4, j, k + 11, placeStoneBricks(random), 0, 2);
        world.setBlock(i + 5, j, k + 11, placeStoneBricks(random), 0, 2);
        world.setBlock(i + 6, j, k + 11, placeStoneBricks(random), 0, 2);
        world.setBlock(i + 7, j, k + 11, placeStoneBricks(random), 0, 2);
        world.setBlock(i + 8, j, k + 11, placeStoneBricks(random), 0, 2);
        world.setBlock(i + 9, j, k + 11, placeStoneBricks(random), 0, 2);
        world.setBlock(i + 10, j, k + 11, placeStoneBricks(random), 0, 2);
        world.setBlock(i + 11, j, k + 11, placeStoneBricks(random), 0, 2);
        world.setBlock(i + 12, j, k + 11, placeStoneBricks(random), 0, 2);
        world.setBlock(i + 13, j, k + 11, placeStoneBricks(random), 0, 2);
        world.setBlock(i + 14, j, k + 11, placeStoneBricks(random), 0, 2);
        world.setBlock(i + 15, j, k + 11, placeStoneBricks(random), 0, 2);
        world.setBlock(i + 16, j, k + 11, placeStoneBricks(random), 0, 2);
        world.setBlock(i + 17, j, k + 11, NovaCraftBlocks.cobbled_grimstone, 0, 2);
        world.setBlock(i + 1, j, k + 12, NovaCraftBlocks.cobbled_grimstone, 0, 2);
        world.setBlock(i + 2, j, k + 12, placeStoneBricks(random), 0, 2);
        world.setBlock(i + 3, j, k + 12, placeStoneBricks(random), 0, 2);
        world.setBlock(i + 4, j, k + 12, placeStoneBricks(random), 0, 2);
        world.setBlock(i + 5, j, k + 12, placeStoneBricks(random), 0, 2);
        world.setBlock(i + 6, j, k + 12, placeStoneBricks(random), 0, 2);
        world.setBlock(i + 7, j, k + 12, placeStoneBricks(random), 0, 2);
        world.setBlock(i + 8, j, k + 12, placeStoneBricks(random), 0, 2);
        world.setBlock(i + 9, j, k + 12, placeStoneBricks(random), 0, 2);
        world.setBlock(i + 10, j, k + 12, placeStoneBricks(random), 0, 2);
        world.setBlock(i + 11, j, k + 12, placeStoneBricks(random), 0, 2);
        world.setBlock(i + 12, j, k + 12, placeStoneBricks(random), 0, 2);
        world.setBlock(i + 13, j, k + 12, placeStoneBricks(random), 0, 2);
        world.setBlock(i + 14, j, k + 12, placeStoneBricks(random), 0, 2);
        world.setBlock(i + 15, j, k + 12, placeStoneBricks(random), 0, 2);
        world.setBlock(i + 16, j, k + 12, placeStoneBricks(random), 0, 2);
        world.setBlock(i + 17, j, k + 12, NovaCraftBlocks.cobbled_grimstone, 0, 2);
        world.setBlock(i + 1, j, k + 13, NovaCraftBlocks.cobbled_grimstone, 0, 2);
        world.setBlock(i + 2, j, k + 13, placeStoneBricks(random), 0, 2);
        world.setBlock(i + 3, j, k + 13, placeStoneBricks(random), 0, 2);
        world.setBlock(i + 4, j, k + 13, placeStoneBricks(random), 0, 2);
        world.setBlock(i + 5, j, k + 13, placeStoneBricks(random), 0, 2);
        world.setBlock(i + 6, j, k + 13, placeStoneBricks(random), 0, 2);
        world.setBlock(i + 7, j, k + 13, placeStoneBricks(random), 0, 2);
        world.setBlock(i + 8, j, k + 13, placeStoneBricks(random), 0, 2);
        world.setBlock(i + 9, j, k + 13, placeStoneBricks(random), 0, 2);
        world.setBlock(i + 10, j, k + 13, placeStoneBricks(random), 0, 2);
        world.setBlock(i + 11, j, k + 13, placeStoneBricks(random), 0, 2);
        world.setBlock(i + 12, j, k + 13, placeStoneBricks(random), 0, 2);
        world.setBlock(i + 13, j, k + 13, placeStoneBricks(random), 0, 2);
        world.setBlock(i + 14, j, k + 13, placeStoneBricks(random), 0, 2);
        world.setBlock(i + 15, j, k + 13, placeStoneBricks(random), 0, 2);
        world.setBlock(i + 16, j, k + 13, placeStoneBricks(random), 0, 2);
        world.setBlock(i + 17, j, k + 13, NovaCraftBlocks.cobbled_grimstone, 0, 2);
        world.setBlock(i + 1, j, k + 14, NovaCraftBlocks.cobbled_grimstone, 0, 2);
        world.setBlock(i + 2, j, k + 14, placeStoneBricks(random), 0, 2);
        world.setBlock(i + 3, j, k + 14, placeStoneBricks(random), 0, 2);
        world.setBlock(i + 4, j, k + 14, placeStoneBricks(random), 0, 2);
        world.setBlock(i + 5, j, k + 14, placeStoneBricks(random), 0, 2);
        world.setBlock(i + 6, j, k + 14, placeStoneBricks(random), 0, 2);
        world.setBlock(i + 7, j, k + 14, placeStoneBricks(random), 0, 2);
        world.setBlock(i + 8, j, k + 14, placeStoneBricks(random), 0, 2);
        world.setBlock(i + 9, j, k + 14, placeStoneBricks(random), 0, 2);
        world.setBlock(i + 10, j, k + 14, placeStoneBricks(random), 0, 2);
        world.setBlock(i + 11, j, k + 14, placeStoneBricks(random), 0, 2);
        world.setBlock(i + 12, j, k + 14, placeStoneBricks(random), 0, 2);
        world.setBlock(i + 13, j, k + 14, placeStoneBricks(random), 0, 2);
        world.setBlock(i + 14, j, k + 14, placeStoneBricks(random), 0, 2);
        world.setBlock(i + 15, j, k + 14, placeStoneBricks(random), 0, 2);
        world.setBlock(i + 16, j, k + 14, placeStoneBricks(random), 0, 2);
        world.setBlock(i + 17, j, k + 14, NovaCraftBlocks.cobbled_grimstone, 0, 2);
        world.setBlock(i + 1, j, k + 15, NovaCraftBlocks.cobbled_grimstone, 0, 2);
        world.setBlock(i + 2, j, k + 15, NovaCraftBlocks.cobbled_grimstone, 0, 2);
        world.setBlock(i + 3, j, k + 15, NovaCraftBlocks.cobbled_grimstone, 0, 2);
        world.setBlock(i + 4, j, k + 15, NovaCraftBlocks.cobbled_grimstone, 0, 2);
        world.setBlock(i + 5, j, k + 15, NovaCraftBlocks.cobbled_grimstone, 0, 2);
        world.setBlock(i + 6, j, k + 15, NovaCraftBlocks.cobbled_grimstone, 0, 2);
        world.setBlock(i + 7, j, k + 15, NovaCraftBlocks.cobbled_grimstone, 0, 2);
        world.setBlock(i + 8, j, k + 15, NovaCraftBlocks.cobbled_grimstone, 0, 2);
        world.setBlock(i + 9, j, k + 15, placeStoneBricks(random), 0, 2);
        world.setBlock(i + 10, j, k + 15, placeStoneBricks(random), 0, 2);
        world.setBlock(i + 11, j, k + 15, placeStoneBricks(random), 0, 2);
        world.setBlock(i + 12, j, k + 15, placeStoneBricks(random), 0, 2);
        world.setBlock(i + 13, j, k + 15, placeStoneBricks(random), 0, 2);
        world.setBlock(i + 14, j, k + 15, placeStoneBricks(random), 0, 2);
        world.setBlock(i + 15, j, k + 15, placeStoneBricks(random), 0, 2);
        world.setBlock(i + 16, j, k + 15, NovaCraftBlocks.cobbled_grimstone, 0, 2);
        world.setBlock(i + 17, j, k + 15, NovaCraftBlocks.cobbled_grimstone, 0, 2);
        world.setBlock(i + 8, j, k + 16, NovaCraftBlocks.cobbled_grimstone, 0, 2);
        world.setBlock(i + 9, j, k + 16, placeStoneBricks(random), 0, 2);
        world.setBlock(i + 10, j, k + 16, placeStoneBricks(random), 0, 2);
        world.setBlock(i + 11, j, k + 16, placeStoneBricks(random), 0, 2);
        world.setBlock(i + 12, j, k + 16, placeStoneBricks(random), 0, 2);
        world.setBlock(i + 13, j, k + 16, placeStoneBricks(random), 0, 2);
        world.setBlock(i + 14, j, k + 16, placeStoneBricks(random), 0, 2);
        world.setBlock(i + 15, j, k + 16, placeStoneBricks(random), 0, 2);
        world.setBlock(i + 16, j, k + 16, NovaCraftBlocks.cobbled_grimstone, 0, 2);
        world.setBlock(i + 8, j, k + 17, NovaCraftBlocks.cobbled_grimstone, 0, 2);
        world.setBlock(i + 9, j, k + 17, placeStoneBricks(random), 0, 2);
        world.setBlock(i + 10, j, k + 17, placeStoneBricks(random), 0, 2);
        world.setBlock(i + 11, j, k + 17, placeStoneBricks(random), 0, 2);
        world.setBlock(i + 12, j, k + 17, placeStoneBricks(random), 0, 2);
        world.setBlock(i + 13, j, k + 17, placeStoneBricks(random), 0, 2);
        world.setBlock(i + 14, j, k + 17, placeStoneBricks(random), 0, 2);
        world.setBlock(i + 15, j, k + 17, placeStoneBricks(random), 0, 2);
        world.setBlock(i + 16, j, k + 17, NovaCraftBlocks.cobbled_grimstone, 0, 2);
        world.setBlock(i + 8, j, k + 18, NovaCraftBlocks.cobbled_grimstone, 0, 2);
        world.setBlock(i + 9, j, k + 18, placeStoneBricks(random), 0, 2);
        world.setBlock(i + 10, j, k + 18, placeStoneBricks(random), 0, 2);
        world.setBlock(i + 11, j, k + 18, placeStoneBricks(random), 0, 2);
        world.setBlock(i + 12, j, k + 18, placeStoneBricks(random), 0, 2);
        world.setBlock(i + 13, j, k + 18, placeStoneBricks(random), 0, 2);
        world.setBlock(i + 14, j, k + 18, placeStoneBricks(random), 0, 2);
        world.setBlock(i + 15, j, k + 18, placeStoneBricks(random), 0, 2);
        world.setBlock(i + 16, j, k + 18, NovaCraftBlocks.cobbled_grimstone, 0, 2);
        world.setBlock(i + 8, j, k + 19, NovaCraftBlocks.cobbled_grimstone, 0, 2);
        world.setBlock(i + 9, j, k + 19, placeStoneBricks(random), 0, 2);
        world.setBlock(i + 10, j, k + 19, placeStoneBricks(random), 0, 2);
        world.setBlock(i + 11, j, k + 19, placeStoneBricks(random), 0, 2);
        world.setBlock(i + 12, j, k + 19, placeStoneBricks(random), 0, 2);
        world.setBlock(i + 13, j, k + 19, placeStoneBricks(random), 0, 2);
        world.setBlock(i + 14, j, k + 19, placeStoneBricks(random), 0, 2);
        world.setBlock(i + 15, j, k + 19, placeStoneBricks(random), 0, 2);
        world.setBlock(i + 16, j, k + 19, NovaCraftBlocks.cobbled_grimstone, 0, 2);
        world.setBlock(i + 8, j, k + 20, NovaCraftBlocks.cobbled_grimstone, 0, 2);
        world.setBlock(i + 9, j, k + 20, placeStoneBricks(random), 0, 2);
        world.setBlock(i + 10, j, k + 20, placeStoneBricks(random), 0, 2);
        world.setBlock(i + 11, j, k + 20, placeStoneBricks(random), 0, 2);
        world.setBlock(i + 12, j, k + 20, placeStoneBricks(random), 0, 2);
        world.setBlock(i + 13, j, k + 20, placeStoneBricks(random), 0, 2);
        world.setBlock(i + 14, j, k + 20, placeStoneBricks(random), 0, 2);
        world.setBlock(i + 15, j, k + 20, placeStoneBricks(random), 0, 2);
        world.setBlock(i + 16, j, k + 20, NovaCraftBlocks.cobbled_grimstone, 0, 2);
        world.setBlock(i + 8, j, k + 21, NovaCraftBlocks.cobbled_grimstone, 0, 2);
        world.setBlock(i + 9, j, k + 21, placeStoneBricks(random), 0, 2);
        world.setBlock(i + 10, j, k + 21, placeStoneBricks(random), 0, 2);
        world.setBlock(i + 11, j, k + 21, placeStoneBricks(random), 0, 2);
        world.setBlock(i + 12, j, k + 21, placeStoneBricks(random), 0, 2);
        world.setBlock(i + 13, j, k + 21, placeStoneBricks(random), 0, 2);
        world.setBlock(i + 14, j, k + 21, placeStoneBricks(random), 0, 2);
        world.setBlock(i + 15, j, k + 21, placeStoneBricks(random), 0, 2);
        world.setBlock(i + 16, j, k + 21, NovaCraftBlocks.cobbled_grimstone, 0, 2);
        world.setBlock(i + 8, j, k + 22, NovaCraftBlocks.cobbled_grimstone, 0, 2);
        world.setBlock(i + 9, j, k + 22, NovaCraftBlocks.cobbled_grimstone, 0, 2);
        world.setBlock(i + 10, j, k + 22, NovaCraftBlocks.cobbled_grimstone, 0, 2);
        world.setBlock(i + 11, j, k + 22, NovaCraftBlocks.cobbled_grimstone, 0, 2);
        world.setBlock(i + 12, j, k + 22, NovaCraftBlocks.cobbled_grimstone, 0, 2);
        world.setBlock(i + 13, j, k + 22, NovaCraftBlocks.cobbled_grimstone, 0, 2);
        world.setBlock(i + 14, j, k + 22, NovaCraftBlocks.cobbled_grimstone, 0, 2);
        world.setBlock(i + 15, j, k + 22, NovaCraftBlocks.cobbled_grimstone, 0, 2);
        world.setBlock(i + 16, j, k + 22, NovaCraftBlocks.cobbled_grimstone, 0, 2);
        world.setBlock(i + 8, j + 1, k, placeStoneBricks(random), 0, 2);
        world.setBlock(i + 9, j + 1, k, placeStoneBricks(random), 0, 2);
        world.setBlock(i + 10, j + 1, k, placeStoneBricks(random), 0, 2);
        world.setBlock(i + 11, j + 1, k, placeStoneBricks(random), 0, 2);
        world.setBlock(i + 12, j + 1, k, placeStoneBricks(random), 0, 2);
        world.setBlock(i + 13, j + 1, k, placeStoneBricks(random), 0, 2);
        world.setBlock(i + 14, j + 1, k, placeStoneBricks(random), 0, 2);
        world.setBlock(i + 15, j + 1, k, placeStoneBricks(random), 0, 2);
        world.setBlock(i + 16, j + 1, k, placeStoneBricks(random), 0, 2);
        world.setBlock(i + 8, j + 1, k + 1, placeStoneBricks(random), 0, 2);
        world.setBlock(i + 9, j + 1, k + 1, Blocks.air, 0, 2);
        world.setBlock(i + 10, j + 1, k + 1, Blocks.air, 0, 2);
        world.setBlock(i + 11, j + 1, k + 1, Blocks.air, 0, 2);
        world.setBlock(i + 12, j + 1, k + 1, Blocks.air, 0, 2);
        world.setBlock(i + 13, j + 1, k + 1, Blocks.air, 0, 2);
        world.setBlock(i + 14, j + 1, k + 1, Blocks.air, 0, 2);
        world.setBlock(i + 15, j + 1, k + 1, Blocks.air, 0, 2);
        world.setBlock(i + 16, j + 1, k + 1, placeStoneBricks(random), 0, 2);
        world.setBlock(i + 8, j + 1, k + 2, placeStoneBricks(random), 0, 2);
        world.setBlock(i + 9, j + 1, k + 2, Blocks.skull, 1, 2);
        world.setBlock(i + 10, j + 1, k + 2, Blocks.air, 0, 2);
        world.setBlock(i + 11, j + 1, k + 2, Blocks.air, 0, 2);
        world.setBlock(i + 12, j + 1, k + 2, Blocks.air, 0, 2);
        world.setBlock(i + 13, j + 1, k + 2, Blocks.air, 0, 2);
        world.setBlock(i + 14, j + 1, k + 2, Blocks.air, 0, 2);
        world.setBlock(i + 15, j + 1, k + 2, Blocks.air, 0, 2);
        world.setBlock(i + 16, j + 1, k + 2, placeStoneBricks(random), 0, 2);
        world.setBlock(i + 8, j + 1, k + 3, placeStoneBricks(random), 0, 2);
        world.setBlock(i + 9, j + 1, k + 3, Blocks.air, 0, 2);
        world.setBlock(i + 10, j + 1, k + 3, Blocks.air, 0, 2);
        world.setBlock(i + 11, j + 1, k + 3, Blocks.air, 0, 2);
        world.setBlock(i + 12, j + 1, k + 3, NovaCraftBlocks.vanite_glass, 0, 2);
        world.setBlock(i + 13, j + 1, k + 3, Blocks.air, 0, 2);
        world.setBlock(i + 14, j + 1, k + 3, Blocks.air, 0, 2);
        world.setBlock(i + 15, j + 1, k + 3, Blocks.air, 0, 2);
        world.setBlock(i + 16, j + 1, k + 3, placeStoneBricks(random), 0, 2);
        world.setBlock(i + 8, j + 1, k + 4, placeStoneBricks(random), 0, 2);
        world.setBlock(i + 9, j + 1, k + 4, Blocks.air, 0, 2);
        world.setBlock(i + 10, j + 1, k + 4, Blocks.air, 0, 2);
        world.setBlock(i + 11, j + 1, k + 4, NovaCraftBlocks.vanite_glass, 0, 2);
        world.setBlock(i + 13, j + 1, k + 4, NovaCraftBlocks.vanite_glass, 0, 2);
        world.setBlock(i + 14, j + 1, k + 4, Blocks.skull, 1, 2);
        world.setBlock(i + 15, j + 1, k + 4, Blocks.air, 0, 2);
        world.setBlock(i + 16, j + 1, k + 4, placeStoneBricks(random), 0, 2);
        world.setBlock(i + 8, j + 1, k + 5, placeStoneBricks(random), 0, 2);
        world.setBlock(i + 9, j + 1, k + 5, Blocks.air, 0, 2);
        world.setBlock(i + 10, j + 1, k + 5, Blocks.air, 0, 2);
        world.setBlock(i + 11, j + 1, k + 5, Blocks.air, 0, 2);
        world.setBlock(i + 12, j + 1, k + 5, NovaCraftBlocks.vanite_glass, 0, 2);
        world.setBlock(i + 13, j + 1, k + 5, Blocks.air, 0, 2);
        world.setBlock(i + 14, j + 1, k + 5, Blocks.air, 0, 2);
        world.setBlock(i + 15, j + 1, k + 5, NovaCraftBlocks.cobbled_grimstone_slab, 3, 2);
        world.setBlock(i + 16, j + 1, k + 5, placeStoneBricks(random), 0, 2);
        world.setBlock(i + 8, j + 1, k + 6, placeStoneBricks(random), 0, 2);
        world.setBlock(i + 9, j + 1, k + 6, Blocks.air, 0, 2);
        world.setBlock(i + 10, j + 1, k + 6, Blocks.air, 0, 2);
        world.setBlock(i + 11, j + 1, k + 6, Blocks.air, 0, 2);
        world.setBlock(i + 12, j + 1, k + 6, Blocks.air, 0, 2);
        world.setBlock(i + 13, j + 1, k + 6, Blocks.air, 0, 2);
        world.setBlock(i + 14, j + 1, k + 6, Blocks.air, 0, 2);
        world.setBlock(i + 15, j + 1, k + 6, Blocks.air, 0, 2);
        world.setBlock(i + 16, j + 1, k + 6, placeStoneBricks(random), 0, 2);
        world.setBlock(i + 8, j + 1, k + 7, placeStoneBricks(random), 0, 2);
        world.setBlock(i + 9, j + 1, k + 7, placeStoneBricks(random), 0, 2);
        world.setBlock(i + 10, j + 1, k + 7, Blocks.air, 0, 2);
        world.setBlock(i + 11, j + 1, k + 7, Blocks.iron_bars, 0, 2);
        world.setBlock(i + 12, j + 1, k + 7, Blocks.air, 0, 2);
        world.setBlock(i + 13, j + 1, k + 7, Blocks.iron_bars, 0, 2);
        world.setBlock(i + 14, j + 1, k + 7, Blocks.iron_bars, 0, 2);
        world.setBlock(i + 15, j + 1, k + 7, placeStoneBricks(random), 0, 2);
        world.setBlock(i + 16, j + 1, k + 7, placeStoneBricks(random), 0, 2);
        world.setBlock(i + 1, j + 1, k + 8, placeStoneBricks(random), 0, 2);
        world.setBlock(i + 2, j + 1, k + 8, placeStoneBricks(random), 0, 2);
        world.setBlock(i + 3, j + 1, k + 8, placeStoneBricks(random), 0, 2);
        world.setBlock(i + 4, j + 1, k + 8, placeStoneBricks(random), 0, 2);
        world.setBlock(i + 5, j + 1, k + 8, placeStoneBricks(random), 0, 2);
        world.setBlock(i + 6, j + 1, k + 8, placeStoneBricks(random), 0, 2);
        world.setBlock(i + 7, j + 1, k + 8, placeStoneBricks(random), 0, 2);
        world.setBlock(i + 8, j + 1, k + 8, placeStoneBricks(random), 0, 2);
        world.setBlock(i + 9, j + 1, k + 8, placeStoneBricks(random), 0, 2);
        world.setBlock(i + 10, j + 1, k + 8, Blocks.air, 0, 2);
        world.setBlock(i + 11, j + 1, k + 8, Blocks.air, 0, 2);
        world.setBlock(i + 12, j + 1, k + 8, Blocks.air, 0, 2);
        world.setBlock(i + 13, j + 1, k + 8, Blocks.air, 0, 2);
        world.setBlock(i + 14, j + 1, k + 8, Blocks.air, 0, 2);
        world.setBlock(i + 15, j + 1, k + 8, placeStoneBricks(random), 0, 2);
        world.setBlock(i + 16, j + 1, k + 8, placeStoneBricks(random), 0, 2);
        world.setBlock(i + 17, j + 1, k + 8, placeStoneBricks(random), 0, 2);
        world.setBlock(i + 1, j + 1, k + 9, placeStoneBricks(random), 0, 2);
        world.setBlock(i + 2, j + 1, k + 9, Blocks.web, 0, 2);
        world.setBlock(i + 3, j + 1, k + 9, Blocks.air, 0, 2);
        world.setBlock(i + 4, j + 1, k + 9, Blocks.air, 0, 2);
        world.setBlock(i + 5, j + 1, k + 9, Blocks.air, 0, 2);
        world.setBlock(i + 6, j + 1, k + 9, Blocks.air, 0, 2);
        world.setBlock(i + 7, j + 1, k + 9, Blocks.web, 0, 2);
        world.setBlock(i + 8, j + 1, k + 9, Blocks.air, 0, 2);
        world.setBlock(i + 9, j + 1, k + 9, Blocks.air, 0, 2);
        world.setBlock(i + 10, j + 1, k + 9, Blocks.air, 0, 2);
        world.setBlock(i + 11, j + 1, k + 9, NovaCraftBlocks.cobbled_grimstone_slab, 3, 2);
        world.setBlock(i + 12, j + 1, k + 9, Blocks.air, 0, 2);
        world.setBlock(i + 13, j + 1, k + 9, Blocks.air, 0, 2);
        world.setBlock(i + 14, j + 1, k + 9, Blocks.air, 0, 2);
        world.setBlock(i + 15, j + 1, k + 9, Blocks.air, 0, 2);
        world.setBlock(i + 16, j + 1, k + 9, Blocks.web, 0, 2);
        world.setBlock(i + 17, j + 1, k + 9, placeStoneBricks(random), 0, 2);
        world.setBlock(i + 1, j + 1, k + 10, placeStoneBricks(random), 0, 2);
        world.setBlock(i + 2, j + 1, k + 10, Blocks.air, 0, 2);
        world.setBlock(i + 3, j + 1, k + 10, Blocks.air, 0, 2);
        world.setBlock(i + 4, j + 1, k + 10, Blocks.air, 0, 2);
        world.setBlock(i + 5, j + 1, k + 10, NovaCraftBlocks.cobbled_grimstone_slab, 3, 2);
        world.setBlock(i + 6, j + 1, k + 10, Blocks.air, 0, 2);
        world.setBlock(i + 7, j + 1, k + 10, Blocks.air, 0, 2);
        world.setBlock(i + 8, j + 1, k + 10, Blocks.air, 0, 2);
        world.setBlock(i + 9, j + 1, k + 10, Blocks.air, 0, 2);
        world.setBlock(i + 10, j + 1, k + 10, Blocks.air, 0, 2);
        world.setBlock(i + 11, j + 1, k + 10, Blocks.air, 0, 2);
        world.setBlock(i + 12, j + 1, k + 10, Blocks.air, 0, 2);
        world.setBlock(i + 13, j + 1, k + 10, Blocks.air, 0, 2);
        world.setBlock(i + 14, j + 1, k + 10, Blocks.air, 0, 2);
        world.setBlock(i + 15, j + 1, k + 10, Blocks.air, 0, 2);
        world.setBlock(i + 16, j + 1, k + 10, Blocks.air, 0, 2);
        world.setBlock(i + 17, j + 1, k + 10, placeStoneBricks(random), 0, 2);
        world.setBlock(i + 1, j + 1, k + 11, Blocks.planks, 5, 2);
        world.setBlock(i + 2, j + 1, k + 11, Blocks.air, 0, 2);
        world.setBlock(i + 3, j + 1, k + 11, Blocks.air, 0, 2);
        world.setBlock(i + 4, j + 1, k + 11, Blocks.air, 0, 2);
        world.setBlock(i + 5, j + 1, k + 11, Blocks.air, 0, 2);
        world.setBlock(i + 6, j + 1, k + 11, Blocks.air, 0, 2);
        world.setBlock(i + 7, j + 1, k + 11, Blocks.air, 0, 2);
        world.setBlock(i + 8, j + 1, k + 11, Blocks.air, 0, 2);
        world.setBlock(i + 9, j + 1, k + 11, Blocks.air, 0, 2);
        world.setBlock(i + 10, j + 1, k + 11, Blocks.air, 0, 2);
        world.setBlock(i + 11, j + 1, k + 11, Blocks.air, 0, 2);
        world.setBlock(i + 12, j + 1, k + 11, Blocks.air, 0, 2);
        world.setBlock(i + 13, j + 1, k + 11, Blocks.air, 0, 2);
        world.setBlock(i + 14, j + 1, k + 11, NovaCraftBlocks.cobbled_grimstone_slab, 3, 2);
        world.setBlock(i + 15, j + 1, k + 11, Blocks.air, 0, 2);
        world.setBlock(i + 16, j + 1, k + 11, NovaCraftBlocks.cobbled_grimstone_wall, 0, 2);
        world.setBlock(i + 17, j + 1, k + 11, placeStoneBricks(random), 0, 2);
        world.setBlock(i + 1, j + 1, k + 12, Blocks.iron_bars, 0, 2);
        world.setBlock(i + 2, j + 1, k + 12, Blocks.air, 0, 2);
        world.setBlock(i + 3, j + 1, k + 12, Blocks.air, 0, 2);
        world.setBlock(i + 4, j + 1, k + 12, Blocks.air, 0, 2);
        world.setBlock(i + 5, j + 1, k + 12, Blocks.air, 0, 2);
        world.setBlock(i + 6, j + 1, k + 12, Blocks.air, 0, 2);
        world.setBlock(i + 7, j + 1, k + 12, Blocks.air, 0, 2);
        world.setBlock(i + 8, j + 1, k + 12, Blocks.air, 0, 2);
        world.setBlock(i + 9, j + 1, k + 12, Blocks.air, 0, 2);
        world.setBlock(i + 10, j + 1, k + 12, Blocks.air, 0, 2);
        world.setBlock(i + 11, j + 1, k + 12, Blocks.air, 0, 2);
        world.setBlock(i + 12, j + 1, k + 12, Blocks.air, 0, 2);
        world.setBlock(i + 13, j + 1, k + 12, Blocks.air, 0, 2);
        world.setBlock(i + 14, j + 1, k + 12, Blocks.air, 0, 2);
        world.setBlock(i + 15, j + 1, k + 12, Blocks.air, 0, 2);
        world.setBlock(i + 16, j + 1, k + 12, NovaCraftBlocks.cobbled_grimstone_wall, 0, 2);
        world.setBlock(i + 17, j + 1, k + 12, placeStoneBricks(random), 0, 2);
        world.setBlock(i + 1, j + 1, k + 13, placeStoneBricks(random), 0, 2);
        world.setBlock(i + 2, j + 1, k + 13, Blocks.web, 0, 2);
        world.setBlock(i + 3, j + 1, k + 13, Blocks.air, 0, 2);
        world.setBlock(i + 4, j + 1, k + 13, NovaCraftBlocks.cobbled_grimstone_slab, 3, 2);
        world.setBlock(i + 5, j + 1, k + 13, Blocks.air, 0, 2);
        world.setBlock(i + 6, j + 1, k + 13, Blocks.air, 0, 2);
        world.setBlock(i + 7, j + 1, k + 13, Blocks.air, 0, 2);
        world.setBlock(i + 8, j + 1, k + 13, Blocks.air, 0, 2);
        world.setBlock(i + 9, j + 1, k + 13, Blocks.air, 0, 2);
        world.setBlock(i + 10, j + 1, k + 13, NovaCraftBlocks.cobbled_grimstone_slab, 3, 2);
        world.setBlock(i + 11, j + 1, k + 13, Blocks.air, 0, 2);
        world.setBlock(i + 12, j + 1, k + 13, Blocks.air, 0, 2);
        world.setBlock(i + 13, j + 1, k + 13, Blocks.air, 0, 2);
        world.setBlock(i + 14, j + 1, k + 13, Blocks.air, 0, 2);
        world.setBlock(i + 15, j + 1, k + 13, Blocks.air, 0, 2);
        world.setBlock(i + 16, j + 1, k + 13, Blocks.skull, 1, 2);
        world.setBlock(i + 17, j + 1, k + 13, placeStoneBricks(random), 0, 2);
        world.setBlock(i + 1, j + 1, k + 14, placeStoneBricks(random), 0, 2);
        world.setBlock(i + 2, j + 1, k + 14, Blocks.air, 0, 2);
        world.setBlock(i + 3, j + 1, k + 14, Blocks.air, 0, 2);
        world.setBlock(i + 4, j + 1, k + 14, Blocks.air, 0, 2);
        world.setBlock(i + 5, j + 1, k + 14, Blocks.air, 0, 2);
        world.setBlock(i + 6, j + 1, k + 14, Blocks.web, 0, 2);
        world.setBlock(i + 7, j + 1, k + 14, Blocks.air, 0, 2);
        world.setBlock(i + 8, j + 1, k + 14, Blocks.web, 0, 2);
        world.setBlock(i + 9, j + 1, k + 14, Blocks.air, 0, 2);
        world.setBlock(i + 10, j + 1, k + 14, Blocks.air, 0, 2);
        world.setBlock(i + 11, j + 1, k + 14, Blocks.air, 0, 2);
        world.setBlock(i + 12, j + 1, k + 14, Blocks.air, 0, 2);
        world.setBlock(i + 13, j + 1, k + 14, Blocks.air, 0, 2);
        world.setBlock(i + 14, j + 1, k + 14, Blocks.air, 0, 2);
        world.setBlock(i + 15, j + 1, k + 14, Blocks.air, 0, 2);
        world.setBlock(i + 16, j + 1, k + 14, Blocks.air, 0, 2);
        world.setBlock(i + 17, j + 1, k + 14, placeStoneBricks(random), 0, 2);
        world.setBlock(i + 1, j + 1, k + 15, placeStoneBricks(random), 0, 2);
        world.setBlock(i + 2, j + 1, k + 15, placeStoneBricks(random), 0, 2);
        world.setBlock(i + 3, j + 1, k + 15, placeStoneBricks(random), 0, 2);
        world.setBlock(i + 4, j + 1, k + 15, placeStoneBricks(random), 0, 2);
        world.setBlock(i + 5, j + 1, k + 15, placeStoneBricks(random), 0, 2);
        world.setBlock(i + 6, j + 1, k + 15, placeStoneBricks(random), 0, 2);
        world.setBlock(i + 7, j + 1, k + 15, placeStoneBricks(random), 0, 2);
        world.setBlock(i + 8, j + 1, k + 15, placeStoneBricks(random), 0, 2);
        world.setBlock(i + 9, j + 1, k + 15, placeStoneBricks(random), 0, 2);
        world.setBlock(i + 10, j + 1, k + 15, Blocks.air, 0, 2);
        world.setBlock(i + 11, j + 1, k + 15, Blocks.air, 0, 2);
        world.setBlock(i + 12, j + 1, k + 15, Blocks.air, 0, 2);
        world.setBlock(i + 13, j + 1, k + 15, Blocks.air, 0, 2);
        world.setBlock(i + 14, j + 1, k + 15, Blocks.air, 0, 2);
        world.setBlock(i + 15, j + 1, k + 15, placeStoneBricks(random), 0, 2);
        world.setBlock(i + 16, j + 1, k + 15, placeStoneBricks(random), 0, 2);
        world.setBlock(i + 17, j + 1, k + 15, placeStoneBricks(random), 0, 2);
        world.setBlock(i + 8, j + 1, k + 16, placeStoneBricks(random), 0, 2);
        world.setBlock(i + 10, j + 1, k + 16, Blocks.air, 0, 2);
        world.setBlock(i + 11, j + 1, k + 16, Blocks.air, 0, 2);
        world.setBlock(i + 12, j + 1, k + 16, NovaCraftBlocks.cobbled_grimstone_slab, 3, 2);
        world.setBlock(i + 13, j + 1, k + 16, Blocks.air, 0, 2);
        world.setBlock(i + 14, j + 1, k + 16, Blocks.air, 0, 2);
        world.setBlock(i + 16, j + 1, k + 16, placeStoneBricks(random), 0, 2);
        world.setBlock(i + 8, j + 1, k + 17, placeStoneBricks(random), 0, 2);
        world.setBlock(i + 9, j + 1, k + 17, Blocks.air, 0, 2);
        world.setBlock(i + 10, j + 1, k + 17, Blocks.air, 0, 2);
        world.setBlock(i + 11, j + 1, k + 17, Blocks.air, 0, 2);
        world.setBlock(i + 12, j + 1, k + 17, Blocks.air, 0, 2);
        world.setBlock(i + 13, j + 1, k + 17, Blocks.air, 0, 2);
        world.setBlock(i + 14, j + 1, k + 17, Blocks.air, 0, 2);
        world.setBlock(i + 15, j + 1, k + 17, Blocks.air, 0, 2);
        world.setBlock(i + 16, j + 1, k + 17, placeStoneBricks(random), 0, 2);
        world.setBlock(i + 8, j + 1, k + 18, placeStoneBricks(random), 0, 2);
        world.setBlock(i + 9, j + 1, k + 18, NovaCraftBlocks.cobbled_grimstone_stairs, 3, 2);
        world.setBlock(i + 10, j + 1, k + 18, Blocks.air, 0, 2);
        world.setBlock(i + 11, j + 1, k + 18, Blocks.air, 0, 2);
        world.setBlock(i + 12, j + 1, k + 18, Blocks.air, 0, 2);
        world.setBlock(i + 13, j + 1, k + 18, Blocks.air, 0, 2);
        world.setBlock(i + 14, j + 1, k + 18, Blocks.air, 0, 2);
        world.setBlock(i + 15, j + 1, k + 18, NovaCraftBlocks.cobbled_grimstone_stairs, 3, 2);
        world.setBlock(i + 16, j + 1, k + 18, placeStoneBricks(random), 0, 2);
        world.setBlock(i + 8, j + 1, k + 19, placeStoneBricks(random), 0, 2);
        world.setBlock(i + 9, j + 1, k + 19, Blocks.air, 0, 2);
        world.setBlock(i + 10, j + 1, k + 19, Blocks.air, 0, 2);
        world.setBlock(i + 11, j + 1, k + 19, Blocks.air, 0, 2);
        world.setBlock(i + 12, j + 1, k + 19, Blocks.air, 0, 2);
        world.setBlock(i + 13, j + 1, k + 19, Blocks.air, 0, 2);
        world.setBlock(i + 14, j + 1, k + 19, Blocks.skull, 1, 2);
        world.setBlock(i + 15, j + 1, k + 19, Blocks.air, 0, 2);
        world.setBlock(i + 16, j + 1, k + 19, placeStoneBricks(random), 0, 2);
        world.setBlock(i + 8, j + 1, k + 20, placeStoneBricks(random), 0, 2);
        world.setBlock(i + 9, j + 1, k + 20, NovaCraftBlocks.cobbled_grimstone_stairs, 2, 2);
        world.setBlock(i + 10, j + 1, k + 20, Blocks.air, 0, 2);
        world.setBlock(i + 11, j + 1, k + 20, Blocks.air, 0, 2);
        world.setBlock(i + 12, j + 1, k + 20, Blocks.air, 0, 2);
        world.setBlock(i + 13, j + 1, k + 20, NovaCraftBlocks.cobbled_grimstone_slab, 3, 2);
        world.setBlock(i + 14, j + 1, k + 20, Blocks.air, 0, 2);
        world.setBlock(i + 15, j + 1, k + 20, NovaCraftBlocks.cobbled_grimstone_stairs, 2, 2);
        world.setBlock(i + 16, j + 1, k + 20, placeStoneBricks(random), 0, 2);
        world.setBlock(i + 8, j + 1, k + 21, placeStoneBricks(random), 0, 2);
        world.setBlock(i + 9, j + 1, k + 21, Blocks.air, 0, 2);
        world.setBlock(i + 10, j + 1, k + 21, Blocks.air, 0, 2);
        world.setBlock(i + 11, j + 1, k + 21, Blocks.air, 0, 2);
        world.setBlock(i + 13, j + 1, k + 21, Blocks.air, 0, 2);
        world.setBlock(i + 14, j + 1, k + 21, Blocks.air, 0, 2);
        world.setBlock(i + 15, j + 1, k + 21, Blocks.air, 0, 2);
        world.setBlock(i + 16, j + 1, k + 21, placeStoneBricks(random), 0, 2);
        world.setBlock(i + 8, j + 1, k + 22, placeStoneBricks(random), 0, 2);
        world.setBlock(i + 9, j + 1, k + 22, placeStoneBricks(random), 0, 2);
        world.setBlock(i + 10, j + 1, k + 22, placeStoneBricks(random), 0, 2);
        world.setBlock(i + 11, j + 1, k + 22, placeStoneBricks(random), 0, 2);
        world.setBlock(i + 12, j + 1, k + 22, placeStoneBricks(random), 0, 2);
        world.setBlock(i + 13, j + 1, k + 22, placeStoneBricks(random), 0, 2);
        world.setBlock(i + 14, j + 1, k + 22, placeStoneBricks(random), 0, 2);
        world.setBlock(i + 15, j + 1, k + 22, placeStoneBricks(random), 0, 2);
        world.setBlock(i + 16, j + 1, k + 22, placeStoneBricks(random), 0, 2);
        world.setBlock(i + 8, j + 2, k, placeStoneBricks(random), 0, 2);
        world.setBlock(i + 9, j + 2, k, placeStoneBricks(random), 0, 2);
        world.setBlock(i + 10, j + 2, k, NovaCraftBlocks.sculk_block, 0, 2);
        world.setBlock(i + 11, j + 2, k, placeStoneBricks(random), 0, 2);
        world.setBlock(i + 12, j + 2, k, placeStoneBricks(random), 0, 2);
        world.setBlock(i + 13, j + 2, k, placeStoneBricks(random), 0, 2);
        world.setBlock(i + 14, j + 2, k, placeStoneBricks(random), 0, 2);
        world.setBlock(i + 15, j + 2, k, placeStoneBricks(random), 0, 2);
        world.setBlock(i + 16, j + 2, k, placeStoneBricks(random), 0, 2);
        world.setBlock(i + 8, j + 2, k + 1, placeStoneBricks(random), 0, 2);
        world.setBlock(i + 9, j + 2, k + 1, Blocks.air, 0, 2);
        world.setBlock(i + 10, j + 2, k + 1, Blocks.air, 0, 2);
        world.setBlock(i + 11, j + 2, k + 1, Blocks.air, 0, 2);
        world.setBlock(i + 12, j + 2, k + 1, Blocks.air, 0, 2);
        world.setBlock(i + 13, j + 2, k + 1, Blocks.air, 0, 2);
        world.setBlock(i + 14, j + 2, k + 1, Blocks.air, 0, 2);
        world.setBlock(i + 15, j + 2, k + 1, Blocks.air, 0, 2);
        world.setBlock(i + 16, j + 2, k + 1, placeStoneBricks(random), 0, 2);
        world.setBlock(i + 8, j + 2, k + 2, placeStoneBricks(random), 0, 2);
        world.setBlock(i + 9, j + 2, k + 2, Blocks.air, 0, 2);
        world.setBlock(i + 10, j + 2, k + 2, Blocks.air, 0, 2);
        world.setBlock(i + 11, j + 2, k + 2, Blocks.air, 0, 2);
        world.setBlock(i + 12, j + 2, k + 2, Blocks.air, 0, 2);
        world.setBlock(i + 13, j + 2, k + 2, Blocks.air, 0, 2);
        world.setBlock(i + 14, j + 2, k + 2, Blocks.air, 0, 2);
        world.setBlock(i + 15, j + 2, k + 2, Blocks.air, 0, 2);
        world.setBlock(i + 16, j + 2, k + 2, NovaCraftBlocks.sculk_block, 0, 2);
        world.setBlock(i + 8, j + 2, k + 3, placeStoneBricks(random), 0, 2);
        world.setBlock(i + 9, j + 2, k + 3, Blocks.air, 0, 2);
        world.setBlock(i + 10, j + 2, k + 3, Blocks.air, 0, 2);
        world.setBlock(i + 11, j + 2, k + 3, Blocks.air, 0, 2);
        world.setBlock(i + 12, j + 2, k + 3, Blocks.air, 0, 2);
        world.setBlock(i + 13, j + 2, k + 3, Blocks.air, 0, 2);
        world.setBlock(i + 14, j + 2, k + 3, Blocks.air, 0, 2);
        world.setBlock(i + 15, j + 2, k + 3, Blocks.air, 0, 2);
        world.setBlock(i + 16, j + 2, k + 3, placeStoneBricks(random), 0, 2);
        world.setBlock(i + 8, j + 2, k + 4, NovaCraftBlocks.sculk_block, 0, 2);
        world.setBlock(i + 9, j + 2, k + 4, Blocks.air, 0, 2);
        world.setBlock(i + 10, j + 2, k + 4, Blocks.air, 0, 2);
        world.setBlock(i + 11, j + 2, k + 4, Blocks.air, 0, 2);
        world.setBlock(i + 12, j + 2, k + 4, NovaCraftBlocks.vanite_glass, 0, 2);
        world.setBlock(i + 13, j + 2, k + 4, Blocks.air, 0, 2);
        world.setBlock(i + 14, j + 2, k + 4, Blocks.air, 0, 2);
        world.setBlock(i + 15, j + 2, k + 4, Blocks.air, 0, 2);
        world.setBlock(i + 16, j + 2, k + 4, placeStoneBricks(random), 0, 2);
        world.setBlock(i + 8, j + 2, k + 5, placeStoneBricks(random), 0, 2);
        world.setBlock(i + 9, j + 2, k + 5, Blocks.air, 0, 2);
        world.setBlock(i + 10, j + 2, k + 5, Blocks.air, 0, 2);
        world.setBlock(i + 11, j + 2, k + 5, Blocks.air, 0, 2);
        world.setBlock(i + 12, j + 2, k + 5, Blocks.air, 0, 2);
        world.setBlock(i + 13, j + 2, k + 5, Blocks.air, 0, 2);
        world.setBlock(i + 14, j + 2, k + 5, Blocks.air, 0, 2);
        world.setBlock(i + 15, j + 2, k + 5, Blocks.web, 0, 2);
        world.setBlock(i + 16, j + 2, k + 5, placeStoneBricks(random), 0, 2);
        world.setBlock(i + 8, j + 2, k + 6, placeStoneBricks(random), 0, 2);
        world.setBlock(i + 9, j + 2, k + 6, Blocks.air, 0, 2);
        world.setBlock(i + 10, j + 2, k + 6, Blocks.air, 0, 2);
        world.setBlock(i + 11, j + 2, k + 6, Blocks.air, 0, 2);
        world.setBlock(i + 12, j + 2, k + 6, Blocks.air, 0, 2);
        world.setBlock(i + 13, j + 2, k + 6, Blocks.air, 0, 2);
        world.setBlock(i + 14, j + 2, k + 6, Blocks.air, 0, 2);
        world.setBlock(i + 15, j + 2, k + 6, Blocks.air, 0, 2);
        world.setBlock(i + 16, j + 2, k + 6, placeStoneBricks(random), 0, 2);
        world.setBlock(i + 8, j + 2, k + 7, placeStoneBricks(random), 0, 2);
        world.setBlock(i + 9, j + 2, k + 7, placeStoneBricks(random), 0, 2);
        world.setBlock(i + 10, j + 2, k + 7, Blocks.air, 0, 2);
        world.setBlock(i + 11, j + 2, k + 7, Blocks.iron_bars, 0, 2);
        world.setBlock(i + 12, j + 2, k + 7, Blocks.air, 0, 2);
        world.setBlock(i + 13, j + 2, k + 7, Blocks.air, 0, 2);
        world.setBlock(i + 14, j + 2, k + 7, Blocks.iron_bars, 0, 2);
        world.setBlock(i + 15, j + 2, k + 7, placeStoneBricks(random), 0, 2);
        world.setBlock(i + 16, j + 2, k + 7, placeStoneBricks(random), 0, 2);
        world.setBlock(i + 1, j + 2, k + 8, placeStoneBricks(random), 0, 2);
        world.setBlock(i + 2, j + 2, k + 8, placeStoneBricks(random), 0, 2);
        world.setBlock(i + 3, j + 2, k + 8, placeStoneBricks(random), 0, 2);
        world.setBlock(i + 4, j + 2, k + 8, placeStoneBricks(random), 0, 2);
        world.setBlock(i + 5, j + 2, k + 8, placeStoneBricks(random), 0, 2);
        world.setBlock(i + 6, j + 2, k + 8, placeStoneBricks(random), 0, 2);
        world.setBlock(i + 7, j + 2, k + 8, placeStoneBricks(random), 0, 2);
        world.setBlock(i + 8, j + 2, k + 8, placeStoneBricks(random), 0, 2);
        world.setBlock(i + 9, j + 2, k + 8, placeStoneBricks(random), 0, 2);
        world.setBlock(i + 10, j + 2, k + 8, Blocks.air, 0, 2);
        world.setBlock(i + 11, j + 2, k + 8, Blocks.air, 0, 2);
        world.setBlock(i + 12, j + 2, k + 8, Blocks.air, 0, 2);
        world.setBlock(i + 13, j + 2, k + 8, Blocks.air, 0, 2);
        world.setBlock(i + 14, j + 2, k + 8, Blocks.air, 0, 2);
        world.setBlock(i + 15, j + 2, k + 8, placeStoneBricks(random), 0, 2);
        world.setBlock(i + 16, j + 2, k + 8, placeStoneBricks(random), 0, 2);
        world.setBlock(i + 17, j + 2, k + 8, placeStoneBricks(random), 0, 2);
        world.setBlock(i + 1, j + 2, k + 9, placeStoneBricks(random), 0, 2);
        world.setBlock(i + 2, j + 2, k + 9, Blocks.air, 0, 2);
        world.setBlock(i + 3, j + 2, k + 9, Blocks.air, 0, 2);
        world.setBlock(i + 4, j + 2, k + 9, Blocks.air, 0, 2);
        world.setBlock(i + 5, j + 2, k + 9, Blocks.air, 0, 2);
        world.setBlock(i + 6, j + 2, k + 9, Blocks.air, 0, 2);
        world.setBlock(i + 7, j + 2, k + 9, Blocks.air, 0, 2);
        world.setBlock(i + 8, j + 2, k + 9, Blocks.air, 0, 2);
        world.setBlock(i + 9, j + 2, k + 9, Blocks.air, 0, 2);
        world.setBlock(i + 10, j + 2, k + 9, Blocks.air, 0, 2);
        world.setBlock(i + 11, j + 2, k + 9, Blocks.air, 0, 2);
        world.setBlock(i + 12, j + 2, k + 9, Blocks.air, 0, 2);
        world.setBlock(i + 13, j + 2, k + 9, Blocks.air, 0, 2);
        world.setBlock(i + 14, j + 2, k + 9, Blocks.air, 0, 2);
        world.setBlock(i + 15, j + 2, k + 9, Blocks.air, 0, 2);
        world.setBlock(i + 16, j + 2, k + 9, Blocks.air, 0, 2);
        world.setBlock(i + 17, j + 2, k + 9, placeStoneBricks(random), 0, 2);
        world.setBlock(i + 1, j + 2, k + 10, placeStoneBricks(random), 0, 2);
        world.setBlock(i + 2, j + 2, k + 10, Blocks.air, 0, 2);
        world.setBlock(i + 3, j + 2, k + 10, Blocks.air, 0, 2);
        world.setBlock(i + 4, j + 2, k + 10, Blocks.air, 0, 2);
        world.setBlock(i + 5, j + 2, k + 10, Blocks.air, 0, 2);
        world.setBlock(i + 6, j + 2, k + 10, Blocks.air, 0, 2);
        world.setBlock(i + 7, j + 2, k + 10, Blocks.air, 0, 2);
        world.setBlock(i + 8, j + 2, k + 10, Blocks.air, 0, 2);
        world.setBlock(i + 9, j + 2, k + 10, Blocks.air, 0, 2);
        world.setBlock(i + 10, j + 2, k + 10, Blocks.air, 0, 2);
        world.setBlock(i + 11, j + 2, k + 10, Blocks.air, 0, 2);
        world.setBlock(i + 12, j + 2, k + 10, Blocks.air, 0, 2);
        world.setBlock(i + 13, j + 2, k + 10, Blocks.air, 0, 2);
        world.setBlock(i + 14, j + 2, k + 10, Blocks.air, 0, 2);
        world.setBlock(i + 15, j + 2, k + 10, Blocks.air, 0, 2);
        world.setBlock(i + 16, j + 2, k + 10, Blocks.air, 0, 2);
        world.setBlock(i + 17, j + 2, k + 10, placeStoneBricks(random), 0, 2);
        world.setBlock(i + 1, j + 2, k + 11, Blocks.planks, 5, 2);
        world.setBlock(i + 2, j + 2, k + 11, Blocks.air, 0, 2);
        world.setBlock(i + 3, j + 2, k + 11, Blocks.air, 0, 2);
        world.setBlock(i + 4, j + 2, k + 11, Blocks.air, 0, 2);
        world.setBlock(i + 5, j + 2, k + 11, Blocks.air, 0, 2);
        world.setBlock(i + 6, j + 2, k + 11, Blocks.air, 0, 2);
        world.setBlock(i + 7, j + 2, k + 11, Blocks.air, 0, 2);
        world.setBlock(i + 8, j + 2, k + 11, Blocks.air, 0, 2);
        world.setBlock(i + 9, j + 2, k + 11, Blocks.air, 0, 2);
        world.setBlock(i + 10, j + 2, k + 11, Blocks.air, 0, 2);
        world.setBlock(i + 11, j + 2, k + 11, Blocks.air, 0, 2);
        world.setBlock(i + 12, j + 2, k + 11, Blocks.air, 0, 2);
        world.setBlock(i + 13, j + 2, k + 11, Blocks.air, 0, 2);
        world.setBlock(i + 14, j + 2, k + 11, Blocks.air, 0, 2);
        world.setBlock(i + 15, j + 2, k + 11, Blocks.air, 0, 2);
        world.setBlock(i + 16, j + 2, k + 11, Blocks.air, 0, 2);
        world.setBlock(i + 17, j + 2, k + 11, placeStoneBricks(random), 0, 2);
        world.setBlock(i + 1, j + 2, k + 12, Blocks.planks, 5, 2);
        world.setBlock(i + 2, j + 2, k + 12, Blocks.air, 0, 2);
        world.setBlock(i + 3, j + 2, k + 12, Blocks.air, 0, 2);
        world.setBlock(i + 4, j + 2, k + 12, Blocks.air, 0, 2);
        world.setBlock(i + 5, j + 2, k + 12, Blocks.air, 0, 2);
        world.setBlock(i + 6, j + 2, k + 12, Blocks.air, 0, 2);
        world.setBlock(i + 7, j + 2, k + 12, Blocks.air, 0, 2);
        world.setBlock(i + 8, j + 2, k + 12, Blocks.air, 0, 2);
        world.setBlock(i + 9, j + 2, k + 12, Blocks.air, 0, 2);
        world.setBlock(i + 10, j + 2, k + 12, Blocks.air, 0, 2);
        world.setBlock(i + 11, j + 2, k + 12, Blocks.air, 0, 2);
        world.setBlock(i + 12, j + 2, k + 12, Blocks.air, 0, 2);
        world.setBlock(i + 13, j + 2, k + 12, Blocks.air, 0, 2);
        world.setBlock(i + 14, j + 2, k + 12, Blocks.air, 0, 2);
        world.setBlock(i + 15, j + 2, k + 12, Blocks.air, 0, 2);
        world.setBlock(i + 16, j + 2, k + 12, Blocks.air, 0, 2);
        world.setBlock(i + 17, j + 2, k + 12, placeStoneBricks(random), 0, 2);
        world.setBlock(i + 1, j + 2, k + 13, placeStoneBricks(random), 0, 2);
        world.setBlock(i + 2, j + 2, k + 13, Blocks.air, 0, 2);
        world.setBlock(i + 3, j + 2, k + 13, Blocks.air, 0, 2);
        world.setBlock(i + 4, j + 2, k + 13, Blocks.air, 0, 2);
        world.setBlock(i + 5, j + 2, k + 13, Blocks.air, 0, 2);
        world.setBlock(i + 6, j + 2, k + 13, Blocks.air, 0, 2);
        world.setBlock(i + 7, j + 2, k + 13, Blocks.air, 0, 2);
        world.setBlock(i + 8, j + 2, k + 13, Blocks.air, 0, 2);
        world.setBlock(i + 9, j + 2, k + 13, Blocks.air, 0, 2);
        world.setBlock(i + 10, j + 2, k + 13, Blocks.air, 0, 2);
        world.setBlock(i + 11, j + 2, k + 13, Blocks.air, 0, 2);
        world.setBlock(i + 12, j + 2, k + 13, Blocks.air, 0, 2);
        world.setBlock(i + 13, j + 2, k + 13, Blocks.air, 0, 2);
        world.setBlock(i + 14, j + 2, k + 13, Blocks.air, 0, 2);
        world.setBlock(i + 15, j + 2, k + 13, Blocks.air, 0, 2);
        world.setBlock(i + 16, j + 2, k + 13, Blocks.air, 0, 2);
        world.setBlock(i + 17, j + 2, k + 13, placeStoneBricks(random), 0, 2);
        world.setBlock(i + 1, j + 2, k + 14, placeStoneBricks(random), 0, 2);
        world.setBlock(i + 2, j + 2, k + 14, Blocks.air, 0, 2);
        world.setBlock(i + 3, j + 2, k + 14, Blocks.air, 0, 2);
        world.setBlock(i + 4, j + 2, k + 14, Blocks.web, 0, 2);
        world.setBlock(i + 5, j + 2, k + 14, Blocks.air, 0, 2);
        world.setBlock(i + 6, j + 2, k + 14, Blocks.air, 0, 2);
        world.setBlock(i + 7, j + 2, k + 14, Blocks.air, 0, 2);
        world.setBlock(i + 8, j + 2, k + 14, Blocks.web, 0, 2);
        world.setBlock(i + 9, j + 2, k + 14, Blocks.air, 0, 2);
        world.setBlock(i + 10, j + 2, k + 14, Blocks.air, 0, 2);
        world.setBlock(i + 11, j + 2, k + 14, Blocks.air, 0, 2);
        world.setBlock(i + 12, j + 2, k + 14, Blocks.air, 0, 2);
        world.setBlock(i + 13, j + 2, k + 14, Blocks.air, 0, 2);
        world.setBlock(i + 14, j + 2, k + 14, Blocks.air, 0, 2);
        world.setBlock(i + 15, j + 2, k + 14, Blocks.air, 0, 2);
        world.setBlock(i + 16, j + 2, k + 14, Blocks.air, 0, 2);
        world.setBlock(i + 17, j + 2, k + 14, placeStoneBricks(random), 0, 2);
        world.setBlock(i + 1, j + 2, k + 15, placeStoneBricks(random), 0, 2);
        world.setBlock(i + 2, j + 2, k + 15, placeStoneBricks(random), 0, 2);
        world.setBlock(i + 3, j + 2, k + 15, placeStoneBricks(random), 0, 2);
        world.setBlock(i + 4, j + 2, k + 15, placeStoneBricks(random), 0, 2);
        world.setBlock(i + 5, j + 2, k + 15, placeStoneBricks(random), 0, 2);
        world.setBlock(i + 6, j + 2, k + 15, placeStoneBricks(random), 0, 2);
        world.setBlock(i + 7, j + 2, k + 15, placeStoneBricks(random), 0, 2);
        world.setBlock(i + 8, j + 2, k + 15, placeStoneBricks(random), 0, 2);
        world.setBlock(i + 9, j + 2, k + 15, placeStoneBricks(random), 0, 2);
        world.setBlock(i + 10, j + 2, k + 15, Blocks.air, 0, 2);
        world.setBlock(i + 11, j + 2, k + 15, Blocks.air, 0, 2);
        world.setBlock(i + 12, j + 2, k + 15, Blocks.air, 0, 2);
        world.setBlock(i + 13, j + 2, k + 15, Blocks.air, 0, 2);
        world.setBlock(i + 14, j + 2, k + 15, Blocks.air, 0, 2);
        world.setBlock(i + 15, j + 2, k + 15, placeStoneBricks(random), 0, 2);
        world.setBlock(i + 16, j + 2, k + 15, placeStoneBricks(random), 0, 2);
        world.setBlock(i + 17, j + 2, k + 15, placeStoneBricks(random), 0, 2);
        world.setBlock(i + 8, j + 2, k + 16, placeStoneBricks(random), 0, 2);
        world.setBlock(i + 9, j + 2, k + 16, Blocks.air, 0, 2);
        world.setBlock(i + 10, j + 2, k + 16, Blocks.air, 0, 2);
        world.setBlock(i + 11, j + 2, k + 16, Blocks.air, 0, 2);
        world.setBlock(i + 12, j + 2, k + 16, Blocks.air, 0, 2);
        world.setBlock(i + 13, j + 2, k + 16, Blocks.air, 0, 2);
        world.setBlock(i + 14, j + 2, k + 16, Blocks.air, 0, 2);
        world.setBlock(i + 15, j + 2, k + 16, Blocks.air, 0, 2);
        world.setBlock(i + 16, j + 2, k + 16, placeStoneBricks(random), 0, 2);
        world.setBlock(i + 8, j + 2, k + 17, placeStoneBricks(random), 0, 2);
        world.setBlock(i + 9, j + 2, k + 17, Blocks.air, 0, 2);
        world.setBlock(i + 10, j + 2, k + 17, Blocks.air, 0, 2);
        world.setBlock(i + 11, j + 2, k + 17, Blocks.air, 0, 2);
        world.setBlock(i + 12, j + 2, k + 17, Blocks.air, 0, 2);
        world.setBlock(i + 13, j + 2, k + 17, Blocks.air, 0, 2);
        world.setBlock(i + 14, j + 2, k + 17, Blocks.air, 0, 2);
        world.setBlock(i + 15, j + 2, k + 17, Blocks.air, 0, 2);
        world.setBlock(i + 16, j + 2, k + 17, placeStoneBricks(random), 0, 2);
        world.setBlock(i + 8, j + 2, k + 18, placeStoneBricks(random), 0, 2);
        world.setBlock(i + 9, j + 2, k + 18, Blocks.air, 0, 2);
        world.setBlock(i + 10, j + 2, k + 18, Blocks.air, 0, 2);
        world.setBlock(i + 11, j + 2, k + 18, Blocks.air, 0, 2);
        world.setBlock(i + 12, j + 2, k + 18, Blocks.air, 0, 2);
        world.setBlock(i + 13, j + 2, k + 18, Blocks.air, 0, 2);
        world.setBlock(i + 14, j + 2, k + 18, Blocks.air, 0, 2);
        world.setBlock(i + 15, j + 2, k + 18, Blocks.air, 0, 2);
        world.setBlock(i + 16, j + 2, k + 18, placeStoneBricks(random), 0, 2);
        world.setBlock(i + 8, j + 2, k + 19, placeStoneBricks(random), 0, 2);
        world.setBlock(i + 9, j + 2, k + 19, Blocks.air, 0, 2);
        world.setBlock(i + 10, j + 2, k + 19, Blocks.air, 0, 2);
        world.setBlock(i + 11, j + 2, k + 19, Blocks.air, 0, 2);
        world.setBlock(i + 12, j + 2, k + 19, Blocks.air, 0, 2);
        world.setBlock(i + 13, j + 2, k + 19, Blocks.air, 0, 2);
        world.setBlock(i + 14, j + 2, k + 19, Blocks.air, 0, 2);
        world.setBlock(i + 15, j + 2, k + 19, Blocks.air, 0, 2);
        world.setBlock(i + 16, j + 2, k + 19, placeStoneBricks(random), 0, 2);
        world.setBlock(i + 8, j + 2, k + 20, placeStoneBricks(random), 0, 2);
        world.setBlock(i + 9, j + 2, k + 20, Blocks.air, 0, 2);
        world.setBlock(i + 10, j + 2, k + 20, Blocks.air, 0, 2);
        world.setBlock(i + 11, j + 2, k + 20, Blocks.air, 0, 2);
        world.setBlock(i + 12, j + 2, k + 20, Blocks.air, 0, 2);
        world.setBlock(i + 13, j + 2, k + 20, Blocks.air, 0, 2);
        world.setBlock(i + 14, j + 2, k + 20, Blocks.air, 0, 2);
        world.setBlock(i + 15, j + 2, k + 20, Blocks.air, 0, 2);
        world.setBlock(i + 16, j + 2, k + 20, placeStoneBricks(random), 0, 2);
        world.setBlock(i + 8, j + 2, k + 21, placeStoneBricks(random), 0, 2);
        world.setBlock(i + 9, j + 2, k + 21, Blocks.air, 0, 2);
        world.setBlock(i + 10, j + 2, k + 21, Blocks.air, 0, 2);
        world.setBlock(i + 11, j + 2, k + 21, Blocks.air, 0, 2);
        world.setBlock(i + 12, j + 2, k + 21, Blocks.air, 0, 2);
        world.setBlock(i + 13, j + 2, k + 21, Blocks.air, 0, 2);
        world.setBlock(i + 14, j + 2, k + 21, Blocks.air, 0, 2);
        world.setBlock(i + 15, j + 2, k + 21, Blocks.air, 0, 2);
        world.setBlock(i + 16, j + 2, k + 21, placeStoneBricks(random), 0, 2);
        world.setBlock(i + 8, j + 2, k + 22, placeStoneBricks(random), 0, 2);
        world.setBlock(i + 9, j + 2, k + 22, placeStoneBricks(random), 0, 2);
        world.setBlock(i + 10, j + 2, k + 22, placeStoneBricks(random), 0, 2);
        world.setBlock(i + 11, j + 2, k + 22, placeStoneBricks(random), 0, 2);
        world.setBlock(i + 12, j + 2, k + 22, placeStoneBricks(random), 0, 2);
        world.setBlock(i + 13, j + 2, k + 22, placeStoneBricks(random), 0, 2);
        world.setBlock(i + 14, j + 2, k + 22, placeStoneBricks(random), 0, 2);
        world.setBlock(i + 15, j + 2, k + 22, placeStoneBricks(random), 0, 2);
        world.setBlock(i + 16, j + 2, k + 22, placeStoneBricks(random), 0, 2);
        world.setBlock(i + 8, j + 3, k, placeStoneBricks(random), 0, 2);
        world.setBlock(i + 9, j + 3, k, placeStoneBricks(random), 0, 2);
        world.setBlock(i + 10, j + 3, k, placeStoneBricks(random), 0, 2);
        world.setBlock(i + 11, j + 3, k, placeStoneBricks(random), 0, 2);
        world.setBlock(i + 12, j + 3, k, placeStoneBricks(random), 0, 2);
        world.setBlock(i + 13, j + 3, k, NovaCraftBlocks.sculk_block, 0, 2);
        world.setBlock(i + 14, j + 3, k, placeStoneBricks(random), 0, 2);
        world.setBlock(i + 15, j + 3, k, placeStoneBricks(random), 0, 2);
        world.setBlock(i + 16, j + 3, k, placeStoneBricks(random), 0, 2);
        world.setBlock(i + 8, j + 3, k + 1, placeStoneBricks(random), 0, 2);
        world.setBlock(i + 9, j + 3, k + 1, Blocks.air, 0, 2);
        world.setBlock(i + 10, j + 3, k + 1, Blocks.air, 0, 2);
        world.setBlock(i + 11, j + 3, k + 1, Blocks.air, 0, 2);
        world.setBlock(i + 12, j + 3, k + 1, Blocks.air, 0, 2);
        world.setBlock(i + 13, j + 3, k + 1, Blocks.air, 0, 2);
        world.setBlock(i + 14, j + 3, k + 1, Blocks.air, 0, 2);
        world.setBlock(i + 15, j + 3, k + 1, Blocks.air, 0, 2);
        world.setBlock(i + 16, j + 3, k + 1, placeStoneBricks(random), 0, 2);
        world.setBlock(i + 8, j + 3, k + 2, placeStoneBricks(random), 0, 2);
        world.setBlock(i + 9, j + 3, k + 2, Blocks.air, 0, 2);
        world.setBlock(i + 10, j + 3, k + 2, Blocks.air, 0, 2);
        world.setBlock(i + 11, j + 3, k + 2, Blocks.air, 0, 2);
        world.setBlock(i + 12, j + 3, k + 2, Blocks.air, 0, 2);
        world.setBlock(i + 13, j + 3, k + 2, Blocks.air, 0, 2);
        world.setBlock(i + 14, j + 3, k + 2, Blocks.air, 0, 2);
        world.setBlock(i + 15, j + 3, k + 2, Blocks.air, 0, 2);
        world.setBlock(i + 16, j + 3, k + 2, placeStoneBricks(random), 0, 2);
        world.setBlock(i + 8, j + 3, k + 3, placeStoneBricks(random), 0, 2);
        world.setBlock(i + 9, j + 3, k + 3, Blocks.air, 0, 2);
        world.setBlock(i + 10, j + 3, k + 3, Blocks.air, 0, 2);
        world.setBlock(i + 11, j + 3, k + 3, Blocks.air, 0, 2);
        world.setBlock(i + 12, j + 3, k + 3, Blocks.air, 0, 2);
        world.setBlock(i + 13, j + 3, k + 3, Blocks.air, 0, 2);
        world.setBlock(i + 14, j + 3, k + 3, Blocks.air, 0, 2);
        world.setBlock(i + 15, j + 3, k + 3, Blocks.air, 0, 2);
        world.setBlock(i + 16, j + 3, k + 3, NovaCraftBlocks.sculk_block, 0, 2);
        world.setBlock(i + 8, j + 3, k + 4, placeStoneBricks(random), 0, 2);
        world.setBlock(i + 9, j + 3, k + 4, Blocks.web, 0, 2);
        world.setBlock(i + 10, j + 3, k + 4, Blocks.air, 0, 2);
        world.setBlock(i + 11, j + 3, k + 4, Blocks.air, 0, 2);
        world.setBlock(i + 12, j + 3, k + 4, Blocks.air, 0, 2);
        world.setBlock(i + 13, j + 3, k + 4, Blocks.air, 0, 2);
        world.setBlock(i + 14, j + 3, k + 4, Blocks.air, 0, 2);
        world.setBlock(i + 15, j + 3, k + 4, Blocks.air, 0, 2);
        world.setBlock(i + 16, j + 3, k + 4, placeStoneBricks(random), 0, 2);
        world.setBlock(i + 8, j + 3, k + 5, placeStoneBricks(random), 0, 2);
        world.setBlock(i + 9, j + 3, k + 5, Blocks.air, 0, 2);
        world.setBlock(i + 10, j + 3, k + 5, Blocks.air, 0, 2);
        world.setBlock(i + 11, j + 3, k + 5, Blocks.air, 0, 2);
        world.setBlock(i + 12, j + 3, k + 5, Blocks.air, 0, 2);
        world.setBlock(i + 13, j + 3, k + 5, Blocks.air, 0, 2);
        world.setBlock(i + 14, j + 3, k + 5, Blocks.air, 0, 2);
        world.setBlock(i + 15, j + 3, k + 5, Blocks.air, 0, 2);
        world.setBlock(i + 16, j + 3, k + 5, placeStoneBricks(random), 0, 2);
        world.setBlock(i + 8, j + 3, k + 6, placeStoneBricks(random), 0, 2);
        world.setBlock(i + 9, j + 3, k + 6, Blocks.air, 0, 2);
        world.setBlock(i + 10, j + 3, k + 6, Blocks.air, 0, 2);
        world.setBlock(i + 11, j + 3, k + 6, Blocks.air, 0, 2);
        world.setBlock(i + 12, j + 3, k + 6, Blocks.air, 0, 2);
        world.setBlock(i + 13, j + 3, k + 6, Blocks.air, 0, 2);
        world.setBlock(i + 14, j + 3, k + 6, Blocks.air, 0, 2);
        world.setBlock(i + 15, j + 3, k + 6, Blocks.air, 0, 2);
        world.setBlock(i + 16, j + 3, k + 6, placeStoneBricks(random), 0, 2);
        world.setBlock(i + 8, j + 3, k + 7, placeStoneBricks(random), 0, 2);
        world.setBlock(i + 9, j + 3, k + 7, placeStoneBricks(random), 0, 2);
        world.setBlock(i + 10, j + 3, k + 7, Blocks.air, 0, 2);
        world.setBlock(i + 11, j + 3, k + 7, Blocks.iron_bars, 0, 2);
        world.setBlock(i + 12, j + 3, k + 7, Blocks.iron_bars, 0, 2);
        world.setBlock(i + 13, j + 3, k + 7, Blocks.iron_bars, 0, 2);
        world.setBlock(i + 14, j + 3, k + 7, Blocks.air, 0, 2);
        world.setBlock(i + 15, j + 3, k + 7, placeStoneBricks(random), 0, 2);
        world.setBlock(i + 16, j + 3, k + 7, placeStoneBricks(random), 0, 2);
        world.setBlock(i + 1, j + 3, k + 8, placeStoneBricks(random), 0, 2);
        world.setBlock(i + 2, j + 3, k + 8, placeStoneBricks(random), 0, 2);
        world.setBlock(i + 3, j + 3, k + 8, placeStoneBricks(random), 0, 2);
        world.setBlock(i + 4, j + 3, k + 8, placeStoneBricks(random), 0, 2);
        world.setBlock(i + 5, j + 3, k + 8, placeStoneBricks(random), 0, 2);
        world.setBlock(i + 6, j + 3, k + 8, placeStoneBricks(random), 0, 2);
        world.setBlock(i + 7, j + 3, k + 8, placeStoneBricks(random), 0, 2);
        world.setBlock(i + 8, j + 3, k + 8, placeStoneBricks(random), 0, 2);
        world.setBlock(i + 9, j + 3, k + 8, placeStoneBricks(random), 0, 2);
        world.setBlock(i + 10, j + 3, k + 8, Blocks.air, 0, 2);
        world.setBlock(i + 11, j + 3, k + 8, Blocks.air, 0, 2);
        world.setBlock(i + 12, j + 3, k + 8, Blocks.air, 0, 2);
        world.setBlock(i + 13, j + 3, k + 8, Blocks.air, 0, 2);
        world.setBlock(i + 14, j + 3, k + 8, Blocks.air, 0, 2);
        world.setBlock(i + 15, j + 3, k + 8, placeStoneBricks(random), 0, 2);
        world.setBlock(i + 16, j + 3, k + 8, placeStoneBricks(random), 0, 2);
        world.setBlock(i + 17, j + 3, k + 8, placeStoneBricks(random), 0, 2);
        world.setBlock(i + 1, j + 3, k + 9, placeStoneBricks(random), 0, 2);
        world.setBlock(i + 2, j + 3, k + 9, Blocks.air, 0, 2);
        world.setBlock(i + 3, j + 3, k + 9, Blocks.air, 0, 2);
        world.setBlock(i + 4, j + 3, k + 9, Blocks.air, 0, 2);
        world.setBlock(i + 5, j + 3, k + 9, NovaCraftBlocks.cobbled_grimstone_wall, 0, 2);
        world.setBlock(i + 6, j + 3, k + 9, Blocks.air, 0, 2);
        world.setBlock(i + 7, j + 3, k + 9, Blocks.air, 0, 2);
        world.setBlock(i + 8, j + 3, k + 9, Blocks.air, 0, 2);
        world.setBlock(i + 9, j + 3, k + 9, Blocks.air, 0, 2);
        world.setBlock(i + 10, j + 3, k + 9, Blocks.air, 0, 2);
        world.setBlock(i + 11, j + 3, k + 9, Blocks.air, 0, 2);
        world.setBlock(i + 12, j + 3, k + 9, Blocks.air, 0, 2);
        world.setBlock(i + 13, j + 3, k + 9, Blocks.air, 0, 2);
        world.setBlock(i + 14, j + 3, k + 9, Blocks.air, 0, 2);
        world.setBlock(i + 15, j + 3, k + 9, Blocks.air, 0, 2);
        world.setBlock(i + 16, j + 3, k + 9, Blocks.air, 0, 2);
        world.setBlock(i + 17, j + 3, k + 9, placeStoneBricks(random), 0, 2);
        world.setBlock(i + 1, j + 3, k + 10, placeStoneBricks(random), 0, 2);
        world.setBlock(i + 2, j + 3, k + 10, Blocks.air, 0, 2);
        world.setBlock(i + 3, j + 3, k + 10, Blocks.air, 0, 2);
        world.setBlock(i + 4, j + 3, k + 10, Blocks.air, 0, 2);
        world.setBlock(i + 5, j + 3, k + 10, Blocks.air, 0, 2);
        world.setBlock(i + 6, j + 3, k + 10, Blocks.air, 0, 2);
        world.setBlock(i + 7, j + 3, k + 10, Blocks.air, 0, 2);
        world.setBlock(i + 8, j + 3, k + 10, Blocks.air, 0, 2);
        world.setBlock(i + 9, j + 3, k + 10, Blocks.air, 0, 2);
        world.setBlock(i + 10, j + 3, k + 10, Blocks.air, 0, 2);
        world.setBlock(i + 11, j + 3, k + 10, Blocks.air, 0, 2);
        world.setBlock(i + 12, j + 3, k + 10, Blocks.air, 0, 2);
        world.setBlock(i + 13, j + 3, k + 10, Blocks.air, 0, 2);
        world.setBlock(i + 14, j + 3, k + 10, Blocks.air, 0, 2);
        world.setBlock(i + 15, j + 3, k + 10, Blocks.air, 0, 2);
        world.setBlock(i + 16, j + 3, k + 10, Blocks.air, 0, 2);
        world.setBlock(i + 17, j + 3, k + 10, placeStoneBricks(random), 0, 2);
        world.setBlock(i + 1, j + 3, k + 11, Blocks.planks, 5, 2);
        world.setBlock(i + 2, j + 3, k + 11, Blocks.air, 0, 2);
        world.setBlock(i + 3, j + 3, k + 11, Blocks.air, 0, 2);
        world.setBlock(i + 4, j + 3, k + 11, Blocks.air, 0, 2);
        world.setBlock(i + 5, j + 3, k + 11, Blocks.air, 0, 2);
        world.setBlock(i + 6, j + 3, k + 11, Blocks.air, 0, 2);
        world.setBlock(i + 7, j + 3, k + 11, Blocks.air, 0, 2);
        world.setBlock(i + 8, j + 3, k + 11, Blocks.air, 0, 2);
        world.setBlock(i + 9, j + 3, k + 11, Blocks.air, 0, 2);
        world.setBlock(i + 10, j + 3, k + 11, Blocks.air, 0, 2);
        world.setBlock(i + 11, j + 3, k + 11, Blocks.air, 0, 2);
        world.setBlock(i + 12, j + 3, k + 11, Blocks.air, 0, 2);
        world.setBlock(i + 13, j + 3, k + 11, Blocks.air, 0, 2);
        world.setBlock(i + 14, j + 3, k + 11, Blocks.air, 0, 2);
        world.setBlock(i + 15, j + 3, k + 11, Blocks.air, 0, 2);
        world.setBlock(i + 16, j + 3, k + 11, Blocks.air, 0, 2);
        world.setBlock(i + 17, j + 3, k + 11, placeStoneBricks(random), 0, 2);
        world.setBlock(i + 1, j + 3, k + 12, Blocks.iron_bars, 0, 2);
        world.setBlock(i + 2, j + 3, k + 12, Blocks.air, 0, 2);
        world.setBlock(i + 3, j + 3, k + 12, Blocks.air, 0, 2);
        world.setBlock(i + 4, j + 3, k + 12, Blocks.air, 0, 2);
        world.setBlock(i + 5, j + 3, k + 12, Blocks.air, 0, 2);
        world.setBlock(i + 6, j + 3, k + 12, Blocks.air, 0, 2);
        world.setBlock(i + 7, j + 3, k + 12, Blocks.air, 0, 2);
        world.setBlock(i + 8, j + 3, k + 12, Blocks.air, 0, 2);
        world.setBlock(i + 9, j + 3, k + 12, Blocks.air, 0, 2);
        world.setBlock(i + 10, j + 3, k + 12, Blocks.air, 0, 2);
        world.setBlock(i + 11, j + 3, k + 12, Blocks.air, 0, 2);
        world.setBlock(i + 12, j + 3, k + 12, Blocks.air, 0, 2);
        world.setBlock(i + 13, j + 3, k + 12, Blocks.air, 0, 2);
        world.setBlock(i + 14, j + 3, k + 12, Blocks.air, 0, 2);
        world.setBlock(i + 15, j + 3, k + 12, Blocks.air, 0, 2);
        world.setBlock(i + 16, j + 3, k + 12, Blocks.air, 0, 2);
        world.setBlock(i + 17, j + 3, k + 12, placeStoneBricks(random), 0, 2);
        world.setBlock(i + 1, j + 3, k + 13, placeStoneBricks(random), 0, 2);
        world.setBlock(i + 2, j + 3, k + 13, Blocks.air, 0, 2);
        world.setBlock(i + 3, j + 3, k + 13, Blocks.air, 0, 2);
        world.setBlock(i + 4, j + 3, k + 13, Blocks.air, 0, 2);
        world.setBlock(i + 5, j + 3, k + 13, Blocks.air, 0, 2);
        world.setBlock(i + 6, j + 3, k + 13, Blocks.air, 0, 2);
        world.setBlock(i + 7, j + 3, k + 13, Blocks.air, 0, 2);
        world.setBlock(i + 8, j + 3, k + 13, Blocks.air, 0, 2);
        world.setBlock(i + 9, j + 3, k + 13, Blocks.air, 0, 2);
        world.setBlock(i + 10, j + 3, k + 13, Blocks.air, 0, 2);
        world.setBlock(i + 11, j + 3, k + 13, Blocks.air, 0, 2);
        world.setBlock(i + 12, j + 3, k + 13, Blocks.air, 0, 2);
        world.setBlock(i + 13, j + 3, k + 13, Blocks.air, 0, 2);
        world.setBlock(i + 14, j + 3, k + 13, Blocks.air, 0, 2);
        world.setBlock(i + 15, j + 3, k + 13, Blocks.air, 0, 2);
        world.setBlock(i + 16, j + 3, k + 13, Blocks.air, 0, 2);
        world.setBlock(i + 17, j + 3, k + 13, placeStoneBricks(random), 0, 2);
        world.setBlock(i + 1, j + 3, k + 14, placeStoneBricks(random), 0, 2);
        world.setBlock(i + 2, j + 3, k + 14, Blocks.air, 0, 2);
        world.setBlock(i + 3, j + 3, k + 14, Blocks.air, 0, 2);
        world.setBlock(i + 4, j + 3, k + 14, Blocks.air, 0, 2);
        world.setBlock(i + 5, j + 3, k + 14, NovaCraftBlocks.cobbled_grimstone_wall, 0, 2);
        world.setBlock(i + 6, j + 3, k + 14, Blocks.air, 0, 2);
        world.setBlock(i + 7, j + 3, k + 14, Blocks.air, 0, 2);
        world.setBlock(i + 8, j + 3, k + 14, Blocks.air, 0, 2);
        world.setBlock(i + 9, j + 3, k + 14, Blocks.air, 0, 2);
        world.setBlock(i + 10, j + 3, k + 14, Blocks.air, 0, 2);
        world.setBlock(i + 11, j + 3, k + 14, Blocks.air, 0, 2);
        world.setBlock(i + 12, j + 3, k + 14, Blocks.air, 0, 2);
        world.setBlock(i + 13, j + 3, k + 14, Blocks.air, 0, 2);
        world.setBlock(i + 14, j + 3, k + 14, Blocks.air, 0, 2);
        world.setBlock(i + 15, j + 3, k + 14, Blocks.air, 0, 2);
        world.setBlock(i + 16, j + 3, k + 14, Blocks.air, 0, 2);
        world.setBlock(i + 17, j + 3, k + 14, placeStoneBricks(random), 0, 2);
        world.setBlock(i + 1, j + 3, k + 15, placeStoneBricks(random), 0, 2);
        world.setBlock(i + 2, j + 3, k + 15, placeStoneBricks(random), 0, 2);
        world.setBlock(i + 3, j + 3, k + 15, placeStoneBricks(random), 0, 2);
        world.setBlock(i + 4, j + 3, k + 15, placeStoneBricks(random), 0, 2);
        world.setBlock(i + 5, j + 3, k + 15, placeStoneBricks(random), 0, 2);
        world.setBlock(i + 6, j + 3, k + 15, placeStoneBricks(random), 0, 2);
        world.setBlock(i + 7, j + 3, k + 15, placeStoneBricks(random), 0, 2);
        world.setBlock(i + 8, j + 3, k + 15, placeStoneBricks(random), 0, 2);
        world.setBlock(i + 9, j + 3, k + 15, placeStoneBricks(random), 0, 2);
        world.setBlock(i + 10, j + 3, k + 15, Blocks.air, 0, 2);
        world.setBlock(i + 11, j + 3, k + 15, Blocks.air, 0, 2);
        world.setBlock(i + 12, j + 3, k + 15, Blocks.air, 0, 2);
        world.setBlock(i + 13, j + 3, k + 15, Blocks.air, 0, 2);
        world.setBlock(i + 14, j + 3, k + 15, Blocks.air, 0, 2);
        world.setBlock(i + 15, j + 3, k + 15, placeStoneBricks(random), 0, 2);
        world.setBlock(i + 16, j + 3, k + 15, placeStoneBricks(random), 0, 2);
        world.setBlock(i + 17, j + 3, k + 15, placeStoneBricks(random), 0, 2);
        world.setBlock(i + 8, j + 3, k + 16, placeStoneBricks(random), 0, 2);
        world.setBlock(i + 9, j + 3, k + 16, Blocks.air, 0, 2);
        world.setBlock(i + 10, j + 3, k + 16, Blocks.air, 0, 2);
        world.setBlock(i + 11, j + 3, k + 16, Blocks.air, 0, 2);
        world.setBlock(i + 12, j + 3, k + 16, Blocks.air, 0, 2);
        world.setBlock(i + 13, j + 3, k + 16, Blocks.air, 0, 2);
        world.setBlock(i + 14, j + 3, k + 16, Blocks.air, 0, 2);
        world.setBlock(i + 15, j + 3, k + 16, Blocks.air, 0, 2);
        world.setBlock(i + 16, j + 3, k + 16, placeStoneBricks(random), 0, 2);
        world.setBlock(i + 8, j + 3, k + 17, placeStoneBricks(random), 0, 2);
        world.setBlock(i + 9, j + 3, k + 17, NovaCraftBlocks.cobbled_grimstone_wall, 0, 2);
        world.setBlock(i + 10, j + 3, k + 17, Blocks.air, 0, 2);
        world.setBlock(i + 11, j + 3, k + 17, Blocks.air, 0, 2);
        world.setBlock(i + 12, j + 3, k + 17, Blocks.air, 0, 2);
        world.setBlock(i + 13, j + 3, k + 17, Blocks.air, 0, 2);
        world.setBlock(i + 14, j + 3, k + 17, Blocks.air, 0, 2);
        world.setBlock(i + 15, j + 3, k + 17, NovaCraftBlocks.cobbled_grimstone_wall, 0, 2);
        world.setBlock(i + 16, j + 3, k + 17, placeStoneBricks(random), 0, 2);
        world.setBlock(i + 8, j + 3, k + 18, placeStoneBricks(random), 0, 2);
        world.setBlock(i + 9, j + 3, k + 18, Blocks.air, 0, 2);
        world.setBlock(i + 10, j + 3, k + 18, Blocks.air, 0, 2);
        world.setBlock(i + 11, j + 3, k + 18, Blocks.air, 0, 2);
        world.setBlock(i + 12, j + 3, k + 18, Blocks.air, 0, 2);
        world.setBlock(i + 13, j + 3, k + 18, Blocks.air, 0, 2);
        world.setBlock(i + 14, j + 3, k + 18, Blocks.air, 0, 2);
        world.setBlock(i + 15, j + 3, k + 18, Blocks.web, 0, 2);
        world.setBlock(i + 16, j + 3, k + 18, placeStoneBricks(random), 0, 2);
        world.setBlock(i + 8, j + 3, k + 19, placeStoneBricks(random), 0, 2);
        world.setBlock(i + 9, j + 3, k + 19, Blocks.air, 0, 2);
        world.setBlock(i + 10, j + 3, k + 19, Blocks.air, 0, 2);
        world.setBlock(i + 11, j + 3, k + 19, Blocks.air, 0, 2);
        world.setBlock(i + 12, j + 3, k + 19, Blocks.air, 0, 2);
        world.setBlock(i + 13, j + 3, k + 19, Blocks.air, 0, 2);
        world.setBlock(i + 14, j + 3, k + 19, Blocks.air, 0, 2);
        world.setBlock(i + 15, j + 3, k + 19, Blocks.air, 0, 2);
        world.setBlock(i + 16, j + 3, k + 19, placeStoneBricks(random), 0, 2);
        world.setBlock(i + 8, j + 3, k + 20, placeStoneBricks(random), 0, 2);
        world.setBlock(i + 9, j + 3, k + 20, Blocks.air, 0, 2);
        world.setBlock(i + 10, j + 3, k + 20, Blocks.air, 0, 2);
        world.setBlock(i + 11, j + 3, k + 20, Blocks.air, 0, 2);
        world.setBlock(i + 12, j + 3, k + 20, Blocks.air, 0, 2);
        world.setBlock(i + 13, j + 3, k + 20, Blocks.air, 0, 2);
        world.setBlock(i + 14, j + 3, k + 20, Blocks.air, 0, 2);
        world.setBlock(i + 15, j + 3, k + 20, Blocks.air, 0, 2);
        world.setBlock(i + 16, j + 3, k + 20, placeStoneBricks(random), 0, 2);
        world.setBlock(i + 8, j + 3, k + 21, placeStoneBricks(random), 0, 2);
        world.setBlock(i + 9, j + 3, k + 21, Blocks.air, 0, 2);
        world.setBlock(i + 10, j + 3, k + 21, Blocks.air, 0, 2);
        world.setBlock(i + 11, j + 3, k + 21, Blocks.air, 0, 2);
        world.setBlock(i + 12, j + 3, k + 21, NovaCraftBlocks.cobbled_grimstone_wall, 0, 2);
        world.setBlock(i + 13, j + 3, k + 21, Blocks.air, 0, 2);
        world.setBlock(i + 14, j + 3, k + 21, Blocks.web, 0, 2);
        world.setBlock(i + 15, j + 3, k + 21, Blocks.air, 0, 2);
        world.setBlock(i + 16, j + 3, k + 21, placeStoneBricks(random), 0, 2);
        world.setBlock(i + 8, j + 3, k + 22, placeStoneBricks(random), 0, 2);
        world.setBlock(i + 9, j + 3, k + 22, placeStoneBricks(random), 0, 2);
        world.setBlock(i + 10, j + 3, k + 22, placeStoneBricks(random), 0, 2);
        world.setBlock(i + 11, j + 3, k + 22, placeStoneBricks(random), 0, 2);
        world.setBlock(i + 12, j + 3, k + 22, placeStoneBricks(random), 0, 2);
        world.setBlock(i + 13, j + 3, k + 22, placeStoneBricks(random), 0, 2);
        world.setBlock(i + 14, j + 3, k + 22, placeStoneBricks(random), 0, 2);
        world.setBlock(i + 15, j + 3, k + 22, placeStoneBricks(random), 0, 2);
        world.setBlock(i + 16, j + 3, k + 22, placeStoneBricks(random), 0, 2);
        world.setBlock(i + 8, j + 4, k, placeStoneBricks(random), 0, 2);
        world.setBlock(i + 9, j + 4, k, placeStoneBricks(random), 0, 2);
        world.setBlock(i + 10, j + 4, k, placeStoneBricks(random), 0, 2);
        world.setBlock(i + 11, j + 4, k, placeStoneBricks(random), 0, 2);
        world.setBlock(i + 12, j + 4, k, placeStoneBricks(random), 0, 2);
        world.setBlock(i + 13, j + 4, k, placeStoneBricks(random), 0, 2);
        world.setBlock(i + 14, j + 4, k, placeStoneBricks(random), 0, 2);
        world.setBlock(i + 15, j + 4, k, placeStoneBricks(random), 0, 2);
        world.setBlock(i + 16, j + 4, k, placeStoneBricks(random), 0, 2);
        world.setBlock(i + 8, j + 4, k + 1, NovaCraftBlocks.sculk_block, 0, 2);
        world.setBlock(i + 9, j + 4, k + 1, Blocks.air, 0, 2);
        world.setBlock(i + 10, j + 4, k + 1, Blocks.air, 0, 2);
        world.setBlock(i + 11, j + 4, k + 1, Blocks.air, 0, 2);
        world.setBlock(i + 12, j + 4, k + 1, Blocks.air, 0, 2);
        world.setBlock(i + 13, j + 4, k + 1, Blocks.air, 0, 2);
        world.setBlock(i + 14, j + 4, k + 1, Blocks.air, 0, 2);
        world.setBlock(i + 15, j + 4, k + 1, Blocks.air, 0, 2);
        world.setBlock(i + 16, j + 4, k + 1, placeStoneBricks(random), 0, 2);
        world.setBlock(i + 8, j + 4, k + 2, placeStoneBricks(random), 0, 2);
        world.setBlock(i + 9, j + 4, k + 2, Blocks.air, 0, 2);
        world.setBlock(i + 10, j + 4, k + 2, Blocks.air, 0, 2);
        world.setBlock(i + 11, j + 4, k + 2, Blocks.air, 0, 2);
        world.setBlock(i + 12, j + 4, k + 2, Blocks.air, 0, 2);
        world.setBlock(i + 13, j + 4, k + 2, Blocks.air, 0, 2);
        world.setBlock(i + 14, j + 4, k + 2, Blocks.air, 0, 2);
        world.setBlock(i + 15, j + 4, k + 2, Blocks.air, 0, 2);
        world.setBlock(i + 16, j + 4, k + 2, placeStoneBricks(random), 0, 2);
        world.setBlock(i + 8, j + 4, k + 3, placeStoneBricks(random), 0, 2);
        world.setBlock(i + 9, j + 4, k + 3, Blocks.air, 0, 2);
        world.setBlock(i + 10, j + 4, k + 3, Blocks.air, 0, 2);
        world.setBlock(i + 11, j + 4, k + 3, Blocks.air, 0, 2);
        world.setBlock(i + 12, j + 4, k + 3, Blocks.air, 0, 2);
        world.setBlock(i + 13, j + 4, k + 3, Blocks.air, 0, 2);
        world.setBlock(i + 14, j + 4, k + 3, Blocks.air, 0, 2);
        world.setBlock(i + 15, j + 4, k + 3, Blocks.air, 0, 2);
        world.setBlock(i + 16, j + 4, k + 3, placeStoneBricks(random), 0, 2);
        world.setBlock(i + 8, j + 4, k + 4, placeStoneBricks(random), 0, 2);
        world.setBlock(i + 9, j + 4, k + 4, Blocks.air, 0, 2);
        world.setBlock(i + 10, j + 4, k + 4, Blocks.air, 0, 2);
        world.setBlock(i + 11, j + 4, k + 4, Blocks.air, 0, 2);
        world.setBlock(i + 12, j + 4, k + 4, Blocks.air, 0, 2);
        world.setBlock(i + 13, j + 4, k + 4, Blocks.air, 0, 2);
        world.setBlock(i + 14, j + 4, k + 4, Blocks.air, 0, 2);
        world.setBlock(i + 15, j + 4, k + 4, Blocks.air, 0, 2);
        world.setBlock(i + 16, j + 4, k + 4, placeStoneBricks(random), 0, 2);
        world.setBlock(i + 8, j + 4, k + 5, placeStoneBricks(random), 0, 2);
        world.setBlock(i + 9, j + 4, k + 5, Blocks.air, 0, 2);
        world.setBlock(i + 10, j + 4, k + 5, Blocks.air, 0, 2);
        world.setBlock(i + 11, j + 4, k + 5, Blocks.air, 0, 2);
        world.setBlock(i + 12, j + 4, k + 5, Blocks.air, 0, 2);
        world.setBlock(i + 13, j + 4, k + 5, Blocks.air, 0, 2);
        world.setBlock(i + 14, j + 4, k + 5, Blocks.air, 0, 2);
        world.setBlock(i + 15, j + 4, k + 5, Blocks.air, 0, 2);
        world.setBlock(i + 16, j + 4, k + 5, NovaCraftBlocks.sculk_block, 0, 2);
        world.setBlock(i + 8, j + 4, k + 6, placeStoneBricks(random), 0, 2);
        world.setBlock(i + 9, j + 4, k + 6, Blocks.air, 0, 2);
        world.setBlock(i + 10, j + 4, k + 6, Blocks.air, 0, 2);
        world.setBlock(i + 11, j + 4, k + 6, Blocks.air, 0, 2);
        world.setBlock(i + 12, j + 4, k + 6, Blocks.air, 0, 2);
        world.setBlock(i + 13, j + 4, k + 6, Blocks.air, 0, 2);
        world.setBlock(i + 14, j + 4, k + 6, Blocks.air, 0, 2);
        world.setBlock(i + 15, j + 4, k + 6, Blocks.air, 0, 2);
        world.setBlock(i + 16, j + 4, k + 6, placeStoneBricks(random), 0, 2);
        world.setBlock(i + 8, j + 4, k + 7, placeStoneBricks(random), 0, 2);
        world.setBlock(i + 9, j + 4, k + 7, NovaCraftBlocks.sculk_block, 0, 2);
        world.setBlock(i + 10, j + 4, k + 7, placeStoneBricks(random), 0, 2);
        world.setBlock(i + 11, j + 4, k + 7, placeStoneBricks(random), 0, 2);
        world.setBlock(i + 12, j + 4, k + 7, placeStoneBricks(random), 0, 2);
        world.setBlock(i + 13, j + 4, k + 7, placeStoneBricks(random), 0, 2);
        world.setBlock(i + 14, j + 4, k + 7, placeStoneBricks(random), 0, 2);
        world.setBlock(i + 15, j + 4, k + 7, placeStoneBricks(random), 0, 2);
        world.setBlock(i + 16, j + 4, k + 7, placeStoneBricks(random), 0, 2);
        world.setBlock(i + 1, j + 4, k + 8, placeStoneBricks(random), 0, 2);
        world.setBlock(i + 2, j + 4, k + 8, placeStoneBricks(random), 0, 2);
        world.setBlock(i + 3, j + 4, k + 8, placeStoneBricks(random), 0, 2);
        world.setBlock(i + 4, j + 4, k + 8, placeStoneBricks(random), 0, 2);
        world.setBlock(i + 5, j + 4, k + 8, placeStoneBricks(random), 0, 2);
        world.setBlock(i + 6, j + 4, k + 8, placeStoneBricks(random), 0, 2);
        world.setBlock(i + 7, j + 4, k + 8, placeStoneBricks(random), 0, 2);
        world.setBlock(i + 8, j + 4, k + 8, placeStoneBricks(random), 0, 2);
        world.setBlock(i + 9, j + 4, k + 8, placeStoneBricks(random), 0, 2);
        world.setBlock(i + 10, j + 4, k + 8, NovaCraftBlocks.cobbled_grimstone_stairs, 5, 2);
        world.setBlock(i + 11, j + 4, k + 8, Blocks.air, 0, 2);
        world.setBlock(i + 12, j + 4, k + 8, Blocks.air, 0, 2);
        world.setBlock(i + 13, j + 4, k + 8, Blocks.air, 0, 2);
        world.setBlock(i + 14, j + 4, k + 8, NovaCraftBlocks.cobbled_grimstone_stairs, 4, 2);
        world.setBlock(i + 15, j + 4, k + 8, placeStoneBricks(random), 0, 2);
        world.setBlock(i + 16, j + 4, k + 8, placeStoneBricks(random), 0, 2);
        world.setBlock(i + 17, j + 4, k + 8, placeStoneBricks(random), 0, 2);
        world.setBlock(i + 1, j + 4, k + 9, placeStoneBricks(random), 0, 2);
        world.setBlock(i + 2, j + 4, k + 9, Blocks.air, 0, 2);
        world.setBlock(i + 3, j + 4, k + 9, Blocks.air, 0, 2);
        world.setBlock(i + 4, j + 4, k + 9, Blocks.air, 0, 2);
        world.setBlock(i + 5, j + 4, k + 9, Blocks.air, 0, 2);
        world.setBlock(i + 6, j + 4, k + 9, Blocks.air, 0, 2);
        world.setBlock(i + 7, j + 4, k + 9, Blocks.air, 0, 2);
        world.setBlock(i + 8, j + 4, k + 9, Blocks.air, 0, 2);
        world.setBlock(i + 9, j + 4, k + 9, NovaCraftBlocks.cobbled_grimstone_stairs, 7, 2);
        world.setBlock(i + 10, j + 4, k + 9, Blocks.air, 0, 2);
        world.setBlock(i + 11, j + 4, k + 9, Blocks.air, 0, 2);
        world.setBlock(i + 12, j + 4, k + 9, Blocks.air, 0, 2);
        world.setBlock(i + 13, j + 4, k + 9, Blocks.air, 0, 2);
        world.setBlock(i + 14, j + 4, k + 9, Blocks.air, 0, 2);
        world.setBlock(i + 15, j + 4, k + 9, NovaCraftBlocks.cobbled_grimstone_stairs, 7, 2);
        world.setBlock(i + 16, j + 4, k + 9, Blocks.web, 0, 2);
        world.setBlock(i + 17, j + 4, k + 9, placeStoneBricks(random), 0, 2);
        world.setBlock(i + 1, j + 4, k + 10, placeStoneBricks(random), 0, 2);
        world.setBlock(i + 2, j + 4, k + 10, Blocks.air, 0, 2);
        world.setBlock(i + 3, j + 4, k + 10, Blocks.air, 0, 2);
        world.setBlock(i + 4, j + 4, k + 10, Blocks.air, 0, 2);
        world.setBlock(i + 5, j + 4, k + 10, Blocks.air, 0, 2);
        world.setBlock(i + 6, j + 4, k + 10, Blocks.air, 0, 2);
        world.setBlock(i + 7, j + 4, k + 10, Blocks.air, 0, 2);
        world.setBlock(i + 8, j + 4, k + 10, Blocks.air, 0, 2);
        world.setBlock(i + 9, j + 4, k + 10, Blocks.air, 0, 2);
        world.setBlock(i + 10, j + 4, k + 10, Blocks.air, 0, 2);
        world.setBlock(i + 11, j + 4, k + 10, Blocks.air, 0, 2);
        world.setBlock(i + 12, j + 4, k + 10, Blocks.air, 0, 2);
        world.setBlock(i + 13, j + 4, k + 10, Blocks.air, 0, 2);
        world.setBlock(i + 14, j + 4, k + 10, Blocks.air, 0, 2);
        world.setBlock(i + 15, j + 4, k + 10, Blocks.air, 0, 2);
        world.setBlock(i + 16, j + 4, k + 10, Blocks.air, 0, 2);
        world.setBlock(i + 17, j + 4, k + 10, placeStoneBricks(random), 0, 2);
        world.setBlock(i + 1, j + 4, k + 11, placeStoneBricks(random), 0, 2);
        world.setBlock(i + 2, j + 4, k + 11, Blocks.air, 0, 2);
        world.setBlock(i + 3, j + 4, k + 11, Blocks.air, 0, 2);
        world.setBlock(i + 4, j + 4, k + 11, Blocks.air, 0, 2);
        world.setBlock(i + 5, j + 4, k + 11, Blocks.air, 0, 2);
        world.setBlock(i + 6, j + 4, k + 11, Blocks.air, 0, 2);
        world.setBlock(i + 7, j + 4, k + 11, Blocks.air, 0, 2);
        world.setBlock(i + 8, j + 4, k + 11, Blocks.air, 0, 2);
        world.setBlock(i + 9, j + 4, k + 11, Blocks.air, 0, 2);
        world.setBlock(i + 10, j + 4, k + 11, Blocks.air, 0, 2);
        world.setBlock(i + 11, j + 4, k + 11, Blocks.air, 0, 2);
        world.setBlock(i + 12, j + 4, k + 11, Blocks.air, 0, 2);
        world.setBlock(i + 13, j + 4, k + 11, Blocks.air, 0, 2);
        world.setBlock(i + 14, j + 4, k + 11, Blocks.air, 0, 2);
        world.setBlock(i + 15, j + 4, k + 11, Blocks.air, 0, 2);
        world.setBlock(i + 16, j + 4, k + 11, Blocks.air, 0, 2);
        world.setBlock(i + 17, j + 4, k + 11, placeStoneBricks(random), 0, 2);
        world.setBlock(i + 1, j + 4, k + 12, placeStoneBricks(random), 0, 2);
        world.setBlock(i + 2, j + 4, k + 12, Blocks.air, 0, 2);
        world.setBlock(i + 3, j + 4, k + 12, Blocks.air, 0, 2);
        world.setBlock(i + 4, j + 4, k + 12, Blocks.air, 0, 2);
        world.setBlock(i + 5, j + 4, k + 12, Blocks.air, 0, 2);
        world.setBlock(i + 6, j + 4, k + 12, Blocks.air, 0, 2);
        world.setBlock(i + 7, j + 4, k + 12, Blocks.air, 0, 2);
        world.setBlock(i + 8, j + 4, k + 12, Blocks.air, 0, 2);
        world.setBlock(i + 9, j + 4, k + 12, Blocks.air, 0, 2);
        world.setBlock(i + 10, j + 4, k + 12, Blocks.air, 0, 2);
        world.setBlock(i + 11, j + 4, k + 12, Blocks.air, 0, 2);
        world.setBlock(i + 12, j + 4, k + 12, Blocks.air, 0, 2);
        world.setBlock(i + 13, j + 4, k + 12, Blocks.air, 0, 2);
        world.setBlock(i + 14, j + 4, k + 12, Blocks.air, 0, 2);
        world.setBlock(i + 15, j + 4, k + 12, Blocks.air, 0, 2);
        world.setBlock(i + 16, j + 4, k + 12, Blocks.air, 0, 2);
        world.setBlock(i + 17, j + 4, k + 12, placeStoneBricks(random), 0, 2);
        world.setBlock(i + 1, j + 4, k + 13, placeStoneBricks(random), 0, 2);
        world.setBlock(i + 2, j + 4, k + 13, Blocks.air, 0, 2);
        world.setBlock(i + 3, j + 4, k + 13, Blocks.air, 0, 2);
        world.setBlock(i + 4, j + 4, k + 13, Blocks.air, 0, 2);
        world.setBlock(i + 5, j + 4, k + 13, Blocks.air, 0, 2);
        world.setBlock(i + 6, j + 4, k + 13, Blocks.air, 0, 2);
        world.setBlock(i + 7, j + 4, k + 13, Blocks.air, 0, 2);
        world.setBlock(i + 8, j + 4, k + 13, Blocks.air, 0, 2);
        world.setBlock(i + 9, j + 4, k + 13, Blocks.air, 0, 2);
        world.setBlock(i + 10, j + 4, k + 13, Blocks.air, 0, 2);
        world.setBlock(i + 11, j + 4, k + 13, Blocks.air, 0, 2);
        world.setBlock(i + 12, j + 4, k + 13, Blocks.air, 0, 2);
        world.setBlock(i + 13, j + 4, k + 13, Blocks.air, 0, 2);
        world.setBlock(i + 14, j + 4, k + 13, Blocks.air, 0, 2);
        world.setBlock(i + 15, j + 4, k + 13, Blocks.air, 0, 2);
        world.setBlock(i + 16, j + 4, k + 13, Blocks.air, 0, 2);
        world.setBlock(i + 17, j + 4, k + 13, placeStoneBricks(random), 0, 2);
        world.setBlock(i + 1, j + 4, k + 14, placeStoneBricks(random), 0, 2);
        world.setBlock(i + 2, j + 4, k + 14, Blocks.air, 0, 2);
        world.setBlock(i + 3, j + 4, k + 14, Blocks.air, 0, 2);
        world.setBlock(i + 4, j + 4, k + 14, Blocks.air, 0, 2);
        world.setBlock(i + 5, j + 4, k + 14, Blocks.air, 0, 2);
        world.setBlock(i + 6, j + 4, k + 14, Blocks.web, 0, 2);
        world.setBlock(i + 7, j + 4, k + 14, Blocks.air, 0, 2);
        world.setBlock(i + 8, j + 4, k + 14, Blocks.air, 0, 2);
        world.setBlock(i + 9, j + 4, k + 14, NovaCraftBlocks.cobbled_grimstone_stairs, 6, 2);
        world.setBlock(i + 10, j + 4, k + 14, Blocks.air, 0, 2);
        world.setBlock(i + 11, j + 4, k + 14, Blocks.air, 0, 2);
        world.setBlock(i + 12, j + 4, k + 14, Blocks.air, 0, 2);
        world.setBlock(i + 13, j + 4, k + 14, Blocks.air, 0, 2);
        world.setBlock(i + 14, j + 4, k + 14, Blocks.air, 0, 2);
        world.setBlock(i + 15, j + 4, k + 14, NovaCraftBlocks.cobbled_grimstone_stairs, 6, 2);
        world.setBlock(i + 16, j + 4, k + 14, Blocks.web, 0, 2);
        world.setBlock(i + 17, j + 4, k + 14, placeStoneBricks(random), 0, 2);
        world.setBlock(i + 1, j + 4, k + 15, placeStoneBricks(random), 0, 2);
        world.setBlock(i + 2, j + 4, k + 15, placeStoneBricks(random), 0, 2);
        world.setBlock(i + 3, j + 4, k + 15, placeStoneBricks(random), 0, 2);
        world.setBlock(i + 4, j + 4, k + 15, placeStoneBricks(random), 0, 2);
        world.setBlock(i + 5, j + 4, k + 15, placeStoneBricks(random), 0, 2);
        world.setBlock(i + 6, j + 4, k + 15, placeStoneBricks(random), 0, 2);
        world.setBlock(i + 7, j + 4, k + 15, placeStoneBricks(random), 0, 2);
        world.setBlock(i + 8, j + 4, k + 15, placeStoneBricks(random), 0, 2);
        world.setBlock(i + 9, j + 4, k + 15, placeStoneBricks(random), 0, 2);
        world.setBlock(i + 10, j + 4, k + 15, NovaCraftBlocks.cobbled_grimstone_stairs, 5, 2);
        world.setBlock(i + 11, j + 4, k + 15, Blocks.air, 0, 2);
        world.setBlock(i + 12, j + 4, k + 15, Blocks.air, 0, 2);
        world.setBlock(i + 13, j + 4, k + 15, Blocks.air, 0, 2);
        world.setBlock(i + 14, j + 4, k + 15, NovaCraftBlocks.cobbled_grimstone_stairs, 4, 2);
        world.setBlock(i + 15, j + 4, k + 15, placeStoneBricks(random), 0, 2);
        world.setBlock(i + 16, j + 4, k + 15, placeStoneBricks(random), 0, 2);
        world.setBlock(i + 17, j + 4, k + 15, placeStoneBricks(random), 0, 2);
        world.setBlock(i + 8, j + 4, k + 16, placeStoneBricks(random), 0, 2);
        world.setBlock(i + 9, j + 4, k + 16, Blocks.air, 0, 2);
        world.setBlock(i + 10, j + 4, k + 16, Blocks.air, 0, 2);
        world.setBlock(i + 11, j + 4, k + 16, Blocks.air, 0, 2);
        world.setBlock(i + 12, j + 4, k + 16, Blocks.air, 0, 2);
        world.setBlock(i + 13, j + 4, k + 16, Blocks.air, 0, 2);
        world.setBlock(i + 14, j + 4, k + 16, Blocks.air, 0, 2);
        world.setBlock(i + 15, j + 4, k + 16, Blocks.air, 0, 2);
        world.setBlock(i + 16, j + 4, k + 16, placeStoneBricks(random), 0, 2);
        world.setBlock(i + 8, j + 4, k + 17, placeStoneBricks(random), 0, 2);
        world.setBlock(i + 9, j + 4, k + 17, Blocks.air, 0, 2);
        world.setBlock(i + 10, j + 4, k + 17, Blocks.air, 0, 2);
        world.setBlock(i + 11, j + 4, k + 17, Blocks.air, 0, 2);
        world.setBlock(i + 12, j + 4, k + 17, Blocks.air, 0, 2);
        world.setBlock(i + 13, j + 4, k + 17, Blocks.air, 0, 2);
        world.setBlock(i + 14, j + 4, k + 17, Blocks.air, 0, 2);
        world.setBlock(i + 15, j + 4, k + 17, Blocks.air, 0, 2);
        world.setBlock(i + 16, j + 4, k + 17, placeStoneBricks(random), 0, 2);
        world.setBlock(i + 8, j + 4, k + 18, placeStoneBricks(random), 0, 2);
        world.setBlock(i + 9, j + 4, k + 18, Blocks.web, 0, 2);
        world.setBlock(i + 10, j + 4, k + 18, Blocks.air, 0, 2);
        world.setBlock(i + 11, j + 4, k + 18, Blocks.air, 0, 2);
        world.setBlock(i + 12, j + 4, k + 18, Blocks.air, 0, 2);
        world.setBlock(i + 13, j + 4, k + 18, Blocks.air, 0, 2);
        world.setBlock(i + 14, j + 4, k + 18, Blocks.air, 0, 2);
        world.setBlock(i + 15, j + 4, k + 18, Blocks.air, 0, 2);
        world.setBlock(i + 16, j + 4, k + 18, placeStoneBricks(random), 0, 2);
        world.setBlock(i + 8, j + 4, k + 19, placeStoneBricks(random), 0, 2);
        world.setBlock(i + 9, j + 4, k + 19, Blocks.air, 0, 2);
        world.setBlock(i + 10, j + 4, k + 19, Blocks.air, 0, 2);
        world.setBlock(i + 11, j + 4, k + 19, Blocks.air, 0, 2);
        world.setBlock(i + 12, j + 4, k + 19, Blocks.air, 0, 2);
        world.setBlock(i + 13, j + 4, k + 19, Blocks.air, 0, 2);
        world.setBlock(i + 14, j + 4, k + 19, Blocks.air, 0, 2);
        world.setBlock(i + 15, j + 4, k + 19, Blocks.air, 0, 2);
        world.setBlock(i + 16, j + 4, k + 19, placeStoneBricks(random), 0, 2);
        world.setBlock(i + 8, j + 4, k + 20, placeStoneBricks(random), 0, 2);
        world.setBlock(i + 9, j + 4, k + 20, Blocks.air, 0, 2);
        world.setBlock(i + 10, j + 4, k + 20, Blocks.air, 0, 2);
        world.setBlock(i + 11, j + 4, k + 20, Blocks.air, 0, 2);
        world.setBlock(i + 12, j + 4, k + 20, Blocks.air, 0, 2);
        world.setBlock(i + 13, j + 4, k + 20, Blocks.air, 0, 2);
        world.setBlock(i + 14, j + 4, k + 20, Blocks.air, 0, 2);
        world.setBlock(i + 15, j + 4, k + 20, Blocks.air, 0, 2);
        world.setBlock(i + 16, j + 4, k + 20, placeStoneBricks(random), 0, 2);
        world.setBlock(i + 8, j + 4, k + 21, placeStoneBricks(random), 0, 2);
        world.setBlock(i + 9, j + 4, k + 21, Blocks.air, 0, 2);
        world.setBlock(i + 10, j + 4, k + 21, Blocks.air, 0, 2);
        world.setBlock(i + 11, j + 4, k + 21, Blocks.air, 0, 2);
        world.setBlock(i + 12, j + 4, k + 21, Blocks.air, 0, 2);
        world.setBlock(i + 13, j + 4, k + 21, Blocks.air, 0, 2);
        world.setBlock(i + 14, j + 4, k + 21, Blocks.air, 0, 2);
        world.setBlock(i + 15, j + 4, k + 21, Blocks.air, 0, 2);
        world.setBlock(i + 16, j + 4, k + 21, placeStoneBricks(random), 0, 2);
        world.setBlock(i + 8, j + 4, k + 22, placeStoneBricks(random), 0, 2);
        world.setBlock(i + 9, j + 4, k + 22, placeStoneBricks(random), 0, 2);
        world.setBlock(i + 10, j + 4, k + 22, placeStoneBricks(random), 0, 2);
        world.setBlock(i + 11, j + 4, k + 22, placeStoneBricks(random), 0, 2);
        world.setBlock(i + 12, j + 4, k + 22, placeStoneBricks(random), 0, 2);
        world.setBlock(i + 13, j + 4, k + 22, placeStoneBricks(random), 0, 2);
        world.setBlock(i + 14, j + 4, k + 22, placeStoneBricks(random), 0, 2);
        world.setBlock(i + 15, j + 4, k + 22, placeStoneBricks(random), 0, 2);
        world.setBlock(i + 16, j + 4, k + 22, placeStoneBricks(random), 0, 2);
        world.setBlock(i + 8, j + 5, k, NovaCraftBlocks.cobbled_grimstone, 0, 2);
        world.setBlock(i + 9, j + 5, k, NovaCraftBlocks.cobbled_grimstone, 0, 2);
        world.setBlock(i + 10, j + 5, k, NovaCraftBlocks.cobbled_grimstone, 0, 2);
        world.setBlock(i + 11, j + 5, k, NovaCraftBlocks.cobbled_grimstone, 0, 2);
        world.setBlock(i + 12, j + 5, k, NovaCraftBlocks.cobbled_grimstone, 0, 2);
        world.setBlock(i + 13, j + 5, k, NovaCraftBlocks.cobbled_grimstone, 0, 2);
        world.setBlock(i + 14, j + 5, k, NovaCraftBlocks.cobbled_grimstone, 0, 2);
        world.setBlock(i + 15, j + 5, k, NovaCraftBlocks.cobbled_grimstone, 0, 2);
        world.setBlock(i + 16, j + 5, k, NovaCraftBlocks.cobbled_grimstone, 0, 2);
        world.setBlock(i + 8, j + 5, k + 1, NovaCraftBlocks.cobbled_grimstone, 0, 2);
        world.setBlock(i + 9, j + 5, k + 1, placeTiles(random), 2, 2);
        world.setBlock(i + 10, j + 5, k + 1, placeTiles(random), 2, 2);
        world.setBlock(i + 11, j + 5, k + 1, placeTiles(random), 2, 2);
        world.setBlock(i + 12, j + 5, k + 1, placeTiles(random), 2, 2);
        world.setBlock(i + 13, j + 5, k + 1, placeTiles(random), 2, 2);
        world.setBlock(i + 14, j + 5, k + 1, placeTiles(random), 2, 2);
        world.setBlock(i + 15, j + 5, k + 1, placeTiles(random), 2, 2);
        world.setBlock(i + 16, j + 5, k + 1, NovaCraftBlocks.cobbled_grimstone, 0, 2);
        world.setBlock(i + 8, j + 5, k + 2, NovaCraftBlocks.cobbled_grimstone, 0, 2);
        world.setBlock(i + 9, j + 5, k + 2, placeTiles(random), 2, 2);
        world.setBlock(i + 10, j + 5, k + 2, placeTiles(random), 2, 2);
        world.setBlock(i + 11, j + 5, k + 2, placeTiles(random), 2, 2);
        world.setBlock(i + 12, j + 5, k + 2, placeTiles(random), 2, 2);
        world.setBlock(i + 13, j + 5, k + 2, placeTiles(random), 2, 2);
        world.setBlock(i + 14, j + 5, k + 2, placeTiles(random), 2, 2);
        world.setBlock(i + 15, j + 5, k + 2, placeTiles(random), 2, 2);
        world.setBlock(i + 16, j + 5, k + 2, NovaCraftBlocks.cobbled_grimstone, 0, 2);
        world.setBlock(i + 8, j + 5, k + 3, NovaCraftBlocks.cobbled_grimstone, 0, 2);
        world.setBlock(i + 9, j + 5, k + 3, placeTiles(random), 2, 2);
        world.setBlock(i + 10, j + 5, k + 3, placeTiles(random), 2, 2);
        world.setBlock(i + 11, j + 5, k + 3, placeTiles(random), 2, 2);
        world.setBlock(i + 12, j + 5, k + 3, placeTiles(random), 2, 2);
        world.setBlock(i + 13, j + 5, k + 3, placeTiles(random), 2, 2);
        world.setBlock(i + 14, j + 5, k + 3, placeTiles(random), 2, 2);
        world.setBlock(i + 15, j + 5, k + 3, placeTiles(random), 2, 2);
        world.setBlock(i + 16, j + 5, k + 3, NovaCraftBlocks.cobbled_grimstone, 0, 2);
        world.setBlock(i + 8, j + 5, k + 4, NovaCraftBlocks.cobbled_grimstone, 0, 2);
        world.setBlock(i + 9, j + 5, k + 4, placeTiles(random), 2, 2);
        world.setBlock(i + 10, j + 5, k + 4, placeTiles(random), 2, 2);
        world.setBlock(i + 11, j + 5, k + 4, placeTiles(random), 2, 2);
        world.setBlock(i + 12, j + 5, k + 4, placeTiles(random), 2, 2);
        world.setBlock(i + 13, j + 5, k + 4, placeTiles(random), 2, 2);
        world.setBlock(i + 14, j + 5, k + 4, placeTiles(random), 2, 2);
        world.setBlock(i + 15, j + 5, k + 4, placeTiles(random), 2, 2);
