package com.NovaCraft.world.bastion.treasure;

import net.minecraft.world.gen.feature.*;
import net.minecraft.world.*;
import java.util.*;
import com.NovaCraftBlocks.NovaCraftBlocks;
import net.minecraft.init.*;

public class BastionTreasureBarracksGen3 extends WorldGenerator
{
	public BastionTreasureBarracksGen3() {

	}
    
    public boolean generate(final World world, final Random random, final int i, final int j, final int k) {
    	
    	world.setBlock(i + 9, j + 13, k + 1, NovaCraftBlocks.basal, 0, 2);
		world.setBlock(i, j + 13, k + 2, NovaCraftBlocks.basal, 0, 2);
		world.setBlock(i + 1, j + 13, k + 2, NovaCraftBlocks.basal, 0, 2);
		world.setBlock(i + 2, j + 13, k + 2, NovaCraftBlocks.basal, 0, 2);
		world.setBlock(i + 3, j + 13, k + 2, NovaCraftBlocks.basal, 0, 2);
		world.setBlock(i + 4, j + 13, k + 2, NovaCraftBlocks.basal, 0, 2);
		world.setBlock(i + 5, j + 13, k + 2, NovaCraftBlocks.basal, 0, 2);
		world.setBlock(i + 6, j + 13, k + 2, NovaCraftBlocks.cracked_basal_bricks, 0, 2);
		world.setBlock(i + 7, j + 13, k + 2, NovaCraftBlocks.basal_bricks, 0, 2);
		world.setBlock(i + 8, j + 13, k + 2, NovaCraftBlocks.basal, 0, 2);
		world.setBlock(i + 9, j + 13, k + 2, NovaCraftBlocks.basal, 0, 2);
		world.setBlock(i + 10, j + 13, k + 2, NovaCraftBlocks.basal, 0, 2);
		world.setBlock(i + 11, j + 13, k + 2, NovaCraftBlocks.basal, 0, 2);
		world.setBlock(i + 12, j + 13, k + 2, NovaCraftBlocks.basal, 0, 2);
		world.setBlock(i + 13, j + 13, k + 2, NovaCraftBlocks.basal, 0, 2);
		world.setBlock(i, j + 13, k + 3, NovaCraftBlocks.basal, 0, 2);
		world.setBlock(i + 1, j + 13, k + 3, NovaCraftBlocks.basal, 0, 2);
		world.setBlock(i + 2, j + 13, k + 3, NovaCraftBlocks.basal, 0, 2);
		world.setBlock(i + 3, j + 13, k + 3, NovaCraftBlocks.basal, 0, 2);
		world.setBlock(i + 4, j + 13, k + 3, NovaCraftBlocks.basal, 0, 2);
		world.setBlock(i + 7, j + 13, k + 3, NovaCraftBlocks.basal, 0, 2);
		world.setBlock(i + 8, j + 13, k + 3, NovaCraftBlocks.basal, 0, 2);
		world.setBlock(i + 9, j + 13, k + 3, NovaCraftBlocks.basal, 0, 2);
		world.setBlock(i + 10, j + 13, k + 3, NovaCraftBlocks.basal, 0, 2);
		world.setBlock(i + 11, j + 13, k + 3, NovaCraftBlocks.basal, 0, 2);
		world.setBlock(i + 12, j + 13, k + 3, NovaCraftBlocks.basal, 0, 2);
		world.setBlock(i + 13, j + 13, k + 3, NovaCraftBlocks.basal, 0, 2);
		world.setBlock(i + 18, j + 13, k + 3, NovaCraftBlocks.basal, 0, 2);
		world.setBlock(i + 23, j + 13, k + 3, NovaCraftBlocks.basal, 0, 2);
		world.setBlock(i, j + 13, k + 4, NovaCraftBlocks.basal, 0, 2);
		world.setBlock(i + 1, j + 13, k + 4, NovaCraftBlocks.basal, 0, 2);
		world.setBlock(i + 2, j + 13, k + 4, NovaCraftBlocks.basal, 0, 2);
		world.setBlock(i + 3, j + 13, k + 4, NovaCraftBlocks.basal, 0, 2);
		world.setBlock(i + 4, j + 13, k + 4, Blocks.air, 0, 2);
		world.setBlock(i + 5, j + 13, k + 4, Blocks.air, 0, 2);
		world.setBlock(i + 6, j + 13, k + 4, Blocks.air, 0, 2);
		world.setBlock(i + 7, j + 13, k + 4, NovaCraftBlocks.basal, 0, 2);
		world.setBlock(i + 8, j + 13, k + 4, NovaCraftBlocks.basal, 0, 2);
		world.setBlock(i + 9, j + 13, k + 4, NovaCraftBlocks.basal, 0, 2);
		world.setBlock(i + 10, j + 13, k + 4, NovaCraftBlocks.basal, 0, 2);
		world.setBlock(i + 11, j + 13, k + 4, NovaCraftBlocks.basal, 0, 2);
		world.setBlock(i + 12, j + 13, k + 4, NovaCraftBlocks.basal, 0, 2);
		world.setBlock(i + 13, j + 13, k + 4, NovaCraftBlocks.basal, 0, 2);
		world.setBlock(i + 14, j + 13, k + 4, NovaCraftBlocks.basal, 0, 2);
		world.setBlock(i + 15, j + 13, k + 4, NovaCraftBlocks.basal, 0, 2);
		world.setBlock(i + 16, j + 13, k + 4, NovaCraftBlocks.basal, 0, 2);
		world.setBlock(i + 17, j + 13, k + 4, NovaCraftBlocks.basal, 0, 2);
		world.setBlock(i + 18, j + 13, k + 4, NovaCraftBlocks.basal, 0, 2);
		world.setBlock(i + 19, j + 13, k + 4, NovaCraftBlocks.basal, 0, 2);
		world.setBlock(i + 20, j + 13, k + 4, NovaCraftBlocks.cracked_basal_bricks, 0, 2);
		world.setBlock(i + 21, j + 13, k + 4, NovaCraftBlocks.cracked_basal_bricks, 0, 2);
		world.setBlock(i + 22, j + 13, k + 4, NovaCraftBlocks.basal, 0, 2);
		world.setBlock(i + 23, j + 13, k + 4, NovaCraftBlocks.basal, 0, 2);
		world.setBlock(i + 24, j + 13, k + 4, NovaCraftBlocks.basal, 0, 2);
		world.setBlock(i + 25, j + 13, k + 4, NovaCraftBlocks.basal, 0, 2);
		world.setBlock(i + 26, j + 13, k + 4, NovaCraftBlocks.basal, 0, 2);
		world.setBlock(i + 27, j + 13, k + 4, NovaCraftBlocks.basal, 0, 2);
		world.setBlock(i, j + 13, k + 5, NovaCraftBlocks.basal, 0, 2);
		world.setBlock(i + 1, j + 13, k + 5, NovaCraftBlocks.basal, 0, 2);
		world.setBlock(i + 2, j + 13, k + 5, Blocks.air, 0, 2);
		world.setBlock(i + 3, j + 13, k + 5, Blocks.air, 0, 2);
		world.setBlock(i + 4, j + 13, k + 5, Blocks.air, 0, 2);
		world.setBlock(i + 5, j + 13, k + 5, Blocks.air, 0, 2);
		world.setBlock(i + 6, j + 13, k + 5, NovaCraftBlocks.basal, 0, 2);
		world.setBlock(i + 7, j + 13, k + 5, NovaCraftBlocks.basal, 0, 2);
		world.setBlock(i + 8, j + 13, k + 5, NovaCraftBlocks.basal, 0, 2);
		world.setBlock(i + 9, j + 13, k + 5, NovaCraftBlocks.basal, 0, 2);
		world.setBlock(i + 10, j + 13, k + 5, NovaCraftBlocks.basal, 0, 2);
		world.setBlock(i + 11, j + 13, k + 5, NovaCraftBlocks.basal, 0, 2);
		world.setBlock(i + 12, j + 13, k + 5, NovaCraftBlocks.basal, 0, 2);
		world.setBlock(i + 13, j + 13, k + 5, NovaCraftBlocks.basal, 0, 2);
		world.setBlock(i + 14, j + 13, k + 5, NovaCraftBlocks.basal, 0, 2);
		world.setBlock(i + 15, j + 13, k + 5, NovaCraftBlocks.basal, 0, 2);
		world.setBlock(i + 16, j + 13, k + 5, NovaCraftBlocks.basal, 0, 2);
		world.setBlock(i + 17, j + 13, k + 5, NovaCraftBlocks.basal, 0, 2);
		world.setBlock(i + 18, j + 13, k + 5, NovaCraftBlocks.basal, 0, 2);
		world.setBlock(i + 19, j + 13, k + 5, Blocks.air, 0, 2);
		world.setBlock(i + 20, j + 13, k + 5, Blocks.air, 0, 2);
		world.setBlock(i + 21, j + 13, k + 5, NovaCraftBlocks.basal, 0, 2);
		world.setBlock(i + 22, j + 13, k + 5, NovaCraftBlocks.basal, 0, 2);
		world.setBlock(i + 23, j + 13, k + 5, NovaCraftBlocks.basal, 0, 2);
		world.setBlock(i + 24, j + 13, k + 5, NovaCraftBlocks.basal, 0, 2);
		world.setBlock(i + 25, j + 13, k + 5, NovaCraftBlocks.basal, 0, 2);
		world.setBlock(i + 26, j + 13, k + 5, NovaCraftBlocks.basal, 0, 2);
		world.setBlock(i + 27, j + 13, k + 5, NovaCraftBlocks.basal, 0, 2);
		world.setBlock(i, j + 13, k + 6, NovaCraftBlocks.basal, 0, 2);
		world.setBlock(i + 1, j + 13, k + 6, NovaCraftBlocks.basal, 0, 2);
		world.setBlock(i + 2, j + 13, k + 6, NovaCraftBlocks.basal, 0, 2);
		world.setBlock(i + 3, j + 13, k + 6, Blocks.air, 0, 2);
		world.setBlock(i + 4, j + 13, k + 6, Blocks.air, 0, 2);
		world.setBlock(i + 5, j + 13, k + 6, NovaCraftBlocks.basal, 0, 2);
		world.setBlock(i + 6, j + 13, k + 6, NovaCraftBlocks.basal, 0, 2);
		world.setBlock(i + 7, j + 13, k + 6, NovaCraftBlocks.basal, 0, 2);
		world.setBlock(i + 8, j + 13, k + 6, NovaCraftBlocks.basal, 0, 2);
		world.setBlock(i + 9, j + 13, k + 6, NovaCraftBlocks.basal, 0, 2);
		world.setBlock(i + 10, j + 13, k + 6, NovaCraftBlocks.basal, 0, 2);
		world.setBlock(i + 11, j + 13, k + 6, NovaCraftBlocks.basal, 0, 2);
		world.setBlock(i + 12, j + 13, k + 6, NovaCraftBlocks.basal, 0, 2);
		world.setBlock(i + 13, j + 13, k + 6, NovaCraftBlocks.basal, 0, 2);
		world.setBlock(i + 14, j + 13, k + 6, NovaCraftBlocks.basal, 0, 2);
		world.setBlock(i + 15, j + 13, k + 6, NovaCraftBlocks.basal, 0, 2);
		world.setBlock(i + 16, j + 13, k + 6, NovaCraftBlocks.basal, 0, 2);
		world.setBlock(i + 17, j + 13, k + 6, NovaCraftBlocks.basal, 0, 2);
		world.setBlock(i + 18, j + 13, k + 6, Blocks.air, 0, 2);
		world.setBlock(i + 19, j + 13, k + 6, Blocks.air, 0, 2);
		world.setBlock(i + 20, j + 13, k + 6, Blocks.air, 0, 2);
		world.setBlock(i + 21, j + 13, k + 6, NovaCraftBlocks.basal, 0, 2);
		world.setBlock(i + 22, j + 13, k + 6, NovaCraftBlocks.basal, 0, 2);
		world.setBlock(i + 23, j + 13, k + 6, NovaCraftBlocks.basal, 0, 2);
		world.setBlock(i + 24, j + 13, k + 6, NovaCraftBlocks.basal, 0, 2);
		world.setBlock(i + 25, j + 13, k + 6, NovaCraftBlocks.basal, 0, 2);
		world.setBlock(i + 26, j + 13, k + 6, NovaCraftBlocks.basal, 0, 2);
		world.setBlock(i + 27, j + 13, k + 6, NovaCraftBlocks.basal, 0, 2);
		world.setBlock(i, j + 13, k + 7, NovaCraftBlocks.basal, 0, 2);
		world.setBlock(i + 1, j + 13, k + 7, NovaCraftBlocks.basal, 0, 2);
		world.setBlock(i + 2, j + 13, k + 7, Blocks.lava, 8, 2);
		world.setBlock(i + 3, j + 13, k + 7, NovaCraftBlocks.basal, 0, 2);
		world.setBlock(i + 4, j + 13, k + 7, NovaCraftBlocks.basal, 0, 2);
		world.setBlock(i + 5, j + 13, k + 7, NovaCraftBlocks.basal, 0, 2);
		world.setBlock(i + 6, j + 13, k + 7, NovaCraftBlocks.basal, 0, 2);
		world.setBlock(i + 7, j + 13, k + 7, Blocks.lava, 8, 2);
		world.setBlock(i + 8, j + 13, k + 7, NovaCraftBlocks.basal, 0, 2);
		world.setBlock(i + 9, j + 13, k + 7, NovaCraftBlocks.basal, 0, 2);
		world.setBlock(i + 10, j + 13, k + 7, NovaCraftBlocks.basal, 0, 2);
		world.setBlock(i + 11, j + 13, k + 7, NovaCraftBlocks.basal, 0, 2);
		world.setBlock(i + 12, j + 13, k + 7, NovaCraftBlocks.basal, 0, 2);
		world.setBlock(i + 13, j + 13, k + 7, NovaCraftBlocks.basal, 0, 2);
		world.setBlock(i + 14, j + 13, k + 7, NovaCraftBlocks.basal, 0, 2);
		world.setBlock(i + 15, j + 13, k + 7, NovaCraftBlocks.basal, 0, 2);
		world.setBlock(i + 16, j + 13, k + 7, Blocks.air, 0, 2);
		world.setBlock(i + 17, j + 13, k + 7, Blocks.air, 0, 2);
		world.setBlock(i + 18, j + 13, k + 7, Blocks.air, 0, 2);
		world.setBlock(i + 19, j + 13, k + 7, Blocks.air, 0, 2);
		world.setBlock(i + 20, j + 13, k + 7, NovaCraftBlocks.basal, 0, 2);
		world.setBlock(i + 21, j + 13, k + 7, NovaCraftBlocks.basal, 0, 2);
		world.setBlock(i + 22, j + 13, k + 7, NovaCraftBlocks.basal, 0, 2);
		world.setBlock(i + 23, j + 13, k + 7, NovaCraftBlocks.basal, 0, 2);
		world.setBlock(i + 24, j + 13, k + 7, NovaCraftBlocks.basal, 0, 2);
		world.setBlock(i + 25, j + 13, k + 7, NovaCraftBlocks.basal, 0, 2);
		world.setBlock(i + 26, j + 13, k + 7, NovaCraftBlocks.basal, 0, 2);
		world.setBlock(i + 27, j + 13, k + 7, NovaCraftBlocks.basal, 0, 2);
		world.setBlock(i, j + 13, k + 8, NovaCraftBlocks.basal, 0, 2);
		world.setBlock(i + 1, j + 13, k + 8, NovaCraftBlocks.basal, 0, 2);
		world.setBlock(i + 2, j + 13, k + 8, NovaCraftBlocks.basal, 0, 2);
		world.setBlock(i + 3, j + 13, k + 8, NovaCraftBlocks.basal, 0, 2);
		world.setBlock(i + 4, j + 13, k + 8, NovaCraftBlocks.basal, 0, 2);
		world.setBlock(i + 5, j + 13, k + 8, NovaCraftBlocks.basal, 0, 2);
		world.setBlock(i + 6, j + 13, k + 8, NovaCraftBlocks.basal, 0, 2);
		world.setBlock(i + 7, j + 13, k + 8, NovaCraftBlocks.basal, 0, 2);
		world.setBlock(i + 8, j + 13, k + 8, NovaCraftBlocks.basal, 0, 2);
		world.setBlock(i + 9, j + 13, k + 8, NovaCraftBlocks.basal, 0, 2);
		world.setBlock(i + 10, j + 13, k + 8, NovaCraftBlocks.basal, 0, 2);
		world.setBlock(i + 11, j + 13, k + 8, NovaCraftBlocks.basal, 0, 2);
		world.setBlock(i + 12, j + 13, k + 8, NovaCraftBlocks.basal, 0, 2);
		world.setBlock(i + 13, j + 13, k + 8, NovaCraftBlocks.basal, 0, 2);
		world.setBlock(i + 14, j + 13, k + 8, NovaCraftBlocks.basal, 0, 2);
		world.setBlock(i + 15, j + 13, k + 8, NovaCraftBlocks.basal, 0, 2);
		world.setBlock(i + 16, j + 13, k + 8, NovaCraftBlocks.glowing_basal, 0, 2);
		world.setBlock(i + 17, j + 13, k + 8, Blocks.air, 0, 2);
		world.setBlock(i + 18, j + 13, k + 8, Blocks.air, 0, 2);
		world.setBlock(i + 19, j + 13, k + 8, NovaCraftBlocks.basal, 0, 2);
		world.setBlock(i + 20, j + 13, k + 8, NovaCraftBlocks.basal, 0, 2);
		world.setBlock(i + 21, j + 13, k + 8, NovaCraftBlocks.basal, 0, 2);
		world.setBlock(i + 22, j + 13, k + 8, NovaCraftBlocks.basal, 0, 2);
		world.setBlock(i + 23, j + 13, k + 8, NovaCraftBlocks.basal, 0, 2);
		world.setBlock(i + 24, j + 13, k + 8, NovaCraftBlocks.basal, 0, 2);
		world.setBlock(i + 25, j + 13, k + 8, NovaCraftBlocks.basal, 0, 2);
		world.setBlock(i + 26, j + 13, k + 8, NovaCraftBlocks.basal, 0, 2);
		world.setBlock(i + 27, j + 13, k + 8, NovaCraftBlocks.basal, 0, 2);
		world.setBlock(i, j + 13, k + 9, NovaCraftBlocks.cracked_basal_bricks, 0, 2);
		world.setBlock(i + 1, j + 13, k + 9, NovaCraftBlocks.basal, 0, 2);
		world.setBlock(i + 2, j + 13, k + 9, NovaCraftBlocks.basal, 0, 2);
		world.setBlock(i + 3, j + 13, k + 9, NovaCraftBlocks.basal, 0, 2);
		world.setBlock(i + 4, j + 13, k + 9, NovaCraftBlocks.basal, 0, 2);
		world.setBlock(i + 5, j + 13, k + 9, NovaCraftBlocks.basal, 0, 2);
		world.setBlock(i + 6, j + 13, k + 9, NovaCraftBlocks.basal, 0, 2);
		world.setBlock(i + 7, j + 13, k + 9, NovaCraftBlocks.basal, 0, 2);
		world.setBlock(i + 8, j + 13, k + 9, NovaCraftBlocks.basal, 0, 2);
		world.setBlock(i + 9, j + 13, k + 9, NovaCraftBlocks.basal, 0, 2);
		world.setBlock(i + 10, j + 13, k + 9, NovaCraftBlocks.basal, 0, 2);
		world.setBlock(i + 11, j + 13, k + 9, NovaCraftBlocks.basal, 0, 2);
		world.setBlock(i + 12, j + 13, k + 9, NovaCraftBlocks.basal, 0, 2);
		world.setBlock(i + 13, j + 13, k + 9, NovaCraftBlocks.glowing_basal, 0, 2);
		world.setBlock(i + 14, j + 13, k + 9, NovaCraftBlocks.basal, 0, 2);
		world.setBlock(i + 15, j + 13, k + 9, NovaCraftBlocks.basal, 0, 2);
		world.setBlock(i + 16, j + 13, k + 9, Blocks.lava, 8, 2);
		world.setBlock(i + 17, j + 13, k + 9, NovaCraftBlocks.basal, 0, 2);
		world.setBlock(i + 18, j + 13, k + 9, NovaCraftBlocks.basal, 0, 2);
		world.setBlock(i + 19, j + 13, k + 9, NovaCraftBlocks.basal, 0, 2);
		world.setBlock(i + 20, j + 13, k + 9, NovaCraftBlocks.basal, 0, 2);
		world.setBlock(i + 21, j + 13, k + 9, Blocks.lava, 8, 2);
		world.setBlock(i + 22, j + 13, k + 9, NovaCraftBlocks.basal, 0, 2);
		world.setBlock(i + 23, j + 13, k + 9, NovaCraftBlocks.basal, 0, 2);
		world.setBlock(i + 24, j + 13, k + 9, NovaCraftBlocks.basal, 0, 2);
		world.setBlock(i + 25, j + 13, k + 9, NovaCraftBlocks.basal, 0, 2);
		world.setBlock(i + 26, j + 13, k + 9, NovaCraftBlocks.basal, 0, 2);
		world.setBlock(i + 27, j + 13, k + 9, NovaCraftBlocks.basal, 0, 2);
		world.setBlock(i, j + 13, k + 10, Blocks.air, 0, 2);
		world.setBlock(i + 1, j + 13, k + 10, NovaCraftBlocks.cracked_basal_bricks, 0, 2);
		world.setBlock(i + 2, j + 13, k + 10, NovaCraftBlocks.basal, 0, 2);
		world.setBlock(i + 3, j + 13, k + 10, NovaCraftBlocks.basal, 0, 2);
		world.setBlock(i + 4, j + 13, k + 10, NovaCraftBlocks.basal, 0, 2);
		world.setBlock(i + 5, j + 13, k + 10, NovaCraftBlocks.basal, 0, 2);
		world.setBlock(i + 6, j + 13, k + 10, NovaCraftBlocks.basal, 0, 2);
		world.setBlock(i + 7, j + 13, k + 10, NovaCraftBlocks.basal, 0, 2);
		world.setBlock(i + 8, j + 13, k + 10, NovaCraftBlocks.basal, 0, 2);
		world.setBlock(i + 9, j + 13, k + 10, NovaCraftBlocks.basal, 0, 2);
		world.setBlock(i + 10, j + 13, k + 10, NovaCraftBlocks.basal, 0, 2);
		world.setBlock(i + 11, j + 13, k + 10, NovaCraftBlocks.basal, 0, 2);
		world.setBlock(i + 12, j + 13, k + 10, NovaCraftBlocks.basal, 0, 2);
		world.setBlock(i + 13, j + 13, k + 10, NovaCraftBlocks.basal, 0, 2);
		world.setBlock(i + 14, j + 13, k + 10, NovaCraftBlocks.basal, 0, 2);
		world.setBlock(i + 15, j + 13, k + 10, NovaCraftBlocks.basal, 0, 2);
		world.setBlock(i + 16, j + 13, k + 10, NovaCraftBlocks.basal, 0, 2);
		world.setBlock(i + 17, j + 13, k + 10, NovaCraftBlocks.basal, 0, 2);
		world.setBlock(i + 18, j + 13, k + 10, NovaCraftBlocks.basal, 0, 2);
		world.setBlock(i + 19, j + 13, k + 10, NovaCraftBlocks.basal, 0, 2);
		world.setBlock(i + 20, j + 13, k + 10, NovaCraftBlocks.basal, 0, 2);
		world.setBlock(i + 21, j + 13, k + 10, NovaCraftBlocks.basal, 0, 2);
		world.setBlock(i + 22, j + 13, k + 10, NovaCraftBlocks.basal, 0, 2);
		world.setBlock(i + 23, j + 13, k + 10, NovaCraftBlocks.basal, 0, 2);
		world.setBlock(i + 24, j + 13, k + 10, NovaCraftBlocks.basal, 0, 2);
		world.setBlock(i + 25, j + 13, k + 10, NovaCraftBlocks.basal, 0, 2);
		world.setBlock(i + 26, j + 13, k + 10, NovaCraftBlocks.basal, 0, 2);
		world.setBlock(i + 27, j + 13, k + 10, NovaCraftBlocks.basal, 0, 2);
		world.setBlock(i, j + 13, k + 11, NovaCraftBlocks.basal_bricks, 0, 2);
		world.setBlock(i + 1, j + 13, k + 11, NovaCraftBlocks.cracked_basal_bricks, 0, 2);
		world.setBlock(i + 2, j + 13, k + 11, NovaCraftBlocks.cracked_basal_bricks, 0, 2);
		world.setBlock(i + 3, j + 13, k + 11, NovaCraftBlocks.basal_bricks, 0, 2);
		world.setBlock(i + 4, j + 13, k + 11, NovaCraftBlocks.basal_bricks, 0, 2);
		world.setBlock(i + 5, j + 13, k + 11, NovaCraftBlocks.basal_bricks, 0, 2);
		world.setBlock(i + 6, j + 13, k + 11, NovaCraftBlocks.cracked_basal_bricks, 0, 2);
		world.setBlock(i + 7, j + 13, k + 11, NovaCraftBlocks.basal_bricks, 0, 2);
		world.setBlock(i + 8, j + 13, k + 11, NovaCraftBlocks.basal_bricks, 0, 2);
		world.setBlock(i + 9, j + 13, k + 11, NovaCraftBlocks.basal_bricks, 0, 2);
		world.setBlock(i + 10, j + 13, k + 11, NovaCraftBlocks.basal_bricks, 0, 2);
		world.setBlock(i + 11, j + 13, k + 11, NovaCraftBlocks.basal_bricks, 0, 2);
		world.setBlock(i + 12, j + 13, k + 11, NovaCraftBlocks.basal_bricks, 0, 2);
		world.setBlock(i + 13, j + 13, k + 11, NovaCraftBlocks.cracked_basal_bricks, 0, 2);
		world.setBlock(i + 14, j + 13, k + 11, NovaCraftBlocks.cracked_basal_bricks, 0, 2);
		world.setBlock(i + 15, j + 13, k + 11, NovaCraftBlocks.basal, 0, 2);
		world.setBlock(i + 16, j + 13, k + 11, NovaCraftBlocks.basal, 0, 2);
		world.setBlock(i + 17, j + 13, k + 11, NovaCraftBlocks.basal, 0, 2);
		world.setBlock(i + 18, j + 13, k + 11, NovaCraftBlocks.basal, 0, 2);
		world.setBlock(i + 19, j + 13, k + 11, NovaCraftBlocks.basal, 0, 2);
		world.setBlock(i + 20, j + 13, k + 11, NovaCraftBlocks.basal, 0, 2);
		world.setBlock(i + 21, j + 13, k + 11, NovaCraftBlocks.basal, 0, 2);
		world.setBlock(i + 22, j + 13, k + 11, NovaCraftBlocks.basal, 0, 2);
		world.setBlock(i + 23, j + 13, k + 11, NovaCraftBlocks.basal, 0, 2);
		world.setBlock(i + 24, j + 13, k + 11, NovaCraftBlocks.basal, 0, 2);
		world.setBlock(i + 25, j + 13, k + 11, NovaCraftBlocks.basal, 0, 2);
		world.setBlock(i + 26, j + 13, k + 11, NovaCraftBlocks.basal, 0, 2);
		world.setBlock(i + 27, j + 13, k + 11, NovaCraftBlocks.basal, 0, 2);
		world.setBlock(i, j + 13, k + 12, NovaCraftBlocks.basal_bricks, 0, 2);
		world.setBlock(i + 1, j + 13, k + 12, NovaCraftBlocks.basal_bricks, 0, 2);
		world.setBlock(i + 2, j + 13, k + 12, NovaCraftBlocks.cracked_basal_bricks, 0, 2);
		world.setBlock(i + 3, j + 13, k + 12, NovaCraftBlocks.basal_bricks, 0, 2);
		world.setBlock(i + 4, j + 13, k + 12, NovaCraftBlocks.cracked_basal_bricks, 0, 2);
		world.setBlock(i + 5, j + 13, k + 12, NovaCraftBlocks.basal_bricks, 0, 2);
		world.setBlock(i + 6, j + 13, k + 12, NovaCraftBlocks.basal_bricks, 0, 2);
		world.setBlock(i + 7, j + 13, k + 12, NovaCraftBlocks.basal_bricks, 0, 2);
		world.setBlock(i + 8, j + 13, k + 12, NovaCraftBlocks.basal_bricks, 0, 2);
		world.setBlock(i + 9, j + 13, k + 12, NovaCraftBlocks.cracked_basal_bricks, 0, 2);
		world.setBlock(i + 10, j + 13, k + 12, NovaCraftBlocks.basal_bricks, 0, 2);
		world.setBlock(i + 11, j + 13, k + 12, NovaCraftBlocks.cracked_basal_bricks, 0, 2);
		world.setBlock(i + 12, j + 13, k + 12, NovaCraftBlocks.basal_bricks, 0, 2);
		world.setBlock(i + 13, j + 13, k + 12, NovaCraftBlocks.cracked_basal_bricks, 0, 2);
		world.setBlock(i + 14, j + 13, k + 12, Blocks.air, 0, 2);
		world.setBlock(i + 15, j + 13, k + 12, NovaCraftBlocks.cracked_basal_bricks, 0, 2);
		world.setBlock(i + 16, j + 13, k + 12, NovaCraftBlocks.basal, 0, 2);
		world.setBlock(i + 17, j + 13, k + 12, NovaCraftBlocks.basal, 0, 2);
		world.setBlock(i + 18, j + 13, k + 12, NovaCraftBlocks.basal, 0, 2);
		world.setBlock(i + 19, j + 13, k + 12, NovaCraftBlocks.glowing_basal, 0, 2);
		world.setBlock(i + 20, j + 13, k + 12, NovaCraftBlocks.glowing_basal, 0, 2);
		world.setBlock(i + 21, j + 13, k + 12, NovaCraftBlocks.basal, 0, 2);
		world.setBlock(i + 22, j + 13, k + 12, NovaCraftBlocks.basal, 0, 2);
		world.setBlock(i + 23, j + 13, k + 12, NovaCraftBlocks.basal, 0, 2);
		world.setBlock(i + 24, j + 13, k + 12, NovaCraftBlocks.basal, 0, 2);
		world.setBlock(i + 25, j + 13, k + 12, NovaCraftBlocks.glowing_basal, 0, 2);
		world.setBlock(i + 26, j + 13, k + 12, NovaCraftBlocks.basal, 0, 2);
		world.setBlock(i + 27, j + 13, k + 12, NovaCraftBlocks.basal, 0, 2);
		world.setBlock(i + 1, j + 14, k + 1, NovaCraftBlocks.basal, 0, 2);
		world.setBlock(i + 4, j + 14, k + 1, NovaCraftBlocks.basal, 0, 2);
		world.setBlock(i + 5, j + 14, k + 1, NovaCraftBlocks.basal, 0, 2);
		world.setBlock(i + 8, j + 14, k + 1, NovaCraftBlocks.basal, 0, 2);
		world.setBlock(i + 12, j + 14, k + 1, NovaCraftBlocks.cracked_basal_bricks, 0, 2);
		world.setBlock(i + 13, j + 14, k + 1, NovaCraftBlocks.basal, 0, 2);
		world.setBlock(i, j + 14, k + 2, NovaCraftBlocks.basal, 0, 2);
		world.setBlock(i + 1, j + 14, k + 2, NovaCraftBlocks.basal, 0, 2);
		world.setBlock(i + 2, j + 14, k + 2, NovaCraftBlocks.basal_bricks, 0, 2);
		world.setBlock(i + 3, j + 14, k + 2, NovaCraftBlocks.basal, 0, 2);
		world.setBlock(i + 4, j + 14, k + 2, NovaCraftBlocks.basal, 0, 2);
		world.setBlock(i + 5, j + 14, k + 2, NovaCraftBlocks.basal_bricks, 0, 2);
		world.setBlock(i + 6, j + 14, k + 2, NovaCraftBlocks.cracked_basal_bricks, 0, 2);
		world.setBlock(i + 7, j + 14, k + 2, NovaCraftBlocks.basal, 0, 2);
		world.setBlock(i + 8, j + 14, k + 2, NovaCraftBlocks.basal, 0, 2);
		world.setBlock(i + 9, j + 14, k + 2, NovaCraftBlocks.basal, 0, 2);
		world.setBlock(i + 10, j + 14, k + 2, NovaCraftBlocks.basal, 0, 2);
		world.setBlock(i + 11, j + 14, k + 2, NovaCraftBlocks.basal, 0, 2);
		world.setBlock(i + 12, j + 14, k + 2, NovaCraftBlocks.basal, 0, 2);
		world.setBlock(i + 13, j + 14, k + 2, NovaCraftBlocks.basal, 0, 2);
		world.setBlock(i, j + 14, k + 3, NovaCraftBlocks.basal, 0, 2);
		world.setBlock(i + 1, j + 14, k + 3, NovaCraftBlocks.basal, 0, 2);
		world.setBlock(i + 2, j + 14, k + 3, NovaCraftBlocks.basal, 0, 2);
		world.setBlock(i + 3, j + 14, k + 3, NovaCraftBlocks.basal, 0, 2);
		world.setBlock(i + 4, j + 14, k + 3, NovaCraftBlocks.basal, 0, 2);
		world.setBlock(i + 5, j + 14, k + 3, NovaCraftBlocks.basal, 0, 2);
		world.setBlock(i + 6, j + 14, k + 3, NovaCraftBlocks.basal, 0, 2);
		world.setBlock(i + 7, j + 14, k + 3, NovaCraftBlocks.basal, 0, 2);
		world.setBlock(i + 8, j + 14, k + 3, NovaCraftBlocks.basal, 0, 2);
		world.setBlock(i + 9, j + 14, k + 3, NovaCraftBlocks.basal, 0, 2);
		world.setBlock(i + 10, j + 14, k + 3, NovaCraftBlocks.basal, 0, 2);
		world.setBlock(i + 11, j + 14, k + 3, NovaCraftBlocks.basal, 0, 2);
		world.setBlock(i + 12, j + 14, k + 3, NovaCraftBlocks.basal, 0, 2);
		world.setBlock(i + 13, j + 14, k + 3, NovaCraftBlocks.basal, 0, 2);
		world.setBlock(i + 15, j + 14, k + 3, NovaCraftBlocks.basal, 0, 2);
		world.setBlock(i + 18, j + 14, k + 3, NovaCraftBlocks.basal, 0, 2);
		world.setBlock(i + 19, j + 14, k + 3, NovaCraftBlocks.basal, 0, 2);
		world.setBlock(i + 22, j + 14, k + 3, NovaCraftBlocks.basal, 0, 2);
		world.setBlock(i + 26, j + 14, k + 3, NovaCraftBlocks.cracked_basal_bricks, 0, 2);
		world.setBlock(i + 27, j + 14, k + 3, NovaCraftBlocks.basal, 0, 2);
		world.setBlock(i, j + 14, k + 4, NovaCraftBlocks.basal, 0, 2);
		world.setBlock(i + 1, j + 14, k + 4, NovaCraftBlocks.basal, 0, 2);
		world.setBlock(i + 2, j + 14, k + 4, NovaCraftBlocks.basal, 0, 2);
		world.setBlock(i + 3, j + 14, k + 4, NovaCraftBlocks.basal, 0, 2);
		world.setBlock(i + 4, j + 14, k + 4, Blocks.air, 0, 2);
		world.setBlock(i + 5, j + 14, k + 4, Blocks.air, 0, 2);
		world.setBlock(i + 6, j + 14, k + 4, NovaCraftBlocks.basal, 0, 2);
		world.setBlock(i + 7, j + 14, k + 4, NovaCraftBlocks.basal, 0, 2);
		world.setBlock(i + 8, j + 14, k + 4, NovaCraftBlocks.basal, 0, 2);
		world.setBlock(i + 9, j + 14, k + 4, NovaCraftBlocks.basal, 0, 2);
		world.setBlock(i + 10, j + 14, k + 4, NovaCraftBlocks.basal, 0, 2);
		world.setBlock(i + 11, j + 14, k + 4, NovaCraftBlocks.basal, 0, 2);
		world.setBlock(i + 12, j + 14, k + 4, NovaCraftBlocks.basal, 0, 2);
		world.setBlock(i + 13, j + 14, k + 4, NovaCraftBlocks.basal, 0, 2);
		world.setBlock(i + 14, j + 14, k + 4, NovaCraftBlocks.basal, 0, 2);
		world.setBlock(i + 15, j + 14, k + 4, NovaCraftBlocks.basal, 0, 2);
		world.setBlock(i + 16, j + 14, k + 4, NovaCraftBlocks.cracked_basal_bricks, 0, 2);
		world.setBlock(i + 17, j + 14, k + 4, NovaCraftBlocks.basal, 0, 2);
		world.setBlock(i + 18, j + 14, k + 4, NovaCraftBlocks.basal, 0, 2);
		world.setBlock(i + 19, j + 14, k + 4, NovaCraftBlocks.cracked_basal_bricks, 0, 2);
		world.setBlock(i + 20, j + 14, k + 4, NovaCraftBlocks.cracked_basal_bricks, 0, 2);
		world.setBlock(i + 21, j + 14, k + 4, NovaCraftBlocks.basal, 0, 2);
		world.setBlock(i + 22, j + 14, k + 4, NovaCraftBlocks.basal, 0, 2);
		world.setBlock(i + 23, j + 14, k + 4, NovaCraftBlocks.basal, 0, 2);
		world.setBlock(i + 24, j + 14, k + 4, NovaCraftBlocks.basal, 0, 2);
		world.setBlock(i + 25, j + 14, k + 4, NovaCraftBlocks.basal, 0, 2);
		world.setBlock(i + 26, j + 14, k + 4, NovaCraftBlocks.basal, 0, 2);
		world.setBlock(i + 27, j + 14, k + 4, NovaCraftBlocks.basal, 0, 2);
		world.setBlock(i, j + 14, k + 5, NovaCraftBlocks.basal, 0, 2);
		world.setBlock(i + 1, j + 14, k + 5, NovaCraftBlocks.basal, 0, 2);
		world.setBlock(i + 2, j + 14, k + 5, Blocks.air, 0, 2);
		world.setBlock(i + 3, j + 14, k + 5, Blocks.air, 0, 2);
		world.setBlock(i + 4, j + 14, k + 5, Blocks.air, 0, 2);
		world.setBlock(i + 5, j + 14, k + 5, Blocks.air, 0, 2);
		world.setBlock(i + 6, j + 14, k + 5, NovaCraftBlocks.basal, 0, 2);
		world.setBlock(i + 7, j + 14, k + 5, NovaCraftBlocks.basal, 0, 2);
		world.setBlock(i + 8, j + 14, k + 5, NovaCraftBlocks.basal, 0, 2);
		world.setBlock(i + 9, j + 14, k + 5, NovaCraftBlocks.basal, 0, 2);
		world.setBlock(i + 10, j + 14, k + 5, NovaCraftBlocks.basal, 0, 2);
		world.setBlock(i + 11, j + 14, k + 5, NovaCraftBlocks.basal, 0, 2);
		world.setBlock(i + 12, j + 14, k + 5, NovaCraftBlocks.basal, 0, 2);
		world.setBlock(i + 13, j + 14, k + 5, NovaCraftBlocks.basal, 0, 2);
		world.setBlock(i + 14, j + 14, k + 5, NovaCraftBlocks.basal, 0, 2);
		world.setBlock(i + 15, j + 14, k + 5, NovaCraftBlocks.basal, 0, 2);
		world.setBlock(i + 16, j + 14, k + 5, NovaCraftBlocks.basal, 0, 2);
		world.setBlock(i + 17, j + 14, k + 5, NovaCraftBlocks.basal, 0, 2);
		world.setBlock(i + 18, j + 14, k + 5, NovaCraftBlocks.basal, 0, 2);
		world.setBlock(i + 19, j + 14, k + 5, NovaCraftBlocks.basal, 0, 2);
		world.setBlock(i + 20, j + 14, k + 5, NovaCraftBlocks.basal, 0, 2);
		world.setBlock(i + 21, j + 14, k + 5, NovaCraftBlocks.basal, 0, 2);
		world.setBlock(i + 22, j + 14, k + 5, NovaCraftBlocks.basal, 0, 2);
		world.setBlock(i + 23, j + 14, k + 5, NovaCraftBlocks.basal, 0, 2);
		world.setBlock(i + 24, j + 14, k + 5, NovaCraftBlocks.basal, 0, 2);
		world.setBlock(i + 25, j + 14, k + 5, NovaCraftBlocks.basal, 0, 2);
		world.setBlock(i + 26, j + 14, k + 5, NovaCraftBlocks.basal, 0, 2);
		world.setBlock(i + 27, j + 14, k + 5, NovaCraftBlocks.basal, 0, 2);
		world.setBlock(i, j + 14, k + 6, NovaCraftBlocks.basal, 0, 2);
		world.setBlock(i + 1, j + 14, k + 6, NovaCraftBlocks.basal, 0, 2);
		world.setBlock(i + 2, j + 14, k + 6, NovaCraftBlocks.basal, 0, 2);
		world.setBlock(i + 3, j + 14, k + 6, Blocks.air, 0, 2);
		world.setBlock(i + 4, j + 14, k + 6, Blocks.air, 0, 2);
		world.setBlock(i + 5, j + 14, k + 6, NovaCraftBlocks.basal, 0, 2);
		world.setBlock(i + 6, j + 14, k + 6, NovaCraftBlocks.basal, 0, 2);
		world.setBlock(i + 7, j + 14, k + 6, NovaCraftBlocks.basal, 0, 2);
		world.setBlock(i + 8, j + 14, k + 6, NovaCraftBlocks.basal, 0, 2);
		world.setBlock(i + 9, j + 14, k + 6, NovaCraftBlocks.basal, 0, 2);
		world.setBlock(i + 10, j + 14, k + 6, NovaCraftBlocks.basal, 0, 2);
		world.setBlock(i + 11, j + 14, k + 6, NovaCraftBlocks.basal, 0, 2);
		world.setBlock(i + 12, j + 14, k + 6, NovaCraftBlocks.basal, 0, 2);
		world.setBlock(i + 13, j + 14, k + 6, NovaCraftBlocks.basal, 0, 2);
		world.setBlock(i + 14, j + 14, k + 6, NovaCraftBlocks.basal, 0, 2);
		world.setBlock(i + 15, j + 14, k + 6, NovaCraftBlocks.basal, 0, 2);
		world.setBlock(i + 16, j + 14, k + 6, NovaCraftBlocks.basal, 0, 2);
		world.setBlock(i + 17, j + 14, k + 6, NovaCraftBlocks.basal, 0, 2);
		world.setBlock(i + 18, j + 14, k + 6, Blocks.air, 0, 2);
		world.setBlock(i + 19, j + 14, k + 6, Blocks.air, 0, 2);
		world.setBlock(i + 20, j + 14, k + 6, NovaCraftBlocks.basal, 0, 2);
		world.setBlock(i + 21, j + 14, k + 6, NovaCraftBlocks.basal, 0, 2);
		world.setBlock(i + 22, j + 14, k + 6, NovaCraftBlocks.basal, 0, 2);
		world.setBlock(i + 23, j + 14, k + 6, NovaCraftBlocks.basal, 0, 2);
		world.setBlock(i + 24, j + 14, k + 6, NovaCraftBlocks.basal, 0, 2);
		world.setBlock(i + 25, j + 14, k + 6, NovaCraftBlocks.basal, 0, 2);
		world.setBlock(i + 26, j + 14, k + 6, NovaCraftBlocks.basal, 0, 2);
		world.setBlock(i + 27, j + 14, k + 6, NovaCraftBlocks.basal, 0, 2);
		world.setBlock(i, j + 14, k + 7, NovaCraftBlocks.basal, 0, 2);
		world.setBlock(i + 1, j + 14, k + 7, NovaCraftBlocks.basal, 0, 2);
		world.setBlock(i + 2, j + 14, k + 7, Blocks.lava, 8, 2);
		world.setBlock(i + 3, j + 14, k + 7, Blocks.air, 0, 2);
		world.setBlock(i + 4, j + 14, k + 7, Blocks.air, 0, 2);
		world.setBlock(i + 5, j + 14, k + 7, NovaCraftBlocks.basal, 0, 2);
		world.setBlock(i + 6, j + 14, k + 7, NovaCraftBlocks.basal, 0, 2);
		world.setBlock(i + 7, j + 14, k + 7, Blocks.lava, 8, 2);
		world.setBlock(i + 8, j + 14, k + 7, NovaCraftBlocks.basal, 0, 2);
		world.setBlock(i + 9, j + 14, k + 7, NovaCraftBlocks.basal, 0, 2);
		world.setBlock(i + 10, j + 14, k + 7, NovaCraftBlocks.basal, 0, 2);
		world.setBlock(i + 11, j + 14, k + 7, NovaCraftBlocks.basal, 0, 2);
		world.setBlock(i + 12, j + 14, k + 7, NovaCraftBlocks.basal, 0, 2);
		world.setBlock(i + 13, j + 14, k + 7, NovaCraftBlocks.basal, 0, 2);
		world.setBlock(i + 14, j + 14, k + 7, NovaCraftBlocks.basal, 0, 2);
		world.setBlock(i + 15, j + 14, k + 7, NovaCraftBlocks.basal, 0, 2);
		world.setBlock(i + 16, j + 14, k + 7, Blocks.air, 0, 2);
		world.setBlock(i + 17, j + 14, k + 7, Blocks.air, 0, 2);
		world.setBlock(i + 18, j + 14, k + 7, Blocks.air, 0, 2);
		world.setBlock(i + 19, j + 14, k + 7, Blocks.air, 0, 2);
		world.setBlock(i + 20, j + 14, k + 7, NovaCraftBlocks.basal, 0, 2);
		world.setBlock(i + 21, j + 14, k + 7, NovaCraftBlocks.basal, 0, 2);
		world.setBlock(i + 22, j + 14, k + 7, NovaCraftBlocks.basal, 0, 2);
		world.setBlock(i + 23, j + 14, k + 7, NovaCraftBlocks.basal, 0, 2);
		world.setBlock(i + 24, j + 14, k + 7, NovaCraftBlocks.basal, 0, 2);
		world.setBlock(i + 25, j + 14, k + 7, NovaCraftBlocks.basal, 0, 2);
		world.setBlock(i + 26, j + 14, k + 7, NovaCraftBlocks.basal, 0, 2);
		world.setBlock(i + 27, j + 14, k + 7, NovaCraftBlocks.basal, 0, 2);
		world.setBlock(i, j + 14, k + 8, NovaCraftBlocks.basal, 0, 2);
		world.setBlock(i + 1, j + 14, k + 8, NovaCraftBlocks.basal, 0, 2);
		world.setBlock(i + 2, j + 14, k + 8, NovaCraftBlocks.basal, 0, 2);
		world.setBlock(i + 3, j + 14, k + 8, NovaCraftBlocks.basal, 0, 2);
		world.setBlock(i + 4, j + 14, k + 8, NovaCraftBlocks.basal, 0, 2);
		world.setBlock(i + 5, j + 14, k + 8, NovaCraftBlocks.basal, 0, 2);
		world.setBlock(i + 6, j + 14, k + 8, NovaCraftBlocks.basal, 0, 2);
		world.setBlock(i + 7, j + 14, k + 8, NovaCraftBlocks.basal, 0, 2);
		world.setBlock(i + 8, j + 14, k + 8, NovaCraftBlocks.basal, 0, 2);
		world.setBlock(i + 9, j + 14, k + 8, NovaCraftBlocks.basal, 0, 2);
		world.setBlock(i + 10, j + 14, k + 8, NovaCraftBlocks.basal, 0, 2);
		world.setBlock(i + 11, j + 14, k + 8, NovaCraftBlocks.basal, 0, 2);
		world.setBlock(i + 12, j + 14, k + 8, NovaCraftBlocks.basal, 0, 2);
		world.setBlock(i + 13, j + 14, k + 8, NovaCraftBlocks.basal, 0, 2);
		world.setBlock(i + 14, j + 14, k + 8, NovaCraftBlocks.basal, 0, 2);
		world.setBlock(i + 15, j + 14, k + 8, NovaCraftBlocks.basal, 0, 2);
		world.setBlock(i + 16, j + 14, k + 8, NovaCraftBlocks.basal, 0, 2);
		world.setBlock(i + 17, j + 14, k + 8, Blocks.air, 0, 2);
		world.setBlock(i + 18, j + 14, k + 8, Blocks.air, 0, 2);
		world.setBlock(i + 19, j + 14, k + 8, NovaCraftBlocks.basal, 0, 2);
		world.setBlock(i + 20, j + 14, k + 8, NovaCraftBlocks.basal, 0, 2);
		world.setBlock(i + 21, j + 14, k + 8, NovaCraftBlocks.basal, 0, 2);
		world.setBlock(i + 22, j + 14, k + 8, NovaCraftBlocks.basal, 0, 2);
		world.setBlock(i + 23, j + 14, k + 8, NovaCraftBlocks.basal, 0, 2);
		world.setBlock(i + 24, j + 14, k + 8, NovaCraftBlocks.basal, 0, 2);
		world.setBlock(i + 25, j + 14, k + 8, NovaCraftBlocks.basal, 0, 2);
		world.setBlock(i + 26, j + 14, k + 8, NovaCraftBlocks.basal, 0, 2);
		world.setBlock(i + 27, j + 14, k + 8, NovaCraftBlocks.basal, 0, 2);
		world.setBlock(i, j + 14, k + 9, NovaCraftBlocks.cracked_basal_bricks, 0, 2);
		world.setBlock(i + 1, j + 14, k + 9, NovaCraftBlocks.cracked_basal_bricks, 0, 2);
		world.setBlock(i + 2, j + 14, k + 9, NovaCraftBlocks.basal, 0, 2);
		world.setBlock(i + 3, j + 14, k + 9, NovaCraftBlocks.basal, 0, 2);
		world.setBlock(i + 4, j + 14, k + 9, NovaCraftBlocks.basal, 0, 2);
		world.setBlock(i + 5, j + 14, k + 9, NovaCraftBlocks.basal, 0, 2);
		world.setBlock(i + 6, j + 14, k + 9, NovaCraftBlocks.basal, 0, 2);
		world.setBlock(i + 7, j + 14, k + 9, NovaCraftBlocks.basal, 0, 2);
		world.setBlock(i + 8, j + 14, k + 9, NovaCraftBlocks.basal, 0, 2);
		world.setBlock(i + 9, j + 14, k + 9, NovaCraftBlocks.basal, 0, 2);
		world.setBlock(i + 10, j + 14, k + 9, NovaCraftBlocks.basal, 0, 2);
		world.setBlock(i + 11, j + 14, k + 9, NovaCraftBlocks.basal, 0, 2);
		world.setBlock(i + 12, j + 14, k + 9, NovaCraftBlocks.basal, 0, 2);
		world.setBlock(i + 13, j + 14, k + 9, NovaCraftBlocks.basal, 0, 2);
		world.setBlock(i + 14, j + 14, k + 9, NovaCraftBlocks.basal, 0, 2);
		world.setBlock(i + 15, j + 14, k + 9, NovaCraftBlocks.basal, 0, 2);
		world.setBlock(i + 16, j + 14, k + 9, Blocks.lava, 8, 2);
		world.setBlock(i + 17, j + 14, k + 9, Blocks.air, 0, 2);
		world.setBlock(i + 18, j + 14, k + 9, Blocks.air, 0, 2);
		world.setBlock(i + 19, j + 14, k + 9, NovaCraftBlocks.basal, 0, 2);
		world.setBlock(i + 20, j + 14, k + 9, NovaCraftBlocks.basal, 0, 2);
		world.setBlock(i + 21, j + 14, k + 9, Blocks.lava, 8, 2);
		world.setBlock(i + 22, j + 14, k + 9, NovaCraftBlocks.basal, 0, 2);
		world.setBlock(i + 23, j + 14, k + 9, NovaCraftBlocks.basal, 0, 2);
		world.setBlock(i + 24, j + 14, k + 9, NovaCraftBlocks.basal, 0, 2);
		world.setBlock(i + 25, j + 14, k + 9, NovaCraftBlocks.basal, 0, 2);
		world.setBlock(i + 26, j + 14, k + 9, NovaCraftBlocks.basal, 0, 2);
		world.setBlock(i + 27, j + 14, k + 9, NovaCraftBlocks.basal, 0, 2);
		world.setBlock(i, j + 14, k + 10, Blocks.air, 0, 2);
		world.setBlock(i + 1, j + 14, k + 10, NovaCraftBlocks.cracked_basal_bricks, 0, 2);
		world.setBlock(i + 2, j + 14, k + 10, NovaCraftBlocks.basal, 0, 2);
		world.setBlock(i + 3, j + 14, k + 10, NovaCraftBlocks.basal, 0, 2);
		world.setBlock(i + 4, j + 14, k + 10, NovaCraftBlocks.basal, 0, 2);
		world.setBlock(i + 5, j + 14, k + 10, NovaCraftBlocks.basal, 0, 2);
		world.setBlock(i + 6, j + 14, k + 10, NovaCraftBlocks.basal, 0, 2);
		world.setBlock(i + 7, j + 14, k + 10, NovaCraftBlocks.basal, 0, 2);
		world.setBlock(i + 8, j + 14, k + 10, NovaCraftBlocks.basal, 0, 2);
		world.setBlock(i + 9, j + 14, k + 10, NovaCraftBlocks.basal, 0, 2);
		world.setBlock(i + 10, j + 14, k + 10, NovaCraftBlocks.basal, 0, 2);
		world.setBlock(i + 11, j + 14, k + 10, NovaCraftBlocks.basal, 0, 2);
		world.setBlock(i + 12, j + 14, k + 10, NovaCraftBlocks.basal, 0, 2);
		world.setBlock(i + 13, j + 14, k + 10, NovaCraftBlocks.basal, 0, 2);
		world.setBlock(i + 14, j + 14, k + 10, NovaCraftBlocks.basal, 0, 2);
		world.setBlock(i + 15, j + 14, k + 10, NovaCraftBlocks.basal, 0, 2);
		world.setBlock(i + 16, j + 14, k + 10, NovaCraftBlocks.basal, 0, 2);
		world.setBlock(i + 17, j + 14, k + 10, NovaCraftBlocks.basal, 0, 2);
		world.setBlock(i + 18, j + 14, k + 10, NovaCraftBlocks.basal, 0, 2);
		world.setBlock(i + 19, j + 14, k + 10, NovaCraftBlocks.basal, 0, 2);
		world.setBlock(i + 20, j + 14, k + 10, NovaCraftBlocks.basal, 0, 2);
		world.setBlock(i + 21, j + 14, k + 10, NovaCraftBlocks.basal, 0, 2);
		world.setBlock(i + 22, j + 14, k + 10, NovaCraftBlocks.basal, 0, 2);
		world.setBlock(i + 23, j + 14, k + 10, NovaCraftBlocks.basal, 0, 2);
		world.setBlock(i + 24, j + 14, k + 10, NovaCraftBlocks.basal, 0, 2);
		world.setBlock(i + 25, j + 14, k + 10, NovaCraftBlocks.basal, 0, 2);
		world.setBlock(i + 26, j + 14, k + 10, NovaCraftBlocks.basal, 0, 2);
		world.setBlock(i + 27, j + 14, k + 10, NovaCraftBlocks.basal, 0, 2);
		world.setBlock(i, j + 14, k + 11, NovaCraftBlocks.basal_bricks, 0, 2);
		world.setBlock(i + 1, j + 14, k + 11, NovaCraftBlocks.basal_bricks, 0, 2);
		world.setBlock(i + 2, j + 14, k + 11, NovaCraftBlocks.basal_bricks, 0, 2);
		world.setBlock(i + 3, j + 14, k + 11, NovaCraftBlocks.basal_bricks, 0, 2);
		world.setBlock(i + 4, j + 14, k + 11, NovaCraftBlocks.cracked_basal_bricks, 0, 2);
		world.setBlock(i + 5, j + 14, k + 11, NovaCraftBlocks.basal_bricks, 0, 2);
		world.setBlock(i + 6, j + 14, k + 11, NovaCraftBlocks.cracked_basal_bricks, 0, 2);
		world.setBlock(i + 7, j + 14, k + 11, NovaCraftBlocks.basal_bricks, 0, 2);
		world.setBlock(i + 8, j + 14, k + 11, NovaCraftBlocks.cracked_basal_bricks, 0, 2);
		world.setBlock(i + 9, j + 14, k + 11, NovaCraftBlocks.basal_bricks, 0, 2);
		world.setBlock(i + 10, j + 14, k + 11, NovaCraftBlocks.basal_bricks, 0, 2);
		world.setBlock(i + 11, j + 14, k + 11, NovaCraftBlocks.basal_bricks, 0, 2);
		world.setBlock(i + 12, j + 14, k + 11, NovaCraftBlocks.cracked_basal_bricks, 0, 2);
		world.setBlock(i + 13, j + 14, k + 11, NovaCraftBlocks.basal_bricks, 0, 2);
		world.setBlock(i + 14, j + 14, k + 11, NovaCraftBlocks.cracked_basal_bricks, 0, 2);
		world.setBlock(i + 15, j + 14, k + 11, NovaCraftBlocks.basal_bricks, 0, 2);
		world.setBlock(i + 16, j + 14, k + 11, NovaCraftBlocks.basal, 0, 2);
		world.setBlock(i + 17, j + 14, k + 11, NovaCraftBlocks.basal, 0, 2);
		world.setBlock(i + 18, j + 14, k + 11, NovaCraftBlocks.basal, 0, 2);
		world.setBlock(i + 19, j + 14, k + 11, NovaCraftBlocks.basal, 0, 2);
		world.setBlock(i + 20, j + 14, k + 11, NovaCraftBlocks.basal, 0, 2);
		world.setBlock(i + 21, j + 14, k + 11, NovaCraftBlocks.basal, 0, 2);
		world.setBlock(i + 22, j + 14, k + 11, NovaCraftBlocks.basal, 0, 2);
		world.setBlock(i + 23, j + 14, k + 11, NovaCraftBlocks.basal, 0, 2);
		world.setBlock(i + 24, j + 14, k + 11, NovaCraftBlocks.basal, 0, 2);
		world.setBlock(i + 25, j + 14, k + 11, NovaCraftBlocks.basal, 0, 2);
		world.setBlock(i + 26, j + 14, k + 11, NovaCraftBlocks.basal, 0, 2);
		world.setBlock(i + 27, j + 14, k + 11, NovaCraftBlocks.basal, 0, 2);
		world.setBlock(i, j + 14, k + 12, NovaCraftBlocks.basal_bricks, 0, 2);
		world.setBlock(i + 1, j + 14, k + 12, NovaCraftBlocks.basal_bricks, 0, 2);
		world.setBlock(i + 2, j + 14, k + 12, NovaCraftBlocks.basal_bricks, 0, 2);
		world.setBlock(i + 3, j + 14, k + 12, NovaCraftBlocks.cracked_basal_bricks, 0, 2);
		world.setBlock(i + 4, j + 14, k + 12, NovaCraftBlocks.cracked_basal_bricks, 0, 2);
		world.setBlock(i + 5, j + 14, k + 12, NovaCraftBlocks.basal_bricks, 0, 2);
		world.setBlock(i + 6, j + 14, k + 12, NovaCraftBlocks.basal_bricks, 0, 2);
		world.setBlock(i + 7, j + 14, k + 12, NovaCraftBlocks.basal_bricks, 0, 2);
		world.setBlock(i + 8, j + 14, k + 12, NovaCraftBlocks.basal_bricks, 0, 2);
		world.setBlock(i + 9, j + 14, k + 12, NovaCraftBlocks.basal_bricks, 0, 2);
		world.setBlock(i + 10, j + 14, k + 12, NovaCraftBlocks.cracked_basal_bricks, 0, 2);
		world.setBlock(i + 11, j + 14, k + 12, NovaCraftBlocks.cracked_basal_bricks, 0, 2);
		world.setBlock(i + 12, j + 14, k + 12, NovaCraftBlocks.basal_bricks, 0, 2);
		world.setBlock(i + 13, j + 14, k + 12, NovaCraftBlocks.basal_bricks, 0, 2);
		world.setBlock(i + 14, j + 14, k + 12, Blocks.air, 0, 2);
		world.setBlock(i + 15, j + 14, k + 12, NovaCraftBlocks.cracked_basal_bricks, 0, 2);
		world.setBlock(i + 16, j + 14, k + 12, NovaCraftBlocks.basal, 0, 2);
		world.setBlock(i + 17, j + 14, k + 12, NovaCraftBlocks.basal, 0, 2);
		world.setBlock(i + 18, j + 14, k + 12, NovaCraftBlocks.basal, 0, 2);
		world.setBlock(i + 19, j + 14, k + 12, NovaCraftBlocks.basal, 0, 2);
		world.setBlock(i + 20, j + 14, k + 12, NovaCraftBlocks.basal, 0, 2);
		world.setBlock(i + 21, j + 14, k + 12, NovaCraftBlocks.basal, 0, 2);
		world.setBlock(i + 22, j + 14, k + 12, NovaCraftBlocks.basal, 0, 2);
		world.setBlock(i + 23, j + 14, k + 12, NovaCraftBlocks.basal, 0, 2);
		world.setBlock(i + 24, j + 14, k + 12, NovaCraftBlocks.basal, 0, 2);
		world.setBlock(i + 25, j + 14, k + 12, NovaCraftBlocks.basal, 0, 2);
		world.setBlock(i + 26, j + 14, k + 12, NovaCraftBlocks.basal, 0, 2);
		world.setBlock(i + 27, j + 14, k + 12, NovaCraftBlocks.basal, 0, 2);
		world.setBlock(i, j + 15, k + 1, NovaCraftBlocks.basal, 0, 2);
		world.setBlock(i + 1, j + 15, k + 1, NovaCraftBlocks.basal, 0, 2);
		world.setBlock(i + 4, j + 15, k + 1, NovaCraftBlocks.cracked_basal_bricks, 0, 2);
		world.setBlock(i + 8, j + 15, k + 1, NovaCraftBlocks.basal, 0, 2);
		world.setBlock(i + 9, j + 15, k + 1, NovaCraftBlocks.basal, 0, 2);
		world.setBlock(i, j + 15, k + 2, NovaCraftBlocks.basal, 0, 2);
		world.setBlock(i + 1, j + 15, k + 2, NovaCraftBlocks.basal, 0, 2);
		world.setBlock(i + 2, j + 15, k + 2, NovaCraftBlocks.cracked_basal_bricks, 0, 2);
		world.setBlock(i + 3, j + 15, k + 2, NovaCraftBlocks.basal_bricks, 0, 2);
		world.setBlock(i + 4, j + 15, k + 2, NovaCraftBlocks.basal, 0, 2);
		world.setBlock(i + 5, j + 15, k + 2, NovaCraftBlocks.basal, 0, 2);
		world.setBlock(i + 6, j + 15, k + 2, NovaCraftBlocks.basal, 0, 2);
		world.setBlock(i + 7, j + 15, k + 2, NovaCraftBlocks.cracked_basal_bricks, 0, 2);
		world.setBlock(i + 8, j + 15, k + 2, NovaCraftBlocks.basal, 0, 2);
		world.setBlock(i + 9, j + 15, k + 2, NovaCraftBlocks.basal, 0, 2);
		world.setBlock(i + 10, j + 15, k + 2, NovaCraftBlocks.basal, 0, 2);
		world.setBlock(i + 11, j + 15, k + 2, NovaCraftBlocks.cracked_basal_bricks, 0, 2);
		world.setBlock(i + 13, j + 15, k + 2, NovaCraftBlocks.basal, 0, 2);
		world.setBlock(i, j + 15, k + 3, NovaCraftBlocks.basal, 0, 2);
		world.setBlock(i + 1, j + 15, k + 3, NovaCraftBlocks.basal, 0, 2);
		world.setBlock(i + 2, j + 15, k + 3, NovaCraftBlocks.basal, 0, 2);
		world.setBlock(i + 3, j + 15, k + 3, NovaCraftBlocks.basal, 0, 2);
		world.setBlock(i + 4, j + 15, k + 3, NovaCraftBlocks.basal, 0, 2);
		world.setBlock(i + 5, j + 15, k + 3, NovaCraftBlocks.basal, 0, 2);
		world.setBlock(i + 6, j + 15, k + 3, NovaCraftBlocks.basal, 0, 2);
		world.setBlock(i + 7, j + 15, k + 3, NovaCraftBlocks.basal, 0, 2);
		world.setBlock(i + 8, j + 15, k + 3, NovaCraftBlocks.basal, 0, 2);
		world.setBlock(i + 9, j + 15, k + 3, NovaCraftBlocks.basal, 0, 2);
		world.setBlock(i + 10, j + 15, k + 3, NovaCraftBlocks.basal, 0, 2);
		world.setBlock(i + 11, j + 15, k + 3, NovaCraftBlocks.basal, 0, 2);
		world.setBlock(i + 12, j + 15, k + 3, NovaCraftBlocks.basal, 0, 2);
		world.setBlock(i + 13, j + 15, k + 3, NovaCraftBlocks.basal, 0, 2);
		world.setBlock(i + 14, j + 15, k + 3, NovaCraftBlocks.basal, 0, 2);
		world.setBlock(i + 15, j + 15, k + 3, NovaCraftBlocks.basal, 0, 2);
		world.setBlock(i + 18, j + 15, k + 3, NovaCraftBlocks.cracked_basal_bricks, 0, 2);
		world.setBlock(i + 22, j + 15, k + 3, NovaCraftBlocks.basal, 0, 2);
		world.setBlock(i + 23, j + 15, k + 3, NovaCraftBlocks.basal, 0, 2);
		world.setBlock(i, j + 15, k + 4, NovaCraftBlocks.basal, 0, 2);
		world.setBlock(i + 1, j + 15, k + 4, NovaCraftBlocks.basal, 0, 2);
		world.setBlock(i + 2, j + 15, k + 4, NovaCraftBlocks.basal, 0, 2);
		world.setBlock(i + 3, j + 15, k + 4, NovaCraftBlocks.basal, 0, 2);
		world.setBlock(i + 4, j + 15, k + 4, NovaCraftBlocks.basal, 0, 2);
		world.setBlock(i + 5, j + 15, k + 4, NovaCraftBlocks.basal, 0, 2);
		world.setBlock(i + 6, j + 15, k + 4, NovaCraftBlocks.basal, 0, 2);
		world.setBlock(i + 7, j + 15, k + 4, NovaCraftBlocks.basal, 0, 2);
		world.setBlock(i + 8, j + 15, k + 4, NovaCraftBlocks.basal, 0, 2);
		world.setBlock(i + 9, j + 15, k + 4, NovaCraftBlocks.basal, 0, 2);
		world.setBlock(i + 10, j + 15, k + 4, NovaCraftBlocks.basal, 0, 2);
		world.setBlock(i + 11, j + 15, k + 4, NovaCraftBlocks.basal, 0, 2);
		world.setBlock(i + 12, j + 15, k + 4, NovaCraftBlocks.basal, 0, 2);
		world.setBlock(i + 13, j + 15, k + 4, Blocks.air, 0, 2);
		world.setBlock(i + 14, j + 15, k + 4, NovaCraftBlocks.basal, 0, 2);
		world.setBlock(i + 15, j + 15, k + 4, NovaCraftBlocks.basal, 0, 2);
		world.setBlock(i + 16, j + 15, k + 4, NovaCraftBlocks.cracked_basal_bricks, 0, 2);
		world.setBlock(i + 17, j + 15, k + 4, NovaCraftBlocks.cracked_basal_bricks, 0, 2);
		world.setBlock(i + 18, j + 15, k + 4, NovaCraftBlocks.basal, 0, 2);
		world.setBlock(i + 19, j + 15, k + 4, NovaCraftBlocks.basal, 0, 2);
		world.setBlock(i + 20, j + 15, k + 4, NovaCraftBlocks.basal, 0, 2);
		world.setBlock(i + 21, j + 15, k + 4, NovaCraftBlocks.basal_bricks, 0, 2);
		world.setBlock(i + 22, j + 15, k + 4, NovaCraftBlocks.basal, 0, 2);
		world.setBlock(i + 23, j + 15, k + 4, NovaCraftBlocks.basal, 0, 2);
		world.setBlock(i + 24, j + 15, k + 4, NovaCraftBlocks.basal, 0, 2);
		world.setBlock(i + 25, j + 15, k + 4, NovaCraftBlocks.cracked_basal_bricks, 0, 2);
		world.setBlock(i + 26, j + 15, k + 4, Blocks.air, 0, 2);
		world.setBlock(i + 27, j + 15, k + 4, NovaCraftBlocks.basal, 0, 2);
		world.setBlock(i, j + 15, k + 5, NovaCraftBlocks.basal, 0, 2);
		world.setBlock(i + 1, j + 15, k + 5, NovaCraftBlocks.basal, 0, 2);
		world.setBlock(i + 2, j + 15, k + 5, NovaCraftBlocks.basal, 0, 2);
		world.setBlock(i + 3, j + 15, k + 5, Blocks.air, 0, 2);
		world.setBlock(i + 4, j + 15, k + 5, Blocks.air, 0, 2);
		world.setBlock(i + 5, j + 15, k + 5, NovaCraftBlocks.basal, 0, 2);
		world.setBlock(i + 6, j + 15, k + 5, NovaCraftBlocks.basal, 0, 2);
		world.setBlock(i + 7, j + 15, k + 5, NovaCraftBlocks.basal, 0, 2);
		world.setBlock(i + 8, j + 15, k + 5, NovaCraftBlocks.basal, 0, 2);
		world.setBlock(i + 9, j + 15, k + 5, NovaCraftBlocks.basal, 0, 2);
		world.setBlock(i + 10, j + 15, k + 5, NovaCraftBlocks.basal, 0, 2);
		world.setBlock(i + 11, j + 15, k + 5, NovaCraftBlocks.basal, 0, 2);
		world.setBlock(i + 12, j + 15, k + 5, NovaCraftBlocks.basal, 0, 2);
		world.setBlock(i + 13, j + 15, k + 5, Blocks.air, 0, 2);
		world.setBlock(i + 14, j + 15, k + 5, NovaCraftBlocks.basal, 0, 2);
		world.setBlock(i + 15, j + 15, k + 5, NovaCraftBlocks.basal, 0, 2);
		world.setBlock(i + 16, j + 15, k + 5, NovaCraftBlocks.basal, 0, 2);
		world.setBlock(i + 17, j + 15, k + 5, NovaCraftBlocks.basal, 0, 2);
		world.setBlock(i + 18, j + 15, k + 5, NovaCraftBlocks.basal, 0, 2);
		world.setBlock(i + 19, j + 15, k + 5, NovaCraftBlocks.basal, 0, 2);
		world.setBlock(i + 20, j + 15, k + 5, NovaCraftBlocks.basal, 0, 2);
		world.setBlock(i + 21, j + 15, k + 5, NovaCraftBlocks.basal, 0, 2);
		world.setBlock(i + 22, j + 15, k + 5, NovaCraftBlocks.basal, 0, 2);
		world.setBlock(i + 23, j + 15, k + 5, NovaCraftBlocks.basal, 0, 2);
		world.setBlock(i + 24, j + 15, k + 5, NovaCraftBlocks.basal, 0, 2);
		world.setBlock(i + 25, j + 15, k + 5, NovaCraftBlocks.basal, 0, 2);
		world.setBlock(i + 26, j + 15, k + 5, NovaCraftBlocks.basal, 0, 2);
		world.setBlock(i + 27, j + 15, k + 5, NovaCraftBlocks.basal, 0, 2);
		world.setBlock(i, j + 15, k + 6, NovaCraftBlocks.basal, 0, 2);
		world.setBlock(i + 1, j + 15, k + 6, NovaCraftBlocks.basal, 0, 2);
		world.setBlock(i + 2, j + 15, k + 6, NovaCraftBlocks.basal, 0, 2);
		world.setBlock(i + 3, j + 15, k + 6, Blocks.air, 0, 2);
		world.setBlock(i + 4, j + 15, k + 6, Blocks.air, 0, 2);
		world.setBlock(i + 5, j + 15, k + 6, NovaCraftBlocks.basal, 0, 2);
		world.setBlock(i + 6, j + 15, k + 6, NovaCraftBlocks.basal, 0, 2);
		world.setBlock(i + 7, j + 15, k + 6, NovaCraftBlocks.basal, 0, 2);
		world.setBlock(i + 8, j + 15, k + 6, NovaCraftBlocks.basal, 0, 2);
		world.setBlock(i + 9, j + 15, k + 6, NovaCraftBlocks.basal, 0, 2);
		world.setBlock(i + 10, j + 15, k + 6, NovaCraftBlocks.basal, 0, 2);
		world.setBlock(i + 11, j + 15, k + 6, NovaCraftBlocks.basal, 0, 2);
		world.setBlock(i + 12, j + 15, k + 6, NovaCraftBlocks.basal, 0, 2);
		world.setBlock(i + 13, j + 15, k + 6, NovaCraftBlocks.basal, 0, 2);
		world.setBlock(i + 14, j + 15, k + 6, NovaCraftBlocks.basal, 0, 2);
		world.setBlock(i + 15, j + 15, k + 6, NovaCraftBlocks.basal, 0, 2);
		world.setBlock(i + 16, j + 15, k + 6, NovaCraftBlocks.basal, 0, 2);
		world.setBlock(i + 17, j + 15, k + 6, NovaCraftBlocks.basal, 0, 2);
		world.setBlock(i + 18, j + 15, k + 6, NovaCraftBlocks.basal, 0, 2);
		world.setBlock(i + 19, j + 15, k + 6, NovaCraftBlocks.basal, 0, 2);
		world.setBlock(i + 20, j + 15, k + 6, NovaCraftBlocks.basal, 0, 2);
		world.setBlock(i + 21, j + 15, k + 6, NovaCraftBlocks.basal, 0, 2);
		world.setBlock(i + 22, j + 15, k + 6, NovaCraftBlocks.basal, 0, 2);
		world.setBlock(i + 23, j + 15, k + 6, NovaCraftBlocks.basal, 0, 2);
		world.setBlock(i + 24, j + 15, k + 6, NovaCraftBlocks.basal, 0, 2);
		world.setBlock(i + 25, j + 15, k + 6, NovaCraftBlocks.basal, 0, 2);
		world.setBlock(i + 26, j + 15, k + 6, NovaCraftBlocks.basal, 0, 2);
		world.setBlock(i + 27, j + 15, k + 6, Blocks.air, 0, 2);
		world.setBlock(i, j + 15, k + 7, NovaCraftBlocks.basal, 0, 2);
		world.setBlock(i + 1, j + 15, k + 7, NovaCraftBlocks.basal, 0, 2);
		world.setBlock(i + 2, j + 15, k + 7, Blocks.lava, 8, 2);
		world.setBlock(i + 3, j + 15, k + 7, Blocks.air, 0, 2);
		world.setBlock(i + 4, j + 15, k + 7, Blocks.air, 0, 2);
		world.setBlock(i + 5, j + 15, k + 7, NovaCraftBlocks.basal, 0, 2);
		world.setBlock(i + 6, j + 15, k + 7, NovaCraftBlocks.basal, 0, 2);
		world.setBlock(i + 7, j + 15, k + 7, Blocks.lava, 8, 2);
		world.setBlock(i + 8, j + 15, k + 7, NovaCraftBlocks.basal, 0, 2);
		world.setBlock(i + 9, j + 15, k + 7, NovaCraftBlocks.basal, 0, 2);
		world.setBlock(i + 10, j + 15, k + 7, NovaCraftBlocks.basal, 0, 2);
		world.setBlock(i + 11, j + 15, k + 7, NovaCraftBlocks.basal, 0, 2);
		world.setBlock(i + 12, j + 15, k + 7, NovaCraftBlocks.basal, 0, 2);
		world.setBlock(i + 13, j + 15, k + 7, NovaCraftBlocks.basal, 0, 2);
		world.setBlock(i + 14, j + 15, k + 7, NovaCraftBlocks.basal, 0, 2);
		world.setBlock(i + 15, j + 15, k + 7, NovaCraftBlocks.basal, 0, 2);
		world.setBlock(i + 16, j + 15, k + 7, NovaCraftBlocks.basal, 0, 2);
		world.setBlock(i + 17, j + 15, k + 7, Blocks.air, 0, 2);
		world.setBlock(i + 18, j + 15, k + 7, Blocks.air, 0, 2);
		world.setBlock(i + 19, j + 15, k + 7, NovaCraftBlocks.basal, 0, 2);
		world.setBlock(i + 20, j + 15, k + 7, NovaCraftBlocks.basal, 0, 2);
		world.setBlock(i + 21, j + 15, k + 7, NovaCraftBlocks.basal, 0, 2);
		world.setBlock(i + 22, j + 15, k + 7, NovaCraftBlocks.basal, 0, 2);
		world.setBlock(i + 23, j + 15, k + 7, NovaCraftBlocks.basal, 0, 2);
		world.setBlock(i + 24, j + 15, k + 7, NovaCraftBlocks.basal, 0, 2);
		world.setBlock(i + 25, j + 15, k + 7, NovaCraftBlocks.basal, 0, 2);
		world.setBlock(i + 26, j + 15, k + 7, NovaCraftBlocks.basal, 0, 2);
		world.setBlock(i + 27, j + 15, k + 7, Blocks.air, 0, 2);
		world.setBlock(i, j + 15, k + 8, NovaCraftBlocks.basal, 0, 2);
		world.setBlock(i + 1, j + 15, k + 8, NovaCraftBlocks.basal, 0, 2);
		world.setBlock(i + 2, j + 15, k + 8, NovaCraftBlocks.basal, 0, 2);
		world.setBlock(i + 3, j + 15, k + 8, Blocks.air, 0, 2);
		world.setBlock(i + 4, j + 15, k + 8, Blocks.air, 0, 2);
		world.setBlock(i + 5, j + 15, k + 8, NovaCraftBlocks.basal, 0, 2);
		world.setBlock(i + 6, j + 15, k + 8, NovaCraftBlocks.basal, 0, 2);
		world.setBlock(i + 7, j + 15, k + 8, NovaCraftBlocks.basal, 0, 2);
		world.setBlock(i + 8, j + 15, k + 8, NovaCraftBlocks.basal, 0, 2);
		world.setBlock(i + 9, j + 15, k + 8, NovaCraftBlocks.basal, 0, 2);
		world.setBlock(i + 10, j + 15, k + 8, NovaCraftBlocks.basal, 0, 2);
		world.setBlock(i + 11, j + 15, k + 8, NovaCraftBlocks.basal, 0, 2);
		world.setBlock(i + 12, j + 15, k + 8, NovaCraftBlocks.basal, 0, 2);
		world.setBlock(i + 13, j + 15, k + 8, NovaCraftBlocks.basal, 0, 2);
		world.setBlock(i + 14, j + 15, k + 8, NovaCraftBlocks.basal, 0, 2);
		world.setBlock(i + 15, j + 15, k + 8, NovaCraftBlocks.basal, 0, 2);
		world.setBlock(i + 16, j + 15, k + 8, NovaCraftBlocks.basal, 0, 2);
		world.setBlock(i + 17, j + 15, k + 8, Blocks.air, 0, 2);
		world.setBlock(i + 18, j + 15, k + 8, Blocks.air, 0, 2);
		world.setBlock(i + 19, j + 15, k + 8, NovaCraftBlocks.basal, 0, 2);
		world.setBlock(i + 20, j + 15, k + 8, NovaCraftBlocks.basal, 0, 2);
		world.setBlock(i + 21, j + 15, k + 8, NovaCraftBlocks.basal, 0, 2);
		world.setBlock(i + 22, j + 15, k + 8, NovaCraftBlocks.basal, 0, 2);
		world.setBlock(i + 23, j + 15, k + 8, NovaCraftBlocks.basal, 0, 2);
		world.setBlock(i + 24, j + 15, k + 8, NovaCraftBlocks.basal, 0, 2);
		world.setBlock(i + 25, j + 15, k + 8, NovaCraftBlocks.basal, 0, 2);
		world.setBlock(i + 26, j + 15, k + 8, NovaCraftBlocks.basal, 0, 2);
		world.setBlock(i + 27, j + 15, k + 8, NovaCraftBlocks.basal, 0, 2);
		world.setBlock(i, j + 15, k + 9, NovaCraftBlocks.cracked_basal_bricks, 0, 2);
		world.setBlock(i + 1, j + 15, k + 9, NovaCraftBlocks.basal, 0, 2);
		world.setBlock(i + 2, j + 15, k + 9, NovaCraftBlocks.basal, 0, 2);
		world.setBlock(i + 3, j + 15, k + 9, NovaCraftBlocks.basal, 0, 2);
		world.setBlock(i + 4, j + 15, k + 9, NovaCraftBlocks.basal, 0, 2);
		world.setBlock(i + 5, j + 15, k + 9, NovaCraftBlocks.basal, 0, 2);
		world.setBlock(i + 6, j + 15, k + 9, NovaCraftBlocks.basal, 0, 2);
		world.setBlock(i + 7, j + 15, k + 9, NovaCraftBlocks.basal, 0, 2);
		world.setBlock(i + 8, j + 15, k + 9, NovaCraftBlocks.basal, 0, 2);
		world.setBlock(i + 9, j + 15, k + 9, NovaCraftBlocks.basal, 0, 2);
		world.setBlock(i + 10, j + 15, k + 9, NovaCraftBlocks.basal, 0, 2);
		world.setBlock(i + 11, j + 15, k + 9, NovaCraftBlocks.basal, 0, 2);
		world.setBlock(i + 12, j + 15, k + 9, NovaCraftBlocks.basal, 0, 2);
		world.setBlock(i + 13, j + 15, k + 9, NovaCraftBlocks.basal, 0, 2);
		world.setBlock(i + 14, j + 15, k + 9, NovaCraftBlocks.basal, 0, 2);
		world.setBlock(i + 15, j + 15, k + 9, NovaCraftBlocks.basal, 0, 2);
		world.setBlock(i + 16, j + 15, k + 9, Blocks.lava, 8, 2);
		world.setBlock(i + 17, j + 15, k + 9, Blocks.air, 0, 2);
		world.setBlock(i + 18, j + 15, k + 9, Blocks.air, 0, 2);
		world.setBlock(i + 19, j + 15, k + 9, NovaCraftBlocks.basal, 0, 2);
		world.setBlock(i + 20, j + 15, k + 9, NovaCraftBlocks.basal, 0, 2);
		world.setBlock(i + 21, j + 15, k + 9, Blocks.lava, 8, 2);
		world.setBlock(i + 22, j + 15, k + 9, NovaCraftBlocks.basal, 0, 2);
		world.setBlock(i + 23, j + 15, k + 9, NovaCraftBlocks.basal, 0, 2);
		world.setBlock(i + 24, j + 15, k + 9, NovaCraftBlocks.basal, 0, 2);
		world.setBlock(i + 25, j + 15, k + 9, NovaCraftBlocks.basal, 0, 2);
		world.setBlock(i + 26, j + 15, k + 9, NovaCraftBlocks.basal, 0, 2);
		world.setBlock(i + 27, j + 15, k + 9, NovaCraftBlocks.basal, 0, 2);
		world.setBlock(i, j + 15, k + 10, NovaCraftBlocks.cracked_basal_bricks, 0, 2);
		world.setBlock(i + 1, j + 15, k + 10, NovaCraftBlocks.basal, 0, 2);
		world.setBlock(i + 2, j + 15, k + 10, NovaCraftBlocks.basal, 0, 2);
		world.setBlock(i + 3, j + 15, k + 10, NovaCraftBlocks.basal, 0, 2);
		world.setBlock(i + 4, j + 15, k + 10, NovaCraftBlocks.basal, 0, 2);
		world.setBlock(i + 5, j + 15, k + 10, NovaCraftBlocks.basal, 0, 2);
		world.setBlock(i + 6, j + 15, k + 10, NovaCraftBlocks.basal, 0, 2);
		world.setBlock(i + 7, j + 15, k + 10, NovaCraftBlocks.basal, 0, 2);
		world.setBlock(i + 8, j + 15, k + 10, NovaCraftBlocks.basal, 0, 2);
		world.setBlock(i + 9, j + 15, k + 10, NovaCraftBlocks.basal, 0, 2);
		world.setBlock(i + 10, j + 15, k + 10, NovaCraftBlocks.basal, 0, 2);
		world.setBlock(i + 11, j + 15, k + 10, NovaCraftBlocks.basal, 0, 2);
		world.setBlock(i + 12, j + 15, k + 10, NovaCraftBlocks.basal, 0, 2);
		world.setBlock(i + 13, j + 15, k + 10, NovaCraftBlocks.basal, 0, 2);
		world.setBlock(i + 14, j + 15, k + 10, NovaCraftBlocks.basal, 0, 2);
		world.setBlock(i + 15, j + 15, k + 10, NovaCraftBlocks.basal, 0, 2);
		world.setBlock(i + 16, j + 15, k + 10, NovaCraftBlocks.basal, 0, 2);
		world.setBlock(i + 17, j + 15, k + 10, Blocks.air, 0, 2);
		world.setBlock(i + 18, j + 15, k + 10, Blocks.air, 0, 2);
		world.setBlock(i + 19, j + 15, k + 10, NovaCraftBlocks.basal, 0, 2);
		world.setBlock(i + 20, j + 15, k + 10, NovaCraftBlocks.basal, 0, 2);
		world.setBlock(i + 21, j + 15, k + 10, NovaCraftBlocks.basal, 0, 2);
		world.setBlock(i + 22, j + 15, k + 10, NovaCraftBlocks.basal, 0, 2);
		world.setBlock(i + 23, j + 15, k + 10, NovaCraftBlocks.basal, 0, 2);
		world.setBlock(i + 24, j + 15, k + 10, NovaCraftBlocks.basal, 0, 2);
		world.setBlock(i + 25, j + 15, k + 10, NovaCraftBlocks.basal, 0, 2);
		world.setBlock(i + 26, j + 15, k + 10, NovaCraftBlocks.basal, 0, 2);
		world.setBlock(i + 27, j + 15, k + 10, NovaCraftBlocks.basal, 0, 2);
		world.setBlock(i, j + 15, k + 11, NovaCraftBlocks.cracked_basal_bricks, 0, 2);
		world.setBlock(i + 1, j + 15, k + 11, NovaCraftBlocks.basal_bricks, 0, 2);
		world.setBlock(i + 2, j + 15, k + 11, NovaCraftBlocks.basal_bricks, 0, 2);
		world.setBlock(i + 3, j + 15, k + 11, NovaCraftBlocks.basal_bricks, 0, 2);
		world.setBlock(i + 4, j + 15, k + 11, NovaCraftBlocks.basal_bricks, 0, 2);
		world.setBlock(i + 5, j + 15, k + 11, NovaCraftBlocks.basal_bricks, 0, 2);
		world.setBlock(i + 6, j + 15, k + 11, NovaCraftBlocks.cracked_basal_bricks, 0, 2);
		world.setBlock(i + 7, j + 15, k + 11, NovaCraftBlocks.cracked_basal_bricks, 0, 2);
		world.setBlock(i + 8, j + 15, k + 11, NovaCraftBlocks.basal_bricks, 0, 2);
		world.setBlock(i + 9, j + 15, k + 11, NovaCraftBlocks.basal_bricks, 0, 2);
		world.setBlock(i + 10, j + 15, k + 11, NovaCraftBlocks.basal_bricks, 0, 2);
		world.setBlock(i + 11, j + 15, k + 11, NovaCraftBlocks.basal_bricks, 0, 2);
		world.setBlock(i + 12, j + 15, k + 11, NovaCraftBlocks.basal_bricks, 0, 2);
		world.setBlock(i + 13, j + 15, k + 11, NovaCraftBlocks.basal_bricks, 0, 2);
		world.setBlock(i + 14, j + 15, k + 11, NovaCraftBlocks.basal_bricks, 0, 2);
		world.setBlock(i + 15, j + 15, k + 11, NovaCraftBlocks.basal, 0, 2);
		world.setBlock(i + 16, j + 15, k + 11, NovaCraftBlocks.basal, 0, 2);
		world.setBlock(i + 17, j + 15, k + 11, NovaCraftBlocks.basal, 0, 2);
		world.setBlock(i + 18, j + 15, k + 11, NovaCraftBlocks.basal, 0, 2);
		world.setBlock(i + 19, j + 15, k + 11, NovaCraftBlocks.basal, 0, 2);
		world.setBlock(i + 20, j + 15, k + 11, NovaCraftBlocks.basal, 0, 2);
		world.setBlock(i + 21, j + 15, k + 11, NovaCraftBlocks.basal, 0, 2);
		world.setBlock(i + 22, j + 15, k + 11, NovaCraftBlocks.basal, 0, 2);
		world.setBlock(i + 23, j + 15, k + 11, NovaCraftBlocks.basal, 0, 2);
		world.setBlock(i + 24, j + 15, k + 11, NovaCraftBlocks.basal, 0, 2);
		world.setBlock(i + 25, j + 15, k + 11, NovaCraftBlocks.basal, 0, 2);
		world.setBlock(i + 26, j + 15, k + 11, NovaCraftBlocks.basal, 0, 2);
		world.setBlock(i + 27, j + 15, k + 11, NovaCraftBlocks.glowing_basal, 0, 2);
		world.setBlock(i, j + 15, k + 12, NovaCraftBlocks.basal_bricks, 0, 2);
		world.setBlock(i + 1, j + 15, k + 12, NovaCraftBlocks.basal_bricks, 0, 2);
		world.setBlock(i + 2, j + 15, k + 12, NovaCraftBlocks.basal_bricks, 0, 2);
		world.setBlock(i + 3, j + 15, k + 12, NovaCraftBlocks.basal_bricks, 0, 2);
		world.setBlock(i + 4, j + 15, k + 12, NovaCraftBlocks.cracked_basal_bricks, 0, 2);
		world.setBlock(i + 5, j + 15, k + 12, NovaCraftBlocks.basal_bricks, 0, 2);
		world.setBlock(i + 6, j + 15, k + 12, NovaCraftBlocks.basal_bricks, 0, 2);
		world.setBlock(i + 7, j + 15, k + 12, NovaCraftBlocks.cracked_basal_bricks, 0, 2);
		world.setBlock(i + 8, j + 15, k + 12, NovaCraftBlocks.basal_bricks, 0, 2);
		world.setBlock(i + 9, j + 15, k + 12, NovaCraftBlocks.basal_bricks, 0, 2);
		world.setBlock(i + 10, j + 15, k + 12, NovaCraftBlocks.basal_bricks, 0, 2);
		world.setBlock(i + 11, j + 15, k + 12, NovaCraftBlocks.cracked_basal_bricks, 0, 2);
		world.setBlock(i + 12, j + 15, k + 12, NovaCraftBlocks.basal_bricks, 0, 2);
		world.setBlock(i + 13, j + 15, k + 12, NovaCraftBlocks.basal_bricks, 0, 2);
		world.setBlock(i + 14, j + 15, k + 12, NovaCraftBlocks.basal_bricks, 0, 2);
		world.setBlock(i + 15, j + 15, k + 12, NovaCraftBlocks.basal, 0, 2);
		world.setBlock(i + 16, j + 15, k + 12, NovaCraftBlocks.basal, 0, 2);
		world.setBlock(i + 17, j + 15, k + 12, NovaCraftBlocks.basal, 0, 2);
		world.setBlock(i + 18, j + 15, k + 12, NovaCraftBlocks.basal, 0, 2);
		world.setBlock(i + 19, j + 15, k + 12, NovaCraftBlocks.basal, 0, 2);
		world.setBlock(i + 20, j + 15, k + 12, NovaCraftBlocks.basal, 0, 2);
		world.setBlock(i + 21, j + 15, k + 12, NovaCraftBlocks.basal, 0, 2);
		world.setBlock(i + 22, j + 15, k + 12, NovaCraftBlocks.basal, 0, 2);
		world.setBlock(i + 23, j + 15, k + 12, NovaCraftBlocks.basal, 0, 2);
		world.setBlock(i + 24, j + 15, k + 12, NovaCraftBlocks.basal, 0, 2);
		world.setBlock(i + 25, j + 15, k + 12, NovaCraftBlocks.basal, 0, 2);
		world.setBlock(i + 26, j + 15, k + 12, NovaCraftBlocks.basal, 0, 2);
		world.setBlock(i + 27, j + 15, k + 12, NovaCraftBlocks.basal, 0, 2);
		world.setBlock(i + 4, j + 16, k + 1, NovaCraftBlocks.basal, 0, 2);
		world.setBlock(i + 5, j + 16, k + 1, NovaCraftBlocks.basal, 0, 2);
		world.setBlock(i + 8, j + 16, k + 1, NovaCraftBlocks.basal, 0, 2);
		world.setBlock(i + 9, j + 16, k + 1, NovaCraftBlocks.basal, 0, 2);
		world.setBlock(i, j + 16, k + 2, NovaCraftBlocks.basal, 0, 2);
		world.setBlock(i + 1, j + 16, k + 2, NovaCraftBlocks.basal, 0, 2);
		world.setBlock(i + 2, j + 16, k + 2, NovaCraftBlocks.cracked_basal_bricks, 0, 2);
		world.setBlock(i + 3, j + 16, k + 2, NovaCraftBlocks.cracked_basal_bricks, 0, 2);
		world.setBlock(i + 4, j + 16, k + 2, NovaCraftBlocks.basal, 0, 2);
		world.setBlock(i + 5, j + 16, k + 2, NovaCraftBlocks.basal, 0, 2);
		world.setBlock(i + 6, j + 16, k + 2, NovaCraftBlocks.basal, 0, 2);
		world.setBlock(i + 7, j + 16, k + 2, NovaCraftBlocks.cracked_basal_bricks, 0, 2);
		world.setBlock(i + 8, j + 16, k + 2, NovaCraftBlocks.basal, 0, 2);
		world.setBlock(i + 9, j + 16, k + 2, NovaCraftBlocks.basal, 0, 2);
		world.setBlock(i + 10, j + 16, k + 2, NovaCraftBlocks.basal, 0, 2);
		world.setBlock(i + 11, j + 16, k + 2, NovaCraftBlocks.basal_bricks, 0, 2);
		world.setBlock(i + 12, j + 16, k + 2, NovaCraftBlocks.cracked_basal_bricks, 0, 2);
		world.setBlock(i + 13, j + 16, k + 2, NovaCraftBlocks.basal, 0, 2);
		world.setBlock(i, j + 16, k + 3, NovaCraftBlocks.basal, 0, 2);
		world.setBlock(i + 1, j + 16, k + 3, NovaCraftBlocks.basal, 0, 2);
		world.setBlock(i + 2, j + 16, k + 3, NovaCraftBlocks.basal, 0, 2);
		world.setBlock(i + 3, j + 16, k + 3, NovaCraftBlocks.basal, 0, 2);
		world.setBlock(i + 4, j + 16, k + 3, NovaCraftBlocks.basal, 0, 2);
		world.setBlock(i + 5, j + 16, k + 3, NovaCraftBlocks.basal, 0, 2);
		world.setBlock(i + 6, j + 16, k + 3, NovaCraftBlocks.basal, 0, 2);
		world.setBlock(i + 7, j + 16, k + 3, NovaCraftBlocks.basal, 0, 2);
		world.setBlock(i + 8, j + 16, k + 3, NovaCraftBlocks.basal, 0, 2);
		world.setBlock(i + 9, j + 16, k + 3, NovaCraftBlocks.basal, 0, 2);
		world.setBlock(i + 10, j + 16, k + 3, NovaCraftBlocks.basal, 0, 2);
		world.setBlock(i + 11, j + 16, k + 3, NovaCraftBlocks.basal, 0, 2);
		world.setBlock(i + 12, j + 16, k + 3, NovaCraftBlocks.basal, 0, 2);
		world.setBlock(i + 13, j + 16, k + 3, NovaCraftBlocks.basal, 0, 2);
		world.setBlock(i + 18, j + 16, k + 3, NovaCraftBlocks.basal, 0, 2);
		world.setBlock(i + 19, j + 16, k + 3, NovaCraftBlocks.basal, 0, 2);
		world.setBlock(i + 22, j + 16, k + 3, NovaCraftBlocks.basal, 0, 2);
		world.setBlock(i + 23, j + 16, k + 3, NovaCraftBlocks.basal, 0, 2);
		world.setBlock(i, j + 16, k + 4, NovaCraftBlocks.basal, 0, 2);
		world.setBlock(i + 1, j + 16, k + 4, NovaCraftBlocks.basal, 0, 2);
		world.setBlock(i + 2, j + 16, k + 4, NovaCraftBlocks.basal, 0, 2);
		world.setBlock(i + 3, j + 16, k + 4, NovaCraftBlocks.basal, 0, 2);
		world.setBlock(i + 4, j + 16, k + 4, NovaCraftBlocks.basal, 0, 2);
		world.setBlock(i + 5, j + 16, k + 4, NovaCraftBlocks.basal, 0, 2);
		world.setBlock(i + 6, j + 16, k + 4, NovaCraftBlocks.basal, 0, 2);
		world.setBlock(i + 7, j + 16, k + 4, NovaCraftBlocks.basal, 0, 2);
		world.setBlock(i + 8, j + 16, k + 4, NovaCraftBlocks.basal, 0, 2);
		world.setBlock(i + 9, j + 16, k + 4, NovaCraftBlocks.basal, 0, 2);
		world.setBlock(i + 10, j + 16, k + 4, NovaCraftBlocks.basal, 0, 2);
		world.setBlock(i + 11, j + 16, k + 4, NovaCraftBlocks.basal, 0, 2);
		world.setBlock(i + 12, j + 16, k + 4, NovaCraftBlocks.basal, 0, 2);
		world.setBlock(i + 13, j + 16, k + 4, Blocks.air, 0, 2);
		world.setBlock(i + 14, j + 16, k + 4, NovaCraftBlocks.basal, 0, 2);
		world.setBlock(i + 15, j + 16, k + 4, NovaCraftBlocks.basal, 0, 2);
		world.setBlock(i + 16, j + 16, k + 4, NovaCraftBlocks.basal_bricks, 0, 2);
		world.setBlock(i + 17, j + 16, k + 4, NovaCraftBlocks.cracked_basal_bricks, 0, 2);
		world.setBlock(i + 18, j + 16, k + 4, NovaCraftBlocks.basal, 0, 2);
		world.setBlock(i + 19, j + 16, k + 4, NovaCraftBlocks.basal, 0, 2);
		world.setBlock(i + 20, j + 16, k + 4, NovaCraftBlocks.basal, 0, 2);
		world.setBlock(i + 21, j + 16, k + 4, NovaCraftBlocks.cracked_basal_bricks, 0, 2);
		world.setBlock(i + 22, j + 16, k + 4, NovaCraftBlocks.basal, 0, 2);
		world.setBlock(i + 23, j + 16, k + 4, NovaCraftBlocks.basal, 0, 2);
		world.setBlock(i + 24, j + 16, k + 4, NovaCraftBlocks.basal, 0, 2);
		world.setBlock(i + 25, j + 16, k + 4, NovaCraftBlocks.cracked_basal_bricks, 0, 2);
		world.setBlock(i + 26, j + 16, k + 4, NovaCraftBlocks.cracked_basal_bricks, 0, 2);
		world.setBlock(i + 27, j + 16, k + 4, NovaCraftBlocks.basal, 0, 2);
		world.setBlock(i, j + 16, k + 5, NovaCraftBlocks.basal, 0, 2);
		world.setBlock(i + 1, j + 16, k + 5, NovaCraftBlocks.basal, 0, 2);
		world.setBlock(i + 2, j + 16, k + 5, NovaCraftBlocks.basal, 0, 2);
		world.setBlock(i + 3, j + 16, k + 5, NovaCraftBlocks.basal, 0, 2);
		world.setBlock(i + 4, j + 16, k + 5, NovaCraftBlocks.basal, 0, 2);
		world.setBlock(i + 5, j + 16, k + 5, NovaCraftBlocks.basal, 0, 2);
		world.setBlock(i + 6, j + 16, k + 5, NovaCraftBlocks.basal, 0, 2);
		world.setBlock(i + 7, j + 16, k + 5, NovaCraftBlocks.basal, 0, 2);
		world.setBlock(i + 8, j + 16, k + 5, NovaCraftBlocks.basal, 0, 2);
		world.setBlock(i + 9, j + 16, k + 5, NovaCraftBlocks.basal, 0, 2);
		world.setBlock(i + 10, j + 16, k + 5, NovaCraftBlocks.basal, 0, 2);
		world.setBlock(i + 11, j + 16, k + 5, Blocks.air, 0, 2);
		world.setBlock(i + 12, j + 16, k + 5, Blocks.air, 0, 2);
		world.setBlock(i + 13, j + 16, k + 5, Blocks.air, 0, 2);
		world.setBlock(i + 14, j + 16, k + 5, NovaCraftBlocks.basal, 0, 2);
		world.setBlock(i + 15, j + 16, k + 5, NovaCraftBlocks.basal, 0, 2);
		world.setBlock(i + 16, j + 16, k + 5, NovaCraftBlocks.basal, 0, 2);
		world.setBlock(i + 17, j + 16, k + 5, NovaCraftBlocks.basal, 0, 2);
		world.setBlock(i + 18, j + 16, k + 5, NovaCraftBlocks.basal, 0, 2);
		world.setBlock(i + 19, j + 16, k + 5, NovaCraftBlocks.basal, 0, 2);
		world.setBlock(i + 20, j + 16, k + 5, NovaCraftBlocks.basal, 0, 2);
		world.setBlock(i + 21, j + 16, k + 5, NovaCraftBlocks.basal, 0, 2);
		world.setBlock(i + 22, j + 16, k + 5, NovaCraftBlocks.basal, 0, 2);
		world.setBlock(i + 23, j + 16, k + 5, NovaCraftBlocks.basal, 0, 2);
		world.setBlock(i + 24, j + 16, k + 5, NovaCraftBlocks.basal, 0, 2);
		world.setBlock(i + 25, j + 16, k + 5, NovaCraftBlocks.basal, 0, 2);
		world.setBlock(i + 26, j + 16, k + 5, NovaCraftBlocks.basal, 0, 2);
		world.setBlock(i + 27, j + 16, k + 5, NovaCraftBlocks.basal, 0, 2);
		world.setBlock(i, j + 16, k + 6, NovaCraftBlocks.basal, 0, 2);
		world.setBlock(i + 1, j + 16, k + 6, NovaCraftBlocks.basal, 0, 2);
		world.setBlock(i + 2, j + 16, k + 6, NovaCraftBlocks.basal, 0, 2);
		world.setBlock(i + 3, j + 16, k + 6, Blocks.air, 0, 2);
		world.setBlock(i + 4, j + 16, k + 6, Blocks.air, 0, 2);
		world.setBlock(i + 5, j + 16, k + 6, NovaCraftBlocks.glowing_basal, 0, 2);
		world.setBlock(i + 6, j + 16, k + 6, NovaCraftBlocks.basal, 0, 2);
		world.setBlock(i + 7, j + 16, k + 6, NovaCraftBlocks.basal, 0, 2);
		world.setBlock(i + 8, j + 16, k + 6, NovaCraftBlocks.basal, 0, 2);
		world.setBlock(i + 9, j + 16, k + 6, NovaCraftBlocks.basal, 0, 2);
		world.setBlock(i + 10, j + 16, k + 6, NovaCraftBlocks.basal, 0, 2);
		world.setBlock(i + 11, j + 16, k + 6, Blocks.air, 0, 2);
		world.setBlock(i + 12, j + 16, k + 6, Blocks.air, 0, 2);
		world.setBlock(i + 13, j + 16, k + 6, Blocks.air, 0, 2);
		world.setBlock(i + 14, j + 16, k + 6, NovaCraftBlocks.basal, 0, 2);
		world.setBlock(i + 15, j + 16, k + 6, NovaCraftBlocks.basal, 0, 2);
		world.setBlock(i + 16, j + 16, k + 6, NovaCraftBlocks.basal, 0, 2);
		world.setBlock(i + 17, j + 16, k + 6, NovaCraftBlocks.basal, 0, 2);
		world.setBlock(i + 18, j + 16, k + 6, NovaCraftBlocks.basal, 0, 2);
		world.setBlock(i + 19, j + 16, k + 6, NovaCraftBlocks.basal, 0, 2);
		world.setBlock(i + 20, j + 16, k + 6, NovaCraftBlocks.basal, 0, 2);
		world.setBlock(i + 21, j + 16, k + 6, NovaCraftBlocks.basal, 0, 2);
		world.setBlock(i + 22, j + 16, k + 6, NovaCraftBlocks.basal, 0, 2);
		world.setBlock(i + 23, j + 16, k + 6, NovaCraftBlocks.basal, 0, 2);
		world.setBlock(i + 24, j + 16, k + 6, NovaCraftBlocks.basal, 0, 2);
		world.setBlock(i + 25, j + 16, k + 6, NovaCraftBlocks.basal, 0, 2);
		world.setBlock(i + 26, j + 16, k + 6, NovaCraftBlocks.basal, 0, 2);
		world.setBlock(i + 27, j + 16, k + 6, Blocks.air, 0, 2);
		world.setBlock(i, j + 16, k + 7, NovaCraftBlocks.basal, 0, 2);
		world.setBlock(i + 1, j + 16, k + 7, NovaCraftBlocks.basal, 0, 2);
		world.setBlock(i + 2, j + 16, k + 7, Blocks.lava, 8, 2);
		world.setBlock(i + 3, j + 16, k + 7, Blocks.air, 0, 2);
		world.setBlock(i + 4, j + 16, k + 7, Blocks.air, 0, 2);
		world.setBlock(i + 5, j + 16, k + 7, NovaCraftBlocks.basal, 0, 2);
		world.setBlock(i + 6, j + 16, k + 7, NovaCraftBlocks.basal, 0, 2);
		world.setBlock(i + 7, j + 16, k + 7, Blocks.lava, 8, 2);
		world.setBlock(i + 8, j + 16, k + 7, NovaCraftBlocks.basal, 0, 2);
		world.setBlock(i + 9, j + 16, k + 7, NovaCraftBlocks.basal, 0, 2);
		world.setBlock(i + 10, j + 16, k + 7, NovaCraftBlocks.basal, 0, 2);
		world.setBlock(i + 11, j + 16, k + 7, NovaCraftBlocks.basal, 0, 2);
		world.setBlock(i + 12, j + 16, k + 7, NovaCraftBlocks.basal, 0, 2);
		world.setBlock(i + 13, j + 16, k + 7, Blocks.air, 0, 2);
		world.setBlock(i + 14, j + 16, k + 7, NovaCraftBlocks.basal, 0, 2);
		world.setBlock(i + 15, j + 16, k + 7, NovaCraftBlocks.basal, 0, 2);
		world.setBlock(i + 16, j + 16, k + 7, NovaCraftBlocks.basal, 0, 2);
		world.setBlock(i + 17, j + 16, k + 7, NovaCraftBlocks.basal, 0, 2);
		world.setBlock(i + 18, j + 16, k + 7, NovaCraftBlocks.basal, 0, 2);
		world.setBlock(i + 19, j + 16, k + 7, NovaCraftBlocks.basal, 0, 2);
		world.setBlock(i + 20, j + 16, k + 7, NovaCraftBlocks.basal, 0, 2);
		world.setBlock(i + 21, j + 16, k + 7, NovaCraftBlocks.basal, 0, 2);
		world.setBlock(i + 22, j + 16, k + 7, NovaCraftBlocks.basal, 0, 2);
		world.setBlock(i + 23, j + 16, k + 7, NovaCraftBlocks.basal, 0, 2);
		world.setBlock(i + 24, j + 16, k + 7, NovaCraftBlocks.basal, 0, 2);
		world.setBlock(i + 25, j + 16, k + 7, Blocks.air, 0, 2);
		world.setBlock(i + 26, j + 16, k + 7, Blocks.air, 0, 2);
		world.setBlock(i + 27, j + 16, k + 7, Blocks.air, 0, 2);
		world.setBlock(i, j + 16, k + 8, NovaCraftBlocks.basal, 0, 2);
		world.setBlock(i + 1, j + 16, k + 8, NovaCraftBlocks.basal, 0, 2);
		world.setBlock(i + 2, j + 16, k + 8, NovaCraftBlocks.basal, 0, 2);
		world.setBlock(i + 3, j + 16, k + 8, Blocks.air, 0, 2);
		world.setBlock(i + 4, j + 16, k + 8, Blocks.air, 0, 2);
		world.setBlock(i + 5, j + 16, k + 8, Blocks.air, 0, 2);
		world.setBlock(i + 6, j + 16, k + 8, NovaCraftBlocks.basal, 0, 2);
		world.setBlock(i + 7, j + 16, k + 8, NovaCraftBlocks.basal, 0, 2);
		world.setBlock(i + 8, j + 16, k + 8, NovaCraftBlocks.basal, 0, 2);
		world.setBlock(i + 9, j + 16, k + 8, NovaCraftBlocks.basal, 0, 2);
		world.setBlock(i + 10, j + 16, k + 8, NovaCraftBlocks.basal, 0, 2);
		world.setBlock(i + 11, j + 16, k + 8, NovaCraftBlocks.basal, 0, 2);
		world.setBlock(i + 12, j + 16, k + 8, NovaCraftBlocks.basal, 0, 2);
		world.setBlock(i + 13, j + 16, k + 8, NovaCraftBlocks.basal, 0, 2);
		world.setBlock(i + 14, j + 16, k + 8, NovaCraftBlocks.basal, 0, 2);
		world.setBlock(i + 15, j + 16, k + 8, NovaCraftBlocks.basal, 0, 2);
		world.setBlock(i + 16, j + 16, k + 8, NovaCraftBlocks.basal, 0, 2);
		world.setBlock(i + 17, j + 16, k + 8, Blocks.air, 0, 2);
		world.setBlock(i + 18, j + 16, k + 8, Blocks.air, 0, 2);
		world.setBlock(i + 19, j + 16, k + 8, NovaCraftBlocks.basal, 0, 2);
		world.setBlock(i + 20, j + 16, k + 8, NovaCraftBlocks.basal, 0, 2);
		world.setBlock(i + 21, j + 16, k + 8, NovaCraftBlocks.basal, 0, 2);
		world.setBlock(i + 22, j + 16, k + 8, NovaCraftBlocks.basal, 0, 2);
		world.setBlock(i + 23, j + 16, k + 8, NovaCraftBlocks.basal, 0, 2);
		world.setBlock(i + 24, j + 16, k + 8, NovaCraftBlocks.basal, 0, 2);
		world.setBlock(i + 25, j + 16, k + 8, Blocks.air, 0, 2);
		world.setBlock(i + 26, j + 16, k + 8, Blocks.air, 0, 2);
		world.setBlock(i + 27, j + 16, k + 8, Blocks.air, 0, 2);
		world.setBlock(i, j + 16, k + 9, NovaCraftBlocks.basal, 0, 2);
		world.setBlock(i + 1, j + 16, k + 9, NovaCraftBlocks.basal, 0, 2);
		world.setBlock(i + 2, j + 16, k + 9, NovaCraftBlocks.basal, 0, 2);
		world.setBlock(i + 3, j + 16, k + 9, Blocks.air, 0, 2);
		world.setBlock(i + 4, j + 16, k + 9, Blocks.air, 0, 2);
		world.setBlock(i + 5, j + 16, k + 9, NovaCraftBlocks.basal, 0, 2);
		world.setBlock(i + 6, j + 16, k + 9, NovaCraftBlocks.basal, 0, 2);
		world.setBlock(i + 7, j + 16, k + 9, NovaCraftBlocks.basal, 0, 2);
		world.setBlock(i + 8, j + 16, k + 9, NovaCraftBlocks.basal, 0, 2);
		world.setBlock(i + 9, j + 16, k + 9, NovaCraftBlocks.basal, 0, 2);
		world.setBlock(i + 10, j + 16, k + 9, NovaCraftBlocks.basal, 0, 2);
		world.setBlock(i + 11, j + 16, k + 9, NovaCraftBlocks.basal, 0, 2);
		world.setBlock(i + 12, j + 16, k + 9, NovaCraftBlocks.basal, 0, 2);
		world.setBlock(i + 13, j + 16, k + 9, NovaCraftBlocks.basal, 0, 2);
		world.setBlock(i + 14, j + 16, k + 9, NovaCraftBlocks.basal, 0, 2);
		world.setBlock(i + 15, j + 16, k + 9, NovaCraftBlocks.basal, 0, 2);
		world.setBlock(i + 16, j + 16, k + 9, Blocks.lava, 8, 2);
		world.setBlock(i + 17, j + 16, k + 9, Blocks.air, 0, 2);
		world.setBlock(i + 18, j + 16, k + 9, Blocks.air, 0, 2);
		world.setBlock(i + 19, j + 16, k + 9, NovaCraftBlocks.basal, 0, 2);
		world.setBlock(i + 20, j + 16, k + 9, NovaCraftBlocks.basal, 0, 2);
		world.setBlock(i + 21, j + 16, k + 9, Blocks.lava, 8, 2);
		world.setBlock(i + 22, j + 16, k + 9, NovaCraftBlocks.basal, 0, 2);
		world.setBlock(i + 23, j + 16, k + 9, NovaCraftBlocks.basal, 0, 2);
		world.setBlock(i + 24, j + 16, k + 9, NovaCraftBlocks.basal, 0, 2);
		world.setBlock(i + 25, j + 16, k + 9, NovaCraftBlocks.basal, 0, 2);
		world.setBlock(i + 26, j + 16, k + 9, NovaCraftBlocks.basal, 0, 2);
		world.setBlock(i + 27, j + 16, k + 9, Blocks.air, 0, 2);
		world.setBlock(i, j + 16, k + 10, NovaCraftBlocks.cracked_basal_bricks, 0, 2);
		world.setBlock(i + 1, j + 16, k + 10, NovaCraftBlocks.basal, 0, 2);
		world.setBlock(i + 2, j + 16, k + 10, NovaCraftBlocks.basal, 0, 2);
		world.setBlock(i + 3, j + 16, k + 10, NovaCraftBlocks.basal, 0, 2);
		world.setBlock(i + 4, j + 16, k + 10, NovaCraftBlocks.basal, 0, 2);
		world.setBlock(i + 5, j + 16, k + 10, NovaCraftBlocks.basal, 0, 2);
		world.setBlock(i + 6, j + 16, k + 10, NovaCraftBlocks.basal, 0, 2);
		world.setBlock(i + 7, j + 16, k + 10, NovaCraftBlocks.basal, 0, 2);
		world.setBlock(i + 8, j + 16, k + 10, NovaCraftBlocks.basal, 0, 2);
		world.setBlock(i + 9, j + 16, k + 10, NovaCraftBlocks.basal, 0, 2);
		world.setBlock(i + 10, j + 16, k + 10, NovaCraftBlocks.basal, 0, 2);
		world.setBlock(i + 11, j + 16, k + 10, NovaCraftBlocks.basal, 0, 2);
		world.setBlock(i + 12, j + 16, k + 10, NovaCraftBlocks.basal, 0, 2);
		world.setBlock(i + 13, j + 16, k + 10, NovaCraftBlocks.basal, 0, 2);
		world.setBlock(i + 14, j + 16, k + 10, NovaCraftBlocks.basal, 0, 2);
		world.setBlock(i + 15, j + 16, k + 10, NovaCraftBlocks.basal, 0, 2);
		world.setBlock(i + 16, j + 16, k + 10, NovaCraftBlocks.basal, 0, 2);
		world.setBlock(i + 17, j + 16, k + 10, Blocks.air, 0, 2);
		world.setBlock(i + 18, j + 16, k + 10, Blocks.air, 0, 2);
		world.setBlock(i + 19, j + 16, k + 10, Blocks.air, 0, 2);
		world.setBlock(i + 20, j + 16, k + 10, NovaCraftBlocks.basal, 0, 2);
		world.setBlock(i + 21, j + 16, k + 10, NovaCraftBlocks.basal, 0, 2);
		world.setBlock(i + 22, j + 16, k + 10, NovaCraftBlocks.basal, 0, 2);
		world.setBlock(i + 23, j + 16, k + 10, NovaCraftBlocks.basal, 0, 2);
		world.setBlock(i + 24, j + 16, k + 10, NovaCraftBlocks.basal, 0, 2);
		world.setBlock(i + 25, j + 16, k + 10, NovaCraftBlocks.basal, 0, 2);
		world.setBlock(i + 26, j + 16, k + 10, NovaCraftBlocks.basal, 0, 2);
		world.setBlock(i + 27, j + 16, k + 10, NovaCraftBlocks.basal, 0, 2);
		world.setBlock(i, j + 16, k + 11, NovaCraftBlocks.basal_bricks, 0, 2);
		world.setBlock(i + 1, j + 16, k + 11, NovaCraftBlocks.basal_bricks, 0, 2);
		world.setBlock(i + 2, j + 16, k + 11, NovaCraftBlocks.basal_bricks, 0, 2);
		world.setBlock(i + 3, j + 16, k + 11, NovaCraftBlocks.basal_bricks, 0, 2);
		world.setBlock(i + 4, j + 16, k + 11, NovaCraftBlocks.cracked_basal_bricks, 0, 2);
		world.setBlock(i + 5, j + 16, k + 11, NovaCraftBlocks.basal_bricks, 0, 2);
		world.setBlock(i + 6, j + 16, k + 11, NovaCraftBlocks.basal_bricks, 0, 2);
		world.setBlock(i + 7, j + 16, k + 11, NovaCraftBlocks.cracked_basal_bricks, 0, 2);
		world.setBlock(i + 8, j + 16, k + 11, NovaCraftBlocks.basal_bricks, 0, 2);
		world.setBlock(i + 9, j + 16, k + 11, NovaCraftBlocks.cracked_basal_bricks, 0, 2);
		world.setBlock(i + 10, j + 16, k + 11, NovaCraftBlocks.basal_bricks, 0, 2);
		world.setBlock(i + 11, j + 16, k + 11, NovaCraftBlocks.cracked_basal_bricks, 0, 2);
		world.setBlock(i + 12, j + 16, k + 11, NovaCraftBlocks.basal_bricks, 0, 2);
		world.setBlock(i + 13, j + 16, k + 11, NovaCraftBlocks.cracked_basal_bricks, 0, 2);
		world.setBlock(i + 14, j + 16, k + 11, NovaCraftBlocks.basal, 0, 2);
		world.setBlock(i + 15, j + 16, k + 11, NovaCraftBlocks.basal, 0, 2);
		world.setBlock(i + 16, j + 16, k + 11, NovaCraftBlocks.basal, 0, 2);
		world.setBlock(i + 17, j + 16, k + 11, Blocks.air, 0, 2);
		world.setBlock(i + 18, j + 16, k + 11, Blocks.air, 0, 2);
		world.setBlock(i + 19, j + 16, k + 11, NovaCraftBlocks.basal, 0, 2);
		world.setBlock(i + 20, j + 16, k + 11, NovaCraftBlocks.basal, 0, 2);
		world.setBlock(i + 21, j + 16, k + 11, NovaCraftBlocks.basal, 0, 2);
		world.setBlock(i + 22, j + 16, k + 11, NovaCraftBlocks.basal, 0, 2);
		world.setBlock(i + 23, j + 16, k + 11, NovaCraftBlocks.basal, 0, 2);
		world.setBlock(i + 24, j + 16, k + 11, NovaCraftBlocks.basal, 0, 2);
		world.setBlock(i + 25, j + 16, k + 11, NovaCraftBlocks.basal, 0, 2);
		world.setBlock(i + 26, j + 16, k + 11, NovaCraftBlocks.basal, 0, 2);
		world.setBlock(i + 27, j + 16, k + 11, NovaCraftBlocks.basal, 0, 2);
		world.setBlock(i, j + 16, k + 12, NovaCraftBlocks.cracked_basal_bricks, 0, 2);
		world.setBlock(i + 1, j + 16, k + 12, NovaCraftBlocks.cracked_basal_bricks, 0, 2);
		world.setBlock(i + 2, j + 16, k + 12, NovaCraftBlocks.basal_bricks, 0, 2);
		world.setBlock(i + 3, j + 16, k + 12, NovaCraftBlocks.basal_bricks, 0, 2);
		world.setBlock(i + 4, j + 16, k + 12, NovaCraftBlocks.cracked_basal_bricks, 0, 2);
		world.setBlock(i + 5, j + 16, k + 12, NovaCraftBlocks.basal_bricks, 0, 2);
		world.setBlock(i + 6, j + 16, k + 12, NovaCraftBlocks.cracked_basal_bricks, 0, 2);
		world.setBlock(i + 7, j + 16, k + 12, NovaCraftBlocks.cracked_basal_bricks, 0, 2);
		world.setBlock(i + 8, j + 16, k + 12, NovaCraftBlocks.cracked_basal_bricks, 0, 2);
		world.setBlock(i + 9, j + 16, k + 12, NovaCraftBlocks.basal_bricks, 0, 2);
		world.setBlock(i + 10, j + 16, k + 12, NovaCraftBlocks.basal_bricks, 0, 2);
		world.setBlock(i + 11, j + 16, k + 12, NovaCraftBlocks.cracked_basal_bricks, 0, 2);
		world.setBlock(i + 12, j + 16, k + 12, NovaCraftBlocks.basal_bricks, 0, 2);
		world.setBlock(i + 13, j + 16, k + 12, NovaCraftBlocks.cracked_basal_bricks, 0, 2);
		world.setBlock(i + 14, j + 16, k + 12, NovaCraftBlocks.cracked_basal_bricks, 0, 2);
		world.setBlock(i + 15, j + 16, k + 12, NovaCraftBlocks.basal, 0, 2);
		world.setBlock(i + 16, j + 16, k + 12, NovaCraftBlocks.basal, 0, 2);
		world.setBlock(i + 17, j + 16, k + 12, NovaCraftBlocks.basal, 0, 2);
		world.setBlock(i + 18, j + 16, k + 12, NovaCraftBlocks.basal, 0, 2);
		world.setBlock(i + 19, j + 16, k + 12, NovaCraftBlocks.basal, 0, 2);
		world.setBlock(i + 20, j + 16, k + 12, NovaCraftBlocks.basal, 0, 2);
		world.setBlock(i + 21, j + 16, k + 12, NovaCraftBlocks.basal, 0, 2);
		world.setBlock(i + 22, j + 16, k + 12, NovaCraftBlocks.basal, 0, 2);
		world.setBlock(i + 23, j + 16, k + 12, NovaCraftBlocks.basal, 0, 2);
		world.setBlock(i + 24, j + 16, k + 12, NovaCraftBlocks.basal, 0, 2);
		world.setBlock(i + 25, j + 16, k + 12, NovaCraftBlocks.basal, 0, 2);
		world.setBlock(i + 26, j + 16, k + 12, NovaCraftBlocks.basal, 0, 2);
		world.setBlock(i + 27, j + 16, k + 12, NovaCraftBlocks.basal, 0, 2);
		world.setBlock(i, j + 17, k + 1, NovaCraftBlocks.basal, 0, 2);
		world.setBlock(i + 1, j + 17, k + 1, NovaCraftBlocks.basal, 0, 2);
		world.setBlock(i + 4, j + 17, k + 1, NovaCraftBlocks.basal, 0, 2);
		world.setBlock(i + 5, j + 17, k + 1, NovaCraftBlocks.basal, 0, 2);
		world.setBlock(i + 8, j + 17, k + 1, NovaCraftBlocks.basal, 0, 2);
		world.setBlock(i + 9, j + 17, k + 1, NovaCraftBlocks.basal, 0, 2);
		world.setBlock(i + 12, j + 17, k + 1, NovaCraftBlocks.basal, 0, 2);
		world.setBlock(i + 13, j + 17, k + 1, NovaCraftBlocks.basal, 0, 2);
		world.setBlock(i, j + 17, k + 2, NovaCraftBlocks.basal, 0, 2);
		world.setBlock(i + 1, j + 17, k + 2, NovaCraftBlocks.basal, 0, 2);
		world.setBlock(i + 2, j + 17, k + 2, NovaCraftBlocks.basal, 0, 2);
		world.setBlock(i + 3, j + 17, k + 2, NovaCraftBlocks.basal, 0, 2);
		world.setBlock(i + 4, j + 17, k + 2, NovaCraftBlocks.basal, 0, 2);
		world.setBlock(i + 5, j + 17, k + 2, NovaCraftBlocks.basal, 0, 2);
		world.setBlock(i + 6, j + 17, k + 2, NovaCraftBlocks.basal, 0, 2);
		world.setBlock(i + 7, j + 17, k + 2, NovaCraftBlocks.cracked_basal_bricks, 0, 2);
		world.setBlock(i + 8, j + 17, k + 2, NovaCraftBlocks.cracked_basal_bricks, 0, 2);
		world.setBlock(i + 9, j + 17, k + 2, NovaCraftBlocks.basal, 0, 2);
		world.setBlock(i + 10, j + 17, k + 2, NovaCraftBlocks.basal, 0, 2);
		world.setBlock(i + 11, j + 17, k + 2, NovaCraftBlocks.basal, 0, 2);
		world.setBlock(i + 12, j + 17, k + 2, NovaCraftBlocks.basal, 0, 2);
		world.setBlock(i + 13, j + 17, k + 2, NovaCraftBlocks.basal, 0, 2);
		world.setBlock(i, j + 17, k + 3, NovaCraftBlocks.basal, 0, 2);
		world.setBlock(i + 1, j + 17, k + 3, NovaCraftBlocks.basal, 0, 2);
		world.setBlock(i + 2, j + 17, k + 3, NovaCraftBlocks.basal, 0, 2);
		world.setBlock(i + 3, j + 17, k + 3, NovaCraftBlocks.basal, 0, 2);
		world.setBlock(i + 4, j + 17, k + 3, NovaCraftBlocks.basal, 0, 2);
		world.setBlock(i + 5, j + 17, k + 3, NovaCraftBlocks.basal, 0, 2);
		world.setBlock(i + 6, j + 17, k + 3, NovaCraftBlocks.basal, 0, 2);
		world.setBlock(i + 7, j + 17, k + 3, NovaCraftBlocks.basal, 0, 2);
		world.setBlock(i + 8, j + 17, k + 3, NovaCraftBlocks.basal, 0, 2);
		world.setBlock(i + 9, j + 17, k + 3, NovaCraftBlocks.basal, 0, 2);
		world.setBlock(i + 10, j + 17, k + 3, NovaCraftBlocks.basal, 0, 2);
		world.setBlock(i + 11, j + 17, k + 3, NovaCraftBlocks.basal, 0, 2);
		world.setBlock(i + 12, j + 17, k + 3, NovaCraftBlocks.basal, 0, 2);
		world.setBlock(i + 14, j + 17, k + 3, NovaCraftBlocks.basal, 0, 2);
		world.setBlock(i + 15, j + 17, k + 3, NovaCraftBlocks.basal, 0, 2);
		world.setBlock(i + 18, j + 17, k + 3, NovaCraftBlocks.basal, 0, 2);
		world.setBlock(i + 19, j + 17, k + 3, NovaCraftBlocks.basal, 0, 2);
		world.setBlock(i + 22, j + 17, k + 3, NovaCraftBlocks.basal, 0, 2);
		world.setBlock(i + 23, j + 17, k + 3, NovaCraftBlocks.basal, 0, 2);
		world.setBlock(i + 26, j + 17, k + 3, NovaCraftBlocks.basal, 0, 2);
		world.setBlock(i + 27, j + 17, k + 3, NovaCraftBlocks.basal, 0, 2);
		world.setBlock(i, j + 17, k + 4, NovaCraftBlocks.basal, 0, 2);
		world.setBlock(i + 1, j + 17, k + 4, NovaCraftBlocks.basal, 0, 2);
		world.setBlock(i + 2, j + 17, k + 4, NovaCraftBlocks.basal, 0, 2);
		world.setBlock(i + 3, j + 17, k + 4, NovaCraftBlocks.basal, 0, 2);
		world.setBlock(i + 4, j + 17, k + 4, NovaCraftBlocks.basal, 0, 2);
		world.setBlock(i + 5, j + 17, k + 4, NovaCraftBlocks.basal, 0, 2);
		world.setBlock(i + 6, j + 17, k + 4, NovaCraftBlocks.basal, 0, 2);
		world.setBlock(i + 7, j + 17, k + 4, NovaCraftBlocks.basal, 0, 2);
		world.setBlock(i + 8, j + 17, k + 4, NovaCraftBlocks.basal, 0, 2);
		world.setBlock(i + 9, j + 17, k + 4, NovaCraftBlocks.basal, 0, 2);
		world.setBlock(i + 10, j + 17, k + 4, NovaCraftBlocks.basal, 0, 2);
		world.setBlock(i + 11, j + 17, k + 4, NovaCraftBlocks.basal, 0, 2);
		world.setBlock(i + 12, j + 17, k + 4, Blocks.air, 0, 2);
		world.setBlock(i + 13, j + 17, k + 4, Blocks.air, 0, 2);
		world.setBlock(i + 14, j + 17, k + 4, NovaCraftBlocks.basal, 0, 2);
		world.setBlock(i + 15, j + 17, k + 4, NovaCraftBlocks.basal, 0, 2);
		world.setBlock(i + 16, j + 17, k + 4, NovaCraftBlocks.basal, 0, 2);
		world.setBlock(i + 17, j + 17, k + 4, NovaCraftBlocks.basal, 0, 2);
		world.setBlock(i + 18, j + 17, k + 4, NovaCraftBlocks.basal, 0, 2);
		world.setBlock(i + 19, j + 17, k + 4, NovaCraftBlocks.basal, 0, 2);
		world.setBlock(i + 20, j + 17, k + 4, NovaCraftBlocks.basal, 0, 2);
		world.setBlock(i + 21, j + 17, k + 4, NovaCraftBlocks.cracked_basal_bricks, 0, 2);
		world.setBlock(i + 22, j + 17, k + 4, NovaCraftBlocks.cracked_basal_bricks, 0, 2);
		world.setBlock(i + 23, j + 17, k + 4, NovaCraftBlocks.basal, 0, 2);
		world.setBlock(i + 24, j + 17, k + 4, NovaCraftBlocks.basal, 0, 2);
		world.setBlock(i + 25, j + 17, k + 4, NovaCraftBlocks.basal, 0, 2);
		world.setBlock(i + 26, j + 17, k + 4, NovaCraftBlocks.basal, 0, 2);
		world.setBlock(i + 27, j + 17, k + 4, NovaCraftBlocks.basal, 0, 2);
		world.setBlock(i, j + 17, k + 5, NovaCraftBlocks.basal, 0, 2);
		world.setBlock(i + 1, j + 17, k + 5, NovaCraftBlocks.basal, 0, 2);
		world.setBlock(i + 2, j + 17, k + 5, NovaCraftBlocks.basal, 0, 2);
		world.setBlock(i + 3, j + 17, k + 5, NovaCraftBlocks.basal, 0, 2);
		world.setBlock(i + 4, j + 17, k + 5, NovaCraftBlocks.basal, 0, 2);
		world.setBlock(i + 5, j + 17, k + 5, NovaCraftBlocks.basal, 0, 2);
		world.setBlock(i + 6, j + 17, k + 5, NovaCraftBlocks.basal, 0, 2);
		world.setBlock(i + 7, j + 17, k + 5, NovaCraftBlocks.basal, 0, 2);
		world.setBlock(i + 8, j + 17, k + 5, NovaCraftBlocks.basal, 0, 2);
		world.setBlock(i + 9, j + 17, k + 5, NovaCraftBlocks.basal, 0, 2);
		world.setBlock(i + 10, j + 17, k + 5, NovaCraftBlocks.basal, 0, 2);
		world.setBlock(i + 11, j + 17, k + 5, Blocks.air, 0, 2);
		world.setBlock(i + 12, j + 17, k + 5, Blocks.air, 0, 2);
		world.setBlock(i + 13, j + 17, k + 5, Blocks.air, 0, 2);
		world.setBlock(i + 14, j + 17, k + 5, NovaCraftBlocks.basal, 0, 2);
		world.setBlock(i + 15, j + 17, k + 5, NovaCraftBlocks.basal, 0, 2);
		world.setBlock(i + 16, j + 17, k + 5, NovaCraftBlocks.basal, 0, 2);
		world.setBlock(i + 17, j + 17, k + 5, NovaCraftBlocks.basal, 0, 2);
		world.setBlock(i + 18, j + 17, k + 5, NovaCraftBlocks.basal, 0, 2);
		world.setBlock(i + 19, j + 17, k + 5, NovaCraftBlocks.basal, 0, 2);
		world.setBlock(i + 20, j + 17, k + 5, NovaCraftBlocks.basal, 0, 2);
		world.setBlock(i + 21, j + 17, k + 5, NovaCraftBlocks.glowing_basal, 0, 2);
		world.setBlock(i + 22, j + 17, k + 5, NovaCraftBlocks.basal, 0, 2);
		world.setBlock(i + 23, j + 17, k + 5, NovaCraftBlocks.basal, 0, 2);
		world.setBlock(i + 24, j + 17, k + 5, NovaCraftBlocks.basal, 0, 2);
		world.setBlock(i + 25, j + 17, k + 5, NovaCraftBlocks.basal, 0, 2);
		world.setBlock(i + 26, j + 17, k + 5, NovaCraftBlocks.basal, 0, 2);
		world.setBlock(i + 27, j + 17, k + 5, Blocks.air, 0, 2);
		world.setBlock(i, j + 17, k + 6, NovaCraftBlocks.basal, 0, 2);
		world.setBlock(i + 1, j + 17, k + 6, NovaCraftBlocks.basal, 0, 2);
		world.setBlock(i + 2, j + 17, k + 6, NovaCraftBlocks.basal, 0, 2);
		world.setBlock(i + 3, j + 17, k + 6, NovaCraftBlocks.basal, 0, 2);
		world.setBlock(i + 4, j + 17, k + 6, NovaCraftBlocks.basal, 0, 2);
		world.setBlock(i + 5, j + 17, k + 6, NovaCraftBlocks.basal, 0, 2);
		world.setBlock(i + 6, j + 17, k + 6, NovaCraftBlocks.basal, 0, 2);
		world.setBlock(i + 7, j + 17, k + 6, NovaCraftBlocks.basal, 0, 2);
		world.setBlock(i + 8, j + 17, k + 6, NovaCraftBlocks.basal, 0, 2);
		world.setBlock(i + 9, j + 17, k + 6, NovaCraftBlocks.basal, 0, 2);
		world.setBlock(i + 10, j + 17, k + 6, NovaCraftBlocks.basal, 0, 2);
		world.setBlock(i + 11, j + 17, k + 6, Blocks.air, 0, 2);
		world.setBlock(i + 12, j + 17, k + 6, Blocks.air, 0, 2);
		world.setBlock(i + 13, j + 17, k + 6, Blocks.air, 0, 2);
		world.setBlock(i + 14, j + 17, k + 6, NovaCraftBlocks.basal, 0, 2);
		world.setBlock(i + 15, j + 17, k + 6, NovaCraftBlocks.basal, 0, 2);
		world.setBlock(i + 16, j + 17, k + 6, NovaCraftBlocks.glowing_basal, 0, 2);
		world.setBlock(i + 17, j + 17, k + 6, NovaCraftBlocks.basal, 0, 2);
		world.setBlock(i + 18, j + 17, k + 6, NovaCraftBlocks.basal, 0, 2);
		world.setBlock(i + 19, j + 17, k + 6, NovaCraftBlocks.basal, 0, 2);
		world.setBlock(i + 20, j + 17, k + 6, NovaCraftBlocks.basal, 0, 2);
		world.setBlock(i + 21, j + 17, k + 6, NovaCraftBlocks.basal, 0, 2);
		world.setBlock(i + 22, j + 17, k + 6, NovaCraftBlocks.basal, 0, 2);
		world.setBlock(i + 23, j + 17, k + 6, NovaCraftBlocks.basal, 0, 2);
		world.setBlock(i + 24, j + 17, k + 6, NovaCraftBlocks.basal, 0, 2);
		world.setBlock(i + 25, j + 17, k + 6, NovaCraftBlocks.basal, 0, 2);
		world.setBlock(i + 26, j + 17, k + 6, Blocks.air, 0, 2);
		world.setBlock(i + 27, j + 17, k + 6, Blocks.air, 0, 2);
		world.setBlock(i, j + 17, k + 7, NovaCraftBlocks.basal, 0, 2);
		world.setBlock(i + 1, j + 17, k + 7, NovaCraftBlocks.basal, 0, 2);
		world.setBlock(i + 2, j + 17, k + 7, Blocks.lava, 0, 2);
		world.setBlock(i + 3, j + 17, k + 7, NovaCraftBlocks.basal, 0, 2);
		world.setBlock(i + 4, j + 17, k + 7, NovaCraftBlocks.basal, 0, 2);
		world.setBlock(i + 5, j + 17, k + 7, NovaCraftBlocks.basal, 0, 2);
		world.setBlock(i + 6, j + 17, k + 7, NovaCraftBlocks.basal, 0, 2);
		world.setBlock(i + 7, j + 17, k + 7, Blocks.lava, 8, 2);
		world.setBlock(i + 8, j + 17, k + 7, NovaCraftBlocks.basal, 0, 2);
		world.setBlock(i + 9, j + 17, k + 7, NovaCraftBlocks.basal, 0, 2);
		world.setBlock(i + 10, j + 17, k + 7, NovaCraftBlocks.basal, 0, 2);
		world.setBlock(i + 11, j + 17, k + 7, NovaCraftBlocks.basal, 0, 2);
		world.setBlock(i + 12, j + 17, k + 7, NovaCraftBlocks.basal, 0, 2);
		world.setBlock(i + 13, j + 17, k + 7, Blocks.air, 0, 2);
		world.setBlock(i + 14, j + 17, k + 7, NovaCraftBlocks.basal, 0, 2);
		world.setBlock(i + 15, j + 17, k + 7, NovaCraftBlocks.basal, 0, 2);
		world.setBlock(i + 16, j + 17, k + 7, NovaCraftBlocks.basal, 0, 2);
		world.setBlock(i + 17, j + 17, k + 7, NovaCraftBlocks.basal, 0, 2);
		world.setBlock(i + 18, j + 17, k + 7, NovaCraftBlocks.basal, 0, 2);
		world.setBlock(i + 19, j + 17, k + 7, NovaCraftBlocks.basal, 0, 2);
		world.setBlock(i + 20, j + 17, k + 7, NovaCraftBlocks.basal, 0, 2);
		world.setBlock(i + 21, j + 17, k + 7, NovaCraftBlocks.basal, 0, 2);
		world.setBlock(i + 22, j + 17, k + 7, NovaCraftBlocks.basal, 0, 2);
		world.setBlock(i + 23, j + 17, k + 7, NovaCraftBlocks.basal, 0, 2);
		world.setBlock(i + 24, j + 17, k + 7, NovaCraftBlocks.basal, 0, 2);
		world.setBlock(i + 25, j + 17, k + 7, Blocks.air, 0, 2);
		world.setBlock(i + 26, j + 17, k + 7, Blocks.air, 0, 2);
		world.setBlock(i + 27, j + 17, k + 7, Blocks.air, 0, 2);
		world.setBlock(i, j + 17, k + 8, NovaCraftBlocks.basal, 0, 2);
		world.setBlock(i + 1, j + 17, k + 8, NovaCraftBlocks.basal, 0, 2);
		world.setBlock(i + 2, j + 17, k + 8, NovaCraftBlocks.basal, 0, 2);
		world.setBlock(i + 3, j + 17, k + 8, Blocks.air, 0, 2);
		world.setBlock(i + 4, j + 17, k + 8, Blocks.air, 0, 2);
		world.setBlock(i + 5, j + 17, k + 8, Blocks.air, 0, 2);
		world.setBlock(i + 6, j + 17, k + 8, Blocks.air, 0, 2);
		world.setBlock(i + 7, j + 17, k + 8, NovaCraftBlocks.basal, 0, 2);
		world.setBlock(i + 8, j + 17, k + 8, NovaCraftBlocks.basal, 0, 2);
		world.setBlock(i + 9, j + 17, k + 8, NovaCraftBlocks.basal, 0, 2);
		world.setBlock(i + 10, j + 17, k + 8, NovaCraftBlocks.basal, 0, 2);
		world.setBlock(i + 11, j + 17, k + 8, NovaCraftBlocks.basal, 0, 2);
		world.setBlock(i + 12, j + 17, k + 8, NovaCraftBlocks.basal, 0, 2);
		world.setBlock(i + 13, j + 17, k + 8, NovaCraftBlocks.basal, 0, 2);
		world.setBlock(i + 14, j + 17, k + 8, NovaCraftBlocks.basal, 0, 2);
		world.setBlock(i + 15, j + 17, k + 8, NovaCraftBlocks.basal, 0, 2);
		world.setBlock(i + 16, j + 17, k + 8, NovaCraftBlocks.basal, 0, 2);
		world.setBlock(i + 17, j + 17, k + 8, NovaCraftBlocks.basal, 0, 2);
		world.setBlock(i + 18, j + 17, k + 8, NovaCraftBlocks.basal, 0, 2);
		world.setBlock(i + 19, j + 17, k + 8, NovaCraftBlocks.basal, 0, 2);
		world.setBlock(i + 20, j + 17, k + 8, NovaCraftBlocks.glowing_basal, 0, 2);
		world.setBlock(i + 21, j + 17, k + 8, NovaCraftBlocks.basal, 0, 2);
		world.setBlock(i + 22, j + 17, k + 8, NovaCraftBlocks.basal, 0, 2);
		world.setBlock(i + 23, j + 17, k + 8, NovaCraftBlocks.basal, 0, 2);
		world.setBlock(i + 24, j + 17, k + 8, NovaCraftBlocks.basal, 0, 2);
		world.setBlock(i + 25, j + 17, k + 8, Blocks.air, 0, 2);
		world.setBlock(i + 26, j + 17, k + 8, Blocks.air, 0, 2);
		world.setBlock(i + 27, j + 17, k + 8, Blocks.air, 0, 2);
		world.setBlock(i, j + 17, k + 9, NovaCraftBlocks.basal, 0, 2);
		world.setBlock(i + 1, j + 17, k + 9, NovaCraftBlocks.basal, 0, 2);
		world.setBlock(i + 2, j + 17, k + 9, NovaCraftBlocks.basal, 0, 2);
		world.setBlock(i + 3, j + 17, k + 9, Blocks.air, 0, 2);
		world.setBlock(i + 4, j + 17, k + 9, Blocks.air, 0, 2);
		world.setBlock(i + 5, j + 17, k + 9, Blocks.air, 0, 2);
		world.setBlock(i + 6, j + 17, k + 9, Blocks.air, 0, 2);
		world.setBlock(i + 7, j + 17, k + 9, NovaCraftBlocks.basal, 0, 2);
		world.setBlock(i + 8, j + 17, k + 9, NovaCraftBlocks.basal, 0, 2);
		world.setBlock(i + 9, j + 17, k + 9, NovaCraftBlocks.basal, 0, 2);
		world.setBlock(i + 10, j + 17, k + 9, NovaCraftBlocks.basal, 0, 2);
		world.setBlock(i + 11, j + 17, k + 9, NovaCraftBlocks.basal, 0, 2);
		world.setBlock(i + 12, j + 17, k + 9, NovaCraftBlocks.basal, 0, 2);
		world.setBlock(i + 13, j + 17, k + 9, NovaCraftBlocks.basal, 0, 2);
		world.setBlock(i + 14, j + 17, k + 9, NovaCraftBlocks.basal, 0, 2);
		world.setBlock(i + 15, j + 17, k + 9, NovaCraftBlocks.basal, 0, 2);
		world.setBlock(i + 16, j + 17, k + 9, Blocks.lava, 0, 2);
		world.setBlock(i + 17, j + 17, k + 9, NovaCraftBlocks.basal, 0, 2);
		world.setBlock(i + 18, j + 17, k + 9, NovaCraftBlocks.basal, 0, 2);
		world.setBlock(i + 19, j + 17, k + 9, NovaCraftBlocks.basal, 0, 2);
		world.setBlock(i + 20, j + 17, k + 9, NovaCraftBlocks.basal, 0, 2);
		world.setBlock(i + 21, j + 17, k + 9, Blocks.lava, 8, 2);
		world.setBlock(i + 22, j + 17, k + 9, NovaCraftBlocks.basal, 0, 2);
		world.setBlock(i + 23, j + 17, k + 9, NovaCraftBlocks.basal, 0, 2);
		world.setBlock(i + 24, j + 17, k + 9, NovaCraftBlocks.basal, 0, 2);
		world.setBlock(i + 25, j + 17, k + 9, NovaCraftBlocks.basal, 0, 2);
		world.setBlock(i + 26, j + 17, k + 9, NovaCraftBlocks.basal, 0, 2);
		world.setBlock(i + 27, j + 17, k + 9, Blocks.air, 0, 2);
		world.setBlock(i, j + 17, k + 10, NovaCraftBlocks.basal, 0, 2);
		world.setBlock(i + 1, j + 17, k + 10, NovaCraftBlocks.basal, 0, 2);
		world.setBlock(i + 2, j + 17, k + 10, NovaCraftBlocks.basal, 0, 2);
		world.setBlock(i + 3, j + 17, k + 10, NovaCraftBlocks.basal, 0, 2);
		world.setBlock(i + 4, j + 17, k + 10, NovaCraftBlocks.basal, 0, 2);
		world.setBlock(i + 5, j + 17, k + 10, NovaCraftBlocks.basal, 0, 2);
		world.setBlock(i + 6, j + 17, k + 10, NovaCraftBlocks.basal, 0, 2);
		world.setBlock(i + 7, j + 17, k + 10, NovaCraftBlocks.basal, 0, 2);
		world.setBlock(i + 8, j + 17, k + 10, NovaCraftBlocks.basal, 0, 2);
		world.setBlock(i + 9, j + 17, k + 10, NovaCraftBlocks.basal, 0, 2);
		world.setBlock(i + 10, j + 17, k + 10, NovaCraftBlocks.basal, 0, 2);
		world.setBlock(i + 11, j + 17, k + 10, NovaCraftBlocks.basal, 0, 2);
		world.setBlock(i + 12, j + 17, k + 10, NovaCraftBlocks.basal, 0, 2);
		world.setBlock(i + 13, j + 17, k + 10, NovaCraftBlocks.basal, 0, 2);
		world.setBlock(i + 14, j + 17, k + 10, NovaCraftBlocks.basal, 0, 2);
		world.setBlock(i + 15, j + 17, k + 10, NovaCraftBlocks.basal, 0, 2);
		world.setBlock(i + 16, j + 17, k + 10, NovaCraftBlocks.basal, 0, 2);
		world.setBlock(i + 17, j + 17, k + 10, Blocks.air, 0, 2);
		world.setBlock(i + 18, j + 17, k + 10, Blocks.air, 0, 2);
		world.setBlock(i + 19, j + 17, k + 10, Blocks.air, 0, 2);
		world.setBlock(i + 20, j + 17, k + 10, Blocks.air, 0, 2);
		world.setBlock(i + 21, j + 17, k + 10, NovaCraftBlocks.basal, 0, 2);
		world.setBlock(i + 22, j + 17, k + 10, NovaCraftBlocks.basal, 0, 2);
		world.setBlock(i + 23, j + 17, k + 10, NovaCraftBlocks.basal, 0, 2);
		world.setBlock(i + 24, j + 17, k + 10, NovaCraftBlocks.basal, 0, 2);
		world.setBlock(i + 25, j + 17, k + 10, NovaCraftBlocks.basal, 0, 2);
		world.setBlock(i + 26, j + 17, k + 10, NovaCraftBlocks.basal, 0, 2);
		world.setBlock(i + 27, j + 17, k + 10, NovaCraftBlocks.basal, 0, 2);
		world.setBlock(i, j + 17, k + 11, NovaCraftBlocks.cracked_basal_bricks, 0, 2);
		world.setBlock(i + 1, j + 17, k + 11, NovaCraftBlocks.basal_bricks, 0, 2);
		world.setBlock(i + 2, j + 17, k + 11, NovaCraftBlocks.basal_bricks, 0, 2);
		world.setBlock(i + 3, j + 17, k + 11, NovaCraftBlocks.basal_bricks, 0, 2);
		world.setBlock(i + 4, j + 17, k + 11, NovaCraftBlocks.basal_bricks, 0, 2);
		world.setBlock(i + 5, j + 17, k + 11, NovaCraftBlocks.cracked_basal_bricks, 0, 2);
		world.setBlock(i + 6, j + 17, k + 11, NovaCraftBlocks.cracked_basal_bricks, 0, 2);
		world.setBlock(i + 7, j + 17, k + 11, NovaCraftBlocks.cracked_basal_bricks, 0, 2);
		world.setBlock(i + 8, j + 17, k + 11, NovaCraftBlocks.cracked_basal_bricks, 0, 2);
		world.setBlock(i + 9, j + 17, k + 11, NovaCraftBlocks.basal_bricks, 0, 2);
		world.setBlock(i + 10, j + 17, k + 11, NovaCraftBlocks.basal_bricks, 0, 2);
		world.setBlock(i + 11, j + 17, k + 11, NovaCraftBlocks.basal_bricks, 0, 2);
		world.setBlock(i + 12, j + 17, k + 11, NovaCraftBlocks.cracked_basal_bricks, 0, 2);
		world.setBlock(i + 13, j + 17, k + 11, NovaCraftBlocks.basal_bricks, 0, 2);
		world.setBlock(i + 14, j + 17, k + 11, NovaCraftBlocks.basal, 0, 2);
		world.setBlock(i + 15, j + 17, k + 11, NovaCraftBlocks.basal, 0, 2);
		world.setBlock(i + 16, j + 17, k + 11, NovaCraftBlocks.basal, 0, 2);
		world.setBlock(i + 17, j + 17, k + 11, Blocks.air, 0, 2);
		world.setBlock(i + 18, j + 17, k + 11, Blocks.air, 0, 2);
		world.setBlock(i + 19, j + 17, k + 11, Blocks.air, 0, 2);
		world.setBlock(i + 20, j + 17, k + 11, Blocks.air, 0, 2);
		world.setBlock(i + 21, j + 17, k + 11, NovaCraftBlocks.basal, 0, 2);
		world.setBlock(i + 22, j + 17, k + 11, NovaCraftBlocks.basal, 0, 2);
		world.setBlock(i + 23, j + 17, k + 11, NovaCraftBlocks.basal, 0, 2);
		world.setBlock(i + 24, j + 17, k + 11, NovaCraftBlocks.basal, 0, 2);
		world.setBlock(i + 25, j + 17, k + 11, NovaCraftBlocks.basal, 0, 2);
		world.setBlock(i + 26, j + 17, k + 11, NovaCraftBlocks.basal, 0, 2);
		world.setBlock(i + 27, j + 17, k + 11, NovaCraftBlocks.basal, 0, 2);
		world.setBlock(i, j + 17, k + 12, NovaCraftBlocks.cracked_basal_bricks, 0, 2);
		world.setBlock(i + 1, j + 17, k + 12, NovaCraftBlocks.basal_bricks, 0, 2);
		world.setBlock(i + 2, j + 17, k + 12, NovaCraftBlocks.basal_bricks, 0, 2);
		world.setBlock(i + 3, j + 17, k + 12, NovaCraftBlocks.cracked_basal_bricks, 0, 2);
		world.setBlock(i + 4, j + 17, k + 12, NovaCraftBlocks.cracked_basal_bricks, 0, 2);
