package com.NovaCraft.world.bastion.treasure;

import net.minecraft.world.gen.feature.*;
import net.minecraft.block.*;
import net.minecraft.world.*;
import java.util.*;

import com.NovaCraft.config.Configs;
import com.NovaCraft.registry.OtherModBlocks;
import com.NovaCraftBlocks.NovaCraftBlocks;

import cpw.mods.fml.common.Loader;
import net.minecraft.init.*;

public class BastionTreasureBarracksGen8 extends WorldGenerator
{
	public BastionTreasureBarracksGen8() {

	}
    
    public boolean generate(final World world, final Random random, final int i, final int j, final int k) {
    	
    	world.setBlock(i + 0, j + 48, k + 3, NovaCraftBlocks.basal_bricks, 0, 2);
		world.setBlock(i + 1, j + 48, k + 3, NovaCraftBlocks.cracked_basal_bricks, 0, 2);
		world.setBlock(i + 2, j + 48, k + 3, NovaCraftBlocks.basal_bricks, 0, 2);
		world.setBlock(i + 3, j + 48, k + 3, NovaCraftBlocks.basal_bricks, 0, 2);
		world.setBlock(i + 4, j + 48, k + 3, NovaCraftBlocks.basal_bricks, 0, 2);
		world.setBlock(i + 5, j + 48, k + 3, NovaCraftBlocks.cracked_basal_bricks, 0, 2);
		world.setBlock(i + 6, j + 48, k + 3, NovaCraftBlocks.cracked_basal_bricks, 0, 2);
		world.setBlock(i + 7, j + 48, k + 3, NovaCraftBlocks.basal_bricks, 0, 2);
		world.setBlock(i + 8, j + 48, k + 3, NovaCraftBlocks.basal_bricks, 0, 2);
		world.setBlock(i + 9, j + 48, k + 3, NovaCraftBlocks.basal_bricks, 0, 2);
		world.setBlock(i + 10, j + 48, k + 3, NovaCraftBlocks.cracked_basal_bricks, 0, 2);
		world.setBlock(i + 11, j + 48, k + 3, NovaCraftBlocks.basal_bricks, 0, 2);
		world.setBlock(i + 12, j + 48, k + 3, NovaCraftBlocks.cracked_basal_bricks, 0, 2);
		world.setBlock(i + 13, j + 48, k + 3, NovaCraftBlocks.basal_bricks, 0, 2);
		world.setBlock(i + 14, j + 48, k + 3, NovaCraftBlocks.basal_bricks, 0, 2);
		world.setBlock(i + 15, j + 48, k + 3, NovaCraftBlocks.basal_bricks, 0, 2);
		world.setBlock(i + 16, j + 48, k + 3, Blocks.air, 0, 2);
		world.setBlock(i + 17, j + 48, k + 3, Blocks.air, 0, 2);
		world.setBlock(i + 18, j + 48, k + 3, NovaCraftBlocks.cracked_basal_bricks, 0, 2);
		world.setBlock(i + 19, j + 48, k + 3, NovaCraftBlocks.basal_bricks, 0, 2);
		world.setBlock(i + 20, j + 48, k + 3, Blocks.air, 0, 2);
		world.setBlock(i + 21, j + 48, k + 3, Blocks.air, 0, 2);
		world.setBlock(i + 22, j + 48, k + 3, NovaCraftBlocks.basal_bricks, 0, 2);
		world.setBlock(i + 23, j + 48, k + 3, NovaCraftBlocks.basal_bricks, 0, 2);
		world.setBlock(i + 24, j + 48, k + 3, Blocks.air, 0, 2);
		world.setBlock(i + 25, j + 48, k + 3, Blocks.air, 0, 2);
		world.setBlock(i + 26, j + 48, k + 3, NovaCraftBlocks.basal_bricks, 0, 2);
		world.setBlock(i + 27, j + 48, k + 3, NovaCraftBlocks.cracked_basal_bricks, 0, 2);
		world.setBlock(i + 0, j + 48, k + 4, NovaCraftBlocks.basal_bricks, 0, 2);
		world.setBlock(i + 1, j + 48, k + 4, NovaCraftBlocks.basal_bricks, 0, 2);
		world.setBlock(i + 2, j + 48, k + 4, NovaCraftBlocks.basal_bricks, 0, 2);
		world.setBlock(i + 3, j + 48, k + 4, NovaCraftBlocks.basal_bricks, 0, 2);
		world.setBlock(i + 4, j + 48, k + 4, NovaCraftBlocks.basal_bricks, 0, 2);
		world.setBlock(i + 5, j + 48, k + 4, NovaCraftBlocks.cracked_basal_bricks, 0, 2);
		world.setBlock(i + 6, j + 48, k + 4, NovaCraftBlocks.basal_bricks, 0, 2);
		world.setBlock(i + 7, j + 48, k + 4, NovaCraftBlocks.basal_bricks, 0, 2);
		world.setBlock(i + 8, j + 48, k + 4, NovaCraftBlocks.basal_bricks, 0, 2);
		world.setBlock(i + 9, j + 48, k + 4, NovaCraftBlocks.basal_bricks, 0, 2);
		world.setBlock(i + 10, j + 48, k + 4, NovaCraftBlocks.basal_bricks, 0, 2);
		world.setBlock(i + 11, j + 48, k + 4, NovaCraftBlocks.basal_bricks, 0, 2);
		world.setBlock(i + 12, j + 48, k + 4, NovaCraftBlocks.cracked_basal_bricks, 0, 2);
		world.setBlock(i + 13, j + 48, k + 4, NovaCraftBlocks.cracked_basal_bricks, 0, 2);
		world.setBlock(i + 14, j + 48, k + 4, NovaCraftBlocks.cracked_basal_bricks, 0, 2);
		world.setBlock(i + 15, j + 48, k + 4, NovaCraftBlocks.cracked_basal_bricks, 0, 2);
		world.setBlock(i + 16, j + 48, k + 4, Blocks.air, 0, 2);
		world.setBlock(i + 17, j + 48, k + 4, Blocks.air, 0, 2);
		world.setBlock(i + 18, j + 48, k + 4, NovaCraftBlocks.basal_bricks, 0, 2);
		world.setBlock(i + 19, j + 48, k + 4, NovaCraftBlocks.cracked_basal_bricks, 0, 2);
		world.setBlock(i + 20, j + 48, k + 4, Blocks.air, 0, 2);
		world.setBlock(i + 21, j + 48, k + 4, Blocks.air, 0, 2);
		world.setBlock(i + 22, j + 48, k + 4, NovaCraftBlocks.basal_bricks, 0, 2);
		world.setBlock(i + 23, j + 48, k + 4, NovaCraftBlocks.cracked_basal_bricks, 0, 2);
		world.setBlock(i + 24, j + 48, k + 4, Blocks.air, 0, 2);
		world.setBlock(i + 25, j + 48, k + 4, Blocks.air, 0, 2);
		world.setBlock(i + 26, j + 48, k + 4, NovaCraftBlocks.cracked_basal_bricks, 0, 2);
		world.setBlock(i + 27, j + 48, k + 4, NovaCraftBlocks.cracked_basal_bricks, 0, 2);
		world.setBlock(i + 0, j + 48, k + 5, NovaCraftBlocks.basal_bricks, 0, 2);
		world.setBlock(i + 1, j + 48, k + 5, NovaCraftBlocks.basal_bricks, 0, 2);
		world.setBlock(i + 2, j + 48, k + 5, NovaCraftBlocks.cracked_basal_bricks, 0, 2);
		world.setBlock(i + 3, j + 48, k + 5, NovaCraftBlocks.cracked_basal_bricks, 0, 2);
		world.setBlock(i + 4, j + 48, k + 5, NovaCraftBlocks.basal_bricks, 0, 2);
		world.setBlock(i + 5, j + 48, k + 5, NovaCraftBlocks.cracked_basal_bricks, 0, 2);
		world.setBlock(i + 6, j + 48, k + 5, NovaCraftBlocks.basal_bricks, 0, 2);
		world.setBlock(i + 7, j + 48, k + 5, NovaCraftBlocks.basal_bricks, 0, 2);
		world.setBlock(i + 8, j + 48, k + 5, NovaCraftBlocks.basal_bricks, 0, 2);
		world.setBlock(i + 9, j + 48, k + 5, NovaCraftBlocks.basal_bricks, 0, 2);
		world.setBlock(i + 10, j + 48, k + 5, NovaCraftBlocks.basal_bricks, 0, 2);
		world.setBlock(i + 11, j + 48, k + 5, NovaCraftBlocks.basal_bricks, 0, 2);
		world.setBlock(i + 12, j + 48, k + 5, NovaCraftBlocks.basal_bricks, 0, 2);
		world.setBlock(i + 13, j + 48, k + 5, NovaCraftBlocks.basal_bricks, 0, 2);
		world.setBlock(i + 14, j + 48, k + 5, NovaCraftBlocks.basal_bricks, 0, 2);
		world.setBlock(i + 15, j + 48, k + 5, NovaCraftBlocks.basal_bricks, 0, 2);
		world.setBlock(i + 16, j + 48, k + 5, NovaCraftBlocks.basal_bricks, 0, 2);
		world.setBlock(i + 17, j + 48, k + 5, NovaCraftBlocks.cracked_basal_bricks, 0, 2);
		world.setBlock(i + 18, j + 48, k + 5, NovaCraftBlocks.cracked_basal_bricks, 0, 2);
		world.setBlock(i + 19, j + 48, k + 5, NovaCraftBlocks.cracked_basal_bricks, 0, 2);
		world.setBlock(i + 20, j + 48, k + 5, NovaCraftBlocks.cracked_basal_bricks, 0, 2);
		world.setBlock(i + 21, j + 48, k + 5, NovaCraftBlocks.basal_bricks, 0, 2);
		world.setBlock(i + 22, j + 48, k + 5, NovaCraftBlocks.cracked_basal_bricks, 0, 2);
		world.setBlock(i + 23, j + 48, k + 5, NovaCraftBlocks.cracked_basal_bricks, 0, 2);
		world.setBlock(i + 24, j + 48, k + 5, NovaCraftBlocks.basal_bricks, 0, 2);
		world.setBlock(i + 25, j + 48, k + 5, NovaCraftBlocks.basal_bricks, 0, 2);
		world.setBlock(i + 26, j + 48, k + 5, NovaCraftBlocks.basal_bricks, 0, 2);
		world.setBlock(i + 27, j + 48, k + 5, Blocks.air, 0, 2);
		world.setBlock(i + 0, j + 48, k + 6, NovaCraftBlocks.basal_bricks, 0, 2);
		world.setBlock(i + 1, j + 48, k + 6, NovaCraftBlocks.cracked_basal_bricks, 0, 2);
		world.setBlock(i + 2, j + 48, k + 6, NovaCraftBlocks.basal_bricks, 0, 2);
		world.setBlock(i + 3, j + 48, k + 6, NovaCraftBlocks.basal_bricks, 0, 2);
		world.setBlock(i + 4, j + 48, k + 6, NovaCraftBlocks.cracked_basal_bricks, 0, 2);
		world.setBlock(i + 5, j + 48, k + 6, NovaCraftBlocks.basal_bricks, 0, 2);
		world.setBlock(i + 6, j + 48, k + 6, NovaCraftBlocks.cracked_basal_bricks, 0, 2);
		world.setBlock(i + 7, j + 48, k + 6, NovaCraftBlocks.cracked_basal_bricks, 0, 2);
		world.setBlock(i + 8, j + 48, k + 6, NovaCraftBlocks.cracked_basal_bricks, 0, 2);
		world.setBlock(i + 9, j + 48, k + 6, NovaCraftBlocks.basal_bricks, 0, 2);
		world.setBlock(i + 10, j + 48, k + 6, NovaCraftBlocks.cracked_basal_bricks, 0, 2);
		world.setBlock(i + 11, j + 48, k + 6, NovaCraftBlocks.basal_bricks, 0, 2);
		world.setBlock(i + 12, j + 48, k + 6, NovaCraftBlocks.basal_bricks, 0, 2);
		world.setBlock(i + 13, j + 48, k + 6, NovaCraftBlocks.cracked_basal_bricks, 0, 2);
		world.setBlock(i + 14, j + 48, k + 6, NovaCraftBlocks.basal_bricks, 0, 2);
		world.setBlock(i + 15, j + 48, k + 6, NovaCraftBlocks.cracked_basal_bricks, 0, 2);
		world.setBlock(i + 16, j + 48, k + 6, NovaCraftBlocks.basal_bricks, 0, 2);
		world.setBlock(i + 17, j + 48, k + 6, NovaCraftBlocks.basal_bricks, 0, 2);
		world.setBlock(i + 18, j + 48, k + 6, NovaCraftBlocks.cracked_basal_bricks, 0, 2);
		world.setBlock(i + 19, j + 48, k + 6, NovaCraftBlocks.cracked_basal_bricks, 0, 2);
		world.setBlock(i + 20, j + 48, k + 6, NovaCraftBlocks.cracked_basal_bricks, 0, 2);
		world.setBlock(i + 21, j + 48, k + 6, NovaCraftBlocks.basal_bricks, 0, 2);
		world.setBlock(i + 22, j + 48, k + 6, NovaCraftBlocks.basal_bricks, 0, 2);
		world.setBlock(i + 23, j + 48, k + 6, NovaCraftBlocks.basal_bricks, 0, 2);
		world.setBlock(i + 24, j + 48, k + 6, NovaCraftBlocks.cracked_basal_bricks, 0, 2);
		world.setBlock(i + 25, j + 48, k + 6, NovaCraftBlocks.basal_bricks, 0, 2);
		world.setBlock(i + 26, j + 48, k + 6, NovaCraftBlocks.basal_bricks, 0, 2);
		world.setBlock(i + 27, j + 48, k + 6, NovaCraftBlocks.cracked_basal_bricks, 0, 2);
		world.setBlock(i + 0, j + 48, k + 7, NovaCraftBlocks.cracked_basal_bricks, 0, 2);
		world.setBlock(i + 1, j + 48, k + 7, NovaCraftBlocks.basal_bricks, 0, 2);
		world.setBlock(i + 2, j + 48, k + 7, NovaCraftBlocks.basal_bricks, 0, 2);
		world.setBlock(i + 3, j + 48, k + 7, NovaCraftBlocks.basal_bricks, 0, 2);
		world.setBlock(i + 4, j + 48, k + 7, NovaCraftBlocks.cracked_basal_bricks, 0, 2);
		world.setBlock(i + 5, j + 48, k + 7, NovaCraftBlocks.cracked_basal_bricks, 0, 2);
		world.setBlock(i + 6, j + 48, k + 7, NovaCraftBlocks.basal_bricks, 0, 2);
		world.setBlock(i + 7, j + 48, k + 7, NovaCraftBlocks.cracked_basal_bricks, 0, 2);
		world.setBlock(i + 8, j + 48, k + 7, NovaCraftBlocks.basal_bricks, 0, 2);
		world.setBlock(i + 9, j + 48, k + 7, NovaCraftBlocks.basal_bricks, 0, 2);
		world.setBlock(i + 10, j + 48, k + 7, NovaCraftBlocks.cracked_basal_bricks, 0, 2);
		world.setBlock(i + 11, j + 48, k + 7, NovaCraftBlocks.basal_bricks, 0, 2);
		world.setBlock(i + 12, j + 48, k + 7, NovaCraftBlocks.basal_bricks, 0, 2);
		world.setBlock(i + 13, j + 48, k + 7, NovaCraftBlocks.basal_bricks, 0, 2);
		world.setBlock(i + 14, j + 48, k + 7, NovaCraftBlocks.cracked_basal_bricks, 0, 2);
		world.setBlock(i + 15, j + 48, k + 7, NovaCraftBlocks.basal_bricks, 0, 2);
		world.setBlock(i + 16, j + 48, k + 7, NovaCraftBlocks.cracked_basal_bricks, 0, 2);
		world.setBlock(i + 17, j + 48, k + 7, NovaCraftBlocks.cracked_basal_bricks, 0, 2);
		world.setBlock(i + 18, j + 48, k + 7, NovaCraftBlocks.basal_bricks, 0, 2);
		world.setBlock(i + 19, j + 48, k + 7, NovaCraftBlocks.basal_bricks, 0, 2);
		world.setBlock(i + 20, j + 48, k + 7, NovaCraftBlocks.basal_bricks, 0, 2);
		world.setBlock(i + 21, j + 48, k + 7, NovaCraftBlocks.basal_bricks, 0, 2);
		world.setBlock(i + 22, j + 48, k + 7, NovaCraftBlocks.cracked_basal_bricks, 0, 2);
		world.setBlock(i + 23, j + 48, k + 7, NovaCraftBlocks.cracked_basal_bricks, 0, 2);
		world.setBlock(i + 24, j + 48, k + 7, NovaCraftBlocks.basal_bricks, 0, 2);
		world.setBlock(i + 25, j + 48, k + 7, NovaCraftBlocks.basal_bricks, 0, 2);
		world.setBlock(i + 26, j + 48, k + 7, NovaCraftBlocks.basal_bricks, 0, 2);
		world.setBlock(i + 27, j + 48, k + 7, NovaCraftBlocks.cracked_basal_bricks, 0, 2);
		world.setBlock(i + 0, j + 48, k + 8, NovaCraftBlocks.basal_bricks, 0, 2);
		world.setBlock(i + 1, j + 48, k + 8, NovaCraftBlocks.cracked_basal_bricks, 0, 2);
		world.setBlock(i + 2, j + 48, k + 8, NovaCraftBlocks.basal_bricks, 0, 2);
		world.setBlock(i + 3, j + 48, k + 8, NovaCraftBlocks.basal_bricks, 0, 2);
		world.setBlock(i + 4, j + 48, k + 8, NovaCraftBlocks.basal_bricks, 0, 2);
		world.setBlock(i + 5, j + 48, k + 8, NovaCraftBlocks.basal_bricks, 0, 2);
		world.setBlock(i + 6, j + 48, k + 8, NovaCraftBlocks.basal_bricks, 0, 2);
		world.setBlock(i + 7, j + 48, k + 8, NovaCraftBlocks.cracked_basal_bricks, 0, 2);
		world.setBlock(i + 8, j + 48, k + 8, NovaCraftBlocks.basal_bricks, 0, 2);
		world.setBlock(i + 9, j + 48, k + 8, NovaCraftBlocks.basal_bricks, 0, 2);
		world.setBlock(i + 10, j + 48, k + 8, NovaCraftBlocks.basal_bricks, 0, 2);
		world.setBlock(i + 11, j + 48, k + 8, NovaCraftBlocks.basal, 0, 2);
		world.setBlock(i + 12, j + 48, k + 8, NovaCraftBlocks.basal, 0, 2);
		world.setBlock(i + 13, j + 48, k + 8, NovaCraftBlocks.cracked_basal_bricks, 0, 2);
		world.setBlock(i + 14, j + 48, k + 8, NovaCraftBlocks.basal_bricks, 0, 2);
		world.setBlock(i + 15, j + 48, k + 8, NovaCraftBlocks.basal_bricks, 0, 2);
		world.setBlock(i + 16, j + 48, k + 8, NovaCraftBlocks.cracked_basal_bricks, 0, 2);
		world.setBlock(i + 17, j + 48, k + 8, NovaCraftBlocks.basal_bricks, 0, 2);
		world.setBlock(i + 18, j + 48, k + 8, NovaCraftBlocks.cracked_basal_bricks, 0, 2);
		world.setBlock(i + 19, j + 48, k + 8, NovaCraftBlocks.basal_bricks, 0, 2);
		world.setBlock(i + 20, j + 48, k + 8, NovaCraftBlocks.basal_bricks, 0, 2);
		world.setBlock(i + 21, j + 48, k + 8, NovaCraftBlocks.cracked_basal_bricks, 0, 2);
		world.setBlock(i + 22, j + 48, k + 8, NovaCraftBlocks.basal_bricks, 0, 2);
		world.setBlock(i + 23, j + 48, k + 8, NovaCraftBlocks.cracked_basal_bricks, 0, 2);
		world.setBlock(i + 24, j + 48, k + 8, NovaCraftBlocks.cracked_basal_bricks, 0, 2);
		world.setBlock(i + 25, j + 48, k + 8, NovaCraftBlocks.cracked_basal_bricks, 0, 2);
		world.setBlock(i + 26, j + 48, k + 8, NovaCraftBlocks.cracked_basal_bricks, 0, 2);
		world.setBlock(i + 27, j + 48, k + 8, NovaCraftBlocks.basal_bricks, 0, 2);
		world.setBlock(i + 0, j + 48, k + 9, NovaCraftBlocks.cracked_basal_bricks, 0, 2);
		world.setBlock(i + 1, j + 48, k + 9, Blocks.air, 0, 2);
		world.setBlock(i + 2, j + 48, k + 9, Blocks.air, 0, 2);
		world.setBlock(i + 3, j + 48, k + 9, Blocks.air, 0, 2);
		world.setBlock(i + 4, j + 48, k + 9, Blocks.air, 0, 2);
		world.setBlock(i + 5, j + 48, k + 9, Blocks.air, 0, 2);
		world.setBlock(i + 6, j + 48, k + 9, NovaCraftBlocks.basal_bricks, 0, 2);
		world.setBlock(i + 7, j + 48, k + 9, NovaCraftBlocks.basal_bricks, 0, 2);
		world.setBlock(i + 8, j + 48, k + 9, Blocks.air, 0, 2);
		world.setBlock(i + 9, j + 48, k + 9, Blocks.air, 0, 2);
		world.setBlock(i + 10, j + 48, k + 9, Blocks.air, 0, 2);
		world.setBlock(i + 11, j + 48, k + 9, Blocks.air, 0, 2);
		world.setBlock(i + 12, j + 48, k + 9, Blocks.air, 0, 2);
		world.setBlock(i + 13, j + 48, k + 9, NovaCraftBlocks.basal, 0, 2);
		world.setBlock(i + 14, j + 48, k + 9, NovaCraftBlocks.basal_bricks, 0, 2);
		world.setBlock(i + 15, j + 48, k + 9, NovaCraftBlocks.basal_bricks, 0, 2);
		world.setBlock(i + 16, j + 48, k + 9, NovaCraftBlocks.basal_bricks, 0, 2);
		world.setBlock(i + 17, j + 48, k + 9, NovaCraftBlocks.cracked_basal_bricks, 0, 2);
		world.setBlock(i + 18, j + 48, k + 9, NovaCraftBlocks.cracked_basal_bricks, 0, 2);
		world.setBlock(i + 19, j + 48, k + 9, NovaCraftBlocks.basal_bricks, 0, 2);
		world.setBlock(i + 20, j + 48, k + 9, NovaCraftBlocks.basal_bricks, 0, 2);
		world.setBlock(i + 21, j + 48, k + 9, NovaCraftBlocks.basal_bricks, 0, 2);
		world.setBlock(i + 22, j + 48, k + 9, NovaCraftBlocks.basal_bricks, 0, 2);
		world.setBlock(i + 23, j + 48, k + 9, NovaCraftBlocks.basal_bricks, 0, 2);
		world.setBlock(i + 24, j + 48, k + 9, NovaCraftBlocks.basal_bricks, 0, 2);
		world.setBlock(i + 25, j + 48, k + 9, NovaCraftBlocks.cracked_basal_bricks, 0, 2);
		world.setBlock(i + 26, j + 48, k + 9, NovaCraftBlocks.basal_bricks, 0, 2);
		world.setBlock(i + 27, j + 48, k + 9, NovaCraftBlocks.basal_bricks, 0, 2);
		world.setBlock(i + 0, j + 48, k + 10, NovaCraftBlocks.cracked_basal_bricks, 0, 2);
		world.setBlock(i + 1, j + 48, k + 10, Blocks.air, 0, 2);
		world.setBlock(i + 2, j + 48, k + 10, Blocks.air, 0, 2);
		world.setBlock(i + 3, j + 48, k + 10, NovaCraftBlocks.basal_brick_stairs, 0, 2);
		world.setBlock(i + 4, j + 48, k + 10, NovaCraftBlocks.basal_bricks, 0, 2);
		world.setBlock(i + 5, j + 48, k + 10, NovaCraftBlocks.basal_bricks, 0, 2);
		world.setBlock(i + 6, j + 48, k + 10, NovaCraftBlocks.basal_bricks, 0, 2);
		world.setBlock(i + 7, j + 48, k + 10, NovaCraftBlocks.basal_scrap, 0, 2);
		world.setBlock(i + 8, j + 48, k + 10, NovaCraftBlocks.basal_scrap, 0, 2);
		world.setBlock(i + 9, j + 48, k + 10, Blocks.air, 0, 2);
		world.setBlock(i + 10, j + 48, k + 10, Blocks.air, 0, 2);
		world.setBlock(i + 11, j + 48, k + 10, Blocks.air, 0, 2);
		world.setBlock(i + 12, j + 48, k + 10, Blocks.air, 0, 2);
		world.setBlock(i + 13, j + 48, k + 10, NovaCraftBlocks.basal, 0, 2);
		world.setBlock(i + 14, j + 48, k + 10, NovaCraftBlocks.cracked_basal_bricks, 0, 2);
		world.setBlock(i + 15, j + 48, k + 10, NovaCraftBlocks.cracked_basal_bricks, 0, 2);
		world.setBlock(i + 16, j + 48, k + 10, NovaCraftBlocks.basal_bricks, 0, 2);
		world.setBlock(i + 17, j + 48, k + 10, NovaCraftBlocks.cracked_basal_bricks, 0, 2);
		world.setBlock(i + 18, j + 48, k + 10, NovaCraftBlocks.cracked_basal_bricks, 0, 2);
		world.setBlock(i + 19, j + 48, k + 10, NovaCraftBlocks.cracked_basal_bricks, 0, 2);
		world.setBlock(i + 20, j + 48, k + 10, NovaCraftBlocks.basal_bricks, 0, 2);
		world.setBlock(i + 21, j + 48, k + 10, NovaCraftBlocks.basal_bricks, 0, 2);
		world.setBlock(i + 22, j + 48, k + 10, NovaCraftBlocks.cracked_basal_bricks, 0, 2);
		world.setBlock(i + 23, j + 48, k + 10, NovaCraftBlocks.basal_bricks, 0, 2);
		world.setBlock(i + 24, j + 48, k + 10, NovaCraftBlocks.basal_bricks, 0, 2);
		world.setBlock(i + 25, j + 48, k + 10, NovaCraftBlocks.basal, 0, 2);
		world.setBlock(i + 26, j + 48, k + 10, NovaCraftBlocks.basal, 0, 2);
		world.setBlock(i + 27, j + 48, k + 10, NovaCraftBlocks.cracked_basal_bricks, 0, 2);
		world.setBlock(i + 0, j + 48, k + 11, Blocks.air, 0, 2);
		world.setBlock(i + 1, j + 48, k + 11, Blocks.air, 0, 2);
		world.setBlock(i + 2, j + 48, k + 11, Blocks.air, 0, 2);
		world.setBlock(i + 3, j + 48, k + 11, Blocks.air, 0, 2);
		world.setBlock(i + 4, j + 48, k + 11, Blocks.air, 0, 2);
		world.setBlock(i + 5, j + 48, k + 11, Blocks.air, 0, 2);
		world.setBlock(i + 6, j + 48, k + 11, Blocks.air, 0, 2);
		world.setBlock(i + 7, j + 48, k + 11, Blocks.air, 0, 2);
		world.setBlock(i + 8, j + 48, k + 11, Blocks.air, 0, 2);
		world.setBlock(i + 9, j + 48, k + 11, Blocks.air, 0, 2);
		world.setBlock(i + 10, j + 48, k + 11, Blocks.air, 0, 2);
		world.setBlock(i + 11, j + 48, k + 11, Blocks.air, 0, 2);
		world.setBlock(i + 12, j + 48, k + 11, Blocks.air, 0, 2);
		world.setBlock(i + 13, j + 48, k + 11, Blocks.air, 0, 2);
		world.setBlock(i + 14, j + 48, k + 11, NovaCraftBlocks.cracked_basal_bricks, 0, 2);
		world.setBlock(i + 15, j + 48, k + 11, Blocks.air, 0, 2);
		world.setBlock(i + 16, j + 48, k + 11, Blocks.air, 0, 2);
		world.setBlock(i + 17, j + 48, k + 11, Blocks.air, 0, 2);
		world.setBlock(i + 18, j + 48, k + 11, Blocks.air, 0, 2);
		world.setBlock(i + 19, j + 48, k + 11, Blocks.air, 0, 2);
		world.setBlock(i + 20, j + 48, k + 11, NovaCraftBlocks.basal_bricks, 0, 2);
		world.setBlock(i + 21, j + 48, k + 11, NovaCraftBlocks.basal_bricks, 0, 2);
		world.setBlock(i + 22, j + 48, k + 11, Blocks.air, 0, 2);
		world.setBlock(i + 23, j + 48, k + 11, Blocks.air, 0, 2);
		world.setBlock(i + 24, j + 48, k + 11, Blocks.air, 0, 2);
		world.setBlock(i + 25, j + 48, k + 11, Blocks.air, 0, 2);
		world.setBlock(i + 26, j + 48, k + 11, Blocks.air, 0, 2);
		world.setBlock(i + 27, j + 48, k + 11, NovaCraftBlocks.basal, 0, 2);
		world.setBlock(i + 0, j + 48, k + 12, Blocks.air, 0, 2);
		world.setBlock(i + 1, j + 48, k + 12, Blocks.air, 0, 2);
		world.setBlock(i + 2, j + 48, k + 12, Blocks.air, 0, 2);
		world.setBlock(i + 3, j + 48, k + 12, Blocks.air, 0, 2);
		world.setBlock(i + 4, j + 48, k + 12, Blocks.air, 0, 2);
		world.setBlock(i + 5, j + 48, k + 12, Blocks.air, 0, 2);
		world.setBlock(i + 6, j + 48, k + 12, Blocks.air, 0, 2);
		world.setBlock(i + 7, j + 48, k + 12, Blocks.air, 0, 2);
		world.setBlock(i + 8, j + 48, k + 12, Blocks.air, 0, 2);
		world.setBlock(i + 9, j + 48, k + 12, Blocks.air, 0, 2);
		world.setBlock(i + 10, j + 48, k + 12, Blocks.air, 0, 2);
		world.setBlock(i + 11, j + 48, k + 12, Blocks.air, 0, 2);
		world.setBlock(i + 12, j + 48, k + 12, Blocks.air, 0, 2);
		world.setBlock(i + 13, j + 48, k + 12, Blocks.air, 0, 2);
		world.setBlock(i + 14, j + 48, k + 12, NovaCraftBlocks.basal_bricks, 0, 2);
		world.setBlock(i + 15, j + 48, k + 12, Blocks.air, 0, 2);
		world.setBlock(i + 16, j + 48, k + 12, Blocks.air, 0, 2);
		world.setBlock(i + 17, j + 48, k + 12, NovaCraftBlocks.basal_brick_stairs, 0, 2);
		world.setBlock(i + 18, j + 48, k + 12, NovaCraftBlocks.cracked_basal_bricks, 0, 2);
		world.setBlock(i + 19, j + 48, k + 12, NovaCraftBlocks.basal_bricks, 0, 2);
		world.setBlock(i + 20, j + 48, k + 12, NovaCraftBlocks.basal_bricks, 0, 2);
		world.setBlock(i + 21, j + 48, k + 12, NovaCraftBlocks.basal_scrap, 0, 2);
		world.setBlock(i + 22, j + 48, k + 12, Blocks.air, 0, 2);
		world.setBlock(i + 23, j + 48, k + 12, Blocks.air, 0, 2);
		world.setBlock(i + 24, j + 48, k + 12, Blocks.air, 0, 2);
		world.setBlock(i + 25, j + 48, k + 12, Blocks.air, 0, 2);
		world.setBlock(i + 26, j + 48, k + 12, Blocks.air, 0, 2);
		world.setBlock(i + 27, j + 48, k + 12, NovaCraftBlocks.basal, 0, 2);
		world.setBlock(i + 0, j + 49, k + 0, Blocks.air, 0, 2);
		world.setBlock(i + 1, j + 49, k + 0, Blocks.air, 0, 2);
		world.setBlock(i + 2, j + 49, k + 0, Blocks.air, 0, 2);
		world.setBlock(i + 3, j + 49, k + 0, Blocks.air, 0, 2);
		world.setBlock(i + 4, j + 49, k + 0, Blocks.air, 0, 2);
		world.setBlock(i + 5, j + 49, k + 0, Blocks.air, 0, 2);
		world.setBlock(i + 6, j + 49, k + 0, Blocks.air, 0, 2);
		world.setBlock(i + 7, j + 49, k + 0, Blocks.air, 0, 2);
		world.setBlock(i + 8, j + 49, k + 0, Blocks.air, 0, 2);
		world.setBlock(i + 9, j + 49, k + 0, Blocks.air, 0, 2);
		world.setBlock(i + 10, j + 49, k + 0, Blocks.air, 0, 2);
		world.setBlock(i + 11, j + 49, k + 0, Blocks.air, 0, 2);
		world.setBlock(i + 12, j + 49, k + 0, Blocks.air, 0, 2);
		world.setBlock(i + 13, j + 49, k + 0, Blocks.air, 0, 2);
		world.setBlock(i + 14, j + 49, k + 0, Blocks.air, 0, 2);
		world.setBlock(i + 15, j + 49, k + 0, Blocks.air, 0, 2);
		world.setBlock(i + 16, j + 49, k + 0, Blocks.air, 0, 2);
		world.setBlock(i + 17, j + 49, k + 0, Blocks.air, 0, 2);
		world.setBlock(i + 18, j + 49, k + 0, Blocks.air, 0, 2);
		world.setBlock(i + 19, j + 49, k + 0, Blocks.air, 0, 2);
		world.setBlock(i + 20, j + 49, k + 0, Blocks.air, 0, 2);
		world.setBlock(i + 21, j + 49, k + 0, Blocks.air, 0, 2);
		world.setBlock(i + 22, j + 49, k + 0, Blocks.air, 0, 2);
		world.setBlock(i + 23, j + 49, k + 0, Blocks.air, 0, 2);
		world.setBlock(i + 24, j + 49, k + 0, Blocks.air, 0, 2);
		world.setBlock(i + 25, j + 49, k + 0, Blocks.air, 0, 2);
		world.setBlock(i + 26, j + 49, k + 0, Blocks.air, 0, 2);
		world.setBlock(i + 27, j + 49, k + 0, Blocks.air, 0, 2);
		world.setBlock(i + 0, j + 49, k + 1, NovaCraftBlocks.basal_bricks, 0, 2);
		world.setBlock(i + 1, j + 49, k + 1, NovaCraftBlocks.basal_bricks, 0, 2);
		world.setBlock(i + 2, j + 49, k + 1, Blocks.air, 0, 2);
		world.setBlock(i + 3, j + 49, k + 1, Blocks.air, 0, 2);
		world.setBlock(i + 4, j + 49, k + 1, NovaCraftBlocks.basal_bricks, 0, 2);
		world.setBlock(i + 5, j + 49, k + 1, NovaCraftBlocks.basal_bricks, 0, 2);
		world.setBlock(i + 6, j + 49, k + 1, Blocks.air, 0, 2);
		world.setBlock(i + 7, j + 49, k + 1, Blocks.air, 0, 2);
		world.setBlock(i + 8, j + 49, k + 1, NovaCraftBlocks.basal_bricks, 0, 2);
		world.setBlock(i + 9, j + 49, k + 1, NovaCraftBlocks.cracked_basal_bricks, 0, 2);
		world.setBlock(i + 10, j + 49, k + 1, Blocks.air, 0, 2);
		world.setBlock(i + 11, j + 49, k + 1, Blocks.air, 0, 2);
		world.setBlock(i + 12, j + 49, k + 1, NovaCraftBlocks.cracked_basal_bricks, 0, 2);
		world.setBlock(i + 13, j + 49, k + 1, NovaCraftBlocks.cracked_basal_bricks, 0, 2);
		world.setBlock(i + 14, j + 49, k + 1, Blocks.air, 0, 2);
		world.setBlock(i + 15, j + 49, k + 1, Blocks.air, 0, 2);
		world.setBlock(i + 16, j + 49, k + 1, Blocks.air, 0, 2);
		world.setBlock(i + 17, j + 49, k + 1, Blocks.air, 0, 2);
		world.setBlock(i + 18, j + 49, k + 1, Blocks.air, 0, 2);
		world.setBlock(i + 19, j + 49, k + 1, Blocks.air, 0, 2);
		world.setBlock(i + 20, j + 49, k + 1, Blocks.air, 0, 2);
		world.setBlock(i + 21, j + 49, k + 1, Blocks.air, 0, 2);
		world.setBlock(i + 22, j + 49, k + 1, Blocks.air, 0, 2);
		world.setBlock(i + 23, j + 49, k + 1, Blocks.air, 0, 2);
		world.setBlock(i + 24, j + 49, k + 1, Blocks.air, 0, 2);
		world.setBlock(i + 25, j + 49, k + 1, Blocks.air, 0, 2);
		world.setBlock(i + 26, j + 49, k + 1, Blocks.air, 0, 2);
		world.setBlock(i + 27, j + 49, k + 1, Blocks.air, 0, 2);
		world.setBlock(i + 0, j + 49, k + 2, NovaCraftBlocks.cracked_basal_bricks, 0, 2);
		world.setBlock(i + 1, j + 49, k + 2, NovaCraftBlocks.basal_bricks, 0, 2);
		world.setBlock(i + 2, j + 49, k + 2, Blocks.air, 0, 2);
		world.setBlock(i + 3, j + 49, k + 2, Blocks.air, 0, 2);
		world.setBlock(i + 4, j + 49, k + 2, NovaCraftBlocks.basal_bricks, 0, 2);
		world.setBlock(i + 5, j + 49, k + 2, NovaCraftBlocks.basal_bricks, 0, 2);
		world.setBlock(i + 6, j + 49, k + 2, Blocks.air, 0, 2);
		world.setBlock(i + 7, j + 49, k + 2, Blocks.air, 0, 2);
		world.setBlock(i + 8, j + 49, k + 2, NovaCraftBlocks.basal_bricks, 0, 2);
		world.setBlock(i + 9, j + 49, k + 2, NovaCraftBlocks.cracked_basal_bricks, 0, 2);
		world.setBlock(i + 10, j + 49, k + 2, Blocks.air, 0, 2);
		world.setBlock(i + 11, j + 49, k + 2, Blocks.air, 0, 2);
		world.setBlock(i + 12, j + 49, k + 2, NovaCraftBlocks.basal_bricks, 0, 2);
		world.setBlock(i + 13, j + 49, k + 2, NovaCraftBlocks.basal_bricks, 0, 2);
		world.setBlock(i + 14, j + 49, k + 2, Blocks.air, 0, 2);
		world.setBlock(i + 15, j + 49, k + 2, Blocks.air, 0, 2);
		world.setBlock(i + 16, j + 49, k + 2, Blocks.air, 0, 2);
		world.setBlock(i + 17, j + 49, k + 2, Blocks.air, 0, 2);
		world.setBlock(i + 18, j + 49, k + 2, Blocks.air, 0, 2);
		world.setBlock(i + 19, j + 49, k + 2, Blocks.air, 0, 2);
		world.setBlock(i + 20, j + 49, k + 2, Blocks.air, 0, 2);
		world.setBlock(i + 21, j + 49, k + 2, Blocks.air, 0, 2);
		world.setBlock(i + 22, j + 49, k + 2, Blocks.air, 0, 2);
		world.setBlock(i + 23, j + 49, k + 2, Blocks.air, 0, 2);
		world.setBlock(i + 24, j + 49, k + 2, Blocks.air, 0, 2);
		world.setBlock(i + 25, j + 49, k + 2, Blocks.air, 0, 2);
		world.setBlock(i + 26, j + 49, k + 2, Blocks.air, 0, 2);
		world.setBlock(i + 27, j + 49, k + 2, Blocks.air, 0, 2);
		world.setBlock(i + 0, j + 49, k + 3, NovaCraftBlocks.cracked_basal_bricks, 0, 2);
		world.setBlock(i + 1, j + 49, k + 3, NovaCraftBlocks.basal_bricks, 0, 2);
		world.setBlock(i + 2, j + 49, k + 3, NovaCraftBlocks.cracked_basal_bricks, 0, 2);
		world.setBlock(i + 3, j + 49, k + 3, NovaCraftBlocks.basal_bricks, 0, 2);
		world.setBlock(i + 4, j + 49, k + 3, NovaCraftBlocks.basal_bricks, 0, 2);
		world.setBlock(i + 5, j + 49, k + 3, NovaCraftBlocks.basal_bricks, 0, 2);
		world.setBlock(i + 6, j + 49, k + 3, NovaCraftBlocks.basal_bricks, 0, 2);
		world.setBlock(i + 7, j + 49, k + 3, NovaCraftBlocks.cracked_basal_bricks, 0, 2);
		world.setBlock(i + 8, j + 49, k + 3, NovaCraftBlocks.cracked_basal_bricks, 0, 2);
		world.setBlock(i + 9, j + 49, k + 3, NovaCraftBlocks.basal_bricks, 0, 2);
		world.setBlock(i + 10, j + 49, k + 3, NovaCraftBlocks.basal_bricks, 0, 2);
		world.setBlock(i + 11, j + 49, k + 3, NovaCraftBlocks.cracked_basal_bricks, 0, 2);
		world.setBlock(i + 12, j + 49, k + 3, NovaCraftBlocks.basal_bricks, 0, 2);
		world.setBlock(i + 13, j + 49, k + 3, NovaCraftBlocks.basal_bricks, 0, 2);
		world.setBlock(i + 14, j + 49, k + 3, NovaCraftBlocks.basal_bricks, 0, 2);
		world.setBlock(i + 15, j + 49, k + 3, NovaCraftBlocks.basal_bricks, 0, 2);
		world.setBlock(i + 16, j + 49, k + 3, Blocks.air, 0, 2);
		world.setBlock(i + 17, j + 49, k + 3, Blocks.air, 0, 2);
		world.setBlock(i + 18, j + 49, k + 3, NovaCraftBlocks.basal_bricks, 0, 2);
		world.setBlock(i + 19, j + 49, k + 3, NovaCraftBlocks.basal_bricks, 0, 2);
		world.setBlock(i + 20, j + 49, k + 3, Blocks.air, 0, 2);
		world.setBlock(i + 21, j + 49, k + 3, Blocks.air, 0, 2);
		world.setBlock(i + 22, j + 49, k + 3, NovaCraftBlocks.basal_bricks, 0, 2);
		world.setBlock(i + 23, j + 49, k + 3, NovaCraftBlocks.cracked_basal_bricks, 0, 2);
		world.setBlock(i + 24, j + 49, k + 3, Blocks.air, 0, 2);
		world.setBlock(i + 25, j + 49, k + 3, Blocks.air, 0, 2);
		world.setBlock(i + 26, j + 49, k + 3, NovaCraftBlocks.basal_bricks, 0, 2);
		world.setBlock(i + 27, j + 49, k + 3, NovaCraftBlocks.cracked_basal_bricks, 0, 2);
		world.setBlock(i + 0, j + 49, k + 4, NovaCraftBlocks.basal_bricks, 0, 2);
		world.setBlock(i + 1, j + 49, k + 4, NovaCraftBlocks.basal_bricks, 0, 2);
		world.setBlock(i + 2, j + 49, k + 4, NovaCraftBlocks.cracked_basal_bricks, 0, 2);
		world.setBlock(i + 3, j + 49, k + 4, NovaCraftBlocks.basal_bricks, 0, 2);
		world.setBlock(i + 4, j + 49, k + 4, NovaCraftBlocks.basal_bricks, 0, 2);
		world.setBlock(i + 5, j + 49, k + 4, NovaCraftBlocks.basal_bricks, 0, 2);
		world.setBlock(i + 6, j + 49, k + 4, NovaCraftBlocks.basal_bricks, 0, 2);
		world.setBlock(i + 7, j + 49, k + 4, NovaCraftBlocks.basal_bricks, 0, 2);
		world.setBlock(i + 8, j + 49, k + 4, NovaCraftBlocks.basal_bricks, 0, 2);
		world.setBlock(i + 9, j + 49, k + 4, NovaCraftBlocks.basal_bricks, 0, 2);
		world.setBlock(i + 10, j + 49, k + 4, NovaCraftBlocks.cracked_basal_bricks, 0, 2);
		world.setBlock(i + 11, j + 49, k + 4, NovaCraftBlocks.cracked_basal_bricks, 0, 2);
		world.setBlock(i + 12, j + 49, k + 4, NovaCraftBlocks.cracked_basal_bricks, 0, 2);
		world.setBlock(i + 13, j + 49, k + 4, NovaCraftBlocks.basal_bricks, 0, 2);
		world.setBlock(i + 14, j + 49, k + 4, NovaCraftBlocks.basal_bricks, 0, 2);
		world.setBlock(i + 15, j + 49, k + 4, NovaCraftBlocks.basal_bricks, 0, 2);
		world.setBlock(i + 16, j + 49, k + 4, Blocks.air, 0, 2);
		world.setBlock(i + 17, j + 49, k + 4, Blocks.air, 0, 2);
		world.setBlock(i + 18, j + 49, k + 4, NovaCraftBlocks.basal_bricks, 0, 2);
		world.setBlock(i + 19, j + 49, k + 4, NovaCraftBlocks.basal_bricks, 0, 2);
		world.setBlock(i + 20, j + 49, k + 4, Blocks.air, 0, 2);
		world.setBlock(i + 21, j + 49, k + 4, Blocks.air, 0, 2);
		world.setBlock(i + 22, j + 49, k + 4, NovaCraftBlocks.basal_bricks, 0, 2);
		world.setBlock(i + 23, j + 49, k + 4, NovaCraftBlocks.basal_bricks, 0, 2);
		world.setBlock(i + 24, j + 49, k + 4, Blocks.air, 0, 2);
		world.setBlock(i + 25, j + 49, k + 4, Blocks.air, 0, 2);
		world.setBlock(i + 26, j + 49, k + 4, NovaCraftBlocks.basal_bricks, 0, 2);
		world.setBlock(i + 27, j + 49, k + 4, NovaCraftBlocks.basal_bricks, 0, 2);
		world.setBlock(i + 0, j + 49, k + 5, NovaCraftBlocks.basal_bricks, 0, 2);
		world.setBlock(i + 1, j + 49, k + 5, NovaCraftBlocks.basal_bricks, 0, 2);
		world.setBlock(i + 2, j + 49, k + 5, NovaCraftBlocks.cracked_basal_bricks, 0, 2);
		world.setBlock(i + 3, j + 49, k + 5, NovaCraftBlocks.cracked_basal_bricks, 0, 2);
		world.setBlock(i + 4, j + 49, k + 5, NovaCraftBlocks.basal_bricks, 0, 2);
		world.setBlock(i + 5, j + 49, k + 5, NovaCraftBlocks.basal_bricks, 0, 2);
		world.setBlock(i + 6, j + 49, k + 5, NovaCraftBlocks.basal_bricks, 0, 2);
		world.setBlock(i + 7, j + 49, k + 5, NovaCraftBlocks.basal_bricks, 0, 2);
		world.setBlock(i + 8, j + 49, k + 5, NovaCraftBlocks.cracked_basal_bricks, 0, 2);
		world.setBlock(i + 9, j + 49, k + 5, NovaCraftBlocks.cracked_basal_bricks, 0, 2);
		world.setBlock(i + 10, j + 49, k + 5, NovaCraftBlocks.basal_bricks, 0, 2);
		world.setBlock(i + 11, j + 49, k + 5, NovaCraftBlocks.basal_bricks, 0, 2);
		world.setBlock(i + 12, j + 49, k + 5, NovaCraftBlocks.basal_bricks, 0, 2);
		world.setBlock(i + 13, j + 49, k + 5, NovaCraftBlocks.basal_bricks, 0, 2);
		world.setBlock(i + 14, j + 49, k + 5, NovaCraftBlocks.basal_bricks, 0, 2);
		world.setBlock(i + 15, j + 49, k + 5, NovaCraftBlocks.basal_bricks, 0, 2);
		world.setBlock(i + 16, j + 49, k + 5, NovaCraftBlocks.basal_bricks, 0, 2);
		world.setBlock(i + 17, j + 49, k + 5, NovaCraftBlocks.basal_bricks, 0, 2);
		world.setBlock(i + 18, j + 49, k + 5, NovaCraftBlocks.cracked_basal_bricks, 0, 2);
		world.setBlock(i + 19, j + 49, k + 5, NovaCraftBlocks.basal_bricks, 0, 2);
		world.setBlock(i + 20, j + 49, k + 5, NovaCraftBlocks.basal_bricks, 0, 2);
		world.setBlock(i + 21, j + 49, k + 5, NovaCraftBlocks.cracked_basal_bricks, 0, 2);
		world.setBlock(i + 22, j + 49, k + 5, NovaCraftBlocks.basal_bricks, 0, 2);
		world.setBlock(i + 23, j + 49, k + 5, NovaCraftBlocks.cracked_basal_bricks, 0, 2);
		world.setBlock(i + 24, j + 49, k + 5, NovaCraftBlocks.basal_bricks, 0, 2);
		world.setBlock(i + 25, j + 49, k + 5, NovaCraftBlocks.basal_bricks, 0, 2);
		world.setBlock(i + 26, j + 49, k + 5, NovaCraftBlocks.cracked_basal_bricks, 0, 2);
		world.setBlock(i + 27, j + 49, k + 5, NovaCraftBlocks.cracked_basal_bricks, 0, 2);
		world.setBlock(i + 0, j + 49, k + 6, NovaCraftBlocks.cracked_basal_bricks, 0, 2);
		world.setBlock(i + 1, j + 49, k + 6, NovaCraftBlocks.cracked_basal_bricks, 0, 2);
		world.setBlock(i + 2, j + 49, k + 6, NovaCraftBlocks.basal_bricks, 0, 2);
		world.setBlock(i + 3, j + 49, k + 6, NovaCraftBlocks.cracked_basal_bricks, 0, 2);
		world.setBlock(i + 4, j + 49, k + 6, NovaCraftBlocks.basal_bricks, 0, 2);
		world.setBlock(i + 5, j + 49, k + 6, NovaCraftBlocks.cracked_basal_bricks, 0, 2);
		world.setBlock(i + 6, j + 49, k + 6, NovaCraftBlocks.basal_bricks, 0, 2);
		world.setBlock(i + 7, j + 49, k + 6, NovaCraftBlocks.basal_bricks, 0, 2);
		world.setBlock(i + 8, j + 49, k + 6, NovaCraftBlocks.basal_bricks, 0, 2);
		world.setBlock(i + 9, j + 49, k + 6, NovaCraftBlocks.basal_bricks, 0, 2);
		world.setBlock(i + 10, j + 49, k + 6, NovaCraftBlocks.basal_bricks, 0, 2);
		world.setBlock(i + 11, j + 49, k + 6, NovaCraftBlocks.cracked_basal_bricks, 0, 2);
		world.setBlock(i + 12, j + 49, k + 6, NovaCraftBlocks.basal_bricks, 0, 2);
		world.setBlock(i + 13, j + 49, k + 6, NovaCraftBlocks.basal_bricks, 0, 2);
		world.setBlock(i + 14, j + 49, k + 6, NovaCraftBlocks.basal_bricks, 0, 2);
		world.setBlock(i + 15, j + 49, k + 6, NovaCraftBlocks.basal_bricks, 0, 2);
		world.setBlock(i + 16, j + 49, k + 6, NovaCraftBlocks.basal_bricks, 0, 2);
		world.setBlock(i + 17, j + 49, k + 6, NovaCraftBlocks.cracked_basal_bricks, 0, 2);
		world.setBlock(i + 18, j + 49, k + 6, NovaCraftBlocks.cracked_basal_bricks, 0, 2);
		world.setBlock(i + 19, j + 49, k + 6, NovaCraftBlocks.basal_bricks, 0, 2);
		world.setBlock(i + 20, j + 49, k + 6, NovaCraftBlocks.basal_bricks, 0, 2);
		world.setBlock(i + 21, j + 49, k + 6, NovaCraftBlocks.cracked_basal_bricks, 0, 2);
		world.setBlock(i + 22, j + 49, k + 6, NovaCraftBlocks.basal_bricks, 0, 2);
		world.setBlock(i + 23, j + 49, k + 6, NovaCraftBlocks.basal_bricks, 0, 2);
		world.setBlock(i + 24, j + 49, k + 6, NovaCraftBlocks.basal_bricks, 0, 2);
		world.setBlock(i + 25, j + 49, k + 6, NovaCraftBlocks.basal_bricks, 0, 2);
		world.setBlock(i + 26, j + 49, k + 6, NovaCraftBlocks.basal_bricks, 0, 2);
		world.setBlock(i + 27, j + 49, k + 6, NovaCraftBlocks.cracked_basal_bricks, 0, 2);
		world.setBlock(i + 0, j + 49, k + 7, NovaCraftBlocks.basal_bricks, 0, 2);
		world.setBlock(i + 1, j + 49, k + 7, NovaCraftBlocks.basal_bricks, 0, 2);
		world.setBlock(i + 2, j + 49, k + 7, NovaCraftBlocks.cracked_basal_bricks, 0, 2);
		world.setBlock(i + 3, j + 49, k + 7, NovaCraftBlocks.cracked_basal_bricks, 0, 2);
		world.setBlock(i + 4, j + 49, k + 7, NovaCraftBlocks.basal_bricks, 0, 2);
		world.setBlock(i + 5, j + 49, k + 7, NovaCraftBlocks.cracked_basal_bricks, 0, 2);
		world.setBlock(i + 6, j + 49, k + 7, NovaCraftBlocks.basal_bricks, 0, 2);
		world.setBlock(i + 7, j + 49, k + 7, NovaCraftBlocks.basal_bricks, 0, 2);
		world.setBlock(i + 8, j + 49, k + 7, NovaCraftBlocks.cracked_basal_bricks, 0, 2);
		world.setBlock(i + 9, j + 49, k + 7, NovaCraftBlocks.basal_bricks, 0, 2);
		world.setBlock(i + 10, j + 49, k + 7, NovaCraftBlocks.cracked_basal_bricks, 0, 2);
		world.setBlock(i + 11, j + 49, k + 7, NovaCraftBlocks.basal_bricks, 0, 2);
		world.setBlock(i + 12, j + 49, k + 7, NovaCraftBlocks.basal_bricks, 0, 2);
		world.setBlock(i + 13, j + 49, k + 7, NovaCraftBlocks.cracked_basal_bricks, 0, 2);
		world.setBlock(i + 14, j + 49, k + 7, NovaCraftBlocks.basal_bricks, 0, 2);
		world.setBlock(i + 15, j + 49, k + 7, NovaCraftBlocks.cracked_basal_bricks, 0, 2);
		world.setBlock(i + 16, j + 49, k + 7, NovaCraftBlocks.cracked_basal_bricks, 0, 2);
		world.setBlock(i + 17, j + 49, k + 7, NovaCraftBlocks.basal_bricks, 0, 2);
		world.setBlock(i + 18, j + 49, k + 7, NovaCraftBlocks.basal_bricks, 0, 2);
		world.setBlock(i + 19, j + 49, k + 7, NovaCraftBlocks.basal_bricks, 0, 2);
		world.setBlock(i + 20, j + 49, k + 7, NovaCraftBlocks.cracked_basal_bricks, 0, 2);
		world.setBlock(i + 21, j + 49, k + 7, NovaCraftBlocks.basal_bricks, 0, 2);
		world.setBlock(i + 22, j + 49, k + 7, NovaCraftBlocks.cracked_basal_bricks, 0, 2);
		world.setBlock(i + 23, j + 49, k + 7, NovaCraftBlocks.cracked_basal_bricks, 0, 2);
		world.setBlock(i + 24, j + 49, k + 7, NovaCraftBlocks.basal_bricks, 0, 2);
		world.setBlock(i + 25, j + 49, k + 7, NovaCraftBlocks.basal_bricks, 0, 2);
		world.setBlock(i + 26, j + 49, k + 7, NovaCraftBlocks.basal_bricks, 0, 2);
		world.setBlock(i + 27, j + 49, k + 7, NovaCraftBlocks.cracked_basal_bricks, 0, 2);
		world.setBlock(i + 0, j + 49, k + 8, NovaCraftBlocks.basal_bricks, 0, 2);
		world.setBlock(i + 1, j + 49, k + 8, NovaCraftBlocks.cracked_basal_bricks, 0, 2);
		world.setBlock(i + 2, j + 49, k + 8, NovaCraftBlocks.basal_bricks, 0, 2);
		world.setBlock(i + 3, j + 49, k + 8, NovaCraftBlocks.basal_bricks, 0, 2);
		world.setBlock(i + 4, j + 49, k + 8, NovaCraftBlocks.basal_bricks, 0, 2);
		world.setBlock(i + 5, j + 49, k + 8, NovaCraftBlocks.cracked_basal_bricks, 0, 2);
		world.setBlock(i + 6, j + 49, k + 8, NovaCraftBlocks.basal_bricks, 0, 2);
		world.setBlock(i + 7, j + 49, k + 8, NovaCraftBlocks.basal_bricks, 0, 2);
		world.setBlock(i + 8, j + 49, k + 8, NovaCraftBlocks.basal_bricks, 0, 2);
		world.setBlock(i + 9, j + 49, k + 8, NovaCraftBlocks.basal_bricks, 0, 2);
		world.setBlock(i + 10, j + 49, k + 8, NovaCraftBlocks.basal_bricks, 0, 2);
		world.setBlock(i + 11, j + 49, k + 8, NovaCraftBlocks.cracked_basal_bricks, 0, 2);
		world.setBlock(i + 12, j + 49, k + 8, NovaCraftBlocks.basal, 0, 2);
		world.setBlock(i + 13, j + 49, k + 8, NovaCraftBlocks.cracked_basal_bricks, 0, 2);
		world.setBlock(i + 14, j + 49, k + 8, NovaCraftBlocks.basal_bricks, 0, 2);
		world.setBlock(i + 15, j + 49, k + 8, NovaCraftBlocks.basal_bricks, 0, 2);
		world.setBlock(i + 16, j + 49, k + 8, NovaCraftBlocks.basal_bricks, 0, 2);
		world.setBlock(i + 17, j + 49, k + 8, NovaCraftBlocks.basal_bricks, 0, 2);
		world.setBlock(i + 18, j + 49, k + 8, NovaCraftBlocks.basal_bricks, 0, 2);
		world.setBlock(i + 19, j + 49, k + 8, NovaCraftBlocks.basal_bricks, 0, 2);
		world.setBlock(i + 20, j + 49, k + 8, NovaCraftBlocks.basal_bricks, 0, 2);
		world.setBlock(i + 21, j + 49, k + 8, NovaCraftBlocks.basal_bricks, 0, 2);
		world.setBlock(i + 22, j + 49, k + 8, NovaCraftBlocks.basal_bricks, 0, 2);
		world.setBlock(i + 23, j + 49, k + 8, NovaCraftBlocks.basal_bricks, 0, 2);
		world.setBlock(i + 24, j + 49, k + 8, NovaCraftBlocks.basal_bricks, 0, 2);
		world.setBlock(i + 25, j + 49, k + 8, NovaCraftBlocks.cracked_basal_bricks, 0, 2);
		world.setBlock(i + 26, j + 49, k + 8, NovaCraftBlocks.basal_bricks, 0, 2);
		world.setBlock(i + 27, j + 49, k + 8, NovaCraftBlocks.cracked_basal_bricks, 0, 2);
		world.setBlock(i + 0, j + 49, k + 9, NovaCraftBlocks.basal_bricks, 0, 2);
		world.setBlock(i + 1, j + 49, k + 9, Blocks.air, 0, 2);
		world.setBlock(i + 2, j + 49, k + 9, Blocks.air, 0, 2);
		world.setBlock(i + 3, j + 49, k + 9, Blocks.air, 0, 2);
		world.setBlock(i + 4, j + 49, k + 9, Blocks.air, 0, 2);
		world.setBlock(i + 5, j + 49, k + 9, Blocks.air, 0, 2);
		world.setBlock(i + 6, j + 49, k + 9, NovaCraftBlocks.basal_bricks, 0, 2);
		world.setBlock(i + 7, j + 49, k + 9, NovaCraftBlocks.cracked_basal_bricks, 0, 2);
		world.setBlock(i + 8, j + 49, k + 9, NovaCraftBlocks.cracked_basal_bricks, 0, 2);
		world.setBlock(i + 9, j + 49, k + 9, Blocks.air, 0, 2);
		world.setBlock(i + 10, j + 49, k + 9, Blocks.air, 0, 2);
		world.setBlock(i + 11, j + 49, k + 9, Blocks.air, 0, 2);
		world.setBlock(i + 12, j + 49, k + 9, Blocks.air, 0, 2);
		world.setBlock(i + 13, j + 49, k + 9, NovaCraftBlocks.basal_bricks, 0, 2);
		world.setBlock(i + 14, j + 49, k + 9, NovaCraftBlocks.basal_bricks, 0, 2);
		world.setBlock(i + 15, j + 49, k + 9, NovaCraftBlocks.basal_bricks, 0, 2);
		world.setBlock(i + 16, j + 49, k + 9, NovaCraftBlocks.basal_bricks, 0, 2);
		world.setBlock(i + 17, j + 49, k + 9, NovaCraftBlocks.basal_bricks, 0, 2);
		world.setBlock(i + 18, j + 49, k + 9, NovaCraftBlocks.cracked_basal_bricks, 0, 2);
		world.setBlock(i + 19, j + 49, k + 9, NovaCraftBlocks.basal_bricks, 0, 2);
		world.setBlock(i + 20, j + 49, k + 9, NovaCraftBlocks.basal_bricks, 0, 2);
		world.setBlock(i + 21, j + 49, k + 9, NovaCraftBlocks.basal_bricks, 0, 2);
		world.setBlock(i + 22, j + 49, k + 9, NovaCraftBlocks.basal_bricks, 0, 2);
		world.setBlock(i + 23, j + 49, k + 9, NovaCraftBlocks.basal_bricks, 0, 2);
		world.setBlock(i + 24, j + 49, k + 9, NovaCraftBlocks.basal_bricks, 0, 2);
		world.setBlock(i + 25, j + 49, k + 9, NovaCraftBlocks.cracked_basal_bricks, 0, 2);
		world.setBlock(i + 26, j + 49, k + 9, NovaCraftBlocks.basal_bricks, 0, 2);
		world.setBlock(i + 27, j + 49, k + 9, NovaCraftBlocks.cracked_basal_bricks, 0, 2);
		world.setBlock(i + 0, j + 49, k + 10, NovaCraftBlocks.cracked_basal_bricks, 0, 2);
		world.setBlock(i + 1, j + 49, k + 10, Blocks.air, 0, 2);
		world.setBlock(i + 2, j + 49, k + 10, Blocks.air, 0, 2);
		world.setBlock(i + 3, j + 49, k + 10, Blocks.air, 0, 2);
		world.setBlock(i + 4, j + 49, k + 10, NovaCraftBlocks.basal_brick_stairs, 0, 2);
		world.setBlock(i + 5, j + 49, k + 10, NovaCraftBlocks.basal_scrap, 0, 2);
		world.setBlock(i + 6, j + 49, k + 10, NovaCraftBlocks.basal_scrap, 0, 2);
		world.setBlock(i + 7, j + 49, k + 10, NovaCraftBlocks.basal_scrap, 0, 2);
		world.setBlock(i + 8, j + 49, k + 10, Blocks.air, 0, 2);
		world.setBlock(i + 9, j + 49, k + 10, Blocks.air, 0, 2);
		world.setBlock(i + 10, j + 49, k + 10, Blocks.air, 0, 2);
		world.setBlock(i + 11, j + 49, k + 10, Blocks.air, 0, 2);
		world.setBlock(i + 12, j + 49, k + 10, Blocks.air, 0, 2);
		world.setBlock(i + 13, j + 49, k + 10, NovaCraftBlocks.basal_bricks, 0, 2);
		world.setBlock(i + 14, j + 49, k + 10, NovaCraftBlocks.cracked_basal_bricks, 0, 2);
		world.setBlock(i + 15, j + 49, k + 10, NovaCraftBlocks.cracked_basal_bricks, 0, 2);
		world.setBlock(i + 16, j + 49, k + 10, NovaCraftBlocks.basal_bricks, 0, 2);
		world.setBlock(i + 17, j + 49, k + 10, NovaCraftBlocks.cracked_basal_bricks, 0, 2);
		world.setBlock(i + 18, j + 49, k + 10, NovaCraftBlocks.basal_bricks, 0, 2);
		world.setBlock(i + 19, j + 49, k + 10, NovaCraftBlocks.cracked_basal_bricks, 0, 2);
		world.setBlock(i + 20, j + 49, k + 10, NovaCraftBlocks.cracked_basal_bricks, 0, 2);
		world.setBlock(i + 21, j + 49, k + 10, NovaCraftBlocks.basal_bricks, 0, 2);
		world.setBlock(i + 22, j + 49, k + 10, NovaCraftBlocks.basal_bricks, 0, 2);
		world.setBlock(i + 23, j + 49, k + 10, NovaCraftBlocks.cracked_basal_bricks, 0, 2);
		world.setBlock(i + 24, j + 49, k + 10, NovaCraftBlocks.cracked_basal_bricks, 0, 2);
		world.setBlock(i + 25, j + 49, k + 10, NovaCraftBlocks.basal_bricks, 0, 2);
		world.setBlock(i + 26, j + 49, k + 10, NovaCraftBlocks.basal, 0, 2);
		world.setBlock(i + 27, j + 49, k + 10, NovaCraftBlocks.basal_bricks, 0, 2);
		world.setBlock(i + 0, j + 49, k + 11, Blocks.air, 0, 2);
		world.setBlock(i + 1, j + 49, k + 11, Blocks.air, 0, 2);
		world.setBlock(i + 2, j + 49, k + 11, Blocks.air, 0, 2);
		world.setBlock(i + 3, j + 49, k + 11, Blocks.air, 0, 2);
		world.setBlock(i + 4, j + 49, k + 11, Blocks.air, 0, 2);
		world.setBlock(i + 5, j + 49, k + 11, Blocks.air, 0, 2);
		world.setBlock(i + 6, j + 49, k + 11, Blocks.air, 0, 2);
		world.setBlock(i + 7, j + 49, k + 11, Blocks.air, 0, 2);
		world.setBlock(i + 8, j + 49, k + 11, Blocks.air, 0, 2);
		world.setBlock(i + 9, j + 49, k + 11, Blocks.air, 0, 2);
		world.setBlock(i + 10, j + 49, k + 11, Blocks.air, 0, 2);
		world.setBlock(i + 11, j + 49, k + 11, Blocks.air, 0, 2);
		world.setBlock(i + 12, j + 49, k + 11, Blocks.air, 0, 2);
		world.setBlock(i + 13, j + 49, k + 11, Blocks.air, 0, 2);
		world.setBlock(i + 14, j + 49, k + 11, NovaCraftBlocks.basal_bricks, 0, 2);
		world.setBlock(i + 15, j + 49, k + 11, Blocks.air, 0, 2);
		world.setBlock(i + 16, j + 49, k + 11, Blocks.air, 0, 2);
		world.setBlock(i + 17, j + 49, k + 11, Blocks.air, 0, 2);
		world.setBlock(i + 18, j + 49, k + 11, Blocks.air, 0, 2);
		world.setBlock(i + 19, j + 49, k + 11, Blocks.air, 0, 2);
		world.setBlock(i + 20, j + 49, k + 11, NovaCraftBlocks.cracked_basal_bricks, 0, 2);
		world.setBlock(i + 21, j + 49, k + 11, NovaCraftBlocks.cracked_basal_bricks, 0, 2);
		world.setBlock(i + 22, j + 49, k + 11, NovaCraftBlocks.basal_bricks, 0, 2);
		world.setBlock(i + 23, j + 49, k + 11, Blocks.air, 0, 2);
		world.setBlock(i + 24, j + 49, k + 11, Blocks.air, 0, 2);
		world.setBlock(i + 25, j + 49, k + 11, Blocks.air, 0, 2);
		world.setBlock(i + 26, j + 49, k + 11, Blocks.air, 0, 2);
		world.setBlock(i + 27, j + 49, k + 11, NovaCraftBlocks.basal_bricks, 0, 2);
		world.setBlock(i + 0, j + 49, k + 12, Blocks.air, 0, 2);
		world.setBlock(i + 1, j + 49, k + 12, Blocks.air, 0, 2);
		world.setBlock(i + 2, j + 49, k + 12, Blocks.air, 0, 2);
		world.setBlock(i + 3, j + 49, k + 12, Blocks.air, 0, 2);
		world.setBlock(i + 4, j + 49, k + 12, Blocks.air, 0, 2);
		world.setBlock(i + 5, j + 49, k + 12, Blocks.air, 0, 2);
		world.setBlock(i + 6, j + 49, k + 12, Blocks.air, 0, 2);
		world.setBlock(i + 7, j + 49, k + 12, Blocks.air, 0, 2);
		world.setBlock(i + 8, j + 49, k + 12, Blocks.air, 0, 2);
		world.setBlock(i + 9, j + 49, k + 12, Blocks.air, 0, 2);
		world.setBlock(i + 10, j + 49, k + 12, Blocks.air, 0, 2);
		world.setBlock(i + 11, j + 49, k + 12, Blocks.air, 0, 2);
		world.setBlock(i + 12, j + 49, k + 12, Blocks.air, 0, 2);
		world.setBlock(i + 13, j + 49, k + 12, Blocks.air, 0, 2);
		world.setBlock(i + 14, j + 49, k + 12, NovaCraftBlocks.basal_bricks, 0, 2);
		world.setBlock(i + 15, j + 49, k + 12, Blocks.air, 0, 2);
		world.setBlock(i + 16, j + 49, k + 12, Blocks.air, 0, 2);
		world.setBlock(i + 17, j + 49, k + 12, Blocks.air, 0, 2);
		world.setBlock(i + 18, j + 49, k + 12, NovaCraftBlocks.basal_brick_stairs, 0, 2);
		world.setBlock(i + 19, j + 49, k + 12, NovaCraftBlocks.basal_scrap, 0, 2);
		world.setBlock(i + 20, j + 49, k + 12, NovaCraftBlocks.basal_scrap, 0, 2);
		world.setBlock(i + 21, j + 49, k + 12, NovaCraftBlocks.basal_scrap, 0, 2);
		world.setBlock(i + 22, j + 49, k + 12, Blocks.air, 0, 2);
		world.setBlock(i + 23, j + 49, k + 12, Blocks.air, 0, 2);
		world.setBlock(i + 24, j + 49, k + 12, Blocks.air, 0, 2);
		world.setBlock(i + 25, j + 49, k + 12, Blocks.air, 0, 2);
		world.setBlock(i + 26, j + 49, k + 12, Blocks.air, 0, 2);
		world.setBlock(i + 27, j + 49, k + 12, NovaCraftBlocks.basal_bricks, 0, 2);
		world.setBlock(i + 0, j + 50, k + 0, Blocks.air, 0, 2);
		world.setBlock(i + 1, j + 50, k + 0, Blocks.air, 0, 2);
		world.setBlock(i + 2, j + 50, k + 0, Blocks.air, 0, 2);
		world.setBlock(i + 3, j + 50, k + 0, Blocks.air, 0, 2);
		world.setBlock(i + 4, j + 50, k + 0, Blocks.air, 0, 2);
		world.setBlock(i + 5, j + 50, k + 0, Blocks.air, 0, 2);
		world.setBlock(i + 6, j + 50, k + 0, Blocks.air, 0, 2);
		world.setBlock(i + 7, j + 50, k + 0, Blocks.air, 0, 2);
		world.setBlock(i + 8, j + 50, k + 0, Blocks.air, 0, 2);
		world.setBlock(i + 9, j + 50, k + 0, Blocks.air, 0, 2);
		world.setBlock(i + 10, j + 50, k + 0, Blocks.air, 0, 2);
		world.setBlock(i + 11, j + 50, k + 0, Blocks.air, 0, 2);
		world.setBlock(i + 12, j + 50, k + 0, Blocks.air, 0, 2);
		world.setBlock(i + 13, j + 50, k + 0, Blocks.air, 0, 2);
		world.setBlock(i + 14, j + 50, k + 0, Blocks.air, 0, 2);
		world.setBlock(i + 15, j + 50, k + 0, Blocks.air, 0, 2);
		world.setBlock(i + 16, j + 50, k + 0, Blocks.air, 0, 2);
		world.setBlock(i + 17, j + 50, k + 0, Blocks.air, 0, 2);
		world.setBlock(i + 18, j + 50, k + 0, Blocks.air, 0, 2);
		world.setBlock(i + 19, j + 50, k + 0, Blocks.air, 0, 2);
		world.setBlock(i + 20, j + 50, k + 0, Blocks.air, 0, 2);
		world.setBlock(i + 21, j + 50, k + 0, Blocks.air, 0, 2);
		world.setBlock(i + 22, j + 50, k + 0, Blocks.air, 0, 2);
		world.setBlock(i + 23, j + 50, k + 0, Blocks.air, 0, 2);
		world.setBlock(i + 24, j + 50, k + 0, Blocks.air, 0, 2);
		world.setBlock(i + 25, j + 50, k + 0, Blocks.air, 0, 2);
		world.setBlock(i + 26, j + 50, k + 0, Blocks.air, 0, 2);
		world.setBlock(i + 27, j + 50, k + 0, Blocks.air, 0, 2);
		world.setBlock(i + 0, j + 50, k + 1, NovaCraftBlocks.basal_bricks, 0, 2);
		world.setBlock(i + 1, j + 50, k + 1, NovaCraftBlocks.cracked_basal_bricks, 0, 2);
		world.setBlock(i + 2, j + 50, k + 1, Blocks.air, 0, 2);
		world.setBlock(i + 3, j + 50, k + 1, Blocks.air, 0, 2);
		world.setBlock(i + 4, j + 50, k + 1, NovaCraftBlocks.cracked_basal_bricks, 0, 2);
		world.setBlock(i + 5, j + 50, k + 1, NovaCraftBlocks.basal_bricks, 0, 2);
		world.setBlock(i + 6, j + 50, k + 1, Blocks.air, 0, 2);
		world.setBlock(i + 7, j + 50, k + 1, Blocks.air, 0, 2);
		world.setBlock(i + 8, j + 50, k + 1, NovaCraftBlocks.cracked_basal_bricks, 0, 2);
		world.setBlock(i + 9, j + 50, k + 1, NovaCraftBlocks.cracked_basal_bricks, 0, 2);
		world.setBlock(i + 10, j + 50, k + 1, Blocks.air, 0, 2);
		world.setBlock(i + 11, j + 50, k + 1, Blocks.air, 0, 2);
		world.setBlock(i + 12, j + 50, k + 1, NovaCraftBlocks.basal_bricks, 0, 2);
		world.setBlock(i + 13, j + 50, k + 1, NovaCraftBlocks.basal_bricks, 0, 2);
		world.setBlock(i + 14, j + 50, k + 1, Blocks.air, 0, 2);
		world.setBlock(i + 15, j + 50, k + 1, Blocks.air, 0, 2);
		world.setBlock(i + 16, j + 50, k + 1, Blocks.air, 0, 2);
		world.setBlock(i + 17, j + 50, k + 1, Blocks.air, 0, 2);
		world.setBlock(i + 18, j + 50, k + 1, Blocks.air, 0, 2);
		world.setBlock(i + 19, j + 50, k + 1, Blocks.air, 0, 2);
		world.setBlock(i + 20, j + 50, k + 1, Blocks.air, 0, 2);
		world.setBlock(i + 21, j + 50, k + 1, Blocks.air, 0, 2);
		world.setBlock(i + 22, j + 50, k + 1, Blocks.air, 0, 2);
		world.setBlock(i + 23, j + 50, k + 1, Blocks.air, 0, 2);
		world.setBlock(i + 24, j + 50, k + 1, Blocks.air, 0, 2);
		world.setBlock(i + 25, j + 50, k + 1, Blocks.air, 0, 2);
		world.setBlock(i + 26, j + 50, k + 1, Blocks.air, 0, 2);
		world.setBlock(i + 27, j + 50, k + 1, Blocks.air, 0, 2);
		world.setBlock(i + 0, j + 50, k + 2, NovaCraftBlocks.cracked_basal_bricks, 0, 2);
		world.setBlock(i + 1, j + 50, k + 2, NovaCraftBlocks.basal_bricks, 0, 2);
		world.setBlock(i + 2, j + 50, k + 2, Blocks.air, 0, 2);
		world.setBlock(i + 3, j + 50, k + 2, Blocks.air, 0, 2);
		world.setBlock(i + 4, j + 50, k + 2, NovaCraftBlocks.basal_bricks, 0, 2);
		world.setBlock(i + 5, j + 50, k + 2, NovaCraftBlocks.cracked_basal_bricks, 0, 2);
		world.setBlock(i + 6, j + 50, k + 2, Blocks.air, 0, 2);
		world.setBlock(i + 7, j + 50, k + 2, Blocks.air, 0, 2);
		world.setBlock(i + 8, j + 50, k + 2, NovaCraftBlocks.basal_bricks, 0, 2);
		world.setBlock(i + 9, j + 50, k + 2, NovaCraftBlocks.cracked_basal_bricks, 0, 2);
		world.setBlock(i + 10, j + 50, k + 2, Blocks.air, 0, 2);
		world.setBlock(i + 11, j + 50, k + 2, Blocks.air, 0, 2);
		world.setBlock(i + 12, j + 50, k + 2, NovaCraftBlocks.basal_bricks, 0, 2);
		world.setBlock(i + 13, j + 50, k + 2, NovaCraftBlocks.cracked_basal_bricks, 0, 2);
		world.setBlock(i + 14, j + 50, k + 2, Blocks.air, 0, 2);
		world.setBlock(i + 15, j + 50, k + 2, Blocks.air, 0, 2);
		world.setBlock(i + 16, j + 50, k + 2, Blocks.air, 0, 2);
		world.setBlock(i + 17, j + 50, k + 2, Blocks.air, 0, 2);
		world.setBlock(i + 18, j + 50, k + 2, Blocks.air, 0, 2);
		world.setBlock(i + 19, j + 50, k + 2, Blocks.air, 0, 2);
		world.setBlock(i + 20, j + 50, k + 2, Blocks.air, 0, 2);
		world.setBlock(i + 21, j + 50, k + 2, Blocks.air, 0, 2);
		world.setBlock(i + 22, j + 50, k + 2, Blocks.air, 0, 2);
		world.setBlock(i + 23, j + 50, k + 2, Blocks.air, 0, 2);
		world.setBlock(i + 24, j + 50, k + 2, Blocks.air, 0, 2);
		world.setBlock(i + 25, j + 50, k + 2, Blocks.air, 0, 2);
		world.setBlock(i + 26, j + 50, k + 2, Blocks.air, 0, 2);
		world.setBlock(i + 27, j + 50, k + 2, Blocks.air, 0, 2);
		world.setBlock(i + 0, j + 50, k + 3, NovaCraftBlocks.cracked_basal_bricks, 0, 2);
		world.setBlock(i + 1, j + 50, k + 3, NovaCraftBlocks.basal_bricks, 0, 2);
		world.setBlock(i + 2, j + 50, k + 3, NovaCraftBlocks.basal_bricks, 0, 2);
		world.setBlock(i + 3, j + 50, k + 3, NovaCraftBlocks.cracked_basal_bricks, 0, 2);
		world.setBlock(i + 4, j + 50, k + 3, NovaCraftBlocks.cracked_basal_bricks, 0, 2);
		world.setBlock(i + 5, j + 50, k + 3, NovaCraftBlocks.basal_bricks, 0, 2);
		world.setBlock(i + 6, j + 50, k + 3, NovaCraftBlocks.basal_bricks, 0, 2);
		world.setBlock(i + 7, j + 50, k + 3, NovaCraftBlocks.cracked_basal_bricks, 0, 2);
		world.setBlock(i + 8, j + 50, k + 3, NovaCraftBlocks.basal_bricks, 0, 2);
		world.setBlock(i + 9, j + 50, k + 3, NovaCraftBlocks.cracked_basal_bricks, 0, 2);
		world.setBlock(i + 10, j + 50, k + 3, NovaCraftBlocks.basal_bricks, 0, 2);
		world.setBlock(i + 11, j + 50, k + 3, NovaCraftBlocks.basal_bricks, 0, 2);
		world.setBlock(i + 12, j + 50, k + 3, NovaCraftBlocks.basal_bricks, 0, 2);
		world.setBlock(i + 13, j + 50, k + 3, NovaCraftBlocks.basal_bricks, 0, 2);
		world.setBlock(i + 14, j + 50, k + 3, NovaCraftBlocks.cracked_basal_bricks, 0, 2);
		world.setBlock(i + 15, j + 50, k + 3, NovaCraftBlocks.basal_bricks, 0, 2);
		world.setBlock(i + 16, j + 50, k + 3, Blocks.air, 0, 2);
		world.setBlock(i + 17, j + 50, k + 3, Blocks.air, 0, 2);
		world.setBlock(i + 18, j + 50, k + 3, NovaCraftBlocks.cracked_basal_bricks, 0, 2);
		world.setBlock(i + 19, j + 50, k + 3, NovaCraftBlocks.cracked_basal_bricks, 0, 2);
		world.setBlock(i + 20, j + 50, k + 3, Blocks.air, 0, 2);
		world.setBlock(i + 21, j + 50, k + 3, Blocks.air, 0, 2);
		world.setBlock(i + 22, j + 50, k + 3, NovaCraftBlocks.cracked_basal_bricks, 0, 2);
		world.setBlock(i + 23, j + 50, k + 3, NovaCraftBlocks.cracked_basal_bricks, 0, 2);
		world.setBlock(i + 24, j + 50, k + 3, Blocks.air, 0, 2);
		world.setBlock(i + 25, j + 50, k + 3, Blocks.air, 0, 2);
		world.setBlock(i + 26, j + 50, k + 3, NovaCraftBlocks.basal_bricks, 0, 2);
		world.setBlock(i + 27, j + 50, k + 3, NovaCraftBlocks.basal_bricks, 0, 2);
		world.setBlock(i + 0, j + 50, k + 4, NovaCraftBlocks.basal_bricks, 0, 2);
		world.setBlock(i + 1, j + 50, k + 4, NovaCraftBlocks.basal_bricks, 0, 2);
		world.setBlock(i + 2, j + 50, k + 4, NovaCraftBlocks.basal_bricks, 0, 2);
		world.setBlock(i + 3, j + 50, k + 4, NovaCraftBlocks.cracked_basal_bricks, 0, 2);
		world.setBlock(i + 4, j + 50, k + 4, NovaCraftBlocks.basal_bricks, 0, 2);
		world.setBlock(i + 5, j + 50, k + 4, NovaCraftBlocks.basal_bricks, 0, 2);
		world.setBlock(i + 6, j + 50, k + 4, NovaCraftBlocks.basal_bricks, 0, 2);
		world.setBlock(i + 7, j + 50, k + 4, NovaCraftBlocks.basal_bricks, 0, 2);
		world.setBlock(i + 8, j + 50, k + 4, NovaCraftBlocks.basal_bricks, 0, 2);
		world.setBlock(i + 9, j + 50, k + 4, NovaCraftBlocks.cracked_basal_bricks, 0, 2);
		world.setBlock(i + 10, j + 50, k + 4, NovaCraftBlocks.cracked_basal_bricks, 0, 2);
		world.setBlock(i + 11, j + 50, k + 4, NovaCraftBlocks.basal_bricks, 0, 2);
		world.setBlock(i + 12, j + 50, k + 4, NovaCraftBlocks.basal_bricks, 0, 2);
		world.setBlock(i + 13, j + 50, k + 4, NovaCraftBlocks.basal_bricks, 0, 2);
		world.setBlock(i + 14, j + 50, k + 4, NovaCraftBlocks.cracked_basal_bricks, 0, 2);
		world.setBlock(i + 15, j + 50, k + 4, NovaCraftBlocks.basal_bricks, 0, 2);
		world.setBlock(i + 16, j + 50, k + 4, Blocks.air, 0, 2);
		world.setBlock(i + 17, j + 50, k + 4, Blocks.air, 0, 2);
		world.setBlock(i + 18, j + 50, k + 4, NovaCraftBlocks.basal_bricks, 0, 2);
		world.setBlock(i + 19, j + 50, k + 4, NovaCraftBlocks.cracked_basal_bricks, 0, 2);
		world.setBlock(i + 20, j + 50, k + 4, Blocks.air, 0, 2);
		world.setBlock(i + 21, j + 50, k + 4, Blocks.air, 0, 2);
		world.setBlock(i + 22, j + 50, k + 4, NovaCraftBlocks.basal_bricks, 0, 2);
		world.setBlock(i + 23, j + 50, k + 4, NovaCraftBlocks.basal_bricks, 0, 2);
		world.setBlock(i + 24, j + 50, k + 4, Blocks.air, 0, 2);
		world.setBlock(i + 25, j + 50, k + 4, Blocks.air, 0, 2);
		world.setBlock(i + 26, j + 50, k + 4, NovaCraftBlocks.basal_bricks, 0, 2);
		world.setBlock(i + 27, j + 50, k + 4, NovaCraftBlocks.cracked_basal_bricks, 0, 2);
		world.setBlock(i + 0, j + 50, k + 5, NovaCraftBlocks.basal_bricks, 0, 2);
		world.setBlock(i + 1, j + 50, k + 5, NovaCraftBlocks.cracked_basal_bricks, 0, 2);
		world.setBlock(i + 2, j + 50, k + 5, NovaCraftBlocks.cracked_basal_bricks, 0, 2);
		world.setBlock(i + 3, j + 50, k + 5, NovaCraftBlocks.cracked_basal_bricks, 0, 2);
		world.setBlock(i + 4, j + 50, k + 5, NovaCraftBlocks.basal_bricks, 0, 2);
		world.setBlock(i + 5, j + 50, k + 5, NovaCraftBlocks.cracked_basal_bricks, 0, 2);
		world.setBlock(i + 6, j + 50, k + 5, NovaCraftBlocks.basal_bricks, 0, 2);
		world.setBlock(i + 7, j + 50, k + 5, NovaCraftBlocks.basal_bricks, 0, 2);
		world.setBlock(i + 8, j + 50, k + 5, NovaCraftBlocks.basal_bricks, 0, 2);
		world.setBlock(i + 9, j + 50, k + 5, NovaCraftBlocks.basal_bricks, 0, 2);
		world.setBlock(i + 10, j + 50, k + 5, NovaCraftBlocks.cracked_basal_bricks, 0, 2);
		world.setBlock(i + 11, j + 50, k + 5, NovaCraftBlocks.basal_bricks, 0, 2);
		world.setBlock(i + 12, j + 50, k + 5, NovaCraftBlocks.basal_bricks, 0, 2);
		world.setBlock(i + 13, j + 50, k + 5, NovaCraftBlocks.basal_bricks, 0, 2);
		world.setBlock(i + 14, j + 50, k + 5, NovaCraftBlocks.basal_bricks, 0, 2);
		world.setBlock(i + 15, j + 50, k + 5, NovaCraftBlocks.cracked_basal_bricks, 0, 2);
		world.setBlock(i + 16, j + 50, k + 5, NovaCraftBlocks.cracked_basal_bricks, 0, 2);
		world.setBlock(i + 17, j + 50, k + 5, NovaCraftBlocks.basal_bricks, 0, 2);
		world.setBlock(i + 18, j + 50, k + 5, NovaCraftBlocks.basal_bricks, 0, 2);
		world.setBlock(i + 19, j + 50, k + 5, NovaCraftBlocks.cracked_basal_bricks, 0, 2);
		world.setBlock(i + 20, j + 50, k + 5, NovaCraftBlocks.basal_bricks, 0, 2);
		world.setBlock(i + 21, j + 50, k + 5, NovaCraftBlocks.cracked_basal_bricks, 0, 2);
		world.setBlock(i + 22, j + 50, k + 5, NovaCraftBlocks.basal_bricks, 0, 2);
		world.setBlock(i + 23, j + 50, k + 5, NovaCraftBlocks.basal_bricks, 0, 2);
		world.setBlock(i + 24, j + 50, k + 5, NovaCraftBlocks.basal_bricks, 0, 2);
		world.setBlock(i + 25, j + 50, k + 5, NovaCraftBlocks.cracked_basal_bricks, 0, 2);
		world.setBlock(i + 26, j + 50, k + 5, NovaCraftBlocks.basal_bricks, 0, 2);
		world.setBlock(i + 27, j + 50, k + 5, NovaCraftBlocks.basal_bricks, 0, 2);
		world.setBlock(i + 0, j + 50, k + 6, NovaCraftBlocks.basal_bricks, 0, 2);
		world.setBlock(i + 1, j + 50, k + 6, NovaCraftBlocks.cracked_basal_bricks, 0, 2);
		world.setBlock(i + 2, j + 50, k + 6, NovaCraftBlocks.basal_bricks, 0, 2);
		world.setBlock(i + 3, j + 50, k + 6, NovaCraftBlocks.basal_bricks, 0, 2);
		world.setBlock(i + 4, j + 50, k + 6, NovaCraftBlocks.basal_bricks, 0, 2);
		world.setBlock(i + 5, j + 50, k + 6, NovaCraftBlocks.cracked_basal_bricks, 0, 2);
		world.setBlock(i + 6, j + 50, k + 6, NovaCraftBlocks.cracked_basal_bricks, 0, 2);
		world.setBlock(i + 7, j + 50, k + 6, NovaCraftBlocks.cracked_basal_bricks, 0, 2);
		world.setBlock(i + 8, j + 50, k + 6, NovaCraftBlocks.cracked_basal_bricks, 0, 2);
		world.setBlock(i + 9, j + 50, k + 6, NovaCraftBlocks.cracked_basal_bricks, 0, 2);
		world.setBlock(i + 10, j + 50, k + 6, NovaCraftBlocks.basal_bricks, 0, 2);
		world.setBlock(i + 11, j + 50, k + 6, NovaCraftBlocks.cracked_basal_bricks, 0, 2);
		world.setBlock(i + 12, j + 50, k + 6, NovaCraftBlocks.basal_bricks, 0, 2);
		world.setBlock(i + 13, j + 50, k + 6, NovaCraftBlocks.cracked_basal_bricks, 0, 2);
		world.setBlock(i + 14, j + 50, k + 6, NovaCraftBlocks.basal_bricks, 0, 2);
		world.setBlock(i + 15, j + 50, k + 6, NovaCraftBlocks.cracked_basal_bricks, 0, 2);
		world.setBlock(i + 16, j + 50, k + 6, NovaCraftBlocks.basal_bricks, 0, 2);
		world.setBlock(i + 17, j + 50, k + 6, NovaCraftBlocks.cracked_basal_bricks, 0, 2);
		world.setBlock(i + 18, j + 50, k + 6, NovaCraftBlocks.basal_bricks, 0, 2);
		world.setBlock(i + 19, j + 50, k + 6, NovaCraftBlocks.basal_bricks, 0, 2);
		world.setBlock(i + 20, j + 50, k + 6, NovaCraftBlocks.basal_bricks, 0, 2);
		world.setBlock(i + 21, j + 50, k + 6, NovaCraftBlocks.basal_bricks, 0, 2);
		world.setBlock(i + 22, j + 50, k + 6, NovaCraftBlocks.basal_bricks, 0, 2);
		world.setBlock(i + 23, j + 50, k + 6, NovaCraftBlocks.cracked_basal_bricks, 0, 2);
		world.setBlock(i + 24, j + 50, k + 6, NovaCraftBlocks.cracked_basal_bricks, 0, 2);
		world.setBlock(i + 25, j + 50, k + 6, NovaCraftBlocks.basal_bricks, 0, 2);
		world.setBlock(i + 26, j + 50, k + 6, NovaCraftBlocks.basal_bricks, 0, 2);
		world.setBlock(i + 27, j + 50, k + 6, NovaCraftBlocks.cracked_basal_bricks, 0, 2);
		world.setBlock(i + 0, j + 50, k + 7, NovaCraftBlocks.cracked_basal_bricks, 0, 2);
		world.setBlock(i + 1, j + 50, k + 7, NovaCraftBlocks.cracked_basal_bricks, 0, 2);
		world.setBlock(i + 2, j + 50, k + 7, NovaCraftBlocks.basal_bricks, 0, 2);
		world.setBlock(i + 3, j + 50, k + 7, NovaCraftBlocks.basal_bricks, 0, 2);
		world.setBlock(i + 4, j + 50, k + 7, NovaCraftBlocks.basal_bricks, 0, 2);
		world.setBlock(i + 5, j + 50, k + 7, NovaCraftBlocks.cracked_basal_bricks, 0, 2);
		world.setBlock(i + 6, j + 50, k + 7, NovaCraftBlocks.basal_bricks, 0, 2);
		world.setBlock(i + 7, j + 50, k + 7, NovaCraftBlocks.basal_bricks, 0, 2);
		world.setBlock(i + 8, j + 50, k + 7, NovaCraftBlocks.cracked_basal_bricks, 0, 2);
		world.setBlock(i + 9, j + 50, k + 7, NovaCraftBlocks.basal_bricks, 0, 2);
		world.setBlock(i + 10, j + 50, k + 7, NovaCraftBlocks.cracked_basal_bricks, 0, 2);
		world.setBlock(i + 11, j + 50, k + 7, NovaCraftBlocks.basal_bricks, 0, 2);
		world.setBlock(i + 12, j + 50, k + 7, NovaCraftBlocks.cracked_basal_bricks, 0, 2);
		world.setBlock(i + 13, j + 50, k + 7, NovaCraftBlocks.basal_bricks, 0, 2);
		world.setBlock(i + 14, j + 50, k + 7, NovaCraftBlocks.cracked_basal_bricks, 0, 2);
		world.setBlock(i + 15, j + 50, k + 7, NovaCraftBlocks.basal_bricks, 0, 2);
		world.setBlock(i + 16, j + 50, k + 7, NovaCraftBlocks.basal_bricks, 0, 2);
		world.setBlock(i + 17, j + 50, k + 7, NovaCraftBlocks.basal_bricks, 0, 2);
		world.setBlock(i + 18, j + 50, k + 7, NovaCraftBlocks.basal_bricks, 0, 2);
		world.setBlock(i + 19, j + 50, k + 7, NovaCraftBlocks.cracked_basal_bricks, 0, 2);
		world.setBlock(i + 20, j + 50, k + 7, NovaCraftBlocks.basal_bricks, 0, 2);
		world.setBlock(i + 21, j + 50, k + 7, NovaCraftBlocks.cracked_basal_bricks, 0, 2);
		world.setBlock(i + 22, j + 50, k + 7, NovaCraftBlocks.cracked_basal_bricks, 0, 2);
		world.setBlock(i + 23, j + 50, k + 7, NovaCraftBlocks.basal_bricks, 0, 2);
		world.setBlock(i + 24, j + 50, k + 7, NovaCraftBlocks.cracked_basal_bricks, 0, 2);
		world.setBlock(i + 25, j + 50, k + 7, NovaCraftBlocks.cracked_basal_bricks, 0, 2);
		world.setBlock(i + 26, j + 50, k + 7, NovaCraftBlocks.basal_bricks, 0, 2);
		world.setBlock(i + 27, j + 50, k + 7, NovaCraftBlocks.basal_bricks, 0, 2);
		world.setBlock(i + 0, j + 50, k + 8, NovaCraftBlocks.basal_bricks, 0, 2);
		world.setBlock(i + 1, j + 50, k + 8, NovaCraftBlocks.basal_bricks, 0, 2);
		world.setBlock(i + 2, j + 50, k + 8, NovaCraftBlocks.basal_bricks, 0, 2);
		world.setBlock(i + 3, j + 50, k + 8, NovaCraftBlocks.basal_bricks, 0, 2);
		world.setBlock(i + 4, j + 50, k + 8, NovaCraftBlocks.cracked_basal_bricks, 0, 2);
		world.setBlock(i + 5, j + 50, k + 8, NovaCraftBlocks.basal_bricks, 0, 2);
		world.setBlock(i + 6, j + 50, k + 8, NovaCraftBlocks.basal_bricks, 0, 2);
		world.setBlock(i + 7, j + 50, k + 8, NovaCraftBlocks.cracked_basal_bricks, 0, 2);
		world.setBlock(i + 8, j + 50, k + 8, NovaCraftBlocks.basal_bricks, 0, 2);
		world.setBlock(i + 9, j + 50, k + 8, NovaCraftBlocks.basal_bricks, 0, 2);
		world.setBlock(i + 10, j + 50, k + 8, NovaCraftBlocks.basal_bricks, 0, 2);
		world.setBlock(i + 11, j + 50, k + 8, NovaCraftBlocks.basal_bricks, 0, 2);
		world.setBlock(i + 12, j + 50, k + 8, NovaCraftBlocks.basal_bricks, 0, 2);
		world.setBlock(i + 13, j + 50, k + 8, NovaCraftBlocks.basal_bricks, 0, 2);
		world.setBlock(i + 14, j + 50, k + 8, NovaCraftBlocks.basal_bricks, 0, 2);
		world.setBlock(i + 15, j + 50, k + 8, NovaCraftBlocks.basal_bricks, 0, 2);
		world.setBlock(i + 16, j + 50, k + 8, NovaCraftBlocks.basal_bricks, 0, 2);
		world.setBlock(i + 17, j + 50, k + 8, NovaCraftBlocks.cracked_basal_bricks, 0, 2);
		world.setBlock(i + 18, j + 50, k + 8, NovaCraftBlocks.cracked_basal_bricks, 0, 2);
		world.setBlock(i + 19, j + 50, k + 8, NovaCraftBlocks.cracked_basal_bricks, 0, 2);
		world.setBlock(i + 20, j + 50, k + 8, NovaCraftBlocks.cracked_basal_bricks, 0, 2);
		world.setBlock(i + 21, j + 50, k + 8, NovaCraftBlocks.cracked_basal_bricks, 0, 2);
		world.setBlock(i + 22, j + 50, k + 8, NovaCraftBlocks.cracked_basal_bricks, 0, 2);
		world.setBlock(i + 23, j + 50, k + 8, NovaCraftBlocks.cracked_basal_bricks, 0, 2);
		world.setBlock(i + 24, j + 50, k + 8, NovaCraftBlocks.basal_bricks, 0, 2);
		world.setBlock(i + 25, j + 50, k + 8, NovaCraftBlocks.cracked_basal_bricks, 0, 2);
		world.setBlock(i + 26, j + 50, k + 8, NovaCraftBlocks.basal_bricks, 0, 2);
		world.setBlock(i + 27, j + 50, k + 8, NovaCraftBlocks.basal_bricks, 0, 2);
		world.setBlock(i + 0, j + 50, k + 9, NovaCraftBlocks.basal_bricks, 0, 2);
		world.setBlock(i + 1, j + 50, k + 9, NovaCraftBlocks.cracked_basal_bricks, 0, 2);
		world.setBlock(i + 2, j + 50, k + 9, NovaCraftBlocks.cracked_basal_bricks, 0, 2);
		world.setBlock(i + 3, j + 50, k + 9, NovaCraftBlocks.basal_bricks, 0, 2);
		world.setBlock(i + 4, j + 50, k + 9, NovaCraftBlocks.basal_bricks, 0, 2);
		world.setBlock(i + 5, j + 50, k + 9, NovaCraftBlocks.basal_bricks, 0, 2);
		world.setBlock(i + 6, j + 50, k + 9, NovaCraftBlocks.basal_scrap, 0, 2);
		world.setBlock(i + 7, j + 50, k + 9, NovaCraftBlocks.basal_scrap, 0, 2);
		world.setBlock(i + 8, j + 50, k + 9, NovaCraftBlocks.cracked_basal_bricks, 0, 2);
		world.setBlock(i + 9, j + 50, k + 9, NovaCraftBlocks.basal_bricks, 0, 2);
		world.setBlock(i + 10, j + 50, k + 9, Blocks.air, 0, 2);
		world.setBlock(i + 11, j + 50, k + 9, NovaCraftBlocks.cracked_basal_bricks, 0, 2);
		world.setBlock(i + 12, j + 50, k + 9, NovaCraftBlocks.basal_bricks, 0, 2);
		world.setBlock(i + 13, j + 50, k + 9, NovaCraftBlocks.basal_bricks, 0, 2);
		world.setBlock(i + 14, j + 50, k + 9, NovaCraftBlocks.cracked_basal_bricks, 0, 2);
		world.setBlock(i + 15, j + 50, k + 9, NovaCraftBlocks.basal_bricks, 0, 2);
		world.setBlock(i + 16, j + 50, k + 9, NovaCraftBlocks.basal_bricks, 0, 2);
		world.setBlock(i + 17, j + 50, k + 9, NovaCraftBlocks.cracked_basal_bricks, 0, 2);
		world.setBlock(i + 18, j + 50, k + 9, NovaCraftBlocks.cracked_basal_bricks, 0, 2);
		world.setBlock(i + 19, j + 50, k + 9, NovaCraftBlocks.cracked_basal_bricks, 0, 2);
		world.setBlock(i + 20, j + 50, k + 9, NovaCraftBlocks.basal_bricks, 0, 2);
		world.setBlock(i + 21, j + 50, k + 9, NovaCraftBlocks.basal_bricks, 0, 2);
		world.setBlock(i + 22, j + 50, k + 9, NovaCraftBlocks.basal_bricks, 0, 2);
		world.setBlock(i + 23, j + 50, k + 9, NovaCraftBlocks.basal_bricks, 0, 2);
		world.setBlock(i + 24, j + 50, k + 9, NovaCraftBlocks.basal_bricks, 0, 2);
		world.setBlock(i + 25, j + 50, k + 9, NovaCraftBlocks.cracked_basal_bricks, 0, 2);
		world.setBlock(i + 26, j + 50, k + 9, NovaCraftBlocks.basal_bricks, 0, 2);
		world.setBlock(i + 27, j + 50, k + 9, NovaCraftBlocks.basal_bricks, 0, 2);
		world.setBlock(i + 0, j + 50, k + 10, NovaCraftBlocks.basal_bricks, 0, 2);
		world.setBlock(i + 1, j + 50, k + 10, Blocks.air, 0, 2);
		world.setBlock(i + 2, j + 50, k + 10, Blocks.air, 0, 2);
		world.setBlock(i + 3, j + 50, k + 10, Blocks.air, 0, 2);
		world.setBlock(i + 4, j + 50, k + 10, Blocks.air, 0, 2);
		world.setBlock(i + 5, j + 50, k + 10, NovaCraftBlocks.basal_brick_stairs, 0, 2);
		world.setBlock(i + 6, j + 50, k + 10, NovaCraftBlocks.basal_scrap, 0, 2);
		world.setBlock(i + 7, j + 50, k + 10, NovaCraftBlocks.basal_scrap, 0, 2);
		world.setBlock(i + 8, j + 50, k + 10, NovaCraftBlocks.basal_brick_stairs, 1, 2);
		world.setBlock(i + 9, j + 50, k + 10, Blocks.air, 0, 2);
		world.setBlock(i + 10, j + 50, k + 10, Blocks.air, 0, 2);
		world.setBlock(i + 11, j + 50, k + 10, Blocks.air, 0, 2);
		world.setBlock(i + 12, j + 50, k + 10, Blocks.air, 0, 2);
		world.setBlock(i + 13, j + 50, k + 10, NovaCraftBlocks.cracked_basal_bricks, 0, 2);
		world.setBlock(i + 14, j + 50, k + 10, NovaCraftBlocks.cracked_basal_bricks, 0, 2);
		world.setBlock(i + 15, j + 50, k + 10, NovaCraftBlocks.basal_bricks, 0, 2);
		world.setBlock(i + 16, j + 50, k + 10, NovaCraftBlocks.basal_bricks, 0, 2);
		world.setBlock(i + 17, j + 50, k + 10, NovaCraftBlocks.cracked_basal_bricks, 0, 2);
		world.setBlock(i + 18, j + 50, k + 10, NovaCraftBlocks.cracked_basal_bricks, 0, 2);
		world.setBlock(i + 19, j + 50, k + 10, NovaCraftBlocks.cracked_basal_bricks, 0, 2);
		world.setBlock(i + 20, j + 50, k + 10, NovaCraftBlocks.cracked_basal_bricks, 0, 2);
		world.setBlock(i + 21, j + 50, k + 10, NovaCraftBlocks.basal_bricks, 0, 2);
		world.setBlock(i + 22, j + 50, k + 10, NovaCraftBlocks.basal_bricks, 0, 2);
		world.setBlock(i + 23, j + 50, k + 10, NovaCraftBlocks.cracked_basal_bricks, 0, 2);
		world.setBlock(i + 24, j + 50, k + 10, NovaCraftBlocks.cracked_basal_bricks, 0, 2);
		world.setBlock(i + 25, j + 50, k + 10, NovaCraftBlocks.basal_bricks, 0, 2);
		world.setBlock(i + 26, j + 50, k + 10, NovaCraftBlocks.cracked_basal_bricks, 0, 2);
		world.setBlock(i + 27, j + 50, k + 10, NovaCraftBlocks.basal_bricks, 0, 2);
		world.setBlock(i + 0, j + 50, k + 11, Blocks.air, 0, 2);
		world.setBlock(i + 1, j + 50, k + 11, Blocks.air, 0, 2);
		world.setBlock(i + 2, j + 50, k + 11, Blocks.air, 0, 2);
		world.setBlock(i + 3, j + 50, k + 11, Blocks.air, 0, 2);
		world.setBlock(i + 4, j + 50, k + 11, Blocks.air, 0, 2);
		world.setBlock(i + 5, j + 50, k + 11, Blocks.air, 0, 2);
		world.setBlock(i + 6, j + 50, k + 11, Blocks.air, 0, 2);
		world.setBlock(i + 7, j + 50, k + 11, Blocks.air, 0, 2);
		world.setBlock(i + 8, j + 50, k + 11, Blocks.air, 0, 2);
		world.setBlock(i + 9, j + 50, k + 11, Blocks.air, 0, 2);
		world.setBlock(i + 10, j + 50, k + 11, Blocks.air, 0, 2);
		world.setBlock(i + 11, j + 50, k + 11, Blocks.air, 0, 2);
		world.setBlock(i + 12, j + 50, k + 11, Blocks.air, 0, 2);
		world.setBlock(i + 13, j + 50, k + 11, Blocks.air, 0, 2);
		world.setBlock(i + 14, j + 50, k + 11, NovaCraftBlocks.cracked_basal_bricks, 0, 2);
		world.setBlock(i + 15, j + 50, k + 11, NovaCraftBlocks.basal_bricks, 0, 2);
		world.setBlock(i + 16, j + 50, k + 11, NovaCraftBlocks.basal_bricks, 0, 2);
		world.setBlock(i + 17, j + 50, k + 11, NovaCraftBlocks.cracked_basal_bricks, 0, 2);
		world.setBlock(i + 18, j + 50, k + 11, NovaCraftBlocks.cracked_basal_bricks, 0, 2);
		world.setBlock(i + 19, j + 50, k + 11, NovaCraftBlocks.basal_bricks, 0, 2);
		world.setBlock(i + 20, j + 50, k + 11, NovaCraftBlocks.basal_scrap, 0, 2);
		world.setBlock(i + 21, j + 50, k + 11, NovaCraftBlocks.basal_scrap, 0, 2);
		world.setBlock(i + 22, j + 50, k + 11, NovaCraftBlocks.basal_bricks, 0, 2);
		world.setBlock(i + 23, j + 50, k + 11, NovaCraftBlocks.basal_bricks, 0, 2);
		world.setBlock(i + 24, j + 50, k + 11, Blocks.air, 0, 2);
		world.setBlock(i + 25, j + 50, k + 11, NovaCraftBlocks.basal_bricks, 0, 2);
		world.setBlock(i + 26, j + 50, k + 11, NovaCraftBlocks.cracked_basal_bricks, 0, 2);
		world.setBlock(i + 27, j + 50, k + 11, NovaCraftBlocks.cracked_basal_bricks, 0, 2);
		world.setBlock(i + 0, j + 50, k + 12, Blocks.air, 0, 2);
		world.setBlock(i + 1, j + 50, k + 12, Blocks.air, 0, 2);
		world.setBlock(i + 2, j + 50, k + 12, Blocks.air, 0, 2);
		world.setBlock(i + 3, j + 50, k + 12, Blocks.air, 0, 2);
		world.setBlock(i + 4, j + 50, k + 12, Blocks.air, 0, 2);
		world.setBlock(i + 5, j + 50, k + 12, Blocks.air, 0, 2);
		world.setBlock(i + 6, j + 50, k + 12, Blocks.air, 0, 2);
		world.setBlock(i + 7, j + 50, k + 12, Blocks.air, 0, 2);
		world.setBlock(i + 8, j + 50, k + 12, Blocks.air, 0, 2);
		world.setBlock(i + 9, j + 50, k + 12, Blocks.air, 0, 2);
		world.setBlock(i + 10, j + 50, k + 12, Blocks.air, 0, 2);
		world.setBlock(i + 11, j + 50, k + 12, Blocks.air, 0, 2);
		world.setBlock(i + 12, j + 50, k + 12, Blocks.air, 0, 2);
		world.setBlock(i + 13, j + 50, k + 12, Blocks.air, 0, 2);
		world.setBlock(i + 14, j + 50, k + 12, NovaCraftBlocks.cracked_basal_bricks, 0, 2);
		world.setBlock(i + 15, j + 50, k + 12, Blocks.air, 0, 2);
		world.setBlock(i + 16, j + 50, k + 12, Blocks.air, 0, 2);
		world.setBlock(i + 17, j + 50, k + 12, Blocks.air, 0, 2);
		world.setBlock(i + 18, j + 50, k + 12, Blocks.air, 0, 2);
		world.setBlock(i + 19, j + 50, k + 12, NovaCraftBlocks.basal_brick_stairs, 0, 2);
		world.setBlock(i + 20, j + 50, k + 12, NovaCraftBlocks.basal_scrap, 0, 2);
		world.setBlock(i + 21, j + 50, k + 12, NovaCraftBlocks.basal_scrap, 0, 2);
		world.setBlock(i + 22, j + 50, k + 12, NovaCraftBlocks.basal_brick_stairs, 1, 2);
		world.setBlock(i + 23, j + 50, k + 12, Blocks.air, 0, 2);
		world.setBlock(i + 24, j + 50, k + 12, Blocks.air, 0, 2);
		world.setBlock(i + 25, j + 50, k + 12, Blocks.air, 0, 2);
		world.setBlock(i + 26, j + 50, k + 12, Blocks.air, 0, 2);
		world.setBlock(i + 27, j + 50, k + 12, NovaCraftBlocks.basal_bricks, 0, 2);
		world.setBlock(i + 0, j + 51, k + 0, Blocks.air, 0, 2);
		world.setBlock(i + 1, j + 51, k + 0, Blocks.air, 0, 2);
		world.setBlock(i + 2, j + 51, k + 0, Blocks.air, 0, 2);
		world.setBlock(i + 3, j + 51, k + 0, Blocks.air, 0, 2);
		world.setBlock(i + 4, j + 51, k + 0, Blocks.air, 0, 2);
		world.setBlock(i + 5, j + 51, k + 0, Blocks.air, 0, 2);
		world.setBlock(i + 6, j + 51, k + 0, Blocks.air, 0, 2);
		world.setBlock(i + 7, j + 51, k + 0, Blocks.air, 0, 2);
		world.setBlock(i + 8, j + 51, k + 0, Blocks.air, 0, 2);
		world.setBlock(i + 9, j + 51, k + 0, Blocks.air, 0, 2);
		world.setBlock(i + 10, j + 51, k + 0, Blocks.air, 0, 2);
		world.setBlock(i + 11, j + 51, k + 0, Blocks.air, 0, 2);
		world.setBlock(i + 12, j + 51, k + 0, Blocks.air, 0, 2);
		world.setBlock(i + 13, j + 51, k + 0, Blocks.air, 0, 2);
		world.setBlock(i + 14, j + 51, k + 0, Blocks.air, 0, 2);
		world.setBlock(i + 15, j + 51, k + 0, Blocks.air, 0, 2);
		world.setBlock(i + 16, j + 51, k + 0, Blocks.air, 0, 2);
		world.setBlock(i + 17, j + 51, k + 0, Blocks.air, 0, 2);
		world.setBlock(i + 18, j + 51, k + 0, Blocks.air, 0, 2);
		world.setBlock(i + 19, j + 51, k + 0, Blocks.air, 0, 2);
		world.setBlock(i + 20, j + 51, k + 0, Blocks.air, 0, 2);
		world.setBlock(i + 21, j + 51, k + 0, Blocks.air, 0, 2);
		world.setBlock(i + 22, j + 51, k + 0, Blocks.air, 0, 2);
		world.setBlock(i + 23, j + 51, k + 0, Blocks.air, 0, 2);
		world.setBlock(i + 24, j + 51, k + 0, Blocks.air, 0, 2);
		world.setBlock(i + 25, j + 51, k + 0, Blocks.air, 0, 2);
		world.setBlock(i + 26, j + 51, k + 0, Blocks.air, 0, 2);
		world.setBlock(i + 27, j + 51, k + 0, Blocks.air, 0, 2);
		world.setBlock(i + 0, j + 51, k + 1, NovaCraftBlocks.cracked_basal_bricks, 0, 2);
		world.setBlock(i + 1, j + 51, k + 1, NovaCraftBlocks.cracked_basal_bricks, 0, 2);
		world.setBlock(i + 2, j + 51, k + 1, Blocks.air, 0, 2);
		world.setBlock(i + 3, j + 51, k + 1, Blocks.air, 0, 2);
		world.setBlock(i + 4, j + 51, k + 1, NovaCraftBlocks.basal_bricks, 0, 2);
		world.setBlock(i + 5, j + 51, k + 1, NovaCraftBlocks.basal_bricks, 0, 2);
		world.setBlock(i + 6, j + 51, k + 1, Blocks.air, 0, 2);
		world.setBlock(i + 7, j + 51, k + 1, Blocks.air, 0, 2);
		world.setBlock(i + 8, j + 51, k + 1, NovaCraftBlocks.basal_bricks, 0, 2);
		world.setBlock(i + 9, j + 51, k + 1, NovaCraftBlocks.cracked_basal_bricks, 0, 2);
		world.setBlock(i + 10, j + 51, k + 1, Blocks.air, 0, 2);
		world.setBlock(i + 11, j + 51, k + 1, Blocks.air, 0, 2);
		world.setBlock(i + 12, j + 51, k + 1, NovaCraftBlocks.basal_bricks, 0, 2);
		world.setBlock(i + 13, j + 51, k + 1, NovaCraftBlocks.basal_bricks, 0, 2);
		world.setBlock(i + 14, j + 51, k + 1, Blocks.air, 0, 2);
		world.setBlock(i + 15, j + 51, k + 1, Blocks.air, 0, 2);
		world.setBlock(i + 16, j + 51, k + 1, Blocks.air, 0, 2);
		world.setBlock(i + 17, j + 51, k + 1, Blocks.air, 0, 2);
		world.setBlock(i + 18, j + 51, k + 1, Blocks.air, 0, 2);
		world.setBlock(i + 19, j + 51, k + 1, Blocks.air, 0, 2);
		world.setBlock(i + 20, j + 51, k + 1, Blocks.air, 0, 2);
		world.setBlock(i + 21, j + 51, k + 1, Blocks.air, 0, 2);
		world.setBlock(i + 22, j + 51, k + 1, Blocks.air, 0, 2);
		world.setBlock(i + 23, j + 51, k + 1, Blocks.air, 0, 2);
		world.setBlock(i + 24, j + 51, k + 1, Blocks.air, 0, 2);
		world.setBlock(i + 25, j + 51, k + 1, Blocks.air, 0, 2);
		world.setBlock(i + 26, j + 51, k + 1, Blocks.air, 0, 2);
		world.setBlock(i + 27, j + 51, k + 1, Blocks.air, 0, 2);
		world.setBlock(i + 0, j + 51, k + 2, NovaCraftBlocks.basal_bricks, 0, 2);
		world.setBlock(i + 1, j + 51, k + 2, NovaCraftBlocks.cracked_basal_bricks, 0, 2);
		world.setBlock(i + 2, j + 51, k + 2, Blocks.air, 0, 2);
		world.setBlock(i + 3, j + 51, k + 2, Blocks.air, 0, 2);
		world.setBlock(i + 4, j + 51, k + 2, NovaCraftBlocks.cracked_basal_bricks, 0, 2);
		world.setBlock(i + 5, j + 51, k + 2, NovaCraftBlocks.basal_bricks, 0, 2);
		world.setBlock(i + 6, j + 51, k + 2, Blocks.air, 0, 2);
		world.setBlock(i + 7, j + 51, k + 2, Blocks.air, 0, 2);
		world.setBlock(i + 8, j + 51, k + 2, NovaCraftBlocks.cracked_basal_bricks, 0, 2);
		world.setBlock(i + 9, j + 51, k + 2, NovaCraftBlocks.basal_bricks, 0, 2);
		world.setBlock(i + 10, j + 51, k + 2, Blocks.air, 0, 2);
		world.setBlock(i + 11, j + 51, k + 2, Blocks.air, 0, 2);
		world.setBlock(i + 12, j + 51, k + 2, NovaCraftBlocks.basal_bricks, 0, 2);
		world.setBlock(i + 13, j + 51, k + 2, NovaCraftBlocks.cracked_basal_bricks, 0, 2);
		world.setBlock(i + 14, j + 51, k + 2, Blocks.air, 0, 2);
		world.setBlock(i + 15, j + 51, k + 2, Blocks.air, 0, 2);
		world.setBlock(i + 16, j + 51, k + 2, Blocks.air, 0, 2);
		world.setBlock(i + 17, j + 51, k + 2, Blocks.air, 0, 2);
		world.setBlock(i + 18, j + 51, k + 2, Blocks.air, 0, 2);
		world.setBlock(i + 19, j + 51, k + 2, Blocks.air, 0, 2);
		world.setBlock(i + 20, j + 51, k + 2, Blocks.air, 0, 2);
		world.setBlock(i + 21, j + 51, k + 2, Blocks.air, 0, 2);
		world.setBlock(i + 22, j + 51, k + 2, Blocks.air, 0, 2);
		world.setBlock(i + 23, j + 51, k + 2, Blocks.air, 0, 2);
		world.setBlock(i + 24, j + 51, k + 2, Blocks.air, 0, 2);
		world.setBlock(i + 25, j + 51, k + 2, Blocks.air, 0, 2);
		world.setBlock(i + 26, j + 51, k + 2, Blocks.air, 0, 2);
		world.setBlock(i + 27, j + 51, k + 2, Blocks.air, 0, 2);
		world.setBlock(i + 0, j + 51, k + 3, NovaCraftBlocks.basal_bricks, 0, 2);
		world.setBlock(i + 1, j + 51, k + 3, NovaCraftBlocks.basal_bricks, 0, 2);
		world.setBlock(i + 2, j + 51, k + 3, NovaCraftBlocks.cracked_basal_bricks, 0, 2);
		world.setBlock(i + 3, j + 51, k + 3, NovaCraftBlocks.basal_bricks, 0, 2);
		world.setBlock(i + 4, j + 51, k + 3, NovaCraftBlocks.basal_bricks, 0, 2);
		world.setBlock(i + 5, j + 51, k + 3, NovaCraftBlocks.basal_bricks, 0, 2);
		world.setBlock(i + 6, j + 51, k + 3, NovaCraftBlocks.basal_bricks, 0, 2);
		world.setBlock(i + 7, j + 51, k + 3, NovaCraftBlocks.basal_bricks, 0, 2);
		world.setBlock(i + 8, j + 51, k + 3, NovaCraftBlocks.basal_bricks, 0, 2);
		world.setBlock(i + 9, j + 51, k + 3, NovaCraftBlocks.basal_bricks, 0, 2);
		world.setBlock(i + 10, j + 51, k + 3, NovaCraftBlocks.basal_bricks, 0, 2);
		world.setBlock(i + 11, j + 51, k + 3, NovaCraftBlocks.basal_bricks, 0, 2);
		world.setBlock(i + 12, j + 51, k + 3, NovaCraftBlocks.basal_bricks, 0, 2);
		world.setBlock(i + 13, j + 51, k + 3, NovaCraftBlocks.basal_bricks, 0, 2);
		world.setBlock(i + 14, j + 51, k + 3, NovaCraftBlocks.basal_bricks, 0, 2);
		world.setBlock(i + 15, j + 51, k + 3, NovaCraftBlocks.basal_bricks, 0, 2);
		world.setBlock(i + 16, j + 51, k + 3, Blocks.air, 0, 2);
		world.setBlock(i + 17, j + 51, k + 3, Blocks.air, 0, 2);
		world.setBlock(i + 18, j + 51, k + 3, NovaCraftBlocks.basal_bricks, 0, 2);
		world.setBlock(i + 19, j + 51, k + 3, NovaCraftBlocks.cracked_basal_bricks, 0, 2);
		world.setBlock(i + 20, j + 51, k + 3, Blocks.air, 0, 2);
		world.setBlock(i + 21, j + 51, k + 3, Blocks.air, 0, 2);
		world.setBlock(i + 22, j + 51, k + 3, NovaCraftBlocks.basal_bricks, 0, 2);
		world.setBlock(i + 23, j + 51, k + 3, NovaCraftBlocks.basal_bricks, 0, 2);
		world.setBlock(i + 24, j + 51, k + 3, Blocks.air, 0, 2);
		world.setBlock(i + 25, j + 51, k + 3, Blocks.air, 0, 2);
		world.setBlock(i + 26, j + 51, k + 3, NovaCraftBlocks.basal_bricks, 0, 2);
		world.setBlock(i + 27, j + 51, k + 3, NovaCraftBlocks.basal_bricks, 0, 2);
		world.setBlock(i + 0, j + 51, k + 4, NovaCraftBlocks.basal_bricks, 0, 2);
		world.setBlock(i + 1, j + 51, k + 4, NovaCraftBlocks.cracked_basal_bricks, 0, 2);
		world.setBlock(i + 2, j + 51, k + 4, NovaCraftBlocks.basal_bricks, 0, 2);
		world.setBlock(i + 3, j + 51, k + 4, NovaCraftBlocks.basal_bricks, 0, 2);
		world.setBlock(i + 4, j + 51, k + 4, NovaCraftBlocks.basal_bricks, 0, 2);
		world.setBlock(i + 5, j + 51, k + 4, NovaCraftBlocks.basal_bricks, 0, 2);
		world.setBlock(i + 6, j + 51, k + 4, NovaCraftBlocks.cracked_basal_bricks, 0, 2);
		world.setBlock(i + 7, j + 51, k + 4, NovaCraftBlocks.cracked_basal_bricks, 0, 2);
		world.setBlock(i + 8, j + 51, k + 4, NovaCraftBlocks.cracked_basal_bricks, 0, 2);
		world.setBlock(i + 9, j + 51, k + 4, NovaCraftBlocks.cracked_basal_bricks, 0, 2);
		world.setBlock(i + 10, j + 51, k + 4, NovaCraftBlocks.basal_bricks, 0, 2);
		world.setBlock(i + 11, j + 51, k + 4, NovaCraftBlocks.cracked_basal_bricks, 0, 2);
		world.setBlock(i + 12, j + 51, k + 4, NovaCraftBlocks.cracked_basal_bricks, 0, 2);
		world.setBlock(i + 13, j + 51, k + 4, NovaCraftBlocks.cracked_basal_bricks, 0, 2);
		world.setBlock(i + 14, j + 51, k + 4, NovaCraftBlocks.cracked_basal_bricks, 0, 2);
		world.setBlock(i + 15, j + 51, k + 4, NovaCraftBlocks.cracked_basal_bricks, 0, 2);
		world.setBlock(i + 16, j + 51, k + 4, Blocks.air, 0, 2);
		world.setBlock(i + 17, j + 51, k + 4, Blocks.air, 0, 2);
		world.setBlock(i + 18, j + 51, k + 4, NovaCraftBlocks.cracked_basal_bricks, 0, 2);
		world.setBlock(i + 19, j + 51, k + 4, NovaCraftBlocks.basal_bricks, 0, 2);
		world.setBlock(i + 20, j + 51, k + 4, Blocks.air, 0, 2);
		world.setBlock(i + 21, j + 51, k + 4, Blocks.air, 0, 2);
		world.setBlock(i + 22, j + 51, k + 4, NovaCraftBlocks.basal_bricks, 0, 2);
		world.setBlock(i + 23, j + 51, k + 4, NovaCraftBlocks.basal_bricks, 0, 2);
		world.setBlock(i + 24, j + 51, k + 4, Blocks.air, 0, 2);
		world.setBlock(i + 25, j + 51, k + 4, Blocks.air, 0, 2);
		world.setBlock(i + 26, j + 51, k + 4, NovaCraftBlocks.basal_bricks, 0, 2);
		world.setBlock(i + 27, j + 51, k + 4, NovaCraftBlocks.basal_bricks, 0, 2);
		world.setBlock(i + 0, j + 51, k + 5, NovaCraftBlocks.basal_bricks, 0, 2);
		world.setBlock(i + 1, j + 51, k + 5, NovaCraftBlocks.cracked_basal_bricks, 0, 2);
		world.setBlock(i + 2, j + 51, k + 5, NovaCraftBlocks.basal_bricks, 0, 2);
		world.setBlock(i + 3, j + 51, k + 5, NovaCraftBlocks.basal_bricks, 0, 2);
		world.setBlock(i + 4, j + 51, k + 5, NovaCraftBlocks.basal_bricks, 0, 2);
		world.setBlock(i + 5, j + 51, k + 5, NovaCraftBlocks.basal_bricks, 0, 2);
		world.setBlock(i + 6, j + 51, k + 5, NovaCraftBlocks.basal_bricks, 0, 2);
		world.setBlock(i + 7, j + 51, k + 5, NovaCraftBlocks.basal_bricks, 0, 2);
		world.setBlock(i + 8, j + 51, k + 5, NovaCraftBlocks.cracked_basal_bricks, 0, 2);
		world.setBlock(i + 9, j + 51, k + 5, NovaCraftBlocks.cracked_basal_bricks, 0, 2);
		world.setBlock(i + 10, j + 51, k + 5, NovaCraftBlocks.basal_bricks, 0, 2);
		world.setBlock(i + 11, j + 51, k + 5, NovaCraftBlocks.cracked_basal_bricks, 0, 2);
		world.setBlock(i + 12, j + 51, k + 5, NovaCraftBlocks.cracked_basal_bricks, 0, 2);
		world.setBlock(i + 13, j + 51, k + 5, NovaCraftBlocks.basal_bricks, 0, 2);
		world.setBlock(i + 14, j + 51, k + 5, NovaCraftBlocks.cracked_basal_bricks, 0, 2);
		world.setBlock(i + 15, j + 51, k + 5, NovaCraftBlocks.basal_bricks, 0, 2);
		world.setBlock(i + 16, j + 51, k + 5, NovaCraftBlocks.basal_bricks, 0, 2);
		world.setBlock(i + 17, j + 51, k + 5, NovaCraftBlocks.cracked_basal_bricks, 0, 2);
		world.setBlock(i + 18, j + 51, k + 5, NovaCraftBlocks.basal_bricks, 0, 2);
		world.setBlock(i + 19, j + 51, k + 5, NovaCraftBlocks.basal_bricks, 0, 2);
		world.setBlock(i + 20, j + 51, k + 5, NovaCraftBlocks.cracked_basal_bricks, 0, 2);
		world.setBlock(i + 21, j + 51, k + 5, NovaCraftBlocks.basal_bricks, 0, 2);
		world.setBlock(i + 22, j + 51, k + 5, NovaCraftBlocks.basal_bricks, 0, 2);
		world.setBlock(i + 23, j + 51, k + 5, NovaCraftBlocks.basal_bricks, 0, 2);
		world.setBlock(i + 24, j + 51, k + 5, NovaCraftBlocks.basal_bricks, 0, 2);
		world.setBlock(i + 25, j + 51, k + 5, NovaCraftBlocks.basal_bricks, 0, 2);
		world.setBlock(i + 26, j + 51, k + 5, NovaCraftBlocks.basal_bricks, 0, 2);
		world.setBlock(i + 27, j + 51, k + 5, NovaCraftBlocks.basal_bricks, 0, 2);
		world.setBlock(i + 0, j + 51, k + 6, NovaCraftBlocks.cracked_basal_bricks, 0, 2);
		world.setBlock(i + 1, j + 51, k + 6, NovaCraftBlocks.cracked_basal_bricks, 0, 2);
		world.setBlock(i + 2, j + 51, k + 6, NovaCraftBlocks.basal_bricks, 0, 2);
		world.setBlock(i + 3, j + 51, k + 6, NovaCraftBlocks.cracked_basal_bricks, 0, 2);
		world.setBlock(i + 4, j + 51, k + 6, NovaCraftBlocks.basal_bricks, 0, 2);
		world.setBlock(i + 5, j + 51, k + 6, NovaCraftBlocks.basal_bricks, 0, 2);
		world.setBlock(i + 6, j + 51, k + 6, NovaCraftBlocks.basal_bricks, 0, 2);
		world.setBlock(i + 7, j + 51, k + 6, NovaCraftBlocks.basal_bricks, 0, 2);
		world.setBlock(i + 8, j + 51, k + 6, NovaCraftBlocks.basal_bricks, 0, 2);
		world.setBlock(i + 9, j + 51, k + 6, NovaCraftBlocks.basal_bricks, 0, 2);
		world.setBlock(i + 10, j + 51, k + 6, NovaCraftBlocks.cracked_basal_bricks, 0, 2);
		world.setBlock(i + 11, j + 51, k + 6, NovaCraftBlocks.basal_bricks, 0, 2);
		world.setBlock(i + 12, j + 51, k + 6, NovaCraftBlocks.basal_bricks, 0, 2);
		world.setBlock(i + 13, j + 51, k + 6, NovaCraftBlocks.basal_bricks, 0, 2);
		world.setBlock(i + 14, j + 51, k + 6, NovaCraftBlocks.basal_bricks, 0, 2);
		world.setBlock(i + 15, j + 51, k + 6, NovaCraftBlocks.basal_bricks, 0, 2);
		world.setBlock(i + 16, j + 51, k + 6, NovaCraftBlocks.basal_bricks, 0, 2);
		world.setBlock(i + 17, j + 51, k + 6, NovaCraftBlocks.cracked_basal_bricks, 0, 2);
		world.setBlock(i + 18, j + 51, k + 6, NovaCraftBlocks.basal_bricks, 0, 2);
		world.setBlock(i + 19, j + 51, k + 6, NovaCraftBlocks.basal_bricks, 0, 2);
		world.setBlock(i + 20, j + 51, k + 6, NovaCraftBlocks.cracked_basal_bricks, 0, 2);
		world.setBlock(i + 21, j + 51, k + 6, NovaCraftBlocks.cracked_basal_bricks, 0, 2);
		world.setBlock(i + 22, j + 51, k + 6, NovaCraftBlocks.basal_bricks, 0, 2);
		world.setBlock(i + 23, j + 51, k + 6, NovaCraftBlocks.basal_bricks, 0, 2);
		world.setBlock(i + 24, j + 51, k + 6, NovaCraftBlocks.basal_bricks, 0, 2);
		world.setBlock(i + 25, j + 51, k + 6, NovaCraftBlocks.cracked_basal_bricks, 0, 2);
		world.setBlock(i + 26, j + 51, k + 6, NovaCraftBlocks.basal_bricks, 0, 2);
		world.setBlock(i + 27, j + 51, k + 6, NovaCraftBlocks.basal_bricks, 0, 2);
		world.setBlock(i + 0, j + 51, k + 7, NovaCraftBlocks.cracked_basal_bricks, 0, 2);
		world.setBlock(i + 1, j + 51, k + 7, NovaCraftBlocks.basal_bricks, 0, 2);
		world.setBlock(i + 2, j + 51, k + 7, NovaCraftBlocks.basal_bricks, 0, 2);
		world.setBlock(i + 3, j + 51, k + 7, NovaCraftBlocks.cracked_basal_bricks, 0, 2);
		world.setBlock(i + 4, j + 51, k + 7, NovaCraftBlocks.basal_bricks, 0, 2);
		world.setBlock(i + 5, j + 51, k + 7, NovaCraftBlocks.basal_bricks, 0, 2);
		world.setBlock(i + 6, j + 51, k + 7, NovaCraftBlocks.basal_bricks, 0, 2);
		world.setBlock(i + 7, j + 51, k + 7, NovaCraftBlocks.basal_bricks, 0, 2);
		world.setBlock(i + 8, j + 51, k + 7, NovaCraftBlocks.basal_bricks, 0, 2);
		world.setBlock(i + 9, j + 51, k + 7, NovaCraftBlocks.basal_bricks, 0, 2);
		world.setBlock(i + 10, j + 51, k + 7, NovaCraftBlocks.cracked_basal_bricks, 0, 2);
		world.setBlock(i + 11, j + 51, k + 7, NovaCraftBlocks.basal_bricks, 0, 2);
		world.setBlock(i + 12, j + 51, k + 7, NovaCraftBlocks.basal_bricks, 0, 2);
		world.setBlock(i + 13, j + 51, k + 7, NovaCraftBlocks.basal_bricks, 0, 2);
		world.setBlock(i + 14, j + 51, k + 7, NovaCraftBlocks.cracked_basal_bricks, 0, 2);
		world.setBlock(i + 15, j + 51, k + 7, NovaCraftBlocks.basal_bricks, 0, 2);
		world.setBlock(i + 16, j + 51, k + 7, NovaCraftBlocks.basal_bricks, 0, 2);
		world.setBlock(i + 17, j + 51, k + 7, NovaCraftBlocks.cracked_basal_bricks, 0, 2);
		world.setBlock(i + 18, j + 51, k + 7, NovaCraftBlocks.basal_bricks, 0, 2);
		world.setBlock(i + 19, j + 51, k + 7, NovaCraftBlocks.basal_bricks, 0, 2);
		world.setBlock(i + 20, j + 51, k + 7, NovaCraftBlocks.basal_bricks, 0, 2);
		world.setBlock(i + 21, j + 51, k + 7, NovaCraftBlocks.cracked_basal_bricks, 0, 2);
		world.setBlock(i + 22, j + 51, k + 7, NovaCraftBlocks.cracked_basal_bricks, 0, 2);
		world.setBlock(i + 23, j + 51, k + 7, NovaCraftBlocks.cracked_basal_bricks, 0, 2);
		world.setBlock(i + 24, j + 51, k + 7, NovaCraftBlocks.cracked_basal_bricks, 0, 2);
		world.setBlock(i + 25, j + 51, k + 7, NovaCraftBlocks.cracked_basal_bricks, 0, 2);
		world.setBlock(i + 26, j + 51, k + 7, NovaCraftBlocks.basal_bricks, 0, 2);
		world.setBlock(i + 27, j + 51, k + 7, NovaCraftBlocks.basal_bricks, 0, 2);
		world.setBlock(i + 0, j + 51, k + 8, NovaCraftBlocks.cracked_basal_bricks, 0, 2);
		world.setBlock(i + 1, j + 51, k + 8, NovaCraftBlocks.cracked_basal_bricks, 0, 2);
		world.setBlock(i + 2, j + 51, k + 8, NovaCraftBlocks.cracked_basal_bricks, 0, 2);
		world.setBlock(i + 3, j + 51, k + 8, NovaCraftBlocks.basal_bricks, 0, 2);
		world.setBlock(i + 4, j + 51, k + 8, NovaCraftBlocks.basal_bricks, 0, 2);
		world.setBlock(i + 5, j + 51, k + 8, NovaCraftBlocks.cracked_basal_bricks, 0, 2);
		world.setBlock(i + 6, j + 51, k + 8, NovaCraftBlocks.basal_bricks, 0, 2);
		world.setBlock(i + 7, j + 51, k + 8, NovaCraftBlocks.cracked_basal_bricks, 0, 2);
		world.setBlock(i + 8, j + 51, k + 8, NovaCraftBlocks.cracked_basal_bricks, 0, 2);
		world.setBlock(i + 9, j + 51, k + 8, NovaCraftBlocks.basal_bricks, 0, 2);
		world.setBlock(i + 10, j + 51, k + 8, NovaCraftBlocks.cracked_basal_bricks, 0, 2);
		world.setBlock(i + 11, j + 51, k + 8, NovaCraftBlocks.basal_bricks, 0, 2);
		world.setBlock(i + 12, j + 51, k + 8, NovaCraftBlocks.basal_bricks, 0, 2);
		world.setBlock(i + 13, j + 51, k + 8, NovaCraftBlocks.basal_bricks, 0, 2);
		world.setBlock(i + 14, j + 51, k + 8, NovaCraftBlocks.basal_bricks, 0, 2);
		world.setBlock(i + 15, j + 51, k + 8, NovaCraftBlocks.basal_bricks, 0, 2);
		world.setBlock(i + 16, j + 51, k + 8, NovaCraftBlocks.cracked_basal_bricks, 0, 2);
		world.setBlock(i + 17, j + 51, k + 8, NovaCraftBlocks.basal_bricks, 0, 2);
		world.setBlock(i + 18, j + 51, k + 8, NovaCraftBlocks.cracked_basal_bricks, 0, 2);
		world.setBlock(i + 19, j + 51, k + 8, NovaCraftBlocks.basal_bricks, 0, 2);
		world.setBlock(i + 20, j + 51, k + 8, NovaCraftBlocks.cracked_basal_bricks, 0, 2);
		world.setBlock(i + 21, j + 51, k + 8, NovaCraftBlocks.cracked_basal_bricks, 0, 2);
		world.setBlock(i + 22, j + 51, k + 8, NovaCraftBlocks.basal_bricks, 0, 2);
		world.setBlock(i + 23, j + 51, k + 8, NovaCraftBlocks.cracked_basal_bricks, 0, 2);
		world.setBlock(i + 24, j + 51, k + 8, NovaCraftBlocks.basal_bricks, 0, 2);
		world.setBlock(i + 25, j + 51, k + 8, NovaCraftBlocks.basal_bricks, 0, 2);
		world.setBlock(i + 26, j + 51, k + 8, NovaCraftBlocks.cracked_basal_bricks, 0, 2);
		world.setBlock(i + 27, j + 51, k + 8, NovaCraftBlocks.basal_bricks, 0, 2);
		world.setBlock(i + 0, j + 51, k + 9, NovaCraftBlocks.cracked_basal_bricks, 0, 2);
		world.setBlock(i + 1, j + 51, k + 9, NovaCraftBlocks.basal_bricks, 0, 2);
		world.setBlock(i + 2, j + 51, k + 9, NovaCraftBlocks.basal_bricks, 0, 2);
		world.setBlock(i + 3, j + 51, k + 9, NovaCraftBlocks.basal_bricks, 0, 2);
		world.setBlock(i + 4, j + 51, k + 9, NovaCraftBlocks.basal_bricks, 0, 2);
		world.setBlock(i + 5, j + 51, k + 9, NovaCraftBlocks.basal_brick_stairs, 1, 2);
		world.setBlock(i + 6, j + 51, k + 9, Blocks.air, 0, 2);
		world.setBlock(i + 7, j + 51, k + 9, Blocks.air, 0, 2);
		world.setBlock(i + 8, j + 51, k + 9, NovaCraftBlocks.basal_brick_stairs, 0, 2);
		world.setBlock(i + 9, j + 51, k + 9, NovaCraftBlocks.basal_bricks, 0, 2);
		world.setBlock(i + 10, j + 51, k + 9, NovaCraftBlocks.basal_bricks, 0, 2);
		world.setBlock(i + 11, j + 51, k + 9, NovaCraftBlocks.cracked_basal_bricks, 0, 2);
		world.setBlock(i + 12, j + 51, k + 9, NovaCraftBlocks.basal_bricks, 0, 2);
		world.setBlock(i + 13, j + 51, k + 9, NovaCraftBlocks.cracked_basal_bricks, 0, 2);
		world.setBlock(i + 14, j + 51, k + 9, NovaCraftBlocks.basal_bricks, 0, 2);
		world.setBlock(i + 15, j + 51, k + 9, NovaCraftBlocks.basal_bricks, 0, 2);
		world.setBlock(i + 16, j + 51, k + 9, NovaCraftBlocks.basal_bricks, 0, 2);
		world.setBlock(i + 17, j + 51, k + 9, NovaCraftBlocks.basal_bricks, 0, 2);
		world.setBlock(i + 18, j + 51, k + 9, NovaCraftBlocks.basal_bricks, 0, 2);
		world.setBlock(i + 19, j + 51, k + 9, NovaCraftBlocks.basal_bricks, 0, 2);
		world.setBlock(i + 20, j + 51, k + 9, NovaCraftBlocks.basal_bricks, 0, 2);
		world.setBlock(i + 21, j + 51, k + 9, NovaCraftBlocks.cracked_basal_bricks, 0, 2);
		world.setBlock(i + 22, j + 51, k + 9, NovaCraftBlocks.basal_bricks, 0, 2);
		world.setBlock(i + 23, j + 51, k + 9, NovaCraftBlocks.basal_bricks, 0, 2);
		world.setBlock(i + 24, j + 51, k + 9, NovaCraftBlocks.basal_bricks, 0, 2);
		world.setBlock(i + 25, j + 51, k + 9, NovaCraftBlocks.cracked_basal_bricks, 0, 2);
		world.setBlock(i + 26, j + 51, k + 9, NovaCraftBlocks.cracked_basal_bricks, 0, 2);
		world.setBlock(i + 27, j + 51, k + 9, NovaCraftBlocks.basal_bricks, 0, 2);
		world.setBlock(i + 0, j + 51, k + 10, NovaCraftBlocks.basal_bricks, 0, 2);
		world.setBlock(i + 1, j + 51, k + 10, NovaCraftBlocks.basal_bricks, 0, 2);
		world.setBlock(i + 2, j + 51, k + 10, Blocks.air, 0, 2);
		world.setBlock(i + 3, j + 51, k + 10, Blocks.air, 0, 2);
		world.setBlock(i + 4, j + 51, k + 10, Blocks.air, 0, 2);
		world.setBlock(i + 5, j + 51, k + 10, Blocks.air, 0, 2);
		world.setBlock(i + 6, j + 51, k + 10, Blocks.air, 0, 2);
		world.setBlock(i + 7, j + 51, k + 10, Blocks.air, 0, 2);
		world.setBlock(i + 8, j + 51, k + 10, Blocks.air, 0, 2);
		world.setBlock(i + 9, j + 51, k + 10, Blocks.air, 0, 2);
		world.setBlock(i + 10, j + 51, k + 10, Blocks.air, 0, 2);
		world.setBlock(i + 11, j + 51, k + 10, Blocks.air, 0, 2);
		world.setBlock(i + 12, j + 51, k + 10, NovaCraftBlocks.cracked_basal_bricks, 0, 2);
		world.setBlock(i + 13, j + 51, k + 10, NovaCraftBlocks.basal_scrap, 0, 2);
		world.setBlock(i + 14, j + 51, k + 10, NovaCraftBlocks.basal_bricks, 0, 2);
		world.setBlock(i + 15, j + 51, k + 10, NovaCraftBlocks.cracked_basal_bricks, 0, 2);
		world.setBlock(i + 16, j + 51, k + 10, NovaCraftBlocks.basal_bricks, 0, 2);
		world.setBlock(i + 17, j + 51, k + 10, NovaCraftBlocks.basal_bricks, 0, 2);
		world.setBlock(i + 18, j + 51, k + 10, NovaCraftBlocks.basal_bricks, 0, 2);
		world.setBlock(i + 19, j + 51, k + 10, NovaCraftBlocks.cracked_basal_bricks, 0, 2);
		world.setBlock(i + 20, j + 51, k + 10, NovaCraftBlocks.basal_bricks, 0, 2);
		world.setBlock(i + 21, j + 51, k + 10, NovaCraftBlocks.basal_bricks, 0, 2);
		world.setBlock(i + 22, j + 51, k + 10, NovaCraftBlocks.basal_bricks, 0, 2);
		world.setBlock(i + 23, j + 51, k + 10, NovaCraftBlocks.cracked_basal_bricks, 0, 2);
		world.setBlock(i + 24, j + 51, k + 10, NovaCraftBlocks.basal_bricks, 0, 2);
		world.setBlock(i + 25, j + 51, k + 10, NovaCraftBlocks.basal_bricks, 0, 2);
		world.setBlock(i + 26, j + 51, k + 10, NovaCraftBlocks.cracked_basal_bricks, 0, 2);
		world.setBlock(i + 27, j + 51, k + 10, NovaCraftBlocks.cracked_basal_bricks, 0, 2);
		world.setBlock(i + 0, j + 51, k + 11, Blocks.air, 0, 2);
		world.setBlock(i + 1, j + 51, k + 11, Blocks.air, 0, 2);
		world.setBlock(i + 2, j + 51, k + 11, Blocks.air, 0, 2);
		world.setBlock(i + 3, j + 51, k + 11, Blocks.air, 0, 2);
		world.setBlock(i + 4, j + 51, k + 11, Blocks.air, 0, 2);
		world.setBlock(i + 5, j + 51, k + 11, Blocks.air, 0, 2);
		world.setBlock(i + 6, j + 51, k + 11, Blocks.air, 0, 2);
		world.setBlock(i + 7, j + 51, k + 11, Blocks.air, 0, 2);
		world.setBlock(i + 8, j + 51, k + 11, Blocks.air, 0, 2);
		world.setBlock(i + 9, j + 51, k + 11, Blocks.air, 0, 2);
		world.setBlock(i + 10, j + 51, k + 11, Blocks.air, 0, 2);
		world.setBlock(i + 11, j + 51, k + 11, Blocks.air, 0, 2);
		world.setBlock(i + 12, j + 51, k + 11, Blocks.air, 0, 2);
		world.setBlock(i + 13, j + 51, k + 11, Blocks.air, 0, 2);
		world.setBlock(i + 14, j + 51, k + 11, NovaCraftBlocks.basal_bricks, 0, 2);
		world.setBlock(i + 15, j + 51, k + 11, NovaCraftBlocks.cracked_basal_bricks, 0, 2);
		world.setBlock(i + 16, j + 51, k + 11, NovaCraftBlocks.basal_bricks, 0, 2);
		world.setBlock(i + 17, j + 51, k + 11, NovaCraftBlocks.basal_bricks, 0, 2);
		world.setBlock(i + 18, j + 51, k + 11, NovaCraftBlocks.basal_bricks, 0, 2);
		world.setBlock(i + 19, j + 51, k + 11, NovaCraftBlocks.basal_brick_stairs, 1, 2);
		world.setBlock(i + 20, j + 51, k + 11, Blocks.air, 0, 2);
		world.setBlock(i + 21, j + 51, k + 11, Blocks.air, 0, 2);
		world.setBlock(i + 22, j + 51, k + 11, NovaCraftBlocks.basal_brick_stairs, 0, 2);
		world.setBlock(i + 23, j + 51, k + 11, NovaCraftBlocks.cracked_basal_bricks, 0, 2);
		world.setBlock(i + 24, j + 51, k + 11, NovaCraftBlocks.basal_bricks, 0, 2);
		world.setBlock(i + 25, j + 51, k + 11, NovaCraftBlocks.cracked_basal_bricks, 0, 2);
		world.setBlock(i + 26, j + 51, k + 11, NovaCraftBlocks.cracked_basal_bricks, 0, 2);
		world.setBlock(i + 27, j + 51, k + 11, NovaCraftBlocks.cracked_basal_bricks, 0, 2);
		world.setBlock(i + 0, j + 51, k + 12, Blocks.air, 0, 2);
		world.setBlock(i + 1, j + 51, k + 12, Blocks.air, 0, 2);
		world.setBlock(i + 2, j + 51, k + 12, Blocks.air, 0, 2);
		world.setBlock(i + 3, j + 51, k + 12, Blocks.air, 0, 2);
		world.setBlock(i + 4, j + 51, k + 12, Blocks.air, 0, 2);
		world.setBlock(i + 5, j + 51, k + 12, Blocks.air, 0, 2);
		world.setBlock(i + 6, j + 51, k + 12, Blocks.air, 0, 2);
		world.setBlock(i + 7, j + 51, k + 12, Blocks.air, 0, 2);
		world.setBlock(i + 8, j + 51, k + 12, Blocks.air, 0, 2);
		world.setBlock(i + 9, j + 51, k + 12, Blocks.air, 0, 2);
		world.setBlock(i + 10, j + 51, k + 12, Blocks.air, 0, 2);
		world.setBlock(i + 11, j + 51, k + 12, Blocks.air, 0, 2);
		world.setBlock(i + 12, j + 51, k + 12, Blocks.air, 0, 2);
		world.setBlock(i + 13, j + 51, k + 12, Blocks.air, 0, 2);
		world.setBlock(i + 14, j + 51, k + 12, NovaCraftBlocks.basal_bricks, 0, 2);
		world.setBlock(i + 15, j + 51, k + 12, NovaCraftBlocks.basal_bricks, 0, 2);
		world.setBlock(i + 16, j + 51, k + 12, Blocks.air, 0, 2);
		world.setBlock(i + 17, j + 51, k + 12, Blocks.air, 0, 2);
		world.setBlock(i + 18, j + 51, k + 12, Blocks.air, 0, 2);
		world.setBlock(i + 19, j + 51, k + 12, Blocks.air, 0, 2);
		world.setBlock(i + 20, j + 51, k + 12, Blocks.air, 0, 2);
		world.setBlock(i + 21, j + 51, k + 12, Blocks.air, 0, 2);
		world.setBlock(i + 22, j + 51, k + 12, Blocks.air, 0, 2);
		world.setBlock(i + 23, j + 51, k + 12, Blocks.air, 0, 2);
		world.setBlock(i + 24, j + 51, k + 12, Blocks.air, 0, 2);
		world.setBlock(i + 25, j + 51, k + 12, Blocks.air, 0, 2);
		world.setBlock(i + 26, j + 51, k + 12, NovaCraftBlocks.basal_bricks, 0, 2);
