package com.NovaCraft.world.bastion.treasure;

import net.minecraft.world.gen.feature.*;
import net.minecraft.world.*;
import java.util.*;
import com.NovaCraftBlocks.NovaCraftBlocks;
import net.minecraft.init.*;

public class BastionTreasureBridgeGen5 extends WorldGenerator
{
	public BastionTreasureBridgeGen5() {

	}
	
	public boolean generate(final World world, final Random random, final int i, final int j, final int k) {
		
		world.setBlock(i + 14, j + 20, k + 9, NovaCraftBlocks.basal_bricks, 0, 2);
		world.setBlock(i + 15, j + 20, k + 9, NovaCraftBlocks.basal_bricks, 0, 2);
		world.setBlock(i + 16, j + 20, k + 9, NovaCraftBlocks.basal_bricks, 0, 2);
		world.setBlock(i + 17, j + 20, k + 9, NovaCraftBlocks.cracked_basal_bricks, 0, 2);
		world.setBlock(i + 18, j + 20, k + 9, NovaCraftBlocks.cracked_basal_bricks, 0, 2);
		world.setBlock(i + 19, j + 20, k + 9, NovaCraftBlocks.cracked_basal_bricks, 0, 2);
		world.setBlock(i + 20, j + 20, k + 9, NovaCraftBlocks.basal_bricks, 0, 2);
		world.setBlock(i + 21, j + 20, k + 9, NovaCraftBlocks.basal_bricks, 0, 2);
		world.setBlock(i + 22, j + 20, k + 9, NovaCraftBlocks.basal_bricks, 0, 2);
		world.setBlock(i + 23, j + 20, k + 9, NovaCraftBlocks.basal_bricks, 0, 2);
		world.setBlock(i + 24, j + 20, k + 9, NovaCraftBlocks.cracked_basal_bricks, 0, 2);
		world.setBlock(i + 25, j + 20, k + 9, NovaCraftBlocks.basal_bricks, 0, 2);
		world.setBlock(i + 26, j + 20, k + 9, Blocks.air, 0, 2);
		world.setBlock(i + 27, j + 20, k + 9, Blocks.air, 0, 2);
		world.setBlock(i, j + 20, k + 10, NovaCraftBlocks.basal_bricks, 0, 2);
		world.setBlock(i + 1, j + 20, k + 10, NovaCraftBlocks.cracked_basal_bricks, 0, 2);
		world.setBlock(i + 2, j + 20, k + 10, NovaCraftBlocks.basal_bricks, 0, 2);
		world.setBlock(i + 3, j + 20, k + 10, NovaCraftBlocks.basal_bricks, 0, 2);
		world.setBlock(i + 4, j + 20, k + 10, NovaCraftBlocks.cracked_basal_bricks, 0, 2);
		world.setBlock(i + 5, j + 20, k + 10, NovaCraftBlocks.cracked_basal_bricks, 0, 2);
		world.setBlock(i + 6, j + 20, k + 10, NovaCraftBlocks.basal_bricks, 0, 2);
		world.setBlock(i + 7, j + 20, k + 10, NovaCraftBlocks.cracked_basal_bricks, 0, 2);
		world.setBlock(i + 8, j + 20, k + 10, NovaCraftBlocks.basal_bricks, 0, 2);
		world.setBlock(i + 9, j + 20, k + 10, NovaCraftBlocks.basal_bricks, 0, 2);
		world.setBlock(i + 10, j + 20, k + 10, NovaCraftBlocks.cracked_basal_bricks, 0, 2);
		world.setBlock(i + 11, j + 20, k + 10, NovaCraftBlocks.basal_bricks, 0, 2);
		world.setBlock(i + 12, j + 20, k + 10, NovaCraftBlocks.basal_bricks, 0, 2);
		world.setBlock(i + 13, j + 20, k + 10, NovaCraftBlocks.basal_bricks, 0, 2);
		world.setBlock(i + 14, j + 20, k + 10, NovaCraftBlocks.basal_bricks, 0, 2);
		world.setBlock(i + 15, j + 20, k + 10, NovaCraftBlocks.basal_bricks, 0, 2);
		world.setBlock(i + 16, j + 20, k + 10, NovaCraftBlocks.cracked_basal_bricks, 0, 2);
		world.setBlock(i + 17, j + 20, k + 10, NovaCraftBlocks.basal_bricks, 0, 2);
		world.setBlock(i + 18, j + 20, k + 10, NovaCraftBlocks.cracked_basal_bricks, 0, 2);
		world.setBlock(i + 19, j + 20, k + 10, NovaCraftBlocks.cracked_basal_bricks, 0, 2);
		world.setBlock(i + 20, j + 20, k + 10, NovaCraftBlocks.basal_bricks, 0, 2);
		world.setBlock(i + 21, j + 20, k + 10, NovaCraftBlocks.cracked_basal_bricks, 0, 2);
		world.setBlock(i + 22, j + 20, k + 10, NovaCraftBlocks.basal_bricks, 0, 2);
		world.setBlock(i + 23, j + 20, k + 10, NovaCraftBlocks.basal_bricks, 0, 2);
		world.setBlock(i + 24, j + 20, k + 10, NovaCraftBlocks.basal_bricks, 0, 2);
		world.setBlock(i + 25, j + 20, k + 10, NovaCraftBlocks.cracked_basal_bricks, 0, 2);
		world.setBlock(i + 26, j + 20, k + 10, Blocks.air, 0, 2);
		world.setBlock(i + 27, j + 20, k + 10, Blocks.air, 0, 2);
		world.setBlock(i, j + 20, k + 11, NovaCraftBlocks.cracked_basal_bricks, 0, 2);
		world.setBlock(i + 1, j + 20, k + 11, NovaCraftBlocks.cracked_basal_bricks, 0, 2);
		world.setBlock(i + 2, j + 20, k + 11, NovaCraftBlocks.basal_bricks, 0, 2);
		world.setBlock(i + 3, j + 20, k + 11, NovaCraftBlocks.basal_bricks, 0, 2);
		world.setBlock(i + 4, j + 20, k + 11, NovaCraftBlocks.basal_bricks, 0, 2);
		world.setBlock(i + 5, j + 20, k + 11, NovaCraftBlocks.cracked_basal_bricks, 0, 2);
		world.setBlock(i + 6, j + 20, k + 11, NovaCraftBlocks.basal_bricks, 0, 2);
		world.setBlock(i + 7, j + 20, k + 11, NovaCraftBlocks.basal_bricks, 0, 2);
		world.setBlock(i + 8, j + 20, k + 11, NovaCraftBlocks.basal_bricks, 0, 2);
		world.setBlock(i + 9, j + 20, k + 11, NovaCraftBlocks.cracked_basal_bricks, 0, 2);
		world.setBlock(i + 10, j + 20, k + 11, NovaCraftBlocks.cracked_basal_bricks, 0, 2);
		world.setBlock(i + 11, j + 20, k + 11, NovaCraftBlocks.basal_bricks, 0, 2);
		world.setBlock(i + 12, j + 20, k + 11, NovaCraftBlocks.basal_bricks, 0, 2);
		world.setBlock(i + 13, j + 20, k + 11, NovaCraftBlocks.basal_bricks, 0, 2);
		world.setBlock(i + 14, j + 20, k + 11, NovaCraftBlocks.cracked_basal_bricks, 0, 2);
		world.setBlock(i + 15, j + 20, k + 11, NovaCraftBlocks.basal_bricks, 0, 2);
		world.setBlock(i + 16, j + 20, k + 11, NovaCraftBlocks.cracked_basal_bricks, 0, 2);
		world.setBlock(i + 17, j + 20, k + 11, NovaCraftBlocks.cracked_basal_bricks, 0, 2);
		world.setBlock(i + 18, j + 20, k + 11, NovaCraftBlocks.cracked_basal_bricks, 0, 2);
		world.setBlock(i + 19, j + 20, k + 11, NovaCraftBlocks.basal_bricks, 0, 2);
		world.setBlock(i + 20, j + 20, k + 11, NovaCraftBlocks.cracked_basal_bricks, 0, 2);
		world.setBlock(i + 21, j + 20, k + 11, NovaCraftBlocks.basal_bricks, 0, 2);
		world.setBlock(i + 22, j + 20, k + 11, NovaCraftBlocks.cracked_basal_bricks, 0, 2);
		world.setBlock(i + 23, j + 20, k + 11, NovaCraftBlocks.basal_bricks, 0, 2);
		world.setBlock(i + 24, j + 20, k + 11, NovaCraftBlocks.cracked_basal_bricks, 0, 2);
		world.setBlock(i + 25, j + 20, k + 11, NovaCraftBlocks.basal_bricks, 0, 2);
		world.setBlock(i + 26, j + 20, k + 11, NovaCraftBlocks.cracked_basal_bricks, 0, 2);
		world.setBlock(i + 27, j + 20, k + 11, Blocks.air, 0, 2);
		world.setBlock(i, j + 20, k + 12, NovaCraftBlocks.basal_bricks, 0, 2);
		world.setBlock(i + 1, j + 20, k + 12, NovaCraftBlocks.cracked_basal_bricks, 0, 2);
		world.setBlock(i + 2, j + 20, k + 12, NovaCraftBlocks.basal_bricks, 0, 2);
		world.setBlock(i + 3, j + 20, k + 12, NovaCraftBlocks.basal_bricks, 0, 2);
		world.setBlock(i + 4, j + 20, k + 12, NovaCraftBlocks.cracked_basal_bricks, 0, 2);
		world.setBlock(i + 5, j + 20, k + 12, NovaCraftBlocks.cracked_basal_bricks, 0, 2);
		world.setBlock(i + 6, j + 20, k + 12, NovaCraftBlocks.basal_bricks, 0, 2);
		world.setBlock(i + 7, j + 20, k + 12, NovaCraftBlocks.basal_bricks, 0, 2);
		world.setBlock(i + 8, j + 20, k + 12, NovaCraftBlocks.cracked_basal_bricks, 0, 2);
		world.setBlock(i + 9, j + 20, k + 12, NovaCraftBlocks.cracked_basal_bricks, 0, 2);
		world.setBlock(i + 10, j + 20, k + 12, NovaCraftBlocks.basal_bricks, 0, 2);
		world.setBlock(i + 11, j + 20, k + 12, NovaCraftBlocks.cracked_basal_bricks, 0, 2);
		world.setBlock(i + 12, j + 20, k + 12, NovaCraftBlocks.cracked_basal_bricks, 0, 2);
		world.setBlock(i + 13, j + 20, k + 12, NovaCraftBlocks.cracked_basal_bricks, 0, 2);
		world.setBlock(i + 14, j + 20, k + 12, NovaCraftBlocks.cracked_basal_bricks, 0, 2);
		world.setBlock(i + 15, j + 20, k + 12, NovaCraftBlocks.cracked_basal_bricks, 0, 2);
		world.setBlock(i + 16, j + 20, k + 12, NovaCraftBlocks.basal_bricks, 0, 2);
		world.setBlock(i + 17, j + 20, k + 12, NovaCraftBlocks.cracked_basal_bricks, 0, 2);
		world.setBlock(i + 18, j + 20, k + 12, NovaCraftBlocks.basal_bricks, 0, 2);
		world.setBlock(i + 19, j + 20, k + 12, NovaCraftBlocks.basal_bricks, 0, 2);
		world.setBlock(i + 20, j + 20, k + 12, NovaCraftBlocks.basal_bricks, 0, 2);
		world.setBlock(i + 21, j + 20, k + 12, NovaCraftBlocks.cracked_basal_bricks, 0, 2);
		world.setBlock(i + 22, j + 20, k + 12, NovaCraftBlocks.basal_bricks, 0, 2);
		world.setBlock(i + 23, j + 20, k + 12, NovaCraftBlocks.basal_bricks, 0, 2);
		world.setBlock(i + 24, j + 20, k + 12, NovaCraftBlocks.cracked_basal_bricks, 0, 2);
		world.setBlock(i + 25, j + 20, k + 12, NovaCraftBlocks.cracked_basal_bricks, 0, 2);
		world.setBlock(i + 26, j + 20, k + 12, NovaCraftBlocks.basal_bricks, 0, 2);
		world.setBlock(i + 27, j + 20, k + 12, NovaCraftBlocks.basal_bricks, 0, 2);
		world.setBlock(i, j + 20, k + 13, NovaCraftBlocks.cracked_basal_bricks, 0, 2);
		world.setBlock(i + 1, j + 20, k + 13, NovaCraftBlocks.cracked_basal_bricks, 0, 2);
		world.setBlock(i + 2, j + 20, k + 13, NovaCraftBlocks.basal_bricks, 0, 2);
		world.setBlock(i + 3, j + 20, k + 13, NovaCraftBlocks.basal_bricks, 0, 2);
		world.setBlock(i + 4, j + 20, k + 13, NovaCraftBlocks.cracked_basal_bricks, 0, 2);
		world.setBlock(i + 5, j + 20, k + 13, NovaCraftBlocks.basal_bricks, 0, 2);
		world.setBlock(i + 6, j + 20, k + 13, NovaCraftBlocks.basal_bricks, 0, 2);
		world.setBlock(i + 7, j + 20, k + 13, NovaCraftBlocks.basal_bricks, 0, 2);
		world.setBlock(i + 8, j + 20, k + 13, NovaCraftBlocks.basal_bricks, 0, 2);
		world.setBlock(i + 9, j + 20, k + 13, NovaCraftBlocks.basal_bricks, 0, 2);
		world.setBlock(i + 10, j + 20, k + 13, NovaCraftBlocks.cracked_basal_bricks, 0, 2);
		world.setBlock(i + 11, j + 20, k + 13, NovaCraftBlocks.basal_bricks, 0, 2);
		world.setBlock(i + 12, j + 20, k + 13, NovaCraftBlocks.basal_bricks, 0, 2);
		world.setBlock(i + 13, j + 20, k + 13, NovaCraftBlocks.basal_bricks, 0, 2);
		world.setBlock(i + 14, j + 20, k + 13, NovaCraftBlocks.basal_bricks, 0, 2);
		world.setBlock(i + 15, j + 20, k + 13, NovaCraftBlocks.basal_bricks, 0, 2);
		world.setBlock(i + 16, j + 20, k + 13, NovaCraftBlocks.basal_bricks, 0, 2);
		world.setBlock(i + 17, j + 20, k + 13, NovaCraftBlocks.basal_bricks, 0, 2);
		world.setBlock(i + 18, j + 20, k + 13, NovaCraftBlocks.cracked_basal_bricks, 0, 2);
		world.setBlock(i + 19, j + 20, k + 13, NovaCraftBlocks.basal_bricks, 0, 2);
		world.setBlock(i + 20, j + 20, k + 13, NovaCraftBlocks.basal_bricks, 0, 2);
		world.setBlock(i + 21, j + 20, k + 13, NovaCraftBlocks.basal_bricks, 0, 2);
		world.setBlock(i + 22, j + 20, k + 13, NovaCraftBlocks.basal_bricks, 0, 2);
		world.setBlock(i + 23, j + 20, k + 13, NovaCraftBlocks.basal_bricks, 0, 2);
		world.setBlock(i + 24, j + 20, k + 13, NovaCraftBlocks.basal_bricks, 0, 2);
		world.setBlock(i + 25, j + 20, k + 13, NovaCraftBlocks.basal_bricks, 0, 2);
		world.setBlock(i + 26, j + 20, k + 13, NovaCraftBlocks.basal_bricks, 0, 2);
		world.setBlock(i + 27, j + 20, k + 13, NovaCraftBlocks.cracked_basal_bricks, 0, 2);
		world.setBlock(i, j + 20, k + 14, NovaCraftBlocks.cracked_basal_bricks, 0, 2);
		world.setBlock(i + 1, j + 20, k + 14, NovaCraftBlocks.basal_bricks, 0, 2);
		world.setBlock(i + 2, j + 20, k + 14, NovaCraftBlocks.basal_bricks, 0, 2);
		world.setBlock(i + 3, j + 20, k + 14, NovaCraftBlocks.basal_bricks, 0, 2);
		world.setBlock(i + 4, j + 20, k + 14, NovaCraftBlocks.basal_bricks, 0, 2);
		world.setBlock(i + 5, j + 20, k + 14, NovaCraftBlocks.basal_bricks, 0, 2);
		world.setBlock(i + 6, j + 20, k + 14, NovaCraftBlocks.basal_bricks, 0, 2);
		world.setBlock(i + 7, j + 20, k + 14, NovaCraftBlocks.basal_bricks, 0, 2);
		world.setBlock(i + 8, j + 20, k + 14, NovaCraftBlocks.cracked_basal_bricks, 0, 2);
		world.setBlock(i + 9, j + 20, k + 14, NovaCraftBlocks.basal_bricks, 0, 2);
		world.setBlock(i + 10, j + 20, k + 14, NovaCraftBlocks.cracked_basal_bricks, 0, 2);
		world.setBlock(i + 11, j + 20, k + 14, NovaCraftBlocks.cracked_basal_bricks, 0, 2);
		world.setBlock(i + 12, j + 20, k + 14, NovaCraftBlocks.cracked_basal_bricks, 0, 2);
		world.setBlock(i + 13, j + 20, k + 14, NovaCraftBlocks.cracked_basal_bricks, 0, 2);
		world.setBlock(i + 14, j + 20, k + 14, NovaCraftBlocks.cracked_basal_bricks, 0, 2);
		world.setBlock(i + 15, j + 20, k + 14, NovaCraftBlocks.cracked_basal_bricks, 0, 2);
		world.setBlock(i + 16, j + 20, k + 14, NovaCraftBlocks.basal_bricks, 0, 2);
		world.setBlock(i + 17, j + 20, k + 14, NovaCraftBlocks.cracked_basal_bricks, 0, 2);
		world.setBlock(i + 18, j + 20, k + 14, NovaCraftBlocks.basal_bricks, 0, 2);
		world.setBlock(i + 19, j + 20, k + 14, NovaCraftBlocks.cracked_basal_bricks, 0, 2);
		world.setBlock(i + 20, j + 20, k + 14, NovaCraftBlocks.cracked_basal_bricks, 0, 2);
		world.setBlock(i + 21, j + 20, k + 14, NovaCraftBlocks.cracked_basal_bricks, 0, 2);
		world.setBlock(i + 22, j + 20, k + 14, NovaCraftBlocks.basal_bricks, 0, 2);
		world.setBlock(i + 23, j + 20, k + 14, NovaCraftBlocks.basal_bricks, 0, 2);
		world.setBlock(i + 24, j + 20, k + 14, NovaCraftBlocks.basal_bricks, 0, 2);
		world.setBlock(i + 25, j + 20, k + 14, NovaCraftBlocks.basal_bricks, 0, 2);
		world.setBlock(i + 26, j + 20, k + 14, NovaCraftBlocks.basal_bricks, 0, 2);
		world.setBlock(i + 27, j + 20, k + 14, NovaCraftBlocks.cracked_basal_bricks, 0, 2);
		world.setBlock(i, j + 20, k + 15, NovaCraftBlocks.cracked_basal_bricks, 0, 2);
		world.setBlock(i + 1, j + 20, k + 15, NovaCraftBlocks.basal_bricks, 0, 2);
		world.setBlock(i + 2, j + 20, k + 15, NovaCraftBlocks.cracked_basal_bricks, 0, 2);
		world.setBlock(i + 3, j + 20, k + 15, NovaCraftBlocks.cracked_basal_bricks, 0, 2);
		world.setBlock(i + 4, j + 20, k + 15, NovaCraftBlocks.cracked_basal_bricks, 0, 2);
		world.setBlock(i + 5, j + 20, k + 15, NovaCraftBlocks.cracked_basal_bricks, 0, 2);
		world.setBlock(i + 6, j + 20, k + 15, NovaCraftBlocks.basal_bricks, 0, 2);
		world.setBlock(i + 7, j + 20, k + 15, NovaCraftBlocks.cracked_basal_bricks, 0, 2);
		world.setBlock(i + 8, j + 20, k + 15, NovaCraftBlocks.basal_bricks, 0, 2);
		world.setBlock(i + 9, j + 20, k + 15, NovaCraftBlocks.basal_bricks, 0, 2);
		world.setBlock(i + 10, j + 20, k + 15, NovaCraftBlocks.basal_bricks, 0, 2);
		world.setBlock(i + 11, j + 20, k + 15, NovaCraftBlocks.basal_bricks, 0, 2);
		world.setBlock(i + 12, j + 20, k + 15, NovaCraftBlocks.cracked_basal_bricks, 0, 2);
		world.setBlock(i + 13, j + 20, k + 15, NovaCraftBlocks.cracked_basal_bricks, 0, 2);
		world.setBlock(i + 14, j + 20, k + 15, NovaCraftBlocks.basal_bricks, 0, 2);
		world.setBlock(i + 15, j + 20, k + 15, NovaCraftBlocks.basal_bricks, 0, 2);
		world.setBlock(i + 16, j + 20, k + 15, NovaCraftBlocks.cracked_basal_bricks, 0, 2);
		world.setBlock(i + 17, j + 20, k + 15, NovaCraftBlocks.basal_bricks, 0, 2);
		world.setBlock(i + 18, j + 20, k + 15, NovaCraftBlocks.cracked_basal_bricks, 0, 2);
		world.setBlock(i + 19, j + 20, k + 15, NovaCraftBlocks.cracked_basal_bricks, 0, 2);
		world.setBlock(i + 20, j + 20, k + 15, NovaCraftBlocks.basal_bricks, 0, 2);
		world.setBlock(i + 21, j + 20, k + 15, NovaCraftBlocks.cracked_basal_bricks, 0, 2);
		world.setBlock(i + 22, j + 20, k + 15, NovaCraftBlocks.basal_bricks, 0, 2);
		world.setBlock(i + 23, j + 20, k + 15, NovaCraftBlocks.cracked_basal_bricks, 0, 2);
		world.setBlock(i + 24, j + 20, k + 15, NovaCraftBlocks.basal_bricks, 0, 2);
		world.setBlock(i + 25, j + 20, k + 15, NovaCraftBlocks.cracked_basal_bricks, 0, 2);
		world.setBlock(i + 26, j + 20, k + 15, NovaCraftBlocks.cracked_basal_bricks, 0, 2);
		world.setBlock(i + 27, j + 20, k + 15, NovaCraftBlocks.basal_bricks, 0, 2);
		world.setBlock(i, j + 20, k + 16, NovaCraftBlocks.basal_bricks, 0, 2);
		world.setBlock(i + 1, j + 20, k + 16, NovaCraftBlocks.cracked_basal_bricks, 0, 2);
		world.setBlock(i + 2, j + 20, k + 16, NovaCraftBlocks.basal_bricks, 0, 2);
		world.setBlock(i + 3, j + 20, k + 16, NovaCraftBlocks.basal_bricks, 0, 2);
		world.setBlock(i + 4, j + 20, k + 16, NovaCraftBlocks.basal_bricks, 0, 2);
		world.setBlock(i + 5, j + 20, k + 16, NovaCraftBlocks.cracked_basal_bricks, 0, 2);
		world.setBlock(i + 6, j + 20, k + 16, NovaCraftBlocks.basal_bricks, 0, 2);
		world.setBlock(i + 7, j + 20, k + 16, NovaCraftBlocks.basal_bricks, 0, 2);
		world.setBlock(i + 8, j + 20, k + 16, NovaCraftBlocks.cracked_basal_bricks, 0, 2);
		world.setBlock(i + 9, j + 20, k + 16, NovaCraftBlocks.basal_bricks, 0, 2);
		world.setBlock(i + 10, j + 20, k + 16, NovaCraftBlocks.cracked_basal_bricks, 0, 2);
		world.setBlock(i + 11, j + 20, k + 16, NovaCraftBlocks.cracked_basal_bricks, 0, 2);
		world.setBlock(i + 12, j + 20, k + 16, NovaCraftBlocks.basal_bricks, 0, 2);
		world.setBlock(i + 13, j + 20, k + 16, NovaCraftBlocks.basal_bricks, 0, 2);
		world.setBlock(i + 14, j + 20, k + 16, NovaCraftBlocks.basal_bricks, 0, 2);
		world.setBlock(i + 15, j + 20, k + 16, NovaCraftBlocks.cracked_basal_bricks, 0, 2);
		world.setBlock(i + 16, j + 20, k + 16, NovaCraftBlocks.cracked_basal_bricks, 0, 2);
		world.setBlock(i + 17, j + 20, k + 16, NovaCraftBlocks.basal_bricks, 0, 2);
		world.setBlock(i + 18, j + 20, k + 16, NovaCraftBlocks.basal_bricks, 0, 2);
		world.setBlock(i + 19, j + 20, k + 16, NovaCraftBlocks.cracked_basal_bricks, 0, 2);
		world.setBlock(i + 20, j + 20, k + 16, NovaCraftBlocks.basal_bricks, 0, 2);
		world.setBlock(i + 21, j + 20, k + 16, NovaCraftBlocks.basal_bricks, 0, 2);
		world.setBlock(i + 22, j + 20, k + 16, NovaCraftBlocks.basal_bricks, 0, 2);
		world.setBlock(i + 23, j + 20, k + 16, NovaCraftBlocks.cracked_basal_bricks, 0, 2);
		world.setBlock(i + 24, j + 20, k + 16, NovaCraftBlocks.basal_bricks, 0, 2);
		world.setBlock(i + 25, j + 20, k + 16, NovaCraftBlocks.cracked_basal_bricks, 0, 2);
		world.setBlock(i + 26, j + 20, k + 16, NovaCraftBlocks.basal_bricks, 0, 2);
		world.setBlock(i + 27, j + 20, k + 16, NovaCraftBlocks.basal_bricks, 0, 2);
		world.setBlock(i, j + 20, k + 17, NovaCraftBlocks.cracked_basal_bricks, 0, 2);
		world.setBlock(i + 1, j + 20, k + 17, NovaCraftBlocks.cracked_basal_bricks, 0, 2);
		world.setBlock(i + 2, j + 20, k + 17, NovaCraftBlocks.cracked_basal_bricks, 0, 2);
		world.setBlock(i + 3, j + 20, k + 17, NovaCraftBlocks.basal_bricks, 0, 2);
		world.setBlock(i + 4, j + 20, k + 17, NovaCraftBlocks.cracked_basal_bricks, 0, 2);
		world.setBlock(i + 5, j + 20, k + 17, NovaCraftBlocks.basal_bricks, 0, 2);
		world.setBlock(i + 6, j + 20, k + 17, NovaCraftBlocks.basal_bricks, 0, 2);
		world.setBlock(i + 7, j + 20, k + 17, NovaCraftBlocks.basal_bricks, 0, 2);
		world.setBlock(i + 8, j + 20, k + 17, NovaCraftBlocks.basal_bricks, 0, 2);
		world.setBlock(i + 9, j + 20, k + 17, NovaCraftBlocks.basal_bricks, 0, 2);
		world.setBlock(i + 10, j + 20, k + 17, NovaCraftBlocks.basal_bricks, 0, 2);
		world.setBlock(i + 11, j + 20, k + 17, NovaCraftBlocks.basal_bricks, 0, 2);
		world.setBlock(i + 12, j + 20, k + 17, NovaCraftBlocks.cracked_basal_bricks, 0, 2);
		world.setBlock(i + 13, j + 20, k + 17, NovaCraftBlocks.basal_bricks, 0, 2);
		world.setBlock(i + 14, j + 20, k + 17, NovaCraftBlocks.cracked_basal_bricks, 0, 2);
		world.setBlock(i + 15, j + 20, k + 17, NovaCraftBlocks.cracked_basal_bricks, 0, 2);
		world.setBlock(i + 16, j + 20, k + 17, NovaCraftBlocks.basal_bricks, 0, 2);
		world.setBlock(i + 17, j + 20, k + 17, NovaCraftBlocks.cracked_basal_bricks, 0, 2);
		world.setBlock(i + 18, j + 20, k + 17, NovaCraftBlocks.basal_bricks, 0, 2);
		world.setBlock(i + 19, j + 20, k + 17, NovaCraftBlocks.basal_bricks, 0, 2);
		world.setBlock(i + 20, j + 20, k + 17, NovaCraftBlocks.basal_bricks, 0, 2);
		world.setBlock(i + 21, j + 20, k + 17, NovaCraftBlocks.cracked_basal_bricks, 0, 2);
		world.setBlock(i + 22, j + 20, k + 17, NovaCraftBlocks.cracked_basal_bricks, 0, 2);
		world.setBlock(i + 23, j + 20, k + 17, NovaCraftBlocks.basal_bricks, 0, 2);
		world.setBlock(i + 24, j + 20, k + 17, NovaCraftBlocks.basal_bricks, 0, 2);
		world.setBlock(i + 25, j + 20, k + 17, NovaCraftBlocks.basal_bricks, 0, 2);
		world.setBlock(i + 26, j + 20, k + 17, NovaCraftBlocks.basal_bricks, 0, 2);
		world.setBlock(i + 27, j + 20, k + 17, NovaCraftBlocks.basal_bricks, 0, 2);
		world.setBlock(i, j + 20, k + 18, NovaCraftBlocks.basal_bricks, 0, 2);
		world.setBlock(i + 1, j + 20, k + 18, NovaCraftBlocks.basal_bricks, 0, 2);
		world.setBlock(i + 2, j + 20, k + 18, NovaCraftBlocks.basal_bricks, 0, 2);
		world.setBlock(i + 3, j + 20, k + 18, NovaCraftBlocks.cracked_basal_bricks, 0, 2);
		world.setBlock(i + 4, j + 20, k + 18, NovaCraftBlocks.cracked_basal_bricks, 0, 2);
		world.setBlock(i + 5, j + 20, k + 18, NovaCraftBlocks.basal_bricks, 0, 2);
		world.setBlock(i + 6, j + 20, k + 18, NovaCraftBlocks.basal_bricks, 0, 2);
		world.setBlock(i + 7, j + 20, k + 18, NovaCraftBlocks.basal_bricks, 0, 2);
		world.setBlock(i + 8, j + 20, k + 18, NovaCraftBlocks.cracked_basal_bricks, 0, 2);
		world.setBlock(i + 9, j + 20, k + 18, NovaCraftBlocks.cracked_basal_bricks, 0, 2);
		world.setBlock(i + 10, j + 20, k + 18, NovaCraftBlocks.basal_bricks, 0, 2);
		world.setBlock(i + 11, j + 20, k + 18, NovaCraftBlocks.basal_bricks, 0, 2);
		world.setBlock(i + 12, j + 20, k + 18, NovaCraftBlocks.cracked_basal_bricks, 0, 2);
		world.setBlock(i + 13, j + 20, k + 18, NovaCraftBlocks.cracked_basal_bricks, 0, 2);
		world.setBlock(i + 14, j + 20, k + 18, NovaCraftBlocks.basal_bricks, 0, 2);
		world.setBlock(i + 15, j + 20, k + 18, NovaCraftBlocks.cracked_basal_bricks, 0, 2);
		world.setBlock(i + 16, j + 20, k + 18, NovaCraftBlocks.basal_bricks, 0, 2);
		world.setBlock(i + 17, j + 20, k + 18, NovaCraftBlocks.basal_bricks, 0, 2);
		world.setBlock(i + 18, j + 20, k + 18, NovaCraftBlocks.cracked_basal_bricks, 0, 2);
		world.setBlock(i + 19, j + 20, k + 18, NovaCraftBlocks.cracked_basal_bricks, 0, 2);
		world.setBlock(i + 20, j + 20, k + 18, NovaCraftBlocks.basal_bricks, 0, 2);
		world.setBlock(i + 21, j + 20, k + 18, NovaCraftBlocks.cracked_basal_bricks, 0, 2);
		world.setBlock(i + 22, j + 20, k + 18, NovaCraftBlocks.basal_bricks, 0, 2);
		world.setBlock(i + 23, j + 20, k + 18, NovaCraftBlocks.basal_bricks, 0, 2);
		world.setBlock(i + 24, j + 20, k + 18, NovaCraftBlocks.basal_bricks, 0, 2);
		world.setBlock(i + 25, j + 20, k + 18, NovaCraftBlocks.cracked_basal_bricks, 0, 2);
		world.setBlock(i + 26, j + 20, k + 18, NovaCraftBlocks.basal_bricks, 0, 2);
		world.setBlock(i + 27, j + 20, k + 18, NovaCraftBlocks.basal_bricks, 0, 2);
		world.setBlock(i, j + 21, k, Blocks.air, 0, 2);
		world.setBlock(i + 1, j + 21, k, Blocks.air, 0, 2);
		world.setBlock(i + 2, j + 21, k, NovaCraftBlocks.basal_bricks, 0, 2);
		world.setBlock(i + 3, j + 21, k, NovaCraftBlocks.basal_bricks, 0, 2);
		world.setBlock(i + 4, j + 21, k, NovaCraftBlocks.cracked_basal_bricks, 0, 2);
		world.setBlock(i + 5, j + 21, k, NovaCraftBlocks.basal_bricks, 0, 2);
		world.setBlock(i + 6, j + 21, k, NovaCraftBlocks.basal_bricks, 0, 2);
		world.setBlock(i + 7, j + 21, k, NovaCraftBlocks.basal_bricks, 0, 2);
		world.setBlock(i + 8, j + 21, k, NovaCraftBlocks.cracked_basal_bricks, 0, 2);
		world.setBlock(i + 9, j + 21, k, NovaCraftBlocks.cracked_basal_bricks, 0, 2);
		world.setBlock(i + 10, j + 21, k, NovaCraftBlocks.basal_bricks, 0, 2);
		world.setBlock(i + 11, j + 21, k, NovaCraftBlocks.cracked_basal_bricks, 0, 2);
		world.setBlock(i + 12, j + 21, k, NovaCraftBlocks.basal_bricks, 0, 2);
		world.setBlock(i + 13, j + 21, k, NovaCraftBlocks.basal_bricks, 0, 2);
		world.setBlock(i + 14, j + 21, k, Blocks.air, 0, 2);
		world.setBlock(i + 15, j + 21, k, Blocks.air, 0, 2);
		world.setBlock(i + 16, j + 21, k, Blocks.air, 0, 2);
		world.setBlock(i + 17, j + 21, k, Blocks.air, 0, 2);
		world.setBlock(i + 18, j + 21, k, NovaCraftBlocks.basal_bricks, 0, 2);
		world.setBlock(i + 19, j + 21, k, NovaCraftBlocks.basal_bricks, 0, 2);
		world.setBlock(i + 20, j + 21, k, NovaCraftBlocks.basal_bricks, 0, 2);
		world.setBlock(i + 21, j + 21, k, NovaCraftBlocks.basal_bricks, 0, 2);
		world.setBlock(i + 22, j + 21, k, NovaCraftBlocks.basal_bricks, 0, 2);
		world.setBlock(i + 23, j + 21, k, NovaCraftBlocks.basal_bricks, 0, 2);
		world.setBlock(i + 24, j + 21, k, NovaCraftBlocks.basal_bricks, 0, 2);
		world.setBlock(i + 25, j + 21, k, NovaCraftBlocks.basal_bricks, 0, 2);
		world.setBlock(i + 26, j + 21, k, NovaCraftBlocks.cracked_basal_bricks, 0, 2);
		world.setBlock(i + 27, j + 21, k, NovaCraftBlocks.basal_bricks, 0, 2);
		world.setBlock(i, j + 21, k + 1, NovaCraftBlocks.cracked_basal_bricks, 0, 2);
		world.setBlock(i + 1, j + 21, k + 1, NovaCraftBlocks.basal_bricks, 0, 2);
		world.setBlock(i + 2, j + 21, k + 1, NovaCraftBlocks.cracked_basal_bricks, 0, 2);
		world.setBlock(i + 3, j + 21, k + 1, NovaCraftBlocks.basal_bricks, 0, 2);
		world.setBlock(i + 4, j + 21, k + 1, NovaCraftBlocks.basal_bricks, 0, 2);
		world.setBlock(i + 5, j + 21, k + 1, NovaCraftBlocks.basal_bricks, 0, 2);
		world.setBlock(i + 6, j + 21, k + 1, NovaCraftBlocks.cracked_basal_bricks, 0, 2);
		world.setBlock(i + 7, j + 21, k + 1, NovaCraftBlocks.basal_bricks, 0, 2);
		world.setBlock(i + 8, j + 21, k + 1, NovaCraftBlocks.cracked_basal_bricks, 0, 2);
		world.setBlock(i + 9, j + 21, k + 1, NovaCraftBlocks.basal_bricks, 0, 2);
		world.setBlock(i + 10, j + 21, k + 1, NovaCraftBlocks.basal_bricks, 0, 2);
		world.setBlock(i + 11, j + 21, k + 1, NovaCraftBlocks.basal_bricks, 0, 2);
		world.setBlock(i + 12, j + 21, k + 1, NovaCraftBlocks.basal_bricks, 0, 2);
		world.setBlock(i + 13, j + 21, k + 1, NovaCraftBlocks.cracked_basal_bricks, 0, 2);
		world.setBlock(i + 14, j + 21, k + 1, Blocks.air, 0, 2);
		world.setBlock(i + 15, j + 21, k + 1, Blocks.air, 0, 2);
		world.setBlock(i + 16, j + 21, k + 1, Blocks.air, 0, 2);
		world.setBlock(i + 17, j + 21, k + 1, NovaCraftBlocks.basal_bricks, 0, 2);
		world.setBlock(i + 18, j + 21, k + 1, NovaCraftBlocks.basal_bricks, 0, 2);
		world.setBlock(i + 19, j + 21, k + 1, NovaCraftBlocks.cracked_basal_bricks, 0, 2);
		world.setBlock(i + 20, j + 21, k + 1, NovaCraftBlocks.cracked_basal_bricks, 0, 2);
		world.setBlock(i + 21, j + 21, k + 1, NovaCraftBlocks.basal_bricks, 0, 2);
		world.setBlock(i + 22, j + 21, k + 1, NovaCraftBlocks.cracked_basal_bricks, 0, 2);
		world.setBlock(i + 23, j + 21, k + 1, NovaCraftBlocks.cracked_basal_bricks, 0, 2);
		world.setBlock(i + 24, j + 21, k + 1, NovaCraftBlocks.basal_bricks, 0, 2);
		world.setBlock(i + 25, j + 21, k + 1, NovaCraftBlocks.cracked_basal_bricks, 0, 2);
		world.setBlock(i + 26, j + 21, k + 1, NovaCraftBlocks.cracked_basal_bricks, 0, 2);
		world.setBlock(i + 27, j + 21, k + 1, NovaCraftBlocks.basal_bricks, 0, 2);
		world.setBlock(i, j + 21, k + 2, NovaCraftBlocks.basal_bricks, 0, 2);
		world.setBlock(i + 1, j + 21, k + 2, NovaCraftBlocks.cracked_basal_bricks, 0, 2);
		world.setBlock(i + 2, j + 21, k + 2, NovaCraftBlocks.cracked_basal_bricks, 0, 2);
		world.setBlock(i + 3, j + 21, k + 2, NovaCraftBlocks.basal_bricks, 0, 2);
		world.setBlock(i + 4, j + 21, k + 2, NovaCraftBlocks.cracked_basal_bricks, 0, 2);
		world.setBlock(i + 5, j + 21, k + 2, NovaCraftBlocks.basal_bricks, 0, 2);
		world.setBlock(i + 6, j + 21, k + 2, NovaCraftBlocks.cracked_basal_bricks, 0, 2);
		world.setBlock(i + 7, j + 21, k + 2, NovaCraftBlocks.basal_bricks, 0, 2);
		world.setBlock(i + 8, j + 21, k + 2, NovaCraftBlocks.cracked_basal_bricks, 0, 2);
		world.setBlock(i + 9, j + 21, k + 2, NovaCraftBlocks.cracked_basal_bricks, 0, 2);
		world.setBlock(i + 10, j + 21, k + 2, NovaCraftBlocks.basal_bricks, 0, 2);
		world.setBlock(i + 11, j + 21, k + 2, NovaCraftBlocks.cracked_basal_bricks, 0, 2);
		world.setBlock(i + 12, j + 21, k + 2, NovaCraftBlocks.basal_bricks, 0, 2);
		world.setBlock(i + 13, j + 21, k + 2, NovaCraftBlocks.basal_bricks, 0, 2);
		world.setBlock(i + 14, j + 21, k + 2, Blocks.air, 0, 2);
		world.setBlock(i + 15, j + 21, k + 2, Blocks.air, 0, 2);
		world.setBlock(i + 16, j + 21, k + 2, NovaCraftBlocks.cracked_basal_bricks, 0, 2);
		world.setBlock(i + 17, j + 21, k + 2, NovaCraftBlocks.basal_bricks, 0, 2);
		world.setBlock(i + 18, j + 21, k + 2, NovaCraftBlocks.cracked_basal_bricks, 0, 2);
		world.setBlock(i + 19, j + 21, k + 2, NovaCraftBlocks.basal_bricks, 0, 2);
		world.setBlock(i + 20, j + 21, k + 2, NovaCraftBlocks.basal_bricks, 0, 2);
		world.setBlock(i + 21, j + 21, k + 2, NovaCraftBlocks.basal_bricks, 0, 2);
		world.setBlock(i + 22, j + 21, k + 2, NovaCraftBlocks.basal_bricks, 0, 2);
		world.setBlock(i + 23, j + 21, k + 2, NovaCraftBlocks.cracked_basal_bricks, 0, 2);
		world.setBlock(i + 24, j + 21, k + 2, NovaCraftBlocks.cracked_basal_bricks, 0, 2);
		world.setBlock(i + 25, j + 21, k + 2, NovaCraftBlocks.cracked_basal_bricks, 0, 2);
		world.setBlock(i + 26, j + 21, k + 2, NovaCraftBlocks.cracked_basal_bricks, 0, 2);
		world.setBlock(i + 27, j + 21, k + 2, NovaCraftBlocks.cracked_basal_bricks, 0, 2);
		world.setBlock(i, j + 21, k + 3, NovaCraftBlocks.cracked_basal_bricks, 0, 2);
		world.setBlock(i + 1, j + 21, k + 3, NovaCraftBlocks.cracked_basal_bricks, 0, 2);
		world.setBlock(i + 2, j + 21, k + 3, NovaCraftBlocks.basal_bricks, 0, 2);
		world.setBlock(i + 3, j + 21, k + 3, NovaCraftBlocks.cracked_basal_bricks, 0, 2);
		world.setBlock(i + 4, j + 21, k + 3, NovaCraftBlocks.cracked_basal_bricks, 0, 2);
		world.setBlock(i + 5, j + 21, k + 3, NovaCraftBlocks.basal_bricks, 0, 2);
		world.setBlock(i + 6, j + 21, k + 3, NovaCraftBlocks.cracked_basal_bricks, 0, 2);
		world.setBlock(i + 7, j + 21, k + 3, NovaCraftBlocks.cracked_basal_bricks, 0, 2);
		world.setBlock(i + 8, j + 21, k + 3, NovaCraftBlocks.basal_bricks, 0, 2);
		world.setBlock(i + 9, j + 21, k + 3, NovaCraftBlocks.cracked_basal_bricks, 0, 2);
		world.setBlock(i + 10, j + 21, k + 3, NovaCraftBlocks.basal_bricks, 0, 2);
		world.setBlock(i + 11, j + 21, k + 3, NovaCraftBlocks.basal_bricks, 0, 2);
		world.setBlock(i + 12, j + 21, k + 3, NovaCraftBlocks.basal_bricks, 0, 2);
		world.setBlock(i + 13, j + 21, k + 3, NovaCraftBlocks.basal_bricks, 0, 2);
		world.setBlock(i + 14, j + 21, k + 3, NovaCraftBlocks.cracked_basal_bricks, 0, 2);
		world.setBlock(i + 15, j + 21, k + 3, NovaCraftBlocks.cracked_basal_bricks, 0, 2);
		world.setBlock(i + 16, j + 21, k + 3, NovaCraftBlocks.cracked_basal_bricks, 0, 2);
		world.setBlock(i + 17, j + 21, k + 3, NovaCraftBlocks.cracked_basal_bricks, 0, 2);
		world.setBlock(i + 18, j + 21, k + 3, NovaCraftBlocks.basal_bricks, 0, 2);
		world.setBlock(i + 19, j + 21, k + 3, NovaCraftBlocks.basal_bricks, 0, 2);
		world.setBlock(i + 20, j + 21, k + 3, NovaCraftBlocks.basal_bricks, 0, 2);
		world.setBlock(i + 21, j + 21, k + 3, NovaCraftBlocks.basal_bricks, 0, 2);
		world.setBlock(i + 22, j + 21, k + 3, NovaCraftBlocks.basal_bricks, 0, 2);
		world.setBlock(i + 23, j + 21, k + 3, NovaCraftBlocks.basal_bricks, 0, 2);
		world.setBlock(i + 24, j + 21, k + 3, NovaCraftBlocks.basal_bricks, 0, 2);
		world.setBlock(i + 25, j + 21, k + 3, NovaCraftBlocks.cracked_basal_bricks, 0, 2);
		world.setBlock(i + 26, j + 21, k + 3, NovaCraftBlocks.basal_bricks, 0, 2);
		world.setBlock(i + 27, j + 21, k + 3, NovaCraftBlocks.cracked_basal_bricks, 0, 2);
		world.setBlock(i, j + 21, k + 4, NovaCraftBlocks.basal_bricks, 0, 2);
		world.setBlock(i + 1, j + 21, k + 4, NovaCraftBlocks.basal_bricks, 0, 2);
		world.setBlock(i + 2, j + 21, k + 4, NovaCraftBlocks.cracked_basal_bricks, 0, 2);
		world.setBlock(i + 3, j + 21, k + 4, NovaCraftBlocks.basal_bricks, 0, 2);
		world.setBlock(i + 4, j + 21, k + 4, NovaCraftBlocks.cracked_basal_bricks, 0, 2);
		world.setBlock(i + 5, j + 21, k + 4, NovaCraftBlocks.basal_bricks, 0, 2);
		world.setBlock(i + 6, j + 21, k + 4, NovaCraftBlocks.basal_bricks, 0, 2);
		world.setBlock(i + 7, j + 21, k + 4, NovaCraftBlocks.cracked_basal_bricks, 0, 2);
		world.setBlock(i + 8, j + 21, k + 4, NovaCraftBlocks.cracked_basal_bricks, 0, 2);
		world.setBlock(i + 9, j + 21, k + 4, NovaCraftBlocks.basal_bricks, 0, 2);
		world.setBlock(i + 10, j + 21, k + 4, NovaCraftBlocks.cracked_basal_bricks, 0, 2);
		world.setBlock(i + 11, j + 21, k + 4, NovaCraftBlocks.cracked_basal_bricks, 0, 2);
		world.setBlock(i + 12, j + 21, k + 4, Blocks.air, 0, 2);
		world.setBlock(i + 13, j + 21, k + 4, Blocks.air, 0, 2);
		world.setBlock(i + 14, j + 21, k + 4, NovaCraftBlocks.basal_bricks, 0, 2);
		world.setBlock(i + 15, j + 21, k + 4, NovaCraftBlocks.basal_bricks, 0, 2);
		world.setBlock(i + 16, j + 21, k + 4, NovaCraftBlocks.basal_bricks, 0, 2);
		world.setBlock(i + 17, j + 21, k + 4, NovaCraftBlocks.basal_bricks, 0, 2);
		world.setBlock(i + 18, j + 21, k + 4, NovaCraftBlocks.cracked_basal_bricks, 0, 2);
		world.setBlock(i + 19, j + 21, k + 4, NovaCraftBlocks.basal_bricks, 0, 2);
		world.setBlock(i + 20, j + 21, k + 4, NovaCraftBlocks.cracked_basal_bricks, 0, 2);
		world.setBlock(i + 21, j + 21, k + 4, NovaCraftBlocks.basal_bricks, 0, 2);
		world.setBlock(i + 22, j + 21, k + 4, NovaCraftBlocks.basal_bricks, 0, 2);
		world.setBlock(i + 23, j + 21, k + 4, NovaCraftBlocks.basal_bricks, 0, 2);
		world.setBlock(i + 24, j + 21, k + 4, NovaCraftBlocks.cracked_basal_bricks, 0, 2);
		world.setBlock(i + 25, j + 21, k + 4, NovaCraftBlocks.basal_bricks, 0, 2);
		world.setBlock(i + 26, j + 21, k + 4, NovaCraftBlocks.basal_bricks, 0, 2);
		world.setBlock(i + 27, j + 21, k + 4, NovaCraftBlocks.cracked_basal_bricks, 0, 2);
		world.setBlock(i, j + 21, k + 5, NovaCraftBlocks.basal_bricks, 0, 2);
		world.setBlock(i + 1, j + 21, k + 5, NovaCraftBlocks.basal_bricks, 0, 2);
		world.setBlock(i + 2, j + 21, k + 5, NovaCraftBlocks.basal_bricks, 0, 2);
		world.setBlock(i + 3, j + 21, k + 5, NovaCraftBlocks.cracked_basal_bricks, 0, 2);
		world.setBlock(i + 4, j + 21, k + 5, NovaCraftBlocks.cracked_basal_bricks, 0, 2);
		world.setBlock(i + 5, j + 21, k + 5, NovaCraftBlocks.basal_bricks, 0, 2);
		world.setBlock(i + 6, j + 21, k + 5, NovaCraftBlocks.cracked_basal_bricks, 0, 2);
		world.setBlock(i + 7, j + 21, k + 5, NovaCraftBlocks.basal_bricks, 0, 2);
		world.setBlock(i + 8, j + 21, k + 5, NovaCraftBlocks.cracked_basal_bricks, 0, 2);
		world.setBlock(i + 9, j + 21, k + 5, NovaCraftBlocks.basal_bricks, 0, 2);
		world.setBlock(i + 10, j + 21, k + 5, NovaCraftBlocks.basal_bricks, 0, 2);
		world.setBlock(i + 11, j + 21, k + 5, NovaCraftBlocks.basal_bricks, 0, 2);
		world.setBlock(i + 12, j + 21, k + 5, Blocks.air, 0, 2);
		world.setBlock(i + 13, j + 21, k + 5, Blocks.air, 0, 2);
		world.setBlock(i + 14, j + 21, k + 5, NovaCraftBlocks.basal_bricks, 0, 2);
		world.setBlock(i + 15, j + 21, k + 5, NovaCraftBlocks.cracked_basal_bricks, 0, 2);
		world.setBlock(i + 16, j + 21, k + 5, NovaCraftBlocks.cracked_basal_bricks, 0, 2);
		world.setBlock(i + 17, j + 21, k + 5, NovaCraftBlocks.cracked_basal_bricks, 0, 2);
		world.setBlock(i + 18, j + 21, k + 5, NovaCraftBlocks.cracked_basal_bricks, 0, 2);
		world.setBlock(i + 19, j + 21, k + 5, NovaCraftBlocks.basal_bricks, 0, 2);
		world.setBlock(i + 20, j + 21, k + 5, NovaCraftBlocks.basal_bricks, 0, 2);
		world.setBlock(i + 21, j + 21, k + 5, NovaCraftBlocks.basal_bricks, 0, 2);
		world.setBlock(i + 22, j + 21, k + 5, NovaCraftBlocks.basal_bricks, 0, 2);
		world.setBlock(i + 23, j + 21, k + 5, NovaCraftBlocks.cracked_basal_bricks, 0, 2);
		world.setBlock(i + 24, j + 21, k + 5, NovaCraftBlocks.cracked_basal_bricks, 0, 2);
		world.setBlock(i + 25, j + 21, k + 5, NovaCraftBlocks.basal_bricks, 0, 2);
		world.setBlock(i + 26, j + 21, k + 5, NovaCraftBlocks.basal_bricks, 0, 2);
		world.setBlock(i + 27, j + 21, k + 5, NovaCraftBlocks.basal_bricks, 0, 2);
		world.setBlock(i, j + 21, k + 6, NovaCraftBlocks.basal_bricks, 0, 2);
		world.setBlock(i + 1, j + 21, k + 6, NovaCraftBlocks.basal_bricks, 0, 2);
		world.setBlock(i + 2, j + 21, k + 6, NovaCraftBlocks.basal_bricks, 0, 2);
		world.setBlock(i + 3, j + 21, k + 6, NovaCraftBlocks.basal_bricks, 0, 2);
		world.setBlock(i + 4, j + 21, k + 6, NovaCraftBlocks.cracked_basal_bricks, 0, 2);
		world.setBlock(i + 5, j + 21, k + 6, NovaCraftBlocks.basal_bricks, 0, 2);
		world.setBlock(i + 6, j + 21, k + 6, NovaCraftBlocks.cracked_basal_bricks, 0, 2);
		world.setBlock(i + 7, j + 21, k + 6, NovaCraftBlocks.cracked_basal_bricks, 0, 2);
		world.setBlock(i + 8, j + 21, k + 6, NovaCraftBlocks.basal_bricks, 0, 2);
		world.setBlock(i + 9, j + 21, k + 6, NovaCraftBlocks.basal_bricks, 0, 2);
		world.setBlock(i + 10, j + 21, k + 6, NovaCraftBlocks.cracked_basal_bricks, 0, 2);
		world.setBlock(i + 11, j + 21, k + 6, NovaCraftBlocks.basal_bricks, 0, 2);
		world.setBlock(i + 12, j + 21, k + 6, Blocks.air, 0, 2);
		world.setBlock(i + 13, j + 21, k + 6, Blocks.air, 0, 2);
		world.setBlock(i + 14, j + 21, k + 6, NovaCraftBlocks.basal_bricks, 0, 2);
		world.setBlock(i + 15, j + 21, k + 6, NovaCraftBlocks.cracked_basal_bricks, 0, 2);
		world.setBlock(i + 16, j + 21, k + 6, NovaCraftBlocks.cracked_basal_bricks, 0, 2);
		world.setBlock(i + 17, j + 21, k + 6, NovaCraftBlocks.basal_bricks, 0, 2);
		world.setBlock(i + 18, j + 21, k + 6, NovaCraftBlocks.basal_bricks, 0, 2);
		world.setBlock(i + 19, j + 21, k + 6, NovaCraftBlocks.basal_bricks, 0, 2);
		world.setBlock(i + 20, j + 21, k + 6, NovaCraftBlocks.basal_bricks, 0, 2);
		world.setBlock(i + 21, j + 21, k + 6, NovaCraftBlocks.basal_bricks, 0, 2);
		world.setBlock(i + 22, j + 21, k + 6, NovaCraftBlocks.basal_bricks, 0, 2);
		world.setBlock(i + 23, j + 21, k + 6, NovaCraftBlocks.basal_bricks, 0, 2);
		world.setBlock(i + 24, j + 21, k + 6, NovaCraftBlocks.basal_bricks, 0, 2);
		world.setBlock(i + 25, j + 21, k + 6, NovaCraftBlocks.cracked_basal_bricks, 0, 2);
		world.setBlock(i + 26, j + 21, k + 6, Blocks.air, 0, 2);
		world.setBlock(i + 27, j + 21, k + 6, Blocks.air, 0, 2);
		world.setBlock(i, j + 21, k + 7, NovaCraftBlocks.basal_bricks, 0, 2);
		world.setBlock(i + 1, j + 21, k + 7, NovaCraftBlocks.basal_bricks, 0, 2);
		world.setBlock(i + 2, j + 21, k + 7, NovaCraftBlocks.cracked_basal_bricks, 0, 2);
		world.setBlock(i + 3, j + 21, k + 7, NovaCraftBlocks.cracked_basal_bricks, 0, 2);
		world.setBlock(i + 4, j + 21, k + 7, NovaCraftBlocks.basal_bricks, 0, 2);
		world.setBlock(i + 5, j + 21, k + 7, NovaCraftBlocks.cracked_basal_bricks, 0, 2);
		world.setBlock(i + 6, j + 21, k + 7, NovaCraftBlocks.basal_bricks, 0, 2);
		world.setBlock(i + 7, j + 21, k + 7, NovaCraftBlocks.basal_bricks, 0, 2);
		world.setBlock(i + 8, j + 21, k + 7, NovaCraftBlocks.basal_bricks, 0, 2);
		world.setBlock(i + 9, j + 21, k + 7, NovaCraftBlocks.basal_bricks, 0, 2);
		world.setBlock(i + 10, j + 21, k + 7, NovaCraftBlocks.basal_bricks, 0, 2);
		world.setBlock(i + 11, j + 21, k + 7, NovaCraftBlocks.cracked_basal_bricks, 0, 2);
		world.setBlock(i + 12, j + 21, k + 7, Blocks.air, 0, 2);
		world.setBlock(i + 13, j + 21, k + 7, Blocks.air, 0, 2);
		world.setBlock(i + 14, j + 21, k + 7, NovaCraftBlocks.basal_bricks, 0, 2);
		world.setBlock(i + 15, j + 21, k + 7, NovaCraftBlocks.basal_bricks, 0, 2);
		world.setBlock(i + 16, j + 21, k + 7, NovaCraftBlocks.basal_bricks, 0, 2);
		world.setBlock(i + 17, j + 21, k + 7, NovaCraftBlocks.basal_bricks, 0, 2);
		world.setBlock(i + 18, j + 21, k + 7, NovaCraftBlocks.cracked_basal_bricks, 0, 2);
		world.setBlock(i + 19, j + 21, k + 7, NovaCraftBlocks.cracked_basal_bricks, 0, 2);
		world.setBlock(i + 20, j + 21, k + 7, NovaCraftBlocks.basal_bricks, 0, 2);
		world.setBlock(i + 21, j + 21, k + 7, NovaCraftBlocks.cracked_basal_bricks, 0, 2);
		world.setBlock(i + 22, j + 21, k + 7, NovaCraftBlocks.cracked_basal_bricks, 0, 2);
		world.setBlock(i + 23, j + 21, k + 7, NovaCraftBlocks.basal_bricks, 0, 2);
		world.setBlock(i + 24, j + 21, k + 7, NovaCraftBlocks.basal_bricks, 0, 2);
		world.setBlock(i + 25, j + 21, k + 7, NovaCraftBlocks.basal_bricks, 0, 2);
		world.setBlock(i + 26, j + 21, k + 7, Blocks.air, 0, 2);
		world.setBlock(i + 27, j + 21, k + 7, Blocks.air, 0, 2);
		world.setBlock(i, j + 21, k + 8, NovaCraftBlocks.basal_bricks, 0, 2);
		world.setBlock(i + 1, j + 21, k + 8, NovaCraftBlocks.cracked_basal_bricks, 0, 2);
		world.setBlock(i + 2, j + 21, k + 8, NovaCraftBlocks.basal_bricks, 0, 2);
		world.setBlock(i + 3, j + 21, k + 8, NovaCraftBlocks.basal_bricks, 0, 2);
		world.setBlock(i + 4, j + 21, k + 8, NovaCraftBlocks.cracked_basal_bricks, 0, 2);
		world.setBlock(i + 5, j + 21, k + 8, NovaCraftBlocks.basal_bricks, 0, 2);
		world.setBlock(i + 6, j + 21, k + 8, NovaCraftBlocks.cracked_basal_bricks, 0, 2);
		world.setBlock(i + 7, j + 21, k + 8, NovaCraftBlocks.basal_bricks, 0, 2);
		world.setBlock(i + 8, j + 21, k + 8, NovaCraftBlocks.basal_bricks, 0, 2);
		world.setBlock(i + 9, j + 21, k + 8, NovaCraftBlocks.basal_bricks, 0, 2);
		world.setBlock(i + 10, j + 21, k + 8, NovaCraftBlocks.basal_bricks, 0, 2);
		world.setBlock(i + 11, j + 21, k + 8, NovaCraftBlocks.basal_bricks, 0, 2);
		world.setBlock(i + 12, j + 21, k + 8, NovaCraftBlocks.basal_bricks, 0, 2);
		world.setBlock(i + 13, j + 21, k + 8, Blocks.air, 0, 2);
		world.setBlock(i + 14, j + 21, k + 8, NovaCraftBlocks.cracked_basal_bricks, 0, 2);
		world.setBlock(i + 15, j + 21, k + 8, NovaCraftBlocks.basal_bricks, 0, 2);
		world.setBlock(i + 16, j + 21, k + 8, NovaCraftBlocks.basal_bricks, 0, 2);
		world.setBlock(i + 17, j + 21, k + 8, NovaCraftBlocks.cracked_basal_bricks, 0, 2);
		world.setBlock(i + 18, j + 21, k + 8, NovaCraftBlocks.basal_bricks, 0, 2);
		world.setBlock(i + 19, j + 21, k + 8, NovaCraftBlocks.cracked_basal_bricks, 0, 2);
		world.setBlock(i + 20, j + 21, k + 8, NovaCraftBlocks.basal_bricks, 0, 2);
		world.setBlock(i + 21, j + 21, k + 8, NovaCraftBlocks.basal_bricks, 0, 2);
		world.setBlock(i + 22, j + 21, k + 8, NovaCraftBlocks.basal_bricks, 0, 2);
		world.setBlock(i + 23, j + 21, k + 8, NovaCraftBlocks.basal_bricks, 0, 2);
		world.setBlock(i + 24, j + 21, k + 8, NovaCraftBlocks.basal_bricks, 0, 2);
		world.setBlock(i + 25, j + 21, k + 8, NovaCraftBlocks.basal_bricks, 0, 2);
		world.setBlock(i + 26, j + 21, k + 8, Blocks.air, 0, 2);
		world.setBlock(i + 27, j + 21, k + 8, Blocks.air, 0, 2);
		world.setBlock(i, j + 21, k + 9, NovaCraftBlocks.cracked_basal_bricks, 0, 2);
		world.setBlock(i + 1, j + 21, k + 9, NovaCraftBlocks.basal_bricks, 0, 2);
		world.setBlock(i + 2, j + 21, k + 9, NovaCraftBlocks.basal_bricks, 0, 2);
		world.setBlock(i + 3, j + 21, k + 9, NovaCraftBlocks.cracked_basal_bricks, 0, 2);
		world.setBlock(i + 4, j + 21, k + 9, NovaCraftBlocks.basal_bricks, 0, 2);
		world.setBlock(i + 5, j + 21, k + 9, NovaCraftBlocks.cracked_basal_bricks, 0, 2);
		world.setBlock(i + 6, j + 21, k + 9, NovaCraftBlocks.basal_bricks, 0, 2);
		world.setBlock(i + 7, j + 21, k + 9, NovaCraftBlocks.basal_bricks, 0, 2);
		world.setBlock(i + 8, j + 21, k + 9, NovaCraftBlocks.basal_bricks, 0, 2);
		world.setBlock(i + 9, j + 21, k + 9, NovaCraftBlocks.basal_bricks, 0, 2);
		world.setBlock(i + 10, j + 21, k + 9, NovaCraftBlocks.basal_bricks, 0, 2);
		world.setBlock(i + 11, j + 21, k + 9, NovaCraftBlocks.cracked_basal_bricks, 0, 2);
		world.setBlock(i + 12, j + 21, k + 9, NovaCraftBlocks.basal_bricks, 0, 2);
		world.setBlock(i + 13, j + 21, k + 9, Blocks.air, 0, 2);
		world.setBlock(i + 14, j + 21, k + 9, NovaCraftBlocks.basal_bricks, 0, 2);
		world.setBlock(i + 15, j + 21, k + 9, NovaCraftBlocks.basal_bricks, 0, 2);
		world.setBlock(i + 16, j + 21, k + 9, NovaCraftBlocks.basal_bricks, 0, 2);
		world.setBlock(i + 17, j + 21, k + 9, NovaCraftBlocks.basal_bricks, 0, 2);
		world.setBlock(i + 18, j + 21, k + 9, NovaCraftBlocks.cracked_basal_bricks, 0, 2);
		world.setBlock(i + 19, j + 21, k + 9, NovaCraftBlocks.cracked_basal_bricks, 0, 2);
		world.setBlock(i + 20, j + 21, k + 9, NovaCraftBlocks.basal_bricks, 0, 2);
		world.setBlock(i + 21, j + 21, k + 9, NovaCraftBlocks.basal_bricks, 0, 2);
		world.setBlock(i + 22, j + 21, k + 9, NovaCraftBlocks.basal_bricks, 0, 2);
		world.setBlock(i + 23, j + 21, k + 9, NovaCraftBlocks.basal_bricks, 0, 2);
		world.setBlock(i + 24, j + 21, k + 9, NovaCraftBlocks.basal_bricks, 0, 2);
		world.setBlock(i + 25, j + 21, k + 9, NovaCraftBlocks.basal_bricks, 0, 2);
		world.setBlock(i + 26, j + 21, k + 9, Blocks.air, 0, 2);
		world.setBlock(i + 27, j + 21, k + 9, Blocks.air, 0, 2);
		world.setBlock(i, j + 21, k + 10, NovaCraftBlocks.basal_bricks, 0, 2);
		world.setBlock(i + 1, j + 21, k + 10, NovaCraftBlocks.basal_bricks, 0, 2);
		world.setBlock(i + 2, j + 21, k + 10, NovaCraftBlocks.cracked_basal_bricks, 0, 2);
		world.setBlock(i + 3, j + 21, k + 10, NovaCraftBlocks.basal_bricks, 0, 2);
		world.setBlock(i + 4, j + 21, k + 10, NovaCraftBlocks.basal_bricks, 0, 2);
		world.setBlock(i + 5, j + 21, k + 10, NovaCraftBlocks.basal_bricks, 0, 2);
		world.setBlock(i + 6, j + 21, k + 10, NovaCraftBlocks.cracked_basal_bricks, 0, 2);
		world.setBlock(i + 7, j + 21, k + 10, NovaCraftBlocks.cracked_basal_bricks, 0, 2);
		world.setBlock(i + 8, j + 21, k + 10, NovaCraftBlocks.cracked_basal_bricks, 0, 2);
		world.setBlock(i + 9, j + 21, k + 10, NovaCraftBlocks.basal_bricks, 0, 2);
		world.setBlock(i + 10, j + 21, k + 10, NovaCraftBlocks.cracked_basal_bricks, 0, 2);
		world.setBlock(i + 11, j + 21, k + 10, NovaCraftBlocks.cracked_basal_bricks, 0, 2);
		world.setBlock(i + 12, j + 21, k + 10, NovaCraftBlocks.cracked_basal_bricks, 0, 2);
		world.setBlock(i + 13, j + 21, k + 10, NovaCraftBlocks.cracked_basal_bricks, 0, 2);
		world.setBlock(i + 14, j + 21, k + 10, NovaCraftBlocks.cracked_basal_bricks, 0, 2);
		world.setBlock(i + 15, j + 21, k + 10, NovaCraftBlocks.basal_bricks, 0, 2);
		world.setBlock(i + 16, j + 21, k + 10, NovaCraftBlocks.cracked_basal_bricks, 0, 2);
		world.setBlock(i + 17, j + 21, k + 10, NovaCraftBlocks.basal_bricks, 0, 2);
		world.setBlock(i + 18, j + 21, k + 10, NovaCraftBlocks.basal_bricks, 0, 2);
		world.setBlock(i + 19, j + 21, k + 10, NovaCraftBlocks.basal_bricks, 0, 2);
		world.setBlock(i + 20, j + 21, k + 10, NovaCraftBlocks.basal_bricks, 0, 2);
		world.setBlock(i + 21, j + 21, k + 10, NovaCraftBlocks.cracked_basal_bricks, 0, 2);
		world.setBlock(i + 22, j + 21, k + 10, NovaCraftBlocks.basal_bricks, 0, 2);
		world.setBlock(i + 23, j + 21, k + 10, NovaCraftBlocks.cracked_basal_bricks, 0, 2);
		world.setBlock(i + 24, j + 21, k + 10, NovaCraftBlocks.basal_bricks, 0, 2);
		world.setBlock(i + 25, j + 21, k + 10, NovaCraftBlocks.basal_bricks, 0, 2);
		world.setBlock(i + 26, j + 21, k + 10, NovaCraftBlocks.basal_bricks, 0, 2);
		world.setBlock(i + 27, j + 21, k + 10, Blocks.air, 0, 2);
		world.setBlock(i, j + 21, k + 11, NovaCraftBlocks.cracked_basal_bricks, 0, 2);
		world.setBlock(i + 1, j + 21, k + 11, NovaCraftBlocks.cracked_basal_bricks, 0, 2);
		world.setBlock(i + 2, j + 21, k + 11, NovaCraftBlocks.basal_bricks, 0, 2);
		world.setBlock(i + 3, j + 21, k + 11, NovaCraftBlocks.basal_bricks, 0, 2);
		world.setBlock(i + 4, j + 21, k + 11, NovaCraftBlocks.basal_bricks, 0, 2);
		world.setBlock(i + 5, j + 21, k + 11, NovaCraftBlocks.basal_bricks, 0, 2);
		world.setBlock(i + 6, j + 21, k + 11, NovaCraftBlocks.basal_bricks, 0, 2);
		world.setBlock(i + 7, j + 21, k + 11, NovaCraftBlocks.cracked_basal_bricks, 0, 2);
		world.setBlock(i + 8, j + 21, k + 11, NovaCraftBlocks.basal_bricks, 0, 2);
		world.setBlock(i + 9, j + 21, k + 11, NovaCraftBlocks.cracked_basal_bricks, 0, 2);
		world.setBlock(i + 10, j + 21, k + 11, NovaCraftBlocks.cracked_basal_bricks, 0, 2);
		world.setBlock(i + 11, j + 21, k + 11, NovaCraftBlocks.cracked_basal_bricks, 0, 2);
		world.setBlock(i + 12, j + 21, k + 11, NovaCraftBlocks.basal_bricks, 0, 2);
		world.setBlock(i + 13, j + 21, k + 11, NovaCraftBlocks.basal_bricks, 0, 2);
		world.setBlock(i + 14, j + 21, k + 11, NovaCraftBlocks.basal_bricks, 0, 2);
		world.setBlock(i + 15, j + 21, k + 11, NovaCraftBlocks.basal_bricks, 0, 2);
		world.setBlock(i + 16, j + 21, k + 11, NovaCraftBlocks.basal_bricks, 0, 2);
		world.setBlock(i + 17, j + 21, k + 11, NovaCraftBlocks.cracked_basal_bricks, 0, 2);
		world.setBlock(i + 18, j + 21, k + 11, NovaCraftBlocks.cracked_basal_bricks, 0, 2);
		world.setBlock(i + 19, j + 21, k + 11, NovaCraftBlocks.cracked_basal_bricks, 0, 2);
		world.setBlock(i + 20, j + 21, k + 11, NovaCraftBlocks.basal_bricks, 0, 2);
		world.setBlock(i + 21, j + 21, k + 11, NovaCraftBlocks.cracked_basal_bricks, 0, 2);
		world.setBlock(i + 22, j + 21, k + 11, NovaCraftBlocks.basal_bricks, 0, 2);
		world.setBlock(i + 23, j + 21, k + 11, NovaCraftBlocks.basal_bricks, 0, 2);
		world.setBlock(i + 24, j + 21, k + 11, NovaCraftBlocks.basal_bricks, 0, 2);
		world.setBlock(i + 25, j + 21, k + 11, NovaCraftBlocks.basal_bricks, 0, 2);
		world.setBlock(i + 26, j + 21, k + 11, NovaCraftBlocks.basal_bricks, 0, 2);
		world.setBlock(i + 27, j + 21, k + 11, Blocks.air, 0, 2);
		world.setBlock(i, j + 21, k + 12, NovaCraftBlocks.basal_bricks, 0, 2);
		world.setBlock(i + 1, j + 21, k + 12, NovaCraftBlocks.basal_bricks, 0, 2);
		world.setBlock(i + 2, j + 21, k + 12, NovaCraftBlocks.cracked_basal_bricks, 0, 2);
		world.setBlock(i + 3, j + 21, k + 12, NovaCraftBlocks.basal_bricks, 0, 2);
		world.setBlock(i + 4, j + 21, k + 12, NovaCraftBlocks.basal_bricks, 0, 2);
		world.setBlock(i + 5, j + 21, k + 12, NovaCraftBlocks.cracked_basal_bricks, 0, 2);
		world.setBlock(i + 6, j + 21, k + 12, NovaCraftBlocks.basal_bricks, 0, 2);
		world.setBlock(i + 7, j + 21, k + 12, NovaCraftBlocks.basal_bricks, 0, 2);
		world.setBlock(i + 8, j + 21, k + 12, NovaCraftBlocks.cracked_basal_bricks, 0, 2);
		world.setBlock(i + 9, j + 21, k + 12, NovaCraftBlocks.basal_bricks, 0, 2);
		world.setBlock(i + 10, j + 21, k + 12, NovaCraftBlocks.basal_bricks, 0, 2);
		world.setBlock(i + 11, j + 21, k + 12, NovaCraftBlocks.basal_bricks, 0, 2);
		world.setBlock(i + 12, j + 21, k + 12, NovaCraftBlocks.cracked_basal_bricks, 0, 2);
		world.setBlock(i + 13, j + 21, k + 12, NovaCraftBlocks.cracked_basal_bricks, 0, 2);
		world.setBlock(i + 14, j + 21, k + 12, NovaCraftBlocks.basal_bricks, 0, 2);
		world.setBlock(i + 15, j + 21, k + 12, NovaCraftBlocks.basal_bricks, 0, 2);
		world.setBlock(i + 16, j + 21, k + 12, NovaCraftBlocks.cracked_basal_bricks, 0, 2);
		world.setBlock(i + 17, j + 21, k + 12, NovaCraftBlocks.basal_bricks, 0, 2);
		world.setBlock(i + 18, j + 21, k + 12, NovaCraftBlocks.basal_bricks, 0, 2);
		world.setBlock(i + 19, j + 21, k + 12, NovaCraftBlocks.cracked_basal_bricks, 0, 2);
		world.setBlock(i + 20, j + 21, k + 12, NovaCraftBlocks.cracked_basal_bricks, 0, 2);
		world.setBlock(i + 21, j + 21, k + 12, NovaCraftBlocks.cracked_basal_bricks, 0, 2);
		world.setBlock(i + 22, j + 21, k + 12, NovaCraftBlocks.cracked_basal_bricks, 0, 2);
		world.setBlock(i + 23, j + 21, k + 12, NovaCraftBlocks.basal_bricks, 0, 2);
		world.setBlock(i + 24, j + 21, k + 12, NovaCraftBlocks.cracked_basal_bricks, 0, 2);
		world.setBlock(i + 25, j + 21, k + 12, NovaCraftBlocks.basal_bricks, 0, 2);
		world.setBlock(i + 26, j + 21, k + 12, NovaCraftBlocks.cracked_basal_bricks, 0, 2);
		world.setBlock(i + 27, j + 21, k + 12, NovaCraftBlocks.basal_bricks, 0, 2);
		world.setBlock(i, j + 21, k + 13, NovaCraftBlocks.basal_bricks, 0, 2);
		world.setBlock(i + 1, j + 21, k + 13, NovaCraftBlocks.basal_bricks, 0, 2);
		world.setBlock(i + 2, j + 21, k + 13, NovaCraftBlocks.basal_bricks, 0, 2);
		world.setBlock(i + 3, j + 21, k + 13, NovaCraftBlocks.basal_bricks, 0, 2);
		world.setBlock(i + 4, j + 21, k + 13, NovaCraftBlocks.basal_bricks, 0, 2);
		world.setBlock(i + 5, j + 21, k + 13, NovaCraftBlocks.cracked_basal_bricks, 0, 2);
		world.setBlock(i + 6, j + 21, k + 13, NovaCraftBlocks.basal_bricks, 0, 2);
		world.setBlock(i + 7, j + 21, k + 13, NovaCraftBlocks.basal_bricks, 0, 2);
		world.setBlock(i + 8, j + 21, k + 13, NovaCraftBlocks.cracked_basal_bricks, 0, 2);
		world.setBlock(i + 9, j + 21, k + 13, NovaCraftBlocks.cracked_basal_bricks, 0, 2);
		world.setBlock(i + 10, j + 21, k + 13, NovaCraftBlocks.basal_bricks, 0, 2);
		world.setBlock(i + 11, j + 21, k + 13, NovaCraftBlocks.basal_bricks, 0, 2);
		world.setBlock(i + 12, j + 21, k + 13, NovaCraftBlocks.cracked_basal_bricks, 0, 2);
		world.setBlock(i + 13, j + 21, k + 13, NovaCraftBlocks.basal_bricks, 0, 2);
		world.setBlock(i + 14, j + 21, k + 13, NovaCraftBlocks.cracked_basal_bricks, 0, 2);
		world.setBlock(i + 15, j + 21, k + 13, NovaCraftBlocks.basal_bricks, 0, 2);
		world.setBlock(i + 16, j + 21, k + 13, NovaCraftBlocks.basal_bricks, 0, 2);
		world.setBlock(i + 17, j + 21, k + 13, NovaCraftBlocks.cracked_basal_bricks, 0, 2);
		world.setBlock(i + 18, j + 21, k + 13, NovaCraftBlocks.basal_bricks, 0, 2);
		world.setBlock(i + 19, j + 21, k + 13, NovaCraftBlocks.cracked_basal_bricks, 0, 2);
		world.setBlock(i + 20, j + 21, k + 13, NovaCraftBlocks.cracked_basal_bricks, 0, 2);
		world.setBlock(i + 21, j + 21, k + 13, NovaCraftBlocks.cracked_basal_bricks, 0, 2);
		world.setBlock(i + 22, j + 21, k + 13, NovaCraftBlocks.cracked_basal_bricks, 0, 2);
		world.setBlock(i + 23, j + 21, k + 13, NovaCraftBlocks.cracked_basal_bricks, 0, 2);
		world.setBlock(i + 24, j + 21, k + 13, NovaCraftBlocks.cracked_basal_bricks, 0, 2);
		world.setBlock(i + 25, j + 21, k + 13, NovaCraftBlocks.basal_bricks, 0, 2);
		world.setBlock(i + 26, j + 21, k + 13, NovaCraftBlocks.cracked_basal_bricks, 0, 2);
		world.setBlock(i + 27, j + 21, k + 13, NovaCraftBlocks.basal_bricks, 0, 2);
		world.setBlock(i, j + 21, k + 14, NovaCraftBlocks.basal_bricks, 0, 2);
		world.setBlock(i + 1, j + 21, k + 14, NovaCraftBlocks.basal_bricks, 0, 2);
		world.setBlock(i + 2, j + 21, k + 14, NovaCraftBlocks.basal_bricks, 0, 2);
		world.setBlock(i + 3, j + 21, k + 14, NovaCraftBlocks.cracked_basal_bricks, 0, 2);
		world.setBlock(i + 4, j + 21, k + 14, NovaCraftBlocks.basal_bricks, 0, 2);
		world.setBlock(i + 5, j + 21, k + 14, NovaCraftBlocks.basal_bricks, 0, 2);
		world.setBlock(i + 6, j + 21, k + 14, NovaCraftBlocks.basal_bricks, 0, 2);
		world.setBlock(i + 7, j + 21, k + 14, NovaCraftBlocks.cracked_basal_bricks, 0, 2);
		world.setBlock(i + 8, j + 21, k + 14, NovaCraftBlocks.basal_bricks, 0, 2);
		world.setBlock(i + 9, j + 21, k + 14, NovaCraftBlocks.basal_bricks, 0, 2);
		world.setBlock(i + 10, j + 21, k + 14, NovaCraftBlocks.basal_bricks, 0, 2);
		world.setBlock(i + 11, j + 21, k + 14, NovaCraftBlocks.cracked_basal_bricks, 0, 2);
		world.setBlock(i + 12, j + 21, k + 14, NovaCraftBlocks.cracked_basal_bricks, 0, 2);
		world.setBlock(i + 13, j + 21, k + 14, NovaCraftBlocks.cracked_basal_bricks, 0, 2);
		world.setBlock(i + 14, j + 21, k + 14, NovaCraftBlocks.cracked_basal_bricks, 0, 2);
		world.setBlock(i + 15, j + 21, k + 14, NovaCraftBlocks.basal_bricks, 0, 2);
		world.setBlock(i + 16, j + 21, k + 14, NovaCraftBlocks.basal_bricks, 0, 2);
		world.setBlock(i + 17, j + 21, k + 14, NovaCraftBlocks.cracked_basal_bricks, 0, 2);
		world.setBlock(i + 18, j + 21, k + 14, NovaCraftBlocks.cracked_basal_bricks, 0, 2);
		world.setBlock(i + 19, j + 21, k + 14, NovaCraftBlocks.basal_bricks, 0, 2);
		world.setBlock(i + 20, j + 21, k + 14, NovaCraftBlocks.basal_bricks, 0, 2);
		world.setBlock(i + 21, j + 21, k + 14, NovaCraftBlocks.cracked_basal_bricks, 0, 2);
		world.setBlock(i + 22, j + 21, k + 14, NovaCraftBlocks.basal_bricks, 0, 2);
		world.setBlock(i + 23, j + 21, k + 14, NovaCraftBlocks.cracked_basal_bricks, 0, 2);
		world.setBlock(i + 24, j + 21, k + 14, NovaCraftBlocks.cracked_basal_bricks, 0, 2);
		world.setBlock(i + 25, j + 21, k + 14, NovaCraftBlocks.cracked_basal_bricks, 0, 2);
		world.setBlock(i + 26, j + 21, k + 14, NovaCraftBlocks.basal_bricks, 0, 2);
		world.setBlock(i + 27, j + 21, k + 14, NovaCraftBlocks.basal_bricks, 0, 2);
		world.setBlock(i, j + 21, k + 15, NovaCraftBlocks.basal_bricks, 0, 2);
		world.setBlock(i + 1, j + 21, k + 15, NovaCraftBlocks.basal_bricks, 0, 2);
		world.setBlock(i + 2, j + 21, k + 15, NovaCraftBlocks.cracked_basal_bricks, 0, 2);
		world.setBlock(i + 3, j + 21, k + 15, NovaCraftBlocks.basal_bricks, 0, 2);
		world.setBlock(i + 4, j + 21, k + 15, NovaCraftBlocks.basal_bricks, 0, 2);
		world.setBlock(i + 5, j + 21, k + 15, NovaCraftBlocks.cracked_basal_bricks, 0, 2);
		world.setBlock(i + 6, j + 21, k + 15, NovaCraftBlocks.basal_bricks, 0, 2);
		world.setBlock(i + 7, j + 21, k + 15, NovaCraftBlocks.cracked_basal_bricks, 0, 2);
		world.setBlock(i + 8, j + 21, k + 15, NovaCraftBlocks.basal_bricks, 0, 2);
		world.setBlock(i + 9, j + 21, k + 15, NovaCraftBlocks.basal_bricks, 0, 2);
		world.setBlock(i + 10, j + 21, k + 15, NovaCraftBlocks.cracked_basal_bricks, 0, 2);
		world.setBlock(i + 11, j + 21, k + 15, NovaCraftBlocks.basal_bricks, 0, 2);
		world.setBlock(i + 12, j + 21, k + 15, NovaCraftBlocks.basal_bricks, 0, 2);
		world.setBlock(i + 13, j + 21, k + 15, NovaCraftBlocks.basal_bricks, 0, 2);
		world.setBlock(i + 14, j + 21, k + 15, NovaCraftBlocks.basal_bricks, 0, 2);
		world.setBlock(i + 15, j + 21, k + 15, NovaCraftBlocks.basal_bricks, 0, 2);
		world.setBlock(i + 16, j + 21, k + 15, NovaCraftBlocks.basal_bricks, 0, 2);
		world.setBlock(i + 17, j + 21, k + 15, NovaCraftBlocks.basal_bricks, 0, 2);
		world.setBlock(i + 18, j + 21, k + 15, NovaCraftBlocks.basal_bricks, 0, 2);
		world.setBlock(i + 19, j + 21, k + 15, NovaCraftBlocks.basal_bricks, 0, 2);
		world.setBlock(i + 20, j + 21, k + 15, NovaCraftBlocks.basal_bricks, 0, 2);
		world.setBlock(i + 21, j + 21, k + 15, NovaCraftBlocks.cracked_basal_bricks, 0, 2);
		world.setBlock(i + 22, j + 21, k + 15, NovaCraftBlocks.cracked_basal_bricks, 0, 2);
		world.setBlock(i + 23, j + 21, k + 15, NovaCraftBlocks.basal_bricks, 0, 2);
		world.setBlock(i + 24, j + 21, k + 15, NovaCraftBlocks.basal_bricks, 0, 2);
		world.setBlock(i + 25, j + 21, k + 15, NovaCraftBlocks.basal_bricks, 0, 2);
		world.setBlock(i + 26, j + 21, k + 15, NovaCraftBlocks.cracked_basal_bricks, 0, 2);
		world.setBlock(i + 27, j + 21, k + 15, NovaCraftBlocks.basal_bricks, 0, 2);
		world.setBlock(i, j + 21, k + 16, NovaCraftBlocks.cracked_basal_bricks, 0, 2);
		world.setBlock(i + 1, j + 21, k + 16, NovaCraftBlocks.basal_bricks, 0, 2);
		world.setBlock(i + 2, j + 21, k + 16, NovaCraftBlocks.basal_bricks, 0, 2);
		world.setBlock(i + 3, j + 21, k + 16, NovaCraftBlocks.cracked_basal_bricks, 0, 2);
		world.setBlock(i + 4, j + 21, k + 16, NovaCraftBlocks.cracked_basal_bricks, 0, 2);
		world.setBlock(i + 5, j + 21, k + 16, NovaCraftBlocks.basal_bricks, 0, 2);
		world.setBlock(i + 6, j + 21, k + 16, NovaCraftBlocks.basal_bricks, 0, 2);
		world.setBlock(i + 7, j + 21, k + 16, NovaCraftBlocks.basal_bricks, 0, 2);
		world.setBlock(i + 8, j + 21, k + 16, NovaCraftBlocks.basal_bricks, 0, 2);
		world.setBlock(i + 9, j + 21, k + 16, NovaCraftBlocks.cracked_basal_bricks, 0, 2);
		world.setBlock(i + 10, j + 21, k + 16, NovaCraftBlocks.cracked_basal_bricks, 0, 2);
		world.setBlock(i + 11, j + 21, k + 16, NovaCraftBlocks.cracked_basal_bricks, 0, 2);
		world.setBlock(i + 12, j + 21, k + 16, NovaCraftBlocks.basal_bricks, 0, 2);
		world.setBlock(i + 13, j + 21, k + 16, NovaCraftBlocks.cracked_basal_bricks, 0, 2);
		world.setBlock(i + 14, j + 21, k + 16, NovaCraftBlocks.basal_bricks, 0, 2);
		world.setBlock(i + 15, j + 21, k + 16, NovaCraftBlocks.basal_bricks, 0, 2);
		world.setBlock(i + 16, j + 21, k + 16, NovaCraftBlocks.basal_bricks, 0, 2);
		world.setBlock(i + 17, j + 21, k + 16, NovaCraftBlocks.cracked_basal_bricks, 0, 2);
		world.setBlock(i + 18, j + 21, k + 16, NovaCraftBlocks.basal_bricks, 0, 2);
		world.setBlock(i + 19, j + 21, k + 16, NovaCraftBlocks.basal_bricks, 0, 2);
		world.setBlock(i + 20, j + 21, k + 16, NovaCraftBlocks.cracked_basal_bricks, 0, 2);
		world.setBlock(i + 21, j + 21, k + 16, NovaCraftBlocks.basal_bricks, 0, 2);
		world.setBlock(i + 22, j + 21, k + 16, NovaCraftBlocks.basal_bricks, 0, 2);
		world.setBlock(i + 23, j + 21, k + 16, NovaCraftBlocks.basal_bricks, 0, 2);
		world.setBlock(i + 24, j + 21, k + 16, NovaCraftBlocks.basal_bricks, 0, 2);
		world.setBlock(i + 25, j + 21, k + 16, NovaCraftBlocks.basal_bricks, 0, 2);
		world.setBlock(i + 26, j + 21, k + 16, NovaCraftBlocks.basal_bricks, 0, 2);
		world.setBlock(i + 27, j + 21, k + 16, NovaCraftBlocks.cracked_basal_bricks, 0, 2);
		world.setBlock(i, j + 21, k + 17, NovaCraftBlocks.cracked_basal_bricks, 0, 2);
		world.setBlock(i + 1, j + 21, k + 17, NovaCraftBlocks.basal_bricks, 0, 2);
		world.setBlock(i + 2, j + 21, k + 17, NovaCraftBlocks.basal_bricks, 0, 2);
		world.setBlock(i + 3, j + 21, k + 17, NovaCraftBlocks.basal_bricks, 0, 2);
		world.setBlock(i + 4, j + 21, k + 17, NovaCraftBlocks.basal_bricks, 0, 2);
		world.setBlock(i + 5, j + 21, k + 17, NovaCraftBlocks.cracked_basal_bricks, 0, 2);
		world.setBlock(i + 6, j + 21, k + 17, NovaCraftBlocks.cracked_basal_bricks, 0, 2);
		world.setBlock(i + 7, j + 21, k + 17, NovaCraftBlocks.cracked_basal_bricks, 0, 2);
		world.setBlock(i + 8, j + 21, k + 17, NovaCraftBlocks.cracked_basal_bricks, 0, 2);
		world.setBlock(i + 9, j + 21, k + 17, NovaCraftBlocks.basal_bricks, 0, 2);
		world.setBlock(i + 10, j + 21, k + 17, NovaCraftBlocks.cracked_basal_bricks, 0, 2);
		world.setBlock(i + 11, j + 21, k + 17, NovaCraftBlocks.basal_bricks, 0, 2);
		world.setBlock(i + 12, j + 21, k + 17, NovaCraftBlocks.basal_bricks, 0, 2);
		world.setBlock(i + 13, j + 21, k + 17, NovaCraftBlocks.basal_bricks, 0, 2);
		world.setBlock(i + 14, j + 21, k + 17, NovaCraftBlocks.basal_bricks, 0, 2);
		world.setBlock(i + 15, j + 21, k + 17, NovaCraftBlocks.basal_bricks, 0, 2);
		world.setBlock(i + 16, j + 21, k + 17, NovaCraftBlocks.cracked_basal_bricks, 0, 2);
		world.setBlock(i + 17, j + 21, k + 17, NovaCraftBlocks.basal_bricks, 0, 2);
		world.setBlock(i + 18, j + 21, k + 17, NovaCraftBlocks.cracked_basal_bricks, 0, 2);
		world.setBlock(i + 19, j + 21, k + 17, NovaCraftBlocks.basal_bricks, 0, 2);
		world.setBlock(i + 20, j + 21, k + 17, NovaCraftBlocks.basal_bricks, 0, 2);
		world.setBlock(i + 21, j + 21, k + 17, NovaCraftBlocks.cracked_basal_bricks, 0, 2);
		world.setBlock(i + 22, j + 21, k + 17, NovaCraftBlocks.cracked_basal_bricks, 0, 2);
		world.setBlock(i + 23, j + 21, k + 17, NovaCraftBlocks.basal_bricks, 0, 2);
		world.setBlock(i + 24, j + 21, k + 17, NovaCraftBlocks.basal_bricks, 0, 2);
		world.setBlock(i + 25, j + 21, k + 17, NovaCraftBlocks.basal_bricks, 0, 2);
		world.setBlock(i + 26, j + 21, k + 17, NovaCraftBlocks.basal_bricks, 0, 2);
		world.setBlock(i + 27, j + 21, k + 17, NovaCraftBlocks.basal_bricks, 0, 2);
		world.setBlock(i, j + 21, k + 18, NovaCraftBlocks.basal_bricks, 0, 2);
		world.setBlock(i + 1, j + 21, k + 18, NovaCraftBlocks.basal_bricks, 0, 2);
		world.setBlock(i + 2, j + 21, k + 18, NovaCraftBlocks.basal_bricks, 0, 2);
		world.setBlock(i + 3, j + 21, k + 18, NovaCraftBlocks.cracked_basal_bricks, 0, 2);
		world.setBlock(i + 4, j + 21, k + 18, NovaCraftBlocks.cracked_basal_bricks, 0, 2);
		world.setBlock(i + 5, j + 21, k + 18, NovaCraftBlocks.basal_bricks, 0, 2);
		world.setBlock(i + 6, j + 21, k + 18, NovaCraftBlocks.basal_bricks, 0, 2);
		world.setBlock(i + 7, j + 21, k + 18, NovaCraftBlocks.basal_bricks, 0, 2);
		world.setBlock(i + 8, j + 21, k + 18, NovaCraftBlocks.basal_bricks, 0, 2);
		world.setBlock(i + 9, j + 21, k + 18, NovaCraftBlocks.cracked_basal_bricks, 0, 2);
		world.setBlock(i + 10, j + 21, k + 18, NovaCraftBlocks.basal_bricks, 0, 2);
		world.setBlock(i + 11, j + 21, k + 18, NovaCraftBlocks.basal_bricks, 0, 2);
		world.setBlock(i + 12, j + 21, k + 18, NovaCraftBlocks.basal_bricks, 0, 2);
		world.setBlock(i + 13, j + 21, k + 18, NovaCraftBlocks.cracked_basal_bricks, 0, 2);
		world.setBlock(i + 14, j + 21, k + 18, NovaCraftBlocks.cracked_basal_bricks, 0, 2);
		world.setBlock(i + 15, j + 21, k + 18, NovaCraftBlocks.basal_bricks, 0, 2);
		world.setBlock(i + 16, j + 21, k + 18, NovaCraftBlocks.basal_bricks, 0, 2);
		world.setBlock(i + 17, j + 21, k + 18, NovaCraftBlocks.basal_bricks, 0, 2);
		world.setBlock(i + 18, j + 21, k + 18, NovaCraftBlocks.basal_bricks, 0, 2);
		world.setBlock(i + 19, j + 21, k + 18, NovaCraftBlocks.cracked_basal_bricks, 0, 2);
		world.setBlock(i + 20, j + 21, k + 18, NovaCraftBlocks.basal_bricks, 0, 2);
		world.setBlock(i + 21, j + 21, k + 18, NovaCraftBlocks.basal_bricks, 0, 2);
		world.setBlock(i + 22, j + 21, k + 18, NovaCraftBlocks.basal_bricks, 0, 2);
		world.setBlock(i + 23, j + 21, k + 18, NovaCraftBlocks.basal_bricks, 0, 2);
		world.setBlock(i + 24, j + 21, k + 18, NovaCraftBlocks.basal_bricks, 0, 2);
		world.setBlock(i + 25, j + 21, k + 18, NovaCraftBlocks.cracked_basal_bricks, 0, 2);
		world.setBlock(i + 26, j + 21, k + 18, NovaCraftBlocks.basal_bricks, 0, 2);
		world.setBlock(i + 27, j + 21, k + 18, NovaCraftBlocks.basal_bricks, 0, 2);
		world.setBlock(i, j + 22, k, Blocks.air, 0, 2);
		world.setBlock(i + 1, j + 22, k, Blocks.air, 0, 2);
		world.setBlock(i + 2, j + 22, k, NovaCraftBlocks.cracked_basal_bricks, 0, 2);
		world.setBlock(i + 3, j + 22, k, NovaCraftBlocks.cracked_basal_bricks, 0, 2);
		world.setBlock(i + 4, j + 22, k, NovaCraftBlocks.basal_bricks, 0, 2);
		world.setBlock(i + 5, j + 22, k, NovaCraftBlocks.basal_bricks, 0, 2);
		world.setBlock(i + 6, j + 22, k, NovaCraftBlocks.basal_bricks, 0, 2);
		world.setBlock(i + 7, j + 22, k, NovaCraftBlocks.cracked_basal_bricks, 0, 2);
		world.setBlock(i + 8, j + 22, k, NovaCraftBlocks.cracked_basal_bricks, 0, 2);
		world.setBlock(i + 9, j + 22, k, NovaCraftBlocks.basal_bricks, 0, 2);
		world.setBlock(i + 10, j + 22, k, NovaCraftBlocks.cracked_basal_bricks, 0, 2);
		world.setBlock(i + 11, j + 22, k, NovaCraftBlocks.basal_bricks, 0, 2);
		world.setBlock(i + 12, j + 22, k, NovaCraftBlocks.basal_bricks, 0, 2);
		world.setBlock(i + 13, j + 22, k, NovaCraftBlocks.cracked_basal_bricks, 0, 2);
		world.setBlock(i + 14, j + 22, k, Blocks.air, 0, 2);
		world.setBlock(i + 15, j + 22, k, Blocks.air, 0, 2);
		world.setBlock(i + 16, j + 22, k, Blocks.air, 0, 2);
		world.setBlock(i + 17, j + 22, k, NovaCraftBlocks.cracked_basal_bricks, 0, 2);
		world.setBlock(i + 18, j + 22, k, NovaCraftBlocks.basal_bricks, 0, 2);
		world.setBlock(i + 19, j + 22, k, NovaCraftBlocks.basal_bricks, 0, 2);
		world.setBlock(i + 20, j + 22, k, NovaCraftBlocks.cracked_basal_bricks, 0, 2);
		world.setBlock(i + 21, j + 22, k, NovaCraftBlocks.basal_bricks, 0, 2);
		world.setBlock(i + 22, j + 22, k, NovaCraftBlocks.basal_bricks, 0, 2);
		world.setBlock(i + 23, j + 22, k, NovaCraftBlocks.cracked_basal_bricks, 0, 2);
		world.setBlock(i + 24, j + 22, k, NovaCraftBlocks.cracked_basal_bricks, 0, 2);
		world.setBlock(i + 25, j + 22, k, NovaCraftBlocks.cracked_basal_bricks, 0, 2);
		world.setBlock(i + 26, j + 22, k, NovaCraftBlocks.basal_bricks, 0, 2);
		world.setBlock(i + 27, j + 22, k, NovaCraftBlocks.basal_bricks, 0, 2);
		world.setBlock(i, j + 22, k + 1, Blocks.air, 0, 2);
		world.setBlock(i + 1, j + 22, k + 1, NovaCraftBlocks.cracked_basal_bricks, 0, 2);
		world.setBlock(i + 2, j + 22, k + 1, NovaCraftBlocks.basal_bricks, 0, 2);
		world.setBlock(i + 3, j + 22, k + 1, NovaCraftBlocks.cracked_basal_bricks, 0, 2);
		world.setBlock(i + 4, j + 22, k + 1, NovaCraftBlocks.cracked_basal_bricks, 0, 2);
		world.setBlock(i + 5, j + 22, k + 1, NovaCraftBlocks.basal_bricks, 0, 2);
		world.setBlock(i + 6, j + 22, k + 1, NovaCraftBlocks.basal_bricks, 0, 2);
		world.setBlock(i + 7, j + 22, k + 1, NovaCraftBlocks.cracked_basal_bricks, 0, 2);
		world.setBlock(i + 8, j + 22, k + 1, NovaCraftBlocks.cracked_basal_bricks, 0, 2);
		world.setBlock(i + 9, j + 22, k + 1, NovaCraftBlocks.basal_bricks, 0, 2);
		world.setBlock(i + 10, j + 22, k + 1, NovaCraftBlocks.basal_bricks, 0, 2);
		world.setBlock(i + 11, j + 22, k + 1, NovaCraftBlocks.cracked_basal_bricks, 0, 2);
		world.setBlock(i + 12, j + 22, k + 1, NovaCraftBlocks.cracked_basal_bricks, 0, 2);
		world.setBlock(i + 13, j + 22, k + 1, NovaCraftBlocks.basal_bricks, 0, 2);
		world.setBlock(i + 14, j + 22, k + 1, Blocks.air, 0, 2);
		world.setBlock(i + 15, j + 22, k + 1, Blocks.air, 0, 2);
		world.setBlock(i + 16, j + 22, k + 1, Blocks.air, 0, 2);
		world.setBlock(i + 17, j + 22, k + 1, NovaCraftBlocks.basal_bricks, 0, 2);
		world.setBlock(i + 18, j + 22, k + 1, NovaCraftBlocks.basal_bricks, 0, 2);
		world.setBlock(i + 19, j + 22, k + 1, NovaCraftBlocks.basal_bricks, 0, 2);
		world.setBlock(i + 20, j + 22, k + 1, NovaCraftBlocks.basal_bricks, 0, 2);
		world.setBlock(i + 21, j + 22, k + 1, NovaCraftBlocks.basal_bricks, 0, 2);
		world.setBlock(i + 22, j + 22, k + 1, NovaCraftBlocks.cracked_basal_bricks, 0, 2);
		world.setBlock(i + 23, j + 22, k + 1, NovaCraftBlocks.basal_bricks, 0, 2);
		world.setBlock(i + 24, j + 22, k + 1, NovaCraftBlocks.basal_bricks, 0, 2);
		world.setBlock(i + 25, j + 22, k + 1, NovaCraftBlocks.cracked_basal_bricks, 0, 2);
		world.setBlock(i + 26, j + 22, k + 1, NovaCraftBlocks.basal_bricks, 0, 2);
		world.setBlock(i + 27, j + 22, k + 1, NovaCraftBlocks.cracked_basal_bricks, 0, 2);
		world.setBlock(i, j + 22, k + 2, NovaCraftBlocks.basal_bricks, 0, 2);
		world.setBlock(i + 1, j + 22, k + 2, NovaCraftBlocks.cracked_basal_bricks, 0, 2);
		world.setBlock(i + 2, j + 22, k + 2, NovaCraftBlocks.basal_bricks, 0, 2);
		world.setBlock(i + 3, j + 22, k + 2, NovaCraftBlocks.cracked_basal_bricks, 0, 2);
		world.setBlock(i + 4, j + 22, k + 2, NovaCraftBlocks.basal_bricks, 0, 2);
		world.setBlock(i + 5, j + 22, k + 2, NovaCraftBlocks.basal_bricks, 0, 2);
		world.setBlock(i + 6, j + 22, k + 2, NovaCraftBlocks.cracked_basal_bricks, 0, 2);
		world.setBlock(i + 7, j + 22, k + 2, NovaCraftBlocks.cracked_basal_bricks, 0, 2);
		world.setBlock(i + 8, j + 22, k + 2, NovaCraftBlocks.basal_bricks, 0, 2);
		world.setBlock(i + 9, j + 22, k + 2, NovaCraftBlocks.basal_bricks, 0, 2);
		world.setBlock(i + 10, j + 22, k + 2, NovaCraftBlocks.basal_bricks, 0, 2);
		world.setBlock(i + 11, j + 22, k + 2, NovaCraftBlocks.basal_bricks, 0, 2);
		world.setBlock(i + 12, j + 22, k + 2, NovaCraftBlocks.cracked_basal_bricks, 0, 2);
		world.setBlock(i + 13, j + 22, k + 2, NovaCraftBlocks.basal_bricks, 0, 2);
		world.setBlock(i + 14, j + 22, k + 2, Blocks.air, 0, 2);
		world.setBlock(i + 15, j + 22, k + 2, Blocks.air, 0, 2);
		world.setBlock(i + 16, j + 22, k + 2, NovaCraftBlocks.cracked_basal_bricks, 0, 2);
		world.setBlock(i + 17, j + 22, k + 2, NovaCraftBlocks.basal_bricks, 0, 2);
		world.setBlock(i + 18, j + 22, k + 2, NovaCraftBlocks.cracked_basal_bricks, 0, 2);
		world.setBlock(i + 19, j + 22, k + 2, NovaCraftBlocks.basal_bricks, 0, 2);
		world.setBlock(i + 20, j + 22, k + 2, NovaCraftBlocks.cracked_basal_bricks, 0, 2);
		world.setBlock(i + 21, j + 22, k + 2, NovaCraftBlocks.basal_bricks, 0, 2);
		world.setBlock(i + 22, j + 22, k + 2, NovaCraftBlocks.basal_bricks, 0, 2);
		world.setBlock(i + 23, j + 22, k + 2, NovaCraftBlocks.cracked_basal_bricks, 0, 2);
		world.setBlock(i + 24, j + 22, k + 2, NovaCraftBlocks.basal_bricks, 0, 2);
		world.setBlock(i + 25, j + 22, k + 2, NovaCraftBlocks.basal_bricks, 0, 2);
		world.setBlock(i + 26, j + 22, k + 2, NovaCraftBlocks.cracked_basal_bricks, 0, 2);
		world.setBlock(i + 27, j + 22, k + 2, NovaCraftBlocks.cracked_basal_bricks, 0, 2);
		world.setBlock(i, j + 22, k + 3, NovaCraftBlocks.basal_bricks, 0, 2);
		world.setBlock(i + 1, j + 22, k + 3, NovaCraftBlocks.cracked_basal_bricks, 0, 2);
		world.setBlock(i + 2, j + 22, k + 3, NovaCraftBlocks.basal_bricks, 0, 2);
		world.setBlock(i + 3, j + 22, k + 3, NovaCraftBlocks.basal_bricks, 0, 2);
		world.setBlock(i + 4, j + 22, k + 3, NovaCraftBlocks.basal_bricks, 0, 2);
		world.setBlock(i + 5, j + 22, k + 3, NovaCraftBlocks.basal_bricks, 0, 2);
		world.setBlock(i + 6, j + 22, k + 3, NovaCraftBlocks.basal_bricks, 0, 2);
		world.setBlock(i + 7, j + 22, k + 3, NovaCraftBlocks.basal_bricks, 0, 2);
		world.setBlock(i + 8, j + 22, k + 3, NovaCraftBlocks.cracked_basal_bricks, 0, 2);
		world.setBlock(i + 9, j + 22, k + 3, NovaCraftBlocks.basal_bricks, 0, 2);
		world.setBlock(i + 10, j + 22, k + 3, NovaCraftBlocks.cracked_basal_bricks, 0, 2);
		world.setBlock(i + 11, j + 22, k + 3, NovaCraftBlocks.basal_bricks, 0, 2);
		world.setBlock(i + 12, j + 22, k + 3, NovaCraftBlocks.cracked_basal_bricks, 0, 2);
		world.setBlock(i + 13, j + 22, k + 3, NovaCraftBlocks.cracked_basal_bricks, 0, 2);
		world.setBlock(i + 14, j + 22, k + 3, Blocks.air, 0, 2);
		world.setBlock(i + 15, j + 22, k + 3, NovaCraftBlocks.basal_bricks, 0, 2);
		world.setBlock(i + 16, j + 22, k + 3, NovaCraftBlocks.cracked_basal_bricks, 0, 2);
		world.setBlock(i + 17, j + 22, k + 3, NovaCraftBlocks.cracked_basal_bricks, 0, 2);
		world.setBlock(i + 18, j + 22, k + 3, NovaCraftBlocks.cracked_basal_bricks, 0, 2);
		world.setBlock(i + 19, j + 22, k + 3, NovaCraftBlocks.cracked_basal_bricks, 0, 2);
		world.setBlock(i + 20, j + 22, k + 3, NovaCraftBlocks.basal_bricks, 0, 2);
		world.setBlock(i + 21, j + 22, k + 3, NovaCraftBlocks.basal_bricks, 0, 2);
		world.setBlock(i + 22, j + 22, k + 3, NovaCraftBlocks.basal_bricks, 0, 2);
		world.setBlock(i + 23, j + 22, k + 3, NovaCraftBlocks.basal_bricks, 0, 2);
		world.setBlock(i + 24, j + 22, k + 3, NovaCraftBlocks.basal_bricks, 0, 2);
		world.setBlock(i + 25, j + 22, k + 3, NovaCraftBlocks.basal_bricks, 0, 2);
		world.setBlock(i + 26, j + 22, k + 3, NovaCraftBlocks.basal_bricks, 0, 2);
		world.setBlock(i + 27, j + 22, k + 3, NovaCraftBlocks.cracked_basal_bricks, 0, 2);
		world.setBlock(i, j + 22, k + 4, NovaCraftBlocks.cracked_basal_bricks, 0, 2);
		world.setBlock(i + 1, j + 22, k + 4, NovaCraftBlocks.basal_bricks, 0, 2);
		world.setBlock(i + 2, j + 22, k + 4, NovaCraftBlocks.basal_bricks, 0, 2);
		world.setBlock(i + 3, j + 22, k + 4, NovaCraftBlocks.cracked_basal_bricks, 0, 2);
		world.setBlock(i + 4, j + 22, k + 4, NovaCraftBlocks.basal_bricks, 0, 2);
		world.setBlock(i + 5, j + 22, k + 4, NovaCraftBlocks.basal_bricks, 0, 2);
		world.setBlock(i + 6, j + 22, k + 4, NovaCraftBlocks.basal_bricks, 0, 2);
		world.setBlock(i + 7, j + 22, k + 4, NovaCraftBlocks.basal_bricks, 0, 2);
		world.setBlock(i + 8, j + 22, k + 4, NovaCraftBlocks.basal_bricks, 0, 2);
		world.setBlock(i + 9, j + 22, k + 4, NovaCraftBlocks.cracked_basal_bricks, 0, 2);
		world.setBlock(i + 10, j + 22, k + 4, NovaCraftBlocks.basal_bricks, 0, 2);
		world.setBlock(i + 11, j + 22, k + 4, NovaCraftBlocks.basal_bricks, 0, 2);
		world.setBlock(i + 12, j + 22, k + 4, NovaCraftBlocks.basal_bricks, 0, 2);
		world.setBlock(i + 13, j + 22, k + 4, Blocks.air, 0, 2);
		world.setBlock(i + 14, j + 22, k + 4, NovaCraftBlocks.basal_bricks, 0, 2);
		world.setBlock(i + 15, j + 22, k + 4, NovaCraftBlocks.basal_bricks, 0, 2);
		world.setBlock(i + 16, j + 22, k + 4, NovaCraftBlocks.cracked_basal_bricks, 0, 2);
		world.setBlock(i + 17, j + 22, k + 4, NovaCraftBlocks.basal_bricks, 0, 2);
		world.setBlock(i + 18, j + 22, k + 4, NovaCraftBlocks.basal_bricks, 0, 2);
		world.setBlock(i + 19, j + 22, k + 4, NovaCraftBlocks.basal_bricks, 0, 2);
		world.setBlock(i + 20, j + 22, k + 4, NovaCraftBlocks.cracked_basal_bricks, 0, 2);
		world.setBlock(i + 21, j + 22, k + 4, NovaCraftBlocks.cracked_basal_bricks, 0, 2);
		world.setBlock(i + 22, j + 22, k + 4, NovaCraftBlocks.basal_bricks, 0, 2);
		world.setBlock(i + 23, j + 22, k + 4, NovaCraftBlocks.basal_bricks, 0, 2);
		world.setBlock(i + 24, j + 22, k + 4, NovaCraftBlocks.cracked_basal_bricks, 0, 2);
		world.setBlock(i + 25, j + 22, k + 4, NovaCraftBlocks.basal_bricks, 0, 2);
		world.setBlock(i + 26, j + 22, k + 4, NovaCraftBlocks.basal_bricks, 0, 2);
		world.setBlock(i + 27, j + 22, k + 4, NovaCraftBlocks.basal_bricks, 0, 2);
		world.setBlock(i, j + 22, k + 5, NovaCraftBlocks.basal_bricks, 0, 2);
		world.setBlock(i + 1, j + 22, k + 5, NovaCraftBlocks.basal_bricks, 0, 2);
		world.setBlock(i + 2, j + 22, k + 5, NovaCraftBlocks.basal_bricks, 0, 2);
		world.setBlock(i + 3, j + 22, k + 5, NovaCraftBlocks.basal_bricks, 0, 2);
		world.setBlock(i + 4, j + 22, k + 5, NovaCraftBlocks.basal_bricks, 0, 2);
		world.setBlock(i + 5, j + 22, k + 5, NovaCraftBlocks.basal_bricks, 0, 2);
		world.setBlock(i + 6, j + 22, k + 5, NovaCraftBlocks.basal_bricks, 0, 2);
		world.setBlock(i + 7, j + 22, k + 5, NovaCraftBlocks.basal_bricks, 0, 2);
		world.setBlock(i + 8, j + 22, k + 5, NovaCraftBlocks.basal_bricks, 0, 2);
		world.setBlock(i + 9, j + 22, k + 5, NovaCraftBlocks.cracked_basal_bricks, 0, 2);
		world.setBlock(i + 10, j + 22, k + 5, NovaCraftBlocks.basal_bricks, 0, 2);
		world.setBlock(i + 11, j + 22, k + 5, NovaCraftBlocks.basal_bricks, 0, 2);
		world.setBlock(i + 12, j + 22, k + 5, NovaCraftBlocks.basal_bricks, 0, 2);
		world.setBlock(i + 13, j + 22, k + 5, Blocks.air, 0, 2);
		world.setBlock(i + 14, j + 22, k + 5, NovaCraftBlocks.basal_bricks, 0, 2);
		world.setBlock(i + 15, j + 22, k + 5, NovaCraftBlocks.basal_bricks, 0, 2);
		world.setBlock(i + 16, j + 22, k + 5, NovaCraftBlocks.basal_bricks, 0, 2);
		world.setBlock(i + 17, j + 22, k + 5, NovaCraftBlocks.basal_bricks, 0, 2);
		world.setBlock(i + 18, j + 22, k + 5, NovaCraftBlocks.basal_bricks, 0, 2);
		world.setBlock(i + 19, j + 22, k + 5, NovaCraftBlocks.cracked_basal_bricks, 0, 2);
		world.setBlock(i + 20, j + 22, k + 5, NovaCraftBlocks.cracked_basal_bricks, 0, 2);
		world.setBlock(i + 21, j + 22, k + 5, NovaCraftBlocks.basal_bricks, 0, 2);
		world.setBlock(i + 22, j + 22, k + 5, NovaCraftBlocks.basal_bricks, 0, 2);
		world.setBlock(i + 23, j + 22, k + 5, NovaCraftBlocks.cracked_basal_bricks, 0, 2);
		world.setBlock(i + 24, j + 22, k + 5, NovaCraftBlocks.basal_bricks, 0, 2);
		world.setBlock(i + 25, j + 22, k + 5, NovaCraftBlocks.basal_bricks, 0, 2);
		world.setBlock(i + 26, j + 22, k + 5, NovaCraftBlocks.cracked_basal_bricks, 0, 2);
		world.setBlock(i + 27, j + 22, k + 5, NovaCraftBlocks.cracked_basal_bricks, 0, 2);
		world.setBlock(i, j + 22, k + 6, NovaCraftBlocks.cracked_basal_bricks, 0, 2);
		world.setBlock(i + 1, j + 22, k + 6, NovaCraftBlocks.basal_bricks, 0, 2);
		world.setBlock(i + 2, j + 22, k + 6, NovaCraftBlocks.cracked_basal_bricks, 0, 2);
		world.setBlock(i + 3, j + 22, k + 6, NovaCraftBlocks.cracked_basal_bricks, 0, 2);
		world.setBlock(i + 4, j + 22, k + 6, NovaCraftBlocks.basal_bricks, 0, 2);
		world.setBlock(i + 5, j + 22, k + 6, NovaCraftBlocks.cracked_basal_bricks, 0, 2);
		world.setBlock(i + 6, j + 22, k + 6, NovaCraftBlocks.basal_bricks, 0, 2);
		world.setBlock(i + 7, j + 22, k + 6, NovaCraftBlocks.basal_bricks, 0, 2);
		world.setBlock(i + 8, j + 22, k + 6, NovaCraftBlocks.cracked_basal_bricks, 0, 2);
		world.setBlock(i + 9, j + 22, k + 6, NovaCraftBlocks.basal_bricks, 0, 2);
		world.setBlock(i + 10, j + 22, k + 6, NovaCraftBlocks.basal_bricks, 0, 2);
		world.setBlock(i + 11, j + 22, k + 6, NovaCraftBlocks.basal_bricks, 0, 2);
		world.setBlock(i + 12, j + 22, k + 6, NovaCraftBlocks.cracked_basal_bricks, 0, 2);
		world.setBlock(i + 13, j + 22, k + 6, Blocks.air, 0, 2);
		world.setBlock(i + 14, j + 22, k + 6, NovaCraftBlocks.basal_bricks, 0, 2);
		world.setBlock(i + 15, j + 22, k + 6, NovaCraftBlocks.basal_bricks, 0, 2);
		world.setBlock(i + 16, j + 22, k + 6, NovaCraftBlocks.cracked_basal_bricks, 0, 2);
		world.setBlock(i + 17, j + 22, k + 6, NovaCraftBlocks.cracked_basal_bricks, 0, 2);
		world.setBlock(i + 18, j + 22, k + 6, NovaCraftBlocks.cracked_basal_bricks, 0, 2);
		world.setBlock(i + 19, j + 22, k + 6, NovaCraftBlocks.basal_bricks, 0, 2);
		world.setBlock(i + 20, j + 22, k + 6, NovaCraftBlocks.basal_bricks, 0, 2);
		world.setBlock(i + 21, j + 22, k + 6, NovaCraftBlocks.cracked_basal_bricks, 0, 2);
		world.setBlock(i + 22, j + 22, k + 6, NovaCraftBlocks.cracked_basal_bricks, 0, 2);
		world.setBlock(i + 23, j + 22, k + 6, NovaCraftBlocks.cracked_basal_bricks, 0, 2);
		world.setBlock(i + 24, j + 22, k + 6, NovaCraftBlocks.basal_bricks, 0, 2);
		world.setBlock(i + 25, j + 22, k + 6, NovaCraftBlocks.basal_bricks, 0, 2);
		world.setBlock(i + 26, j + 22, k + 6, NovaCraftBlocks.cracked_basal_bricks, 0, 2);
		world.setBlock(i + 27, j + 22, k + 6, Blocks.air, 0, 2);
		world.setBlock(i, j + 22, k + 7, NovaCraftBlocks.cracked_basal_bricks, 0, 2);
		world.setBlock(i + 1, j + 22, k + 7, NovaCraftBlocks.basal_bricks, 0, 2);
		world.setBlock(i + 2, j + 22, k + 7, NovaCraftBlocks.cracked_basal_bricks, 0, 2);
		world.setBlock(i + 3, j + 22, k + 7, NovaCraftBlocks.basal_bricks, 0, 2);
		world.setBlock(i + 4, j + 22, k + 7, NovaCraftBlocks.basal_bricks, 0, 2);
		world.setBlock(i + 5, j + 22, k + 7, NovaCraftBlocks.basal_bricks, 0, 2);
		world.setBlock(i + 6, j + 22, k + 7, NovaCraftBlocks.cracked_basal_bricks, 0, 2);
		world.setBlock(i + 7, j + 22, k + 7, NovaCraftBlocks.basal_bricks, 0, 2);
		world.setBlock(i + 8, j + 22, k + 7, NovaCraftBlocks.basal_bricks, 0, 2);
		world.setBlock(i + 9, j + 22, k + 7, NovaCraftBlocks.basal_bricks, 0, 2);
		world.setBlock(i + 10, j + 22, k + 7, NovaCraftBlocks.basal_bricks, 0, 2);
		world.setBlock(i + 11, j + 22, k + 7, NovaCraftBlocks.basal_bricks, 0, 2);
		world.setBlock(i + 12, j + 22, k + 7, NovaCraftBlocks.cracked_basal_bricks, 0, 2);
		world.setBlock(i + 13, j + 22, k + 7, NovaCraftBlocks.basal_bricks, 0, 2);
		world.setBlock(i + 14, j + 22, k + 7, NovaCraftBlocks.cracked_basal_bricks, 0, 2);
		world.setBlock(i + 15, j + 22, k + 7, NovaCraftBlocks.basal_bricks, 0, 2);
		world.setBlock(i + 16, j + 22, k + 7, NovaCraftBlocks.cracked_basal_bricks, 0, 2);
		world.setBlock(i + 17, j + 22, k + 7, NovaCraftBlocks.basal_bricks, 0, 2);
		world.setBlock(i + 18, j + 22, k + 7, NovaCraftBlocks.basal_bricks, 0, 2);
		world.setBlock(i + 19, j + 22, k + 7, NovaCraftBlocks.basal_bricks, 0, 2);
		world.setBlock(i + 20, j + 22, k + 7, NovaCraftBlocks.basal_bricks, 0, 2);
		world.setBlock(i + 21, j + 22, k + 7, NovaCraftBlocks.cracked_basal_bricks, 0, 2);
		world.setBlock(i + 22, j + 22, k + 7, NovaCraftBlocks.basal_bricks, 0, 2);
		world.setBlock(i + 23, j + 22, k + 7, NovaCraftBlocks.basal_bricks, 0, 2);
		world.setBlock(i + 24, j + 22, k + 7, NovaCraftBlocks.basal_bricks, 0, 2);
		world.setBlock(i + 25, j + 22, k + 7, NovaCraftBlocks.basal_bricks, 0, 2);
		world.setBlock(i + 26, j + 22, k + 7, NovaCraftBlocks.basal_bricks, 0, 2);
		world.setBlock(i + 27, j + 22, k + 7, Blocks.air, 0, 2);
		world.setBlock(i, j + 22, k + 8, NovaCraftBlocks.basal_bricks, 0, 2);
		world.setBlock(i + 1, j + 22, k + 8, NovaCraftBlocks.basal_bricks, 0, 2);
		world.setBlock(i + 2, j + 22, k + 8, NovaCraftBlocks.cracked_basal_bricks, 0, 2);
		world.setBlock(i + 3, j + 22, k + 8, NovaCraftBlocks.basal_bricks, 0, 2);
		world.setBlock(i + 4, j + 22, k + 8, NovaCraftBlocks.basal_bricks, 0, 2);
		world.setBlock(i + 5, j + 22, k + 8, NovaCraftBlocks.basal_bricks, 0, 2);
		world.setBlock(i + 6, j + 22, k + 8, NovaCraftBlocks.basal_bricks, 0, 2);
		world.setBlock(i + 7, j + 22, k + 8, NovaCraftBlocks.basal_bricks, 0, 2);
		world.setBlock(i + 8, j + 22, k + 8, NovaCraftBlocks.basal_bricks, 0, 2);
		world.setBlock(i + 9, j + 22, k + 8, NovaCraftBlocks.basal_bricks, 0, 2);
		world.setBlock(i + 10, j + 22, k + 8, NovaCraftBlocks.basal_bricks, 0, 2);
		world.setBlock(i + 11, j + 22, k + 8, NovaCraftBlocks.basal_bricks, 0, 2);
		world.setBlock(i + 12, j + 22, k + 8, NovaCraftBlocks.cracked_basal_bricks, 0, 2);
		world.setBlock(i + 13, j + 22, k + 8, NovaCraftBlocks.basal_bricks, 0, 2);
		world.setBlock(i + 14, j + 22, k + 8, NovaCraftBlocks.cracked_basal_bricks, 0, 2);
		world.setBlock(i + 15, j + 22, k + 8, NovaCraftBlocks.basal_bricks, 0, 2);
		world.setBlock(i + 16, j + 22, k + 8, NovaCraftBlocks.cracked_basal_bricks, 0, 2);
		world.setBlock(i + 17, j + 22, k + 8, NovaCraftBlocks.basal_bricks, 0, 2);
		world.setBlock(i + 18, j + 22, k + 8, NovaCraftBlocks.basal_bricks, 0, 2);
		world.setBlock(i + 19, j + 22, k + 8, NovaCraftBlocks.basal_bricks, 0, 2);
		world.setBlock(i + 20, j + 22, k + 8, NovaCraftBlocks.cracked_basal_bricks, 0, 2);
		world.setBlock(i + 21, j + 22, k + 8, NovaCraftBlocks.basal_bricks, 0, 2);
		world.setBlock(i + 22, j + 22, k + 8, NovaCraftBlocks.basal_bricks, 0, 2);
		world.setBlock(i + 23, j + 22, k + 8, NovaCraftBlocks.cracked_basal_bricks, 0, 2);
		world.setBlock(i + 24, j + 22, k + 8, NovaCraftBlocks.cracked_basal_bricks, 0, 2);
		world.setBlock(i + 25, j + 22, k + 8, NovaCraftBlocks.cracked_basal_bricks, 0, 2);
		world.setBlock(i + 26, j + 22, k + 8, NovaCraftBlocks.cracked_basal_bricks, 0, 2);
		world.setBlock(i + 27, j + 22, k + 8, Blocks.air, 0, 2);
		world.setBlock(i, j + 22, k + 9, NovaCraftBlocks.cracked_basal_bricks, 0, 2);
		world.setBlock(i + 1, j + 22, k + 9, NovaCraftBlocks.cracked_basal_bricks, 0, 2);
		world.setBlock(i + 2, j + 22, k + 9, NovaCraftBlocks.cracked_basal_bricks, 0, 2);
		world.setBlock(i + 3, j + 22, k + 9, NovaCraftBlocks.basal_bricks, 0, 2);
		world.setBlock(i + 4, j + 22, k + 9, NovaCraftBlocks.cracked_basal_bricks, 0, 2);
		world.setBlock(i + 5, j + 22, k + 9, NovaCraftBlocks.basal_bricks, 0, 2);
		world.setBlock(i + 6, j + 22, k + 9, NovaCraftBlocks.cracked_basal_bricks, 0, 2);
		world.setBlock(i + 7, j + 22, k + 9, NovaCraftBlocks.basal_bricks, 0, 2);
		world.setBlock(i + 8, j + 22, k + 9, NovaCraftBlocks.basal_bricks, 0, 2);
		world.setBlock(i + 9, j + 22, k + 9, NovaCraftBlocks.basal_bricks, 0, 2);
		world.setBlock(i + 10, j + 22, k + 9, NovaCraftBlocks.basal_bricks, 0, 2);
		world.setBlock(i + 11, j + 22, k + 9, NovaCraftBlocks.basal_bricks, 0, 2);
		world.setBlock(i + 12, j + 22, k + 9, NovaCraftBlocks.basal_bricks, 0, 2);
		world.setBlock(i + 13, j + 22, k + 9, NovaCraftBlocks.cracked_basal_bricks, 0, 2);
		world.setBlock(i + 14, j + 22, k + 9, NovaCraftBlocks.cracked_basal_bricks, 0, 2);
		world.setBlock(i + 15, j + 22, k + 9, NovaCraftBlocks.cracked_basal_bricks, 0, 2);
		world.setBlock(i + 16, j + 22, k + 9, NovaCraftBlocks.basal_bricks, 0, 2);
		world.setBlock(i + 17, j + 22, k + 9, NovaCraftBlocks.cracked_basal_bricks, 0, 2);
		world.setBlock(i + 18, j + 22, k + 9, NovaCraftBlocks.cracked_basal_bricks, 0, 2);
		world.setBlock(i + 19, j + 22, k + 9, NovaCraftBlocks.cracked_basal_bricks, 0, 2);
		world.setBlock(i + 20, j + 22, k + 9, NovaCraftBlocks.cracked_basal_bricks, 0, 2);
		world.setBlock(i + 21, j + 22, k + 9, NovaCraftBlocks.cracked_basal_bricks, 0, 2);
		world.setBlock(i + 22, j + 22, k + 9, NovaCraftBlocks.cracked_basal_bricks, 0, 2);
		world.setBlock(i + 23, j + 22, k + 9, NovaCraftBlocks.cracked_basal_bricks, 0, 2);
		world.setBlock(i + 24, j + 22, k + 9, NovaCraftBlocks.cracked_basal_bricks, 0, 2);
		world.setBlock(i + 25, j + 22, k + 9, NovaCraftBlocks.cracked_basal_bricks, 0, 2);
		world.setBlock(i + 26, j + 22, k + 9, NovaCraftBlocks.basal_bricks, 0, 2);
		world.setBlock(i + 27, j + 22, k + 9, NovaCraftBlocks.cracked_basal_bricks, 0, 2);
		world.setBlock(i, j + 22, k + 10, NovaCraftBlocks.cracked_basal_bricks, 0, 2);
		world.setBlock(i + 1, j + 22, k + 10, NovaCraftBlocks.basal_bricks, 0, 2);
		world.setBlock(i + 2, j + 22, k + 10, NovaCraftBlocks.basal_bricks, 0, 2);
		world.setBlock(i + 3, j + 22, k + 10, NovaCraftBlocks.basal_bricks, 0, 2);
		world.setBlock(i + 4, j + 22, k + 10, NovaCraftBlocks.basal_bricks, 0, 2);
		world.setBlock(i + 5, j + 22, k + 10, NovaCraftBlocks.basal_bricks, 0, 2);
		world.setBlock(i + 6, j + 22, k + 10, NovaCraftBlocks.basal_bricks, 0, 2);
		world.setBlock(i + 7, j + 22, k + 10, NovaCraftBlocks.cracked_basal_bricks, 0, 2);
		world.setBlock(i + 8, j + 22, k + 10, NovaCraftBlocks.cracked_basal_bricks, 0, 2);
		world.setBlock(i + 9, j + 22, k + 10, NovaCraftBlocks.basal_bricks, 0, 2);
		world.setBlock(i + 10, j + 22, k + 10, NovaCraftBlocks.basal_bricks, 0, 2);
		world.setBlock(i + 11, j + 22, k + 10, NovaCraftBlocks.basal_bricks, 0, 2);
		world.setBlock(i + 12, j + 22, k + 10, NovaCraftBlocks.cracked_basal_bricks, 0, 2);
		world.setBlock(i + 13, j + 22, k + 10, NovaCraftBlocks.cracked_basal_bricks, 0, 2);
		world.setBlock(i + 14, j + 22, k + 10, NovaCraftBlocks.basal_bricks, 0, 2);
		world.setBlock(i + 15, j + 22, k + 10, NovaCraftBlocks.basal_bricks, 0, 2);
		world.setBlock(i + 16, j + 22, k + 10, NovaCraftBlocks.basal_bricks, 0, 2);
		world.setBlock(i + 17, j + 22, k + 10, NovaCraftBlocks.cracked_basal_bricks, 0, 2);
		world.setBlock(i + 18, j + 22, k + 10, NovaCraftBlocks.cracked_basal_bricks, 0, 2);
		world.setBlock(i + 19, j + 22, k + 10, NovaCraftBlocks.cracked_basal_bricks, 0, 2);
		world.setBlock(i + 20, j + 22, k + 10, NovaCraftBlocks.cracked_basal_bricks, 0, 2);
		world.setBlock(i + 21, j + 22, k + 10, NovaCraftBlocks.cracked_basal_bricks, 0, 2);
		world.setBlock(i + 22, j + 22, k + 10, NovaCraftBlocks.basal_bricks, 0, 2);
		world.setBlock(i + 23, j + 22, k + 10, NovaCraftBlocks.basal_bricks, 0, 2);
		world.setBlock(i + 24, j + 22, k + 10, NovaCraftBlocks.cracked_basal_bricks, 0, 2);
		world.setBlock(i + 25, j + 22, k + 10, NovaCraftBlocks.basal_bricks, 0, 2);
		world.setBlock(i + 26, j + 22, k + 10, NovaCraftBlocks.basal_bricks, 0, 2);
		world.setBlock(i + 27, j + 22, k + 10, NovaCraftBlocks.cracked_basal_bricks, 0, 2);
		world.setBlock(i, j + 22, k + 11, NovaCraftBlocks.basal_bricks, 0, 2);
		world.setBlock(i + 1, j + 22, k + 11, NovaCraftBlocks.cracked_basal_bricks, 0, 2);
		world.setBlock(i + 2, j + 22, k + 11, NovaCraftBlocks.basal_bricks, 0, 2);
		world.setBlock(i + 3, j + 22, k + 11, NovaCraftBlocks.basal_bricks, 0, 2);
		world.setBlock(i + 4, j + 22, k + 11, NovaCraftBlocks.basal_bricks, 0, 2);
		world.setBlock(i + 5, j + 22, k + 11, NovaCraftBlocks.basal_bricks, 0, 2);
		world.setBlock(i + 6, j + 22, k + 11, NovaCraftBlocks.basal_bricks, 0, 2);
		world.setBlock(i + 7, j + 22, k + 11, NovaCraftBlocks.cracked_basal_bricks, 0, 2);
		world.setBlock(i + 8, j + 22, k + 11, NovaCraftBlocks.cracked_basal_bricks, 0, 2);
		world.setBlock(i + 9, j + 22, k + 11, NovaCraftBlocks.basal_bricks, 0, 2);
		world.setBlock(i + 10, j + 22, k + 11, NovaCraftBlocks.basal_bricks, 0, 2);
		world.setBlock(i + 11, j + 22, k + 11, NovaCraftBlocks.cracked_basal_bricks, 0, 2);
		world.setBlock(i + 12, j + 22, k + 11, NovaCraftBlocks.basal_bricks, 0, 2);
		world.setBlock(i + 13, j + 22, k + 11, NovaCraftBlocks.basal_bricks, 0, 2);
		world.setBlock(i + 14, j + 22, k + 11, NovaCraftBlocks.cracked_basal_bricks, 0, 2);
		world.setBlock(i + 15, j + 22, k + 11, NovaCraftBlocks.basal_bricks, 0, 2);
		world.setBlock(i + 16, j + 22, k + 11, NovaCraftBlocks.basal_bricks, 0, 2);
		world.setBlock(i + 17, j + 22, k + 11, NovaCraftBlocks.basal_bricks, 0, 2);
		world.setBlock(i + 18, j + 22, k + 11, NovaCraftBlocks.cracked_basal_bricks, 0, 2);
		world.setBlock(i + 19, j + 22, k + 11, NovaCraftBlocks.basal_bricks, 0, 2);
		world.setBlock(i + 20, j + 22, k + 11, NovaCraftBlocks.cracked_basal_bricks, 0, 2);
		world.setBlock(i + 21, j + 22, k + 11, NovaCraftBlocks.basal_bricks, 0, 2);
		world.setBlock(i + 22, j + 22, k + 11, NovaCraftBlocks.basal_bricks, 0, 2);
		world.setBlock(i + 23, j + 22, k + 11, NovaCraftBlocks.basal_bricks, 0, 2);
		world.setBlock(i + 24, j + 22, k + 11, NovaCraftBlocks.basal_bricks, 0, 2);
		world.setBlock(i + 25, j + 22, k + 11, NovaCraftBlocks.cracked_basal_bricks, 0, 2);
		world.setBlock(i + 26, j + 22, k + 11, NovaCraftBlocks.cracked_basal_bricks, 0, 2);
		world.setBlock(i + 27, j + 22, k + 11, NovaCraftBlocks.basal_bricks, 0, 2);
		world.setBlock(i, j + 22, k + 12, NovaCraftBlocks.cracked_basal_bricks, 0, 2);
		world.setBlock(i + 1, j + 22, k + 12, NovaCraftBlocks.basal_bricks, 0, 2);
		world.setBlock(i + 2, j + 22, k + 12, NovaCraftBlocks.cracked_basal_bricks, 0, 2);
		world.setBlock(i + 3, j + 22, k + 12, NovaCraftBlocks.basal_bricks, 0, 2);
		world.setBlock(i + 4, j + 22, k + 12, NovaCraftBlocks.basal_bricks, 0, 2);
		world.setBlock(i + 5, j + 22, k + 12, NovaCraftBlocks.basal_bricks, 0, 2);
		world.setBlock(i + 6, j + 22, k + 12, NovaCraftBlocks.basal_bricks, 0, 2);
		world.setBlock(i + 7, j + 22, k + 12, NovaCraftBlocks.basal_bricks, 0, 2);
		world.setBlock(i + 8, j + 22, k + 12, NovaCraftBlocks.basal_bricks, 0, 2);
		world.setBlock(i + 9, j + 22, k + 12, NovaCraftBlocks.basal_bricks, 0, 2);
		world.setBlock(i + 10, j + 22, k + 12, NovaCraftBlocks.basal_bricks, 0, 2);
		world.setBlock(i + 11, j + 22, k + 12, NovaCraftBlocks.basal_bricks, 0, 2);
		world.setBlock(i + 12, j + 22, k + 12, NovaCraftBlocks.cracked_basal_bricks, 0, 2);
		world.setBlock(i + 13, j + 22, k + 12, NovaCraftBlocks.basal_bricks, 0, 2);
		world.setBlock(i + 14, j + 22, k + 12, NovaCraftBlocks.basal_bricks, 0, 2);
		world.setBlock(i + 15, j + 22, k + 12, NovaCraftBlocks.cracked_basal_bricks, 0, 2);
		world.setBlock(i + 16, j + 22, k + 12, NovaCraftBlocks.basal_bricks, 0, 2);
		world.setBlock(i + 17, j + 22, k + 12, NovaCraftBlocks.cracked_basal_bricks, 0, 2);
		world.setBlock(i + 18, j + 22, k + 12, NovaCraftBlocks.basal_bricks, 0, 2);
		world.setBlock(i + 19, j + 22, k + 12, NovaCraftBlocks.cracked_basal_bricks, 0, 2);
		world.setBlock(i + 20, j + 22, k + 12, NovaCraftBlocks.basal_bricks, 0, 2);
		world.setBlock(i + 21, j + 22, k + 12, NovaCraftBlocks.basal_bricks, 0, 2);
		world.setBlock(i + 22, j + 22, k + 12, NovaCraftBlocks.cracked_basal_bricks, 0, 2);
		world.setBlock(i + 23, j + 22, k + 12, NovaCraftBlocks.basal_bricks, 0, 2);
		world.setBlock(i + 24, j + 22, k + 12, NovaCraftBlocks.cracked_basal_bricks, 0, 2);
		world.setBlock(i + 25, j + 22, k + 12, NovaCraftBlocks.cracked_basal_bricks, 0, 2);
		world.setBlock(i + 26, j + 22, k + 12, NovaCraftBlocks.cracked_basal_bricks, 0, 2);
		world.setBlock(i + 27, j + 22, k + 12, NovaCraftBlocks.cracked_basal_bricks, 0, 2);
		world.setBlock(i, j + 22, k + 13, NovaCraftBlocks.cracked_basal_bricks, 0, 2);
		world.setBlock(i + 1, j + 22, k + 13, NovaCraftBlocks.basal_bricks, 0, 2);
		world.setBlock(i + 2, j + 22, k + 13, NovaCraftBlocks.basal_bricks, 0, 2);
		world.setBlock(i + 3, j + 22, k + 13, NovaCraftBlocks.basal_bricks, 0, 2);
		world.setBlock(i + 4, j + 22, k + 13, NovaCraftBlocks.cracked_basal_bricks, 0, 2);
		world.setBlock(i + 5, j + 22, k + 13, NovaCraftBlocks.basal_bricks, 0, 2);
		world.setBlock(i + 6, j + 22, k + 13, NovaCraftBlocks.basal_bricks, 0, 2);
		world.setBlock(i + 7, j + 22, k + 13, NovaCraftBlocks.basal_bricks, 0, 2);
		world.setBlock(i + 8, j + 22, k + 13, NovaCraftBlocks.basal_bricks, 0, 2);
		world.setBlock(i + 9, j + 22, k + 13, NovaCraftBlocks.basal_bricks, 0, 2);
		world.setBlock(i + 10, j + 22, k + 13, NovaCraftBlocks.basal_bricks, 0, 2);
		world.setBlock(i + 11, j + 22, k + 13, NovaCraftBlocks.cracked_basal_bricks, 0, 2);
		world.setBlock(i + 12, j + 22, k + 13, NovaCraftBlocks.basal_bricks, 0, 2);
		world.setBlock(i + 13, j + 22, k + 13, NovaCraftBlocks.basal_bricks, 0, 2);
		world.setBlock(i + 14, j + 22, k + 13, NovaCraftBlocks.basal_bricks, 0, 2);
		world.setBlock(i + 15, j + 22, k + 13, NovaCraftBlocks.basal_bricks, 0, 2);
		world.setBlock(i + 16, j + 22, k + 13, NovaCraftBlocks.basal_bricks, 0, 2);
		world.setBlock(i + 17, j + 22, k + 13, NovaCraftBlocks.basal_bricks, 0, 2);
		world.setBlock(i + 18, j + 22, k + 13, NovaCraftBlocks.basal_bricks, 0, 2);
		world.setBlock(i + 19, j + 22, k + 13, NovaCraftBlocks.cracked_basal_bricks, 0, 2);
		world.setBlock(i + 20, j + 22, k + 13, NovaCraftBlocks.basal_bricks, 0, 2);
		world.setBlock(i + 21, j + 22, k + 13, NovaCraftBlocks.cracked_basal_bricks, 0, 2);
		world.setBlock(i + 22, j + 22, k + 13, NovaCraftBlocks.basal_bricks, 0, 2);
		world.setBlock(i + 23, j + 22, k + 13, NovaCraftBlocks.basal_bricks, 0, 2);
		world.setBlock(i + 24, j + 22, k + 13, NovaCraftBlocks.cracked_basal_bricks, 0, 2);
		world.setBlock(i + 25, j + 22, k + 13, NovaCraftBlocks.basal_bricks, 0, 2);
		world.setBlock(i + 26, j + 22, k + 13, NovaCraftBlocks.cracked_basal_bricks, 0, 2);
		world.setBlock(i + 27, j + 22, k + 13, NovaCraftBlocks.basal_bricks, 0, 2);
		world.setBlock(i, j + 22, k + 14, NovaCraftBlocks.basal_bricks, 0, 2);
		world.setBlock(i + 1, j + 22, k + 14, NovaCraftBlocks.cracked_basal_bricks, 0, 2);
		world.setBlock(i + 2, j + 22, k + 14, NovaCraftBlocks.basal_bricks, 0, 2);
		world.setBlock(i + 3, j + 22, k + 14, NovaCraftBlocks.cracked_basal_bricks, 0, 2);
		world.setBlock(i + 4, j + 22, k + 14, NovaCraftBlocks.basal_bricks, 0, 2);
		world.setBlock(i + 5, j + 22, k + 14, NovaCraftBlocks.cracked_basal_bricks, 0, 2);
		world.setBlock(i + 6, j + 22, k + 14, NovaCraftBlocks.basal_bricks, 0, 2);
		world.setBlock(i + 7, j + 22, k + 14, NovaCraftBlocks.basal_bricks, 0, 2);
		world.setBlock(i + 8, j + 22, k + 14, NovaCraftBlocks.cracked_basal_bricks, 0, 2);
		world.setBlock(i + 9, j + 22, k + 14, NovaCraftBlocks.basal_bricks, 0, 2);
		world.setBlock(i + 10, j + 22, k + 14, NovaCraftBlocks.cracked_basal_bricks, 0, 2);
		world.setBlock(i + 11, j + 22, k + 14, NovaCraftBlocks.cracked_basal_bricks, 0, 2);
		world.setBlock(i + 12, j + 22, k + 14, NovaCraftBlocks.basal_bricks, 0, 2);
		world.setBlock(i + 13, j + 22, k + 14, NovaCraftBlocks.basal_bricks, 0, 2);
		world.setBlock(i + 14, j + 22, k + 14, NovaCraftBlocks.cracked_basal_bricks, 0, 2);
		world.setBlock(i + 15, j + 22, k + 14, NovaCraftBlocks.basal_bricks, 0, 2);
		world.setBlock(i + 16, j + 22, k + 14, NovaCraftBlocks.basal_bricks, 0, 2);
		world.setBlock(i + 17, j + 22, k + 14, NovaCraftBlocks.cracked_basal_bricks, 0, 2);
		world.setBlock(i + 18, j + 22, k + 14, NovaCraftBlocks.cracked_basal_bricks, 0, 2);
		world.setBlock(i + 19, j + 22, k + 14, NovaCraftBlocks.basal_bricks, 0, 2);
		world.setBlock(i + 20, j + 22, k + 14, NovaCraftBlocks.basal_bricks, 0, 2);
		world.setBlock(i + 21, j + 22, k + 14, NovaCraftBlocks.basal_bricks, 0, 2);
		world.setBlock(i + 22, j + 22, k + 14, NovaCraftBlocks.basal_bricks, 0, 2);
		world.setBlock(i + 23, j + 22, k + 14, NovaCraftBlocks.basal_bricks, 0, 2);
		world.setBlock(i + 24, j + 22, k + 14, NovaCraftBlocks.cracked_basal_bricks, 0, 2);
		world.setBlock(i + 25, j + 22, k + 14, NovaCraftBlocks.basal_bricks, 0, 2);
		world.setBlock(i + 26, j + 22, k + 14, NovaCraftBlocks.cracked_basal_bricks, 0, 2);
		world.setBlock(i + 27, j + 22, k + 14, NovaCraftBlocks.cracked_basal_bricks, 0, 2);
		world.setBlock(i, j + 22, k + 15, NovaCraftBlocks.basal_bricks, 0, 2);
		world.setBlock(i + 1, j + 22, k + 15, NovaCraftBlocks.cracked_basal_bricks, 0, 2);
		world.setBlock(i + 2, j + 22, k + 15, NovaCraftBlocks.cracked_basal_bricks, 0, 2);
		world.setBlock(i + 3, j + 22, k + 15, NovaCraftBlocks.basal_bricks, 0, 2);
		world.setBlock(i + 4, j + 22, k + 15, NovaCraftBlocks.basal_bricks, 0, 2);
		world.setBlock(i + 5, j + 22, k + 15, NovaCraftBlocks.basal_bricks, 0, 2);
		world.setBlock(i + 6, j + 22, k + 15, NovaCraftBlocks.basal_bricks, 0, 2);
		world.setBlock(i + 7, j + 22, k + 15, NovaCraftBlocks.cracked_basal_bricks, 0, 2);
		world.setBlock(i + 8, j + 22, k + 15, NovaCraftBlocks.basal_bricks, 0, 2);
		world.setBlock(i + 9, j + 22, k + 15, NovaCraftBlocks.cracked_basal_bricks, 0, 2);
		world.setBlock(i + 10, j + 22, k + 15, NovaCraftBlocks.basal_bricks, 0, 2);
		world.setBlock(i + 11, j + 22, k + 15, NovaCraftBlocks.basal_bricks, 0, 2);
		world.setBlock(i + 12, j + 22, k + 15, NovaCraftBlocks.basal_bricks, 0, 2);
		world.setBlock(i + 13, j + 22, k + 15, NovaCraftBlocks.cracked_basal_bricks, 0, 2);
		world.setBlock(i + 14, j + 22, k + 15, NovaCraftBlocks.cracked_basal_bricks, 0, 2);
		world.setBlock(i + 15, j + 22, k + 15, NovaCraftBlocks.cracked_basal_bricks, 0, 2);
		world.setBlock(i + 16, j + 22, k + 15, NovaCraftBlocks.cracked_basal_bricks, 0, 2);
		world.setBlock(i + 17, j + 22, k + 15, NovaCraftBlocks.basal_bricks, 0, 2);
		world.setBlock(i + 18, j + 22, k + 15, NovaCraftBlocks.basal_bricks, 0, 2);
		world.setBlock(i + 19, j + 22, k + 15, NovaCraftBlocks.basal_bricks, 0, 2);
		world.setBlock(i + 20, j + 22, k + 15, NovaCraftBlocks.cracked_basal_bricks, 0, 2);
		world.setBlock(i + 21, j + 22, k + 15, NovaCraftBlocks.basal_bricks, 0, 2);
		world.setBlock(i + 22, j + 22, k + 15, NovaCraftBlocks.basal_bricks, 0, 2);
		world.setBlock(i + 23, j + 22, k + 15, NovaCraftBlocks.basal_bricks, 0, 2);
		world.setBlock(i + 24, j + 22, k + 15, NovaCraftBlocks.basal_bricks, 0, 2);
		world.setBlock(i + 25, j + 22, k + 15, NovaCraftBlocks.basal_bricks, 0, 2);
		world.setBlock(i + 26, j + 22, k + 15, NovaCraftBlocks.basal_bricks, 0, 2);
		world.setBlock(i + 27, j + 22, k + 15, NovaCraftBlocks.basal_bricks, 0, 2);
		world.setBlock(i, j + 22, k + 16, NovaCraftBlocks.basal_bricks, 0, 2);
		world.setBlock(i + 1, j + 22, k + 16, NovaCraftBlocks.basal_bricks, 0, 2);
		world.setBlock(i + 2, j + 22, k + 16, NovaCraftBlocks.basal_bricks, 0, 2);
		world.setBlock(i + 3, j + 22, k + 16, NovaCraftBlocks.basal_bricks, 0, 2);
		world.setBlock(i + 4, j + 22, k + 16, NovaCraftBlocks.cracked_basal_bricks, 0, 2);
		world.setBlock(i + 5, j + 22, k + 16, NovaCraftBlocks.basal_bricks, 0, 2);
		world.setBlock(i + 6, j + 22, k + 16, NovaCraftBlocks.basal_bricks, 0, 2);
		world.setBlock(i + 7, j + 22, k + 16, NovaCraftBlocks.basal_bricks, 0, 2);
		world.setBlock(i + 8, j + 22, k + 16, NovaCraftBlocks.basal_bricks, 0, 2);
		world.setBlock(i + 9, j + 22, k + 16, NovaCraftBlocks.basal_bricks, 0, 2);
		world.setBlock(i + 10, j + 22, k + 16, NovaCraftBlocks.basal_bricks, 0, 2);
		world.setBlock(i + 11, j + 22, k + 16, NovaCraftBlocks.basal_bricks, 0, 2);
		world.setBlock(i + 12, j + 22, k + 16, NovaCraftBlocks.basal_bricks, 0, 2);
		world.setBlock(i + 13, j + 22, k + 16, Blocks.air, 0, 2);
		world.setBlock(i + 14, j + 22, k + 16, NovaCraftBlocks.basal_bricks, 0, 2);
