package com.NovaCraft.world.bastion.treasure;

import net.minecraft.world.gen.feature.*;
import net.minecraft.block.*;
import net.minecraft.world.*;
import java.util.*;

import com.NovaCraft.config.Configs;
import com.NovaCraft.entity.EntitySavageSerpent;
import com.NovaCraft.registry.OtherModBlocks;
import com.NovaCraftBlocks.NovaCraftBlocks;

import cpw.mods.fml.common.Loader;
import net.minecraft.init.*;

public class BastionTreasureBarracksGen6 extends WorldGenerator
{
	public BastionTreasureBarracksGen6() {

	}
	
	public boolean generate(final World world, final Random random, final int i, final int j, final int k) {
		
		world.setBlock(i + 0, j + 34, k + 2, NovaCraftBlocks.basal_bricks, 0, 2);
		world.setBlock(i + 1, j + 34, k + 2, NovaCraftBlocks.basal_bricks, 0, 2);
		world.setBlock(i + 4, j + 34, k + 2, NovaCraftBlocks.cracked_basal_bricks, 0, 2);
		world.setBlock(i + 5, j + 34, k + 2, NovaCraftBlocks.basal_bricks, 0, 2);
		world.setBlock(i + 8, j + 34, k + 2, NovaCraftBlocks.cracked_basal_bricks, 0, 2);
		world.setBlock(i + 9, j + 34, k + 2, NovaCraftBlocks.basal_bricks, 0, 2);
		world.setBlock(i + 12, j + 34, k + 2, NovaCraftBlocks.basal_bricks, 0, 2);
		world.setBlock(i + 13, j + 34, k + 2, NovaCraftBlocks.cracked_basal_bricks, 0, 2);
		world.setBlock(i + 0, j + 34, k + 3, NovaCraftBlocks.basal_bricks, 0, 2);
		world.setBlock(i + 1, j + 34, k + 3, NovaCraftBlocks.basal_bricks, 0, 2);
		world.setBlock(i + 2, j + 34, k + 3, NovaCraftBlocks.basal_scrap, 0, 2);
		world.setBlock(i + 3, j + 34, k + 3, NovaCraftBlocks.basal_scrap, 0, 2);
		world.setBlock(i + 4, j + 34, k + 3, NovaCraftBlocks.basal_bricks, 0, 2);
		world.setBlock(i + 5, j + 34, k + 3, NovaCraftBlocks.basal_bricks, 0, 2);
		world.setBlock(i + 6, j + 34, k + 3, NovaCraftBlocks.cracked_basal_bricks, 0, 2);
		world.setBlock(i + 7, j + 34, k + 3, NovaCraftBlocks.cracked_basal_bricks, 0, 2);
		world.setBlock(i + 8, j + 34, k + 3, NovaCraftBlocks.basal_bricks, 0, 2);
		world.setBlock(i + 9, j + 34, k + 3, NovaCraftBlocks.basal_bricks, 0, 2);
		world.setBlock(i + 10, j + 34, k + 3, NovaCraftBlocks.basal_scrap, 0, 2);
		world.setBlock(i + 11, j + 34, k + 3, NovaCraftBlocks.basal_scrap, 0, 2);
		world.setBlock(i + 12, j + 34, k + 3, NovaCraftBlocks.basal_bricks, 0, 2);
		world.setBlock(i + 13, j + 34, k + 3, NovaCraftBlocks.basal_bricks, 0, 2);
		world.setBlock(i + 0, j + 34, k + 4, NovaCraftBlocks.basal_bricks, 0, 2);
		world.setBlock(i + 1, j + 34, k + 4, NovaCraftBlocks.cracked_basal_bricks, 0, 2);
		world.setBlock(i + 2, j + 34, k + 4, NovaCraftBlocks.cracked_basal_bricks, 0, 2);
		world.setBlock(i + 3, j + 34, k + 4, NovaCraftBlocks.basal_bricks, 0, 2);
		world.setBlock(i + 4, j + 34, k + 4, NovaCraftBlocks.basal_bricks, 0, 2);
		world.setBlock(i + 5, j + 34, k + 4, NovaCraftBlocks.basal_bricks, 0, 2);
		world.setBlock(i + 6, j + 34, k + 4, NovaCraftBlocks.basal_bricks, 0, 2);
		world.setBlock(i + 7, j + 34, k + 4, NovaCraftBlocks.basal_bricks, 0, 2);
		world.setBlock(i + 8, j + 34, k + 4, NovaCraftBlocks.basal_bricks, 0, 2);
		world.setBlock(i + 9, j + 34, k + 4, NovaCraftBlocks.cracked_basal_bricks, 0, 2);
		world.setBlock(i + 10, j + 34, k + 4, NovaCraftBlocks.basal_bricks, 0, 2);
		world.setBlock(i + 11, j + 34, k + 4, NovaCraftBlocks.basal_bricks, 0, 2);
		world.setBlock(i + 12, j + 34, k + 4, NovaCraftBlocks.basal_bricks, 0, 2);
		world.setBlock(i + 13, j + 34, k + 4, NovaCraftBlocks.basal_scrap, 0, 2);
		world.setBlock(i + 14, j + 34, k + 4, NovaCraftBlocks.basal_bricks, 0, 2);
		world.setBlock(i + 15, j + 34, k + 4, NovaCraftBlocks.basal_bricks, 0, 2);
		world.setBlock(i + 16, j + 34, k + 4, Blocks.air, 0, 2);
		world.setBlock(i + 17, j + 34, k + 4, Blocks.air, 0, 2);
		world.setBlock(i + 18, j + 34, k + 4, NovaCraftBlocks.cracked_basal_bricks, 0, 2);
		world.setBlock(i + 19, j + 34, k + 4, NovaCraftBlocks.basal_bricks, 0, 2);
		world.setBlock(i + 20, j + 34, k + 4, Blocks.air, 0, 2);
		world.setBlock(i + 21, j + 34, k + 4, Blocks.air, 0, 2);
		world.setBlock(i + 22, j + 34, k + 4, NovaCraftBlocks.basal_bricks, 0, 2);
		world.setBlock(i + 23, j + 34, k + 4, NovaCraftBlocks.cracked_basal_bricks, 0, 2);
		world.setBlock(i + 24, j + 34, k + 4, Blocks.air, 0, 2);
		world.setBlock(i + 25, j + 34, k + 4, Blocks.air, 0, 2);
		world.setBlock(i + 26, j + 34, k + 4, NovaCraftBlocks.cracked_basal_bricks, 0, 2);
		world.setBlock(i + 27, j + 34, k + 4, NovaCraftBlocks.basal_bricks, 0, 2);
		world.setBlock(i + 0, j + 34, k + 5, NovaCraftBlocks.cracked_basal_bricks, 0, 2);
		world.setBlock(i + 1, j + 34, k + 5, NovaCraftBlocks.basal_bricks, 0, 2);
		world.setBlock(i + 2, j + 34, k + 5, NovaCraftBlocks.basal_bricks, 0, 2);
		world.setBlock(i + 3, j + 34, k + 5, NovaCraftBlocks.basal_bricks, 0, 2);
		world.setBlock(i + 4, j + 34, k + 5, NovaCraftBlocks.cracked_basal_bricks, 0, 2);
		world.setBlock(i + 5, j + 34, k + 5, NovaCraftBlocks.basal_bricks, 0, 2);
		world.setBlock(i + 6, j + 34, k + 5, NovaCraftBlocks.basal_bricks, 0, 2);
		world.setBlock(i + 7, j + 34, k + 5, NovaCraftBlocks.cracked_basal_bricks, 0, 2);
		world.setBlock(i + 8, j + 34, k + 5, NovaCraftBlocks.basal_bricks, 0, 2);
		world.setBlock(i + 9, j + 34, k + 5, NovaCraftBlocks.basal_bricks, 0, 2);
		world.setBlock(i + 10, j + 34, k + 5, NovaCraftBlocks.cracked_basal_bricks, 0, 2);
		world.setBlock(i + 11, j + 34, k + 5, NovaCraftBlocks.cracked_basal_bricks, 0, 2);
		world.setBlock(i + 12, j + 34, k + 5, NovaCraftBlocks.basal_bricks, 0, 2);
		world.setBlock(i + 13, j + 34, k + 5, NovaCraftBlocks.basal_bricks, 0, 2);
		world.setBlock(i + 14, j + 34, k + 5, NovaCraftBlocks.basal_bricks, 0, 2);
		world.setBlock(i + 15, j + 34, k + 5, NovaCraftBlocks.cracked_basal_bricks, 0, 2);
		world.setBlock(i + 16, j + 34, k + 5, NovaCraftBlocks.basal_scrap, 0, 2);
		world.setBlock(i + 17, j + 34, k + 5, NovaCraftBlocks.basal_scrap, 0, 2);
		world.setBlock(i + 18, j + 34, k + 5, NovaCraftBlocks.cracked_basal_bricks, 0, 2);
		world.setBlock(i + 19, j + 34, k + 5, NovaCraftBlocks.basal_bricks, 0, 2);
		world.setBlock(i + 20, j + 34, k + 5, NovaCraftBlocks.basal_bricks, 0, 2);
		world.setBlock(i + 21, j + 34, k + 5, NovaCraftBlocks.cracked_basal_bricks, 0, 2);
		world.setBlock(i + 22, j + 34, k + 5, NovaCraftBlocks.basal_bricks, 0, 2);
		world.setBlock(i + 23, j + 34, k + 5, NovaCraftBlocks.basal_bricks, 0, 2);
		world.setBlock(i + 24, j + 34, k + 5, NovaCraftBlocks.basal_scrap, 0, 2);
		world.setBlock(i + 25, j + 34, k + 5, NovaCraftBlocks.basal_scrap, 0, 2);
		world.setBlock(i + 26, j + 34, k + 5, NovaCraftBlocks.basal_bricks, 0, 2);
		world.setBlock(i + 27, j + 34, k + 5, NovaCraftBlocks.basal_bricks, 0, 2);
		world.setBlock(i + 0, j + 34, k + 6, NovaCraftBlocks.basal_bricks, 0, 2);
		world.setBlock(i + 1, j + 34, k + 6, NovaCraftBlocks.cracked_basal_bricks, 0, 2);
		world.setBlock(i + 2, j + 34, k + 6, NovaCraftBlocks.basal_bricks, 0, 2);
		world.setBlock(i + 3, j + 34, k + 6, NovaCraftBlocks.basal_bricks, 0, 2);
		world.setBlock(i + 4, j + 34, k + 6, NovaCraftBlocks.cracked_basal_bricks, 0, 2);
		world.setBlock(i + 5, j + 34, k + 6, NovaCraftBlocks.basal_bricks, 0, 2);
		world.setBlock(i + 6, j + 34, k + 6, NovaCraftBlocks.basal_brick_stairs, 3, 2);
		world.setBlock(i + 7, j + 34, k + 6, NovaCraftBlocks.basal_brick_stairs, 3, 2);
		world.setBlock(i + 8, j + 34, k + 6, NovaCraftBlocks.basal_bricks, 0, 2);
		world.setBlock(i + 9, j + 34, k + 6, NovaCraftBlocks.cracked_basal_bricks, 0, 2);
		world.setBlock(i + 10, j + 34, k + 6, NovaCraftBlocks.basal_bricks, 0, 2);
		world.setBlock(i + 11, j + 34, k + 6, NovaCraftBlocks.basal_bricks, 0, 2);
		world.setBlock(i + 12, j + 34, k + 6, NovaCraftBlocks.cracked_basal_bricks, 0, 2);
		world.setBlock(i + 13, j + 34, k + 6, NovaCraftBlocks.basal_scrap, 0, 2);
		world.setBlock(i + 14, j + 34, k + 6, NovaCraftBlocks.basal_bricks, 0, 2);
		world.setBlock(i + 15, j + 34, k + 6, NovaCraftBlocks.cracked_basal_bricks, 0, 2);
		world.setBlock(i + 16, j + 34, k + 6, NovaCraftBlocks.basal_bricks, 0, 2);
		world.setBlock(i + 17, j + 34, k + 6, NovaCraftBlocks.cracked_basal_bricks, 0, 2);
		world.setBlock(i + 18, j + 34, k + 6, NovaCraftBlocks.cracked_basal_bricks, 0, 2);
		world.setBlock(i + 19, j + 34, k + 6, NovaCraftBlocks.cracked_basal_bricks, 0, 2);
		world.setBlock(i + 20, j + 34, k + 6, NovaCraftBlocks.cracked_basal_bricks, 0, 2);
		world.setBlock(i + 21, j + 34, k + 6, NovaCraftBlocks.basal_bricks, 0, 2);
		world.setBlock(i + 22, j + 34, k + 6, NovaCraftBlocks.cracked_basal_bricks, 0, 2);
		world.setBlock(i + 23, j + 34, k + 6, NovaCraftBlocks.cracked_basal_bricks, 0, 2);
		world.setBlock(i + 24, j + 34, k + 6, NovaCraftBlocks.basal_bricks, 0, 2);
		world.setBlock(i + 25, j + 34, k + 6, NovaCraftBlocks.basal_bricks, 0, 2);
		world.setBlock(i + 26, j + 34, k + 6, NovaCraftBlocks.basal_bricks, 0, 2);
		world.setBlock(i + 27, j + 34, k + 6, NovaCraftBlocks.basal_scrap, 0, 2);
		world.setBlock(i + 0, j + 34, k + 7, NovaCraftBlocks.cracked_basal_bricks, 0, 2);
		world.setBlock(i + 1, j + 34, k + 7, NovaCraftBlocks.basal_bricks, 0, 2);
		world.setBlock(i + 2, j + 34, k + 7, NovaCraftBlocks.basal_bricks, 0, 2);
		world.setBlock(i + 3, j + 34, k + 7, NovaCraftBlocks.cracked_basal_bricks, 0, 2);
		world.setBlock(i + 4, j + 34, k + 7, NovaCraftBlocks.cracked_basal_bricks, 0, 2);
		world.setBlock(i + 5, j + 34, k + 7, NovaCraftBlocks.cracked_basal_bricks, 0, 2);
		world.setBlock(i + 6, j + 34, k + 7, Blocks.air, 0, 2);
		world.setBlock(i + 7, j + 34, k + 7, Blocks.air, 0, 2);
		world.setBlock(i + 8, j + 34, k + 7, NovaCraftBlocks.basal_bricks, 0, 2);
		world.setBlock(i + 9, j + 34, k + 7, NovaCraftBlocks.basal_bricks, 0, 2);
		world.setBlock(i + 10, j + 34, k + 7, NovaCraftBlocks.cracked_basal_bricks, 0, 2);
		world.setBlock(i + 11, j + 34, k + 7, NovaCraftBlocks.cracked_basal_bricks, 0, 2);
		world.setBlock(i + 12, j + 34, k + 7, NovaCraftBlocks.basal_bricks, 0, 2);
		world.setBlock(i + 13, j + 34, k + 7, NovaCraftBlocks.basal_bricks, 0, 2);
		world.setBlock(i + 14, j + 34, k + 7, NovaCraftBlocks.basal_bricks, 0, 2);
		world.setBlock(i + 15, j + 34, k + 7, NovaCraftBlocks.basal_bricks, 0, 2);
		world.setBlock(i + 16, j + 34, k + 7, NovaCraftBlocks.basal_bricks, 0, 2);
		world.setBlock(i + 17, j + 34, k + 7, NovaCraftBlocks.basal_bricks, 0, 2);
		world.setBlock(i + 18, j + 34, k + 7, NovaCraftBlocks.cracked_basal_bricks, 0, 2);
		world.setBlock(i + 19, j + 34, k + 7, NovaCraftBlocks.cracked_basal_bricks, 0, 2);
		world.setBlock(i + 20, j + 34, k + 7, NovaCraftBlocks.cracked_basal_bricks, 0, 2);
		world.setBlock(i + 21, j + 34, k + 7, NovaCraftBlocks.basal_bricks, 0, 2);
		world.setBlock(i + 22, j + 34, k + 7, NovaCraftBlocks.cracked_basal_bricks, 0, 2);
		world.setBlock(i + 23, j + 34, k + 7, NovaCraftBlocks.cracked_basal_bricks, 0, 2);
		world.setBlock(i + 24, j + 34, k + 7, NovaCraftBlocks.basal_bricks, 0, 2);
		world.setBlock(i + 25, j + 34, k + 7, NovaCraftBlocks.basal_bricks, 0, 2);
		world.setBlock(i + 26, j + 34, k + 7, NovaCraftBlocks.basal_bricks, 0, 2);
		world.setBlock(i + 27, j + 34, k + 7, NovaCraftBlocks.basal_bricks, 0, 2);
		world.setBlock(i + 0, j + 34, k + 8, NovaCraftBlocks.basal_bricks, 0, 2);
		world.setBlock(i + 1, j + 34, k + 8, NovaCraftBlocks.cracked_basal_bricks, 0, 2);
		world.setBlock(i + 2, j + 34, k + 8, NovaCraftBlocks.basal_bricks, 0, 2);
		world.setBlock(i + 3, j + 34, k + 8, NovaCraftBlocks.basal_bricks, 0, 2);
		world.setBlock(i + 4, j + 34, k + 8, Blocks.air, 0, 2);
		world.setBlock(i + 5, j + 34, k + 8, Blocks.air, 0, 2);
		world.setBlock(i + 6, j + 34, k + 8, Blocks.air, 0, 2);
		world.setBlock(i + 7, j + 34, k + 8, Blocks.air, 0, 2);
		world.setBlock(i + 8, j + 34, k + 8, Blocks.air, 0, 2);
		world.setBlock(i + 9, j + 34, k + 8, Blocks.air, 0, 2);
		world.setBlock(i + 10, j + 34, k + 8, NovaCraftBlocks.basal_bricks, 0, 2);
		world.setBlock(i + 11, j + 34, k + 8, NovaCraftBlocks.basal_bricks, 0, 2);
		world.setBlock(i + 12, j + 34, k + 8, NovaCraftBlocks.basal_bricks, 0, 2);
		world.setBlock(i + 13, j + 34, k + 8, NovaCraftBlocks.basal_bricks, 0, 2);
		world.setBlock(i + 14, j + 34, k + 8, NovaCraftBlocks.basal_bricks, 0, 2);
		world.setBlock(i + 15, j + 34, k + 8, NovaCraftBlocks.cracked_basal_bricks, 0, 2);
		world.setBlock(i + 16, j + 34, k + 8, NovaCraftBlocks.basal_bricks, 0, 2);
		world.setBlock(i + 17, j + 34, k + 8, NovaCraftBlocks.basal_bricks, 0, 2);
		world.setBlock(i + 18, j + 34, k + 8, NovaCraftBlocks.basal_bricks, 0, 2);
		world.setBlock(i + 19, j + 34, k + 8, NovaCraftBlocks.cracked_basal_bricks, 0, 2);
		world.setBlock(i + 20, j + 34, k + 8, Blocks.air, 0, 2);
		world.setBlock(i + 21, j + 34, k + 8, Blocks.air, 0, 2);
		world.setBlock(i + 22, j + 34, k + 8, NovaCraftBlocks.basal_bricks, 0, 2);
		world.setBlock(i + 23, j + 34, k + 8, NovaCraftBlocks.basal_bricks, 0, 2);
		world.setBlock(i + 24, j + 34, k + 8, NovaCraftBlocks.basal_bricks, 0, 2);
		world.setBlock(i + 25, j + 34, k + 8, NovaCraftBlocks.basal_bricks, 0, 2);
		world.setBlock(i + 26, j + 34, k + 8, NovaCraftBlocks.basal_bricks, 0, 2);
		world.setBlock(i + 27, j + 34, k + 8, NovaCraftBlocks.basal_scrap, 0, 2);
		world.setBlock(i + 0, j + 34, k + 9, Blocks.air, 0, 2);
		world.setBlock(i + 1, j + 34, k + 9, NovaCraftBlocks.basal_bricks, 0, 2);
		world.setBlock(i + 2, j + 34, k + 9, NovaCraftBlocks.cracked_basal_bricks, 0, 2);
		world.setBlock(i + 3, j + 34, k + 9, NovaCraftBlocks.basal_bricks, 0, 2);
		world.setBlock(i + 4, j + 34, k + 9, Blocks.air, 0, 2);
		world.setBlock(i + 5, j + 34, k + 9, Blocks.air, 0, 2);
		world.setBlock(i + 6, j + 34, k + 9, Blocks.air, 0, 2);
		world.setBlock(i + 7, j + 34, k + 9, Blocks.air, 0, 2);
		world.setBlock(i + 8, j + 34, k + 9, Blocks.air, 0, 2);
		world.setBlock(i + 9, j + 34, k + 9, Blocks.air, 0, 2);
		world.setBlock(i + 10, j + 34, k + 9, NovaCraftBlocks.cracked_basal_bricks, 0, 2);
		world.setBlock(i + 11, j + 34, k + 9, NovaCraftBlocks.basal_bricks, 0, 2);
		world.setBlock(i + 12, j + 34, k + 9, NovaCraftBlocks.cracked_basal_bricks, 0, 2);
		world.setBlock(i + 13, j + 34, k + 9, NovaCraftBlocks.cracked_basal_bricks, 0, 2);
		world.setBlock(i + 14, j + 34, k + 9, NovaCraftBlocks.basal_bricks, 0, 2);
		world.setBlock(i + 15, j + 34, k + 9, NovaCraftBlocks.basal_bricks, 0, 2);
		world.setBlock(i + 16, j + 34, k + 9, NovaCraftBlocks.basal_bricks, 0, 2);
		world.setBlock(i + 17, j + 34, k + 9, NovaCraftBlocks.basal_bricks, 0, 2);
		world.setBlock(i + 18, j + 34, k + 9, NovaCraftBlocks.basal_bricks, 0, 2);
		world.setBlock(i + 19, j + 34, k + 9, NovaCraftBlocks.cracked_basal_bricks, 0, 2);
		world.setBlock(i + 20, j + 34, k + 9, Blocks.air, 0, 2);
		world.setBlock(i + 21, j + 34, k + 9, Blocks.air, 0, 2);
		world.setBlock(i + 22, j + 34, k + 9, NovaCraftBlocks.basal_bricks, 0, 2);
		world.setBlock(i + 23, j + 34, k + 9, NovaCraftBlocks.basal_bricks, 0, 2);
		world.setBlock(i + 24, j + 34, k + 9, NovaCraftBlocks.cracked_basal_bricks, 0, 2);
		world.setBlock(i + 25, j + 34, k + 9, NovaCraftBlocks.basal_bricks, 0, 2);
		world.setBlock(i + 26, j + 34, k + 9, NovaCraftBlocks.basal_bricks, 0, 2);
		world.setBlock(i + 27, j + 34, k + 9, NovaCraftBlocks.cracked_basal_bricks, 0, 2);
		world.setBlock(i + 0, j + 34, k + 10, Blocks.air, 0, 2);
		world.setBlock(i + 1, j + 34, k + 10, Blocks.air, 0, 2);
		world.setBlock(i + 2, j + 34, k + 10, NovaCraftBlocks.cracked_basal_bricks, 0, 2);
		world.setBlock(i + 3, j + 34, k + 10, NovaCraftBlocks.cracked_basal_bricks, 0, 2);
		world.setBlock(i + 4, j + 34, k + 10, NovaCraftBlocks.basal_bricks, 0, 2);
		world.setBlock(i + 5, j + 34, k + 10, NovaCraftBlocks.basal_bricks, 0, 2);
		world.setBlock(i + 6, j + 34, k + 10, NovaCraftBlocks.cracked_basal_bricks, 0, 2);
		world.setBlock(i + 7, j + 34, k + 10, NovaCraftBlocks.basal_bricks, 0, 2);
		world.setBlock(i + 8, j + 34, k + 10, NovaCraftBlocks.basal_bricks, 0, 2);
		world.setBlock(i + 9, j + 34, k + 10, NovaCraftBlocks.cracked_basal_bricks, 0, 2);
		world.setBlock(i + 10, j + 34, k + 10, NovaCraftBlocks.cracked_basal_bricks, 0, 2);
		world.setBlock(i + 11, j + 34, k + 10, NovaCraftBlocks.cracked_basal_bricks, 0, 2);
		world.setBlock(i + 12, j + 34, k + 10, NovaCraftBlocks.basal_bricks, 0, 2);
		world.setBlock(i + 13, j + 34, k + 10, NovaCraftBlocks.basal_bricks, 0, 2);
		world.setBlock(i + 14, j + 34, k + 10, NovaCraftBlocks.cracked_basal_bricks, 0, 2);
		world.setBlock(i + 15, j + 34, k + 10, NovaCraftBlocks.basal_bricks, 0, 2);
		world.setBlock(i + 16, j + 34, k + 10, NovaCraftBlocks.cracked_basal_bricks, 0, 2);
		world.setBlock(i + 17, j + 34, k + 10, NovaCraftBlocks.cracked_basal_bricks, 0, 2);
		world.setBlock(i + 18, j + 34, k + 10, NovaCraftBlocks.basal_bricks, 0, 2);
		world.setBlock(i + 19, j + 34, k + 10, NovaCraftBlocks.basal_bricks, 0, 2);
		world.setBlock(i + 20, j + 34, k + 10, Blocks.air, 0, 2);
		world.setBlock(i + 21, j + 34, k + 10, Blocks.air, 0, 2);
		world.setBlock(i + 22, j + 34, k + 10, NovaCraftBlocks.basal_bricks, 0, 2);
		world.setBlock(i + 23, j + 34, k + 10, NovaCraftBlocks.cracked_basal_bricks, 0, 2);
		world.setBlock(i + 24, j + 34, k + 10, NovaCraftBlocks.cracked_basal_bricks, 0, 2);
		world.setBlock(i + 25, j + 34, k + 10, NovaCraftBlocks.basal_bricks, 0, 2);
		world.setBlock(i + 26, j + 34, k + 10, NovaCraftBlocks.basal_bricks, 0, 2);
		world.setBlock(i + 27, j + 34, k + 10, NovaCraftBlocks.basal_bricks, 0, 2);
		world.setBlock(i + 0, j + 34, k + 11, Blocks.air, 0, 2);
		world.setBlock(i + 1, j + 34, k + 11, Blocks.air, 0, 2);
		world.setBlock(i + 2, j + 34, k + 11, Blocks.air, 0, 2);
		world.setBlock(i + 3, j + 34, k + 11, Blocks.air, 0, 2);
		world.setBlock(i + 4, j + 34, k + 11, Blocks.air, 0, 2);
		world.setBlock(i + 5, j + 34, k + 11, Blocks.air, 0, 2);
		world.setBlock(i + 6, j + 34, k + 11, Blocks.air, 0, 2);
		world.setBlock(i + 7, j + 34, k + 11, Blocks.air, 0, 2);
		world.setBlock(i + 8, j + 34, k + 11, Blocks.air, 0, 2);
		world.setBlock(i + 9, j + 34, k + 11, Blocks.air, 0, 2);
		world.setBlock(i + 10, j + 34, k + 11, Blocks.air, 0, 2);
		world.setBlock(i + 11, j + 34, k + 11, Blocks.air, 0, 2);
		world.setBlock(i + 12, j + 34, k + 11, Blocks.air, 0, 2);
		world.setBlock(i + 13, j + 34, k + 11, Blocks.air, 0, 2);
		world.setBlock(i + 14, j + 34, k + 11, NovaCraftBlocks.cracked_basal_bricks, 0, 2);
		world.setBlock(i + 15, j + 34, k + 11, NovaCraftBlocks.cracked_basal_bricks, 0, 2);
		world.setBlock(i + 16, j + 34, k + 11, NovaCraftBlocks.basal_bricks, 0, 2);
		world.setBlock(i + 17, j + 34, k + 11, NovaCraftBlocks.basal_bricks, 0, 2);
		world.setBlock(i + 18, j + 34, k + 11, NovaCraftBlocks.cracked_basal_bricks, 0, 2);
		world.setBlock(i + 19, j + 34, k + 11, NovaCraftBlocks.cracked_basal_bricks, 0, 2);
		world.setBlock(i + 20, j + 34, k + 11, Blocks.air, 0, 2);
		world.setBlock(i + 21, j + 34, k + 11, Blocks.air, 0, 2);
		world.setBlock(i + 22, j + 34, k + 11, Blocks.air, 0, 2);
		world.setBlock(i + 23, j + 34, k + 11, NovaCraftBlocks.basal_bricks, 0, 2);
		world.setBlock(i + 24, j + 34, k + 11, NovaCraftBlocks.cracked_basal_bricks, 0, 2);
		world.setBlock(i + 25, j + 34, k + 11, NovaCraftBlocks.basal_bricks, 0, 2);
		world.setBlock(i + 26, j + 34, k + 11, NovaCraftBlocks.basal_bricks, 0, 2);
		world.setBlock(i + 27, j + 34, k + 11, NovaCraftBlocks.basal_bricks, 0, 2);
		world.setBlock(i + 0, j + 34, k + 12, Blocks.air, 0, 2);
		world.setBlock(i + 1, j + 34, k + 12, Blocks.air, 0, 2);
		world.setBlock(i + 2, j + 34, k + 12, Blocks.air, 0, 2);
		world.setBlock(i + 3, j + 34, k + 12, Blocks.air, 0, 2);
		world.setBlock(i + 4, j + 34, k + 12, Blocks.air, 0, 2);
		world.setBlock(i + 5, j + 34, k + 12, Blocks.air, 0, 2);
		world.setBlock(i + 6, j + 34, k + 12, Blocks.air, 0, 2);
		world.setBlock(i + 7, j + 34, k + 12, Blocks.air, 0, 2);
		world.setBlock(i + 8, j + 34, k + 12, Blocks.air, 0, 2);
		world.setBlock(i + 9, j + 34, k + 12, Blocks.air, 0, 2);
		world.setBlock(i + 10, j + 34, k + 12, Blocks.air, 0, 2);
		world.setBlock(i + 11, j + 34, k + 12, Blocks.air, 0, 2);
		world.setBlock(i + 12, j + 34, k + 12, Blocks.air, 0, 2);
		world.setBlock(i + 13, j + 34, k + 12, Blocks.air, 0, 2);
		world.setBlock(i + 14, j + 34, k + 12, NovaCraftBlocks.basal_bricks, 0, 2);
		world.setBlock(i + 15, j + 34, k + 12, NovaCraftBlocks.cracked_basal_bricks, 0, 2);
		world.setBlock(i + 16, j + 34, k + 12, NovaCraftBlocks.cracked_basal_bricks, 0, 2);
		world.setBlock(i + 17, j + 34, k + 12, NovaCraftBlocks.cracked_basal_bricks, 0, 2);
		world.setBlock(i + 18, j + 34, k + 12, NovaCraftBlocks.cracked_basal_bricks, 0, 2);
		world.setBlock(i + 19, j + 34, k + 12, NovaCraftBlocks.basal_bricks, 0, 2);
		world.setBlock(i + 20, j + 34, k + 12, NovaCraftBlocks.cracked_basal_bricks, 0, 2);
		world.setBlock(i + 21, j + 34, k + 12, NovaCraftBlocks.cracked_basal_bricks, 0, 2);
		world.setBlock(i + 22, j + 34, k + 12, NovaCraftBlocks.cracked_basal_bricks, 0, 2);
		world.setBlock(i + 23, j + 34, k + 12, NovaCraftBlocks.basal_bricks, 0, 2);
		world.setBlock(i + 24, j + 34, k + 12, NovaCraftBlocks.basal_bricks, 0, 2);
		world.setBlock(i + 25, j + 34, k + 12, NovaCraftBlocks.basal_bricks, 0, 2);
		world.setBlock(i + 26, j + 34, k + 12, NovaCraftBlocks.cracked_basal_bricks, 0, 2);
		world.setBlock(i + 27, j + 34, k + 12, NovaCraftBlocks.cracked_basal_bricks, 0, 2);
		world.setBlock(i + 0, j + 35, k + 2, NovaCraftBlocks.basal_bricks, 0, 2);
		world.setBlock(i + 1, j + 35, k + 2, NovaCraftBlocks.basal_bricks, 0, 2);
		world.setBlock(i + 4, j + 35, k + 2, NovaCraftBlocks.basal_bricks, 0, 2);
		world.setBlock(i + 5, j + 35, k + 2, NovaCraftBlocks.cracked_basal_bricks, 0, 2);
		world.setBlock(i + 8, j + 35, k + 2, NovaCraftBlocks.basal_bricks, 0, 2);
		world.setBlock(i + 9, j + 35, k + 2, NovaCraftBlocks.basal_bricks, 0, 2);
		world.setBlock(i + 12, j + 35, k + 2, NovaCraftBlocks.basal_bricks, 0, 2);
		world.setBlock(i + 13, j + 35, k + 2, NovaCraftBlocks.basal_bricks, 0, 2);
		world.setBlock(i + 0, j + 35, k + 3, NovaCraftBlocks.basal_bricks, 0, 2);
		world.setBlock(i + 1, j + 35, k + 3, NovaCraftBlocks.basal_bricks, 0, 2);
		world.setBlock(i + 2, j + 35, k + 3, NovaCraftBlocks.basal_scrap, 0, 2);
		world.setBlock(i + 3, j + 35, k + 3, NovaCraftBlocks.basal_scrap, 0, 2);
		world.setBlock(i + 4, j + 35, k + 3, NovaCraftBlocks.cracked_basal_bricks, 0, 2);
		world.setBlock(i + 5, j + 35, k + 3, NovaCraftBlocks.basal_bricks, 0, 2);
		world.setBlock(i + 6, j + 35, k + 3, NovaCraftBlocks.basal_scrap, 0, 2);
		world.setBlock(i + 7, j + 35, k + 3, NovaCraftBlocks.basal, 0, 2);
		world.setBlock(i + 8, j + 35, k + 3, NovaCraftBlocks.basal_bricks, 0, 2);
		world.setBlock(i + 9, j + 35, k + 3, NovaCraftBlocks.basal_bricks, 0, 2);
		world.setBlock(i + 10, j + 35, k + 3, NovaCraftBlocks.basal_scrap, 0, 2);
		world.setBlock(i + 11, j + 35, k + 3, NovaCraftBlocks.basal_scrap, 0, 2);
		world.setBlock(i + 12, j + 35, k + 3, NovaCraftBlocks.basal_bricks, 0, 2);
		world.setBlock(i + 13, j + 35, k + 3, NovaCraftBlocks.basal_bricks, 0, 2);
		world.setBlock(i + 0, j + 35, k + 4, NovaCraftBlocks.basal_bricks, 0, 2);
		world.setBlock(i + 1, j + 35, k + 4, NovaCraftBlocks.basal_bricks, 0, 2);
		world.setBlock(i + 2, j + 35, k + 4, NovaCraftBlocks.cracked_basal_bricks, 0, 2);
		world.setBlock(i + 3, j + 35, k + 4, NovaCraftBlocks.basal_scrap, 0, 2);
		world.setBlock(i + 4, j + 35, k + 4, NovaCraftBlocks.basal_scrap, 0, 2);
		world.setBlock(i + 5, j + 35, k + 4, NovaCraftBlocks.basal, 0, 2);
		world.setBlock(i + 6, j + 35, k + 4, NovaCraftBlocks.basal, 0, 2);
		world.setBlock(i + 7, j + 35, k + 4, NovaCraftBlocks.cracked_basal_bricks, 0, 2);
		world.setBlock(i + 8, j + 35, k + 4, NovaCraftBlocks.cracked_basal_bricks, 0, 2);
		world.setBlock(i + 9, j + 35, k + 4, NovaCraftBlocks.basal_scrap, 0, 2);
		world.setBlock(i + 10, j + 35, k + 4, NovaCraftBlocks.basal_scrap, 0, 2);
		world.setBlock(i + 11, j + 35, k + 4, NovaCraftBlocks.basal_scrap, 0, 2);
		world.setBlock(i + 12, j + 35, k + 4, NovaCraftBlocks.basal_scrap, 0, 2);
		world.setBlock(i + 13, j + 35, k + 4, NovaCraftBlocks.basal_scrap, 0, 2);
		world.setBlock(i + 14, j + 35, k + 4, NovaCraftBlocks.cracked_basal_bricks, 0, 2);
		world.setBlock(i + 15, j + 35, k + 4, NovaCraftBlocks.basal_bricks, 0, 2);
		world.setBlock(i + 16, j + 35, k + 4, Blocks.air, 0, 2);
		world.setBlock(i + 17, j + 35, k + 4, Blocks.air, 0, 2);
		world.setBlock(i + 18, j + 35, k + 4, NovaCraftBlocks.cracked_basal_bricks, 0, 2);
		world.setBlock(i + 19, j + 35, k + 4, NovaCraftBlocks.basal_bricks, 0, 2);
		world.setBlock(i + 20, j + 35, k + 4, Blocks.air, 0, 2);
		world.setBlock(i + 21, j + 35, k + 4, Blocks.air, 0, 2);
		world.setBlock(i + 22, j + 35, k + 4, NovaCraftBlocks.basal_bricks, 0, 2);
		world.setBlock(i + 23, j + 35, k + 4, NovaCraftBlocks.basal_bricks, 0, 2);
		world.setBlock(i + 24, j + 35, k + 4, Blocks.air, 0, 2);
		world.setBlock(i + 25, j + 35, k + 4, Blocks.air, 0, 2);
		world.setBlock(i + 26, j + 35, k + 4, NovaCraftBlocks.basal_bricks, 0, 2);
		world.setBlock(i + 27, j + 35, k + 4, NovaCraftBlocks.basal_bricks, 0, 2);
		world.setBlock(i + 0, j + 35, k + 5, NovaCraftBlocks.basal_bricks, 0, 2);
		world.setBlock(i + 1, j + 35, k + 5, NovaCraftBlocks.cracked_basal_bricks, 0, 2);
		world.setBlock(i + 2, j + 35, k + 5, NovaCraftBlocks.cracked_basal_bricks, 0, 2);
		world.setBlock(i + 3, j + 35, k + 5, NovaCraftBlocks.cracked_basal_bricks, 0, 2);
		world.setBlock(i + 4, j + 35, k + 5, NovaCraftBlocks.basal, 0, 2);
		world.setBlock(i + 5, j + 35, k + 5, NovaCraftBlocks.glowing_basal, 0, 2);
		world.setBlock(i + 6, j + 35, k + 5, NovaCraftBlocks.basal_brick_stairs, 3, 2);
		world.setBlock(i + 7, j + 35, k + 5, NovaCraftBlocks.basal_brick_stairs, 3, 2);
		world.setBlock(i + 8, j + 35, k + 5, NovaCraftBlocks.basal_scrap, 0, 2);
		world.setBlock(i + 9, j + 35, k + 5, NovaCraftBlocks.basal_scrap, 0, 2);
		world.setBlock(i + 10, j + 35, k + 5, NovaCraftBlocks.basal_bricks, 0, 2);
		world.setBlock(i + 11, j + 35, k + 5, NovaCraftBlocks.cracked_basal_bricks, 0, 2);
		world.setBlock(i + 12, j + 35, k + 5, NovaCraftBlocks.basal_bricks, 0, 2);
		world.setBlock(i + 13, j + 35, k + 5, NovaCraftBlocks.basal_scrap, 0, 2);
		world.setBlock(i + 14, j + 35, k + 5, NovaCraftBlocks.basal_bricks, 0, 2);
		world.setBlock(i + 15, j + 35, k + 5, NovaCraftBlocks.basal_bricks, 0, 2);
		world.setBlock(i + 16, j + 35, k + 5, NovaCraftBlocks.basal_scrap, 0, 2);
		world.setBlock(i + 17, j + 35, k + 5, NovaCraftBlocks.basal_scrap, 0, 2);
		world.setBlock(i + 18, j + 35, k + 5, NovaCraftBlocks.basal_bricks, 0, 2);
		world.setBlock(i + 19, j + 35, k + 5, NovaCraftBlocks.cracked_basal_bricks, 0, 2);
		world.setBlock(i + 20, j + 35, k + 5, NovaCraftBlocks.basal_scrap, 0, 2);
		world.setBlock(i + 21, j + 35, k + 5, NovaCraftBlocks.basal, 0, 2);
		world.setBlock(i + 22, j + 35, k + 5, NovaCraftBlocks.cracked_basal_bricks, 0, 2);
		world.setBlock(i + 23, j + 35, k + 5, NovaCraftBlocks.basal_bricks, 0, 2);
		world.setBlock(i + 24, j + 35, k + 5, NovaCraftBlocks.basal_scrap, 0, 2);
		world.setBlock(i + 25, j + 35, k + 5, NovaCraftBlocks.basal_scrap, 0, 2);
		world.setBlock(i + 26, j + 35, k + 5, NovaCraftBlocks.cracked_basal_bricks, 0, 2);
		world.setBlock(i + 27, j + 35, k + 5, NovaCraftBlocks.basal_bricks, 0, 2);
		world.setBlock(i + 0, j + 35, k + 6, NovaCraftBlocks.basal_bricks, 0, 2);
		world.setBlock(i + 1, j + 35, k + 6, NovaCraftBlocks.cracked_basal_bricks, 0, 2);
		world.setBlock(i + 2, j + 35, k + 6, NovaCraftBlocks.cracked_basal_bricks, 0, 2);
		world.setBlock(i + 3, j + 35, k + 6, NovaCraftBlocks.basal_bricks, 0, 2);
		world.setBlock(i + 4, j + 35, k + 6, NovaCraftBlocks.cracked_basal_bricks, 0, 2);
		world.setBlock(i + 5, j + 35, k + 6, NovaCraftBlocks.basal_bricks, 0, 2);
		world.setBlock(i + 6, j + 35, k + 6, Blocks.air, 0, 2);
		world.setBlock(i + 7, j + 35, k + 6, Blocks.air, 0, 2);
		world.setBlock(i + 8, j + 35, k + 6, NovaCraftBlocks.basal_bricks, 0, 2);
		world.setBlock(i + 9, j + 35, k + 6, NovaCraftBlocks.basal_bricks, 0, 2);
		world.setBlock(i + 10, j + 35, k + 6, NovaCraftBlocks.basal_bricks, 0, 2);
		world.setBlock(i + 11, j + 35, k + 6, NovaCraftBlocks.basal_bricks, 0, 2);
		world.setBlock(i + 12, j + 35, k + 6, NovaCraftBlocks.cracked_basal_bricks, 0, 2);
		world.setBlock(i + 13, j + 35, k + 6, NovaCraftBlocks.basal_scrap, 0, 2);
		world.setBlock(i + 14, j + 35, k + 6, NovaCraftBlocks.basal_bricks, 0, 2);
		world.setBlock(i + 15, j + 35, k + 6, NovaCraftBlocks.basal_bricks, 0, 2);
		world.setBlock(i + 16, j + 35, k + 6, NovaCraftBlocks.basal_bricks, 0, 2);
		world.setBlock(i + 17, j + 35, k + 6, NovaCraftBlocks.basal_scrap, 0, 2);
		world.setBlock(i + 18, j + 35, k + 6, NovaCraftBlocks.basal_scrap, 0, 2);
		world.setBlock(i + 19, j + 35, k + 6, NovaCraftBlocks.basal, 0, 2);
		world.setBlock(i + 20, j + 35, k + 6, NovaCraftBlocks.basal, 0, 2);
		world.setBlock(i + 21, j + 35, k + 6, NovaCraftBlocks.basal_bricks, 0, 2);
		world.setBlock(i + 22, j + 35, k + 6, NovaCraftBlocks.basal_bricks, 0, 2);
		world.setBlock(i + 23, j + 35, k + 6, NovaCraftBlocks.basal_scrap, 0, 2);
		world.setBlock(i + 24, j + 35, k + 6, NovaCraftBlocks.basal_scrap, 0, 2);
		world.setBlock(i + 25, j + 35, k + 6, NovaCraftBlocks.basal_scrap, 0, 2);
		world.setBlock(i + 26, j + 35, k + 6, NovaCraftBlocks.basal_scrap, 0, 2);
		world.setBlock(i + 27, j + 35, k + 6, NovaCraftBlocks.basal_scrap, 0, 2);
		world.setBlock(i + 0, j + 35, k + 7, NovaCraftBlocks.cracked_basal_bricks, 0, 2);
		world.setBlock(i + 1, j + 35, k + 7, NovaCraftBlocks.cracked_basal_bricks, 0, 2);
		world.setBlock(i + 2, j + 35, k + 7, NovaCraftBlocks.cracked_basal_bricks, 0, 2);
		world.setBlock(i + 3, j + 35, k + 7, NovaCraftBlocks.basal_bricks, 0, 2);
		world.setBlock(i + 4, j + 35, k + 7, NovaCraftBlocks.basal_bricks, 0, 2);
		world.setBlock(i + 5, j + 35, k + 7, NovaCraftBlocks.cracked_basal_bricks, 0, 2);
		world.setBlock(i + 6, j + 35, k + 7, Blocks.air, 0, 2);
		world.setBlock(i + 7, j + 35, k + 7, Blocks.air, 0, 2);
		world.setBlock(i + 8, j + 35, k + 7, NovaCraftBlocks.basal_bricks, 0, 2);
		world.setBlock(i + 9, j + 35, k + 7, NovaCraftBlocks.basal_bricks, 0, 2);
		world.setBlock(i + 10, j + 35, k + 7, NovaCraftBlocks.cracked_basal_bricks, 0, 2);
		world.setBlock(i + 11, j + 35, k + 7, NovaCraftBlocks.basal_bricks, 0, 2);
		world.setBlock(i + 12, j + 35, k + 7, NovaCraftBlocks.cracked_basal_bricks, 0, 2);
		world.setBlock(i + 13, j + 35, k + 7, NovaCraftBlocks.cracked_basal_bricks, 0, 2);
		world.setBlock(i + 14, j + 35, k + 7, NovaCraftBlocks.cracked_basal_bricks, 0, 2);
		world.setBlock(i + 15, j + 35, k + 7, NovaCraftBlocks.cracked_basal_bricks, 0, 2);
		world.setBlock(i + 16, j + 35, k + 7, NovaCraftBlocks.cracked_basal_bricks, 0, 2);
		world.setBlock(i + 17, j + 35, k + 7, NovaCraftBlocks.cracked_basal_bricks, 0, 2);
		world.setBlock(i + 18, j + 35, k + 7, NovaCraftBlocks.basal, 0, 2);
		world.setBlock(i + 19, j + 35, k + 7, NovaCraftBlocks.basal, 0, 2);
		world.setBlock(i + 20, j + 35, k + 7, Blocks.air, 0, 2);
		world.setBlock(i + 21, j + 35, k + 7, Blocks.air, 0, 2);
		world.setBlock(i + 22, j + 35, k + 7, NovaCraftBlocks.basal_scrap, 0, 2);
		world.setBlock(i + 23, j + 35, k + 7, NovaCraftBlocks.basal_scrap, 0, 2);
		world.setBlock(i + 24, j + 35, k + 7, NovaCraftBlocks.basal_bricks, 0, 2);
		world.setBlock(i + 25, j + 35, k + 7, NovaCraftBlocks.basal_bricks, 0, 2);
		world.setBlock(i + 26, j + 35, k + 7, NovaCraftBlocks.cracked_basal_bricks, 0, 2);
		world.setBlock(i + 27, j + 35, k + 7, NovaCraftBlocks.basal_scrap, 0, 2);
		world.setBlock(i + 0, j + 35, k + 8, NovaCraftBlocks.cracked_basal_bricks, 0, 2);
		world.setBlock(i + 1, j + 35, k + 8, NovaCraftBlocks.basal_bricks, 0, 2);
		world.setBlock(i + 2, j + 35, k + 8, NovaCraftBlocks.basal_bricks, 0, 2);
		world.setBlock(i + 3, j + 35, k + 8, NovaCraftBlocks.basal_bricks, 0, 2);
		world.setBlock(i + 4, j + 35, k + 8, NovaCraftBlocks.basal_bricks, 0, 2);
		world.setBlock(i + 5, j + 35, k + 8, Blocks.air, 0, 2);
		world.setBlock(i + 6, j + 35, k + 8, Blocks.air, 0, 2);
		world.setBlock(i + 7, j + 35, k + 8, Blocks.air, 0, 2);
		world.setBlock(i + 8, j + 35, k + 8, Blocks.air, 0, 2);
		world.setBlock(i + 9, j + 35, k + 8, NovaCraftBlocks.cracked_basal_bricks, 0, 2);
		world.setBlock(i + 10, j + 35, k + 8, NovaCraftBlocks.basal_bricks, 0, 2);
		world.setBlock(i + 11, j + 35, k + 8, NovaCraftBlocks.basal_bricks, 0, 2);
		world.setBlock(i + 12, j + 35, k + 8, NovaCraftBlocks.basal_bricks, 0, 2);
		world.setBlock(i + 13, j + 35, k + 8, NovaCraftBlocks.cracked_basal_bricks, 0, 2);
		world.setBlock(i + 14, j + 35, k + 8, NovaCraftBlocks.cracked_basal_bricks, 0, 2);
		world.setBlock(i + 15, j + 35, k + 8, NovaCraftBlocks.cracked_basal_bricks, 0, 2);
		world.setBlock(i + 16, j + 35, k + 8, NovaCraftBlocks.cracked_basal_bricks, 0, 2);
		world.setBlock(i + 17, j + 35, k + 8, NovaCraftBlocks.basal_bricks, 0, 2);
		world.setBlock(i + 18, j + 35, k + 8, NovaCraftBlocks.basal_bricks, 0, 2);
		world.setBlock(i + 19, j + 35, k + 8, NovaCraftBlocks.basal_bricks, 0, 2);
		world.setBlock(i + 20, j + 35, k + 8, Blocks.air, 0, 2);
		world.setBlock(i + 21, j + 35, k + 8, Blocks.air, 0, 2);
		world.setBlock(i + 22, j + 35, k + 8, NovaCraftBlocks.cracked_basal_bricks, 0, 2);
		world.setBlock(i + 23, j + 35, k + 8, NovaCraftBlocks.basal_bricks, 0, 2);
		world.setBlock(i + 24, j + 35, k + 8, NovaCraftBlocks.basal_bricks, 0, 2);
		world.setBlock(i + 25, j + 35, k + 8, NovaCraftBlocks.cracked_basal_bricks, 0, 2);
		world.setBlock(i + 26, j + 35, k + 8, NovaCraftBlocks.basal_bricks, 0, 2);
		world.setBlock(i + 27, j + 35, k + 8, NovaCraftBlocks.basal_scrap, 0, 2);
		world.setBlock(i + 0, j + 35, k + 9, Blocks.air, 0, 2);
		world.setBlock(i + 1, j + 35, k + 9, NovaCraftBlocks.basal_bricks, 0, 2);
		world.setBlock(i + 2, j + 35, k + 9, NovaCraftBlocks.basal_bricks, 0, 2);
		world.setBlock(i + 3, j + 35, k + 9, NovaCraftBlocks.basal_bricks, 0, 2);
		world.setBlock(i + 4, j + 35, k + 9, NovaCraftBlocks.basal_bricks, 0, 2);
		world.setBlock(i + 5, j + 35, k + 9, Blocks.air, 0, 2);
		world.setBlock(i + 6, j + 35, k + 9, Blocks.air, 0, 2);
		world.setBlock(i + 7, j + 35, k + 9, Blocks.air, 0, 2);
		world.setBlock(i + 8, j + 35, k + 9, Blocks.air, 0, 2);
		world.setBlock(i + 9, j + 35, k + 9, NovaCraftBlocks.basal_bricks, 0, 2);
		world.setBlock(i + 10, j + 35, k + 9, NovaCraftBlocks.cracked_basal_bricks, 0, 2);
		world.setBlock(i + 11, j + 35, k + 9, NovaCraftBlocks.basal_bricks, 0, 2);
		world.setBlock(i + 12, j + 35, k + 9, NovaCraftBlocks.cracked_basal_bricks, 0, 2);
		world.setBlock(i + 13, j + 35, k + 9, NovaCraftBlocks.basal_bricks, 0, 2);
		world.setBlock(i + 14, j + 35, k + 9, NovaCraftBlocks.basal_bricks, 0, 2);
		world.setBlock(i + 15, j + 35, k + 9, NovaCraftBlocks.basal_bricks, 0, 2);
		world.setBlock(i + 16, j + 35, k + 9, NovaCraftBlocks.basal_bricks, 0, 2);
		world.setBlock(i + 17, j + 35, k + 9, NovaCraftBlocks.cracked_basal_bricks, 0, 2);
		world.setBlock(i + 18, j + 35, k + 9, NovaCraftBlocks.cracked_basal_bricks, 0, 2);
		world.setBlock(i + 19, j + 35, k + 9, NovaCraftBlocks.basal_bricks, 0, 2);
		world.setBlock(i + 20, j + 35, k + 9, Blocks.air, 0, 2);
		world.setBlock(i + 21, j + 35, k + 9, Blocks.air, 0, 2);
		world.setBlock(i + 22, j + 35, k + 9, NovaCraftBlocks.cracked_basal_bricks, 0, 2);
		world.setBlock(i + 23, j + 35, k + 9, NovaCraftBlocks.cracked_basal_bricks, 0, 2);
		world.setBlock(i + 24, j + 35, k + 9, NovaCraftBlocks.cracked_basal_bricks, 0, 2);
		world.setBlock(i + 25, j + 35, k + 9, NovaCraftBlocks.basal_bricks, 0, 2);
		world.setBlock(i + 26, j + 35, k + 9, NovaCraftBlocks.cracked_basal_bricks, 0, 2);
		world.setBlock(i + 27, j + 35, k + 9, NovaCraftBlocks.basal_bricks, 0, 2);
		world.setBlock(i + 0, j + 35, k + 10, Blocks.air, 0, 2);
		world.setBlock(i + 1, j + 35, k + 10, NovaCraftBlocks.basal_bricks, 0, 2);
		world.setBlock(i + 2, j + 35, k + 10, NovaCraftBlocks.basal_bricks, 0, 2);
		world.setBlock(i + 3, j + 35, k + 10, NovaCraftBlocks.basal_bricks, 0, 2);
		world.setBlock(i + 4, j + 35, k + 10, NovaCraftBlocks.basal_bricks, 0, 2);
		world.setBlock(i + 5, j + 35, k + 10, NovaCraftBlocks.basal_bricks, 0, 2);
		world.setBlock(i + 6, j + 35, k + 10, NovaCraftBlocks.basal_bricks, 0, 2);
		world.setBlock(i + 7, j + 35, k + 10, NovaCraftBlocks.basal_bricks, 0, 2);
		world.setBlock(i + 8, j + 35, k + 10, NovaCraftBlocks.basal_bricks, 0, 2);
		world.setBlock(i + 9, j + 35, k + 10, NovaCraftBlocks.basal_bricks, 0, 2);
		world.setBlock(i + 10, j + 35, k + 10, NovaCraftBlocks.basal_bricks, 0, 2);
		world.setBlock(i + 11, j + 35, k + 10, NovaCraftBlocks.basal_scrap, 0, 2);
		world.setBlock(i + 12, j + 35, k + 10, NovaCraftBlocks.basal_bricks, 0, 2);
		world.setBlock(i + 13, j + 35, k + 10, NovaCraftBlocks.cracked_basal_bricks, 0, 2);
		world.setBlock(i + 14, j + 35, k + 10, NovaCraftBlocks.basal_bricks, 0, 2);
		world.setBlock(i + 15, j + 35, k + 10, NovaCraftBlocks.basal_bricks, 0, 2);
		world.setBlock(i + 16, j + 35, k + 10, NovaCraftBlocks.cracked_basal_bricks, 0, 2);
		world.setBlock(i + 17, j + 35, k + 10, NovaCraftBlocks.cracked_basal_bricks, 0, 2);
		world.setBlock(i + 18, j + 35, k + 10, NovaCraftBlocks.basal_bricks, 0, 2);
		world.setBlock(i + 19, j + 35, k + 10, NovaCraftBlocks.cracked_basal_bricks, 0, 2);
		world.setBlock(i + 20, j + 35, k + 10, Blocks.air, 0, 2);
		world.setBlock(i + 21, j + 35, k + 10, Blocks.air, 0, 2);
		world.setBlock(i + 22, j + 35, k + 10, NovaCraftBlocks.basal_bricks, 0, 2);
		world.setBlock(i + 23, j + 35, k + 10, NovaCraftBlocks.cracked_basal_bricks, 0, 2);
		world.setBlock(i + 24, j + 35, k + 10, NovaCraftBlocks.basal_bricks, 0, 2);
		world.setBlock(i + 25, j + 35, k + 10, NovaCraftBlocks.cracked_basal_bricks, 0, 2);
		world.setBlock(i + 26, j + 35, k + 10, NovaCraftBlocks.cracked_basal_bricks, 0, 2);
		world.setBlock(i + 27, j + 35, k + 10, NovaCraftBlocks.basal_bricks, 0, 2);
		world.setBlock(i + 0, j + 35, k + 11, Blocks.air, 0, 2);
		world.setBlock(i + 1, j + 35, k + 11, Blocks.air, 0, 2);
		world.setBlock(i + 2, j + 35, k + 11, Blocks.air, 0, 2);
		world.setBlock(i + 3, j + 35, k + 11, Blocks.air, 0, 2);
		world.setBlock(i + 4, j + 35, k + 11, Blocks.air, 0, 2);
		world.setBlock(i + 5, j + 35, k + 11, Blocks.air, 0, 2);
		world.setBlock(i + 6, j + 35, k + 11, Blocks.air, 0, 2);
		world.setBlock(i + 7, j + 35, k + 11, Blocks.air, 0, 2);
		world.setBlock(i + 8, j + 35, k + 11, Blocks.air, 0, 2);
		world.setBlock(i + 9, j + 35, k + 11, Blocks.air, 0, 2);
		world.setBlock(i + 10, j + 35, k + 11, Blocks.air, 0, 2);
		world.setBlock(i + 11, j + 35, k + 11, Blocks.air, 0, 2);
		world.setBlock(i + 12, j + 35, k + 11, Blocks.air, 0, 2);
		world.setBlock(i + 13, j + 35, k + 11, Blocks.air, 0, 2);
		world.setBlock(i + 14, j + 35, k + 11, NovaCraftBlocks.basal_bricks, 0, 2);
		world.setBlock(i + 15, j + 35, k + 11, NovaCraftBlocks.basal_bricks, 0, 2);
		world.setBlock(i + 16, j + 35, k + 11, NovaCraftBlocks.basal_bricks, 0, 2);
		world.setBlock(i + 17, j + 35, k + 11, NovaCraftBlocks.cracked_basal_bricks, 0, 2);
		world.setBlock(i + 18, j + 35, k + 11, NovaCraftBlocks.basal_bricks, 0, 2);
		world.setBlock(i + 19, j + 35, k + 11, NovaCraftBlocks.cracked_basal_bricks, 0, 2);
		world.setBlock(i + 21, j + 35, k + 11, Blocks.air, 0, 2);
		world.setBlock(i + 22, j + 35, k + 11, NovaCraftBlocks.basal_bricks, 0, 2);
		world.setBlock(i + 23, j + 35, k + 11, NovaCraftBlocks.cracked_basal_bricks, 0, 2);
		world.setBlock(i + 24, j + 35, k + 11, NovaCraftBlocks.basal_bricks, 0, 2);
		world.setBlock(i + 25, j + 35, k + 11, NovaCraftBlocks.basal_bricks, 0, 2);
		world.setBlock(i + 26, j + 35, k + 11, NovaCraftBlocks.basal_bricks, 0, 2);
		world.setBlock(i + 27, j + 35, k + 11, NovaCraftBlocks.basal_bricks, 0, 2);
		world.setBlock(i + 0, j + 35, k + 12, Blocks.air, 0, 2);
		world.setBlock(i + 1, j + 35, k + 12, Blocks.air, 0, 2);
		world.setBlock(i + 2, j + 35, k + 12, Blocks.air, 0, 2);
		world.setBlock(i + 3, j + 35, k + 12, Blocks.air, 0, 2);
		world.setBlock(i + 4, j + 35, k + 12, Blocks.air, 0, 2);
		world.setBlock(i + 5, j + 35, k + 12, Blocks.air, 0, 2);
		world.setBlock(i + 6, j + 35, k + 12, Blocks.air, 0, 2);
		world.setBlock(i + 7, j + 35, k + 12, Blocks.air, 0, 2);
		world.setBlock(i + 8, j + 35, k + 12, Blocks.air, 0, 2);
		world.setBlock(i + 9, j + 35, k + 12, Blocks.air, 0, 2);
		world.setBlock(i + 10, j + 35, k + 12, Blocks.air, 0, 2);
		world.setBlock(i + 11, j + 35, k + 12, Blocks.air, 0, 2);
		world.setBlock(i + 12, j + 35, k + 12, Blocks.air, 0, 2);
		world.setBlock(i + 13, j + 35, k + 12, Blocks.air, 0, 2);
		world.setBlock(i + 14, j + 35, k + 12, NovaCraftBlocks.basal_bricks, 0, 2);
		world.setBlock(i + 15, j + 35, k + 12, NovaCraftBlocks.basal_bricks, 0, 2);
		world.setBlock(i + 16, j + 35, k + 12, NovaCraftBlocks.basal_bricks, 0, 2);
		world.setBlock(i + 17, j + 35, k + 12, NovaCraftBlocks.cracked_basal_bricks, 0, 2);
		world.setBlock(i + 18, j + 35, k + 12, NovaCraftBlocks.basal_bricks, 0, 2);
		world.setBlock(i + 19, j + 35, k + 12, NovaCraftBlocks.basal_bricks, 0, 2);
		world.setBlock(i + 20, j + 35, k + 12, NovaCraftBlocks.basal_bricks, 0, 2);
		world.setBlock(i + 21, j + 35, k + 12, NovaCraftBlocks.cracked_basal_bricks, 0, 2);
		world.setBlock(i + 22, j + 35, k + 12, NovaCraftBlocks.cracked_basal_bricks, 0, 2);
		world.setBlock(i + 23, j + 35, k + 12, NovaCraftBlocks.basal_bricks, 0, 2);
		world.setBlock(i + 24, j + 35, k + 12, NovaCraftBlocks.basal_bricks, 0, 2);
		world.setBlock(i + 25, j + 35, k + 12, NovaCraftBlocks.basal_scrap, 0, 2);
		world.setBlock(i + 26, j + 35, k + 12, NovaCraftBlocks.cracked_basal_bricks, 0, 2);
		world.setBlock(i + 27, j + 35, k + 12, NovaCraftBlocks.basal_bricks, 0, 2);
		world.setBlock(i + 0, j + 36, k + 2, NovaCraftBlocks.basal_bricks, 0, 2);
		world.setBlock(i + 1, j + 36, k + 2, NovaCraftBlocks.cracked_basal_bricks, 0, 2);
		world.setBlock(i + 4, j + 36, k + 2, NovaCraftBlocks.cracked_basal_bricks, 0, 2);
		world.setBlock(i + 5, j + 36, k + 2, NovaCraftBlocks.cracked_basal_bricks, 0, 2);
		world.setBlock(i + 8, j + 36, k + 2, NovaCraftBlocks.cracked_basal_bricks, 0, 2);
		world.setBlock(i + 9, j + 36, k + 2, NovaCraftBlocks.basal_bricks, 0, 2);
		world.setBlock(i + 12, j + 36, k + 2, NovaCraftBlocks.basal_bricks, 0, 2);
		world.setBlock(i + 13, j + 36, k + 2, NovaCraftBlocks.basal_bricks, 0, 2);
		world.setBlock(i + 0, j + 36, k + 3, NovaCraftBlocks.basal_bricks, 0, 2);
		world.setBlock(i + 1, j + 36, k + 3, NovaCraftBlocks.basal_bricks, 0, 2);
		world.setBlock(i + 4, j + 36, k + 3, NovaCraftBlocks.cracked_basal_bricks, 0, 2);
		world.setBlock(i + 5, j + 36, k + 3, NovaCraftBlocks.basal_bricks, 0, 2);
		world.setBlock(i + 8, j + 36, k + 3, NovaCraftBlocks.cracked_basal_bricks, 0, 2);
		world.setBlock(i + 9, j + 36, k + 3, NovaCraftBlocks.basal_bricks, 0, 2);
		world.setBlock(i + 12, j + 36, k + 3, NovaCraftBlocks.basal_bricks, 0, 2);
		world.setBlock(i + 13, j + 36, k + 3, NovaCraftBlocks.basal_bricks, 0, 2);
		world.setBlock(i + 0, j + 36, k + 4, Blocks.air, 0, 2);
		world.setBlock(i + 1, j + 36, k + 4, Blocks.air, 0, 2);
		world.setBlock(i + 2, j + 36, k + 4, Blocks.air, 0, 2);
		world.setBlock(i + 3, j + 36, k + 4, Blocks.air, 0, 2);
		world.setBlock(i + 4, j + 36, k + 4, Blocks.air, 0, 2);
		world.setBlock(i + 5, j + 36, k + 4, Blocks.air, 0, 2);
		world.setBlock(i + 6, j + 36, k + 4, Blocks.air, 0, 2);
		world.setBlock(i + 7, j + 36, k + 4, Blocks.air, 0, 2);
		world.setBlock(i + 8, j + 36, k + 4, Blocks.air, 0, 2);
		world.setBlock(i + 9, j + 36, k + 4, Blocks.air, 0, 2);
		world.setBlock(i + 10, j + 36, k + 4, Blocks.air, 0, 2);
		world.setBlock(i + 11, j + 36, k + 4, Blocks.air, 0, 2);
		world.setBlock(i + 12, j + 36, k + 4, Blocks.air, 0, 2);
		world.setBlock(i + 13, j + 36, k + 4, Blocks.air, 0, 2);
		world.setBlock(i + 14, j + 36, k + 4, NovaCraftBlocks.cracked_basal_bricks, 0, 2);
		world.setBlock(i + 15, j + 36, k + 4, NovaCraftBlocks.basal_bricks, 0, 2);
		world.setBlock(i + 16, j + 36, k + 4, Blocks.air, 0, 2);
		world.setBlock(i + 17, j + 36, k + 4, Blocks.air, 0, 2);
		world.setBlock(i + 18, j + 36, k + 4, NovaCraftBlocks.cracked_basal_bricks, 0, 2);
		world.setBlock(i + 19, j + 36, k + 4, NovaCraftBlocks.cracked_basal_bricks, 0, 2);
		world.setBlock(i + 20, j + 36, k + 4, Blocks.air, 0, 2);
		world.setBlock(i + 21, j + 36, k + 4, Blocks.air, 0, 2);
		world.setBlock(i + 22, j + 36, k + 4, NovaCraftBlocks.basal_bricks, 0, 2);
		world.setBlock(i + 23, j + 36, k + 4, NovaCraftBlocks.basal_bricks, 0, 2);
		world.setBlock(i + 24, j + 36, k + 4, Blocks.air, 0, 2);
		world.setBlock(i + 25, j + 36, k + 4, Blocks.air, 0, 2);
		world.setBlock(i + 26, j + 36, k + 4, NovaCraftBlocks.cracked_basal_bricks, 0, 2);
		world.setBlock(i + 27, j + 36, k + 4, NovaCraftBlocks.cracked_basal_bricks, 0, 2);
		world.setBlock(i + 0, j + 36, k + 5, Blocks.air, 0, 2);
		world.setBlock(i + 1, j + 36, k + 5, NovaCraftBlocks.cracked_basal_bricks, 0, 2);
		world.setBlock(i + 2, j + 36, k + 5, NovaCraftBlocks.basal_bricks, 0, 2);
		world.setBlock(i + 3, j + 36, k + 5, NovaCraftBlocks.cracked_basal_bricks, 0, 2);
		world.setBlock(i + 4, j + 36, k + 5, Blocks.air, 0, 2);
		world.setBlock(i + 5, j + 36, k + 5, Blocks.air, 0, 2);
		world.setBlock(i + 6, j + 36, k + 5, Blocks.air, 0, 2);
		world.setBlock(i + 7, j + 36, k + 5, Blocks.air, 0, 2);
		world.setBlock(i + 8, j + 36, k + 5, Blocks.air, 0, 2);
		world.setBlock(i + 9, j + 36, k + 5, Blocks.air, 0, 2);
		world.setBlock(i + 10, j + 36, k + 5, NovaCraftBlocks.basal_bricks, 0, 2);
		world.setBlock(i + 11, j + 36, k + 5, NovaCraftBlocks.basal_bricks, 0, 2);
		world.setBlock(i + 12, j + 36, k + 5, NovaCraftBlocks.basal_bricks, 0, 2);
		world.setBlock(i + 13, j + 36, k + 5, Blocks.air, 0, 2);
		world.setBlock(i + 14, j + 36, k + 5, NovaCraftBlocks.basal_bricks, 0, 2);
		world.setBlock(i + 15, j + 36, k + 5, NovaCraftBlocks.basal_bricks, 0, 2);
		world.setBlock(i + 16, j + 36, k + 5, Blocks.air, 0, 2);
		world.setBlock(i + 17, j + 36, k + 5, Blocks.air, 0, 2);
		world.setBlock(i + 18, j + 36, k + 5, NovaCraftBlocks.cracked_basal_bricks, 0, 2);
		world.setBlock(i + 19, j + 36, k + 5, NovaCraftBlocks.basal_bricks, 0, 2);
		world.setBlock(i + 20, j + 36, k + 5, Blocks.air, 0, 2);
		world.setBlock(i + 21, j + 36, k + 5, Blocks.air, 0, 2);
		world.setBlock(i + 22, j + 36, k + 5, NovaCraftBlocks.basal_bricks, 0, 2);
		world.setBlock(i + 23, j + 36, k + 5, NovaCraftBlocks.basal_bricks, 0, 2);
		world.setBlock(i + 24, j + 36, k + 5, Blocks.air, 0, 2);
		world.setBlock(i + 25, j + 36, k + 5, Blocks.air, 0, 2);
		world.setBlock(i + 26, j + 36, k + 5, NovaCraftBlocks.basal_bricks, 0, 2);
		world.setBlock(i + 27, j + 36, k + 5, NovaCraftBlocks.basal_bricks, 0, 2);
		world.setBlock(i + 0, j + 36, k + 6, Blocks.air, 0, 2);
		world.setBlock(i + 1, j + 36, k + 6, NovaCraftBlocks.basal_bricks, 0, 2);
		world.setBlock(i + 2, j + 36, k + 6, NovaCraftBlocks.cracked_basal_bricks, 0, 2);
		world.setBlock(i + 3, j + 36, k + 6, NovaCraftBlocks.basal_bricks, 0, 2);
		world.setBlock(i + 4, j + 36, k + 6, NovaCraftBlocks.basal_brick_stairs, 2, 2);
		world.setBlock(i + 5, j + 36, k + 6, NovaCraftBlocks.basal_brick_stairs, 2, 2);
		world.setBlock(i + 6, j + 36, k + 6, Blocks.air, 0, 2);
		world.setBlock(i + 7, j + 36, k + 6, Blocks.air, 0, 2);
		world.setBlock(i + 8, j + 36, k + 6, NovaCraftBlocks.basal_brick_stairs, 2, 2);
		world.setBlock(i + 9, j + 36, k + 6, NovaCraftBlocks.basal_brick_stairs, 2, 2);
		world.setBlock(i + 10, j + 36, k + 6, NovaCraftBlocks.basal_bricks, 0, 2);
		world.setBlock(i + 11, j + 36, k + 6, NovaCraftBlocks.basal_bricks, 0, 2);
		world.setBlock(i + 12, j + 36, k + 6, NovaCraftBlocks.cracked_basal_bricks, 0, 2);
		world.setBlock(i + 13, j + 36, k + 6, Blocks.air, 0, 2);
		world.setBlock(i + 14, j + 36, k + 6, Blocks.air, 0, 2);
		world.setBlock(i + 15, j + 36, k + 6, Blocks.air, 0, 2);
		world.setBlock(i + 16, j + 36, k + 6, Blocks.air, 0, 2);
		world.setBlock(i + 17, j + 36, k + 6, Blocks.air, 0, 2);
		world.setBlock(i + 18, j + 36, k + 6, Blocks.air, 0, 2);
		world.setBlock(i + 19, j + 36, k + 6, Blocks.air, 0, 2);
		world.setBlock(i + 20, j + 36, k + 6, Blocks.air, 0, 2);
		world.setBlock(i + 21, j + 36, k + 6, Blocks.air, 0, 2);
		world.setBlock(i + 23, j + 36, k + 6, Blocks.air, 0, 2);
		world.setBlock(i + 24, j + 36, k + 6, Blocks.air, 0, 2);
		world.setBlock(i + 25, j + 36, k + 6, Blocks.air, 0, 2);
		world.setBlock(i + 26, j + 36, k + 6, Blocks.air, 0, 2);
		world.setBlock(i + 27, j + 36, k + 6, Blocks.air, 0, 2);
		world.setBlock(i + 0, j + 36, k + 7, NovaCraftBlocks.basal_bricks, 0, 2);
		world.setBlock(i + 1, j + 36, k + 7, NovaCraftBlocks.cracked_basal_bricks, 0, 2);
		world.setBlock(i + 2, j + 36, k + 7, NovaCraftBlocks.cracked_basal_bricks, 0, 2);
		world.setBlock(i + 3, j + 36, k + 7, NovaCraftBlocks.cracked_basal_bricks, 0, 2);
		world.setBlock(i + 4, j + 36, k + 7, NovaCraftBlocks.basal_bricks, 0, 2);
		world.setBlock(i + 5, j + 36, k + 7, NovaCraftBlocks.basal_bricks, 0, 2);
		world.setBlock(i + 6, j + 36, k + 7, Blocks.air, 0, 2);
		world.setBlock(i + 7, j + 36, k + 7, Blocks.air, 0, 2);
		world.setBlock(i + 8, j + 36, k + 7, NovaCraftBlocks.cracked_basal_bricks, 0, 2);
		world.setBlock(i + 9, j + 36, k + 7, NovaCraftBlocks.cracked_basal_bricks, 0, 2);
		world.setBlock(i + 10, j + 36, k + 7, NovaCraftBlocks.basal_bricks, 0, 2);
		world.setBlock(i + 11, j + 36, k + 7, NovaCraftBlocks.basal_bricks, 0, 2);
		world.setBlock(i + 12, j + 36, k + 7, NovaCraftBlocks.basal_bricks, 0, 2);
		world.setBlock(i + 13, j + 36, k + 7, NovaCraftBlocks.cracked_basal_bricks, 0, 2);
		world.setBlock(i + 14, j + 36, k + 7, Blocks.air, 0, 2);
		world.setBlock(i + 15, j + 36, k + 7, NovaCraftBlocks.cracked_basal_bricks, 0, 2);
		world.setBlock(i + 16, j + 36, k + 7, NovaCraftBlocks.basal_bricks, 0, 2);
		world.setBlock(i + 17, j + 36, k + 7, NovaCraftBlocks.cracked_basal_bricks, 0, 2);
		world.setBlock(i + 18, j + 36, k + 7, Blocks.air, 0, 2);
		world.setBlock(i + 19, j + 36, k + 7, Blocks.air, 0, 2);
		world.setBlock(i + 20, j + 36, k + 7, Blocks.air, 0, 2);
		world.setBlock(i + 21, j + 36, k + 7, Blocks.air, 0, 2);
		world.setBlock(i + 22, j + 36, k + 7, Blocks.air, 0, 2);
		world.setBlock(i + 23, j + 36, k + 7, Blocks.air, 0, 2);
		world.setBlock(i + 24, j + 36, k + 7, NovaCraftBlocks.basal_bricks, 0, 2);
		world.setBlock(i + 25, j + 36, k + 7, NovaCraftBlocks.basal_bricks, 0, 2);
		world.setBlock(i + 26, j + 36, k + 7, NovaCraftBlocks.basal_bricks, 0, 2);
		world.setBlock(i + 27, j + 36, k + 7, Blocks.air, 0, 2);
		world.setBlock(i + 0, j + 36, k + 8, NovaCraftBlocks.basal_bricks, 0, 2);
		world.setBlock(i + 1, j + 36, k + 8, NovaCraftBlocks.basal_bricks, 0, 2);
		world.setBlock(i + 2, j + 36, k + 8, NovaCraftBlocks.basal_bricks, 0, 2);
		world.setBlock(i + 3, j + 36, k + 8, NovaCraftBlocks.cracked_basal_bricks, 0, 2);
		world.setBlock(i + 4, j + 36, k + 8, NovaCraftBlocks.basal_bricks, 0, 2);
		world.setBlock(i + 5, j + 36, k + 8, NovaCraftBlocks.cracked_basal_bricks, 0, 2);
		world.setBlock(i + 6, j + 36, k + 8, Blocks.air, 0, 2);
		world.setBlock(i + 7, j + 36, k + 8, Blocks.air, 0, 2);
		world.setBlock(i + 8, j + 36, k + 8, NovaCraftBlocks.basal_bricks, 0, 2);
		world.setBlock(i + 9, j + 36, k + 8, NovaCraftBlocks.basal_bricks, 0, 2);
		world.setBlock(i + 10, j + 36, k + 8, NovaCraftBlocks.basal_bricks, 0, 2);
		world.setBlock(i + 11, j + 36, k + 8, NovaCraftBlocks.cracked_basal_bricks, 0, 2);
		world.setBlock(i + 12, j + 36, k + 8, NovaCraftBlocks.basal_bricks, 0, 2);
		world.setBlock(i + 13, j + 36, k + 8, NovaCraftBlocks.basal_bricks, 0, 2);
		world.setBlock(i + 14, j + 36, k + 8, Blocks.air, 0, 2);
		world.setBlock(i + 15, j + 36, k + 8, NovaCraftBlocks.basal_bricks, 0, 2);
		world.setBlock(i + 16, j + 36, k + 8, NovaCraftBlocks.basal_bricks, 0, 2);
		world.setBlock(i + 17, j + 36, k + 8, NovaCraftBlocks.basal_bricks, 0, 2);
		world.setBlock(i + 18, j + 36, k + 8, NovaCraftBlocks.basal_brick_stairs, 2, 2);
		world.setBlock(i + 19, j + 36, k + 8, NovaCraftBlocks.basal_brick_stairs, 2, 2);
		world.setBlock(i + 20, j + 36, k + 8, Blocks.air, 0, 2);
		world.setBlock(i + 21, j + 36, k + 8, Blocks.air, 0, 2);
		world.setBlock(i + 22, j + 36, k + 8, NovaCraftBlocks.basal_brick_stairs, 2, 2);
		world.setBlock(i + 23, j + 36, k + 8, NovaCraftBlocks.basal_brick_stairs, 2, 2);
		world.setBlock(i + 24, j + 36, k + 8, NovaCraftBlocks.cracked_basal_bricks, 0, 2);
		world.setBlock(i + 25, j + 36, k + 8, NovaCraftBlocks.basal_bricks, 0, 2);
		world.setBlock(i + 26, j + 36, k + 8, NovaCraftBlocks.cracked_basal_bricks, 0, 2);
		world.setBlock(i + 27, j + 36, k + 8, Blocks.air, 0, 2);
		world.setBlock(i + 0, j + 36, k + 9, NovaCraftBlocks.basal_bricks, 0, 2);
		world.setBlock(i + 1, j + 36, k + 9, NovaCraftBlocks.cracked_basal_bricks, 0, 2);
		world.setBlock(i + 2, j + 36, k + 9, NovaCraftBlocks.cracked_basal_bricks, 0, 2);
		world.setBlock(i + 3, j + 36, k + 9, NovaCraftBlocks.cracked_basal_bricks, 0, 2);
		world.setBlock(i + 4, j + 36, k + 9, NovaCraftBlocks.cracked_basal_bricks, 0, 2);
		world.setBlock(i + 5, j + 36, k + 9, NovaCraftBlocks.cracked_basal_bricks, 0, 2);
		world.setBlock(i + 6, j + 36, k + 9, Blocks.air, 0, 2);
		world.setBlock(i + 8, j + 36, k + 9, NovaCraftBlocks.basal_bricks, 0, 2);
		world.setBlock(i + 9, j + 36, k + 9, NovaCraftBlocks.basal_bricks, 0, 2);
		world.setBlock(i + 10, j + 36, k + 9, NovaCraftBlocks.basal_bricks, 0, 2);
		world.setBlock(i + 11, j + 36, k + 9, NovaCraftBlocks.basal_bricks, 0, 2);
		world.setBlock(i + 12, j + 36, k + 9, NovaCraftBlocks.basal_bricks, 0, 2);
		world.setBlock(i + 13, j + 36, k + 9, NovaCraftBlocks.cracked_basal_bricks, 0, 2);
		world.setBlock(i + 14, j + 36, k + 9, NovaCraftBlocks.basal_bricks, 0, 2);
		world.setBlock(i + 15, j + 36, k + 9, NovaCraftBlocks.basal_bricks, 0, 2);
		world.setBlock(i + 16, j + 36, k + 9, NovaCraftBlocks.basal_bricks, 0, 2);
		world.setBlock(i + 17, j + 36, k + 9, NovaCraftBlocks.basal_bricks, 0, 2);
		world.setBlock(i + 18, j + 36, k + 9, NovaCraftBlocks.cracked_basal_bricks, 0, 2);
		world.setBlock(i + 19, j + 36, k + 9, NovaCraftBlocks.basal_bricks, 0, 2);
		world.setBlock(i + 20, j + 36, k + 9, NovaCraftBlocks.basal_bricks, 0, 2);
		world.setBlock(i + 21, j + 36, k + 9, NovaCraftBlocks.basal_bricks, 0, 2);
		world.setBlock(i + 22, j + 36, k + 9, NovaCraftBlocks.cracked_basal_bricks, 0, 2);
		world.setBlock(i + 23, j + 36, k + 9, NovaCraftBlocks.cracked_basal_bricks, 0, 2);
		world.setBlock(i + 24, j + 36, k + 9, NovaCraftBlocks.basal_bricks, 0, 2);
		world.setBlock(i + 25, j + 36, k + 9, NovaCraftBlocks.basal_bricks, 0, 2);
		world.setBlock(i + 26, j + 36, k + 9, NovaCraftBlocks.basal_bricks, 0, 2);
		world.setBlock(i + 27, j + 36, k + 9, NovaCraftBlocks.basal_bricks, 0, 2);
		world.setBlock(i + 0, j + 36, k + 10, Blocks.air, 0, 2);
		world.setBlock(i + 1, j + 36, k + 10, NovaCraftBlocks.cracked_basal_bricks, 0, 2);
		world.setBlock(i + 2, j + 36, k + 10, NovaCraftBlocks.basal_bricks, 0, 2);
		world.setBlock(i + 3, j + 36, k + 10, NovaCraftBlocks.cracked_basal_bricks, 0, 2);
		world.setBlock(i + 4, j + 36, k + 10, NovaCraftBlocks.basal_scrap, 0, 2);
		world.setBlock(i + 5, j + 36, k + 10, NovaCraftBlocks.basal_bricks, 0, 2);
		world.setBlock(i + 6, j + 36, k + 10, NovaCraftBlocks.basal_bricks, 0, 2);
		world.setBlock(i + 7, j + 36, k + 10, NovaCraftBlocks.basal_bricks, 0, 2);
		world.setBlock(i + 8, j + 36, k + 10, NovaCraftBlocks.basal_bricks, 0, 2);
		world.setBlock(i + 9, j + 36, k + 10, NovaCraftBlocks.basal_bricks, 0, 2);
		world.setBlock(i + 10, j + 36, k + 10, NovaCraftBlocks.basal_bricks, 0, 2);
		world.setBlock(i + 11, j + 36, k + 10, NovaCraftBlocks.basal_scrap, 0, 2);
		world.setBlock(i + 12, j + 36, k + 10, NovaCraftBlocks.basal_bricks, 0, 2);
		world.setBlock(i + 13, j + 36, k + 10, NovaCraftBlocks.basal_bricks, 0, 2);
		world.setBlock(i + 14, j + 36, k + 10, NovaCraftBlocks.basal_bricks, 0, 2);
		world.setBlock(i + 15, j + 36, k + 10, NovaCraftBlocks.basal_bricks, 0, 2);
		world.setBlock(i + 16, j + 36, k + 10, NovaCraftBlocks.basal_bricks, 0, 2);
		world.setBlock(i + 17, j + 36, k + 10, NovaCraftBlocks.basal_bricks, 0, 2);
		world.setBlock(i + 18, j + 36, k + 10, NovaCraftBlocks.basal_bricks, 0, 2);
		world.setBlock(i + 19, j + 36, k + 10, NovaCraftBlocks.basal_bricks, 0, 2);
		world.setBlock(i + 20, j + 36, k + 10, NovaCraftBlocks.basal_bricks, 0, 2);
		world.setBlock(i + 21, j + 36, k + 10, NovaCraftBlocks.cracked_basal_bricks, 0, 2);
		world.setBlock(i + 22, j + 36, k + 10, NovaCraftBlocks.basal_bricks, 0, 2);
		world.setBlock(i + 23, j + 36, k + 10, NovaCraftBlocks.basal_bricks, 0, 2);
		world.setBlock(i + 24, j + 36, k + 10, NovaCraftBlocks.cracked_basal_bricks, 0, 2);
		world.setBlock(i + 25, j + 36, k + 10, NovaCraftBlocks.basal_bricks, 0, 2);
		world.setBlock(i + 26, j + 36, k + 10, NovaCraftBlocks.basal_bricks, 0, 2);
		world.setBlock(i + 27, j + 36, k + 10, NovaCraftBlocks.basal_bricks, 0, 2);
		world.setBlock(i + 0, j + 36, k + 11, Blocks.air, 0, 2);
		world.setBlock(i + 1, j + 36, k + 11, Blocks.air, 0, 2);
		world.setBlock(i + 2, j + 36, k + 11, Blocks.air, 0, 2);
		world.setBlock(i + 3, j + 36, k + 11, Blocks.air, 0, 2);
		world.setBlock(i + 4, j + 36, k + 11, Blocks.air, 0, 2);
		world.setBlock(i + 5, j + 36, k + 11, Blocks.air, 0, 2);
		world.setBlock(i + 6, j + 36, k + 11, Blocks.air, 0, 2);
		world.setBlock(i + 7, j + 36, k + 11, Blocks.air, 0, 2);
		world.setBlock(i + 8, j + 36, k + 11, Blocks.air, 0, 2);
		world.setBlock(i + 9, j + 36, k + 11, Blocks.air, 0, 2);
		world.setBlock(i + 10, j + 36, k + 11, Blocks.air, 0, 2);
		world.setBlock(i + 11, j + 36, k + 11, Blocks.air, 0, 2);
		world.setBlock(i + 12, j + 36, k + 11, Blocks.air, 0, 2);
		world.setBlock(i + 13, j + 36, k + 11, Blocks.air, 0, 2);
		world.setBlock(i + 14, j + 36, k + 11, NovaCraftBlocks.basal_bricks, 0, 2);
		world.setBlock(i + 15, j + 36, k + 11, NovaCraftBlocks.cracked_basal_bricks, 0, 2);
		world.setBlock(i + 16, j + 36, k + 11, NovaCraftBlocks.basal_bricks, 0, 2);
		world.setBlock(i + 17, j + 36, k + 11, NovaCraftBlocks.cracked_basal_bricks, 0, 2);
		world.setBlock(i + 18, j + 36, k + 11, NovaCraftBlocks.basal_bricks, 0, 2);
		world.setBlock(i + 19, j + 36, k + 11, NovaCraftBlocks.basal_bricks, 0, 2);
		world.setBlock(i + 20, j + 36, k + 11, NovaCraftBlocks.basal_bricks, 0, 2);
		world.setBlock(i + 21, j + 36, k + 11, NovaCraftBlocks.basal_bricks, 0, 2);
		world.setBlock(i + 22, j + 36, k + 11, NovaCraftBlocks.basal_bricks, 0, 2);
		world.setBlock(i + 23, j + 36, k + 11, NovaCraftBlocks.basal_bricks, 0, 2);
		world.setBlock(i + 24, j + 36, k + 11, NovaCraftBlocks.basal_bricks, 0, 2);
		world.setBlock(i + 25, j + 36, k + 11, NovaCraftBlocks.cracked_basal_bricks, 0, 2);
		world.setBlock(i + 26, j + 36, k + 11, NovaCraftBlocks.basal_bricks, 0, 2);
		world.setBlock(i + 27, j + 36, k + 11, NovaCraftBlocks.cracked_basal_bricks, 0, 2);
		world.setBlock(i + 0, j + 36, k + 12, Blocks.air, 0, 2);
		world.setBlock(i + 1, j + 36, k + 12, Blocks.air, 0, 2);
		world.setBlock(i + 2, j + 36, k + 12, Blocks.air, 0, 2);
		world.setBlock(i + 3, j + 36, k + 12, Blocks.air, 0, 2);
		world.setBlock(i + 4, j + 36, k + 12, Blocks.air, 0, 2);
		world.setBlock(i + 5, j + 36, k + 12, Blocks.air, 0, 2);
		world.setBlock(i + 6, j + 36, k + 12, Blocks.air, 0, 2);
		world.setBlock(i + 7, j + 36, k + 12, Blocks.air, 0, 2);
		world.setBlock(i + 8, j + 36, k + 12, Blocks.air, 0, 2);
		world.setBlock(i + 9, j + 36, k + 12, Blocks.air, 0, 2);
		world.setBlock(i + 10, j + 36, k + 12, Blocks.air, 0, 2);
		world.setBlock(i + 11, j + 36, k + 12, Blocks.air, 0, 2);
		world.setBlock(i + 12, j + 36, k + 12, Blocks.air, 0, 2);
		world.setBlock(i + 13, j + 36, k + 12, Blocks.air, 0, 2);
		world.setBlock(i + 14, j + 36, k + 12, NovaCraftBlocks.cracked_basal_bricks, 0, 2);
		world.setBlock(i + 15, j + 36, k + 12, NovaCraftBlocks.basal_bricks, 0, 2);
		world.setBlock(i + 16, j + 36, k + 12, NovaCraftBlocks.basal_bricks, 0, 2);
		world.setBlock(i + 17, j + 36, k + 12, NovaCraftBlocks.basal_bricks, 0, 2);
		world.setBlock(i + 18, j + 36, k + 12, NovaCraftBlocks.basal_scrap, 0, 2);
		world.setBlock(i + 19, j + 36, k + 12, NovaCraftBlocks.cracked_basal_bricks, 0, 2);
		world.setBlock(i + 20, j + 36, k + 12, NovaCraftBlocks.basal_bricks, 0, 2);
		world.setBlock(i + 21, j + 36, k + 12, NovaCraftBlocks.cracked_basal_bricks, 0, 2);
		world.setBlock(i + 22, j + 36, k + 12, NovaCraftBlocks.basal_bricks, 0, 2);
		world.setBlock(i + 23, j + 36, k + 12, NovaCraftBlocks.cracked_basal_bricks, 0, 2);
		world.setBlock(i + 24, j + 36, k + 12, NovaCraftBlocks.basal_bricks, 0, 2);
		world.setBlock(i + 25, j + 36, k + 12, NovaCraftBlocks.basal_scrap, 0, 2);
		world.setBlock(i + 26, j + 36, k + 12, NovaCraftBlocks.cracked_basal_bricks, 0, 2);
		world.setBlock(i + 27, j + 36, k + 12, NovaCraftBlocks.cracked_basal_bricks, 0, 2);
		world.setBlock(i + 0, j + 37, k + 2, NovaCraftBlocks.cracked_basal_bricks, 0, 2);
		world.setBlock(i + 1, j + 37, k + 2, NovaCraftBlocks.basal_bricks, 0, 2);
		world.setBlock(i + 4, j + 37, k + 2, NovaCraftBlocks.basal_bricks, 0, 2);
		world.setBlock(i + 5, j + 37, k + 2, NovaCraftBlocks.cracked_basal_bricks, 0, 2);
		world.setBlock(i + 8, j + 37, k + 2, NovaCraftBlocks.basal_bricks, 0, 2);
		world.setBlock(i + 9, j + 37, k + 2, NovaCraftBlocks.basal_bricks, 0, 2);
		world.setBlock(i + 12, j + 37, k + 2, NovaCraftBlocks.basal_bricks, 0, 2);
		world.setBlock(i + 13, j + 37, k + 2, NovaCraftBlocks.basal_bricks, 0, 2);
		world.setBlock(i + 0, j + 37, k + 3, NovaCraftBlocks.cracked_basal_bricks, 0, 2);
		world.setBlock(i + 1, j + 37, k + 3, NovaCraftBlocks.cracked_basal_bricks, 0, 2);
		world.setBlock(i + 4, j + 37, k + 3, NovaCraftBlocks.basal_bricks, 0, 2);
		world.setBlock(i + 5, j + 37, k + 3, NovaCraftBlocks.cracked_basal_bricks, 0, 2);
		world.setBlock(i + 8, j + 37, k + 3, NovaCraftBlocks.cracked_basal_bricks, 0, 2);
		world.setBlock(i + 9, j + 37, k + 3, NovaCraftBlocks.basal_bricks, 0, 2);
		world.setBlock(i + 12, j + 37, k + 3, NovaCraftBlocks.cracked_basal_bricks, 0, 2);
		world.setBlock(i + 13, j + 37, k + 3, NovaCraftBlocks.cracked_basal_bricks, 0, 2);
		world.setBlock(i + 0, j + 37, k + 4, Blocks.air, 0, 2);
		world.setBlock(i + 1, j + 37, k + 4, Blocks.air, 0, 2);
		world.setBlock(i + 2, j + 37, k + 4, Blocks.air, 0, 2);
		world.setBlock(i + 3, j + 37, k + 4, Blocks.air, 0, 2);
		world.setBlock(i + 4, j + 37, k + 4, Blocks.air, 0, 2);
		world.setBlock(i + 5, j + 37, k + 4, Blocks.air, 0, 2);
		world.setBlock(i + 6, j + 37, k + 4, Blocks.air, 0, 2);
		world.setBlock(i + 7, j + 37, k + 4, Blocks.air, 0, 2);
		world.setBlock(i + 8, j + 37, k + 4, Blocks.air, 0, 2);
		world.setBlock(i + 9, j + 37, k + 4, Blocks.air, 0, 2);
		world.setBlock(i + 10, j + 37, k + 4, Blocks.air, 0, 2);
		world.setBlock(i + 11, j + 37, k + 4, Blocks.air, 0, 2);
		world.setBlock(i + 12, j + 37, k + 4, Blocks.air, 0, 2);
		world.setBlock(i + 13, j + 37, k + 4, Blocks.air, 0, 2);
		world.setBlock(i + 14, j + 37, k + 4, NovaCraftBlocks.cracked_basal_bricks, 0, 2);
		world.setBlock(i + 15, j + 37, k + 4, NovaCraftBlocks.cracked_basal_bricks, 0, 2);
		world.setBlock(i + 16, j + 37, k + 4, Blocks.air, 0, 2);
		world.setBlock(i + 17, j + 37, k + 4, Blocks.air, 0, 2);
		world.setBlock(i + 18, j + 37, k + 4, NovaCraftBlocks.basal_bricks, 0, 2);
		world.setBlock(i + 19, j + 37, k + 4, NovaCraftBlocks.basal_bricks, 0, 2);
		world.setBlock(i + 20, j + 37, k + 4, Blocks.air, 0, 2);
		world.setBlock(i + 21, j + 37, k + 4, Blocks.air, 0, 2);
		world.setBlock(i + 22, j + 37, k + 4, NovaCraftBlocks.basal_bricks, 0, 2);
		world.setBlock(i + 23, j + 37, k + 4, NovaCraftBlocks.cracked_basal_bricks, 0, 2);
		world.setBlock(i + 24, j + 37, k + 4, Blocks.air, 0, 2);
		world.setBlock(i + 25, j + 37, k + 4, Blocks.air, 0, 2);
		world.setBlock(i + 26, j + 37, k + 4, NovaCraftBlocks.basal_bricks, 0, 2);
		world.setBlock(i + 27, j + 37, k + 4, NovaCraftBlocks.cracked_basal_bricks, 0, 2);
		world.setBlock(i + 0, j + 37, k + 5, Blocks.air, 0, 2);
		world.setBlock(i + 1, j + 37, k + 5, NovaCraftBlocks.cracked_basal_bricks, 0, 2);
		world.setBlock(i + 2, j + 37, k + 5, NovaCraftBlocks.cracked_basal_bricks, 0, 2);
		world.setBlock(i + 3, j + 37, k + 5, NovaCraftBlocks.basal_bricks, 0, 2);
		world.setBlock(i + 4, j + 37, k + 5, Blocks.air, 0, 2);
		world.setBlock(i + 5, j + 37, k + 5, Blocks.air, 0, 2);
		world.setBlock(i + 6, j + 37, k + 5, Blocks.air, 0, 2);
		world.setBlock(i + 7, j + 37, k + 5, Blocks.air, 0, 2);
		world.setBlock(i + 8, j + 37, k + 5, Blocks.air, 0, 2);
		world.setBlock(i + 9, j + 37, k + 5, Blocks.air, 0, 2);
		world.setBlock(i + 10, j + 37, k + 5, NovaCraftBlocks.basal_bricks, 0, 2);
		world.setBlock(i + 11, j + 37, k + 5, NovaCraftBlocks.basal_bricks, 0, 2);
		world.setBlock(i + 12, j + 37, k + 5, NovaCraftBlocks.basal_bricks, 0, 2);
		world.setBlock(i + 13, j + 37, k + 5, Blocks.air, 0, 2);
		world.setBlock(i + 14, j + 37, k + 5, NovaCraftBlocks.basal_bricks, 0, 2);
		world.setBlock(i + 15, j + 37, k + 5, NovaCraftBlocks.cracked_basal_bricks, 0, 2);
		world.setBlock(i + 16, j + 37, k + 5, Blocks.air, 0, 2);
		world.setBlock(i + 17, j + 37, k + 5, Blocks.air, 0, 2);
		world.setBlock(i + 18, j + 37, k + 5, NovaCraftBlocks.basal_bricks, 0, 2);
		world.setBlock(i + 19, j + 37, k + 5, NovaCraftBlocks.basal_bricks, 0, 2);
		world.setBlock(i + 20, j + 37, k + 5, Blocks.air, 0, 2);
		world.setBlock(i + 21, j + 37, k + 5, Blocks.air, 0, 2);
		world.setBlock(i + 22, j + 37, k + 5, NovaCraftBlocks.basal_bricks, 0, 2);
		world.setBlock(i + 23, j + 37, k + 5, NovaCraftBlocks.basal_bricks, 0, 2);
		world.setBlock(i + 24, j + 37, k + 5, Blocks.air, 0, 2);
		world.setBlock(i + 25, j + 37, k + 5, Blocks.air, 0, 2);
		world.setBlock(i + 26, j + 37, k + 5, NovaCraftBlocks.basal_bricks, 0, 2);
		world.setBlock(i + 27, j + 37, k + 5, NovaCraftBlocks.cracked_basal_bricks, 0, 2);
		world.setBlock(i + 0, j + 37, k + 6, Blocks.air, 0, 2);
		world.setBlock(i + 1, j + 37, k + 6, NovaCraftBlocks.basal_bricks, 0, 2);
		world.setBlock(i + 2, j + 37, k + 6, NovaCraftBlocks.basal_bricks, 0, 2);
		world.setBlock(i + 3, j + 37, k + 6, NovaCraftBlocks.basal_bricks, 0, 2);
		world.setBlock(i + 4, j + 37, k + 6, Blocks.air, 0, 2);
		world.setBlock(i + 5, j + 37, k + 6, Blocks.air, 0, 2);
		world.setBlock(i + 6, j + 37, k + 6, Blocks.air, 0, 2);
		world.setBlock(i + 7, j + 37, k + 6, Blocks.air, 0, 2);
		world.setBlock(i + 8, j + 37, k + 6, Blocks.air, 0, 2);
		world.setBlock(i + 9, j + 37, k + 6, Blocks.air, 0, 2);
		world.setBlock(i + 10, j + 37, k + 6, NovaCraftBlocks.basal_bricks, 0, 2);
		world.setBlock(i + 11, j + 37, k + 6, NovaCraftBlocks.basal_bricks, 0, 2);
		world.setBlock(i + 12, j + 37, k + 6, NovaCraftBlocks.basal_bricks, 0, 2);
		world.setBlock(i + 13, j + 37, k + 6, Blocks.air, 0, 2);
		world.setBlock(i + 14, j + 37, k + 6, Blocks.air, 0, 2);
		world.setBlock(i + 15, j + 37, k + 6, Blocks.air, 0, 2);
		world.setBlock(i + 16, j + 37, k + 6, Blocks.air, 0, 2);
		world.setBlock(i + 17, j + 37, k + 6, Blocks.air, 0, 2);
		world.setBlock(i + 18, j + 37, k + 6, Blocks.air, 0, 2);
		world.setBlock(i + 19, j + 37, k + 6, Blocks.air, 0, 2);
		world.setBlock(i + 20, j + 37, k + 6, Blocks.air, 0, 2);
		world.setBlock(i + 21, j + 37, k + 6, Blocks.air, 0, 2);
		world.setBlock(i + 22, j + 37, k + 6, Blocks.air, 0, 2);
		world.setBlock(i + 23, j + 37, k + 6, Blocks.air, 0, 2);
		world.setBlock(i + 24, j + 37, k + 6, Blocks.air, 0, 2);
		world.setBlock(i + 25, j + 37, k + 6, Blocks.air, 0, 2);
		world.setBlock(i + 26, j + 37, k + 6, Blocks.air, 0, 2);
		world.setBlock(i + 27, j + 37, k + 6, Blocks.air, 0, 2);
		world.setBlock(i + 0, j + 37, k + 7, NovaCraftBlocks.basal_bricks, 0, 2);
		world.setBlock(i + 1, j + 37, k + 7, NovaCraftBlocks.cracked_basal_bricks, 0, 2);
		world.setBlock(i + 2, j + 37, k + 7, NovaCraftBlocks.basal_bricks, 0, 2);
		world.setBlock(i + 3, j + 37, k + 7, NovaCraftBlocks.basal_bricks, 0, 2);
		world.setBlock(i + 4, j + 37, k + 7, NovaCraftBlocks.basal_brick_stairs, 2, 2);
		world.setBlock(i + 5, j + 37, k + 7, NovaCraftBlocks.basal_brick_stairs, 2, 2);
		world.setBlock(i + 6, j + 37, k + 7, NovaCraftBlocks.cracked_basal_bricks, 0, 2);
		world.setBlock(i + 7, j + 37, k + 7, NovaCraftBlocks.cracked_basal_bricks, 0, 2);
		world.setBlock(i + 8, j + 37, k + 7, NovaCraftBlocks.basal_brick_stairs, 2, 2);
		world.setBlock(i + 9, j + 37, k + 7, NovaCraftBlocks.basal_brick_stairs, 2, 2);
		world.setBlock(i + 10, j + 37, k + 7, NovaCraftBlocks.basal_bricks, 0, 2);
		world.setBlock(i + 11, j + 37, k + 7, NovaCraftBlocks.cracked_basal_bricks, 0, 2);
		world.setBlock(i + 12, j + 37, k + 7, NovaCraftBlocks.cracked_basal_bricks, 0, 2);
		world.setBlock(i + 13, j + 37, k + 7, NovaCraftBlocks.basal_bricks, 0, 2);
		world.setBlock(i + 14, j + 37, k + 7, Blocks.air, 0, 2);
		world.setBlock(i + 15, j + 37, k + 7, NovaCraftBlocks.basal_bricks, 0, 2);
		world.setBlock(i + 16, j + 37, k + 7, NovaCraftBlocks.cracked_basal_bricks, 0, 2);
		world.setBlock(i + 17, j + 37, k + 7, NovaCraftBlocks.basal_bricks, 0, 2);
		world.setBlock(i + 18, j + 37, k + 7, Blocks.air, 0, 2);
		world.setBlock(i + 19, j + 37, k + 7, Blocks.air, 0, 2);
		world.setBlock(i + 20, j + 37, k + 7, Blocks.air, 0, 2);
		world.setBlock(i + 21, j + 37, k + 7, Blocks.air, 0, 2);
		world.setBlock(i + 22, j + 37, k + 7, Blocks.air, 0, 2);
		world.setBlock(i + 23, j + 37, k + 7, Blocks.air, 0, 2);
		world.setBlock(i + 24, j + 37, k + 7, NovaCraftBlocks.basal_bricks, 0, 2);
		world.setBlock(i + 25, j + 37, k + 7, NovaCraftBlocks.cracked_basal_bricks, 0, 2);
		world.setBlock(i + 26, j + 37, k + 7, NovaCraftBlocks.basal_bricks, 0, 2);
		world.setBlock(i + 27, j + 37, k + 7, Blocks.air, 0, 2);
		world.setBlock(i + 0, j + 37, k + 8, NovaCraftBlocks.cracked_basal_bricks, 0, 2);
		world.setBlock(i + 1, j + 37, k + 8, NovaCraftBlocks.basal_bricks, 0, 2);
		world.setBlock(i + 2, j + 37, k + 8, NovaCraftBlocks.basal_bricks, 0, 2);
		world.setBlock(i + 3, j + 37, k + 8, NovaCraftBlocks.basal_bricks, 0, 2);
		world.setBlock(i + 4, j + 37, k + 8, NovaCraftBlocks.basal_bricks, 0, 2);
		world.setBlock(i + 5, j + 37, k + 8, NovaCraftBlocks.basal_bricks, 0, 2);
		world.setBlock(i + 6, j + 37, k + 8, NovaCraftBlocks.basal_bricks, 0, 2);
		world.setBlock(i + 7, j + 37, k + 8, NovaCraftBlocks.basal_bricks, 0, 2);
		world.setBlock(i + 8, j + 37, k + 8, NovaCraftBlocks.basal_bricks, 0, 2);
		world.setBlock(i + 9, j + 37, k + 8, NovaCraftBlocks.basal_bricks, 0, 2);
		world.setBlock(i + 10, j + 37, k + 8, NovaCraftBlocks.basal_bricks, 0, 2);
		world.setBlock(i + 11, j + 37, k + 8, NovaCraftBlocks.cracked_basal_bricks, 0, 2);
		world.setBlock(i + 12, j + 37, k + 8, NovaCraftBlocks.basal_bricks, 0, 2);
		world.setBlock(i + 13, j + 37, k + 8, NovaCraftBlocks.basal_bricks, 0, 2);
		world.setBlock(i + 14, j + 37, k + 8, Blocks.air, 0, 2);
		world.setBlock(i + 15, j + 37, k + 8, NovaCraftBlocks.cracked_basal_bricks, 0, 2);
		world.setBlock(i + 16, j + 37, k + 8, NovaCraftBlocks.basal_bricks, 0, 2);
		world.setBlock(i + 17, j + 37, k + 8, NovaCraftBlocks.basal_bricks, 0, 2);
		world.setBlock(i + 18, j + 37, k + 8, Blocks.air, 0, 2);
		world.setBlock(i + 19, j + 37, k + 8, Blocks.air, 0, 2);
		world.setBlock(i + 20, j + 37, k + 8, NovaCraftBlocks.basal_bricks, 0, 2);
		world.setBlock(i + 21, j + 37, k + 8, NovaCraftBlocks.basal_bricks, 0, 2);
		world.setBlock(i + 22, j + 37, k + 8, Blocks.air, 0, 2);
		world.setBlock(i + 23, j + 37, k + 8, Blocks.air, 0, 2);
		world.setBlock(i + 24, j + 37, k + 8, NovaCraftBlocks.cracked_basal_bricks, 0, 2);
		world.setBlock(i + 25, j + 37, k + 8, NovaCraftBlocks.basal_bricks, 0, 2);
		world.setBlock(i + 26, j + 37, k + 8, NovaCraftBlocks.cracked_basal_bricks, 0, 2);
		world.setBlock(i + 27, j + 37, k + 8, Blocks.air, 0, 2);
		world.setBlock(i + 0, j + 37, k + 9, NovaCraftBlocks.cracked_basal_bricks, 0, 2);
		world.setBlock(i + 1, j + 37, k + 9, NovaCraftBlocks.basal_bricks, 0, 2);
		world.setBlock(i + 2, j + 37, k + 9, NovaCraftBlocks.basal_bricks, 0, 2);
		world.setBlock(i + 3, j + 37, k + 9, NovaCraftBlocks.basal_bricks, 0, 2);
		world.setBlock(i + 4, j + 37, k + 9, NovaCraftBlocks.basal_bricks, 0, 2);
		world.setBlock(i + 5, j + 37, k + 9, NovaCraftBlocks.cracked_basal_bricks, 0, 2);
		world.setBlock(i + 6, j + 37, k + 9, NovaCraftBlocks.cracked_basal_bricks, 0, 2);
		world.setBlock(i + 7, j + 37, k + 9, NovaCraftBlocks.cracked_basal_bricks, 0, 2);
		world.setBlock(i + 8, j + 37, k + 9, NovaCraftBlocks.basal_bricks, 0, 2);
		world.setBlock(i + 9, j + 37, k + 9, NovaCraftBlocks.basal_bricks, 0, 2);
		world.setBlock(i + 10, j + 37, k + 9, NovaCraftBlocks.cracked_basal_bricks, 0, 2);
		world.setBlock(i + 11, j + 37, k + 9, NovaCraftBlocks.basal_bricks, 0, 2);
		world.setBlock(i + 12, j + 37, k + 9, NovaCraftBlocks.basal_bricks, 0, 2);
		world.setBlock(i + 13, j + 37, k + 9, NovaCraftBlocks.cracked_basal_bricks, 0, 2);
		world.setBlock(i + 14, j + 37, k + 9, NovaCraftBlocks.basal_bricks, 0, 2);
		world.setBlock(i + 15, j + 37, k + 9, NovaCraftBlocks.cracked_basal_bricks, 0, 2);
		world.setBlock(i + 16, j + 37, k + 9, NovaCraftBlocks.basal_bricks, 0, 2);
		world.setBlock(i + 17, j + 37, k + 9, NovaCraftBlocks.cracked_basal_bricks, 0, 2);
		world.setBlock(i + 18, j + 37, k + 9, NovaCraftBlocks.basal_brick_stairs, 2, 2);
		world.setBlock(i + 19, j + 37, k + 9, NovaCraftBlocks.basal_brick_stairs, 2, 2);
		world.setBlock(i + 20, j + 37, k + 9, NovaCraftBlocks.cracked_basal_bricks, 0, 2);
		world.setBlock(i + 21, j + 37, k + 9, NovaCraftBlocks.cracked_basal_bricks, 0, 2);
		world.setBlock(i + 22, j + 37, k + 9, NovaCraftBlocks.basal_brick_stairs, 2, 2);
		world.setBlock(i + 23, j + 37, k + 9, NovaCraftBlocks.basal_brick_stairs, 2, 2);
		world.setBlock(i + 24, j + 37, k + 9, NovaCraftBlocks.basal_bricks, 0, 2);
		world.setBlock(i + 25, j + 37, k + 9, NovaCraftBlocks.cracked_basal_bricks, 0, 2);
		world.setBlock(i + 26, j + 37, k + 9, NovaCraftBlocks.basal_bricks, 0, 2);
		world.setBlock(i + 27, j + 37, k + 9, NovaCraftBlocks.cracked_basal_bricks, 0, 2);
		world.setBlock(i + 0, j + 37, k + 10, NovaCraftBlocks.basal_bricks, 0, 2);
		world.setBlock(i + 1, j + 37, k + 10, NovaCraftBlocks.basal_bricks, 0, 2);
		world.setBlock(i + 2, j + 37, k + 10, NovaCraftBlocks.basal, 0, 2);
		world.setBlock(i + 3, j + 37, k + 10, NovaCraftBlocks.basal_scrap, 0, 2);
		world.setBlock(i + 4, j + 37, k + 10, NovaCraftBlocks.basal_scrap, 0, 2);
		world.setBlock(i + 5, j + 37, k + 10, NovaCraftBlocks.basal_scrap, 0, 2);
		world.setBlock(i + 6, j + 37, k + 10, NovaCraftBlocks.cracked_basal_bricks, 0, 2);
		world.setBlock(i + 7, j + 37, k + 10, NovaCraftBlocks.basal_bricks, 0, 2);
		world.setBlock(i + 8, j + 37, k + 10, NovaCraftBlocks.cracked_basal_bricks, 0, 2);
		world.setBlock(i + 9, j + 37, k + 10, NovaCraftBlocks.basal_scrap, 0, 2);
		world.setBlock(i + 10, j + 37, k + 10, NovaCraftBlocks.basal_scrap, 0, 2);
		world.setBlock(i + 11, j + 37, k + 10, NovaCraftBlocks.basal_scrap, 0, 2);
		world.setBlock(i + 12, j + 37, k + 10, NovaCraftBlocks.basal_scrap, 0, 2);
		world.setBlock(i + 13, j + 37, k + 10, NovaCraftBlocks.basal_bricks, 0, 2);
		world.setBlock(i + 14, j + 37, k + 10, NovaCraftBlocks.basal_bricks, 0, 2);
		world.setBlock(i + 15, j + 37, k + 10, NovaCraftBlocks.basal_bricks, 0, 2);
		world.setBlock(i + 16, j + 37, k + 10, NovaCraftBlocks.basal_bricks, 0, 2);
		world.setBlock(i + 17, j + 37, k + 10, NovaCraftBlocks.cracked_basal_bricks, 0, 2);
		world.setBlock(i + 18, j + 37, k + 10, NovaCraftBlocks.basal_bricks, 0, 2);
		world.setBlock(i + 19, j + 37, k + 10, NovaCraftBlocks.basal_bricks, 0, 2);
		world.setBlock(i + 20, j + 37, k + 10, NovaCraftBlocks.basal_bricks, 0, 2);
		world.setBlock(i + 21, j + 37, k + 10, NovaCraftBlocks.cracked_basal_bricks, 0, 2);
		world.setBlock(i + 22, j + 37, k + 10, NovaCraftBlocks.basal_bricks, 0, 2);
		world.setBlock(i + 23, j + 37, k + 10, NovaCraftBlocks.basal_bricks, 0, 2);
		world.setBlock(i + 24, j + 37, k + 10, NovaCraftBlocks.basal_bricks, 0, 2);
		world.setBlock(i + 25, j + 37, k + 10, NovaCraftBlocks.cracked_basal_bricks, 0, 2);
		world.setBlock(i + 26, j + 37, k + 10, NovaCraftBlocks.basal_bricks, 0, 2);
		world.setBlock(i + 27, j + 37, k + 10, NovaCraftBlocks.cracked_basal_bricks, 0, 2);
		world.setBlock(i + 0, j + 37, k + 11, Blocks.air, 0, 2);
		world.setBlock(i + 1, j + 37, k + 11, Blocks.air, 0, 2);
		world.setBlock(i + 2, j + 37, k + 11, Blocks.air, 0, 2);
		world.setBlock(i + 3, j + 37, k + 11, Blocks.air, 0, 2);
		world.setBlock(i + 4, j + 37, k + 11, Blocks.air, 0, 2);
		world.setBlock(i + 5, j + 37, k + 11, Blocks.air, 0, 2);
		world.setBlock(i + 6, j + 37, k + 11, Blocks.air, 0, 2);
		world.setBlock(i + 7, j + 37, k + 11, Blocks.air, 0, 2);
		world.setBlock(i + 8, j + 37, k + 11, Blocks.air, 0, 2);
		world.setBlock(i + 9, j + 37, k + 11, Blocks.air, 0, 2);
		world.setBlock(i + 10, j + 37, k + 11, Blocks.air, 0, 2);
		world.setBlock(i + 11, j + 37, k + 11, Blocks.air, 0, 2);
		world.setBlock(i + 12, j + 37, k + 11, Blocks.air, 0, 2);
		world.setBlock(i + 13, j + 37, k + 11, Blocks.air, 0, 2);
		world.setBlock(i + 14, j + 37, k + 11, NovaCraftBlocks.cracked_basal_bricks, 0, 2);
		world.setBlock(i + 15, j + 37, k + 11, NovaCraftBlocks.cracked_basal_bricks, 0, 2);
		world.setBlock(i + 16, j + 37, k + 11, NovaCraftBlocks.cracked_basal_bricks, 0, 2);
		world.setBlock(i + 17, j + 37, k + 11, NovaCraftBlocks.basal_bricks, 0, 2);
		world.setBlock(i + 18, j + 37, k + 11, NovaCraftBlocks.cracked_basal_bricks, 0, 2);
		world.setBlock(i + 19, j + 37, k + 11, NovaCraftBlocks.basal_bricks, 0, 2);
		world.setBlock(i + 20, j + 37, k + 11, NovaCraftBlocks.cracked_basal_bricks, 0, 2);
		world.setBlock(i + 21, j + 37, k + 11, NovaCraftBlocks.basal_bricks, 0, 2);
		world.setBlock(i + 22, j + 37, k + 11, NovaCraftBlocks.basal_bricks, 0, 2);
		world.setBlock(i + 23, j + 37, k + 11, NovaCraftBlocks.basal_bricks, 0, 2);
		world.setBlock(i + 24, j + 37, k + 11, NovaCraftBlocks.basal_bricks, 0, 2);
		world.setBlock(i + 25, j + 37, k + 11, NovaCraftBlocks.basal_bricks, 0, 2);
		world.setBlock(i + 26, j + 37, k + 11, NovaCraftBlocks.cracked_basal_bricks, 0, 2);
		world.setBlock(i + 27, j + 37, k + 11, NovaCraftBlocks.basal_bricks, 0, 2);
		world.setBlock(i + 0, j + 37, k + 12, Blocks.air, 0, 2);
		world.setBlock(i + 1, j + 37, k + 12, Blocks.air, 0, 2);
		world.setBlock(i + 2, j + 37, k + 12, Blocks.air, 0, 2);
		world.setBlock(i + 3, j + 37, k + 12, Blocks.air, 0, 2);
		world.setBlock(i + 4, j + 37, k + 12, Blocks.air, 0, 2);
		world.setBlock(i + 5, j + 37, k + 12, Blocks.air, 0, 2);
		world.setBlock(i + 6, j + 37, k + 12, Blocks.air, 0, 2);
		world.setBlock(i + 7, j + 37, k + 12, Blocks.air, 0, 2);
		world.setBlock(i + 8, j + 37, k + 12, Blocks.air, 0, 2);
		world.setBlock(i + 9, j + 37, k + 12, Blocks.air, 0, 2);
		world.setBlock(i + 10, j + 37, k + 12, Blocks.air, 0, 2);
		world.setBlock(i + 11, j + 37, k + 12, Blocks.air, 0, 2);
		world.setBlock(i + 12, j + 37, k + 12, Blocks.air, 0, 2);
		world.setBlock(i + 13, j + 37, k + 12, Blocks.air, 0, 2);
		world.setBlock(i + 14, j + 37, k + 12, NovaCraftBlocks.cracked_basal_bricks, 0, 2);
		world.setBlock(i + 15, j + 37, k + 12, NovaCraftBlocks.cracked_basal_bricks, 0, 2);
		world.setBlock(i + 16, j + 37, k + 12, NovaCraftBlocks.basal, 0, 2);
		world.setBlock(i + 17, j + 37, k + 12, NovaCraftBlocks.basal_scrap, 0, 2);
		world.setBlock(i + 18, j + 37, k + 12, NovaCraftBlocks.basal_scrap, 0, 2);
		world.setBlock(i + 19, j + 37, k + 12, NovaCraftBlocks.basal_scrap, 0, 2);
		world.setBlock(i + 20, j + 37, k + 12, NovaCraftBlocks.basal_bricks, 0, 2);
		world.setBlock(i + 21, j + 37, k + 12, NovaCraftBlocks.basal_bricks, 0, 2);
		world.setBlock(i + 22, j + 37, k + 12, NovaCraftBlocks.basal_bricks, 0, 2);
		world.setBlock(i + 23, j + 37, k + 12, NovaCraftBlocks.basal_scrap, 0, 2);
		world.setBlock(i + 24, j + 37, k + 12, NovaCraftBlocks.basal_scrap, 0, 2);
		world.setBlock(i + 25, j + 37, k + 12, NovaCraftBlocks.basal_scrap, 0, 2);
		world.setBlock(i + 26, j + 37, k + 12, NovaCraftBlocks.basal_scrap, 0, 2);
		world.setBlock(i + 27, j + 37, k + 12, NovaCraftBlocks.cracked_basal_bricks, 0, 2);
		world.setBlock(i + 0, j + 38, k + 2, NovaCraftBlocks.basal_bricks, 0, 2);
		world.setBlock(i + 1, j + 38, k + 2, NovaCraftBlocks.basal_bricks, 0, 2);
		world.setBlock(i + 4, j + 38, k + 2, NovaCraftBlocks.basal_bricks, 0, 2);
		world.setBlock(i + 5, j + 38, k + 2, NovaCraftBlocks.cracked_basal_bricks, 0, 2);
		world.setBlock(i + 8, j + 38, k + 2, NovaCraftBlocks.basal_bricks, 0, 2);
		world.setBlock(i + 9, j + 38, k + 2, NovaCraftBlocks.cracked_basal_bricks, 0, 2);
		world.setBlock(i + 12, j + 38, k + 2, NovaCraftBlocks.cracked_basal_bricks, 0, 2);
		world.setBlock(i + 13, j + 38, k + 2, NovaCraftBlocks.cracked_basal_bricks, 0, 2);
		world.setBlock(i + 0, j + 38, k + 3, NovaCraftBlocks.basal_bricks, 0, 2);
		world.setBlock(i + 1, j + 38, k + 3, NovaCraftBlocks.basal_bricks, 0, 2);
		world.setBlock(i + 4, j + 38, k + 3, NovaCraftBlocks.basal_bricks, 0, 2);
		world.setBlock(i + 5, j + 38, k + 3, NovaCraftBlocks.basal_bricks, 0, 2);
		world.setBlock(i + 8, j + 38, k + 3, NovaCraftBlocks.basal_bricks, 0, 2);
		world.setBlock(i + 9, j + 38, k + 3, NovaCraftBlocks.cracked_basal_bricks, 0, 2);
		world.setBlock(i + 12, j + 38, k + 3, NovaCraftBlocks.basal_bricks, 0, 2);
		world.setBlock(i + 13, j + 38, k + 3, NovaCraftBlocks.cracked_basal_bricks, 0, 2);
		world.setBlock(i + 0, j + 38, k + 4, NovaCraftBlocks.basal_bricks, 0, 2);
		world.setBlock(i + 1, j + 38, k + 4, NovaCraftBlocks.basal_bricks, 0, 2);
		world.setBlock(i + 2, j + 38, k + 4, Blocks.air, 0, 2);
		world.setBlock(i + 3, j + 38, k + 4, Blocks.air, 0, 2);
		world.setBlock(i + 4, j + 38, k + 4, NovaCraftBlocks.basal_bricks, 0, 2);
		world.setBlock(i + 5, j + 38, k + 4, NovaCraftBlocks.cracked_basal_bricks, 0, 2);
		world.setBlock(i + 6, j + 38, k + 4, Blocks.air, 0, 2);
		world.setBlock(i + 7, j + 38, k + 4, Blocks.air, 0, 2);
		world.setBlock(i + 8, j + 38, k + 4, NovaCraftBlocks.basal_bricks, 0, 2);
		world.setBlock(i + 9, j + 38, k + 4, NovaCraftBlocks.basal_bricks, 0, 2);
		world.setBlock(i + 10, j + 38, k + 4, Blocks.air, 0, 2);
		world.setBlock(i + 11, j + 38, k + 4, Blocks.air, 0, 2);
		world.setBlock(i + 12, j + 38, k + 4, NovaCraftBlocks.basal_bricks, 0, 2);
		world.setBlock(i + 13, j + 38, k + 4, NovaCraftBlocks.basal_bricks, 0, 2);
		world.setBlock(i + 14, j + 38, k + 4, NovaCraftBlocks.cracked_basal_bricks, 0, 2);
		world.setBlock(i + 15, j + 38, k + 4, NovaCraftBlocks.basal_bricks, 0, 2);
		world.setBlock(i + 16, j + 38, k + 4, Blocks.air, 0, 2);
		world.setBlock(i + 17, j + 38, k + 4, Blocks.air, 0, 2);
		world.setBlock(i + 18, j + 38, k + 4, NovaCraftBlocks.cracked_basal_bricks, 0, 2);
		world.setBlock(i + 19, j + 38, k + 4, NovaCraftBlocks.cracked_basal_bricks, 0, 2);
		world.setBlock(i + 20, j + 38, k + 4, Blocks.air, 0, 2);
		world.setBlock(i + 21, j + 38, k + 4, Blocks.air, 0, 2);
		world.setBlock(i + 22, j + 38, k + 4, NovaCraftBlocks.cracked_basal_bricks, 0, 2);
		world.setBlock(i + 23, j + 38, k + 4, NovaCraftBlocks.cracked_basal_bricks, 0, 2);
		world.setBlock(i + 24, j + 38, k + 4, Blocks.air, 0, 2);
		world.setBlock(i + 25, j + 38, k + 4, Blocks.air, 0, 2);
		world.setBlock(i + 26, j + 38, k + 4, NovaCraftBlocks.cracked_basal_bricks, 0, 2);
		world.setBlock(i + 27, j + 38, k + 4, NovaCraftBlocks.basal_bricks, 0, 2);
		world.setBlock(i + 0, j + 38, k + 5, NovaCraftBlocks.basal_bricks, 0, 2);
		world.setBlock(i + 1, j + 38, k + 5, NovaCraftBlocks.basal_bricks, 0, 2);
		world.setBlock(i + 2, j + 38, k + 5, NovaCraftBlocks.basal_bricks, 0, 2);
		world.setBlock(i + 3, j + 38, k + 5, NovaCraftBlocks.cracked_basal_bricks, 0, 2);
		world.setBlock(i + 4, j + 38, k + 5, Blocks.air, 0, 2);
		world.setBlock(i + 5, j + 38, k + 5, Blocks.air, 0, 2);
		world.setBlock(i + 6, j + 38, k + 5, NovaCraftBlocks.basal_brick_stairs, 6, 2);
		world.setBlock(i + 7, j + 38, k + 5, NovaCraftBlocks.basal_brick_stairs, 6, 2);
		world.setBlock(i + 8, j + 38, k + 5, Blocks.air, 0, 2);
		world.setBlock(i + 9, j + 38, k + 5, Blocks.air, 0, 2);
		world.setBlock(i + 10, j + 38, k + 5, NovaCraftBlocks.cracked_basal_bricks, 0, 2);
		world.setBlock(i + 11, j + 38, k + 5, NovaCraftBlocks.cracked_basal_bricks, 0, 2);
		world.setBlock(i + 12, j + 38, k + 5, NovaCraftBlocks.cracked_basal_bricks, 0, 2);
		world.setBlock(i + 13, j + 38, k + 5, NovaCraftBlocks.basal_bricks, 0, 2);
		world.setBlock(i + 14, j + 38, k + 5, NovaCraftBlocks.basal_bricks, 0, 2);
		world.setBlock(i + 15, j + 38, k + 5, NovaCraftBlocks.cracked_basal_bricks, 0, 2);
		world.setBlock(i + 16, j + 38, k + 5, Blocks.air, 0, 2);
		world.setBlock(i + 17, j + 38, k + 5, Blocks.air, 0, 2);
		world.setBlock(i + 18, j + 38, k + 5, NovaCraftBlocks.basal_bricks, 0, 2);
		world.setBlock(i + 19, j + 38, k + 5, NovaCraftBlocks.basal_bricks, 0, 2);
		world.setBlock(i + 20, j + 38, k + 5, Blocks.air, 0, 2);
		world.setBlock(i + 21, j + 38, k + 5, Blocks.air, 0, 2);
		world.setBlock(i + 22, j + 38, k + 5, NovaCraftBlocks.basal_bricks, 0, 2);
		world.setBlock(i + 23, j + 38, k + 5, NovaCraftBlocks.basal_bricks, 0, 2);
		world.setBlock(i + 24, j + 38, k + 5, Blocks.air, 0, 2);
		world.setBlock(i + 25, j + 38, k + 5, Blocks.air, 0, 2);
		world.setBlock(i + 26, j + 38, k + 5, NovaCraftBlocks.basal_bricks, 0, 2);
		world.setBlock(i + 27, j + 38, k + 5, NovaCraftBlocks.basal_bricks, 0, 2);
		world.setBlock(i + 0, j + 38, k + 6, NovaCraftBlocks.cracked_basal_bricks, 0, 2);
		world.setBlock(i + 1, j + 38, k + 6, NovaCraftBlocks.cracked_basal_bricks, 0, 2);
		world.setBlock(i + 2, j + 38, k + 6, NovaCraftBlocks.basal_bricks, 0, 2);
		world.setBlock(i + 3, j + 38, k + 6, NovaCraftBlocks.cracked_basal_bricks, 0, 2);
		world.setBlock(i + 4, j + 38, k + 6, Blocks.air, 0, 2);
		world.setBlock(i + 5, j + 38, k + 6, Blocks.air, 0, 2);
		world.setBlock(i + 6, j + 38, k + 6, NovaCraftBlocks.basal_bricks, 0, 2);
		world.setBlock(i + 7, j + 38, k + 6, NovaCraftBlocks.cracked_basal_bricks, 0, 2);
		world.setBlock(i + 8, j + 38, k + 6, Blocks.air, 0, 2);
		world.setBlock(i + 9, j + 38, k + 6, Blocks.air, 0, 2);
		world.setBlock(i + 10, j + 38, k + 6, NovaCraftBlocks.cracked_basal_bricks, 0, 2);
		world.setBlock(i + 11, j + 38, k + 6, NovaCraftBlocks.basal_bricks, 0, 2);
		world.setBlock(i + 12, j + 38, k + 6, NovaCraftBlocks.basal_bricks, 0, 2);
		world.setBlock(i + 13, j + 38, k + 6, NovaCraftBlocks.cracked_basal_bricks, 0, 2);
		world.setBlock(i + 14, j + 38, k + 6, NovaCraftBlocks.basal_bricks, 0, 2);
		world.setBlock(i + 15, j + 38, k + 6, NovaCraftBlocks.basal_bricks, 0, 2);
		world.setBlock(i + 16, j + 38, k + 6, Blocks.air, 0, 2);
		world.setBlock(i + 17, j + 38, k + 6, Blocks.air, 0, 2);
		world.setBlock(i + 18, j + 38, k + 6, NovaCraftBlocks.cracked_basal_bricks, 0, 2);
		world.setBlock(i + 19, j + 38, k + 6, NovaCraftBlocks.basal_bricks, 0, 2);
		world.setBlock(i + 20, j + 38, k + 6, Blocks.air, 0, 2);
		world.setBlock(i + 21, j + 38, k + 6, Blocks.air, 0, 2);
		world.setBlock(i + 22, j + 38, k + 6, NovaCraftBlocks.cracked_basal_bricks, 0, 2);
		world.setBlock(i + 23, j + 38, k + 6, NovaCraftBlocks.basal_bricks, 0, 2);
		world.setBlock(i + 24, j + 38, k + 6, Blocks.air, 0, 2);
		world.setBlock(i + 25, j + 38, k + 6, Blocks.air, 0, 2);
		world.setBlock(i + 26, j + 38, k + 6, NovaCraftBlocks.cracked_basal_bricks, 0, 2);
		world.setBlock(i + 27, j + 38, k + 6, NovaCraftBlocks.basal_bricks, 0, 2);
		world.setBlock(i + 0, j + 38, k + 7, NovaCraftBlocks.basal_bricks, 0, 2);
		world.setBlock(i + 1, j + 38, k + 7, NovaCraftBlocks.basal_bricks, 0, 2);
		world.setBlock(i + 2, j + 38, k + 7, NovaCraftBlocks.cracked_basal_bricks, 0, 2);
		world.setBlock(i + 3, j + 38, k + 7, NovaCraftBlocks.cracked_basal_bricks, 0, 2);
		world.setBlock(i + 4, j + 38, k + 7, Blocks.air, 0, 2);
		world.setBlock(i + 5, j + 38, k + 7, Blocks.air, 0, 2);
		world.setBlock(i + 6, j + 38, k + 7, NovaCraftBlocks.cracked_basal_bricks, 0, 2);
		world.setBlock(i + 7, j + 38, k + 7, NovaCraftBlocks.basal_bricks, 0, 2);
		world.setBlock(i + 8, j + 38, k + 7, Blocks.air, 0, 2);
		world.setBlock(i + 9, j + 38, k + 7, Blocks.air, 0, 2);
		world.setBlock(i + 10, j + 38, k + 7, NovaCraftBlocks.basal_bricks, 0, 2);
		world.setBlock(i + 11, j + 38, k + 7, NovaCraftBlocks.basal_bricks, 0, 2);
		world.setBlock(i + 12, j + 38, k + 7, NovaCraftBlocks.basal_bricks, 0, 2);
		world.setBlock(i + 13, j + 38, k + 7, NovaCraftBlocks.cracked_basal_bricks, 0, 2);
		world.setBlock(i + 14, j + 38, k + 7, NovaCraftBlocks.basal_bricks, 0, 2);
		world.setBlock(i + 15, j + 38, k + 7, NovaCraftBlocks.cracked_basal_bricks, 0, 2);
		world.setBlock(i + 16, j + 38, k + 7, NovaCraftBlocks.basal_bricks, 0, 2);
		world.setBlock(i + 17, j + 38, k + 7, NovaCraftBlocks.basal_bricks, 0, 2);
		world.setBlock(i + 18, j + 38, k + 7, Blocks.air, 0, 2);
		world.setBlock(i + 19, j + 38, k + 7, Blocks.air, 0, 2);
		world.setBlock(i + 20, j + 38, k + 7, NovaCraftBlocks.basal_bricks, 0, 2);
		world.setBlock(i + 21, j + 38, k + 7, NovaCraftBlocks.cracked_basal_bricks, 0, 2);
		world.setBlock(i + 22, j + 38, k + 7, Blocks.air, 0, 2);
		world.setBlock(i + 23, j + 38, k + 7, Blocks.air, 0, 2);
		world.setBlock(i + 24, j + 38, k + 7, NovaCraftBlocks.cracked_basal_bricks, 0, 2);
		world.setBlock(i + 25, j + 38, k + 7, NovaCraftBlocks.cracked_basal_bricks, 0, 2);
		world.setBlock(i + 26, j + 38, k + 7, NovaCraftBlocks.basal_bricks, 0, 2);
		world.setBlock(i + 27, j + 38, k + 7, NovaCraftBlocks.basal_bricks, 0, 2);
		world.setBlock(i + 0, j + 38, k + 8, NovaCraftBlocks.basal_bricks, 0, 2);
		world.setBlock(i + 1, j + 38, k + 8, NovaCraftBlocks.basal_bricks, 0, 2);
		world.setBlock(i + 2, j + 38, k + 8, NovaCraftBlocks.basal_bricks, 0, 2);
		world.setBlock(i + 3, j + 38, k + 8, NovaCraftBlocks.basal_bricks, 0, 2);
		world.setBlock(i + 4, j + 38, k + 8, Blocks.air, 0, 2);
		world.setBlock(i + 5, j + 38, k + 8, Blocks.air, 0, 2);
		world.setBlock(i + 6, j + 38, k + 8, NovaCraftBlocks.basal_brick_stairs, 0, 2);
		world.setBlock(i + 7, j + 38, k + 8, NovaCraftBlocks.basal_brick_stairs, 1, 2);
		world.setBlock(i + 8, j + 38, k + 8, Blocks.air, 0, 2);
		world.setBlock(i + 9, j + 38, k + 8, Blocks.air, 0, 2);
		world.setBlock(i + 10, j + 38, k + 8, NovaCraftBlocks.basal_bricks, 0, 2);
		world.setBlock(i + 11, j + 38, k + 8, NovaCraftBlocks.cracked_basal_bricks, 0, 2);
		world.setBlock(i + 12, j + 38, k + 8, NovaCraftBlocks.basal_bricks, 0, 2);
		world.setBlock(i + 13, j + 38, k + 8, NovaCraftBlocks.cracked_basal_bricks, 0, 2);
		world.setBlock(i + 14, j + 38, k + 8, NovaCraftBlocks.basal_bricks, 0, 2);
		world.setBlock(i + 15, j + 38, k + 8, NovaCraftBlocks.cracked_basal_bricks, 0, 2);
		world.setBlock(i + 16, j + 38, k + 8, NovaCraftBlocks.basal_bricks, 0, 2);
		world.setBlock(i + 17, j + 38, k + 8, NovaCraftBlocks.cracked_basal_bricks, 0, 2);
		world.setBlock(i + 18, j + 38, k + 8, Blocks.air, 0, 2);
		world.setBlock(i + 19, j + 38, k + 8, Blocks.air, 0, 2);
		world.setBlock(i + 20, j + 38, k + 8, NovaCraftBlocks.basal_bricks, 0, 2);
		world.setBlock(i + 21, j + 38, k + 8, NovaCraftBlocks.basal_bricks, 0, 2);
		world.setBlock(i + 22, j + 38, k + 8, Blocks.air, 0, 2);
		world.setBlock(i + 23, j + 38, k + 8, Blocks.air, 0, 2);
		world.setBlock(i + 24, j + 38, k + 8, NovaCraftBlocks.basal_bricks, 0, 2);
		world.setBlock(i + 25, j + 38, k + 8, NovaCraftBlocks.basal_bricks, 0, 2);
		world.setBlock(i + 26, j + 38, k + 8, NovaCraftBlocks.basal_bricks, 0, 2);
		world.setBlock(i + 27, j + 38, k + 8, NovaCraftBlocks.basal_bricks, 0, 2);
		world.setBlock(i + 0, j + 38, k + 9, NovaCraftBlocks.basal_bricks, 0, 2);
		world.setBlock(i + 1, j + 38, k + 9, NovaCraftBlocks.basal_bricks, 0, 2);
		world.setBlock(i + 2, j + 38, k + 9, NovaCraftBlocks.basal_bricks, 0, 2);
		world.setBlock(i + 3, j + 38, k + 9, NovaCraftBlocks.cracked_basal_bricks, 0, 2);
		world.setBlock(i + 4, j + 38, k + 9, NovaCraftBlocks.basal_bricks, 0, 2);
		world.setBlock(i + 5, j + 38, k + 9, NovaCraftBlocks.cracked_basal_bricks, 0, 2);
		world.setBlock(i + 6, j + 38, k + 9, NovaCraftBlocks.cracked_basal_bricks, 0, 2);
		world.setBlock(i + 7, j + 38, k + 9, NovaCraftBlocks.basal_scrap, 0, 2);
		world.setBlock(i + 8, j + 38, k + 9, NovaCraftBlocks.cracked_basal_bricks, 0, 2);
		world.setBlock(i + 9, j + 38, k + 9, NovaCraftBlocks.cracked_basal_bricks, 0, 2);
		world.setBlock(i + 10, j + 38, k + 9, NovaCraftBlocks.basal_bricks, 0, 2);
		world.setBlock(i + 11, j + 38, k + 9, NovaCraftBlocks.basal_bricks, 0, 2);
		world.setBlock(i + 12, j + 38, k + 9, NovaCraftBlocks.cracked_basal_bricks, 0, 2);
		world.setBlock(i + 13, j + 38, k + 9, NovaCraftBlocks.basal_bricks, 0, 2);
		world.setBlock(i + 14, j + 38, k + 9, NovaCraftBlocks.basal_bricks, 0, 2);
		world.setBlock(i + 15, j + 38, k + 9, NovaCraftBlocks.basal_bricks, 0, 2);
		world.setBlock(i + 16, j + 38, k + 9, NovaCraftBlocks.basal_bricks, 0, 2);
		world.setBlock(i + 17, j + 38, k + 9, NovaCraftBlocks.basal_bricks, 0, 2);
		world.setBlock(i + 18, j + 38, k + 9, Blocks.air, 0, 2);
		world.setBlock(i + 19, j + 38, k + 9, Blocks.air, 0, 2);
		world.setBlock(i + 20, j + 38, k + 9, NovaCraftBlocks.cracked_basal_bricks, 0, 2);
		world.setBlock(i + 21, j + 38, k + 9, NovaCraftBlocks.basal_bricks, 0, 2);
		world.setBlock(i + 22, j + 38, k + 9, Blocks.air, 0, 2);
		world.setBlock(i + 23, j + 38, k + 9, Blocks.air, 0, 2);
		world.setBlock(i + 24, j + 38, k + 9, NovaCraftBlocks.cracked_basal_bricks, 0, 2);
		world.setBlock(i + 25, j + 38, k + 9, NovaCraftBlocks.basal_bricks, 0, 2);
		world.setBlock(i + 26, j + 38, k + 9, NovaCraftBlocks.basal_bricks, 0, 2);
		world.setBlock(i + 27, j + 38, k + 9, NovaCraftBlocks.basal_bricks, 0, 2);
		world.setBlock(i + 0, j + 38, k + 10, NovaCraftBlocks.basal_bricks, 0, 2);
		world.setBlock(i + 1, j + 38, k + 10, NovaCraftBlocks.basal, 0, 2);
		world.setBlock(i + 2, j + 38, k + 10, Blocks.air, 0, 2);
		world.setBlock(i + 3, j + 38, k + 10, NovaCraftBlocks.basal_scrap, 0, 2);
		world.setBlock(i + 4, j + 38, k + 10, NovaCraftBlocks.basal_scrap, 0, 2);
		world.setBlock(i + 5, j + 38, k + 10, NovaCraftBlocks.basal_scrap, 0, 2);
		world.setBlock(i + 6, j + 38, k + 10, NovaCraftBlocks.basal_scrap, 0, 2);
		world.setBlock(i + 7, j + 38, k + 10, NovaCraftBlocks.basal_scrap, 0, 2);
		world.setBlock(i + 8, j + 38, k + 10, NovaCraftBlocks.basal_scrap, 0, 2);
		world.setBlock(i + 9, j + 38, k + 10, NovaCraftBlocks.basal_scrap, 0, 2);
		world.setBlock(i + 10, j + 38, k + 10, NovaCraftBlocks.basal_scrap, 0, 2);
		world.setBlock(i + 11, j + 38, k + 10, NovaCraftBlocks.basal_scrap, 0, 2);
		world.setBlock(i + 12, j + 38, k + 10, NovaCraftBlocks.basal_scrap, 0, 2);
		world.setBlock(i + 13, j + 38, k + 10, NovaCraftBlocks.basal_bricks, 0, 2);
		world.setBlock(i + 14, j + 38, k + 10, NovaCraftBlocks.cracked_basal_bricks, 0, 2);
		world.setBlock(i + 15, j + 38, k + 10, NovaCraftBlocks.basal_bricks, 0, 2);
		world.setBlock(i + 16, j + 38, k + 10, NovaCraftBlocks.cracked_basal_bricks, 0, 2);
		world.setBlock(i + 17, j + 38, k + 10, NovaCraftBlocks.basal_bricks, 0, 2);
		world.setBlock(i + 18, j + 38, k + 10, Blocks.air, 0, 2);
		world.setBlock(i + 19, j + 38, k + 10, Blocks.air, 0, 2);
		world.setBlock(i + 20, j + 38, k + 10, NovaCraftBlocks.basal_brick_stairs, 0, 2);
		world.setBlock(i + 21, j + 38, k + 10, NovaCraftBlocks.basal_brick_stairs, 1, 2);
		world.setBlock(i + 22, j + 38, k + 10, Blocks.air, 0, 2);
		world.setBlock(i + 23, j + 38, k + 10, Blocks.air, 0, 2);
		world.setBlock(i + 24, j + 38, k + 10, NovaCraftBlocks.basal_bricks, 0, 2);
		world.setBlock(i + 25, j + 38, k + 10, NovaCraftBlocks.basal_bricks, 0, 2);
		world.setBlock(i + 26, j + 38, k + 10, NovaCraftBlocks.basal_bricks, 0, 2);
		world.setBlock(i + 27, j + 38, k + 10, NovaCraftBlocks.basal_bricks, 0, 2);
		world.setBlock(i + 0, j + 38, k + 11, Blocks.air, 0, 2);
		world.setBlock(i + 1, j + 38, k + 11, Blocks.air, 0, 2);
		world.setBlock(i + 2, j + 38, k + 11, Blocks.air, 0, 2);
		world.setBlock(i + 3, j + 38, k + 11, Blocks.air, 0, 2);
		world.setBlock(i + 4, j + 38, k + 11, Blocks.air, 0, 2);
		world.setBlock(i + 5, j + 38, k + 11, Blocks.air, 0, 2);
		world.setBlock(i + 6, j + 38, k + 11, Blocks.air, 0, 2);
		world.setBlock(i + 7, j + 38, k + 11, Blocks.air, 0, 2);
		world.setBlock(i + 8, j + 38, k + 11, Blocks.air, 0, 2);
		world.setBlock(i + 9, j + 38, k + 11, Blocks.air, 0, 2);
		world.setBlock(i + 10, j + 38, k + 11, Blocks.air, 0, 2);
		world.setBlock(i + 11, j + 38, k + 11, Blocks.air, 0, 2);
		world.setBlock(i + 12, j + 38, k + 11, Blocks.air, 0, 2);
		world.setBlock(i + 13, j + 38, k + 11, Blocks.air, 0, 2);
		world.setBlock(i + 14, j + 38, k + 11, NovaCraftBlocks.cracked_basal_bricks, 0, 2);
		world.setBlock(i + 15, j + 38, k + 11, NovaCraftBlocks.basal_bricks, 0, 2);
		world.setBlock(i + 16, j + 38, k + 11, NovaCraftBlocks.cracked_basal_bricks, 0, 2);
		world.setBlock(i + 17, j + 38, k + 11, NovaCraftBlocks.cracked_basal_bricks, 0, 2);
		world.setBlock(i + 18, j + 38, k + 11, NovaCraftBlocks.basal_bricks, 0, 2);
		world.setBlock(i + 19, j + 38, k + 11, NovaCraftBlocks.cracked_basal_bricks, 0, 2);
		world.setBlock(i + 20, j + 38, k + 11, NovaCraftBlocks.cracked_basal_bricks, 0, 2);
		world.setBlock(i + 21, j + 38, k + 11, NovaCraftBlocks.basal_scrap, 0, 2);
		world.setBlock(i + 22, j + 38, k + 11, NovaCraftBlocks.basal_bricks, 0, 2);
		world.setBlock(i + 23, j + 38, k + 11, NovaCraftBlocks.cracked_basal_bricks, 0, 2);
		world.setBlock(i + 24, j + 38, k + 11, NovaCraftBlocks.cracked_basal_bricks, 0, 2);
		world.setBlock(i + 25, j + 38, k + 11, NovaCraftBlocks.basal_bricks, 0, 2);
		world.setBlock(i + 26, j + 38, k + 11, NovaCraftBlocks.basal_bricks, 0, 2);
		world.setBlock(i + 27, j + 38, k + 11, NovaCraftBlocks.basal_bricks, 0, 2);
		world.setBlock(i + 0, j + 38, k + 12, Blocks.air, 0, 2);
		world.setBlock(i + 1, j + 38, k + 12, Blocks.air, 0, 2);
		world.setBlock(i + 2, j + 38, k + 12, Blocks.air, 0, 2);
		world.setBlock(i + 3, j + 38, k + 12, Blocks.air, 0, 2);
		world.setBlock(i + 4, j + 38, k + 12, Blocks.air, 0, 2);
		world.setBlock(i + 5, j + 38, k + 12, Blocks.air, 0, 2);
		world.setBlock(i + 6, j + 38, k + 12, Blocks.air, 0, 2);
		world.setBlock(i + 7, j + 38, k + 12, Blocks.air, 0, 2);
		world.setBlock(i + 8, j + 38, k + 12, Blocks.air, 0, 2);
		world.setBlock(i + 9, j + 38, k + 12, Blocks.air, 0, 2);
		world.setBlock(i + 10, j + 38, k + 12, Blocks.air, 0, 2);
		world.setBlock(i + 11, j + 38, k + 12, Blocks.air, 0, 2);
		world.setBlock(i + 12, j + 38, k + 12, Blocks.air, 0, 2);
		world.setBlock(i + 13, j + 38, k + 12, Blocks.air, 0, 2);
		world.setBlock(i + 14, j + 38, k + 12, NovaCraftBlocks.cracked_basal_bricks, 0, 2);
		world.setBlock(i + 15, j + 38, k + 12, NovaCraftBlocks.basal, 0, 2);
		world.setBlock(i + 16, j + 38, k + 12, Blocks.air, 0, 2);
		world.setBlock(i + 17, j + 38, k + 12, Blocks.air, 0, 2);
		world.setBlock(i + 18, j + 38, k + 12, NovaCraftBlocks.basal_scrap, 0, 2);
		world.setBlock(i + 19, j + 38, k + 12, NovaCraftBlocks.basal_scrap, 0, 2);
		world.setBlock(i + 20, j + 38, k + 12, NovaCraftBlocks.basal_scrap, 0, 2);
		world.setBlock(i + 21, j + 38, k + 12, NovaCraftBlocks.basal_scrap, 0, 2);
		world.setBlock(i + 22, j + 38, k + 12, NovaCraftBlocks.basal_scrap, 0, 2);
		world.setBlock(i + 23, j + 38, k + 12, NovaCraftBlocks.basal_scrap, 0, 2);
		world.setBlock(i + 24, j + 38, k + 12, NovaCraftBlocks.basal_scrap, 0, 2);
		world.setBlock(i + 25, j + 38, k + 12, NovaCraftBlocks.basal_scrap, 0, 2);
		world.setBlock(i + 26, j + 38, k + 12, NovaCraftBlocks.basal_scrap, 0, 2);
		world.setBlock(i + 27, j + 38, k + 12, NovaCraftBlocks.cracked_basal_bricks, 0, 2);
		world.setBlock(i + 0, j + 39, k + 1, NovaCraftBlocks.basal_bricks, 0, 2);
		world.setBlock(i + 1, j + 39, k + 1, NovaCraftBlocks.basal_bricks, 0, 2);
		world.setBlock(i + 4, j + 39, k + 1, NovaCraftBlocks.basal_bricks, 0, 2);
		world.setBlock(i + 5, j + 39, k + 1, NovaCraftBlocks.basal_bricks, 0, 2);
		world.setBlock(i + 8, j + 39, k + 1, NovaCraftBlocks.basal_bricks, 0, 2);
