package com.NovaCraft.world.bastion.treasure;

import net.minecraft.world.gen.feature.*;
import net.minecraft.block.*;
import net.minecraft.world.*;
import java.util.*;

import com.NovaCraft.config.Configs;
import com.NovaCraft.entity.EntitySavageSerpent;
import com.NovaCraft.registry.OtherModBlocks;
import com.NovaCraftBlocks.NovaCraftBlocks;

import cpw.mods.fml.common.Loader;
import net.minecraft.init.*;

public class BastionTreasureBridgeGen6 extends WorldGenerator
{
	public BastionTreasureBridgeGen6() {

	}
	
	public boolean generate(final World world, final Random random, final int i, final int j, final int k) {
		
		world.setBlock(i + 9, j + 25, k + 11, NovaCraftBlocks.cracked_basal_bricks, 0, 2);
		world.setBlock(i + 10, j + 25, k + 11, NovaCraftBlocks.cracked_basal_bricks, 0, 2);
		world.setBlock(i + 11, j + 25, k + 11, NovaCraftBlocks.cracked_basal_bricks, 0, 2);
		world.setBlock(i + 12, j + 25, k + 11, NovaCraftBlocks.cracked_basal_bricks, 0, 2);
		world.setBlock(i + 13, j + 25, k + 11, NovaCraftBlocks.cracked_basal_bricks, 0, 2);
		world.setBlock(i + 14, j + 25, k + 11, NovaCraftBlocks.cracked_basal_bricks, 0, 2);
		world.setBlock(i + 15, j + 25, k + 11, NovaCraftBlocks.cracked_basal_bricks, 0, 2);
		world.setBlock(i + 16, j + 25, k + 11, NovaCraftBlocks.basal_bricks, 0, 2);
		world.setBlock(i + 17, j + 25, k + 11, NovaCraftBlocks.basal_bricks, 0, 2);
		world.setBlock(i + 18, j + 25, k + 11, NovaCraftBlocks.cracked_basal_bricks, 0, 2);
		world.setBlock(i + 19, j + 25, k + 11, NovaCraftBlocks.basal_bricks, 0, 2);
		world.setBlock(i + 20, j + 25, k + 11, NovaCraftBlocks.cracked_basal_bricks, 0, 2);
		world.setBlock(i + 21, j + 25, k + 11, NovaCraftBlocks.basal_bricks, 0, 2);
		world.setBlock(i + 22, j + 25, k + 11, NovaCraftBlocks.basal_bricks, 0, 2);
		world.setBlock(i + 23, j + 25, k + 11, NovaCraftBlocks.cracked_basal_bricks, 0, 2);
		world.setBlock(i + 24, j + 25, k + 11, NovaCraftBlocks.cracked_basal_bricks, 0, 2);
		world.setBlock(i + 25, j + 25, k + 11, NovaCraftBlocks.cracked_basal_bricks, 0, 2);
		world.setBlock(i + 26, j + 25, k + 11, NovaCraftBlocks.basal_bricks, 0, 2);
		world.setBlock(i + 27, j + 25, k + 11, NovaCraftBlocks.cracked_basal_bricks, 0, 2);
		world.setBlock(i + 0, j + 25, k + 12, NovaCraftBlocks.basal_bricks, 0, 2);
		world.setBlock(i + 1, j + 25, k + 12, NovaCraftBlocks.basal_bricks, 0, 2);
		world.setBlock(i + 2, j + 25, k + 12, NovaCraftBlocks.basal_bricks, 0, 2);
		world.setBlock(i + 3, j + 25, k + 12, NovaCraftBlocks.basal_bricks, 0, 2);
		world.setBlock(i + 4, j + 25, k + 12, NovaCraftBlocks.basal_bricks, 0, 2);
		world.setBlock(i + 5, j + 25, k + 12, NovaCraftBlocks.basal_bricks, 0, 2);
		world.setBlock(i + 6, j + 25, k + 12, NovaCraftBlocks.basal_bricks, 0, 2);
		world.setBlock(i + 7, j + 25, k + 12, NovaCraftBlocks.basal_bricks, 0, 2);
		world.setBlock(i + 8, j + 25, k + 12, NovaCraftBlocks.basal_bricks, 0, 2);
		world.setBlock(i + 9, j + 25, k + 12, NovaCraftBlocks.cracked_basal_bricks, 0, 2);
		world.setBlock(i + 10, j + 25, k + 12, NovaCraftBlocks.cracked_basal_bricks, 0, 2);
		world.setBlock(i + 11, j + 25, k + 12, NovaCraftBlocks.basal_bricks, 0, 2);
		world.setBlock(i + 12, j + 25, k + 12, NovaCraftBlocks.cracked_basal_bricks, 0, 2);
		world.setBlock(i + 13, j + 25, k + 12, NovaCraftBlocks.cracked_basal_bricks, 0, 2);
		world.setBlock(i + 14, j + 25, k + 12, NovaCraftBlocks.basal_bricks, 0, 2);
		world.setBlock(i + 15, j + 25, k + 12, NovaCraftBlocks.cracked_basal_bricks, 0, 2);
		world.setBlock(i + 16, j + 25, k + 12, NovaCraftBlocks.basal_bricks, 0, 2);
		world.setBlock(i + 17, j + 25, k + 12, NovaCraftBlocks.cracked_basal_bricks, 0, 2);
		world.setBlock(i + 18, j + 25, k + 12, NovaCraftBlocks.cracked_basal_bricks, 0, 2);
		world.setBlock(i + 19, j + 25, k + 12, NovaCraftBlocks.cracked_basal_bricks, 0, 2);
		world.setBlock(i + 20, j + 25, k + 12, NovaCraftBlocks.basal_bricks, 0, 2);
		world.setBlock(i + 21, j + 25, k + 12, NovaCraftBlocks.basal_bricks, 0, 2);
		world.setBlock(i + 22, j + 25, k + 12, NovaCraftBlocks.basal_bricks, 0, 2);
		world.setBlock(i + 23, j + 25, k + 12, NovaCraftBlocks.basal_bricks, 0, 2);
		world.setBlock(i + 24, j + 25, k + 12, NovaCraftBlocks.basal_bricks, 0, 2);
		world.setBlock(i + 25, j + 25, k + 12, NovaCraftBlocks.cracked_basal_bricks, 0, 2);
		world.setBlock(i + 26, j + 25, k + 12, NovaCraftBlocks.basal_bricks, 0, 2);
		world.setBlock(i + 27, j + 25, k + 12, NovaCraftBlocks.cracked_basal_bricks, 0, 2);
		world.setBlock(i + 0, j + 25, k + 13, NovaCraftBlocks.basal_bricks, 0, 2);
		world.setBlock(i + 1, j + 25, k + 13, NovaCraftBlocks.basal_bricks, 0, 2);
		world.setBlock(i + 2, j + 25, k + 13, NovaCraftBlocks.basal_bricks, 0, 2);
		world.setBlock(i + 3, j + 25, k + 13, NovaCraftBlocks.cracked_basal_bricks, 0, 2);
		world.setBlock(i + 4, j + 25, k + 13, NovaCraftBlocks.cracked_basal_bricks, 0, 2);
		world.setBlock(i + 5, j + 25, k + 13, NovaCraftBlocks.cracked_basal_bricks, 0, 2);
		world.setBlock(i + 6, j + 25, k + 13, NovaCraftBlocks.basal_bricks, 0, 2);
		world.setBlock(i + 7, j + 25, k + 13, NovaCraftBlocks.cracked_basal_bricks, 0, 2);
		world.setBlock(i + 8, j + 25, k + 13, NovaCraftBlocks.basal_bricks, 0, 2);
		world.setBlock(i + 9, j + 25, k + 13, NovaCraftBlocks.basal_bricks, 0, 2);
		world.setBlock(i + 10, j + 25, k + 13, NovaCraftBlocks.basal_bricks, 0, 2);
		world.setBlock(i + 11, j + 25, k + 13, NovaCraftBlocks.basal_bricks, 0, 2);
		world.setBlock(i + 12, j + 25, k + 13, NovaCraftBlocks.cracked_basal_bricks, 0, 2);
		world.setBlock(i + 13, j + 25, k + 13, NovaCraftBlocks.basal_bricks, 0, 2);
		world.setBlock(i + 14, j + 25, k + 13, NovaCraftBlocks.cracked_basal_bricks, 0, 2);
		world.setBlock(i + 15, j + 25, k + 13, NovaCraftBlocks.basal_bricks, 0, 2);
		world.setBlock(i + 16, j + 25, k + 13, NovaCraftBlocks.cracked_basal_bricks, 0, 2);
		world.setBlock(i + 17, j + 25, k + 13, NovaCraftBlocks.cracked_basal_bricks, 0, 2);
		world.setBlock(i + 18, j + 25, k + 13, NovaCraftBlocks.cracked_basal_bricks, 0, 2);
		world.setBlock(i + 19, j + 25, k + 13, NovaCraftBlocks.basal_bricks, 0, 2);
		world.setBlock(i + 20, j + 25, k + 13, NovaCraftBlocks.basal_bricks, 0, 2);
		world.setBlock(i + 21, j + 25, k + 13, NovaCraftBlocks.cracked_basal_bricks, 0, 2);
		world.setBlock(i + 22, j + 25, k + 13, NovaCraftBlocks.cracked_basal_bricks, 0, 2);
		world.setBlock(i + 23, j + 25, k + 13, NovaCraftBlocks.basal_bricks, 0, 2);
		world.setBlock(i + 24, j + 25, k + 13, NovaCraftBlocks.basal_bricks, 0, 2);
		world.setBlock(i + 25, j + 25, k + 13, NovaCraftBlocks.basal_bricks, 0, 2);
		world.setBlock(i + 26, j + 25, k + 13, NovaCraftBlocks.cracked_basal_bricks, 0, 2);
		world.setBlock(i + 27, j + 25, k + 13, NovaCraftBlocks.basal_bricks, 0, 2);
		world.setBlock(i + 0, j + 25, k + 14, NovaCraftBlocks.cracked_basal_bricks, 0, 2);
		world.setBlock(i + 1, j + 25, k + 14, NovaCraftBlocks.basal_bricks, 0, 2);
		world.setBlock(i + 2, j + 25, k + 14, NovaCraftBlocks.cracked_basal_bricks, 0, 2);
		world.setBlock(i + 3, j + 25, k + 14, NovaCraftBlocks.basal_bricks, 0, 2);
		world.setBlock(i + 4, j + 25, k + 14, NovaCraftBlocks.basal_bricks, 0, 2);
		world.setBlock(i + 5, j + 25, k + 14, NovaCraftBlocks.cracked_basal_bricks, 0, 2);
		world.setBlock(i + 6, j + 25, k + 14, NovaCraftBlocks.cracked_basal_bricks, 0, 2);
		world.setBlock(i + 7, j + 25, k + 14, NovaCraftBlocks.basal_bricks, 0, 2);
		world.setBlock(i + 8, j + 25, k + 14, NovaCraftBlocks.basal_bricks, 0, 2);
		world.setBlock(i + 9, j + 25, k + 14, NovaCraftBlocks.basal_bricks, 0, 2);
		world.setBlock(i + 10, j + 25, k + 14, NovaCraftBlocks.cracked_basal_bricks, 0, 2);
		world.setBlock(i + 11, j + 25, k + 14, NovaCraftBlocks.basal_bricks, 0, 2);
		world.setBlock(i + 12, j + 25, k + 14, NovaCraftBlocks.basal_bricks, 0, 2);
		world.setBlock(i + 13, j + 25, k + 14, NovaCraftBlocks.basal_bricks, 0, 2);
		world.setBlock(i + 14, j + 25, k + 14, NovaCraftBlocks.basal_bricks, 0, 2);
		world.setBlock(i + 15, j + 25, k + 14, NovaCraftBlocks.basal_bricks, 0, 2);
		world.setBlock(i + 16, j + 25, k + 14, NovaCraftBlocks.cracked_basal_bricks, 0, 2);
		world.setBlock(i + 17, j + 25, k + 14, NovaCraftBlocks.basal_bricks, 0, 2);
		world.setBlock(i + 18, j + 25, k + 14, NovaCraftBlocks.cracked_basal_bricks, 0, 2);
		world.setBlock(i + 19, j + 25, k + 14, NovaCraftBlocks.basal_bricks, 0, 2);
		world.setBlock(i + 20, j + 25, k + 14, NovaCraftBlocks.basal_bricks, 0, 2);
		world.setBlock(i + 21, j + 25, k + 14, NovaCraftBlocks.cracked_basal_bricks, 0, 2);
		world.setBlock(i + 22, j + 25, k + 14, NovaCraftBlocks.cracked_basal_bricks, 0, 2);
		world.setBlock(i + 23, j + 25, k + 14, NovaCraftBlocks.basal_bricks, 0, 2);
		world.setBlock(i + 24, j + 25, k + 14, NovaCraftBlocks.cracked_basal_bricks, 0, 2);
		world.setBlock(i + 25, j + 25, k + 14, NovaCraftBlocks.cracked_basal_bricks, 0, 2);
		world.setBlock(i + 26, j + 25, k + 14, NovaCraftBlocks.basal_bricks, 0, 2);
		world.setBlock(i + 27, j + 25, k + 14, NovaCraftBlocks.cracked_basal_bricks, 0, 2);
		world.setBlock(i + 0, j + 25, k + 15, NovaCraftBlocks.basal_bricks, 0, 2);
		world.setBlock(i + 1, j + 25, k + 15, NovaCraftBlocks.cracked_basal_bricks, 0, 2);
		world.setBlock(i + 2, j + 25, k + 15, NovaCraftBlocks.cracked_basal_bricks, 0, 2);
		world.setBlock(i + 3, j + 25, k + 15, NovaCraftBlocks.basal_bricks, 0, 2);
		world.setBlock(i + 4, j + 25, k + 15, NovaCraftBlocks.basal_bricks, 0, 2);
		world.setBlock(i + 5, j + 25, k + 15, NovaCraftBlocks.basal_bricks, 0, 2);
		world.setBlock(i + 6, j + 25, k + 15, NovaCraftBlocks.cracked_basal_bricks, 0, 2);
		world.setBlock(i + 7, j + 25, k + 15, NovaCraftBlocks.basal_bricks, 0, 2);
		world.setBlock(i + 8, j + 25, k + 15, NovaCraftBlocks.cracked_basal_bricks, 0, 2);
		world.setBlock(i + 9, j + 25, k + 15, NovaCraftBlocks.basal_bricks, 0, 2);
		world.setBlock(i + 10, j + 25, k + 15, NovaCraftBlocks.basal_bricks, 0, 2);
		world.setBlock(i + 11, j + 25, k + 15, NovaCraftBlocks.cracked_basal_bricks, 0, 2);
		world.setBlock(i + 12, j + 25, k + 15, NovaCraftBlocks.cracked_basal_bricks, 0, 2);
		world.setBlock(i + 13, j + 25, k + 15, Blocks.air, 0, 2);
		world.setBlock(i + 14, j + 25, k + 15, NovaCraftBlocks.basal_bricks, 0, 2);
		world.setBlock(i + 15, j + 25, k + 15, NovaCraftBlocks.basal_bricks, 0, 2);
		world.setBlock(i + 16, j + 25, k + 15, NovaCraftBlocks.cracked_basal_bricks, 0, 2);
		world.setBlock(i + 17, j + 25, k + 15, NovaCraftBlocks.cracked_basal_bricks, 0, 2);
		world.setBlock(i + 18, j + 25, k + 15, NovaCraftBlocks.basal_bricks, 0, 2);
		world.setBlock(i + 19, j + 25, k + 15, NovaCraftBlocks.basal_bricks, 0, 2);
		world.setBlock(i + 20, j + 25, k + 15, NovaCraftBlocks.basal_bricks, 0, 2);
		world.setBlock(i + 21, j + 25, k + 15, NovaCraftBlocks.basal_bricks, 0, 2);
		world.setBlock(i + 22, j + 25, k + 15, NovaCraftBlocks.basal_bricks, 0, 2);
		world.setBlock(i + 23, j + 25, k + 15, NovaCraftBlocks.cracked_basal_bricks, 0, 2);
		world.setBlock(i + 24, j + 25, k + 15, NovaCraftBlocks.basal_bricks, 0, 2);
		world.setBlock(i + 25, j + 25, k + 15, NovaCraftBlocks.basal_bricks, 0, 2);
		world.setBlock(i + 26, j + 25, k + 15, NovaCraftBlocks.basal_bricks, 0, 2);
		world.setBlock(i + 27, j + 25, k + 15, NovaCraftBlocks.cracked_basal_bricks, 0, 2);
		world.setBlock(i + 0, j + 25, k + 16, NovaCraftBlocks.basal_bricks, 0, 2);
		world.setBlock(i + 1, j + 25, k + 16, NovaCraftBlocks.basal_bricks, 0, 2);
		world.setBlock(i + 2, j + 25, k + 16, NovaCraftBlocks.basal_bricks, 0, 2);
		world.setBlock(i + 3, j + 25, k + 16, NovaCraftBlocks.cracked_basal_bricks, 0, 2);
		world.setBlock(i + 4, j + 25, k + 16, NovaCraftBlocks.cracked_basal_bricks, 0, 2);
		world.setBlock(i + 5, j + 25, k + 16, NovaCraftBlocks.basal_bricks, 0, 2);
		world.setBlock(i + 6, j + 25, k + 16, NovaCraftBlocks.cracked_basal_bricks, 0, 2);
		world.setBlock(i + 7, j + 25, k + 16, NovaCraftBlocks.basal_bricks, 0, 2);
		world.setBlock(i + 8, j + 25, k + 16, NovaCraftBlocks.cracked_basal_bricks, 0, 2);
		world.setBlock(i + 9, j + 25, k + 16, NovaCraftBlocks.basal_bricks, 0, 2);
		world.setBlock(i + 10, j + 25, k + 16, NovaCraftBlocks.basal_bricks, 0, 2);
		world.setBlock(i + 11, j + 25, k + 16, NovaCraftBlocks.cracked_basal_bricks, 0, 2);
		world.setBlock(i + 12, j + 25, k + 16, Blocks.air, 0, 2);
		world.setBlock(i + 13, j + 25, k + 16, Blocks.air, 0, 2);
		world.setBlock(i + 14, j + 25, k + 16, NovaCraftBlocks.basal_bricks, 0, 2);
		world.setBlock(i + 15, j + 25, k + 16, NovaCraftBlocks.basal_bricks, 0, 2);
		world.setBlock(i + 16, j + 25, k + 16, NovaCraftBlocks.cracked_basal_bricks, 0, 2);
		world.setBlock(i + 17, j + 25, k + 16, NovaCraftBlocks.basal_bricks, 0, 2);
		world.setBlock(i + 18, j + 25, k + 16, NovaCraftBlocks.cracked_basal_bricks, 0, 2);
		world.setBlock(i + 19, j + 25, k + 16, NovaCraftBlocks.cracked_basal_bricks, 0, 2);
		world.setBlock(i + 20, j + 25, k + 16, NovaCraftBlocks.cracked_basal_bricks, 0, 2);
		world.setBlock(i + 21, j + 25, k + 16, NovaCraftBlocks.basal_bricks, 0, 2);
		world.setBlock(i + 22, j + 25, k + 16, NovaCraftBlocks.basal_bricks, 0, 2);
		world.setBlock(i + 23, j + 25, k + 16, NovaCraftBlocks.basal_bricks, 0, 2);
		world.setBlock(i + 24, j + 25, k + 16, NovaCraftBlocks.basal_bricks, 0, 2);
		world.setBlock(i + 25, j + 25, k + 16, NovaCraftBlocks.basal_bricks, 0, 2);
		world.setBlock(i + 26, j + 25, k + 16, NovaCraftBlocks.cracked_basal_bricks, 0, 2);
		world.setBlock(i + 27, j + 25, k + 16, NovaCraftBlocks.basal_bricks, 0, 2);
		world.setBlock(i + 0, j + 25, k + 17, NovaCraftBlocks.cracked_basal_bricks, 0, 2);
		world.setBlock(i + 1, j + 25, k + 17, NovaCraftBlocks.basal_bricks, 0, 2);
		world.setBlock(i + 2, j + 25, k + 17, NovaCraftBlocks.basal_bricks, 0, 2);
		world.setBlock(i + 3, j + 25, k + 17, NovaCraftBlocks.basal_bricks, 0, 2);
		world.setBlock(i + 4, j + 25, k + 17, NovaCraftBlocks.basal_bricks, 0, 2);
		world.setBlock(i + 5, j + 25, k + 17, NovaCraftBlocks.basal_bricks, 0, 2);
		world.setBlock(i + 6, j + 25, k + 17, NovaCraftBlocks.cracked_basal_bricks, 0, 2);
		world.setBlock(i + 7, j + 25, k + 17, NovaCraftBlocks.basal_bricks, 0, 2);
		world.setBlock(i + 8, j + 25, k + 17, NovaCraftBlocks.cracked_basal_bricks, 0, 2);
		world.setBlock(i + 9, j + 25, k + 17, NovaCraftBlocks.cracked_basal_bricks, 0, 2);
		world.setBlock(i + 10, j + 25, k + 17, NovaCraftBlocks.cracked_basal_bricks, 0, 2);
		world.setBlock(i + 11, j + 25, k + 17, NovaCraftBlocks.cracked_basal_bricks, 0, 2);
		world.setBlock(i + 12, j + 25, k + 17, NovaCraftBlocks.basal_bricks, 0, 2);
		world.setBlock(i + 13, j + 25, k + 17, NovaCraftBlocks.basal_bricks, 0, 2);
		world.setBlock(i + 14, j + 25, k + 17, NovaCraftBlocks.cracked_basal_bricks, 0, 2);
		world.setBlock(i + 15, j + 25, k + 17, NovaCraftBlocks.cracked_basal_bricks, 0, 2);
		world.setBlock(i + 16, j + 25, k + 17, NovaCraftBlocks.cracked_basal_bricks, 0, 2);
		world.setBlock(i + 17, j + 25, k + 17, NovaCraftBlocks.basal_bricks, 0, 2);
		world.setBlock(i + 18, j + 25, k + 17, NovaCraftBlocks.basal_bricks, 0, 2);
		world.setBlock(i + 19, j + 25, k + 17, NovaCraftBlocks.basal_bricks, 0, 2);
		world.setBlock(i + 20, j + 25, k + 17, NovaCraftBlocks.basal_bricks, 0, 2);
		world.setBlock(i + 21, j + 25, k + 17, NovaCraftBlocks.basal_bricks, 0, 2);
		world.setBlock(i + 22, j + 25, k + 17, NovaCraftBlocks.cracked_basal_bricks, 0, 2);
		world.setBlock(i + 23, j + 25, k + 17, NovaCraftBlocks.cracked_basal_bricks, 0, 2);
		world.setBlock(i + 24, j + 25, k + 17, NovaCraftBlocks.cracked_basal_bricks, 0, 2);
		world.setBlock(i + 25, j + 25, k + 17, NovaCraftBlocks.basal_bricks, 0, 2);
		world.setBlock(i + 26, j + 25, k + 17, NovaCraftBlocks.cracked_basal_bricks, 0, 2);
		world.setBlock(i + 27, j + 25, k + 17, Blocks.air, 0, 2);
		world.setBlock(i + 0, j + 25, k + 18, NovaCraftBlocks.cracked_basal_bricks, 0, 2);
		world.setBlock(i + 1, j + 25, k + 18, NovaCraftBlocks.basal_bricks, 0, 2);
		world.setBlock(i + 2, j + 25, k + 18, NovaCraftBlocks.cracked_basal_bricks, 0, 2);
		world.setBlock(i + 3, j + 25, k + 18, NovaCraftBlocks.basal_bricks, 0, 2);
		world.setBlock(i + 4, j + 25, k + 18, NovaCraftBlocks.cracked_basal_bricks, 0, 2);
		world.setBlock(i + 5, j + 25, k + 18, NovaCraftBlocks.cracked_basal_bricks, 0, 2);
		world.setBlock(i + 6, j + 25, k + 18, NovaCraftBlocks.basal_bricks, 0, 2);
		world.setBlock(i + 7, j + 25, k + 18, NovaCraftBlocks.basal_bricks, 0, 2);
		world.setBlock(i + 8, j + 25, k + 18, NovaCraftBlocks.basal_bricks, 0, 2);
		world.setBlock(i + 9, j + 25, k + 18, NovaCraftBlocks.cracked_basal_bricks, 0, 2);
		world.setBlock(i + 10, j + 25, k + 18, NovaCraftBlocks.basal_bricks, 0, 2);
		world.setBlock(i + 11, j + 25, k + 18, NovaCraftBlocks.cracked_basal_bricks, 0, 2);
		world.setBlock(i + 12, j + 25, k + 18, NovaCraftBlocks.basal_bricks, 0, 2);
		world.setBlock(i + 13, j + 25, k + 18, NovaCraftBlocks.basal_bricks, 0, 2);
		world.setBlock(i + 14, j + 25, k + 18, NovaCraftBlocks.basal_bricks, 0, 2);
		world.setBlock(i + 15, j + 25, k + 18, NovaCraftBlocks.basal_bricks, 0, 2);
		world.setBlock(i + 16, j + 25, k + 18, NovaCraftBlocks.basal_bricks, 0, 2);
		world.setBlock(i + 17, j + 25, k + 18, NovaCraftBlocks.cracked_basal_bricks, 0, 2);
		world.setBlock(i + 18, j + 25, k + 18, NovaCraftBlocks.basal_bricks, 0, 2);
		world.setBlock(i + 19, j + 25, k + 18, NovaCraftBlocks.basal_bricks, 0, 2);
		world.setBlock(i + 20, j + 25, k + 18, NovaCraftBlocks.cracked_basal_bricks, 0, 2);
		world.setBlock(i + 21, j + 25, k + 18, NovaCraftBlocks.basal_bricks, 0, 2);
		world.setBlock(i + 22, j + 25, k + 18, NovaCraftBlocks.basal_bricks, 0, 2);
		world.setBlock(i + 23, j + 25, k + 18, NovaCraftBlocks.basal_bricks, 0, 2);
		world.setBlock(i + 24, j + 25, k + 18, NovaCraftBlocks.basal_bricks, 0, 2);
		world.setBlock(i + 25, j + 25, k + 18, NovaCraftBlocks.basal_bricks, 0, 2);
		world.setBlock(i + 26, j + 25, k + 18, Blocks.air, 0, 2);
		world.setBlock(i + 27, j + 25, k + 18, Blocks.air, 0, 2);
		world.setBlock(i + 0, j + 26, k + 0, Blocks.air, 0, 2);
		world.setBlock(i + 1, j + 26, k + 0, NovaCraftBlocks.basal_bricks, 0, 2);
		world.setBlock(i + 2, j + 26, k + 0, NovaCraftBlocks.cracked_basal_bricks, 0, 2);
		world.setBlock(i + 3, j + 26, k + 0, NovaCraftBlocks.basal_bricks, 0, 2);
		world.setBlock(i + 4, j + 26, k + 0, NovaCraftBlocks.cracked_basal_bricks, 0, 2);
		world.setBlock(i + 5, j + 26, k + 0, NovaCraftBlocks.cracked_basal_bricks, 0, 2);
		world.setBlock(i + 6, j + 26, k + 0, NovaCraftBlocks.cracked_basal_bricks, 0, 2);
		world.setBlock(i + 7, j + 26, k + 0, NovaCraftBlocks.cracked_basal_bricks, 0, 2);
		world.setBlock(i + 8, j + 26, k + 0, NovaCraftBlocks.basal_bricks, 0, 2);
		world.setBlock(i + 9, j + 26, k + 0, NovaCraftBlocks.cracked_basal_bricks, 0, 2);
		world.setBlock(i + 10, j + 26, k + 0, NovaCraftBlocks.basal_bricks, 0, 2);
		world.setBlock(i + 11, j + 26, k + 0, NovaCraftBlocks.basal_bricks, 0, 2);
		world.setBlock(i + 12, j + 26, k + 0, NovaCraftBlocks.basal_bricks, 0, 2);
		world.setBlock(i + 13, j + 26, k + 0, NovaCraftBlocks.cracked_basal_bricks, 0, 2);
		world.setBlock(i + 14, j + 26, k + 0, NovaCraftBlocks.cracked_basal_bricks, 0, 2);
		world.setBlock(i + 15, j + 26, k + 0, NovaCraftBlocks.cracked_basal_bricks, 0, 2);
		world.setBlock(i + 16, j + 26, k + 0, NovaCraftBlocks.basal_bricks, 0, 2);
		world.setBlock(i + 17, j + 26, k + 0, NovaCraftBlocks.cracked_basal_bricks, 0, 2);
		world.setBlock(i + 18, j + 26, k + 0, NovaCraftBlocks.basal_bricks, 0, 2);
		world.setBlock(i + 19, j + 26, k + 0, NovaCraftBlocks.cracked_basal_bricks, 0, 2);
		world.setBlock(i + 20, j + 26, k + 0, NovaCraftBlocks.basal_bricks, 0, 2);
		world.setBlock(i + 21, j + 26, k + 0, NovaCraftBlocks.basal_bricks, 0, 2);
		world.setBlock(i + 22, j + 26, k + 0, NovaCraftBlocks.basal_bricks, 0, 2);
		world.setBlock(i + 23, j + 26, k + 0, NovaCraftBlocks.basal_bricks, 0, 2);
		world.setBlock(i + 24, j + 26, k + 0, NovaCraftBlocks.cracked_basal_bricks, 0, 2);
		world.setBlock(i + 25, j + 26, k + 0, NovaCraftBlocks.basal_bricks, 0, 2);
		world.setBlock(i + 26, j + 26, k + 0, NovaCraftBlocks.cracked_basal_bricks, 0, 2);
		world.setBlock(i + 27, j + 26, k + 0, Blocks.air, 0, 2);
		world.setBlock(i + 0, j + 26, k + 1, NovaCraftBlocks.basal_bricks, 0, 2);
		world.setBlock(i + 1, j + 26, k + 1, NovaCraftBlocks.basal_bricks, 0, 2);
		world.setBlock(i + 2, j + 26, k + 1, NovaCraftBlocks.basal_bricks, 0, 2);
		world.setBlock(i + 3, j + 26, k + 1, NovaCraftBlocks.basal_bricks, 0, 2);
		world.setBlock(i + 4, j + 26, k + 1, NovaCraftBlocks.basal_bricks, 0, 2);
		world.setBlock(i + 5, j + 26, k + 1, NovaCraftBlocks.basal_bricks, 0, 2);
		world.setBlock(i + 6, j + 26, k + 1, NovaCraftBlocks.basal_bricks, 0, 2);
		world.setBlock(i + 7, j + 26, k + 1, NovaCraftBlocks.basal_bricks, 0, 2);
		world.setBlock(i + 8, j + 26, k + 1, NovaCraftBlocks.basal_bricks, 0, 2);
		world.setBlock(i + 9, j + 26, k + 1, NovaCraftBlocks.basal_bricks, 0, 2);
		world.setBlock(i + 10, j + 26, k + 1, NovaCraftBlocks.basal_bricks, 0, 2);
		world.setBlock(i + 11, j + 26, k + 1, NovaCraftBlocks.basal_bricks, 0, 2);
		world.setBlock(i + 12, j + 26, k + 1, NovaCraftBlocks.basal_bricks, 0, 2);
		world.setBlock(i + 13, j + 26, k + 1, NovaCraftBlocks.basal_bricks, 0, 2);
		world.setBlock(i + 14, j + 26, k + 1, NovaCraftBlocks.cracked_basal_bricks, 0, 2);
		world.setBlock(i + 15, j + 26, k + 1, NovaCraftBlocks.basal_bricks, 0, 2);
		world.setBlock(i + 16, j + 26, k + 1, NovaCraftBlocks.basal_bricks, 0, 2);
		world.setBlock(i + 17, j + 26, k + 1, NovaCraftBlocks.basal_bricks, 0, 2);
		world.setBlock(i + 18, j + 26, k + 1, NovaCraftBlocks.basal_bricks, 0, 2);
		world.setBlock(i + 19, j + 26, k + 1, NovaCraftBlocks.basal_bricks, 0, 2);
		world.setBlock(i + 20, j + 26, k + 1, NovaCraftBlocks.basal_bricks, 0, 2);
		world.setBlock(i + 21, j + 26, k + 1, NovaCraftBlocks.cracked_basal_bricks, 0, 2);
		world.setBlock(i + 22, j + 26, k + 1, NovaCraftBlocks.cracked_basal_bricks, 0, 2);
		world.setBlock(i + 23, j + 26, k + 1, NovaCraftBlocks.basal_bricks, 0, 2);
		world.setBlock(i + 24, j + 26, k + 1, NovaCraftBlocks.basal_bricks, 0, 2);
		world.setBlock(i + 25, j + 26, k + 1, NovaCraftBlocks.basal_bricks, 0, 2);
		world.setBlock(i + 26, j + 26, k + 1, NovaCraftBlocks.basal_bricks, 0, 2);
		world.setBlock(i + 27, j + 26, k + 1, Blocks.air, 0, 2);
		world.setBlock(i + 0, j + 26, k + 2, NovaCraftBlocks.basal_bricks, 0, 2);
		world.setBlock(i + 1, j + 26, k + 2, NovaCraftBlocks.basal_bricks, 0, 2);
		world.setBlock(i + 2, j + 26, k + 2, NovaCraftBlocks.basal_bricks, 0, 2);
		world.setBlock(i + 3, j + 26, k + 2, NovaCraftBlocks.basal_bricks, 0, 2);
		world.setBlock(i + 4, j + 26, k + 2, NovaCraftBlocks.basal_bricks, 0, 2);
		world.setBlock(i + 5, j + 26, k + 2, NovaCraftBlocks.basal_bricks, 0, 2);
		world.setBlock(i + 6, j + 26, k + 2, NovaCraftBlocks.cracked_basal_bricks, 0, 2);
		world.setBlock(i + 7, j + 26, k + 2, NovaCraftBlocks.basal_bricks, 0, 2);
		world.setBlock(i + 8, j + 26, k + 2, NovaCraftBlocks.basal_bricks, 0, 2);
		world.setBlock(i + 9, j + 26, k + 2, NovaCraftBlocks.basal_bricks, 0, 2);
		world.setBlock(i + 10, j + 26, k + 2, NovaCraftBlocks.cracked_basal_bricks, 0, 2);
		world.setBlock(i + 11, j + 26, k + 2, NovaCraftBlocks.basal_bricks, 0, 2);
		world.setBlock(i + 12, j + 26, k + 2, NovaCraftBlocks.cracked_basal_bricks, 0, 2);
		world.setBlock(i + 13, j + 26, k + 2, NovaCraftBlocks.basal_bricks, 0, 2);
		world.setBlock(i + 14, j + 26, k + 2, Blocks.air, 0, 2);
		world.setBlock(i + 15, j + 26, k + 2, NovaCraftBlocks.basal_bricks, 0, 2);
		world.setBlock(i + 16, j + 26, k + 2, NovaCraftBlocks.basal_bricks, 0, 2);
		world.setBlock(i + 17, j + 26, k + 2, NovaCraftBlocks.basal_bricks, 0, 2);
		world.setBlock(i + 18, j + 26, k + 2, NovaCraftBlocks.basal_bricks, 0, 2);
		world.setBlock(i + 19, j + 26, k + 2, NovaCraftBlocks.basal_bricks, 0, 2);
		world.setBlock(i + 20, j + 26, k + 2, NovaCraftBlocks.basal_bricks, 0, 2);
		world.setBlock(i + 21, j + 26, k + 2, NovaCraftBlocks.basal_bricks, 0, 2);
		world.setBlock(i + 22, j + 26, k + 2, NovaCraftBlocks.cracked_basal_bricks, 0, 2);
		world.setBlock(i + 23, j + 26, k + 2, NovaCraftBlocks.basal_bricks, 0, 2);
		world.setBlock(i + 24, j + 26, k + 2, NovaCraftBlocks.cracked_basal_bricks, 0, 2);
		world.setBlock(i + 25, j + 26, k + 2, NovaCraftBlocks.basal_bricks, 0, 2);
		world.setBlock(i + 26, j + 26, k + 2, NovaCraftBlocks.basal_bricks, 0, 2);
		world.setBlock(i + 27, j + 26, k + 2, NovaCraftBlocks.basal_bricks, 0, 2);
		world.setBlock(i + 0, j + 26, k + 3, NovaCraftBlocks.cracked_basal_bricks, 0, 2);
		world.setBlock(i + 1, j + 26, k + 3, NovaCraftBlocks.cracked_basal_bricks, 0, 2);
		world.setBlock(i + 2, j + 26, k + 3, NovaCraftBlocks.basal_bricks, 0, 2);
		world.setBlock(i + 3, j + 26, k + 3, NovaCraftBlocks.basal_bricks, 0, 2);
		world.setBlock(i + 4, j + 26, k + 3, NovaCraftBlocks.basal_bricks, 0, 2);
		world.setBlock(i + 5, j + 26, k + 3, NovaCraftBlocks.cracked_basal_bricks, 0, 2);
		world.setBlock(i + 6, j + 26, k + 3, NovaCraftBlocks.basal_bricks, 0, 2);
		world.setBlock(i + 7, j + 26, k + 3, NovaCraftBlocks.cracked_basal_bricks, 0, 2);
		world.setBlock(i + 8, j + 26, k + 3, NovaCraftBlocks.basal_bricks, 0, 2);
		world.setBlock(i + 9, j + 26, k + 3, NovaCraftBlocks.cracked_basal_bricks, 0, 2);
		world.setBlock(i + 10, j + 26, k + 3, NovaCraftBlocks.basal_bricks, 0, 2);
		world.setBlock(i + 11, j + 26, k + 3, NovaCraftBlocks.basal_bricks, 0, 2);
		world.setBlock(i + 12, j + 26, k + 3, NovaCraftBlocks.basal_bricks, 0, 2);
		world.setBlock(i + 13, j + 26, k + 3, NovaCraftBlocks.basal_bricks, 0, 2);
		world.setBlock(i + 14, j + 26, k + 3, NovaCraftBlocks.basal_bricks, 0, 2);
		world.setBlock(i + 15, j + 26, k + 3, NovaCraftBlocks.basal_bricks, 0, 2);
		world.setBlock(i + 16, j + 26, k + 3, NovaCraftBlocks.basal_bricks, 0, 2);
		world.setBlock(i + 17, j + 26, k + 3, NovaCraftBlocks.basal_bricks, 0, 2);
		world.setBlock(i + 18, j + 26, k + 3, NovaCraftBlocks.basal_bricks, 0, 2);
		world.setBlock(i + 19, j + 26, k + 3, NovaCraftBlocks.basal_bricks, 0, 2);
		world.setBlock(i + 20, j + 26, k + 3, NovaCraftBlocks.basal_bricks, 0, 2);
		world.setBlock(i + 21, j + 26, k + 3, NovaCraftBlocks.basal_bricks, 0, 2);
		world.setBlock(i + 22, j + 26, k + 3, NovaCraftBlocks.basal_bricks, 0, 2);
		world.setBlock(i + 23, j + 26, k + 3, NovaCraftBlocks.basal_bricks, 0, 2);
		world.setBlock(i + 24, j + 26, k + 3, NovaCraftBlocks.basal_bricks, 0, 2);
		world.setBlock(i + 25, j + 26, k + 3, NovaCraftBlocks.basal_bricks, 0, 2);
		world.setBlock(i + 26, j + 26, k + 3, NovaCraftBlocks.basal_bricks, 0, 2);
		world.setBlock(i + 27, j + 26, k + 3, NovaCraftBlocks.basal_bricks, 0, 2);
		world.setBlock(i + 0, j + 26, k + 4, NovaCraftBlocks.basal_bricks, 0, 2);
		world.setBlock(i + 1, j + 26, k + 4, NovaCraftBlocks.basal_bricks, 0, 2);
		world.setBlock(i + 2, j + 26, k + 4, NovaCraftBlocks.cracked_basal_bricks, 0, 2);
		world.setBlock(i + 3, j + 26, k + 4, NovaCraftBlocks.cracked_basal_bricks, 0, 2);
		world.setBlock(i + 4, j + 26, k + 4, NovaCraftBlocks.cracked_basal_bricks, 0, 2);
		world.setBlock(i + 5, j + 26, k + 4, NovaCraftBlocks.cracked_basal_bricks, 0, 2);
		world.setBlock(i + 6, j + 26, k + 4, NovaCraftBlocks.basal_bricks, 0, 2);
		world.setBlock(i + 7, j + 26, k + 4, NovaCraftBlocks.cracked_basal_bricks, 0, 2);
		world.setBlock(i + 8, j + 26, k + 4, NovaCraftBlocks.basal_bricks, 0, 2);
		world.setBlock(i + 9, j + 26, k + 4, NovaCraftBlocks.cracked_basal_bricks, 0, 2);
		world.setBlock(i + 10, j + 26, k + 4, NovaCraftBlocks.basal_bricks, 0, 2);
		world.setBlock(i + 11, j + 26, k + 4, NovaCraftBlocks.basal_bricks, 0, 2);
		world.setBlock(i + 12, j + 26, k + 4, NovaCraftBlocks.basal_bricks, 0, 2);
		world.setBlock(i + 13, j + 26, k + 4, NovaCraftBlocks.basal_bricks, 0, 2);
		world.setBlock(i + 14, j + 26, k + 4, NovaCraftBlocks.basal_bricks, 0, 2);
		world.setBlock(i + 15, j + 26, k + 4, NovaCraftBlocks.basal_bricks, 0, 2);
		world.setBlock(i + 16, j + 26, k + 4, NovaCraftBlocks.basal_bricks, 0, 2);
		world.setBlock(i + 17, j + 26, k + 4, NovaCraftBlocks.cracked_basal_bricks, 0, 2);
		world.setBlock(i + 18, j + 26, k + 4, NovaCraftBlocks.basal_bricks, 0, 2);
		world.setBlock(i + 19, j + 26, k + 4, NovaCraftBlocks.cracked_basal_bricks, 0, 2);
		world.setBlock(i + 20, j + 26, k + 4, NovaCraftBlocks.basal_bricks, 0, 2);
		world.setBlock(i + 21, j + 26, k + 4, NovaCraftBlocks.cracked_basal_bricks, 0, 2);
		world.setBlock(i + 22, j + 26, k + 4, NovaCraftBlocks.cracked_basal_bricks, 0, 2);
		world.setBlock(i + 23, j + 26, k + 4, NovaCraftBlocks.basal_bricks, 0, 2);
		world.setBlock(i + 24, j + 26, k + 4, NovaCraftBlocks.cracked_basal_bricks, 0, 2);
		world.setBlock(i + 25, j + 26, k + 4, NovaCraftBlocks.cracked_basal_bricks, 0, 2);
		world.setBlock(i + 26, j + 26, k + 4, NovaCraftBlocks.basal_bricks, 0, 2);
		world.setBlock(i + 27, j + 26, k + 4, NovaCraftBlocks.basal_bricks, 0, 2);
		world.setBlock(i + 0, j + 26, k + 5, NovaCraftBlocks.basal_bricks, 0, 2);
		world.setBlock(i + 1, j + 26, k + 5, NovaCraftBlocks.basal_bricks, 0, 2);
		world.setBlock(i + 2, j + 26, k + 5, NovaCraftBlocks.basal_bricks, 0, 2);
		world.setBlock(i + 3, j + 26, k + 5, NovaCraftBlocks.basal_bricks, 0, 2);
		world.setBlock(i + 4, j + 26, k + 5, NovaCraftBlocks.cracked_basal_bricks, 0, 2);
		world.setBlock(i + 5, j + 26, k + 5, NovaCraftBlocks.cracked_basal_bricks, 0, 2);
		world.setBlock(i + 6, j + 26, k + 5, NovaCraftBlocks.cracked_basal_bricks, 0, 2);
		world.setBlock(i + 7, j + 26, k + 5, NovaCraftBlocks.cracked_basal_bricks, 0, 2);
		world.setBlock(i + 8, j + 26, k + 5, NovaCraftBlocks.basal_bricks, 0, 2);
		world.setBlock(i + 9, j + 26, k + 5, NovaCraftBlocks.basal_bricks, 0, 2);
		world.setBlock(i + 10, j + 26, k + 5, NovaCraftBlocks.cracked_basal_bricks, 0, 2);
		world.setBlock(i + 11, j + 26, k + 5, NovaCraftBlocks.basal_bricks, 0, 2);
		world.setBlock(i + 12, j + 26, k + 5, NovaCraftBlocks.basal_bricks, 0, 2);
		world.setBlock(i + 13, j + 26, k + 5, NovaCraftBlocks.cracked_basal_bricks, 0, 2);
		world.setBlock(i + 14, j + 26, k + 5, NovaCraftBlocks.basal_bricks, 0, 2);
		world.setBlock(i + 15, j + 26, k + 5, NovaCraftBlocks.cracked_basal_bricks, 0, 2);
		world.setBlock(i + 16, j + 26, k + 5, NovaCraftBlocks.cracked_basal_bricks, 0, 2);
		world.setBlock(i + 17, j + 26, k + 5, NovaCraftBlocks.basal_bricks, 0, 2);
		world.setBlock(i + 18, j + 26, k + 5, NovaCraftBlocks.cracked_basal_bricks, 0, 2);
		world.setBlock(i + 19, j + 26, k + 5, NovaCraftBlocks.basal_bricks, 0, 2);
		world.setBlock(i + 20, j + 26, k + 5, NovaCraftBlocks.cracked_basal_bricks, 0, 2);
		world.setBlock(i + 21, j + 26, k + 5, NovaCraftBlocks.basal_bricks, 0, 2);
		world.setBlock(i + 22, j + 26, k + 5, NovaCraftBlocks.cracked_basal_bricks, 0, 2);
		world.setBlock(i + 23, j + 26, k + 5, NovaCraftBlocks.basal_bricks, 0, 2);
		world.setBlock(i + 24, j + 26, k + 5, NovaCraftBlocks.cracked_basal_bricks, 0, 2);
		world.setBlock(i + 25, j + 26, k + 5, NovaCraftBlocks.basal_bricks, 0, 2);
		world.setBlock(i + 26, j + 26, k + 5, NovaCraftBlocks.cracked_basal_bricks, 0, 2);
		world.setBlock(i + 27, j + 26, k + 5, NovaCraftBlocks.basal_bricks, 0, 2);
		world.setBlock(i + 0, j + 26, k + 6, NovaCraftBlocks.cracked_basal_bricks, 0, 2);
		world.setBlock(i + 1, j + 26, k + 6, NovaCraftBlocks.basal_bricks, 0, 2);
		world.setBlock(i + 2, j + 26, k + 6, NovaCraftBlocks.basal_bricks, 0, 2);
		world.setBlock(i + 3, j + 26, k + 6, NovaCraftBlocks.basal_bricks, 0, 2);
		world.setBlock(i + 4, j + 26, k + 6, NovaCraftBlocks.cracked_basal_bricks, 0, 2);
		world.setBlock(i + 5, j + 26, k + 6, NovaCraftBlocks.basal_bricks, 0, 2);
		world.setBlock(i + 6, j + 26, k + 6, NovaCraftBlocks.cracked_basal_bricks, 0, 2);
		world.setBlock(i + 7, j + 26, k + 6, NovaCraftBlocks.basal_bricks, 0, 2);
		world.setBlock(i + 8, j + 26, k + 6, NovaCraftBlocks.basal_bricks, 0, 2);
		world.setBlock(i + 9, j + 26, k + 6, NovaCraftBlocks.cracked_basal_bricks, 0, 2);
		world.setBlock(i + 10, j + 26, k + 6, NovaCraftBlocks.basal_bricks, 0, 2);
		world.setBlock(i + 11, j + 26, k + 6, NovaCraftBlocks.cracked_basal_bricks, 0, 2);
		world.setBlock(i + 12, j + 26, k + 6, NovaCraftBlocks.basal_bricks, 0, 2);
		world.setBlock(i + 13, j + 26, k + 6, NovaCraftBlocks.basal_bricks, 0, 2);
		world.setBlock(i + 14, j + 26, k + 6, NovaCraftBlocks.cracked_basal_bricks, 0, 2);
		world.setBlock(i + 15, j + 26, k + 6, NovaCraftBlocks.basal_bricks, 0, 2);
		world.setBlock(i + 16, j + 26, k + 6, NovaCraftBlocks.cracked_basal_bricks, 0, 2);
		world.setBlock(i + 17, j + 26, k + 6, NovaCraftBlocks.basal_bricks, 0, 2);
		world.setBlock(i + 18, j + 26, k + 6, NovaCraftBlocks.cracked_basal_bricks, 0, 2);
		world.setBlock(i + 19, j + 26, k + 6, NovaCraftBlocks.cracked_basal_bricks, 0, 2);
		world.setBlock(i + 20, j + 26, k + 6, NovaCraftBlocks.cracked_basal_bricks, 0, 2);
		world.setBlock(i + 21, j + 26, k + 6, NovaCraftBlocks.basal_bricks, 0, 2);
		world.setBlock(i + 22, j + 26, k + 6, NovaCraftBlocks.basal_bricks, 0, 2);
		world.setBlock(i + 23, j + 26, k + 6, NovaCraftBlocks.basal_bricks, 0, 2);
		world.setBlock(i + 24, j + 26, k + 6, NovaCraftBlocks.basal_bricks, 0, 2);
		world.setBlock(i + 25, j + 26, k + 6, NovaCraftBlocks.basal_bricks, 0, 2);
		world.setBlock(i + 26, j + 26, k + 6, NovaCraftBlocks.basal_bricks, 0, 2);
		world.setBlock(i + 27, j + 26, k + 6, NovaCraftBlocks.cracked_basal_bricks, 0, 2);
		world.setBlock(i + 0, j + 26, k + 7, NovaCraftBlocks.cracked_basal_bricks, 0, 2);
		world.setBlock(i + 1, j + 26, k + 7, NovaCraftBlocks.basal_bricks, 0, 2);
		world.setBlock(i + 2, j + 26, k + 7, NovaCraftBlocks.basal_bricks, 0, 2);
		world.setBlock(i + 3, j + 26, k + 7, NovaCraftBlocks.basal_bricks, 0, 2);
		world.setBlock(i + 4, j + 26, k + 7, NovaCraftBlocks.basal_bricks, 0, 2);
		world.setBlock(i + 5, j + 26, k + 7, NovaCraftBlocks.basal_bricks, 0, 2);
		world.setBlock(i + 6, j + 26, k + 7, NovaCraftBlocks.basal_bricks, 0, 2);
		world.setBlock(i + 7, j + 26, k + 7, NovaCraftBlocks.cracked_basal_bricks, 0, 2);
		world.setBlock(i + 8, j + 26, k + 7, NovaCraftBlocks.basal_bricks, 0, 2);
		world.setBlock(i + 9, j + 26, k + 7, NovaCraftBlocks.cracked_basal_bricks, 0, 2);
		world.setBlock(i + 10, j + 26, k + 7, NovaCraftBlocks.basal_bricks, 0, 2);
		world.setBlock(i + 11, j + 26, k + 7, NovaCraftBlocks.cracked_basal_bricks, 0, 2);
		world.setBlock(i + 12, j + 26, k + 7, NovaCraftBlocks.basal_bricks, 0, 2);
		world.setBlock(i + 13, j + 26, k + 7, NovaCraftBlocks.basal_bricks, 0, 2);
		world.setBlock(i + 14, j + 26, k + 7, NovaCraftBlocks.basal_bricks, 0, 2);
		world.setBlock(i + 15, j + 26, k + 7, NovaCraftBlocks.cracked_basal_bricks, 0, 2);
		world.setBlock(i + 16, j + 26, k + 7, NovaCraftBlocks.basal_bricks, 0, 2);
		world.setBlock(i + 17, j + 26, k + 7, NovaCraftBlocks.basal_bricks, 0, 2);
		world.setBlock(i + 18, j + 26, k + 7, NovaCraftBlocks.basal_bricks, 0, 2);
		world.setBlock(i + 19, j + 26, k + 7, NovaCraftBlocks.cracked_basal_bricks, 0, 2);
		world.setBlock(i + 20, j + 26, k + 7, NovaCraftBlocks.basal_bricks, 0, 2);
		world.setBlock(i + 21, j + 26, k + 7, NovaCraftBlocks.cracked_basal_bricks, 0, 2);
		world.setBlock(i + 22, j + 26, k + 7, NovaCraftBlocks.basal_bricks, 0, 2);
		world.setBlock(i + 23, j + 26, k + 7, NovaCraftBlocks.basal_bricks, 0, 2);
		world.setBlock(i + 24, j + 26, k + 7, NovaCraftBlocks.cracked_basal_bricks, 0, 2);
		world.setBlock(i + 25, j + 26, k + 7, NovaCraftBlocks.cracked_basal_bricks, 0, 2);
		world.setBlock(i + 26, j + 26, k + 7, NovaCraftBlocks.basal_bricks, 0, 2);
		world.setBlock(i + 27, j + 26, k + 7, NovaCraftBlocks.basal_bricks, 0, 2);
		world.setBlock(i + 0, j + 26, k + 8, NovaCraftBlocks.basal_bricks, 0, 2);
		world.setBlock(i + 1, j + 26, k + 8, NovaCraftBlocks.basal_bricks, 0, 2);
		world.setBlock(i + 2, j + 26, k + 8, NovaCraftBlocks.basal_bricks, 0, 2);
		world.setBlock(i + 3, j + 26, k + 8, NovaCraftBlocks.basal_bricks, 0, 2);
		world.setBlock(i + 4, j + 26, k + 8, NovaCraftBlocks.basal_bricks, 0, 2);
		world.setBlock(i + 5, j + 26, k + 8, NovaCraftBlocks.basal_bricks, 0, 2);
		world.setBlock(i + 6, j + 26, k + 8, NovaCraftBlocks.basal_bricks, 0, 2);
		world.setBlock(i + 7, j + 26, k + 8, NovaCraftBlocks.cracked_basal_bricks, 0, 2);
		world.setBlock(i + 8, j + 26, k + 8, NovaCraftBlocks.basal_bricks, 0, 2);
		world.setBlock(i + 9, j + 26, k + 8, NovaCraftBlocks.basal_bricks, 0, 2);
		world.setBlock(i + 10, j + 26, k + 8, NovaCraftBlocks.cracked_basal_bricks, 0, 2);
		world.setBlock(i + 11, j + 26, k + 8, NovaCraftBlocks.basal_bricks, 0, 2);
		world.setBlock(i + 12, j + 26, k + 8, NovaCraftBlocks.cracked_basal_bricks, 0, 2);
		world.setBlock(i + 13, j + 26, k + 8, NovaCraftBlocks.basal_bricks, 0, 2);
		world.setBlock(i + 14, j + 26, k + 8, NovaCraftBlocks.cracked_basal_bricks, 0, 2);
		world.setBlock(i + 15, j + 26, k + 8, NovaCraftBlocks.basal_bricks, 0, 2);
		world.setBlock(i + 16, j + 26, k + 8, NovaCraftBlocks.cracked_basal_bricks, 0, 2);
		world.setBlock(i + 17, j + 26, k + 8, NovaCraftBlocks.basal_bricks, 0, 2);
		world.setBlock(i + 18, j + 26, k + 8, NovaCraftBlocks.basal_bricks, 0, 2);
		world.setBlock(i + 19, j + 26, k + 8, NovaCraftBlocks.cracked_basal_bricks, 0, 2);
		world.setBlock(i + 20, j + 26, k + 8, NovaCraftBlocks.basal_bricks, 0, 2);
		world.setBlock(i + 21, j + 26, k + 8, NovaCraftBlocks.basal_bricks, 0, 2);
		world.setBlock(i + 22, j + 26, k + 8, NovaCraftBlocks.basal_bricks, 0, 2);
		world.setBlock(i + 23, j + 26, k + 8, NovaCraftBlocks.cracked_basal_bricks, 0, 2);
		world.setBlock(i + 24, j + 26, k + 8, NovaCraftBlocks.cracked_basal_bricks, 0, 2);
		world.setBlock(i + 25, j + 26, k + 8, NovaCraftBlocks.basal_bricks, 0, 2);
		world.setBlock(i + 26, j + 26, k + 8, NovaCraftBlocks.basal_bricks, 0, 2);
		world.setBlock(i + 27, j + 26, k + 8, NovaCraftBlocks.cracked_basal_bricks, 0, 2);
		world.setBlock(i + 0, j + 26, k + 9, NovaCraftBlocks.cracked_basal_bricks, 0, 2);
		world.setBlock(i + 1, j + 26, k + 9, NovaCraftBlocks.basal_bricks, 0, 2);
		world.setBlock(i + 2, j + 26, k + 9, NovaCraftBlocks.basal_bricks, 0, 2);
		world.setBlock(i + 3, j + 26, k + 9, NovaCraftBlocks.basal_bricks, 0, 2);
		world.setBlock(i + 4, j + 26, k + 9, NovaCraftBlocks.basal_bricks, 0, 2);
		world.setBlock(i + 5, j + 26, k + 9, NovaCraftBlocks.cracked_basal_bricks, 0, 2);
		world.setBlock(i + 6, j + 26, k + 9, NovaCraftBlocks.cracked_basal_bricks, 0, 2);
		world.setBlock(i + 7, j + 26, k + 9, NovaCraftBlocks.basal_bricks, 0, 2);
		world.setBlock(i + 8, j + 26, k + 9, NovaCraftBlocks.cracked_basal_bricks, 0, 2);
		world.setBlock(i + 9, j + 26, k + 9, NovaCraftBlocks.basal_bricks, 0, 2);
		world.setBlock(i + 10, j + 26, k + 9, NovaCraftBlocks.basal_bricks, 0, 2);
		world.setBlock(i + 11, j + 26, k + 9, NovaCraftBlocks.cracked_basal_bricks, 0, 2);
		world.setBlock(i + 12, j + 26, k + 9, NovaCraftBlocks.basal_bricks, 0, 2);
		world.setBlock(i + 13, j + 26, k + 9, NovaCraftBlocks.cracked_basal_bricks, 0, 2);
		world.setBlock(i + 14, j + 26, k + 9, NovaCraftBlocks.cracked_basal_bricks, 0, 2);
		world.setBlock(i + 15, j + 26, k + 9, NovaCraftBlocks.cracked_basal_bricks, 0, 2);
		world.setBlock(i + 16, j + 26, k + 9, NovaCraftBlocks.basal_bricks, 0, 2);
		world.setBlock(i + 17, j + 26, k + 9, NovaCraftBlocks.basal_bricks, 0, 2);
		world.setBlock(i + 18, j + 26, k + 9, NovaCraftBlocks.basal_bricks, 0, 2);
		world.setBlock(i + 19, j + 26, k + 9, NovaCraftBlocks.cracked_basal_bricks, 0, 2);
		world.setBlock(i + 20, j + 26, k + 9, NovaCraftBlocks.cracked_basal_bricks, 0, 2);
		world.setBlock(i + 21, j + 26, k + 9, NovaCraftBlocks.basal_bricks, 0, 2);
		world.setBlock(i + 22, j + 26, k + 9, NovaCraftBlocks.basal_bricks, 0, 2);
		world.setBlock(i + 23, j + 26, k + 9, NovaCraftBlocks.basal_bricks, 0, 2);
		world.setBlock(i + 24, j + 26, k + 9, NovaCraftBlocks.cracked_basal_bricks, 0, 2);
		world.setBlock(i + 25, j + 26, k + 9, NovaCraftBlocks.cracked_basal_bricks, 0, 2);
		world.setBlock(i + 26, j + 26, k + 9, NovaCraftBlocks.basal_bricks, 0, 2);
		world.setBlock(i + 27, j + 26, k + 9, NovaCraftBlocks.cracked_basal_bricks, 0, 2);
		world.setBlock(i + 0, j + 26, k + 10, NovaCraftBlocks.basal_bricks, 0, 2);
		world.setBlock(i + 1, j + 26, k + 10, NovaCraftBlocks.cracked_basal_bricks, 0, 2);
		world.setBlock(i + 2, j + 26, k + 10, NovaCraftBlocks.basal_bricks, 0, 2);
		world.setBlock(i + 3, j + 26, k + 10, NovaCraftBlocks.cracked_basal_bricks, 0, 2);
		world.setBlock(i + 4, j + 26, k + 10, NovaCraftBlocks.basal_bricks, 0, 2);
		world.setBlock(i + 5, j + 26, k + 10, NovaCraftBlocks.basal_bricks, 0, 2);
		world.setBlock(i + 6, j + 26, k + 10, NovaCraftBlocks.basal_bricks, 0, 2);
		world.setBlock(i + 7, j + 26, k + 10, NovaCraftBlocks.basal_bricks, 0, 2);
		world.setBlock(i + 8, j + 26, k + 10, NovaCraftBlocks.cracked_basal_bricks, 0, 2);
		world.setBlock(i + 9, j + 26, k + 10, NovaCraftBlocks.basal_bricks, 0, 2);
		world.setBlock(i + 10, j + 26, k + 10, NovaCraftBlocks.cracked_basal_bricks, 0, 2);
		world.setBlock(i + 11, j + 26, k + 10, NovaCraftBlocks.cracked_basal_bricks, 0, 2);
		world.setBlock(i + 12, j + 26, k + 10, NovaCraftBlocks.basal_bricks, 0, 2);
		world.setBlock(i + 13, j + 26, k + 10, NovaCraftBlocks.cracked_basal_bricks, 0, 2);
		world.setBlock(i + 14, j + 26, k + 10, NovaCraftBlocks.cracked_basal_bricks, 0, 2);
		world.setBlock(i + 15, j + 26, k + 10, NovaCraftBlocks.basal_bricks, 0, 2);
		world.setBlock(i + 16, j + 26, k + 10, NovaCraftBlocks.basal_bricks, 0, 2);
		world.setBlock(i + 17, j + 26, k + 10, NovaCraftBlocks.cracked_basal_bricks, 0, 2);
		world.setBlock(i + 18, j + 26, k + 10, NovaCraftBlocks.basal_bricks, 0, 2);
		world.setBlock(i + 19, j + 26, k + 10, NovaCraftBlocks.basal_bricks, 0, 2);
		world.setBlock(i + 20, j + 26, k + 10, NovaCraftBlocks.basal_bricks, 0, 2);
		world.setBlock(i + 21, j + 26, k + 10, NovaCraftBlocks.cracked_basal_bricks, 0, 2);
		world.setBlock(i + 22, j + 26, k + 10, NovaCraftBlocks.basal_bricks, 0, 2);
		world.setBlock(i + 23, j + 26, k + 10, NovaCraftBlocks.basal_bricks, 0, 2);
		world.setBlock(i + 24, j + 26, k + 10, NovaCraftBlocks.basal_bricks, 0, 2);
		world.setBlock(i + 25, j + 26, k + 10, NovaCraftBlocks.basal_bricks, 0, 2);
		world.setBlock(i + 26, j + 26, k + 10, NovaCraftBlocks.cracked_basal_bricks, 0, 2);
		world.setBlock(i + 27, j + 26, k + 10, NovaCraftBlocks.basal_bricks, 0, 2);
		world.setBlock(i + 0, j + 26, k + 11, NovaCraftBlocks.basal_bricks, 0, 2);
		world.setBlock(i + 1, j + 26, k + 11, NovaCraftBlocks.basal_bricks, 0, 2);
		world.setBlock(i + 2, j + 26, k + 11, NovaCraftBlocks.basal_bricks, 0, 2);
		world.setBlock(i + 3, j + 26, k + 11, NovaCraftBlocks.cracked_basal_bricks, 0, 2);
		world.setBlock(i + 4, j + 26, k + 11, NovaCraftBlocks.basal_bricks, 0, 2);
		world.setBlock(i + 5, j + 26, k + 11, NovaCraftBlocks.cracked_basal_bricks, 0, 2);
		world.setBlock(i + 6, j + 26, k + 11, NovaCraftBlocks.basal_bricks, 0, 2);
		world.setBlock(i + 7, j + 26, k + 11, NovaCraftBlocks.basal_bricks, 0, 2);
		world.setBlock(i + 8, j + 26, k + 11, NovaCraftBlocks.basal_bricks, 0, 2);
		world.setBlock(i + 9, j + 26, k + 11, NovaCraftBlocks.basal_bricks, 0, 2);
		world.setBlock(i + 10, j + 26, k + 11, NovaCraftBlocks.basal_bricks, 0, 2);
		world.setBlock(i + 11, j + 26, k + 11, NovaCraftBlocks.basal_bricks, 0, 2);
		world.setBlock(i + 12, j + 26, k + 11, NovaCraftBlocks.cracked_basal_bricks, 0, 2);
		world.setBlock(i + 13, j + 26, k + 11, NovaCraftBlocks.basal_bricks, 0, 2);
		world.setBlock(i + 14, j + 26, k + 11, NovaCraftBlocks.basal_bricks, 0, 2);
		world.setBlock(i + 15, j + 26, k + 11, NovaCraftBlocks.basal_bricks, 0, 2);
		world.setBlock(i + 16, j + 26, k + 11, NovaCraftBlocks.basal_bricks, 0, 2);
		world.setBlock(i + 17, j + 26, k + 11, NovaCraftBlocks.cracked_basal_bricks, 0, 2);
		world.setBlock(i + 18, j + 26, k + 11, NovaCraftBlocks.basal_bricks, 0, 2);
		world.setBlock(i + 19, j + 26, k + 11, NovaCraftBlocks.cracked_basal_bricks, 0, 2);
		world.setBlock(i + 20, j + 26, k + 11, NovaCraftBlocks.basal_bricks, 0, 2);
		world.setBlock(i + 21, j + 26, k + 11, NovaCraftBlocks.basal_bricks, 0, 2);
		world.setBlock(i + 22, j + 26, k + 11, NovaCraftBlocks.basal_bricks, 0, 2);
		world.setBlock(i + 23, j + 26, k + 11, NovaCraftBlocks.basal_bricks, 0, 2);
		world.setBlock(i + 24, j + 26, k + 11, NovaCraftBlocks.basal_bricks, 0, 2);
		world.setBlock(i + 25, j + 26, k + 11, NovaCraftBlocks.cracked_basal_bricks, 0, 2);
		world.setBlock(i + 26, j + 26, k + 11, NovaCraftBlocks.cracked_basal_bricks, 0, 2);
		world.setBlock(i + 27, j + 26, k + 11, NovaCraftBlocks.basal_bricks, 0, 2);
		world.setBlock(i + 0, j + 26, k + 12, NovaCraftBlocks.basal_bricks, 0, 2);
		world.setBlock(i + 1, j + 26, k + 12, NovaCraftBlocks.basal_bricks, 0, 2);
		world.setBlock(i + 2, j + 26, k + 12, NovaCraftBlocks.cracked_basal_bricks, 0, 2);
		world.setBlock(i + 3, j + 26, k + 12, NovaCraftBlocks.basal_bricks, 0, 2);
		world.setBlock(i + 4, j + 26, k + 12, NovaCraftBlocks.basal_bricks, 0, 2);
		world.setBlock(i + 5, j + 26, k + 12, NovaCraftBlocks.basal_bricks, 0, 2);
		world.setBlock(i + 6, j + 26, k + 12, NovaCraftBlocks.cracked_basal_bricks, 0, 2);
		world.setBlock(i + 7, j + 26, k + 12, NovaCraftBlocks.basal_bricks, 0, 2);
		world.setBlock(i + 8, j + 26, k + 12, NovaCraftBlocks.cracked_basal_bricks, 0, 2);
		world.setBlock(i + 9, j + 26, k + 12, NovaCraftBlocks.basal_bricks, 0, 2);
		world.setBlock(i + 10, j + 26, k + 12, NovaCraftBlocks.basal_bricks, 0, 2);
		world.setBlock(i + 11, j + 26, k + 12, NovaCraftBlocks.basal_bricks, 0, 2);
		world.setBlock(i + 12, j + 26, k + 12, NovaCraftBlocks.cracked_basal_bricks, 0, 2);
		world.setBlock(i + 13, j + 26, k + 12, NovaCraftBlocks.basal_bricks, 0, 2);
		world.setBlock(i + 14, j + 26, k + 12, NovaCraftBlocks.cracked_basal_bricks, 0, 2);
		world.setBlock(i + 15, j + 26, k + 12, NovaCraftBlocks.basal_bricks, 0, 2);
		world.setBlock(i + 16, j + 26, k + 12, NovaCraftBlocks.cracked_basal_bricks, 0, 2);
		world.setBlock(i + 17, j + 26, k + 12, NovaCraftBlocks.basal_bricks, 0, 2);
		world.setBlock(i + 18, j + 26, k + 12, NovaCraftBlocks.cracked_basal_bricks, 0, 2);
		world.setBlock(i + 19, j + 26, k + 12, NovaCraftBlocks.basal_bricks, 0, 2);
		world.setBlock(i + 20, j + 26, k + 12, NovaCraftBlocks.basal_bricks, 0, 2);
		world.setBlock(i + 21, j + 26, k + 12, NovaCraftBlocks.basal_bricks, 0, 2);
		world.setBlock(i + 22, j + 26, k + 12, NovaCraftBlocks.basal_bricks, 0, 2);
		world.setBlock(i + 23, j + 26, k + 12, NovaCraftBlocks.cracked_basal_bricks, 0, 2);
		world.setBlock(i + 24, j + 26, k + 12, NovaCraftBlocks.basal_bricks, 0, 2);
		world.setBlock(i + 25, j + 26, k + 12, NovaCraftBlocks.basal_bricks, 0, 2);
		world.setBlock(i + 26, j + 26, k + 12, NovaCraftBlocks.basal_bricks, 0, 2);
		world.setBlock(i + 27, j + 26, k + 12, NovaCraftBlocks.basal_bricks, 0, 2);
		world.setBlock(i + 0, j + 26, k + 13, NovaCraftBlocks.basal_bricks, 0, 2);
		world.setBlock(i + 1, j + 26, k + 13, NovaCraftBlocks.basal_bricks, 0, 2);
		world.setBlock(i + 2, j + 26, k + 13, NovaCraftBlocks.basal_bricks, 0, 2);
		world.setBlock(i + 3, j + 26, k + 13, NovaCraftBlocks.basal_bricks, 0, 2);
		world.setBlock(i + 4, j + 26, k + 13, NovaCraftBlocks.basal_bricks, 0, 2);
		world.setBlock(i + 5, j + 26, k + 13, NovaCraftBlocks.basal_bricks, 0, 2);
		world.setBlock(i + 6, j + 26, k + 13, NovaCraftBlocks.basal_bricks, 0, 2);
		world.setBlock(i + 7, j + 26, k + 13, NovaCraftBlocks.cracked_basal_bricks, 0, 2);
		world.setBlock(i + 8, j + 26, k + 13, NovaCraftBlocks.cracked_basal_bricks, 0, 2);
		world.setBlock(i + 9, j + 26, k + 13, NovaCraftBlocks.cracked_basal_bricks, 0, 2);
		world.setBlock(i + 10, j + 26, k + 13, NovaCraftBlocks.cracked_basal_bricks, 0, 2);
		world.setBlock(i + 11, j + 26, k + 13, NovaCraftBlocks.cracked_basal_bricks, 0, 2);
		world.setBlock(i + 12, j + 26, k + 13, NovaCraftBlocks.basal_bricks, 0, 2);
		world.setBlock(i + 13, j + 26, k + 13, NovaCraftBlocks.cracked_basal_bricks, 0, 2);
		world.setBlock(i + 14, j + 26, k + 13, NovaCraftBlocks.basal_bricks, 0, 2);
		world.setBlock(i + 15, j + 26, k + 13, NovaCraftBlocks.basal_bricks, 0, 2);
		world.setBlock(i + 16, j + 26, k + 13, NovaCraftBlocks.basal_bricks, 0, 2);
		world.setBlock(i + 17, j + 26, k + 13, NovaCraftBlocks.basal_bricks, 0, 2);
		world.setBlock(i + 18, j + 26, k + 13, NovaCraftBlocks.basal_bricks, 0, 2);
		world.setBlock(i + 19, j + 26, k + 13, NovaCraftBlocks.basal_bricks, 0, 2);
		world.setBlock(i + 20, j + 26, k + 13, NovaCraftBlocks.basal_bricks, 0, 2);
		world.setBlock(i + 21, j + 26, k + 13, NovaCraftBlocks.basal_bricks, 0, 2);
		world.setBlock(i + 22, j + 26, k + 13, NovaCraftBlocks.basal_bricks, 0, 2);
		world.setBlock(i + 23, j + 26, k + 13, NovaCraftBlocks.basal_bricks, 0, 2);
		world.setBlock(i + 24, j + 26, k + 13, NovaCraftBlocks.basal_bricks, 0, 2);
		world.setBlock(i + 25, j + 26, k + 13, NovaCraftBlocks.cracked_basal_bricks, 0, 2);
		world.setBlock(i + 26, j + 26, k + 13, NovaCraftBlocks.cracked_basal_bricks, 0, 2);
		world.setBlock(i + 27, j + 26, k + 13, NovaCraftBlocks.cracked_basal_bricks, 0, 2);
		world.setBlock(i + 0, j + 26, k + 14, NovaCraftBlocks.basal_bricks, 0, 2);
		world.setBlock(i + 1, j + 26, k + 14, NovaCraftBlocks.basal_bricks, 0, 2);
		world.setBlock(i + 2, j + 26, k + 14, NovaCraftBlocks.cracked_basal_bricks, 0, 2);
		world.setBlock(i + 3, j + 26, k + 14, NovaCraftBlocks.basal_bricks, 0, 2);
		world.setBlock(i + 4, j + 26, k + 14, NovaCraftBlocks.cracked_basal_bricks, 0, 2);
		world.setBlock(i + 5, j + 26, k + 14, NovaCraftBlocks.basal_bricks, 0, 2);
		world.setBlock(i + 6, j + 26, k + 14, NovaCraftBlocks.cracked_basal_bricks, 0, 2);
		world.setBlock(i + 7, j + 26, k + 14, NovaCraftBlocks.cracked_basal_bricks, 0, 2);
		world.setBlock(i + 8, j + 26, k + 14, NovaCraftBlocks.basal_bricks, 0, 2);
		world.setBlock(i + 9, j + 26, k + 14, NovaCraftBlocks.basal_bricks, 0, 2);
		world.setBlock(i + 10, j + 26, k + 14, NovaCraftBlocks.basal_bricks, 0, 2);
		world.setBlock(i + 11, j + 26, k + 14, NovaCraftBlocks.cracked_basal_bricks, 0, 2);
		world.setBlock(i + 12, j + 26, k + 14, NovaCraftBlocks.basal_bricks, 0, 2);
		world.setBlock(i + 13, j + 26, k + 14, NovaCraftBlocks.cracked_basal_bricks, 0, 2);
		world.setBlock(i + 14, j + 26, k + 14, NovaCraftBlocks.basal_bricks, 0, 2);
		world.setBlock(i + 15, j + 26, k + 14, NovaCraftBlocks.basal_bricks, 0, 2);
		world.setBlock(i + 16, j + 26, k + 14, NovaCraftBlocks.cracked_basal_bricks, 0, 2);
		world.setBlock(i + 17, j + 26, k + 14, NovaCraftBlocks.basal_bricks, 0, 2);
		world.setBlock(i + 18, j + 26, k + 14, NovaCraftBlocks.cracked_basal_bricks, 0, 2);
		world.setBlock(i + 19, j + 26, k + 14, NovaCraftBlocks.cracked_basal_bricks, 0, 2);
		world.setBlock(i + 20, j + 26, k + 14, NovaCraftBlocks.basal_bricks, 0, 2);
		world.setBlock(i + 21, j + 26, k + 14, NovaCraftBlocks.basal_bricks, 0, 2);
		world.setBlock(i + 22, j + 26, k + 14, NovaCraftBlocks.basal_bricks, 0, 2);
		world.setBlock(i + 23, j + 26, k + 14, NovaCraftBlocks.basal_bricks, 0, 2);
		world.setBlock(i + 24, j + 26, k + 14, NovaCraftBlocks.basal_bricks, 0, 2);
		world.setBlock(i + 25, j + 26, k + 14, NovaCraftBlocks.basal_bricks, 0, 2);
		world.setBlock(i + 26, j + 26, k + 14, NovaCraftBlocks.cracked_basal_bricks, 0, 2);
		world.setBlock(i + 27, j + 26, k + 14, NovaCraftBlocks.basal_bricks, 0, 2);
		world.setBlock(i + 0, j + 26, k + 15, NovaCraftBlocks.cracked_basal_bricks, 0, 2);
		world.setBlock(i + 1, j + 26, k + 15, NovaCraftBlocks.cracked_basal_bricks, 0, 2);
		world.setBlock(i + 2, j + 26, k + 15, NovaCraftBlocks.basal_bricks, 0, 2);
		world.setBlock(i + 3, j + 26, k + 15, NovaCraftBlocks.basal_bricks, 0, 2);
		world.setBlock(i + 4, j + 26, k + 15, NovaCraftBlocks.basal_bricks, 0, 2);
		world.setBlock(i + 5, j + 26, k + 15, NovaCraftBlocks.cracked_basal_bricks, 0, 2);
		world.setBlock(i + 6, j + 26, k + 15, NovaCraftBlocks.basal_bricks, 0, 2);
		world.setBlock(i + 7, j + 26, k + 15, NovaCraftBlocks.cracked_basal_bricks, 0, 2);
		world.setBlock(i + 8, j + 26, k + 15, NovaCraftBlocks.cracked_basal_bricks, 0, 2);
		world.setBlock(i + 9, j + 26, k + 15, NovaCraftBlocks.basal_bricks, 0, 2);
		world.setBlock(i + 10, j + 26, k + 15, NovaCraftBlocks.cracked_basal_bricks, 0, 2);
		world.setBlock(i + 11, j + 26, k + 15, NovaCraftBlocks.cracked_basal_bricks, 0, 2);
		world.setBlock(i + 12, j + 26, k + 15, NovaCraftBlocks.basal_bricks, 0, 2);
		world.setBlock(i + 13, j + 26, k + 15, Blocks.air, 0, 2);
		world.setBlock(i + 14, j + 26, k + 15, NovaCraftBlocks.basal_bricks, 0, 2);
		world.setBlock(i + 15, j + 26, k + 15, NovaCraftBlocks.basal_bricks, 0, 2);
		world.setBlock(i + 16, j + 26, k + 15, NovaCraftBlocks.basal_bricks, 0, 2);
		world.setBlock(i + 17, j + 26, k + 15, NovaCraftBlocks.basal_bricks, 0, 2);
		world.setBlock(i + 18, j + 26, k + 15, NovaCraftBlocks.cracked_basal_bricks, 0, 2);
		world.setBlock(i + 19, j + 26, k + 15, NovaCraftBlocks.basal_bricks, 0, 2);
		world.setBlock(i + 20, j + 26, k + 15, NovaCraftBlocks.basal_bricks, 0, 2);
		world.setBlock(i + 21, j + 26, k + 15, NovaCraftBlocks.basal_bricks, 0, 2);
		world.setBlock(i + 22, j + 26, k + 15, NovaCraftBlocks.basal_bricks, 0, 2);
		world.setBlock(i + 23, j + 26, k + 15, NovaCraftBlocks.basal_bricks, 0, 2);
		world.setBlock(i + 24, j + 26, k + 15, NovaCraftBlocks.basal_bricks, 0, 2);
		world.setBlock(i + 25, j + 26, k + 15, NovaCraftBlocks.basal_bricks, 0, 2);
		world.setBlock(i + 26, j + 26, k + 15, NovaCraftBlocks.basal_bricks, 0, 2);
		world.setBlock(i + 27, j + 26, k + 15, NovaCraftBlocks.basal_bricks, 0, 2);
		world.setBlock(i + 0, j + 26, k + 16, NovaCraftBlocks.cracked_basal_bricks, 0, 2);
		world.setBlock(i + 1, j + 26, k + 16, NovaCraftBlocks.cracked_basal_bricks, 0, 2);
		world.setBlock(i + 2, j + 26, k + 16, NovaCraftBlocks.basal_bricks, 0, 2);
		world.setBlock(i + 3, j + 26, k + 16, NovaCraftBlocks.basal_bricks, 0, 2);
		world.setBlock(i + 4, j + 26, k + 16, NovaCraftBlocks.basal_bricks, 0, 2);
		world.setBlock(i + 5, j + 26, k + 16, NovaCraftBlocks.basal_bricks, 0, 2);
		world.setBlock(i + 6, j + 26, k + 16, NovaCraftBlocks.cracked_basal_bricks, 0, 2);
		world.setBlock(i + 7, j + 26, k + 16, NovaCraftBlocks.basal_bricks, 0, 2);
		world.setBlock(i + 8, j + 26, k + 16, NovaCraftBlocks.basal_bricks, 0, 2);
		world.setBlock(i + 9, j + 26, k + 16, NovaCraftBlocks.basal_bricks, 0, 2);
		world.setBlock(i + 10, j + 26, k + 16, NovaCraftBlocks.basal_bricks, 0, 2);
		world.setBlock(i + 11, j + 26, k + 16, NovaCraftBlocks.basal_bricks, 0, 2);
		world.setBlock(i + 12, j + 26, k + 16, NovaCraftBlocks.cracked_basal_bricks, 0, 2);
		world.setBlock(i + 13, j + 26, k + 16, Blocks.air, 0, 2);
		world.setBlock(i + 14, j + 26, k + 16, NovaCraftBlocks.basal_bricks, 0, 2);
		world.setBlock(i + 15, j + 26, k + 16, NovaCraftBlocks.basal_bricks, 0, 2);
		world.setBlock(i + 16, j + 26, k + 16, NovaCraftBlocks.basal_bricks, 0, 2);
		world.setBlock(i + 17, j + 26, k + 16, NovaCraftBlocks.basal_bricks, 0, 2);
		world.setBlock(i + 18, j + 26, k + 16, NovaCraftBlocks.cracked_basal_bricks, 0, 2);
		world.setBlock(i + 19, j + 26, k + 16, NovaCraftBlocks.basal_bricks, 0, 2);
		world.setBlock(i + 20, j + 26, k + 16, NovaCraftBlocks.basal_bricks, 0, 2);
		world.setBlock(i + 21, j + 26, k + 16, NovaCraftBlocks.basal_bricks, 0, 2);
		world.setBlock(i + 22, j + 26, k + 16, NovaCraftBlocks.basal_bricks, 0, 2);
		world.setBlock(i + 23, j + 26, k + 16, NovaCraftBlocks.cracked_basal_bricks, 0, 2);
		world.setBlock(i + 24, j + 26, k + 16, NovaCraftBlocks.basal_bricks, 0, 2);
		world.setBlock(i + 25, j + 26, k + 16, NovaCraftBlocks.cracked_basal_bricks, 0, 2);
		world.setBlock(i + 26, j + 26, k + 16, NovaCraftBlocks.basal_bricks, 0, 2);
		world.setBlock(i + 27, j + 26, k + 16, NovaCraftBlocks.basal_bricks, 0, 2);
		world.setBlock(i + 0, j + 26, k + 17, NovaCraftBlocks.basal_bricks, 0, 2);
		world.setBlock(i + 1, j + 26, k + 17, NovaCraftBlocks.cracked_basal_bricks, 0, 2);
		world.setBlock(i + 2, j + 26, k + 17, NovaCraftBlocks.cracked_basal_bricks, 0, 2);
		world.setBlock(i + 3, j + 26, k + 17, NovaCraftBlocks.basal_bricks, 0, 2);
		world.setBlock(i + 4, j + 26, k + 17, NovaCraftBlocks.basal_bricks, 0, 2);
		world.setBlock(i + 5, j + 26, k + 17, NovaCraftBlocks.cracked_basal_bricks, 0, 2);
		world.setBlock(i + 6, j + 26, k + 17, NovaCraftBlocks.cracked_basal_bricks, 0, 2);
		world.setBlock(i + 7, j + 26, k + 17, NovaCraftBlocks.basal_bricks, 0, 2);
		world.setBlock(i + 8, j + 26, k + 17, NovaCraftBlocks.cracked_basal_bricks, 0, 2);
		world.setBlock(i + 9, j + 26, k + 17, NovaCraftBlocks.basal_bricks, 0, 2);
		world.setBlock(i + 10, j + 26, k + 17, NovaCraftBlocks.basal_bricks, 0, 2);
		world.setBlock(i + 11, j + 26, k + 17, NovaCraftBlocks.cracked_basal_bricks, 0, 2);
		world.setBlock(i + 12, j + 26, k + 17, NovaCraftBlocks.basal_bricks, 0, 2);
		world.setBlock(i + 13, j + 26, k + 17, NovaCraftBlocks.basal_bricks, 0, 2);
		world.setBlock(i + 14, j + 26, k + 17, NovaCraftBlocks.basal_bricks, 0, 2);
		world.setBlock(i + 15, j + 26, k + 17, NovaCraftBlocks.basal_bricks, 0, 2);
		world.setBlock(i + 16, j + 26, k + 17, NovaCraftBlocks.cracked_basal_bricks, 0, 2);
		world.setBlock(i + 17, j + 26, k + 17, NovaCraftBlocks.cracked_basal_bricks, 0, 2);
		world.setBlock(i + 18, j + 26, k + 17, NovaCraftBlocks.cracked_basal_bricks, 0, 2);
		world.setBlock(i + 19, j + 26, k + 17, NovaCraftBlocks.basal_bricks, 0, 2);
		world.setBlock(i + 20, j + 26, k + 17, NovaCraftBlocks.basal_bricks, 0, 2);
		world.setBlock(i + 21, j + 26, k + 17, NovaCraftBlocks.basal_bricks, 0, 2);
		world.setBlock(i + 22, j + 26, k + 17, NovaCraftBlocks.cracked_basal_bricks, 0, 2);
		world.setBlock(i + 23, j + 26, k + 17, NovaCraftBlocks.cracked_basal_bricks, 0, 2);
		world.setBlock(i + 24, j + 26, k + 17, NovaCraftBlocks.basal_bricks, 0, 2);
		world.setBlock(i + 25, j + 26, k + 17, NovaCraftBlocks.cracked_basal_bricks, 0, 2);
		world.setBlock(i + 26, j + 26, k + 17, NovaCraftBlocks.basal_bricks, 0, 2);
		world.setBlock(i + 27, j + 26, k + 17, Blocks.air, 0, 2);
		world.setBlock(i + 0, j + 26, k + 18, NovaCraftBlocks.cracked_basal_bricks, 0, 2);
		world.setBlock(i + 1, j + 26, k + 18, NovaCraftBlocks.basal_bricks, 0, 2);
		world.setBlock(i + 2, j + 26, k + 18, NovaCraftBlocks.cracked_basal_bricks, 0, 2);
		world.setBlock(i + 3, j + 26, k + 18, NovaCraftBlocks.basal_bricks, 0, 2);
		world.setBlock(i + 4, j + 26, k + 18, NovaCraftBlocks.basal_bricks, 0, 2);
		world.setBlock(i + 5, j + 26, k + 18, NovaCraftBlocks.basal_bricks, 0, 2);
		world.setBlock(i + 6, j + 26, k + 18, NovaCraftBlocks.cracked_basal_bricks, 0, 2);
		world.setBlock(i + 7, j + 26, k + 18, NovaCraftBlocks.basal_bricks, 0, 2);
		world.setBlock(i + 8, j + 26, k + 18, NovaCraftBlocks.basal_bricks, 0, 2);
		world.setBlock(i + 9, j + 26, k + 18, NovaCraftBlocks.basal_bricks, 0, 2);
		world.setBlock(i + 10, j + 26, k + 18, NovaCraftBlocks.basal_bricks, 0, 2);
		world.setBlock(i + 11, j + 26, k + 18, NovaCraftBlocks.basal_bricks, 0, 2);
		world.setBlock(i + 12, j + 26, k + 18, NovaCraftBlocks.basal_bricks, 0, 2);
		world.setBlock(i + 13, j + 26, k + 18, NovaCraftBlocks.basal_bricks, 0, 2);
		world.setBlock(i + 14, j + 26, k + 18, NovaCraftBlocks.basal_bricks, 0, 2);
		world.setBlock(i + 15, j + 26, k + 18, NovaCraftBlocks.basal_bricks, 0, 2);
		world.setBlock(i + 16, j + 26, k + 18, NovaCraftBlocks.basal_bricks, 0, 2);
		world.setBlock(i + 17, j + 26, k + 18, NovaCraftBlocks.basal_bricks, 0, 2);
		world.setBlock(i + 18, j + 26, k + 18, NovaCraftBlocks.basal_bricks, 0, 2);
		world.setBlock(i + 19, j + 26, k + 18, NovaCraftBlocks.cracked_basal_bricks, 0, 2);
		world.setBlock(i + 20, j + 26, k + 18, NovaCraftBlocks.basal_bricks, 0, 2);
		world.setBlock(i + 21, j + 26, k + 18, NovaCraftBlocks.basal_bricks, 0, 2);
		world.setBlock(i + 22, j + 26, k + 18, NovaCraftBlocks.cracked_basal_bricks, 0, 2);
		world.setBlock(i + 23, j + 26, k + 18, NovaCraftBlocks.basal_bricks, 0, 2);
		world.setBlock(i + 24, j + 26, k + 18, NovaCraftBlocks.cracked_basal_bricks, 0, 2);
		world.setBlock(i + 25, j + 26, k + 18, NovaCraftBlocks.basal_bricks, 0, 2);
		world.setBlock(i + 26, j + 26, k + 18, NovaCraftBlocks.basal_bricks, 0, 2);
		world.setBlock(i + 27, j + 26, k + 18, Blocks.air, 0, 2);
		world.setBlock(i + 0, j + 27, k + 0, NovaCraftBlocks.cracked_basal_bricks, 0, 2);
		world.setBlock(i + 1, j + 27, k + 0, NovaCraftBlocks.cracked_basal_bricks, 0, 2);
		world.setBlock(i + 2, j + 27, k + 0, NovaCraftBlocks.cracked_basal_bricks, 0, 2);
		world.setBlock(i + 3, j + 27, k + 0, NovaCraftBlocks.cracked_basal_bricks, 0, 2);
		world.setBlock(i + 4, j + 27, k + 0, NovaCraftBlocks.basal_bricks, 0, 2);
		world.setBlock(i + 5, j + 27, k + 0, NovaCraftBlocks.cracked_basal_bricks, 0, 2);
		world.setBlock(i + 6, j + 27, k + 0, NovaCraftBlocks.basal_bricks, 0, 2);
		world.setBlock(i + 7, j + 27, k + 0, NovaCraftBlocks.basal_bricks, 0, 2);
		world.setBlock(i + 8, j + 27, k + 0, NovaCraftBlocks.basal_bricks, 0, 2);
		world.setBlock(i + 9, j + 27, k + 0, NovaCraftBlocks.basal_bricks, 0, 2);
		world.setBlock(i + 10, j + 27, k + 0, NovaCraftBlocks.cracked_basal_bricks, 0, 2);
		world.setBlock(i + 11, j + 27, k + 0, NovaCraftBlocks.cracked_basal_bricks, 0, 2);
		world.setBlock(i + 12, j + 27, k + 0, NovaCraftBlocks.basal_bricks, 0, 2);
		world.setBlock(i + 13, j + 27, k + 0, NovaCraftBlocks.basal_bricks, 0, 2);
		world.setBlock(i + 14, j + 27, k + 0, NovaCraftBlocks.cracked_basal_bricks, 0, 2);
		world.setBlock(i + 15, j + 27, k + 0, NovaCraftBlocks.cracked_basal_bricks, 0, 2);
		world.setBlock(i + 16, j + 27, k + 0, NovaCraftBlocks.basal_bricks, 0, 2);
		world.setBlock(i + 17, j + 27, k + 0, NovaCraftBlocks.cracked_basal_bricks, 0, 2);
		world.setBlock(i + 18, j + 27, k + 0, NovaCraftBlocks.basal_bricks, 0, 2);
		world.setBlock(i + 19, j + 27, k + 0, NovaCraftBlocks.basal_bricks, 0, 2);
		world.setBlock(i + 20, j + 27, k + 0, NovaCraftBlocks.basal_bricks, 0, 2);
		world.setBlock(i + 21, j + 27, k + 0, NovaCraftBlocks.cracked_basal_bricks, 0, 2);
		world.setBlock(i + 22, j + 27, k + 0, NovaCraftBlocks.cracked_basal_bricks, 0, 2);
		world.setBlock(i + 23, j + 27, k + 0, NovaCraftBlocks.cracked_basal_bricks, 0, 2);
		world.setBlock(i + 24, j + 27, k + 0, NovaCraftBlocks.basal_bricks, 0, 2);
		world.setBlock(i + 25, j + 27, k + 0, NovaCraftBlocks.basal_bricks, 0, 2);
		world.setBlock(i + 26, j + 27, k + 0, NovaCraftBlocks.basal_bricks, 0, 2);
		world.setBlock(i + 27, j + 27, k + 0, NovaCraftBlocks.basal_bricks, 0, 2);
		world.setBlock(i + 0, j + 27, k + 1, NovaCraftBlocks.basal_bricks, 0, 2);
		world.setBlock(i + 1, j + 27, k + 1, NovaCraftBlocks.basal_bricks, 0, 2);
		world.setBlock(i + 2, j + 27, k + 1, NovaCraftBlocks.cracked_basal_bricks, 0, 2);
		world.setBlock(i + 3, j + 27, k + 1, NovaCraftBlocks.basal_bricks, 0, 2);
		world.setBlock(i + 4, j + 27, k + 1, NovaCraftBlocks.cracked_basal_bricks, 0, 2);
		world.setBlock(i + 5, j + 27, k + 1, NovaCraftBlocks.cracked_basal_bricks, 0, 2);
		world.setBlock(i + 6, j + 27, k + 1, NovaCraftBlocks.basal_bricks, 0, 2);
		world.setBlock(i + 7, j + 27, k + 1, NovaCraftBlocks.basal_bricks, 0, 2);
		world.setBlock(i + 8, j + 27, k + 1, NovaCraftBlocks.cracked_basal_bricks, 0, 2);
		world.setBlock(i + 9, j + 27, k + 1, NovaCraftBlocks.basal_bricks, 0, 2);
		world.setBlock(i + 10, j + 27, k + 1, NovaCraftBlocks.basal_bricks, 0, 2);
		world.setBlock(i + 11, j + 27, k + 1, NovaCraftBlocks.basal_bricks, 0, 2);
		world.setBlock(i + 12, j + 27, k + 1, NovaCraftBlocks.basal_bricks, 0, 2);
		world.setBlock(i + 13, j + 27, k + 1, NovaCraftBlocks.basal_bricks, 0, 2);
		world.setBlock(i + 14, j + 27, k + 1, NovaCraftBlocks.basal_bricks, 0, 2);
		world.setBlock(i + 15, j + 27, k + 1, NovaCraftBlocks.basal_bricks, 0, 2);
		world.setBlock(i + 16, j + 27, k + 1, NovaCraftBlocks.basal_bricks, 0, 2);
		world.setBlock(i + 17, j + 27, k + 1, NovaCraftBlocks.basal_bricks, 0, 2);
		world.setBlock(i + 18, j + 27, k + 1, NovaCraftBlocks.basal_bricks, 0, 2);
		world.setBlock(i + 19, j + 27, k + 1, NovaCraftBlocks.basal_bricks, 0, 2);
		world.setBlock(i + 20, j + 27, k + 1, NovaCraftBlocks.cracked_basal_bricks, 0, 2);
		world.setBlock(i + 21, j + 27, k + 1, NovaCraftBlocks.basal_bricks, 0, 2);
		world.setBlock(i + 22, j + 27, k + 1, NovaCraftBlocks.cracked_basal_bricks, 0, 2);
		world.setBlock(i + 23, j + 27, k + 1, NovaCraftBlocks.cracked_basal_bricks, 0, 2);
		world.setBlock(i + 24, j + 27, k + 1, NovaCraftBlocks.basal_bricks, 0, 2);
		world.setBlock(i + 25, j + 27, k + 1, NovaCraftBlocks.cracked_basal_bricks, 0, 2);
		world.setBlock(i + 26, j + 27, k + 1, NovaCraftBlocks.cracked_basal_bricks, 0, 2);
		world.setBlock(i + 27, j + 27, k + 1, NovaCraftBlocks.cracked_basal_bricks, 0, 2);
		world.setBlock(i + 0, j + 27, k + 2, NovaCraftBlocks.cracked_basal_bricks, 0, 2);
		world.setBlock(i + 1, j + 27, k + 2, NovaCraftBlocks.basal_bricks, 0, 2);
		world.setBlock(i + 2, j + 27, k + 2, NovaCraftBlocks.basal_bricks, 0, 2);
		world.setBlock(i + 3, j + 27, k + 2, NovaCraftBlocks.cracked_basal_bricks, 0, 2);
		world.setBlock(i + 4, j + 27, k + 2, NovaCraftBlocks.cracked_basal_bricks, 0, 2);
		world.setBlock(i + 5, j + 27, k + 2, NovaCraftBlocks.cracked_basal_bricks, 0, 2);
		world.setBlock(i + 6, j + 27, k + 2, NovaCraftBlocks.cracked_basal_bricks, 0, 2);
		world.setBlock(i + 7, j + 27, k + 2, NovaCraftBlocks.basal_bricks, 0, 2);
		world.setBlock(i + 8, j + 27, k + 2, NovaCraftBlocks.basal_bricks, 0, 2);
		world.setBlock(i + 9, j + 27, k + 2, NovaCraftBlocks.basal_bricks, 0, 2);
		world.setBlock(i + 10, j + 27, k + 2, NovaCraftBlocks.basal_bricks, 0, 2);
		world.setBlock(i + 11, j + 27, k + 2, NovaCraftBlocks.cracked_basal_bricks, 0, 2);
		world.setBlock(i + 12, j + 27, k + 2, NovaCraftBlocks.cracked_basal_bricks, 0, 2);
		world.setBlock(i + 13, j + 27, k + 2, NovaCraftBlocks.basal_bricks, 0, 2);
		world.setBlock(i + 14, j + 27, k + 2, NovaCraftBlocks.basal_bricks, 0, 2);
		world.setBlock(i + 15, j + 27, k + 2, NovaCraftBlocks.basal_bricks, 0, 2);
		world.setBlock(i + 16, j + 27, k + 2, NovaCraftBlocks.cracked_basal_bricks, 0, 2);
		world.setBlock(i + 17, j + 27, k + 2, NovaCraftBlocks.basal_bricks, 0, 2);
		world.setBlock(i + 18, j + 27, k + 2, NovaCraftBlocks.basal_bricks, 0, 2);
		world.setBlock(i + 19, j + 27, k + 2, NovaCraftBlocks.basal_bricks, 0, 2);
		world.setBlock(i + 20, j + 27, k + 2, NovaCraftBlocks.cracked_basal_bricks, 0, 2);
		world.setBlock(i + 21, j + 27, k + 2, NovaCraftBlocks.basal_bricks, 0, 2);
		world.setBlock(i + 22, j + 27, k + 2, NovaCraftBlocks.cracked_basal_bricks, 0, 2);
		world.setBlock(i + 23, j + 27, k + 2, NovaCraftBlocks.basal_bricks, 0, 2);
		world.setBlock(i + 24, j + 27, k + 2, NovaCraftBlocks.cracked_basal_bricks, 0, 2);
		world.setBlock(i + 25, j + 27, k + 2, NovaCraftBlocks.basal_bricks, 0, 2);
		world.setBlock(i + 26, j + 27, k + 2, NovaCraftBlocks.basal_bricks, 0, 2);
		world.setBlock(i + 27, j + 27, k + 2, NovaCraftBlocks.cracked_basal_bricks, 0, 2);
		world.setBlock(i + 0, j + 27, k + 3, NovaCraftBlocks.cracked_basal_bricks, 0, 2);
		world.setBlock(i + 1, j + 27, k + 3, NovaCraftBlocks.cracked_basal_bricks, 0, 2);
		world.setBlock(i + 2, j + 27, k + 3, NovaCraftBlocks.cracked_basal_bricks, 0, 2);
		world.setBlock(i + 3, j + 27, k + 3, NovaCraftBlocks.basal_bricks, 0, 2);
		world.setBlock(i + 4, j + 27, k + 3, NovaCraftBlocks.basal_bricks, 0, 2);
		world.setBlock(i + 5, j + 27, k + 3, NovaCraftBlocks.basal_bricks, 0, 2);
		world.setBlock(i + 6, j + 27, k + 3, NovaCraftBlocks.basal_bricks, 0, 2);
		world.setBlock(i + 7, j + 27, k + 3, NovaCraftBlocks.cracked_basal_bricks, 0, 2);
		world.setBlock(i + 8, j + 27, k + 3, NovaCraftBlocks.basal_bricks, 0, 2);
		world.setBlock(i + 9, j + 27, k + 3, NovaCraftBlocks.basal_bricks, 0, 2);
		world.setBlock(i + 10, j + 27, k + 3, NovaCraftBlocks.basal_bricks, 0, 2);
		world.setBlock(i + 11, j + 27, k + 3, NovaCraftBlocks.basal_bricks, 0, 2);
		world.setBlock(i + 12, j + 27, k + 3, NovaCraftBlocks.cracked_basal_bricks, 0, 2);
		world.setBlock(i + 13, j + 27, k + 3, NovaCraftBlocks.basal_bricks, 0, 2);
		world.setBlock(i + 14, j + 27, k + 3, NovaCraftBlocks.basal_bricks, 0, 2);
		world.setBlock(i + 15, j + 27, k + 3, NovaCraftBlocks.basal_bricks, 0, 2);
		world.setBlock(i + 16, j + 27, k + 3, NovaCraftBlocks.basal_bricks, 0, 2);
		world.setBlock(i + 17, j + 27, k + 3, NovaCraftBlocks.cracked_basal_bricks, 0, 2);
		world.setBlock(i + 18, j + 27, k + 3, NovaCraftBlocks.basal_bricks, 0, 2);
		world.setBlock(i + 19, j + 27, k + 3, NovaCraftBlocks.basal_bricks, 0, 2);
		world.setBlock(i + 20, j + 27, k + 3, NovaCraftBlocks.basal_bricks, 0, 2);
		world.setBlock(i + 21, j + 27, k + 3, NovaCraftBlocks.basal_bricks, 0, 2);
		world.setBlock(i + 22, j + 27, k + 3, NovaCraftBlocks.basal_bricks, 0, 2);
		world.setBlock(i + 23, j + 27, k + 3, NovaCraftBlocks.basal_bricks, 0, 2);
		world.setBlock(i + 24, j + 27, k + 3, NovaCraftBlocks.cracked_basal_bricks, 0, 2);
		world.setBlock(i + 25, j + 27, k + 3, NovaCraftBlocks.basal_bricks, 0, 2);
		world.setBlock(i + 26, j + 27, k + 3, NovaCraftBlocks.cracked_basal_bricks, 0, 2);
		world.setBlock(i + 27, j + 27, k + 3, NovaCraftBlocks.cracked_basal_bricks, 0, 2);
		world.setBlock(i + 0, j + 27, k + 4, NovaCraftBlocks.basal_bricks, 0, 2);
		world.setBlock(i + 1, j + 27, k + 4, NovaCraftBlocks.cracked_basal_bricks, 0, 2);
		world.setBlock(i + 2, j + 27, k + 4, NovaCraftBlocks.cracked_basal_bricks, 0, 2);
		world.setBlock(i + 3, j + 27, k + 4, NovaCraftBlocks.basal_bricks, 0, 2);
		world.setBlock(i + 4, j + 27, k + 4, NovaCraftBlocks.basal_bricks, 0, 2);
		world.setBlock(i + 5, j + 27, k + 4, NovaCraftBlocks.basal_bricks, 0, 2);
		world.setBlock(i + 6, j + 27, k + 4, NovaCraftBlocks.cracked_basal_bricks, 0, 2);
		world.setBlock(i + 7, j + 27, k + 4, NovaCraftBlocks.basal_bricks, 0, 2);
		world.setBlock(i + 8, j + 27, k + 4, NovaCraftBlocks.basal_bricks, 0, 2);
		world.setBlock(i + 9, j + 27, k + 4, NovaCraftBlocks.basal_bricks, 0, 2);
		world.setBlock(i + 10, j + 27, k + 4, NovaCraftBlocks.basal_bricks, 0, 2);
		world.setBlock(i + 11, j + 27, k + 4, NovaCraftBlocks.basal_bricks, 0, 2);
		world.setBlock(i + 12, j + 27, k + 4, NovaCraftBlocks.basal_bricks, 0, 2);
		world.setBlock(i + 13, j + 27, k + 4, NovaCraftBlocks.basal_bricks, 0, 2);
		world.setBlock(i + 14, j + 27, k + 4, NovaCraftBlocks.basal_bricks, 0, 2);
		world.setBlock(i + 15, j + 27, k + 4, NovaCraftBlocks.basal_bricks, 0, 2);
		world.setBlock(i + 16, j + 27, k + 4, NovaCraftBlocks.basal_bricks, 0, 2);
		world.setBlock(i + 17, j + 27, k + 4, NovaCraftBlocks.cracked_basal_bricks, 0, 2);
		world.setBlock(i + 18, j + 27, k + 4, NovaCraftBlocks.cracked_basal_bricks, 0, 2);
		world.setBlock(i + 19, j + 27, k + 4, NovaCraftBlocks.basal_bricks, 0, 2);
		world.setBlock(i + 20, j + 27, k + 4, NovaCraftBlocks.basal_bricks, 0, 2);
		world.setBlock(i + 21, j + 27, k + 4, NovaCraftBlocks.basal_bricks, 0, 2);
		world.setBlock(i + 22, j + 27, k + 4, NovaCraftBlocks.cracked_basal_bricks, 0, 2);
		world.setBlock(i + 23, j + 27, k + 4, NovaCraftBlocks.cracked_basal_bricks, 0, 2);
		world.setBlock(i + 24, j + 27, k + 4, NovaCraftBlocks.basal_bricks, 0, 2);
		world.setBlock(i + 25, j + 27, k + 4, NovaCraftBlocks.basal_bricks, 0, 2);
		world.setBlock(i + 26, j + 27, k + 4, NovaCraftBlocks.basal_bricks, 0, 2);
		world.setBlock(i + 27, j + 27, k + 4, NovaCraftBlocks.cracked_basal_bricks, 0, 2);
		world.setBlock(i + 0, j + 27, k + 5, NovaCraftBlocks.cracked_basal_bricks, 0, 2);
		world.setBlock(i + 1, j + 27, k + 5, NovaCraftBlocks.cracked_basal_bricks, 0, 2);
		world.setBlock(i + 2, j + 27, k + 5, NovaCraftBlocks.basal_bricks, 0, 2);
		world.setBlock(i + 3, j + 27, k + 5, NovaCraftBlocks.cracked_basal_bricks, 0, 2);
		world.setBlock(i + 4, j + 27, k + 5, NovaCraftBlocks.basal_bricks, 0, 2);
		world.setBlock(i + 5, j + 27, k + 5, NovaCraftBlocks.basal_bricks, 0, 2);
		world.setBlock(i + 6, j + 27, k + 5, NovaCraftBlocks.basal_bricks, 0, 2);
		world.setBlock(i + 7, j + 27, k + 5, NovaCraftBlocks.basal_bricks, 0, 2);
		world.setBlock(i + 8, j + 27, k + 5, NovaCraftBlocks.basal_bricks, 0, 2);
		world.setBlock(i + 9, j + 27, k + 5, NovaCraftBlocks.basal_bricks, 0, 2);
		world.setBlock(i + 10, j + 27, k + 5, NovaCraftBlocks.basal_bricks, 0, 2);
		world.setBlock(i + 11, j + 27, k + 5, NovaCraftBlocks.cracked_basal_bricks, 0, 2);
		world.setBlock(i + 12, j + 27, k + 5, NovaCraftBlocks.cracked_basal_bricks, 0, 2);
		world.setBlock(i + 13, j + 27, k + 5, NovaCraftBlocks.cracked_basal_bricks, 0, 2);
		world.setBlock(i + 14, j + 27, k + 5, NovaCraftBlocks.basal_bricks, 0, 2);
		world.setBlock(i + 15, j + 27, k + 5, NovaCraftBlocks.cracked_basal_bricks, 0, 2);
		world.setBlock(i + 16, j + 27, k + 5, NovaCraftBlocks.basal_bricks, 0, 2);
		world.setBlock(i + 17, j + 27, k + 5, NovaCraftBlocks.basal_bricks, 0, 2);
		world.setBlock(i + 18, j + 27, k + 5, NovaCraftBlocks.basal_bricks, 0, 2);
		world.setBlock(i + 19, j + 27, k + 5, NovaCraftBlocks.basal_bricks, 0, 2);
		world.setBlock(i + 20, j + 27, k + 5, NovaCraftBlocks.basal_bricks, 0, 2);
		world.setBlock(i + 21, j + 27, k + 5, NovaCraftBlocks.basal_bricks, 0, 2);
		world.setBlock(i + 22, j + 27, k + 5, NovaCraftBlocks.basal_bricks, 0, 2);
		world.setBlock(i + 23, j + 27, k + 5, NovaCraftBlocks.basal_bricks, 0, 2);
		world.setBlock(i + 24, j + 27, k + 5, NovaCraftBlocks.basal_bricks, 0, 2);
		world.setBlock(i + 25, j + 27, k + 5, NovaCraftBlocks.basal_bricks, 0, 2);
		world.setBlock(i + 26, j + 27, k + 5, NovaCraftBlocks.cracked_basal_bricks, 0, 2);
		world.setBlock(i + 27, j + 27, k + 5, NovaCraftBlocks.cracked_basal_bricks, 0, 2);
		world.setBlock(i + 0, j + 27, k + 6, NovaCraftBlocks.cracked_basal_bricks, 0, 2);
		world.setBlock(i + 1, j + 27, k + 6, NovaCraftBlocks.basal_bricks, 0, 2);
		world.setBlock(i + 2, j + 27, k + 6, NovaCraftBlocks.basal_bricks, 0, 2);
		world.setBlock(i + 3, j + 27, k + 6, NovaCraftBlocks.basal_bricks, 0, 2);
		world.setBlock(i + 4, j + 27, k + 6, NovaCraftBlocks.basal_bricks, 0, 2);
		world.setBlock(i + 5, j + 27, k + 6, NovaCraftBlocks.basal_bricks, 0, 2);
		world.setBlock(i + 6, j + 27, k + 6, NovaCraftBlocks.cracked_basal_bricks, 0, 2);
		world.setBlock(i + 7, j + 27, k + 6, NovaCraftBlocks.basal_bricks, 0, 2);
		world.setBlock(i + 8, j + 27, k + 6, NovaCraftBlocks.cracked_basal_bricks, 0, 2);
		world.setBlock(i + 9, j + 27, k + 6, NovaCraftBlocks.basal_bricks, 0, 2);
		world.setBlock(i + 10, j + 27, k + 6, NovaCraftBlocks.basal_bricks, 0, 2);
		world.setBlock(i + 11, j + 27, k + 6, NovaCraftBlocks.cracked_basal_bricks, 0, 2);
		world.setBlock(i + 12, j + 27, k + 6, NovaCraftBlocks.basal_bricks, 0, 2);
		world.setBlock(i + 13, j + 27, k + 6, NovaCraftBlocks.basal_bricks, 0, 2);
		world.setBlock(i + 14, j + 27, k + 6, NovaCraftBlocks.basal_bricks, 0, 2);
		world.setBlock(i + 15, j + 27, k + 6, NovaCraftBlocks.cracked_basal_bricks, 0, 2);
		world.setBlock(i + 16, j + 27, k + 6, NovaCraftBlocks.basal_bricks, 0, 2);
		world.setBlock(i + 17, j + 27, k + 6, NovaCraftBlocks.cracked_basal_bricks, 0, 2);
		world.setBlock(i + 18, j + 27, k + 6, NovaCraftBlocks.cracked_basal_bricks, 0, 2);
		world.setBlock(i + 19, j + 27, k + 6, NovaCraftBlocks.cracked_basal_bricks, 0, 2);
		world.setBlock(i + 20, j + 27, k + 6, NovaCraftBlocks.cracked_basal_bricks, 0, 2);
		world.setBlock(i + 21, j + 27, k + 6, NovaCraftBlocks.basal_bricks, 0, 2);
		world.setBlock(i + 22, j + 27, k + 6, NovaCraftBlocks.cracked_basal_bricks, 0, 2);
		world.setBlock(i + 23, j + 27, k + 6, NovaCraftBlocks.cracked_basal_bricks, 0, 2);
		world.setBlock(i + 24, j + 27, k + 6, NovaCraftBlocks.cracked_basal_bricks, 0, 2);
		world.setBlock(i + 25, j + 27, k + 6, NovaCraftBlocks.basal_bricks, 0, 2);
		world.setBlock(i + 26, j + 27, k + 6, NovaCraftBlocks.cracked_basal_bricks, 0, 2);
		world.setBlock(i + 27, j + 27, k + 6, NovaCraftBlocks.basal_bricks, 0, 2);
		world.setBlock(i + 0, j + 27, k + 7, NovaCraftBlocks.cracked_basal_bricks, 0, 2);
		world.setBlock(i + 1, j + 27, k + 7, NovaCraftBlocks.cracked_basal_bricks, 0, 2);
		world.setBlock(i + 2, j + 27, k + 7, NovaCraftBlocks.cracked_basal_bricks, 0, 2);
		world.setBlock(i + 3, j + 27, k + 7, NovaCraftBlocks.basal_bricks, 0, 2);
		world.setBlock(i + 4, j + 27, k + 7, NovaCraftBlocks.basal_bricks, 0, 2);
		world.setBlock(i + 5, j + 27, k + 7, NovaCraftBlocks.basal_bricks, 0, 2);
		world.setBlock(i + 6, j + 27, k + 7, NovaCraftBlocks.basal_bricks, 0, 2);
		world.setBlock(i + 7, j + 27, k + 7, NovaCraftBlocks.basal_bricks, 0, 2);
		world.setBlock(i + 8, j + 27, k + 7, NovaCraftBlocks.basal_bricks, 0, 2);
		world.setBlock(i + 9, j + 27, k + 7, NovaCraftBlocks.basal_bricks, 0, 2);
		world.setBlock(i + 10, j + 27, k + 7, NovaCraftBlocks.basal_bricks, 0, 2);
		world.setBlock(i + 11, j + 27, k + 7, NovaCraftBlocks.basal_bricks, 0, 2);
		world.setBlock(i + 12, j + 27, k + 7, NovaCraftBlocks.cracked_basal_bricks, 0, 2);
		world.setBlock(i + 13, j + 27, k + 7, NovaCraftBlocks.cracked_basal_bricks, 0, 2);
		world.setBlock(i + 14, j + 27, k + 7, NovaCraftBlocks.basal_bricks, 0, 2);
		world.setBlock(i + 15, j + 27, k + 7, NovaCraftBlocks.basal_bricks, 0, 2);
		world.setBlock(i + 16, j + 27, k + 7, NovaCraftBlocks.basal_bricks, 0, 2);
		world.setBlock(i + 17, j + 27, k + 7, NovaCraftBlocks.basal_bricks, 0, 2);
		world.setBlock(i + 18, j + 27, k + 7, NovaCraftBlocks.basal_bricks, 0, 2);
		world.setBlock(i + 19, j + 27, k + 7, NovaCraftBlocks.basal_bricks, 0, 2);
		world.setBlock(i + 20, j + 27, k + 7, NovaCraftBlocks.cracked_basal_bricks, 0, 2);
		world.setBlock(i + 21, j + 27, k + 7, NovaCraftBlocks.basal_bricks, 0, 2);
		world.setBlock(i + 22, j + 27, k + 7, NovaCraftBlocks.basal_bricks, 0, 2);
		world.setBlock(i + 23, j + 27, k + 7, NovaCraftBlocks.cracked_basal_bricks, 0, 2);
		world.setBlock(i + 24, j + 27, k + 7, NovaCraftBlocks.basal_bricks, 0, 2);
		world.setBlock(i + 25, j + 27, k + 7, NovaCraftBlocks.cracked_basal_bricks, 0, 2);
		world.setBlock(i + 26, j + 27, k + 7, NovaCraftBlocks.basal_bricks, 0, 2);
		world.setBlock(i + 27, j + 27, k + 7, NovaCraftBlocks.basal_bricks, 0, 2);
		world.setBlock(i + 0, j + 27, k + 8, NovaCraftBlocks.basal_bricks, 0, 2);
		world.setBlock(i + 1, j + 27, k + 8, NovaCraftBlocks.basal_bricks, 0, 2);
		world.setBlock(i + 2, j + 27, k + 8, NovaCraftBlocks.cracked_basal_bricks, 0, 2);
		world.setBlock(i + 3, j + 27, k + 8, NovaCraftBlocks.cracked_basal_bricks, 0, 2);
		world.setBlock(i + 4, j + 27, k + 8, NovaCraftBlocks.cracked_basal_bricks, 0, 2);
		world.setBlock(i + 5, j + 27, k + 8, NovaCraftBlocks.basal_bricks, 0, 2);
		world.setBlock(i + 6, j + 27, k + 8, NovaCraftBlocks.cracked_basal_bricks, 0, 2);
		world.setBlock(i + 7, j + 27, k + 8, NovaCraftBlocks.cracked_basal_bricks, 0, 2);
		world.setBlock(i + 8, j + 27, k + 8, NovaCraftBlocks.cracked_basal_bricks, 0, 2);
		world.setBlock(i + 9, j + 27, k + 8, NovaCraftBlocks.basal_bricks, 0, 2);
		world.setBlock(i + 10, j + 27, k + 8, NovaCraftBlocks.basal_bricks, 0, 2);
		world.setBlock(i + 11, j + 27, k + 8, NovaCraftBlocks.basal_bricks, 0, 2);
		world.setBlock(i + 12, j + 27, k + 8, NovaCraftBlocks.cracked_basal_bricks, 0, 2);
		world.setBlock(i + 13, j + 27, k + 8, NovaCraftBlocks.basal_bricks, 0, 2);
		world.setBlock(i + 14, j + 27, k + 8, NovaCraftBlocks.cracked_basal_bricks, 0, 2);
		world.setBlock(i + 15, j + 27, k + 8, NovaCraftBlocks.cracked_basal_bricks, 0, 2);
		world.setBlock(i + 16, j + 27, k + 8, NovaCraftBlocks.basal_bricks, 0, 2);
		world.setBlock(i + 17, j + 27, k + 8, NovaCraftBlocks.basal_bricks, 0, 2);
		world.setBlock(i + 18, j + 27, k + 8, NovaCraftBlocks.basal_bricks, 0, 2);
		world.setBlock(i + 19, j + 27, k + 8, NovaCraftBlocks.basal_bricks, 0, 2);
		world.setBlock(i + 20, j + 27, k + 8, NovaCraftBlocks.cracked_basal_bricks, 0, 2);
		world.setBlock(i + 21, j + 27, k + 8, NovaCraftBlocks.cracked_basal_bricks, 0, 2);
		world.setBlock(i + 22, j + 27, k + 8, NovaCraftBlocks.cracked_basal_bricks, 0, 2);
		world.setBlock(i + 23, j + 27, k + 8, NovaCraftBlocks.cracked_basal_bricks, 0, 2);
		world.setBlock(i + 24, j + 27, k + 8, NovaCraftBlocks.basal_bricks, 0, 2);
		world.setBlock(i + 25, j + 27, k + 8, NovaCraftBlocks.cracked_basal_bricks, 0, 2);
		world.setBlock(i + 26, j + 27, k + 8, NovaCraftBlocks.basal_bricks, 0, 2);
		world.setBlock(i + 27, j + 27, k + 8, NovaCraftBlocks.basal_bricks, 0, 2);
		world.setBlock(i + 0, j + 27, k + 9, NovaCraftBlocks.cracked_basal_bricks, 0, 2);
		world.setBlock(i + 1, j + 27, k + 9, NovaCraftBlocks.basal_bricks, 0, 2);
		world.setBlock(i + 2, j + 27, k + 9, NovaCraftBlocks.cracked_basal_bricks, 0, 2);
		world.setBlock(i + 3, j + 27, k + 9, NovaCraftBlocks.cracked_basal_bricks, 0, 2);
		world.setBlock(i + 4, j + 27, k + 9, NovaCraftBlocks.cracked_basal_bricks, 0, 2);
		world.setBlock(i + 5, j + 27, k + 9, NovaCraftBlocks.basal_bricks, 0, 2);
		world.setBlock(i + 6, j + 27, k + 9, NovaCraftBlocks.basal_bricks, 0, 2);
		world.setBlock(i + 7, j + 27, k + 9, NovaCraftBlocks.cracked_basal_bricks, 0, 2);
		world.setBlock(i + 8, j + 27, k + 9, NovaCraftBlocks.basal_bricks, 0, 2);
		world.setBlock(i + 9, j + 27, k + 9, NovaCraftBlocks.basal_bricks, 0, 2);
		world.setBlock(i + 10, j + 27, k + 9, NovaCraftBlocks.cracked_basal_bricks, 0, 2);
		world.setBlock(i + 11, j + 27, k + 9, NovaCraftBlocks.basal_bricks, 0, 2);
		world.setBlock(i + 12, j + 27, k + 9, NovaCraftBlocks.cracked_basal_bricks, 0, 2);
		world.setBlock(i + 13, j + 27, k + 9, NovaCraftBlocks.basal_bricks, 0, 2);
		world.setBlock(i + 14, j + 27, k + 9, NovaCraftBlocks.basal_bricks, 0, 2);
		world.setBlock(i + 15, j + 27, k + 9, NovaCraftBlocks.basal_bricks, 0, 2);
		world.setBlock(i + 16, j + 27, k + 9, NovaCraftBlocks.cracked_basal_bricks, 0, 2);
		world.setBlock(i + 17, j + 27, k + 9, NovaCraftBlocks.basal_bricks, 0, 2);
		world.setBlock(i + 18, j + 27, k + 9, NovaCraftBlocks.cracked_basal_bricks, 0, 2);
		world.setBlock(i + 19, j + 27, k + 9, NovaCraftBlocks.basal_bricks, 0, 2);
		world.setBlock(i + 20, j + 27, k + 9, NovaCraftBlocks.basal_bricks, 0, 2);
		world.setBlock(i + 21, j + 27, k + 9, NovaCraftBlocks.cracked_basal_bricks, 0, 2);
		world.setBlock(i + 22, j + 27, k + 9, NovaCraftBlocks.basal_bricks, 0, 2);
		world.setBlock(i + 23, j + 27, k + 9, NovaCraftBlocks.basal_bricks, 0, 2);
		world.setBlock(i + 24, j + 27, k + 9, NovaCraftBlocks.cracked_basal_bricks, 0, 2);
		world.setBlock(i + 25, j + 27, k + 9, NovaCraftBlocks.basal_bricks, 0, 2);
		world.setBlock(i + 26, j + 27, k + 9, NovaCraftBlocks.basal_bricks, 0, 2);
		world.setBlock(i + 27, j + 27, k + 9, NovaCraftBlocks.basal_bricks, 0, 2);
		world.setBlock(i + 0, j + 27, k + 10, NovaCraftBlocks.cracked_basal_bricks, 0, 2);
		world.setBlock(i + 1, j + 27, k + 10, NovaCraftBlocks.basal_bricks, 0, 2);
		world.setBlock(i + 2, j + 27, k + 10, NovaCraftBlocks.cracked_basal_bricks, 0, 2);
		world.setBlock(i + 3, j + 27, k + 10, NovaCraftBlocks.cracked_basal_bricks, 0, 2);
		world.setBlock(i + 4, j + 27, k + 10, NovaCraftBlocks.basal_bricks, 0, 2);
		world.setBlock(i + 5, j + 27, k + 10, NovaCraftBlocks.basal_bricks, 0, 2);
		world.setBlock(i + 6, j + 27, k + 10, NovaCraftBlocks.basal_bricks, 0, 2);
		world.setBlock(i + 7, j + 27, k + 10, NovaCraftBlocks.basal_bricks, 0, 2);
		world.setBlock(i + 8, j + 27, k + 10, NovaCraftBlocks.basal_bricks, 0, 2);
		world.setBlock(i + 9, j + 27, k + 10, NovaCraftBlocks.basal_bricks, 0, 2);
		world.setBlock(i + 10, j + 27, k + 10, NovaCraftBlocks.basal_bricks, 0, 2);
		world.setBlock(i + 11, j + 27, k + 10, NovaCraftBlocks.basal_bricks, 0, 2);
		world.setBlock(i + 12, j + 27, k + 10, NovaCraftBlocks.cracked_basal_bricks, 0, 2);
		world.setBlock(i + 13, j + 27, k + 10, NovaCraftBlocks.basal_bricks, 0, 2);
		world.setBlock(i + 14, j + 27, k + 10, NovaCraftBlocks.basal_bricks, 0, 2);
		world.setBlock(i + 15, j + 27, k + 10, NovaCraftBlocks.basal_bricks, 0, 2);
		world.setBlock(i + 16, j + 27, k + 10, NovaCraftBlocks.cracked_basal_bricks, 0, 2);
		world.setBlock(i + 17, j + 27, k + 10, NovaCraftBlocks.cracked_basal_bricks, 0, 2);
		world.setBlock(i + 18, j + 27, k + 10, NovaCraftBlocks.basal_bricks, 0, 2);
		world.setBlock(i + 19, j + 27, k + 10, NovaCraftBlocks.cracked_basal_bricks, 0, 2);
		world.setBlock(i + 20, j + 27, k + 10, NovaCraftBlocks.basal_bricks, 0, 2);
		world.setBlock(i + 21, j + 27, k + 10, NovaCraftBlocks.cracked_basal_bricks, 0, 2);
		world.setBlock(i + 22, j + 27, k + 10, NovaCraftBlocks.basal_bricks, 0, 2);
		world.setBlock(i + 23, j + 27, k + 10, NovaCraftBlocks.cracked_basal_bricks, 0, 2);
		world.setBlock(i + 24, j + 27, k + 10, NovaCraftBlocks.basal_bricks, 0, 2);
		world.setBlock(i + 25, j + 27, k + 10, NovaCraftBlocks.cracked_basal_bricks, 0, 2);
		world.setBlock(i + 26, j + 27, k + 10, NovaCraftBlocks.basal_bricks, 0, 2);
		world.setBlock(i + 27, j + 27, k + 10, NovaCraftBlocks.cracked_basal_bricks, 0, 2);
		world.setBlock(i + 0, j + 27, k + 11, NovaCraftBlocks.basal_bricks, 0, 2);
		world.setBlock(i + 1, j + 27, k + 11, NovaCraftBlocks.basal_bricks, 0, 2);
		world.setBlock(i + 2, j + 27, k + 11, NovaCraftBlocks.basal_bricks, 0, 2);
		world.setBlock(i + 3, j + 27, k + 11, NovaCraftBlocks.basal_bricks, 0, 2);
		world.setBlock(i + 4, j + 27, k + 11, NovaCraftBlocks.basal_bricks, 0, 2);
		world.setBlock(i + 5, j + 27, k + 11, NovaCraftBlocks.basal_bricks, 0, 2);
		world.setBlock(i + 6, j + 27, k + 11, NovaCraftBlocks.basal_bricks, 0, 2);
		world.setBlock(i + 7, j + 27, k + 11, NovaCraftBlocks.basal_bricks, 0, 2);
		world.setBlock(i + 8, j + 27, k + 11, NovaCraftBlocks.basal_bricks, 0, 2);
		world.setBlock(i + 9, j + 27, k + 11, NovaCraftBlocks.basal_bricks, 0, 2);
		world.setBlock(i + 10, j + 27, k + 11, NovaCraftBlocks.basal_bricks, 0, 2);
		world.setBlock(i + 11, j + 27, k + 11, NovaCraftBlocks.basal_bricks, 0, 2);
		world.setBlock(i + 12, j + 27, k + 11, NovaCraftBlocks.basal_bricks, 0, 2);
		world.setBlock(i + 13, j + 27, k + 11, NovaCraftBlocks.basal_bricks, 0, 2);
		world.setBlock(i + 14, j + 27, k + 11, NovaCraftBlocks.cracked_basal_bricks, 0, 2);
		world.setBlock(i + 15, j + 27, k + 11, NovaCraftBlocks.cracked_basal_bricks, 0, 2);
		world.setBlock(i + 16, j + 27, k + 11, NovaCraftBlocks.basal_bricks, 0, 2);
		world.setBlock(i + 17, j + 27, k + 11, NovaCraftBlocks.basal_bricks, 0, 2);
		world.setBlock(i + 18, j + 27, k + 11, NovaCraftBlocks.basal_bricks, 0, 2);
		world.setBlock(i + 19, j + 27, k + 11, NovaCraftBlocks.basal_bricks, 0, 2);
		world.setBlock(i + 20, j + 27, k + 11, NovaCraftBlocks.basal_bricks, 0, 2);
		world.setBlock(i + 21, j + 27, k + 11, NovaCraftBlocks.cracked_basal_bricks, 0, 2);
		world.setBlock(i + 22, j + 27, k + 11, NovaCraftBlocks.basal_bricks, 0, 2);
		world.setBlock(i + 23, j + 27, k + 11, NovaCraftBlocks.basal_bricks, 0, 2);
		world.setBlock(i + 24, j + 27, k + 11, NovaCraftBlocks.cracked_basal_bricks, 0, 2);
		world.setBlock(i + 25, j + 27, k + 11, NovaCraftBlocks.basal_bricks, 0, 2);
		world.setBlock(i + 26, j + 27, k + 11, NovaCraftBlocks.basal_bricks, 0, 2);
		world.setBlock(i + 27, j + 27, k + 11, NovaCraftBlocks.basal_bricks, 0, 2);
		world.setBlock(i + 0, j + 27, k + 12, NovaCraftBlocks.cracked_basal_bricks, 0, 2);
		world.setBlock(i + 1, j + 27, k + 12, NovaCraftBlocks.cracked_basal_bricks, 0, 2);
		world.setBlock(i + 2, j + 27, k + 12, NovaCraftBlocks.cracked_basal_bricks, 0, 2);
		world.setBlock(i + 3, j + 27, k + 12, NovaCraftBlocks.cracked_basal_bricks, 0, 2);
		world.setBlock(i + 4, j + 27, k + 12, NovaCraftBlocks.basal_bricks, 0, 2);
		world.setBlock(i + 5, j + 27, k + 12, NovaCraftBlocks.basal_bricks, 0, 2);
		world.setBlock(i + 6, j + 27, k + 12, NovaCraftBlocks.basal_bricks, 0, 2);
		world.setBlock(i + 7, j + 27, k + 12, NovaCraftBlocks.basal_bricks, 0, 2);
		world.setBlock(i + 8, j + 27, k + 12, NovaCraftBlocks.basal_bricks, 0, 2);
		world.setBlock(i + 9, j + 27, k + 12, NovaCraftBlocks.basal_bricks, 0, 2);
		world.setBlock(i + 10, j + 27, k + 12, NovaCraftBlocks.cracked_basal_bricks, 0, 2);
		world.setBlock(i + 11, j + 27, k + 12, NovaCraftBlocks.basal_bricks, 0, 2);
		world.setBlock(i + 12, j + 27, k + 12, NovaCraftBlocks.basal_bricks, 0, 2);
		world.setBlock(i + 13, j + 27, k + 12, NovaCraftBlocks.cracked_basal_bricks, 0, 2);
		world.setBlock(i + 14, j + 27, k + 12, NovaCraftBlocks.basal_bricks, 0, 2);
		world.setBlock(i + 15, j + 27, k + 12, NovaCraftBlocks.basal_bricks, 0, 2);
		world.setBlock(i + 16, j + 27, k + 12, NovaCraftBlocks.cracked_basal_bricks, 0, 2);
		world.setBlock(i + 17, j + 27, k + 12, NovaCraftBlocks.cracked_basal_bricks, 0, 2);
		world.setBlock(i + 18, j + 27, k + 12, NovaCraftBlocks.cracked_basal_bricks, 0, 2);
		world.setBlock(i + 19, j + 27, k + 12, NovaCraftBlocks.basal_bricks, 0, 2);
		world.setBlock(i + 20, j + 27, k + 12, NovaCraftBlocks.cracked_basal_bricks, 0, 2);
		world.setBlock(i + 21, j + 27, k + 12, NovaCraftBlocks.cracked_basal_bricks, 0, 2);
		world.setBlock(i + 22, j + 27, k + 12, NovaCraftBlocks.basal_bricks, 0, 2);
		world.setBlock(i + 23, j + 27, k + 12, NovaCraftBlocks.cracked_basal_bricks, 0, 2);
		world.setBlock(i + 24, j + 27, k + 12, NovaCraftBlocks.cracked_basal_bricks, 0, 2);
		world.setBlock(i + 25, j + 27, k + 12, NovaCraftBlocks.basal_bricks, 0, 2);
		world.setBlock(i + 26, j + 27, k + 12, NovaCraftBlocks.cracked_basal_bricks, 0, 2);
		world.setBlock(i + 27, j + 27, k + 12, NovaCraftBlocks.cracked_basal_bricks, 0, 2);
		world.setBlock(i + 0, j + 27, k + 13, NovaCraftBlocks.basal_bricks, 0, 2);
		world.setBlock(i + 1, j + 27, k + 13, NovaCraftBlocks.basal_bricks, 0, 2);
		world.setBlock(i + 2, j + 27, k + 13, NovaCraftBlocks.basal_bricks, 0, 2);
		world.setBlock(i + 3, j + 27, k + 13, NovaCraftBlocks.basal_bricks, 0, 2);
		world.setBlock(i + 4, j + 27, k + 13, NovaCraftBlocks.basal_bricks, 0, 2);
		world.setBlock(i + 5, j + 27, k + 13, NovaCraftBlocks.cracked_basal_bricks, 0, 2);
		world.setBlock(i + 6, j + 27, k + 13, NovaCraftBlocks.basal_bricks, 0, 2);
		world.setBlock(i + 7, j + 27, k + 13, NovaCraftBlocks.cracked_basal_bricks, 0, 2);
		world.setBlock(i + 8, j + 27, k + 13, NovaCraftBlocks.basal_bricks, 0, 2);
		world.setBlock(i + 9, j + 27, k + 13, NovaCraftBlocks.cracked_basal_bricks, 0, 2);
		world.setBlock(i + 10, j + 27, k + 13, NovaCraftBlocks.basal_bricks, 0, 2);
		world.setBlock(i + 11, j + 27, k + 13, NovaCraftBlocks.basal_bricks, 0, 2);
		world.setBlock(i + 12, j + 27, k + 13, NovaCraftBlocks.basal_bricks, 0, 2);
		world.setBlock(i + 13, j + 27, k + 13, NovaCraftBlocks.basal_bricks, 0, 2);
		world.setBlock(i + 14, j + 27, k + 13, NovaCraftBlocks.basal_bricks, 0, 2);
		world.setBlock(i + 15, j + 27, k + 13, NovaCraftBlocks.cracked_basal_bricks, 0, 2);
		world.setBlock(i + 16, j + 27, k + 13, NovaCraftBlocks.cracked_basal_bricks, 0, 2);
		world.setBlock(i + 17, j + 27, k + 13, NovaCraftBlocks.basal_bricks, 0, 2);
		world.setBlock(i + 18, j + 27, k + 13, NovaCraftBlocks.basal_bricks, 0, 2);
		world.setBlock(i + 19, j + 27, k + 13, NovaCraftBlocks.cracked_basal_bricks, 0, 2);
		world.setBlock(i + 20, j + 27, k + 13, NovaCraftBlocks.cracked_basal_bricks, 0, 2);
		world.setBlock(i + 21, j + 27, k + 13, NovaCraftBlocks.cracked_basal_bricks, 0, 2);
		world.setBlock(i + 22, j + 27, k + 13, NovaCraftBlocks.basal_bricks, 0, 2);
		world.setBlock(i + 23, j + 27, k + 13, NovaCraftBlocks.cracked_basal_bricks, 0, 2);
		world.setBlock(i + 24, j + 27, k + 13, NovaCraftBlocks.cracked_basal_bricks, 0, 2);
		world.setBlock(i + 25, j + 27, k + 13, NovaCraftBlocks.basal_bricks, 0, 2);
		world.setBlock(i + 26, j + 27, k + 13, NovaCraftBlocks.basal_bricks, 0, 2);
		world.setBlock(i + 27, j + 27, k + 13, NovaCraftBlocks.basal_bricks, 0, 2);
		world.setBlock(i + 0, j + 27, k + 14, NovaCraftBlocks.cracked_basal_bricks, 0, 2);
		world.setBlock(i + 1, j + 27, k + 14, NovaCraftBlocks.basal_bricks, 0, 2);
		world.setBlock(i + 2, j + 27, k + 14, NovaCraftBlocks.basal_bricks, 0, 2);
		world.setBlock(i + 3, j + 27, k + 14, NovaCraftBlocks.basal_bricks, 0, 2);
		world.setBlock(i + 4, j + 27, k + 14, NovaCraftBlocks.basal_bricks, 0, 2);
		world.setBlock(i + 5, j + 27, k + 14, NovaCraftBlocks.basal_bricks, 0, 2);
		world.setBlock(i + 6, j + 27, k + 14, NovaCraftBlocks.basal_bricks, 0, 2);
		world.setBlock(i + 7, j + 27, k + 14, NovaCraftBlocks.basal_bricks, 0, 2);
		world.setBlock(i + 8, j + 27, k + 14, NovaCraftBlocks.basal_bricks, 0, 2);
		world.setBlock(i + 9, j + 27, k + 14, NovaCraftBlocks.basal_bricks, 0, 2);
		world.setBlock(i + 10, j + 27, k + 14, NovaCraftBlocks.basal_bricks, 0, 2);
		world.setBlock(i + 11, j + 27, k + 14, NovaCraftBlocks.basal_bricks, 0, 2);
		world.setBlock(i + 12, j + 27, k + 14, NovaCraftBlocks.basal_bricks, 0, 2);
		world.setBlock(i + 13, j + 27, k + 14, NovaCraftBlocks.basal_bricks, 0, 2);
		world.setBlock(i + 14, j + 27, k + 14, NovaCraftBlocks.cracked_basal_bricks, 0, 2);
		world.setBlock(i + 15, j + 27, k + 14, NovaCraftBlocks.basal_bricks, 0, 2);
		world.setBlock(i + 16, j + 27, k + 14, NovaCraftBlocks.cracked_basal_bricks, 0, 2);
		world.setBlock(i + 17, j + 27, k + 14, NovaCraftBlocks.cracked_basal_bricks, 0, 2);
		world.setBlock(i + 18, j + 27, k + 14, NovaCraftBlocks.basal_bricks, 0, 2);
		world.setBlock(i + 19, j + 27, k + 14, NovaCraftBlocks.basal_bricks, 0, 2);
		world.setBlock(i + 20, j + 27, k + 14, NovaCraftBlocks.basal_bricks, 0, 2);
		world.setBlock(i + 21, j + 27, k + 14, NovaCraftBlocks.cracked_basal_bricks, 0, 2);
		world.setBlock(i + 22, j + 27, k + 14, NovaCraftBlocks.cracked_basal_bricks, 0, 2);
		world.setBlock(i + 23, j + 27, k + 14, NovaCraftBlocks.cracked_basal_bricks, 0, 2);
		world.setBlock(i + 24, j + 27, k + 14, NovaCraftBlocks.cracked_basal_bricks, 0, 2);
		world.setBlock(i + 25, j + 27, k + 14, NovaCraftBlocks.basal_bricks, 0, 2);
		world.setBlock(i + 26, j + 27, k + 14, NovaCraftBlocks.basal_bricks, 0, 2);
		world.setBlock(i + 27, j + 27, k + 14, NovaCraftBlocks.basal_bricks, 0, 2);
		world.setBlock(i + 0, j + 27, k + 15, NovaCraftBlocks.cracked_basal_bricks, 0, 2);
		world.setBlock(i + 1, j + 27, k + 15, NovaCraftBlocks.cracked_basal_bricks, 0, 2);
		world.setBlock(i + 2, j + 27, k + 15, NovaCraftBlocks.basal_bricks, 0, 2);
		world.setBlock(i + 3, j + 27, k + 15, NovaCraftBlocks.basal_bricks, 0, 2);
		world.setBlock(i + 4, j + 27, k + 15, NovaCraftBlocks.basal_bricks, 0, 2);
		world.setBlock(i + 5, j + 27, k + 15, NovaCraftBlocks.basal_bricks, 0, 2);
		world.setBlock(i + 6, j + 27, k + 15, NovaCraftBlocks.cracked_basal_bricks, 0, 2);
		world.setBlock(i + 7, j + 27, k + 15, NovaCraftBlocks.basal_bricks, 0, 2);
		world.setBlock(i + 8, j + 27, k + 15, NovaCraftBlocks.basal_bricks, 0, 2);
		world.setBlock(i + 9, j + 27, k + 15, NovaCraftBlocks.basal_bricks, 0, 2);
		world.setBlock(i + 10, j + 27, k + 15, NovaCraftBlocks.basal_bricks, 0, 2);
		world.setBlock(i + 11, j + 27, k + 15, NovaCraftBlocks.basal_bricks, 0, 2);
		world.setBlock(i + 12, j + 27, k + 15, NovaCraftBlocks.cracked_basal_bricks, 0, 2);
		world.setBlock(i + 13, j + 27, k + 15, NovaCraftBlocks.cracked_basal_bricks, 0, 2);
		world.setBlock(i + 14, j + 27, k + 15, NovaCraftBlocks.basal_bricks, 0, 2);
		world.setBlock(i + 15, j + 27, k + 15, NovaCraftBlocks.basal_bricks, 0, 2);
		world.setBlock(i + 16, j + 27, k + 15, NovaCraftBlocks.basal_bricks, 0, 2);
		world.setBlock(i + 17, j + 27, k + 15, NovaCraftBlocks.basal_bricks, 0, 2);
		world.setBlock(i + 18, j + 27, k + 15, NovaCraftBlocks.cracked_basal_bricks, 0, 2);
		world.setBlock(i + 19, j + 27, k + 15, NovaCraftBlocks.cracked_basal_bricks, 0, 2);
		world.setBlock(i + 20, j + 27, k + 15, NovaCraftBlocks.basal_bricks, 0, 2);
		world.setBlock(i + 21, j + 27, k + 15, NovaCraftBlocks.cracked_basal_bricks, 0, 2);
		world.setBlock(i + 22, j + 27, k + 15, NovaCraftBlocks.basal_bricks, 0, 2);
		world.setBlock(i + 23, j + 27, k + 15, NovaCraftBlocks.basal_bricks, 0, 2);
		world.setBlock(i + 24, j + 27, k + 15, NovaCraftBlocks.basal_bricks, 0, 2);
		world.setBlock(i + 25, j + 27, k + 15, NovaCraftBlocks.basal_bricks, 0, 2);
		world.setBlock(i + 26, j + 27, k + 15, NovaCraftBlocks.basal_bricks, 0, 2);
		world.setBlock(i + 27, j + 27, k + 15, NovaCraftBlocks.basal_bricks, 0, 2);
		world.setBlock(i + 0, j + 27, k + 16, NovaCraftBlocks.cracked_basal_bricks, 0, 2);
		world.setBlock(i + 1, j + 27, k + 16, NovaCraftBlocks.basal_bricks, 0, 2);
		world.setBlock(i + 2, j + 27, k + 16, NovaCraftBlocks.basal_bricks, 0, 2);
		world.setBlock(i + 3, j + 27, k + 16, NovaCraftBlocks.basal_bricks, 0, 2);
		world.setBlock(i + 4, j + 27, k + 16, NovaCraftBlocks.cracked_basal_bricks, 0, 2);
		world.setBlock(i + 5, j + 27, k + 16, NovaCraftBlocks.cracked_basal_bricks, 0, 2);
		world.setBlock(i + 6, j + 27, k + 16, NovaCraftBlocks.basal_bricks, 0, 2);
		world.setBlock(i + 7, j + 27, k + 16, NovaCraftBlocks.basal_bricks, 0, 2);
		world.setBlock(i + 8, j + 27, k + 16, NovaCraftBlocks.basal_bricks, 0, 2);
		world.setBlock(i + 9, j + 27, k + 16, NovaCraftBlocks.basal_bricks, 0, 2);
		world.setBlock(i + 10, j + 27, k + 16, NovaCraftBlocks.basal_bricks, 0, 2);
		world.setBlock(i + 11, j + 27, k + 16, NovaCraftBlocks.basal_bricks, 0, 2);
		world.setBlock(i + 12, j + 27, k + 16, NovaCraftBlocks.cracked_basal_bricks, 0, 2);
		world.setBlock(i + 13, j + 27, k + 16, NovaCraftBlocks.cracked_basal_bricks, 0, 2);
		world.setBlock(i + 14, j + 27, k + 16, NovaCraftBlocks.cracked_basal_bricks, 0, 2);
		world.setBlock(i + 15, j + 27, k + 16, NovaCraftBlocks.basal_bricks, 0, 2);
		world.setBlock(i + 16, j + 27, k + 16, NovaCraftBlocks.basal_bricks, 0, 2);
		world.setBlock(i + 17, j + 27, k + 16, NovaCraftBlocks.cracked_basal_bricks, 0, 2);
		world.setBlock(i + 18, j + 27, k + 16, NovaCraftBlocks.cracked_basal_bricks, 0, 2);
		world.setBlock(i + 19, j + 27, k + 16, NovaCraftBlocks.basal_bricks, 0, 2);
		world.setBlock(i + 20, j + 27, k + 16, NovaCraftBlocks.basal_bricks, 0, 2);
		world.setBlock(i + 21, j + 27, k + 16, NovaCraftBlocks.basal_bricks, 0, 2);
		world.setBlock(i + 22, j + 27, k + 16, NovaCraftBlocks.cracked_basal_bricks, 0, 2);
		world.setBlock(i + 23, j + 27, k + 16, NovaCraftBlocks.basal_bricks, 0, 2);
		world.setBlock(i + 24, j + 27, k + 16, NovaCraftBlocks.basal_bricks, 0, 2);
		world.setBlock(i + 25, j + 27, k + 16, NovaCraftBlocks.basal_bricks, 0, 2);
		world.setBlock(i + 26, j + 27, k + 16, NovaCraftBlocks.cracked_basal_bricks, 0, 2);
		world.setBlock(i + 27, j + 27, k + 16, NovaCraftBlocks.cracked_basal_bricks, 0, 2);
		world.setBlock(i + 0, j + 27, k + 17, NovaCraftBlocks.basal_bricks, 0, 2);
		world.setBlock(i + 1, j + 27, k + 17, NovaCraftBlocks.basal_bricks, 0, 2);
		world.setBlock(i + 2, j + 27, k + 17, NovaCraftBlocks.basal_bricks, 0, 2);
		world.setBlock(i + 3, j + 27, k + 17, NovaCraftBlocks.cracked_basal_bricks, 0, 2);
		world.setBlock(i + 4, j + 27, k + 17, NovaCraftBlocks.basal_bricks, 0, 2);
		world.setBlock(i + 5, j + 27, k + 17, NovaCraftBlocks.basal_bricks, 0, 2);
		world.setBlock(i + 6, j + 27, k + 17, NovaCraftBlocks.basal_bricks, 0, 2);
		world.setBlock(i + 7, j + 27, k + 17, NovaCraftBlocks.cracked_basal_bricks, 0, 2);
		world.setBlock(i + 8, j + 27, k + 17, NovaCraftBlocks.basal_bricks, 0, 2);
		world.setBlock(i + 9, j + 27, k + 17, NovaCraftBlocks.cracked_basal_bricks, 0, 2);
		world.setBlock(i + 10, j + 27, k + 17, NovaCraftBlocks.basal_bricks, 0, 2);
		world.setBlock(i + 11, j + 27, k + 17, NovaCraftBlocks.cracked_basal_bricks, 0, 2);
		world.setBlock(i + 12, j + 27, k + 17, NovaCraftBlocks.basal_bricks, 0, 2);
		world.setBlock(i + 13, j + 27, k + 17, NovaCraftBlocks.cracked_basal_bricks, 0, 2);
		world.setBlock(i + 14, j + 27, k + 17, NovaCraftBlocks.basal_bricks, 0, 2);
		world.setBlock(i + 15, j + 27, k + 17, NovaCraftBlocks.basal_bricks, 0, 2);
		world.setBlock(i + 16, j + 27, k + 17, NovaCraftBlocks.basal_bricks, 0, 2);
		world.setBlock(i + 17, j + 27, k + 17, NovaCraftBlocks.basal_bricks, 0, 2);
		world.setBlock(i + 18, j + 27, k + 17, NovaCraftBlocks.basal_bricks, 0, 2);
		world.setBlock(i + 19, j + 27, k + 17, NovaCraftBlocks.basal_bricks, 0, 2);
		world.setBlock(i + 20, j + 27, k + 17, NovaCraftBlocks.cracked_basal_bricks, 0, 2);
		world.setBlock(i + 21, j + 27, k + 17, NovaCraftBlocks.cracked_basal_bricks, 0, 2);
