package com.NovaCraft.world.bastion.treasure;

import net.minecraft.world.gen.feature.*;
import net.minecraft.block.*;
import net.minecraft.world.*;
import java.util.*;

import com.NovaCraft.config.Configs;
import com.NovaCraft.entity.EntitySavageSerpent;
import com.NovaCraft.registry.OtherModBlocks;
import com.NovaCraftBlocks.NovaCraftBlocks;

import cpw.mods.fml.common.Loader;
import net.minecraft.init.*;

public class BastionTreasureBarracksGen4 extends WorldGenerator
{
	public BastionTreasureBarracksGen4() {

	}
    
    public boolean generate(final World world, final Random random, final int i, final int j, final int k) {
    	
    	world.setBlock(i + 0, j + 20, k + 3, NovaCraftBlocks.basal, 0, 2);
		world.setBlock(i + 1, j + 20, k + 3, NovaCraftBlocks.basal, 0, 2);
		world.setBlock(i + 2, j + 20, k + 3, NovaCraftBlocks.basal, 0, 2);
		world.setBlock(i + 3, j + 20, k + 3, NovaCraftBlocks.basal, 0, 2);
		world.setBlock(i + 4, j + 20, k + 3, NovaCraftBlocks.basal, 0, 2);
		world.setBlock(i + 5, j + 20, k + 3, NovaCraftBlocks.basal, 0, 2);
		world.setBlock(i + 6, j + 20, k + 3, NovaCraftBlocks.basal, 0, 2);
		world.setBlock(i + 7, j + 20, k + 3, NovaCraftBlocks.basal, 0, 2);
		world.setBlock(i + 8, j + 20, k + 3, NovaCraftBlocks.basal, 0, 2);
		world.setBlock(i + 9, j + 20, k + 3, NovaCraftBlocks.basal, 0, 2);
		world.setBlock(i + 10, j + 20, k + 3, NovaCraftBlocks.basal, 0, 2);
		world.setBlock(i + 11, j + 20, k + 3, NovaCraftBlocks.basal, 0, 2);
		world.setBlock(i + 12, j + 20, k + 3, NovaCraftBlocks.basal, 0, 2);
		world.setBlock(i + 13, j + 20, k + 3, NovaCraftBlocks.basal, 0, 2);
		world.setBlock(i + 18, j + 20, k + 3, NovaCraftBlocks.basal_scrap, 0, 2);
		world.setBlock(i + 19, j + 20, k + 3, NovaCraftBlocks.cracked_basal_bricks, 0, 2);
		world.setBlock(i + 22, j + 20, k + 3, NovaCraftBlocks.cracked_basal_bricks, 0, 2);
		world.setBlock(i + 23, j + 20, k + 3, NovaCraftBlocks.basal, 0, 2);
		world.setBlock(i + 0, j + 20, k + 4, NovaCraftBlocks.basal, 0, 2);
		world.setBlock(i + 1, j + 20, k + 4, NovaCraftBlocks.basal, 0, 2);
		world.setBlock(i + 2, j + 20, k + 4, NovaCraftBlocks.basal, 0, 2);
		world.setBlock(i + 3, j + 20, k + 4, NovaCraftBlocks.basal, 0, 2);
		world.setBlock(i + 4, j + 20, k + 4, NovaCraftBlocks.basal, 0, 2);
		world.setBlock(i + 5, j + 20, k + 4, NovaCraftBlocks.basal, 0, 2);
		world.setBlock(i + 6, j + 20, k + 4, NovaCraftBlocks.basal, 0, 2);
		world.setBlock(i + 7, j + 20, k + 4, NovaCraftBlocks.basal, 0, 2);
		world.setBlock(i + 8, j + 20, k + 4, NovaCraftBlocks.basal, 0, 2);
		world.setBlock(i + 9, j + 20, k + 4, NovaCraftBlocks.basal, 0, 2);
		world.setBlock(i + 10, j + 20, k + 4, NovaCraftBlocks.basal, 0, 2);
		world.setBlock(i + 11, j + 20, k + 4, NovaCraftBlocks.basal, 0, 2);
		world.setBlock(i + 12, j + 20, k + 4, NovaCraftBlocks.basal, 0, 2);
		world.setBlock(i + 13, j + 20, k + 4, NovaCraftBlocks.basal, 0, 2);
		world.setBlock(i + 14, j + 20, k + 4, NovaCraftBlocks.basal, 0, 2);
		world.setBlock(i + 15, j + 20, k + 4, Blocks.air, 0, 2);
		world.setBlock(i + 16, j + 20, k + 4, Blocks.air, 0, 2);
		world.setBlock(i + 17, j + 20, k + 4, NovaCraftBlocks.cracked_basal_bricks, 0, 2);
		world.setBlock(i + 18, j + 20, k + 4, NovaCraftBlocks.basal, 0, 2);
		world.setBlock(i + 19, j + 20, k + 4, NovaCraftBlocks.basal, 0, 2);
		world.setBlock(i + 20, j + 20, k + 4, NovaCraftBlocks.basal, 0, 2);
		world.setBlock(i + 21, j + 20, k + 4, NovaCraftBlocks.basal, 0, 2);
		world.setBlock(i + 22, j + 20, k + 4, NovaCraftBlocks.basal, 0, 2);
		world.setBlock(i + 23, j + 20, k + 4, NovaCraftBlocks.basal, 0, 2);
		world.setBlock(i + 24, j + 20, k + 4, NovaCraftBlocks.cracked_basal_bricks, 0, 2);
		world.setBlock(i + 25, j + 20, k + 4, NovaCraftBlocks.cracked_basal_bricks, 0, 2);
		world.setBlock(i + 26, j + 20, k + 4, NovaCraftBlocks.basal, 0, 2);
		world.setBlock(i + 27, j + 20, k + 4, NovaCraftBlocks.basal, 0, 2);
		world.setBlock(i + 0, j + 20, k + 5, NovaCraftBlocks.basal, 0, 2);
		world.setBlock(i + 1, j + 20, k + 5, NovaCraftBlocks.basal, 0, 2);
		world.setBlock(i + 2, j + 20, k + 5, NovaCraftBlocks.basal, 0, 2);
		world.setBlock(i + 3, j + 20, k + 5, NovaCraftBlocks.basal, 0, 2);
		world.setBlock(i + 4, j + 20, k + 5, NovaCraftBlocks.basal, 0, 2);
		world.setBlock(i + 5, j + 20, k + 5, NovaCraftBlocks.basal, 0, 2);
		world.setBlock(i + 6, j + 20, k + 5, NovaCraftBlocks.basal, 0, 2);
		world.setBlock(i + 7, j + 20, k + 5, NovaCraftBlocks.basal, 0, 2);
		world.setBlock(i + 8, j + 20, k + 5, NovaCraftBlocks.basal, 0, 2);
		world.setBlock(i + 9, j + 20, k + 5, NovaCraftBlocks.basal, 0, 2);
		world.setBlock(i + 10, j + 20, k + 5, NovaCraftBlocks.basal, 0, 2);
		world.setBlock(i + 11, j + 20, k + 5, NovaCraftBlocks.basal, 0, 2);
		world.setBlock(i + 12, j + 20, k + 5, NovaCraftBlocks.basal, 0, 2);
		world.setBlock(i + 13, j + 20, k + 5, NovaCraftBlocks.basal, 0, 2);
		world.setBlock(i + 14, j + 20, k + 5, NovaCraftBlocks.basal, 0, 2);
		world.setBlock(i + 15, j + 20, k + 5, NovaCraftBlocks.basal, 0, 2);
		world.setBlock(i + 16, j + 20, k + 5, NovaCraftBlocks.basal, 0, 2);
		world.setBlock(i + 17, j + 20, k + 5, NovaCraftBlocks.basal, 0, 2);
		world.setBlock(i + 18, j + 20, k + 5, NovaCraftBlocks.basal, 0, 2);
		world.setBlock(i + 19, j + 20, k + 5, NovaCraftBlocks.basal, 0, 2);
		world.setBlock(i + 20, j + 20, k + 5, NovaCraftBlocks.basal, 0, 2);
		world.setBlock(i + 21, j + 20, k + 5, NovaCraftBlocks.basal, 0, 2);
		world.setBlock(i + 22, j + 20, k + 5, NovaCraftBlocks.basal, 0, 2);
		world.setBlock(i + 23, j + 20, k + 5, NovaCraftBlocks.basal, 0, 2);
		world.setBlock(i + 24, j + 20, k + 5, NovaCraftBlocks.basal, 0, 2);
		world.setBlock(i + 25, j + 20, k + 5, NovaCraftBlocks.basal, 0, 2);
		world.setBlock(i + 26, j + 20, k + 5, NovaCraftBlocks.basal, 0, 2);
		world.setBlock(i + 27, j + 20, k + 5, NovaCraftBlocks.basal, 0, 2);
		world.setBlock(i + 0, j + 20, k + 6, NovaCraftBlocks.basal, 0, 2);
		world.setBlock(i + 1, j + 20, k + 6, NovaCraftBlocks.basal, 0, 2);
		world.setBlock(i + 2, j + 20, k + 6, NovaCraftBlocks.basal, 0, 2);
		world.setBlock(i + 3, j + 20, k + 6, NovaCraftBlocks.basal, 0, 2);
		world.setBlock(i + 4, j + 20, k + 6, NovaCraftBlocks.basal, 0, 2);
		world.setBlock(i + 5, j + 20, k + 6, NovaCraftBlocks.basal, 0, 2);
		world.setBlock(i + 6, j + 20, k + 6, NovaCraftBlocks.basal, 0, 2);
		world.setBlock(i + 7, j + 20, k + 6, NovaCraftBlocks.basal, 0, 2);
		world.setBlock(i + 8, j + 20, k + 6, Blocks.air, 0, 2);
		world.setBlock(i + 9, j + 20, k + 6, Blocks.air, 0, 2);
		world.setBlock(i + 10, j + 20, k + 6, NovaCraftBlocks.basal, 0, 2);
		world.setBlock(i + 11, j + 20, k + 6, NovaCraftBlocks.basal, 0, 2);
		world.setBlock(i + 12, j + 20, k + 6, NovaCraftBlocks.basal, 0, 2);
		world.setBlock(i + 13, j + 20, k + 6, NovaCraftBlocks.basal, 0, 2);
		world.setBlock(i + 14, j + 20, k + 6, NovaCraftBlocks.basal, 0, 2);
		world.setBlock(i + 15, j + 20, k + 6, NovaCraftBlocks.basal, 0, 2);
		world.setBlock(i + 16, j + 20, k + 6, NovaCraftBlocks.basal, 0, 2);
		world.setBlock(i + 17, j + 20, k + 6, NovaCraftBlocks.basal, 0, 2);
		world.setBlock(i + 18, j + 20, k + 6, NovaCraftBlocks.basal, 0, 2);
		world.setBlock(i + 19, j + 20, k + 6, NovaCraftBlocks.basal, 0, 2);
		world.setBlock(i + 20, j + 20, k + 6, NovaCraftBlocks.basal, 0, 2);
		world.setBlock(i + 21, j + 20, k + 6, NovaCraftBlocks.basal, 0, 2);
		world.setBlock(i + 22, j + 20, k + 6, NovaCraftBlocks.basal, 0, 2);
		world.setBlock(i + 23, j + 20, k + 6, NovaCraftBlocks.basal, 0, 2);
		world.setBlock(i + 24, j + 20, k + 6, NovaCraftBlocks.basal, 0, 2);
		world.setBlock(i + 25, j + 20, k + 6, NovaCraftBlocks.basal, 0, 2);
		world.setBlock(i + 26, j + 20, k + 6, NovaCraftBlocks.basal, 0, 2);
		world.setBlock(i + 27, j + 20, k + 6, NovaCraftBlocks.basal, 0, 2);
		world.setBlock(i + 0, j + 20, k + 7, NovaCraftBlocks.basal, 0, 2);
		world.setBlock(i + 1, j + 20, k + 7, NovaCraftBlocks.basal, 0, 2);
		world.setBlock(i + 2, j + 20, k + 7, NovaCraftBlocks.basal, 0, 2);
		world.setBlock(i + 3, j + 20, k + 7, NovaCraftBlocks.basal, 0, 2);
		world.setBlock(i + 4, j + 20, k + 7, NovaCraftBlocks.basal, 0, 2);
		world.setBlock(i + 5, j + 20, k + 7, NovaCraftBlocks.basal, 0, 2);
		world.setBlock(i + 6, j + 20, k + 7, NovaCraftBlocks.basal, 0, 2);
		world.setBlock(i + 7, j + 20, k + 7, Blocks.lava, 8, 2);
		world.setBlock(i + 8, j + 20, k + 7, Blocks.air, 0, 2);
		world.setBlock(i + 9, j + 20, k + 7, Blocks.air, 0, 2);
		world.setBlock(i + 10, j + 20, k + 7, NovaCraftBlocks.basal, 0, 2);
		world.setBlock(i + 11, j + 20, k + 7, NovaCraftBlocks.basal, 0, 2);
		world.setBlock(i + 12, j + 20, k + 7, NovaCraftBlocks.basal, 0, 2);
		world.setBlock(i + 13, j + 20, k + 7, NovaCraftBlocks.basal, 0, 2);
		world.setBlock(i + 14, j + 20, k + 7, NovaCraftBlocks.basal, 0, 2);
		world.setBlock(i + 15, j + 20, k + 7, NovaCraftBlocks.basal, 0, 2);
		world.setBlock(i + 16, j + 20, k + 7, NovaCraftBlocks.basal, 0, 2);
		world.setBlock(i + 17, j + 20, k + 7, NovaCraftBlocks.basal, 0, 2);
		world.setBlock(i + 18, j + 20, k + 7, NovaCraftBlocks.basal, 0, 2);
		world.setBlock(i + 19, j + 20, k + 7, NovaCraftBlocks.basal, 0, 2);
		world.setBlock(i + 20, j + 20, k + 7, NovaCraftBlocks.basal, 0, 2);
		world.setBlock(i + 21, j + 20, k + 7, NovaCraftBlocks.basal, 0, 2);
		world.setBlock(i + 22, j + 20, k + 7, NovaCraftBlocks.basal, 0, 2);
		world.setBlock(i + 23, j + 20, k + 7, NovaCraftBlocks.basal, 0, 2);
		world.setBlock(i + 24, j + 20, k + 7, NovaCraftBlocks.basal, 0, 2);
		world.setBlock(i + 25, j + 20, k + 7, NovaCraftBlocks.basal, 0, 2);
		world.setBlock(i + 26, j + 20, k + 7, NovaCraftBlocks.basal, 0, 2);
		world.setBlock(i + 27, j + 20, k + 7, NovaCraftBlocks.basal, 0, 2);
		world.setBlock(i + 0, j + 20, k + 8, Blocks.air, 0, 2);
		world.setBlock(i + 1, j + 20, k + 8, NovaCraftBlocks.cracked_basal_bricks, 0, 2);
		world.setBlock(i + 2, j + 20, k + 8, Blocks.air, 0, 2);
		world.setBlock(i + 3, j + 20, k + 8, NovaCraftBlocks.basal, 0, 2);
		world.setBlock(i + 4, j + 20, k + 8, NovaCraftBlocks.basal, 0, 2);
		world.setBlock(i + 5, j + 20, k + 8, NovaCraftBlocks.basal, 0, 2);
		world.setBlock(i + 6, j + 20, k + 8, NovaCraftBlocks.basal, 0, 2);
		world.setBlock(i + 7, j + 20, k + 8, Blocks.air, 0, 2);
		world.setBlock(i + 8, j + 20, k + 8, Blocks.air, 0, 2);
		world.setBlock(i + 9, j + 20, k + 8, Blocks.air, 0, 2);
		world.setBlock(i + 10, j + 20, k + 8, NovaCraftBlocks.basal, 0, 2);
		world.setBlock(i + 11, j + 20, k + 8, NovaCraftBlocks.basal, 0, 2);
		world.setBlock(i + 12, j + 20, k + 8, NovaCraftBlocks.basal, 0, 2);
		world.setBlock(i + 13, j + 20, k + 8, NovaCraftBlocks.cracked_basal_bricks, 0, 2);
		world.setBlock(i + 14, j + 20, k + 8, NovaCraftBlocks.basal, 0, 2);
		world.setBlock(i + 15, j + 20, k + 8, NovaCraftBlocks.basal, 0, 2);
		world.setBlock(i + 16, j + 20, k + 8, NovaCraftBlocks.basal, 0, 2);
		world.setBlock(i + 17, j + 20, k + 8, NovaCraftBlocks.basal, 0, 2);
		world.setBlock(i + 18, j + 20, k + 8, NovaCraftBlocks.basal, 0, 2);
		world.setBlock(i + 19, j + 20, k + 8, NovaCraftBlocks.basal, 0, 2);
		world.setBlock(i + 20, j + 20, k + 8, NovaCraftBlocks.basal, 0, 2);
		world.setBlock(i + 21, j + 20, k + 8, NovaCraftBlocks.basal, 0, 2);
		world.setBlock(i + 22, j + 20, k + 8, Blocks.air, 0, 2);
		world.setBlock(i + 23, j + 20, k + 8, Blocks.air, 0, 2);
		world.setBlock(i + 24, j + 20, k + 8, NovaCraftBlocks.basal, 0, 2);
		world.setBlock(i + 25, j + 20, k + 8, NovaCraftBlocks.basal, 0, 2);
		world.setBlock(i + 26, j + 20, k + 8, NovaCraftBlocks.basal, 0, 2);
		world.setBlock(i + 27, j + 20, k + 8, NovaCraftBlocks.basal, 0, 2);
		world.setBlock(i + 0, j + 20, k + 9, Blocks.air, 0, 2);
		world.setBlock(i + 1, j + 20, k + 9, Blocks.air, 0, 2);
		world.setBlock(i + 2, j + 20, k + 9, Blocks.air, 0, 2);
		world.setBlock(i + 3, j + 20, k + 9, NovaCraftBlocks.basal, 0, 2);
		world.setBlock(i + 4, j + 20, k + 9, NovaCraftBlocks.basal, 0, 2);
		world.setBlock(i + 5, j + 20, k + 9, NovaCraftBlocks.basal, 0, 2);
		world.setBlock(i + 6, j + 20, k + 9, NovaCraftBlocks.basal, 0, 2);
		world.setBlock(i + 7, j + 20, k + 9, Blocks.air, 0, 2);
		world.setBlock(i + 8, j + 20, k + 9, Blocks.air, 0, 2);
		world.setBlock(i + 9, j + 20, k + 9, NovaCraftBlocks.basal, 0, 2);
		world.setBlock(i + 10, j + 20, k + 9, NovaCraftBlocks.basal, 0, 2);
		world.setBlock(i + 11, j + 20, k + 9, NovaCraftBlocks.cracked_basal_bricks, 0, 2);
		world.setBlock(i + 12, j + 20, k + 9, Blocks.air, 0, 2);
		world.setBlock(i + 13, j + 20, k + 9, Blocks.air, 0, 2);
		world.setBlock(i + 14, j + 20, k + 9, NovaCraftBlocks.basal, 0, 2);
		world.setBlock(i + 15, j + 20, k + 9, NovaCraftBlocks.basal, 0, 2);
		world.setBlock(i + 16, j + 20, k + 9, NovaCraftBlocks.basal, 0, 2);
		world.setBlock(i + 17, j + 20, k + 9, NovaCraftBlocks.basal, 0, 2);
		world.setBlock(i + 18, j + 20, k + 9, NovaCraftBlocks.basal, 0, 2);
		world.setBlock(i + 19, j + 20, k + 9, NovaCraftBlocks.basal, 0, 2);
		world.setBlock(i + 20, j + 20, k + 9, NovaCraftBlocks.basal, 0, 2);
		world.setBlock(i + 21, j + 20, k + 9, Blocks.lava, 8, 2);
		world.setBlock(i + 22, j + 20, k + 9, Blocks.air, 0, 2);
		world.setBlock(i + 23, j + 20, k + 9, Blocks.air, 0, 2);
		world.setBlock(i + 24, j + 20, k + 9, NovaCraftBlocks.basal, 0, 2);
		world.setBlock(i + 25, j + 20, k + 9, NovaCraftBlocks.basal, 0, 2);
		world.setBlock(i + 26, j + 20, k + 9, NovaCraftBlocks.basal, 0, 2);
		world.setBlock(i + 27, j + 20, k + 9, NovaCraftBlocks.basal, 0, 2);
		world.setBlock(i + 0, j + 20, k + 10, Blocks.air, 0, 2);
		world.setBlock(i + 1, j + 20, k + 10, Blocks.air, 0, 2);
		world.setBlock(i + 2, j + 20, k + 10, Blocks.air, 0, 2);
		world.setBlock(i + 3, j + 20, k + 10, Blocks.air, 0, 2);
		world.setBlock(i + 4, j + 20, k + 10, NovaCraftBlocks.basal, 0, 2);
		world.setBlock(i + 5, j + 20, k + 10, NovaCraftBlocks.basal, 0, 2);
		world.setBlock(i + 6, j + 20, k + 10, NovaCraftBlocks.basal, 0, 2);
		world.setBlock(i + 7, j + 20, k + 10, NovaCraftBlocks.basal, 0, 2);
		world.setBlock(i + 8, j + 20, k + 10, NovaCraftBlocks.basal, 0, 2);
		world.setBlock(i + 9, j + 20, k + 10, NovaCraftBlocks.basal, 0, 2);
		world.setBlock(i + 10, j + 20, k + 10, NovaCraftBlocks.basal, 0, 2);
		world.setBlock(i + 11, j + 20, k + 10, Blocks.air, 0, 2);
		world.setBlock(i + 12, j + 20, k + 10, Blocks.air, 0, 2);
		world.setBlock(i + 13, j + 20, k + 10, Blocks.air, 0, 2);
		world.setBlock(i + 14, j + 20, k + 10, Blocks.air, 0, 2);
		world.setBlock(i + 15, j + 20, k + 10, NovaCraftBlocks.cracked_basal_bricks, 0, 2);
		world.setBlock(i + 16, j + 20, k + 10, Blocks.air, 0, 2);
		world.setBlock(i + 17, j + 20, k + 10, NovaCraftBlocks.basal, 0, 2);
		world.setBlock(i + 18, j + 20, k + 10, NovaCraftBlocks.basal, 0, 2);
		world.setBlock(i + 19, j + 20, k + 10, NovaCraftBlocks.basal, 0, 2);
		world.setBlock(i + 20, j + 20, k + 10, NovaCraftBlocks.basal, 0, 2);
		world.setBlock(i + 21, j + 20, k + 10, Blocks.air, 0, 2);
		world.setBlock(i + 22, j + 20, k + 10, Blocks.air, 0, 2);
		world.setBlock(i + 23, j + 20, k + 10, Blocks.air, 0, 2);
		world.setBlock(i + 24, j + 20, k + 10, NovaCraftBlocks.basal, 0, 2);
		world.setBlock(i + 25, j + 20, k + 10, NovaCraftBlocks.basal, 0, 2);
		world.setBlock(i + 26, j + 20, k + 10, NovaCraftBlocks.basal, 0, 2);
		world.setBlock(i + 27, j + 20, k + 10, NovaCraftBlocks.cracked_basal_bricks, 0, 2);
		world.setBlock(i + 0, j + 20, k + 11, Blocks.air, 0, 2);
		world.setBlock(i + 1, j + 20, k + 11, Blocks.air, 0, 2);
		world.setBlock(i + 2, j + 20, k + 11, Blocks.air, 0, 2);
		world.setBlock(i + 3, j + 20, k + 11, NovaCraftBlocks.cracked_basal_bricks, 0, 2);
		world.setBlock(i + 4, j + 20, k + 11, NovaCraftBlocks.cracked_basal_bricks, 0, 2);
		world.setBlock(i + 5, j + 20, k + 11, NovaCraftBlocks.cracked_basal_bricks, 0, 2);
		world.setBlock(i + 6, j + 20, k + 11, NovaCraftBlocks.cracked_basal_bricks, 0, 2);
		world.setBlock(i + 7, j + 20, k + 11, NovaCraftBlocks.basal_bricks, 0, 2);
		world.setBlock(i + 8, j + 20, k + 11, NovaCraftBlocks.cracked_basal_bricks, 0, 2);
		world.setBlock(i + 9, j + 20, k + 11, NovaCraftBlocks.basal_bricks, 0, 2);
		world.setBlock(i + 10, j + 20, k + 11, NovaCraftBlocks.basal_bricks, 0, 2);
		world.setBlock(i + 11, j + 20, k + 11, NovaCraftBlocks.cracked_basal_bricks, 0, 2);
		world.setBlock(i + 12, j + 20, k + 11, NovaCraftBlocks.basal_bricks, 0, 2);
		world.setBlock(i + 13, j + 20, k + 11, NovaCraftBlocks.basal_bricks, 0, 2);
		world.setBlock(i + 14, j + 20, k + 11, Blocks.air, 0, 2);
		world.setBlock(i + 15, j + 20, k + 11, Blocks.air, 0, 2);
		world.setBlock(i + 16, j + 20, k + 11, Blocks.air, 0, 2);
		world.setBlock(i + 17, j + 20, k + 11, NovaCraftBlocks.basal, 0, 2);
		world.setBlock(i + 18, j + 20, k + 11, NovaCraftBlocks.basal, 0, 2);
		world.setBlock(i + 19, j + 20, k + 11, NovaCraftBlocks.basal, 0, 2);
		world.setBlock(i + 20, j + 20, k + 11, NovaCraftBlocks.basal, 0, 2);
		world.setBlock(i + 21, j + 20, k + 11, Blocks.air, 0, 2);
		world.setBlock(i + 22, j + 20, k + 11, Blocks.air, 0, 2);
		world.setBlock(i + 23, j + 20, k + 11, NovaCraftBlocks.basal, 0, 2);
		world.setBlock(i + 24, j + 20, k + 11, NovaCraftBlocks.basal, 0, 2);
		world.setBlock(i + 25, j + 20, k + 11, NovaCraftBlocks.cracked_basal_bricks, 0, 2);
		world.setBlock(i + 26, j + 20, k + 11, Blocks.air, 0, 2);
		world.setBlock(i + 27, j + 20, k + 11, Blocks.air, 0, 2);
		world.setBlock(i + 0, j + 20, k + 12, Blocks.air, 0, 2);
		world.setBlock(i + 1, j + 20, k + 12, NovaCraftBlocks.basal_bricks, 0, 2);
		world.setBlock(i + 2, j + 20, k + 12, NovaCraftBlocks.cracked_basal_bricks, 0, 2);
		world.setBlock(i + 3, j + 20, k + 12, NovaCraftBlocks.cracked_basal_bricks, 0, 2);
		world.setBlock(i + 4, j + 20, k + 12, NovaCraftBlocks.basal_bricks, 0, 2);
		world.setBlock(i + 5, j + 20, k + 12, NovaCraftBlocks.cracked_basal_bricks, 0, 2);
		world.setBlock(i + 6, j + 20, k + 12, NovaCraftBlocks.cracked_basal_bricks, 0, 2);
		world.setBlock(i + 7, j + 20, k + 12, NovaCraftBlocks.cracked_basal_bricks, 0, 2);
		world.setBlock(i + 8, j + 20, k + 12, NovaCraftBlocks.basal_bricks, 0, 2);
		world.setBlock(i + 9, j + 20, k + 12, NovaCraftBlocks.basal_bricks, 0, 2);
		world.setBlock(i + 10, j + 20, k + 12, NovaCraftBlocks.cracked_basal_bricks, 0, 2);
		world.setBlock(i + 11, j + 20, k + 12, NovaCraftBlocks.basal_bricks, 0, 2);
		world.setBlock(i + 12, j + 20, k + 12, NovaCraftBlocks.basal_bricks, 0, 2);
		world.setBlock(i + 13, j + 20, k + 12, NovaCraftBlocks.basal_bricks, 0, 2);
		world.setBlock(i + 14, j + 20, k + 12, Blocks.air, 0, 2);
		world.setBlock(i + 15, j + 20, k + 12, Blocks.air, 0, 2);
		world.setBlock(i + 16, j + 20, k + 12, Blocks.air, 0, 2);
		world.setBlock(i + 17, j + 20, k + 12, Blocks.air, 0, 2);
		world.setBlock(i + 18, j + 20, k + 12, NovaCraftBlocks.basal, 0, 2);
		world.setBlock(i + 19, j + 20, k + 12, NovaCraftBlocks.basal, 0, 2);
		world.setBlock(i + 20, j + 20, k + 12, NovaCraftBlocks.basal, 0, 2);
		world.setBlock(i + 21, j + 20, k + 12, NovaCraftBlocks.basal, 0, 2);
		world.setBlock(i + 22, j + 20, k + 12, NovaCraftBlocks.basal, 0, 2);
		world.setBlock(i + 23, j + 20, k + 12, NovaCraftBlocks.basal, 0, 2);
		world.setBlock(i + 24, j + 20, k + 12, NovaCraftBlocks.basal, 0, 2);
		world.setBlock(i + 25, j + 20, k + 12, Blocks.air, 0, 2);
		world.setBlock(i + 26, j + 20, k + 12, Blocks.air, 0, 2);
		world.setBlock(i + 27, j + 20, k + 12, Blocks.air, 0, 2);
		world.setBlock(i + 0, j + 21, k + 1, NovaCraftBlocks.basal, 0, 2);
		world.setBlock(i + 1, j + 21, k + 1, NovaCraftBlocks.basal_scrap, 0, 2);
		world.setBlock(i + 4, j + 21, k + 1, NovaCraftBlocks.basal_scrap, 0, 2);
		world.setBlock(i + 5, j + 21, k + 1, NovaCraftBlocks.basal_scrap, 0, 2);
		world.setBlock(i + 8, j + 21, k + 1, NovaCraftBlocks.cracked_basal_bricks, 0, 2);
		world.setBlock(i + 9, j + 21, k + 1, NovaCraftBlocks.basal, 0, 2);
		world.setBlock(i + 12, j + 21, k + 1, NovaCraftBlocks.basal, 0, 2);
		world.setBlock(i + 13, j + 21, k + 1, NovaCraftBlocks.basal, 0, 2);
		world.setBlock(i + 0, j + 21, k + 2, NovaCraftBlocks.basal, 0, 2);
		world.setBlock(i + 1, j + 21, k + 2, NovaCraftBlocks.basal, 0, 2);
		world.setBlock(i + 3, j + 21, k + 2, NovaCraftBlocks.cracked_basal_bricks, 0, 2);
		world.setBlock(i + 4, j + 21, k + 2, NovaCraftBlocks.basal, 0, 2);
		world.setBlock(i + 6, j + 21, k + 2, NovaCraftBlocks.cracked_basal_bricks, 0, 2);
		world.setBlock(i + 7, j + 21, k + 2, NovaCraftBlocks.basal, 0, 2);
		world.setBlock(i + 8, j + 21, k + 2, NovaCraftBlocks.basal, 0, 2);
		world.setBlock(i + 9, j + 21, k + 2, NovaCraftBlocks.basal, 0, 2);
		world.setBlock(i + 10, j + 21, k + 2, NovaCraftBlocks.cracked_basal_bricks, 0, 2);
		world.setBlock(i + 11, j + 21, k + 2, NovaCraftBlocks.cracked_basal_bricks, 0, 2);
		world.setBlock(i + 12, j + 21, k + 2, NovaCraftBlocks.basal, 0, 2);
		world.setBlock(i + 13, j + 21, k + 2, NovaCraftBlocks.basal, 0, 2);
		world.setBlock(i + 0, j + 21, k + 3, NovaCraftBlocks.basal, 0, 2);
		world.setBlock(i + 1, j + 21, k + 3, NovaCraftBlocks.basal, 0, 2);
		world.setBlock(i + 2, j + 21, k + 3, NovaCraftBlocks.basal, 0, 2);
		world.setBlock(i + 3, j + 21, k + 3, NovaCraftBlocks.glowing_basal, 0, 2);
		world.setBlock(i + 4, j + 21, k + 3, NovaCraftBlocks.basal, 0, 2);
		world.setBlock(i + 5, j + 21, k + 3, NovaCraftBlocks.basal, 0, 2);
		world.setBlock(i + 6, j + 21, k + 3, NovaCraftBlocks.basal, 0, 2);
		world.setBlock(i + 7, j + 21, k + 3, NovaCraftBlocks.basal, 0, 2);
		world.setBlock(i + 8, j + 21, k + 3, NovaCraftBlocks.basal, 0, 2);
		world.setBlock(i + 9, j + 21, k + 3, NovaCraftBlocks.basal, 0, 2);
		world.setBlock(i + 10, j + 21, k + 3, NovaCraftBlocks.basal, 0, 2);
		world.setBlock(i + 11, j + 21, k + 3, NovaCraftBlocks.basal, 0, 2);
		world.setBlock(i + 12, j + 21, k + 3, NovaCraftBlocks.basal, 0, 2);
		world.setBlock(i + 13, j + 21, k + 3, NovaCraftBlocks.basal, 0, 2);
		world.setBlock(i + 14, j + 21, k + 3, NovaCraftBlocks.basal, 0, 2);
		world.setBlock(i + 15, j + 21, k + 3, NovaCraftBlocks.basal_scrap, 0, 2);
		world.setBlock(i + 18, j + 21, k + 3, NovaCraftBlocks.basal_scrap, 0, 2);
		world.setBlock(i + 19, j + 21, k + 3, NovaCraftBlocks.basal_scrap, 0, 2);
		world.setBlock(i + 22, j + 21, k + 3, NovaCraftBlocks.cracked_basal_bricks, 0, 2);
		world.setBlock(i + 23, j + 21, k + 3, NovaCraftBlocks.basal, 0, 2);
		world.setBlock(i + 26, j + 21, k + 3, NovaCraftBlocks.basal, 0, 2);
		world.setBlock(i + 27, j + 21, k + 3, NovaCraftBlocks.basal, 0, 2);
		world.setBlock(i + 0, j + 21, k + 4, NovaCraftBlocks.basal, 0, 2);
		world.setBlock(i + 1, j + 21, k + 4, NovaCraftBlocks.basal, 0, 2);
		world.setBlock(i + 2, j + 21, k + 4, NovaCraftBlocks.basal, 0, 2);
		world.setBlock(i + 3, j + 21, k + 4, NovaCraftBlocks.basal, 0, 2);
		world.setBlock(i + 4, j + 21, k + 4, NovaCraftBlocks.basal, 0, 2);
		world.setBlock(i + 5, j + 21, k + 4, NovaCraftBlocks.basal, 0, 2);
		world.setBlock(i + 6, j + 21, k + 4, NovaCraftBlocks.basal, 0, 2);
		world.setBlock(i + 7, j + 21, k + 4, NovaCraftBlocks.basal, 0, 2);
		world.setBlock(i + 8, j + 21, k + 4, NovaCraftBlocks.basal, 0, 2);
		world.setBlock(i + 9, j + 21, k + 4, NovaCraftBlocks.basal, 0, 2);
		world.setBlock(i + 10, j + 21, k + 4, NovaCraftBlocks.basal, 0, 2);
		world.setBlock(i + 11, j + 21, k + 4, NovaCraftBlocks.basal, 0, 2);
		world.setBlock(i + 12, j + 21, k + 4, NovaCraftBlocks.basal, 0, 2);
		world.setBlock(i + 13, j + 21, k + 4, NovaCraftBlocks.basal, 0, 2);
		world.setBlock(i + 14, j + 21, k + 4, NovaCraftBlocks.basal, 0, 2);
		world.setBlock(i + 15, j + 21, k + 4, NovaCraftBlocks.basal, 0, 2);
		world.setBlock(i + 16, j + 21, k + 4, Blocks.air, 0, 2);
		world.setBlock(i + 17, j + 21, k + 4, NovaCraftBlocks.cracked_basal_bricks, 0, 2);
		world.setBlock(i + 18, j + 21, k + 4, NovaCraftBlocks.basal, 0, 2);
		world.setBlock(i + 19, j + 21, k + 4, Blocks.air, 0, 2);
		world.setBlock(i + 20, j + 21, k + 4, NovaCraftBlocks.cracked_basal_bricks, 0, 2);
		world.setBlock(i + 21, j + 21, k + 4, NovaCraftBlocks.basal, 0, 2);
		world.setBlock(i + 22, j + 21, k + 4, NovaCraftBlocks.basal, 0, 2);
		world.setBlock(i + 23, j + 21, k + 4, NovaCraftBlocks.basal, 0, 2);
		world.setBlock(i + 24, j + 21, k + 4, NovaCraftBlocks.cracked_basal_bricks, 0, 2);
		world.setBlock(i + 25, j + 21, k + 4, NovaCraftBlocks.cracked_basal_bricks, 0, 2);
		world.setBlock(i + 26, j + 21, k + 4, NovaCraftBlocks.basal, 0, 2);
		world.setBlock(i + 27, j + 21, k + 4, NovaCraftBlocks.basal, 0, 2);
		world.setBlock(i + 0, j + 21, k + 5, NovaCraftBlocks.basal, 0, 2);
		world.setBlock(i + 1, j + 21, k + 5, NovaCraftBlocks.basal, 0, 2);
		world.setBlock(i + 2, j + 21, k + 5, NovaCraftBlocks.basal, 0, 2);
		world.setBlock(i + 3, j + 21, k + 5, NovaCraftBlocks.basal, 0, 2);
		world.setBlock(i + 4, j + 21, k + 5, NovaCraftBlocks.basal, 0, 2);
		world.setBlock(i + 5, j + 21, k + 5, NovaCraftBlocks.basal, 0, 2);
		world.setBlock(i + 6, j + 21, k + 5, NovaCraftBlocks.basal, 0, 2);
		world.setBlock(i + 7, j + 21, k + 5, NovaCraftBlocks.basal, 0, 2);
		world.setBlock(i + 8, j + 21, k + 5, Blocks.air, 0, 2);
		world.setBlock(i + 9, j + 21, k + 5, Blocks.air, 0, 2);
		world.setBlock(i + 10, j + 21, k + 5, NovaCraftBlocks.basal, 0, 2);
		world.setBlock(i + 11, j + 21, k + 5, NovaCraftBlocks.basal, 0, 2);
		world.setBlock(i + 12, j + 21, k + 5, NovaCraftBlocks.basal, 0, 2);
		world.setBlock(i + 13, j + 21, k + 5, NovaCraftBlocks.basal, 0, 2);
		world.setBlock(i + 14, j + 21, k + 5, NovaCraftBlocks.basal, 0, 2);
		world.setBlock(i + 15, j + 21, k + 5, NovaCraftBlocks.basal, 0, 2);
		world.setBlock(i + 16, j + 21, k + 5, NovaCraftBlocks.basal, 0, 2);
		world.setBlock(i + 17, j + 21, k + 5, NovaCraftBlocks.basal, 0, 2);
		world.setBlock(i + 18, j + 21, k + 5, NovaCraftBlocks.basal, 0, 2);
		world.setBlock(i + 19, j + 21, k + 5, NovaCraftBlocks.basal, 0, 2);
		world.setBlock(i + 20, j + 21, k + 5, NovaCraftBlocks.basal, 0, 2);
		world.setBlock(i + 21, j + 21, k + 5, NovaCraftBlocks.basal, 0, 2);
		world.setBlock(i + 22, j + 21, k + 5, NovaCraftBlocks.basal, 0, 2);
		world.setBlock(i + 23, j + 21, k + 5, NovaCraftBlocks.basal, 0, 2);
		world.setBlock(i + 24, j + 21, k + 5, NovaCraftBlocks.basal, 0, 2);
		world.setBlock(i + 25, j + 21, k + 5, NovaCraftBlocks.basal, 0, 2);
		world.setBlock(i + 26, j + 21, k + 5, NovaCraftBlocks.basal, 0, 2);
		world.setBlock(i + 27, j + 21, k + 5, NovaCraftBlocks.basal, 0, 2);
		world.setBlock(i + 0, j + 21, k + 6, NovaCraftBlocks.basal, 0, 2);
		world.setBlock(i + 1, j + 21, k + 6, NovaCraftBlocks.basal, 0, 2);
		world.setBlock(i + 2, j + 21, k + 6, NovaCraftBlocks.basal, 0, 2);
		world.setBlock(i + 3, j + 21, k + 6, NovaCraftBlocks.basal, 0, 2);
		world.setBlock(i + 4, j + 21, k + 6, NovaCraftBlocks.basal, 0, 2);
		world.setBlock(i + 5, j + 21, k + 6, NovaCraftBlocks.basal, 0, 2);
		world.setBlock(i + 6, j + 21, k + 6, NovaCraftBlocks.basal, 0, 2);
		world.setBlock(i + 7, j + 21, k + 6, NovaCraftBlocks.basal, 0, 2);
		world.setBlock(i + 8, j + 21, k + 6, Blocks.air, 0, 2);
		world.setBlock(i + 9, j + 21, k + 6, Blocks.air, 0, 2);
		world.setBlock(i + 10, j + 21, k + 6, NovaCraftBlocks.basal, 0, 2);
		world.setBlock(i + 11, j + 21, k + 6, NovaCraftBlocks.basal, 0, 2);
		world.setBlock(i + 12, j + 21, k + 6, NovaCraftBlocks.basal, 0, 2);
		world.setBlock(i + 13, j + 21, k + 6, NovaCraftBlocks.basal, 0, 2);
		world.setBlock(i + 14, j + 21, k + 6, NovaCraftBlocks.basal, 0, 2);
		world.setBlock(i + 15, j + 21, k + 6, NovaCraftBlocks.basal, 0, 2);
		world.setBlock(i + 16, j + 21, k + 6, NovaCraftBlocks.basal, 0, 2);
		world.setBlock(i + 17, j + 21, k + 6, NovaCraftBlocks.basal, 0, 2);
		world.setBlock(i + 18, j + 21, k + 6, NovaCraftBlocks.basal, 0, 2);
		world.setBlock(i + 19, j + 21, k + 6, NovaCraftBlocks.basal, 0, 2);
		world.setBlock(i + 20, j + 21, k + 6, NovaCraftBlocks.basal, 0, 2);
		world.setBlock(i + 21, j + 21, k + 6, NovaCraftBlocks.basal, 0, 2);
		world.setBlock(i + 22, j + 21, k + 6, NovaCraftBlocks.basal, 0, 2);
		world.setBlock(i + 23, j + 21, k + 6, NovaCraftBlocks.basal, 0, 2);
		world.setBlock(i + 24, j + 21, k + 6, NovaCraftBlocks.basal, 0, 2);
		world.setBlock(i + 25, j + 21, k + 6, NovaCraftBlocks.basal, 0, 2);
		world.setBlock(i + 26, j + 21, k + 6, NovaCraftBlocks.basal, 0, 2);
		world.setBlock(i + 27, j + 21, k + 6, NovaCraftBlocks.basal, 0, 2);
		world.setBlock(i + 0, j + 21, k + 7, NovaCraftBlocks.basal, 0, 2);
		world.setBlock(i + 1, j + 21, k + 7, NovaCraftBlocks.glowing_basal, 0, 2);
		world.setBlock(i + 2, j + 21, k + 7, NovaCraftBlocks.basal, 0, 2);
		world.setBlock(i + 3, j + 21, k + 7, NovaCraftBlocks.basal, 0, 2);
		world.setBlock(i + 4, j + 21, k + 7, NovaCraftBlocks.basal, 0, 2);
		world.setBlock(i + 5, j + 21, k + 7, NovaCraftBlocks.basal, 0, 2);
		world.setBlock(i + 6, j + 21, k + 7, NovaCraftBlocks.basal, 0, 2);
		world.setBlock(i + 7, j + 21, k + 7, Blocks.lava, 8, 2);
		world.setBlock(i + 8, j + 21, k + 7, Blocks.air, 0, 2);
		world.setBlock(i + 9, j + 21, k + 7, Blocks.air, 0, 2);
		world.setBlock(i + 10, j + 21, k + 7, NovaCraftBlocks.basal, 0, 2);
		world.setBlock(i + 11, j + 21, k + 7, NovaCraftBlocks.basal, 0, 2);
		world.setBlock(i + 12, j + 21, k + 7, NovaCraftBlocks.basal, 0, 2);
		world.setBlock(i + 13, j + 21, k + 7, Blocks.air, 0, 2);
		world.setBlock(i + 14, j + 21, k + 7, NovaCraftBlocks.basal, 0, 2);
		world.setBlock(i + 15, j + 21, k + 7, NovaCraftBlocks.basal, 0, 2);
		world.setBlock(i + 16, j + 21, k + 7, NovaCraftBlocks.basal, 0, 2);
		world.setBlock(i + 17, j + 21, k + 7, NovaCraftBlocks.basal, 0, 2);
		world.setBlock(i + 18, j + 21, k + 7, NovaCraftBlocks.basal, 0, 2);
		world.setBlock(i + 19, j + 21, k + 7, NovaCraftBlocks.basal, 0, 2);
		world.setBlock(i + 20, j + 21, k + 7, NovaCraftBlocks.basal, 0, 2);
		world.setBlock(i + 21, j + 21, k + 7, NovaCraftBlocks.basal, 0, 2);
		world.setBlock(i + 22, j + 21, k + 7, Blocks.air, 0, 2);
		world.setBlock(i + 23, j + 21, k + 7, Blocks.air, 0, 2);
		world.setBlock(i + 24, j + 21, k + 7, NovaCraftBlocks.basal, 0, 2);
		world.setBlock(i + 25, j + 21, k + 7, NovaCraftBlocks.basal, 0, 2);
		world.setBlock(i + 26, j + 21, k + 7, NovaCraftBlocks.basal, 0, 2);
		world.setBlock(i + 27, j + 21, k + 7, NovaCraftBlocks.basal, 0, 2);
		world.setBlock(i + 0, j + 21, k + 8, Blocks.air, 0, 2);
		world.setBlock(i + 1, j + 21, k + 8, Blocks.air, 0, 2);
		world.setBlock(i + 2, j + 21, k + 8, NovaCraftBlocks.basal, 0, 2);
		world.setBlock(i + 3, j + 21, k + 8, NovaCraftBlocks.basal, 0, 2);
		world.setBlock(i + 4, j + 21, k + 8, NovaCraftBlocks.basal, 0, 2);
		world.setBlock(i + 5, j + 21, k + 8, NovaCraftBlocks.basal, 0, 2);
		world.setBlock(i + 6, j + 21, k + 8, NovaCraftBlocks.basal, 0, 2);
		world.setBlock(i + 7, j + 21, k + 8, NovaCraftBlocks.basal, 0, 2);
		world.setBlock(i + 8, j + 21, k + 8, Blocks.air, 0, 2);
		world.setBlock(i + 9, j + 21, k + 8, Blocks.air, 0, 2);
		world.setBlock(i + 10, j + 21, k + 8, NovaCraftBlocks.basal, 0, 2);
		world.setBlock(i + 11, j + 21, k + 8, NovaCraftBlocks.basal, 0, 2);
		world.setBlock(i + 12, j + 21, k + 8, NovaCraftBlocks.basal, 0, 2);
		world.setBlock(i + 13, j + 21, k + 8, Blocks.air, 0, 2);
		world.setBlock(i + 14, j + 21, k + 8, NovaCraftBlocks.basal, 0, 2);
		world.setBlock(i + 15, j + 21, k + 8, NovaCraftBlocks.basal, 0, 2);
		world.setBlock(i + 16, j + 21, k + 8, NovaCraftBlocks.basal, 0, 2);
		world.setBlock(i + 17, j + 21, k + 8, NovaCraftBlocks.basal, 0, 2);
		world.setBlock(i + 18, j + 21, k + 8, NovaCraftBlocks.basal, 0, 2);
		world.setBlock(i + 19, j + 21, k + 8, NovaCraftBlocks.basal, 0, 2);
		world.setBlock(i + 20, j + 21, k + 8, NovaCraftBlocks.basal, 0, 2);
		world.setBlock(i + 21, j + 21, k + 8, NovaCraftBlocks.basal, 0, 2);
		world.setBlock(i + 22, j + 21, k + 8, Blocks.air, 0, 2);
		world.setBlock(i + 23, j + 21, k + 8, Blocks.air, 0, 2);
		world.setBlock(i + 24, j + 21, k + 8, NovaCraftBlocks.basal, 0, 2);
		world.setBlock(i + 25, j + 21, k + 8, NovaCraftBlocks.basal, 0, 2);
		world.setBlock(i + 26, j + 21, k + 8, NovaCraftBlocks.basal, 0, 2);
		world.setBlock(i + 27, j + 21, k + 8, NovaCraftBlocks.basal, 0, 2);
		world.setBlock(i + 0, j + 21, k + 9, Blocks.air, 0, 2);
		world.setBlock(i + 1, j + 21, k + 9, Blocks.air, 0, 2);
		world.setBlock(i + 2, j + 21, k + 9, Blocks.air, 0, 2);
		world.setBlock(i + 3, j + 21, k + 9, NovaCraftBlocks.basal, 0, 2);
		world.setBlock(i + 4, j + 21, k + 9, Blocks.air, 0, 2);
		world.setBlock(i + 5, j + 21, k + 9, NovaCraftBlocks.basal, 0, 2);
		world.setBlock(i + 6, j + 21, k + 9, NovaCraftBlocks.basal, 0, 2);
		world.setBlock(i + 7, j + 21, k + 9, NovaCraftBlocks.glowing_basal, 0, 2);
		world.setBlock(i + 8, j + 21, k + 9, NovaCraftBlocks.basal, 0, 2);
		world.setBlock(i + 9, j + 21, k + 9, NovaCraftBlocks.basal, 0, 2);
		world.setBlock(i + 10, j + 21, k + 9, NovaCraftBlocks.basal, 0, 2);
		world.setBlock(i + 11, j + 21, k + 9, NovaCraftBlocks.cracked_basal_bricks, 0, 2);
		world.setBlock(i + 12, j + 21, k + 9, Blocks.air, 0, 2);
		world.setBlock(i + 13, j + 21, k + 9, Blocks.air, 0, 2);
		world.setBlock(i + 14, j + 21, k + 9, NovaCraftBlocks.basal, 0, 2);
		world.setBlock(i + 15, j + 21, k + 9, NovaCraftBlocks.basal, 0, 2);
		world.setBlock(i + 16, j + 21, k + 9, NovaCraftBlocks.basal, 0, 2);
		world.setBlock(i + 17, j + 21, k + 9, NovaCraftBlocks.basal, 0, 2);
		world.setBlock(i + 18, j + 21, k + 9, NovaCraftBlocks.basal, 0, 2);
		world.setBlock(i + 19, j + 21, k + 9, NovaCraftBlocks.basal, 0, 2);
		world.setBlock(i + 20, j + 21, k + 9, NovaCraftBlocks.basal, 0, 2);
		world.setBlock(i + 21, j + 21, k + 9, Blocks.lava, 8, 2);
		world.setBlock(i + 22, j + 21, k + 9, Blocks.air, 0, 2);
		world.setBlock(i + 23, j + 21, k + 9, Blocks.air, 0, 2);
		world.setBlock(i + 24, j + 21, k + 9, NovaCraftBlocks.basal, 0, 2);
		world.setBlock(i + 25, j + 21, k + 9, NovaCraftBlocks.basal, 0, 2);
		world.setBlock(i + 26, j + 21, k + 9, NovaCraftBlocks.basal, 0, 2);
		world.setBlock(i + 27, j + 21, k + 9, Blocks.air, 0, 2);
		world.setBlock(i + 0, j + 21, k + 10, Blocks.air, 0, 2);
		world.setBlock(i + 1, j + 21, k + 10, Blocks.air, 0, 2);
		world.setBlock(i + 2, j + 21, k + 10, Blocks.air, 0, 2);
		world.setBlock(i + 3, j + 21, k + 10, Blocks.air, 0, 2);
		world.setBlock(i + 4, j + 21, k + 10, Blocks.air, 0, 2);
		world.setBlock(i + 5, j + 21, k + 10, NovaCraftBlocks.basal, 0, 2);
		world.setBlock(i + 6, j + 21, k + 10, NovaCraftBlocks.basal, 0, 2);
		world.setBlock(i + 7, j + 21, k + 10, NovaCraftBlocks.basal, 0, 2);
		world.setBlock(i + 8, j + 21, k + 10, NovaCraftBlocks.basal, 0, 2);
		world.setBlock(i + 9, j + 21, k + 10, NovaCraftBlocks.glowing_basal, 0, 2);
		world.setBlock(i + 10, j + 21, k + 10, NovaCraftBlocks.cracked_basal_bricks, 0, 2);
		world.setBlock(i + 11, j + 21, k + 10, Blocks.air, 0, 2);
		world.setBlock(i + 12, j + 21, k + 10, Blocks.air, 0, 2);
		world.setBlock(i + 13, j + 21, k + 10, Blocks.air, 0, 2);
		world.setBlock(i + 14, j + 21, k + 10, Blocks.air, 0, 2);
		world.setBlock(i + 15, j + 21, k + 10, Blocks.air, 0, 2);
		world.setBlock(i + 16, j + 21, k + 10, NovaCraftBlocks.basal, 0, 2);
		world.setBlock(i + 17, j + 21, k + 10, NovaCraftBlocks.basal, 0, 2);
		world.setBlock(i + 18, j + 21, k + 10, NovaCraftBlocks.basal, 0, 2);
		world.setBlock(i + 19, j + 21, k + 10, NovaCraftBlocks.basal, 0, 2);
		world.setBlock(i + 20, j + 21, k + 10, NovaCraftBlocks.basal, 0, 2);
		world.setBlock(i + 21, j + 21, k + 10, NovaCraftBlocks.basal, 0, 2);
		world.setBlock(i + 22, j + 21, k + 10, Blocks.air, 0, 2);
		world.setBlock(i + 23, j + 21, k + 10, Blocks.air, 0, 2);
		world.setBlock(i + 24, j + 21, k + 10, NovaCraftBlocks.basal, 0, 2);
		world.setBlock(i + 25, j + 21, k + 10, NovaCraftBlocks.basal, 0, 2);
		world.setBlock(i + 26, j + 21, k + 10, NovaCraftBlocks.basal, 0, 2);
		world.setBlock(i + 27, j + 21, k + 10, Blocks.air, 0, 2);
		world.setBlock(i + 0, j + 21, k + 11, Blocks.air, 0, 2);
		world.setBlock(i + 1, j + 21, k + 11, Blocks.air, 0, 2);
		world.setBlock(i + 2, j + 21, k + 11, Blocks.air, 0, 2);
		world.setBlock(i + 3, j + 21, k + 11, Blocks.air, 0, 2);
		world.setBlock(i + 4, j + 21, k + 11, NovaCraftBlocks.basal_bricks, 0, 2);
		world.setBlock(i + 5, j + 21, k + 11, NovaCraftBlocks.cracked_basal_bricks, 0, 2);
		world.setBlock(i + 6, j + 21, k + 11, NovaCraftBlocks.basal_bricks, 0, 2);
		world.setBlock(i + 7, j + 21, k + 11, NovaCraftBlocks.cracked_basal_bricks, 0, 2);
		world.setBlock(i + 8, j + 21, k + 11, NovaCraftBlocks.cracked_basal_bricks, 0, 2);
		world.setBlock(i + 9, j + 21, k + 11, NovaCraftBlocks.basal_bricks, 0, 2);
		world.setBlock(i + 10, j + 21, k + 11, NovaCraftBlocks.basal_bricks, 0, 2);
		world.setBlock(i + 11, j + 21, k + 11, NovaCraftBlocks.basal_bricks, 0, 2);
		world.setBlock(i + 12, j + 21, k + 11, NovaCraftBlocks.basal_bricks, 0, 2);
		world.setBlock(i + 13, j + 21, k + 11, NovaCraftBlocks.basal_bricks, 0, 2);
		world.setBlock(i + 14, j + 21, k + 11, Blocks.air, 0, 2);
		world.setBlock(i + 15, j + 21, k + 11, Blocks.air, 0, 2);
		world.setBlock(i + 16, j + 21, k + 11, Blocks.air, 0, 2);
		world.setBlock(i + 17, j + 21, k + 11, NovaCraftBlocks.basal, 0, 2);
		world.setBlock(i + 18, j + 21, k + 11, Blocks.air, 0, 2);
		world.setBlock(i + 19, j + 21, k + 11, NovaCraftBlocks.basal, 0, 2);
		world.setBlock(i + 20, j + 21, k + 11, NovaCraftBlocks.basal, 0, 2);
		world.setBlock(i + 21, j + 21, k + 11, NovaCraftBlocks.basal, 0, 2);
		world.setBlock(i + 22, j + 21, k + 11, NovaCraftBlocks.glowing_basal, 0, 2);
		world.setBlock(i + 23, j + 21, k + 11, NovaCraftBlocks.basal, 0, 2);
		world.setBlock(i + 24, j + 21, k + 11, NovaCraftBlocks.basal, 0, 2);
		world.setBlock(i + 25, j + 21, k + 11, NovaCraftBlocks.basal_bricks, 0, 2);
		world.setBlock(i + 26, j + 21, k + 11, Blocks.air, 0, 2);
		world.setBlock(i + 27, j + 21, k + 11, Blocks.air, 0, 2);
		world.setBlock(i + 0, j + 21, k + 12, Blocks.air, 0, 2);
		world.setBlock(i + 1, j + 21, k + 12, Blocks.air, 0, 2);
		world.setBlock(i + 2, j + 21, k + 12, Blocks.air, 0, 2);
		world.setBlock(i + 3, j + 21, k + 12, NovaCraftBlocks.cracked_basal_bricks, 0, 2);
		world.setBlock(i + 4, j + 21, k + 12, NovaCraftBlocks.basal_bricks, 0, 2);
		world.setBlock(i + 5, j + 21, k + 12, NovaCraftBlocks.basal_bricks, 0, 2);
		world.setBlock(i + 6, j + 21, k + 12, NovaCraftBlocks.cracked_basal_bricks, 0, 2);
		world.setBlock(i + 7, j + 21, k + 12, NovaCraftBlocks.basal_bricks, 0, 2);
		world.setBlock(i + 8, j + 21, k + 12, NovaCraftBlocks.cracked_basal_bricks, 0, 2);
		world.setBlock(i + 9, j + 21, k + 12, NovaCraftBlocks.cracked_basal_bricks, 0, 2);
		world.setBlock(i + 10, j + 21, k + 12, NovaCraftBlocks.basal_bricks, 0, 2);
		world.setBlock(i + 11, j + 21, k + 12, NovaCraftBlocks.basal_bricks, 0, 2);
		world.setBlock(i + 12, j + 21, k + 12, NovaCraftBlocks.basal_bricks, 0, 2);
		world.setBlock(i + 13, j + 21, k + 12, NovaCraftBlocks.basal_bricks, 0, 2);
		world.setBlock(i + 14, j + 21, k + 12, Blocks.air, 0, 2);
		world.setBlock(i + 15, j + 21, k + 12, Blocks.air, 0, 2);
		world.setBlock(i + 16, j + 21, k + 12, Blocks.air, 0, 2);
		world.setBlock(i + 17, j + 21, k + 12, Blocks.air, 0, 2);
		world.setBlock(i + 18, j + 21, k + 12, Blocks.air, 0, 2);
		world.setBlock(i + 19, j + 21, k + 12, NovaCraftBlocks.basal, 0, 2);
		world.setBlock(i + 20, j + 21, k + 12, NovaCraftBlocks.basal, 0, 2);
		world.setBlock(i + 21, j + 21, k + 12, NovaCraftBlocks.basal, 0, 2);
		world.setBlock(i + 22, j + 21, k + 12, NovaCraftBlocks.basal, 0, 2);
		world.setBlock(i + 23, j + 21, k + 12, NovaCraftBlocks.basal, 0, 2);
		world.setBlock(i + 24, j + 21, k + 12, NovaCraftBlocks.cracked_basal_bricks, 0, 2);
		world.setBlock(i + 25, j + 21, k + 12, Blocks.air, 0, 2);
		world.setBlock(i + 26, j + 21, k + 12, Blocks.air, 0, 2);
		world.setBlock(i + 27, j + 21, k + 12, Blocks.air, 0, 2);
		world.setBlock(i + 0, j + 22, k + 1, NovaCraftBlocks.basal_scrap, 0, 2);
		world.setBlock(i + 1, j + 22, k + 1, NovaCraftBlocks.basal_scrap, 0, 2);
		world.setBlock(i + 4, j + 22, k + 1, NovaCraftBlocks.basal_scrap, 0, 2);
		world.setBlock(i + 5, j + 22, k + 1, NovaCraftBlocks.basal_scrap, 0, 2);
		world.setBlock(i + 8, j + 22, k + 1, NovaCraftBlocks.cracked_basal_bricks, 0, 2);
		world.setBlock(i + 9, j + 22, k + 1, NovaCraftBlocks.basal, 0, 2);
		world.setBlock(i + 12, j + 22, k + 1, NovaCraftBlocks.basal, 0, 2);
		world.setBlock(i + 13, j + 22, k + 1, NovaCraftBlocks.basal, 0, 2);
		world.setBlock(i + 0, j + 22, k + 2, NovaCraftBlocks.basal, 0, 2);
		world.setBlock(i + 1, j + 22, k + 2, NovaCraftBlocks.basal, 0, 2);
		world.setBlock(i + 2, j + 22, k + 2, NovaCraftBlocks.basal, 0, 2);
		world.setBlock(i + 3, j + 22, k + 2, NovaCraftBlocks.basal, 0, 2);
		world.setBlock(i + 4, j + 22, k + 2, NovaCraftBlocks.basal, 0, 2);
		world.setBlock(i + 5, j + 22, k + 2, NovaCraftBlocks.basal, 0, 2);
		world.setBlock(i + 6, j + 22, k + 2, NovaCraftBlocks.cracked_basal_bricks, 0, 2);
		world.setBlock(i + 7, j + 22, k + 2, NovaCraftBlocks.basal, 0, 2);
		world.setBlock(i + 8, j + 22, k + 2, NovaCraftBlocks.basal, 0, 2);
		world.setBlock(i + 9, j + 22, k + 2, NovaCraftBlocks.basal, 0, 2);
		world.setBlock(i + 10, j + 22, k + 2, NovaCraftBlocks.basal, 0, 2);
		world.setBlock(i + 11, j + 22, k + 2, NovaCraftBlocks.cracked_basal_bricks, 0, 2);
		world.setBlock(i + 12, j + 22, k + 2, NovaCraftBlocks.basal, 0, 2);
		world.setBlock(i + 13, j + 22, k + 2, NovaCraftBlocks.basal, 0, 2);
		world.setBlock(i + 0, j + 22, k + 3, NovaCraftBlocks.basal, 0, 2);
		world.setBlock(i + 1, j + 22, k + 3, NovaCraftBlocks.basal, 0, 2);
		world.setBlock(i + 2, j + 22, k + 3, NovaCraftBlocks.basal, 0, 2);
		world.setBlock(i + 3, j + 22, k + 3, NovaCraftBlocks.basal, 0, 2);
		world.setBlock(i + 4, j + 22, k + 3, NovaCraftBlocks.basal, 0, 2);
		world.setBlock(i + 5, j + 22, k + 3, NovaCraftBlocks.basal, 0, 2);
		world.setBlock(i + 6, j + 22, k + 3, NovaCraftBlocks.basal, 0, 2);
		world.setBlock(i + 7, j + 22, k + 3, NovaCraftBlocks.basal, 0, 2);
		world.setBlock(i + 8, j + 22, k + 3, NovaCraftBlocks.glowing_basal, 0, 2);
		world.setBlock(i + 9, j + 22, k + 3, NovaCraftBlocks.basal, 0, 2);
		world.setBlock(i + 10, j + 22, k + 3, NovaCraftBlocks.basal, 0, 2);
		world.setBlock(i + 11, j + 22, k + 3, NovaCraftBlocks.basal, 0, 2);
		world.setBlock(i + 12, j + 22, k + 3, NovaCraftBlocks.basal, 0, 2);
		world.setBlock(i + 13, j + 22, k + 3, NovaCraftBlocks.basal, 0, 2);
		world.setBlock(i + 14, j + 22, k + 3, NovaCraftBlocks.basal_scrap, 0, 2);
		world.setBlock(i + 15, j + 22, k + 3, NovaCraftBlocks.basal_scrap, 0, 2);
		world.setBlock(i + 18, j + 22, k + 3, NovaCraftBlocks.basal_scrap, 0, 2);
		world.setBlock(i + 19, j + 22, k + 3, NovaCraftBlocks.basal_scrap, 0, 2);
		world.setBlock(i + 22, j + 22, k + 3, NovaCraftBlocks.basal_bricks, 0, 2);
		world.setBlock(i + 23, j + 22, k + 3, NovaCraftBlocks.basal, 0, 2);
		world.setBlock(i + 26, j + 22, k + 3, NovaCraftBlocks.basal, 0, 2);
		world.setBlock(i + 27, j + 22, k + 3, NovaCraftBlocks.basal, 0, 2);
		world.setBlock(i + 0, j + 22, k + 4, NovaCraftBlocks.basal, 0, 2);
		world.setBlock(i + 1, j + 22, k + 4, NovaCraftBlocks.basal, 0, 2);
		world.setBlock(i + 2, j + 22, k + 4, NovaCraftBlocks.basal, 0, 2);
		world.setBlock(i + 3, j + 22, k + 4, NovaCraftBlocks.basal, 0, 2);
		world.setBlock(i + 4, j + 22, k + 4, NovaCraftBlocks.basal, 0, 2);
		world.setBlock(i + 5, j + 22, k + 4, NovaCraftBlocks.basal, 0, 2);
		world.setBlock(i + 6, j + 22, k + 4, NovaCraftBlocks.basal, 0, 2);
		world.setBlock(i + 7, j + 22, k + 4, Blocks.air, 0, 2);
		world.setBlock(i + 8, j + 22, k + 4, Blocks.air, 0, 2);
		world.setBlock(i + 9, j + 22, k + 4, NovaCraftBlocks.basal, 0, 2);
		world.setBlock(i + 10, j + 22, k + 4, NovaCraftBlocks.basal, 0, 2);
		world.setBlock(i + 11, j + 22, k + 4, NovaCraftBlocks.basal, 0, 2);
		world.setBlock(i + 12, j + 22, k + 4, NovaCraftBlocks.basal, 0, 2);
		world.setBlock(i + 13, j + 22, k + 4, NovaCraftBlocks.basal, 0, 2);
		world.setBlock(i + 14, j + 22, k + 4, NovaCraftBlocks.basal, 0, 2);
		world.setBlock(i + 15, j + 22, k + 4, NovaCraftBlocks.basal, 0, 2);
		world.setBlock(i + 16, j + 22, k + 4, NovaCraftBlocks.basal, 0, 2);
		world.setBlock(i + 17, j + 22, k + 4, NovaCraftBlocks.basal, 0, 2);
		world.setBlock(i + 18, j + 22, k + 4, NovaCraftBlocks.basal, 0, 2);
		world.setBlock(i + 19, j + 22, k + 4, NovaCraftBlocks.basal, 0, 2);
		world.setBlock(i + 20, j + 22, k + 4, NovaCraftBlocks.cracked_basal_bricks, 0, 2);
		world.setBlock(i + 21, j + 22, k + 4, NovaCraftBlocks.basal, 0, 2);
		world.setBlock(i + 22, j + 22, k + 4, NovaCraftBlocks.basal, 0, 2);
		world.setBlock(i + 23, j + 22, k + 4, NovaCraftBlocks.basal, 0, 2);
		world.setBlock(i + 24, j + 22, k + 4, NovaCraftBlocks.basal, 0, 2);
		world.setBlock(i + 25, j + 22, k + 4, NovaCraftBlocks.basal_bricks, 0, 2);
		world.setBlock(i + 26, j + 22, k + 4, NovaCraftBlocks.basal, 0, 2);
		world.setBlock(i + 27, j + 22, k + 4, NovaCraftBlocks.basal, 0, 2);
		world.setBlock(i + 0, j + 22, k + 5, NovaCraftBlocks.basal, 0, 2);
		world.setBlock(i + 1, j + 22, k + 5, NovaCraftBlocks.basal, 0, 2);
		world.setBlock(i + 2, j + 22, k + 5, NovaCraftBlocks.basal, 0, 2);
		world.setBlock(i + 3, j + 22, k + 5, NovaCraftBlocks.basal, 0, 2);
		world.setBlock(i + 4, j + 22, k + 5, NovaCraftBlocks.basal, 0, 2);
		world.setBlock(i + 5, j + 22, k + 5, NovaCraftBlocks.basal, 0, 2);
		world.setBlock(i + 6, j + 22, k + 5, NovaCraftBlocks.basal, 0, 2);
		world.setBlock(i + 7, j + 22, k + 5, Blocks.air, 0, 2);
		world.setBlock(i + 8, j + 22, k + 5, Blocks.air, 0, 2);
		world.setBlock(i + 9, j + 22, k + 5, Blocks.air, 0, 2);
		world.setBlock(i + 10, j + 22, k + 5, NovaCraftBlocks.basal, 0, 2);
		world.setBlock(i + 11, j + 22, k + 5, NovaCraftBlocks.basal, 0, 2);
		world.setBlock(i + 12, j + 22, k + 5, NovaCraftBlocks.basal, 0, 2);
		world.setBlock(i + 13, j + 22, k + 5, NovaCraftBlocks.basal, 0, 2);
		world.setBlock(i + 14, j + 22, k + 5, NovaCraftBlocks.basal, 0, 2);
		world.setBlock(i + 15, j + 22, k + 5, NovaCraftBlocks.basal, 0, 2);
		world.setBlock(i + 16, j + 22, k + 5, NovaCraftBlocks.basal, 0, 2);
		world.setBlock(i + 17, j + 22, k + 5, NovaCraftBlocks.basal, 0, 2);
		world.setBlock(i + 18, j + 22, k + 5, NovaCraftBlocks.basal, 0, 2);
		world.setBlock(i + 19, j + 22, k + 5, NovaCraftBlocks.basal, 0, 2);
		world.setBlock(i + 20, j + 22, k + 5, NovaCraftBlocks.basal, 0, 2);
		world.setBlock(i + 21, j + 22, k + 5, NovaCraftBlocks.basal, 0, 2);
		world.setBlock(i + 22, j + 22, k + 5, NovaCraftBlocks.basal, 0, 2);
		world.setBlock(i + 23, j + 22, k + 5, NovaCraftBlocks.basal, 0, 2);
		world.setBlock(i + 24, j + 22, k + 5, NovaCraftBlocks.basal, 0, 2);
		world.setBlock(i + 25, j + 22, k + 5, NovaCraftBlocks.basal, 0, 2);
		world.setBlock(i + 26, j + 22, k + 5, NovaCraftBlocks.basal, 0, 2);
		world.setBlock(i + 27, j + 22, k + 5, NovaCraftBlocks.basal, 0, 2);
		world.setBlock(i + 0, j + 22, k + 6, NovaCraftBlocks.basal, 0, 2);
		world.setBlock(i + 1, j + 22, k + 6, NovaCraftBlocks.basal, 0, 2);
		world.setBlock(i + 2, j + 22, k + 6, NovaCraftBlocks.basal, 0, 2);
		world.setBlock(i + 3, j + 22, k + 6, NovaCraftBlocks.basal, 0, 2);
		world.setBlock(i + 4, j + 22, k + 6, NovaCraftBlocks.basal, 0, 2);
		world.setBlock(i + 5, j + 22, k + 6, NovaCraftBlocks.basal, 0, 2);
		world.setBlock(i + 6, j + 22, k + 6, NovaCraftBlocks.basal, 0, 2);
		world.setBlock(i + 7, j + 22, k + 6, NovaCraftBlocks.basal, 0, 2);
		world.setBlock(i + 8, j + 22, k + 6, Blocks.air, 0, 2);
		world.setBlock(i + 9, j + 22, k + 6, Blocks.air, 0, 2);
		world.setBlock(i + 10, j + 22, k + 6, NovaCraftBlocks.basal, 0, 2);
		world.setBlock(i + 11, j + 22, k + 6, NovaCraftBlocks.basal, 0, 2);
		world.setBlock(i + 12, j + 22, k + 6, NovaCraftBlocks.basal, 0, 2);
		world.setBlock(i + 13, j + 22, k + 6, NovaCraftBlocks.basal, 0, 2);
		world.setBlock(i + 14, j + 22, k + 6, NovaCraftBlocks.basal, 0, 2);
		world.setBlock(i + 15, j + 22, k + 6, NovaCraftBlocks.basal, 0, 2);
		world.setBlock(i + 16, j + 22, k + 6, NovaCraftBlocks.basal, 0, 2);
		world.setBlock(i + 17, j + 22, k + 6, NovaCraftBlocks.basal, 0, 2);
		world.setBlock(i + 18, j + 22, k + 6, NovaCraftBlocks.basal, 0, 2);
		world.setBlock(i + 19, j + 22, k + 6, NovaCraftBlocks.basal, 0, 2);
		world.setBlock(i + 20, j + 22, k + 6, NovaCraftBlocks.basal, 0, 2);
		world.setBlock(i + 21, j + 22, k + 6, Blocks.air, 0, 2);
		world.setBlock(i + 22, j + 22, k + 6, Blocks.air, 0, 2);
		world.setBlock(i + 23, j + 22, k + 6, NovaCraftBlocks.basal, 0, 2);
		world.setBlock(i + 24, j + 22, k + 6, NovaCraftBlocks.basal, 0, 2);
		world.setBlock(i + 25, j + 22, k + 6, NovaCraftBlocks.basal, 0, 2);
		world.setBlock(i + 26, j + 22, k + 6, NovaCraftBlocks.basal, 0, 2);
		world.setBlock(i + 27, j + 22, k + 6, NovaCraftBlocks.basal, 0, 2);
		world.setBlock(i + 0, j + 22, k + 7, NovaCraftBlocks.basal, 0, 2);
		world.setBlock(i + 1, j + 22, k + 7, Blocks.air, 0, 2);
		world.setBlock(i + 2, j + 22, k + 7, NovaCraftBlocks.basal, 0, 2);
		world.setBlock(i + 3, j + 22, k + 7, NovaCraftBlocks.basal, 0, 2);
		world.setBlock(i + 4, j + 22, k + 7, NovaCraftBlocks.basal, 0, 2);
		world.setBlock(i + 5, j + 22, k + 7, NovaCraftBlocks.basal, 0, 2);
		world.setBlock(i + 6, j + 22, k + 7, NovaCraftBlocks.basal, 0, 2);
		world.setBlock(i + 7, j + 22, k + 7, Blocks.lava, 0, 2);
		world.setBlock(i + 8, j + 22, k + 7, NovaCraftBlocks.cracked_basal_bricks, 0, 2);
		world.setBlock(i + 9, j + 22, k + 7, Blocks.air, 0, 2);
		world.setBlock(i + 10, j + 22, k + 7, NovaCraftBlocks.basal, 0, 2);
		world.setBlock(i + 11, j + 22, k + 7, NovaCraftBlocks.basal, 0, 2);
		world.setBlock(i + 12, j + 22, k + 7, Blocks.air, 0, 2);
		world.setBlock(i + 13, j + 22, k + 7, Blocks.air, 0, 2);
		world.setBlock(i + 14, j + 22, k + 7, NovaCraftBlocks.basal, 0, 2);
		world.setBlock(i + 15, j + 22, k + 7, NovaCraftBlocks.basal, 0, 2);
		world.setBlock(i + 16, j + 22, k + 7, NovaCraftBlocks.basal, 0, 2);
		world.setBlock(i + 17, j + 22, k + 7, NovaCraftBlocks.basal, 0, 2);
		world.setBlock(i + 18, j + 22, k + 7, NovaCraftBlocks.basal, 0, 2);
		world.setBlock(i + 19, j + 22, k + 7, NovaCraftBlocks.basal, 0, 2);
		world.setBlock(i + 20, j + 22, k + 7, NovaCraftBlocks.basal, 0, 2);
		world.setBlock(i + 21, j + 22, k + 7, Blocks.air, 0, 2);
		world.setBlock(i + 22, j + 22, k + 7, Blocks.air, 0, 2);
		world.setBlock(i + 23, j + 22, k + 7, Blocks.air, 0, 2);
		world.setBlock(i + 24, j + 22, k + 7, NovaCraftBlocks.basal, 0, 2);
		world.setBlock(i + 25, j + 22, k + 7, NovaCraftBlocks.basal, 0, 2);
		world.setBlock(i + 26, j + 22, k + 7, NovaCraftBlocks.basal, 0, 2);
		world.setBlock(i + 27, j + 22, k + 7, NovaCraftBlocks.basal, 0, 2);
		world.setBlock(i + 0, j + 22, k + 8, Blocks.air, 0, 2);
		world.setBlock(i + 1, j + 22, k + 8, Blocks.air, 0, 2);
		world.setBlock(i + 2, j + 22, k + 8, NovaCraftBlocks.basal, 0, 2);
		world.setBlock(i + 3, j + 22, k + 8, NovaCraftBlocks.basal, 0, 2);
		world.setBlock(i + 4, j + 22, k + 8, NovaCraftBlocks.basal, 0, 2);
		world.setBlock(i + 5, j + 22, k + 8, NovaCraftBlocks.basal, 0, 2);
		world.setBlock(i + 6, j + 22, k + 8, NovaCraftBlocks.basal, 0, 2);
		world.setBlock(i + 7, j + 22, k + 8, NovaCraftBlocks.basal, 0, 2);
		world.setBlock(i + 8, j + 22, k + 8, NovaCraftBlocks.cracked_basal_bricks, 0, 2);
		world.setBlock(i + 9, j + 22, k + 8, NovaCraftBlocks.cracked_basal_bricks, 0, 2);
		world.setBlock(i + 10, j + 22, k + 8, NovaCraftBlocks.basal, 0, 2);
		world.setBlock(i + 11, j + 22, k + 8, NovaCraftBlocks.cracked_basal_bricks, 0, 2);
		world.setBlock(i + 12, j + 22, k + 8, Blocks.air, 0, 2);
		world.setBlock(i + 13, j + 22, k + 8, Blocks.air, 0, 2);
		world.setBlock(i + 14, j + 22, k + 8, NovaCraftBlocks.basal, 0, 2);
		world.setBlock(i + 15, j + 22, k + 8, NovaCraftBlocks.basal, 0, 2);
		world.setBlock(i + 16, j + 22, k + 8, NovaCraftBlocks.basal, 0, 2);
		world.setBlock(i + 17, j + 22, k + 8, NovaCraftBlocks.basal, 0, 2);
		world.setBlock(i + 18, j + 22, k + 8, NovaCraftBlocks.basal, 0, 2);
		world.setBlock(i + 19, j + 22, k + 8, NovaCraftBlocks.basal, 0, 2);
		world.setBlock(i + 20, j + 22, k + 8, NovaCraftBlocks.basal, 0, 2);
		world.setBlock(i + 21, j + 22, k + 8, NovaCraftBlocks.basal, 0, 2);
		world.setBlock(i + 22, j + 22, k + 8, Blocks.air, 0, 2);
		world.setBlock(i + 23, j + 22, k + 8, Blocks.air, 0, 2);
		world.setBlock(i + 24, j + 22, k + 8, NovaCraftBlocks.basal, 0, 2);
		world.setBlock(i + 25, j + 22, k + 8, NovaCraftBlocks.basal, 0, 2);
		world.setBlock(i + 26, j + 22, k + 8, NovaCraftBlocks.basal, 0, 2);
		world.setBlock(i + 27, j + 22, k + 8, NovaCraftBlocks.basal, 0, 2);
		world.setBlock(i + 0, j + 22, k + 9, Blocks.air, 0, 2);
		world.setBlock(i + 1, j + 22, k + 9, Blocks.air, 0, 2);
		world.setBlock(i + 2, j + 22, k + 9, Blocks.air, 0, 2);
		world.setBlock(i + 3, j + 22, k + 9, NovaCraftBlocks.basal, 0, 2);
		world.setBlock(i + 4, j + 22, k + 9, NovaCraftBlocks.basal, 0, 2);
		world.setBlock(i + 5, j + 22, k + 9, NovaCraftBlocks.basal, 0, 2);
		world.setBlock(i + 6, j + 22, k + 9, NovaCraftBlocks.basal, 0, 2);
		world.setBlock(i + 7, j + 22, k + 9, NovaCraftBlocks.basal, 0, 2);
		world.setBlock(i + 8, j + 22, k + 9, NovaCraftBlocks.basal, 0, 2);
		world.setBlock(i + 9, j + 22, k + 9, NovaCraftBlocks.basal, 0, 2);
		world.setBlock(i + 10, j + 22, k + 9, NovaCraftBlocks.basal, 0, 2);
		world.setBlock(i + 11, j + 22, k + 9, Blocks.air, 0, 2);
		world.setBlock(i + 12, j + 22, k + 9, Blocks.air, 0, 2);
		world.setBlock(i + 13, j + 22, k + 9, Blocks.air, 0, 2);
		world.setBlock(i + 14, j + 22, k + 9, NovaCraftBlocks.basal, 0, 2);
		world.setBlock(i + 15, j + 22, k + 9, Blocks.air, 0, 2);
		world.setBlock(i + 16, j + 22, k + 9, NovaCraftBlocks.basal, 0, 2);
		world.setBlock(i + 17, j + 22, k + 9, NovaCraftBlocks.basal, 0, 2);
		world.setBlock(i + 18, j + 22, k + 9, NovaCraftBlocks.basal, 0, 2);
		world.setBlock(i + 19, j + 22, k + 9, NovaCraftBlocks.basal, 0, 2);
		world.setBlock(i + 20, j + 22, k + 9, NovaCraftBlocks.basal, 0, 2);
		world.setBlock(i + 21, j + 22, k + 9, Blocks.lava, 0, 2);
		world.setBlock(i + 22, j + 22, k + 9, NovaCraftBlocks.cracked_basal_bricks, 0, 2);
		world.setBlock(i + 23, j + 22, k + 9, Blocks.air, 0, 2);
		world.setBlock(i + 24, j + 22, k + 9, NovaCraftBlocks.basal, 0, 2);
		world.setBlock(i + 25, j + 22, k + 9, NovaCraftBlocks.basal, 0, 2);
		world.setBlock(i + 26, j + 22, k + 9, Blocks.air, 0, 2);
		world.setBlock(i + 27, j + 22, k + 9, Blocks.air, 0, 2);
		world.setBlock(i + 0, j + 22, k + 10, Blocks.air, 0, 2);
		world.setBlock(i + 1, j + 22, k + 10, Blocks.air, 0, 2);
		world.setBlock(i + 2, j + 22, k + 10, Blocks.air, 0, 2);
		world.setBlock(i + 3, j + 22, k + 10, Blocks.air, 0, 2);
		world.setBlock(i + 4, j + 22, k + 10, Blocks.air, 0, 2);
		world.setBlock(i + 5, j + 22, k + 10, NovaCraftBlocks.cracked_basal_bricks, 0, 2);
		world.setBlock(i + 6, j + 22, k + 10, NovaCraftBlocks.basal, 0, 2);
		world.setBlock(i + 7, j + 22, k + 10, NovaCraftBlocks.basal, 0, 2);
		world.setBlock(i + 8, j + 22, k + 10, NovaCraftBlocks.basal, 0, 2);
		world.setBlock(i + 9, j + 22, k + 10, NovaCraftBlocks.cracked_basal_bricks, 0, 2);
		world.setBlock(i + 10, j + 22, k + 10, Blocks.air, 0, 2);
		world.setBlock(i + 11, j + 22, k + 10, Blocks.air, 0, 2);
		world.setBlock(i + 12, j + 22, k + 10, Blocks.air, 0, 2);
		world.setBlock(i + 13, j + 22, k + 10, Blocks.air, 0, 2);
		world.setBlock(i + 14, j + 22, k + 10, Blocks.air, 0, 2);
		world.setBlock(i + 15, j + 22, k + 10, Blocks.air, 0, 2);
		world.setBlock(i + 16, j + 22, k + 10, NovaCraftBlocks.basal, 0, 2);
		world.setBlock(i + 17, j + 22, k + 10, NovaCraftBlocks.basal, 0, 2);
		world.setBlock(i + 18, j + 22, k + 10, NovaCraftBlocks.basal, 0, 2);
		world.setBlock(i + 19, j + 22, k + 10, NovaCraftBlocks.basal, 0, 2);
		world.setBlock(i + 20, j + 22, k + 10, NovaCraftBlocks.basal, 0, 2);
		world.setBlock(i + 21, j + 22, k + 10, NovaCraftBlocks.basal, 0, 2);
		world.setBlock(i + 22, j + 22, k + 10, NovaCraftBlocks.basal_bricks, 0, 2);
		world.setBlock(i + 23, j + 22, k + 10, NovaCraftBlocks.cracked_basal_bricks, 0, 2);
		world.setBlock(i + 24, j + 22, k + 10, NovaCraftBlocks.basal, 0, 2);
		world.setBlock(i + 25, j + 22, k + 10, NovaCraftBlocks.cracked_basal_bricks, 0, 2);
		world.setBlock(i + 26, j + 22, k + 10, Blocks.air, 0, 2);
		world.setBlock(i + 27, j + 22, k + 10, Blocks.air, 0, 2);
		world.setBlock(i + 0, j + 22, k + 11, Blocks.air, 0, 2);
		world.setBlock(i + 1, j + 22, k + 11, Blocks.air, 0, 2);
		world.setBlock(i + 2, j + 22, k + 11, Blocks.air, 0, 2);
		world.setBlock(i + 3, j + 22, k + 11, NovaCraftBlocks.basal_bricks, 0, 2);
		world.setBlock(i + 4, j + 22, k + 11, NovaCraftBlocks.basal_bricks, 0, 2);
		world.setBlock(i + 5, j + 22, k + 11, NovaCraftBlocks.basal_bricks, 0, 2);
		world.setBlock(i + 6, j + 22, k + 11, NovaCraftBlocks.cracked_basal_bricks, 0, 2);
		world.setBlock(i + 7, j + 22, k + 11, NovaCraftBlocks.basal_bricks, 0, 2);
		world.setBlock(i + 8, j + 22, k + 11, NovaCraftBlocks.basal_bricks, 0, 2);
		world.setBlock(i + 9, j + 22, k + 11, NovaCraftBlocks.basal_bricks, 0, 2);
		world.setBlock(i + 10, j + 22, k + 11, NovaCraftBlocks.basal_bricks, 0, 2);
		world.setBlock(i + 11, j + 22, k + 11, NovaCraftBlocks.cracked_basal_bricks, 0, 2);
		world.setBlock(i + 12, j + 22, k + 11, NovaCraftBlocks.basal_bricks, 0, 2);
		world.setBlock(i + 13, j + 22, k + 11, NovaCraftBlocks.cracked_basal_bricks, 0, 2);
		world.setBlock(i + 14, j + 22, k + 11, Blocks.air, 0, 2);
		world.setBlock(i + 15, j + 22, k + 11, Blocks.air, 0, 2);
		world.setBlock(i + 16, j + 22, k + 11, Blocks.air, 0, 2);
		world.setBlock(i + 17, j + 22, k + 11, NovaCraftBlocks.basal, 0, 2);
		world.setBlock(i + 18, j + 22, k + 11, NovaCraftBlocks.basal, 0, 2);
		world.setBlock(i + 19, j + 22, k + 11, NovaCraftBlocks.basal, 0, 2);
		world.setBlock(i + 20, j + 22, k + 11, NovaCraftBlocks.basal, 0, 2);
		world.setBlock(i + 21, j + 22, k + 11, NovaCraftBlocks.basal, 0, 2);
		world.setBlock(i + 22, j + 22, k + 11, NovaCraftBlocks.basal, 0, 2);
		world.setBlock(i + 23, j + 22, k + 11, NovaCraftBlocks.basal, 0, 2);
		world.setBlock(i + 24, j + 22, k + 11, NovaCraftBlocks.basal, 0, 2);
		world.setBlock(i + 25, j + 22, k + 11, Blocks.air, 0, 2);
		world.setBlock(i + 26, j + 22, k + 11, Blocks.air, 0, 2);
		world.setBlock(i + 27, j + 22, k + 11, Blocks.air, 0, 2);
		world.setBlock(i + 0, j + 22, k + 12, Blocks.air, 0, 2);
		world.setBlock(i + 1, j + 22, k + 12, Blocks.air, 0, 2);
		world.setBlock(i + 2, j + 22, k + 12, Blocks.air, 0, 2);
		world.setBlock(i + 3, j + 22, k + 12, NovaCraftBlocks.cracked_basal_bricks, 0, 2);
		world.setBlock(i + 4, j + 22, k + 12, NovaCraftBlocks.basal_bricks, 0, 2);
		world.setBlock(i + 5, j + 22, k + 12, NovaCraftBlocks.basal_bricks, 0, 2);
		world.setBlock(i + 6, j + 22, k + 12, NovaCraftBlocks.basal_bricks, 0, 2);
		world.setBlock(i + 7, j + 22, k + 12, NovaCraftBlocks.cracked_basal_bricks, 0, 2);
		world.setBlock(i + 8, j + 22, k + 12, NovaCraftBlocks.basal_bricks, 0, 2);
		world.setBlock(i + 9, j + 22, k + 12, NovaCraftBlocks.basal_bricks, 0, 2);
		world.setBlock(i + 10, j + 22, k + 12, NovaCraftBlocks.basal_bricks, 0, 2);
		world.setBlock(i + 11, j + 22, k + 12, NovaCraftBlocks.basal_bricks, 0, 2);
		world.setBlock(i + 12, j + 22, k + 12, NovaCraftBlocks.basal_bricks, 0, 2);
		world.setBlock(i + 13, j + 22, k + 12, NovaCraftBlocks.cracked_basal_bricks, 0, 2);
		world.setBlock(i + 14, j + 22, k + 12, Blocks.air, 0, 2);
		world.setBlock(i + 15, j + 22, k + 12, Blocks.air, 0, 2);
		world.setBlock(i + 16, j + 22, k + 12, Blocks.air, 0, 2);
		world.setBlock(i + 17, j + 22, k + 12, Blocks.air, 0, 2);
		world.setBlock(i + 18, j + 22, k + 12, Blocks.air, 0, 2);
		world.setBlock(i + 19, j + 22, k + 12, NovaCraftBlocks.cracked_basal_bricks, 0, 2);
		world.setBlock(i + 20, j + 22, k + 12, NovaCraftBlocks.basal, 0, 2);
		world.setBlock(i + 21, j + 22, k + 12, NovaCraftBlocks.basal, 0, 2);
		world.setBlock(i + 22, j + 22, k + 12, NovaCraftBlocks.basal, 0, 2);
		world.setBlock(i + 23, j + 22, k + 12, NovaCraftBlocks.basal_bricks, 0, 2);
		world.setBlock(i + 24, j + 22, k + 12, Blocks.air, 0, 2);
		world.setBlock(i + 25, j + 22, k + 12, Blocks.air, 0, 2);
		world.setBlock(i + 26, j + 22, k + 12, Blocks.air, 0, 2);
		world.setBlock(i + 27, j + 22, k + 12, Blocks.air, 0, 2);
		world.setBlock(i + 0, j + 23, k + 1, NovaCraftBlocks.basal_scrap, 0, 2);
		world.setBlock(i + 1, j + 23, k + 1, NovaCraftBlocks.basal_scrap, 0, 2);
		world.setBlock(i + 4, j + 23, k + 1, NovaCraftBlocks.basal_scrap, 0, 2);
		world.setBlock(i + 5, j + 23, k + 1, NovaCraftBlocks.basal_scrap, 0, 2);
		world.setBlock(i + 8, j + 23, k + 1, NovaCraftBlocks.cracked_basal_bricks, 0, 2);
		world.setBlock(i + 9, j + 23, k + 1, NovaCraftBlocks.cracked_basal_bricks, 0, 2);
		world.setBlock(i + 10, j + 23, k + 1, NovaCraftBlocks.basal, 0, 2);
		world.setBlock(i + 12, j + 23, k + 1, NovaCraftBlocks.basal, 0, 2);
		world.setBlock(i + 13, j + 23, k + 1, NovaCraftBlocks.basal, 0, 2);
		world.setBlock(i + 0, j + 23, k + 2, NovaCraftBlocks.basal, 0, 2);
		world.setBlock(i + 1, j + 23, k + 2, NovaCraftBlocks.basal, 0, 2);
		world.setBlock(i + 2, j + 23, k + 2, NovaCraftBlocks.basal, 0, 2);
		world.setBlock(i + 3, j + 23, k + 2, NovaCraftBlocks.basal, 0, 2);
		world.setBlock(i + 4, j + 23, k + 2, NovaCraftBlocks.basal, 0, 2);
		world.setBlock(i + 5, j + 23, k + 2, NovaCraftBlocks.basal, 0, 2);
		world.setBlock(i + 6, j + 23, k + 2, NovaCraftBlocks.basal, 0, 2);
		world.setBlock(i + 7, j + 23, k + 2, NovaCraftBlocks.basal, 0, 2);
		world.setBlock(i + 8, j + 23, k + 2, NovaCraftBlocks.basal, 0, 2);
		world.setBlock(i + 9, j + 23, k + 2, NovaCraftBlocks.basal, 0, 2);
		world.setBlock(i + 10, j + 23, k + 2, NovaCraftBlocks.basal, 0, 2);
		world.setBlock(i + 11, j + 23, k + 2, NovaCraftBlocks.basal, 0, 2);
		world.setBlock(i + 12, j + 23, k + 2, NovaCraftBlocks.glowing_basal, 0, 2);
		world.setBlock(i + 13, j + 23, k + 2, NovaCraftBlocks.basal, 0, 2);
		world.setBlock(i + 0, j + 23, k + 3, NovaCraftBlocks.basal, 0, 2);
		world.setBlock(i + 1, j + 23, k + 3, NovaCraftBlocks.basal, 0, 2);
		world.setBlock(i + 2, j + 23, k + 3, NovaCraftBlocks.basal, 0, 2);
		world.setBlock(i + 3, j + 23, k + 3, NovaCraftBlocks.basal, 0, 2);
		world.setBlock(i + 4, j + 23, k + 3, NovaCraftBlocks.basal, 0, 2);
		world.setBlock(i + 5, j + 23, k + 3, NovaCraftBlocks.basal, 0, 2);
		world.setBlock(i + 6, j + 23, k + 3, NovaCraftBlocks.basal, 0, 2);
		world.setBlock(i + 7, j + 23, k + 3, NovaCraftBlocks.basal, 0, 2);
		world.setBlock(i + 8, j + 23, k + 3, NovaCraftBlocks.basal, 0, 2);
		world.setBlock(i + 9, j + 23, k + 3, NovaCraftBlocks.basal, 0, 2);
		world.setBlock(i + 10, j + 23, k + 3, NovaCraftBlocks.basal, 0, 2);
		world.setBlock(i + 11, j + 23, k + 3, NovaCraftBlocks.basal, 0, 2);
		world.setBlock(i + 12, j + 23, k + 3, NovaCraftBlocks.basal, 0, 2);
		world.setBlock(i + 13, j + 23, k + 3, NovaCraftBlocks.basal, 0, 2);
		world.setBlock(i + 14, j + 23, k + 3, NovaCraftBlocks.basal_scrap, 0, 2);
		world.setBlock(i + 15, j + 23, k + 3, NovaCraftBlocks.basal_scrap, 0, 2);
		world.setBlock(i + 18, j + 23, k + 3, NovaCraftBlocks.basal_scrap, 0, 2);
		world.setBlock(i + 19, j + 23, k + 3, NovaCraftBlocks.basal_scrap, 0, 2);
		world.setBlock(i + 22, j + 23, k + 3, NovaCraftBlocks.cracked_basal_bricks, 0, 2);
		world.setBlock(i + 23, j + 23, k + 3, NovaCraftBlocks.cracked_basal_bricks, 0, 2);
		world.setBlock(i + 24, j + 23, k + 3, NovaCraftBlocks.basal, 0, 2);
		world.setBlock(i + 26, j + 23, k + 3, NovaCraftBlocks.basal, 0, 2);
		world.setBlock(i + 27, j + 23, k + 3, NovaCraftBlocks.basal, 0, 2);
		world.setBlock(i + 0, j + 23, k + 4, NovaCraftBlocks.basal, 0, 2);
		world.setBlock(i + 1, j + 23, k + 4, NovaCraftBlocks.basal, 0, 2);
		world.setBlock(i + 2, j + 23, k + 4, NovaCraftBlocks.basal, 0, 2);
		world.setBlock(i + 3, j + 23, k + 4, NovaCraftBlocks.basal, 0, 2);
		world.setBlock(i + 4, j + 23, k + 4, NovaCraftBlocks.basal, 0, 2);
		world.setBlock(i + 5, j + 23, k + 4, NovaCraftBlocks.basal, 0, 2);
		world.setBlock(i + 6, j + 23, k + 4, Blocks.air, 0, 2);
		world.setBlock(i + 7, j + 23, k + 4, Blocks.air, 0, 2);
		world.setBlock(i + 8, j + 23, k + 4, Blocks.air, 0, 2);
		world.setBlock(i + 9, j + 23, k + 4, NovaCraftBlocks.basal, 0, 2);
		world.setBlock(i + 10, j + 23, k + 4, NovaCraftBlocks.basal, 0, 2);
		world.setBlock(i + 11, j + 23, k + 4, NovaCraftBlocks.basal, 0, 2);
		world.setBlock(i + 12, j + 23, k + 4, NovaCraftBlocks.basal, 0, 2);
		world.setBlock(i + 13, j + 23, k + 4, NovaCraftBlocks.basal, 0, 2);
		world.setBlock(i + 14, j + 23, k + 4, NovaCraftBlocks.basal, 0, 2);
		world.setBlock(i + 15, j + 23, k + 4, NovaCraftBlocks.basal, 0, 2);
		world.setBlock(i + 16, j + 23, k + 4, NovaCraftBlocks.basal, 0, 2);
		world.setBlock(i + 17, j + 23, k + 4, NovaCraftBlocks.basal, 0, 2);
		world.setBlock(i + 18, j + 23, k + 4, NovaCraftBlocks.basal, 0, 2);
		world.setBlock(i + 19, j + 23, k + 4, NovaCraftBlocks.basal, 0, 2);
		world.setBlock(i + 20, j + 23, k + 4, NovaCraftBlocks.basal, 0, 2);
		world.setBlock(i + 21, j + 23, k + 4, NovaCraftBlocks.basal, 0, 2);
		world.setBlock(i + 22, j + 23, k + 4, NovaCraftBlocks.basal, 0, 2);
		world.setBlock(i + 23, j + 23, k + 4, NovaCraftBlocks.basal, 0, 2);
		world.setBlock(i + 24, j + 23, k + 4, NovaCraftBlocks.basal, 0, 2);
		world.setBlock(i + 25, j + 23, k + 4, NovaCraftBlocks.basal, 0, 2);
		world.setBlock(i + 26, j + 23, k + 4, NovaCraftBlocks.basal, 0, 2);
		world.setBlock(i + 27, j + 23, k + 4, NovaCraftBlocks.basal, 0, 2);
		world.setBlock(i + 0, j + 23, k + 5, NovaCraftBlocks.basal, 0, 2);
		world.setBlock(i + 1, j + 23, k + 5, NovaCraftBlocks.basal, 0, 2);
		world.setBlock(i + 2, j + 23, k + 5, NovaCraftBlocks.basal, 0, 2);
		world.setBlock(i + 3, j + 23, k + 5, NovaCraftBlocks.basal, 0, 2);
		world.setBlock(i + 4, j + 23, k + 5, NovaCraftBlocks.basal, 0, 2);
		world.setBlock(i + 5, j + 23, k + 5, NovaCraftBlocks.basal, 0, 2);
		world.setBlock(i + 6, j + 23, k + 5, Blocks.air, 0, 2);
		world.setBlock(i + 7, j + 23, k + 5, Blocks.air, 0, 2);
		world.setBlock(i + 8, j + 23, k + 5, Blocks.air, 0, 2);
		world.setBlock(i + 9, j + 23, k + 5, NovaCraftBlocks.basal, 0, 2);
		world.setBlock(i + 10, j + 23, k + 5, NovaCraftBlocks.basal, 0, 2);
		world.setBlock(i + 11, j + 23, k + 5, NovaCraftBlocks.basal, 0, 2);
		world.setBlock(i + 12, j + 23, k + 5, NovaCraftBlocks.basal, 0, 2);
		world.setBlock(i + 13, j + 23, k + 5, NovaCraftBlocks.basal, 0, 2);
		world.setBlock(i + 14, j + 23, k + 5, NovaCraftBlocks.basal, 0, 2);
		world.setBlock(i + 15, j + 23, k + 5, NovaCraftBlocks.basal, 0, 2);
		world.setBlock(i + 16, j + 23, k + 5, NovaCraftBlocks.basal, 0, 2);
		world.setBlock(i + 17, j + 23, k + 5, NovaCraftBlocks.basal, 0, 2);
		world.setBlock(i + 18, j + 23, k + 5, NovaCraftBlocks.basal, 0, 2);
		world.setBlock(i + 19, j + 23, k + 5, NovaCraftBlocks.basal, 0, 2);
		world.setBlock(i + 20, j + 23, k + 5, NovaCraftBlocks.basal, 0, 2);
		world.setBlock(i + 21, j + 23, k + 5, NovaCraftBlocks.basal, 0, 2);
		world.setBlock(i + 22, j + 23, k + 5, NovaCraftBlocks.basal, 0, 2);
		world.setBlock(i + 23, j + 23, k + 5, NovaCraftBlocks.basal, 0, 2);
		world.setBlock(i + 24, j + 23, k + 5, NovaCraftBlocks.basal, 0, 2);
		world.setBlock(i + 25, j + 23, k + 5, NovaCraftBlocks.basal, 0, 2);
		world.setBlock(i + 26, j + 23, k + 5, NovaCraftBlocks.basal, 0, 2);
		world.setBlock(i + 27, j + 23, k + 5, NovaCraftBlocks.basal, 0, 2);
		world.setBlock(i + 0, j + 23, k + 6, NovaCraftBlocks.basal, 0, 2);
		world.setBlock(i + 1, j + 23, k + 6, NovaCraftBlocks.basal, 0, 2);
		world.setBlock(i + 2, j + 23, k + 6, NovaCraftBlocks.basal, 0, 2);
		world.setBlock(i + 3, j + 23, k + 6, NovaCraftBlocks.basal, 0, 2);
		world.setBlock(i + 4, j + 23, k + 6, NovaCraftBlocks.basal, 0, 2);
		world.setBlock(i + 5, j + 23, k + 6, NovaCraftBlocks.basal, 0, 2);
		world.setBlock(i + 6, j + 23, k + 6, NovaCraftBlocks.basal, 0, 2);
		world.setBlock(i + 7, j + 23, k + 6, NovaCraftBlocks.basal, 0, 2);
		world.setBlock(i + 8, j + 23, k + 6, NovaCraftBlocks.basal, 0, 2);
		world.setBlock(i + 9, j + 23, k + 6, NovaCraftBlocks.basal, 0, 2);
		world.setBlock(i + 10, j + 23, k + 6, NovaCraftBlocks.basal, 0, 2);
		world.setBlock(i + 11, j + 23, k + 6, NovaCraftBlocks.basal, 0, 2);
		world.setBlock(i + 12, j + 23, k + 6, NovaCraftBlocks.basal, 0, 2);
		world.setBlock(i + 13, j + 23, k + 6, NovaCraftBlocks.basal, 0, 2);
		world.setBlock(i + 14, j + 23, k + 6, NovaCraftBlocks.basal, 0, 2);
		world.setBlock(i + 15, j + 23, k + 6, NovaCraftBlocks.basal, 0, 2);
		world.setBlock(i + 16, j + 23, k + 6, NovaCraftBlocks.basal, 0, 2);
		world.setBlock(i + 17, j + 23, k + 6, NovaCraftBlocks.basal, 0, 2);
		world.setBlock(i + 18, j + 23, k + 6, NovaCraftBlocks.basal, 0, 2);
		world.setBlock(i + 19, j + 23, k + 6, NovaCraftBlocks.basal, 0, 2);
		world.setBlock(i + 20, j + 23, k + 6, Blocks.air, 0, 2);
		world.setBlock(i + 21, j + 23, k + 6, Blocks.air, 0, 2);
		world.setBlock(i + 22, j + 23, k + 6, Blocks.air, 0, 2);
		world.setBlock(i + 23, j + 23, k + 6, NovaCraftBlocks.basal, 0, 2);
		world.setBlock(i + 24, j + 23, k + 6, NovaCraftBlocks.basal, 0, 2);
		world.setBlock(i + 25, j + 23, k + 6, NovaCraftBlocks.basal, 0, 2);
		world.setBlock(i + 26, j + 23, k + 6, NovaCraftBlocks.basal, 0, 2);
		world.setBlock(i + 27, j + 23, k + 6, NovaCraftBlocks.basal, 0, 2);
		world.setBlock(i + 0, j + 23, k + 7, NovaCraftBlocks.basal, 0, 2);
		world.setBlock(i + 1, j + 23, k + 7, NovaCraftBlocks.basal, 0, 2);
		world.setBlock(i + 2, j + 23, k + 7, NovaCraftBlocks.basal, 0, 2);
		world.setBlock(i + 3, j + 23, k + 7, NovaCraftBlocks.basal, 0, 2);
		world.setBlock(i + 4, j + 23, k + 7, NovaCraftBlocks.basal, 0, 2);
		world.setBlock(i + 5, j + 23, k + 7, NovaCraftBlocks.basal, 0, 2);
		world.setBlock(i + 6, j + 23, k + 7, NovaCraftBlocks.basal, 0, 2);
		world.setBlock(i + 7, j + 23, k + 7, NovaCraftBlocks.glowing_basal, 0, 2);
		world.setBlock(i + 8, j + 23, k + 7, NovaCraftBlocks.cracked_basal_bricks, 0, 2);
		world.setBlock(i + 9, j + 23, k + 7, NovaCraftBlocks.basal, 0, 2);
		world.setBlock(i + 10, j + 23, k + 7, NovaCraftBlocks.basal, 0, 2);
		world.setBlock(i + 11, j + 23, k + 7, NovaCraftBlocks.basal, 0, 2);
		world.setBlock(i + 12, j + 23, k + 7, NovaCraftBlocks.basal, 0, 2);
		world.setBlock(i + 13, j + 23, k + 7, Blocks.air, 0, 2);
		world.setBlock(i + 14, j + 23, k + 7, NovaCraftBlocks.basal, 0, 2);
		world.setBlock(i + 15, j + 23, k + 7, NovaCraftBlocks.basal, 0, 2);
		world.setBlock(i + 16, j + 23, k + 7, NovaCraftBlocks.basal, 0, 2);
		world.setBlock(i + 17, j + 23, k + 7, NovaCraftBlocks.basal, 0, 2);
		world.setBlock(i + 18, j + 23, k + 7, NovaCraftBlocks.basal, 0, 2);
		world.setBlock(i + 19, j + 23, k + 7, NovaCraftBlocks.basal, 0, 2);
		world.setBlock(i + 20, j + 23, k + 7, Blocks.air, 0, 2);
		world.setBlock(i + 21, j + 23, k + 7, Blocks.air, 0, 2);
		world.setBlock(i + 22, j + 23, k + 7, Blocks.air, 0, 2);
		world.setBlock(i + 23, j + 23, k + 7, NovaCraftBlocks.basal, 0, 2);
		world.setBlock(i + 24, j + 23, k + 7, NovaCraftBlocks.basal, 0, 2);
		world.setBlock(i + 25, j + 23, k + 7, NovaCraftBlocks.basal, 0, 2);
		world.setBlock(i + 26, j + 23, k + 7, NovaCraftBlocks.basal, 0, 2);
		world.setBlock(i + 27, j + 23, k + 7, NovaCraftBlocks.basal, 0, 2);
		world.setBlock(i + 0, j + 23, k + 8, Blocks.air, 0, 2);
		world.setBlock(i + 1, j + 23, k + 8, Blocks.air, 0, 2);
		world.setBlock(i + 2, j + 23, k + 8, NovaCraftBlocks.basal, 0, 2);
		world.setBlock(i + 3, j + 23, k + 8, NovaCraftBlocks.basal, 0, 2);
		world.setBlock(i + 4, j + 23, k + 8, NovaCraftBlocks.basal, 0, 2);
		world.setBlock(i + 5, j + 23, k + 8, NovaCraftBlocks.basal, 0, 2);
		world.setBlock(i + 6, j + 23, k + 8, NovaCraftBlocks.basal, 0, 2);
		world.setBlock(i + 7, j + 23, k + 8, NovaCraftBlocks.basal, 0, 2);
		world.setBlock(i + 8, j + 23, k + 8, NovaCraftBlocks.basal, 0, 2);
		world.setBlock(i + 9, j + 23, k + 8, NovaCraftBlocks.basal, 0, 2);
		world.setBlock(i + 10, j + 23, k + 8, NovaCraftBlocks.basal, 0, 2);
		world.setBlock(i + 11, j + 23, k + 8, NovaCraftBlocks.basal, 0, 2);
		world.setBlock(i + 12, j + 23, k + 8, NovaCraftBlocks.cracked_basal_bricks, 0, 2);
		world.setBlock(i + 13, j + 23, k + 8, Blocks.air, 0, 2);
		world.setBlock(i + 14, j + 23, k + 8, NovaCraftBlocks.basal, 0, 2);
		world.setBlock(i + 15, j + 23, k + 8, NovaCraftBlocks.basal, 0, 2);
		world.setBlock(i + 16, j + 23, k + 8, NovaCraftBlocks.basal, 0, 2);
		world.setBlock(i + 17, j + 23, k + 8, NovaCraftBlocks.basal, 0, 2);
		world.setBlock(i + 18, j + 23, k + 8, NovaCraftBlocks.basal, 0, 2);
		world.setBlock(i + 19, j + 23, k + 8, NovaCraftBlocks.basal, 0, 2);
		world.setBlock(i + 20, j + 23, k + 8, NovaCraftBlocks.basal, 0, 2);
		world.setBlock(i + 21, j + 23, k + 8, NovaCraftBlocks.basal, 0, 2);
		world.setBlock(i + 22, j + 23, k + 8, NovaCraftBlocks.basal, 0, 2);
		world.setBlock(i + 23, j + 23, k + 8, NovaCraftBlocks.basal, 0, 2);
		world.setBlock(i + 24, j + 23, k + 8, NovaCraftBlocks.basal, 0, 2);
		world.setBlock(i + 25, j + 23, k + 8, NovaCraftBlocks.basal, 0, 2);
		world.setBlock(i + 26, j + 23, k + 8, NovaCraftBlocks.basal, 0, 2);
		world.setBlock(i + 27, j + 23, k + 8, NovaCraftBlocks.basal, 0, 2);
		world.setBlock(i + 0, j + 23, k + 9, Blocks.air, 0, 2);
		world.setBlock(i + 1, j + 23, k + 9, Blocks.air, 0, 2);
		world.setBlock(i + 2, j + 23, k + 9, Blocks.air, 0, 2);
		world.setBlock(i + 3, j + 23, k + 9, NovaCraftBlocks.basal, 0, 2);
		world.setBlock(i + 4, j + 23, k + 9, NovaCraftBlocks.basal, 0, 2);
		world.setBlock(i + 5, j + 23, k + 9, NovaCraftBlocks.basal, 0, 2);
		world.setBlock(i + 6, j + 23, k + 9, NovaCraftBlocks.basal, 0, 2);
		world.setBlock(i + 7, j + 23, k + 9, NovaCraftBlocks.basal, 0, 2);
		world.setBlock(i + 8, j + 23, k + 9, NovaCraftBlocks.basal, 0, 2);
		world.setBlock(i + 9, j + 23, k + 9, NovaCraftBlocks.basal, 0, 2);
		world.setBlock(i + 10, j + 23, k + 9, NovaCraftBlocks.basal, 0, 2);
		world.setBlock(i + 11, j + 23, k + 9, NovaCraftBlocks.cracked_basal_bricks, 0, 2);
		world.setBlock(i + 12, j + 23, k + 9, Blocks.air, 0, 2);
		world.setBlock(i + 13, j + 23, k + 9, Blocks.air, 0, 2);
		world.setBlock(i + 14, j + 23, k + 9, NovaCraftBlocks.basal, 0, 2);
		world.setBlock(i + 15, j + 23, k + 9, NovaCraftBlocks.basal, 0, 2);
		world.setBlock(i + 16, j + 23, k + 9, NovaCraftBlocks.basal, 0, 2);
		world.setBlock(i + 17, j + 23, k + 9, NovaCraftBlocks.basal, 0, 2);
		world.setBlock(i + 18, j + 23, k + 9, NovaCraftBlocks.basal, 0, 2);
		world.setBlock(i + 19, j + 23, k + 9, NovaCraftBlocks.basal, 0, 2);
		world.setBlock(i + 20, j + 23, k + 9, NovaCraftBlocks.basal, 0, 2);
		world.setBlock(i + 21, j + 23, k + 9, NovaCraftBlocks.basal, 0, 2);
		world.setBlock(i + 22, j + 23, k + 9, NovaCraftBlocks.cracked_basal_bricks, 0, 2);
		world.setBlock(i + 23, j + 23, k + 9, NovaCraftBlocks.basal, 0, 2);
		world.setBlock(i + 24, j + 23, k + 9, NovaCraftBlocks.basal, 0, 2);
		world.setBlock(i + 25, j + 23, k + 9, NovaCraftBlocks.basal, 0, 2);
		world.setBlock(i + 26, j + 23, k + 9, NovaCraftBlocks.basal, 0, 2);
		world.setBlock(i + 27, j + 23, k + 9, Blocks.air, 0, 2);
		world.setBlock(i + 0, j + 23, k + 10, Blocks.air, 0, 2);
		world.setBlock(i + 1, j + 23, k + 10, Blocks.air, 0, 2);
		world.setBlock(i + 2, j + 23, k + 10, Blocks.air, 0, 2);
		world.setBlock(i + 3, j + 23, k + 10, Blocks.air, 0, 2);
		world.setBlock(i + 4, j + 23, k + 10, Blocks.air, 0, 2);
		world.setBlock(i + 5, j + 23, k + 10, Blocks.air, 0, 2);
		world.setBlock(i + 6, j + 23, k + 10, NovaCraftBlocks.basal, 0, 2);
		world.setBlock(i + 7, j + 23, k + 10, NovaCraftBlocks.basal, 0, 2);
		world.setBlock(i + 8, j + 23, k + 10, NovaCraftBlocks.basal, 0, 2);
		world.setBlock(i + 9, j + 23, k + 10, Blocks.air, 0, 2);
		world.setBlock(i + 10, j + 23, k + 10, Blocks.air, 0, 2);
		world.setBlock(i + 11, j + 23, k + 10, Blocks.air, 0, 2);
		world.setBlock(i + 12, j + 23, k + 10, Blocks.air, 0, 2);
		world.setBlock(i + 13, j + 23, k + 10, Blocks.air, 0, 2);
		world.setBlock(i + 14, j + 23, k + 10, Blocks.air, 0, 2);
		world.setBlock(i + 15, j + 23, k + 10, Blocks.air, 0, 2);
		world.setBlock(i + 16, j + 23, k + 10, NovaCraftBlocks.basal, 0, 2);
		world.setBlock(i + 17, j + 23, k + 10, NovaCraftBlocks.basal, 0, 2);
		world.setBlock(i + 18, j + 23, k + 10, NovaCraftBlocks.basal, 0, 2);
		world.setBlock(i + 19, j + 23, k + 10, NovaCraftBlocks.basal, 0, 2);
		world.setBlock(i + 20, j + 23, k + 10, NovaCraftBlocks.basal, 0, 2);
		world.setBlock(i + 21, j + 23, k + 10, NovaCraftBlocks.basal, 0, 2);
		world.setBlock(i + 22, j + 23, k + 10, NovaCraftBlocks.basal, 0, 2);
		world.setBlock(i + 23, j + 23, k + 10, NovaCraftBlocks.basal, 0, 2);
		world.setBlock(i + 24, j + 23, k + 10, NovaCraftBlocks.basal, 0, 2);
		world.setBlock(i + 25, j + 23, k + 10, NovaCraftBlocks.basal, 0, 2);
		world.setBlock(i + 26, j + 23, k + 10, NovaCraftBlocks.cracked_basal_bricks, 0, 2);
		world.setBlock(i + 27, j + 23, k + 10, Blocks.air, 0, 2);
		world.setBlock(i + 0, j + 23, k + 11, Blocks.air, 0, 2);
		world.setBlock(i + 1, j + 23, k + 11, Blocks.air, 0, 2);
		world.setBlock(i + 2, j + 23, k + 11, Blocks.air, 0, 2);
		world.setBlock(i + 3, j + 23, k + 11, Blocks.air, 0, 2);
		world.setBlock(i + 4, j + 23, k + 11, Blocks.air, 0, 2);
		world.setBlock(i + 5, j + 23, k + 11, NovaCraftBlocks.basal_bricks, 0, 2);
		world.setBlock(i + 6, j + 23, k + 11, NovaCraftBlocks.cracked_basal_bricks, 0, 2);
		world.setBlock(i + 7, j + 23, k + 11, NovaCraftBlocks.basal_bricks, 0, 2);
		world.setBlock(i + 8, j + 23, k + 11, NovaCraftBlocks.cracked_basal_bricks, 0, 2);
		world.setBlock(i + 9, j + 23, k + 11, NovaCraftBlocks.cracked_basal_bricks, 0, 2);
		world.setBlock(i + 10, j + 23, k + 11, NovaCraftBlocks.cracked_basal_bricks, 0, 2);
		world.setBlock(i + 11, j + 23, k + 11, NovaCraftBlocks.basal_bricks, 0, 2);
		world.setBlock(i + 12, j + 23, k + 11, NovaCraftBlocks.basal_bricks, 0, 2);
		world.setBlock(i + 13, j + 23, k + 11, Blocks.air, 0, 2);
		world.setBlock(i + 14, j + 23, k + 11, Blocks.air, 0, 2);
		world.setBlock(i + 15, j + 23, k + 11, Blocks.air, 0, 2);
		world.setBlock(i + 16, j + 23, k + 11, Blocks.air, 0, 2);
		world.setBlock(i + 17, j + 23, k + 11, NovaCraftBlocks.basal, 0, 2);
		world.setBlock(i + 18, j + 23, k + 11, NovaCraftBlocks.basal, 0, 2);
		world.setBlock(i + 19, j + 23, k + 11, NovaCraftBlocks.basal, 0, 2);
		world.setBlock(i + 20, j + 23, k + 11, NovaCraftBlocks.basal, 0, 2);
		world.setBlock(i + 21, j + 23, k + 11, NovaCraftBlocks.basal, 0, 2);
		world.setBlock(i + 22, j + 23, k + 11, NovaCraftBlocks.basal, 0, 2);
		world.setBlock(i + 23, j + 23, k + 11, NovaCraftBlocks.basal, 0, 2);
		world.setBlock(i + 24, j + 23, k + 11, NovaCraftBlocks.basal, 0, 2);
		world.setBlock(i + 25, j + 23, k + 11, NovaCraftBlocks.cracked_basal_bricks, 0, 2);
		world.setBlock(i + 26, j + 23, k + 11, Blocks.air, 0, 2);
		world.setBlock(i + 27, j + 23, k + 11, Blocks.air, 0, 2);
		world.setBlock(i + 0, j + 23, k + 12, Blocks.air, 0, 2);
		world.setBlock(i + 1, j + 23, k + 12, Blocks.air, 0, 2);
		world.setBlock(i + 2, j + 23, k + 12, Blocks.air, 0, 2);
		world.setBlock(i + 3, j + 23, k + 12, Blocks.air, 0, 2);
		world.setBlock(i + 4, j + 23, k + 12, NovaCraftBlocks.basal_bricks, 0, 2);
		world.setBlock(i + 5, j + 23, k + 12, NovaCraftBlocks.basal_bricks, 0, 2);
		world.setBlock(i + 6, j + 23, k + 12, NovaCraftBlocks.basal_bricks, 0, 2);
		world.setBlock(i + 7, j + 23, k + 12, NovaCraftBlocks.basal_bricks, 0, 2);
		world.setBlock(i + 8, j + 23, k + 12, NovaCraftBlocks.basal_bricks, 0, 2);
		world.setBlock(i + 9, j + 23, k + 12, NovaCraftBlocks.basal_bricks, 0, 2);
		world.setBlock(i + 10, j + 23, k + 12, NovaCraftBlocks.basal_bricks, 0, 2);
		world.setBlock(i + 11, j + 23, k + 12, NovaCraftBlocks.basal_bricks, 0, 2);
		world.setBlock(i + 12, j + 23, k + 12, NovaCraftBlocks.basal_bricks, 0, 2);
		world.setBlock(i + 13, j + 23, k + 12, NovaCraftBlocks.basal_bricks, 0, 2);
		world.setBlock(i + 14, j + 23, k + 12, Blocks.air, 0, 2);
		world.setBlock(i + 15, j + 23, k + 12, Blocks.air, 0, 2);
		world.setBlock(i + 16, j + 23, k + 12, Blocks.air, 0, 2);
		world.setBlock(i + 17, j + 23, k + 12, Blocks.air, 0, 2);
		world.setBlock(i + 18, j + 23, k + 12, Blocks.air, 0, 2);
		world.setBlock(i + 19, j + 23, k + 12, Blocks.air, 0, 2);
		world.setBlock(i + 20, j + 23, k + 12, NovaCraftBlocks.basal, 0, 2);
		world.setBlock(i + 21, j + 23, k + 12, NovaCraftBlocks.basal, 0, 2);
		world.setBlock(i + 22, j + 23, k + 12, NovaCraftBlocks.basal, 0, 2);
		world.setBlock(i + 23, j + 23, k + 12, Blocks.air, 0, 2);
		world.setBlock(i + 24, j + 23, k + 12, Blocks.air, 0, 2);
		world.setBlock(i + 25, j + 23, k + 12, Blocks.air, 0, 2);
		world.setBlock(i + 26, j + 23, k + 12, Blocks.air, 0, 2);
		world.setBlock(i + 27, j + 23, k + 12, Blocks.air, 0, 2);
		world.setBlock(i + 0, j + 24, k + 1, NovaCraftBlocks.basal_bricks, 0, 2);
		world.setBlock(i + 1, j + 24, k + 1, NovaCraftBlocks.basal_bricks, 0, 2);
		world.setBlock(i + 4, j + 24, k + 1, NovaCraftBlocks.basal_bricks, 0, 2);
		world.setBlock(i + 5, j + 24, k + 1, NovaCraftBlocks.basal_scrap, 0, 2);
		world.setBlock(i + 8, j + 24, k + 1, NovaCraftBlocks.basal_scrap, 0, 2);
		world.setBlock(i + 9, j + 24, k + 1, NovaCraftBlocks.basal_scrap, 0, 2);
		world.setBlock(i + 12, j + 24, k + 1, NovaCraftBlocks.basal_scrap, 0, 2);
		world.setBlock(i + 13, j + 24, k + 1, NovaCraftBlocks.basal_scrap, 0, 2);
		world.setBlock(i + 0, j + 24, k + 2, NovaCraftBlocks.basal_bricks, 0, 2);
		world.setBlock(i + 1, j + 24, k + 2, NovaCraftBlocks.cracked_basal_bricks, 0, 2);
		world.setBlock(i + 4, j + 24, k + 2, NovaCraftBlocks.cracked_basal_bricks, 0, 2);
		world.setBlock(i + 5, j + 24, k + 2, NovaCraftBlocks.basal_bricks, 0, 2);
		world.setBlock(i + 8, j + 24, k + 2, NovaCraftBlocks.cracked_basal_bricks, 0, 2);
		world.setBlock(i + 9, j + 24, k + 2, NovaCraftBlocks.cracked_basal_bricks, 0, 2);
		world.setBlock(i + 12, j + 24, k + 2, NovaCraftBlocks.basal_bricks, 0, 2);
		world.setBlock(i + 13, j + 24, k + 2, NovaCraftBlocks.basal_bricks, 0, 2);
		world.setBlock(i + 0, j + 24, k + 3, NovaCraftBlocks.basal_bricks, 0, 2);
		world.setBlock(i + 1, j + 24, k + 3, NovaCraftBlocks.cracked_basal_bricks, 0, 2);
		world.setBlock(i + 2, j + 24, k + 3, NovaCraftBlocks.cracked_basal_bricks, 0, 2);
		world.setBlock(i + 3, j + 24, k + 3, NovaCraftBlocks.basal_bricks, 0, 2);
		world.setBlock(i + 4, j + 24, k + 3, NovaCraftBlocks.cracked_basal_bricks, 0, 2);
		world.setBlock(i + 5, j + 24, k + 3, NovaCraftBlocks.basal_bricks, 0, 2);
		world.setBlock(i + 6, j + 24, k + 3, NovaCraftBlocks.cracked_basal_bricks, 0, 2);
		world.setBlock(i + 7, j + 24, k + 3, NovaCraftBlocks.basal_bricks, 0, 2);
		world.setBlock(i + 8, j + 24, k + 3, NovaCraftBlocks.basal_bricks, 0, 2);
		world.setBlock(i + 9, j + 24, k + 3, NovaCraftBlocks.basal_bricks, 0, 2);
		world.setBlock(i + 10, j + 24, k + 3, NovaCraftBlocks.cracked_basal_bricks, 0, 2);
		world.setBlock(i + 11, j + 24, k + 3, NovaCraftBlocks.basal_bricks, 0, 2);
		world.setBlock(i + 12, j + 24, k + 3, NovaCraftBlocks.cracked_basal_bricks, 0, 2);
		world.setBlock(i + 13, j + 24, k + 3, NovaCraftBlocks.basal_bricks, 0, 2);
		world.setBlock(i + 14, j + 24, k + 3, NovaCraftBlocks.basal_scrap, 0, 2);
		world.setBlock(i + 15, j + 24, k + 3, NovaCraftBlocks.basal_scrap, 0, 2);
		world.setBlock(i + 18, j + 24, k + 3, NovaCraftBlocks.basal_scrap, 0, 2);
		world.setBlock(i + 19, j + 24, k + 3, NovaCraftBlocks.basal_bricks, 0, 2);
		world.setBlock(i + 22, j + 24, k + 3, NovaCraftBlocks.basal_bricks, 0, 2);
		world.setBlock(i + 23, j + 24, k + 3, NovaCraftBlocks.basal_bricks, 0, 2);
		world.setBlock(i + 26, j + 24, k + 3, NovaCraftBlocks.basal_bricks, 0, 2);
		world.setBlock(i + 27, j + 24, k + 3, NovaCraftBlocks.cracked_basal_bricks, 0, 2);
		world.setBlock(i + 0, j + 24, k + 4, NovaCraftBlocks.cracked_basal_bricks, 0, 2);
		world.setBlock(i + 1, j + 24, k + 4, NovaCraftBlocks.cracked_basal_bricks, 0, 2);
		world.setBlock(i + 2, j + 24, k + 4, NovaCraftBlocks.basal_bricks, 0, 2);
		world.setBlock(i + 3, j + 24, k + 4, Blocks.air, 0, 2);
		world.setBlock(i + 4, j + 24, k + 4, Blocks.air, 0, 2);
		world.setBlock(i + 5, j + 24, k + 4, Blocks.air, 0, 2);
		world.setBlock(i + 6, j + 24, k + 4, Blocks.air, 0, 2);
		world.setBlock(i + 7, j + 24, k + 4, Blocks.air, 0, 2);
		world.setBlock(i + 8, j + 24, k + 4, NovaCraftBlocks.cracked_basal_bricks, 0, 2);
		world.setBlock(i + 9, j + 24, k + 4, NovaCraftBlocks.basal_bricks, 0, 2);
		world.setBlock(i + 10, j + 24, k + 4, NovaCraftBlocks.basal_bricks, 0, 2);
		world.setBlock(i + 11, j + 24, k + 4, NovaCraftBlocks.basal_bricks, 0, 2);
		world.setBlock(i + 12, j + 24, k + 4, NovaCraftBlocks.cracked_basal_bricks, 0, 2);
		world.setBlock(i + 13, j + 24, k + 4, NovaCraftBlocks.cracked_basal_bricks, 0, 2);
		world.setBlock(i + 14, j + 24, k + 4, NovaCraftBlocks.basal_bricks, 0, 2);
		world.setBlock(i + 15, j + 24, k + 4, NovaCraftBlocks.cracked_basal_bricks, 0, 2);
		world.setBlock(i + 16, j + 24, k + 4, Blocks.air, 0, 2);
		world.setBlock(i + 17, j + 24, k + 4, Blocks.air, 0, 2);
		world.setBlock(i + 18, j + 24, k + 4, NovaCraftBlocks.basal_bricks, 0, 2);
		world.setBlock(i + 19, j + 24, k + 4, NovaCraftBlocks.basal_bricks, 0, 2);
		world.setBlock(i + 20, j + 24, k + 4, Blocks.air, 0, 2);
		world.setBlock(i + 21, j + 24, k + 4, Blocks.air, 0, 2);
		world.setBlock(i + 22, j + 24, k + 4, NovaCraftBlocks.basal_bricks, 0, 2);
		world.setBlock(i + 23, j + 24, k + 4, NovaCraftBlocks.basal_bricks, 0, 2);
		world.setBlock(i + 24, j + 24, k + 4, Blocks.air, 0, 2);
		world.setBlock(i + 25, j + 24, k + 4, Blocks.air, 0, 2);
		world.setBlock(i + 26, j + 24, k + 4, NovaCraftBlocks.cracked_basal_bricks, 0, 2);
		world.setBlock(i + 27, j + 24, k + 4, NovaCraftBlocks.cracked_basal_bricks, 0, 2);
		world.setBlock(i + 0, j + 24, k + 5, NovaCraftBlocks.basal_bricks, 0, 2);
		world.setBlock(i + 1, j + 24, k + 5, NovaCraftBlocks.basal_bricks, 0, 2);
		world.setBlock(i + 2, j + 24, k + 5, NovaCraftBlocks.cracked_basal_bricks, 0, 2);
		world.setBlock(i + 3, j + 24, k + 5, Blocks.air, 0, 2);
		world.setBlock(i + 4, j + 24, k + 5, Blocks.air, 0, 2);
		world.setBlock(i + 5, j + 24, k + 5, Blocks.air, 0, 2);
		world.setBlock(i + 6, j + 24, k + 5, Blocks.air, 0, 2);
		world.setBlock(i + 7, j + 24, k + 5, Blocks.air, 0, 2);
		world.setBlock(i + 8, j + 24, k + 5, NovaCraftBlocks.basal_bricks, 0, 2);
		world.setBlock(i + 9, j + 24, k + 5, NovaCraftBlocks.cracked_basal_bricks, 0, 2);
		world.setBlock(i + 10, j + 24, k + 5, NovaCraftBlocks.basal_bricks, 0, 2);
		world.setBlock(i + 11, j + 24, k + 5, NovaCraftBlocks.basal_bricks, 0, 2);
		world.setBlock(i + 12, j + 24, k + 5, NovaCraftBlocks.basal_bricks, 0, 2);
		world.setBlock(i + 13, j + 24, k + 5, NovaCraftBlocks.basal_bricks, 0, 2);
		world.setBlock(i + 14, j + 24, k + 5, NovaCraftBlocks.cracked_basal_bricks, 0, 2);
		world.setBlock(i + 15, j + 24, k + 5, NovaCraftBlocks.cracked_basal_bricks, 0, 2);
		world.setBlock(i + 16, j + 24, k + 5, NovaCraftBlocks.basal_bricks, 0, 2);
		world.setBlock(i + 17, j + 24, k + 5, NovaCraftBlocks.cracked_basal_bricks, 0, 2);
		world.setBlock(i + 18, j + 24, k + 5, NovaCraftBlocks.basal_bricks, 0, 2);
		world.setBlock(i + 19, j + 24, k + 5, NovaCraftBlocks.basal_bricks, 0, 2);
		world.setBlock(i + 20, j + 24, k + 5, NovaCraftBlocks.basal_bricks, 0, 2);
		world.setBlock(i + 21, j + 24, k + 5, NovaCraftBlocks.basal_bricks, 0, 2);
		world.setBlock(i + 22, j + 24, k + 5, NovaCraftBlocks.basal_bricks, 0, 2);
		world.setBlock(i + 23, j + 24, k + 5, NovaCraftBlocks.cracked_basal_bricks, 0, 2);
		world.setBlock(i + 24, j + 24, k + 5, NovaCraftBlocks.basal_bricks, 0, 2);
		world.setBlock(i + 25, j + 24, k + 5, NovaCraftBlocks.cracked_basal_bricks, 0, 2);
		world.setBlock(i + 26, j + 24, k + 5, NovaCraftBlocks.basal_bricks, 0, 2);
		world.setBlock(i + 27, j + 24, k + 5, NovaCraftBlocks.cracked_basal_bricks, 0, 2);
		world.setBlock(i + 0, j + 24, k + 6, NovaCraftBlocks.basal_bricks, 0, 2);
		world.setBlock(i + 1, j + 24, k + 6, NovaCraftBlocks.cracked_basal_bricks, 0, 2);
		world.setBlock(i + 2, j + 24, k + 6, NovaCraftBlocks.cracked_basal_bricks, 0, 2);
		world.setBlock(i + 3, j + 24, k + 6, NovaCraftBlocks.basal_bricks, 0, 2);
		world.setBlock(i + 4, j + 24, k + 6, NovaCraftBlocks.cracked_basal_bricks, 0, 2);
		world.setBlock(i + 5, j + 24, k + 6, NovaCraftBlocks.basal_bricks, 0, 2);
		world.setBlock(i + 6, j + 24, k + 6, NovaCraftBlocks.cracked_basal_bricks, 0, 2);
		world.setBlock(i + 7, j + 24, k + 6, NovaCraftBlocks.cracked_basal_bricks, 0, 2);
		world.setBlock(i + 8, j + 24, k + 6, NovaCraftBlocks.basal_bricks, 0, 2);
		world.setBlock(i + 9, j + 24, k + 6, NovaCraftBlocks.basal_bricks, 0, 2);
		world.setBlock(i + 10, j + 24, k + 6, NovaCraftBlocks.basal_bricks, 0, 2);
		world.setBlock(i + 11, j + 24, k + 6, NovaCraftBlocks.basal_bricks, 0, 2);
		world.setBlock(i + 12, j + 24, k + 6, NovaCraftBlocks.basal_bricks, 0, 2);
		world.setBlock(i + 13, j + 24, k + 6, NovaCraftBlocks.cracked_basal_bricks, 0, 2);
		world.setBlock(i + 14, j + 24, k + 6, NovaCraftBlocks.basal_bricks, 0, 2);
		world.setBlock(i + 15, j + 24, k + 6, NovaCraftBlocks.basal_bricks, 0, 2);
		world.setBlock(i + 16, j + 24, k + 6, NovaCraftBlocks.cracked_basal_bricks, 0, 2);
		world.setBlock(i + 17, j + 24, k + 6, Blocks.air, 0, 2);
		world.setBlock(i + 19, j + 24, k + 6, Blocks.air, 0, 2);
		world.setBlock(i + 20, j + 24, k + 6, Blocks.air, 0, 2);
		world.setBlock(i + 21, j + 24, k + 6, Blocks.air, 0, 2);
		world.setBlock(i + 22, j + 24, k + 6, NovaCraftBlocks.basal_bricks, 0, 2);
		world.setBlock(i + 23, j + 24, k + 6, NovaCraftBlocks.basal_bricks, 0, 2);
		world.setBlock(i + 24, j + 24, k + 6, NovaCraftBlocks.basal_bricks, 0, 2);
		world.setBlock(i + 25, j + 24, k + 6, NovaCraftBlocks.basal_bricks, 0, 2);
		world.setBlock(i + 26, j + 24, k + 6, NovaCraftBlocks.basal_bricks, 0, 2);
		world.setBlock(i + 27, j + 24, k + 6, NovaCraftBlocks.basal_bricks, 0, 2);
		world.setBlock(i + 0, j + 24, k + 7, NovaCraftBlocks.basal_bricks, 0, 2);
		world.setBlock(i + 1, j + 24, k + 7, NovaCraftBlocks.cracked_basal_bricks, 0, 2);
		world.setBlock(i + 2, j + 24, k + 7, NovaCraftBlocks.basal_bricks, 0, 2);
		world.setBlock(i + 3, j + 24, k + 7, NovaCraftBlocks.basal_bricks, 0, 2);
		world.setBlock(i + 4, j + 24, k + 7, NovaCraftBlocks.cracked_basal_bricks, 0, 2);
		world.setBlock(i + 5, j + 24, k + 7, NovaCraftBlocks.basal_bricks, 0, 2);
		world.setBlock(i + 6, j + 24, k + 7, NovaCraftBlocks.basal_bricks, 0, 2);
		world.setBlock(i + 7, j + 24, k + 7, NovaCraftBlocks.basal_bricks, 0, 2);
		world.setBlock(i + 8, j + 24, k + 7, NovaCraftBlocks.basal_bricks, 0, 2);
		world.setBlock(i + 9, j + 24, k + 7, NovaCraftBlocks.basal_bricks, 0, 2);
		world.setBlock(i + 10, j + 24, k + 7, NovaCraftBlocks.cracked_basal_bricks, 0, 2);
		world.setBlock(i + 11, j + 24, k + 7, NovaCraftBlocks.basal_bricks, 0, 2);
		world.setBlock(i + 12, j + 24, k + 7, NovaCraftBlocks.basal_bricks, 0, 2);
		world.setBlock(i + 13, j + 24, k + 7, NovaCraftBlocks.basal_bricks, 0, 2);
		world.setBlock(i + 14, j + 24, k + 7, NovaCraftBlocks.cracked_basal_bricks, 0, 2);
		world.setBlock(i + 15, j + 24, k + 7, NovaCraftBlocks.basal_bricks, 0, 2);
		world.setBlock(i + 16, j + 24, k + 7, NovaCraftBlocks.basal_bricks, 0, 2);
		world.setBlock(i + 17, j + 24, k + 7, Blocks.air, 0, 2);
		world.setBlock(i + 18, j + 24, k + 7, Blocks.air, 0, 2);
		world.setBlock(i + 19, j + 24, k + 7, Blocks.air, 0, 2);
		world.setBlock(i + 20, j + 24, k + 7, Blocks.air, 0, 2);
		world.setBlock(i + 21, j + 24, k + 7, Blocks.air, 0, 2);
		world.setBlock(i + 22, j + 24, k + 7, NovaCraftBlocks.basal_bricks, 0, 2);
		world.setBlock(i + 23, j + 24, k + 7, NovaCraftBlocks.basal_bricks, 0, 2);
		world.setBlock(i + 24, j + 24, k + 7, NovaCraftBlocks.basal_bricks, 0, 2);
		world.setBlock(i + 25, j + 24, k + 7, NovaCraftBlocks.basal_bricks, 0, 2);
		world.setBlock(i + 26, j + 24, k + 7, NovaCraftBlocks.cracked_basal_bricks, 0, 2);
		world.setBlock(i + 27, j + 24, k + 7, NovaCraftBlocks.basal_bricks, 0, 2);
		world.setBlock(i + 0, j + 24, k + 8, NovaCraftBlocks.basal_bricks, 0, 2);
		world.setBlock(i + 1, j + 24, k + 8, NovaCraftBlocks.basal_bricks, 0, 2);
		world.setBlock(i + 2, j + 24, k + 8, NovaCraftBlocks.cracked_basal_bricks, 0, 2);
		world.setBlock(i + 3, j + 24, k + 8, NovaCraftBlocks.basal_bricks, 0, 2);
		world.setBlock(i + 4, j + 24, k + 8, NovaCraftBlocks.basal_bricks, 0, 2);
		world.setBlock(i + 5, j + 24, k + 8, NovaCraftBlocks.basal_bricks, 0, 2);
		world.setBlock(i + 6, j + 24, k + 8, NovaCraftBlocks.cracked_basal_bricks, 0, 2);
		world.setBlock(i + 7, j + 24, k + 8, NovaCraftBlocks.cracked_basal_bricks, 0, 2);
		world.setBlock(i + 8, j + 24, k + 8, NovaCraftBlocks.cracked_basal_bricks, 0, 2);
		world.setBlock(i + 9, j + 24, k + 8, NovaCraftBlocks.basal_bricks, 0, 2);
		world.setBlock(i + 10, j + 24, k + 8, NovaCraftBlocks.basal_bricks, 0, 2);
		world.setBlock(i + 11, j + 24, k + 8, NovaCraftBlocks.basal_bricks, 0, 2);
		world.setBlock(i + 12, j + 24, k + 8, NovaCraftBlocks.basal_bricks, 0, 2);
		world.setBlock(i + 13, j + 24, k + 8, NovaCraftBlocks.cracked_basal_bricks, 0, 2);
		world.setBlock(i + 14, j + 24, k + 8, NovaCraftBlocks.basal_bricks, 0, 2);
		world.setBlock(i + 15, j + 24, k + 8, NovaCraftBlocks.basal_bricks, 0, 2);
		world.setBlock(i + 16, j + 24, k + 8, NovaCraftBlocks.cracked_basal_bricks, 0, 2);
		world.setBlock(i + 17, j + 24, k + 8, NovaCraftBlocks.basal_bricks, 0, 2);
		world.setBlock(i + 18, j + 24, k + 8, NovaCraftBlocks.cracked_basal_bricks, 0, 2);
		world.setBlock(i + 19, j + 24, k + 8, NovaCraftBlocks.basal_bricks, 0, 2);
		world.setBlock(i + 20, j + 24, k + 8, NovaCraftBlocks.cracked_basal_bricks, 0, 2);
		world.setBlock(i + 21, j + 24, k + 8, NovaCraftBlocks.basal_bricks, 0, 2);
		world.setBlock(i + 22, j + 24, k + 8, NovaCraftBlocks.basal_bricks, 0, 2);
		world.setBlock(i + 23, j + 24, k + 8, NovaCraftBlocks.basal_bricks, 0, 2);
		world.setBlock(i + 24, j + 24, k + 8, NovaCraftBlocks.basal_bricks, 0, 2);
		world.setBlock(i + 25, j + 24, k + 8, NovaCraftBlocks.cracked_basal_bricks, 0, 2);
		world.setBlock(i + 26, j + 24, k + 8, NovaCraftBlocks.cracked_basal_bricks, 0, 2);
		world.setBlock(i + 27, j + 24, k + 8, NovaCraftBlocks.cracked_basal_bricks, 0, 2);
		world.setBlock(i + 0, j + 24, k + 9, NovaCraftBlocks.basal_bricks, 0, 2);
		world.setBlock(i + 1, j + 24, k + 9, NovaCraftBlocks.cracked_basal_bricks, 0, 2);
		world.setBlock(i + 2, j + 24, k + 9, NovaCraftBlocks.basal_bricks, 0, 2);
		world.setBlock(i + 3, j + 24, k + 9, NovaCraftBlocks.basal_bricks, 0, 2);
		world.setBlock(i + 4, j + 24, k + 9, NovaCraftBlocks.basal_bricks, 0, 2);
		world.setBlock(i + 5, j + 24, k + 9, NovaCraftBlocks.cracked_basal_bricks, 0, 2);
		world.setBlock(i + 6, j + 24, k + 9, NovaCraftBlocks.basal_bricks, 0, 2);
		world.setBlock(i + 7, j + 24, k + 9, NovaCraftBlocks.basal_bricks, 0, 2);
		world.setBlock(i + 8, j + 24, k + 9, NovaCraftBlocks.basal_bricks, 0, 2);
		world.setBlock(i + 9, j + 24, k + 9, NovaCraftBlocks.cracked_basal_bricks, 0, 2);
		world.setBlock(i + 10, j + 24, k + 9, NovaCraftBlocks.cracked_basal_bricks, 0, 2);
		world.setBlock(i + 11, j + 24, k + 9, NovaCraftBlocks.basal_bricks, 0, 2);
		world.setBlock(i + 12, j + 24, k + 9, NovaCraftBlocks.basal_bricks, 0, 2);
		world.setBlock(i + 13, j + 24, k + 9, NovaCraftBlocks.cracked_basal_bricks, 0, 2);
		world.setBlock(i + 14, j + 24, k + 9, NovaCraftBlocks.basal_bricks, 0, 2);
		world.setBlock(i + 15, j + 24, k + 9, NovaCraftBlocks.cracked_basal_bricks, 0, 2);
		world.setBlock(i + 16, j + 24, k + 9, NovaCraftBlocks.basal_bricks, 0, 2);
		world.setBlock(i + 17, j + 24, k + 9, NovaCraftBlocks.basal_bricks, 0, 2);
		world.setBlock(i + 18, j + 24, k + 9, NovaCraftBlocks.cracked_basal_bricks, 0, 2);
		world.setBlock(i + 19, j + 24, k + 9, NovaCraftBlocks.basal_bricks, 0, 2);
		world.setBlock(i + 20, j + 24, k + 9, NovaCraftBlocks.basal, 0, 2);
		world.setBlock(i + 21, j + 24, k + 9, NovaCraftBlocks.basal, 0, 2);
		world.setBlock(i + 22, j + 24, k + 9, NovaCraftBlocks.basal_bricks, 0, 2);
		world.setBlock(i + 23, j + 24, k + 9, NovaCraftBlocks.cracked_basal_bricks, 0, 2);
		world.setBlock(i + 24, j + 24, k + 9, NovaCraftBlocks.cracked_basal_bricks, 0, 2);
		world.setBlock(i + 25, j + 24, k + 9, NovaCraftBlocks.cracked_basal_bricks, 0, 2);
		world.setBlock(i + 26, j + 24, k + 9, NovaCraftBlocks.basal_bricks, 0, 2);
		world.setBlock(i + 27, j + 24, k + 9, NovaCraftBlocks.basal_bricks, 0, 2);
		world.setBlock(i + 0, j + 24, k + 10, NovaCraftBlocks.basal_bricks, 0, 2);
		world.setBlock(i + 1, j + 24, k + 10, NovaCraftBlocks.basal_bricks, 0, 2);
		world.setBlock(i + 2, j + 24, k + 10, NovaCraftBlocks.basal_bricks, 0, 2);
		world.setBlock(i + 3, j + 24, k + 10, NovaCraftBlocks.cracked_basal_bricks, 0, 2);
		world.setBlock(i + 4, j + 24, k + 10, NovaCraftBlocks.cracked_basal_bricks, 0, 2);
		world.setBlock(i + 5, j + 24, k + 10, NovaCraftBlocks.basal_bricks, 0, 2);
		world.setBlock(i + 6, j + 24, k + 10, NovaCraftBlocks.cracked_basal_bricks, 0, 2);
		world.setBlock(i + 7, j + 24, k + 10, NovaCraftBlocks.basal_bricks, 0, 2);
		world.setBlock(i + 8, j + 24, k + 10, NovaCraftBlocks.basal_bricks, 0, 2);
		world.setBlock(i + 9, j + 24, k + 10, NovaCraftBlocks.cracked_basal_bricks, 0, 2);
		world.setBlock(i + 10, j + 24, k + 10, NovaCraftBlocks.basal_bricks, 0, 2);
		world.setBlock(i + 11, j + 24, k + 10, NovaCraftBlocks.cracked_basal_bricks, 0, 2);
		world.setBlock(i + 12, j + 24, k + 10, NovaCraftBlocks.cracked_basal_bricks, 0, 2);
		world.setBlock(i + 13, j + 24, k + 10, NovaCraftBlocks.basal_bricks, 0, 2);
		world.setBlock(i + 14, j + 24, k + 10, NovaCraftBlocks.cracked_basal_bricks, 0, 2);
		world.setBlock(i + 15, j + 24, k + 10, NovaCraftBlocks.cracked_basal_bricks, 0, 2);
		world.setBlock(i + 16, j + 24, k + 10, NovaCraftBlocks.basal_bricks, 0, 2);
		world.setBlock(i + 17, j + 24, k + 10, NovaCraftBlocks.basal_bricks, 0, 2);
		world.setBlock(i + 18, j + 24, k + 10, NovaCraftBlocks.basal_bricks, 0, 2);
		world.setBlock(i + 19, j + 24, k + 10, NovaCraftBlocks.cracked_basal_bricks, 0, 2);
		world.setBlock(i + 20, j + 24, k + 10, NovaCraftBlocks.basal, 0, 2);
		world.setBlock(i + 21, j + 24, k + 10, NovaCraftBlocks.basal, 0, 2);
		world.setBlock(i + 22, j + 24, k + 10, NovaCraftBlocks.basal, 0, 2);
		world.setBlock(i + 23, j + 24, k + 10, NovaCraftBlocks.basal_bricks, 0, 2);
		world.setBlock(i + 24, j + 24, k + 10, NovaCraftBlocks.basal_bricks, 0, 2);
		world.setBlock(i + 25, j + 24, k + 10, NovaCraftBlocks.cracked_basal_bricks, 0, 2);
		world.setBlock(i + 26, j + 24, k + 10, NovaCraftBlocks.basal_bricks, 0, 2);
		world.setBlock(i + 27, j + 24, k + 10, NovaCraftBlocks.cracked_basal_bricks, 0, 2);
		world.setBlock(i + 0, j + 24, k + 11, Blocks.air, 0, 2);
		world.setBlock(i + 1, j + 24, k + 11, Blocks.air, 0, 2);
		world.setBlock(i + 2, j + 24, k + 11, Blocks.air, 0, 2);
		world.setBlock(i + 3, j + 24, k + 11, NovaCraftBlocks.cracked_basal_bricks, 0, 2);
		world.setBlock(i + 4, j + 24, k + 11, NovaCraftBlocks.basal_bricks, 0, 2);
		world.setBlock(i + 5, j + 24, k + 11, NovaCraftBlocks.basal_bricks, 0, 2);
		world.setBlock(i + 6, j + 24, k + 11, NovaCraftBlocks.basal_bricks, 0, 2);
		world.setBlock(i + 7, j + 24, k + 11, NovaCraftBlocks.basal_bricks, 0, 2);
		world.setBlock(i + 8, j + 24, k + 11, NovaCraftBlocks.basal_bricks, 0, 2);
		world.setBlock(i + 9, j + 24, k + 11, NovaCraftBlocks.basal_bricks, 0, 2);
		world.setBlock(i + 10, j + 24, k + 11, NovaCraftBlocks.basal_bricks, 0, 2);
		world.setBlock(i + 11, j + 24, k + 11, NovaCraftBlocks.basal_bricks, 0, 2);
		world.setBlock(i + 12, j + 24, k + 11, NovaCraftBlocks.basal_bricks, 0, 2);
		world.setBlock(i + 13, j + 24, k + 11, Blocks.air, 0, 2);
		world.setBlock(i + 14, j + 24, k + 11, NovaCraftBlocks.cracked_basal_bricks, 0, 2);
		world.setBlock(i + 15, j + 24, k + 11, NovaCraftBlocks.cracked_basal_bricks, 0, 2);
		world.setBlock(i + 16, j + 24, k + 11, NovaCraftBlocks.cracked_basal_bricks, 0, 2);
		world.setBlock(i + 17, j + 24, k + 11, NovaCraftBlocks.basal_bricks, 0, 2);
