package com.NovaCraft.world.bastion.treasure;

import cpw.mods.fml.common.registry.GameRegistry;
import net.minecraft.world.gen.feature.*;
import net.minecraft.block.*;
import net.minecraft.world.*;
import java.util.*;
import com.NovaCraft.config.Configs;
import com.NovaCraft.entity.EntitySavageSerpent;
import com.NovaCraftBlocks.NovaCraftBlocks;
import cpw.mods.fml.common.Loader;
import net.minecraft.init.*;

public class BastionTreasureRoomGen6 extends WorldGenerator
{
	public BastionTreasureRoomGen6() {

	}
	
	private Block PlaceChain;

	private Block determineIfChainExists(World world, int x, int y, int z) {
		Block existingBlock = world.getBlock(x, y, z);
		if (!(Configs.disableChain) && Loader.isModLoaded("etfuturum")) {
			try {
				Block chain = GameRegistry.findBlock("etfuturum", "chain");
				if (chain != null && (existingBlock == null || existingBlock != chain)) {
					return chain;
				}
			} catch (Exception ex) {
				if (Configs.enableDebugMode) {
					System.out.println("Missing Chains from Et Futurum Requiem, using Basal Walls instead...");
				}
				return NovaCraftBlocks.basal_wall;
			}
		}

		return NovaCraftBlocks.basal_bricks;
	}
	
	public boolean generate(final World world, final Random random, final int i, final int j, final int k) {		
		PlaceChain = determineIfChainExists(world, i + 12, j + 20, k + 3);
		
		world.setBlock(i + 19, j + 19, k + 1, NovaCraftBlocks.cracked_basal_bricks, 0, 2);
		world.setBlock(i + 20, j + 19, k + 1, NovaCraftBlocks.cracked_basal_bricks, 0, 2);
		world.setBlock(i + 21, j + 19, k + 1, NovaCraftBlocks.cracked_basal_bricks, 0, 2);
		world.setBlock(i + 22, j + 19, k + 1, NovaCraftBlocks.basal_bricks, 0, 2);
		world.setBlock(i + 23, j + 19, k + 1, NovaCraftBlocks.basal, 0, 2);
		world.setBlock(i + 24, j + 19, k + 1, NovaCraftBlocks.basal_bricks, 0, 2);
		world.setBlock(i + 25, j + 19, k + 1, NovaCraftBlocks.basal_bricks, 0, 2);
		world.setBlock(i + 26, j + 19, k + 1, NovaCraftBlocks.cracked_basal_bricks, 0, 2);
		world.setBlock(i + 27, j + 19, k + 1, NovaCraftBlocks.cracked_basal_bricks, 0, 2);
		world.setBlock(i + 28, j + 19, k + 1, NovaCraftBlocks.basal_bricks, 0, 2);
		world.setBlock(i + 29, j + 19, k + 1, NovaCraftBlocks.cracked_basal_bricks, 0, 2);
		world.setBlock(i + 30, j + 19, k + 1, NovaCraftBlocks.cracked_basal_bricks, 0, 2);
		world.setBlock(i + 31, j + 19, k + 1, NovaCraftBlocks.cracked_basal_bricks, 0, 2);
		world.setBlock(i + 32, j + 19, k + 1, NovaCraftBlocks.cracked_basal_bricks, 0, 2);
		world.setBlock(i + 33, j + 19, k + 1, NovaCraftBlocks.cracked_basal_bricks, 0, 2);
		world.setBlock(i + 34, j + 19, k + 1, NovaCraftBlocks.basal_bricks, 0, 2);
		world.setBlock(i + 35, j + 19, k + 1, NovaCraftBlocks.cracked_basal_bricks, 0, 2);
		world.setBlock(i, j + 19, k + 2, NovaCraftBlocks.basal_bricks, 0, 2);
		world.setBlock(i + 1, j + 19, k + 2, NovaCraftBlocks.basal, 0, 2);
		world.setBlock(i + 18, j + 19, k + 2, NovaCraftBlocks.cracked_basal_bricks, 0, 2);
		world.setBlock(i + 19, j + 19, k + 2, NovaCraftBlocks.basal_scrap, 0, 2);
		world.setBlock(i + 31, j + 19, k + 2, NovaCraftBlocks.cracked_basal_bricks, 0, 2);
		world.setBlock(i + 36, j + 19, k + 2, NovaCraftBlocks.cracked_basal_bricks, 0, 2);
		world.setBlock(i + 37, j + 19, k + 2, NovaCraftBlocks.cracked_basal_bricks, 0, 2);
		world.setBlock(i, j + 19, k + 3, NovaCraftBlocks.cracked_basal_bricks, 0, 2);
		world.setBlock(i + 1, j + 19, k + 3, NovaCraftBlocks.basal_bricks, 0, 2);
		world.setBlock(i + 19, j + 19, k + 3, NovaCraftBlocks.cracked_basal_bricks, 0, 2);
		world.setBlock(i + 20, j + 19, k + 3, NovaCraftBlocks.basal_scrap, 0, 2);
		world.setBlock(i + 36, j + 19, k + 3, NovaCraftBlocks.basal_bricks, 0, 2);
		world.setBlock(i + 37, j + 19, k + 3, NovaCraftBlocks.basal_bricks, 0, 2);
		world.setBlock(i, j + 19, k + 4, NovaCraftBlocks.basal_bricks, 0, 2);
		world.setBlock(i + 1, j + 19, k + 4, NovaCraftBlocks.cracked_basal_bricks, 0, 2);
		world.setBlock(i + 18, j + 19, k + 4, NovaCraftBlocks.basal_scrap, 0, 2);
		world.setBlock(i + 19, j + 19, k + 4, NovaCraftBlocks.basal_bricks, 0, 2);
		world.setBlock(i + 20, j + 19, k + 4, NovaCraftBlocks.basal_scrap, 0, 2);
		world.setBlock(i + 21, j + 19, k + 4, NovaCraftBlocks.basal_scrap, 0, 2);
		world.setBlock(i + 36, j + 19, k + 4, NovaCraftBlocks.cracked_basal_bricks, 0, 2);
		world.setBlock(i + 37, j + 19, k + 4, NovaCraftBlocks.basal, 0, 2);
		world.setBlock(i, j + 19, k + 5, NovaCraftBlocks.basal_bricks, 0, 2);
		world.setBlock(i + 1, j + 19, k + 5, NovaCraftBlocks.cracked_basal_bricks, 0, 2);
		world.setBlock(i + 16, j + 19, k + 5, NovaCraftBlocks.cracked_basal_bricks, 0, 2);
		world.setBlock(i + 17, j + 19, k + 5, Blocks.lava, 8, 2);
		world.setBlock(i + 18, j + 19, k + 5, Blocks.lava, 8, 2);
		world.setBlock(i + 19, j + 19, k + 5, Blocks.lava, 8, 2);
		world.setBlock(i + 20, j + 19, k + 5, NovaCraftBlocks.cracked_basal_bricks, 0, 2);
		world.setBlock(i + 21, j + 19, k + 5, NovaCraftBlocks.cracked_basal_bricks, 0, 2);
		world.setBlock(i + 36, j + 19, k + 5, NovaCraftBlocks.basal_bricks, 0, 2);
		world.setBlock(i + 37, j + 19, k + 5, NovaCraftBlocks.basal_bricks, 0, 2);
		world.setBlock(i, j + 19, k + 6, NovaCraftBlocks.cracked_basal_bricks, 0, 2);
		world.setBlock(i + 1, j + 19, k + 6, NovaCraftBlocks.cracked_basal_bricks, 0, 2);
		world.setBlock(i + 6, j + 19, k + 6, NovaCraftBlocks.cracked_basal_bricks, 0, 2);
		world.setBlock(i + 7, j + 19, k + 6, NovaCraftBlocks.basal_bricks, 0, 2);
		world.setBlock(i + 10, j + 19, k + 6, NovaCraftBlocks.basal_bricks, 0, 2);
		world.setBlock(i + 11, j + 19, k + 6, NovaCraftBlocks.basal, 0, 2);
		world.setBlock(i + 12, j + 19, k + 6, NovaCraftBlocks.basal, 0, 2);
		world.setBlock(i + 13, j + 19, k + 6, NovaCraftBlocks.cracked_basal_bricks, 0, 2);
		world.setBlock(i + 14, j + 19, k + 6, NovaCraftBlocks.cracked_basal_bricks, 0, 2);
		world.setBlock(i + 16, j + 19, k + 6, NovaCraftBlocks.basal_bricks, 0, 2);
		world.setBlock(i + 18, j + 19, k + 6, NovaCraftBlocks.basal_bricks, 0, 2);
		world.setBlock(i + 19, j + 19, k + 6, NovaCraftBlocks.basal_scrap, 0, 2);
		world.setBlock(i + 20, j + 19, k + 6, NovaCraftBlocks.basal_bricks, 0, 2);
		world.setBlock(i + 21, j + 19, k + 6, NovaCraftBlocks.basal_bricks, 0, 2);
		world.setBlock(i + 22, j + 19, k + 6, NovaCraftBlocks.basal_bricks, 0, 2);
		world.setBlock(i + 25, j + 19, k + 6, NovaCraftBlocks.cracked_basal_bricks, 0, 2);
		world.setBlock(i + 26, j + 19, k + 6, NovaCraftBlocks.basal_bricks, 0, 2);
		world.setBlock(i + 29, j + 19, k + 6, NovaCraftBlocks.cracked_basal_bricks, 0, 2);
		world.setBlock(i + 30, j + 19, k + 6, NovaCraftBlocks.basal_bricks, 0, 2);
		world.setBlock(i + 31, j + 19, k + 6, NovaCraftBlocks.cracked_basal_bricks, 0, 2);
		world.setBlock(i + 35, j + 19, k + 6, NovaCraftBlocks.basal_bricks, 0, 2);
		world.setBlock(i + 36, j + 19, k + 6, NovaCraftBlocks.cracked_basal_bricks, 0, 2);
		world.setBlock(i + 37, j + 19, k + 6, NovaCraftBlocks.cracked_basal_bricks, 0, 2);
		world.setBlock(i, j + 19, k + 7, NovaCraftBlocks.cracked_basal_bricks, 0, 2);
		world.setBlock(i + 1, j + 19, k + 7, NovaCraftBlocks.basal_bricks, 0, 2);
		world.setBlock(i + 36, j + 19, k + 7, NovaCraftBlocks.cracked_basal_bricks, 0, 2);
		world.setBlock(i, j + 19, k + 8, NovaCraftBlocks.cracked_basal_bricks, 0, 2);
		world.setBlock(i + 1, j + 19, k + 8, NovaCraftBlocks.cracked_basal_bricks, 0, 2);
		world.setBlock(i + 6, j + 19, k + 8, NovaCraftBlocks.cracked_basal_bricks, 0, 2);
		world.setBlock(i + 31, j + 19, k + 8, NovaCraftBlocks.basal_bricks, 0, 2);
		world.setBlock(i + 36, j + 19, k + 8, NovaCraftBlocks.cracked_basal_bricks, 0, 2);
		world.setBlock(i + 37, j + 19, k + 8, NovaCraftBlocks.cracked_basal_bricks, 0, 2);
		world.setBlock(i, j + 19, k + 9, NovaCraftBlocks.basal_bricks, 0, 2);
		world.setBlock(i + 1, j + 19, k + 9, NovaCraftBlocks.cracked_basal_bricks, 0, 2);
		world.setBlock(i + 37, j + 19, k + 9, NovaCraftBlocks.basal, 0, 2);
		world.setBlock(i, j + 19, k + 10, NovaCraftBlocks.cracked_basal_bricks, 0, 2);
		world.setBlock(i + 1, j + 19, k + 10, NovaCraftBlocks.basal_bricks, 0, 2);
		world.setBlock(i + 36, j + 19, k + 10, NovaCraftBlocks.cracked_basal_bricks, 0, 2);
		world.setBlock(i + 37, j + 19, k + 10, NovaCraftBlocks.basal, 0, 2);
		world.setBlock(i, j + 19, k + 11, NovaCraftBlocks.basal, 0, 2);
		world.setBlock(i + 1, j + 19, k + 11, NovaCraftBlocks.basal, 0, 2);
		world.setBlock(i + 2, j + 19, k + 11, NovaCraftBlocks.basal_bricks, 0, 2);
		world.setBlock(i + 3, j + 19, k + 11, NovaCraftBlocks.basal_bricks, 0, 2);
		world.setBlock(i + 34, j + 19, k + 11, NovaCraftBlocks.basal_bricks, 0, 2);
		world.setBlock(i + 35, j + 19, k + 11, NovaCraftBlocks.basal_bricks, 0, 2);
		world.setBlock(i + 36, j + 19, k + 11, NovaCraftBlocks.basal, 0, 2);
		world.setBlock(i + 37, j + 19, k + 11, NovaCraftBlocks.basal_bricks, 0, 2);
		world.setBlock(i, j + 19, k + 12, NovaCraftBlocks.basal, 0, 2);
		world.setBlock(i + 1, j + 19, k + 12, NovaCraftBlocks.basal_bricks, 0, 2);
		world.setBlock(i + 2, j + 19, k + 12, NovaCraftBlocks.basal_scrap, 0, 2);
		world.setBlock(i + 3, j + 19, k + 12, NovaCraftBlocks.cracked_basal_bricks, 0, 2);
		world.setBlock(i + 34, j + 19, k + 12, NovaCraftBlocks.basal_bricks, 0, 2);
		world.setBlock(i + 35, j + 19, k + 12, NovaCraftBlocks.cracked_basal_bricks, 0, 2);
		world.setBlock(i + 36, j + 19, k + 12, NovaCraftBlocks.basal, 0, 2);
		world.setBlock(i + 37, j + 19, k + 12, NovaCraftBlocks.basal_bricks, 0, 2);
		world.setBlock(i, j + 19, k + 13, NovaCraftBlocks.basal_bricks, 0, 2);
		world.setBlock(i + 1, j + 19, k + 13, NovaCraftBlocks.basal_bricks, 0, 2);
		world.setBlock(i + 36, j + 19, k + 13, NovaCraftBlocks.basal_bricks, 0, 2);
		world.setBlock(i + 37, j + 19, k + 13, NovaCraftBlocks.basal_bricks, 0, 2);
		world.setBlock(i, j + 19, k + 14, NovaCraftBlocks.basal, 0, 2);
		world.setBlock(i + 1, j + 19, k + 14, NovaCraftBlocks.basal_bricks, 0, 2);
		world.setBlock(i + 36, j + 19, k + 14, NovaCraftBlocks.basal_bricks, 0, 2);
		world.setBlock(i + 37, j + 19, k + 14, NovaCraftBlocks.basal, 0, 2);
		world.setBlock(i, j + 19, k + 15, NovaCraftBlocks.cracked_basal_bricks, 0, 2);
		world.setBlock(i + 1, j + 19, k + 15, NovaCraftBlocks.basal_bricks, 0, 2);
		world.setBlock(i + 36, j + 19, k + 15, NovaCraftBlocks.cracked_basal_bricks, 0, 2);
		world.setBlock(i + 37, j + 19, k + 15, NovaCraftBlocks.cracked_basal_bricks, 0, 2);
		world.setBlock(i, j + 19, k + 16, NovaCraftBlocks.basal, 0, 2);
		world.setBlock(i + 1, j + 19, k + 16, NovaCraftBlocks.cracked_basal_bricks, 0, 2);
		world.setBlock(i + 6, j + 19, k + 16, NovaCraftBlocks.basal_bricks, 0, 2);
		world.setBlock(i + 31, j + 19, k + 16, NovaCraftBlocks.basal_bricks, 0, 2);
		world.setBlock(i + 36, j + 19, k + 16, NovaCraftBlocks.cracked_basal_bricks, 0, 2);
		world.setBlock(i + 37, j + 19, k + 16, NovaCraftBlocks.basal, 0, 2);
		world.setBlock(i, j + 19, k + 17, NovaCraftBlocks.basal_bricks, 0, 2);
		world.setBlock(i + 1, j + 19, k + 17, NovaCraftBlocks.cracked_basal_bricks, 0, 2);
		world.setBlock(i + 2, j + 19, k + 17, NovaCraftBlocks.basal_bricks, 0, 2);
		world.setBlock(i + 35, j + 19, k + 17, NovaCraftBlocks.basal_bricks, 0, 2);
		world.setBlock(i + 36, j + 19, k + 17, NovaCraftBlocks.cracked_basal_bricks, 0, 2);
		world.setBlock(i + 37, j + 19, k + 17, NovaCraftBlocks.cracked_basal_bricks, 0, 2);
		world.setBlock(i, j + 19, k + 18, NovaCraftBlocks.basal_bricks, 0, 2);
		world.setBlock(i + 1, j + 19, k + 18, NovaCraftBlocks.basal, 0, 2);
		world.setBlock(i + 2, j + 19, k + 18, NovaCraftBlocks.cracked_basal_bricks, 0, 2);
		world.setBlock(i + 35, j + 19, k + 18, NovaCraftBlocks.basal_bricks, 0, 2);
		world.setBlock(i + 36, j + 19, k + 18, NovaCraftBlocks.basal_bricks, 0, 2);
		world.setBlock(i + 37, j + 19, k + 18, NovaCraftBlocks.basal_bricks, 0, 2);
		world.setBlock(i, j + 19, k + 19, NovaCraftBlocks.cracked_basal_bricks, 0, 2);
		world.setBlock(i + 1, j + 19, k + 19, NovaCraftBlocks.cracked_basal_bricks, 0, 2);
		world.setBlock(i + 2, j + 19, k + 19, NovaCraftBlocks.cracked_basal_bricks, 0, 2);
		world.setBlock(i + 35, j + 19, k + 19, NovaCraftBlocks.cracked_basal_bricks, 0, 2);
		world.setBlock(i + 36, j + 19, k + 19, NovaCraftBlocks.cracked_basal_bricks, 0, 2);
		world.setBlock(i + 37, j + 19, k + 19, NovaCraftBlocks.cracked_basal_bricks, 0, 2);
		world.setBlock(i, j + 19, k + 20, NovaCraftBlocks.basal_bricks, 0, 2);
		world.setBlock(i + 1, j + 19, k + 20, NovaCraftBlocks.basal_bricks, 0, 2);
		world.setBlock(i + 2, j + 19, k + 20, NovaCraftBlocks.basal_bricks, 0, 2);
		world.setBlock(i + 35, j + 19, k + 20, NovaCraftBlocks.cracked_basal_bricks, 0, 2);
		world.setBlock(i + 36, j + 19, k + 20, NovaCraftBlocks.cracked_basal_bricks, 0, 2);
		world.setBlock(i + 37, j + 19, k + 20, NovaCraftBlocks.cracked_basal_bricks, 0, 2);
		world.setBlock(i, j + 19, k + 21, NovaCraftBlocks.basal, 0, 2);
		world.setBlock(i + 1, j + 19, k + 21, NovaCraftBlocks.basal, 0, 2);
		world.setBlock(i + 6, j + 19, k + 21, NovaCraftBlocks.cracked_basal_bricks, 0, 2);
		world.setBlock(i + 31, j + 19, k + 21, NovaCraftBlocks.basal_bricks, 0, 2);
		world.setBlock(i + 36, j + 19, k + 21, NovaCraftBlocks.basal_bricks, 0, 2);
		world.setBlock(i + 37, j + 19, k + 21, NovaCraftBlocks.cracked_basal_bricks, 0, 2);
		world.setBlock(i, j + 19, k + 22, NovaCraftBlocks.basal_bricks, 0, 2);
		world.setBlock(i + 1, j + 19, k + 22, NovaCraftBlocks.basal_bricks, 0, 2);
		world.setBlock(i + 36, j + 19, k + 22, NovaCraftBlocks.cracked_basal_bricks, 0, 2);
		world.setBlock(i + 37, j + 19, k + 22, NovaCraftBlocks.cracked_basal_bricks, 0, 2);
		world.setBlock(i, j + 19, k + 23, NovaCraftBlocks.basal_bricks, 0, 2);
		world.setBlock(i + 1, j + 19, k + 23, NovaCraftBlocks.cracked_basal_bricks, 0, 2);
		world.setBlock(i + 36, j + 19, k + 23, NovaCraftBlocks.cracked_basal_bricks, 0, 2);
		world.setBlock(i + 37, j + 19, k + 23, NovaCraftBlocks.basal, 0, 2);
		world.setBlock(i, j + 19, k + 24, NovaCraftBlocks.cracked_basal_bricks, 0, 2);
		world.setBlock(i + 1, j + 19, k + 24, NovaCraftBlocks.basal_bricks, 0, 2);
		world.setBlock(i + 36, j + 19, k + 24, NovaCraftBlocks.basal_bricks, 0, 2);
		world.setBlock(i + 37, j + 19, k + 24, NovaCraftBlocks.basal_bricks, 0, 2);
		world.setBlock(i, j + 19, k + 25, NovaCraftBlocks.cracked_basal_bricks, 0, 2);
		world.setBlock(i + 1, j + 19, k + 25, NovaCraftBlocks.basal, 0, 2);
		world.setBlock(i + 2, j + 19, k + 25, NovaCraftBlocks.basal_bricks, 0, 2);
		world.setBlock(i + 3, j + 19, k + 25, NovaCraftBlocks.basal_bricks, 0, 2);
		world.setBlock(i + 34, j + 19, k + 25, NovaCraftBlocks.basal_bricks, 0, 2);
		world.setBlock(i + 35, j + 19, k + 25, NovaCraftBlocks.basal_scrap, 0, 2);
		world.setBlock(i + 36, j + 19, k + 25, NovaCraftBlocks.basal_bricks, 0, 2);
		world.setBlock(i + 37, j + 19, k + 25, NovaCraftBlocks.basal_bricks, 0, 2);
		world.setBlock(i, j + 19, k + 26, NovaCraftBlocks.cracked_basal_bricks, 0, 2);
		world.setBlock(i + 1, j + 19, k + 26, NovaCraftBlocks.cracked_basal_bricks, 0, 2);
		world.setBlock(i + 2, j + 19, k + 26, NovaCraftBlocks.basal_bricks, 0, 2);
		world.setBlock(i + 3, j + 19, k + 26, NovaCraftBlocks.basal_bricks, 0, 2);
		world.setBlock(i + 34, j + 19, k + 26, NovaCraftBlocks.basal_bricks, 0, 2);
		world.setBlock(i + 35, j + 19, k + 26, NovaCraftBlocks.basal_bricks, 0, 2);
		world.setBlock(i + 36, j + 19, k + 26, NovaCraftBlocks.basal_bricks, 0, 2);
		world.setBlock(i + 37, j + 19, k + 26, NovaCraftBlocks.basal_bricks, 0, 2);
		world.setBlock(i, j + 19, k + 27, NovaCraftBlocks.basal_bricks, 0, 2);
		world.setBlock(i + 1, j + 19, k + 27, NovaCraftBlocks.cracked_basal_bricks, 0, 2);
		world.setBlock(i + 36, j + 19, k + 27, NovaCraftBlocks.basal, 0, 2);
		world.setBlock(i + 37, j + 19, k + 27, NovaCraftBlocks.basal_bricks, 0, 2);
		world.setBlock(i, j + 19, k + 28, NovaCraftBlocks.cracked_basal_bricks, 0, 2);
		world.setBlock(i + 1, j + 19, k + 28, NovaCraftBlocks.basal_bricks, 0, 2);
		world.setBlock(i + 36, j + 19, k + 28, NovaCraftBlocks.cracked_basal_bricks, 0, 2);
		world.setBlock(i + 37, j + 19, k + 28, NovaCraftBlocks.basal_bricks, 0, 2);
		world.setBlock(i, j + 19, k + 29, NovaCraftBlocks.basal_bricks, 0, 2);
		world.setBlock(i + 1, j + 19, k + 29, NovaCraftBlocks.cracked_basal_bricks, 0, 2);
		world.setBlock(i + 6, j + 19, k + 29, NovaCraftBlocks.basal_bricks, 0, 2);
		world.setBlock(i + 31, j + 19, k + 29, NovaCraftBlocks.basal_bricks, 0, 2);
		world.setBlock(i + 36, j + 19, k + 29, NovaCraftBlocks.cracked_basal_bricks, 0, 2);
		world.setBlock(i + 37, j + 19, k + 29, NovaCraftBlocks.basal, 0, 2);
		world.setBlock(i, j + 19, k + 30, NovaCraftBlocks.basal, 0, 2);
		world.setBlock(i + 1, j + 19, k + 30, NovaCraftBlocks.basal_bricks, 0, 2);
		world.setBlock(i + 36, j + 19, k + 30, NovaCraftBlocks.basal_bricks, 0, 2);
		world.setBlock(i + 37, j + 19, k + 30, NovaCraftBlocks.cracked_basal_bricks, 0, 2);
		world.setBlock(i, j + 19, k + 31, NovaCraftBlocks.basal_bricks, 0, 2);
		world.setBlock(i + 1, j + 19, k + 31, NovaCraftBlocks.basal, 0, 2);
		world.setBlock(i + 6, j + 19, k + 31, NovaCraftBlocks.cracked_basal_bricks, 0, 2);
		world.setBlock(i + 7, j + 19, k + 31, NovaCraftBlocks.cracked_basal_bricks, 0, 2);
		world.setBlock(i + 8, j + 19, k + 31, NovaCraftBlocks.cracked_basal_bricks, 0, 2);
		world.setBlock(i + 11, j + 19, k + 31, NovaCraftBlocks.cracked_basal_bricks, 0, 2);
		world.setBlock(i + 12, j + 19, k + 31, NovaCraftBlocks.basal_bricks, 0, 2);
		world.setBlock(i + 15, j + 19, k + 31, NovaCraftBlocks.basal_bricks, 0, 2);
		world.setBlock(i + 16, j + 19, k + 31, NovaCraftBlocks.basal_bricks, 0, 2);
		world.setBlock(i + 17, j + 19, k + 31, NovaCraftBlocks.cracked_basal_bricks, 0, 2);
		world.setBlock(i + 18, j + 19, k + 31, NovaCraftBlocks.basal_scrap, 0, 2);
		world.setBlock(i + 19, j + 19, k + 31, NovaCraftBlocks.basal_bricks, 0, 2);
		world.setBlock(i + 21, j + 19, k + 31, NovaCraftBlocks.basal_bricks, 0, 2);
		world.setBlock(i + 23, j + 19, k + 31, NovaCraftBlocks.basal_bricks, 0, 2);
		world.setBlock(i + 24, j + 19, k + 31, NovaCraftBlocks.basal_bricks, 0, 2);
		world.setBlock(i + 25, j + 19, k + 31, NovaCraftBlocks.basal, 0, 2);
		world.setBlock(i + 26, j + 19, k + 31, NovaCraftBlocks.basal, 0, 2);
		world.setBlock(i + 27, j + 19, k + 31, NovaCraftBlocks.basal_bricks, 0, 2);
		world.setBlock(i + 30, j + 19, k + 31, NovaCraftBlocks.basal_bricks, 0, 2);
		world.setBlock(i + 31, j + 19, k + 31, NovaCraftBlocks.basal_bricks, 0, 2);
		world.setBlock(i + 35, j + 19, k + 31, NovaCraftBlocks.cracked_basal_bricks, 0, 2);
		world.setBlock(i + 36, j + 19, k + 31, NovaCraftBlocks.basal_bricks, 0, 2);
		world.setBlock(i + 37, j + 19, k + 31, NovaCraftBlocks.basal_bricks, 0, 2);
		world.setBlock(i, j + 19, k + 32, NovaCraftBlocks.cracked_basal_bricks, 0, 2);
		world.setBlock(i + 1, j + 19, k + 32, NovaCraftBlocks.cracked_basal_bricks, 0, 2);
		world.setBlock(i + 16, j + 19, k + 32, NovaCraftBlocks.basal_bricks, 0, 2);
		world.setBlock(i + 17, j + 19, k + 32, NovaCraftBlocks.basal_bricks, 0, 2);
		world.setBlock(i + 18, j + 19, k + 32, Blocks.lava, 8, 2);
		world.setBlock(i + 19, j + 19, k + 32, Blocks.lava, 8, 2);
		world.setBlock(i + 20, j + 19, k + 32, Blocks.lava, 8, 2);
		world.setBlock(i + 21, j + 19, k + 32, NovaCraftBlocks.cracked_basal_bricks, 0, 2);
		world.setBlock(i + 36, j + 19, k + 32, NovaCraftBlocks.basal_bricks, 0, 2);
		world.setBlock(i + 37, j + 19, k + 32, NovaCraftBlocks.cracked_basal_bricks, 0, 2);
		world.setBlock(i, j + 19, k + 33, NovaCraftBlocks.cracked_basal_bricks, 0, 2);
		world.setBlock(i + 1, j + 19, k + 33, NovaCraftBlocks.cracked_basal_bricks, 0, 2);
		world.setBlock(i + 16, j + 19, k + 33, NovaCraftBlocks.basal_scrap, 0, 2);
		world.setBlock(i + 17, j + 19, k + 33, NovaCraftBlocks.basal_scrap, 0, 2);
		world.setBlock(i + 18, j + 19, k + 33, NovaCraftBlocks.basal_bricks, 0, 2);
		world.setBlock(i + 19, j + 19, k + 33, NovaCraftBlocks.basal_scrap, 0, 2);
		world.setBlock(i + 36, j + 19, k + 33, NovaCraftBlocks.basal, 0, 2);
		world.setBlock(i + 37, j + 19, k + 33, NovaCraftBlocks.cracked_basal_bricks, 0, 2);
		world.setBlock(i, j + 19, k + 34, NovaCraftBlocks.basal_bricks, 0, 2);
		world.setBlock(i + 1, j + 19, k + 34, NovaCraftBlocks.basal_bricks, 0, 2);
		world.setBlock(i + 17, j + 19, k + 34, NovaCraftBlocks.basal_scrap, 0, 2);
		world.setBlock(i + 18, j + 19, k + 34, NovaCraftBlocks.cracked_basal_bricks, 0, 2);
		world.setBlock(i + 36, j + 19, k + 34, NovaCraftBlocks.cracked_basal_bricks, 0, 2);
		world.setBlock(i + 37, j + 19, k + 34, NovaCraftBlocks.cracked_basal_bricks, 0, 2);
		world.setBlock(i, j + 19, k + 35, NovaCraftBlocks.basal_bricks, 0, 2);
		world.setBlock(i + 1, j + 19, k + 35, NovaCraftBlocks.cracked_basal_bricks, 0, 2);
		world.setBlock(i + 18, j + 19, k + 35, NovaCraftBlocks.basal_scrap, 0, 2);
		world.setBlock(i + 19, j + 19, k + 35, NovaCraftBlocks.cracked_basal_bricks, 0, 2);
		world.setBlock(i + 31, j + 19, k + 35, NovaCraftBlocks.basal_bricks, 0, 2);
		world.setBlock(i + 36, j + 19, k + 35, NovaCraftBlocks.basal_bricks, 0, 2);
		world.setBlock(i + 37, j + 19, k + 35, NovaCraftBlocks.cracked_basal_bricks, 0, 2);
		world.setBlock(i + 2, j + 19, k + 36, NovaCraftBlocks.basal_bricks, 0, 2);
		world.setBlock(i + 3, j + 19, k + 36, NovaCraftBlocks.cracked_basal_bricks, 0, 2);
		world.setBlock(i + 4, j + 19, k + 36, NovaCraftBlocks.cracked_basal_bricks, 0, 2);
		world.setBlock(i + 5, j + 19, k + 36, NovaCraftBlocks.cracked_basal_bricks, 0, 2);
		world.setBlock(i + 6, j + 19, k + 36, NovaCraftBlocks.cracked_basal_bricks, 0, 2);
		world.setBlock(i + 7, j + 19, k + 36, NovaCraftBlocks.cracked_basal_bricks, 0, 2);
		world.setBlock(i + 8, j + 19, k + 36, NovaCraftBlocks.basal, 0, 2);
		world.setBlock(i + 9, j + 19, k + 36, NovaCraftBlocks.basal, 0, 2);
		world.setBlock(i + 10, j + 19, k + 36, NovaCraftBlocks.cracked_basal_bricks, 0, 2);
		world.setBlock(i + 11, j + 19, k + 36, NovaCraftBlocks.basal_bricks, 0, 2);
		world.setBlock(i + 12, j + 19, k + 36, NovaCraftBlocks.cracked_basal_bricks, 0, 2);
		world.setBlock(i + 13, j + 19, k + 36, NovaCraftBlocks.cracked_basal_bricks, 0, 2);
		world.setBlock(i + 14, j + 19, k + 36, NovaCraftBlocks.basal_bricks, 0, 2);
		world.setBlock(i + 15, j + 19, k + 36, NovaCraftBlocks.cracked_basal_bricks, 0, 2);
		world.setBlock(i + 16, j + 19, k + 36, NovaCraftBlocks.cracked_basal_bricks, 0, 2);
		world.setBlock(i + 17, j + 19, k + 36, NovaCraftBlocks.basal, 0, 2);
		world.setBlock(i + 18, j + 19, k + 36, NovaCraftBlocks.cracked_basal_bricks, 0, 2);
		world.setBlock(i + 19, j + 19, k + 36, NovaCraftBlocks.basal_bricks, 0, 2);
		world.setBlock(i + 20, j + 19, k + 36, NovaCraftBlocks.basal_bricks, 0, 2);
		world.setBlock(i + 21, j + 19, k + 36, NovaCraftBlocks.basal_bricks, 0, 2);
		world.setBlock(i + 22, j + 19, k + 36, NovaCraftBlocks.cracked_basal_bricks, 0, 2);
		world.setBlock(i + 23, j + 19, k + 36, NovaCraftBlocks.cracked_basal_bricks, 0, 2);
		world.setBlock(i + 24, j + 19, k + 36, NovaCraftBlocks.basal_bricks, 0, 2);
		world.setBlock(i + 25, j + 19, k + 36, NovaCraftBlocks.cracked_basal_bricks, 0, 2);
		world.setBlock(i + 26, j + 19, k + 36, NovaCraftBlocks.basal_bricks, 0, 2);
		world.setBlock(i + 27, j + 19, k + 36, NovaCraftBlocks.cracked_basal_bricks, 0, 2);
		world.setBlock(i + 28, j + 19, k + 36, NovaCraftBlocks.basal_bricks, 0, 2);
		world.setBlock(i + 29, j + 19, k + 36, NovaCraftBlocks.cracked_basal_bricks, 0, 2);
		world.setBlock(i + 30, j + 19, k + 36, NovaCraftBlocks.basal_bricks, 0, 2);
		world.setBlock(i + 31, j + 19, k + 36, NovaCraftBlocks.cracked_basal_bricks, 0, 2);
		world.setBlock(i + 32, j + 19, k + 36, NovaCraftBlocks.basal, 0, 2);
		world.setBlock(i + 33, j + 19, k + 36, NovaCraftBlocks.basal_bricks, 0, 2);
		world.setBlock(i + 34, j + 19, k + 36, NovaCraftBlocks.basal, 0, 2);
		world.setBlock(i + 35, j + 19, k + 36, NovaCraftBlocks.cracked_basal_bricks, 0, 2);
		world.setBlock(i + 2, j + 19, k + 37, NovaCraftBlocks.basal_bricks, 0, 2);
		world.setBlock(i + 3, j + 19, k + 37, NovaCraftBlocks.cracked_basal_bricks, 0, 2);
		world.setBlock(i + 4, j + 19, k + 37, NovaCraftBlocks.basal, 0, 2);
		world.setBlock(i + 5, j + 19, k + 37, NovaCraftBlocks.basal_bricks, 0, 2);
		world.setBlock(i + 6, j + 19, k + 37, NovaCraftBlocks.basal_bricks, 0, 2);
		world.setBlock(i + 7, j + 19, k + 37, NovaCraftBlocks.basal_bricks, 0, 2);
		world.setBlock(i + 8, j + 19, k + 37, NovaCraftBlocks.basal, 0, 2);
		world.setBlock(i + 9, j + 19, k + 37, NovaCraftBlocks.cracked_basal_bricks, 0, 2);
		world.setBlock(i + 10, j + 19, k + 37, NovaCraftBlocks.cracked_basal_bricks, 0, 2);
		world.setBlock(i + 11, j + 19, k + 37, NovaCraftBlocks.basal_bricks, 0, 2);
		world.setBlock(i + 12, j + 19, k + 37, NovaCraftBlocks.basal_bricks, 0, 2);
		world.setBlock(i + 13, j + 19, k + 37, NovaCraftBlocks.basal_bricks, 0, 2);
		world.setBlock(i + 14, j + 19, k + 37, NovaCraftBlocks.cracked_basal_bricks, 0, 2);
		world.setBlock(i + 15, j + 19, k + 37, NovaCraftBlocks.cracked_basal_bricks, 0, 2);
		world.setBlock(i + 16, j + 19, k + 37, NovaCraftBlocks.basal_bricks, 0, 2);
		world.setBlock(i + 17, j + 19, k + 37, NovaCraftBlocks.basal, 0, 2);
		world.setBlock(i + 18, j + 19, k + 37, NovaCraftBlocks.basal, 0, 2);
		world.setBlock(i + 19, j + 19, k + 37, NovaCraftBlocks.cracked_basal_bricks, 0, 2);
		world.setBlock(i + 20, j + 19, k + 37, NovaCraftBlocks.cracked_basal_bricks, 0, 2);
		world.setBlock(i + 21, j + 19, k + 37, NovaCraftBlocks.basal_bricks, 0, 2);
		world.setBlock(i + 22, j + 19, k + 37, NovaCraftBlocks.basal_bricks, 0, 2);
		world.setBlock(i + 23, j + 19, k + 37, NovaCraftBlocks.basal_bricks, 0, 2);
		world.setBlock(i + 24, j + 19, k + 37, NovaCraftBlocks.cracked_basal_bricks, 0, 2);
		world.setBlock(i + 25, j + 19, k + 37, NovaCraftBlocks.cracked_basal_bricks, 0, 2);
		world.setBlock(i + 26, j + 19, k + 37, NovaCraftBlocks.basal_bricks, 0, 2);
		world.setBlock(i + 27, j + 19, k + 37, NovaCraftBlocks.cracked_basal_bricks, 0, 2);
		world.setBlock(i + 28, j + 19, k + 37, NovaCraftBlocks.cracked_basal_bricks, 0, 2);
		world.setBlock(i + 29, j + 19, k + 37, NovaCraftBlocks.basal_bricks, 0, 2);
		world.setBlock(i + 30, j + 19, k + 37, NovaCraftBlocks.basal_bricks, 0, 2);
		world.setBlock(i + 31, j + 19, k + 37, NovaCraftBlocks.cracked_basal_bricks, 0, 2);
		world.setBlock(i + 32, j + 19, k + 37, NovaCraftBlocks.basal_bricks, 0, 2);
		world.setBlock(i + 33, j + 19, k + 37, NovaCraftBlocks.basal_bricks, 0, 2);
		world.setBlock(i + 34, j + 19, k + 37, NovaCraftBlocks.basal, 0, 2);
		world.setBlock(i + 35, j + 19, k + 37, NovaCraftBlocks.cracked_basal_bricks, 0, 2);
		world.setBlock(i + 2, j + 20, k, NovaCraftBlocks.cracked_basal_bricks, 0, 2);
		world.setBlock(i + 3, j + 20, k, NovaCraftBlocks.cracked_basal_bricks, 0, 2);
		world.setBlock(i + 4, j + 20, k, NovaCraftBlocks.basal_bricks, 0, 2);
		world.setBlock(i + 5, j + 20, k, NovaCraftBlocks.basal, 0, 2);
		world.setBlock(i + 6, j + 20, k, NovaCraftBlocks.basal_bricks, 0, 2);
		world.setBlock(i + 7, j + 20, k, NovaCraftBlocks.cracked_basal_bricks, 0, 2);
		world.setBlock(i + 8, j + 20, k, NovaCraftBlocks.cracked_basal_bricks, 0, 2);
		world.setBlock(i + 9, j + 20, k, NovaCraftBlocks.basal_bricks, 0, 2);
		world.setBlock(i + 10, j + 20, k, NovaCraftBlocks.cracked_basal_bricks, 0, 2);
		world.setBlock(i + 11, j + 20, k, NovaCraftBlocks.basal_bricks, 0, 2);
		world.setBlock(i + 12, j + 20, k, NovaCraftBlocks.cracked_basal_bricks, 0, 2);
		world.setBlock(i + 13, j + 20, k, NovaCraftBlocks.cracked_basal_bricks, 0, 2);
		world.setBlock(i + 14, j + 20, k, NovaCraftBlocks.cracked_basal_bricks, 0, 2);
		world.setBlock(i + 15, j + 20, k, NovaCraftBlocks.cracked_basal_bricks, 0, 2);
		world.setBlock(i + 16, j + 20, k, NovaCraftBlocks.basal, 0, 2);
		world.setBlock(i + 17, j + 20, k, NovaCraftBlocks.cracked_basal_bricks, 0, 2);
		world.setBlock(i + 18, j + 20, k, NovaCraftBlocks.basal, 0, 2);
		world.setBlock(i + 19, j + 20, k, NovaCraftBlocks.basal_bricks, 0, 2);
		world.setBlock(i + 20, j + 20, k, NovaCraftBlocks.basal_bricks, 0, 2);
		world.setBlock(i + 21, j + 20, k, NovaCraftBlocks.cracked_basal_bricks, 0, 2);
		world.setBlock(i + 22, j + 20, k, NovaCraftBlocks.cracked_basal_bricks, 0, 2);
		world.setBlock(i + 23, j + 20, k, NovaCraftBlocks.cracked_basal_bricks, 0, 2);
		world.setBlock(i + 24, j + 20, k, NovaCraftBlocks.basal_bricks, 0, 2);
		world.setBlock(i + 25, j + 20, k, NovaCraftBlocks.cracked_basal_bricks, 0, 2);
		world.setBlock(i + 26, j + 20, k, NovaCraftBlocks.cracked_basal_bricks, 0, 2);
		world.setBlock(i + 27, j + 20, k, NovaCraftBlocks.cracked_basal_bricks, 0, 2);
		world.setBlock(i + 28, j + 20, k, NovaCraftBlocks.cracked_basal_bricks, 0, 2);
		world.setBlock(i + 29, j + 20, k, NovaCraftBlocks.cracked_basal_bricks, 0, 2);
		world.setBlock(i + 30, j + 20, k, NovaCraftBlocks.cracked_basal_bricks, 0, 2);
		world.setBlock(i + 31, j + 20, k, NovaCraftBlocks.cracked_basal_bricks, 0, 2);
		world.setBlock(i + 32, j + 20, k, NovaCraftBlocks.cracked_basal_bricks, 0, 2);
		world.setBlock(i + 33, j + 20, k, NovaCraftBlocks.cracked_basal_bricks, 0, 2);
		world.setBlock(i + 34, j + 20, k, NovaCraftBlocks.basal_bricks, 0, 2);
		world.setBlock(i + 35, j + 20, k, NovaCraftBlocks.basal, 0, 2);
		world.setBlock(i + 2, j + 20, k + 1, NovaCraftBlocks.cracked_basal_bricks, 0, 2);
		world.setBlock(i + 3, j + 20, k + 1, NovaCraftBlocks.basal, 0, 2);
		world.setBlock(i + 4, j + 20, k + 1, NovaCraftBlocks.basal_bricks, 0, 2);
		world.setBlock(i + 5, j + 20, k + 1, NovaCraftBlocks.basal, 0, 2);
		world.setBlock(i + 6, j + 20, k + 1, NovaCraftBlocks.cracked_basal_bricks, 0, 2);
		world.setBlock(i + 7, j + 20, k + 1, NovaCraftBlocks.cracked_basal_bricks, 0, 2);
		world.setBlock(i + 8, j + 20, k + 1, NovaCraftBlocks.basal_bricks, 0, 2);
		world.setBlock(i + 9, j + 20, k + 1, NovaCraftBlocks.cracked_basal_bricks, 0, 2);
		world.setBlock(i + 10, j + 20, k + 1, NovaCraftBlocks.cracked_basal_bricks, 0, 2);
		world.setBlock(i + 11, j + 20, k + 1, NovaCraftBlocks.cracked_basal_bricks, 0, 2);
		world.setBlock(i + 12, j + 20, k + 1, NovaCraftBlocks.cracked_basal_bricks, 0, 2);
		world.setBlock(i + 13, j + 20, k + 1, NovaCraftBlocks.cracked_basal_bricks, 0, 2);
		world.setBlock(i + 14, j + 20, k + 1, NovaCraftBlocks.cracked_basal_bricks, 0, 2);
		world.setBlock(i + 15, j + 20, k + 1, NovaCraftBlocks.cracked_basal_bricks, 0, 2);
		world.setBlock(i + 16, j + 20, k + 1, NovaCraftBlocks.cracked_basal_bricks, 0, 2);
		world.setBlock(i + 17, j + 20, k + 1, NovaCraftBlocks.basal_bricks, 0, 2);
		world.setBlock(i + 18, j + 20, k + 1, NovaCraftBlocks.cracked_basal_bricks, 0, 2);
		world.setBlock(i + 19, j + 20, k + 1, NovaCraftBlocks.cracked_basal_bricks, 0, 2);
		world.setBlock(i + 20, j + 20, k + 1, NovaCraftBlocks.basal_bricks, 0, 2);
		world.setBlock(i + 21, j + 20, k + 1, NovaCraftBlocks.basal_bricks, 0, 2);
		world.setBlock(i + 22, j + 20, k + 1, NovaCraftBlocks.cracked_basal_bricks, 0, 2);
		world.setBlock(i + 23, j + 20, k + 1, NovaCraftBlocks.cracked_basal_bricks, 0, 2);
		world.setBlock(i + 24, j + 20, k + 1, NovaCraftBlocks.cracked_basal_bricks, 0, 2);
		world.setBlock(i + 25, j + 20, k + 1, NovaCraftBlocks.cracked_basal_bricks, 0, 2);
		world.setBlock(i + 26, j + 20, k + 1, NovaCraftBlocks.cracked_basal_bricks, 0, 2);
		world.setBlock(i + 27, j + 20, k + 1, NovaCraftBlocks.cracked_basal_bricks, 0, 2);
		world.setBlock(i + 28, j + 20, k + 1, NovaCraftBlocks.basal_bricks, 0, 2);
		world.setBlock(i + 29, j + 20, k + 1, NovaCraftBlocks.basal_bricks, 0, 2);
		world.setBlock(i + 30, j + 20, k + 1, NovaCraftBlocks.basal_bricks, 0, 2);
		world.setBlock(i + 31, j + 20, k + 1, NovaCraftBlocks.basal, 0, 2);
		world.setBlock(i + 32, j + 20, k + 1, NovaCraftBlocks.basal_bricks, 0, 2);
		world.setBlock(i + 33, j + 20, k + 1, NovaCraftBlocks.basal, 0, 2);
		world.setBlock(i + 34, j + 20, k + 1, NovaCraftBlocks.cracked_basal_bricks, 0, 2);
		world.setBlock(i + 35, j + 20, k + 1, NovaCraftBlocks.cracked_basal_bricks, 0, 2);
		world.setBlock(i, j + 20, k + 2, NovaCraftBlocks.basal_bricks, 0, 2);
		world.setBlock(i + 1, j + 20, k + 2, NovaCraftBlocks.basal_bricks, 0, 2);
		world.setBlock(i + 18, j + 20, k + 2, NovaCraftBlocks.basal_bricks, 0, 2);
		world.setBlock(i + 19, j + 20, k + 2, NovaCraftBlocks.basal_bricks, 0, 2);
		world.setBlock(i + 20, j + 20, k + 2, NovaCraftBlocks.basal_bricks, 0, 2);
		world.setBlock(i + 31, j + 20, k + 2, NovaCraftBlocks.basal, 0, 2);
		world.setBlock(i + 36, j + 20, k + 2, NovaCraftBlocks.cracked_basal_bricks, 0, 2);
		world.setBlock(i + 37, j + 20, k + 2, NovaCraftBlocks.basal_bricks, 0, 2);
		world.setBlock(i, j + 20, k + 3, NovaCraftBlocks.cracked_basal_bricks, 0, 2);
		world.setBlock(i + 1, j + 20, k + 3, NovaCraftBlocks.cracked_basal_bricks, 0, 2);
		world.setBlock(i + 12, j + 20, k + 3, PlaceChain, 0, 2);
		world.setBlock(i + 17, j + 20, k + 3, NovaCraftBlocks.basal_bricks, 0, 2);
		world.setBlock(i + 18, j + 20, k + 3, NovaCraftBlocks.basal_bricks, 0, 2);
		world.setBlock(i + 19, j + 20, k + 3, NovaCraftBlocks.cracked_basal_bricks, 0, 2);
		world.setBlock(i + 20, j + 20, k + 3, NovaCraftBlocks.cracked_basal_bricks, 0, 2);
		world.setBlock(i + 21, j + 20, k + 3, NovaCraftBlocks.basal_bricks, 0, 2);
		world.setBlock(i + 36, j + 20, k + 3, NovaCraftBlocks.cracked_basal_bricks, 0, 2);
		world.setBlock(i + 37, j + 20, k + 3, NovaCraftBlocks.cracked_basal_bricks, 0, 2);
		world.setBlock(i, j + 20, k + 4, NovaCraftBlocks.basal, 0, 2);
		world.setBlock(i + 1, j + 20, k + 4, NovaCraftBlocks.basal_bricks, 0, 2);
		world.setBlock(i + 16, j + 20, k + 4, NovaCraftBlocks.cracked_basal_bricks, 0, 2);
		world.setBlock(i + 17, j + 20, k + 4, NovaCraftBlocks.cracked_basal_bricks, 0, 2);
		world.setBlock(i + 18, j + 20, k + 4, NovaCraftBlocks.basal_bricks, 0, 2);
		world.setBlock(i + 19, j + 20, k + 4, NovaCraftBlocks.cracked_basal_bricks, 0, 2);
		world.setBlock(i + 20, j + 20, k + 4, NovaCraftBlocks.basal_scrap, 0, 2);
		world.setBlock(i + 21, j + 20, k + 4, NovaCraftBlocks.basal_bricks, 0, 2);
		world.setBlock(i + 36, j + 20, k + 4, NovaCraftBlocks.basal_bricks, 0, 2);
		world.setBlock(i + 37, j + 20, k + 4, NovaCraftBlocks.cracked_basal_bricks, 0, 2);
		world.setBlock(i, j + 20, k + 5, NovaCraftBlocks.cracked_basal_bricks, 0, 2);
		world.setBlock(i + 1, j + 20, k + 5, NovaCraftBlocks.basal, 0, 2);
		world.setBlock(i + 16, j + 20, k + 5, NovaCraftBlocks.basal_bricks, 0, 2);
		world.setBlock(i + 17, j + 20, k + 5, Blocks.lava, 8, 2);
		world.setBlock(i + 18, j + 20, k + 5, Blocks.lava, 8, 2);
		world.setBlock(i + 19, j + 20, k + 5, Blocks.lava, 8, 2);
		world.setBlock(i + 20, j + 20, k + 5, Blocks.lava, 8, 2);
		world.setBlock(i + 36, j + 20, k + 5, NovaCraftBlocks.cracked_basal_bricks, 0, 2);
		world.setBlock(i + 37, j + 20, k + 5, NovaCraftBlocks.cracked_basal_bricks, 0, 2);
		world.setBlock(i, j + 20, k + 6, NovaCraftBlocks.basal, 0, 2);
		world.setBlock(i + 1, j + 20, k + 6, NovaCraftBlocks.basal, 0, 2);
		world.setBlock(i + 6, j + 20, k + 6, NovaCraftBlocks.basal_bricks, 0, 2);
		world.setBlock(i + 12, j + 20, k + 6, NovaCraftBlocks.basal, 0, 2);
		world.setBlock(i + 16, j + 20, k + 6, NovaCraftBlocks.cracked_basal_bricks, 0, 2);
		world.setBlock(i + 17, j + 20, k + 6, NovaCraftBlocks.basal_scrap, 0, 2);
		world.setBlock(i + 20, j + 20, k + 6, NovaCraftBlocks.basal_bricks, 0, 2);
		world.setBlock(i + 21, j + 20, k + 6, NovaCraftBlocks.basal_bricks, 0, 2);
		world.setBlock(i + 25, j + 20, k + 6, NovaCraftBlocks.cracked_basal_bricks, 0, 2);
		world.setBlock(i + 29, j + 20, k + 6, NovaCraftBlocks.basal_bricks, 0, 2);
		world.setBlock(i + 31, j + 20, k + 6, NovaCraftBlocks.basal_bricks, 0, 2);
		world.setBlock(i + 35, j + 20, k + 6, NovaCraftBlocks.basal_bricks, 0, 2);
		world.setBlock(i + 36, j + 20, k + 6, NovaCraftBlocks.cracked_basal_bricks, 0, 2);
		world.setBlock(i + 37, j + 20, k + 6, NovaCraftBlocks.cracked_basal_bricks, 0, 2);
		world.setBlock(i, j + 20, k + 7, NovaCraftBlocks.cracked_basal_bricks, 0, 2);
		world.setBlock(i + 1, j + 20, k + 7, NovaCraftBlocks.cracked_basal_bricks, 0, 2);
		world.setBlock(i + 36, j + 20, k + 7, NovaCraftBlocks.cracked_basal_bricks, 0, 2);
		world.setBlock(i + 37, j + 20, k + 7, NovaCraftBlocks.cracked_basal_bricks, 0, 2);
		world.setBlock(i + 1, j + 20, k + 8, NovaCraftBlocks.basal_bricks, 0, 2);
		world.setBlock(i + 6, j + 20, k + 8, NovaCraftBlocks.cracked_basal_bricks, 0, 2);
		world.setBlock(i + 31, j + 20, k + 8, NovaCraftBlocks.basal_bricks, 0, 2);
		world.setBlock(i + 36, j + 20, k + 8, NovaCraftBlocks.cracked_basal_bricks, 0, 2);
		world.setBlock(i + 37, j + 20, k + 8, NovaCraftBlocks.cracked_basal_bricks, 0, 2);
		world.setBlock(i, j + 20, k + 9, NovaCraftBlocks.basal, 0, 2);
		world.setBlock(i + 1, j + 20, k + 9, NovaCraftBlocks.basal_bricks, 0, 2);
		world.setBlock(i + 36, j + 20, k + 9, NovaCraftBlocks.basal, 0, 2);
		world.setBlock(i + 37, j + 20, k + 9, NovaCraftBlocks.basal, 0, 2);
		world.setBlock(i, j + 20, k + 10, NovaCraftBlocks.cracked_basal_bricks, 0, 2);
		world.setBlock(i + 1, j + 20, k + 10, NovaCraftBlocks.cracked_basal_bricks, 0, 2);
		world.setBlock(i + 36, j + 20, k + 10, NovaCraftBlocks.cracked_basal_bricks, 0, 2);
		world.setBlock(i + 37, j + 20, k + 10, NovaCraftBlocks.cracked_basal_bricks, 0, 2);
		world.setBlock(i, j + 20, k + 11, NovaCraftBlocks.cracked_basal_bricks, 0, 2);
		world.setBlock(i + 1, j + 20, k + 11, NovaCraftBlocks.cracked_basal_bricks, 0, 2);
		world.setBlock(i + 2, j + 20, k + 11, NovaCraftBlocks.cracked_basal_bricks, 0, 2);
		world.setBlock(i + 3, j + 20, k + 11, NovaCraftBlocks.cracked_basal_bricks, 0, 2);
		world.setBlock(i + 34, j + 20, k + 11, NovaCraftBlocks.basal_bricks, 0, 2);
		world.setBlock(i + 35, j + 20, k + 11, NovaCraftBlocks.basal_bricks, 0, 2);
		world.setBlock(i + 36, j + 20, k + 11, NovaCraftBlocks.cracked_basal_bricks, 0, 2);
		world.setBlock(i + 37, j + 20, k + 11, NovaCraftBlocks.basal, 0, 2);
		world.setBlock(i, j + 20, k + 12, NovaCraftBlocks.basal_bricks, 0, 2);
		world.setBlock(i + 1, j + 20, k + 12, NovaCraftBlocks.cracked_basal_bricks, 0, 2);
		world.setBlock(i + 2, j + 20, k + 12, NovaCraftBlocks.basal_bricks, 0, 2);
		world.setBlock(i + 3, j + 20, k + 12, NovaCraftBlocks.basal_bricks, 0, 2);
		world.setBlock(i + 34, j + 20, k + 12, NovaCraftBlocks.basal_bricks, 0, 2);
		world.setBlock(i + 35, j + 20, k + 12, NovaCraftBlocks.basal_bricks, 0, 2);
		world.setBlock(i + 36, j + 20, k + 12, NovaCraftBlocks.cracked_basal_bricks, 0, 2);
		world.setBlock(i + 37, j + 20, k + 12, NovaCraftBlocks.cracked_basal_bricks, 0, 2);
		world.setBlock(i, j + 20, k + 13, NovaCraftBlocks.basal_bricks, 0, 2);
		world.setBlock(i + 1, j + 20, k + 13, NovaCraftBlocks.cracked_basal_bricks, 0, 2);
		world.setBlock(i + 36, j + 20, k + 13, NovaCraftBlocks.cracked_basal_bricks, 0, 2);
		world.setBlock(i + 37, j + 20, k + 13, NovaCraftBlocks.basal, 0, 2);
		world.setBlock(i + 1, j + 20, k + 14, NovaCraftBlocks.basal_bricks, 0, 2);
		world.setBlock(i + 5, j + 20, k + 14, PlaceChain, 0, 2);
		world.setBlock(i + 32, j + 20, k + 14, PlaceChain, 0, 2);
		world.setBlock(i + 36, j + 20, k + 14, NovaCraftBlocks.basal_bricks, 0, 2);
		world.setBlock(i + 37, j + 20, k + 14, NovaCraftBlocks.basal, 0, 2);
		world.setBlock(i, j + 20, k + 15, NovaCraftBlocks.basal, 0, 2);
		world.setBlock(i + 1, j + 20, k + 15, NovaCraftBlocks.cracked_basal_bricks, 0, 2);
		world.setBlock(i + 36, j + 20, k + 15, NovaCraftBlocks.basal_bricks, 0, 2);
		world.setBlock(i + 37, j + 20, k + 15, NovaCraftBlocks.basal_bricks, 0, 2);
		world.setBlock(i, j + 20, k + 16, NovaCraftBlocks.cracked_basal_bricks, 0, 2);
		world.setBlock(i + 1, j + 20, k + 16, NovaCraftBlocks.basal_bricks, 0, 2);
		world.setBlock(i + 6, j + 20, k + 16, NovaCraftBlocks.basal_bricks, 0, 2);
		world.setBlock(i + 31, j + 20, k + 16, NovaCraftBlocks.basal_bricks, 0, 2);
		world.setBlock(i + 36, j + 20, k + 16, NovaCraftBlocks.basal, 0, 2);
		world.setBlock(i + 37, j + 20, k + 16, NovaCraftBlocks.cracked_basal_bricks, 0, 2);
		world.setBlock(i, j + 20, k + 17, NovaCraftBlocks.basal_bricks, 0, 2);
		world.setBlock(i + 1, j + 20, k + 17, NovaCraftBlocks.basal_bricks, 0, 2);
		world.setBlock(i + 36, j + 20, k + 17, NovaCraftBlocks.basal_bricks, 0, 2);
		world.setBlock(i + 37, j + 20, k + 17, NovaCraftBlocks.basal, 0, 2);
		world.setBlock(i, j + 20, k + 18, NovaCraftBlocks.basal, 0, 2);
		world.setBlock(i + 1, j + 20, k + 18, NovaCraftBlocks.basal_bricks, 0, 2);
		world.setBlock(i + 36, j + 20, k + 18, NovaCraftBlocks.cracked_basal_bricks, 0, 2);
		world.setBlock(i + 37, j + 20, k + 18, NovaCraftBlocks.basal, 0, 2);
		world.setBlock(i, j + 20, k + 19, NovaCraftBlocks.basal_bricks, 0, 2);
		world.setBlock(i + 1, j + 20, k + 19, NovaCraftBlocks.cracked_basal_bricks, 0, 2);
		world.setBlock(i + 36, j + 20, k + 19, NovaCraftBlocks.cracked_basal_bricks, 0, 2);
		world.setBlock(i + 37, j + 20, k + 19, NovaCraftBlocks.basal, 0, 2);
		world.setBlock(i, j + 20, k + 20, NovaCraftBlocks.basal, 0, 2);
		world.setBlock(i + 1, j + 20, k + 20, NovaCraftBlocks.basal, 0, 2);
		world.setBlock(i + 36, j + 20, k + 20, NovaCraftBlocks.basal_bricks, 0, 2);
		world.setBlock(i + 37, j + 20, k + 20, NovaCraftBlocks.basal, 0, 2);
		world.setBlock(i, j + 20, k + 21, NovaCraftBlocks.cracked_basal_bricks, 0, 2);
		world.setBlock(i + 1, j + 20, k + 21, NovaCraftBlocks.basal_bricks, 0, 2);
		world.setBlock(i + 6, j + 20, k + 21, NovaCraftBlocks.cracked_basal_bricks, 0, 2);
		world.setBlock(i + 31, j + 20, k + 21, NovaCraftBlocks.cracked_basal_bricks, 0, 2);
		world.setBlock(i + 36, j + 20, k + 21, NovaCraftBlocks.basal, 0, 2);
		world.setBlock(i + 37, j + 20, k + 21, NovaCraftBlocks.cracked_basal_bricks, 0, 2);
		world.setBlock(i, j + 20, k + 22, NovaCraftBlocks.cracked_basal_bricks, 0, 2);
		world.setBlock(i + 1, j + 20, k + 22, NovaCraftBlocks.cracked_basal_bricks, 0, 2);
		world.setBlock(i + 36, j + 20, k + 22, NovaCraftBlocks.cracked_basal_bricks, 0, 2);
		world.setBlock(i + 37, j + 20, k + 22, NovaCraftBlocks.cracked_basal_bricks, 0, 2);
		world.setBlock(i, j + 20, k + 23, NovaCraftBlocks.cracked_basal_bricks, 0, 2);
		world.setBlock(i + 1, j + 20, k + 23, NovaCraftBlocks.cracked_basal_bricks, 0, 2);
		world.setBlock(i + 5, j + 20, k + 23, PlaceChain, 0, 2);
		world.setBlock(i + 32, j + 20, k + 23, PlaceChain, 0, 2);
		world.setBlock(i + 36, j + 20, k + 23, NovaCraftBlocks.cracked_basal_bricks, 0, 2);
		world.setBlock(i + 37, j + 20, k + 23, NovaCraftBlocks.cracked_basal_bricks, 0, 2);
		world.setBlock(i, j + 20, k + 24, NovaCraftBlocks.basal_bricks, 0, 2);
		world.setBlock(i + 1, j + 20, k + 24, NovaCraftBlocks.basal_bricks, 0, 2);
		world.setBlock(i + 36, j + 20, k + 24, NovaCraftBlocks.basal_bricks, 0, 2);
		world.setBlock(i + 37, j + 20, k + 24, NovaCraftBlocks.basal, 0, 2);
		world.setBlock(i, j + 20, k + 25, NovaCraftBlocks.cracked_basal_bricks, 0, 2);
		world.setBlock(i + 1, j + 20, k + 25, NovaCraftBlocks.basal_bricks, 0, 2);
		world.setBlock(i + 2, j + 20, k + 25, NovaCraftBlocks.cracked_basal_bricks, 0, 2);
		world.setBlock(i + 3, j + 20, k + 25, NovaCraftBlocks.basal_bricks, 0, 2);
		world.setBlock(i + 34, j + 20, k + 25, NovaCraftBlocks.basal_bricks, 0, 2);
		world.setBlock(i + 35, j + 20, k + 25, NovaCraftBlocks.basal_bricks, 0, 2);
		world.setBlock(i + 36, j + 20, k + 25, NovaCraftBlocks.cracked_basal_bricks, 0, 2);
		world.setBlock(i + 37, j + 20, k + 25, NovaCraftBlocks.cracked_basal_bricks, 0, 2);
		world.setBlock(i, j + 20, k + 26, NovaCraftBlocks.cracked_basal_bricks, 0, 2);
		world.setBlock(i + 1, j + 20, k + 26, NovaCraftBlocks.cracked_basal_bricks, 0, 2);
		world.setBlock(i + 2, j + 20, k + 26, NovaCraftBlocks.basal_bricks, 0, 2);
		world.setBlock(i + 3, j + 20, k + 26, NovaCraftBlocks.cracked_basal_bricks, 0, 2);
		world.setBlock(i + 34, j + 20, k + 26, NovaCraftBlocks.basal_bricks, 0, 2);
		world.setBlock(i + 35, j + 20, k + 26, NovaCraftBlocks.cracked_basal_bricks, 0, 2);
		world.setBlock(i + 36, j + 20, k + 26, NovaCraftBlocks.cracked_basal_bricks, 0, 2);
		world.setBlock(i + 37, j + 20, k + 26, NovaCraftBlocks.cracked_basal_bricks, 0, 2);
		world.setBlock(i, j + 20, k + 27, NovaCraftBlocks.basal_bricks, 0, 2);
		world.setBlock(i + 1, j + 20, k + 27, NovaCraftBlocks.basal_bricks, 0, 2);
		world.setBlock(i + 36, j + 20, k + 27, NovaCraftBlocks.basal, 0, 2);
		world.setBlock(i + 37, j + 20, k + 27, NovaCraftBlocks.basal, 0, 2);
		world.setBlock(i, j + 20, k + 28, NovaCraftBlocks.basal_bricks, 0, 2);
		world.setBlock(i + 1, j + 20, k + 28, NovaCraftBlocks.basal_bricks, 0, 2);
		world.setBlock(i + 36, j + 20, k + 28, NovaCraftBlocks.cracked_basal_bricks, 0, 2);
		world.setBlock(i + 37, j + 20, k + 28, NovaCraftBlocks.basal, 0, 2);
		world.setBlock(i, j + 20, k + 29, NovaCraftBlocks.basal, 0, 2);
		world.setBlock(i + 1, j + 20, k + 29, NovaCraftBlocks.cracked_basal_bricks, 0, 2);
		world.setBlock(i + 6, j + 20, k + 29, NovaCraftBlocks.basal_bricks, 0, 2);
		world.setBlock(i + 31, j + 20, k + 29, NovaCraftBlocks.cracked_basal_bricks, 0, 2);
		world.setBlock(i + 36, j + 20, k + 29, NovaCraftBlocks.cracked_basal_bricks, 0, 2);
		world.setBlock(i + 37, j + 20, k + 29, NovaCraftBlocks.basal_bricks, 0, 2);
		world.setBlock(i, j + 20, k + 30, NovaCraftBlocks.basal_bricks, 0, 2);
		world.setBlock(i + 1, j + 20, k + 30, NovaCraftBlocks.cracked_basal_bricks, 0, 2);
		world.setBlock(i + 36, j + 20, k + 30, NovaCraftBlocks.cracked_basal_bricks, 0, 2);
		world.setBlock(i + 37, j + 20, k + 30, NovaCraftBlocks.basal_bricks, 0, 2);
		world.setBlock(i, j + 20, k + 31, NovaCraftBlocks.cracked_basal_bricks, 0, 2);
		world.setBlock(i + 1, j + 20, k + 31, NovaCraftBlocks.basal, 0, 2);
		world.setBlock(i + 6, j + 20, k + 31, NovaCraftBlocks.cracked_basal_bricks, 0, 2);
		world.setBlock(i + 8, j + 20, k + 31, NovaCraftBlocks.cracked_basal_bricks, 0, 2);
		world.setBlock(i + 12, j + 20, k + 31, NovaCraftBlocks.cracked_basal_bricks, 0, 2);
		world.setBlock(i + 16, j + 20, k + 31, NovaCraftBlocks.basal_bricks, 0, 2);
		world.setBlock(i + 17, j + 20, k + 31, NovaCraftBlocks.basal_bricks, 0, 2);
		world.setBlock(i + 20, j + 20, k + 31, NovaCraftBlocks.basal_scrap, 0, 2);
		world.setBlock(i + 21, j + 20, k + 31, NovaCraftBlocks.cracked_basal_bricks, 0, 2);
		world.setBlock(i + 25, j + 20, k + 31, NovaCraftBlocks.basal, 0, 2);
		world.setBlock(i + 31, j + 20, k + 31, NovaCraftBlocks.cracked_basal_bricks, 0, 2);
		world.setBlock(i + 35, j + 20, k + 31, NovaCraftBlocks.basal, 0, 2);
		world.setBlock(i + 36, j + 20, k + 31, NovaCraftBlocks.cracked_basal_bricks, 0, 2);
		world.setBlock(i + 37, j + 20, k + 31, NovaCraftBlocks.cracked_basal_bricks, 0, 2);
		world.setBlock(i, j + 20, k + 32, NovaCraftBlocks.cracked_basal_bricks, 0, 2);
		world.setBlock(i + 1, j + 20, k + 32, NovaCraftBlocks.cracked_basal_bricks, 0, 2);
		world.setBlock(i + 17, j + 20, k + 32, Blocks.lava, 8, 2);
		world.setBlock(i + 18, j + 20, k + 32, Blocks.lava, 8, 2);
		world.setBlock(i + 19, j + 20, k + 32, Blocks.lava, 8, 2);
		world.setBlock(i + 20, j + 20, k + 32, Blocks.lava, 8, 2);
		world.setBlock(i + 21, j + 20, k + 32, NovaCraftBlocks.basal_bricks, 0, 2);
		world.setBlock(i + 36, j + 20, k + 32, NovaCraftBlocks.cracked_basal_bricks, 0, 2);
		world.setBlock(i + 37, j + 20, k + 32, NovaCraftBlocks.basal, 0, 2);
		world.setBlock(i, j + 20, k + 33, NovaCraftBlocks.basal_bricks, 0, 2);
		world.setBlock(i + 16, j + 20, k + 33, NovaCraftBlocks.basal_bricks, 0, 2);
		world.setBlock(i + 17, j + 20, k + 33, NovaCraftBlocks.basal_scrap, 0, 2);
		world.setBlock(i + 18, j + 20, k + 33, NovaCraftBlocks.cracked_basal_bricks, 0, 2);
		world.setBlock(i + 19, j + 20, k + 33, NovaCraftBlocks.cracked_basal_bricks, 0, 2);
		world.setBlock(i + 20, j + 20, k + 33, NovaCraftBlocks.basal_bricks, 0, 2);
		world.setBlock(i + 21, j + 20, k + 33, NovaCraftBlocks.cracked_basal_bricks, 0, 2);
		world.setBlock(i + 36, j + 20, k + 33, NovaCraftBlocks.basal_bricks, 0, 2);
		world.setBlock(i + 37, j + 20, k + 33, NovaCraftBlocks.cracked_basal_bricks, 0, 2);
		world.setBlock(i, j + 20, k + 34, NovaCraftBlocks.basal_bricks, 0, 2);
		world.setBlock(i + 1, j + 20, k + 34, NovaCraftBlocks.basal_bricks, 0, 2);
		world.setBlock(i + 16, j + 20, k + 34, NovaCraftBlocks.basal_bricks, 0, 2);
		world.setBlock(i + 17, j + 20, k + 34, NovaCraftBlocks.basal_bricks, 0, 2);
		world.setBlock(i + 18, j + 20, k + 34, NovaCraftBlocks.basal_bricks, 0, 2);
		world.setBlock(i + 19, j + 20, k + 34, NovaCraftBlocks.basal_bricks, 0, 2);
		world.setBlock(i + 20, j + 20, k + 34, NovaCraftBlocks.basal_bricks, 0, 2);
		world.setBlock(i + 25, j + 20, k + 34, PlaceChain, 0, 2);
		world.setBlock(i + 36, j + 20, k + 34, NovaCraftBlocks.basal_bricks, 0, 2);
		world.setBlock(i + 37, j + 20, k + 34, NovaCraftBlocks.cracked_basal_bricks, 0, 2);
		world.setBlock(i, j + 20, k + 35, NovaCraftBlocks.basal_bricks, 0, 2);
		world.setBlock(i + 1, j + 20, k + 35, NovaCraftBlocks.cracked_basal_bricks, 0, 2);
		world.setBlock(i + 17, j + 20, k + 35, NovaCraftBlocks.cracked_basal_bricks, 0, 2);
		world.setBlock(i + 18, j + 20, k + 35, NovaCraftBlocks.cracked_basal_bricks, 0, 2);
		world.setBlock(i + 19, j + 20, k + 35, NovaCraftBlocks.cracked_basal_bricks, 0, 2);
		world.setBlock(i + 31, j + 20, k + 35, NovaCraftBlocks.cracked_basal_bricks, 0, 2);
		world.setBlock(i + 36, j + 20, k + 35, NovaCraftBlocks.cracked_basal_bricks, 0, 2);
		world.setBlock(i + 37, j + 20, k + 35, NovaCraftBlocks.basal, 0, 2);
		world.setBlock(i + 2, j + 20, k + 36, NovaCraftBlocks.basal_bricks, 0, 2);
		world.setBlock(i + 3, j + 20, k + 36, NovaCraftBlocks.cracked_basal_bricks, 0, 2);
		world.setBlock(i + 4, j + 20, k + 36, NovaCraftBlocks.basal_bricks, 0, 2);
		world.setBlock(i + 5, j + 20, k + 36, NovaCraftBlocks.basal_bricks, 0, 2);
		world.setBlock(i + 6, j + 20, k + 36, NovaCraftBlocks.basal_bricks, 0, 2);
		world.setBlock(i + 7, j + 20, k + 36, NovaCraftBlocks.cracked_basal_bricks, 0, 2);
		world.setBlock(i + 8, j + 20, k + 36, NovaCraftBlocks.cracked_basal_bricks, 0, 2);
		world.setBlock(i + 9, j + 20, k + 36, NovaCraftBlocks.cracked_basal_bricks, 0, 2);
		world.setBlock(i + 10, j + 20, k + 36, NovaCraftBlocks.cracked_basal_bricks, 0, 2);
		world.setBlock(i + 11, j + 20, k + 36, NovaCraftBlocks.cracked_basal_bricks, 0, 2);
		world.setBlock(i + 12, j + 20, k + 36, NovaCraftBlocks.cracked_basal_bricks, 0, 2);
		world.setBlock(i + 13, j + 20, k + 36, NovaCraftBlocks.cracked_basal_bricks, 0, 2);
		world.setBlock(i + 14, j + 20, k + 36, NovaCraftBlocks.cracked_basal_bricks, 0, 2);
		world.setBlock(i + 15, j + 20, k + 36, NovaCraftBlocks.basal_bricks, 0, 2);
		world.setBlock(i + 16, j + 20, k + 36, NovaCraftBlocks.basal_bricks, 0, 2);
		world.setBlock(i + 17, j + 20, k + 36, NovaCraftBlocks.basal_bricks, 0, 2);
		world.setBlock(i + 18, j + 20, k + 36, NovaCraftBlocks.cracked_basal_bricks, 0, 2);
		world.setBlock(i + 19, j + 20, k + 36, NovaCraftBlocks.cracked_basal_bricks, 0, 2);
		world.setBlock(i + 20, j + 20, k + 36, NovaCraftBlocks.cracked_basal_bricks, 0, 2);
		world.setBlock(i + 21, j + 20, k + 36, NovaCraftBlocks.basal_bricks, 0, 2);
		world.setBlock(i + 22, j + 20, k + 36, NovaCraftBlocks.basal_bricks, 0, 2);
		world.setBlock(i + 23, j + 20, k + 36, NovaCraftBlocks.cracked_basal_bricks, 0, 2);
		world.setBlock(i + 24, j + 20, k + 36, NovaCraftBlocks.cracked_basal_bricks, 0, 2);
		world.setBlock(i + 25, j + 20, k + 36, NovaCraftBlocks.cracked_basal_bricks, 0, 2);
		world.setBlock(i + 26, j + 20, k + 36, NovaCraftBlocks.cracked_basal_bricks, 0, 2);
		world.setBlock(i + 27, j + 20, k + 36, NovaCraftBlocks.cracked_basal_bricks, 0, 2);
		world.setBlock(i + 28, j + 20, k + 36, NovaCraftBlocks.basal, 0, 2);
		world.setBlock(i + 29, j + 20, k + 36, NovaCraftBlocks.basal_bricks, 0, 2);
		world.setBlock(i + 30, j + 20, k + 36, NovaCraftBlocks.cracked_basal_bricks, 0, 2);
		world.setBlock(i + 31, j + 20, k + 36, NovaCraftBlocks.basal_bricks, 0, 2);
		world.setBlock(i + 32, j + 20, k + 36, NovaCraftBlocks.basal_bricks, 0, 2);
		world.setBlock(i + 33, j + 20, k + 36, NovaCraftBlocks.cracked_basal_bricks, 0, 2);
		world.setBlock(i + 34, j + 20, k + 36, NovaCraftBlocks.cracked_basal_bricks, 0, 2);
		world.setBlock(i + 35, j + 20, k + 36, NovaCraftBlocks.basal_bricks, 0, 2);
		world.setBlock(i + 2, j + 20, k + 37, NovaCraftBlocks.cracked_basal_bricks, 0, 2);
		world.setBlock(i + 3, j + 20, k + 37, NovaCraftBlocks.basal_bricks, 0, 2);
		world.setBlock(i + 4, j + 20, k + 37, NovaCraftBlocks.basal_bricks, 0, 2);
		world.setBlock(i + 5, j + 20, k + 37, NovaCraftBlocks.cracked_basal_bricks, 0, 2);
		world.setBlock(i + 6, j + 20, k + 37, NovaCraftBlocks.cracked_basal_bricks, 0, 2);
		world.setBlock(i + 7, j + 20, k + 37, NovaCraftBlocks.cracked_basal_bricks, 0, 2);
		world.setBlock(i + 8, j + 20, k + 37, NovaCraftBlocks.basal_bricks, 0, 2);
		world.setBlock(i + 9, j + 20, k + 37, NovaCraftBlocks.basal_bricks, 0, 2);
		world.setBlock(i + 10, j + 20, k + 37, NovaCraftBlocks.basal, 0, 2);
		world.setBlock(i + 11, j + 20, k + 37, NovaCraftBlocks.basal_bricks, 0, 2);
		world.setBlock(i + 12, j + 20, k + 37, NovaCraftBlocks.basal_bricks, 0, 2);
		world.setBlock(i + 13, j + 20, k + 37, NovaCraftBlocks.basal_bricks, 0, 2);
		world.setBlock(i + 14, j + 20, k + 37, NovaCraftBlocks.cracked_basal_bricks, 0, 2);
		world.setBlock(i + 15, j + 20, k + 37, NovaCraftBlocks.cracked_basal_bricks, 0, 2);
		world.setBlock(i + 16, j + 20, k + 37, NovaCraftBlocks.cracked_basal_bricks, 0, 2);
		world.setBlock(i + 17, j + 20, k + 37, NovaCraftBlocks.basal_bricks, 0, 2);
		world.setBlock(i + 18, j + 20, k + 37, NovaCraftBlocks.cracked_basal_bricks, 0, 2);
		world.setBlock(i + 19, j + 20, k + 37, NovaCraftBlocks.cracked_basal_bricks, 0, 2);
		world.setBlock(i + 20, j + 20, k + 37, NovaCraftBlocks.cracked_basal_bricks, 0, 2);
		world.setBlock(i + 21, j + 20, k + 37, NovaCraftBlocks.cracked_basal_bricks, 0, 2);
		world.setBlock(i + 22, j + 20, k + 37, NovaCraftBlocks.cracked_basal_bricks, 0, 2);
		world.setBlock(i + 23, j + 20, k + 37, NovaCraftBlocks.cracked_basal_bricks, 0, 2);
		world.setBlock(i + 24, j + 20, k + 37, NovaCraftBlocks.cracked_basal_bricks, 0, 2);
		world.setBlock(i + 25, j + 20, k + 37, NovaCraftBlocks.cracked_basal_bricks, 0, 2);
		world.setBlock(i + 26, j + 20, k + 37, NovaCraftBlocks.cracked_basal_bricks, 0, 2);
		world.setBlock(i + 27, j + 20, k + 37, NovaCraftBlocks.cracked_basal_bricks, 0, 2);
		world.setBlock(i + 28, j + 20, k + 37, NovaCraftBlocks.basal_bricks, 0, 2);
		world.setBlock(i + 29, j + 20, k + 37, NovaCraftBlocks.cracked_basal_bricks, 0, 2);
		world.setBlock(i + 30, j + 20, k + 37, NovaCraftBlocks.cracked_basal_bricks, 0, 2);
		world.setBlock(i + 31, j + 20, k + 37, NovaCraftBlocks.cracked_basal_bricks, 0, 2);
		world.setBlock(i + 32, j + 20, k + 37, NovaCraftBlocks.basal_bricks, 0, 2);
		world.setBlock(i + 33, j + 20, k + 37, NovaCraftBlocks.cracked_basal_bricks, 0, 2);
		world.setBlock(i + 34, j + 20, k + 37, NovaCraftBlocks.basal, 0, 2);
		world.setBlock(i + 35, j + 20, k + 37, NovaCraftBlocks.basal_bricks, 0, 2);
		world.setBlock(i + 2, j + 21, k, NovaCraftBlocks.cracked_basal_bricks, 0, 2);
		world.setBlock(i + 3, j + 21, k, NovaCraftBlocks.basal_bricks, 0, 2);
		world.setBlock(i + 4, j + 21, k, NovaCraftBlocks.cracked_basal_bricks, 0, 2);
		world.setBlock(i + 5, j + 21, k, NovaCraftBlocks.basal_bricks, 0, 2);
		world.setBlock(i + 6, j + 21, k, NovaCraftBlocks.cracked_basal_bricks, 0, 2);
		world.setBlock(i + 7, j + 21, k, NovaCraftBlocks.cracked_basal_bricks, 0, 2);
		world.setBlock(i + 8, j + 21, k, NovaCraftBlocks.basal, 0, 2);
		world.setBlock(i + 9, j + 21, k, NovaCraftBlocks.basal_bricks, 0, 2);
		world.setBlock(i + 10, j + 21, k, NovaCraftBlocks.basal_bricks, 0, 2);
		world.setBlock(i + 11, j + 21, k, NovaCraftBlocks.basal_bricks, 0, 2);
		world.setBlock(i + 12, j + 21, k, NovaCraftBlocks.basal_bricks, 0, 2);
		world.setBlock(i + 13, j + 21, k, NovaCraftBlocks.cracked_basal_bricks, 0, 2);
		world.setBlock(i + 14, j + 21, k, NovaCraftBlocks.basal, 0, 2);
		world.setBlock(i + 15, j + 21, k, NovaCraftBlocks.basal_bricks, 0, 2);
		world.setBlock(i + 16, j + 21, k, NovaCraftBlocks.basal_bricks, 0, 2);
		world.setBlock(i + 17, j + 21, k, NovaCraftBlocks.basal_bricks, 0, 2);
		world.setBlock(i + 18, j + 21, k, NovaCraftBlocks.basal_bricks, 0, 2);
		world.setBlock(i + 19, j + 21, k, NovaCraftBlocks.basal_bricks, 0, 2);
		world.setBlock(i + 20, j + 21, k, NovaCraftBlocks.cracked_basal_bricks, 0, 2);
		world.setBlock(i + 21, j + 21, k, NovaCraftBlocks.cracked_basal_bricks, 0, 2);
		world.setBlock(i + 23, j + 21, k, NovaCraftBlocks.basal_bricks, 0, 2);
		world.setBlock(i + 24, j + 21, k, NovaCraftBlocks.cracked_basal_bricks, 0, 2);
		world.setBlock(i + 25, j + 21, k, NovaCraftBlocks.cracked_basal_bricks, 0, 2);
		world.setBlock(i + 26, j + 21, k, NovaCraftBlocks.basal, 0, 2);
		world.setBlock(i + 27, j + 21, k, NovaCraftBlocks.cracked_basal_bricks, 0, 2);
		world.setBlock(i + 28, j + 21, k, NovaCraftBlocks.basal, 0, 2);
		world.setBlock(i + 29, j + 21, k, NovaCraftBlocks.cracked_basal_bricks, 0, 2);
		world.setBlock(i + 30, j + 21, k, NovaCraftBlocks.cracked_basal_bricks, 0, 2);
		world.setBlock(i + 31, j + 21, k, NovaCraftBlocks.cracked_basal_bricks, 0, 2);
		world.setBlock(i + 32, j + 21, k, NovaCraftBlocks.basal_bricks, 0, 2);
		world.setBlock(i + 33, j + 21, k, NovaCraftBlocks.cracked_basal_bricks, 0, 2);
		world.setBlock(i + 34, j + 21, k, NovaCraftBlocks.basal, 0, 2);
		world.setBlock(i + 35, j + 21, k, NovaCraftBlocks.cracked_basal_bricks, 0, 2);
		world.setBlock(i + 2, j + 21, k + 1, NovaCraftBlocks.basal_bricks, 0, 2);
		world.setBlock(i + 3, j + 21, k + 1, NovaCraftBlocks.cracked_basal_bricks, 0, 2);
		world.setBlock(i + 4, j + 21, k + 1, NovaCraftBlocks.cracked_basal_bricks, 0, 2);
		world.setBlock(i + 5, j + 21, k + 1, NovaCraftBlocks.cracked_basal_bricks, 0, 2);
		world.setBlock(i + 6, j + 21, k + 1, NovaCraftBlocks.basal_bricks, 0, 2);
		world.setBlock(i + 7, j + 21, k + 1, NovaCraftBlocks.basal_bricks, 0, 2);
		world.setBlock(i + 8, j + 21, k + 1, NovaCraftBlocks.cracked_basal_bricks, 0, 2);
		world.setBlock(i + 9, j + 21, k + 1, NovaCraftBlocks.cracked_basal_bricks, 0, 2);
		world.setBlock(i + 10, j + 21, k + 1, NovaCraftBlocks.cracked_basal_bricks, 0, 2);
		world.setBlock(i + 11, j + 21, k + 1, NovaCraftBlocks.basal, 0, 2);
		world.setBlock(i + 12, j + 21, k + 1, NovaCraftBlocks.cracked_basal_bricks, 0, 2);
		world.setBlock(i + 13, j + 21, k + 1, NovaCraftBlocks.basal_bricks, 0, 2);
		world.setBlock(i + 14, j + 21, k + 1, NovaCraftBlocks.cracked_basal_bricks, 0, 2);
		world.setBlock(i + 15, j + 21, k + 1, NovaCraftBlocks.basal_bricks, 0, 2);
		world.setBlock(i + 16, j + 21, k + 1, NovaCraftBlocks.cracked_basal_bricks, 0, 2);
		world.setBlock(i + 17, j + 21, k + 1, NovaCraftBlocks.cracked_basal_bricks, 0, 2);
		world.setBlock(i + 18, j + 21, k + 1, NovaCraftBlocks.cracked_basal_bricks, 0, 2);
		world.setBlock(i + 19, j + 21, k + 1, NovaCraftBlocks.cracked_basal_bricks, 0, 2);
		world.setBlock(i + 20, j + 21, k + 1, NovaCraftBlocks.basal_bricks, 0, 2);
		world.setBlock(i + 21, j + 21, k + 1, NovaCraftBlocks.basal_bricks, 0, 2);
		world.setBlock(i + 22, j + 21, k + 1, NovaCraftBlocks.basal, 0, 2);
		world.setBlock(i + 23, j + 21, k + 1, NovaCraftBlocks.basal_bricks, 0, 2);
		world.setBlock(i + 24, j + 21, k + 1, NovaCraftBlocks.basal, 0, 2);
		world.setBlock(i + 25, j + 21, k + 1, NovaCraftBlocks.cracked_basal_bricks, 0, 2);
		world.setBlock(i + 26, j + 21, k + 1, NovaCraftBlocks.cracked_basal_bricks, 0, 2);
		world.setBlock(i + 27, j + 21, k + 1, NovaCraftBlocks.cracked_basal_bricks, 0, 2);
		world.setBlock(i + 28, j + 21, k + 1, NovaCraftBlocks.cracked_basal_bricks, 0, 2);
		world.setBlock(i + 29, j + 21, k + 1, NovaCraftBlocks.cracked_basal_bricks, 0, 2);
		world.setBlock(i + 30, j + 21, k + 1, NovaCraftBlocks.basal_bricks, 0, 2);
		world.setBlock(i + 31, j + 21, k + 1, NovaCraftBlocks.cracked_basal_bricks, 0, 2);
		world.setBlock(i + 32, j + 21, k + 1, NovaCraftBlocks.basal_bricks, 0, 2);
		world.setBlock(i + 33, j + 21, k + 1, NovaCraftBlocks.cracked_basal_bricks, 0, 2);
		world.setBlock(i + 34, j + 21, k + 1, NovaCraftBlocks.basal_bricks, 0, 2);
		world.setBlock(i + 35, j + 21, k + 1, NovaCraftBlocks.cracked_basal_bricks, 0, 2);
		world.setBlock(i, j + 21, k + 2, NovaCraftBlocks.cracked_basal_bricks, 0, 2);
		world.setBlock(i + 1, j + 21, k + 2, NovaCraftBlocks.cracked_basal_bricks, 0, 2);
		world.setBlock(i + 2, j + 21, k + 2, NovaCraftBlocks.cracked_basal_bricks, 0, 2);
		world.setBlock(i + 3, j + 21, k + 2, NovaCraftBlocks.basal_bricks, 0, 2);
		world.setBlock(i + 4, j + 21, k + 2, NovaCraftBlocks.basal_bricks, 0, 2);
		world.setBlock(i + 5, j + 21, k + 2, NovaCraftBlocks.basal_bricks, 0, 2);
		world.setBlock(i + 6, j + 21, k + 2, NovaCraftBlocks.cracked_basal_bricks, 0, 2);
		world.setBlock(i + 7, j + 21, k + 2, NovaCraftBlocks.cracked_basal_bricks, 0, 2);
		world.setBlock(i + 8, j + 21, k + 2, NovaCraftBlocks.cracked_basal_bricks, 0, 2);
		world.setBlock(i + 9, j + 21, k + 2, NovaCraftBlocks.basal_bricks, 0, 2);
		world.setBlock(i + 10, j + 21, k + 2, NovaCraftBlocks.basal_scrap, 0, 2);
		world.setBlock(i + 11, j + 21, k + 2, NovaCraftBlocks.basal_bricks, 0, 2);
		world.setBlock(i + 12, j + 21, k + 2, NovaCraftBlocks.cracked_basal_bricks, 0, 2);
		world.setBlock(i + 13, j + 21, k + 2, NovaCraftBlocks.cracked_basal_bricks, 0, 2);
		world.setBlock(i + 14, j + 21, k + 2, NovaCraftBlocks.basal_bricks, 0, 2);
		world.setBlock(i + 15, j + 21, k + 2, NovaCraftBlocks.basal_bricks, 0, 2);
		world.setBlock(i + 16, j + 21, k + 2, NovaCraftBlocks.cracked_basal_bricks, 0, 2);
		world.setBlock(i + 17, j + 21, k + 2, NovaCraftBlocks.basal_bricks, 0, 2);
		world.setBlock(i + 18, j + 21, k + 2, NovaCraftBlocks.basal_bricks, 0, 2);
		world.setBlock(i + 19, j + 21, k + 2, NovaCraftBlocks.cracked_basal_bricks, 0, 2);
		world.setBlock(i + 20, j + 21, k + 2, NovaCraftBlocks.basal_scrap, 0, 2);
		world.setBlock(i + 21, j + 21, k + 2, NovaCraftBlocks.basal_bricks, 0, 2);
		world.setBlock(i + 22, j + 21, k + 2, NovaCraftBlocks.basal_scrap, 0, 2);
		world.setBlock(i + 23, j + 21, k + 2, NovaCraftBlocks.basal_scrap, 0, 2);
		world.setBlock(i + 24, j + 21, k + 2, NovaCraftBlocks.basal_scrap, 0, 2);
		world.setBlock(i + 25, j + 21, k + 2, NovaCraftBlocks.cracked_basal_bricks, 0, 2);
		world.setBlock(i + 26, j + 21, k + 2, NovaCraftBlocks.cracked_basal_bricks, 0, 2);
		world.setBlock(i + 27, j + 21, k + 2, NovaCraftBlocks.cracked_basal_bricks, 0, 2);
		world.setBlock(i + 28, j + 21, k + 2, NovaCraftBlocks.cracked_basal_bricks, 0, 2);
		world.setBlock(i + 29, j + 21, k + 2, NovaCraftBlocks.cracked_basal_bricks, 0, 2);
		world.setBlock(i + 30, j + 21, k + 2, NovaCraftBlocks.basal_bricks, 0, 2);
		world.setBlock(i + 31, j + 21, k + 2, NovaCraftBlocks.basal, 0, 2);
		world.setBlock(i + 32, j + 21, k + 2, NovaCraftBlocks.basal_scrap, 0, 2);
		world.setBlock(i + 33, j + 21, k + 2, NovaCraftBlocks.basal, 0, 2);
		world.setBlock(i + 34, j + 21, k + 2, NovaCraftBlocks.cracked_basal_bricks, 0, 2);
		world.setBlock(i + 35, j + 21, k + 2, NovaCraftBlocks.basal, 0, 2);
		world.setBlock(i + 36, j + 21, k + 2, NovaCraftBlocks.basal_bricks, 0, 2);
		world.setBlock(i + 37, j + 21, k + 2, NovaCraftBlocks.cracked_basal_bricks, 0, 2);
		world.setBlock(i, j + 21, k + 3, NovaCraftBlocks.basal, 0, 2);
		world.setBlock(i + 1, j + 21, k + 3, NovaCraftBlocks.cracked_basal_bricks, 0, 2);
		world.setBlock(i + 2, j + 21, k + 3, NovaCraftBlocks.basal_bricks, 0, 2);
		world.setBlock(i + 3, j + 21, k + 3, NovaCraftBlocks.cracked_basal_bricks, 0, 2);
		world.setBlock(i + 4, j + 21, k + 3, NovaCraftBlocks.basal, 0, 2);
		world.setBlock(i + 5, j + 21, k + 3, NovaCraftBlocks.basal, 0, 2);
		world.setBlock(i + 6, j + 21, k + 3, NovaCraftBlocks.basal_bricks, 0, 2);
		world.setBlock(i + 7, j + 21, k + 3, NovaCraftBlocks.cracked_basal_bricks, 0, 2);
		world.setBlock(i + 8, j + 21, k + 3, NovaCraftBlocks.cracked_basal_bricks, 0, 2);
		world.setBlock(i + 9, j + 21, k + 3, NovaCraftBlocks.basal_bricks, 0, 2);
		world.setBlock(i + 10, j + 21, k + 3, NovaCraftBlocks.basal_bricks, 0, 2);
		world.setBlock(i + 11, j + 21, k + 3, NovaCraftBlocks.basal, 0, 2);
		world.setBlock(i + 12, j + 21, k + 3, NovaCraftBlocks.cracked_basal_bricks, 0, 2);
		world.setBlock(i + 13, j + 21, k + 3, NovaCraftBlocks.basal_bricks, 0, 2);
		world.setBlock(i + 14, j + 21, k + 3, NovaCraftBlocks.cracked_basal_bricks, 0, 2);
		world.setBlock(i + 15, j + 21, k + 3, NovaCraftBlocks.basal_bricks, 0, 2);
		world.setBlock(i + 16, j + 21, k + 3, NovaCraftBlocks.basal_bricks, 0, 2);
		world.setBlock(i + 17, j + 21, k + 3, NovaCraftBlocks.basal_bricks, 0, 2);
		world.setBlock(i + 18, j + 21, k + 3, NovaCraftBlocks.basal_bricks, 0, 2);
		world.setBlock(i + 19, j + 21, k + 3, NovaCraftBlocks.basal_bricks, 0, 2);
		world.setBlock(i + 20, j + 21, k + 3, NovaCraftBlocks.basal_bricks, 0, 2);
		world.setBlock(i + 21, j + 21, k + 3, NovaCraftBlocks.cracked_basal_bricks, 0, 2);
		world.setBlock(i + 22, j + 21, k + 3, NovaCraftBlocks.cracked_basal_bricks, 0, 2);
		world.setBlock(i + 23, j + 21, k + 3, NovaCraftBlocks.basal_bricks, 0, 2);
		world.setBlock(i + 24, j + 21, k + 3, NovaCraftBlocks.cracked_basal_bricks, 0, 2);
		world.setBlock(i + 25, j + 21, k + 3, NovaCraftBlocks.basal_bricks, 0, 2);
		world.setBlock(i + 26, j + 21, k + 3, NovaCraftBlocks.cracked_basal_bricks, 0, 2);
		world.setBlock(i + 27, j + 21, k + 3, NovaCraftBlocks.basal_scrap, 0, 2);
		world.setBlock(i + 28, j + 21, k + 3, NovaCraftBlocks.basal_scrap, 0, 2);
		world.setBlock(i + 29, j + 21, k + 3, NovaCraftBlocks.basal_bricks, 0, 2);
		world.setBlock(i + 35, j + 21, k + 3, NovaCraftBlocks.basal, 0, 2);
		world.setBlock(i + 36, j + 21, k + 3, NovaCraftBlocks.cracked_basal_bricks, 0, 2);
		world.setBlock(i + 37, j + 21, k + 3, NovaCraftBlocks.basal, 0, 2);
		world.setBlock(i, j + 21, k + 4, NovaCraftBlocks.cracked_basal_bricks, 0, 2);
		world.setBlock(i + 1, j + 21, k + 4, NovaCraftBlocks.cracked_basal_bricks, 0, 2);
		world.setBlock(i + 2, j + 21, k + 4, NovaCraftBlocks.basal_bricks, 0, 2);
		world.setBlock(i + 3, j + 21, k + 4, NovaCraftBlocks.cracked_basal_bricks, 0, 2);
		world.setBlock(i + 8, j + 21, k + 4, NovaCraftBlocks.basal_bricks, 0, 2);
		world.setBlock(i + 12, j + 21, k + 4, NovaCraftBlocks.cracked_basal_bricks, 0, 2);
		world.setBlock(i + 16, j + 21, k + 4, NovaCraftBlocks.cracked_basal_bricks, 0, 2);
		world.setBlock(i + 17, j + 21, k + 4, NovaCraftBlocks.basal_bricks, 0, 2);
		world.setBlock(i + 18, j + 21, k + 4, NovaCraftBlocks.basal_bricks, 0, 2);
		world.setBlock(i + 19, j + 21, k + 4, NovaCraftBlocks.basal_bricks, 0, 2);
		world.setBlock(i + 20, j + 21, k + 4, NovaCraftBlocks.basal_bricks, 0, 2);
		world.setBlock(i + 21, j + 21, k + 4, NovaCraftBlocks.basal_bricks, 0, 2);
		world.setBlock(i + 29, j + 21, k + 4, NovaCraftBlocks.basal_bricks, 0, 2);
		world.setBlock(i + 35, j + 21, k + 4, NovaCraftBlocks.basal_bricks, 0, 2);
		world.setBlock(i + 36, j + 21, k + 4, NovaCraftBlocks.basal_bricks, 0, 2);
		world.setBlock(i + 37, j + 21, k + 4, NovaCraftBlocks.basal, 0, 2);
		world.setBlock(i, j + 21, k + 5, NovaCraftBlocks.basal_bricks, 0, 2);
		world.setBlock(i + 1, j + 21, k + 5, NovaCraftBlocks.cracked_basal_bricks, 0, 2);
		world.setBlock(i + 2, j + 21, k + 5, NovaCraftBlocks.basal_bricks, 0, 2);
		world.setBlock(i + 3, j + 21, k + 5, NovaCraftBlocks.cracked_basal_bricks, 0, 2);
		world.setBlock(i + 8, j + 21, k + 5, NovaCraftBlocks.basal_bricks, 0, 2);
		world.setBlock(i + 12, j + 21, k + 5, NovaCraftBlocks.basal_bricks, 0, 2);
		world.setBlock(i + 16, j + 21, k + 5, NovaCraftBlocks.glowing_basal, 0, 2);
		world.setBlock(i + 17, j + 21, k + 5, Blocks.lava, 0, 2);
		world.setBlock(i + 18, j + 21, k + 5, Blocks.lava, 2, 2);
		world.setBlock(i + 19, j + 21, k + 5, Blocks.lava, 0, 2);
		world.setBlock(i + 20, j + 21, k + 5, Blocks.lava, 0, 2);
		world.setBlock(i + 21, j + 21, k + 5, NovaCraftBlocks.basal_bricks, 0, 2);
		world.setBlock(i + 29, j + 21, k + 5, NovaCraftBlocks.basal_bricks, 0, 2);
		world.setBlock(i + 34, j + 21, k + 5, NovaCraftBlocks.basal_bricks, 0, 2);
		world.setBlock(i + 35, j + 21, k + 5, NovaCraftBlocks.basal_bricks, 0, 2);
		world.setBlock(i + 36, j + 21, k + 5, NovaCraftBlocks.basal, 0, 2);
		world.setBlock(i + 37, j + 21, k + 5, NovaCraftBlocks.cracked_basal_bricks, 0, 2);
		world.setBlock(i, j + 21, k + 6, NovaCraftBlocks.cracked_basal_bricks, 0, 2);
		world.setBlock(i + 1, j + 21, k + 6, NovaCraftBlocks.basal, 0, 2);
		world.setBlock(i + 2, j + 21, k + 6, NovaCraftBlocks.cracked_basal_bricks, 0, 2);
		world.setBlock(i + 3, j + 21, k + 6, NovaCraftBlocks.cracked_basal_bricks, 0, 2);
		world.setBlock(i + 6, j + 21, k + 6, NovaCraftBlocks.cracked_basal_bricks, 0, 2);
		world.setBlock(i + 12, j + 21, k + 6, NovaCraftBlocks.basal, 0, 2);
		world.setBlock(i + 16, j + 21, k + 6, NovaCraftBlocks.basal_scrap, 0, 2);
		world.setBlock(i + 17, j + 21, k + 6, NovaCraftBlocks.cracked_basal_bricks, 0, 2);
		world.setBlock(i + 18, j + 21, k + 6, NovaCraftBlocks.cracked_basal_bricks, 0, 2);
		world.setBlock(i + 19, j + 21, k + 6, NovaCraftBlocks.basal_bricks, 0, 2);
		world.setBlock(i + 20, j + 21, k + 6, NovaCraftBlocks.cracked_basal_bricks, 0, 2);
		world.setBlock(i + 21, j + 21, k + 6, NovaCraftBlocks.basal_bricks, 0, 2);
		world.setBlock(i + 25, j + 21, k + 6, NovaCraftBlocks.basal_bricks, 0, 2);
		world.setBlock(i + 29, j + 21, k + 6, NovaCraftBlocks.basal_bricks, 0, 2);
		world.setBlock(i + 31, j + 21, k + 6, NovaCraftBlocks.basal_bricks, 0, 2);
		world.setBlock(i + 33, j + 21, k + 6, NovaCraftBlocks.cracked_basal_bricks, 0, 2);
		world.setBlock(i + 34, j + 21, k + 6, NovaCraftBlocks.cracked_basal_bricks, 0, 2);
		world.setBlock(i + 35, j + 21, k + 6, NovaCraftBlocks.basal_bricks, 0, 2);
		world.setBlock(i + 36, j + 21, k + 6, NovaCraftBlocks.cracked_basal_bricks, 0, 2);
		world.setBlock(i + 37, j + 21, k + 6, NovaCraftBlocks.basal_bricks, 0, 2);
		world.setBlock(i, j + 21, k + 7, NovaCraftBlocks.basal_bricks, 0, 2);
		world.setBlock(i + 1, j + 21, k + 7, NovaCraftBlocks.basal_bricks, 0, 2);
		world.setBlock(i + 2, j + 21, k + 7, NovaCraftBlocks.basal_bricks, 0, 2);
		world.setBlock(i + 3, j + 21, k + 7, NovaCraftBlocks.cracked_basal_bricks, 0, 2);
		world.setBlock(i + 6, j + 21, k + 7, NovaCraftBlocks.basal_scrap, 0, 2);
		world.setBlock(i + 31, j + 21, k + 7, NovaCraftBlocks.basal_bricks, 0, 2);
		world.setBlock(i + 32, j + 21, k + 7, NovaCraftBlocks.basal_scrap, 0, 2);
		world.setBlock(i + 33, j + 21, k + 7, NovaCraftBlocks.basal_scrap, 0, 2);
		world.setBlock(i + 35, j + 21, k + 7, NovaCraftBlocks.basal_bricks, 0, 2);
		world.setBlock(i + 36, j + 21, k + 7, NovaCraftBlocks.cracked_basal_bricks, 0, 2);
		world.setBlock(i + 37, j + 21, k + 7, NovaCraftBlocks.basal, 0, 2);
		world.setBlock(i, j + 21, k + 8, NovaCraftBlocks.cracked_basal_bricks, 0, 2);
		world.setBlock(i + 1, j + 21, k + 8, NovaCraftBlocks.basal, 0, 2);
		world.setBlock(i + 2, j + 21, k + 8, NovaCraftBlocks.basal_scrap, 0, 2);
		world.setBlock(i + 3, j + 21, k + 8, NovaCraftBlocks.basal_bricks, 0, 2);
		world.setBlock(i + 4, j + 21, k + 8, NovaCraftBlocks.basal_scrap, 0, 2);
		world.setBlock(i + 5, j + 21, k + 8, NovaCraftBlocks.basal_scrap, 0, 2);
		world.setBlock(i + 6, j + 21, k + 8, NovaCraftBlocks.basal_bricks, 0, 2);
		world.setBlock(i + 31, j + 21, k + 8, NovaCraftBlocks.basal_bricks, 0, 2);
		world.setBlock(i + 32, j + 21, k + 8, NovaCraftBlocks.basal_bricks, 0, 2);
		world.setBlock(i + 33, j + 21, k + 8, NovaCraftBlocks.basal_bricks, 0, 2);
		world.setBlock(i + 34, j + 21, k + 8, NovaCraftBlocks.basal_scrap, 0, 2);
		world.setBlock(i + 36, j + 21, k + 8, NovaCraftBlocks.cracked_basal_bricks, 0, 2);
		world.setBlock(i + 37, j + 21, k + 8, NovaCraftBlocks.basal_bricks, 0, 2);
		world.setBlock(i, j + 21, k + 9, NovaCraftBlocks.basal_bricks, 0, 2);
		world.setBlock(i + 1, j + 21, k + 9, NovaCraftBlocks.cracked_basal_bricks, 0, 2);
		world.setBlock(i + 2, j + 21, k + 9, NovaCraftBlocks.basal_scrap, 0, 2);
		world.setBlock(i + 3, j + 21, k + 9, NovaCraftBlocks.basal_bricks, 0, 2);
		world.setBlock(i + 4, j + 21, k + 9, NovaCraftBlocks.basal_scrap, 0, 2);
		world.setBlock(i + 5, j + 21, k + 9, NovaCraftBlocks.basal_bricks, 0, 2);
		world.setBlock(i + 6, j + 21, k + 9, NovaCraftBlocks.basal_bricks, 0, 2);
		world.setBlock(i + 31, j + 21, k + 9, NovaCraftBlocks.basal_bricks, 0, 2);
		world.setBlock(i + 32, j + 21, k + 9, NovaCraftBlocks.cracked_basal_bricks, 0, 2);
		world.setBlock(i + 33, j + 21, k + 9, NovaCraftBlocks.basal_scrap, 0, 2);
		world.setBlock(i + 35, j + 21, k + 9, NovaCraftBlocks.basal_bricks, 0, 2);
		world.setBlock(i + 36, j + 21, k + 9, NovaCraftBlocks.basal, 0, 2);
		world.setBlock(i + 37, j + 21, k + 9, NovaCraftBlocks.basal_bricks, 0, 2);
		world.setBlock(i, j + 21, k + 10, NovaCraftBlocks.basal_bricks, 0, 2);
		world.setBlock(i + 1, j + 21, k + 10, NovaCraftBlocks.basal, 0, 2);
		world.setBlock(i + 2, j + 21, k + 10, NovaCraftBlocks.basal_bricks, 0, 2);
		world.setBlock(i + 3, j + 21, k + 10, NovaCraftBlocks.basal_bricks, 0, 2);
		world.setBlock(i + 6, j + 21, k + 10, NovaCraftBlocks.basal_bricks, 0, 2);
		world.setBlock(i + 31, j + 21, k + 10, NovaCraftBlocks.basal_bricks, 0, 2);
		world.setBlock(i + 32, j + 21, k + 10, NovaCraftBlocks.basal_bricks, 0, 2);
		world.setBlock(i + 33, j + 21, k + 10, NovaCraftBlocks.cracked_basal_bricks, 0, 2);
		world.setBlock(i + 34, j + 21, k + 10, NovaCraftBlocks.basal, 0, 2);
		world.setBlock(i + 35, j + 21, k + 10, NovaCraftBlocks.cracked_basal_bricks, 0, 2);
		world.setBlock(i + 36, j + 21, k + 10, NovaCraftBlocks.cracked_basal_bricks, 0, 2);
		world.setBlock(i + 37, j + 21, k + 10, NovaCraftBlocks.basal, 0, 2);
		world.setBlock(i, j + 21, k + 11, NovaCraftBlocks.basal_bricks, 0, 2);
		world.setBlock(i + 1, j + 21, k + 11, NovaCraftBlocks.basal, 0, 2);
		world.setBlock(i + 2, j + 21, k + 11, NovaCraftBlocks.basal_bricks, 0, 2);
		world.setBlock(i + 3, j + 21, k + 11, NovaCraftBlocks.basal_bricks, 0, 2);
		world.setBlock(i + 4, j + 21, k + 11, NovaCraftBlocks.cracked_basal_bricks, 0, 2);
		world.setBlock(i + 6, j + 21, k + 11, NovaCraftBlocks.basal_bricks, 0, 2);
		world.setBlock(i + 31, j + 21, k + 11, NovaCraftBlocks.basal_bricks, 0, 2);
		world.setBlock(i + 32, j + 21, k + 11, NovaCraftBlocks.basal_bricks, 0, 2);
		world.setBlock(i + 33, j + 21, k + 11, NovaCraftBlocks.basal_bricks, 0, 2);
		world.setBlock(i + 34, j + 21, k + 11, NovaCraftBlocks.cracked_basal_bricks, 0, 2);
		world.setBlock(i + 35, j + 21, k + 11, NovaCraftBlocks.basal_bricks, 0, 2);
		world.setBlock(i + 36, j + 21, k + 11, NovaCraftBlocks.cracked_basal_bricks, 0, 2);
		world.setBlock(i + 37, j + 21, k + 11, NovaCraftBlocks.basal_bricks, 0, 2);
		world.setBlock(i, j + 21, k + 12, NovaCraftBlocks.basal, 0, 2);
		world.setBlock(i + 1, j + 21, k + 12, NovaCraftBlocks.basal_bricks, 0, 2);
		world.setBlock(i + 2, j + 21, k + 12, NovaCraftBlocks.cracked_basal_bricks, 0, 2);
		world.setBlock(i + 3, j + 21, k + 12, NovaCraftBlocks.cracked_basal_bricks, 0, 2);
		world.setBlock(i + 4, j + 21, k + 12, NovaCraftBlocks.basal_bricks, 0, 2);
		world.setBlock(i + 31, j + 21, k + 12, NovaCraftBlocks.cracked_basal_bricks, 0, 2);
		world.setBlock(i + 32, j + 21, k + 12, NovaCraftBlocks.cracked_basal_bricks, 0, 2);
		world.setBlock(i + 33, j + 21, k + 12, NovaCraftBlocks.basal_bricks, 0, 2);
		world.setBlock(i + 34, j + 21, k + 12, NovaCraftBlocks.basal_bricks, 0, 2);
		world.setBlock(i + 35, j + 21, k + 12, NovaCraftBlocks.basal, 0, 2);
		world.setBlock(i + 36, j + 21, k + 12, NovaCraftBlocks.basal_bricks, 0, 2);
		world.setBlock(i + 37, j + 21, k + 12, NovaCraftBlocks.cracked_basal_bricks, 0, 2);
		world.setBlock(i, j + 21, k + 13, NovaCraftBlocks.basal, 0, 2);
		world.setBlock(i + 1, j + 21, k + 13, NovaCraftBlocks.basal_bricks, 0, 2);
		world.setBlock(i + 2, j + 21, k + 13, NovaCraftBlocks.basal_bricks, 0, 2);
		world.setBlock(i + 3, j + 21, k + 13, NovaCraftBlocks.cracked_basal_bricks, 0, 2);
		world.setBlock(i + 4, j + 21, k + 13, NovaCraftBlocks.basal_bricks, 0, 2);
		world.setBlock(i + 5, j + 21, k + 13, NovaCraftBlocks.cracked_basal_bricks, 0, 2);
		world.setBlock(i + 6, j + 21, k + 13, NovaCraftBlocks.basal_scrap, 0, 2);
		world.setBlock(i + 31, j + 21, k + 13, NovaCraftBlocks.basal_bricks, 0, 2);
		world.setBlock(i + 32, j + 21, k + 13, NovaCraftBlocks.basal, 0, 2);
		world.setBlock(i + 33, j + 21, k + 13, NovaCraftBlocks.cracked_basal_bricks, 0, 2);
		world.setBlock(i + 34, j + 21, k + 13, NovaCraftBlocks.basal_bricks, 0, 2);
		world.setBlock(i + 36, j + 21, k + 13, NovaCraftBlocks.cracked_basal_bricks, 0, 2);
		world.setBlock(i, j + 21, k + 14, NovaCraftBlocks.cracked_basal_bricks, 0, 2);
		world.setBlock(i + 1, j + 21, k + 14, NovaCraftBlocks.basal, 0, 2);
		world.setBlock(i + 2, j + 21, k + 14, NovaCraftBlocks.basal_bricks, 0, 2);
		world.setBlock(i + 3, j + 21, k + 14, NovaCraftBlocks.basal_bricks, 0, 2);
		world.setBlock(i + 4, j + 21, k + 14, NovaCraftBlocks.cracked_basal_bricks, 0, 2);
		world.setBlock(i + 5, j + 21, k + 14, NovaCraftBlocks.cracked_basal_bricks, 0, 2);
		world.setBlock(i + 6, j + 21, k + 14, NovaCraftBlocks.basal_scrap, 0, 2);
		world.setBlock(i + 31, j + 21, k + 14, NovaCraftBlocks.basal, 0, 2);
		world.setBlock(i + 32, j + 21, k + 14, NovaCraftBlocks.basal_bricks, 0, 2);
		world.setBlock(i + 33, j + 21, k + 14, NovaCraftBlocks.basal_bricks, 0, 2);
		world.setBlock(i + 34, j + 21, k + 14, NovaCraftBlocks.basal_bricks, 0, 2);
		world.setBlock(i + 35, j + 21, k + 14, NovaCraftBlocks.basal, 0, 2);
		world.setBlock(i + 36, j + 21, k + 14, NovaCraftBlocks.cracked_basal_bricks, 0, 2);
		world.setBlock(i + 37, j + 21, k + 14, NovaCraftBlocks.cracked_basal_bricks, 0, 2);
		world.setBlock(i, j + 21, k + 15, NovaCraftBlocks.cracked_basal_bricks, 0, 2);
		world.setBlock(i + 1, j + 21, k + 15, NovaCraftBlocks.cracked_basal_bricks, 0, 2);
		world.setBlock(i + 2, j + 21, k + 15, NovaCraftBlocks.basal_bricks, 0, 2);
		world.setBlock(i + 3, j + 21, k + 15, NovaCraftBlocks.basal_bricks, 0, 2);
		world.setBlock(i + 4, j + 21, k + 15, NovaCraftBlocks.cracked_basal_bricks, 0, 2);
		world.setBlock(i + 5, j + 21, k + 15, NovaCraftBlocks.basal_bricks, 0, 2);
		world.setBlock(i + 6, j + 21, k + 15, NovaCraftBlocks.basal_scrap, 0, 2);
		world.setBlock(i + 31, j + 21, k + 15, NovaCraftBlocks.basal, 0, 2);
		world.setBlock(i + 32, j + 21, k + 15, NovaCraftBlocks.basal_bricks, 0, 2);
		world.setBlock(i + 33, j + 21, k + 15, NovaCraftBlocks.basal, 0, 2);
		world.setBlock(i + 34, j + 21, k + 15, NovaCraftBlocks.basal_bricks, 0, 2);
		world.setBlock(i + 35, j + 21, k + 15, NovaCraftBlocks.cracked_basal_bricks, 0, 2);
		world.setBlock(i + 36, j + 21, k + 15, NovaCraftBlocks.cracked_basal_bricks, 0, 2);
		world.setBlock(i + 37, j + 21, k + 15, NovaCraftBlocks.cracked_basal_bricks, 0, 2);
		world.setBlock(i, j + 21, k + 16, NovaCraftBlocks.basal_bricks, 0, 2);
		world.setBlock(i + 1, j + 21, k + 16, NovaCraftBlocks.cracked_basal_bricks, 0, 2);
		world.setBlock(i + 2, j + 21, k + 16, NovaCraftBlocks.cracked_basal_bricks, 0, 2);
		world.setBlock(i + 3, j + 21, k + 16, NovaCraftBlocks.cracked_basal_bricks, 0, 2);
		world.setBlock(i + 4, j + 21, k + 16, NovaCraftBlocks.basal_bricks, 0, 2);
		world.setBlock(i + 5, j + 21, k + 16, NovaCraftBlocks.cracked_basal_bricks, 0, 2);
		world.setBlock(i + 32, j + 21, k + 16, NovaCraftBlocks.basal_bricks, 0, 2);
		world.setBlock(i + 33, j + 21, k + 16, NovaCraftBlocks.basal, 0, 2);
		world.setBlock(i + 34, j + 21, k + 16, NovaCraftBlocks.cracked_basal_bricks, 0, 2);
		world.setBlock(i + 35, j + 21, k + 16, NovaCraftBlocks.basal_bricks, 0, 2);
		world.setBlock(i + 36, j + 21, k + 16, NovaCraftBlocks.cracked_basal_bricks, 0, 2);
		world.setBlock(i + 37, j + 21, k + 16, NovaCraftBlocks.basal_bricks, 0, 2);
		world.setBlock(i, j + 21, k + 17, NovaCraftBlocks.cracked_basal_bricks, 0, 2);
		world.setBlock(i + 1, j + 21, k + 17, NovaCraftBlocks.basal_bricks, 0, 2);
		world.setBlock(i + 2, j + 21, k + 17, NovaCraftBlocks.basal_bricks, 0, 2);
		world.setBlock(i + 3, j + 21, k + 17, NovaCraftBlocks.cracked_basal_bricks, 0, 2);
		world.setBlock(i + 4, j + 21, k + 17, NovaCraftBlocks.cracked_basal_bricks, 0, 2);
		world.setBlock(i + 5, j + 21, k + 17, NovaCraftBlocks.basal_bricks, 0, 2);
		world.setBlock(i + 7, j + 21, k + 17, NovaCraftBlocks.basal, 0, 2);
		world.setBlock(i + 8, j + 21, k + 17, NovaCraftBlocks.basal, 0, 2);
		world.setBlock(i + 9, j + 21, k + 17, NovaCraftBlocks.basal_bricks, 0, 2);
		world.setBlock(i + 10, j + 21, k + 17, NovaCraftBlocks.basal_bricks, 0, 2);
		world.setBlock(i + 11, j + 21, k + 17, NovaCraftBlocks.basal, 0, 2);
		world.setBlock(i + 24, j + 21, k + 17, NovaCraftBlocks.basal, 0, 2);
		world.setBlock(i + 25, j + 21, k + 17, NovaCraftBlocks.cracked_basal_bricks, 0, 2);
		world.setBlock(i + 26, j + 21, k + 17, NovaCraftBlocks.basal_bricks, 0, 2);
		world.setBlock(i + 27, j + 21, k + 17, NovaCraftBlocks.basal_bricks, 0, 2);
		world.setBlock(i + 28, j + 21, k + 17, NovaCraftBlocks.basal, 0, 2);
		world.setBlock(i + 29, j + 21, k + 17, NovaCraftBlocks.basal, 0, 2);
		world.setBlock(i + 30, j + 21, k + 17, NovaCraftBlocks.basal_bricks, 0, 2);
		world.setBlock(i + 32, j + 21, k + 17, NovaCraftBlocks.basal_bricks, 0, 2);
		world.setBlock(i + 33, j + 21, k + 17, NovaCraftBlocks.basal_bricks, 0, 2);
		world.setBlock(i + 34, j + 21, k + 17, NovaCraftBlocks.cracked_basal_bricks, 0, 2);
		world.setBlock(i + 35, j + 21, k + 17, NovaCraftBlocks.basal_bricks, 0, 2);
		world.setBlock(i + 36, j + 21, k + 17, NovaCraftBlocks.basal_bricks, 0, 2);
		world.setBlock(i + 37, j + 21, k + 17, NovaCraftBlocks.cracked_basal_bricks, 0, 2);
		world.setBlock(i, j + 21, k + 18, NovaCraftBlocks.cracked_basal_bricks, 0, 2);
		world.setBlock(i + 1, j + 21, k + 18, NovaCraftBlocks.basal_bricks, 0, 2);
		world.setBlock(i + 2, j + 21, k + 18, NovaCraftBlocks.basal_bricks, 0, 2);
		world.setBlock(i + 3, j + 21, k + 18, NovaCraftBlocks.basal_bricks, 0, 2);
		world.setBlock(i + 4, j + 21, k + 18, NovaCraftBlocks.cracked_basal_bricks, 0, 2);
		world.setBlock(i + 5, j + 21, k + 18, NovaCraftBlocks.basal, 0, 2);
		world.setBlock(i + 6, j + 21, k + 18, NovaCraftBlocks.basal_scrap, 0, 2);
		world.setBlock(i + 7, j + 21, k + 18, NovaCraftBlocks.basal, 0, 2);
		world.setBlock(i + 8, j + 21, k + 18, NovaCraftBlocks.basal_bricks, 0, 2);
		world.setBlock(i + 9, j + 21, k + 18, NovaCraftBlocks.basal_scrap, 0, 2);
		world.setBlock(i + 10, j + 21, k + 18, NovaCraftBlocks.basal_scrap, 0, 2);
		world.setBlock(i + 11, j + 21, k + 18, NovaCraftBlocks.basal_bricks, 0, 2);
		world.setBlock(i + 24, j + 21, k + 18, NovaCraftBlocks.basal, 0, 2);
		world.setBlock(i + 25, j + 21, k + 18, NovaCraftBlocks.basal, 0, 2);
		world.setBlock(i + 26, j + 21, k + 18, NovaCraftBlocks.cracked_basal_bricks, 0, 2);
		world.setBlock(i + 27, j + 21, k + 18, NovaCraftBlocks.basal, 0, 2);
		world.setBlock(i + 28, j + 21, k + 18, NovaCraftBlocks.basal, 0, 2);
		world.setBlock(i + 29, j + 21, k + 18, NovaCraftBlocks.basal, 0, 2);
		world.setBlock(i + 30, j + 21, k + 18, NovaCraftBlocks.basal, 0, 2);
		world.setBlock(i + 31, j + 21, k + 18, NovaCraftBlocks.basal, 0, 2);
		world.setBlock(i + 32, j + 21, k + 18, NovaCraftBlocks.basal_bricks, 0, 2);
		world.setBlock(i + 33, j + 21, k + 18, NovaCraftBlocks.cracked_basal_bricks, 0, 2);
		world.setBlock(i + 34, j + 21, k + 18, NovaCraftBlocks.basal_bricks, 0, 2);
		world.setBlock(i + 35, j + 21, k + 18, NovaCraftBlocks.basal_bricks, 0, 2);
		world.setBlock(i + 36, j + 21, k + 18, NovaCraftBlocks.basal_bricks, 0, 2);
		world.setBlock(i + 37, j + 21, k + 18, NovaCraftBlocks.cracked_basal_bricks, 0, 2);
		world.setBlock(i, j + 21, k + 19, NovaCraftBlocks.cracked_basal_bricks, 0, 2);
		world.setBlock(i + 1, j + 21, k + 19, NovaCraftBlocks.cracked_basal_bricks, 0, 2);
		world.setBlock(i + 2, j + 21, k + 19, NovaCraftBlocks.basal_bricks, 0, 2);
		world.setBlock(i + 3, j + 21, k + 19, NovaCraftBlocks.basal_bricks, 0, 2);
		world.setBlock(i + 4, j + 21, k + 19, NovaCraftBlocks.basal_bricks, 0, 2);
		world.setBlock(i + 5, j + 21, k + 19, NovaCraftBlocks.basal_bricks, 0, 2);
		world.setBlock(i + 6, j + 21, k + 19, NovaCraftBlocks.basal, 0, 2);
		world.setBlock(i + 7, j + 21, k + 19, NovaCraftBlocks.basal_bricks, 0, 2);
		world.setBlock(i + 8, j + 21, k + 19, NovaCraftBlocks.basal, 0, 2);
		world.setBlock(i + 9, j + 21, k + 19, NovaCraftBlocks.basal_bricks, 0, 2);
		world.setBlock(i + 10, j + 21, k + 19, NovaCraftBlocks.basal_bricks, 0, 2);
		world.setBlock(i + 11, j + 21, k + 19, NovaCraftBlocks.basal, 0, 2);
		world.setBlock(i + 24, j + 21, k + 19, NovaCraftBlocks.basal_bricks, 0, 2);
		world.setBlock(i + 25, j + 21, k + 19, NovaCraftBlocks.basal, 0, 2);
		world.setBlock(i + 26, j + 21, k + 19, NovaCraftBlocks.cracked_basal_bricks, 0, 2);
		world.setBlock(i + 27, j + 21, k + 19, NovaCraftBlocks.cracked_basal_bricks, 0, 2);
		world.setBlock(i + 28, j + 21, k + 19, NovaCraftBlocks.basal_bricks, 0, 2);
		world.setBlock(i + 29, j + 21, k + 19, NovaCraftBlocks.basal, 0, 2);
		world.setBlock(i + 31, j + 21, k + 19, NovaCraftBlocks.basal_scrap, 0, 2);
		world.setBlock(i + 32, j + 21, k + 19, NovaCraftBlocks.basal, 0, 2);
		world.setBlock(i + 33, j + 21, k + 19, NovaCraftBlocks.cracked_basal_bricks, 0, 2);
		world.setBlock(i + 34, j + 21, k + 19, NovaCraftBlocks.cracked_basal_bricks, 0, 2);
		world.setBlock(i + 35, j + 21, k + 19, NovaCraftBlocks.cracked_basal_bricks, 0, 2);
		world.setBlock(i + 36, j + 21, k + 19, NovaCraftBlocks.cracked_basal_bricks, 0, 2);
		world.setBlock(i + 37, j + 21, k + 19, NovaCraftBlocks.cracked_basal_bricks, 0, 2);
		world.setBlock(i, j + 21, k + 20, NovaCraftBlocks.basal, 0, 2);
		world.setBlock(i + 1, j + 21, k + 20, NovaCraftBlocks.cracked_basal_bricks, 0, 2);
		world.setBlock(i + 2, j + 21, k + 20, NovaCraftBlocks.basal_bricks, 0, 2);
		world.setBlock(i + 3, j + 21, k + 20, NovaCraftBlocks.cracked_basal_bricks, 0, 2);
		world.setBlock(i + 4, j + 21, k + 20, NovaCraftBlocks.cracked_basal_bricks, 0, 2);
		world.setBlock(i + 5, j + 21, k + 20, NovaCraftBlocks.cracked_basal_bricks, 0, 2);
		world.setBlock(i + 7, j + 21, k + 20, NovaCraftBlocks.basal_bricks, 0, 2);
		world.setBlock(i + 8, j + 21, k + 20, NovaCraftBlocks.basal_bricks, 0, 2);
		world.setBlock(i + 9, j + 21, k + 20, NovaCraftBlocks.basal, 0, 2);
		world.setBlock(i + 10, j + 21, k + 20, NovaCraftBlocks.basal, 0, 2);
		world.setBlock(i + 11, j + 21, k + 20, NovaCraftBlocks.basal_bricks, 0, 2);
		world.setBlock(i + 25, j + 21, k + 20, NovaCraftBlocks.basal_scrap, 0, 2);
		world.setBlock(i + 26, j + 21, k + 20, NovaCraftBlocks.basal, 0, 2);
		world.setBlock(i + 27, j + 21, k + 20, NovaCraftBlocks.basal, 0, 2);
		world.setBlock(i + 28, j + 21, k + 20, NovaCraftBlocks.basal, 0, 2);
		world.setBlock(i + 29, j + 21, k + 20, NovaCraftBlocks.basal, 0, 2);
		world.setBlock(i + 32, j + 21, k + 20, NovaCraftBlocks.basal_bricks, 0, 2);
		world.setBlock(i + 33, j + 21, k + 20, NovaCraftBlocks.basal_bricks, 0, 2);
		world.setBlock(i + 34, j + 21, k + 20, NovaCraftBlocks.cracked_basal_bricks, 0, 2);
		world.setBlock(i + 35, j + 21, k + 20, NovaCraftBlocks.basal_bricks, 0, 2);
		world.setBlock(i + 36, j + 21, k + 20, NovaCraftBlocks.cracked_basal_bricks, 0, 2);
		world.setBlock(i + 37, j + 21, k + 20, NovaCraftBlocks.cracked_basal_bricks, 0, 2);
		world.setBlock(i, j + 21, k + 21, NovaCraftBlocks.cracked_basal_bricks, 0, 2);
		world.setBlock(i + 1, j + 21, k + 21, NovaCraftBlocks.cracked_basal_bricks, 0, 2);
		world.setBlock(i + 2, j + 21, k + 21, NovaCraftBlocks.basal_bricks, 0, 2);
		world.setBlock(i + 3, j + 21, k + 21, NovaCraftBlocks.cracked_basal_bricks, 0, 2);
		world.setBlock(i + 4, j + 21, k + 21, NovaCraftBlocks.basal, 0, 2);
		world.setBlock(i + 5, j + 21, k + 21, NovaCraftBlocks.basal_bricks, 0, 2);
		world.setBlock(i + 32, j + 21, k + 21, NovaCraftBlocks.basal_bricks, 0, 2);
		world.setBlock(i + 33, j + 21, k + 21, NovaCraftBlocks.cracked_basal_bricks, 0, 2);
		world.setBlock(i + 34, j + 21, k + 21, NovaCraftBlocks.cracked_basal_bricks, 0, 2);
		world.setBlock(i + 35, j + 21, k + 21, NovaCraftBlocks.basal_bricks, 0, 2);
		world.setBlock(i + 36, j + 21, k + 21, NovaCraftBlocks.basal_bricks, 0, 2);
		world.setBlock(i + 37, j + 21, k + 21, NovaCraftBlocks.cracked_basal_bricks, 0, 2);
		world.setBlock(i, j + 21, k + 22, NovaCraftBlocks.basal_bricks, 0, 2);
		world.setBlock(i + 1, j + 21, k + 22, NovaCraftBlocks.cracked_basal_bricks, 0, 2);
		world.setBlock(i + 2, j + 21, k + 22, NovaCraftBlocks.basal_bricks, 0, 2);
		world.setBlock(i + 3, j + 21, k + 22, NovaCraftBlocks.basal_bricks, 0, 2);
		world.setBlock(i + 4, j + 21, k + 22, NovaCraftBlocks.basal, 0, 2);
		world.setBlock(i + 5, j + 21, k + 22, NovaCraftBlocks.basal_bricks, 0, 2);
		world.setBlock(i + 6, j + 21, k + 22, NovaCraftBlocks.basal, 0, 2);
		world.setBlock(i + 31, j + 21, k + 22, NovaCraftBlocks.basal_scrap, 0, 2);
		world.setBlock(i + 32, j + 21, k + 22, NovaCraftBlocks.basal_bricks, 0, 2);
		world.setBlock(i + 33, j + 21, k + 22, NovaCraftBlocks.basal_bricks, 0, 2);
		world.setBlock(i + 34, j + 21, k + 22, NovaCraftBlocks.cracked_basal_bricks, 0, 2);
		world.setBlock(i + 35, j + 21, k + 22, NovaCraftBlocks.basal_bricks, 0, 2);
		world.setBlock(i + 36, j + 21, k + 22, NovaCraftBlocks.cracked_basal_bricks, 0, 2);
		world.setBlock(i + 37, j + 21, k + 22, NovaCraftBlocks.basal, 0, 2);
		world.setBlock(i, j + 21, k + 23, NovaCraftBlocks.basal_bricks, 0, 2);
		world.setBlock(i + 1, j + 21, k + 23, NovaCraftBlocks.basal, 0, 2);
		world.setBlock(i + 2, j + 21, k + 23, NovaCraftBlocks.basal, 0, 2);
		world.setBlock(i + 3, j + 21, k + 23, NovaCraftBlocks.cracked_basal_bricks, 0, 2);
		world.setBlock(i + 4, j + 21, k + 23, NovaCraftBlocks.basal_bricks, 0, 2);
		world.setBlock(i + 5, j + 21, k + 23, NovaCraftBlocks.basal_bricks, 0, 2);
		world.setBlock(i + 6, j + 21, k + 23, NovaCraftBlocks.basal, 0, 2);
		world.setBlock(i + 31, j + 21, k + 23, NovaCraftBlocks.basal_scrap, 0, 2);
		world.setBlock(i + 32, j + 21, k + 23, NovaCraftBlocks.basal_bricks, 0, 2);
		world.setBlock(i + 33, j + 21, k + 23, NovaCraftBlocks.cracked_basal_bricks, 0, 2);
		world.setBlock(i + 34, j + 21, k + 23, NovaCraftBlocks.basal_bricks, 0, 2);
		world.setBlock(i + 35, j + 21, k + 23, NovaCraftBlocks.cracked_basal_bricks, 0, 2);
		world.setBlock(i + 36, j + 21, k + 23, NovaCraftBlocks.cracked_basal_bricks, 0, 2);
		world.setBlock(i + 37, j + 21, k + 23, NovaCraftBlocks.basal, 0, 2);
		world.setBlock(i, j + 21, k + 24, NovaCraftBlocks.basal_bricks, 0, 2);
		world.setBlock(i + 1, j + 21, k + 24, NovaCraftBlocks.cracked_basal_bricks, 0, 2);
		world.setBlock(i + 3, j + 21, k + 24, NovaCraftBlocks.basal_bricks, 0, 2);
		world.setBlock(i + 4, j + 21, k + 24, NovaCraftBlocks.cracked_basal_bricks, 0, 2);
		world.setBlock(i + 5, j + 21, k + 24, NovaCraftBlocks.basal, 0, 2);
		world.setBlock(i + 6, j + 21, k + 24, NovaCraftBlocks.basal_bricks, 0, 2);
		world.setBlock(i + 31, j + 21, k + 24, NovaCraftBlocks.basal_scrap, 0, 2);
		world.setBlock(i + 32, j + 21, k + 24, NovaCraftBlocks.basal_bricks, 0, 2);
		world.setBlock(i + 33, j + 21, k + 24, NovaCraftBlocks.basal_bricks, 0, 2);
		world.setBlock(i + 34, j + 21, k + 24, NovaCraftBlocks.basal_bricks, 0, 2);
		world.setBlock(i + 35, j + 21, k + 24, NovaCraftBlocks.basal_bricks, 0, 2);
		world.setBlock(i + 36, j + 21, k + 24, NovaCraftBlocks.basal, 0, 2);
		world.setBlock(i + 37, j + 21, k + 24, NovaCraftBlocks.cracked_basal_bricks, 0, 2);
		world.setBlock(i, j + 21, k + 25, NovaCraftBlocks.basal, 0, 2);
		world.setBlock(i + 1, j + 21, k + 25, NovaCraftBlocks.basal_bricks, 0, 2);
		world.setBlock(i + 2, j + 21, k + 25, NovaCraftBlocks.basal, 0, 2);
		world.setBlock(i + 3, j + 21, k + 25, NovaCraftBlocks.basal_bricks, 0, 2);
		world.setBlock(i + 4, j + 21, k + 25, NovaCraftBlocks.cracked_basal_bricks, 0, 2);
		world.setBlock(i + 5, j + 21, k + 25, NovaCraftBlocks.basal_bricks, 0, 2);
		world.setBlock(i + 6, j + 21, k + 25, NovaCraftBlocks.cracked_basal_bricks, 0, 2);
		world.setBlock(i + 33, j + 21, k + 25, NovaCraftBlocks.basal_bricks, 0, 2);
		world.setBlock(i + 34, j + 21, k + 25, NovaCraftBlocks.basal_bricks, 0, 2);
		world.setBlock(i + 35, j + 21, k + 25, NovaCraftBlocks.cracked_basal_bricks, 0, 2);
		world.setBlock(i + 36, j + 21, k + 25, NovaCraftBlocks.basal_bricks, 0, 2);
		world.setBlock(i + 37, j + 21, k + 25, NovaCraftBlocks.cracked_basal_bricks, 0, 2);
		world.setBlock(i, j + 21, k + 26, NovaCraftBlocks.basal_bricks, 0, 2);
		world.setBlock(i + 1, j + 21, k + 26, NovaCraftBlocks.basal_bricks, 0, 2);
		world.setBlock(i + 2, j + 21, k + 26, NovaCraftBlocks.basal_bricks, 0, 2);
		world.setBlock(i + 3, j + 21, k + 26, NovaCraftBlocks.cracked_basal_bricks, 0, 2);
		world.setBlock(i + 4, j + 21, k + 26, NovaCraftBlocks.basal_bricks, 0, 2);
		world.setBlock(i + 5, j + 21, k + 26, NovaCraftBlocks.cracked_basal_bricks, 0, 2);
		world.setBlock(i + 6, j + 21, k + 26, NovaCraftBlocks.basal_bricks, 0, 2);
		world.setBlock(i + 31, j + 21, k + 26, NovaCraftBlocks.basal_bricks, 0, 2);
		world.setBlock(i + 33, j + 21, k + 26, NovaCraftBlocks.cracked_basal_bricks, 0, 2);
		world.setBlock(i + 34, j + 21, k + 26, NovaCraftBlocks.cracked_basal_bricks, 0, 2);
		world.setBlock(i + 35, j + 21, k + 26, NovaCraftBlocks.cracked_basal_bricks, 0, 2);
		world.setBlock(i + 36, j + 21, k + 26, NovaCraftBlocks.basal, 0, 2);
		world.setBlock(i + 37, j + 21, k + 26, NovaCraftBlocks.cracked_basal_bricks, 0, 2);
		world.setBlock(i, j + 21, k + 27, NovaCraftBlocks.basal_bricks, 0, 2);
		world.setBlock(i + 1, j + 21, k + 27, NovaCraftBlocks.basal_bricks, 0, 2);
		world.setBlock(i + 2, j + 21, k + 27, NovaCraftBlocks.cracked_basal_bricks, 0, 2);
		world.setBlock(i + 3, j + 21, k + 27, NovaCraftBlocks.basal, 0, 2);
		world.setBlock(i + 4, j + 21, k + 27, NovaCraftBlocks.basal_bricks, 0, 2);
		world.setBlock(i + 5, j + 21, k + 27, NovaCraftBlocks.basal_bricks, 0, 2);
		world.setBlock(i + 6, j + 21, k + 27, NovaCraftBlocks.basal_bricks, 0, 2);
		world.setBlock(i + 31, j + 21, k + 27, NovaCraftBlocks.cracked_basal_bricks, 0, 2);
		world.setBlock(i + 34, j + 21, k + 27, NovaCraftBlocks.cracked_basal_bricks, 0, 2);
		world.setBlock(i + 35, j + 21, k + 27, NovaCraftBlocks.basal_bricks, 0, 2);
		world.setBlock(i + 36, j + 21, k + 27, NovaCraftBlocks.cracked_basal_bricks, 0, 2);
		world.setBlock(i + 37, j + 21, k + 27, NovaCraftBlocks.basal_bricks, 0, 2);
		world.setBlock(i, j + 21, k + 28, NovaCraftBlocks.cracked_basal_bricks, 0, 2);
		world.setBlock(i + 1, j + 21, k + 28, NovaCraftBlocks.basal, 0, 2);
		world.setBlock(i + 2, j + 21, k + 28, NovaCraftBlocks.basal_bricks, 0, 2);
		world.setBlock(i + 4, j + 21, k + 28, NovaCraftBlocks.basal_scrap, 0, 2);
		world.setBlock(i + 5, j + 21, k + 28, NovaCraftBlocks.basal_bricks, 0, 2);
		world.setBlock(i + 6, j + 21, k + 28, NovaCraftBlocks.cracked_basal_bricks, 0, 2);
		world.setBlock(i + 31, j + 21, k + 28, NovaCraftBlocks.cracked_basal_bricks, 0, 2);
		world.setBlock(i + 32, j + 21, k + 28, NovaCraftBlocks.basal_bricks, 0, 2);
		world.setBlock(i + 33, j + 21, k + 28, NovaCraftBlocks.basal_scrap, 0, 2);
		world.setBlock(i + 34, j + 21, k + 28, NovaCraftBlocks.basal_bricks, 0, 2);
		world.setBlock(i + 35, j + 21, k + 28, NovaCraftBlocks.basal_scrap, 0, 2);
		world.setBlock(i + 36, j + 21, k + 28, NovaCraftBlocks.cracked_basal_bricks, 0, 2);
		world.setBlock(i + 37, j + 21, k + 28, NovaCraftBlocks.cracked_basal_bricks, 0, 2);
		world.setBlock(i, j + 21, k + 29, NovaCraftBlocks.cracked_basal_bricks, 0, 2);
		world.setBlock(i + 1, j + 21, k + 29, NovaCraftBlocks.cracked_basal_bricks, 0, 2);
		world.setBlock(i + 3, j + 21, k + 29, NovaCraftBlocks.basal_scrap, 0, 2);
		world.setBlock(i + 4, j + 21, k + 29, NovaCraftBlocks.basal_bricks, 0, 2);
		world.setBlock(i + 5, j + 21, k + 29, NovaCraftBlocks.basal_bricks, 0, 2);
		world.setBlock(i + 6, j + 21, k + 29, NovaCraftBlocks.cracked_basal_bricks, 0, 2);
		world.setBlock(i + 31, j + 21, k + 29, NovaCraftBlocks.cracked_basal_bricks, 0, 2);
		world.setBlock(i + 32, j + 21, k + 29, NovaCraftBlocks.basal_scrap, 0, 2);
		world.setBlock(i + 33, j + 21, k + 29, NovaCraftBlocks.basal_scrap, 0, 2);
		world.setBlock(i + 34, j + 21, k + 29, NovaCraftBlocks.basal_bricks, 0, 2);
		world.setBlock(i + 35, j + 21, k + 29, NovaCraftBlocks.basal_scrap, 0, 2);
		world.setBlock(i + 36, j + 21, k + 29, NovaCraftBlocks.basal_bricks, 0, 2);
		world.setBlock(i + 37, j + 21, k + 29, NovaCraftBlocks.cracked_basal_bricks, 0, 2);
		world.setBlock(i, j + 21, k + 30, NovaCraftBlocks.basal_bricks, 0, 2);
		world.setBlock(i + 1, j + 21, k + 30, NovaCraftBlocks.cracked_basal_bricks, 0, 2);
		world.setBlock(i + 2, j + 21, k + 30, NovaCraftBlocks.basal_bricks, 0, 2);
		world.setBlock(i + 4, j + 21, k + 30, NovaCraftBlocks.basal_scrap, 0, 2);
		world.setBlock(i + 5, j + 21, k + 30, NovaCraftBlocks.basal_scrap, 0, 2);
		world.setBlock(i + 6, j + 21, k + 30, NovaCraftBlocks.basal_bricks, 0, 2);
		world.setBlock(i + 31, j + 21, k + 30, NovaCraftBlocks.basal_scrap, 0, 2);
		world.setBlock(i + 34, j + 21, k + 30, NovaCraftBlocks.cracked_basal_bricks, 0, 2);
		world.setBlock(i + 35, j + 21, k + 30, NovaCraftBlocks.basal_bricks, 0, 2);
		world.setBlock(i + 36, j + 21, k + 30, NovaCraftBlocks.cracked_basal_bricks, 0, 2);
		world.setBlock(i + 37, j + 21, k + 30, NovaCraftBlocks.basal_bricks, 0, 2);
		world.setBlock(i, j + 21, k + 31, NovaCraftBlocks.basal_bricks, 0, 2);
		world.setBlock(i + 1, j + 21, k + 31, NovaCraftBlocks.cracked_basal_bricks, 0, 2);
		world.setBlock(i + 2, j + 21, k + 31, NovaCraftBlocks.cracked_basal_bricks, 0, 2);
		world.setBlock(i + 3, j + 21, k + 31, NovaCraftBlocks.cracked_basal_bricks, 0, 2);
		world.setBlock(i + 6, j + 21, k + 31, NovaCraftBlocks.cracked_basal_bricks, 0, 2);
		world.setBlock(i + 8, j + 21, k + 31, NovaCraftBlocks.basal_bricks, 0, 2);
		world.setBlock(i + 12, j + 21, k + 31, NovaCraftBlocks.basal_bricks, 0, 2);
		world.setBlock(i + 16, j + 21, k + 31, NovaCraftBlocks.basal_bricks, 0, 2);
		world.setBlock(i + 17, j + 21, k + 31, NovaCraftBlocks.basal_bricks, 0, 2);
		world.setBlock(i + 18, j + 21, k + 31, NovaCraftBlocks.basal_bricks, 0, 2);
		world.setBlock(i + 19, j + 21, k + 31, NovaCraftBlocks.cracked_basal_bricks, 0, 2);
		world.setBlock(i + 20, j + 21, k + 31, NovaCraftBlocks.cracked_basal_bricks, 0, 2);
		world.setBlock(i + 21, j + 21, k + 31, NovaCraftBlocks.basal_scrap, 0, 2);
		world.setBlock(i + 25, j + 21, k + 31, NovaCraftBlocks.basal, 0, 2);
		world.setBlock(i + 31, j + 21, k + 31, NovaCraftBlocks.basal_bricks, 0, 2);
		world.setBlock(i + 35, j + 21, k + 31, NovaCraftBlocks.basal, 0, 2);
		world.setBlock(i + 36, j + 21, k + 31, NovaCraftBlocks.basal_bricks, 0, 2);
		world.setBlock(i + 37, j + 21, k + 31, NovaCraftBlocks.cracked_basal_bricks, 0, 2);
		world.setBlock(i, j + 21, k + 32, NovaCraftBlocks.cracked_basal_bricks, 0, 2);
		world.setBlock(i + 1, j + 21, k + 32, NovaCraftBlocks.basal, 0, 2);
		world.setBlock(i + 2, j + 21, k + 32, NovaCraftBlocks.basal_bricks, 0, 2);
		world.setBlock(i + 3, j + 21, k + 32, NovaCraftBlocks.basal, 0, 2);
		world.setBlock(i + 8, j + 21, k + 32, NovaCraftBlocks.basal_bricks, 0, 2);
		world.setBlock(i + 16, j + 21, k + 32, NovaCraftBlocks.basal_bricks, 0, 2);
		world.setBlock(i + 17, j + 21, k + 32, Blocks.lava, 0, 2);
		world.setBlock(i + 18, j + 21, k + 32, Blocks.lava, 0, 2);
		world.setBlock(i + 19, j + 21, k + 32, Blocks.lava, 2, 2);
		world.setBlock(i + 20, j + 21, k + 32, Blocks.lava, 0, 2);
		world.setBlock(i + 21, j + 21, k + 32, NovaCraftBlocks.basal, 0, 2);
		world.setBlock(i + 25, j + 21, k + 32, NovaCraftBlocks.basal_bricks, 0, 2);
		world.setBlock(i + 29, j + 21, k + 32, NovaCraftBlocks.cracked_basal_bricks, 0, 2);
		world.setBlock(i + 35, j + 21, k + 32, NovaCraftBlocks.basal_scrap, 0, 2);
		world.setBlock(i + 36, j + 21, k + 32, NovaCraftBlocks.basal_bricks, 0, 2);
		world.setBlock(i + 37, j + 21, k + 32, NovaCraftBlocks.basal_bricks, 0, 2);
		world.setBlock(i, j + 21, k + 33, NovaCraftBlocks.cracked_basal_bricks, 0, 2);
