package com.NovaCraft.world.bastion.treasure;

import net.minecraft.world.gen.feature.*;
import net.minecraft.enchantment.Enchantment;
import net.minecraft.enchantment.EnchantmentData;
import net.minecraft.world.*;
import java.util.*;

import com.NovaCraft.Items.NovaCraftItems;
import com.NovaCraft.config.Configs;
import com.NovaCraft.registry.OtherModBlocks;
import com.NovaCraft.registry.OtherModItems;
import com.NovaCraftBlocks.NovaCraftBlocks;

import cpw.mods.fml.common.Loader;
import net.minecraft.init.*;
import net.minecraft.item.ItemStack;
import net.minecraft.tileentity.TileEntityChest;
import net.minecraft.util.MathHelper;

public class BastionSerpentQueenLairGen extends WorldGenerator
{
	public BastionSerpentQueenLairGen() {

	}
	
	public boolean generate(final World world, final Random random, final int i, final int j, final int k) {
		
		world.setBlock(i, j, k, NovaCraftBlocks.basal_bricks, 0, 2);
		world.setBlock(i + 1, j, k, NovaCraftBlocks.basal_bricks, 0, 2);
		world.setBlock(i + 2, j, k, NovaCraftBlocks.basal_bricks, 0, 2);
		world.setBlock(i + 3, j, k, NovaCraftBlocks.basal_bricks, 0, 2);
		world.setBlock(i + 4, j, k, NovaCraftBlocks.basal_bricks, 0, 2);
		world.setBlock(i + 5, j, k, NovaCraftBlocks.basal_bricks, 0, 2);
		world.setBlock(i + 6, j, k, NovaCraftBlocks.basal_bricks, 0, 2);
		world.setBlock(i + 7, j, k, NovaCraftBlocks.basal_bricks, 0, 2);
		world.setBlock(i + 8, j, k, NovaCraftBlocks.basal_bricks, 0, 2);
		world.setBlock(i + 9, j, k, NovaCraftBlocks.basal_bricks, 0, 2);
		world.setBlock(i + 10, j, k, NovaCraftBlocks.basal_bricks, 0, 2);
		world.setBlock(i + 11, j, k, NovaCraftBlocks.basal_bricks, 0, 2);
		world.setBlock(i + 12, j, k, NovaCraftBlocks.basal_bricks, 0, 2);
		world.setBlock(i + 13, j, k, NovaCraftBlocks.basal_bricks, 0, 2);
		world.setBlock(i + 14, j, k, NovaCraftBlocks.basal_bricks, 0, 2);
		world.setBlock(i + 15, j, k, NovaCraftBlocks.basal_bricks, 0, 2);
		world.setBlock(i, j, k + 1, NovaCraftBlocks.basal_bricks, 0, 2);
		world.setBlock(i + 1, j, k + 1, NovaCraftBlocks.glowing_basal, 0, 2);
		world.setBlock(i + 2, j, k + 1, NovaCraftBlocks.basal_bricks, 0, 2);
		world.setBlock(i + 3, j, k + 1, NovaCraftBlocks.basal_bricks, 0, 2);
		world.setBlock(i + 4, j, k + 1, NovaCraftBlocks.basal_bricks, 0, 2);
		world.setBlock(i + 5, j, k + 1, NovaCraftBlocks.basal_bricks, 0, 2);
		world.setBlock(i + 6, j, k + 1, NovaCraftBlocks.basal_bricks, 0, 2);
		world.setBlock(i + 7, j, k + 1, NovaCraftBlocks.block_of_vanite, 0, 2);
		world.setBlock(i + 8, j, k + 1, NovaCraftBlocks.basal_bricks, 0, 2);
		world.setBlock(i + 9, j, k + 1, NovaCraftBlocks.cracked_basal_bricks, 0, 2);
		world.setBlock(i + 10, j, k + 1, NovaCraftBlocks.basal_bricks, 0, 2);
		world.setBlock(i + 11, j, k + 1, Blocks.lava, 0, 2);
		world.setBlock(i + 12, j, k + 1, NovaCraftBlocks.basal_bricks, 0, 2);
		world.setBlock(i + 13, j, k + 1, NovaCraftBlocks.cracked_basal_bricks, 0, 2);
		world.setBlock(i + 14, j, k + 1, NovaCraftBlocks.glowing_basal, 0, 2);
		world.setBlock(i + 15, j, k + 1, NovaCraftBlocks.basal_bricks, 0, 2);
		world.setBlock(i, j, k + 2, NovaCraftBlocks.basal_bricks, 0, 2);
		world.setBlock(i + 1, j, k + 2, NovaCraftBlocks.basal_bricks, 0, 2);
		world.setBlock(i + 2, j, k + 2, NovaCraftBlocks.glowing_basal, 0, 2);
		world.setBlock(i + 3, j, k + 2, NovaCraftBlocks.cracked_basal_bricks, 0, 2);
		world.setBlock(i + 4, j, k + 2, Blocks.lava, 0, 2);
		world.setBlock(i + 5, j, k + 2, NovaCraftBlocks.basal_bricks, 0, 2);
		world.setBlock(i + 6, j, k + 2, NovaCraftBlocks.basal_bricks, 0, 2);
		world.setBlock(i + 7, j, k + 2, NovaCraftBlocks.basal_bricks, 0, 2);
		world.setBlock(i + 8, j, k + 2, Blocks.lava, 0, 2);
		world.setBlock(i + 9, j, k + 2, NovaCraftBlocks.basal_bricks, 0, 2);
		world.setBlock(i + 10, j, k + 2, NovaCraftBlocks.glowing_basal, 0, 2);
		world.setBlock(i + 11, j, k + 2, NovaCraftBlocks.basal_bricks, 0, 2);
		world.setBlock(i + 12, j, k + 2, NovaCraftBlocks.cracked_basal_bricks, 0, 2);
		world.setBlock(i + 13, j, k + 2, Blocks.lava, 0, 2);
		world.setBlock(i + 14, j, k + 2, NovaCraftBlocks.basal_bricks, 0, 2);
		world.setBlock(i + 15, j, k + 2, NovaCraftBlocks.basal_bricks, 0, 2);
		world.setBlock(i, j, k + 3, NovaCraftBlocks.basal_bricks, 0, 2);
		world.setBlock(i + 1, j, k + 3, Blocks.lava, 0, 2);
		world.setBlock(i + 2, j, k + 3, NovaCraftBlocks.basal_bricks, 0, 2);
		world.setBlock(i + 3, j, k + 3, NovaCraftBlocks.glowing_basal, 0, 2);
		world.setBlock(i + 4, j, k + 3, NovaCraftBlocks.basal_bricks, 0, 2);
		world.setBlock(i + 5, j, k + 3, NovaCraftBlocks.basal_bricks, 0, 2);
		world.setBlock(i + 6, j, k + 3, Blocks.lava, 0, 2);
		world.setBlock(i + 7, j, k + 3, NovaCraftBlocks.basal_bricks, 0, 2);
		world.setBlock(i + 8, j, k + 3, NovaCraftBlocks.basal_bricks, 0, 2);
		world.setBlock(i + 9, j, k + 3, Blocks.lava, 0, 2);
		world.setBlock(i + 10, j, k + 3, NovaCraftBlocks.basal_bricks, 0, 2);
		world.setBlock(i + 11, j, k + 3, Blocks.lava, 0, 2);
		world.setBlock(i + 12, j, k + 3, NovaCraftBlocks.glowing_basal, 0, 2);
		world.setBlock(i + 13, j, k + 3, NovaCraftBlocks.basal_bricks, 0, 2);
		world.setBlock(i + 14, j, k + 3, Blocks.lava, 0, 2);
		world.setBlock(i + 15, j, k + 3, NovaCraftBlocks.basal_bricks, 0, 2);
		world.setBlock(i, j, k + 4, NovaCraftBlocks.basal_bricks, 0, 2);
		world.setBlock(i + 1, j, k + 4, NovaCraftBlocks.basal_bricks, 0, 2);
		world.setBlock(i + 2, j, k + 4, Blocks.lava, 0, 2);
		world.setBlock(i + 3, j, k + 4, NovaCraftBlocks.basal_bricks, 0, 2);
		world.setBlock(i + 4, j, k + 4, NovaCraftBlocks.glowing_basal, 0, 2);
		world.setBlock(i + 5, j, k + 4, NovaCraftBlocks.basal_bricks, 0, 2);
		world.setBlock(i + 6, j, k + 4, Blocks.lava, 0, 2);
		world.setBlock(i + 7, j, k + 4, NovaCraftBlocks.glowing_basal, 0, 2);
		world.setBlock(i + 8, j, k + 4, NovaCraftBlocks.cracked_basal_bricks, 0, 2);
		world.setBlock(i + 9, j, k + 4, NovaCraftBlocks.basal_bricks, 0, 2);
		world.setBlock(i + 10, j, k + 4, NovaCraftBlocks.basal_bricks, 0, 2);
		world.setBlock(i + 11, j, k + 4, NovaCraftBlocks.glowing_basal, 0, 2);
		world.setBlock(i + 12, j, k + 4, NovaCraftBlocks.cracked_basal_bricks, 0, 2);
		world.setBlock(i + 13, j, k + 4, Blocks.lava, 0, 2);
		world.setBlock(i + 14, j, k + 4, NovaCraftBlocks.basal_bricks, 0, 2);
		world.setBlock(i + 15, j, k + 4, NovaCraftBlocks.basal_bricks, 0, 2);
		world.setBlock(i, j, k + 5, NovaCraftBlocks.basal_bricks, 0, 2);
		world.setBlock(i + 1, j, k + 5, NovaCraftBlocks.basal_bricks, 0, 2);
		world.setBlock(i + 2, j, k + 5, NovaCraftBlocks.basal_bricks, 0, 2);
		world.setBlock(i + 3, j, k + 5, NovaCraftBlocks.basal_bricks, 0, 2);
		world.setBlock(i + 4, j, k + 5, Blocks.lava, 0, 2);
		world.setBlock(i + 5, j, k + 5, NovaCraftBlocks.glowing_basal, 0, 2);
		world.setBlock(i + 6, j, k + 5, NovaCraftBlocks.cracked_basal_bricks, 0, 2);
		world.setBlock(i + 7, j, k + 5, NovaCraftBlocks.basal_bricks, 0, 2);
		world.setBlock(i + 8, j, k + 5, Blocks.lava, 0, 2);
		world.setBlock(i + 9, j, k + 5, NovaCraftBlocks.basal_bricks, 0, 2);
		world.setBlock(i + 10, j, k + 5, NovaCraftBlocks.glowing_basal, 0, 2);
		world.setBlock(i + 11, j, k + 5, NovaCraftBlocks.basal_bricks, 0, 2);
		world.setBlock(i + 12, j, k + 5, NovaCraftBlocks.glowing_basal, 0, 2);
		world.setBlock(i + 13, j, k + 5, NovaCraftBlocks.basal_bricks, 0, 2);
		world.setBlock(i + 14, j, k + 5, NovaCraftBlocks.basal_bricks, 0, 2);
		world.setBlock(i + 15, j, k + 5, NovaCraftBlocks.basal_bricks, 0, 2);
		world.setBlock(i, j, k + 6, NovaCraftBlocks.basal_bricks, 0, 2);
		world.setBlock(i + 1, j, k + 6, NovaCraftBlocks.basal_bricks, 0, 2);
		world.setBlock(i + 2, j, k + 6, Blocks.lava, 0, 2);
		world.setBlock(i + 3, j, k + 6, NovaCraftBlocks.basal_bricks, 0, 2);
		world.setBlock(i + 4, j, k + 6, NovaCraftBlocks.basal_bricks, 0, 2);
		world.setBlock(i + 5, j, k + 6, NovaCraftBlocks.cracked_basal_bricks, 0, 2);
		world.setBlock(i + 6, j, k + 6, NovaCraftBlocks.glowing_basal, 0, 2);
		world.setBlock(i + 7, j, k + 6, NovaCraftBlocks.basal_bricks, 0, 2);
		world.setBlock(i + 8, j, k + 6, NovaCraftBlocks.basal_bricks, 0, 2);
		world.setBlock(i + 9, j, k + 6, NovaCraftBlocks.glowing_basal, 0, 2);
		world.setBlock(i + 10, j, k + 6, Blocks.lava, 0, 2);
		world.setBlock(i + 11, j, k + 6, NovaCraftBlocks.basal_bricks, 0, 2);
		world.setBlock(i + 12, j, k + 6, NovaCraftBlocks.basal_bricks, 0, 2);
		world.setBlock(i + 13, j, k + 6, NovaCraftBlocks.basal_bricks, 0, 2);
		world.setBlock(i + 14, j, k + 6, NovaCraftBlocks.basal_bricks, 0, 2);
		world.setBlock(i + 15, j, k + 6, NovaCraftBlocks.basal_bricks, 0, 2);
		world.setBlock(i, j, k + 7, NovaCraftBlocks.basal_bricks, 0, 2);
		world.setBlock(i + 1, j, k + 7, NovaCraftBlocks.basal_bricks, 0, 2);
		world.setBlock(i + 2, j, k + 7, NovaCraftBlocks.cracked_basal_bricks, 0, 2);
		world.setBlock(i + 3, j, k + 7, NovaCraftBlocks.basal_bricks, 0, 2);
		world.setBlock(i + 4, j, k + 7, Blocks.lava, 0, 2);
		world.setBlock(i + 5, j, k + 7, NovaCraftBlocks.basal_bricks, 0, 2);
		world.setBlock(i + 6, j, k + 7, NovaCraftBlocks.basal_bricks, 0, 2);
		world.setBlock(i + 9, j, k + 7, NovaCraftBlocks.basal_bricks, 0, 2);
		world.setBlock(i + 10, j, k + 7, NovaCraftBlocks.cracked_basal_bricks, 0, 2);
		world.setBlock(i + 11, j, k + 7, NovaCraftBlocks.basal_bricks, 0, 2);
		world.setBlock(i + 12, j, k + 7, NovaCraftBlocks.basal_bricks, 0, 2);
		world.setBlock(i + 13, j, k + 7, NovaCraftBlocks.basal_bricks, 0, 2);
		world.setBlock(i + 14, j, k + 7, NovaCraftBlocks.basal_bricks, 0, 2);
		world.setBlock(i + 15, j, k + 7, NovaCraftBlocks.basal_bricks, 0, 2);
		world.setBlock(i, j, k + 8, NovaCraftBlocks.basal_bricks, 0, 2);
		world.setBlock(i + 1, j, k + 8, Blocks.lava, 0, 2);
		world.setBlock(i + 2, j, k + 8, NovaCraftBlocks.basal_bricks, 0, 2);
		world.setBlock(i + 3, j, k + 8, NovaCraftBlocks.glowing_basal, 0, 2);
		world.setBlock(i + 4, j, k + 8, NovaCraftBlocks.basal_bricks, 0, 2);
		world.setBlock(i + 5, j, k + 8, Blocks.lava, 0, 2);
		world.setBlock(i + 6, j, k + 8, NovaCraftBlocks.basal_bricks, 0, 2);
		world.setBlock(i + 9, j, k + 8, NovaCraftBlocks.cracked_basal_bricks, 0, 2);
		world.setBlock(i + 10, j, k + 8, Blocks.lava, 0, 2);
		world.setBlock(i + 11, j, k + 8, NovaCraftBlocks.glowing_basal, 0, 2);
		world.setBlock(i + 12, j, k + 8, NovaCraftBlocks.basal_bricks, 0, 2);
		world.setBlock(i + 13, j, k + 8, NovaCraftBlocks.basal_bricks, 0, 2);
		world.setBlock(i + 14, j, k + 8, NovaCraftBlocks.basal_bricks, 0, 2);
		world.setBlock(i + 15, j, k + 8, NovaCraftBlocks.basal_bricks, 0, 2);
		world.setBlock(i, j, k + 9, NovaCraftBlocks.basal_bricks, 0, 2);
		world.setBlock(i + 1, j, k + 9, NovaCraftBlocks.cracked_basal_bricks, 0, 2);
		world.setBlock(i + 2, j, k + 9, Blocks.lava, 0, 2);
		world.setBlock(i + 3, j, k + 9, NovaCraftBlocks.cracked_basal_bricks, 0, 2);
		world.setBlock(i + 4, j, k + 9, Blocks.lava, 0, 2);
		world.setBlock(i + 5, j, k + 9, NovaCraftBlocks.basal_bricks, 0, 2);
		world.setBlock(i + 6, j, k + 9, NovaCraftBlocks.glowing_basal, 0, 2);
		world.setBlock(i + 7, j, k + 9, NovaCraftBlocks.cracked_basal_bricks, 0, 2);
		world.setBlock(i + 8, j, k + 9, NovaCraftBlocks.basal_bricks, 0, 2);
		world.setBlock(i + 9, j, k + 9, NovaCraftBlocks.glowing_basal, 0, 2);
		world.setBlock(i + 10, j, k + 9, NovaCraftBlocks.basal_bricks, 0, 2);
		world.setBlock(i + 11, j, k + 9, NovaCraftBlocks.basal_bricks, 0, 2);
		world.setBlock(i + 12, j, k + 9, Blocks.lava, 0, 2);
		world.setBlock(i + 13, j, k + 9, NovaCraftBlocks.basal_bricks, 0, 2);
		world.setBlock(i + 14, j, k + 9, NovaCraftBlocks.basal_bricks, 0, 2);
		world.setBlock(i + 15, j, k + 9, NovaCraftBlocks.basal_bricks, 0, 2);
		world.setBlock(i, j, k + 10, NovaCraftBlocks.basal_bricks, 0, 2);
		world.setBlock(i + 1, j, k + 10, NovaCraftBlocks.basal_bricks, 0, 2);
		world.setBlock(i + 2, j, k + 10, NovaCraftBlocks.basal_bricks, 0, 2);
		world.setBlock(i + 3, j, k + 10, NovaCraftBlocks.basal_bricks, 0, 2);
		world.setBlock(i + 4, j, k + 10, NovaCraftBlocks.cracked_basal_bricks, 0, 2);
		world.setBlock(i + 5, j, k + 10, NovaCraftBlocks.glowing_basal, 0, 2);
		world.setBlock(i + 6, j, k + 10, Blocks.lava, 0, 2);
		world.setBlock(i + 7, j, k + 10, NovaCraftBlocks.basal_bricks, 0, 2);
		world.setBlock(i + 8, j, k + 10, NovaCraftBlocks.basal_bricks, 0, 2);
		world.setBlock(i + 9, j, k + 10, NovaCraftBlocks.glowing_basal, 0, 2);
		world.setBlock(i + 10, j, k + 10, NovaCraftBlocks.glowing_basal, 0, 2);
		world.setBlock(i + 11, j, k + 10, Blocks.lava, 0, 2);
		world.setBlock(i + 12, j, k + 10, NovaCraftBlocks.basal_bricks, 0, 2);
		world.setBlock(i + 13, j, k + 10, NovaCraftBlocks.cracked_basal_bricks, 0, 2);
		world.setBlock(i + 14, j, k + 10, NovaCraftBlocks.glowing_basal, 0, 2);
		world.setBlock(i + 15, j, k + 10, NovaCraftBlocks.basal_bricks, 0, 2);
		world.setBlock(i, j, k + 11, NovaCraftBlocks.basal_bricks, 0, 2);
		world.setBlock(i + 1, j, k + 11, NovaCraftBlocks.basal_bricks, 0, 2);
		world.setBlock(i + 2, j, k + 11, Blocks.lava, 0, 2);
		world.setBlock(i + 3, j, k + 11, NovaCraftBlocks.basal_bricks, 0, 2);
		world.setBlock(i + 4, j, k + 11, NovaCraftBlocks.glowing_basal, 0, 2);
		world.setBlock(i + 5, j, k + 11, NovaCraftBlocks.basal_bricks, 0, 2);
		world.setBlock(i + 6, j, k + 11, NovaCraftBlocks.basal_bricks, 0, 2);
		world.setBlock(i + 7, j, k + 11, NovaCraftBlocks.cracked_basal_bricks, 0, 2);
		world.setBlock(i + 8, j, k + 11, Blocks.lava, 0, 2);
		world.setBlock(i + 9, j, k + 11, NovaCraftBlocks.cracked_basal_bricks, 0, 2);
		world.setBlock(i + 10, j, k + 11, NovaCraftBlocks.basal_bricks, 0, 2);
		world.setBlock(i + 11, j, k + 11, NovaCraftBlocks.glowing_basal, 0, 2);
		world.setBlock(i + 12, j, k + 11, NovaCraftBlocks.glowing_basal, 0, 2);
		world.setBlock(i + 13, j, k + 11, NovaCraftBlocks.basal_bricks, 0, 2);
		world.setBlock(i + 14, j, k + 11, Blocks.lava, 0, 2);
		world.setBlock(i + 15, j, k + 11, NovaCraftBlocks.basal_bricks, 0, 2);
		world.setBlock(i, j, k + 12, NovaCraftBlocks.basal_bricks, 0, 2);
		world.setBlock(i + 1, j, k + 12, Blocks.lava, 0, 2);
		world.setBlock(i + 2, j, k + 12, NovaCraftBlocks.cracked_basal_bricks, 0, 2);
		world.setBlock(i + 3, j, k + 12, NovaCraftBlocks.glowing_basal, 0, 2);
		world.setBlock(i + 4, j, k + 12, NovaCraftBlocks.basal_bricks, 0, 2);
		world.setBlock(i + 5, j, k + 12, Blocks.lava, 0, 2);
		world.setBlock(i + 6, j, k + 12, NovaCraftBlocks.basal_bricks, 0, 2);
		world.setBlock(i + 7, j, k + 12, NovaCraftBlocks.glowing_basal, 0, 2);
		world.setBlock(i + 8, j, k + 12, NovaCraftBlocks.basal_bricks, 0, 2);
		world.setBlock(i + 9, j, k + 12, NovaCraftBlocks.basal_bricks, 0, 2);
		world.setBlock(i + 10, j, k + 12, Blocks.lava, 0, 2);
		world.setBlock(i + 11, j, k + 12, NovaCraftBlocks.basal_bricks, 0, 2);
		world.setBlock(i + 12, j, k + 12, NovaCraftBlocks.glowing_basal, 0, 2);
		world.setBlock(i + 13, j, k + 12, Blocks.lava, 0, 2);
		world.setBlock(i + 14, j, k + 12, NovaCraftBlocks.basal_bricks, 0, 2);
		world.setBlock(i + 15, j, k + 12, NovaCraftBlocks.basal_bricks, 0, 2);
		world.setBlock(i, j, k + 13, NovaCraftBlocks.basal_bricks, 0, 2);
		world.setBlock(i + 1, j, k + 13, NovaCraftBlocks.basal_bricks, 0, 2);
		world.setBlock(i + 2, j, k + 13, NovaCraftBlocks.glowing_basal, 0, 2);
		world.setBlock(i + 3, j, k + 13, Blocks.lava, 0, 2);
		world.setBlock(i + 4, j, k + 13, NovaCraftBlocks.basal_bricks, 0, 2);
		world.setBlock(i + 5, j, k + 13, Blocks.lava, 0, 2);
		world.setBlock(i + 6, j, k + 13, NovaCraftBlocks.basal_bricks, 0, 2);
		world.setBlock(i + 7, j, k + 13, NovaCraftBlocks.cracked_basal_bricks, 0, 2);
		world.setBlock(i + 8, j, k + 13, Blocks.lava, 0, 2);
		world.setBlock(i + 9, j, k + 13, NovaCraftBlocks.basal_bricks, 0, 2);
		world.setBlock(i + 10, j, k + 13, NovaCraftBlocks.cracked_basal_bricks, 0, 2);
		world.setBlock(i + 11, j, k + 13, Blocks.lava, 0, 2);
		world.setBlock(i + 12, j, k + 13, NovaCraftBlocks.cracked_basal_bricks, 0, 2);
		world.setBlock(i + 13, j, k + 13, NovaCraftBlocks.glowing_basal, 0, 2);
		world.setBlock(i + 14, j, k + 13, NovaCraftBlocks.basal_bricks, 0, 2);
		world.setBlock(i + 15, j, k + 13, NovaCraftBlocks.basal_bricks, 0, 2);
		world.setBlock(i, j, k + 14, NovaCraftBlocks.basal_bricks, 0, 2);
		world.setBlock(i + 1, j, k + 14, NovaCraftBlocks.glowing_basal, 0, 2);
		world.setBlock(i + 2, j, k + 14, NovaCraftBlocks.basal_bricks, 0, 2);
		world.setBlock(i + 3, j, k + 14, NovaCraftBlocks.cracked_basal_bricks, 0, 2);
		world.setBlock(i + 4, j, k + 14, NovaCraftBlocks.basal_bricks, 0, 2);
		world.setBlock(i + 5, j, k + 14, NovaCraftBlocks.basal_bricks, 0, 2);
		world.setBlock(i + 6, j, k + 14, NovaCraftBlocks.basal_bricks, 0, 2);
		world.setBlock(i + 7, j, k + 14, Blocks.lava, 0, 2);
		world.setBlock(i + 8, j, k + 14, NovaCraftBlocks.basal_bricks, 0, 2);
		world.setBlock(i + 9, j, k + 14, NovaCraftBlocks.basal_bricks, 0, 2);
		world.setBlock(i + 10, j, k + 14, NovaCraftBlocks.basal_bricks, 0, 2);
		world.setBlock(i + 11, j, k + 14, Blocks.lava, 0, 2);
		world.setBlock(i + 12, j, k + 14, NovaCraftBlocks.glowing_basal, 0, 2);
		world.setBlock(i + 13, j, k + 14, NovaCraftBlocks.basal_bricks, 0, 2);
		world.setBlock(i + 14, j, k + 14, NovaCraftBlocks.basal_bricks, 0, 2);
		world.setBlock(i + 15, j, k + 14, NovaCraftBlocks.basal_bricks, 0, 2);
		world.setBlock(i, j, k + 15, NovaCraftBlocks.basal_bricks, 0, 2);
		world.setBlock(i + 1, j, k + 15, NovaCraftBlocks.basal_bricks, 0, 2);
		world.setBlock(i + 2, j, k + 15, NovaCraftBlocks.basal_bricks, 0, 2);
		world.setBlock(i + 3, j, k + 15, NovaCraftBlocks.basal_bricks, 0, 2);
		world.setBlock(i + 4, j, k + 15, NovaCraftBlocks.basal_bricks, 0, 2);
		world.setBlock(i + 5, j, k + 15, NovaCraftBlocks.basal_bricks, 0, 2);
		world.setBlock(i + 6, j, k + 15, NovaCraftBlocks.basal_bricks, 0, 2);
		world.setBlock(i + 7, j, k + 15, NovaCraftBlocks.basal_bricks, 0, 2);
		world.setBlock(i + 8, j, k + 15, NovaCraftBlocks.basal_bricks, 0, 2);
		world.setBlock(i + 9, j, k + 15, NovaCraftBlocks.basal_bricks, 0, 2);
		world.setBlock(i + 10, j, k + 15, NovaCraftBlocks.basal_bricks, 0, 2);
		world.setBlock(i + 11, j, k + 15, NovaCraftBlocks.basal_bricks, 0, 2);
		world.setBlock(i + 12, j, k + 15, NovaCraftBlocks.basal_bricks, 0, 2);
		world.setBlock(i + 13, j, k + 15, NovaCraftBlocks.basal_bricks, 0, 2);
		world.setBlock(i + 14, j, k + 15, NovaCraftBlocks.basal_bricks, 0, 2);
		world.setBlock(i + 15, j, k + 15, NovaCraftBlocks.basal_bricks, 0, 2);
		world.setBlock(i, j + 1, k, NovaCraftBlocks.basal_bricks, 0, 2);
		world.setBlock(i + 1, j + 1, k, NovaCraftBlocks.basal_bricks, 0, 2);
		world.setBlock(i + 2, j + 1, k, NovaCraftBlocks.basal_bricks, 0, 2);
		world.setBlock(i + 3, j + 1, k, NovaCraftBlocks.cracked_basal_bricks, 0, 2);
		world.setBlock(i + 4, j + 1, k, NovaCraftBlocks.basal_bricks, 0, 2);
		world.setBlock(i + 5, j + 1, k, NovaCraftBlocks.basal_bricks, 0, 2);
		world.setBlock(i + 6, j + 1, k, NovaCraftBlocks.basal_bricks, 0, 2);
		world.setBlock(i + 7, j + 1, k, NovaCraftBlocks.basal_bricks, 0, 2);
		world.setBlock(i + 8, j + 1, k, NovaCraftBlocks.basal_bricks, 0, 2);
		world.setBlock(i + 9, j + 1, k, NovaCraftBlocks.cracked_basal_bricks, 0, 2);
		world.setBlock(i + 10, j + 1, k, NovaCraftBlocks.glowing_basal, 0, 2);
		world.setBlock(i + 11, j + 1, k, NovaCraftBlocks.basal_bricks, 0, 2);
		world.setBlock(i + 12, j + 1, k, NovaCraftBlocks.cracked_basal_bricks, 0, 2);
		world.setBlock(i + 13, j + 1, k, NovaCraftBlocks.basal_bricks, 0, 2);
		world.setBlock(i + 14, j + 1, k, NovaCraftBlocks.basal_bricks, 0, 2);
		world.setBlock(i + 15, j + 1, k, NovaCraftBlocks.basal_bricks, 0, 2);
		world.setBlock(i, j + 1, k + 1, NovaCraftBlocks.basal_bricks, 0, 2);
		world.setBlock(i + 2, j + 1, k + 1, NovaCraftBlocks.basal_brick_wall, 0, 2);
		world.setBlock(i + 3, j + 1, k + 1, Blocks.air, 0, 2);
		world.setBlock(i + 4, j + 1, k + 1, NovaCraftBlocks.block_of_vanite, 0, 2);
		world.setBlock(i + 5, j + 1, k + 1, NovaCraftBlocks.block_of_vanite, 0, 2);
		world.setBlock(i + 6, j + 1, k + 1, NovaCraftBlocks.block_of_vanite, 0, 2);
		world.setBlock(i + 7, j + 1, k + 1, NovaCraftBlocks.block_of_vanite, 0, 2);
		world.setBlock(i + 8, j + 1, k + 1, NovaCraftBlocks.block_of_vanite, 0, 2);
		world.setBlock(i + 9, j + 1, k + 1, Blocks.air, 0, 2);
		world.setBlock(i + 10, j + 1, k + 1, Blocks.air, 0, 2);
		world.setBlock(i + 11, j + 1, k + 1, Blocks.air, 0, 2);
		world.setBlock(i + 12, j + 1, k + 1, Blocks.air, 0, 2);
		world.setBlock(i + 13, j + 1, k + 1, NovaCraftBlocks.basal_brick_wall, 0, 2);
		world.setBlock(i + 15, j + 1, k + 1, NovaCraftBlocks.cracked_basal_bricks, 0, 2);
		world.setBlock(i, j + 1, k + 2, NovaCraftBlocks.basal_bricks, 0, 2);
		world.setBlock(i + 1, j + 1, k + 2, NovaCraftBlocks.basal_brick_wall, 0, 2);
		world.setBlock(i + 2, j + 1, k + 2, Blocks.air, 0, 2);
		world.setBlock(i + 3, j + 1, k + 2, Blocks.air, 0, 2);
		world.setBlock(i + 4, j + 1, k + 2, Blocks.air, 0, 2);
		world.setBlock(i + 5, j + 1, k + 2, NovaCraftBlocks.block_of_vanite, 0, 2);
		world.setBlock(i + 6, j + 1, k + 2, NovaCraftBlocks.block_of_vanite, 0, 2);
		world.setBlock(i + 7, j + 1, k + 2, NovaCraftBlocks.block_of_vanite, 0, 2);
		world.setBlock(i + 8, j + 1, k + 2, Blocks.air, 0, 2);
		world.setBlock(i + 9, j + 1, k + 2, Blocks.air, 0, 2);
		world.setBlock(i + 10, j + 1, k + 2, Blocks.air, 0, 2);
		world.setBlock(i + 11, j + 1, k + 2, Blocks.air, 0, 2);
		world.setBlock(i + 12, j + 1, k + 2, Blocks.air, 0, 2);
		world.setBlock(i + 13, j + 1, k + 2, Blocks.air, 0, 2);
		world.setBlock(i + 14, j + 1, k + 2, NovaCraftBlocks.basal_brick_wall, 0, 2);
		world.setBlock(i + 15, j + 1, k + 2, NovaCraftBlocks.basal_bricks, 0, 2);
		world.setBlock(i, j + 1, k + 3, NovaCraftBlocks.basal_bricks, 0, 2);
		world.setBlock(i + 1, j + 1, k + 3, Blocks.air, 0, 2);
		world.setBlock(i + 2, j + 1, k + 3, Blocks.air, 0, 2);
		world.setBlock(i + 3, j + 1, k + 3, Blocks.air, 0, 2);
		world.setBlock(i + 4, j + 1, k + 3, Blocks.air, 0, 2);
		world.setBlock(i + 5, j + 1, k + 3, Blocks.air, 0, 2);
		world.setBlock(i + 6, j + 1, k + 3, Blocks.air, 0, 2);
		world.setBlock(i + 7, j + 1, k + 3, Blocks.air, 0, 2);
		world.setBlock(i + 8, j + 1, k + 3, Blocks.air, 0, 2);
		world.setBlock(i + 9, j + 1, k + 3, Blocks.air, 0, 2);
		world.setBlock(i + 10, j + 1, k + 3, Blocks.air, 0, 2);
		world.setBlock(i + 11, j + 1, k + 3, Blocks.air, 0, 2);
		world.setBlock(i + 12, j + 1, k + 3, Blocks.air, 0, 2);
		world.setBlock(i + 13, j + 1, k + 3, Blocks.air, 0, 2);
		world.setBlock(i + 14, j + 1, k + 3, Blocks.air, 0, 2);
		world.setBlock(i + 15, j + 1, k + 3, NovaCraftBlocks.basal_bricks, 0, 2);
		world.setBlock(i, j + 1, k + 4, NovaCraftBlocks.basal_bricks, 0, 2);
		world.setBlock(i + 1, j + 1, k + 4, Blocks.air, 0, 2);
		world.setBlock(i + 2, j + 1, k + 4, Blocks.air, 0, 2);
		world.setBlock(i + 3, j + 1, k + 4, Blocks.air, 0, 2);
		world.setBlock(i + 4, j + 1, k + 4, Blocks.air, 0, 2);
		world.setBlock(i + 5, j + 1, k + 4, Blocks.air, 0, 2);
		world.setBlock(i + 6, j + 1, k + 4, Blocks.air, 0, 2);
		world.setBlock(i + 7, j + 1, k + 4, Blocks.air, 0, 2);
		world.setBlock(i + 8, j + 1, k + 4, Blocks.air, 0, 2);
		world.setBlock(i + 9, j + 1, k + 4, Blocks.air, 0, 2);
		world.setBlock(i + 10, j + 1, k + 4, Blocks.air, 0, 2);
		world.setBlock(i + 11, j + 1, k + 4, Blocks.air, 0, 2);
		world.setBlock(i + 12, j + 1, k + 4, Blocks.air, 0, 2);
		world.setBlock(i + 13, j + 1, k + 4, Blocks.air, 0, 2);
		world.setBlock(i + 14, j + 1, k + 4, Blocks.air, 0, 2);
		world.setBlock(i + 15, j + 1, k + 4, NovaCraftBlocks.glowing_basal, 0, 2);
		world.setBlock(i, j + 1, k + 5, NovaCraftBlocks.cracked_basal_bricks, 0, 2);
		world.setBlock(i + 1, j + 1, k + 5, Blocks.air, 0, 2);
		world.setBlock(i + 2, j + 1, k + 5, Blocks.air, 0, 2);
		world.setBlock(i + 3, j + 1, k + 5, Blocks.air, 0, 2);
		world.setBlock(i + 4, j + 1, k + 5, Blocks.air, 0, 2);
		world.setBlock(i + 5, j + 1, k + 5, Blocks.air, 0, 2);
		world.setBlock(i + 6, j + 1, k + 5, Blocks.air, 0, 2);
		world.setBlock(i + 7, j + 1, k + 5, Blocks.air, 0, 2);
		world.setBlock(i + 8, j + 1, k + 5, Blocks.air, 0, 2);
		world.setBlock(i + 9, j + 1, k + 5, Blocks.air, 0, 2);
		world.setBlock(i + 10, j + 1, k + 5, Blocks.air, 0, 2);
		world.setBlock(i + 11, j + 1, k + 5, Blocks.air, 0, 2);
		world.setBlock(i + 12, j + 1, k + 5, Blocks.air, 0, 2);
		world.setBlock(i + 13, j + 1, k + 5, NovaCraftBlocks.basal_bricks, 0, 2);
		world.setBlock(i + 14, j + 1, k + 5, Blocks.air, 0, 2);
		world.setBlock(i + 15, j + 1, k + 5, NovaCraftBlocks.basal_bricks, 0, 2);
		world.setBlock(i, j + 1, k + 6, NovaCraftBlocks.basal_bricks, 0, 2);
		world.setBlock(i + 2, j + 1, k + 6, Blocks.air, 0, 2);
		world.setBlock(i + 3, j + 1, k + 6, Blocks.air, 0, 2);
		world.setBlock(i + 4, j + 1, k + 6, Blocks.air, 0, 2);
		world.setBlock(i + 5, j + 1, k + 6, Blocks.air, 0, 2);
		world.setBlock(i + 6, j + 1, k + 6, Blocks.air, 0, 2);
		world.setBlock(i + 7, j + 1, k + 6, Blocks.air, 0, 2);
		world.setBlock(i + 8, j + 1, k + 6, Blocks.air, 0, 2);
		world.setBlock(i + 9, j + 1, k + 6, Blocks.air, 0, 2);
		world.setBlock(i + 10, j + 1, k + 6, Blocks.air, 0, 2);
		world.setBlock(i + 11, j + 1, k + 6, Blocks.air, 0, 2);
		world.setBlock(i + 12, j + 1, k + 6, NovaCraftBlocks.basal_bricks, 0, 2);
		world.setBlock(i + 13, j + 1, k + 6, Blocks.lava, 0, 2);
		world.setBlock(i + 14, j + 1, k + 6, NovaCraftBlocks.basal_bricks, 0, 2);
		world.setBlock(i + 15, j + 1, k + 6, NovaCraftBlocks.basal_bricks, 0, 2);
		world.setBlock(i, j + 1, k + 7, NovaCraftBlocks.basal_bricks, 0, 2);
		world.setBlock(i + 2, j + 1, k + 7, Blocks.air, 0, 2);
		world.setBlock(i + 3, j + 1, k + 7, Blocks.air, 0, 2);
		world.setBlock(i + 4, j + 1, k + 7, Blocks.air, 0, 2);
		world.setBlock(i + 5, j + 1, k + 7, Blocks.air, 0, 2);
		world.setBlock(i + 6, j + 1, k + 7, Blocks.air, 0, 2);
		world.setBlock(i + 7, j + 1, k + 7, Blocks.air, 0, 2);
		world.setBlock(i + 8, j + 1, k + 7, Blocks.air, 0, 2);
		world.setBlock(i + 9, j + 1, k + 7, Blocks.air, 0, 2);
		world.setBlock(i + 10, j + 1, k + 7, Blocks.air, 0, 2);
		world.setBlock(i + 11, j + 1, k + 7, NovaCraftBlocks.basal_bricks, 0, 2);
		world.setBlock(i + 12, j + 1, k + 7, Blocks.lava, 0, 2);
		world.setBlock(i + 13, j + 1, k + 7, NovaCraftBlocks.vanite_cauldron, 0, 2);
		world.setBlock(i + 15, j + 1, k + 7, NovaCraftBlocks.basal_bricks, 0, 2);
		world.setBlock(i, j + 1, k + 8, NovaCraftBlocks.basal_bricks, 0, 2);
		world.setBlock(i + 1, j + 1, k + 8, Blocks.air, 0, 2);
		world.setBlock(i + 2, j + 1, k + 8, Blocks.air, 0, 2);
		world.setBlock(i + 3, j + 1, k + 8, Blocks.air, 0, 2);
		world.setBlock(i + 4, j + 1, k + 8, Blocks.air, 0, 2);
		world.setBlock(i + 5, j + 1, k + 8, Blocks.air, 0, 2);
		world.setBlock(i + 6, j + 1, k + 8, Blocks.air, 0, 2);
		world.setBlock(i + 7, j + 1, k + 8, Blocks.air, 0, 2);
		world.setBlock(i + 8, j + 1, k + 8, Blocks.air, 0, 2);
		world.setBlock(i + 9, j + 1, k + 8, Blocks.air, 0, 2);
		world.setBlock(i + 10, j + 1, k + 8, Blocks.air, 0, 2);
		world.setBlock(i + 11, j + 1, k + 8, Blocks.air, 0, 2);
		world.setBlock(i + 12, j + 1, k + 8, NovaCraftBlocks.basal_bricks, 0, 2);
		world.setBlock(i + 13, j + 1, k + 8, Blocks.lava, 0, 2);
		world.setBlock(i + 14, j + 1, k + 8, NovaCraftBlocks.basal_bricks, 0, 2);
		world.setBlock(i + 15, j + 1, k + 8, NovaCraftBlocks.basal_bricks, 0, 2);
		world.setBlock(i, j + 1, k + 9, NovaCraftBlocks.glowing_basal, 0, 2);
		world.setBlock(i + 1, j + 1, k + 9, Blocks.air, 0, 2);
		world.setBlock(i + 2, j + 1, k + 9, Blocks.air, 0, 2);
		world.setBlock(i + 3, j + 1, k + 9, Blocks.air, 0, 2);
		world.setBlock(i + 4, j + 1, k + 9, Blocks.air, 0, 2);
		world.setBlock(i + 5, j + 1, k + 9, Blocks.air, 0, 2);
		world.setBlock(i + 6, j + 1, k + 9, Blocks.air, 0, 2);
		world.setBlock(i + 7, j + 1, k + 9, Blocks.air, 0, 2);
		world.setBlock(i + 8, j + 1, k + 9, Blocks.air, 0, 2);
		world.setBlock(i + 9, j + 1, k + 9, Blocks.air, 0, 2);
		world.setBlock(i + 10, j + 1, k + 9, Blocks.air, 0, 2);
		world.setBlock(i + 11, j + 1, k + 9, Blocks.air, 0, 2);
		world.setBlock(i + 12, j + 1, k + 9, Blocks.air, 0, 2);
		world.setBlock(i + 13, j + 1, k + 9, NovaCraftBlocks.basal_bricks, 0, 2);
		world.setBlock(i + 14, j + 1, k + 9, Blocks.air, 0, 2);
		world.setBlock(i + 15, j + 1, k + 9, NovaCraftBlocks.cracked_basal_bricks, 0, 2);
		world.setBlock(i, j + 1, k + 10, NovaCraftBlocks.basal_bricks, 0, 2);
		world.setBlock(i + 1, j + 1, k + 10, Blocks.cauldron, 0, 2);
		world.setBlock(i + 2, j + 1, k + 10, Blocks.air, 0, 2);
		world.setBlock(i + 3, j + 1, k + 10, Blocks.air, 0, 2);
		world.setBlock(i + 4, j + 1, k + 10, Blocks.air, 0, 2);
		world.setBlock(i + 5, j + 1, k + 10, Blocks.air, 0, 2);
		world.setBlock(i + 6, j + 1, k + 10, Blocks.air, 0, 2);
		world.setBlock(i + 7, j + 1, k + 10, Blocks.air, 0, 2);
		world.setBlock(i + 8, j + 1, k + 10, Blocks.air, 0, 2);
		world.setBlock(i + 9, j + 1, k + 10, Blocks.air, 0, 2);
		world.setBlock(i + 10, j + 1, k + 10, Blocks.air, 0, 2);
		world.setBlock(i + 11, j + 1, k + 10, Blocks.air, 0, 2);
		world.setBlock(i + 12, j + 1, k + 10, Blocks.air, 0, 2);
		world.setBlock(i + 13, j + 1, k + 10, Blocks.air, 0, 2);
		world.setBlock(i + 14, j + 1, k + 10, Blocks.air, 0, 2);
		world.setBlock(i + 15, j + 1, k + 10, NovaCraftBlocks.basal_bricks, 0, 2);
		world.setBlock(i, j + 1, k + 11, NovaCraftBlocks.basal_bricks, 0, 2);
		world.setBlock(i + 1, j + 1, k + 11, Blocks.air, 0, 2);
		world.setBlock(i + 2, j + 1, k + 11, Blocks.air, 0, 2);
		world.setBlock(i + 3, j + 1, k + 11, Blocks.air, 0, 2);
		world.setBlock(i + 4, j + 1, k + 11, Blocks.air, 0, 2);
		world.setBlock(i + 5, j + 1, k + 11, Blocks.air, 0, 2);
		world.setBlock(i + 6, j + 1, k + 11, Blocks.air, 0, 2);
		world.setBlock(i + 7, j + 1, k + 11, Blocks.air, 0, 2);
		world.setBlock(i + 8, j + 1, k + 11, Blocks.air, 0, 2);
		world.setBlock(i + 9, j + 1, k + 11, Blocks.air, 0, 2);
		world.setBlock(i + 10, j + 1, k + 11, Blocks.air, 0, 2);
		world.setBlock(i + 11, j + 1, k + 11, Blocks.air, 0, 2);
		world.setBlock(i + 12, j + 1, k + 11, Blocks.air, 0, 2);
		world.setBlock(i + 13, j + 1, k + 11, Blocks.air, 0, 2);
		world.setBlock(i + 14, j + 1, k + 11, Blocks.air, 0, 2);
		world.setBlock(i + 15, j + 1, k + 11, NovaCraftBlocks.glowing_basal, 0, 2);
		world.setBlock(i, j + 1, k + 12, NovaCraftBlocks.basal_bricks, 0, 2);
		world.setBlock(i + 1, j + 1, k + 12, Blocks.air, 0, 2);
		world.setBlock(i + 2, j + 1, k + 12, Blocks.air, 0, 2);
		world.setBlock(i + 3, j + 1, k + 12, Blocks.air, 0, 2);
		world.setBlock(i + 4, j + 1, k + 12, Blocks.air, 0, 2);
		world.setBlock(i + 5, j + 1, k + 12, Blocks.air, 0, 2);
		world.setBlock(i + 6, j + 1, k + 12, Blocks.air, 0, 2);
		world.setBlock(i + 7, j + 1, k + 12, Blocks.air, 0, 2);
		world.setBlock(i + 8, j + 1, k + 12, Blocks.air, 0, 2);
		world.setBlock(i + 9, j + 1, k + 12, Blocks.air, 0, 2);
		world.setBlock(i + 10, j + 1, k + 12, Blocks.air, 0, 2);
		world.setBlock(i + 11, j + 1, k + 12, Blocks.air, 0, 2);
		world.setBlock(i + 12, j + 1, k + 12, Blocks.air, 0, 2);
		world.setBlock(i + 13, j + 1, k + 12, Blocks.air, 0, 2);
		world.setBlock(i + 14, j + 1, k + 12, Blocks.air, 0, 2);
		world.setBlock(i + 15, j + 1, k + 12, NovaCraftBlocks.basal_bricks, 0, 2);
		world.setBlock(i, j + 1, k + 13, NovaCraftBlocks.basal_bricks, 0, 2);
		world.setBlock(i + 1, j + 1, k + 13, NovaCraftBlocks.basal_brick_wall, 0, 2);
		world.setBlock(i + 2, j + 1, k + 13, Blocks.air, 0, 2);
		world.setBlock(i + 3, j + 1, k + 13, Blocks.air, 0, 2);
		world.setBlock(i + 4, j + 1, k + 13, Blocks.air, 0, 2);
		world.setBlock(i + 5, j + 1, k + 13, Blocks.air, 0, 2);
		world.setBlock(i + 6, j + 1, k + 13, Blocks.air, 0, 2);
		world.setBlock(i + 7, j + 1, k + 13, Blocks.air, 0, 2);
		world.setBlock(i + 8, j + 1, k + 13, Blocks.air, 0, 2);
		world.setBlock(i + 9, j + 1, k + 13, Blocks.air, 0, 2);
		world.setBlock(i + 10, j + 1, k + 13, Blocks.air, 0, 2);
		world.setBlock(i + 11, j + 1, k + 13, Blocks.air, 0, 2);
		world.setBlock(i + 12, j + 1, k + 13, Blocks.air, 0, 2);
		world.setBlock(i + 13, j + 1, k + 13, Blocks.air, 0, 2);
		world.setBlock(i + 14, j + 1, k + 13, NovaCraftBlocks.basal_brick_wall, 0, 2);
		world.setBlock(i + 15, j + 1, k + 13, NovaCraftBlocks.cracked_basal_bricks, 0, 2);
		world.setBlock(i, j + 1, k + 14, NovaCraftBlocks.basal_bricks, 0, 2);
		world.setBlock(i + 2, j + 1, k + 14, NovaCraftBlocks.basal_brick_wall, 0, 2);
		world.setBlock(i + 3, j + 1, k + 14, Blocks.air, 0, 2);
		world.setBlock(i + 4, j + 1, k + 14, Blocks.air, 0, 2);
		world.setBlock(i + 5, j + 1, k + 14, Blocks.cauldron, 0, 2);
		world.setBlock(i + 6, j + 1, k + 14, Blocks.air, 0, 2);
		world.setBlock(i + 7, j + 1, k + 14, Blocks.air, 0, 2);
		world.setBlock(i + 8, j + 1, k + 14, Blocks.air, 0, 2);
		world.setBlock(i + 9, j + 1, k + 14, Blocks.cauldron, 0, 2);
		world.setBlock(i + 10, j + 1, k + 14, Blocks.cauldron, 0, 2);
		world.setBlock(i + 11, j + 1, k + 14, Blocks.air, 0, 2);
		world.setBlock(i + 12, j + 1, k + 14, Blocks.air, 0, 2);
		world.setBlock(i + 13, j + 1, k + 14, NovaCraftBlocks.basal_brick_wall, 0, 2);
		world.setBlock(i + 15, j + 1, k + 14, NovaCraftBlocks.basal_bricks, 0, 2);
		world.setBlock(i, j + 1, k + 15, NovaCraftBlocks.basal_bricks, 0, 2);
		world.setBlock(i + 1, j + 1, k + 15, NovaCraftBlocks.basal_bricks, 0, 2);
		world.setBlock(i + 2, j + 1, k + 15, NovaCraftBlocks.basal_bricks, 0, 2);
		world.setBlock(i + 3, j + 1, k + 15, NovaCraftBlocks.basal_bricks, 0, 2);
		world.setBlock(i + 4, j + 1, k + 15, NovaCraftBlocks.basal_bricks, 0, 2);
		world.setBlock(i + 5, j + 1, k + 15, NovaCraftBlocks.basal_bricks, 0, 2);
		world.setBlock(i + 6, j + 1, k + 15, NovaCraftBlocks.basal_bricks, 0, 2);
		world.setBlock(i + 7, j + 1, k + 15, NovaCraftBlocks.basal_bricks, 0, 2);
		world.setBlock(i + 8, j + 1, k + 15, NovaCraftBlocks.glowing_basal, 0, 2);
		world.setBlock(i + 9, j + 1, k + 15, NovaCraftBlocks.basal_bricks, 0, 2);
		world.setBlock(i + 10, j + 1, k + 15, NovaCraftBlocks.basal_bricks, 0, 2);
		world.setBlock(i + 11, j + 1, k + 15, NovaCraftBlocks.basal_bricks, 0, 2);
		world.setBlock(i + 12, j + 1, k + 15, NovaCraftBlocks.basal_bricks, 0, 2);
		world.setBlock(i + 13, j + 1, k + 15, NovaCraftBlocks.basal_bricks, 0, 2);
		world.setBlock(i + 14, j + 1, k + 15, NovaCraftBlocks.basal_bricks, 0, 2);
		world.setBlock(i + 15, j + 1, k + 15, NovaCraftBlocks.basal_bricks, 0, 2);
		world.setBlock(i, j + 2, k, NovaCraftBlocks.basal_bricks, 0, 2);
		world.setBlock(i + 1, j + 2, k, NovaCraftBlocks.basal_bricks, 0, 2);
		world.setBlock(i + 2, j + 2, k, NovaCraftBlocks.cracked_basal_bricks, 0, 2);
		world.setBlock(i + 3, j + 2, k, NovaCraftBlocks.glowing_basal, 0, 2);
		world.setBlock(i + 4, j + 2, k, NovaCraftBlocks.glowing_basal, 0, 2);
		world.setBlock(i + 5, j + 2, k, NovaCraftBlocks.basal_bricks, 0, 2);
		world.setBlock(i + 6, j + 2, k, NovaCraftBlocks.basal_bricks, 0, 2);
		world.setBlock(i + 7, j + 2, k, NovaCraftBlocks.basal_bricks, 0, 2);
		world.setBlock(i + 8, j + 2, k, NovaCraftBlocks.basal_bricks, 0, 2);
		world.setBlock(i + 9, j + 2, k, NovaCraftBlocks.glowing_basal, 0, 2);
		world.setBlock(i + 10, j + 2, k, NovaCraftBlocks.basal_bricks, 0, 2);
		world.setBlock(i + 11, j + 2, k, NovaCraftBlocks.basal_bricks, 0, 2);
		world.setBlock(i + 12, j + 2, k, NovaCraftBlocks.basal_bricks, 0, 2);
		world.setBlock(i + 13, j + 2, k, NovaCraftBlocks.basal_bricks, 0, 2);
		world.setBlock(i + 14, j + 2, k, NovaCraftBlocks.basal_bricks, 0, 2);
		world.setBlock(i + 15, j + 2, k, NovaCraftBlocks.basal_bricks, 0, 2);
		world.setBlock(i, j + 2, k + 1, NovaCraftBlocks.basal_bricks, 0, 2);
		world.setBlock(i + 2, j + 2, k + 1, NovaCraftBlocks.basal_brick_wall, 0, 2);
		world.setBlock(i + 3, j + 2, k + 1, Blocks.air, 0, 2);
		world.setBlock(i + 4, j + 2, k + 1, Blocks.air, 0, 2);
		world.setBlock(i + 5, j + 2, k + 1, NovaCraftBlocks.block_of_vanite, 0, 2);
		world.setBlock(i + 6, j + 2, k + 1, NovaCraftBlocks.block_of_vanite, 0, 2);
		world.setBlock(i + 7, j + 2, k + 1, Blocks.air, 0, 2);
		world.setBlock(i + 8, j + 2, k + 1, Blocks.air, 0, 2);
		world.setBlock(i + 9, j + 2, k + 1, Blocks.air, 0, 2);
		world.setBlock(i + 10, j + 2, k + 1, Blocks.air, 0, 2);
		world.setBlock(i + 11, j + 2, k + 1, Blocks.air, 0, 2);
		world.setBlock(i + 12, j + 2, k + 1, Blocks.air, 0, 2);
		world.setBlock(i + 13, j + 2, k + 1, NovaCraftBlocks.basal_brick_wall, 0, 2);
		world.setBlock(i + 15, j + 2, k + 1, NovaCraftBlocks.basal_bricks, 0, 2);
		world.setBlock(i, j + 2, k + 2, NovaCraftBlocks.basal_bricks, 0, 2);
		world.setBlock(i + 1, j + 2, k + 2, NovaCraftBlocks.basal_brick_wall, 0, 2);
		world.setBlock(i + 2, j + 2, k + 2, Blocks.air, 0, 2);
		world.setBlock(i + 3, j + 2, k + 2, Blocks.air, 0, 2);
		world.setBlock(i + 4, j + 2, k + 2, Blocks.air, 0, 2);
		world.setBlock(i + 5, j + 2, k + 2, Blocks.air, 0, 2);
		world.setBlock(i + 6, j + 2, k + 2, Blocks.air, 0, 2);
		world.setBlock(i + 7, j + 2, k + 2, Blocks.air, 0, 2);
		world.setBlock(i + 8, j + 2, k + 2, Blocks.air, 0, 2);
		world.setBlock(i + 9, j + 2, k + 2, Blocks.air, 0, 2);
		world.setBlock(i + 10, j + 2, k + 2, Blocks.air, 0, 2);
		world.setBlock(i + 11, j + 2, k + 2, Blocks.air, 0, 2);
		world.setBlock(i + 12, j + 2, k + 2, Blocks.air, 0, 2);
		world.setBlock(i + 13, j + 2, k + 2, Blocks.air, 0, 2);
		world.setBlock(i + 14, j + 2, k + 2, NovaCraftBlocks.basal_brick_wall, 0, 2);
		world.setBlock(i + 15, j + 2, k + 2, NovaCraftBlocks.basal_bricks, 0, 2);
		world.setBlock(i, j + 2, k + 3, NovaCraftBlocks.cracked_basal_bricks, 0, 2);
		world.setBlock(i + 1, j + 2, k + 3, Blocks.air, 0, 2);
		world.setBlock(i + 2, j + 2, k + 3, Blocks.air, 0, 2);
		world.setBlock(i + 3, j + 2, k + 3, Blocks.air, 0, 2);
		world.setBlock(i + 4, j + 2, k + 3, Blocks.air, 0, 2);
		world.setBlock(i + 5, j + 2, k + 3, Blocks.air, 0, 2);
		world.setBlock(i + 6, j + 2, k + 3, Blocks.air, 0, 2);
		world.setBlock(i + 7, j + 2, k + 3, Blocks.air, 0, 2);
		world.setBlock(i + 8, j + 2, k + 3, Blocks.air, 0, 2);
		world.setBlock(i + 9, j + 2, k + 3, Blocks.air, 0, 2);
		world.setBlock(i + 10, j + 2, k + 3, Blocks.air, 0, 2);
		world.setBlock(i + 11, j + 2, k + 3, Blocks.air, 0, 2);
		world.setBlock(i + 12, j + 2, k + 3, Blocks.air, 0, 2);
		world.setBlock(i + 13, j + 2, k + 3, Blocks.air, 0, 2);
		world.setBlock(i + 14, j + 2, k + 3, Blocks.air, 0, 2);
		world.setBlock(i + 15, j + 2, k + 3, NovaCraftBlocks.basal_bricks, 0, 2);
		world.setBlock(i, j + 2, k + 4, NovaCraftBlocks.basal_bricks, 0, 2);
		world.setBlock(i + 1, j + 2, k + 4, Blocks.air, 0, 2);
		world.setBlock(i + 2, j + 2, k + 4, Blocks.air, 0, 2);
		world.setBlock(i + 3, j + 2, k + 4, Blocks.air, 0, 2);
		world.setBlock(i + 4, j + 2, k + 4, Blocks.air, 0, 2);
		world.setBlock(i + 5, j + 2, k + 4, Blocks.air, 0, 2);
		world.setBlock(i + 6, j + 2, k + 4, Blocks.air, 0, 2);
		world.setBlock(i + 7, j + 2, k + 4, Blocks.air, 0, 2);
		world.setBlock(i + 8, j + 2, k + 4, Blocks.air, 0, 2);
		world.setBlock(i + 9, j + 2, k + 4, Blocks.air, 0, 2);
		world.setBlock(i + 10, j + 2, k + 4, Blocks.air, 0, 2);
		world.setBlock(i + 11, j + 2, k + 4, Blocks.air, 0, 2);
		world.setBlock(i + 12, j + 2, k + 4, Blocks.air, 0, 2);
		world.setBlock(i + 13, j + 2, k + 4, Blocks.air, 0, 2);
		world.setBlock(i + 14, j + 2, k + 4, Blocks.air, 0, 2);
		world.setBlock(i + 15, j + 2, k + 4, NovaCraftBlocks.cracked_basal_bricks, 0, 2);
		world.setBlock(i, j + 2, k + 5, NovaCraftBlocks.basal_bricks, 0, 2);
		world.setBlock(i + 1, j + 2, k + 5, Blocks.air, 0, 2);
		world.setBlock(i + 2, j + 2, k + 5, Blocks.air, 0, 2);
		world.setBlock(i + 3, j + 2, k + 5, Blocks.air, 0, 2);
		world.setBlock(i + 4, j + 2, k + 5, Blocks.air, 0, 2);
		world.setBlock(i + 5, j + 2, k + 5, Blocks.air, 0, 2);
		world.setBlock(i + 6, j + 2, k + 5, Blocks.air, 0, 2);
		world.setBlock(i + 7, j + 2, k + 5, Blocks.air, 0, 2);
		world.setBlock(i + 8, j + 2, k + 5, Blocks.air, 0, 2);
		world.setBlock(i + 9, j + 2, k + 5, Blocks.air, 0, 2);
		world.setBlock(i + 10, j + 2, k + 5, Blocks.air, 0, 2);
		world.setBlock(i + 11, j + 2, k + 5, Blocks.air, 0, 2);
		world.setBlock(i + 12, j + 2, k + 5, Blocks.air, 0, 2);
		world.setBlock(i + 13, j + 2, k + 5, Blocks.air, 0, 2);
		world.setBlock(i + 14, j + 2, k + 5, Blocks.air, 0, 2);
		world.setBlock(i + 15, j + 2, k + 5, NovaCraftBlocks.basal_bricks, 0, 2);
		world.setBlock(i, j + 2, k + 6, NovaCraftBlocks.cracked_basal_bricks, 0, 2);
		world.setBlock(i + 1, j + 2, k + 6, Blocks.air, 0, 2);
		world.setBlock(i + 2, j + 2, k + 6, Blocks.air, 0, 2);
		world.setBlock(i + 3, j + 2, k + 6, Blocks.air, 0, 2);
		world.setBlock(i + 4, j + 2, k + 6, Blocks.air, 0, 2);
		world.setBlock(i + 5, j + 2, k + 6, Blocks.air, 0, 2);
		world.setBlock(i + 6, j + 2, k + 6, Blocks.air, 0, 2);
		world.setBlock(i + 7, j + 2, k + 6, Blocks.air, 0, 2);
		world.setBlock(i + 8, j + 2, k + 6, Blocks.air, 0, 2);
		world.setBlock(i + 9, j + 2, k + 6, Blocks.air, 0, 2);
		world.setBlock(i + 10, j + 2, k + 6, Blocks.air, 0, 2);
		world.setBlock(i + 11, j + 2, k + 6, Blocks.air, 0, 2);
		world.setBlock(i + 12, j + 2, k + 6, Blocks.air, 0, 2);
		world.setBlock(i + 13, j + 2, k + 6, Blocks.air, 0, 2);
		world.setBlock(i + 15, j + 2, k + 6, NovaCraftBlocks.basal_bricks, 0, 2);
		world.setBlock(i, j + 2, k + 7, NovaCraftBlocks.glowing_basal, 0, 2);
		world.setBlock(i + 1, j + 2, k + 7, Blocks.air, 0, 2);
		world.setBlock(i + 2, j + 2, k + 7, Blocks.air, 0, 2);
		world.setBlock(i + 3, j + 2, k + 7, Blocks.air, 0, 2);
		world.setBlock(i + 4, j + 2, k + 7, Blocks.air, 0, 2);
		world.setBlock(i + 5, j + 2, k + 7, Blocks.air, 0, 2);
		world.setBlock(i + 6, j + 2, k + 7, Blocks.air, 0, 2);
		world.setBlock(i + 7, j + 2, k + 7, Blocks.air, 0, 2);
		world.setBlock(i + 8, j + 2, k + 7, Blocks.air, 0, 2);
		world.setBlock(i + 9, j + 2, k + 7, Blocks.air, 0, 2);
		world.setBlock(i + 10, j + 2, k + 7, Blocks.air, 0, 2);
		world.setBlock(i + 11, j + 2, k + 7, Blocks.air, 0, 2);
		world.setBlock(i + 12, j + 2, k + 7, Blocks.air, 0, 2);
		world.setBlock(i + 13, j + 2, k + 7, Blocks.air, 0, 2);
		world.setBlock(i + 14, j + 2, k + 7, Blocks.air, 0, 2);
		world.setBlock(i + 15, j + 2, k + 7, NovaCraftBlocks.basal_bricks, 0, 2);
		world.setBlock(i, j + 2, k + 8, NovaCraftBlocks.basal_bricks, 0, 2);
		world.setBlock(i + 1, j + 2, k + 8, Blocks.air, 0, 2);
		world.setBlock(i + 2, j + 2, k + 8, Blocks.air, 0, 2);
		world.setBlock(i + 3, j + 2, k + 8, Blocks.air, 0, 2);
		world.setBlock(i + 4, j + 2, k + 8, Blocks.air, 0, 2);
		world.setBlock(i + 5, j + 2, k + 8, Blocks.air, 0, 2);
		world.setBlock(i + 6, j + 2, k + 8, Blocks.air, 0, 2);
		world.setBlock(i + 7, j + 2, k + 8, Blocks.air, 0, 2);
		world.setBlock(i + 8, j + 2, k + 8, Blocks.air, 0, 2);
		world.setBlock(i + 9, j + 2, k + 8, Blocks.air, 0, 2);
		world.setBlock(i + 10, j + 2, k + 8, Blocks.air, 0, 2);
		world.setBlock(i + 11, j + 2, k + 8, Blocks.air, 0, 2);
		world.setBlock(i + 12, j + 2, k + 8, Blocks.air, 0, 2);
		world.setBlock(i + 13, j + 2, k + 8, Blocks.air, 0, 2);
		world.setBlock(i + 14, j + 2, k + 8, Blocks.air, 0, 2);
		world.setBlock(i + 15, j + 2, k + 8, NovaCraftBlocks.basal_bricks, 0, 2);
		world.setBlock(i, j + 2, k + 9, NovaCraftBlocks.basal_bricks, 0, 2);
		world.setBlock(i + 1, j + 2, k + 9, Blocks.air, 0, 2);
		world.setBlock(i + 2, j + 2, k + 9, Blocks.air, 0, 2);
		world.setBlock(i + 3, j + 2, k + 9, Blocks.air, 0, 2);
		world.setBlock(i + 4, j + 2, k + 9, Blocks.air, 0, 2);
		world.setBlock(i + 5, j + 2, k + 9, Blocks.air, 0, 2);
		world.setBlock(i + 6, j + 2, k + 9, Blocks.air, 0, 2);
		world.setBlock(i + 7, j + 2, k + 9, Blocks.air, 0, 2);
		world.setBlock(i + 8, j + 2, k + 9, Blocks.air, 0, 2);
		world.setBlock(i + 9, j + 2, k + 9, Blocks.air, 0, 2);
		world.setBlock(i + 10, j + 2, k + 9, Blocks.air, 0, 2);
		world.setBlock(i + 11, j + 2, k + 9, Blocks.air, 0, 2);
		world.setBlock(i + 12, j + 2, k + 9, Blocks.air, 0, 2);
		world.setBlock(i + 13, j + 2, k + 9, Blocks.air, 0, 2);
		world.setBlock(i + 14, j + 2, k + 9, Blocks.air, 0, 2);
		world.setBlock(i + 15, j + 2, k + 9, NovaCraftBlocks.basal_bricks, 0, 2);
		world.setBlock(i, j + 2, k + 10, NovaCraftBlocks.cracked_basal_bricks, 0, 2);
		world.setBlock(i + 1, j + 2, k + 10, Blocks.air, 0, 2);
		world.setBlock(i + 2, j + 2, k + 10, Blocks.air, 0, 2);
		world.setBlock(i + 3, j + 2, k + 10, Blocks.air, 0, 2);
		world.setBlock(i + 4, j + 2, k + 10, Blocks.air, 0, 2);
		world.setBlock(i + 5, j + 2, k + 10, Blocks.air, 0, 2);
		world.setBlock(i + 6, j + 2, k + 10, Blocks.air, 0, 2);
		world.setBlock(i + 7, j + 2, k + 10, Blocks.air, 0, 2);
		world.setBlock(i + 8, j + 2, k + 10, Blocks.air, 0, 2);
		world.setBlock(i + 9, j + 2, k + 10, Blocks.air, 0, 2);
		world.setBlock(i + 10, j + 2, k + 10, Blocks.air, 0, 2);
		world.setBlock(i + 11, j + 2, k + 10, Blocks.air, 0, 2);
		world.setBlock(i + 12, j + 2, k + 10, Blocks.air, 0, 2);
		world.setBlock(i + 13, j + 2, k + 10, Blocks.air, 0, 2);
		world.setBlock(i + 14, j + 2, k + 10, Blocks.air, 0, 2);
		world.setBlock(i + 15, j + 2, k + 10, NovaCraftBlocks.glowing_basal, 0, 2);
		world.setBlock(i, j + 2, k + 11, NovaCraftBlocks.glowing_basal, 0, 2);
		world.setBlock(i + 1, j + 2, k + 11, Blocks.air, 0, 2);
		world.setBlock(i + 2, j + 2, k + 11, Blocks.air, 0, 2);
		world.setBlock(i + 3, j + 2, k + 11, Blocks.air, 0, 2);
		world.setBlock(i + 4, j + 2, k + 11, Blocks.air, 0, 2);
		world.setBlock(i + 5, j + 2, k + 11, Blocks.air, 0, 2);
		world.setBlock(i + 6, j + 2, k + 11, Blocks.air, 0, 2);
		world.setBlock(i + 7, j + 2, k + 11, Blocks.air, 0, 2);
		world.setBlock(i + 8, j + 2, k + 11, Blocks.air, 0, 2);
		world.setBlock(i + 9, j + 2, k + 11, Blocks.air, 0, 2);
		world.setBlock(i + 10, j + 2, k + 11, Blocks.air, 0, 2);
		world.setBlock(i + 11, j + 2, k + 11, Blocks.air, 0, 2);
		world.setBlock(i + 12, j + 2, k + 11, Blocks.air, 0, 2);
		world.setBlock(i + 13, j + 2, k + 11, Blocks.air, 0, 2);
		world.setBlock(i + 14, j + 2, k + 11, Blocks.air, 0, 2);
		world.setBlock(i + 15, j + 2, k + 11, NovaCraftBlocks.basal_bricks, 0, 2);
		world.setBlock(i, j + 2, k + 12, NovaCraftBlocks.basal_bricks, 0, 2);
		world.setBlock(i + 1, j + 2, k + 12, Blocks.air, 0, 2);
		world.setBlock(i + 2, j + 2, k + 12, Blocks.air, 0, 2);
		world.setBlock(i + 3, j + 2, k + 12, Blocks.air, 0, 2);
		world.setBlock(i + 4, j + 2, k + 12, Blocks.air, 0, 2);
		world.setBlock(i + 5, j + 2, k + 12, Blocks.air, 0, 2);
		world.setBlock(i + 6, j + 2, k + 12, Blocks.air, 0, 2);
		world.setBlock(i + 7, j + 2, k + 12, Blocks.air, 0, 2);
		world.setBlock(i + 8, j + 2, k + 12, Blocks.air, 0, 2);
		world.setBlock(i + 9, j + 2, k + 12, Blocks.air, 0, 2);
		world.setBlock(i + 10, j + 2, k + 12, Blocks.air, 0, 2);
		world.setBlock(i + 11, j + 2, k + 12, Blocks.air, 0, 2);
		world.setBlock(i + 12, j + 2, k + 12, Blocks.air, 0, 2);
		world.setBlock(i + 13, j + 2, k + 12, Blocks.air, 0, 2);
		world.setBlock(i + 14, j + 2, k + 12, Blocks.air, 0, 2);
		world.setBlock(i + 15, j + 2, k + 12, NovaCraftBlocks.cracked_basal_bricks, 0, 2);
		world.setBlock(i, j + 2, k + 13, NovaCraftBlocks.basal_bricks, 0, 2);
		world.setBlock(i + 1, j + 2, k + 13, NovaCraftBlocks.basal_brick_wall, 0, 2);
		world.setBlock(i + 2, j + 2, k + 13, Blocks.air, 0, 2);
		world.setBlock(i + 3, j + 2, k + 13, Blocks.air, 0, 2);
		world.setBlock(i + 4, j + 2, k + 13, Blocks.air, 0, 2);
		world.setBlock(i + 5, j + 2, k + 13, Blocks.air, 0, 2);
		world.setBlock(i + 6, j + 2, k + 13, Blocks.air, 0, 2);
		world.setBlock(i + 7, j + 2, k + 13, Blocks.air, 0, 2);
		world.setBlock(i + 8, j + 2, k + 13, Blocks.air, 0, 2);
		world.setBlock(i + 9, j + 2, k + 13, Blocks.air, 0, 2);
		world.setBlock(i + 10, j + 2, k + 13, Blocks.air, 0, 2);
		world.setBlock(i + 11, j + 2, k + 13, Blocks.air, 0, 2);
		world.setBlock(i + 12, j + 2, k + 13, Blocks.air, 0, 2);
		world.setBlock(i + 13, j + 2, k + 13, Blocks.air, 0, 2);
		world.setBlock(i + 14, j + 2, k + 13, NovaCraftBlocks.basal_brick_wall, 0, 2);
		world.setBlock(i + 15, j + 2, k + 13, NovaCraftBlocks.basal_bricks, 0, 2);
		world.setBlock(i, j + 2, k + 14, NovaCraftBlocks.basal_bricks, 0, 2);
		world.setBlock(i + 2, j + 2, k + 14, NovaCraftBlocks.basal_brick_wall, 0, 2);
		world.setBlock(i + 3, j + 2, k + 14, Blocks.air, 0, 2);
		world.setBlock(i + 4, j + 2, k + 14, Blocks.air, 0, 2);
		world.setBlock(i + 5, j + 2, k + 14, Blocks.air, 0, 2);
		world.setBlock(i + 6, j + 2, k + 14, Blocks.air, 0, 2);
		world.setBlock(i + 7, j + 2, k + 14, Blocks.air, 0, 2);
		world.setBlock(i + 8, j + 2, k + 14, Blocks.air, 0, 2);
		world.setBlock(i + 9, j + 2, k + 14, Blocks.air, 0, 2);
		world.setBlock(i + 10, j + 2, k + 14, Blocks.air, 0, 2);
		world.setBlock(i + 11, j + 2, k + 14, Blocks.air, 0, 2);
		world.setBlock(i + 12, j + 2, k + 14, Blocks.air, 0, 2);
		world.setBlock(i + 13, j + 2, k + 14, NovaCraftBlocks.basal_brick_wall, 0, 2);
		world.setBlock(i + 15, j + 2, k + 14, NovaCraftBlocks.basal_bricks, 0, 2);
		world.setBlock(i, j + 2, k + 15, NovaCraftBlocks.basal_bricks, 0, 2);
		world.setBlock(i + 1, j + 2, k + 15, NovaCraftBlocks.basal_bricks, 0, 2);
		world.setBlock(i + 2, j + 2, k + 15, NovaCraftBlocks.basal_bricks, 0, 2);
		world.setBlock(i + 3, j + 2, k + 15, NovaCraftBlocks.glowing_basal, 0, 2);
		world.setBlock(i + 4, j + 2, k + 15, NovaCraftBlocks.basal_bricks, 0, 2);
		world.setBlock(i + 5, j + 2, k + 15, NovaCraftBlocks.basal_bricks, 0, 2);
		world.setBlock(i + 6, j + 2, k + 15, NovaCraftBlocks.cracked_basal_bricks, 0, 2);
		world.setBlock(i + 7, j + 2, k + 15, NovaCraftBlocks.basal_bricks, 0, 2);
		world.setBlock(i + 8, j + 2, k + 15, NovaCraftBlocks.cracked_basal_bricks, 0, 2);
		world.setBlock(i + 9, j + 2, k + 15, NovaCraftBlocks.basal_bricks, 0, 2);
		world.setBlock(i + 10, j + 2, k + 15, NovaCraftBlocks.glowing_basal, 0, 2);
		world.setBlock(i + 11, j + 2, k + 15, NovaCraftBlocks.basal_bricks, 0, 2);
		world.setBlock(i + 12, j + 2, k + 15, NovaCraftBlocks.glowing_basal, 0, 2);
		world.setBlock(i + 13, j + 2, k + 15, NovaCraftBlocks.basal_bricks, 0, 2);
		world.setBlock(i + 14, j + 2, k + 15, NovaCraftBlocks.basal_bricks, 0, 2);
		world.setBlock(i + 15, j + 2, k + 15, NovaCraftBlocks.basal_bricks, 0, 2);
		world.setBlock(i, j + 3, k, NovaCraftBlocks.basal_bricks, 0, 2);
		world.setBlock(i + 1, j + 3, k, NovaCraftBlocks.basal_bricks, 0, 2);
		world.setBlock(i + 2, j + 3, k, NovaCraftBlocks.basal_bricks, 0, 2);
		world.setBlock(i + 3, j + 3, k, NovaCraftBlocks.basal_bricks, 0, 2);
		world.setBlock(i + 4, j + 3, k, NovaCraftBlocks.glowing_basal, 0, 2);
		world.setBlock(i + 5, j + 3, k, NovaCraftBlocks.basal_bricks, 0, 2);
		world.setBlock(i + 6, j + 3, k, NovaCraftBlocks.glowing_basal, 0, 2);
		world.setBlock(i + 7, j + 3, k, NovaCraftBlocks.cracked_basal_bricks, 0, 2);
		world.setBlock(i + 8, j + 3, k, NovaCraftBlocks.basal_bricks, 0, 2);
		world.setBlock(i + 9, j + 3, k, NovaCraftBlocks.basal_bricks, 0, 2);
		world.setBlock(i + 10, j + 3, k, NovaCraftBlocks.cracked_basal_bricks, 0, 2);
		world.setBlock(i + 11, j + 3, k, NovaCraftBlocks.cracked_basal_bricks, 0, 2);
		world.setBlock(i + 12, j + 3, k, NovaCraftBlocks.basal_bricks, 0, 2);
		world.setBlock(i + 13, j + 3, k, NovaCraftBlocks.basal_bricks, 0, 2);
		world.setBlock(i + 14, j + 3, k, NovaCraftBlocks.basal_bricks, 0, 2);
		world.setBlock(i + 15, j + 3, k, NovaCraftBlocks.basal_bricks, 0, 2);
		world.setBlock(i, j + 3, k + 1, NovaCraftBlocks.basal_bricks, 0, 2);
		world.setBlock(i + 2, j + 3, k + 1, NovaCraftBlocks.basal_brick_wall, 0, 2);
		world.setBlock(i + 3, j + 3, k + 1, Blocks.air, 0, 2);
		world.setBlock(i + 4, j + 3, k + 1, Blocks.air, 0, 2);
		world.setBlock(i + 5, j + 3, k + 1, Blocks.air, 0, 2);
		world.setBlock(i + 6, j + 3, k + 1, Blocks.air, 0, 2);
		world.setBlock(i + 7, j + 3, k + 1, Blocks.air, 0, 2);
		world.setBlock(i + 8, j + 3, k + 1, Blocks.air, 0, 2);
		world.setBlock(i + 9, j + 3, k + 1, Blocks.air, 0, 2);
		world.setBlock(i + 10, j + 3, k + 1, Blocks.air, 0, 2);
		world.setBlock(i + 11, j + 3, k + 1, Blocks.air, 0, 2);
		world.setBlock(i + 12, j + 3, k + 1, Blocks.air, 0, 2);
		world.setBlock(i + 13, j + 3, k + 1, NovaCraftBlocks.basal_brick_wall, 0, 2);
		world.setBlock(i + 15, j + 3, k + 1, NovaCraftBlocks.basal_bricks, 0, 2);
		world.setBlock(i, j + 3, k + 2, NovaCraftBlocks.basal_bricks, 0, 2);
		world.setBlock(i + 1, j + 3, k + 2, NovaCraftBlocks.basal_brick_wall, 0, 2);
		world.setBlock(i + 2, j + 3, k + 2, Blocks.air, 0, 2);
		world.setBlock(i + 3, j + 3, k + 2, Blocks.air, 0, 2);
		world.setBlock(i + 4, j + 3, k + 2, Blocks.air, 0, 2);
		world.setBlock(i + 5, j + 3, k + 2, Blocks.air, 0, 2);
		world.setBlock(i + 6, j + 3, k + 2, Blocks.air, 0, 2);
		world.setBlock(i + 7, j + 3, k + 2, Blocks.air, 0, 2);
		world.setBlock(i + 8, j + 3, k + 2, Blocks.air, 0, 2);
		world.setBlock(i + 9, j + 3, k + 2, Blocks.air, 0, 2);
		world.setBlock(i + 10, j + 3, k + 2, Blocks.air, 0, 2);
		world.setBlock(i + 11, j + 3, k + 2, Blocks.air, 0, 2);
		world.setBlock(i + 12, j + 3, k + 2, Blocks.air, 0, 2);
		world.setBlock(i + 13, j + 3, k + 2, Blocks.air, 0, 2);
		world.setBlock(i + 14, j + 3, k + 2, NovaCraftBlocks.basal_brick_wall, 0, 2);
		world.setBlock(i + 15, j + 3, k + 2, NovaCraftBlocks.glowing_basal, 0, 2);
		world.setBlock(i, j + 3, k + 3, NovaCraftBlocks.glowing_basal, 0, 2);
		world.setBlock(i + 1, j + 3, k + 3, Blocks.air, 0, 2);
		world.setBlock(i + 2, j + 3, k + 3, Blocks.air, 0, 2);
		world.setBlock(i + 3, j + 3, k + 3, Blocks.air, 0, 2);
		world.setBlock(i + 4, j + 3, k + 3, Blocks.air, 0, 2);
		world.setBlock(i + 5, j + 3, k + 3, Blocks.air, 0, 2);
		world.setBlock(i + 6, j + 3, k + 3, Blocks.air, 0, 2);
		world.setBlock(i + 7, j + 3, k + 3, Blocks.air, 0, 2);
		world.setBlock(i + 8, j + 3, k + 3, Blocks.air, 0, 2);
		world.setBlock(i + 9, j + 3, k + 3, Blocks.air, 0, 2);
		world.setBlock(i + 10, j + 3, k + 3, Blocks.air, 0, 2);
		world.setBlock(i + 11, j + 3, k + 3, Blocks.air, 0, 2);
		world.setBlock(i + 12, j + 3, k + 3, Blocks.air, 0, 2);
		world.setBlock(i + 13, j + 3, k + 3, Blocks.air, 0, 2);
		world.setBlock(i + 14, j + 3, k + 3, Blocks.air, 0, 2);
		world.setBlock(i + 15, j + 3, k + 3, NovaCraftBlocks.glowing_basal, 0, 2);
		world.setBlock(i, j + 3, k + 4, NovaCraftBlocks.basal_bricks, 0, 2);
		world.setBlock(i + 1, j + 3, k + 4, Blocks.air, 0, 2);
		world.setBlock(i + 2, j + 3, k + 4, Blocks.air, 0, 2);
		world.setBlock(i + 3, j + 3, k + 4, Blocks.air, 0, 2);
		world.setBlock(i + 4, j + 3, k + 4, Blocks.air, 0, 2);
		world.setBlock(i + 5, j + 3, k + 4, Blocks.air, 0, 2);
		world.setBlock(i + 6, j + 3, k + 4, Blocks.air, 0, 2);
		world.setBlock(i + 7, j + 3, k + 4, Blocks.air, 0, 2);
		world.setBlock(i + 8, j + 3, k + 4, Blocks.air, 0, 2);
		world.setBlock(i + 9, j + 3, k + 4, Blocks.air, 0, 2);
		world.setBlock(i + 10, j + 3, k + 4, Blocks.air, 0, 2);
		world.setBlock(i + 11, j + 3, k + 4, Blocks.air, 0, 2);
		world.setBlock(i + 12, j + 3, k + 4, Blocks.air, 0, 2);
		world.setBlock(i + 13, j + 3, k + 4, Blocks.air, 0, 2);
		world.setBlock(i + 14, j + 3, k + 4, Blocks.air, 0, 2);
		world.setBlock(i + 15, j + 3, k + 4, NovaCraftBlocks.basal_bricks, 0, 2);
		world.setBlock(i, j + 3, k + 5, NovaCraftBlocks.basal_bricks, 0, 2);
		world.setBlock(i + 1, j + 3, k + 5, Blocks.air, 0, 2);
		world.setBlock(i + 2, j + 3, k + 5, Blocks.air, 0, 2);
		world.setBlock(i + 3, j + 3, k + 5, Blocks.air, 0, 2);
		world.setBlock(i + 4, j + 3, k + 5, Blocks.air, 0, 2);
		world.setBlock(i + 5, j + 3, k + 5, Blocks.air, 0, 2);
		world.setBlock(i + 6, j + 3, k + 5, Blocks.air, 0, 2);
		world.setBlock(i + 7, j + 3, k + 5, Blocks.air, 0, 2);
		world.setBlock(i + 8, j + 3, k + 5, Blocks.air, 0, 2);
		world.setBlock(i + 9, j + 3, k + 5, Blocks.air, 0, 2);
		world.setBlock(i + 10, j + 3, k + 5, Blocks.air, 0, 2);
		world.setBlock(i + 11, j + 3, k + 5, Blocks.air, 0, 2);
		world.setBlock(i + 12, j + 3, k + 5, Blocks.air, 0, 2);
		world.setBlock(i + 13, j + 3, k + 5, Blocks.air, 0, 2);
		world.setBlock(i + 14, j + 3, k + 5, Blocks.air, 0, 2);
		world.setBlock(i + 15, j + 3, k + 5, NovaCraftBlocks.cracked_basal_bricks, 0, 2);
		world.setBlock(i, j + 3, k + 6, NovaCraftBlocks.basal_bricks, 0, 2);
		world.setBlock(i + 1, j + 3, k + 6, Blocks.air, 0, 2);
		world.setBlock(i + 2, j + 3, k + 6, Blocks.air, 0, 2);
		world.setBlock(i + 3, j + 3, k + 6, Blocks.air, 0, 2);
		world.setBlock(i + 4, j + 3, k + 6, Blocks.air, 0, 2);
		world.setBlock(i + 5, j + 3, k + 6, Blocks.air, 0, 2);
		world.setBlock(i + 6, j + 3, k + 6, Blocks.air, 0, 2);
		world.setBlock(i + 7, j + 3, k + 6, Blocks.air, 0, 2);
		world.setBlock(i + 8, j + 3, k + 6, Blocks.air, 0, 2);
		world.setBlock(i + 9, j + 3, k + 6, Blocks.air, 0, 2);
		world.setBlock(i + 10, j + 3, k + 6, Blocks.air, 0, 2);
		world.setBlock(i + 11, j + 3, k + 6, Blocks.air, 0, 2);
		world.setBlock(i + 12, j + 3, k + 6, Blocks.air, 0, 2);
		world.setBlock(i + 13, j + 3, k + 6, Blocks.air, 0, 2);
		world.setBlock(i + 14, j + 3, k + 6, Blocks.air, 0, 2);
		world.setBlock(i + 15, j + 3, k + 6, NovaCraftBlocks.basal_bricks, 0, 2);
		world.setBlock(i, j + 3, k + 7, NovaCraftBlocks.basal_bricks, 0, 2);
		world.setBlock(i + 1, j + 3, k + 7, Blocks.air, 0, 2);
		world.setBlock(i + 2, j + 3, k + 7, Blocks.air, 0, 2);
		world.setBlock(i + 3, j + 3, k + 7, Blocks.air, 0, 2);
		world.setBlock(i + 4, j + 3, k + 7, Blocks.air, 0, 2);
		world.setBlock(i + 5, j + 3, k + 7, Blocks.air, 0, 2);
		world.setBlock(i + 6, j + 3, k + 7, Blocks.air, 0, 2);
		world.setBlock(i + 7, j + 3, k + 7, Blocks.air, 0, 2);
		world.setBlock(i + 8, j + 3, k + 7, Blocks.air, 0, 2);
		world.setBlock(i + 9, j + 3, k + 7, Blocks.air, 0, 2);
		world.setBlock(i + 10, j + 3, k + 7, Blocks.air, 0, 2);
		world.setBlock(i + 11, j + 3, k + 7, Blocks.air, 0, 2);
		world.setBlock(i + 12, j + 3, k + 7, Blocks.air, 0, 2);
		world.setBlock(i + 13, j + 3, k + 7, Blocks.air, 0, 2);
		world.setBlock(i + 14, j + 3, k + 7, Blocks.air, 0, 2);
		world.setBlock(i + 15, j + 3, k + 7, NovaCraftBlocks.glowing_basal, 0, 2);
		world.setBlock(i, j + 3, k + 8, NovaCraftBlocks.basal_bricks, 0, 2);
		world.setBlock(i + 1, j + 3, k + 8, Blocks.air, 0, 2);
		world.setBlock(i + 2, j + 3, k + 8, Blocks.air, 0, 2);
		world.setBlock(i + 3, j + 3, k + 8, Blocks.air, 0, 2);
		world.setBlock(i + 4, j + 3, k + 8, Blocks.air, 0, 2);
		world.setBlock(i + 5, j + 3, k + 8, Blocks.air, 0, 2);
		world.setBlock(i + 6, j + 3, k + 8, Blocks.air, 0, 2);
		world.setBlock(i + 7, j + 3, k + 8, Blocks.air, 0, 2);
		world.setBlock(i + 8, j + 3, k + 8, Blocks.air, 0, 2);
		world.setBlock(i + 9, j + 3, k + 8, Blocks.air, 0, 2);
		world.setBlock(i + 10, j + 3, k + 8, Blocks.air, 0, 2);
		world.setBlock(i + 11, j + 3, k + 8, Blocks.air, 0, 2);
		world.setBlock(i + 12, j + 3, k + 8, Blocks.air, 0, 2);
		world.setBlock(i + 13, j + 3, k + 8, Blocks.air, 0, 2);
		world.setBlock(i + 14, j + 3, k + 8, Blocks.air, 0, 2);
		world.setBlock(i + 15, j + 3, k + 8, NovaCraftBlocks.cracked_basal_bricks, 0, 2);
		world.setBlock(i, j + 3, k + 9, NovaCraftBlocks.glowing_basal, 0, 2);
		world.setBlock(i + 1, j + 3, k + 9, Blocks.air, 0, 2);
		world.setBlock(i + 2, j + 3, k + 9, Blocks.air, 0, 2);
		world.setBlock(i + 3, j + 3, k + 9, Blocks.air, 0, 2);
		world.setBlock(i + 4, j + 3, k + 9, Blocks.air, 0, 2);
		world.setBlock(i + 5, j + 3, k + 9, Blocks.air, 0, 2);
		world.setBlock(i + 6, j + 3, k + 9, Blocks.air, 0, 2);
		world.setBlock(i + 7, j + 3, k + 9, Blocks.air, 0, 2);
		world.setBlock(i + 8, j + 3, k + 9, Blocks.air, 0, 2);
		world.setBlock(i + 9, j + 3, k + 9, Blocks.air, 0, 2);
		world.setBlock(i + 10, j + 3, k + 9, Blocks.air, 0, 2);
		world.setBlock(i + 11, j + 3, k + 9, Blocks.air, 0, 2);
		world.setBlock(i + 12, j + 3, k + 9, Blocks.air, 0, 2);
		world.setBlock(i + 13, j + 3, k + 9, Blocks.air, 0, 2);
		world.setBlock(i + 14, j + 3, k + 9, Blocks.air, 0, 2);
		world.setBlock(i + 15, j + 3, k + 9, NovaCraftBlocks.basal_bricks, 0, 2);
		world.setBlock(i, j + 3, k + 10, NovaCraftBlocks.glowing_basal, 0, 2);
		world.setBlock(i + 1, j + 3, k + 10, Blocks.air, 0, 2);
		world.setBlock(i + 2, j + 3, k + 10, Blocks.air, 0, 2);
		world.setBlock(i + 3, j + 3, k + 10, Blocks.air, 0, 2);
		world.setBlock(i + 4, j + 3, k + 10, Blocks.air, 0, 2);
		world.setBlock(i + 5, j + 3, k + 10, Blocks.air, 0, 2);
		world.setBlock(i + 6, j + 3, k + 10, Blocks.air, 0, 2);
		world.setBlock(i + 7, j + 3, k + 10, Blocks.air, 0, 2);
		world.setBlock(i + 8, j + 3, k + 10, Blocks.air, 0, 2);
		world.setBlock(i + 9, j + 3, k + 10, Blocks.air, 0, 2);
		world.setBlock(i + 10, j + 3, k + 10, Blocks.air, 0, 2);
		world.setBlock(i + 11, j + 3, k + 10, Blocks.air, 0, 2);
		world.setBlock(i + 12, j + 3, k + 10, Blocks.air, 0, 2);
		world.setBlock(i + 13, j + 3, k + 10, Blocks.air, 0, 2);
		world.setBlock(i + 14, j + 3, k + 10, Blocks.air, 0, 2);
		world.setBlock(i + 15, j + 3, k + 10, NovaCraftBlocks.basal_bricks, 0, 2);
		world.setBlock(i, j + 3, k + 11, NovaCraftBlocks.basal_bricks, 0, 2);
		world.setBlock(i + 1, j + 3, k + 11, Blocks.air, 0, 2);
		world.setBlock(i + 2, j + 3, k + 11, Blocks.air, 0, 2);
		world.setBlock(i + 3, j + 3, k + 11, Blocks.air, 0, 2);
		world.setBlock(i + 4, j + 3, k + 11, Blocks.air, 0, 2);
		world.setBlock(i + 5, j + 3, k + 11, Blocks.air, 0, 2);
		world.setBlock(i + 6, j + 3, k + 11, Blocks.air, 0, 2);
		world.setBlock(i + 7, j + 3, k + 11, Blocks.air, 0, 2);
		world.setBlock(i + 8, j + 3, k + 11, Blocks.air, 0, 2);
		world.setBlock(i + 9, j + 3, k + 11, Blocks.air, 0, 2);
		world.setBlock(i + 10, j + 3, k + 11, Blocks.air, 0, 2);
		world.setBlock(i + 11, j + 3, k + 11, Blocks.air, 0, 2);
		world.setBlock(i + 12, j + 3, k + 11, Blocks.air, 0, 2);
		world.setBlock(i + 13, j + 3, k + 11, Blocks.air, 0, 2);
		world.setBlock(i + 14, j + 3, k + 11, Blocks.air, 0, 2);
		world.setBlock(i + 15, j + 3, k + 11, NovaCraftBlocks.basal_bricks, 0, 2);
		world.setBlock(i, j + 3, k + 12, NovaCraftBlocks.cracked_basal_bricks, 0, 2);
		world.setBlock(i + 1, j + 3, k + 12, Blocks.air, 0, 2);
		world.setBlock(i + 2, j + 3, k + 12, Blocks.air, 0, 2);
		world.setBlock(i + 3, j + 3, k + 12, Blocks.air, 0, 2);
		world.setBlock(i + 4, j + 3, k + 12, Blocks.air, 0, 2);
		world.setBlock(i + 5, j + 3, k + 12, Blocks.air, 0, 2);
		world.setBlock(i + 6, j + 3, k + 12, Blocks.air, 0, 2);
		world.setBlock(i + 7, j + 3, k + 12, Blocks.air, 0, 2);
		world.setBlock(i + 8, j + 3, k + 12, Blocks.air, 0, 2);
		world.setBlock(i + 9, j + 3, k + 12, Blocks.air, 0, 2);
		world.setBlock(i + 10, j + 3, k + 12, Blocks.air, 0, 2);
		world.setBlock(i + 11, j + 3, k + 12, Blocks.air, 0, 2);
		world.setBlock(i + 12, j + 3, k + 12, Blocks.air, 0, 2);
		world.setBlock(i + 13, j + 3, k + 12, Blocks.air, 0, 2);
		world.setBlock(i + 14, j + 3, k + 12, Blocks.air, 0, 2);
		world.setBlock(i + 15, j + 3, k + 12, NovaCraftBlocks.basal_bricks, 0, 2);
		world.setBlock(i, j + 3, k + 13, NovaCraftBlocks.basal_bricks, 0, 2);
		world.setBlock(i + 1, j + 3, k + 13, NovaCraftBlocks.basal_brick_wall, 0, 2);
		world.setBlock(i + 2, j + 3, k + 13, Blocks.air, 0, 2);
		world.setBlock(i + 3, j + 3, k + 13, Blocks.air, 0, 2);
		world.setBlock(i + 4, j + 3, k + 13, Blocks.air, 0, 2);
		world.setBlock(i + 5, j + 3, k + 13, Blocks.air, 0, 2);
		world.setBlock(i + 6, j + 3, k + 13, Blocks.air, 0, 2);
		world.setBlock(i + 7, j + 3, k + 13, Blocks.air, 0, 2);
		world.setBlock(i + 8, j + 3, k + 13, Blocks.air, 0, 2);
		world.setBlock(i + 9, j + 3, k + 13, Blocks.air, 0, 2);
		world.setBlock(i + 10, j + 3, k + 13, Blocks.air, 0, 2);
		world.setBlock(i + 11, j + 3, k + 13, Blocks.air, 0, 2);
		world.setBlock(i + 12, j + 3, k + 13, Blocks.air, 0, 2);
		world.setBlock(i + 13, j + 3, k + 13, Blocks.air, 0, 2);
		world.setBlock(i + 14, j + 3, k + 13, NovaCraftBlocks.basal_brick_wall, 0, 2);
		world.setBlock(i + 15, j + 3, k + 13, NovaCraftBlocks.basal_bricks, 0, 2);
		world.setBlock(i, j + 3, k + 14, NovaCraftBlocks.basal_bricks, 0, 2);
		world.setBlock(i + 2, j + 3, k + 14, NovaCraftBlocks.basal_brick_wall, 0, 2);
		world.setBlock(i + 3, j + 3, k + 14, Blocks.air, 0, 2);
		world.setBlock(i + 4, j + 3, k + 14, Blocks.air, 0, 2);
		world.setBlock(i + 5, j + 3, k + 14, Blocks.air, 0, 2);
		world.setBlock(i + 6, j + 3, k + 14, Blocks.air, 0, 2);
		world.setBlock(i + 7, j + 3, k + 14, Blocks.air, 0, 2);
		world.setBlock(i + 8, j + 3, k + 14, Blocks.air, 0, 2);
		world.setBlock(i + 9, j + 3, k + 14, Blocks.air, 0, 2);
		world.setBlock(i + 10, j + 3, k + 14, Blocks.air, 0, 2);
		world.setBlock(i + 11, j + 3, k + 14, Blocks.air, 0, 2);
		world.setBlock(i + 12, j + 3, k + 14, Blocks.air, 0, 2);
		world.setBlock(i + 13, j + 3, k + 14, NovaCraftBlocks.basal_brick_wall, 0, 2);
		world.setBlock(i + 15, j + 3, k + 14, NovaCraftBlocks.basal_bricks, 0, 2);
		world.setBlock(i, j + 3, k + 15, NovaCraftBlocks.basal_bricks, 0, 2);
		world.setBlock(i + 1, j + 3, k + 15, NovaCraftBlocks.basal_bricks, 0, 2);
		world.setBlock(i + 2, j + 3, k + 15, NovaCraftBlocks.basal_bricks, 0, 2);
		world.setBlock(i + 3, j + 3, k + 15, NovaCraftBlocks.glowing_basal, 0, 2);
		world.setBlock(i + 4, j + 3, k + 15, NovaCraftBlocks.cracked_basal_bricks, 0, 2);
		world.setBlock(i + 5, j + 3, k + 15, NovaCraftBlocks.cracked_basal_bricks, 0, 2);
		world.setBlock(i + 6, j + 3, k + 15, NovaCraftBlocks.basal_bricks, 0, 2);
		world.setBlock(i + 7, j + 3, k + 15, NovaCraftBlocks.glowing_basal, 0, 2);
		world.setBlock(i + 8, j + 3, k + 15, NovaCraftBlocks.basal_bricks, 0, 2);
		world.setBlock(i + 9, j + 3, k + 15, NovaCraftBlocks.basal_bricks, 0, 2);
		world.setBlock(i + 10, j + 3, k + 15, NovaCraftBlocks.basal_bricks, 0, 2);
		world.setBlock(i + 11, j + 3, k + 15, NovaCraftBlocks.cracked_basal_bricks, 0, 2);
		world.setBlock(i + 12, j + 3, k + 15, NovaCraftBlocks.basal_bricks, 0, 2);
		world.setBlock(i + 13, j + 3, k + 15, NovaCraftBlocks.basal_bricks, 0, 2);
		world.setBlock(i + 14, j + 3, k + 15, NovaCraftBlocks.basal_bricks, 0, 2);
		world.setBlock(i + 15, j + 3, k + 15, NovaCraftBlocks.basal_bricks, 0, 2);
		world.setBlock(i, j + 4, k, NovaCraftBlocks.basal_bricks, 0, 2);
		world.setBlock(i + 1, j + 4, k, NovaCraftBlocks.basal_bricks, 0, 2);
		world.setBlock(i + 2, j + 4, k, NovaCraftBlocks.basal_bricks, 0, 2);
		world.setBlock(i + 3, j + 4, k, NovaCraftBlocks.basal_bricks, 0, 2);
		world.setBlock(i + 4, j + 4, k, NovaCraftBlocks.basal_bricks, 0, 2);
		world.setBlock(i + 5, j + 4, k, NovaCraftBlocks.basal_bricks, 0, 2);
		world.setBlock(i + 6, j + 4, k, NovaCraftBlocks.basal_bricks, 0, 2);
		world.setBlock(i + 7, j + 4, k, NovaCraftBlocks.basal_bricks, 0, 2);
		world.setBlock(i + 8, j + 4, k, NovaCraftBlocks.basal_bricks, 0, 2);
		world.setBlock(i + 9, j + 4, k, NovaCraftBlocks.basal_bricks, 0, 2);
		world.setBlock(i + 10, j + 4, k, NovaCraftBlocks.basal_bricks, 0, 2);
		world.setBlock(i + 11, j + 4, k, NovaCraftBlocks.basal_bricks, 0, 2);
		world.setBlock(i + 12, j + 4, k, NovaCraftBlocks.basal_bricks, 0, 2);
		world.setBlock(i + 13, j + 4, k, NovaCraftBlocks.basal_bricks, 0, 2);
		world.setBlock(i + 14, j + 4, k, NovaCraftBlocks.basal_bricks, 0, 2);
		world.setBlock(i + 15, j + 4, k, NovaCraftBlocks.basal_bricks, 0, 2);
		world.setBlock(i, j + 4, k + 1, NovaCraftBlocks.basal_bricks, 0, 2);
		world.setBlock(i + 1, j + 4, k + 1, NovaCraftBlocks.basal_bricks, 0, 2);
		world.setBlock(i + 2, j + 4, k + 1, NovaCraftBlocks.basal_bricks, 0, 2);
		world.setBlock(i + 3, j + 4, k + 1, NovaCraftBlocks.cracked_basal_bricks, 0, 2);
		world.setBlock(i + 4, j + 4, k + 1, NovaCraftBlocks.basal_bricks, 0, 2);
		world.setBlock(i + 5, j + 4, k + 1, NovaCraftBlocks.glowing_basal, 0, 2);
		world.setBlock(i + 6, j + 4, k + 1, NovaCraftBlocks.basal_bricks, 0, 2);
		world.setBlock(i + 7, j + 4, k + 1, NovaCraftBlocks.basal_bricks, 0, 2);
		world.setBlock(i + 8, j + 4, k + 1, NovaCraftBlocks.basal_bricks, 0, 2);
		world.setBlock(i + 9, j + 4, k + 1, NovaCraftBlocks.basal_bricks, 0, 2);
		world.setBlock(i + 10, j + 4, k + 1, NovaCraftBlocks.basal_bricks, 0, 2);
		world.setBlock(i + 11, j + 4, k + 1, NovaCraftBlocks.glowing_basal, 0, 2);
		world.setBlock(i + 12, j + 4, k + 1, NovaCraftBlocks.basal_bricks, 0, 2);
		world.setBlock(i + 13, j + 4, k + 1, NovaCraftBlocks.basal_bricks, 0, 2);
		world.setBlock(i + 14, j + 4, k + 1, NovaCraftBlocks.basal_bricks, 0, 2);
		world.setBlock(i + 15, j + 4, k + 1, NovaCraftBlocks.basal_bricks, 0, 2);
		world.setBlock(i, j + 4, k + 2, NovaCraftBlocks.basal_bricks, 0, 2);
		world.setBlock(i + 1, j + 4, k + 2, NovaCraftBlocks.cracked_basal_bricks, 0, 2);
		world.setBlock(i + 2, j + 4, k + 2, NovaCraftBlocks.basal_bricks, 0, 2);
		world.setBlock(i + 3, j + 4, k + 2, NovaCraftBlocks.basal_bricks, 0, 2);
		world.setBlock(i + 4, j + 4, k + 2, NovaCraftBlocks.basal_bricks, 0, 2);
		world.setBlock(i + 5, j + 4, k + 2, NovaCraftBlocks.basal_bricks, 0, 2);
		world.setBlock(i + 6, j + 4, k + 2, NovaCraftBlocks.basal_bricks, 0, 2);
		world.setBlock(i + 7, j + 4, k + 2, NovaCraftBlocks.basal_bricks, 0, 2);
		world.setBlock(i + 8, j + 4, k + 2, NovaCraftBlocks.basal_bricks, 0, 2);
		world.setBlock(i + 9, j + 4, k + 2, NovaCraftBlocks.basal_bricks, 0, 2);
		world.setBlock(i + 10, j + 4, k + 2, NovaCraftBlocks.cracked_basal_bricks, 0, 2);
		world.setBlock(i + 11, j + 4, k + 2, NovaCraftBlocks.basal_bricks, 0, 2);
		world.setBlock(i + 12, j + 4, k + 2, NovaCraftBlocks.cracked_basal_bricks, 0, 2);
		world.setBlock(i + 13, j + 4, k + 2, NovaCraftBlocks.basal_bricks, 0, 2);
		world.setBlock(i + 14, j + 4, k + 2, NovaCraftBlocks.basal_bricks, 0, 2);
		world.setBlock(i + 15, j + 4, k + 2, NovaCraftBlocks.basal_bricks, 0, 2);
		world.setBlock(i, j + 4, k + 3, NovaCraftBlocks.basal_bricks, 0, 2);
		world.setBlock(i + 1, j + 4, k + 3, NovaCraftBlocks.basal_bricks, 0, 2);
		world.setBlock(i + 2, j + 4, k + 3, NovaCraftBlocks.basal_bricks, 0, 2);
		world.setBlock(i + 3, j + 4, k + 3, NovaCraftBlocks.basal_bricks, 0, 2);
		world.setBlock(i + 4, j + 4, k + 3, NovaCraftBlocks.basal_bricks, 0, 2);
		world.setBlock(i + 5, j + 4, k + 3, NovaCraftBlocks.glowing_basal, 0, 2);
		world.setBlock(i + 6, j + 4, k + 3, NovaCraftBlocks.basal_bricks, 0, 2);
		world.setBlock(i + 7, j + 4, k + 3, NovaCraftBlocks.basal_bricks, 0, 2);
		world.setBlock(i + 8, j + 4, k + 3, NovaCraftBlocks.glowing_basal, 0, 2);
		world.setBlock(i + 9, j + 4, k + 3, NovaCraftBlocks.glowing_basal, 0, 2);
		world.setBlock(i + 10, j + 4, k + 3, NovaCraftBlocks.basal_bricks, 0, 2);
		world.setBlock(i + 11, j + 4, k + 3, NovaCraftBlocks.basal_bricks, 0, 2);
		world.setBlock(i + 12, j + 4, k + 3, NovaCraftBlocks.basal_bricks, 0, 2);
		world.setBlock(i + 13, j + 4, k + 3, NovaCraftBlocks.cracked_basal_bricks, 0, 2);
		world.setBlock(i + 14, j + 4, k + 3, NovaCraftBlocks.basal_bricks, 0, 2);
		world.setBlock(i + 15, j + 4, k + 3, NovaCraftBlocks.basal_bricks, 0, 2);
		world.setBlock(i, j + 4, k + 4, NovaCraftBlocks.basal_bricks, 0, 2);
		world.setBlock(i + 1, j + 4, k + 4, NovaCraftBlocks.basal_bricks, 0, 2);
		world.setBlock(i + 2, j + 4, k + 4, NovaCraftBlocks.cracked_basal_bricks, 0, 2);
		world.setBlock(i + 3, j + 4, k + 4, NovaCraftBlocks.basal_bricks, 0, 2);
		world.setBlock(i + 4, j + 4, k + 4, NovaCraftBlocks.basal_bricks, 0, 2);
		world.setBlock(i + 5, j + 4, k + 4, NovaCraftBlocks.basal_bricks, 0, 2);
		world.setBlock(i + 6, j + 4, k + 4, NovaCraftBlocks.cracked_basal_bricks, 0, 2);
		world.setBlock(i + 7, j + 4, k + 4, NovaCraftBlocks.basal_bricks, 0, 2);
		world.setBlock(i + 8, j + 4, k + 4, NovaCraftBlocks.cracked_basal_bricks, 0, 2);
		world.setBlock(i + 9, j + 4, k + 4, NovaCraftBlocks.basal_bricks, 0, 2);
		world.setBlock(i + 10, j + 4, k + 4, NovaCraftBlocks.basal_bricks, 0, 2);
		world.setBlock(i + 11, j + 4, k + 4, NovaCraftBlocks.basal_bricks, 0, 2);
		world.setBlock(i + 12, j + 4, k + 4, NovaCraftBlocks.cracked_basal_bricks, 0, 2);
		world.setBlock(i + 13, j + 4, k + 4, NovaCraftBlocks.basal_bricks, 0, 2);
		world.setBlock(i + 14, j + 4, k + 4, NovaCraftBlocks.cracked_basal_bricks, 0, 2);
		world.setBlock(i + 15, j + 4, k + 4, NovaCraftBlocks.basal_bricks, 0, 2);
		world.setBlock(i, j + 4, k + 5, NovaCraftBlocks.basal_bricks, 0, 2);
		world.setBlock(i + 1, j + 4, k + 5, NovaCraftBlocks.basal_bricks, 0, 2);
		world.setBlock(i + 2, j + 4, k + 5, NovaCraftBlocks.basal_bricks, 0, 2);
		world.setBlock(i + 3, j + 4, k + 5, NovaCraftBlocks.glowing_basal, 0, 2);
		world.setBlock(i + 4, j + 4, k + 5, NovaCraftBlocks.basal_bricks, 0, 2);
		world.setBlock(i + 5, j + 4, k + 5, NovaCraftBlocks.basal_bricks, 0, 2);
		world.setBlock(i + 6, j + 4, k + 5, NovaCraftBlocks.basal_bricks, 0, 2);
		world.setBlock(i + 7, j + 4, k + 5, NovaCraftBlocks.basal_bricks, 0, 2);
		world.setBlock(i + 8, j + 4, k + 5, NovaCraftBlocks.basal_bricks, 0, 2);
		world.setBlock(i + 9, j + 4, k + 5, NovaCraftBlocks.basal_bricks, 0, 2);
		world.setBlock(i + 10, j + 4, k + 5, NovaCraftBlocks.cracked_basal_bricks, 0, 2);
		world.setBlock(i + 11, j + 4, k + 5, NovaCraftBlocks.basal_bricks, 0, 2);
		world.setBlock(i + 12, j + 4, k + 5, NovaCraftBlocks.basal_bricks, 0, 2);
		world.setBlock(i + 13, j + 4, k + 5, NovaCraftBlocks.basal_bricks, 0, 2);
		world.setBlock(i + 14, j + 4, k + 5, NovaCraftBlocks.basal_bricks, 0, 2);
		world.setBlock(i + 15, j + 4, k + 5, NovaCraftBlocks.basal_bricks, 0, 2);
		world.setBlock(i, j + 4, k + 6, NovaCraftBlocks.basal_bricks, 0, 2);
		world.setBlock(i + 1, j + 4, k + 6, NovaCraftBlocks.basal_bricks, 0, 2);
		world.setBlock(i + 2, j + 4, k + 6, NovaCraftBlocks.basal_bricks, 0, 2);
		world.setBlock(i + 3, j + 4, k + 6, NovaCraftBlocks.basal_bricks, 0, 2);
		world.setBlock(i + 4, j + 4, k + 6, NovaCraftBlocks.basal_bricks, 0, 2);
		world.setBlock(i + 5, j + 4, k + 6, NovaCraftBlocks.basal_bricks, 0, 2);
		world.setBlock(i + 6, j + 4, k + 6, NovaCraftBlocks.glowing_basal, 0, 2);
		world.setBlock(i + 7, j + 4, k + 6, NovaCraftBlocks.basal_bricks, 0, 2);
		world.setBlock(i + 8, j + 4, k + 6, NovaCraftBlocks.basal_bricks, 0, 2);
		world.setBlock(i + 9, j + 4, k + 6, NovaCraftBlocks.basal_bricks, 0, 2);
		world.setBlock(i + 10, j + 4, k + 6, NovaCraftBlocks.glowing_basal, 0, 2);
		world.setBlock(i + 11, j + 4, k + 6, NovaCraftBlocks.basal_bricks, 0, 2);
		world.setBlock(i + 12, j + 4, k + 6, NovaCraftBlocks.basal_bricks, 0, 2);
		world.setBlock(i + 13, j + 4, k + 6, NovaCraftBlocks.basal_bricks, 0, 2);
		world.setBlock(i + 14, j + 4, k + 6, NovaCraftBlocks.basal_bricks, 0, 2);
		world.setBlock(i + 15, j + 4, k + 6, NovaCraftBlocks.basal_bricks, 0, 2);
		world.setBlock(i, j + 4, k + 7, NovaCraftBlocks.basal_bricks, 0, 2);
		world.setBlock(i + 1, j + 4, k + 7, NovaCraftBlocks.basal_bricks, 0, 2);
		world.setBlock(i + 2, j + 4, k + 7, NovaCraftBlocks.glowing_basal, 0, 2);
		world.setBlock(i + 3, j + 4, k + 7, NovaCraftBlocks.basal_bricks, 0, 2);
		world.setBlock(i + 4, j + 4, k + 7, NovaCraftBlocks.basal_bricks, 0, 2);
		world.setBlock(i + 5, j + 4, k + 7, NovaCraftBlocks.basal_bricks, 0, 2);
		world.setBlock(i + 6, j + 4, k + 7, NovaCraftBlocks.cracked_basal_bricks, 0, 2);
		world.setBlock(i + 7, j + 4, k + 7, Blocks.air, 0, 2);
		world.setBlock(i + 8, j + 4, k + 7, Blocks.air, 0, 2);
		world.setBlock(i + 9, j + 4, k + 7, NovaCraftBlocks.basal_bricks, 0, 2);
		world.setBlock(i + 10, j + 4, k + 7, NovaCraftBlocks.basal_bricks, 0, 2);
		world.setBlock(i + 11, j + 4, k + 7, NovaCraftBlocks.basal_bricks, 0, 2);
		world.setBlock(i + 12, j + 4, k + 7, NovaCraftBlocks.basal_bricks, 0, 2);
		world.setBlock(i + 13, j + 4, k + 7, NovaCraftBlocks.basal_bricks, 0, 2);
		world.setBlock(i + 14, j + 4, k + 7, NovaCraftBlocks.basal_bricks, 0, 2);
		world.setBlock(i + 15, j + 4, k + 7, NovaCraftBlocks.basal_bricks, 0, 2);
		world.setBlock(i, j + 4, k + 8, NovaCraftBlocks.basal_bricks, 0, 2);
		world.setBlock(i + 1, j + 4, k + 8, NovaCraftBlocks.basal_bricks, 0, 2);
		world.setBlock(i + 2, j + 4, k + 8, NovaCraftBlocks.basal_bricks, 0, 2);
		world.setBlock(i + 3, j + 4, k + 8, NovaCraftBlocks.basal_bricks, 0, 2);
		world.setBlock(i + 4, j + 4, k + 8, NovaCraftBlocks.basal_bricks, 0, 2);
		world.setBlock(i + 5, j + 4, k + 8, NovaCraftBlocks.basal_bricks, 0, 2);
		world.setBlock(i + 6, j + 4, k + 8, NovaCraftBlocks.cracked_basal_bricks, 0, 2);
		world.setBlock(i + 7, j + 4, k + 8, Blocks.air, 0, 2);
		world.setBlock(i + 8, j + 4, k + 8, Blocks.air, 0, 2);
		world.setBlock(i + 9, j + 4, k + 8, NovaCraftBlocks.cracked_basal_bricks, 0, 2);
		world.setBlock(i + 10, j + 4, k + 8, NovaCraftBlocks.basal_bricks, 0, 2);
		world.setBlock(i + 11, j + 4, k + 8, NovaCraftBlocks.glowing_basal, 0, 2);
		world.setBlock(i + 12, j + 4, k + 8, NovaCraftBlocks.basal_bricks, 0, 2);
		world.setBlock(i + 13, j + 4, k + 8, NovaCraftBlocks.cracked_basal_bricks, 0, 2);
		world.setBlock(i + 14, j + 4, k + 8, NovaCraftBlocks.cracked_basal_bricks, 0, 2);
		world.setBlock(i + 15, j + 4, k + 8, NovaCraftBlocks.basal_bricks, 0, 2);
		world.setBlock(i, j + 4, k + 9, NovaCraftBlocks.basal_bricks, 0, 2);
		world.setBlock(i + 1, j + 4, k + 9, NovaCraftBlocks.basal_bricks, 0, 2);
		world.setBlock(i + 2, j + 4, k + 9, NovaCraftBlocks.basal_bricks, 0, 2);
		world.setBlock(i + 3, j + 4, k + 9, NovaCraftBlocks.cracked_basal_bricks, 0, 2);
		world.setBlock(i + 4, j + 4, k + 9, NovaCraftBlocks.basal_bricks, 0, 2);
		world.setBlock(i + 5, j + 4, k + 9, NovaCraftBlocks.glowing_basal, 0, 2);
		world.setBlock(i + 6, j + 4, k + 9, NovaCraftBlocks.basal_bricks, 0, 2);
		world.setBlock(i + 7, j + 4, k + 9, NovaCraftBlocks.cracked_basal_bricks, 0, 2);
		world.setBlock(i + 8, j + 4, k + 9, NovaCraftBlocks.basal_bricks, 0, 2);
		world.setBlock(i + 9, j + 4, k + 9, NovaCraftBlocks.glowing_basal, 0, 2);
		world.setBlock(i + 10, j + 4, k + 9, NovaCraftBlocks.basal_bricks, 0, 2);
		world.setBlock(i + 11, j + 4, k + 9, NovaCraftBlocks.basal_bricks, 0, 2);
		world.setBlock(i + 12, j + 4, k + 9, NovaCraftBlocks.basal_bricks, 0, 2);
		world.setBlock(i + 13, j + 4, k + 9, NovaCraftBlocks.basal_bricks, 0, 2);
		world.setBlock(i + 14, j + 4, k + 9, NovaCraftBlocks.basal_bricks, 0, 2);
		world.setBlock(i + 15, j + 4, k + 9, NovaCraftBlocks.basal_bricks, 0, 2);
		world.setBlock(i, j + 4, k + 10, NovaCraftBlocks.basal_bricks, 0, 2);
		world.setBlock(i + 1, j + 4, k + 10, NovaCraftBlocks.basal_bricks, 0, 2);
		world.setBlock(i + 2, j + 4, k + 10, NovaCraftBlocks.basal_bricks, 0, 2);
		world.setBlock(i + 3, j + 4, k + 10, NovaCraftBlocks.basal_bricks, 0, 2);
		world.setBlock(i + 4, j + 4, k + 10, NovaCraftBlocks.basal_bricks, 0, 2);
		world.setBlock(i + 5, j + 4, k + 10, NovaCraftBlocks.cracked_basal_bricks, 0, 2);
		world.setBlock(i + 6, j + 4, k + 10, NovaCraftBlocks.basal_bricks, 0, 2);
		world.setBlock(i + 7, j + 4, k + 10, NovaCraftBlocks.basal_bricks, 0, 2);
		world.setBlock(i + 8, j + 4, k + 10, NovaCraftBlocks.basal_bricks, 0, 2);
		world.setBlock(i + 9, j + 4, k + 10, NovaCraftBlocks.basal_bricks, 0, 2);
		world.setBlock(i + 10, j + 4, k + 10, NovaCraftBlocks.basal_bricks, 0, 2);
		world.setBlock(i + 11, j + 4, k + 10, NovaCraftBlocks.basal_bricks, 0, 2);
		world.setBlock(i + 12, j + 4, k + 10, NovaCraftBlocks.glowing_basal, 0, 2);
		world.setBlock(i + 13, j + 4, k + 10, NovaCraftBlocks.basal_bricks, 0, 2);
		world.setBlock(i + 14, j + 4, k + 10, NovaCraftBlocks.basal_bricks, 0, 2);
		world.setBlock(i + 15, j + 4, k + 10, NovaCraftBlocks.basal_bricks, 0, 2);
		world.setBlock(i, j + 4, k + 11, NovaCraftBlocks.basal_bricks, 0, 2);
		world.setBlock(i + 1, j + 4, k + 11, NovaCraftBlocks.cracked_basal_bricks, 0, 2);
		world.setBlock(i + 2, j + 4, k + 11, NovaCraftBlocks.basal_bricks, 0, 2);
		world.setBlock(i + 3, j + 4, k + 11, NovaCraftBlocks.glowing_basal, 0, 2);
		world.setBlock(i + 4, j + 4, k + 11, NovaCraftBlocks.basal_bricks, 0, 2);
		world.setBlock(i + 5, j + 4, k + 11, NovaCraftBlocks.basal_bricks, 0, 2);
		world.setBlock(i + 6, j + 4, k + 11, NovaCraftBlocks.basal_bricks, 0, 2);
		world.setBlock(i + 7, j + 4, k + 11, NovaCraftBlocks.basal_bricks, 0, 2);
		world.setBlock(i + 8, j + 4, k + 11, NovaCraftBlocks.basal_bricks, 0, 2);
		world.setBlock(i + 9, j + 4, k + 11, NovaCraftBlocks.basal_bricks, 0, 2);
		world.setBlock(i + 10, j + 4, k + 11, NovaCraftBlocks.basal_bricks, 0, 2);
		world.setBlock(i + 11, j + 4, k + 11, NovaCraftBlocks.basal_bricks, 0, 2);
		world.setBlock(i + 12, j + 4, k + 11, NovaCraftBlocks.cracked_basal_bricks, 0, 2);
		world.setBlock(i + 13, j + 4, k + 11, NovaCraftBlocks.basal_bricks, 0, 2);
		world.setBlock(i + 14, j + 4, k + 11, NovaCraftBlocks.basal_bricks, 0, 2);
		world.setBlock(i + 15, j + 4, k + 11, NovaCraftBlocks.basal_bricks, 0, 2);
		world.setBlock(i, j + 4, k + 12, NovaCraftBlocks.basal_bricks, 0, 2);
		world.setBlock(i + 1, j + 4, k + 12, NovaCraftBlocks.basal_bricks, 0, 2);
		world.setBlock(i + 2, j + 4, k + 12, NovaCraftBlocks.basal_bricks, 0, 2);
		world.setBlock(i + 3, j + 4, k + 12, NovaCraftBlocks.cracked_basal_bricks, 0, 2);
		world.setBlock(i + 4, j + 4, k + 12, NovaCraftBlocks.basal_bricks, 0, 2);
		world.setBlock(i + 5, j + 4, k + 12, NovaCraftBlocks.basal_bricks, 0, 2);
		world.setBlock(i + 6, j + 4, k + 12, NovaCraftBlocks.cracked_basal_bricks, 0, 2);
		world.setBlock(i + 7, j + 4, k + 12, NovaCraftBlocks.basal_bricks, 0, 2);
		world.setBlock(i + 8, j + 4, k + 12, NovaCraftBlocks.glowing_basal, 0, 2);
		world.setBlock(i + 9, j + 4, k + 12, NovaCraftBlocks.basal_bricks, 0, 2);
		world.setBlock(i + 10, j + 4, k + 12, NovaCraftBlocks.cracked_basal_bricks, 0, 2);
		world.setBlock(i + 11, j + 4, k + 12, NovaCraftBlocks.glowing_basal, 0, 2);
		world.setBlock(i + 12, j + 4, k + 12, NovaCraftBlocks.basal_bricks, 0, 2);
		world.setBlock(i + 13, j + 4, k + 12, NovaCraftBlocks.basal_bricks, 0, 2);
		world.setBlock(i + 14, j + 4, k + 12, NovaCraftBlocks.basal_bricks, 0, 2);
		world.setBlock(i + 15, j + 4, k + 12, NovaCraftBlocks.basal_bricks, 0, 2);
		world.setBlock(i, j + 4, k + 13, NovaCraftBlocks.basal_bricks, 0, 2);
		world.setBlock(i + 1, j + 4, k + 13, NovaCraftBlocks.basal_bricks, 0, 2);
		world.setBlock(i + 2, j + 4, k + 13, NovaCraftBlocks.basal_bricks, 0, 2);
		world.setBlock(i + 3, j + 4, k + 13, NovaCraftBlocks.basal_bricks, 0, 2);
		world.setBlock(i + 4, j + 4, k + 13, NovaCraftBlocks.basal_bricks, 0, 2);
		world.setBlock(i + 5, j + 4, k + 13, NovaCraftBlocks.cracked_basal_bricks, 0, 2);
		world.setBlock(i + 6, j + 4, k + 13, NovaCraftBlocks.basal_bricks, 0, 2);
		world.setBlock(i + 7, j + 4, k + 13, NovaCraftBlocks.glowing_basal, 0, 2);
		world.setBlock(i + 8, j + 4, k + 13, NovaCraftBlocks.basal_bricks, 0, 2);
		world.setBlock(i + 9, j + 4, k + 13, NovaCraftBlocks.basal_bricks, 0, 2);
		world.setBlock(i + 10, j + 4, k + 13, NovaCraftBlocks.basal_bricks, 0, 2);
		world.setBlock(i + 11, j + 4, k + 13, NovaCraftBlocks.basal_bricks, 0, 2);
		world.setBlock(i + 12, j + 4, k + 13, NovaCraftBlocks.basal_bricks, 0, 2);
		world.setBlock(i + 13, j + 4, k + 13, NovaCraftBlocks.basal_bricks, 0, 2);
		world.setBlock(i + 14, j + 4, k + 13, NovaCraftBlocks.basal_bricks, 0, 2);
		world.setBlock(i + 15, j + 4, k + 13, NovaCraftBlocks.basal_bricks, 0, 2);
		world.setBlock(i, j + 4, k + 14, NovaCraftBlocks.basal_bricks, 0, 2);
		world.setBlock(i + 1, j + 4, k + 14, NovaCraftBlocks.basal_bricks, 0, 2);
		world.setBlock(i + 2, j + 4, k + 14, NovaCraftBlocks.basal_bricks, 0, 2);
		world.setBlock(i + 3, j + 4, k + 14, NovaCraftBlocks.basal_bricks, 0, 2);
		world.setBlock(i + 4, j + 4, k + 14, NovaCraftBlocks.basal_bricks, 0, 2);
		world.setBlock(i + 5, j + 4, k + 14, NovaCraftBlocks.basal_bricks, 0, 2);
		world.setBlock(i + 6, j + 4, k + 14, NovaCraftBlocks.basal_bricks, 0, 2);
		world.setBlock(i + 7, j + 4, k + 14, NovaCraftBlocks.basal_bricks, 0, 2);
		world.setBlock(i + 8, j + 4, k + 14, NovaCraftBlocks.basal_bricks, 0, 2);
		world.setBlock(i + 9, j + 4, k + 14, NovaCraftBlocks.basal_bricks, 0, 2);
		world.setBlock(i + 10, j + 4, k + 14, NovaCraftBlocks.glowing_basal, 0, 2);
		world.setBlock(i + 11, j + 4, k + 14, NovaCraftBlocks.basal_bricks, 0, 2);
		world.setBlock(i + 12, j + 4, k + 14, NovaCraftBlocks.basal_bricks, 0, 2);
		world.setBlock(i + 13, j + 4, k + 14, NovaCraftBlocks.basal_bricks, 0, 2);
		world.setBlock(i + 14, j + 4, k + 14, NovaCraftBlocks.basal_bricks, 0, 2);
		world.setBlock(i + 15, j + 4, k + 14, NovaCraftBlocks.basal_bricks, 0, 2);
		world.setBlock(i, j + 4, k + 15, NovaCraftBlocks.basal_bricks, 0, 2);
		world.setBlock(i + 1, j + 4, k + 15, NovaCraftBlocks.basal_bricks, 0, 2);
		world.setBlock(i + 2, j + 4, k + 15, NovaCraftBlocks.basal_bricks, 0, 2);
		world.setBlock(i + 3, j + 4, k + 15, NovaCraftBlocks.basal_bricks, 0, 2);
		world.setBlock(i + 4, j + 4, k + 15, NovaCraftBlocks.basal_bricks, 0, 2);
		world.setBlock(i + 5, j + 4, k + 15, NovaCraftBlocks.basal_bricks, 0, 2);
		world.setBlock(i + 6, j + 4, k + 15, NovaCraftBlocks.basal_bricks, 0, 2);
		world.setBlock(i + 7, j + 4, k + 15, NovaCraftBlocks.basal_bricks, 0, 2);
		world.setBlock(i + 8, j + 4, k + 15, NovaCraftBlocks.basal_bricks, 0, 2);
		world.setBlock(i + 9, j + 4, k + 15, NovaCraftBlocks.basal_bricks, 0, 2);
		world.setBlock(i + 10, j + 4, k + 15, NovaCraftBlocks.basal_bricks, 0, 2);
		world.setBlock(i + 11, j + 4, k + 15, NovaCraftBlocks.basal_bricks, 0, 2);
		world.setBlock(i + 12, j + 4, k + 15, NovaCraftBlocks.basal_bricks, 0, 2);
		world.setBlock(i + 13, j + 4, k + 15, NovaCraftBlocks.basal_bricks, 0, 2);
		world.setBlock(i + 14, j + 4, k + 15, NovaCraftBlocks.basal_bricks, 0, 2);
		world.setBlock(i + 15, j + 4, k + 15, NovaCraftBlocks.basal_bricks, 0, 2);

		world.setBlock(i + 1, j + 1, k + 1, NovaCraftBlocks.blazlinite, 8, 2);
		world.setBlock(i + 7, j, k + 7, NovaCraftBlocks.blazlinite, 0, 2);
		world.setBlock(i + 8, j, k + 7, NovaCraftBlocks.blazlinite, 0, 2);
		world.setBlock(i + 7, j, k + 8, NovaCraftBlocks.blazlinite, 0, 2);
		world.setBlock(i + 8, j, k + 8, NovaCraftBlocks.blazlinite, 0, 2);
		world.setBlock(i + 14, j + 1, k + 1, NovaCraftBlocks.blazlinite, 8, 2);
		world.setBlock(i + 14, j + 1, k + 7, NovaCraftBlocks.blazlinite, 0, 2);
		world.setBlock(i + 1, j + 1, k + 14, NovaCraftBlocks.blazlinite, 8, 2);
		world.setBlock(i + 14, j + 1, k + 14, NovaCraftBlocks.blazlinite, 8, 2);
		world.setBlock(i + 1, j + 2, k + 1, NovaCraftBlocks.blazlinite, 8, 2);
		world.setBlock(i + 14, j + 2, k + 1, NovaCraftBlocks.blazlinite, 8, 2);
		world.setBlock(i + 1, j + 2, k + 14, NovaCraftBlocks.blazlinite, 8, 2);
		world.setBlock(i + 14, j + 2, k + 14, NovaCraftBlocks.blazlinite, 8, 2);
		world.setBlock(i + 1, j + 3, k + 1, NovaCraftBlocks.blazlinite, 0, 2);
		world.setBlock(i + 14, j + 3, k + 1, NovaCraftBlocks.blazlinite, 0, 2);
		world.setBlock(i + 1, j + 3, k + 14, NovaCraftBlocks.blazlinite, 0, 2);
		world.setBlock(i + 14, j + 3, k + 14, NovaCraftBlocks.blazlinite, 0, 2);
		
		world.setBlock(i + 1, j + 1, k + 6, NovaCraftBlocks.trap_tophinite, 0, 2);
		
		world.setBlock(i + 1, j + 1, k + 7, Blocks.chest, 5, 2);
		TileEntityChest chest = (TileEntityChest) world.getTileEntity(i + 1, j + 1, k + 7);

		for (int slot = 0; slot < 3 + random.nextInt(20); slot++) {
			chest.setInventorySlotContents(random.nextInt(chest.getSizeInventory()), this.getBastionLoot(random));
		}
		
		world.setBlock(i + 14, j + 2, k + 6, Blocks.chest, 4, 2);
		TileEntityChest chest2 = (TileEntityChest) world.getTileEntity(i + 14, j + 2, k + 6);

		for (int slot = 0; slot < 3 + random.nextInt(20); slot++) {
			chest2.setInventorySlotContents(random.nextInt(chest2.getSizeInventory()), this.getBastionLoot(random));
		}
		
		return true;
	}
	
	private ItemStack getBastionLoot(Random random) {
		int item = random.nextInt(34);
		switch (item) {
			case 0:
				return new ItemStack(NovaCraftItems.yttrlinsite_shard, random.nextInt(3) + 1);
			case 1:
				return new ItemStack(NovaCraftItems.vanite_ingot, random.nextInt(3) + 4);
			case 2:
				return new ItemStack(NovaCraftItems.blazing_coal, random.nextInt(5) + 4);
			case 3:
				return new ItemStack(NovaCraftItems.vanite_chunk, random.nextInt(7) + 4);
			case 4:
				return new ItemStack(NovaCraftItems.vanite_bucket, 1);
			case 5:
				return new ItemStack(NovaCraftItems.vanite_bucket_lava, 1);
			case 6:
				return new ItemStack(NovaCraftItems.vanite_bucket_lava, 1);
			case 7:
				return new ItemStack(NovaCraftItems.vanite_bucket_blazlinite, 1);
			case 8:
				//Pickaxe enchants
				int enchant = 1 + random.nextInt(25);
				if (enchant < 12) {
					Enchantment[] pickaxeEnchantments = {Enchantment.efficiency};
				    Enchantment[] pickaxeEnchantments2 = {Enchantment.unbreaking, Enchantment.fortune};
				    Enchantment enchantment3 = pickaxeEnchantments[random.nextInt(pickaxeEnchantments.length)];
				    Enchantment enchantment33 = pickaxeEnchantments2[random.nextInt(pickaxeEnchantments2.length)];	
				    int maxLevel3 = enchantment3.getMinLevel() + 1;			
				    int maxLevel33 = enchantment33.getMinLevel() + 1;	
				    ItemStack itemStack3 = new ItemStack(Items.diamond_pickaxe);
				    
				    itemStack3.addEnchantment(enchantment3, maxLevel3);
				    itemStack3.addEnchantment(enchantment33, maxLevel33);
				    
				    return itemStack3;
				} 
				else {
					Enchantment[] pickaxeEnchantments = {Enchantment.efficiency};
				    Enchantment[] pickaxeEnchantments2 = {Enchantment.unbreaking, Enchantment.silkTouch};
				    Enchantment enchantment3 = pickaxeEnchantments[random.nextInt(pickaxeEnchantments.length)];
				    Enchantment enchantment33 = pickaxeEnchantments2[random.nextInt(pickaxeEnchantments2.length)];	
				    int maxLevel3 = enchantment3.getMinLevel() + 1;			
				    int maxLevel33 = enchantment33.getMinLevel();	
				    ItemStack itemStack3 = new ItemStack(Items.diamond_pickaxe);
				    
				    itemStack3.addEnchantment(enchantment3, maxLevel3);
				    itemStack3.addEnchantment(enchantment33, maxLevel33);
				    
				    return itemStack3;
				}
			case 9:
				//Axe enchants
			    Enchantment[] pickaxeEnchantments = {Enchantment.efficiency};
			    Enchantment[] pickaxeEnchantments2 = {Enchantment.unbreaking, Enchantment.unbreaking, Enchantment.unbreaking, Enchantment.silkTouch};
			    Enchantment enchantment3 = pickaxeEnchantments[random.nextInt(pickaxeEnchantments.length)];
			    Enchantment enchantment33 = pickaxeEnchantments2[random.nextInt(pickaxeEnchantments2.length)];	
			    int maxLevel3 = enchantment3.getMinLevel() + 1;			
			    int maxLevel33 = enchantment33.getMinLevel();	
			    ItemStack itemStack3 = new ItemStack(Items.diamond_axe);
			    
			    itemStack3.addEnchantment(enchantment3, maxLevel3);
			    itemStack3.addEnchantment(enchantment33, maxLevel33);
			    
			    return itemStack3;
			case 10:
				//Shovel enchants
			    Enchantment[] pickaxeEnchantments5 = {Enchantment.efficiency};
			    Enchantment[] pickaxeEnchantments25 = {Enchantment.unbreaking, Enchantment.unbreaking, Enchantment.unbreaking, Enchantment.silkTouch};
			    Enchantment enchantment35 = pickaxeEnchantments5[random.nextInt(pickaxeEnchantments5.length)];
			    Enchantment enchantment335 = pickaxeEnchantments25[random.nextInt(pickaxeEnchantments25.length)];	
			    int maxLevel35 = enchantment35.getMinLevel() + 1;			
			    int maxLevel335 = enchantment335.getMinLevel();	
			    ItemStack itemStack35 = new ItemStack(Items.diamond_axe);
			    
			    itemStack35.addEnchantment(enchantment35, maxLevel35);
			    itemStack35.addEnchantment(enchantment335, maxLevel335);
			    
			    return itemStack35;
			case 11:
				//Sword enchants
				int enchant2 = 1 + random.nextInt(25);
				if (enchant2 < 12) {
					Enchantment[] pickaxeEnchantments6 = {Enchantment.sharpness};
			    	Enchantment[] pickaxeEnchantments26 = {Enchantment.unbreaking, Enchantment.unbreaking, Enchantment.unbreaking, Enchantment.knockback, Enchantment.fireAspect};
			    	Enchantment enchantment36 = pickaxeEnchantments6[random.nextInt(pickaxeEnchantments6.length)];
			    	Enchantment enchantment336 = pickaxeEnchantments26[random.nextInt(pickaxeEnchantments26.length)];	
			    	int maxLevel36 = enchantment36.getMinLevel() + 1;			
			    	int maxLevel336 = enchantment336.getMinLevel();	
			    	ItemStack itemStack36 = new ItemStack(Items.diamond_sword);
			    
			    	itemStack36.addEnchantment(enchantment36, maxLevel36);
			    	itemStack36.addEnchantment(enchantment336, maxLevel336);
			    
			    	return itemStack36;
				}
				else {
					Enchantment[] pickaxeEnchantments6 = {Enchantment.smite};
				    Enchantment[] pickaxeEnchantments26 = {Enchantment.unbreaking, Enchantment.unbreaking, Enchantment.unbreaking, Enchantment.knockback, Enchantment.fireAspect};
				    Enchantment enchantment36 = pickaxeEnchantments6[random.nextInt(pickaxeEnchantments6.length)];
				    Enchantment enchantment336 = pickaxeEnchantments26[random.nextInt(pickaxeEnchantments26.length)];	
				    int maxLevel36 = enchantment36.getMinLevel() + 1;			
				    int maxLevel336 = enchantment336.getMinLevel();	
				    ItemStack itemStack36 = new ItemStack(Items.diamond_sword);
				    
				    itemStack36.addEnchantment(enchantment36, maxLevel36);
				    itemStack36.addEnchantment(enchantment336, maxLevel336);
				    
				    return itemStack36;
				}
			case 12:
				return new ItemStack(NovaCraftBlocks.glowing_basal, random.nextInt(2) + 1);
			case 13:
				if (Loader.isModLoaded("netherlicious")) {
					return new ItemStack(OtherModBlocks.CryingObsidian, random.nextInt(2) + 1);
				}
				else {
					return new ItemStack(Blocks.obsidian, random.nextInt(2) + 1);
				}
			case 14:
				return new ItemStack(Blocks.obsidian, random.nextInt(5) + 1);
			case 15:
				return new ItemStack(NovaCraftItems.luminant_tree_sap, random.nextInt(7) + 7);
			case 16:
				return new ItemStack(Items.coal, random.nextInt(15) + 14);
			case 17:
				return new ItemStack(Items.iron_ingot, random.nextInt(19) + 7);
			case 18:
				return new ItemStack(Items.glowstone_dust, random.nextInt(7) + 3);
			case 19:
				int rand3 = 1 + random.nextInt(100);
				if (Configs.enableTreasureCratesDropDiamonds && rand3 > 70) {
					return new ItemStack(Items.diamond, 1);
				}
				else {
					return new ItemStack(Items.iron_ingot, random.nextInt(19) + 7);
				}
			case 20:
				Enchantment enchantment = Enchantment.enchantmentsBookList[random.nextInt(Enchantment.enchantmentsBookList.length)];
		        
				int minLevel = enchantment.getMinLevel();
		        int maxLevel = enchantment.getMaxLevel();
		        int level = MathHelper.getRandomIntegerInRange(random, minLevel, maxLevel);
		        ItemStack itemStack = Items.enchanted_book.getEnchantedItemStack(new EnchantmentData(enchantment, maxLevel));
                
                return itemStack;
			case 21:
				Enchantment enchantment2 = Enchantment.enchantmentsBookList[random.nextInt(Enchantment.enchantmentsBookList.length)];
		        
				int minLevel2 = enchantment2.getMinLevel();
		        int maxLevel2 = enchantment2.getMaxLevel();
		        int level2 = MathHelper.getRandomIntegerInRange(random, minLevel2, maxLevel2);
		        ItemStack itemStack2 = Items.enchanted_book.getEnchantedItemStack(new EnchantmentData(enchantment2, maxLevel2));
                
                return itemStack2;
			case 22:
				return new ItemStack(NovaCraftItems.blazing_serpent_scales, random.nextInt(3) + 1);
			case 23:
				return new ItemStack(NovaCraftItems.anomalous_essence, random.nextInt(2) + 1);
			case 24:
				return new ItemStack(Items.magma_cream, random.nextInt(3) + 2);
			case 25:
				return new ItemStack(NovaCraftItems.tophinite_gemstone, 1);
			case 26:
				return new ItemStack(NovaCraftItems.vanite_bottle, random.nextInt(7) + 6);
			case 27:
				return new ItemStack(NovaCraftBlocks.block_of_vanite, 1);
			case 28:
				if (Loader.isModLoaded("etfuturum") && Configs.enableNetheriteInRecipes) {
					return new ItemStack(OtherModItems.netherite_scrap, random.nextInt(2) + 1);
				}
				else {
					return new ItemStack(Items.quartz, random.nextInt(15) + 14);
				}
			default: {
				return new ItemStack(NovaCraftItems.vanite_ingot, random.nextInt(9) + 7);
			}
		}
	}

}
