package com.NovaCraft.world.bastion.treasure;

import net.minecraft.world.gen.feature.*;
import net.minecraft.block.*;
import net.minecraft.world.*;
import java.util.*;

import com.NovaCraft.config.Configs;
import com.NovaCraft.entity.EntitySavageSerpent;
import com.NovaCraft.registry.OtherModBlocks;
import com.NovaCraftBlocks.NovaCraftBlocks;

import cpw.mods.fml.common.Loader;
import net.minecraft.init.*;

public class BastionTreasureBarracksGen9 extends WorldGenerator
{
	public BastionTreasureBarracksGen9() {

	}
    
    public boolean generate(final World world, final Random random, final int i, final int j, final int k) {
    	
    	world.setBlock(i + 13, j + 55, k + 5, NovaCraftBlocks.basal_bricks, 0, 2);
		world.setBlock(i + 14, j + 55, k + 5, NovaCraftBlocks.basal_bricks, 0, 2);
		world.setBlock(i + 15, j + 55, k + 5, NovaCraftBlocks.basal_bricks, 0, 2);
		world.setBlock(i + 16, j + 55, k + 5, Blocks.air, 0, 2);
		world.setBlock(i + 17, j + 55, k + 5, Blocks.air, 0, 2);
		world.setBlock(i + 18, j + 55, k + 5, NovaCraftBlocks.basal_bricks, 0, 2);
		world.setBlock(i + 19, j + 55, k + 5, NovaCraftBlocks.cracked_basal_bricks, 0, 2);
		world.setBlock(i + 20, j + 55, k + 5, Blocks.air, 0, 2);
		world.setBlock(i + 21, j + 55, k + 5, Blocks.air, 0, 2);
		world.setBlock(i + 22, j + 55, k + 5, NovaCraftBlocks.cracked_basal_bricks, 0, 2);
		world.setBlock(i + 23, j + 55, k + 5, NovaCraftBlocks.cracked_basal_bricks, 0, 2);
		world.setBlock(i + 24, j + 55, k + 5, NovaCraftBlocks.block_of_vanite, 0, 2);
		world.setBlock(i + 25, j + 55, k + 5, Blocks.air, 0, 2);
		world.setBlock(i + 26, j + 55, k + 5, NovaCraftBlocks.cracked_basal_bricks, 0, 2);
		world.setBlock(i + 27, j + 55, k + 5, NovaCraftBlocks.basal_bricks, 0, 2);
		world.setBlock(i + 0, j + 55, k + 6, NovaCraftBlocks.basal_bricks, 0, 2);
		world.setBlock(i + 1, j + 55, k + 6, Blocks.air, 0, 2);
		world.setBlock(i + 3, j + 55, k + 6, Blocks.air, 0, 2);
		world.setBlock(i + 4, j + 55, k + 6, Blocks.air, 0, 2);
		world.setBlock(i + 5, j + 55, k + 6, Blocks.air, 0, 2);
		world.setBlock(i + 6, j + 55, k + 6, NovaCraftBlocks.basal_bricks, 0, 2);
		world.setBlock(i + 7, j + 55, k + 6, NovaCraftBlocks.basal_bricks, 0, 2);
		world.setBlock(i + 8, j + 55, k + 6, Blocks.air, 0, 2);
		world.setBlock(i + 9, j + 55, k + 6, Blocks.air, 0, 2);
		world.setBlock(i + 10, j + 55, k + 6, Blocks.air, 0, 2);
		world.setBlock(i + 12, j + 55, k + 6, Blocks.air, 0, 2);
		world.setBlock(i + 13, j + 55, k + 6, NovaCraftBlocks.basal_bricks, 0, 2);
		world.setBlock(i + 14, j + 55, k + 6, NovaCraftBlocks.basal_bricks, 0, 2);
		world.setBlock(i + 15, j + 55, k + 6, NovaCraftBlocks.cracked_basal_bricks, 0, 2);
		world.setBlock(i + 16, j + 55, k + 6, NovaCraftBlocks.basal_bricks, 0, 2);
		world.setBlock(i + 17, j + 55, k + 6, NovaCraftBlocks.cracked_basal_bricks, 0, 2);
		world.setBlock(i + 18, j + 55, k + 6, NovaCraftBlocks.basal_bricks, 0, 2);
		world.setBlock(i + 19, j + 55, k + 6, NovaCraftBlocks.basal_bricks, 0, 2);
		world.setBlock(i + 20, j + 55, k + 6, NovaCraftBlocks.basal_bricks, 0, 2);
		world.setBlock(i + 21, j + 55, k + 6, NovaCraftBlocks.basal_bricks, 0, 2);
		world.setBlock(i + 22, j + 55, k + 6, NovaCraftBlocks.cracked_basal_bricks, 0, 2);
		world.setBlock(i + 23, j + 55, k + 6, NovaCraftBlocks.basal_bricks, 0, 2);
		world.setBlock(i + 24, j + 55, k + 6, NovaCraftBlocks.cracked_basal_bricks, 0, 2);
		world.setBlock(i + 25, j + 55, k + 6, NovaCraftBlocks.basal_bricks, 0, 2);
		world.setBlock(i + 26, j + 55, k + 6, NovaCraftBlocks.cracked_basal_bricks, 0, 2);
		world.setBlock(i + 27, j + 55, k + 6, NovaCraftBlocks.basal_bricks, 0, 2);
		world.setBlock(i + 0, j + 55, k + 7, NovaCraftBlocks.basal_bricks, 0, 2);
		world.setBlock(i + 1, j + 55, k + 7, Blocks.air, 0, 2);
		world.setBlock(i + 2, j + 55, k + 7, Blocks.air, 0, 2);
		world.setBlock(i + 3, j + 55, k + 7, Blocks.air, 0, 2);
		world.setBlock(i + 4, j + 55, k + 7, Blocks.air, 0, 2);
		world.setBlock(i + 5, j + 55, k + 7, Blocks.air, 0, 2);
		world.setBlock(i + 6, j + 55, k + 7, NovaCraftBlocks.basal_bricks, 0, 2);
		world.setBlock(i + 7, j + 55, k + 7, NovaCraftBlocks.basal_bricks, 0, 2);
		world.setBlock(i + 8, j + 55, k + 7, Blocks.air, 0, 2);
		world.setBlock(i + 9, j + 55, k + 7, Blocks.air, 0, 2);
		world.setBlock(i + 10, j + 55, k + 7, Blocks.air, 0, 2);
		world.setBlock(i + 11, j + 55, k + 7, Blocks.air, 0, 2);
		world.setBlock(i + 12, j + 55, k + 7, Blocks.air, 0, 2);
		world.setBlock(i + 13, j + 55, k + 7, NovaCraftBlocks.basal_bricks, 0, 2);
		world.setBlock(i + 14, j + 55, k + 7, NovaCraftBlocks.cracked_basal_bricks, 0, 2);
		world.setBlock(i + 15, j + 55, k + 7, Blocks.air, 0, 2);
		world.setBlock(i + 16, j + 55, k + 7, Blocks.air, 0, 2);
		world.setBlock(i + 17, j + 55, k + 7, Blocks.air, 0, 2);
		world.setBlock(i + 18, j + 55, k + 7, Blocks.air, 0, 2);
		world.setBlock(i + 19, j + 55, k + 7, Blocks.air, 0, 2);
		world.setBlock(i + 20, j + 55, k + 7, Blocks.air, 0, 2);
		world.setBlock(i + 21, j + 55, k + 7, Blocks.air, 0, 2);
		world.setBlock(i + 22, j + 55, k + 7, Blocks.air, 0, 2);
		world.setBlock(i + 23, j + 55, k + 7, Blocks.air, 0, 2);
		world.setBlock(i + 24, j + 55, k + 7, Blocks.air, 0, 2);
		world.setBlock(i + 25, j + 55, k + 7, Blocks.air, 0, 2);
		world.setBlock(i + 26, j + 55, k + 7, Blocks.air, 0, 2);
		world.setBlock(i + 27, j + 55, k + 7, NovaCraftBlocks.basal_bricks, 0, 2);
		world.setBlock(i + 0, j + 55, k + 8, NovaCraftBlocks.basal_bricks, 0, 2);
		world.setBlock(i + 1, j + 55, k + 8, Blocks.air, 0, 2);
		world.setBlock(i + 2, j + 55, k + 8, Blocks.air, 0, 2);
		world.setBlock(i + 3, j + 55, k + 8, Blocks.air, 0, 2);
		world.setBlock(i + 4, j + 55, k + 8, Blocks.air, 0, 2);
		world.setBlock(i + 5, j + 55, k + 8, Blocks.air, 0, 2);
		world.setBlock(i + 6, j + 55, k + 8, NovaCraftBlocks.basal_bricks, 0, 2);
		world.setBlock(i + 7, j + 55, k + 8, NovaCraftBlocks.basal_bricks, 0, 2);
		world.setBlock(i + 8, j + 55, k + 8, Blocks.air, 0, 2);
		world.setBlock(i + 9, j + 55, k + 8, Blocks.air, 0, 2);
		world.setBlock(i + 10, j + 55, k + 8, Blocks.air, 0, 2);
		world.setBlock(i + 11, j + 55, k + 8, Blocks.air, 0, 2);
		world.setBlock(i + 12, j + 55, k + 8, Blocks.air, 0, 2);
		world.setBlock(i + 13, j + 55, k + 8, NovaCraftBlocks.basal_bricks, 0, 2);
		world.setBlock(i + 14, j + 55, k + 8, NovaCraftBlocks.basal_bricks, 0, 2);
		world.setBlock(i + 15, j + 55, k + 8, Blocks.air, 0, 2);
		world.setBlock(i + 16, j + 55, k + 8, Blocks.air, 0, 2);
		world.setBlock(i + 17, j + 55, k + 8, Blocks.air, 0, 2);
		world.setBlock(i + 18, j + 55, k + 8, Blocks.air, 0, 2);
		world.setBlock(i + 19, j + 55, k + 8, Blocks.air, 0, 2);
		world.setBlock(i + 20, j + 55, k + 8, Blocks.air, 0, 2);
		world.setBlock(i + 21, j + 55, k + 8, Blocks.air, 0, 2);
		world.setBlock(i + 22, j + 55, k + 8, Blocks.air, 0, 2);
		world.setBlock(i + 23, j + 55, k + 8, Blocks.air, 0, 2);
		world.setBlock(i + 24, j + 55, k + 8, Blocks.air, 0, 2);
		world.setBlock(i + 25, j + 55, k + 8, Blocks.air, 0, 2);
		world.setBlock(i + 26, j + 55, k + 8, Blocks.air, 0, 2);
		world.setBlock(i + 27, j + 55, k + 8, NovaCraftBlocks.basal_bricks, 0, 2);
		world.setBlock(i + 0, j + 55, k + 9, NovaCraftBlocks.basal_bricks, 0, 2);
		world.setBlock(i + 1, j + 55, k + 9, Blocks.air, 0, 2);
		world.setBlock(i + 2, j + 55, k + 9, Blocks.air, 0, 2);
		world.setBlock(i + 3, j + 55, k + 9, Blocks.air, 0, 2);
		world.setBlock(i + 4, j + 55, k + 9, Blocks.air, 0, 2);
		world.setBlock(i + 5, j + 55, k + 9, Blocks.air, 0, 2);
		world.setBlock(i + 6, j + 55, k + 9, NovaCraftBlocks.basal_bricks, 0, 2);
		world.setBlock(i + 7, j + 55, k + 9, NovaCraftBlocks.basal_bricks, 0, 2);
		world.setBlock(i + 8, j + 55, k + 9, Blocks.air, 0, 2);
		world.setBlock(i + 9, j + 55, k + 9, Blocks.air, 0, 2);
		world.setBlock(i + 10, j + 55, k + 9, Blocks.air, 0, 2);
		world.setBlock(i + 11, j + 55, k + 9, Blocks.air, 0, 2);
		world.setBlock(i + 12, j + 55, k + 9, Blocks.air, 0, 2);
		world.setBlock(i + 13, j + 55, k + 9, NovaCraftBlocks.basal_bricks, 0, 2);
		world.setBlock(i + 14, j + 55, k + 9, NovaCraftBlocks.basal_bricks, 0, 2);
		world.setBlock(i + 15, j + 55, k + 9, Blocks.air, 0, 2);
		world.setBlock(i + 16, j + 55, k + 9, Blocks.air, 0, 2);
		world.setBlock(i + 17, j + 55, k + 9, Blocks.air, 0, 2);
		world.setBlock(i + 18, j + 55, k + 9, Blocks.air, 0, 2);
		world.setBlock(i + 19, j + 55, k + 9, Blocks.air, 0, 2);
		world.setBlock(i + 20, j + 55, k + 9, Blocks.air, 0, 2);
		world.setBlock(i + 21, j + 55, k + 9, Blocks.air, 0, 2);
		world.setBlock(i + 22, j + 55, k + 9, Blocks.air, 0, 2);
		world.setBlock(i + 23, j + 55, k + 9, Blocks.air, 0, 2);
		world.setBlock(i + 24, j + 55, k + 9, Blocks.air, 0, 2);
		world.setBlock(i + 25, j + 55, k + 9, Blocks.air, 0, 2);
		world.setBlock(i + 26, j + 55, k + 9, Blocks.air, 0, 2);
		world.setBlock(i + 27, j + 55, k + 9, NovaCraftBlocks.basal_bricks, 0, 2);
		world.setBlock(i + 0, j + 55, k + 10, NovaCraftBlocks.basal_bricks, 0, 2);
		world.setBlock(i + 1, j + 55, k + 10, Blocks.air, 0, 2);
		world.setBlock(i + 2, j + 55, k + 10, Blocks.air, 0, 2);
		world.setBlock(i + 3, j + 55, k + 10, Blocks.air, 0, 2);
		world.setBlock(i + 4, j + 55, k + 10, Blocks.air, 0, 2);
		world.setBlock(i + 5, j + 55, k + 10, NovaCraftBlocks.basal_brick_stairs, 0, 2);
		world.setBlock(i + 6, j + 55, k + 10, NovaCraftBlocks.basal_scrap, 0, 2);
		world.setBlock(i + 7, j + 55, k + 10, Blocks.air, 0, 2);
		world.setBlock(i + 8, j + 55, k + 10, NovaCraftBlocks.basal_brick_stairs, 1, 2);
		world.setBlock(i + 9, j + 55, k + 10, Blocks.air, 0, 2);
		world.setBlock(i + 10, j + 55, k + 10, Blocks.air, 0, 2);
		world.setBlock(i + 11, j + 55, k + 10, Blocks.air, 0, 2);
		world.setBlock(i + 12, j + 55, k + 10, Blocks.air, 0, 2);
		world.setBlock(i + 13, j + 55, k + 10, NovaCraftBlocks.basal_bricks, 0, 2);
		world.setBlock(i + 14, j + 55, k + 10, NovaCraftBlocks.basal_bricks, 0, 2);
		world.setBlock(i + 15, j + 55, k + 10, Blocks.air, 0, 2);
		world.setBlock(i + 16, j + 55, k + 10, Blocks.air, 0, 2);
		world.setBlock(i + 17, j + 55, k + 10, Blocks.air, 0, 2);
		world.setBlock(i + 18, j + 55, k + 10, Blocks.air, 0, 2);
		world.setBlock(i + 19, j + 55, k + 10, Blocks.air, 0, 2);
		world.setBlock(i + 20, j + 55, k + 10, Blocks.air, 0, 2);
		world.setBlock(i + 21, j + 55, k + 10, Blocks.air, 0, 2);
		world.setBlock(i + 22, j + 55, k + 10, Blocks.air, 0, 2);
		world.setBlock(i + 23, j + 55, k + 10, Blocks.air, 0, 2);
		world.setBlock(i + 24, j + 55, k + 10, Blocks.air, 0, 2);
		world.setBlock(i + 25, j + 55, k + 10, Blocks.air, 0, 2);
		world.setBlock(i + 26, j + 55, k + 10, Blocks.air, 0, 2);
		world.setBlock(i + 27, j + 55, k + 10, NovaCraftBlocks.basal_bricks, 0, 2);
		world.setBlock(i + 0, j + 55, k + 11, Blocks.air, 0, 2);
		world.setBlock(i + 1, j + 55, k + 11, Blocks.air, 0, 2);
		world.setBlock(i + 2, j + 55, k + 11, Blocks.air, 0, 2);
		world.setBlock(i + 3, j + 55, k + 11, Blocks.air, 0, 2);
		world.setBlock(i + 4, j + 55, k + 11, Blocks.air, 0, 2);
		world.setBlock(i + 5, j + 55, k + 11, Blocks.air, 0, 2);
		world.setBlock(i + 6, j + 55, k + 11, Blocks.air, 0, 2);
		world.setBlock(i + 7, j + 55, k + 11, Blocks.air, 0, 2);
		world.setBlock(i + 8, j + 55, k + 11, Blocks.air, 0, 2);
		world.setBlock(i + 9, j + 55, k + 11, Blocks.air, 0, 2);
		world.setBlock(i + 10, j + 55, k + 11, Blocks.air, 0, 2);
		world.setBlock(i + 11, j + 55, k + 11, Blocks.air, 0, 2);
		world.setBlock(i + 12, j + 55, k + 11, Blocks.air, 0, 2);
		world.setBlock(i + 13, j + 55, k + 11, Blocks.air, 0, 2);
		world.setBlock(i + 14, j + 55, k + 11, NovaCraftBlocks.basal_bricks, 0, 2);
		world.setBlock(i + 15, j + 55, k + 11, Blocks.air, 0, 2);
		world.setBlock(i + 16, j + 55, k + 11, Blocks.air, 0, 2);
		world.setBlock(i + 17, j + 55, k + 11, Blocks.air, 0, 2);
		world.setBlock(i + 18, j + 55, k + 11, Blocks.air, 0, 2);
		world.setBlock(i + 19, j + 55, k + 11, Blocks.air, 0, 2);
		world.setBlock(i + 20, j + 55, k + 11, Blocks.air, 0, 2);
		world.setBlock(i + 21, j + 55, k + 11, Blocks.air, 0, 2);
		world.setBlock(i + 22, j + 55, k + 11, Blocks.air, 0, 2);
		world.setBlock(i + 23, j + 55, k + 11, Blocks.air, 0, 2);
		world.setBlock(i + 24, j + 55, k + 11, Blocks.air, 0, 2);
		world.setBlock(i + 25, j + 55, k + 11, Blocks.air, 0, 2);
		world.setBlock(i + 26, j + 55, k + 11, Blocks.air, 0, 2);
		world.setBlock(i + 27, j + 55, k + 11, NovaCraftBlocks.basal_bricks, 0, 2);
		world.setBlock(i + 0, j + 55, k + 12, Blocks.air, 0, 2);
		world.setBlock(i + 1, j + 55, k + 12, Blocks.air, 0, 2);
		world.setBlock(i + 2, j + 55, k + 12, Blocks.air, 0, 2);
		world.setBlock(i + 3, j + 55, k + 12, Blocks.air, 0, 2);
		world.setBlock(i + 4, j + 55, k + 12, Blocks.air, 0, 2);
		world.setBlock(i + 5, j + 55, k + 12, Blocks.air, 0, 2);
		world.setBlock(i + 6, j + 55, k + 12, Blocks.air, 0, 2);
		world.setBlock(i + 7, j + 55, k + 12, Blocks.air, 0, 2);
		world.setBlock(i + 8, j + 55, k + 12, Blocks.air, 0, 2);
		world.setBlock(i + 9, j + 55, k + 12, Blocks.air, 0, 2);
		world.setBlock(i + 10, j + 55, k + 12, Blocks.air, 0, 2);
		world.setBlock(i + 11, j + 55, k + 12, Blocks.air, 0, 2);
		world.setBlock(i + 12, j + 55, k + 12, Blocks.air, 0, 2);
		world.setBlock(i + 13, j + 55, k + 12, Blocks.air, 0, 2);
		world.setBlock(i + 14, j + 55, k + 12, NovaCraftBlocks.cracked_basal_bricks, 0, 2);
		world.setBlock(i + 15, j + 55, k + 12, Blocks.air, 0, 2);
		world.setBlock(i + 16, j + 55, k + 12, Blocks.air, 0, 2);
		world.setBlock(i + 17, j + 55, k + 12, Blocks.air, 0, 2);
		world.setBlock(i + 18, j + 55, k + 12, NovaCraftBlocks.basal_brick_stairs, 0, 2);
		world.setBlock(i + 19, j + 55, k + 12, NovaCraftBlocks.cracked_basal_bricks, 0, 2);
		world.setBlock(i + 20, j + 55, k + 12, NovaCraftBlocks.cracked_basal_bricks, 0, 2);
		world.setBlock(i + 21, j + 55, k + 12, NovaCraftBlocks.basal_scrap, 0, 2);
		world.setBlock(i + 22, j + 55, k + 12, NovaCraftBlocks.basal_bricks, 0, 2);
		world.setBlock(i + 23, j + 55, k + 12, NovaCraftBlocks.basal_brick_stairs, 1, 2);
		world.setBlock(i + 24, j + 55, k + 12, Blocks.air, 0, 2);
		world.setBlock(i + 25, j + 55, k + 12, Blocks.air, 0, 2);
		world.setBlock(i + 26, j + 55, k + 12, Blocks.air, 0, 2);
		world.setBlock(i + 27, j + 55, k + 12, NovaCraftBlocks.basal_bricks, 0, 2);
		world.setBlock(i + 0, j + 56, k + 0, NovaCraftBlocks.basal_bricks, 0, 2);
		world.setBlock(i + 1, j + 56, k + 0, NovaCraftBlocks.basal_bricks, 0, 2);
		world.setBlock(i + 4, j + 56, k + 0, NovaCraftBlocks.basal_bricks, 0, 2);
		world.setBlock(i + 5, j + 56, k + 0, NovaCraftBlocks.basal_bricks, 0, 2);
		world.setBlock(i + 12, j + 56, k + 0, NovaCraftBlocks.basal_bricks, 0, 2);
		world.setBlock(i + 13, j + 56, k + 0, NovaCraftBlocks.basal_bricks, 0, 2);
		world.setBlock(i + 0, j + 56, k + 1, NovaCraftBlocks.basal_bricks, 0, 2);
		world.setBlock(i + 1, j + 56, k + 1, NovaCraftBlocks.basal_bricks, 0, 2);
		world.setBlock(i + 4, j + 56, k + 1, NovaCraftBlocks.basal_bricks, 0, 2);
		world.setBlock(i + 5, j + 56, k + 1, NovaCraftBlocks.basal_bricks, 0, 2);
		world.setBlock(i + 8, j + 56, k + 1, NovaCraftBlocks.basal_bricks, 0, 2);
		world.setBlock(i + 12, j + 56, k + 1, NovaCraftBlocks.basal_bricks, 0, 2);
		world.setBlock(i + 13, j + 56, k + 1, NovaCraftBlocks.basal_bricks, 0, 2);
		world.setBlock(i + 0, j + 56, k + 2, NovaCraftBlocks.basal_bricks, 0, 2);
		world.setBlock(i + 1, j + 56, k + 2, NovaCraftBlocks.basal_bricks, 0, 2);
		world.setBlock(i + 2, j + 56, k + 2, NovaCraftBlocks.basal_bricks, 0, 2);
		world.setBlock(i + 3, j + 56, k + 2, NovaCraftBlocks.basal_bricks, 0, 2);
		world.setBlock(i + 4, j + 56, k + 2, NovaCraftBlocks.basal_bricks, 0, 2);
		world.setBlock(i + 5, j + 56, k + 2, NovaCraftBlocks.basal_bricks, 0, 2);
		world.setBlock(i + 6, j + 56, k + 2, NovaCraftBlocks.basal_bricks, 0, 2);
		world.setBlock(i + 7, j + 56, k + 2, NovaCraftBlocks.basal_bricks, 0, 2);
		world.setBlock(i + 8, j + 56, k + 2, NovaCraftBlocks.basal_bricks, 0, 2);
		world.setBlock(i + 9, j + 56, k + 2, NovaCraftBlocks.basal_bricks, 0, 2);
		world.setBlock(i + 10, j + 56, k + 2, NovaCraftBlocks.basal_bricks, 0, 2);
		world.setBlock(i + 12, j + 56, k + 2, NovaCraftBlocks.basal_bricks, 0, 2);
		world.setBlock(i + 13, j + 56, k + 2, NovaCraftBlocks.basal_bricks, 0, 2);
		world.setBlock(i + 14, j + 56, k + 2, NovaCraftBlocks.basal_bricks, 0, 2);
		world.setBlock(i + 15, j + 56, k + 2, NovaCraftBlocks.basal_bricks, 0, 2);
		world.setBlock(i + 18, j + 56, k + 2, NovaCraftBlocks.basal_bricks, 0, 2);
		world.setBlock(i + 19, j + 56, k + 2, NovaCraftBlocks.basal_bricks, 0, 2);
		world.setBlock(i + 22, j + 56, k + 2, NovaCraftBlocks.basal_bricks, 0, 2);
		world.setBlock(i + 23, j + 56, k + 2, NovaCraftBlocks.basal_bricks, 0, 2);
		world.setBlock(i + 27, j + 56, k + 2, NovaCraftBlocks.basal_bricks, 0, 2);
		world.setBlock(i + 0, j + 56, k + 3, NovaCraftBlocks.basal_bricks, 0, 2);
		world.setBlock(i + 1, j + 56, k + 3, NovaCraftBlocks.basal_bricks, 0, 2);
		world.setBlock(i + 2, j + 56, k + 3, NovaCraftBlocks.basal_bricks, 0, 2);
		world.setBlock(i + 3, j + 56, k + 3, NovaCraftBlocks.basal_bricks, 0, 2);
		world.setBlock(i + 4, j + 56, k + 3, NovaCraftBlocks.basal_bricks, 0, 2);
		world.setBlock(i + 5, j + 56, k + 3, NovaCraftBlocks.basal_bricks, 0, 2);
		world.setBlock(i + 6, j + 56, k + 3, NovaCraftBlocks.basal_bricks, 0, 2);
		world.setBlock(i + 7, j + 56, k + 3, NovaCraftBlocks.basal_bricks, 0, 2);
		world.setBlock(i + 8, j + 56, k + 3, NovaCraftBlocks.basal_bricks, 0, 2);
		world.setBlock(i + 9, j + 56, k + 3, NovaCraftBlocks.basal_bricks, 0, 2);
		world.setBlock(i + 10, j + 56, k + 3, NovaCraftBlocks.basal_bricks, 0, 2);
		world.setBlock(i + 11, j + 56, k + 3, NovaCraftBlocks.basal_bricks, 0, 2);
		world.setBlock(i + 12, j + 56, k + 3, NovaCraftBlocks.basal_bricks, 0, 2);
		world.setBlock(i + 13, j + 56, k + 3, NovaCraftBlocks.basal_bricks, 0, 2);
		world.setBlock(i + 15, j + 56, k + 3, NovaCraftBlocks.basal_bricks, 0, 2);
		world.setBlock(i + 18, j + 56, k + 3, NovaCraftBlocks.basal_bricks, 0, 2);
		world.setBlock(i + 19, j + 56, k + 3, NovaCraftBlocks.basal_bricks, 0, 2);
		world.setBlock(i + 22, j + 56, k + 3, NovaCraftBlocks.basal_bricks, 0, 2);
		world.setBlock(i + 23, j + 56, k + 3, NovaCraftBlocks.basal_bricks, 0, 2);
		world.setBlock(i + 26, j + 56, k + 3, NovaCraftBlocks.basal_bricks, 0, 2);
		world.setBlock(i + 27, j + 56, k + 3, NovaCraftBlocks.basal_bricks, 0, 2);
		world.setBlock(i + 0, j + 56, k + 4, NovaCraftBlocks.basal_bricks, 0, 2);
		world.setBlock(i + 1, j + 56, k + 4, NovaCraftBlocks.basal_bricks, 0, 2);
		world.setBlock(i + 2, j + 56, k + 4, NovaCraftBlocks.basal_bricks, 0, 2);
		world.setBlock(i + 3, j + 56, k + 4, NovaCraftBlocks.basal_bricks, 0, 2);
		world.setBlock(i + 4, j + 56, k + 4, NovaCraftBlocks.basal_bricks, 0, 2);
		world.setBlock(i + 5, j + 56, k + 4, NovaCraftBlocks.basal_bricks, 0, 2);
		world.setBlock(i + 6, j + 56, k + 4, NovaCraftBlocks.basal_bricks, 0, 2);
		world.setBlock(i + 7, j + 56, k + 4, NovaCraftBlocks.basal_bricks, 0, 2);
		world.setBlock(i + 8, j + 56, k + 4, NovaCraftBlocks.basal_bricks, 0, 2);
		world.setBlock(i + 9, j + 56, k + 4, NovaCraftBlocks.basal_bricks, 0, 2);
		world.setBlock(i + 10, j + 56, k + 4, NovaCraftBlocks.basal_bricks, 0, 2);
		world.setBlock(i + 11, j + 56, k + 4, NovaCraftBlocks.basal_bricks, 0, 2);
		world.setBlock(i + 12, j + 56, k + 4, NovaCraftBlocks.basal_bricks, 0, 2);
		world.setBlock(i + 13, j + 56, k + 4, NovaCraftBlocks.basal_bricks, 0, 2);
		world.setBlock(i + 14, j + 56, k + 4, NovaCraftBlocks.basal_bricks, 0, 2);
		world.setBlock(i + 15, j + 56, k + 4, NovaCraftBlocks.basal_bricks, 0, 2);
		world.setBlock(i + 16, j + 56, k + 4, NovaCraftBlocks.basal_bricks, 0, 2);
		world.setBlock(i + 17, j + 56, k + 4, NovaCraftBlocks.basal_bricks, 0, 2);
		world.setBlock(i + 18, j + 56, k + 4, Blocks.air, 0, 2);
		world.setBlock(i + 19, j + 56, k + 4, NovaCraftBlocks.basal_bricks, 0, 2);
		world.setBlock(i + 20, j + 56, k + 4, NovaCraftBlocks.basal_bricks, 0, 2);
		world.setBlock(i + 21, j + 56, k + 4, Blocks.air, 0, 2);
		world.setBlock(i + 22, j + 56, k + 4, NovaCraftBlocks.basal_bricks, 0, 2);
		world.setBlock(i + 23, j + 56, k + 4, NovaCraftBlocks.basal_bricks, 0, 2);
		world.setBlock(i + 24, j + 56, k + 4, NovaCraftBlocks.basal_bricks, 0, 2);
		world.setBlock(i + 25, j + 56, k + 4, NovaCraftBlocks.basal_bricks, 0, 2);
		world.setBlock(i + 26, j + 56, k + 4, NovaCraftBlocks.basal_bricks, 0, 2);
		world.setBlock(i + 27, j + 56, k + 4, NovaCraftBlocks.basal_bricks, 0, 2);
		world.setBlock(i + 0, j + 56, k + 5, NovaCraftBlocks.basal_bricks, 0, 2);
		world.setBlock(i + 1, j + 56, k + 5, NovaCraftBlocks.basal_bricks, 0, 2);
		world.setBlock(i + 2, j + 56, k + 5, Blocks.air, 0, 2);
		world.setBlock(i + 3, j + 56, k + 5, NovaCraftBlocks.basal_bricks, 0, 2);
		world.setBlock(i + 4, j + 56, k + 5, NovaCraftBlocks.basal_bricks, 0, 2);
		world.setBlock(i + 5, j + 56, k + 5, NovaCraftBlocks.basal_bricks, 0, 2);
		world.setBlock(i + 6, j + 56, k + 5, NovaCraftBlocks.basal_bricks, 0, 2);
		world.setBlock(i + 7, j + 56, k + 5, NovaCraftBlocks.basal_bricks, 0, 2);
		world.setBlock(i + 8, j + 56, k + 5, NovaCraftBlocks.basal_bricks, 0, 2);
		world.setBlock(i + 9, j + 56, k + 5, NovaCraftBlocks.basal_bricks, 0, 2);
		world.setBlock(i + 10, j + 56, k + 5, NovaCraftBlocks.basal_bricks, 0, 2);
		world.setBlock(i + 11, j + 56, k + 5, NovaCraftBlocks.basal_bricks, 0, 2);
		world.setBlock(i + 12, j + 56, k + 5, NovaCraftBlocks.basal_bricks, 0, 2);
		world.setBlock(i + 13, j + 56, k + 5, NovaCraftBlocks.basal_bricks, 0, 2);
		world.setBlock(i + 14, j + 56, k + 5, NovaCraftBlocks.basal_bricks, 0, 2);
		world.setBlock(i + 15, j + 56, k + 5, NovaCraftBlocks.basal_bricks, 0, 2);
		world.setBlock(i + 16, j + 56, k + 5, NovaCraftBlocks.basal_bricks, 0, 2);
		world.setBlock(i + 17, j + 56, k + 5, NovaCraftBlocks.basal_bricks, 0, 2);
		world.setBlock(i + 18, j + 56, k + 5, NovaCraftBlocks.basal_bricks, 0, 2);
		world.setBlock(i + 19, j + 56, k + 5, NovaCraftBlocks.basal_bricks, 0, 2);
		world.setBlock(i + 20, j + 56, k + 5, NovaCraftBlocks.basal_bricks, 0, 2);
		world.setBlock(i + 21, j + 56, k + 5, NovaCraftBlocks.basal_bricks, 0, 2);
		world.setBlock(i + 22, j + 56, k + 5, NovaCraftBlocks.basal_bricks, 0, 2);
		world.setBlock(i + 23, j + 56, k + 5, NovaCraftBlocks.basal_bricks, 0, 2);
		world.setBlock(i + 24, j + 56, k + 5, NovaCraftBlocks.basal_bricks, 0, 2);
		world.setBlock(i + 25, j + 56, k + 5, NovaCraftBlocks.basal_bricks, 0, 2);
		world.setBlock(i + 26, j + 56, k + 5, NovaCraftBlocks.basal_bricks, 0, 2);
		world.setBlock(i + 27, j + 56, k + 5, NovaCraftBlocks.basal_bricks, 0, 2);
		world.setBlock(i + 0, j + 56, k + 6, NovaCraftBlocks.basal_bricks, 0, 2);
		world.setBlock(i + 1, j + 56, k + 6, NovaCraftBlocks.basal_bricks, 0, 2);
		world.setBlock(i + 2, j + 56, k + 6, NovaCraftBlocks.basal_bricks, 0, 2);
		world.setBlock(i + 3, j + 56, k + 6, NovaCraftBlocks.basal_bricks, 0, 2);
		world.setBlock(i + 4, j + 56, k + 6, NovaCraftBlocks.basal_bricks, 0, 2);
		world.setBlock(i + 5, j + 56, k + 6, NovaCraftBlocks.basal_bricks, 0, 2);
		world.setBlock(i + 6, j + 56, k + 6, NovaCraftBlocks.basal_bricks, 0, 2);
		world.setBlock(i + 7, j + 56, k + 6, NovaCraftBlocks.basal_bricks, 0, 2);
		world.setBlock(i + 8, j + 56, k + 6, NovaCraftBlocks.basal_bricks, 0, 2);
		world.setBlock(i + 9, j + 56, k + 6, NovaCraftBlocks.basal_bricks, 0, 2);
		world.setBlock(i + 10, j + 56, k + 6, NovaCraftBlocks.basal_bricks, 0, 2);
		world.setBlock(i + 11, j + 56, k + 6, NovaCraftBlocks.basal_bricks, 0, 2);
		world.setBlock(i + 12, j + 56, k + 6, NovaCraftBlocks.basal_bricks, 0, 2);
		world.setBlock(i + 13, j + 56, k + 6, NovaCraftBlocks.basal_bricks, 0, 2);
		world.setBlock(i + 14, j + 56, k + 6, NovaCraftBlocks.basal_bricks, 0, 2);
		world.setBlock(i + 15, j + 56, k + 6, NovaCraftBlocks.basal_bricks, 0, 2);
		world.setBlock(i + 16, j + 56, k + 6, NovaCraftBlocks.basal_bricks, 0, 2);
		world.setBlock(i + 17, j + 56, k + 6, NovaCraftBlocks.basal_bricks, 0, 2);
		world.setBlock(i + 18, j + 56, k + 6, NovaCraftBlocks.basal_bricks, 0, 2);
		world.setBlock(i + 19, j + 56, k + 6, NovaCraftBlocks.basal_bricks, 0, 2);
		world.setBlock(i + 20, j + 56, k + 6, NovaCraftBlocks.basal_bricks, 0, 2);
		world.setBlock(i + 21, j + 56, k + 6, Blocks.air, 0, 2);
		world.setBlock(i + 22, j + 56, k + 6, NovaCraftBlocks.basal_bricks, 0, 2);
		world.setBlock(i + 23, j + 56, k + 6, NovaCraftBlocks.basal_bricks, 0, 2);
		world.setBlock(i + 24, j + 56, k + 6, NovaCraftBlocks.basal_bricks, 0, 2);
		world.setBlock(i + 25, j + 56, k + 6, NovaCraftBlocks.basal_bricks, 0, 2);
		world.setBlock(i + 26, j + 56, k + 6, NovaCraftBlocks.basal_bricks, 0, 2);
		world.setBlock(i + 27, j + 56, k + 6, NovaCraftBlocks.basal_bricks, 0, 2);
		world.setBlock(i + 0, j + 56, k + 7, NovaCraftBlocks.basal_bricks, 0, 2);
		world.setBlock(i + 1, j + 56, k + 7, NovaCraftBlocks.basal_bricks, 0, 2);
		world.setBlock(i + 2, j + 56, k + 7, NovaCraftBlocks.basal_bricks, 0, 2);
		world.setBlock(i + 3, j + 56, k + 7, NovaCraftBlocks.basal_bricks, 0, 2);
		world.setBlock(i + 4, j + 56, k + 7, NovaCraftBlocks.basal_bricks, 0, 2);
		world.setBlock(i + 5, j + 56, k + 7, NovaCraftBlocks.basal_bricks, 0, 2);
		world.setBlock(i + 6, j + 56, k + 7, NovaCraftBlocks.basal_bricks, 0, 2);
		world.setBlock(i + 7, j + 56, k + 7, NovaCraftBlocks.basal_bricks, 0, 2);
		world.setBlock(i + 8, j + 56, k + 7, NovaCraftBlocks.basal_bricks, 0, 2);
		world.setBlock(i + 9, j + 56, k + 7, NovaCraftBlocks.basal_bricks, 0, 2);
		world.setBlock(i + 10, j + 56, k + 7, NovaCraftBlocks.basal_bricks, 0, 2);
		world.setBlock(i + 11, j + 56, k + 7, NovaCraftBlocks.basal_bricks, 0, 2);
		world.setBlock(i + 12, j + 56, k + 7, NovaCraftBlocks.basal_bricks, 0, 2);
		world.setBlock(i + 13, j + 56, k + 7, NovaCraftBlocks.basal_bricks, 0, 2);
		world.setBlock(i + 14, j + 56, k + 7, NovaCraftBlocks.basal_bricks, 0, 2);
		world.setBlock(i + 15, j + 56, k + 7, Blocks.air, 0, 2);
		world.setBlock(i + 16, j + 56, k + 7, Blocks.air, 0, 2);
		world.setBlock(i + 17, j + 56, k + 7, Blocks.air, 0, 2);
		world.setBlock(i + 18, j + 56, k + 7, Blocks.air, 0, 2);
		world.setBlock(i + 19, j + 56, k + 7, Blocks.air, 0, 2);
		world.setBlock(i + 20, j + 56, k + 7, NovaCraftBlocks.basal_bricks, 0, 2);
		world.setBlock(i + 21, j + 56, k + 7, NovaCraftBlocks.basal_bricks, 0, 2);
		world.setBlock(i + 22, j + 56, k + 7, Blocks.air, 0, 2);
		world.setBlock(i + 23, j + 56, k + 7, Blocks.air, 0, 2);
		world.setBlock(i + 24, j + 56, k + 7, Blocks.air, 0, 2);
		world.setBlock(i + 25, j + 56, k + 7, Blocks.air, 0, 2);
		world.setBlock(i + 26, j + 56, k + 7, Blocks.air, 0, 2);
		world.setBlock(i + 27, j + 56, k + 7, NovaCraftBlocks.basal_bricks, 0, 2);
		world.setBlock(i + 0, j + 56, k + 8, NovaCraftBlocks.basal_bricks, 0, 2);
		world.setBlock(i + 1, j + 56, k + 8, NovaCraftBlocks.basal_bricks, 0, 2);
		world.setBlock(i + 2, j + 56, k + 8, NovaCraftBlocks.basal_bricks, 0, 2);
		world.setBlock(i + 3, j + 56, k + 8, NovaCraftBlocks.basal_bricks, 0, 2);
		world.setBlock(i + 4, j + 56, k + 8, NovaCraftBlocks.basal_bricks, 0, 2);
		world.setBlock(i + 5, j + 56, k + 8, NovaCraftBlocks.basal_bricks, 0, 2);
		world.setBlock(i + 6, j + 56, k + 8, NovaCraftBlocks.basal_bricks, 0, 2);
		world.setBlock(i + 7, j + 56, k + 8, NovaCraftBlocks.basal_bricks, 0, 2);
		world.setBlock(i + 8, j + 56, k + 8, NovaCraftBlocks.basal_bricks, 0, 2);
		world.setBlock(i + 9, j + 56, k + 8, NovaCraftBlocks.basal_bricks, 0, 2);
		world.setBlock(i + 10, j + 56, k + 8, NovaCraftBlocks.basal_bricks, 0, 2);
		world.setBlock(i + 11, j + 56, k + 8, NovaCraftBlocks.basal_bricks, 0, 2);
		world.setBlock(i + 12, j + 56, k + 8, NovaCraftBlocks.basal_bricks, 0, 2);
		world.setBlock(i + 13, j + 56, k + 8, NovaCraftBlocks.basal_bricks, 0, 2);
		world.setBlock(i + 14, j + 56, k + 8, NovaCraftBlocks.basal_bricks, 0, 2);
		world.setBlock(i + 15, j + 56, k + 8, Blocks.air, 0, 2);
		world.setBlock(i + 17, j + 56, k + 8, Blocks.air, 0, 2);
		world.setBlock(i + 18, j + 56, k + 8, Blocks.air, 0, 2);
		world.setBlock(i + 19, j + 56, k + 8, Blocks.air, 0, 2);
		world.setBlock(i + 20, j + 56, k + 8, NovaCraftBlocks.basal_bricks, 0, 2);
		world.setBlock(i + 21, j + 56, k + 8, NovaCraftBlocks.basal_bricks, 0, 2);
		world.setBlock(i + 22, j + 56, k + 8, Blocks.air, 0, 2);
		world.setBlock(i + 23, j + 56, k + 8, Blocks.air, 0, 2);
		world.setBlock(i + 24, j + 56, k + 8, Blocks.air, 0, 2);
		world.setBlock(i + 26, j + 56, k + 8, Blocks.air, 0, 2);
		world.setBlock(i + 27, j + 56, k + 8, NovaCraftBlocks.basal_bricks, 0, 2);
		world.setBlock(i + 0, j + 56, k + 9, NovaCraftBlocks.basal_bricks, 0, 2);
		world.setBlock(i + 1, j + 56, k + 9, NovaCraftBlocks.basal_bricks, 0, 2);
		world.setBlock(i + 2, j + 56, k + 9, NovaCraftBlocks.basal_bricks, 0, 2);
		world.setBlock(i + 3, j + 56, k + 9, NovaCraftBlocks.basal_bricks, 0, 2);
		world.setBlock(i + 4, j + 56, k + 9, NovaCraftBlocks.basal_bricks, 0, 2);
		world.setBlock(i + 5, j + 56, k + 9, NovaCraftBlocks.basal_bricks, 0, 2);
		world.setBlock(i + 6, j + 56, k + 9, NovaCraftBlocks.basal_brick_stairs, 3, 2);
		world.setBlock(i + 7, j + 56, k + 9, NovaCraftBlocks.basal_brick_stairs, 3, 2);
		world.setBlock(i + 8, j + 56, k + 9, NovaCraftBlocks.basal_bricks, 0, 2);
		world.setBlock(i + 9, j + 56, k + 9, NovaCraftBlocks.basal_bricks, 0, 2);
		world.setBlock(i + 10, j + 56, k + 9, NovaCraftBlocks.basal_bricks, 0, 2);
		world.setBlock(i + 11, j + 56, k + 9, NovaCraftBlocks.basal_bricks, 0, 2);
		world.setBlock(i + 12, j + 56, k + 9, NovaCraftBlocks.basal_bricks, 0, 2);
		world.setBlock(i + 13, j + 56, k + 9, NovaCraftBlocks.basal_bricks, 0, 2);
		world.setBlock(i + 14, j + 56, k + 9, NovaCraftBlocks.basal_bricks, 0, 2);
		world.setBlock(i + 15, j + 56, k + 9, Blocks.air, 0, 2);
		world.setBlock(i + 16, j + 56, k + 9, Blocks.air, 0, 2);
		world.setBlock(i + 17, j + 56, k + 9, Blocks.air, 0, 2);
		world.setBlock(i + 18, j + 56, k + 9, Blocks.air, 0, 2);
		world.setBlock(i + 19, j + 56, k + 9, Blocks.air, 0, 2);
		world.setBlock(i + 20, j + 56, k + 9, NovaCraftBlocks.basal_bricks, 0, 2);
		world.setBlock(i + 21, j + 56, k + 9, NovaCraftBlocks.basal_bricks, 0, 2);
		world.setBlock(i + 22, j + 56, k + 9, Blocks.air, 0, 2);
		world.setBlock(i + 23, j + 56, k + 9, Blocks.air, 0, 2);
		world.setBlock(i + 24, j + 56, k + 9, Blocks.air, 0, 2);
		world.setBlock(i + 25, j + 56, k + 9, Blocks.air, 0, 2);
		world.setBlock(i + 26, j + 56, k + 9, Blocks.air, 0, 2);
		world.setBlock(i + 27, j + 56, k + 9, NovaCraftBlocks.basal_bricks, 0, 2);
		world.setBlock(i + 0, j + 56, k + 10, NovaCraftBlocks.basal_bricks, 0, 2);
		world.setBlock(i + 1, j + 56, k + 10, NovaCraftBlocks.basal_bricks, 0, 2);
		world.setBlock(i + 2, j + 56, k + 10, Blocks.air, 0, 2);
		world.setBlock(i + 3, j + 56, k + 10, Blocks.air, 0, 2);
		world.setBlock(i + 4, j + 56, k + 10, Blocks.air, 0, 2);
		world.setBlock(i + 5, j + 56, k + 10, Blocks.air, 0, 2);
		world.setBlock(i + 6, j + 56, k + 10, Blocks.air, 0, 2);
		world.setBlock(i + 7, j + 56, k + 10, Blocks.air, 0, 2);
		world.setBlock(i + 8, j + 56, k + 10, Blocks.air, 0, 2);
		world.setBlock(i + 9, j + 56, k + 10, Blocks.air, 0, 2);
		world.setBlock(i + 10, j + 56, k + 10, Blocks.air, 0, 2);
		world.setBlock(i + 11, j + 56, k + 10, Blocks.air, 0, 2);
		world.setBlock(i + 12, j + 56, k + 10, NovaCraftBlocks.basal_bricks, 0, 2);
		world.setBlock(i + 13, j + 56, k + 10, Blocks.air, 0, 2);
		world.setBlock(i + 14, j + 56, k + 10, NovaCraftBlocks.basal_bricks, 0, 2);
		world.setBlock(i + 15, j + 56, k + 10, Blocks.air, 0, 2);
		world.setBlock(i + 16, j + 56, k + 10, Blocks.air, 0, 2);
		world.setBlock(i + 17, j + 56, k + 10, Blocks.air, 0, 2);
		world.setBlock(i + 18, j + 56, k + 10, Blocks.air, 0, 2);
		world.setBlock(i + 19, j + 56, k + 10, Blocks.air, 0, 2);
		world.setBlock(i + 20, j + 56, k + 10, NovaCraftBlocks.basal_bricks, 0, 2);
		world.setBlock(i + 21, j + 56, k + 10, NovaCraftBlocks.basal_bricks, 0, 2);
		world.setBlock(i + 22, j + 56, k + 10, Blocks.air, 0, 2);
		world.setBlock(i + 23, j + 56, k + 10, Blocks.air, 0, 2);
		world.setBlock(i + 24, j + 56, k + 10, Blocks.air, 0, 2);
		world.setBlock(i + 25, j + 56, k + 10, Blocks.air, 0, 2);
		world.setBlock(i + 26, j + 56, k + 10, Blocks.air, 0, 2);
		world.setBlock(i + 27, j + 56, k + 10, NovaCraftBlocks.basal_bricks, 0, 2);
		world.setBlock(i + 0, j + 56, k + 11, Blocks.air, 0, 2);
		world.setBlock(i + 1, j + 56, k + 11, Blocks.air, 0, 2);
		world.setBlock(i + 2, j + 56, k + 11, Blocks.air, 0, 2);
		world.setBlock(i + 3, j + 56, k + 11, Blocks.air, 0, 2);
		world.setBlock(i + 4, j + 56, k + 11, Blocks.air, 0, 2);
		world.setBlock(i + 5, j + 56, k + 11, Blocks.air, 0, 2);
		world.setBlock(i + 6, j + 56, k + 11, Blocks.air, 0, 2);
		world.setBlock(i + 7, j + 56, k + 11, Blocks.air, 0, 2);
		world.setBlock(i + 8, j + 56, k + 11, Blocks.air, 0, 2);
		world.setBlock(i + 9, j + 56, k + 11, Blocks.air, 0, 2);
		world.setBlock(i + 10, j + 56, k + 11, Blocks.air, 0, 2);
		world.setBlock(i + 11, j + 56, k + 11, Blocks.air, 0, 2);
		world.setBlock(i + 12, j + 56, k + 11, Blocks.air, 0, 2);
		world.setBlock(i + 13, j + 56, k + 11, Blocks.air, 0, 2);
		world.setBlock(i + 14, j + 56, k + 11, NovaCraftBlocks.basal_bricks, 0, 2);
		world.setBlock(i + 15, j + 56, k + 11, Blocks.air, 0, 2);
		world.setBlock(i + 16, j + 56, k + 11, Blocks.air, 0, 2);
		world.setBlock(i + 17, j + 56, k + 11, Blocks.air, 0, 2);
		world.setBlock(i + 18, j + 56, k + 11, Blocks.air, 0, 2);
		world.setBlock(i + 19, j + 56, k + 11, Blocks.air, 0, 2);
		world.setBlock(i + 20, j + 56, k + 11, NovaCraftBlocks.basal_bricks, 0, 2);
		world.setBlock(i + 21, j + 56, k + 11, NovaCraftBlocks.basal_bricks, 0, 2);
		world.setBlock(i + 22, j + 56, k + 11, Blocks.air, 0, 2);
		world.setBlock(i + 23, j + 56, k + 11, Blocks.air, 0, 2);
		world.setBlock(i + 24, j + 56, k + 11, Blocks.air, 0, 2);
		world.setBlock(i + 25, j + 56, k + 11, Blocks.air, 0, 2);
		world.setBlock(i + 26, j + 56, k + 11, Blocks.air, 0, 2);
		world.setBlock(i + 27, j + 56, k + 11, NovaCraftBlocks.basal_bricks, 0, 2);
		world.setBlock(i + 0, j + 56, k + 12, Blocks.air, 0, 2);
		world.setBlock(i + 1, j + 56, k + 12, Blocks.air, 0, 2);
		world.setBlock(i + 2, j + 56, k + 12, Blocks.air, 0, 2);
		world.setBlock(i + 3, j + 56, k + 12, Blocks.air, 0, 2);
		world.setBlock(i + 4, j + 56, k + 12, Blocks.air, 0, 2);
		world.setBlock(i + 5, j + 56, k + 12, Blocks.air, 0, 2);
		world.setBlock(i + 6, j + 56, k + 12, Blocks.air, 0, 2);
		world.setBlock(i + 7, j + 56, k + 12, Blocks.air, 0, 2);
		world.setBlock(i + 8, j + 56, k + 12, Blocks.air, 0, 2);
		world.setBlock(i + 9, j + 56, k + 12, Blocks.air, 0, 2);
		world.setBlock(i + 10, j + 56, k + 12, Blocks.air, 0, 2);
		world.setBlock(i + 11, j + 56, k + 12, Blocks.air, 0, 2);
		world.setBlock(i + 12, j + 56, k + 12, Blocks.air, 0, 2);
		world.setBlock(i + 13, j + 56, k + 12, Blocks.air, 0, 2);
		world.setBlock(i + 14, j + 56, k + 12, NovaCraftBlocks.basal_bricks, 0, 2);
		world.setBlock(i + 15, j + 56, k + 12, Blocks.air, 0, 2);
		world.setBlock(i + 16, j + 56, k + 12, Blocks.air, 0, 2);
		world.setBlock(i + 17, j + 56, k + 12, Blocks.air, 0, 2);
		world.setBlock(i + 18, j + 56, k + 12, Blocks.air, 0, 2);
		world.setBlock(i + 19, j + 56, k + 12, NovaCraftBlocks.basal_brick_stairs, 0, 2);
		world.setBlock(i + 20, j + 56, k + 12, NovaCraftBlocks.basal_scrap, 0, 2);
		world.setBlock(i + 21, j + 56, k + 12, NovaCraftBlocks.basal_scrap, 0, 2);
		world.setBlock(i + 22, j + 56, k + 12, NovaCraftBlocks.basal_brick_stairs, 1, 2);
		world.setBlock(i + 23, j + 56, k + 12, Blocks.air, 0, 2);
		world.setBlock(i + 24, j + 56, k + 12, Blocks.air, 0, 2);
		world.setBlock(i + 25, j + 56, k + 12, Blocks.air, 0, 2);
		world.setBlock(i + 26, j + 56, k + 12, Blocks.air, 0, 2);
		world.setBlock(i + 27, j + 56, k + 12, NovaCraftBlocks.basal_bricks, 0, 2);
		world.setBlock(i + 0, j + 57, k + 0, NovaCraftBlocks.basal_bricks, 0, 2);
		world.setBlock(i + 1, j + 57, k + 0, NovaCraftBlocks.basal_bricks, 0, 2);
		world.setBlock(i + 4, j + 57, k + 0, NovaCraftBlocks.basal_bricks, 0, 2);
		world.setBlock(i + 8, j + 57, k + 0, NovaCraftBlocks.basal_bricks, 0, 2);
		world.setBlock(i + 12, j + 57, k + 0, NovaCraftBlocks.basal_bricks, 0, 2);
		world.setBlock(i + 13, j + 57, k + 0, NovaCraftBlocks.basal_bricks, 0, 2);
		world.setBlock(i + 0, j + 57, k + 1, NovaCraftBlocks.basal_bricks, 0, 2);
		world.setBlock(i + 1, j + 57, k + 1, NovaCraftBlocks.basal_bricks, 0, 2);
		world.setBlock(i + 4, j + 57, k + 1, NovaCraftBlocks.basal_bricks, 0, 2);
		world.setBlock(i + 5, j + 57, k + 1, NovaCraftBlocks.basal_bricks, 0, 2);
		world.setBlock(i + 8, j + 57, k + 1, NovaCraftBlocks.basal_bricks, 0, 2);
		world.setBlock(i + 9, j + 57, k + 1, NovaCraftBlocks.basal_bricks, 0, 2);
		world.setBlock(i + 12, j + 57, k + 1, NovaCraftBlocks.basal_bricks, 0, 2);
		world.setBlock(i + 13, j + 57, k + 1, NovaCraftBlocks.basal_bricks, 0, 2);
		world.setBlock(i + 0, j + 57, k + 2, NovaCraftBlocks.basal_bricks, 0, 2);
		world.setBlock(i + 1, j + 57, k + 2, NovaCraftBlocks.basal_bricks, 0, 2);
		world.setBlock(i + 4, j + 57, k + 2, NovaCraftBlocks.basal_bricks, 0, 2);
		world.setBlock(i + 5, j + 57, k + 2, NovaCraftBlocks.basal_bricks, 0, 2);
		world.setBlock(i + 8, j + 57, k + 2, NovaCraftBlocks.basal_bricks, 0, 2);
		world.setBlock(i + 9, j + 57, k + 2, NovaCraftBlocks.basal_bricks, 0, 2);
		world.setBlock(i + 12, j + 57, k + 2, NovaCraftBlocks.basal_bricks, 0, 2);
		world.setBlock(i + 13, j + 57, k + 2, NovaCraftBlocks.basal_bricks, 0, 2);
		world.setBlock(i + 14, j + 57, k + 2, NovaCraftBlocks.basal_bricks, 0, 2);
		world.setBlock(i + 15, j + 57, k + 2, NovaCraftBlocks.basal_bricks, 0, 2);
		world.setBlock(i + 18, j + 57, k + 2, NovaCraftBlocks.basal_bricks, 0, 2);
		world.setBlock(i + 19, j + 57, k + 2, NovaCraftBlocks.basal_bricks, 0, 2);
		world.setBlock(i + 26, j + 57, k + 2, NovaCraftBlocks.basal_bricks, 0, 2);
		world.setBlock(i + 27, j + 57, k + 2, NovaCraftBlocks.basal_bricks, 0, 2);
		world.setBlock(i + 0, j + 57, k + 3, NovaCraftBlocks.basal_bricks, 0, 2);
		world.setBlock(i + 1, j + 57, k + 3, NovaCraftBlocks.basal_bricks, 0, 2);
		world.setBlock(i + 3, j + 57, k + 3, NovaCraftBlocks.block_of_vanite, 0, 2);
		world.setBlock(i + 4, j + 57, k + 3, NovaCraftBlocks.basal_bricks, 0, 2);
		world.setBlock(i + 5, j + 57, k + 3, NovaCraftBlocks.basal_bricks, 0, 2);
		world.setBlock(i + 8, j + 57, k + 3, NovaCraftBlocks.basal_bricks, 0, 2);
		world.setBlock(i + 9, j + 57, k + 3, NovaCraftBlocks.basal_bricks, 0, 2);
		world.setBlock(i + 12, j + 57, k + 3, NovaCraftBlocks.basal_bricks, 0, 2);
		world.setBlock(i + 13, j + 57, k + 3, NovaCraftBlocks.basal_bricks, 0, 2);
		world.setBlock(i + 14, j + 57, k + 3, NovaCraftBlocks.basal_bricks, 0, 2);
		world.setBlock(i + 15, j + 57, k + 3, NovaCraftBlocks.basal_bricks, 0, 2);
		world.setBlock(i + 18, j + 57, k + 3, NovaCraftBlocks.basal_bricks, 0, 2);
		world.setBlock(i + 19, j + 57, k + 3, NovaCraftBlocks.basal_bricks, 0, 2);
		world.setBlock(i + 22, j + 57, k + 3, NovaCraftBlocks.basal_bricks, 0, 2);
		world.setBlock(i + 26, j + 57, k + 3, NovaCraftBlocks.basal_bricks, 0, 2);
		world.setBlock(i + 27, j + 57, k + 3, NovaCraftBlocks.basal_bricks, 0, 2);
		world.setBlock(i + 0, j + 57, k + 4, NovaCraftBlocks.basal_bricks, 0, 2);
		world.setBlock(i + 1, j + 57, k + 4, NovaCraftBlocks.basal_bricks, 0, 2);
		world.setBlock(i + 2, j + 57, k + 4, NovaCraftBlocks.basal_bricks, 0, 2);
		world.setBlock(i + 3, j + 57, k + 4, NovaCraftBlocks.basal_bricks, 0, 2);
		world.setBlock(i + 4, j + 57, k + 4, NovaCraftBlocks.basal_bricks, 0, 2);
		world.setBlock(i + 5, j + 57, k + 4, NovaCraftBlocks.basal_bricks, 0, 2);
		world.setBlock(i + 6, j + 57, k + 4, NovaCraftBlocks.basal_bricks, 0, 2);
		world.setBlock(i + 7, j + 57, k + 4, NovaCraftBlocks.basal_bricks, 0, 2);
		world.setBlock(i + 8, j + 57, k + 4, NovaCraftBlocks.basal_bricks, 0, 2);
		world.setBlock(i + 9, j + 57, k + 4, NovaCraftBlocks.basal_bricks, 0, 2);
		world.setBlock(i + 10, j + 57, k + 4, NovaCraftBlocks.basal_bricks, 0, 2);
		world.setBlock(i + 11, j + 57, k + 4, NovaCraftBlocks.basal_bricks, 0, 2);
		world.setBlock(i + 12, j + 57, k + 4, NovaCraftBlocks.basal_bricks, 0, 2);
		world.setBlock(i + 13, j + 57, k + 4, NovaCraftBlocks.basal_bricks, 0, 2);
		world.setBlock(i + 14, j + 57, k + 4, NovaCraftBlocks.basal_bricks, 0, 2);
		world.setBlock(i + 15, j + 57, k + 4, NovaCraftBlocks.basal_bricks, 0, 2);
		world.setBlock(i + 16, j + 57, k + 4, NovaCraftBlocks.basal_bricks, 0, 2);
		world.setBlock(i + 17, j + 57, k + 4, NovaCraftBlocks.basal_bricks, 0, 2);
		world.setBlock(i + 18, j + 57, k + 4, NovaCraftBlocks.basal_bricks, 0, 2);
		world.setBlock(i + 19, j + 57, k + 4, NovaCraftBlocks.basal_bricks, 0, 2);
		world.setBlock(i + 20, j + 57, k + 4, NovaCraftBlocks.basal_bricks, 0, 2);
		world.setBlock(i + 21, j + 57, k + 4, NovaCraftBlocks.basal_bricks, 0, 2);
		world.setBlock(i + 22, j + 57, k + 4, NovaCraftBlocks.basal_bricks, 0, 2);
		world.setBlock(i + 23, j + 57, k + 4, NovaCraftBlocks.basal_bricks, 0, 2);
		world.setBlock(i + 24, j + 57, k + 4, NovaCraftBlocks.basal_bricks, 0, 2);
		world.setBlock(i + 25, j + 57, k + 4, Blocks.air, 0, 2);
		world.setBlock(i + 26, j + 57, k + 4, NovaCraftBlocks.basal_bricks, 0, 2);
		world.setBlock(i + 27, j + 57, k + 4, NovaCraftBlocks.basal_bricks, 0, 2);
		world.setBlock(i + 0, j + 57, k + 5, NovaCraftBlocks.basal_bricks, 0, 2);
		world.setBlock(i + 1, j + 57, k + 5, NovaCraftBlocks.basal_bricks, 0, 2);
		world.setBlock(i + 2, j + 57, k + 5, NovaCraftBlocks.basal_bricks, 0, 2);
		world.setBlock(i + 3, j + 57, k + 5, NovaCraftBlocks.basal_bricks, 0, 2);
		world.setBlock(i + 4, j + 57, k + 5, NovaCraftBlocks.basal_bricks, 0, 2);
		world.setBlock(i + 5, j + 57, k + 5, NovaCraftBlocks.basal_bricks, 0, 2);
		world.setBlock(i + 6, j + 57, k + 5, NovaCraftBlocks.basal_bricks, 0, 2);
		world.setBlock(i + 7, j + 57, k + 5, NovaCraftBlocks.basal_bricks, 0, 2);
		world.setBlock(i + 8, j + 57, k + 5, NovaCraftBlocks.basal_bricks, 0, 2);
		world.setBlock(i + 9, j + 57, k + 5, NovaCraftBlocks.basal_bricks, 0, 2);
		world.setBlock(i + 10, j + 57, k + 5, NovaCraftBlocks.basal_bricks, 0, 2);
		world.setBlock(i + 11, j + 57, k + 5, NovaCraftBlocks.basal_bricks, 0, 2);
		world.setBlock(i + 12, j + 57, k + 5, NovaCraftBlocks.basal_bricks, 0, 2);
		world.setBlock(i + 13, j + 57, k + 5, NovaCraftBlocks.basal_bricks, 0, 2);
		world.setBlock(i + 14, j + 57, k + 5, NovaCraftBlocks.basal_bricks, 0, 2);
		world.setBlock(i + 15, j + 57, k + 5, NovaCraftBlocks.basal_bricks, 0, 2);
		world.setBlock(i + 16, j + 57, k + 5, NovaCraftBlocks.basal_bricks, 0, 2);
		world.setBlock(i + 17, j + 57, k + 5, NovaCraftBlocks.basal_bricks, 0, 2);
		world.setBlock(i + 18, j + 57, k + 5, NovaCraftBlocks.basal_bricks, 0, 2);
		world.setBlock(i + 19, j + 57, k + 5, NovaCraftBlocks.basal_bricks, 0, 2);
		world.setBlock(i + 20, j + 57, k + 5, NovaCraftBlocks.basal_bricks, 0, 2);
		world.setBlock(i + 21, j + 57, k + 5, NovaCraftBlocks.basal_bricks, 0, 2);
		world.setBlock(i + 22, j + 57, k + 5, NovaCraftBlocks.basal_bricks, 0, 2);
		world.setBlock(i + 23, j + 57, k + 5, NovaCraftBlocks.basal_bricks, 0, 2);
		world.setBlock(i + 24, j + 57, k + 5, NovaCraftBlocks.basal_bricks, 0, 2);
		world.setBlock(i + 25, j + 57, k + 5, NovaCraftBlocks.basal_bricks, 0, 2);
		world.setBlock(i + 26, j + 57, k + 5, NovaCraftBlocks.basal_bricks, 0, 2);
		world.setBlock(i + 27, j + 57, k + 5, NovaCraftBlocks.basal_bricks, 0, 2);
		world.setBlock(i + 0, j + 57, k + 6, NovaCraftBlocks.basal_bricks, 0, 2);
		world.setBlock(i + 1, j + 57, k + 6, NovaCraftBlocks.basal_bricks, 0, 2);
		world.setBlock(i + 2, j + 57, k + 6, NovaCraftBlocks.basal_bricks, 0, 2);
		world.setBlock(i + 3, j + 57, k + 6, NovaCraftBlocks.basal_bricks, 0, 2);
		world.setBlock(i + 4, j + 57, k + 6, NovaCraftBlocks.basal_bricks, 0, 2);
		world.setBlock(i + 5, j + 57, k + 6, NovaCraftBlocks.basal_bricks, 0, 2);
		world.setBlock(i + 6, j + 57, k + 6, NovaCraftBlocks.basal_bricks, 0, 2);
		world.setBlock(i + 7, j + 57, k + 6, Blocks.air, 0, 2);
		world.setBlock(i + 8, j + 57, k + 6, NovaCraftBlocks.basal_bricks, 0, 2);
		world.setBlock(i + 9, j + 57, k + 6, NovaCraftBlocks.basal_bricks, 0, 2);
		world.setBlock(i + 10, j + 57, k + 6, NovaCraftBlocks.basal_bricks, 0, 2);
		world.setBlock(i + 11, j + 57, k + 6, NovaCraftBlocks.basal_bricks, 0, 2);
		world.setBlock(i + 12, j + 57, k + 6, NovaCraftBlocks.basal_bricks, 0, 2);
		world.setBlock(i + 13, j + 57, k + 6, NovaCraftBlocks.basal_bricks, 0, 2);
		world.setBlock(i + 14, j + 57, k + 6, NovaCraftBlocks.basal_bricks, 0, 2);
		world.setBlock(i + 15, j + 57, k + 6, NovaCraftBlocks.basal_bricks, 0, 2);
		world.setBlock(i + 16, j + 57, k + 6, NovaCraftBlocks.basal_bricks, 0, 2);
		world.setBlock(i + 17, j + 57, k + 6, NovaCraftBlocks.basal_bricks, 0, 2);
		world.setBlock(i + 18, j + 57, k + 6, NovaCraftBlocks.basal_bricks, 0, 2);
		world.setBlock(i + 19, j + 57, k + 6, NovaCraftBlocks.basal_bricks, 0, 2);
		world.setBlock(i + 20, j + 57, k + 6, NovaCraftBlocks.basal_bricks, 0, 2);
		world.setBlock(i + 21, j + 57, k + 6, Blocks.air, 0, 2);
		world.setBlock(i + 22, j + 57, k + 6, NovaCraftBlocks.basal_bricks, 0, 2);
		world.setBlock(i + 23, j + 57, k + 6, NovaCraftBlocks.basal_bricks, 0, 2);
		world.setBlock(i + 24, j + 57, k + 6, NovaCraftBlocks.basal_bricks, 0, 2);
		world.setBlock(i + 25, j + 57, k + 6, NovaCraftBlocks.basal_bricks, 0, 2);
		world.setBlock(i + 26, j + 57, k + 6, NovaCraftBlocks.basal_bricks, 0, 2);
		world.setBlock(i + 27, j + 57, k + 6, NovaCraftBlocks.basal_bricks, 0, 2);
		world.setBlock(i + 0, j + 57, k + 7, NovaCraftBlocks.basal_bricks, 0, 2);
		world.setBlock(i + 1, j + 57, k + 7, NovaCraftBlocks.basal_bricks, 0, 2);
		world.setBlock(i + 2, j + 57, k + 7, NovaCraftBlocks.basal_bricks, 0, 2);
		world.setBlock(i + 3, j + 57, k + 7, NovaCraftBlocks.basal_bricks, 0, 2);
		world.setBlock(i + 4, j + 57, k + 7, NovaCraftBlocks.basal_bricks, 0, 2);
		world.setBlock(i + 5, j + 57, k + 7, NovaCraftBlocks.basal_bricks, 0, 2);
		world.setBlock(i + 6, j + 57, k + 7, NovaCraftBlocks.basal_bricks, 0, 2);
		world.setBlock(i + 7, j + 57, k + 7, NovaCraftBlocks.basal_bricks, 0, 2);
		world.setBlock(i + 8, j + 57, k + 7, NovaCraftBlocks.basal_bricks, 0, 2);
		world.setBlock(i + 9, j + 57, k + 7, NovaCraftBlocks.basal_bricks, 0, 2);
		world.setBlock(i + 10, j + 57, k + 7, NovaCraftBlocks.basal_bricks, 0, 2);
		world.setBlock(i + 11, j + 57, k + 7, NovaCraftBlocks.basal_bricks, 0, 2);
		world.setBlock(i + 12, j + 57, k + 7, NovaCraftBlocks.basal_bricks, 0, 2);
		world.setBlock(i + 13, j + 57, k + 7, NovaCraftBlocks.basal_bricks, 0, 2);
		world.setBlock(i + 14, j + 57, k + 7, NovaCraftBlocks.basal_bricks, 0, 2);
		world.setBlock(i + 15, j + 57, k + 7, NovaCraftBlocks.basal_bricks, 0, 2);
		world.setBlock(i + 16, j + 57, k + 7, NovaCraftBlocks.basal_bricks, 0, 2);
		world.setBlock(i + 17, j + 57, k + 7, NovaCraftBlocks.basal_bricks, 0, 2);
		world.setBlock(i + 18, j + 57, k + 7, NovaCraftBlocks.basal_bricks, 0, 2);
		world.setBlock(i + 19, j + 57, k + 7, NovaCraftBlocks.basal_bricks, 0, 2);
		world.setBlock(i + 20, j + 57, k + 7, NovaCraftBlocks.basal_bricks, 0, 2);
		world.setBlock(i + 21, j + 57, k + 7, NovaCraftBlocks.basal_bricks, 0, 2);
		world.setBlock(i + 22, j + 57, k + 7, NovaCraftBlocks.basal_bricks, 0, 2);
		world.setBlock(i + 23, j + 57, k + 7, NovaCraftBlocks.basal_bricks, 0, 2);
		world.setBlock(i + 24, j + 57, k + 7, Blocks.air, 0, 2);
		world.setBlock(i + 25, j + 57, k + 7, NovaCraftBlocks.basal_bricks, 0, 2);
		world.setBlock(i + 26, j + 57, k + 7, NovaCraftBlocks.basal_bricks, 0, 2);
		world.setBlock(i + 27, j + 57, k + 7, NovaCraftBlocks.basal_bricks, 0, 2);
		world.setBlock(i + 0, j + 57, k + 8, NovaCraftBlocks.basal_bricks, 0, 2);
		world.setBlock(i + 1, j + 57, k + 8, NovaCraftBlocks.basal_bricks, 0, 2);
		world.setBlock(i + 2, j + 57, k + 8, NovaCraftBlocks.basal_bricks, 0, 2);
		world.setBlock(i + 3, j + 57, k + 8, NovaCraftBlocks.basal_bricks, 0, 2);
		world.setBlock(i + 4, j + 57, k + 8, NovaCraftBlocks.basal_bricks, 0, 2);
		world.setBlock(i + 5, j + 57, k + 8, NovaCraftBlocks.basal_bricks, 0, 2);
		world.setBlock(i + 6, j + 57, k + 8, Blocks.air, 0, 2);
		world.setBlock(i + 7, j + 57, k + 8, NovaCraftBlocks.basal_brick_stairs, 3, 2);
		world.setBlock(i + 8, j + 57, k + 8, NovaCraftBlocks.basal_bricks, 0, 2);
		world.setBlock(i + 9, j + 57, k + 8, NovaCraftBlocks.basal_bricks, 0, 2);
		world.setBlock(i + 10, j + 57, k + 8, NovaCraftBlocks.basal_bricks, 0, 2);
		world.setBlock(i + 11, j + 57, k + 8, NovaCraftBlocks.basal_bricks, 0, 2);
		world.setBlock(i + 12, j + 57, k + 8, NovaCraftBlocks.basal_bricks, 0, 2);
		world.setBlock(i + 13, j + 57, k + 8, NovaCraftBlocks.basal, 0, 2);
		world.setBlock(i + 14, j + 57, k + 8, NovaCraftBlocks.basal_bricks, 0, 2);
		world.setBlock(i + 15, j + 57, k + 8, NovaCraftBlocks.basal_bricks, 0, 2);
		world.setBlock(i + 16, j + 57, k + 8, NovaCraftBlocks.basal_bricks, 0, 2);
		world.setBlock(i + 17, j + 57, k + 8, NovaCraftBlocks.basal_bricks, 0, 2);
		world.setBlock(i + 18, j + 57, k + 8, NovaCraftBlocks.basal_bricks, 0, 2);
		world.setBlock(i + 19, j + 57, k + 8, NovaCraftBlocks.basal_bricks, 0, 2);
		world.setBlock(i + 20, j + 57, k + 8, NovaCraftBlocks.basal_bricks, 0, 2);
		world.setBlock(i + 21, j + 57, k + 8, NovaCraftBlocks.basal_bricks, 0, 2);
		world.setBlock(i + 22, j + 57, k + 8, NovaCraftBlocks.basal_bricks, 0, 2);
		world.setBlock(i + 23, j + 57, k + 8, NovaCraftBlocks.basal_bricks, 0, 2);
		world.setBlock(i + 24, j + 57, k + 8, NovaCraftBlocks.basal_bricks, 0, 2);
		world.setBlock(i + 25, j + 57, k + 8, NovaCraftBlocks.basal_bricks, 0, 2);
		world.setBlock(i + 26, j + 57, k + 8, NovaCraftBlocks.basal_bricks, 0, 2);
		world.setBlock(i + 27, j + 57, k + 8, NovaCraftBlocks.basal_bricks, 0, 2);
		world.setBlock(i + 0, j + 57, k + 9, NovaCraftBlocks.basal_bricks, 0, 2);
		world.setBlock(i + 1, j + 57, k + 9, NovaCraftBlocks.basal_bricks, 0, 2);
		world.setBlock(i + 2, j + 57, k + 9, NovaCraftBlocks.basal_bricks, 0, 2);
		world.setBlock(i + 3, j + 57, k + 9, NovaCraftBlocks.basal_bricks, 0, 2);
		world.setBlock(i + 4, j + 57, k + 9, NovaCraftBlocks.basal_bricks, 0, 2);
		world.setBlock(i + 5, j + 57, k + 9, NovaCraftBlocks.basal_bricks, 0, 2);
		world.setBlock(i + 6, j + 57, k + 9, Blocks.air, 0, 2);
		world.setBlock(i + 7, j + 57, k + 9, Blocks.air, 0, 2);
		world.setBlock(i + 8, j + 57, k + 9, NovaCraftBlocks.basal_bricks, 0, 2);
		world.setBlock(i + 9, j + 57, k + 9, NovaCraftBlocks.basal_bricks, 0, 2);
		world.setBlock(i + 10, j + 57, k + 9, NovaCraftBlocks.basal_bricks, 0, 2);
		world.setBlock(i + 11, j + 57, k + 9, NovaCraftBlocks.basal_bricks, 0, 2);
		world.setBlock(i + 12, j + 57, k + 9, NovaCraftBlocks.basal_bricks, 0, 2);
		world.setBlock(i + 13, j + 57, k + 9, NovaCraftBlocks.basal_bricks, 0, 2);
		world.setBlock(i + 14, j + 57, k + 9, NovaCraftBlocks.basal_bricks, 0, 2);
		world.setBlock(i + 15, j + 57, k + 9, NovaCraftBlocks.basal_bricks, 0, 2);
		world.setBlock(i + 16, j + 57, k + 9, NovaCraftBlocks.basal_bricks, 0, 2);
		world.setBlock(i + 17, j + 57, k + 9, NovaCraftBlocks.basal_bricks, 0, 2);
		world.setBlock(i + 18, j + 57, k + 9, NovaCraftBlocks.basal_bricks, 0, 2);
		world.setBlock(i + 19, j + 57, k + 9, NovaCraftBlocks.basal_bricks, 0, 2);
		world.setBlock(i + 20, j + 57, k + 9, NovaCraftBlocks.basal_bricks, 0, 2);
		world.setBlock(i + 21, j + 57, k + 9, NovaCraftBlocks.basal_bricks, 0, 2);
		world.setBlock(i + 22, j + 57, k + 9, NovaCraftBlocks.basal_bricks, 0, 2);
		world.setBlock(i + 23, j + 57, k + 9, NovaCraftBlocks.basal_bricks, 0, 2);
		world.setBlock(i + 24, j + 57, k + 9, NovaCraftBlocks.basal_bricks, 0, 2);
		world.setBlock(i + 25, j + 57, k + 9, NovaCraftBlocks.basal_bricks, 0, 2);
		world.setBlock(i + 26, j + 57, k + 9, NovaCraftBlocks.basal_bricks, 0, 2);
		world.setBlock(i + 27, j + 57, k + 9, NovaCraftBlocks.basal_bricks, 0, 2);
		world.setBlock(i + 0, j + 57, k + 10, NovaCraftBlocks.basal_bricks, 0, 2);
		world.setBlock(i + 1, j + 57, k + 10, NovaCraftBlocks.basal_bricks, 0, 2);
		world.setBlock(i + 2, j + 57, k + 10, NovaCraftBlocks.basal_bricks, 0, 2);
		world.setBlock(i + 3, j + 57, k + 10, NovaCraftBlocks.basal_bricks, 0, 2);
		world.setBlock(i + 4, j + 57, k + 10, Blocks.air, 0, 2);
		world.setBlock(i + 5, j + 57, k + 10, Blocks.air, 0, 2);
		world.setBlock(i + 6, j + 57, k + 10, Blocks.air, 0, 2);
		world.setBlock(i + 7, j + 57, k + 10, Blocks.air, 0, 2);
		world.setBlock(i + 8, j + 57, k + 10, Blocks.air, 0, 2);
		world.setBlock(i + 9, j + 57, k + 10, Blocks.air, 0, 2);
		world.setBlock(i + 10, j + 57, k + 10, NovaCraftBlocks.basal_bricks, 0, 2);
		world.setBlock(i + 11, j + 57, k + 10, NovaCraftBlocks.basal_bricks, 0, 2);
		world.setBlock(i + 12, j + 57, k + 10, NovaCraftBlocks.basal_bricks, 0, 2);
		world.setBlock(i + 13, j + 57, k + 10, NovaCraftBlocks.basal_bricks, 0, 2);
		world.setBlock(i + 14, j + 57, k + 10, NovaCraftBlocks.basal_bricks, 0, 2);
		world.setBlock(i + 15, j + 57, k + 10, NovaCraftBlocks.basal_bricks, 0, 2);
		world.setBlock(i + 16, j + 57, k + 10, NovaCraftBlocks.basal_bricks, 0, 2);
		world.setBlock(i + 17, j + 57, k + 10, NovaCraftBlocks.basal_bricks, 0, 2);
		world.setBlock(i + 18, j + 57, k + 10, NovaCraftBlocks.basal_bricks, 0, 2);
		world.setBlock(i + 19, j + 57, k + 10, NovaCraftBlocks.basal_bricks, 0, 2);
		world.setBlock(i + 20, j + 57, k + 10, NovaCraftBlocks.basal_bricks, 0, 2);
		world.setBlock(i + 21, j + 57, k + 10, NovaCraftBlocks.basal_bricks, 0, 2);
		world.setBlock(i + 22, j + 57, k + 10, NovaCraftBlocks.basal_bricks, 0, 2);
		world.setBlock(i + 23, j + 57, k + 10, NovaCraftBlocks.basal_bricks, 0, 2);
		world.setBlock(i + 24, j + 57, k + 10, NovaCraftBlocks.basal_bricks, 0, 2);
		world.setBlock(i + 25, j + 57, k + 10, NovaCraftBlocks.basal_bricks, 0, 2);
		world.setBlock(i + 26, j + 57, k + 10, Blocks.air, 0, 2);
		world.setBlock(i + 27, j + 57, k + 10, NovaCraftBlocks.basal_bricks, 0, 2);
		world.setBlock(i + 0, j + 57, k + 11, Blocks.air, 0, 2);
		world.setBlock(i + 1, j + 57, k + 11, Blocks.air, 0, 2);
		world.setBlock(i + 2, j + 57, k + 11, Blocks.air, 0, 2);
		world.setBlock(i + 3, j + 57, k + 11, Blocks.air, 0, 2);
		world.setBlock(i + 4, j + 57, k + 11, Blocks.air, 0, 2);
		world.setBlock(i + 5, j + 57, k + 11, Blocks.air, 0, 2);
		world.setBlock(i + 6, j + 57, k + 11, Blocks.air, 0, 2);
		world.setBlock(i + 7, j + 57, k + 11, Blocks.air, 0, 2);
		world.setBlock(i + 8, j + 57, k + 11, Blocks.air, 0, 2);
		world.setBlock(i + 9, j + 57, k + 11, Blocks.air, 0, 2);
		world.setBlock(i + 10, j + 57, k + 11, Blocks.air, 0, 2);
		world.setBlock(i + 11, j + 57, k + 11, Blocks.air, 0, 2);
		world.setBlock(i + 12, j + 57, k + 11, Blocks.air, 0, 2);
		world.setBlock(i + 13, j + 57, k + 11, Blocks.air, 0, 2);
		world.setBlock(i + 14, j + 57, k + 11, Blocks.air, 0, 2);
		world.setBlock(i + 15, j + 57, k + 11, NovaCraftBlocks.basal_bricks, 0, 2);
		world.setBlock(i + 16, j + 57, k + 11, NovaCraftBlocks.basal_bricks, 0, 2);
		world.setBlock(i + 17, j + 57, k + 11, NovaCraftBlocks.basal_bricks, 0, 2);
		world.setBlock(i + 18, j + 57, k + 11, NovaCraftBlocks.basal_bricks, 0, 2);
		world.setBlock(i + 19, j + 57, k + 11, NovaCraftBlocks.basal_bricks, 0, 2);
		world.setBlock(i + 20, j + 57, k + 11, NovaCraftBlocks.basal_brick_stairs, 3, 2);
		world.setBlock(i + 21, j + 57, k + 11, NovaCraftBlocks.basal_brick_stairs, 3, 2);
		world.setBlock(i + 22, j + 57, k + 11, NovaCraftBlocks.basal_bricks, 0, 2);
		world.setBlock(i + 23, j + 57, k + 11, NovaCraftBlocks.basal_bricks, 0, 2);
		world.setBlock(i + 24, j + 57, k + 11, NovaCraftBlocks.basal_bricks, 0, 2);
		world.setBlock(i + 25, j + 57, k + 11, NovaCraftBlocks.basal_bricks, 0, 2);
		world.setBlock(i + 26, j + 57, k + 11, NovaCraftBlocks.basal_bricks, 0, 2);
		world.setBlock(i + 27, j + 57, k + 11, NovaCraftBlocks.basal_bricks, 0, 2);
		world.setBlock(i + 0, j + 57, k + 12, Blocks.air, 0, 2);
		world.setBlock(i + 1, j + 57, k + 12, Blocks.air, 0, 2);
		world.setBlock(i + 2, j + 57, k + 12, Blocks.air, 0, 2);
		world.setBlock(i + 3, j + 57, k + 12, Blocks.air, 0, 2);
		world.setBlock(i + 4, j + 57, k + 12, Blocks.air, 0, 2);
		world.setBlock(i + 5, j + 57, k + 12, Blocks.air, 0, 2);
		world.setBlock(i + 6, j + 57, k + 12, Blocks.air, 0, 2);
		world.setBlock(i + 7, j + 57, k + 12, Blocks.air, 0, 2);
		world.setBlock(i + 8, j + 57, k + 12, Blocks.air, 0, 2);
		world.setBlock(i + 9, j + 57, k + 12, Blocks.air, 0, 2);
		world.setBlock(i + 10, j + 57, k + 12, Blocks.air, 0, 2);
		world.setBlock(i + 11, j + 57, k + 12, Blocks.air, 0, 2);
		world.setBlock(i + 12, j + 57, k + 12, Blocks.air, 0, 2);
		world.setBlock(i + 13, j + 57, k + 12, Blocks.air, 0, 2);
		world.setBlock(i + 14, j + 57, k + 12, NovaCraftBlocks.basal_bricks, 0, 2);
		world.setBlock(i + 15, j + 57, k + 12, NovaCraftBlocks.basal_bricks, 0, 2);
		world.setBlock(i + 16, j + 57, k + 12, Blocks.air, 0, 2);
		world.setBlock(i + 17, j + 57, k + 12, Blocks.air, 0, 2);
		world.setBlock(i + 18, j + 57, k + 12, Blocks.air, 0, 2);
		world.setBlock(i + 19, j + 57, k + 12, Blocks.air, 0, 2);
		world.setBlock(i + 20, j + 57, k + 12, Blocks.air, 0, 2);
		world.setBlock(i + 21, j + 57, k + 12, Blocks.air, 0, 2);
		world.setBlock(i + 22, j + 57, k + 12, Blocks.air, 0, 2);
		world.setBlock(i + 23, j + 57, k + 12, Blocks.air, 0, 2);
		world.setBlock(i + 24, j + 57, k + 12, Blocks.air, 0, 2);
		world.setBlock(i + 25, j + 57, k + 12, Blocks.air, 0, 2);
		world.setBlock(i + 26, j + 57, k + 12, NovaCraftBlocks.basal_bricks, 0, 2);
		world.setBlock(i + 27, j + 57, k + 12, NovaCraftBlocks.basal_bricks, 0, 2);
		world.setBlock(i + 0, j + 58, k + 0, NovaCraftBlocks.basal_bricks, 0, 2);
		world.setBlock(i + 1, j + 58, k + 0, NovaCraftBlocks.basal_bricks, 0, 2);
		world.setBlock(i + 5, j + 58, k + 0, NovaCraftBlocks.basal_bricks, 0, 2);
		world.setBlock(i + 8, j + 58, k + 0, NovaCraftBlocks.basal_bricks, 0, 2);
		world.setBlock(i + 9, j + 58, k + 0, NovaCraftBlocks.basal_bricks, 0, 2);
		world.setBlock(i + 12, j + 58, k + 0, NovaCraftBlocks.basal_bricks, 0, 2);
		world.setBlock(i + 13, j + 58, k + 0, NovaCraftBlocks.basal_bricks, 0, 2);
		world.setBlock(i + 0, j + 58, k + 1, NovaCraftBlocks.basal_bricks, 0, 2);
		world.setBlock(i + 1, j + 58, k + 1, NovaCraftBlocks.basal_bricks, 0, 2);
		world.setBlock(i + 4, j + 58, k + 1, NovaCraftBlocks.basal_bricks, 0, 2);
		world.setBlock(i + 5, j + 58, k + 1, NovaCraftBlocks.basal_bricks, 0, 2);
		world.setBlock(i + 8, j + 58, k + 1, NovaCraftBlocks.basal_bricks, 0, 2);
		world.setBlock(i + 9, j + 58, k + 1, NovaCraftBlocks.basal_bricks, 0, 2);
		world.setBlock(i + 12, j + 58, k + 1, NovaCraftBlocks.basal_bricks, 0, 2);
		world.setBlock(i + 13, j + 58, k + 1, NovaCraftBlocks.basal_bricks, 0, 2);
		world.setBlock(i + 0, j + 58, k + 2, NovaCraftBlocks.basal_bricks, 0, 2);
		world.setBlock(i + 1, j + 58, k + 2, NovaCraftBlocks.basal_bricks, 0, 2);
		world.setBlock(i + 2, j + 58, k + 2, NovaCraftBlocks.basal_bricks, 0, 2);
		world.setBlock(i + 3, j + 58, k + 2, NovaCraftBlocks.basal_bricks, 0, 2);
		world.setBlock(i + 4, j + 58, k + 2, NovaCraftBlocks.basal_bricks, 0, 2);
		world.setBlock(i + 5, j + 58, k + 2, NovaCraftBlocks.basal_bricks, 0, 2);
		world.setBlock(i + 6, j + 58, k + 2, NovaCraftBlocks.basal_bricks, 0, 2);
		world.setBlock(i + 7, j + 58, k + 2, NovaCraftBlocks.basal_bricks, 0, 2);
		world.setBlock(i + 8, j + 58, k + 2, NovaCraftBlocks.basal_bricks, 0, 2);
		world.setBlock(i + 9, j + 58, k + 2, NovaCraftBlocks.basal_bricks, 0, 2);
		world.setBlock(i + 10, j + 58, k + 2, NovaCraftBlocks.basal_bricks, 0, 2);
		world.setBlock(i + 11, j + 58, k + 2, NovaCraftBlocks.basal_bricks, 0, 2);
		world.setBlock(i + 12, j + 58, k + 2, NovaCraftBlocks.basal_bricks, 0, 2);
		world.setBlock(i + 13, j + 58, k + 2, NovaCraftBlocks.basal_bricks, 0, 2);
		world.setBlock(i + 14, j + 58, k + 2, NovaCraftBlocks.basal_bricks, 0, 2);
		world.setBlock(i + 15, j + 58, k + 2, NovaCraftBlocks.basal_bricks, 0, 2);
		world.setBlock(i + 18, j + 58, k + 2, NovaCraftBlocks.basal_bricks, 0, 2);
		world.setBlock(i + 22, j + 58, k + 2, NovaCraftBlocks.basal_bricks, 0, 2);
		world.setBlock(i + 26, j + 58, k + 2, NovaCraftBlocks.basal_bricks, 0, 2);
		world.setBlock(i + 0, j + 58, k + 3, NovaCraftBlocks.basal_bricks, 0, 2);
		world.setBlock(i + 1, j + 58, k + 3, NovaCraftBlocks.basal_bricks, 0, 2);
		world.setBlock(i + 2, j + 58, k + 3, NovaCraftBlocks.basal_bricks, 0, 2);
		world.setBlock(i + 3, j + 58, k + 3, NovaCraftBlocks.basal_bricks, 0, 2);
		world.setBlock(i + 4, j + 58, k + 3, NovaCraftBlocks.basal_bricks, 0, 2);
		world.setBlock(i + 6, j + 58, k + 3, NovaCraftBlocks.basal_bricks, 0, 2);
		world.setBlock(i + 7, j + 58, k + 3, NovaCraftBlocks.basal_bricks, 0, 2);
		world.setBlock(i + 8, j + 58, k + 3, NovaCraftBlocks.basal_bricks, 0, 2);
		world.setBlock(i + 9, j + 58, k + 3, NovaCraftBlocks.basal_bricks, 0, 2);
		world.setBlock(i + 10, j + 58, k + 3, NovaCraftBlocks.basal_bricks, 0, 2);
		world.setBlock(i + 11, j + 58, k + 3, NovaCraftBlocks.basal_bricks, 0, 2);
		world.setBlock(i + 12, j + 58, k + 3, NovaCraftBlocks.basal_bricks, 0, 2);
		world.setBlock(i + 13, j + 58, k + 3, NovaCraftBlocks.basal_bricks, 0, 2);
		world.setBlock(i + 14, j + 58, k + 3, NovaCraftBlocks.basal_bricks, 0, 2);
		world.setBlock(i + 15, j + 58, k + 3, NovaCraftBlocks.basal_bricks, 0, 2);
		world.setBlock(i + 18, j + 58, k + 3, NovaCraftBlocks.basal_bricks, 0, 2);
		world.setBlock(i + 19, j + 58, k + 3, NovaCraftBlocks.basal_bricks, 0, 2);
		world.setBlock(i + 22, j + 58, k + 3, NovaCraftBlocks.basal_bricks, 0, 2);
		world.setBlock(i + 23, j + 58, k + 3, NovaCraftBlocks.basal_bricks, 0, 2);
		world.setBlock(i + 26, j + 58, k + 3, NovaCraftBlocks.basal_bricks, 0, 2);
		world.setBlock(i + 27, j + 58, k + 3, NovaCraftBlocks.basal_bricks, 0, 2);
		world.setBlock(i + 0, j + 58, k + 4, NovaCraftBlocks.basal_bricks, 0, 2);
		world.setBlock(i + 1, j + 58, k + 4, NovaCraftBlocks.basal_bricks, 0, 2);
		world.setBlock(i + 2, j + 58, k + 4, NovaCraftBlocks.basal_bricks, 0, 2);
		world.setBlock(i + 3, j + 58, k + 4, NovaCraftBlocks.basal_bricks, 0, 2);
		world.setBlock(i + 4, j + 58, k + 4, NovaCraftBlocks.basal_bricks, 0, 2);
		world.setBlock(i + 5, j + 58, k + 4, NovaCraftBlocks.basal_bricks, 0, 2);
		world.setBlock(i + 6, j + 58, k + 4, NovaCraftBlocks.basal_bricks, 0, 2);
		world.setBlock(i + 7, j + 58, k + 4, NovaCraftBlocks.basal_bricks, 0, 2);
		world.setBlock(i + 8, j + 58, k + 4, NovaCraftBlocks.basal_bricks, 0, 2);
		world.setBlock(i + 9, j + 58, k + 4, NovaCraftBlocks.basal_bricks, 0, 2);
		world.setBlock(i + 10, j + 58, k + 4, NovaCraftBlocks.basal_bricks, 0, 2);
		world.setBlock(i + 11, j + 58, k + 4, NovaCraftBlocks.basal_bricks, 0, 2);
		world.setBlock(i + 12, j + 58, k + 4, NovaCraftBlocks.basal_bricks, 0, 2);
		world.setBlock(i + 13, j + 58, k + 4, NovaCraftBlocks.basal_bricks, 0, 2);
		world.setBlock(i + 14, j + 58, k + 4, NovaCraftBlocks.basal_bricks, 0, 2);
		world.setBlock(i + 15, j + 58, k + 4, NovaCraftBlocks.basal_bricks, 0, 2);
		world.setBlock(i + 16, j + 58, k + 4, Blocks.air, 0, 2);
		world.setBlock(i + 17, j + 58, k + 4, Blocks.air, 0, 2);
		world.setBlock(i + 18, j + 58, k + 4, NovaCraftBlocks.basal_bricks, 0, 2);
		world.setBlock(i + 19, j + 58, k + 4, NovaCraftBlocks.basal_bricks, 0, 2);
		world.setBlock(i + 20, j + 58, k + 4, Blocks.air, 0, 2);
		world.setBlock(i + 21, j + 58, k + 4, Blocks.air, 0, 2);
		world.setBlock(i + 22, j + 58, k + 4, NovaCraftBlocks.basal_bricks, 0, 2);
		world.setBlock(i + 23, j + 58, k + 4, NovaCraftBlocks.basal_bricks, 0, 2);
		world.setBlock(i + 24, j + 58, k + 4, Blocks.air, 0, 2);
		world.setBlock(i + 25, j + 58, k + 4, Blocks.air, 0, 2);
		world.setBlock(i + 26, j + 58, k + 4, NovaCraftBlocks.basal_bricks, 0, 2);
		world.setBlock(i + 27, j + 58, k + 4, NovaCraftBlocks.basal_bricks, 0, 2);
		world.setBlock(i + 0, j + 58, k + 5, NovaCraftBlocks.basal_bricks, 0, 2);
		world.setBlock(i + 1, j + 58, k + 5, NovaCraftBlocks.basal_bricks, 0, 2);
		world.setBlock(i + 2, j + 58, k + 5, NovaCraftBlocks.basal_bricks, 0, 2);
		world.setBlock(i + 3, j + 58, k + 5, NovaCraftBlocks.basal_bricks, 0, 2);
		world.setBlock(i + 4, j + 58, k + 5, Blocks.air, 0, 2);
		world.setBlock(i + 5, j + 58, k + 5, NovaCraftBlocks.basal_bricks, 0, 2);
		world.setBlock(i + 6, j + 58, k + 5, NovaCraftBlocks.basal_bricks, 0, 2);
		world.setBlock(i + 7, j + 58, k + 5, NovaCraftBlocks.basal_bricks, 0, 2);
		world.setBlock(i + 8, j + 58, k + 5, NovaCraftBlocks.basal_bricks, 0, 2);
		world.setBlock(i + 9, j + 58, k + 5, NovaCraftBlocks.basal_bricks, 0, 2);
		world.setBlock(i + 10, j + 58, k + 5, NovaCraftBlocks.basal_bricks, 0, 2);
		world.setBlock(i + 11, j + 58, k + 5, NovaCraftBlocks.basal_bricks, 0, 2);
		world.setBlock(i + 12, j + 58, k + 5, Blocks.air, 0, 2);
		world.setBlock(i + 13, j + 58, k + 5, NovaCraftBlocks.basal, 0, 2);
		world.setBlock(i + 14, j + 58, k + 5, NovaCraftBlocks.basal_bricks, 0, 2);
		world.setBlock(i + 15, j + 58, k + 5, NovaCraftBlocks.basal_bricks, 0, 2);
		world.setBlock(i + 16, j + 58, k + 5, Blocks.air, 0, 2);
		world.setBlock(i + 17, j + 58, k + 5, NovaCraftBlocks.block_of_vanite, 0, 2);
		world.setBlock(i + 18, j + 58, k + 5, NovaCraftBlocks.basal_bricks, 0, 2);
		world.setBlock(i + 19, j + 58, k + 5, NovaCraftBlocks.basal_bricks, 0, 2);
		world.setBlock(i + 20, j + 58, k + 5, Blocks.air, 0, 2);
		world.setBlock(i + 21, j + 58, k + 5, Blocks.air, 0, 2);
		world.setBlock(i + 22, j + 58, k + 5, NovaCraftBlocks.basal_bricks, 0, 2);
		world.setBlock(i + 23, j + 58, k + 5, NovaCraftBlocks.basal_bricks, 0, 2);
		world.setBlock(i + 24, j + 58, k + 5, Blocks.air, 0, 2);
		world.setBlock(i + 25, j + 58, k + 5, Blocks.air, 0, 2);
		world.setBlock(i + 26, j + 58, k + 5, NovaCraftBlocks.basal_bricks, 0, 2);
		world.setBlock(i + 27, j + 58, k + 5, NovaCraftBlocks.basal_bricks, 0, 2);
		world.setBlock(i + 0, j + 58, k + 6, NovaCraftBlocks.basal_bricks, 0, 2);
		world.setBlock(i + 1, j + 58, k + 6, NovaCraftBlocks.basal_bricks, 0, 2);
		world.setBlock(i + 2, j + 58, k + 6, Blocks.air, 0, 2);
		world.setBlock(i + 3, j + 58, k + 6, NovaCraftBlocks.basal_bricks, 0, 2);
		world.setBlock(i + 4, j + 58, k + 6, NovaCraftBlocks.basal_bricks, 0, 2);
		world.setBlock(i + 5, j + 58, k + 6, NovaCraftBlocks.basal_bricks, 0, 2);
		world.setBlock(i + 6, j + 58, k + 6, NovaCraftBlocks.basal_bricks, 0, 2);
		world.setBlock(i + 7, j + 58, k + 6, Blocks.air, 0, 2);
		world.setBlock(i + 8, j + 58, k + 6, NovaCraftBlocks.basal_bricks, 0, 2);
		world.setBlock(i + 9, j + 58, k + 6, NovaCraftBlocks.basal_bricks, 0, 2);
		world.setBlock(i + 10, j + 58, k + 6, NovaCraftBlocks.basal_bricks, 0, 2);
		world.setBlock(i + 11, j + 58, k + 6, NovaCraftBlocks.basal_bricks, 0, 2);
		world.setBlock(i + 12, j + 58, k + 6, NovaCraftBlocks.basal_bricks, 0, 2);
		world.setBlock(i + 13, j + 58, k + 6, NovaCraftBlocks.basal, 0, 2);
		world.setBlock(i + 14, j + 58, k + 6, NovaCraftBlocks.basal_bricks, 0, 2);
		world.setBlock(i + 15, j + 58, k + 6, NovaCraftBlocks.basal_bricks, 0, 2);
		world.setBlock(i + 16, j + 58, k + 6, NovaCraftBlocks.basal_bricks, 0, 2);
		world.setBlock(i + 17, j + 58, k + 6, NovaCraftBlocks.basal_bricks, 0, 2);
		world.setBlock(i + 18, j + 58, k + 6, NovaCraftBlocks.basal_bricks, 0, 2);
		world.setBlock(i + 19, j + 58, k + 6, NovaCraftBlocks.basal_bricks, 0, 2);
		world.setBlock(i + 20, j + 58, k + 6, NovaCraftBlocks.basal_bricks, 0, 2);
		world.setBlock(i + 21, j + 58, k + 6, NovaCraftBlocks.basal_bricks, 0, 2);
		world.setBlock(i + 22, j + 58, k + 6, NovaCraftBlocks.basal_bricks, 0, 2);
		world.setBlock(i + 23, j + 58, k + 6, NovaCraftBlocks.basal_bricks, 0, 2);
		world.setBlock(i + 24, j + 58, k + 6, NovaCraftBlocks.basal_bricks, 0, 2);
		world.setBlock(i + 25, j + 58, k + 6, NovaCraftBlocks.basal_bricks, 0, 2);
		world.setBlock(i + 26, j + 58, k + 6, NovaCraftBlocks.basal_bricks, 0, 2);
		world.setBlock(i + 27, j + 58, k + 6, NovaCraftBlocks.basal_bricks, 0, 2);
		world.setBlock(i + 0, j + 58, k + 7, NovaCraftBlocks.basal_bricks, 0, 2);
		world.setBlock(i + 1, j + 58, k + 7, NovaCraftBlocks.basal_bricks, 0, 2);
		world.setBlock(i + 2, j + 58, k + 7, NovaCraftBlocks.basal_bricks, 0, 2);
		world.setBlock(i + 3, j + 58, k + 7, NovaCraftBlocks.basal_bricks, 0, 2);
		world.setBlock(i + 4, j + 58, k + 7, NovaCraftBlocks.basal_bricks, 0, 2);
		world.setBlock(i + 5, j + 58, k + 7, NovaCraftBlocks.basal_bricks, 0, 2);
		world.setBlock(i + 6, j + 58, k + 7, Blocks.air, 0, 2);
		world.setBlock(i + 7, j + 58, k + 7, Blocks.air, 0, 2);
		world.setBlock(i + 8, j + 58, k + 7, NovaCraftBlocks.basal_bricks, 0, 2);
		world.setBlock(i + 9, j + 58, k + 7, NovaCraftBlocks.basal_bricks, 0, 2);
		world.setBlock(i + 10, j + 58, k + 7, NovaCraftBlocks.basal_bricks, 0, 2);
		world.setBlock(i + 11, j + 58, k + 7, NovaCraftBlocks.basal_bricks, 0, 2);
		world.setBlock(i + 12, j + 58, k + 7, NovaCraftBlocks.basal_bricks, 0, 2);
		world.setBlock(i + 13, j + 58, k + 7, NovaCraftBlocks.basal, 0, 2);
		world.setBlock(i + 14, j + 58, k + 7, NovaCraftBlocks.basal_bricks, 0, 2);
		world.setBlock(i + 15, j + 58, k + 7, NovaCraftBlocks.basal_bricks, 0, 2);
		world.setBlock(i + 16, j + 58, k + 7, NovaCraftBlocks.basal_bricks, 0, 2);
		world.setBlock(i + 17, j + 58, k + 7, NovaCraftBlocks.basal_bricks, 0, 2);
		world.setBlock(i + 18, j + 58, k + 7, NovaCraftBlocks.basal_bricks, 0, 2);
		world.setBlock(i + 19, j + 58, k + 7, NovaCraftBlocks.basal_bricks, 0, 2);
		world.setBlock(i + 20, j + 58, k + 7, NovaCraftBlocks.basal_bricks, 0, 2);
		world.setBlock(i + 21, j + 58, k + 7, NovaCraftBlocks.basal_bricks, 0, 2);
		world.setBlock(i + 22, j + 58, k + 7, NovaCraftBlocks.basal_bricks, 0, 2);
		world.setBlock(i + 23, j + 58, k + 7, NovaCraftBlocks.basal_bricks, 0, 2);
		world.setBlock(i + 24, j + 58, k + 7, NovaCraftBlocks.basal_bricks, 0, 2);
		world.setBlock(i + 25, j + 58, k + 7, NovaCraftBlocks.basal_bricks, 0, 2);
		world.setBlock(i + 26, j + 58, k + 7, NovaCraftBlocks.basal_bricks, 0, 2);
		world.setBlock(i + 27, j + 58, k + 7, NovaCraftBlocks.basal_bricks, 0, 2);
		world.setBlock(i + 0, j + 58, k + 8, NovaCraftBlocks.basal_bricks, 0, 2);
		world.setBlock(i + 1, j + 58, k + 8, NovaCraftBlocks.basal_bricks, 0, 2);
		world.setBlock(i + 2, j + 58, k + 8, NovaCraftBlocks.basal_bricks, 0, 2);
		world.setBlock(i + 3, j + 58, k + 8, NovaCraftBlocks.basal_bricks, 0, 2);
		world.setBlock(i + 4, j + 58, k + 8, NovaCraftBlocks.basal_bricks, 0, 2);
		world.setBlock(i + 5, j + 58, k + 8, Blocks.air, 0, 2);
		world.setBlock(i + 6, j + 58, k + 8, Blocks.air, 0, 2);
		world.setBlock(i + 7, j + 58, k + 8, Blocks.air, 0, 2);
		world.setBlock(i + 8, j + 58, k + 8, NovaCraftBlocks.basal_bricks, 0, 2);
		world.setBlock(i + 9, j + 58, k + 8, NovaCraftBlocks.basal_bricks, 0, 2);
		world.setBlock(i + 10, j + 58, k + 8, NovaCraftBlocks.basal_bricks, 0, 2);
		world.setBlock(i + 11, j + 58, k + 8, Blocks.air, 0, 2);
		world.setBlock(i + 12, j + 58, k + 8, NovaCraftBlocks.basal_bricks, 0, 2);
		world.setBlock(i + 13, j + 58, k + 8, NovaCraftBlocks.basal_bricks, 0, 2);
		world.setBlock(i + 14, j + 58, k + 8, NovaCraftBlocks.basal_bricks, 0, 2);
		world.setBlock(i + 15, j + 58, k + 8, NovaCraftBlocks.basal_bricks, 0, 2);
		world.setBlock(i + 16, j + 58, k + 8, NovaCraftBlocks.basal_bricks, 0, 2);
		world.setBlock(i + 17, j + 58, k + 8, NovaCraftBlocks.basal_bricks, 0, 2);
		world.setBlock(i + 18, j + 58, k + 8, NovaCraftBlocks.basal_bricks, 0, 2);
		world.setBlock(i + 19, j + 58, k + 8, NovaCraftBlocks.basal_bricks, 0, 2);
		world.setBlock(i + 20, j + 58, k + 8, NovaCraftBlocks.basal_bricks, 0, 2);
		world.setBlock(i + 21, j + 58, k + 8, Blocks.air, 0, 2);
		world.setBlock(i + 22, j + 58, k + 8, NovaCraftBlocks.basal_bricks, 0, 2);
		world.setBlock(i + 23, j + 58, k + 8, NovaCraftBlocks.basal_bricks, 0, 2);
		world.setBlock(i + 24, j + 58, k + 8, NovaCraftBlocks.basal_bricks, 0, 2);
		world.setBlock(i + 25, j + 58, k + 8, NovaCraftBlocks.basal_bricks, 0, 2);
		world.setBlock(i + 26, j + 58, k + 8, NovaCraftBlocks.basal_bricks, 0, 2);
		world.setBlock(i + 27, j + 58, k + 8, NovaCraftBlocks.basal_bricks, 0, 2);
		world.setBlock(i + 0, j + 58, k + 9, NovaCraftBlocks.basal_bricks, 0, 2);
		world.setBlock(i + 1, j + 58, k + 9, NovaCraftBlocks.basal_bricks, 0, 2);
		world.setBlock(i + 2, j + 58, k + 9, NovaCraftBlocks.basal_bricks, 0, 2);
		world.setBlock(i + 3, j + 58, k + 9, NovaCraftBlocks.basal_bricks, 0, 2);
		world.setBlock(i + 4, j + 58, k + 9, NovaCraftBlocks.basal_bricks, 0, 2);
		world.setBlock(i + 5, j + 58, k + 9, Blocks.air, 0, 2);
		world.setBlock(i + 6, j + 58, k + 9, Blocks.air, 0, 2);
		world.setBlock(i + 7, j + 58, k + 9, Blocks.air, 0, 2);
		world.setBlock(i + 8, j + 58, k + 9, Blocks.air, 0, 2);
		world.setBlock(i + 9, j + 58, k + 9, Blocks.air, 0, 2);
		world.setBlock(i + 10, j + 58, k + 9, NovaCraftBlocks.basal_bricks, 0, 2);
		world.setBlock(i + 11, j + 58, k + 9, NovaCraftBlocks.basal_bricks, 0, 2);
		world.setBlock(i + 12, j + 58, k + 9, NovaCraftBlocks.basal_bricks, 0, 2);
		world.setBlock(i + 13, j + 58, k + 9, NovaCraftBlocks.basal_bricks, 0, 2);
		world.setBlock(i + 14, j + 58, k + 9, NovaCraftBlocks.basal_bricks, 0, 2);
		world.setBlock(i + 15, j + 58, k + 9, NovaCraftBlocks.basal_bricks, 0, 2);
		world.setBlock(i + 16, j + 58, k + 9, NovaCraftBlocks.basal_bricks, 0, 2);
		world.setBlock(i + 17, j + 58, k + 9, NovaCraftBlocks.basal_bricks, 0, 2);
		world.setBlock(i + 18, j + 58, k + 9, NovaCraftBlocks.basal_bricks, 0, 2);
		world.setBlock(i + 19, j + 58, k + 9, NovaCraftBlocks.basal_bricks, 0, 2);
		world.setBlock(i + 20, j + 58, k + 9, NovaCraftBlocks.basal_bricks, 0, 2);
		world.setBlock(i + 21, j + 58, k + 9, NovaCraftBlocks.basal_bricks, 0, 2);
		world.setBlock(i + 22, j + 58, k + 9, NovaCraftBlocks.basal_bricks, 0, 2);
		world.setBlock(i + 23, j + 58, k + 9, NovaCraftBlocks.basal_bricks, 0, 2);
		world.setBlock(i + 24, j + 58, k + 9, NovaCraftBlocks.basal_bricks, 0, 2);
		world.setBlock(i + 25, j + 58, k + 9, NovaCraftBlocks.basal_bricks, 0, 2);
		world.setBlock(i + 26, j + 58, k + 9, NovaCraftBlocks.basal_bricks, 0, 2);
		world.setBlock(i + 27, j + 58, k + 9, NovaCraftBlocks.basal_bricks, 0, 2);
		world.setBlock(i + 0, j + 58, k + 10, NovaCraftBlocks.basal_bricks, 0, 2);
		world.setBlock(i + 1, j + 58, k + 10, NovaCraftBlocks.basal_bricks, 0, 2);
		world.setBlock(i + 2, j + 58, k + 10, NovaCraftBlocks.basal_bricks, 0, 2);
		world.setBlock(i + 3, j + 58, k + 10, NovaCraftBlocks.basal_bricks, 0, 2);
		world.setBlock(i + 4, j + 58, k + 10, NovaCraftBlocks.basal_bricks, 0, 2);
		world.setBlock(i + 5, j + 58, k + 10, Blocks.air, 0, 2);
		world.setBlock(i + 6, j + 58, k + 10, Blocks.air, 0, 2);
		world.setBlock(i + 7, j + 58, k + 10, Blocks.air, 0, 2);
		world.setBlock(i + 8, j + 58, k + 10, Blocks.air, 0, 2);
		world.setBlock(i + 9, j + 58, k + 10, NovaCraftBlocks.basal_bricks, 0, 2);
		world.setBlock(i + 10, j + 58, k + 10, NovaCraftBlocks.basal_bricks, 0, 2);
		world.setBlock(i + 11, j + 58, k + 10, NovaCraftBlocks.basal_bricks, 0, 2);
		world.setBlock(i + 12, j + 58, k + 10, NovaCraftBlocks.basal_bricks, 0, 2);
		world.setBlock(i + 13, j + 58, k + 10, NovaCraftBlocks.basal_bricks, 0, 2);
		world.setBlock(i + 14, j + 58, k + 10, NovaCraftBlocks.basal_bricks, 0, 2);
		world.setBlock(i + 15, j + 58, k + 10, NovaCraftBlocks.basal_bricks, 0, 2);
		world.setBlock(i + 16, j + 58, k + 10, NovaCraftBlocks.basal_bricks, 0, 2);
		world.setBlock(i + 17, j + 58, k + 10, NovaCraftBlocks.basal_bricks, 0, 2);
		world.setBlock(i + 18, j + 58, k + 10, NovaCraftBlocks.basal_bricks, 0, 2);
		world.setBlock(i + 19, j + 58, k + 10, NovaCraftBlocks.basal_bricks, 0, 2);
		world.setBlock(i + 20, j + 58, k + 10, Blocks.air, 0, 2);
		world.setBlock(i + 21, j + 58, k + 10, NovaCraftBlocks.basal_brick_stairs, 3, 2);
		world.setBlock(i + 22, j + 58, k + 10, NovaCraftBlocks.basal_bricks, 0, 2);
		world.setBlock(i + 23, j + 58, k + 10, NovaCraftBlocks.basal_bricks, 0, 2);
		world.setBlock(i + 24, j + 58, k + 10, NovaCraftBlocks.basal_bricks, 0, 2);
		world.setBlock(i + 25, j + 58, k + 10, NovaCraftBlocks.basal_bricks, 0, 2);
		world.setBlock(i + 26, j + 58, k + 10, NovaCraftBlocks.basal_bricks, 0, 2);
		world.setBlock(i + 27, j + 58, k + 10, NovaCraftBlocks.basal, 0, 2);
		world.setBlock(i + 0, j + 58, k + 11, Blocks.air, 0, 2);
		world.setBlock(i + 1, j + 58, k + 11, Blocks.air, 0, 2);
		world.setBlock(i + 2, j + 58, k + 11, Blocks.air, 0, 2);
		world.setBlock(i + 3, j + 58, k + 11, Blocks.air, 0, 2);
		world.setBlock(i + 4, j + 58, k + 11, Blocks.air, 0, 2);
		world.setBlock(i + 5, j + 58, k + 11, Blocks.air, 0, 2);
		world.setBlock(i + 6, j + 58, k + 11, Blocks.air, 0, 2);
		world.setBlock(i + 7, j + 58, k + 11, Blocks.air, 0, 2);
		world.setBlock(i + 8, j + 58, k + 11, Blocks.air, 0, 2);
		world.setBlock(i + 9, j + 58, k + 11, Blocks.air, 0, 2);
		world.setBlock(i + 10, j + 58, k + 11, Blocks.air, 0, 2);
		world.setBlock(i + 11, j + 58, k + 11, Blocks.air, 0, 2);
		world.setBlock(i + 12, j + 58, k + 11, Blocks.air, 0, 2);
		world.setBlock(i + 13, j + 58, k + 11, Blocks.air, 0, 2);
		world.setBlock(i + 14, j + 58, k + 11, NovaCraftBlocks.basal_bricks, 0, 2);
		world.setBlock(i + 15, j + 58, k + 11, NovaCraftBlocks.basal_bricks, 0, 2);
		world.setBlock(i + 16, j + 58, k + 11, NovaCraftBlocks.basal_bricks, 0, 2);
		world.setBlock(i + 17, j + 58, k + 11, NovaCraftBlocks.basal_bricks, 0, 2);
		world.setBlock(i + 18, j + 58, k + 11, Blocks.air, 0, 2);
		world.setBlock(i + 19, j + 58, k + 11, NovaCraftBlocks.basal_bricks, 0, 2);
		world.setBlock(i + 20, j + 58, k + 11, Blocks.air, 0, 2);
		world.setBlock(i + 21, j + 58, k + 11, Blocks.air, 0, 2);
		world.setBlock(i + 22, j + 58, k + 11, NovaCraftBlocks.basal_bricks, 0, 2);
		world.setBlock(i + 23, j + 58, k + 11, NovaCraftBlocks.basal_bricks, 0, 2);
		world.setBlock(i + 24, j + 58, k + 11, NovaCraftBlocks.basal_bricks, 0, 2);
		world.setBlock(i + 25, j + 58, k + 11, NovaCraftBlocks.basal_bricks, 0, 2);
		world.setBlock(i + 26, j + 58, k + 11, NovaCraftBlocks.basal_bricks, 0, 2);
		world.setBlock(i + 27, j + 58, k + 11, NovaCraftBlocks.basal_bricks, 0, 2);
		world.setBlock(i + 0, j + 58, k + 12, Blocks.air, 0, 2);
		world.setBlock(i + 1, j + 58, k + 12, Blocks.air, 0, 2);
		world.setBlock(i + 2, j + 58, k + 12, Blocks.air, 0, 2);
		world.setBlock(i + 3, j + 58, k + 12, Blocks.air, 0, 2);
		world.setBlock(i + 4, j + 58, k + 12, Blocks.air, 0, 2);
		world.setBlock(i + 5, j + 58, k + 12, Blocks.air, 0, 2);
		world.setBlock(i + 6, j + 58, k + 12, Blocks.air, 0, 2);
		world.setBlock(i + 7, j + 58, k + 12, Blocks.air, 0, 2);
		world.setBlock(i + 8, j + 58, k + 12, Blocks.air, 0, 2);
		world.setBlock(i + 9, j + 58, k + 12, Blocks.air, 0, 2);
		world.setBlock(i + 10, j + 58, k + 12, Blocks.air, 0, 2);
		world.setBlock(i + 11, j + 58, k + 12, Blocks.air, 0, 2);
		world.setBlock(i + 12, j + 58, k + 12, Blocks.air, 0, 2);
		world.setBlock(i + 13, j + 58, k + 12, Blocks.air, 0, 2);
		world.setBlock(i + 14, j + 58, k + 12, NovaCraftBlocks.basal_bricks, 0, 2);
		world.setBlock(i + 15, j + 58, k + 12, NovaCraftBlocks.basal_bricks, 0, 2);
		world.setBlock(i + 16, j + 58, k + 12, NovaCraftBlocks.basal_bricks, 0, 2);
		world.setBlock(i + 17, j + 58, k + 12, NovaCraftBlocks.basal_bricks, 0, 2);
		world.setBlock(i + 18, j + 58, k + 12, Blocks.air, 0, 2);
		world.setBlock(i + 19, j + 58, k + 12, Blocks.air, 0, 2);
		world.setBlock(i + 20, j + 58, k + 12, Blocks.air, 0, 2);
		world.setBlock(i + 21, j + 58, k + 12, Blocks.air, 0, 2);
		world.setBlock(i + 22, j + 58, k + 12, Blocks.air, 0, 2);
		world.setBlock(i + 23, j + 58, k + 12, Blocks.air, 0, 2);
		world.setBlock(i + 24, j + 58, k + 12, NovaCraftBlocks.basal_bricks, 0, 2);
		world.setBlock(i + 25, j + 58, k + 12, NovaCraftBlocks.basal_bricks, 0, 2);
		world.setBlock(i + 26, j + 58, k + 12, NovaCraftBlocks.basal_bricks, 0, 2);
		world.setBlock(i + 27, j + 58, k + 12, NovaCraftBlocks.basal_bricks, 0, 2);
		world.setBlock(i + 0, j + 59, k + 0, NovaCraftBlocks.basal_bricks, 0, 2);
		world.setBlock(i + 4, j + 59, k + 0, NovaCraftBlocks.basal_bricks, 0, 2);
		world.setBlock(i + 5, j + 59, k + 0, NovaCraftBlocks.basal_bricks, 0, 2);
		world.setBlock(i + 8, j + 59, k + 0, NovaCraftBlocks.cracked_basal_bricks, 0, 2);
		world.setBlock(i + 9, j + 59, k + 0, NovaCraftBlocks.basal_bricks, 0, 2);
		world.setBlock(i + 12, j + 59, k + 0, NovaCraftBlocks.basal_bricks, 0, 2);
		world.setBlock(i + 13, j + 59, k + 0, NovaCraftBlocks.basal_bricks, 0, 2);
		world.setBlock(i + 0, j + 59, k + 1, NovaCraftBlocks.basal_bricks, 0, 2);
		world.setBlock(i + 1, j + 59, k + 1, NovaCraftBlocks.basal_bricks, 0, 2);
		world.setBlock(i + 4, j + 59, k + 1, NovaCraftBlocks.basal_bricks, 0, 2);
		world.setBlock(i + 5, j + 59, k + 1, NovaCraftBlocks.basal_bricks, 0, 2);
		world.setBlock(i + 8, j + 59, k + 1, NovaCraftBlocks.basal_bricks, 0, 2);
		world.setBlock(i + 9, j + 59, k + 1, NovaCraftBlocks.basal_bricks, 0, 2);
		world.setBlock(i + 12, j + 59, k + 1, NovaCraftBlocks.basal_bricks, 0, 2);
		world.setBlock(i + 13, j + 59, k + 1, NovaCraftBlocks.basal_bricks, 0, 2);
		world.setBlock(i + 0, j + 59, k + 2, NovaCraftBlocks.basal_bricks, 0, 2);
		world.setBlock(i + 1, j + 59, k + 2, NovaCraftBlocks.basal_bricks, 0, 2);
		world.setBlock(i + 2, j + 59, k + 2, NovaCraftBlocks.basal_bricks, 0, 2);
		world.setBlock(i + 3, j + 59, k + 2, NovaCraftBlocks.basal_bricks, 0, 2);
		world.setBlock(i + 4, j + 59, k + 2, NovaCraftBlocks.basal_bricks, 0, 2);
		world.setBlock(i + 5, j + 59, k + 2, NovaCraftBlocks.basal_bricks, 0, 2);
		world.setBlock(i + 6, j + 59, k + 2, NovaCraftBlocks.basal_bricks, 0, 2);
		world.setBlock(i + 7, j + 59, k + 2, NovaCraftBlocks.basal_bricks, 0, 2);
		world.setBlock(i + 8, j + 59, k + 2, NovaCraftBlocks.basal_bricks, 0, 2);
		world.setBlock(i + 10, j + 59, k + 2, NovaCraftBlocks.basal_bricks, 0, 2);
		world.setBlock(i + 11, j + 59, k + 2, NovaCraftBlocks.basal_bricks, 0, 2);
		world.setBlock(i + 13, j + 59, k + 2, NovaCraftBlocks.basal_bricks, 0, 2);
		world.setBlock(i + 14, j + 59, k + 2, NovaCraftBlocks.basal_bricks, 0, 2);
		world.setBlock(i + 15, j + 59, k + 2, NovaCraftBlocks.basal_bricks, 0, 2);
		world.setBlock(i + 19, j + 59, k + 2, NovaCraftBlocks.basal_bricks, 0, 2);
		world.setBlock(i + 22, j + 59, k + 2, NovaCraftBlocks.basal_bricks, 0, 2);
		world.setBlock(i + 23, j + 59, k + 2, NovaCraftBlocks.basal_bricks, 0, 2);
		world.setBlock(i + 26, j + 59, k + 2, NovaCraftBlocks.basal_bricks, 0, 2);
		world.setBlock(i + 27, j + 59, k + 2, NovaCraftBlocks.basal_bricks, 0, 2);
		world.setBlock(i + 0, j + 59, k + 3, NovaCraftBlocks.basal_bricks, 0, 2);
		world.setBlock(i + 1, j + 59, k + 3, NovaCraftBlocks.basal_bricks, 0, 2);
		world.setBlock(i + 2, j + 59, k + 3, NovaCraftBlocks.basal_bricks, 0, 2);
		world.setBlock(i + 3, j + 59, k + 3, NovaCraftBlocks.basal_bricks, 0, 2);
		world.setBlock(i + 4, j + 59, k + 3, NovaCraftBlocks.basal_bricks, 0, 2);
		world.setBlock(i + 5, j + 59, k + 3, NovaCraftBlocks.basal_bricks, 0, 2);
		world.setBlock(i + 6, j + 59, k + 3, NovaCraftBlocks.basal_bricks, 0, 2);
		world.setBlock(i + 7, j + 59, k + 3, NovaCraftBlocks.basal_bricks, 0, 2);
		world.setBlock(i + 8, j + 59, k + 3, NovaCraftBlocks.basal_bricks, 0, 2);
		world.setBlock(i + 9, j + 59, k + 3, NovaCraftBlocks.basal_bricks, 0, 2);
		world.setBlock(i + 10, j + 59, k + 3, NovaCraftBlocks.basal_bricks, 0, 2);
		world.setBlock(i + 11, j + 59, k + 3, NovaCraftBlocks.basal_bricks, 0, 2);
		world.setBlock(i + 12, j + 59, k + 3, NovaCraftBlocks.basal_bricks, 0, 2);
		world.setBlock(i + 13, j + 59, k + 3, NovaCraftBlocks.basal_bricks, 0, 2);
		world.setBlock(i + 14, j + 59, k + 3, NovaCraftBlocks.basal_bricks, 0, 2);
		world.setBlock(i + 15, j + 59, k + 3, NovaCraftBlocks.basal_bricks, 0, 2);
		world.setBlock(i + 18, j + 59, k + 3, NovaCraftBlocks.basal_bricks, 0, 2);
		world.setBlock(i + 19, j + 59, k + 3, NovaCraftBlocks.basal_bricks, 0, 2);
		world.setBlock(i + 22, j + 59, k + 3, NovaCraftBlocks.basal_bricks, 0, 2);
		world.setBlock(i + 23, j + 59, k + 3, NovaCraftBlocks.basal_bricks, 0, 2);
		world.setBlock(i + 26, j + 59, k + 3, NovaCraftBlocks.basal_bricks, 0, 2);
		world.setBlock(i + 27, j + 59, k + 3, NovaCraftBlocks.basal_bricks, 0, 2);
		world.setBlock(i + 0, j + 59, k + 4, NovaCraftBlocks.basal_bricks, 0, 2);
		world.setBlock(i + 1, j + 59, k + 4, NovaCraftBlocks.basal_bricks, 0, 2);
		world.setBlock(i + 2, j + 59, k + 4, NovaCraftBlocks.basal_bricks, 0, 2);
		world.setBlock(i + 3, j + 59, k + 4, NovaCraftBlocks.basal_bricks, 0, 2);
		world.setBlock(i + 4, j + 59, k + 4, NovaCraftBlocks.basal_bricks, 0, 2);
		world.setBlock(i + 5, j + 59, k + 4, NovaCraftBlocks.basal_bricks, 0, 2);
		world.setBlock(i + 6, j + 59, k + 4, NovaCraftBlocks.basal_bricks, 0, 2);
		world.setBlock(i + 7, j + 59, k + 4, NovaCraftBlocks.basal_bricks, 0, 2);
		world.setBlock(i + 8, j + 59, k + 4, NovaCraftBlocks.basal_bricks, 0, 2);
		world.setBlock(i + 9, j + 59, k + 4, NovaCraftBlocks.basal_bricks, 0, 2);
		world.setBlock(i + 10, j + 59, k + 4, NovaCraftBlocks.basal_bricks, 0, 2);
		world.setBlock(i + 11, j + 59, k + 4, NovaCraftBlocks.basal_bricks, 0, 2);
		world.setBlock(i + 12, j + 59, k + 4, Blocks.air, 0, 2);
		world.setBlock(i + 13, j + 59, k + 4, NovaCraftBlocks.basal, 0, 2);
		world.setBlock(i + 14, j + 59, k + 4, NovaCraftBlocks.basal_bricks, 0, 2);
		world.setBlock(i + 15, j + 59, k + 4, NovaCraftBlocks.basal_bricks, 0, 2);
		world.setBlock(i + 16, j + 59, k + 4, NovaCraftBlocks.basal_bricks, 0, 2);
		world.setBlock(i + 17, j + 59, k + 4, NovaCraftBlocks.basal_bricks, 0, 2);
		world.setBlock(i + 18, j + 59, k + 4, NovaCraftBlocks.basal_bricks, 0, 2);
		world.setBlock(i + 19, j + 59, k + 4, NovaCraftBlocks.basal_bricks, 0, 2);
		world.setBlock(i + 20, j + 59, k + 4, NovaCraftBlocks.basal_bricks, 0, 2);
		world.setBlock(i + 21, j + 59, k + 4, NovaCraftBlocks.basal_bricks, 0, 2);
		world.setBlock(i + 22, j + 59, k + 4, NovaCraftBlocks.basal_bricks, 0, 2);
		world.setBlock(i + 23, j + 59, k + 4, NovaCraftBlocks.basal_bricks, 0, 2);
		world.setBlock(i + 24, j + 59, k + 4, NovaCraftBlocks.basal_bricks, 0, 2);
		world.setBlock(i + 25, j + 59, k + 4, NovaCraftBlocks.basal_bricks, 0, 2);
		world.setBlock(i + 26, j + 59, k + 4, NovaCraftBlocks.basal_bricks, 0, 2);
		world.setBlock(i + 27, j + 59, k + 4, NovaCraftBlocks.basal_bricks, 0, 2);
		world.setBlock(i + 0, j + 59, k + 5, NovaCraftBlocks.basal_bricks, 0, 2);
		world.setBlock(i + 1, j + 59, k + 5, NovaCraftBlocks.basal_bricks, 0, 2);
		world.setBlock(i + 2, j + 59, k + 5, NovaCraftBlocks.basal_bricks, 0, 2);
		world.setBlock(i + 3, j + 59, k + 5, NovaCraftBlocks.basal_bricks, 0, 2);
		world.setBlock(i + 4, j + 59, k + 5, NovaCraftBlocks.basal_bricks, 0, 2);
		world.setBlock(i + 5, j + 59, k + 5, NovaCraftBlocks.basal_bricks, 0, 2);
		world.setBlock(i + 6, j + 59, k + 5, NovaCraftBlocks.basal_bricks, 0, 2);
		world.setBlock(i + 7, j + 59, k + 5, NovaCraftBlocks.basal_bricks, 0, 2);
		world.setBlock(i + 8, j + 59, k + 5, NovaCraftBlocks.basal_bricks, 0, 2);
		world.setBlock(i + 9, j + 59, k + 5, NovaCraftBlocks.basal_bricks, 0, 2);
		world.setBlock(i + 10, j + 59, k + 5, NovaCraftBlocks.basal_bricks, 0, 2);
		world.setBlock(i + 11, j + 59, k + 5, NovaCraftBlocks.basal_bricks, 0, 2);
		world.setBlock(i + 12, j + 59, k + 5, NovaCraftBlocks.basal_bricks, 0, 2);
		world.setBlock(i + 13, j + 59, k + 5, NovaCraftBlocks.basal, 0, 2);
		world.setBlock(i + 14, j + 59, k + 5, NovaCraftBlocks.basal_bricks, 0, 2);
		world.setBlock(i + 15, j + 59, k + 5, NovaCraftBlocks.basal_bricks, 0, 2);
		world.setBlock(i + 16, j + 59, k + 5, NovaCraftBlocks.basal_bricks, 0, 2);
		world.setBlock(i + 17, j + 59, k + 5, NovaCraftBlocks.basal_bricks, 0, 2);
		world.setBlock(i + 18, j + 59, k + 5, NovaCraftBlocks.basal_bricks, 0, 2);
		world.setBlock(i + 19, j + 59, k + 5, NovaCraftBlocks.basal_bricks, 0, 2);
		world.setBlock(i + 20, j + 59, k + 5, NovaCraftBlocks.basal_bricks, 0, 2);
		world.setBlock(i + 21, j + 59, k + 5, NovaCraftBlocks.basal_bricks, 0, 2);
		world.setBlock(i + 22, j + 59, k + 5, NovaCraftBlocks.basal_bricks, 0, 2);
		world.setBlock(i + 23, j + 59, k + 5, NovaCraftBlocks.basal_bricks, 0, 2);
		world.setBlock(i + 24, j + 59, k + 5, NovaCraftBlocks.basal_bricks, 0, 2);
		world.setBlock(i + 25, j + 59, k + 5, NovaCraftBlocks.basal_bricks, 0, 2);
		world.setBlock(i + 26, j + 59, k + 5, NovaCraftBlocks.basal_bricks, 0, 2);
		world.setBlock(i + 27, j + 59, k + 5, NovaCraftBlocks.basal_bricks, 0, 2);
		world.setBlock(i + 0, j + 59, k + 6, NovaCraftBlocks.basal_bricks, 0, 2);
		world.setBlock(i + 1, j + 59, k + 6, NovaCraftBlocks.basal_bricks, 0, 2);
		world.setBlock(i + 2, j + 59, k + 6, NovaCraftBlocks.basal_bricks, 0, 2);
		world.setBlock(i + 3, j + 59, k + 6, NovaCraftBlocks.basal_bricks, 0, 2);
		world.setBlock(i + 4, j + 59, k + 6, NovaCraftBlocks.basal_bricks, 0, 2);
		world.setBlock(i + 5, j + 59, k + 6, NovaCraftBlocks.basal_bricks, 0, 2);
		world.setBlock(i + 6, j + 59, k + 6, Blocks.air, 0, 2);
		world.setBlock(i + 7, j + 59, k + 6, Blocks.air, 0, 2);
		world.setBlock(i + 8, j + 59, k + 6, NovaCraftBlocks.basal_bricks, 0, 2);
		world.setBlock(i + 9, j + 59, k + 6, NovaCraftBlocks.basal_bricks, 0, 2);
		world.setBlock(i + 10, j + 59, k + 6, NovaCraftBlocks.basal_bricks, 0, 2);
		world.setBlock(i + 11, j + 59, k + 6, NovaCraftBlocks.basal_bricks, 0, 2);
		world.setBlock(i + 12, j + 59, k + 6, NovaCraftBlocks.basal_bricks, 0, 2);
		world.setBlock(i + 13, j + 59, k + 6, NovaCraftBlocks.basal, 0, 2);
		world.setBlock(i + 14, j + 59, k + 6, NovaCraftBlocks.basal_bricks, 0, 2);
		world.setBlock(i + 15, j + 59, k + 6, NovaCraftBlocks.basal_bricks, 0, 2);
		world.setBlock(i + 16, j + 59, k + 6, NovaCraftBlocks.basal_bricks, 0, 2);
		world.setBlock(i + 17, j + 59, k + 6, NovaCraftBlocks.basal_bricks, 0, 2);
		world.setBlock(i + 18, j + 59, k + 6, NovaCraftBlocks.basal_bricks, 0, 2);
		world.setBlock(i + 19, j + 59, k + 6, NovaCraftBlocks.basal_bricks, 0, 2);
		world.setBlock(i + 20, j + 59, k + 6, NovaCraftBlocks.basal_bricks, 0, 2);
		world.setBlock(i + 21, j + 59, k + 6, NovaCraftBlocks.basal_bricks, 0, 2);
		world.setBlock(i + 22, j + 59, k + 6, NovaCraftBlocks.basal_bricks, 0, 2);
		world.setBlock(i + 23, j + 59, k + 6, NovaCraftBlocks.basal_bricks, 0, 2);
		world.setBlock(i + 24, j + 59, k + 6, NovaCraftBlocks.basal_bricks, 0, 2);
		world.setBlock(i + 25, j + 59, k + 6, NovaCraftBlocks.basal_bricks, 0, 2);
		world.setBlock(i + 26, j + 59, k + 6, NovaCraftBlocks.basal_bricks, 0, 2);
		world.setBlock(i + 27, j + 59, k + 6, NovaCraftBlocks.basal_bricks, 0, 2);
		world.setBlock(i + 0, j + 59, k + 7, NovaCraftBlocks.basal_bricks, 0, 2);
		world.setBlock(i + 1, j + 59, k + 7, NovaCraftBlocks.basal_bricks, 0, 2);
		world.setBlock(i + 2, j + 59, k + 7, NovaCraftBlocks.basal_bricks, 0, 2);
		world.setBlock(i + 3, j + 59, k + 7, NovaCraftBlocks.basal_bricks, 0, 2);
		world.setBlock(i + 4, j + 59, k + 7, NovaCraftBlocks.basal_bricks, 0, 2);
		world.setBlock(i + 5, j + 59, k + 7, NovaCraftBlocks.basal_bricks, 0, 2);
		world.setBlock(i + 6, j + 59, k + 7, Blocks.air, 0, 2);
		world.setBlock(i + 7, j + 59, k + 7, Blocks.air, 0, 2);
		world.setBlock(i + 8, j + 59, k + 7, Blocks.air, 0, 2);
		world.setBlock(i + 9, j + 59, k + 7, NovaCraftBlocks.basal_bricks, 0, 2);
		world.setBlock(i + 10, j + 59, k + 7, NovaCraftBlocks.basal_bricks, 0, 2);
		world.setBlock(i + 11, j + 59, k + 7, NovaCraftBlocks.basal_bricks, 0, 2);
		world.setBlock(i + 12, j + 59, k + 7, NovaCraftBlocks.basal_bricks, 0, 2);
		world.setBlock(i + 13, j + 59, k + 7, NovaCraftBlocks.basal, 0, 2);
		world.setBlock(i + 14, j + 59, k + 7, NovaCraftBlocks.basal_bricks, 0, 2);
		world.setBlock(i + 15, j + 59, k + 7, NovaCraftBlocks.basal_bricks, 0, 2);
		world.setBlock(i + 16, j + 59, k + 7, Blocks.air, 0, 2);
		world.setBlock(i + 17, j + 59, k + 7, NovaCraftBlocks.basal_bricks, 0, 2);
		world.setBlock(i + 18, j + 59, k + 7, NovaCraftBlocks.basal_bricks, 0, 2);
		world.setBlock(i + 19, j + 59, k + 7, NovaCraftBlocks.basal_bricks, 0, 2);
		world.setBlock(i + 20, j + 59, k + 7, NovaCraftBlocks.basal_bricks, 0, 2);
		world.setBlock(i + 21, j + 59, k + 7, NovaCraftBlocks.basal_bricks, 0, 2);
		world.setBlock(i + 22, j + 59, k + 7, NovaCraftBlocks.basal_bricks, 0, 2);
		world.setBlock(i + 23, j + 59, k + 7, NovaCraftBlocks.basal_bricks, 0, 2);
		world.setBlock(i + 24, j + 59, k + 7, NovaCraftBlocks.basal_bricks, 0, 2);
		world.setBlock(i + 25, j + 59, k + 7, NovaCraftBlocks.basal_bricks, 0, 2);
		world.setBlock(i + 26, j + 59, k + 7, NovaCraftBlocks.basal, 0, 2);
		world.setBlock(i + 27, j + 59, k + 7, NovaCraftBlocks.basal, 0, 2);
		world.setBlock(i + 0, j + 59, k + 8, NovaCraftBlocks.basal_bricks, 0, 2);
		world.setBlock(i + 1, j + 59, k + 8, NovaCraftBlocks.basal_bricks, 0, 2);
		world.setBlock(i + 2, j + 59, k + 8, NovaCraftBlocks.basal_bricks, 0, 2);
		world.setBlock(i + 3, j + 59, k + 8, NovaCraftBlocks.basal_bricks, 0, 2);
		world.setBlock(i + 4, j + 59, k + 8, NovaCraftBlocks.basal_bricks, 0, 2);
		world.setBlock(i + 5, j + 59, k + 8, Blocks.air, 0, 2);
		world.setBlock(i + 6, j + 59, k + 8, Blocks.air, 0, 2);
		world.setBlock(i + 7, j + 59, k + 8, Blocks.air, 0, 2);
		world.setBlock(i + 8, j + 59, k + 8, NovaCraftBlocks.basal_bricks, 0, 2);
		world.setBlock(i + 9, j + 59, k + 8, NovaCraftBlocks.basal_bricks, 0, 2);
		world.setBlock(i + 10, j + 59, k + 8, Blocks.air, 0, 2);
		world.setBlock(i + 11, j + 59, k + 8, NovaCraftBlocks.basal_bricks, 0, 2);
		world.setBlock(i + 12, j + 59, k + 8, NovaCraftBlocks.basal_bricks, 0, 2);
		world.setBlock(i + 13, j + 59, k + 8, NovaCraftBlocks.basal_scrap, 0, 2);
		world.setBlock(i + 14, j + 59, k + 8, NovaCraftBlocks.basal_bricks, 0, 2);
		world.setBlock(i + 15, j + 59, k + 8, NovaCraftBlocks.basal_bricks, 0, 2);
		world.setBlock(i + 16, j + 59, k + 8, NovaCraftBlocks.basal_bricks, 0, 2);
		world.setBlock(i + 17, j + 59, k + 8, NovaCraftBlocks.basal_bricks, 0, 2);
		world.setBlock(i + 18, j + 59, k + 8, NovaCraftBlocks.basal_bricks, 0, 2);
		world.setBlock(i + 19, j + 59, k + 8, NovaCraftBlocks.basal_bricks, 0, 2);
		world.setBlock(i + 20, j + 59, k + 8, NovaCraftBlocks.basal_bricks, 0, 2);
		world.setBlock(i + 21, j + 59, k + 8, Blocks.air, 0, 2);
		world.setBlock(i + 22, j + 59, k + 8, NovaCraftBlocks.basal_bricks, 0, 2);
		world.setBlock(i + 23, j + 59, k + 8, NovaCraftBlocks.basal_bricks, 0, 2);
		world.setBlock(i + 24, j + 59, k + 8, NovaCraftBlocks.basal_bricks, 0, 2);
		world.setBlock(i + 25, j + 59, k + 8, NovaCraftBlocks.basal_bricks, 0, 2);
		world.setBlock(i + 26, j + 59, k + 8, NovaCraftBlocks.basal_bricks, 0, 2);
		world.setBlock(i + 27, j + 59, k + 8, NovaCraftBlocks.basal, 0, 2);
		world.setBlock(i + 0, j + 59, k + 9, NovaCraftBlocks.basal_bricks, 0, 2);
		world.setBlock(i + 1, j + 59, k + 9, NovaCraftBlocks.basal_bricks, 0, 2);
		world.setBlock(i + 2, j + 59, k + 9, NovaCraftBlocks.basal_bricks, 0, 2);
		world.setBlock(i + 3, j + 59, k + 9, NovaCraftBlocks.basal_bricks, 0, 2);
		world.setBlock(i + 4, j + 59, k + 9, Blocks.air, 0, 2);
		world.setBlock(i + 5, j + 59, k + 9, Blocks.air, 0, 2);
		world.setBlock(i + 6, j + 59, k + 9, Blocks.air, 0, 2);
		world.setBlock(i + 7, j + 59, k + 9, Blocks.air, 0, 2);
		world.setBlock(i + 8, j + 59, k + 9, Blocks.air, 0, 2);
		world.setBlock(i + 9, j + 59, k + 9, NovaCraftBlocks.basal_bricks, 0, 2);
		world.setBlock(i + 10, j + 59, k + 9, NovaCraftBlocks.basal_bricks, 0, 2);
		world.setBlock(i + 11, j + 59, k + 9, NovaCraftBlocks.basal_bricks, 0, 2);
		world.setBlock(i + 12, j + 59, k + 9, NovaCraftBlocks.basal_bricks, 0, 2);
		world.setBlock(i + 13, j + 59, k + 9, NovaCraftBlocks.basal_bricks, 0, 2);
		world.setBlock(i + 14, j + 59, k + 9, NovaCraftBlocks.basal_bricks, 0, 2);
		world.setBlock(i + 15, j + 59, k + 9, NovaCraftBlocks.basal_bricks, 0, 2);
		world.setBlock(i + 16, j + 59, k + 9, NovaCraftBlocks.basal_bricks, 0, 2);
		world.setBlock(i + 17, j + 59, k + 9, NovaCraftBlocks.basal_bricks, 0, 2);
		world.setBlock(i + 18, j + 59, k + 9, NovaCraftBlocks.basal_bricks, 0, 2);
		world.setBlock(i + 19, j + 59, k + 9, NovaCraftBlocks.basal_bricks, 0, 2);
		world.setBlock(i + 20, j + 59, k + 9, Blocks.air, 0, 2);
		world.setBlock(i + 21, j + 59, k + 9, Blocks.air, 0, 2);
		world.setBlock(i + 22, j + 59, k + 9, NovaCraftBlocks.basal_bricks, 0, 2);
		world.setBlock(i + 23, j + 59, k + 9, NovaCraftBlocks.basal_bricks, 0, 2);
		world.setBlock(i + 24, j + 59, k + 9, NovaCraftBlocks.basal_bricks, 0, 2);
		world.setBlock(i + 25, j + 59, k + 9, Blocks.air, 0, 2);
		world.setBlock(i + 26, j + 59, k + 9, NovaCraftBlocks.basal_bricks, 0, 2);
		world.setBlock(i + 27, j + 59, k + 9, Blocks.air, 0, 2);
		world.setBlock(i + 0, j + 59, k + 10, NovaCraftBlocks.basal_bricks, 0, 2);
		world.setBlock(i + 1, j + 59, k + 10, NovaCraftBlocks.basal_bricks, 0, 2);
		world.setBlock(i + 2, j + 59, k + 10, NovaCraftBlocks.basal_bricks, 0, 2);
		world.setBlock(i + 3, j + 59, k + 10, Blocks.air, 0, 2);
		world.setBlock(i + 4, j + 59, k + 10, Blocks.air, 0, 2);
		world.setBlock(i + 5, j + 59, k + 10, Blocks.air, 0, 2);
		world.setBlock(i + 6, j + 59, k + 10, Blocks.air, 0, 2);
		world.setBlock(i + 7, j + 59, k + 10, Blocks.air, 0, 2);
		world.setBlock(i + 8, j + 59, k + 10, Blocks.air, 0, 2);
		world.setBlock(i + 9, j + 59, k + 10, NovaCraftBlocks.basal_bricks, 0, 2);
		world.setBlock(i + 10, j + 59, k + 10, NovaCraftBlocks.basal_bricks, 0, 2);
		world.setBlock(i + 11, j + 59, k + 10, NovaCraftBlocks.basal_bricks, 0, 2);
		world.setBlock(i + 12, j + 59, k + 10, NovaCraftBlocks.basal_bricks, 0, 2);
		world.setBlock(i + 13, j + 59, k + 10, NovaCraftBlocks.basal_bricks, 0, 2);
		world.setBlock(i + 14, j + 59, k + 10, NovaCraftBlocks.basal_bricks, 0, 2);
		world.setBlock(i + 15, j + 59, k + 10, NovaCraftBlocks.basal_bricks, 0, 2);
		world.setBlock(i + 16, j + 59, k + 10, NovaCraftBlocks.basal_bricks, 0, 2);
		world.setBlock(i + 17, j + 59, k + 10, NovaCraftBlocks.basal_bricks, 0, 2);
		world.setBlock(i + 18, j + 59, k + 10, Blocks.air, 0, 2);
		world.setBlock(i + 19, j + 59, k + 10, Blocks.air, 0, 2);
		world.setBlock(i + 20, j + 59, k + 10, Blocks.air, 0, 2);
		world.setBlock(i + 21, j + 59, k + 10, Blocks.air, 0, 2);
		world.setBlock(i + 22, j + 59, k + 10, NovaCraftBlocks.basal_bricks, 0, 2);
		world.setBlock(i + 23, j + 59, k + 10, NovaCraftBlocks.basal_bricks, 0, 2);
		world.setBlock(i + 24, j + 59, k + 10, NovaCraftBlocks.basal_bricks, 0, 2);
		world.setBlock(i + 25, j + 59, k + 10, NovaCraftBlocks.basal_bricks, 0, 2);
		world.setBlock(i + 26, j + 59, k + 10, NovaCraftBlocks.basal_bricks, 0, 2);
		world.setBlock(i + 27, j + 59, k + 10, NovaCraftBlocks.basal_bricks, 0, 2);
		world.setBlock(i + 0, j + 59, k + 11, Blocks.air, 0, 2);
		world.setBlock(i + 1, j + 59, k + 11, Blocks.air, 0, 2);
		world.setBlock(i + 2, j + 59, k + 11, Blocks.air, 0, 2);
		world.setBlock(i + 3, j + 59, k + 11, Blocks.air, 0, 2);
		world.setBlock(i + 4, j + 59, k + 11, Blocks.air, 0, 2);
		world.setBlock(i + 5, j + 59, k + 11, Blocks.air, 0, 2);
		world.setBlock(i + 6, j + 59, k + 11, Blocks.air, 0, 2);
		world.setBlock(i + 7, j + 59, k + 11, Blocks.air, 0, 2);
		world.setBlock(i + 8, j + 59, k + 11, Blocks.air, 0, 2);
		world.setBlock(i + 9, j + 59, k + 11, Blocks.air, 0, 2);
		world.setBlock(i + 10, j + 59, k + 11, Blocks.air, 0, 2);
		world.setBlock(i + 11, j + 59, k + 11, Blocks.air, 0, 2);
		world.setBlock(i + 12, j + 59, k + 11, Blocks.air, 0, 2);
		world.setBlock(i + 13, j + 59, k + 11, Blocks.air, 0, 2);
		world.setBlock(i + 14, j + 59, k + 11, NovaCraftBlocks.basal_bricks, 0, 2);
		world.setBlock(i + 15, j + 59, k + 11, NovaCraftBlocks.basal_bricks, 0, 2);
		world.setBlock(i + 16, j + 59, k + 11, NovaCraftBlocks.basal_bricks, 0, 2);
		world.setBlock(i + 17, j + 59, k + 11, NovaCraftBlocks.basal_bricks, 0, 2);
		world.setBlock(i + 18, j + 59, k + 11, NovaCraftBlocks.basal_bricks, 0, 2);
