package com.NovaCraft.world.bastion.treasure;

import java.util.Random;

import com.NovaCraft.config.Configs;
import com.NovaCraft.registry.OtherModBlocks;
import com.NovaCraftBlocks.NovaCraftBlocks;

import cpw.mods.fml.common.Loader;
import net.minecraft.block.Block;
import net.minecraft.init.Blocks;
import net.minecraft.world.World;
import net.minecraft.world.gen.feature.WorldGenerator;

public class BastionTreasureBarracksGen7 extends WorldGenerator
{
	public BastionTreasureBarracksGen7() {

	}
    
    public boolean generate(final World world, final Random random, final int i, final int j, final int k) {
    	 	
    	world.setBlock(i + 10, j + 40, k + 11, Blocks.air, 0, 2);
		world.setBlock(i + 11, j + 40, k + 11, Blocks.air, 0, 2);
		world.setBlock(i + 12, j + 40, k + 11, Blocks.air, 0, 2);
		world.setBlock(i + 13, j + 40, k + 11, Blocks.air, 0, 2);
		world.setBlock(i + 14, j + 40, k + 11, NovaCraftBlocks.basal_bricks, 0, 2);
		world.setBlock(i + 15, j + 40, k + 11, NovaCraftBlocks.basal_bricks, 0, 2);
		world.setBlock(i + 16, j + 40, k + 11, NovaCraftBlocks.basal_bricks, 0, 2);
		world.setBlock(i + 17, j + 40, k + 11, NovaCraftBlocks.basal_bricks, 0, 2);
		world.setBlock(i + 18, j + 40, k + 11, Blocks.air, 0, 2);
		world.setBlock(i + 19, j + 40, k + 11, Blocks.air, 0, 2);
		world.setBlock(i + 20, j + 40, k + 11, Blocks.air, 0, 2);
		world.setBlock(i + 21, j + 40, k + 11, Blocks.air, 0, 2);
		world.setBlock(i + 22, j + 40, k + 11, Blocks.air, 0, 2);
		world.setBlock(i + 23, j + 40, k + 11, NovaCraftBlocks.basal_brick_stairs, 0, 2);
		world.setBlock(i + 24, j + 40, k + 11, NovaCraftBlocks.basal_bricks, 0, 2);
		world.setBlock(i + 25, j + 40, k + 11, NovaCraftBlocks.basal_bricks, 0, 2);
		world.setBlock(i + 26, j + 40, k + 11, NovaCraftBlocks.cracked_basal_bricks, 0, 2);
		world.setBlock(i + 27, j + 40, k + 11, NovaCraftBlocks.basal_bricks, 0, 2);
		world.setBlock(i + 0, j + 40, k + 12, Blocks.air, 0, 2);
		world.setBlock(i + 1, j + 40, k + 12, Blocks.air, 0, 2);
		world.setBlock(i + 2, j + 40, k + 12, Blocks.air, 0, 2);
		world.setBlock(i + 3, j + 40, k + 12, Blocks.air, 0, 2);
		world.setBlock(i + 4, j + 40, k + 12, Blocks.air, 0, 2);
		world.setBlock(i + 5, j + 40, k + 12, Blocks.air, 0, 2);
		world.setBlock(i + 6, j + 40, k + 12, Blocks.air, 0, 2);
		world.setBlock(i + 7, j + 40, k + 12, Blocks.air, 0, 2);
		world.setBlock(i + 8, j + 40, k + 12, Blocks.air, 0, 2);
		world.setBlock(i + 9, j + 40, k + 12, Blocks.air, 0, 2);
		world.setBlock(i + 10, j + 40, k + 12, Blocks.air, 0, 2);
		world.setBlock(i + 11, j + 40, k + 12, Blocks.air, 0, 2);
		world.setBlock(i + 12, j + 40, k + 12, Blocks.air, 0, 2);
		world.setBlock(i + 13, j + 40, k + 12, Blocks.air, 0, 2);
		world.setBlock(i + 14, j + 40, k + 12, NovaCraftBlocks.basal_bricks, 0, 2);
		world.setBlock(i + 15, j + 40, k + 12, Blocks.air, 0, 2);
		world.setBlock(i + 16, j + 40, k + 12, Blocks.air, 0, 2);
		world.setBlock(i + 17, j + 40, k + 12, Blocks.air, 0, 2);
		world.setBlock(i + 18, j + 40, k + 12, Blocks.air, 0, 2);
		world.setBlock(i + 19, j + 40, k + 12, Blocks.air, 0, 2);
		world.setBlock(i + 20, j + 40, k + 12, Blocks.air, 0, 2);
		world.setBlock(i + 21, j + 40, k + 12, Blocks.air, 0, 2);
		world.setBlock(i + 22, j + 40, k + 12, Blocks.air, 0, 2);
		world.setBlock(i + 23, j + 40, k + 12, Blocks.air, 0, 2);
		world.setBlock(i + 24, j + 40, k + 12, Blocks.air, 0, 2);
		world.setBlock(i + 25, j + 40, k + 12, Blocks.air, 0, 2);
		world.setBlock(i + 26, j + 40, k + 12, Blocks.air, 0, 2);
		world.setBlock(i + 27, j + 40, k + 12, NovaCraftBlocks.basal_bricks, 0, 2);
		world.setBlock(i + 0, j + 41, k + 0, Blocks.air, 0, 2);
		world.setBlock(i + 1, j + 41, k + 0, Blocks.air, 0, 2);
		world.setBlock(i + 2, j + 41, k + 0, Blocks.air, 0, 2);
		world.setBlock(i + 3, j + 41, k + 0, Blocks.air, 0, 2);
		world.setBlock(i + 4, j + 41, k + 0, Blocks.air, 0, 2);
		world.setBlock(i + 5, j + 41, k + 0, Blocks.air, 0, 2);
		world.setBlock(i + 6, j + 41, k + 0, Blocks.air, 0, 2);
		world.setBlock(i + 7, j + 41, k + 0, Blocks.air, 0, 2);
		world.setBlock(i + 8, j + 41, k + 0, Blocks.air, 0, 2);
		world.setBlock(i + 9, j + 41, k + 0, Blocks.air, 0, 2);
		world.setBlock(i + 10, j + 41, k + 0, Blocks.air, 0, 2);
		world.setBlock(i + 11, j + 41, k + 0, Blocks.air, 0, 2);
		world.setBlock(i + 12, j + 41, k + 0, Blocks.air, 0, 2);
		world.setBlock(i + 13, j + 41, k + 0, Blocks.air, 0, 2);
		world.setBlock(i + 14, j + 41, k + 0, Blocks.air, 0, 2);
		world.setBlock(i + 15, j + 41, k + 0, Blocks.air, 0, 2);
		world.setBlock(i + 16, j + 41, k + 0, Blocks.air, 0, 2);
		world.setBlock(i + 17, j + 41, k + 0, Blocks.air, 0, 2);
		world.setBlock(i + 18, j + 41, k + 0, Blocks.air, 0, 2);
		world.setBlock(i + 19, j + 41, k + 0, Blocks.air, 0, 2);
		world.setBlock(i + 20, j + 41, k + 0, Blocks.air, 0, 2);
		world.setBlock(i + 21, j + 41, k + 0, Blocks.air, 0, 2);
		world.setBlock(i + 22, j + 41, k + 0, Blocks.air, 0, 2);
		world.setBlock(i + 23, j + 41, k + 0, Blocks.air, 0, 2);
		world.setBlock(i + 24, j + 41, k + 0, Blocks.air, 0, 2);
		world.setBlock(i + 25, j + 41, k + 0, Blocks.air, 0, 2);
		world.setBlock(i + 26, j + 41, k + 0, Blocks.air, 0, 2);
		world.setBlock(i + 27, j + 41, k + 0, Blocks.air, 0, 2);
		world.setBlock(i + 0, j + 41, k + 1, NovaCraftBlocks.cracked_basal_bricks, 0, 2);
		world.setBlock(i + 1, j + 41, k + 1, NovaCraftBlocks.basal_bricks, 0, 2);
		world.setBlock(i + 2, j + 41, k + 1, Blocks.air, 0, 2);
		world.setBlock(i + 3, j + 41, k + 1, Blocks.air, 0, 2);
		world.setBlock(i + 4, j + 41, k + 1, NovaCraftBlocks.cracked_basal_bricks, 0, 2);
		world.setBlock(i + 5, j + 41, k + 1, NovaCraftBlocks.basal_bricks, 0, 2);
		world.setBlock(i + 6, j + 41, k + 1, Blocks.air, 0, 2);
		world.setBlock(i + 7, j + 41, k + 1, Blocks.air, 0, 2);
		world.setBlock(i + 8, j + 41, k + 1, NovaCraftBlocks.basal_bricks, 0, 2);
		world.setBlock(i + 9, j + 41, k + 1, NovaCraftBlocks.basal_bricks, 0, 2);
		world.setBlock(i + 10, j + 41, k + 1, Blocks.air, 0, 2);
		world.setBlock(i + 11, j + 41, k + 1, Blocks.air, 0, 2);
		world.setBlock(i + 12, j + 41, k + 1, NovaCraftBlocks.basal_bricks, 0, 2);
		world.setBlock(i + 13, j + 41, k + 1, NovaCraftBlocks.cracked_basal_bricks, 0, 2);
		world.setBlock(i + 14, j + 41, k + 1, Blocks.air, 0, 2);
		world.setBlock(i + 15, j + 41, k + 1, Blocks.air, 0, 2);
		world.setBlock(i + 16, j + 41, k + 1, Blocks.air, 0, 2);
		world.setBlock(i + 17, j + 41, k + 1, Blocks.air, 0, 2);
		world.setBlock(i + 18, j + 41, k + 1, Blocks.air, 0, 2);
		world.setBlock(i + 19, j + 41, k + 1, Blocks.air, 0, 2);
		world.setBlock(i + 20, j + 41, k + 1, Blocks.air, 0, 2);
		world.setBlock(i + 21, j + 41, k + 1, Blocks.air, 0, 2);
		world.setBlock(i + 22, j + 41, k + 1, Blocks.air, 0, 2);
		world.setBlock(i + 23, j + 41, k + 1, Blocks.air, 0, 2);
		world.setBlock(i + 24, j + 41, k + 1, Blocks.air, 0, 2);
		world.setBlock(i + 25, j + 41, k + 1, Blocks.air, 0, 2);
		world.setBlock(i + 26, j + 41, k + 1, Blocks.air, 0, 2);
		world.setBlock(i + 27, j + 41, k + 1, Blocks.air, 0, 2);
		world.setBlock(i + 0, j + 41, k + 2, NovaCraftBlocks.basal_bricks, 0, 2);
		world.setBlock(i + 1, j + 41, k + 2, NovaCraftBlocks.basal_bricks, 0, 2);
		world.setBlock(i + 2, j + 41, k + 2, Blocks.air, 0, 2);
		world.setBlock(i + 3, j + 41, k + 2, Blocks.air, 0, 2);
		world.setBlock(i + 4, j + 41, k + 2, NovaCraftBlocks.basal_bricks, 0, 2);
		world.setBlock(i + 5, j + 41, k + 2, NovaCraftBlocks.basal_bricks, 0, 2);
		world.setBlock(i + 6, j + 41, k + 2, Blocks.air, 0, 2);
		world.setBlock(i + 7, j + 41, k + 2, Blocks.air, 0, 2);
		world.setBlock(i + 8, j + 41, k + 2, NovaCraftBlocks.basal_bricks, 0, 2);
		world.setBlock(i + 9, j + 41, k + 2, NovaCraftBlocks.cracked_basal_bricks, 0, 2);
		world.setBlock(i + 10, j + 41, k + 2, Blocks.air, 0, 2);
		world.setBlock(i + 11, j + 41, k + 2, Blocks.air, 0, 2);
		world.setBlock(i + 12, j + 41, k + 2, NovaCraftBlocks.basal_bricks, 0, 2);
		world.setBlock(i + 13, j + 41, k + 2, NovaCraftBlocks.cracked_basal_bricks, 0, 2);
		world.setBlock(i + 14, j + 41, k + 2, Blocks.air, 0, 2);
		world.setBlock(i + 15, j + 41, k + 2, Blocks.air, 0, 2);
		world.setBlock(i + 16, j + 41, k + 2, Blocks.air, 0, 2);
		world.setBlock(i + 17, j + 41, k + 2, Blocks.air, 0, 2);
		world.setBlock(i + 18, j + 41, k + 2, Blocks.air, 0, 2);
		world.setBlock(i + 19, j + 41, k + 2, Blocks.air, 0, 2);
		world.setBlock(i + 20, j + 41, k + 2, Blocks.air, 0, 2);
		world.setBlock(i + 21, j + 41, k + 2, Blocks.air, 0, 2);
		world.setBlock(i + 22, j + 41, k + 2, Blocks.air, 0, 2);
		world.setBlock(i + 23, j + 41, k + 2, Blocks.air, 0, 2);
		world.setBlock(i + 24, j + 41, k + 2, Blocks.air, 0, 2);
		world.setBlock(i + 25, j + 41, k + 2, Blocks.air, 0, 2);
		world.setBlock(i + 26, j + 41, k + 2, Blocks.air, 0, 2);
		world.setBlock(i + 27, j + 41, k + 2, Blocks.air, 0, 2);
		world.setBlock(i + 0, j + 41, k + 3, NovaCraftBlocks.basal_bricks, 0, 2);
		world.setBlock(i + 1, j + 41, k + 3, NovaCraftBlocks.cracked_basal_bricks, 0, 2);
		world.setBlock(i + 2, j + 41, k + 3, Blocks.air, 0, 2);
		world.setBlock(i + 3, j + 41, k + 3, Blocks.air, 0, 2);
		world.setBlock(i + 4, j + 41, k + 3, NovaCraftBlocks.basal_bricks, 0, 2);
		world.setBlock(i + 5, j + 41, k + 3, NovaCraftBlocks.basal_bricks, 0, 2);
		world.setBlock(i + 6, j + 41, k + 3, Blocks.air, 0, 2);
		world.setBlock(i + 7, j + 41, k + 3, Blocks.air, 0, 2);
		world.setBlock(i + 8, j + 41, k + 3, NovaCraftBlocks.basal_bricks, 0, 2);
		world.setBlock(i + 9, j + 41, k + 3, NovaCraftBlocks.basal_bricks, 0, 2);
		world.setBlock(i + 10, j + 41, k + 3, Blocks.air, 0, 2);
		world.setBlock(i + 11, j + 41, k + 3, Blocks.air, 0, 2);
		world.setBlock(i + 12, j + 41, k + 3, NovaCraftBlocks.basal_bricks, 0, 2);
		world.setBlock(i + 13, j + 41, k + 3, NovaCraftBlocks.basal_bricks, 0, 2);
		world.setBlock(i + 14, j + 41, k + 3, NovaCraftBlocks.cracked_basal_bricks, 0, 2);
		world.setBlock(i + 15, j + 41, k + 3, NovaCraftBlocks.cracked_basal_bricks, 0, 2);
		world.setBlock(i + 16, j + 41, k + 3, Blocks.air, 0, 2);
		world.setBlock(i + 17, j + 41, k + 3, Blocks.air, 0, 2);
		world.setBlock(i + 18, j + 41, k + 3, NovaCraftBlocks.basal_bricks, 0, 2);
		world.setBlock(i + 19, j + 41, k + 3, NovaCraftBlocks.cracked_basal_bricks, 0, 2);
		world.setBlock(i + 20, j + 41, k + 3, Blocks.air, 0, 2);
		world.setBlock(i + 21, j + 41, k + 3, Blocks.air, 0, 2);
		world.setBlock(i + 22, j + 41, k + 3, NovaCraftBlocks.basal_bricks, 0, 2);
		world.setBlock(i + 23, j + 41, k + 3, NovaCraftBlocks.basal_bricks, 0, 2);
		world.setBlock(i + 24, j + 41, k + 3, Blocks.air, 0, 2);
		world.setBlock(i + 25, j + 41, k + 3, Blocks.air, 0, 2);
		world.setBlock(i + 26, j + 41, k + 3, NovaCraftBlocks.cracked_basal_bricks, 0, 2);
		world.setBlock(i + 27, j + 41, k + 3, NovaCraftBlocks.basal_bricks, 0, 2);
		world.setBlock(i + 0, j + 41, k + 4, NovaCraftBlocks.basal_bricks, 0, 2);
		world.setBlock(i + 1, j + 41, k + 4, NovaCraftBlocks.basal_bricks, 0, 2);
		world.setBlock(i + 2, j + 41, k + 4, NovaCraftBlocks.basal_bricks, 0, 2);
		world.setBlock(i + 3, j + 41, k + 4, NovaCraftBlocks.basal_bricks, 0, 2);
		world.setBlock(i + 4, j + 41, k + 4, NovaCraftBlocks.cracked_basal_bricks, 0, 2);
		world.setBlock(i + 5, j + 41, k + 4, NovaCraftBlocks.basal_bricks, 0, 2);
		world.setBlock(i + 6, j + 41, k + 4, NovaCraftBlocks.basal_bricks, 0, 2);
		world.setBlock(i + 7, j + 41, k + 4, NovaCraftBlocks.basal_bricks, 0, 2);
		world.setBlock(i + 8, j + 41, k + 4, NovaCraftBlocks.basal_bricks, 0, 2);
		world.setBlock(i + 9, j + 41, k + 4, NovaCraftBlocks.basal_bricks, 0, 2);
		world.setBlock(i + 10, j + 41, k + 4, NovaCraftBlocks.basal_bricks, 0, 2);
		world.setBlock(i + 11, j + 41, k + 4, NovaCraftBlocks.basal_bricks, 0, 2);
		world.setBlock(i + 12, j + 41, k + 4, NovaCraftBlocks.cracked_basal_bricks, 0, 2);
		world.setBlock(i + 13, j + 41, k + 4, NovaCraftBlocks.basal_bricks, 0, 2);
		world.setBlock(i + 14, j + 41, k + 4, NovaCraftBlocks.cracked_basal_bricks, 0, 2);
		world.setBlock(i + 15, j + 41, k + 4, NovaCraftBlocks.basal_bricks, 0, 2);
		world.setBlock(i + 16, j + 41, k + 4, Blocks.air, 0, 2);
		world.setBlock(i + 17, j + 41, k + 4, Blocks.air, 0, 2);
		world.setBlock(i + 18, j + 41, k + 4, NovaCraftBlocks.basal_bricks, 0, 2);
		world.setBlock(i + 19, j + 41, k + 4, NovaCraftBlocks.cracked_basal_bricks, 0, 2);
		world.setBlock(i + 20, j + 41, k + 4, Blocks.air, 0, 2);
		world.setBlock(i + 21, j + 41, k + 4, Blocks.air, 0, 2);
		world.setBlock(i + 22, j + 41, k + 4, NovaCraftBlocks.basal_bricks, 0, 2);
		world.setBlock(i + 23, j + 41, k + 4, NovaCraftBlocks.basal_bricks, 0, 2);
		world.setBlock(i + 24, j + 41, k + 4, Blocks.air, 0, 2);
		world.setBlock(i + 25, j + 41, k + 4, Blocks.air, 0, 2);
		world.setBlock(i + 26, j + 41, k + 4, NovaCraftBlocks.cracked_basal_bricks, 0, 2);
		world.setBlock(i + 27, j + 41, k + 4, NovaCraftBlocks.basal_bricks, 0, 2);
		world.setBlock(i + 0, j + 41, k + 5, NovaCraftBlocks.basal_bricks, 0, 2);
		world.setBlock(i + 1, j + 41, k + 5, NovaCraftBlocks.basal_bricks, 0, 2);
		world.setBlock(i + 2, j + 41, k + 5, NovaCraftBlocks.basal_bricks, 0, 2);
		world.setBlock(i + 3, j + 41, k + 5, NovaCraftBlocks.basal_bricks, 0, 2);
		world.setBlock(i + 4, j + 41, k + 5, NovaCraftBlocks.basal_bricks, 0, 2);
		world.setBlock(i + 5, j + 41, k + 5, NovaCraftBlocks.cracked_basal_bricks, 0, 2);
		world.setBlock(i + 6, j + 41, k + 5, NovaCraftBlocks.basal_bricks, 0, 2);
		world.setBlock(i + 7, j + 41, k + 5, NovaCraftBlocks.basal_bricks, 0, 2);
		world.setBlock(i + 8, j + 41, k + 5, NovaCraftBlocks.cracked_basal_bricks, 0, 2);
		world.setBlock(i + 9, j + 41, k + 5, NovaCraftBlocks.basal_bricks, 0, 2);
		world.setBlock(i + 10, j + 41, k + 5, NovaCraftBlocks.basal_bricks, 0, 2);
		world.setBlock(i + 11, j + 41, k + 5, NovaCraftBlocks.basal_bricks, 0, 2);
		world.setBlock(i + 12, j + 41, k + 5, NovaCraftBlocks.basal_bricks, 0, 2);
		world.setBlock(i + 13, j + 41, k + 5, NovaCraftBlocks.basal_bricks, 0, 2);
		world.setBlock(i + 14, j + 41, k + 5, NovaCraftBlocks.basal_bricks, 0, 2);
		world.setBlock(i + 15, j + 41, k + 5, NovaCraftBlocks.basal_bricks, 0, 2);
		world.setBlock(i + 16, j + 41, k + 5, Blocks.air, 0, 2);
		world.setBlock(i + 17, j + 41, k + 5, Blocks.air, 0, 2);
		world.setBlock(i + 18, j + 41, k + 5, NovaCraftBlocks.basal_bricks, 0, 2);
		world.setBlock(i + 19, j + 41, k + 5, NovaCraftBlocks.basal_bricks, 0, 2);
		world.setBlock(i + 20, j + 41, k + 5, Blocks.air, 0, 2);
		world.setBlock(i + 21, j + 41, k + 5, Blocks.air, 0, 2);
		world.setBlock(i + 22, j + 41, k + 5, NovaCraftBlocks.basal_bricks, 0, 2);
		world.setBlock(i + 23, j + 41, k + 5, NovaCraftBlocks.cracked_basal_bricks, 0, 2);
		world.setBlock(i + 24, j + 41, k + 5, Blocks.air, 0, 2);
		world.setBlock(i + 25, j + 41, k + 5, Blocks.air, 0, 2);
		world.setBlock(i + 26, j + 41, k + 5, NovaCraftBlocks.basal_bricks, 0, 2);
		world.setBlock(i + 27, j + 41, k + 5, NovaCraftBlocks.basal_bricks, 0, 2);
		world.setBlock(i + 0, j + 41, k + 6, NovaCraftBlocks.basal_bricks, 0, 2);
		world.setBlock(i + 1, j + 41, k + 6, NovaCraftBlocks.cracked_basal_bricks, 0, 2);
		world.setBlock(i + 2, j + 41, k + 6, NovaCraftBlocks.basal_bricks, 0, 2);
		world.setBlock(i + 3, j + 41, k + 6, NovaCraftBlocks.cracked_basal_bricks, 0, 2);
		world.setBlock(i + 4, j + 41, k + 6, NovaCraftBlocks.cracked_basal_bricks, 0, 2);
		world.setBlock(i + 5, j + 41, k + 6, NovaCraftBlocks.basal_bricks, 0, 2);
		world.setBlock(i + 6, j + 41, k + 6, NovaCraftBlocks.cracked_basal_bricks, 0, 2);
		world.setBlock(i + 7, j + 41, k + 6, NovaCraftBlocks.basal_bricks, 0, 2);
		world.setBlock(i + 8, j + 41, k + 6, NovaCraftBlocks.basal_bricks, 0, 2);
		world.setBlock(i + 9, j + 41, k + 6, NovaCraftBlocks.basal_bricks, 0, 2);
		world.setBlock(i + 10, j + 41, k + 6, NovaCraftBlocks.basal_bricks, 0, 2);
		world.setBlock(i + 11, j + 41, k + 6, NovaCraftBlocks.cracked_basal_bricks, 0, 2);
		world.setBlock(i + 12, j + 41, k + 6, NovaCraftBlocks.basal_bricks, 0, 2);
		world.setBlock(i + 13, j + 41, k + 6, NovaCraftBlocks.basal_bricks, 0, 2);
		world.setBlock(i + 14, j + 41, k + 6, NovaCraftBlocks.basal_bricks, 0, 2);
		world.setBlock(i + 15, j + 41, k + 6, NovaCraftBlocks.basal_bricks, 0, 2);
		world.setBlock(i + 16, j + 41, k + 6, NovaCraftBlocks.basal_bricks, 0, 2);
		world.setBlock(i + 17, j + 41, k + 6, NovaCraftBlocks.cracked_basal_bricks, 0, 2);
		world.setBlock(i + 18, j + 41, k + 6, NovaCraftBlocks.basal_bricks, 0, 2);
		world.setBlock(i + 19, j + 41, k + 6, NovaCraftBlocks.basal_bricks, 0, 2);
		world.setBlock(i + 20, j + 41, k + 6, NovaCraftBlocks.cracked_basal_bricks, 0, 2);
		world.setBlock(i + 21, j + 41, k + 6, NovaCraftBlocks.basal_bricks, 0, 2);
		world.setBlock(i + 22, j + 41, k + 6, NovaCraftBlocks.basal_bricks, 0, 2);
		world.setBlock(i + 23, j + 41, k + 6, NovaCraftBlocks.basal_bricks, 0, 2);
		world.setBlock(i + 24, j + 41, k + 6, NovaCraftBlocks.basal_bricks, 0, 2);
		world.setBlock(i + 25, j + 41, k + 6, NovaCraftBlocks.cracked_basal_bricks, 0, 2);
		world.setBlock(i + 26, j + 41, k + 6, NovaCraftBlocks.cracked_basal_bricks, 0, 2);
		world.setBlock(i + 27, j + 41, k + 6, NovaCraftBlocks.cracked_basal_bricks, 0, 2);
		world.setBlock(i + 0, j + 41, k + 7, NovaCraftBlocks.basal_bricks, 0, 2);
		world.setBlock(i + 1, j + 41, k + 7, NovaCraftBlocks.cracked_basal_bricks, 0, 2);
		world.setBlock(i + 2, j + 41, k + 7, NovaCraftBlocks.basal_bricks, 0, 2);
		world.setBlock(i + 3, j + 41, k + 7, NovaCraftBlocks.basal_bricks, 0, 2);
		world.setBlock(i + 4, j + 41, k + 7, NovaCraftBlocks.basal_bricks, 0, 2);
		world.setBlock(i + 5, j + 41, k + 7, NovaCraftBlocks.cracked_basal_bricks, 0, 2);
		world.setBlock(i + 6, j + 41, k + 7, NovaCraftBlocks.basal_bricks, 0, 2);
		world.setBlock(i + 7, j + 41, k + 7, NovaCraftBlocks.basal_bricks, 0, 2);
		world.setBlock(i + 8, j + 41, k + 7, NovaCraftBlocks.cracked_basal_bricks, 0, 2);
		world.setBlock(i + 9, j + 41, k + 7, NovaCraftBlocks.basal_bricks, 0, 2);
		world.setBlock(i + 10, j + 41, k + 7, NovaCraftBlocks.cracked_basal_bricks, 0, 2);
		world.setBlock(i + 11, j + 41, k + 7, NovaCraftBlocks.cracked_basal_bricks, 0, 2);
		world.setBlock(i + 12, j + 41, k + 7, NovaCraftBlocks.cracked_basal_bricks, 0, 2);
		world.setBlock(i + 13, j + 41, k + 7, NovaCraftBlocks.cracked_basal_bricks, 0, 2);
		world.setBlock(i + 14, j + 41, k + 7, NovaCraftBlocks.basal_bricks, 0, 2);
		world.setBlock(i + 15, j + 41, k + 7, NovaCraftBlocks.cracked_basal_bricks, 0, 2);
		world.setBlock(i + 16, j + 41, k + 7, NovaCraftBlocks.basal_bricks, 0, 2);
		world.setBlock(i + 17, j + 41, k + 7, NovaCraftBlocks.basal_bricks, 0, 2);
		world.setBlock(i + 18, j + 41, k + 7, NovaCraftBlocks.cracked_basal_bricks, 0, 2);
		world.setBlock(i + 19, j + 41, k + 7, NovaCraftBlocks.basal_bricks, 0, 2);
		world.setBlock(i + 20, j + 41, k + 7, NovaCraftBlocks.basal_bricks, 0, 2);
		world.setBlock(i + 21, j + 41, k + 7, NovaCraftBlocks.basal_bricks, 0, 2);
		world.setBlock(i + 22, j + 41, k + 7, NovaCraftBlocks.cracked_basal_bricks, 0, 2);
		world.setBlock(i + 23, j + 41, k + 7, NovaCraftBlocks.cracked_basal_bricks, 0, 2);
		world.setBlock(i + 24, j + 41, k + 7, NovaCraftBlocks.basal_bricks, 0, 2);
		world.setBlock(i + 25, j + 41, k + 7, NovaCraftBlocks.basal_bricks, 0, 2);
		world.setBlock(i + 26, j + 41, k + 7, NovaCraftBlocks.cracked_basal_bricks, 0, 2);
		world.setBlock(i + 27, j + 41, k + 7, NovaCraftBlocks.basal_bricks, 0, 2);
		world.setBlock(i + 0, j + 41, k + 8, NovaCraftBlocks.basal_bricks, 0, 2);
		world.setBlock(i + 1, j + 41, k + 8, NovaCraftBlocks.cracked_basal_bricks, 0, 2);
		world.setBlock(i + 2, j + 41, k + 8, NovaCraftBlocks.basal_bricks, 0, 2);
		world.setBlock(i + 3, j + 41, k + 8, NovaCraftBlocks.basal_bricks, 0, 2);
		world.setBlock(i + 4, j + 41, k + 8, NovaCraftBlocks.basal_bricks, 0, 2);
		world.setBlock(i + 5, j + 41, k + 8, NovaCraftBlocks.basal_bricks, 0, 2);
		world.setBlock(i + 6, j + 41, k + 8, NovaCraftBlocks.cracked_basal_bricks, 0, 2);
		world.setBlock(i + 7, j + 41, k + 8, NovaCraftBlocks.basal_bricks, 0, 2);
		world.setBlock(i + 8, j + 41, k + 8, NovaCraftBlocks.basal_bricks, 0, 2);
		world.setBlock(i + 9, j + 41, k + 8, NovaCraftBlocks.basal_bricks, 0, 2);
		world.setBlock(i + 10, j + 41, k + 8, NovaCraftBlocks.basal_bricks, 0, 2);
		world.setBlock(i + 11, j + 41, k + 8, NovaCraftBlocks.cracked_basal_bricks, 0, 2);
		world.setBlock(i + 12, j + 41, k + 8, NovaCraftBlocks.cracked_basal_bricks, 0, 2);
		world.setBlock(i + 13, j + 41, k + 8, NovaCraftBlocks.cracked_basal_bricks, 0, 2);
		world.setBlock(i + 14, j + 41, k + 8, NovaCraftBlocks.basal_bricks, 0, 2);
		world.setBlock(i + 15, j + 41, k + 8, NovaCraftBlocks.basal_bricks, 0, 2);
		world.setBlock(i + 16, j + 41, k + 8, NovaCraftBlocks.basal_bricks, 0, 2);
		world.setBlock(i + 17, j + 41, k + 8, NovaCraftBlocks.cracked_basal_bricks, 0, 2);
		world.setBlock(i + 18, j + 41, k + 8, NovaCraftBlocks.basal_bricks, 0, 2);
		world.setBlock(i + 19, j + 41, k + 8, NovaCraftBlocks.basal_bricks, 0, 2);
		world.setBlock(i + 20, j + 41, k + 8, NovaCraftBlocks.basal_bricks, 0, 2);
		world.setBlock(i + 21, j + 41, k + 8, NovaCraftBlocks.basal_bricks, 0, 2);
		world.setBlock(i + 22, j + 41, k + 8, NovaCraftBlocks.basal_bricks, 0, 2);
		world.setBlock(i + 23, j + 41, k + 8, NovaCraftBlocks.basal_bricks, 0, 2);
		world.setBlock(i + 24, j + 41, k + 8, NovaCraftBlocks.basal_bricks, 0, 2);
		world.setBlock(i + 25, j + 41, k + 8, NovaCraftBlocks.cracked_basal_bricks, 0, 2);
		world.setBlock(i + 26, j + 41, k + 8, NovaCraftBlocks.basal_bricks, 0, 2);
		world.setBlock(i + 27, j + 41, k + 8, NovaCraftBlocks.basal_bricks, 0, 2);
		world.setBlock(i + 0, j + 41, k + 9, NovaCraftBlocks.cracked_basal_bricks, 0, 2);
		world.setBlock(i + 1, j + 41, k + 9, NovaCraftBlocks.basal, 0, 2);
		world.setBlock(i + 2, j + 41, k + 9, NovaCraftBlocks.basal, 0, 2);
		world.setBlock(i + 3, j + 41, k + 9, NovaCraftBlocks.basal_brick_stairs, 1, 2);
		world.setBlock(i + 4, j + 41, k + 9, Blocks.air, 0, 2);
		world.setBlock(i + 5, j + 41, k + 9, Blocks.air, 0, 2);
		world.setBlock(i + 6, j + 41, k + 9, Blocks.air, 0, 2);
		world.setBlock(i + 7, j + 41, k + 9, Blocks.air, 0, 2);
		world.setBlock(i + 8, j + 41, k + 9, Blocks.air, 0, 2);
		world.setBlock(i + 9, j + 41, k + 9, Blocks.air, 0, 2);
		world.setBlock(i + 10, j + 41, k + 9, NovaCraftBlocks.basal_brick_stairs, 0, 2);
		world.setBlock(i + 11, j + 41, k + 9, NovaCraftBlocks.cracked_basal_bricks, 0, 2);
		world.setBlock(i + 12, j + 41, k + 9, NovaCraftBlocks.cracked_basal_bricks, 0, 2);
		world.setBlock(i + 13, j + 41, k + 9, NovaCraftBlocks.basal_bricks, 0, 2);
		world.setBlock(i + 14, j + 41, k + 9, NovaCraftBlocks.basal_bricks, 0, 2);
		world.setBlock(i + 15, j + 41, k + 9, NovaCraftBlocks.basal_bricks, 0, 2);
		world.setBlock(i + 16, j + 41, k + 9, NovaCraftBlocks.basal_bricks, 0, 2);
		world.setBlock(i + 17, j + 41, k + 9, NovaCraftBlocks.basal_bricks, 0, 2);
		world.setBlock(i + 18, j + 41, k + 9, NovaCraftBlocks.basal_bricks, 0, 2);
		world.setBlock(i + 19, j + 41, k + 9, NovaCraftBlocks.basal_bricks, 0, 2);
		world.setBlock(i + 20, j + 41, k + 9, NovaCraftBlocks.cracked_basal_bricks, 0, 2);
		world.setBlock(i + 21, j + 41, k + 9, NovaCraftBlocks.basal_bricks, 0, 2);
		world.setBlock(i + 22, j + 41, k + 9, NovaCraftBlocks.basal_bricks, 0, 2);
		world.setBlock(i + 23, j + 41, k + 9, NovaCraftBlocks.basal_bricks, 0, 2);
		world.setBlock(i + 24, j + 41, k + 9, NovaCraftBlocks.basal_bricks, 0, 2);
		world.setBlock(i + 25, j + 41, k + 9, NovaCraftBlocks.cracked_basal_bricks, 0, 2);
		world.setBlock(i + 26, j + 41, k + 9, NovaCraftBlocks.basal_bricks, 0, 2);
		world.setBlock(i + 27, j + 41, k + 9, NovaCraftBlocks.cracked_basal_bricks, 0, 2);
		world.setBlock(i + 0, j + 41, k + 10, NovaCraftBlocks.basal_bricks, 0, 2);
		world.setBlock(i + 1, j + 41, k + 10, NovaCraftBlocks.basal, 0, 2);
		world.setBlock(i + 2, j + 41, k + 10, NovaCraftBlocks.basal, 0, 2);
		world.setBlock(i + 3, j + 41, k + 10, NovaCraftBlocks.basal_bricks, 0, 2);
		world.setBlock(i + 4, j + 41, k + 10, NovaCraftBlocks.basal_bricks, 0, 2);
		world.setBlock(i + 5, j + 41, k + 10, NovaCraftBlocks.basal_bricks, 0, 2);
		world.setBlock(i + 6, j + 41, k + 10, NovaCraftBlocks.cracked_basal_bricks, 0, 2);
		world.setBlock(i + 7, j + 41, k + 10, NovaCraftBlocks.basal_bricks, 0, 2);
		world.setBlock(i + 8, j + 41, k + 10, NovaCraftBlocks.basal_bricks, 0, 2);
		world.setBlock(i + 9, j + 41, k + 10, NovaCraftBlocks.cracked_basal_bricks, 0, 2);
		world.setBlock(i + 10, j + 41, k + 10, NovaCraftBlocks.cracked_basal_bricks, 0, 2);
		world.setBlock(i + 11, j + 41, k + 10, NovaCraftBlocks.basal_bricks, 0, 2);
		world.setBlock(i + 12, j + 41, k + 10, NovaCraftBlocks.basal_bricks, 0, 2);
		world.setBlock(i + 13, j + 41, k + 10, NovaCraftBlocks.cracked_basal_bricks, 0, 2);
		world.setBlock(i + 14, j + 41, k + 10, NovaCraftBlocks.basal_bricks, 0, 2);
		world.setBlock(i + 15, j + 41, k + 10, NovaCraftBlocks.basal_bricks, 0, 2);
		world.setBlock(i + 16, j + 41, k + 10, NovaCraftBlocks.basal_bricks, 0, 2);
		world.setBlock(i + 17, j + 41, k + 10, NovaCraftBlocks.basal_bricks, 0, 2);
		world.setBlock(i + 18, j + 41, k + 10, NovaCraftBlocks.basal_bricks, 0, 2);
		world.setBlock(i + 19, j + 41, k + 10, NovaCraftBlocks.basal_bricks, 0, 2);
		world.setBlock(i + 20, j + 41, k + 10, NovaCraftBlocks.basal_bricks, 0, 2);
		world.setBlock(i + 21, j + 41, k + 10, NovaCraftBlocks.basal_bricks, 0, 2);
		world.setBlock(i + 22, j + 41, k + 10, NovaCraftBlocks.cracked_basal_bricks, 0, 2);
		world.setBlock(i + 23, j + 41, k + 10, NovaCraftBlocks.cracked_basal_bricks, 0, 2);
		world.setBlock(i + 24, j + 41, k + 10, NovaCraftBlocks.cracked_basal_bricks, 0, 2);
		world.setBlock(i + 25, j + 41, k + 10, NovaCraftBlocks.cracked_basal_bricks, 0, 2);
		world.setBlock(i + 26, j + 41, k + 10, NovaCraftBlocks.basal_bricks, 0, 2);
		world.setBlock(i + 27, j + 41, k + 10, NovaCraftBlocks.basal_bricks, 0, 2);
		world.setBlock(i + 0, j + 41, k + 11, Blocks.air, 0, 2);
		world.setBlock(i + 1, j + 41, k + 11, Blocks.air, 0, 2);
		world.setBlock(i + 2, j + 41, k + 11, Blocks.air, 0, 2);
		world.setBlock(i + 3, j + 41, k + 11, Blocks.air, 0, 2);
		world.setBlock(i + 4, j + 41, k + 11, Blocks.air, 0, 2);
		world.setBlock(i + 5, j + 41, k + 11, Blocks.air, 0, 2);
		world.setBlock(i + 6, j + 41, k + 11, Blocks.air, 0, 2);
		world.setBlock(i + 7, j + 41, k + 11, Blocks.air, 0, 2);
		world.setBlock(i + 8, j + 41, k + 11, Blocks.air, 0, 2);
		world.setBlock(i + 9, j + 41, k + 11, Blocks.air, 0, 2);
		world.setBlock(i + 10, j + 41, k + 11, Blocks.air, 0, 2);
		world.setBlock(i + 11, j + 41, k + 11, Blocks.air, 0, 2);
		world.setBlock(i + 12, j + 41, k + 11, Blocks.air, 0, 2);
		world.setBlock(i + 13, j + 41, k + 11, Blocks.air, 0, 2);
		world.setBlock(i + 14, j + 41, k + 11, NovaCraftBlocks.basal_bricks, 0, 2);
		world.setBlock(i + 15, j + 41, k + 11, NovaCraftBlocks.basal, 0, 2);
		world.setBlock(i + 16, j + 41, k + 11, NovaCraftBlocks.basal, 0, 2);
		world.setBlock(i + 17, j + 41, k + 11, NovaCraftBlocks.basal_brick_stairs, 1, 2);
		world.setBlock(i + 18, j + 41, k + 11, Blocks.air, 0, 2);
		world.setBlock(i + 19, j + 41, k + 11, Blocks.air, 0, 2);
		world.setBlock(i + 20, j + 41, k + 11, Blocks.air, 0, 2);
		world.setBlock(i + 21, j + 41, k + 11, Blocks.air, 0, 2);
		world.setBlock(i + 22, j + 41, k + 11, Blocks.air, 0, 2);
		world.setBlock(i + 23, j + 41, k + 11, Blocks.air, 0, 2);
		world.setBlock(i + 24, j + 41, k + 11, NovaCraftBlocks.basal_brick_stairs, 0, 2);
		world.setBlock(i + 25, j + 41, k + 11, NovaCraftBlocks.cracked_basal_bricks, 0, 2);
		world.setBlock(i + 26, j + 41, k + 11, NovaCraftBlocks.basal_bricks, 0, 2);
		world.setBlock(i + 27, j + 41, k + 11, NovaCraftBlocks.cracked_basal_bricks, 0, 2);
		world.setBlock(i + 0, j + 41, k + 12, Blocks.air, 0, 2);
		world.setBlock(i + 1, j + 41, k + 12, Blocks.air, 0, 2);
		world.setBlock(i + 2, j + 41, k + 12, Blocks.air, 0, 2);
		world.setBlock(i + 3, j + 41, k + 12, Blocks.air, 0, 2);
		world.setBlock(i + 4, j + 41, k + 12, Blocks.air, 0, 2);
		world.setBlock(i + 5, j + 41, k + 12, Blocks.air, 0, 2);
		world.setBlock(i + 6, j + 41, k + 12, Blocks.air, 0, 2);
		world.setBlock(i + 7, j + 41, k + 12, Blocks.air, 0, 2);
		world.setBlock(i + 8, j + 41, k + 12, Blocks.air, 0, 2);
		world.setBlock(i + 9, j + 41, k + 12, Blocks.air, 0, 2);
		world.setBlock(i + 10, j + 41, k + 12, Blocks.air, 0, 2);
		world.setBlock(i + 11, j + 41, k + 12, Blocks.air, 0, 2);
		world.setBlock(i + 12, j + 41, k + 12, Blocks.air, 0, 2);
		world.setBlock(i + 13, j + 41, k + 12, Blocks.air, 0, 2);
		world.setBlock(i + 14, j + 41, k + 12, NovaCraftBlocks.cracked_basal_bricks, 0, 2);
		world.setBlock(i + 15, j + 41, k + 12, NovaCraftBlocks.basal, 0, 2);
		world.setBlock(i + 16, j + 41, k + 12, NovaCraftBlocks.basal, 0, 2);
		world.setBlock(i + 17, j + 41, k + 12, NovaCraftBlocks.cracked_basal_bricks, 0, 2);
		world.setBlock(i + 18, j + 41, k + 12, NovaCraftBlocks.basal_bricks, 0, 2);
		world.setBlock(i + 19, j + 41, k + 12, NovaCraftBlocks.cracked_basal_bricks, 0, 2);
		world.setBlock(i + 20, j + 41, k + 12, NovaCraftBlocks.basal_bricks, 0, 2);
		world.setBlock(i + 21, j + 41, k + 12, NovaCraftBlocks.cracked_basal_bricks, 0, 2);
		world.setBlock(i + 22, j + 41, k + 12, NovaCraftBlocks.cracked_basal_bricks, 0, 2);
		world.setBlock(i + 23, j + 41, k + 12, NovaCraftBlocks.basal_bricks, 0, 2);
		world.setBlock(i + 24, j + 41, k + 12, NovaCraftBlocks.cracked_basal_bricks, 0, 2);
		world.setBlock(i + 25, j + 41, k + 12, NovaCraftBlocks.basal_bricks, 0, 2);
		world.setBlock(i + 26, j + 41, k + 12, NovaCraftBlocks.cracked_basal_bricks, 0, 2);
		world.setBlock(i + 27, j + 41, k + 12, NovaCraftBlocks.basal_bricks, 0, 2);
		world.setBlock(i + 0, j + 42, k + 0, Blocks.air, 0, 2);
		world.setBlock(i + 1, j + 42, k + 0, Blocks.air, 0, 2);
		world.setBlock(i + 2, j + 42, k + 0, Blocks.air, 0, 2);
		world.setBlock(i + 3, j + 42, k + 0, Blocks.air, 0, 2);
		world.setBlock(i + 4, j + 42, k + 0, Blocks.air, 0, 2);
		world.setBlock(i + 5, j + 42, k + 0, Blocks.air, 0, 2);
		world.setBlock(i + 6, j + 42, k + 0, Blocks.air, 0, 2);
		world.setBlock(i + 7, j + 42, k + 0, Blocks.air, 0, 2);
		world.setBlock(i + 8, j + 42, k + 0, Blocks.air, 0, 2);
		world.setBlock(i + 9, j + 42, k + 0, Blocks.air, 0, 2);
		world.setBlock(i + 10, j + 42, k + 0, Blocks.air, 0, 2);
		world.setBlock(i + 11, j + 42, k + 0, Blocks.air, 0, 2);
		world.setBlock(i + 12, j + 42, k + 0, Blocks.air, 0, 2);
		world.setBlock(i + 13, j + 42, k + 0, Blocks.air, 0, 2);
		world.setBlock(i + 14, j + 42, k + 0, Blocks.air, 0, 2);
		world.setBlock(i + 15, j + 42, k + 0, Blocks.air, 0, 2);
		world.setBlock(i + 16, j + 42, k + 0, Blocks.air, 0, 2);
		world.setBlock(i + 17, j + 42, k + 0, Blocks.air, 0, 2);
		world.setBlock(i + 18, j + 42, k + 0, Blocks.air, 0, 2);
		world.setBlock(i + 19, j + 42, k + 0, Blocks.air, 0, 2);
		world.setBlock(i + 20, j + 42, k + 0, Blocks.air, 0, 2);
		world.setBlock(i + 21, j + 42, k + 0, Blocks.air, 0, 2);
		world.setBlock(i + 22, j + 42, k + 0, Blocks.air, 0, 2);
		world.setBlock(i + 23, j + 42, k + 0, Blocks.air, 0, 2);
		world.setBlock(i + 24, j + 42, k + 0, Blocks.air, 0, 2);
		world.setBlock(i + 25, j + 42, k + 0, Blocks.air, 0, 2);
		world.setBlock(i + 26, j + 42, k + 0, Blocks.air, 0, 2);
		world.setBlock(i + 27, j + 42, k + 0, Blocks.air, 0, 2);
		world.setBlock(i + 0, j + 42, k + 1, NovaCraftBlocks.cracked_basal_bricks, 0, 2);
		world.setBlock(i + 1, j + 42, k + 1, NovaCraftBlocks.basal_bricks, 0, 2);
		world.setBlock(i + 2, j + 42, k + 1, Blocks.air, 0, 2);
		world.setBlock(i + 3, j + 42, k + 1, Blocks.air, 0, 2);
		world.setBlock(i + 4, j + 42, k + 1, NovaCraftBlocks.basal_bricks, 0, 2);
		world.setBlock(i + 5, j + 42, k + 1, NovaCraftBlocks.basal_bricks, 0, 2);
		world.setBlock(i + 6, j + 42, k + 1, Blocks.air, 0, 2);
		world.setBlock(i + 7, j + 42, k + 1, Blocks.air, 0, 2);
		world.setBlock(i + 8, j + 42, k + 1, NovaCraftBlocks.basal_bricks, 0, 2);
		world.setBlock(i + 9, j + 42, k + 1, NovaCraftBlocks.basal_bricks, 0, 2);
		world.setBlock(i + 10, j + 42, k + 1, Blocks.air, 0, 2);
		world.setBlock(i + 11, j + 42, k + 1, Blocks.air, 0, 2);
		world.setBlock(i + 12, j + 42, k + 1, NovaCraftBlocks.basal_bricks, 0, 2);
		world.setBlock(i + 13, j + 42, k + 1, NovaCraftBlocks.cracked_basal_bricks, 0, 2);
		world.setBlock(i + 14, j + 42, k + 1, Blocks.air, 0, 2);
		world.setBlock(i + 15, j + 42, k + 1, Blocks.air, 0, 2);
		world.setBlock(i + 16, j + 42, k + 1, Blocks.air, 0, 2);
		world.setBlock(i + 17, j + 42, k + 1, Blocks.air, 0, 2);
		world.setBlock(i + 18, j + 42, k + 1, Blocks.air, 0, 2);
		world.setBlock(i + 19, j + 42, k + 1, Blocks.air, 0, 2);
		world.setBlock(i + 20, j + 42, k + 1, Blocks.air, 0, 2);
		world.setBlock(i + 21, j + 42, k + 1, Blocks.air, 0, 2);
		world.setBlock(i + 22, j + 42, k + 1, Blocks.air, 0, 2);
		world.setBlock(i + 23, j + 42, k + 1, Blocks.air, 0, 2);
		world.setBlock(i + 24, j + 42, k + 1, Blocks.air, 0, 2);
		world.setBlock(i + 25, j + 42, k + 1, Blocks.air, 0, 2);
		world.setBlock(i + 26, j + 42, k + 1, Blocks.air, 0, 2);
		world.setBlock(i + 27, j + 42, k + 1, Blocks.air, 0, 2);
		world.setBlock(i + 0, j + 42, k + 2, NovaCraftBlocks.basal_bricks, 0, 2);
		world.setBlock(i + 1, j + 42, k + 2, NovaCraftBlocks.basal_bricks, 0, 2);
		world.setBlock(i + 2, j + 42, k + 2, Blocks.air, 0, 2);
		world.setBlock(i + 3, j + 42, k + 2, Blocks.air, 0, 2);
		world.setBlock(i + 4, j + 42, k + 2, NovaCraftBlocks.cracked_basal_bricks, 0, 2);
		world.setBlock(i + 5, j + 42, k + 2, NovaCraftBlocks.cracked_basal_bricks, 0, 2);
		world.setBlock(i + 6, j + 42, k + 2, Blocks.air, 0, 2);
		world.setBlock(i + 7, j + 42, k + 2, Blocks.air, 0, 2);
		world.setBlock(i + 8, j + 42, k + 2, NovaCraftBlocks.basal_bricks, 0, 2);
		world.setBlock(i + 9, j + 42, k + 2, NovaCraftBlocks.basal_bricks, 0, 2);
		world.setBlock(i + 10, j + 42, k + 2, Blocks.air, 0, 2);
		world.setBlock(i + 11, j + 42, k + 2, Blocks.air, 0, 2);
		world.setBlock(i + 12, j + 42, k + 2, NovaCraftBlocks.basal_bricks, 0, 2);
		world.setBlock(i + 13, j + 42, k + 2, NovaCraftBlocks.basal_bricks, 0, 2);
		world.setBlock(i + 14, j + 42, k + 2, Blocks.air, 0, 2);
		world.setBlock(i + 15, j + 42, k + 2, Blocks.air, 0, 2);
		world.setBlock(i + 16, j + 42, k + 2, Blocks.air, 0, 2);
		world.setBlock(i + 17, j + 42, k + 2, Blocks.air, 0, 2);
		world.setBlock(i + 18, j + 42, k + 2, Blocks.air, 0, 2);
		world.setBlock(i + 19, j + 42, k + 2, Blocks.air, 0, 2);
		world.setBlock(i + 20, j + 42, k + 2, Blocks.air, 0, 2);
		world.setBlock(i + 21, j + 42, k + 2, Blocks.air, 0, 2);
		world.setBlock(i + 22, j + 42, k + 2, Blocks.air, 0, 2);
		world.setBlock(i + 23, j + 42, k + 2, Blocks.air, 0, 2);
		world.setBlock(i + 24, j + 42, k + 2, Blocks.air, 0, 2);
		world.setBlock(i + 25, j + 42, k + 2, Blocks.air, 0, 2);
		world.setBlock(i + 26, j + 42, k + 2, Blocks.air, 0, 2);
		world.setBlock(i + 27, j + 42, k + 2, Blocks.air, 0, 2);
		world.setBlock(i + 0, j + 42, k + 3, NovaCraftBlocks.basal_bricks, 0, 2);
		world.setBlock(i + 1, j + 42, k + 3, NovaCraftBlocks.cracked_basal_bricks, 0, 2);
		world.setBlock(i + 2, j + 42, k + 3, Blocks.air, 0, 2);
		world.setBlock(i + 3, j + 42, k + 3, Blocks.air, 0, 2);
		world.setBlock(i + 4, j + 42, k + 3, NovaCraftBlocks.basal_bricks, 0, 2);
		world.setBlock(i + 5, j + 42, k + 3, NovaCraftBlocks.basal_bricks, 0, 2);
		world.setBlock(i + 6, j + 42, k + 3, Blocks.air, 0, 2);
		world.setBlock(i + 7, j + 42, k + 3, Blocks.air, 0, 2);
		world.setBlock(i + 8, j + 42, k + 3, NovaCraftBlocks.basal_bricks, 0, 2);
		world.setBlock(i + 9, j + 42, k + 3, NovaCraftBlocks.cracked_basal_bricks, 0, 2);
		world.setBlock(i + 10, j + 42, k + 3, Blocks.air, 0, 2);
		world.setBlock(i + 11, j + 42, k + 3, Blocks.air, 0, 2);
		world.setBlock(i + 12, j + 42, k + 3, NovaCraftBlocks.basal_bricks, 0, 2);
		world.setBlock(i + 13, j + 42, k + 3, NovaCraftBlocks.basal_bricks, 0, 2);
		world.setBlock(i + 14, j + 42, k + 3, NovaCraftBlocks.basal_bricks, 0, 2);
		world.setBlock(i + 15, j + 42, k + 3, NovaCraftBlocks.cracked_basal_bricks, 0, 2);
		world.setBlock(i + 16, j + 42, k + 3, Blocks.air, 0, 2);
		world.setBlock(i + 17, j + 42, k + 3, Blocks.air, 0, 2);
		world.setBlock(i + 18, j + 42, k + 3, NovaCraftBlocks.basal_bricks, 0, 2);
		world.setBlock(i + 19, j + 42, k + 3, NovaCraftBlocks.basal_bricks, 0, 2);
		world.setBlock(i + 20, j + 42, k + 3, Blocks.air, 0, 2);
		world.setBlock(i + 21, j + 42, k + 3, Blocks.air, 0, 2);
		world.setBlock(i + 22, j + 42, k + 3, NovaCraftBlocks.cracked_basal_bricks, 0, 2);
		world.setBlock(i + 23, j + 42, k + 3, NovaCraftBlocks.basal_bricks, 0, 2);
		world.setBlock(i + 24, j + 42, k + 3, Blocks.air, 0, 2);
		world.setBlock(i + 25, j + 42, k + 3, Blocks.air, 0, 2);
		world.setBlock(i + 26, j + 42, k + 3, NovaCraftBlocks.cracked_basal_bricks, 0, 2);
		world.setBlock(i + 27, j + 42, k + 3, NovaCraftBlocks.cracked_basal_bricks, 0, 2);
		world.setBlock(i + 0, j + 42, k + 4, NovaCraftBlocks.basal_bricks, 0, 2);
		world.setBlock(i + 1, j + 42, k + 4, NovaCraftBlocks.basal_bricks, 0, 2);
		world.setBlock(i + 2, j + 42, k + 4, NovaCraftBlocks.cracked_basal_bricks, 0, 2);
		world.setBlock(i + 3, j + 42, k + 4, NovaCraftBlocks.basal_bricks, 0, 2);
		world.setBlock(i + 4, j + 42, k + 4, NovaCraftBlocks.cracked_basal_bricks, 0, 2);
		world.setBlock(i + 5, j + 42, k + 4, NovaCraftBlocks.basal_bricks, 0, 2);
		world.setBlock(i + 6, j + 42, k + 4, NovaCraftBlocks.cracked_basal_bricks, 0, 2);
		world.setBlock(i + 7, j + 42, k + 4, NovaCraftBlocks.basal_bricks, 0, 2);
		world.setBlock(i + 8, j + 42, k + 4, NovaCraftBlocks.cracked_basal_bricks, 0, 2);
		world.setBlock(i + 9, j + 42, k + 4, NovaCraftBlocks.basal_bricks, 0, 2);
		world.setBlock(i + 10, j + 42, k + 4, NovaCraftBlocks.basal_bricks, 0, 2);
		world.setBlock(i + 11, j + 42, k + 4, NovaCraftBlocks.basal_bricks, 0, 2);
		world.setBlock(i + 12, j + 42, k + 4, NovaCraftBlocks.basal_bricks, 0, 2);
		world.setBlock(i + 13, j + 42, k + 4, NovaCraftBlocks.cracked_basal_bricks, 0, 2);
		world.setBlock(i + 14, j + 42, k + 4, NovaCraftBlocks.basal_bricks, 0, 2);
		world.setBlock(i + 15, j + 42, k + 4, NovaCraftBlocks.basal_bricks, 0, 2);
		world.setBlock(i + 16, j + 42, k + 4, Blocks.air, 0, 2);
		world.setBlock(i + 17, j + 42, k + 4, Blocks.air, 0, 2);
		world.setBlock(i + 18, j + 42, k + 4, NovaCraftBlocks.basal_bricks, 0, 2);
		world.setBlock(i + 19, j + 42, k + 4, NovaCraftBlocks.basal_bricks, 0, 2);
		world.setBlock(i + 20, j + 42, k + 4, Blocks.air, 0, 2);
		world.setBlock(i + 21, j + 42, k + 4, Blocks.air, 0, 2);
		world.setBlock(i + 22, j + 42, k + 4, NovaCraftBlocks.basal_bricks, 0, 2);
		world.setBlock(i + 23, j + 42, k + 4, NovaCraftBlocks.cracked_basal_bricks, 0, 2);
		world.setBlock(i + 24, j + 42, k + 4, Blocks.air, 0, 2);
		world.setBlock(i + 25, j + 42, k + 4, Blocks.air, 0, 2);
		world.setBlock(i + 26, j + 42, k + 4, NovaCraftBlocks.basal_bricks, 0, 2);
		world.setBlock(i + 27, j + 42, k + 4, NovaCraftBlocks.cracked_basal_bricks, 0, 2);
		world.setBlock(i + 0, j + 42, k + 5, NovaCraftBlocks.basal_bricks, 0, 2);
		world.setBlock(i + 1, j + 42, k + 5, NovaCraftBlocks.basal_bricks, 0, 2);
		world.setBlock(i + 2, j + 42, k + 5, NovaCraftBlocks.basal_bricks, 0, 2);
		world.setBlock(i + 3, j + 42, k + 5, NovaCraftBlocks.cracked_basal_bricks, 0, 2);
		world.setBlock(i + 4, j + 42, k + 5, NovaCraftBlocks.basal_bricks, 0, 2);
		world.setBlock(i + 5, j + 42, k + 5, NovaCraftBlocks.cracked_basal_bricks, 0, 2);
		world.setBlock(i + 6, j + 42, k + 5, NovaCraftBlocks.cracked_basal_bricks, 0, 2);
		world.setBlock(i + 7, j + 42, k + 5, NovaCraftBlocks.basal_bricks, 0, 2);
		world.setBlock(i + 8, j + 42, k + 5, NovaCraftBlocks.basal_bricks, 0, 2);
		world.setBlock(i + 9, j + 42, k + 5, NovaCraftBlocks.basal_bricks, 0, 2);
		world.setBlock(i + 10, j + 42, k + 5, NovaCraftBlocks.basal_bricks, 0, 2);
		world.setBlock(i + 11, j + 42, k + 5, NovaCraftBlocks.cracked_basal_bricks, 0, 2);
		world.setBlock(i + 12, j + 42, k + 5, NovaCraftBlocks.basal_bricks, 0, 2);
		world.setBlock(i + 13, j + 42, k + 5, NovaCraftBlocks.cracked_basal_bricks, 0, 2);
		world.setBlock(i + 14, j + 42, k + 5, NovaCraftBlocks.cracked_basal_bricks, 0, 2);
		world.setBlock(i + 15, j + 42, k + 5, NovaCraftBlocks.basal_bricks, 0, 2);
		world.setBlock(i + 16, j + 42, k + 5, Blocks.air, 0, 2);
		world.setBlock(i + 17, j + 42, k + 5, Blocks.air, 0, 2);
		world.setBlock(i + 18, j + 42, k + 5, NovaCraftBlocks.cracked_basal_bricks, 0, 2);
		world.setBlock(i + 19, j + 42, k + 5, NovaCraftBlocks.cracked_basal_bricks, 0, 2);
		world.setBlock(i + 20, j + 42, k + 5, Blocks.air, 0, 2);
		world.setBlock(i + 21, j + 42, k + 5, Blocks.air, 0, 2);
		world.setBlock(i + 22, j + 42, k + 5, NovaCraftBlocks.cracked_basal_bricks, 0, 2);
		world.setBlock(i + 23, j + 42, k + 5, NovaCraftBlocks.cracked_basal_bricks, 0, 2);
		world.setBlock(i + 24, j + 42, k + 5, Blocks.air, 0, 2);
		world.setBlock(i + 25, j + 42, k + 5, Blocks.air, 0, 2);
		world.setBlock(i + 26, j + 42, k + 5, NovaCraftBlocks.basal_bricks, 0, 2);
		world.setBlock(i + 27, j + 42, k + 5, NovaCraftBlocks.basal_bricks, 0, 2);
		world.setBlock(i + 0, j + 42, k + 6, NovaCraftBlocks.basal_bricks, 0, 2);
		world.setBlock(i + 1, j + 42, k + 6, NovaCraftBlocks.basal_bricks, 0, 2);
		world.setBlock(i + 2, j + 42, k + 6, NovaCraftBlocks.basal_bricks, 0, 2);
		world.setBlock(i + 3, j + 42, k + 6, NovaCraftBlocks.basal_bricks, 0, 2);
		world.setBlock(i + 4, j + 42, k + 6, NovaCraftBlocks.cracked_basal_bricks, 0, 2);
		world.setBlock(i + 5, j + 42, k + 6, NovaCraftBlocks.cracked_basal_bricks, 0, 2);
		world.setBlock(i + 6, j + 42, k + 6, NovaCraftBlocks.basal_bricks, 0, 2);
		world.setBlock(i + 7, j + 42, k + 6, NovaCraftBlocks.basal_bricks, 0, 2);
		world.setBlock(i + 8, j + 42, k + 6, NovaCraftBlocks.cracked_basal_bricks, 0, 2);
		world.setBlock(i + 9, j + 42, k + 6, NovaCraftBlocks.basal_bricks, 0, 2);
		world.setBlock(i + 10, j + 42, k + 6, NovaCraftBlocks.basal_bricks, 0, 2);
		world.setBlock(i + 11, j + 42, k + 6, NovaCraftBlocks.cracked_basal_bricks, 0, 2);
		world.setBlock(i + 12, j + 42, k + 6, NovaCraftBlocks.cracked_basal_bricks, 0, 2);
		world.setBlock(i + 13, j + 42, k + 6, Blocks.air, 0, 2);
		world.setBlock(i + 14, j + 42, k + 6, NovaCraftBlocks.basal_bricks, 0, 2);
		world.setBlock(i + 15, j + 42, k + 6, NovaCraftBlocks.basal_bricks, 0, 2);
		world.setBlock(i + 16, j + 42, k + 6, NovaCraftBlocks.cracked_basal_bricks, 0, 2);
		world.setBlock(i + 17, j + 42, k + 6, NovaCraftBlocks.basal_bricks, 0, 2);
		world.setBlock(i + 18, j + 42, k + 6, NovaCraftBlocks.cracked_basal_bricks, 0, 2);
		world.setBlock(i + 19, j + 42, k + 6, NovaCraftBlocks.cracked_basal_bricks, 0, 2);
		world.setBlock(i + 20, j + 42, k + 6, NovaCraftBlocks.basal_bricks, 0, 2);
		world.setBlock(i + 21, j + 42, k + 6, NovaCraftBlocks.basal_bricks, 0, 2);
		world.setBlock(i + 22, j + 42, k + 6, NovaCraftBlocks.cracked_basal_bricks, 0, 2);
		world.setBlock(i + 23, j + 42, k + 6, NovaCraftBlocks.basal_bricks, 0, 2);
		world.setBlock(i + 24, j + 42, k + 6, NovaCraftBlocks.cracked_basal_bricks, 0, 2);
		world.setBlock(i + 25, j + 42, k + 6, NovaCraftBlocks.cracked_basal_bricks, 0, 2);
		world.setBlock(i + 26, j + 42, k + 6, NovaCraftBlocks.basal_bricks, 0, 2);
		world.setBlock(i + 27, j + 42, k + 6, NovaCraftBlocks.basal_bricks, 0, 2);
		world.setBlock(i + 0, j + 42, k + 7, NovaCraftBlocks.basal_bricks, 0, 2);
		world.setBlock(i + 1, j + 42, k + 7, NovaCraftBlocks.basal_bricks, 0, 2);
		world.setBlock(i + 2, j + 42, k + 7, NovaCraftBlocks.cracked_basal_bricks, 0, 2);
		world.setBlock(i + 3, j + 42, k + 7, NovaCraftBlocks.cracked_basal_bricks, 0, 2);
		world.setBlock(i + 4, j + 42, k + 7, NovaCraftBlocks.basal_bricks, 0, 2);
		world.setBlock(i + 5, j + 42, k + 7, NovaCraftBlocks.cracked_basal_bricks, 0, 2);
		world.setBlock(i + 6, j + 42, k + 7, NovaCraftBlocks.basal_bricks, 0, 2);
		world.setBlock(i + 7, j + 42, k + 7, NovaCraftBlocks.cracked_basal_bricks, 0, 2);
		world.setBlock(i + 8, j + 42, k + 7, NovaCraftBlocks.basal_bricks, 0, 2);
		world.setBlock(i + 9, j + 42, k + 7, NovaCraftBlocks.basal_bricks, 0, 2);
		world.setBlock(i + 10, j + 42, k + 7, NovaCraftBlocks.cracked_basal_bricks, 0, 2);
		world.setBlock(i + 11, j + 42, k + 7, NovaCraftBlocks.basal_bricks, 0, 2);
		world.setBlock(i + 12, j + 42, k + 7, NovaCraftBlocks.cracked_basal_bricks, 0, 2);
		world.setBlock(i + 13, j + 42, k + 7, NovaCraftBlocks.cracked_basal_bricks, 0, 2);
		world.setBlock(i + 14, j + 42, k + 7, NovaCraftBlocks.cracked_basal_bricks, 0, 2);
		world.setBlock(i + 15, j + 42, k + 7, NovaCraftBlocks.basal_bricks, 0, 2);
		world.setBlock(i + 16, j + 42, k + 7, NovaCraftBlocks.basal_bricks, 0, 2);
		world.setBlock(i + 17, j + 42, k + 7, NovaCraftBlocks.basal_bricks, 0, 2);
		world.setBlock(i + 18, j + 42, k + 7, NovaCraftBlocks.cracked_basal_bricks, 0, 2);
		world.setBlock(i + 19, j + 42, k + 7, NovaCraftBlocks.basal_bricks, 0, 2);
		world.setBlock(i + 20, j + 42, k + 7, NovaCraftBlocks.basal_bricks, 0, 2);
		world.setBlock(i + 21, j + 42, k + 7, NovaCraftBlocks.basal_bricks, 0, 2);
		world.setBlock(i + 22, j + 42, k + 7, NovaCraftBlocks.basal_bricks, 0, 2);
		world.setBlock(i + 23, j + 42, k + 7, NovaCraftBlocks.basal_bricks, 0, 2);
		world.setBlock(i + 24, j + 42, k + 7, NovaCraftBlocks.cracked_basal_bricks, 0, 2);
		world.setBlock(i + 25, j + 42, k + 7, NovaCraftBlocks.cracked_basal_bricks, 0, 2);
		world.setBlock(i + 26, j + 42, k + 7, NovaCraftBlocks.cracked_basal_bricks, 0, 2);
		world.setBlock(i + 27, j + 42, k + 7, NovaCraftBlocks.basal_bricks, 0, 2);
		world.setBlock(i + 0, j + 42, k + 8, NovaCraftBlocks.cracked_basal_bricks, 0, 2);
		world.setBlock(i + 1, j + 42, k + 8, NovaCraftBlocks.basal_bricks, 0, 2);
		world.setBlock(i + 2, j + 42, k + 8, NovaCraftBlocks.cracked_basal_bricks, 0, 2);
		world.setBlock(i + 3, j + 42, k + 8, NovaCraftBlocks.basal_bricks, 0, 2);
		world.setBlock(i + 4, j + 42, k + 8, NovaCraftBlocks.cracked_basal_bricks, 0, 2);
		world.setBlock(i + 5, j + 42, k + 8, NovaCraftBlocks.basal_bricks, 0, 2);
		world.setBlock(i + 6, j + 42, k + 8, NovaCraftBlocks.basal_bricks, 0, 2);
		world.setBlock(i + 7, j + 42, k + 8, NovaCraftBlocks.cracked_basal_bricks, 0, 2);
		world.setBlock(i + 8, j + 42, k + 8, NovaCraftBlocks.basal_bricks, 0, 2);
		world.setBlock(i + 9, j + 42, k + 8, NovaCraftBlocks.cracked_basal_bricks, 0, 2);
		world.setBlock(i + 10, j + 42, k + 8, NovaCraftBlocks.basal_bricks, 0, 2);
		world.setBlock(i + 11, j + 42, k + 8, NovaCraftBlocks.basal_bricks, 0, 2);
		world.setBlock(i + 12, j + 42, k + 8, NovaCraftBlocks.cracked_basal_bricks, 0, 2);
		world.setBlock(i + 13, j + 42, k + 8, NovaCraftBlocks.cracked_basal_bricks, 0, 2);
		world.setBlock(i + 14, j + 42, k + 8, NovaCraftBlocks.basal_bricks, 0, 2);
		world.setBlock(i + 15, j + 42, k + 8, NovaCraftBlocks.cracked_basal_bricks, 0, 2);
		world.setBlock(i + 16, j + 42, k + 8, NovaCraftBlocks.cracked_basal_bricks, 0, 2);
		world.setBlock(i + 17, j + 42, k + 8, NovaCraftBlocks.basal_bricks, 0, 2);
		world.setBlock(i + 18, j + 42, k + 8, NovaCraftBlocks.basal_bricks, 0, 2);
		world.setBlock(i + 19, j + 42, k + 8, NovaCraftBlocks.basal_bricks, 0, 2);
		world.setBlock(i + 20, j + 42, k + 8, NovaCraftBlocks.cracked_basal_bricks, 0, 2);
		world.setBlock(i + 21, j + 42, k + 8, NovaCraftBlocks.basal_bricks, 0, 2);
		world.setBlock(i + 22, j + 42, k + 8, NovaCraftBlocks.basal_bricks, 0, 2);
		world.setBlock(i + 23, j + 42, k + 8, NovaCraftBlocks.basal_bricks, 0, 2);
		world.setBlock(i + 24, j + 42, k + 8, NovaCraftBlocks.basal_bricks, 0, 2);
		world.setBlock(i + 25, j + 42, k + 8, NovaCraftBlocks.cracked_basal_bricks, 0, 2);
		world.setBlock(i + 26, j + 42, k + 8, NovaCraftBlocks.basal_bricks, 0, 2);
		world.setBlock(i + 27, j + 42, k + 8, NovaCraftBlocks.cracked_basal_bricks, 0, 2);
		world.setBlock(i + 0, j + 42, k + 9, NovaCraftBlocks.basal_bricks, 0, 2);
		world.setBlock(i + 1, j + 42, k + 9, Blocks.air, 0, 2);
		world.setBlock(i + 2, j + 42, k + 9, Blocks.air, 0, 2);
		world.setBlock(i + 3, j + 42, k + 9, Blocks.air, 0, 2);
		world.setBlock(i + 4, j + 42, k + 9, Blocks.air, 0, 2);
		world.setBlock(i + 5, j + 42, k + 9, Blocks.air, 0, 2);
		world.setBlock(i + 6, j + 42, k + 9, NovaCraftBlocks.basal_bricks, 0, 2);
		world.setBlock(i + 7, j + 42, k + 9, NovaCraftBlocks.cracked_basal_bricks, 0, 2);
		world.setBlock(i + 8, j + 42, k + 9, Blocks.air, 0, 2);
		world.setBlock(i + 9, j + 42, k + 9, Blocks.air, 0, 2);
		world.setBlock(i + 10, j + 42, k + 9, Blocks.air, 0, 2);
		world.setBlock(i + 11, j + 42, k + 9, Blocks.air, 0, 2);
		world.setBlock(i + 12, j + 42, k + 9, Blocks.air, 0, 2);
		world.setBlock(i + 13, j + 42, k + 9, NovaCraftBlocks.basal_bricks, 0, 2);
		world.setBlock(i + 14, j + 42, k + 9, NovaCraftBlocks.basal_bricks, 0, 2);
		world.setBlock(i + 15, j + 42, k + 9, NovaCraftBlocks.basal_bricks, 0, 2);
		world.setBlock(i + 16, j + 42, k + 9, NovaCraftBlocks.basal_bricks, 0, 2);
		world.setBlock(i + 17, j + 42, k + 9, NovaCraftBlocks.basal_bricks, 0, 2);
		world.setBlock(i + 18, j + 42, k + 9, NovaCraftBlocks.cracked_basal_bricks, 0, 2);
		world.setBlock(i + 19, j + 42, k + 9, NovaCraftBlocks.cracked_basal_bricks, 0, 2);
		world.setBlock(i + 20, j + 42, k + 9, NovaCraftBlocks.basal_bricks, 0, 2);
		world.setBlock(i + 21, j + 42, k + 9, NovaCraftBlocks.cracked_basal_bricks, 0, 2);
		world.setBlock(i + 22, j + 42, k + 9, NovaCraftBlocks.basal_bricks, 0, 2);
		world.setBlock(i + 23, j + 42, k + 9, NovaCraftBlocks.cracked_basal_bricks, 0, 2);
		world.setBlock(i + 24, j + 42, k + 9, NovaCraftBlocks.cracked_basal_bricks, 0, 2);
		world.setBlock(i + 25, j + 42, k + 9, NovaCraftBlocks.basal_bricks, 0, 2);
		world.setBlock(i + 26, j + 42, k + 9, NovaCraftBlocks.basal_bricks, 0, 2);
		world.setBlock(i + 27, j + 42, k + 9, NovaCraftBlocks.cracked_basal_bricks, 0, 2);
		world.setBlock(i + 0, j + 42, k + 10, NovaCraftBlocks.basal_bricks, 0, 2);
		world.setBlock(i + 1, j + 42, k + 10, Blocks.air, 0, 2);
		world.setBlock(i + 2, j + 42, k + 10, Blocks.air, 0, 2);
		world.setBlock(i + 3, j + 42, k + 10, Blocks.air, 0, 2);
		world.setBlock(i + 4, j + 42, k + 10, Blocks.air, 0, 2);
		world.setBlock(i + 5, j + 42, k + 10, NovaCraftBlocks.basal_bricks, 0, 2);
		world.setBlock(i + 6, j + 42, k + 10, NovaCraftBlocks.cracked_basal_bricks, 0, 2);
		world.setBlock(i + 7, j + 42, k + 10, NovaCraftBlocks.basal_bricks, 0, 2);
		world.setBlock(i + 8, j + 42, k + 10, NovaCraftBlocks.basal, 0, 2);
		world.setBlock(i + 9, j + 42, k + 10, NovaCraftBlocks.basal_bricks, 0, 2);
		world.setBlock(i + 10, j + 42, k + 10, NovaCraftBlocks.basal_brick_stairs, 1, 2);
		world.setBlock(i + 11, j + 42, k + 10, Blocks.air, 0, 2);
		world.setBlock(i + 12, j + 42, k + 10, Blocks.air, 0, 2);
		world.setBlock(i + 13, j + 42, k + 10, NovaCraftBlocks.basal_bricks, 0, 2);
		world.setBlock(i + 14, j + 42, k + 10, NovaCraftBlocks.basal_bricks, 0, 2);
		world.setBlock(i + 15, j + 42, k + 10, NovaCraftBlocks.basal_bricks, 0, 2);
		world.setBlock(i + 16, j + 42, k + 10, NovaCraftBlocks.cracked_basal_bricks, 0, 2);
		world.setBlock(i + 17, j + 42, k + 10, NovaCraftBlocks.cracked_basal_bricks, 0, 2);
		world.setBlock(i + 18, j + 42, k + 10, NovaCraftBlocks.basal_bricks, 0, 2);
		world.setBlock(i + 19, j + 42, k + 10, NovaCraftBlocks.basal_bricks, 0, 2);
		world.setBlock(i + 20, j + 42, k + 10, NovaCraftBlocks.basal_bricks, 0, 2);
		world.setBlock(i + 21, j + 42, k + 10, NovaCraftBlocks.basal_bricks, 0, 2);
		world.setBlock(i + 22, j + 42, k + 10, NovaCraftBlocks.basal_bricks, 0, 2);
		world.setBlock(i + 23, j + 42, k + 10, NovaCraftBlocks.cracked_basal_bricks, 0, 2);
		world.setBlock(i + 24, j + 42, k + 10, NovaCraftBlocks.basal_bricks, 0, 2);
		world.setBlock(i + 25, j + 42, k + 10, NovaCraftBlocks.cracked_basal_bricks, 0, 2);
		world.setBlock(i + 26, j + 42, k + 10, NovaCraftBlocks.basal_bricks, 0, 2);
		world.setBlock(i + 27, j + 42, k + 10, NovaCraftBlocks.basal_bricks, 0, 2);
		world.setBlock(i + 0, j + 42, k + 11, Blocks.air, 0, 2);
		world.setBlock(i + 1, j + 42, k + 11, Blocks.air, 0, 2);
		world.setBlock(i + 2, j + 42, k + 11, Blocks.air, 0, 2);
		world.setBlock(i + 3, j + 42, k + 11, Blocks.air, 0, 2);
		world.setBlock(i + 4, j + 42, k + 11, Blocks.air, 0, 2);
		world.setBlock(i + 5, j + 42, k + 11, Blocks.air, 0, 2);
		world.setBlock(i + 6, j + 42, k + 11, Blocks.air, 0, 2);
		world.setBlock(i + 7, j + 42, k + 11, Blocks.air, 0, 2);
		world.setBlock(i + 8, j + 42, k + 11, Blocks.air, 0, 2);
		world.setBlock(i + 9, j + 42, k + 11, Blocks.air, 0, 2);
		world.setBlock(i + 10, j + 42, k + 11, Blocks.air, 0, 2);
		world.setBlock(i + 11, j + 42, k + 11, Blocks.air, 0, 2);
		world.setBlock(i + 12, j + 42, k + 11, Blocks.air, 0, 2);
		world.setBlock(i + 13, j + 42, k + 11, Blocks.air, 0, 2);
		world.setBlock(i + 14, j + 42, k + 11, NovaCraftBlocks.cracked_basal_bricks, 0, 2);
		world.setBlock(i + 15, j + 42, k + 11, Blocks.diamond_block, 0, 2);
		world.setBlock(i + 16, j + 42, k + 11, Blocks.air, 0, 2);
		world.setBlock(i + 17, j + 42, k + 11, Blocks.air, 0, 2);
		world.setBlock(i + 18, j + 42, k + 11, Blocks.air, 0, 2);
		world.setBlock(i + 19, j + 42, k + 11, Blocks.air, 0, 2);
		world.setBlock(i + 20, j + 42, k + 11, NovaCraftBlocks.cracked_basal_bricks, 0, 2);
		world.setBlock(i + 21, j + 42, k + 11, NovaCraftBlocks.basal_bricks, 0, 2);
		world.setBlock(i + 22, j + 42, k + 11, Blocks.air, 0, 2);
		world.setBlock(i + 23, j + 42, k + 11, Blocks.air, 0, 2);
		world.setBlock(i + 24, j + 42, k + 11, Blocks.air, 0, 2);
		world.setBlock(i + 25, j + 42, k + 11, Blocks.air, 0, 2);
		world.setBlock(i + 26, j + 42, k + 11, Blocks.air, 0, 2);
		world.setBlock(i + 27, j + 42, k + 11, NovaCraftBlocks.basal_bricks, 0, 2);
		world.setBlock(i + 0, j + 42, k + 12, Blocks.air, 0, 2);
		world.setBlock(i + 1, j + 42, k + 12, Blocks.air, 0, 2);
		world.setBlock(i + 2, j + 42, k + 12, Blocks.air, 0, 2);
		world.setBlock(i + 3, j + 42, k + 12, Blocks.air, 0, 2);
		world.setBlock(i + 4, j + 42, k + 12, Blocks.air, 0, 2);
		world.setBlock(i + 5, j + 42, k + 12, Blocks.air, 0, 2);
		world.setBlock(i + 6, j + 42, k + 12, Blocks.air, 0, 2);
		world.setBlock(i + 7, j + 42, k + 12, Blocks.air, 0, 2);
		world.setBlock(i + 8, j + 42, k + 12, Blocks.air, 0, 2);
		world.setBlock(i + 9, j + 42, k + 12, Blocks.air, 0, 2);
		world.setBlock(i + 10, j + 42, k + 12, Blocks.air, 0, 2);
		world.setBlock(i + 11, j + 42, k + 12, Blocks.air, 0, 2);
		world.setBlock(i + 12, j + 42, k + 12, Blocks.air, 0, 2);
		world.setBlock(i + 13, j + 42, k + 12, Blocks.air, 0, 2);
		world.setBlock(i + 14, j + 42, k + 12, NovaCraftBlocks.cracked_basal_bricks, 0, 2);
		world.setBlock(i + 15, j + 42, k + 12, Blocks.air, 0, 2);
		world.setBlock(i + 16, j + 42, k + 12, Blocks.air, 0, 2);
		world.setBlock(i + 17, j + 42, k + 12, Blocks.air, 0, 2);
		world.setBlock(i + 18, j + 42, k + 12, Blocks.air, 0, 2);
		world.setBlock(i + 19, j + 42, k + 12, NovaCraftBlocks.basal_bricks, 0, 2);
		world.setBlock(i + 20, j + 42, k + 12, NovaCraftBlocks.basal_bricks, 0, 2);
		world.setBlock(i + 21, j + 42, k + 12, NovaCraftBlocks.cracked_basal_bricks, 0, 2);
		world.setBlock(i + 22, j + 42, k + 12, NovaCraftBlocks.basal, 0, 2);
		world.setBlock(i + 23, j + 42, k + 12, NovaCraftBlocks.basal_bricks, 0, 2);
		world.setBlock(i + 24, j + 42, k + 12, NovaCraftBlocks.basal_brick_stairs, 1, 2);
		world.setBlock(i + 25, j + 42, k + 12, Blocks.air, 0, 2);
		world.setBlock(i + 26, j + 42, k + 12, Blocks.air, 0, 2);
		world.setBlock(i + 27, j + 42, k + 12, NovaCraftBlocks.basal_bricks, 0, 2);
		world.setBlock(i + 0, j + 43, k + 0, Blocks.air, 0, 2);
		world.setBlock(i + 1, j + 43, k + 0, Blocks.air, 0, 2);
		world.setBlock(i + 2, j + 43, k + 0, Blocks.air, 0, 2);
		world.setBlock(i + 3, j + 43, k + 0, Blocks.air, 0, 2);
		world.setBlock(i + 4, j + 43, k + 0, Blocks.air, 0, 2);
		world.setBlock(i + 5, j + 43, k + 0, Blocks.air, 0, 2);
		world.setBlock(i + 6, j + 43, k + 0, Blocks.air, 0, 2);
		world.setBlock(i + 7, j + 43, k + 0, Blocks.air, 0, 2);
		world.setBlock(i + 8, j + 43, k + 0, Blocks.air, 0, 2);
		world.setBlock(i + 9, j + 43, k + 0, Blocks.air, 0, 2);
		world.setBlock(i + 10, j + 43, k + 0, Blocks.air, 0, 2);
		world.setBlock(i + 11, j + 43, k + 0, Blocks.air, 0, 2);
		world.setBlock(i + 12, j + 43, k + 0, Blocks.air, 0, 2);
		world.setBlock(i + 13, j + 43, k + 0, Blocks.air, 0, 2);
		world.setBlock(i + 14, j + 43, k + 0, Blocks.air, 0, 2);
		world.setBlock(i + 15, j + 43, k + 0, Blocks.air, 0, 2);
		world.setBlock(i + 16, j + 43, k + 0, Blocks.air, 0, 2);
		world.setBlock(i + 17, j + 43, k + 0, Blocks.air, 0, 2);
		world.setBlock(i + 18, j + 43, k + 0, Blocks.air, 0, 2);
		world.setBlock(i + 19, j + 43, k + 0, Blocks.air, 0, 2);
		world.setBlock(i + 20, j + 43, k + 0, Blocks.air, 0, 2);
		world.setBlock(i + 21, j + 43, k + 0, Blocks.air, 0, 2);
		world.setBlock(i + 22, j + 43, k + 0, Blocks.air, 0, 2);
		world.setBlock(i + 23, j + 43, k + 0, Blocks.air, 0, 2);
		world.setBlock(i + 24, j + 43, k + 0, Blocks.air, 0, 2);
		world.setBlock(i + 25, j + 43, k + 0, Blocks.air, 0, 2);
		world.setBlock(i + 26, j + 43, k + 0, Blocks.air, 0, 2);
		world.setBlock(i + 27, j + 43, k + 0, Blocks.air, 0, 2);
		world.setBlock(i + 0, j + 43, k + 1, NovaCraftBlocks.cracked_basal_bricks, 0, 2);
		world.setBlock(i + 1, j + 43, k + 1, NovaCraftBlocks.basal_bricks, 0, 2);
		world.setBlock(i + 2, j + 43, k + 1, Blocks.air, 0, 2);
		world.setBlock(i + 3, j + 43, k + 1, Blocks.air, 0, 2);
		world.setBlock(i + 4, j + 43, k + 1, NovaCraftBlocks.basal_bricks, 0, 2);
		world.setBlock(i + 5, j + 43, k + 1, NovaCraftBlocks.basal_bricks, 0, 2);
		world.setBlock(i + 6, j + 43, k + 1, Blocks.air, 0, 2);
		world.setBlock(i + 7, j + 43, k + 1, Blocks.air, 0, 2);
		world.setBlock(i + 8, j + 43, k + 1, NovaCraftBlocks.cracked_basal_bricks, 0, 2);
		world.setBlock(i + 9, j + 43, k + 1, NovaCraftBlocks.basal_bricks, 0, 2);
		world.setBlock(i + 10, j + 43, k + 1, Blocks.air, 0, 2);
		world.setBlock(i + 11, j + 43, k + 1, Blocks.air, 0, 2);
		world.setBlock(i + 12, j + 43, k + 1, NovaCraftBlocks.basal_bricks, 0, 2);
		world.setBlock(i + 13, j + 43, k + 1, NovaCraftBlocks.basal_bricks, 0, 2);
		world.setBlock(i + 14, j + 43, k + 1, Blocks.air, 0, 2);
		world.setBlock(i + 15, j + 43, k + 1, Blocks.air, 0, 2);
		world.setBlock(i + 16, j + 43, k + 1, Blocks.air, 0, 2);
		world.setBlock(i + 17, j + 43, k + 1, Blocks.air, 0, 2);
		world.setBlock(i + 18, j + 43, k + 1, Blocks.air, 0, 2);
		world.setBlock(i + 19, j + 43, k + 1, Blocks.air, 0, 2);
		world.setBlock(i + 20, j + 43, k + 1, Blocks.air, 0, 2);
		world.setBlock(i + 21, j + 43, k + 1, Blocks.air, 0, 2);
		world.setBlock(i + 22, j + 43, k + 1, Blocks.air, 0, 2);
		world.setBlock(i + 23, j + 43, k + 1, Blocks.air, 0, 2);
		world.setBlock(i + 24, j + 43, k + 1, Blocks.air, 0, 2);
		world.setBlock(i + 25, j + 43, k + 1, Blocks.air, 0, 2);
		world.setBlock(i + 26, j + 43, k + 1, Blocks.air, 0, 2);
		world.setBlock(i + 27, j + 43, k + 1, Blocks.air, 0, 2);
		world.setBlock(i + 0, j + 43, k + 2, NovaCraftBlocks.basal_bricks, 0, 2);
		world.setBlock(i + 1, j + 43, k + 2, NovaCraftBlocks.basal_bricks, 0, 2);
		world.setBlock(i + 2, j + 43, k + 2, Blocks.air, 0, 2);
		world.setBlock(i + 3, j + 43, k + 2, Blocks.air, 0, 2);
		world.setBlock(i + 4, j + 43, k + 2, NovaCraftBlocks.basal_bricks, 0, 2);
		world.setBlock(i + 5, j + 43, k + 2, NovaCraftBlocks.cracked_basal_bricks, 0, 2);
		world.setBlock(i + 6, j + 43, k + 2, Blocks.air, 0, 2);
		world.setBlock(i + 7, j + 43, k + 2, Blocks.air, 0, 2);
		world.setBlock(i + 8, j + 43, k + 2, NovaCraftBlocks.cracked_basal_bricks, 0, 2);
		world.setBlock(i + 9, j + 43, k + 2, NovaCraftBlocks.basal_bricks, 0, 2);
		world.setBlock(i + 10, j + 43, k + 2, Blocks.air, 0, 2);
		world.setBlock(i + 11, j + 43, k + 2, Blocks.air, 0, 2);
		world.setBlock(i + 12, j + 43, k + 2, NovaCraftBlocks.basal_bricks, 0, 2);
		world.setBlock(i + 13, j + 43, k + 2, NovaCraftBlocks.basal_bricks, 0, 2);
		world.setBlock(i + 14, j + 43, k + 2, Blocks.air, 0, 2);
		world.setBlock(i + 15, j + 43, k + 2, Blocks.air, 0, 2);
		world.setBlock(i + 16, j + 43, k + 2, Blocks.air, 0, 2);
		world.setBlock(i + 17, j + 43, k + 2, Blocks.air, 0, 2);
		world.setBlock(i + 18, j + 43, k + 2, Blocks.air, 0, 2);
		world.setBlock(i + 19, j + 43, k + 2, Blocks.air, 0, 2);
		world.setBlock(i + 20, j + 43, k + 2, Blocks.air, 0, 2);
		world.setBlock(i + 21, j + 43, k + 2, Blocks.air, 0, 2);
		world.setBlock(i + 22, j + 43, k + 2, Blocks.air, 0, 2);
		world.setBlock(i + 23, j + 43, k + 2, Blocks.air, 0, 2);
		world.setBlock(i + 24, j + 43, k + 2, Blocks.air, 0, 2);
		world.setBlock(i + 25, j + 43, k + 2, Blocks.air, 0, 2);
		world.setBlock(i + 26, j + 43, k + 2, Blocks.air, 0, 2);
		world.setBlock(i + 27, j + 43, k + 2, Blocks.air, 0, 2);
		world.setBlock(i + 0, j + 43, k + 3, NovaCraftBlocks.basal_bricks, 0, 2);
		world.setBlock(i + 1, j + 43, k + 3, NovaCraftBlocks.basal_bricks, 0, 2);
		world.setBlock(i + 2, j + 43, k + 3, Blocks.air, 0, 2);
		world.setBlock(i + 3, j + 43, k + 3, Blocks.air, 0, 2);
		world.setBlock(i + 4, j + 43, k + 3, NovaCraftBlocks.basal_bricks, 0, 2);
		world.setBlock(i + 5, j + 43, k + 3, NovaCraftBlocks.basal_bricks, 0, 2);
		world.setBlock(i + 6, j + 43, k + 3, Blocks.air, 0, 2);
		world.setBlock(i + 7, j + 43, k + 3, Blocks.air, 0, 2);
		world.setBlock(i + 8, j + 43, k + 3, NovaCraftBlocks.basal_bricks, 0, 2);
		world.setBlock(i + 9, j + 43, k + 3, NovaCraftBlocks.basal_bricks, 0, 2);
		world.setBlock(i + 10, j + 43, k + 3, Blocks.air, 0, 2);
		world.setBlock(i + 11, j + 43, k + 3, Blocks.air, 0, 2);
		world.setBlock(i + 12, j + 43, k + 3, NovaCraftBlocks.basal_bricks, 0, 2);
		world.setBlock(i + 13, j + 43, k + 3, Blocks.air, 0, 2);
		world.setBlock(i + 14, j + 43, k + 3, NovaCraftBlocks.basal_bricks, 0, 2);
		world.setBlock(i + 15, j + 43, k + 3, NovaCraftBlocks.basal_bricks, 0, 2);
		world.setBlock(i + 16, j + 43, k + 3, Blocks.air, 0, 2);
		world.setBlock(i + 17, j + 43, k + 3, Blocks.air, 0, 2);
		world.setBlock(i + 18, j + 43, k + 3, NovaCraftBlocks.basal_bricks, 0, 2);
		world.setBlock(i + 19, j + 43, k + 3, NovaCraftBlocks.basal_bricks, 0, 2);
		world.setBlock(i + 20, j + 43, k + 3, Blocks.air, 0, 2);
		world.setBlock(i + 21, j + 43, k + 3, Blocks.air, 0, 2);
		world.setBlock(i + 22, j + 43, k + 3, NovaCraftBlocks.basal_bricks, 0, 2);
		world.setBlock(i + 23, j + 43, k + 3, NovaCraftBlocks.basal_bricks, 0, 2);
		world.setBlock(i + 24, j + 43, k + 3, Blocks.air, 0, 2);
		world.setBlock(i + 25, j + 43, k + 3, Blocks.air, 0, 2);
		world.setBlock(i + 26, j + 43, k + 3, NovaCraftBlocks.basal_bricks, 0, 2);
		world.setBlock(i + 27, j + 43, k + 3, NovaCraftBlocks.basal_bricks, 0, 2);
		world.setBlock(i + 0, j + 43, k + 4, NovaCraftBlocks.cracked_basal_bricks, 0, 2);
		world.setBlock(i + 1, j + 43, k + 4, NovaCraftBlocks.cracked_basal_bricks, 0, 2);
		world.setBlock(i + 2, j + 43, k + 4, NovaCraftBlocks.basal_bricks, 0, 2);
		world.setBlock(i + 3, j + 43, k + 4, NovaCraftBlocks.basal_bricks, 0, 2);
		world.setBlock(i + 4, j + 43, k + 4, NovaCraftBlocks.cracked_basal_bricks, 0, 2);
		world.setBlock(i + 5, j + 43, k + 4, NovaCraftBlocks.basal_bricks, 0, 2);
		world.setBlock(i + 6, j + 43, k + 4, NovaCraftBlocks.basal_bricks, 0, 2);
		world.setBlock(i + 7, j + 43, k + 4, NovaCraftBlocks.basal_bricks, 0, 2);
		world.setBlock(i + 8, j + 43, k + 4, NovaCraftBlocks.cracked_basal_bricks, 0, 2);
		world.setBlock(i + 9, j + 43, k + 4, NovaCraftBlocks.basal_bricks, 0, 2);
		world.setBlock(i + 10, j + 43, k + 4, NovaCraftBlocks.basal_bricks, 0, 2);
		world.setBlock(i + 11, j + 43, k + 4, NovaCraftBlocks.basal_bricks, 0, 2);
		world.setBlock(i + 12, j + 43, k + 4, Blocks.air, 0, 2);
		world.setBlock(i + 13, j + 43, k + 4, Blocks.air, 0, 2);
		world.setBlock(i + 14, j + 43, k + 4, NovaCraftBlocks.basal_bricks, 0, 2);
		world.setBlock(i + 15, j + 43, k + 4, NovaCraftBlocks.basal_bricks, 0, 2);
		world.setBlock(i + 16, j + 43, k + 4, Blocks.air, 0, 2);
		world.setBlock(i + 17, j + 43, k + 4, Blocks.air, 0, 2);
		world.setBlock(i + 18, j + 43, k + 4, NovaCraftBlocks.basal_bricks, 0, 2);
		world.setBlock(i + 19, j + 43, k + 4, NovaCraftBlocks.cracked_basal_bricks, 0, 2);
		world.setBlock(i + 20, j + 43, k + 4, Blocks.air, 0, 2);
		world.setBlock(i + 21, j + 43, k + 4, Blocks.air, 0, 2);
		world.setBlock(i + 22, j + 43, k + 4, NovaCraftBlocks.cracked_basal_bricks, 0, 2);
		world.setBlock(i + 23, j + 43, k + 4, NovaCraftBlocks.basal_bricks, 0, 2);
		world.setBlock(i + 24, j + 43, k + 4, Blocks.air, 0, 2);
		world.setBlock(i + 25, j + 43, k + 4, Blocks.air, 0, 2);
		world.setBlock(i + 26, j + 43, k + 4, NovaCraftBlocks.basal_bricks, 0, 2);
		world.setBlock(i + 27, j + 43, k + 4, NovaCraftBlocks.basal_bricks, 0, 2);
		world.setBlock(i + 0, j + 43, k + 5, NovaCraftBlocks.basal_bricks, 0, 2);
		world.setBlock(i + 1, j + 43, k + 5, NovaCraftBlocks.cracked_basal_bricks, 0, 2);
		world.setBlock(i + 2, j + 43, k + 5, NovaCraftBlocks.basal_bricks, 0, 2);
		world.setBlock(i + 3, j + 43, k + 5, NovaCraftBlocks.cracked_basal_bricks, 0, 2);
		world.setBlock(i + 4, j + 43, k + 5, NovaCraftBlocks.basal_bricks, 0, 2);
		world.setBlock(i + 5, j + 43, k + 5, NovaCraftBlocks.basal_bricks, 0, 2);
		world.setBlock(i + 6, j + 43, k + 5, NovaCraftBlocks.basal_bricks, 0, 2);
		world.setBlock(i + 7, j + 43, k + 5, NovaCraftBlocks.cracked_basal_bricks, 0, 2);
		world.setBlock(i + 8, j + 43, k + 5, NovaCraftBlocks.cracked_basal_bricks, 0, 2);
		world.setBlock(i + 9, j + 43, k + 5, NovaCraftBlocks.basal_bricks, 0, 2);
		world.setBlock(i + 10, j + 43, k + 5, NovaCraftBlocks.basal_bricks, 0, 2);
		world.setBlock(i + 11, j + 43, k + 5, NovaCraftBlocks.basal_bricks, 0, 2);
		world.setBlock(i + 12, j + 43, k + 5, Blocks.air, 0, 2);
		world.setBlock(i + 13, j + 43, k + 5, Blocks.air, 0, 2);
		world.setBlock(i + 14, j + 43, k + 5, NovaCraftBlocks.basal_bricks, 0, 2);
		world.setBlock(i + 15, j + 43, k + 5, NovaCraftBlocks.cracked_basal_bricks, 0, 2);
		world.setBlock(i + 16, j + 43, k + 5, Blocks.air, 0, 2);
		world.setBlock(i + 17, j + 43, k + 5, Blocks.air, 0, 2);
		world.setBlock(i + 18, j + 43, k + 5, NovaCraftBlocks.basal_bricks, 0, 2);
		world.setBlock(i + 19, j + 43, k + 5, NovaCraftBlocks.basal_bricks, 0, 2);
		world.setBlock(i + 20, j + 43, k + 5, Blocks.air, 0, 2);
		world.setBlock(i + 21, j + 43, k + 5, Blocks.air, 0, 2);
		world.setBlock(i + 22, j + 43, k + 5, NovaCraftBlocks.basal_bricks, 0, 2);
		world.setBlock(i + 23, j + 43, k + 5, NovaCraftBlocks.cracked_basal_bricks, 0, 2);
		world.setBlock(i + 24, j + 43, k + 5, Blocks.air, 0, 2);
		world.setBlock(i + 25, j + 43, k + 5, Blocks.air, 0, 2);
		world.setBlock(i + 26, j + 43, k + 5, NovaCraftBlocks.basal_bricks, 0, 2);
		world.setBlock(i + 27, j + 43, k + 5, NovaCraftBlocks.basal_bricks, 0, 2);
		world.setBlock(i + 0, j + 43, k + 6, NovaCraftBlocks.basal_bricks, 0, 2);
		world.setBlock(i + 1, j + 43, k + 6, NovaCraftBlocks.basal_bricks, 0, 2);
		world.setBlock(i + 2, j + 43, k + 6, NovaCraftBlocks.basal_bricks, 0, 2);
		world.setBlock(i + 3, j + 43, k + 6, NovaCraftBlocks.basal_bricks, 0, 2);
		world.setBlock(i + 4, j + 43, k + 6, NovaCraftBlocks.cracked_basal_bricks, 0, 2);
		world.setBlock(i + 5, j + 43, k + 6, NovaCraftBlocks.basal_bricks, 0, 2);
		world.setBlock(i + 6, j + 43, k + 6, NovaCraftBlocks.basal_bricks, 0, 2);
		world.setBlock(i + 7, j + 43, k + 6, NovaCraftBlocks.basal_bricks, 0, 2);
		world.setBlock(i + 8, j + 43, k + 6, NovaCraftBlocks.basal_bricks, 0, 2);
		world.setBlock(i + 9, j + 43, k + 6, NovaCraftBlocks.cracked_basal_bricks, 0, 2);
		world.setBlock(i + 10, j + 43, k + 6, NovaCraftBlocks.basal_bricks, 0, 2);
		world.setBlock(i + 11, j + 43, k + 6, NovaCraftBlocks.basal_bricks, 0, 2);
		world.setBlock(i + 12, j + 43, k + 6, NovaCraftBlocks.basal_bricks, 0, 2);
		world.setBlock(i + 13, j + 43, k + 6, Blocks.air, 0, 2);
		world.setBlock(i + 14, j + 43, k + 6, NovaCraftBlocks.cracked_basal_bricks, 0, 2);
		world.setBlock(i + 15, j + 43, k + 6, NovaCraftBlocks.basal_bricks, 0, 2);
		world.setBlock(i + 16, j + 43, k + 6, NovaCraftBlocks.basal_bricks, 0, 2);
		world.setBlock(i + 17, j + 43, k + 6, NovaCraftBlocks.basal_bricks, 0, 2);
		world.setBlock(i + 18, j + 43, k + 6, NovaCraftBlocks.cracked_basal_bricks, 0, 2);
		world.setBlock(i + 19, j + 43, k + 6, NovaCraftBlocks.basal_bricks, 0, 2);
		world.setBlock(i + 20, j + 43, k + 6, NovaCraftBlocks.basal_bricks, 0, 2);
		world.setBlock(i + 21, j + 43, k + 6, NovaCraftBlocks.basal_bricks, 0, 2);
		world.setBlock(i + 22, j + 43, k + 6, NovaCraftBlocks.cracked_basal_bricks, 0, 2);
		world.setBlock(i + 23, j + 43, k + 6, NovaCraftBlocks.basal_bricks, 0, 2);
		world.setBlock(i + 24, j + 43, k + 6, NovaCraftBlocks.cracked_basal_bricks, 0, 2);
		world.setBlock(i + 25, j + 43, k + 6, NovaCraftBlocks.basal_bricks, 0, 2);
		world.setBlock(i + 26, j + 43, k + 6, NovaCraftBlocks.basal_bricks, 0, 2);
		world.setBlock(i + 27, j + 43, k + 6, NovaCraftBlocks.basal_bricks, 0, 2);
		world.setBlock(i + 0, j + 43, k + 7, NovaCraftBlocks.cracked_basal_bricks, 0, 2);
		world.setBlock(i + 1, j + 43, k + 7, NovaCraftBlocks.basal_bricks, 0, 2);
		world.setBlock(i + 2, j + 43, k + 7, NovaCraftBlocks.basal_bricks, 0, 2);
		world.setBlock(i + 3, j + 43, k + 7, NovaCraftBlocks.basal_bricks, 0, 2);
		world.setBlock(i + 4, j + 43, k + 7, NovaCraftBlocks.basal_bricks, 0, 2);
		world.setBlock(i + 5, j + 43, k + 7, NovaCraftBlocks.basal_bricks, 0, 2);
		world.setBlock(i + 6, j + 43, k + 7, NovaCraftBlocks.basal_bricks, 0, 2);
		world.setBlock(i + 7, j + 43, k + 7, NovaCraftBlocks.basal_bricks, 0, 2);
		world.setBlock(i + 8, j + 43, k + 7, NovaCraftBlocks.basal_bricks, 0, 2);
		world.setBlock(i + 9, j + 43, k + 7, NovaCraftBlocks.basal_bricks, 0, 2);
		world.setBlock(i + 10, j + 43, k + 7, NovaCraftBlocks.cracked_basal_bricks, 0, 2);
		world.setBlock(i + 11, j + 43, k + 7, NovaCraftBlocks.basal_bricks, 0, 2);
		world.setBlock(i + 12, j + 43, k + 7, NovaCraftBlocks.cracked_basal_bricks, 0, 2);
		world.setBlock(i + 13, j + 43, k + 7, NovaCraftBlocks.basal_bricks, 0, 2);
		world.setBlock(i + 14, j + 43, k + 7, NovaCraftBlocks.cracked_basal_bricks, 0, 2);
		world.setBlock(i + 15, j + 43, k + 7, NovaCraftBlocks.basal_bricks, 0, 2);
		world.setBlock(i + 16, j + 43, k + 7, NovaCraftBlocks.basal_bricks, 0, 2);
		world.setBlock(i + 17, j + 43, k + 7, NovaCraftBlocks.cracked_basal_bricks, 0, 2);
		world.setBlock(i + 18, j + 43, k + 7, NovaCraftBlocks.cracked_basal_bricks, 0, 2);
		world.setBlock(i + 19, j + 43, k + 7, NovaCraftBlocks.basal_bricks, 0, 2);
		world.setBlock(i + 20, j + 43, k + 7, NovaCraftBlocks.basal_bricks, 0, 2);
		world.setBlock(i + 21, j + 43, k + 7, NovaCraftBlocks.basal_bricks, 0, 2);
		world.setBlock(i + 22, j + 43, k + 7, NovaCraftBlocks.cracked_basal_bricks, 0, 2);
		world.setBlock(i + 23, j + 43, k + 7, NovaCraftBlocks.basal_bricks, 0, 2);
		world.setBlock(i + 24, j + 43, k + 7, NovaCraftBlocks.cracked_basal_bricks, 0, 2);
		world.setBlock(i + 25, j + 43, k + 7, NovaCraftBlocks.basal_bricks, 0, 2);
		world.setBlock(i + 26, j + 43, k + 7, NovaCraftBlocks.cracked_basal_bricks, 0, 2);
		world.setBlock(i + 27, j + 43, k + 7, NovaCraftBlocks.cracked_basal_bricks, 0, 2);
		world.setBlock(i + 0, j + 43, k + 8, NovaCraftBlocks.basal_bricks, 0, 2);
		world.setBlock(i + 1, j + 43, k + 8, NovaCraftBlocks.cracked_basal_bricks, 0, 2);
		world.setBlock(i + 2, j + 43, k + 8, NovaCraftBlocks.cracked_basal_bricks, 0, 2);
		world.setBlock(i + 3, j + 43, k + 8, NovaCraftBlocks.cracked_basal_bricks, 0, 2);
		world.setBlock(i + 4, j + 43, k + 8, NovaCraftBlocks.cracked_basal_bricks, 0, 2);
		world.setBlock(i + 5, j + 43, k + 8, NovaCraftBlocks.cracked_basal_bricks, 0, 2);
		world.setBlock(i + 6, j + 43, k + 8, NovaCraftBlocks.cracked_basal_bricks, 0, 2);
		world.setBlock(i + 7, j + 43, k + 8, NovaCraftBlocks.cracked_basal_bricks, 0, 2);
		world.setBlock(i + 8, j + 43, k + 8, NovaCraftBlocks.basal_bricks, 0, 2);
		world.setBlock(i + 9, j + 43, k + 8, NovaCraftBlocks.cracked_basal_bricks, 0, 2);
		world.setBlock(i + 10, j + 43, k + 8, NovaCraftBlocks.cracked_basal_bricks, 0, 2);
		world.setBlock(i + 11, j + 43, k + 8, NovaCraftBlocks.basal_bricks, 0, 2);
		world.setBlock(i + 12, j + 43, k + 8, NovaCraftBlocks.basal_bricks, 0, 2);
		world.setBlock(i + 13, j + 43, k + 8, NovaCraftBlocks.cracked_basal_bricks, 0, 2);
		world.setBlock(i + 14, j + 43, k + 8, NovaCraftBlocks.cracked_basal_bricks, 0, 2);
		world.setBlock(i + 15, j + 43, k + 8, NovaCraftBlocks.cracked_basal_bricks, 0, 2);
		world.setBlock(i + 16, j + 43, k + 8, NovaCraftBlocks.basal_bricks, 0, 2);
		world.setBlock(i + 17, j + 43, k + 8, NovaCraftBlocks.cracked_basal_bricks, 0, 2);
		world.setBlock(i + 18, j + 43, k + 8, NovaCraftBlocks.basal_bricks, 0, 2);
		world.setBlock(i + 19, j + 43, k + 8, NovaCraftBlocks.basal_bricks, 0, 2);
		world.setBlock(i + 20, j + 43, k + 8, NovaCraftBlocks.basal_bricks, 0, 2);
		world.setBlock(i + 21, j + 43, k + 8, NovaCraftBlocks.cracked_basal_bricks, 0, 2);
		world.setBlock(i + 22, j + 43, k + 8, NovaCraftBlocks.basal_bricks, 0, 2);
		world.setBlock(i + 23, j + 43, k + 8, NovaCraftBlocks.basal_bricks, 0, 2);
		world.setBlock(i + 24, j + 43, k + 8, NovaCraftBlocks.cracked_basal_bricks, 0, 2);
		world.setBlock(i + 25, j + 43, k + 8, NovaCraftBlocks.cracked_basal_bricks, 0, 2);
		world.setBlock(i + 26, j + 43, k + 8, NovaCraftBlocks.cracked_basal_bricks, 0, 2);
		world.setBlock(i + 27, j + 43, k + 8, NovaCraftBlocks.cracked_basal_bricks, 0, 2);
		world.setBlock(i + 0, j + 43, k + 9, NovaCraftBlocks.basal_bricks, 0, 2);
		world.setBlock(i + 1, j + 43, k + 9, Blocks.air, 0, 2);
		world.setBlock(i + 2, j + 43, k + 9, Blocks.air, 0, 2);
		world.setBlock(i + 3, j + 43, k + 9, Blocks.air, 0, 2);
		world.setBlock(i + 4, j + 43, k + 9, Blocks.air, 0, 2);
		world.setBlock(i + 5, j + 43, k + 9, NovaCraftBlocks.basal_bricks, 0, 2);
		world.setBlock(i + 6, j + 43, k + 9, NovaCraftBlocks.basal_bricks, 0, 2);
		world.setBlock(i + 7, j + 43, k + 9, NovaCraftBlocks.basal_bricks, 0, 2);
		world.setBlock(i + 8, j + 43, k + 9, NovaCraftBlocks.basal_bricks, 0, 2);
		world.setBlock(i + 9, j + 43, k + 9, Blocks.air, 0, 2);
		world.setBlock(i + 10, j + 43, k + 9, Blocks.air, 0, 2);
		world.setBlock(i + 11, j + 43, k + 9, Blocks.air, 0, 2);
		world.setBlock(i + 12, j + 43, k + 9, Blocks.air, 0, 2);
		world.setBlock(i + 13, j + 43, k + 9, NovaCraftBlocks.cracked_basal_bricks, 0, 2);
		world.setBlock(i + 14, j + 43, k + 9, NovaCraftBlocks.basal_bricks, 0, 2);
		world.setBlock(i + 15, j + 43, k + 9, NovaCraftBlocks.cracked_basal_bricks, 0, 2);
		world.setBlock(i + 16, j + 43, k + 9, NovaCraftBlocks.basal_bricks, 0, 2);
		world.setBlock(i + 17, j + 43, k + 9, NovaCraftBlocks.basal_bricks, 0, 2);
		world.setBlock(i + 18, j + 43, k + 9, NovaCraftBlocks.cracked_basal_bricks, 0, 2);
		world.setBlock(i + 19, j + 43, k + 9, NovaCraftBlocks.basal_bricks, 0, 2);
		world.setBlock(i + 20, j + 43, k + 9, NovaCraftBlocks.cracked_basal_bricks, 0, 2);
		world.setBlock(i + 21, j + 43, k + 9, NovaCraftBlocks.basal_bricks, 0, 2);
		world.setBlock(i + 22, j + 43, k + 9, NovaCraftBlocks.basal_bricks, 0, 2);
		world.setBlock(i + 23, j + 43, k + 9, NovaCraftBlocks.basal_bricks, 0, 2);
		world.setBlock(i + 24, j + 43, k + 9, NovaCraftBlocks.cracked_basal_bricks, 0, 2);
		world.setBlock(i + 25, j + 43, k + 9, NovaCraftBlocks.basal_bricks, 0, 2);
		world.setBlock(i + 26, j + 43, k + 9, NovaCraftBlocks.basal_bricks, 0, 2);
		world.setBlock(i + 27, j + 43, k + 9, NovaCraftBlocks.cracked_basal_bricks, 0, 2);
		world.setBlock(i + 0, j + 43, k + 10, NovaCraftBlocks.cracked_basal_bricks, 0, 2);
		world.setBlock(i + 1, j + 43, k + 10, Blocks.air, 0, 2);
		world.setBlock(i + 2, j + 43, k + 10, Blocks.air, 0, 2);
		world.setBlock(i + 3, j + 43, k + 10, Blocks.air, 0, 2);
		world.setBlock(i + 4, j + 43, k + 10, Blocks.air, 0, 2);
		world.setBlock(i + 5, j + 43, k + 10, Blocks.air, 0, 2);
		world.setBlock(i + 6, j + 43, k + 10, NovaCraftBlocks.basal_bricks, 0, 2);
		world.setBlock(i + 7, j + 43, k + 10, NovaCraftBlocks.basal, 0, 2);
		world.setBlock(i + 8, j + 43, k + 10, NovaCraftBlocks.basal, 0, 2);
		world.setBlock(i + 9, j + 43, k + 10, NovaCraftBlocks.basal_brick_stairs, 1, 2);
		world.setBlock(i + 10, j + 43, k + 10, Blocks.air, 0, 2);
		world.setBlock(i + 11, j + 43, k + 10, Blocks.air, 0, 2);
		world.setBlock(i + 12, j + 43, k + 10, Blocks.air, 0, 2);
		world.setBlock(i + 13, j + 43, k + 10, NovaCraftBlocks.basal_bricks, 0, 2);
		world.setBlock(i + 14, j + 43, k + 10, NovaCraftBlocks.cracked_basal_bricks, 0, 2);
		world.setBlock(i + 15, j + 43, k + 10, NovaCraftBlocks.basal_bricks, 0, 2);
		world.setBlock(i + 16, j + 43, k + 10, NovaCraftBlocks.basal_bricks, 0, 2);
		world.setBlock(i + 17, j + 43, k + 10, NovaCraftBlocks.basal_bricks, 0, 2);
		world.setBlock(i + 18, j + 43, k + 10, NovaCraftBlocks.basal_bricks, 0, 2);
		world.setBlock(i + 19, j + 43, k + 10, NovaCraftBlocks.basal_bricks, 0, 2);
		world.setBlock(i + 20, j + 43, k + 10, NovaCraftBlocks.cracked_basal_bricks, 0, 2);
		world.setBlock(i + 21, j + 43, k + 10, NovaCraftBlocks.basal_bricks, 0, 2);
		world.setBlock(i + 22, j + 43, k + 10, NovaCraftBlocks.basal_bricks, 0, 2);
		world.setBlock(i + 23, j + 43, k + 10, NovaCraftBlocks.cracked_basal_bricks, 0, 2);
		world.setBlock(i + 24, j + 43, k + 10, NovaCraftBlocks.cracked_basal_bricks, 0, 2);
		world.setBlock(i + 25, j + 43, k + 10, NovaCraftBlocks.basal_bricks, 0, 2);
		world.setBlock(i + 26, j + 43, k + 10, NovaCraftBlocks.cracked_basal_bricks, 0, 2);
		world.setBlock(i + 27, j + 43, k + 10, NovaCraftBlocks.cracked_basal_bricks, 0, 2);
		world.setBlock(i + 0, j + 43, k + 11, Blocks.air, 0, 2);
		world.setBlock(i + 1, j + 43, k + 11, Blocks.air, 0, 2);
		world.setBlock(i + 2, j + 43, k + 11, Blocks.air, 0, 2);
		world.setBlock(i + 3, j + 43, k + 11, Blocks.air, 0, 2);
		world.setBlock(i + 4, j + 43, k + 11, Blocks.air, 0, 2);
		world.setBlock(i + 5, j + 43, k + 11, Blocks.air, 0, 2);
		world.setBlock(i + 6, j + 43, k + 11, Blocks.air, 0, 2);
		world.setBlock(i + 7, j + 43, k + 11, Blocks.air, 0, 2);
		world.setBlock(i + 8, j + 43, k + 11, Blocks.air, 0, 2);
		world.setBlock(i + 9, j + 43, k + 11, Blocks.air, 0, 2);
		world.setBlock(i + 10, j + 43, k + 11, Blocks.air, 0, 2);
		world.setBlock(i + 11, j + 43, k + 11, Blocks.air, 0, 2);
		world.setBlock(i + 12, j + 43, k + 11, Blocks.air, 0, 2);
		world.setBlock(i + 13, j + 43, k + 11, Blocks.air, 0, 2);
		world.setBlock(i + 14, j + 43, k + 11, NovaCraftBlocks.basal_bricks, 0, 2);
		world.setBlock(i + 15, j + 43, k + 11, Blocks.air, 0, 2);
		world.setBlock(i + 16, j + 43, k + 11, Blocks.air, 0, 2);
		world.setBlock(i + 17, j + 43, k + 11, Blocks.air, 0, 2);
		world.setBlock(i + 18, j + 43, k + 11, Blocks.air, 0, 2);
		world.setBlock(i + 19, j + 43, k + 11, NovaCraftBlocks.cracked_basal_bricks, 0, 2);
		world.setBlock(i + 20, j + 43, k + 11, NovaCraftBlocks.basal_bricks, 0, 2);
		world.setBlock(i + 21, j + 43, k + 11, NovaCraftBlocks.basal_bricks, 0, 2);
		world.setBlock(i + 22, j + 43, k + 11, NovaCraftBlocks.basal_bricks, 0, 2);
		world.setBlock(i + 23, j + 43, k + 11, Blocks.air, 0, 2);
		world.setBlock(i + 24, j + 43, k + 11, Blocks.air, 0, 2);
		world.setBlock(i + 25, j + 43, k + 11, Blocks.air, 0, 2);
		world.setBlock(i + 26, j + 43, k + 11, Blocks.air, 0, 2);
		world.setBlock(i + 27, j + 43, k + 11, NovaCraftBlocks.cracked_basal_bricks, 0, 2);
		world.setBlock(i + 0, j + 43, k + 12, Blocks.air, 0, 2);
		world.setBlock(i + 1, j + 43, k + 12, Blocks.air, 0, 2);
		world.setBlock(i + 2, j + 43, k + 12, Blocks.air, 0, 2);
		world.setBlock(i + 3, j + 43, k + 12, Blocks.air, 0, 2);
		world.setBlock(i + 4, j + 43, k + 12, Blocks.air, 0, 2);
		world.setBlock(i + 5, j + 43, k + 12, Blocks.air, 0, 2);
		world.setBlock(i + 6, j + 43, k + 12, Blocks.air, 0, 2);
		world.setBlock(i + 7, j + 43, k + 12, Blocks.air, 0, 2);
		world.setBlock(i + 8, j + 43, k + 12, Blocks.air, 0, 2);
		world.setBlock(i + 9, j + 43, k + 12, Blocks.air, 0, 2);
		world.setBlock(i + 10, j + 43, k + 12, Blocks.air, 0, 2);
		world.setBlock(i + 11, j + 43, k + 12, Blocks.air, 0, 2);
		world.setBlock(i + 12, j + 43, k + 12, Blocks.air, 0, 2);
		world.setBlock(i + 13, j + 43, k + 12, Blocks.air, 0, 2);
		world.setBlock(i + 14, j + 43, k + 12, NovaCraftBlocks.cracked_basal_bricks, 0, 2);
		world.setBlock(i + 15, j + 43, k + 12, Blocks.air, 0, 2);
		world.setBlock(i + 16, j + 43, k + 12, Blocks.air, 0, 2);
		world.setBlock(i + 17, j + 43, k + 12, Blocks.air, 0, 2);
		world.setBlock(i + 18, j + 43, k + 12, Blocks.air, 0, 2);
		world.setBlock(i + 19, j + 43, k + 12, Blocks.air, 0, 2);
		world.setBlock(i + 20, j + 43, k + 12, NovaCraftBlocks.basal_bricks, 0, 2);
		world.setBlock(i + 21, j + 43, k + 12, NovaCraftBlocks.basal, 0, 2);
		world.setBlock(i + 22, j + 43, k + 12, NovaCraftBlocks.basal, 0, 2);
		world.setBlock(i + 23, j + 43, k + 12, NovaCraftBlocks.basal_brick_stairs, 1, 2);
		world.setBlock(i + 24, j + 43, k + 12, Blocks.air, 0, 2);
		world.setBlock(i + 25, j + 43, k + 12, Blocks.air, 0, 2);
		world.setBlock(i + 26, j + 43, k + 12, Blocks.air, 0, 2);
		world.setBlock(i + 27, j + 43, k + 12, NovaCraftBlocks.basal_bricks, 0, 2);
		world.setBlock(i + 0, j + 44, k + 0, Blocks.air, 0, 2);
		world.setBlock(i + 1, j + 44, k + 0, Blocks.air, 0, 2);
		world.setBlock(i + 2, j + 44, k + 0, Blocks.air, 0, 2);
		world.setBlock(i + 3, j + 44, k + 0, Blocks.air, 0, 2);
		world.setBlock(i + 4, j + 44, k + 0, Blocks.air, 0, 2);
		world.setBlock(i + 5, j + 44, k + 0, Blocks.air, 0, 2);
		world.setBlock(i + 6, j + 44, k + 0, Blocks.air, 0, 2);
		world.setBlock(i + 7, j + 44, k + 0, Blocks.air, 0, 2);
		world.setBlock(i + 8, j + 44, k + 0, Blocks.air, 0, 2);
		world.setBlock(i + 9, j + 44, k + 0, Blocks.air, 0, 2);
		world.setBlock(i + 10, j + 44, k + 0, Blocks.air, 0, 2);
		world.setBlock(i + 11, j + 44, k + 0, Blocks.air, 0, 2);
		world.setBlock(i + 12, j + 44, k + 0, Blocks.air, 0, 2);
		world.setBlock(i + 13, j + 44, k + 0, Blocks.air, 0, 2);
		world.setBlock(i + 14, j + 44, k + 0, Blocks.air, 0, 2);
		world.setBlock(i + 15, j + 44, k + 0, Blocks.air, 0, 2);
		world.setBlock(i + 16, j + 44, k + 0, Blocks.air, 0, 2);
		world.setBlock(i + 17, j + 44, k + 0, Blocks.air, 0, 2);
		world.setBlock(i + 18, j + 44, k + 0, Blocks.air, 0, 2);
		world.setBlock(i + 19, j + 44, k + 0, Blocks.air, 0, 2);
		world.setBlock(i + 20, j + 44, k + 0, Blocks.air, 0, 2);
		world.setBlock(i + 21, j + 44, k + 0, Blocks.air, 0, 2);
		world.setBlock(i + 22, j + 44, k + 0, Blocks.air, 0, 2);
		world.setBlock(i + 23, j + 44, k + 0, Blocks.air, 0, 2);
		world.setBlock(i + 24, j + 44, k + 0, Blocks.air, 0, 2);
		world.setBlock(i + 25, j + 44, k + 0, Blocks.air, 0, 2);
		world.setBlock(i + 26, j + 44, k + 0, Blocks.air, 0, 2);
		world.setBlock(i + 27, j + 44, k + 0, Blocks.air, 0, 2);
		world.setBlock(i + 0, j + 44, k + 1, NovaCraftBlocks.basal_bricks, 0, 2);
		world.setBlock(i + 1, j + 44, k + 1, NovaCraftBlocks.cracked_basal_bricks, 0, 2);
		world.setBlock(i + 2, j + 44, k + 1, Blocks.air, 0, 2);
		world.setBlock(i + 3, j + 44, k + 1, Blocks.air, 0, 2);
		world.setBlock(i + 4, j + 44, k + 1, NovaCraftBlocks.cracked_basal_bricks, 0, 2);
		world.setBlock(i + 5, j + 44, k + 1, NovaCraftBlocks.basal_bricks, 0, 2);
		world.setBlock(i + 6, j + 44, k + 1, Blocks.air, 0, 2);
		world.setBlock(i + 7, j + 44, k + 1, Blocks.air, 0, 2);
		world.setBlock(i + 8, j + 44, k + 1, NovaCraftBlocks.basal_bricks, 0, 2);
		world.setBlock(i + 9, j + 44, k + 1, NovaCraftBlocks.basal_bricks, 0, 2);
		world.setBlock(i + 10, j + 44, k + 1, Blocks.air, 0, 2);
		world.setBlock(i + 11, j + 44, k + 1, Blocks.air, 0, 2);
		world.setBlock(i + 12, j + 44, k + 1, NovaCraftBlocks.basal_bricks, 0, 2);
		world.setBlock(i + 13, j + 44, k + 1, NovaCraftBlocks.basal_bricks, 0, 2);
		world.setBlock(i + 14, j + 44, k + 1, Blocks.air, 0, 2);
		world.setBlock(i + 15, j + 44, k + 1, Blocks.air, 0, 2);
		world.setBlock(i + 16, j + 44, k + 1, Blocks.air, 0, 2);
		world.setBlock(i + 17, j + 44, k + 1, Blocks.air, 0, 2);
		world.setBlock(i + 18, j + 44, k + 1, Blocks.air, 0, 2);
		world.setBlock(i + 19, j + 44, k + 1, Blocks.air, 0, 2);
		world.setBlock(i + 20, j + 44, k + 1, Blocks.air, 0, 2);
		world.setBlock(i + 21, j + 44, k + 1, Blocks.air, 0, 2);
		world.setBlock(i + 22, j + 44, k + 1, Blocks.air, 0, 2);
		world.setBlock(i + 23, j + 44, k + 1, Blocks.air, 0, 2);
		world.setBlock(i + 24, j + 44, k + 1, Blocks.air, 0, 2);
		world.setBlock(i + 25, j + 44, k + 1, Blocks.air, 0, 2);
		world.setBlock(i + 26, j + 44, k + 1, Blocks.air, 0, 2);
		world.setBlock(i + 27, j + 44, k + 1, Blocks.air, 0, 2);
		world.setBlock(i + 0, j + 44, k + 2, NovaCraftBlocks.basal_bricks, 0, 2);
		world.setBlock(i + 1, j + 44, k + 2, NovaCraftBlocks.basal_bricks, 0, 2);
		world.setBlock(i + 2, j + 44, k + 2, Blocks.air, 0, 2);
		world.setBlock(i + 3, j + 44, k + 2, Blocks.air, 0, 2);
		world.setBlock(i + 4, j + 44, k + 2, NovaCraftBlocks.basal_bricks, 0, 2);
		world.setBlock(i + 5, j + 44, k + 2, NovaCraftBlocks.cracked_basal_bricks, 0, 2);
		world.setBlock(i + 6, j + 44, k + 2, Blocks.air, 0, 2);
		world.setBlock(i + 7, j + 44, k + 2, Blocks.air, 0, 2);
		world.setBlock(i + 8, j + 44, k + 2, NovaCraftBlocks.cracked_basal_bricks, 0, 2);
		world.setBlock(i + 9, j + 44, k + 2, NovaCraftBlocks.cracked_basal_bricks, 0, 2);
		world.setBlock(i + 10, j + 44, k + 2, Blocks.air, 0, 2);
		world.setBlock(i + 11, j + 44, k + 2, Blocks.air, 0, 2);
		world.setBlock(i + 12, j + 44, k + 2, NovaCraftBlocks.basal_bricks, 0, 2);
		world.setBlock(i + 13, j + 44, k + 2, Blocks.air, 0, 2);
		world.setBlock(i + 14, j + 44, k + 2, Blocks.air, 0, 2);
		world.setBlock(i + 15, j + 44, k + 2, Blocks.air, 0, 2);
		world.setBlock(i + 16, j + 44, k + 2, Blocks.air, 0, 2);
		world.setBlock(i + 17, j + 44, k + 2, Blocks.air, 0, 2);
		world.setBlock(i + 18, j + 44, k + 2, Blocks.air, 0, 2);
		world.setBlock(i + 19, j + 44, k + 2, Blocks.air, 0, 2);
		world.setBlock(i + 20, j + 44, k + 2, Blocks.air, 0, 2);
		world.setBlock(i + 21, j + 44, k + 2, Blocks.air, 0, 2);
		world.setBlock(i + 22, j + 44, k + 2, Blocks.air, 0, 2);
		world.setBlock(i + 23, j + 44, k + 2, Blocks.air, 0, 2);
		world.setBlock(i + 24, j + 44, k + 2, Blocks.air, 0, 2);
		world.setBlock(i + 25, j + 44, k + 2, Blocks.air, 0, 2);
		world.setBlock(i + 26, j + 44, k + 2, Blocks.air, 0, 2);
		world.setBlock(i + 27, j + 44, k + 2, Blocks.air, 0, 2);
		world.setBlock(i + 0, j + 44, k + 3, NovaCraftBlocks.basal_bricks, 0, 2);
		world.setBlock(i + 1, j + 44, k + 3, NovaCraftBlocks.basal_bricks, 0, 2);
		world.setBlock(i + 2, j + 44, k + 3, Blocks.air, 0, 2);
		world.setBlock(i + 3, j + 44, k + 3, Blocks.air, 0, 2);
		world.setBlock(i + 4, j + 44, k + 3, NovaCraftBlocks.cracked_basal_bricks, 0, 2);
		world.setBlock(i + 5, j + 44, k + 3, NovaCraftBlocks.basal_bricks, 0, 2);
		world.setBlock(i + 6, j + 44, k + 3, Blocks.air, 0, 2);
		world.setBlock(i + 7, j + 44, k + 3, Blocks.air, 0, 2);
		world.setBlock(i + 8, j + 44, k + 3, NovaCraftBlocks.basal_bricks, 0, 2);
		world.setBlock(i + 9, j + 44, k + 3, NovaCraftBlocks.basal_bricks, 0, 2);
		world.setBlock(i + 10, j + 44, k + 3, Blocks.air, 0, 2);
		world.setBlock(i + 11, j + 44, k + 3, NovaCraftBlocks.basal_bricks, 0, 2);
		world.setBlock(i + 12, j + 44, k + 3, NovaCraftBlocks.cracked_basal_bricks, 0, 2);
		world.setBlock(i + 13, j + 44, k + 3, Blocks.air, 0, 2);
		world.setBlock(i + 14, j + 44, k + 3, NovaCraftBlocks.basal_bricks, 0, 2);
		world.setBlock(i + 15, j + 44, k + 3, NovaCraftBlocks.basal_bricks, 0, 2);
		world.setBlock(i + 16, j + 44, k + 3, Blocks.air, 0, 2);
		world.setBlock(i + 17, j + 44, k + 3, Blocks.air, 0, 2);
		world.setBlock(i + 18, j + 44, k + 3, NovaCraftBlocks.basal_bricks, 0, 2);
		world.setBlock(i + 19, j + 44, k + 3, NovaCraftBlocks.basal_bricks, 0, 2);
		world.setBlock(i + 20, j + 44, k + 3, Blocks.air, 0, 2);
		world.setBlock(i + 21, j + 44, k + 3, Blocks.air, 0, 2);
		world.setBlock(i + 22, j + 44, k + 3, NovaCraftBlocks.cracked_basal_bricks, 0, 2);
		world.setBlock(i + 23, j + 44, k + 3, NovaCraftBlocks.basal_bricks, 0, 2);
		world.setBlock(i + 24, j + 44, k + 3, Blocks.air, 0, 2);
		world.setBlock(i + 25, j + 44, k + 3, Blocks.air, 0, 2);
		world.setBlock(i + 26, j + 44, k + 3, NovaCraftBlocks.basal_bricks, 0, 2);
		world.setBlock(i + 27, j + 44, k + 3, NovaCraftBlocks.basal_bricks, 0, 2);
		world.setBlock(i + 0, j + 44, k + 4, NovaCraftBlocks.basal_bricks, 0, 2);
		world.setBlock(i + 1, j + 44, k + 4, NovaCraftBlocks.basal_bricks, 0, 2);
		world.setBlock(i + 2, j + 44, k + 4, NovaCraftBlocks.cracked_basal_bricks, 0, 2);
		world.setBlock(i + 3, j + 44, k + 4, NovaCraftBlocks.basal_bricks, 0, 2);
		world.setBlock(i + 4, j + 44, k + 4, NovaCraftBlocks.cracked_basal_bricks, 0, 2);
		world.setBlock(i + 5, j + 44, k + 4, NovaCraftBlocks.cracked_basal_bricks, 0, 2);
		world.setBlock(i + 6, j + 44, k + 4, NovaCraftBlocks.basal_bricks, 0, 2);
		world.setBlock(i + 7, j + 44, k + 4, NovaCraftBlocks.basal_bricks, 0, 2);
		world.setBlock(i + 8, j + 44, k + 4, NovaCraftBlocks.basal_bricks, 0, 2);
		world.setBlock(i + 9, j + 44, k + 4, NovaCraftBlocks.cracked_basal_bricks, 0, 2);
		world.setBlock(i + 10, j + 44, k + 4, NovaCraftBlocks.basal_bricks, 0, 2);
		world.setBlock(i + 11, j + 44, k + 4, NovaCraftBlocks.cracked_basal_bricks, 0, 2);
		world.setBlock(i + 12, j + 44, k + 4, Blocks.air, 0, 2);
		world.setBlock(i + 13, j + 44, k + 4, Blocks.air, 0, 2);
		world.setBlock(i + 14, j + 44, k + 4, NovaCraftBlocks.basal_bricks, 0, 2);
		world.setBlock(i + 15, j + 44, k + 4, NovaCraftBlocks.basal_bricks, 0, 2);
		world.setBlock(i + 16, j + 44, k + 4, Blocks.air, 0, 2);
		world.setBlock(i + 17, j + 44, k + 4, Blocks.air, 0, 2);
		world.setBlock(i + 18, j + 44, k + 4, NovaCraftBlocks.basal_bricks, 0, 2);
		world.setBlock(i + 19, j + 44, k + 4, NovaCraftBlocks.basal_bricks, 0, 2);
		world.setBlock(i + 20, j + 44, k + 4, Blocks.air, 0, 2);
		world.setBlock(i + 21, j + 44, k + 4, Blocks.air, 0, 2);
		world.setBlock(i + 22, j + 44, k + 4, NovaCraftBlocks.cracked_basal_bricks, 0, 2);
		world.setBlock(i + 23, j + 44, k + 4, NovaCraftBlocks.basal_bricks, 0, 2);
		world.setBlock(i + 24, j + 44, k + 4, Blocks.air, 0, 2);
		world.setBlock(i + 25, j + 44, k + 4, Blocks.air, 0, 2);
		world.setBlock(i + 26, j + 44, k + 4, NovaCraftBlocks.cracked_basal_bricks, 0, 2);
		world.setBlock(i + 27, j + 44, k + 4, NovaCraftBlocks.basal_bricks, 0, 2);
		world.setBlock(i + 0, j + 44, k + 5, NovaCraftBlocks.basal_bricks, 0, 2);
		world.setBlock(i + 1, j + 44, k + 5, NovaCraftBlocks.cracked_basal_bricks, 0, 2);
		world.setBlock(i + 2, j + 44, k + 5, NovaCraftBlocks.cracked_basal_bricks, 0, 2);
		world.setBlock(i + 3, j + 44, k + 5, NovaCraftBlocks.cracked_basal_bricks, 0, 2);
		world.setBlock(i + 4, j + 44, k + 5, NovaCraftBlocks.basal_bricks, 0, 2);
		world.setBlock(i + 5, j + 44, k + 5, NovaCraftBlocks.basal_bricks, 0, 2);
		world.setBlock(i + 6, j + 44, k + 5, NovaCraftBlocks.cracked_basal_bricks, 0, 2);
		world.setBlock(i + 7, j + 44, k + 5, NovaCraftBlocks.cracked_basal_bricks, 0, 2);
		world.setBlock(i + 8, j + 44, k + 5, NovaCraftBlocks.basal_bricks, 0, 2);
		world.setBlock(i + 9, j + 44, k + 5, NovaCraftBlocks.basal_bricks, 0, 2);
		world.setBlock(i + 10, j + 44, k + 5, NovaCraftBlocks.cracked_basal_bricks, 0, 2);
		world.setBlock(i + 11, j + 44, k + 5, NovaCraftBlocks.basal, 0, 2);
		world.setBlock(i + 12, j + 44, k + 5, Blocks.air, 0, 2);
		world.setBlock(i + 13, j + 44, k + 5, Blocks.air, 0, 2);
		world.setBlock(i + 14, j + 44, k + 5, NovaCraftBlocks.cracked_basal_bricks, 0, 2);
		world.setBlock(i + 15, j + 44, k + 5, NovaCraftBlocks.basal_bricks, 0, 2);
		world.setBlock(i + 16, j + 44, k + 5, Blocks.air, 0, 2);
		world.setBlock(i + 17, j + 44, k + 5, Blocks.air, 0, 2);
		world.setBlock(i + 18, j + 44, k + 5, NovaCraftBlocks.basal_bricks, 0, 2);
		world.setBlock(i + 19, j + 44, k + 5, NovaCraftBlocks.cracked_basal_bricks, 0, 2);
		world.setBlock(i + 20, j + 44, k + 5, Blocks.air, 0, 2);
		world.setBlock(i + 21, j + 44, k + 5, Blocks.air, 0, 2);
		world.setBlock(i + 22, j + 44, k + 5, NovaCraftBlocks.basal_bricks, 0, 2);
		world.setBlock(i + 23, j + 44, k + 5, NovaCraftBlocks.cracked_basal_bricks, 0, 2);
		world.setBlock(i + 24, j + 44, k + 5, Blocks.air, 0, 2);
		world.setBlock(i + 25, j + 44, k + 5, Blocks.air, 0, 2);
		world.setBlock(i + 26, j + 44, k + 5, NovaCraftBlocks.cracked_basal_bricks, 0, 2);
		world.setBlock(i + 27, j + 44, k + 5, NovaCraftBlocks.cracked_basal_bricks, 0, 2);
		world.setBlock(i + 0, j + 44, k + 6, NovaCraftBlocks.basal_bricks, 0, 2);
		world.setBlock(i + 1, j + 44, k + 6, NovaCraftBlocks.cracked_basal_bricks, 0, 2);
		world.setBlock(i + 2, j + 44, k + 6, NovaCraftBlocks.basal_bricks, 0, 2);
		world.setBlock(i + 3, j + 44, k + 6, NovaCraftBlocks.basal_bricks, 0, 2);
		world.setBlock(i + 4, j + 44, k + 6, NovaCraftBlocks.cracked_basal_bricks, 0, 2);
		world.setBlock(i + 5, j + 44, k + 6, NovaCraftBlocks.cracked_basal_bricks, 0, 2);
		world.setBlock(i + 6, j + 44, k + 6, NovaCraftBlocks.basal_bricks, 0, 2);
		world.setBlock(i + 7, j + 44, k + 6, NovaCraftBlocks.basal_bricks, 0, 2);
		world.setBlock(i + 8, j + 44, k + 6, NovaCraftBlocks.basal_bricks, 0, 2);
		world.setBlock(i + 9, j + 44, k + 6, NovaCraftBlocks.cracked_basal_bricks, 0, 2);
		world.setBlock(i + 10, j + 44, k + 6, NovaCraftBlocks.cracked_basal_bricks, 0, 2);
		world.setBlock(i + 11, j + 44, k + 6, NovaCraftBlocks.basal_bricks, 0, 2);
		world.setBlock(i + 12, j + 44, k + 6, NovaCraftBlocks.cracked_basal_bricks, 0, 2);
		world.setBlock(i + 13, j + 44, k + 6, Blocks.air, 0, 2);
		world.setBlock(i + 14, j + 44, k + 6, NovaCraftBlocks.cracked_basal_bricks, 0, 2);
		world.setBlock(i + 15, j + 44, k + 6, NovaCraftBlocks.basal_bricks, 0, 2);
		world.setBlock(i + 16, j + 44, k + 6, NovaCraftBlocks.cracked_basal_bricks, 0, 2);
		world.setBlock(i + 17, j + 44, k + 6, NovaCraftBlocks.cracked_basal_bricks, 0, 2);
		world.setBlock(i + 18, j + 44, k + 6, NovaCraftBlocks.cracked_basal_bricks, 0, 2);
		world.setBlock(i + 19, j + 44, k + 6, NovaCraftBlocks.basal_bricks, 0, 2);
		world.setBlock(i + 20, j + 44, k + 6, NovaCraftBlocks.basal_bricks, 0, 2);
		world.setBlock(i + 21, j + 44, k + 6, NovaCraftBlocks.basal_bricks, 0, 2);
		world.setBlock(i + 22, j + 44, k + 6, NovaCraftBlocks.basal_bricks, 0, 2);
		world.setBlock(i + 23, j + 44, k + 6, NovaCraftBlocks.cracked_basal_bricks, 0, 2);
		world.setBlock(i + 24, j + 44, k + 6, NovaCraftBlocks.basal_bricks, 0, 2);
		world.setBlock(i + 25, j + 44, k + 6, NovaCraftBlocks.basal_bricks, 0, 2);
		world.setBlock(i + 26, j + 44, k + 6, NovaCraftBlocks.basal_bricks, 0, 2);
		world.setBlock(i + 27, j + 44, k + 6, NovaCraftBlocks.basal_bricks, 0, 2);
		world.setBlock(i + 0, j + 44, k + 7, NovaCraftBlocks.cracked_basal_bricks, 0, 2);
		world.setBlock(i + 1, j + 44, k + 7, NovaCraftBlocks.cracked_basal_bricks, 0, 2);
		world.setBlock(i + 2, j + 44, k + 7, NovaCraftBlocks.cracked_basal_bricks, 0, 2);
		world.setBlock(i + 3, j + 44, k + 7, NovaCraftBlocks.basal_bricks, 0, 2);
		world.setBlock(i + 4, j + 44, k + 7, NovaCraftBlocks.basal_bricks, 0, 2);
		world.setBlock(i + 5, j + 44, k + 7, NovaCraftBlocks.basal_bricks, 0, 2);
		world.setBlock(i + 6, j + 44, k + 7, NovaCraftBlocks.basal_bricks, 0, 2);
		world.setBlock(i + 7, j + 44, k + 7, NovaCraftBlocks.basal_bricks, 0, 2);
		world.setBlock(i + 8, j + 44, k + 7, NovaCraftBlocks.cracked_basal_bricks, 0, 2);
		world.setBlock(i + 9, j + 44, k + 7, NovaCraftBlocks.cracked_basal_bricks, 0, 2);
		world.setBlock(i + 10, j + 44, k + 7, NovaCraftBlocks.basal_bricks, 0, 2);
		world.setBlock(i + 11, j + 44, k + 7, NovaCraftBlocks.basal_bricks, 0, 2);
		world.setBlock(i + 12, j + 44, k + 7, NovaCraftBlocks.basal_bricks, 0, 2);
		world.setBlock(i + 13, j + 44, k + 7, Blocks.air, 0, 2);
		world.setBlock(i + 14, j + 44, k + 7, NovaCraftBlocks.cracked_basal_bricks, 0, 2);
		world.setBlock(i + 15, j + 44, k + 7, NovaCraftBlocks.basal_bricks, 0, 2);
		world.setBlock(i + 16, j + 44, k + 7, NovaCraftBlocks.cracked_basal_bricks, 0, 2);
		world.setBlock(i + 17, j + 44, k + 7, NovaCraftBlocks.basal_bricks, 0, 2);
		world.setBlock(i + 18, j + 44, k + 7, NovaCraftBlocks.basal_bricks, 0, 2);
		world.setBlock(i + 19, j + 44, k + 7, NovaCraftBlocks.cracked_basal_bricks, 0, 2);
		world.setBlock(i + 20, j + 44, k + 7, NovaCraftBlocks.basal_bricks, 0, 2);
		world.setBlock(i + 21, j + 44, k + 7, NovaCraftBlocks.basal_bricks, 0, 2);
		world.setBlock(i + 22, j + 44, k + 7, NovaCraftBlocks.basal_bricks, 0, 2);
		world.setBlock(i + 23, j + 44, k + 7, NovaCraftBlocks.cracked_basal_bricks, 0, 2);
		world.setBlock(i + 24, j + 44, k + 7, NovaCraftBlocks.basal_bricks, 0, 2);
		world.setBlock(i + 25, j + 44, k + 7, NovaCraftBlocks.basal_bricks, 0, 2);
		world.setBlock(i + 26, j + 44, k + 7, NovaCraftBlocks.basal_bricks, 0, 2);
		world.setBlock(i + 27, j + 44, k + 7, NovaCraftBlocks.cracked_basal_bricks, 0, 2);
		world.setBlock(i + 0, j + 44, k + 8, NovaCraftBlocks.basal_bricks, 0, 2);
		world.setBlock(i + 1, j + 44, k + 8, NovaCraftBlocks.basal_bricks, 0, 2);
		world.setBlock(i + 2, j + 44, k + 8, NovaCraftBlocks.basal_bricks, 0, 2);
		world.setBlock(i + 3, j + 44, k + 8, NovaCraftBlocks.basal_bricks, 0, 2);
		world.setBlock(i + 4, j + 44, k + 8, NovaCraftBlocks.cracked_basal_bricks, 0, 2);
		world.setBlock(i + 5, j + 44, k + 8, NovaCraftBlocks.basal_bricks, 0, 2);
		world.setBlock(i + 6, j + 44, k + 8, NovaCraftBlocks.cracked_basal_bricks, 0, 2);
		world.setBlock(i + 7, j + 44, k + 8, NovaCraftBlocks.basal_bricks, 0, 2);
		world.setBlock(i + 8, j + 44, k + 8, NovaCraftBlocks.cracked_basal_bricks, 0, 2);
		world.setBlock(i + 9, j + 44, k + 8, NovaCraftBlocks.basal_bricks, 0, 2);
		world.setBlock(i + 10, j + 44, k + 8, NovaCraftBlocks.basal_bricks, 0, 2);
		world.setBlock(i + 11, j + 44, k + 8, NovaCraftBlocks.cracked_basal_bricks, 0, 2);
		world.setBlock(i + 12, j + 44, k + 8, NovaCraftBlocks.cracked_basal_bricks, 0, 2);
		world.setBlock(i + 13, j + 44, k + 8, NovaCraftBlocks.basal_bricks, 0, 2);
		world.setBlock(i + 14, j + 44, k + 8, NovaCraftBlocks.basal_bricks, 0, 2);
		world.setBlock(i + 15, j + 44, k + 8, NovaCraftBlocks.basal_bricks, 0, 2);
		world.setBlock(i + 16, j + 44, k + 8, NovaCraftBlocks.cracked_basal_bricks, 0, 2);
		world.setBlock(i + 17, j + 44, k + 8, NovaCraftBlocks.cracked_basal_bricks, 0, 2);
		world.setBlock(i + 18, j + 44, k + 8, NovaCraftBlocks.cracked_basal_bricks, 0, 2);
		world.setBlock(i + 19, j + 44, k + 8, NovaCraftBlocks.basal_bricks, 0, 2);
		world.setBlock(i + 20, j + 44, k + 8, NovaCraftBlocks.basal_bricks, 0, 2);
		world.setBlock(i + 21, j + 44, k + 8, NovaCraftBlocks.cracked_basal_bricks, 0, 2);
		world.setBlock(i + 22, j + 44, k + 8, NovaCraftBlocks.basal_bricks, 0, 2);
		world.setBlock(i + 23, j + 44, k + 8, NovaCraftBlocks.cracked_basal_bricks, 0, 2);
		world.setBlock(i + 24, j + 44, k + 8, NovaCraftBlocks.cracked_basal_bricks, 0, 2);
		world.setBlock(i + 25, j + 44, k + 8, NovaCraftBlocks.basal_bricks, 0, 2);
		world.setBlock(i + 26, j + 44, k + 8, NovaCraftBlocks.basal_bricks, 0, 2);
		world.setBlock(i + 27, j + 44, k + 8, NovaCraftBlocks.basal_bricks, 0, 2);
		world.setBlock(i + 0, j + 44, k + 9, NovaCraftBlocks.basal_bricks, 0, 2);
		world.setBlock(i + 1, j + 44, k + 9, NovaCraftBlocks.basal_bricks, 0, 2);
		world.setBlock(i + 2, j + 44, k + 9, NovaCraftBlocks.basal_bricks, 0, 2);
		world.setBlock(i + 3, j + 44, k + 9, NovaCraftBlocks.basal_bricks, 0, 2);
		world.setBlock(i + 4, j + 44, k + 9, NovaCraftBlocks.basal_bricks, 0, 2);
		world.setBlock(i + 5, j + 44, k + 9, NovaCraftBlocks.cracked_basal_bricks, 0, 2);
		world.setBlock(i + 6, j + 44, k + 9, NovaCraftBlocks.basal_bricks, 0, 2);
		world.setBlock(i + 7, j + 44, k + 9, NovaCraftBlocks.basal_bricks, 0, 2);
		world.setBlock(i + 8, j + 44, k + 9, NovaCraftBlocks.basal_bricks, 0, 2);
		world.setBlock(i + 9, j + 44, k + 9, NovaCraftBlocks.basal_bricks, 0, 2);
