package com.NovaCraft.world.bastion.treasure;

import net.minecraft.world.gen.feature.*;
import net.minecraft.block.*;
import net.minecraft.world.*;
import java.util.*;

import com.NovaCraft.config.Configs;
import com.NovaCraft.registry.OtherModBlocks;
import com.NovaCraftBlocks.NovaCraftBlocks;

import cpw.mods.fml.common.Loader;
import net.minecraft.init.*;

public class BastionTreasureBridgeGen1 extends WorldGenerator
{
	public BastionTreasureBridgeGen1() {

	}
	
	public boolean generate(final World world, final Random random, final int i, final int j, final int k) {
		
		world.setBlock(i + 0, j + 0, k + 0, NovaCraftBlocks.basal_bricks, 0, 2);
		world.setBlock(i + 1, j + 0, k + 0, NovaCraftBlocks.basal_bricks, 0, 2);
		world.setBlock(i + 2, j + 0, k + 0, NovaCraftBlocks.basal_bricks, 0, 2);
		world.setBlock(i + 3, j + 0, k + 0, NovaCraftBlocks.basal_bricks, 0, 2);
		world.setBlock(i + 4, j + 0, k + 0, NovaCraftBlocks.basal_bricks, 0, 2);
		world.setBlock(i + 5, j + 0, k + 0, NovaCraftBlocks.basal_bricks, 0, 2);
		world.setBlock(i + 6, j + 0, k + 0, NovaCraftBlocks.basal_bricks, 0, 2);
		world.setBlock(i + 7, j + 0, k + 0, NovaCraftBlocks.basal_bricks, 0, 2);
		world.setBlock(i + 8, j + 0, k + 0, NovaCraftBlocks.cracked_basal_bricks, 0, 2);
		world.setBlock(i + 9, j + 0, k + 0, NovaCraftBlocks.basal_bricks, 0, 2);
		world.setBlock(i + 10, j + 0, k + 0, NovaCraftBlocks.basal_bricks, 0, 2);
		world.setBlock(i + 11, j + 0, k + 0, NovaCraftBlocks.basal_bricks, 0, 2);
		world.setBlock(i + 12, j + 0, k + 0, NovaCraftBlocks.cracked_basal_bricks, 0, 2);
		world.setBlock(i + 13, j + 0, k + 0, NovaCraftBlocks.basal_bricks, 0, 2);
		world.setBlock(i + 14, j + 0, k + 0, NovaCraftBlocks.basal_bricks, 0, 2);
		world.setBlock(i + 15, j + 0, k + 0, NovaCraftBlocks.basal_bricks, 0, 2);
		world.setBlock(i + 16, j + 0, k + 0, NovaCraftBlocks.cracked_basal_bricks, 0, 2);
		world.setBlock(i + 17, j + 0, k + 0, NovaCraftBlocks.basal_bricks, 0, 2);
		world.setBlock(i + 18, j + 0, k + 0, NovaCraftBlocks.cracked_basal_bricks, 0, 2);
		world.setBlock(i + 19, j + 0, k + 0, NovaCraftBlocks.cracked_basal_bricks, 0, 2);
		world.setBlock(i + 20, j + 0, k + 0, NovaCraftBlocks.basal_bricks, 0, 2);
		world.setBlock(i + 21, j + 0, k + 0, NovaCraftBlocks.basal_bricks, 0, 2);
		world.setBlock(i + 22, j + 0, k + 0, NovaCraftBlocks.basal_bricks, 0, 2);
		world.setBlock(i + 23, j + 0, k + 0, NovaCraftBlocks.cracked_basal_bricks, 0, 2);
		world.setBlock(i + 24, j + 0, k + 0, NovaCraftBlocks.basal_bricks, 0, 2);
		world.setBlock(i + 25, j + 0, k + 0, NovaCraftBlocks.cracked_basal_bricks, 0, 2);
		world.setBlock(i + 26, j + 0, k + 0, NovaCraftBlocks.cracked_basal_bricks, 0, 2);
		world.setBlock(i + 27, j + 0, k + 0, NovaCraftBlocks.basal_bricks, 0, 2);
		world.setBlock(i + 0, j + 0, k + 1, NovaCraftBlocks.basal_bricks, 0, 2);
		world.setBlock(i + 1, j + 0, k + 1, NovaCraftBlocks.basal_bricks, 0, 2);
		world.setBlock(i + 2, j + 0, k + 1, NovaCraftBlocks.cracked_basal_bricks, 0, 2);
		world.setBlock(i + 3, j + 0, k + 1, NovaCraftBlocks.cracked_basal_bricks, 0, 2);
		world.setBlock(i + 4, j + 0, k + 1, NovaCraftBlocks.basal_bricks, 0, 2);
		world.setBlock(i + 5, j + 0, k + 1, NovaCraftBlocks.basal_bricks, 0, 2);
		world.setBlock(i + 6, j + 0, k + 1, NovaCraftBlocks.basal_bricks, 0, 2);
		world.setBlock(i + 7, j + 0, k + 1, NovaCraftBlocks.basal_bricks, 0, 2);
		world.setBlock(i + 8, j + 0, k + 1, NovaCraftBlocks.basal_bricks, 0, 2);
		world.setBlock(i + 9, j + 0, k + 1, NovaCraftBlocks.cracked_basal_bricks, 0, 2);
		world.setBlock(i + 10, j + 0, k + 1, NovaCraftBlocks.basal_bricks, 0, 2);
		world.setBlock(i + 11, j + 0, k + 1, NovaCraftBlocks.basal_bricks, 0, 2);
		world.setBlock(i + 12, j + 0, k + 1, NovaCraftBlocks.basal_bricks, 0, 2);
		world.setBlock(i + 13, j + 0, k + 1, NovaCraftBlocks.basal_bricks, 0, 2);
		world.setBlock(i + 14, j + 0, k + 1, NovaCraftBlocks.basal_bricks, 0, 2);
		world.setBlock(i + 15, j + 0, k + 1, NovaCraftBlocks.basal_bricks, 0, 2);
		world.setBlock(i + 16, j + 0, k + 1, NovaCraftBlocks.basal_bricks, 0, 2);
		world.setBlock(i + 17, j + 0, k + 1, NovaCraftBlocks.basal_bricks, 0, 2);
		world.setBlock(i + 18, j + 0, k + 1, NovaCraftBlocks.cracked_basal_bricks, 0, 2);
		world.setBlock(i + 19, j + 0, k + 1, NovaCraftBlocks.basal_bricks, 0, 2);
		world.setBlock(i + 20, j + 0, k + 1, NovaCraftBlocks.basal_bricks, 0, 2);
		world.setBlock(i + 21, j + 0, k + 1, NovaCraftBlocks.cracked_basal_bricks, 0, 2);
		world.setBlock(i + 22, j + 0, k + 1, NovaCraftBlocks.cracked_basal_bricks, 0, 2);
		world.setBlock(i + 23, j + 0, k + 1, NovaCraftBlocks.cracked_basal_bricks, 0, 2);
		world.setBlock(i + 24, j + 0, k + 1, NovaCraftBlocks.cracked_basal_bricks, 0, 2);
		world.setBlock(i + 25, j + 0, k + 1, NovaCraftBlocks.basal_bricks, 0, 2);
		world.setBlock(i + 26, j + 0, k + 1, NovaCraftBlocks.basal_bricks, 0, 2);
		world.setBlock(i + 27, j + 0, k + 1, NovaCraftBlocks.cracked_basal_bricks, 0, 2);
		world.setBlock(i + 0, j + 0, k + 2, NovaCraftBlocks.basal_bricks, 0, 2);
		world.setBlock(i + 1, j + 0, k + 2, NovaCraftBlocks.basal_bricks, 0, 2);
		world.setBlock(i + 2, j + 0, k + 2, NovaCraftBlocks.basal_bricks, 0, 2);
		world.setBlock(i + 3, j + 0, k + 2, NovaCraftBlocks.cracked_basal_bricks, 0, 2);
		world.setBlock(i + 4, j + 0, k + 2, NovaCraftBlocks.basal_bricks, 0, 2);
		world.setBlock(i + 5, j + 0, k + 2, NovaCraftBlocks.cracked_basal_bricks, 0, 2);
		world.setBlock(i + 6, j + 0, k + 2, NovaCraftBlocks.basal_bricks, 0, 2);
		world.setBlock(i + 7, j + 0, k + 2, NovaCraftBlocks.cracked_basal_bricks, 0, 2);
		world.setBlock(i + 8, j + 0, k + 2, NovaCraftBlocks.cracked_basal_bricks, 0, 2);
		world.setBlock(i + 9, j + 0, k + 2, NovaCraftBlocks.basal_bricks, 0, 2);
		world.setBlock(i + 10, j + 0, k + 2, NovaCraftBlocks.basal_bricks, 0, 2);
		world.setBlock(i + 11, j + 0, k + 2, NovaCraftBlocks.basal_bricks, 0, 2);
		world.setBlock(i + 12, j + 0, k + 2, NovaCraftBlocks.basal_bricks, 0, 2);
		world.setBlock(i + 13, j + 0, k + 2, NovaCraftBlocks.basal_bricks, 0, 2);
		world.setBlock(i + 14, j + 0, k + 2, NovaCraftBlocks.basal_bricks, 0, 2);
		world.setBlock(i + 15, j + 0, k + 2, NovaCraftBlocks.basal_bricks, 0, 2);
		world.setBlock(i + 16, j + 0, k + 2, NovaCraftBlocks.basal_bricks, 0, 2);
		world.setBlock(i + 17, j + 0, k + 2, NovaCraftBlocks.basal_bricks, 0, 2);
		world.setBlock(i + 18, j + 0, k + 2, NovaCraftBlocks.basal_bricks, 0, 2);
		world.setBlock(i + 19, j + 0, k + 2, NovaCraftBlocks.basal_bricks, 0, 2);
		world.setBlock(i + 20, j + 0, k + 2, NovaCraftBlocks.cracked_basal_bricks, 0, 2);
		world.setBlock(i + 21, j + 0, k + 2, NovaCraftBlocks.basal_bricks, 0, 2);
		world.setBlock(i + 22, j + 0, k + 2, NovaCraftBlocks.basal_bricks, 0, 2);
		world.setBlock(i + 23, j + 0, k + 2, NovaCraftBlocks.basal_bricks, 0, 2);
		world.setBlock(i + 24, j + 0, k + 2, NovaCraftBlocks.basal_bricks, 0, 2);
		world.setBlock(i + 25, j + 0, k + 2, NovaCraftBlocks.basal_bricks, 0, 2);
		world.setBlock(i + 26, j + 0, k + 2, NovaCraftBlocks.basal_bricks, 0, 2);
		world.setBlock(i + 27, j + 0, k + 2, NovaCraftBlocks.basal_bricks, 0, 2);
		world.setBlock(i + 0, j + 0, k + 3, NovaCraftBlocks.cracked_basal_bricks, 0, 2);
		world.setBlock(i + 1, j + 0, k + 3, NovaCraftBlocks.basal_bricks, 0, 2);
		world.setBlock(i + 2, j + 0, k + 3, NovaCraftBlocks.basal_bricks, 0, 2);
		world.setBlock(i + 3, j + 0, k + 3, NovaCraftBlocks.cracked_basal_bricks, 0, 2);
		world.setBlock(i + 4, j + 0, k + 3, NovaCraftBlocks.cracked_basal_bricks, 0, 2);
		world.setBlock(i + 5, j + 0, k + 3, NovaCraftBlocks.basal_bricks, 0, 2);
		world.setBlock(i + 6, j + 0, k + 3, NovaCraftBlocks.basal_bricks, 0, 2);
		world.setBlock(i + 7, j + 0, k + 3, NovaCraftBlocks.basal_bricks, 0, 2);
		world.setBlock(i + 8, j + 0, k + 3, NovaCraftBlocks.cracked_basal_bricks, 0, 2);
		world.setBlock(i + 9, j + 0, k + 3, NovaCraftBlocks.cracked_basal_bricks, 0, 2);
		world.setBlock(i + 10, j + 0, k + 3, NovaCraftBlocks.basal_bricks, 0, 2);
		world.setBlock(i + 11, j + 0, k + 3, NovaCraftBlocks.basal_bricks, 0, 2);
		world.setBlock(i + 12, j + 0, k + 3, NovaCraftBlocks.basal_bricks, 0, 2);
		world.setBlock(i + 13, j + 0, k + 3, NovaCraftBlocks.basal_bricks, 0, 2);
		world.setBlock(i + 14, j + 0, k + 3, NovaCraftBlocks.basal_bricks, 0, 2);
		world.setBlock(i + 15, j + 0, k + 3, NovaCraftBlocks.cracked_basal_bricks, 0, 2);
		world.setBlock(i + 16, j + 0, k + 3, NovaCraftBlocks.basal_bricks, 0, 2);
		world.setBlock(i + 17, j + 0, k + 3, NovaCraftBlocks.basal_bricks, 0, 2);
		world.setBlock(i + 18, j + 0, k + 3, NovaCraftBlocks.basal_bricks, 0, 2);
		world.setBlock(i + 19, j + 0, k + 3, NovaCraftBlocks.cracked_basal_bricks, 0, 2);
		world.setBlock(i + 20, j + 0, k + 3, NovaCraftBlocks.basal_bricks, 0, 2);
		world.setBlock(i + 21, j + 0, k + 3, NovaCraftBlocks.cracked_basal_bricks, 0, 2);
		world.setBlock(i + 22, j + 0, k + 3, NovaCraftBlocks.cracked_basal_bricks, 0, 2);
		world.setBlock(i + 23, j + 0, k + 3, NovaCraftBlocks.basal_bricks, 0, 2);
		world.setBlock(i + 24, j + 0, k + 3, NovaCraftBlocks.basal_bricks, 0, 2);
		world.setBlock(i + 25, j + 0, k + 3, NovaCraftBlocks.basal_bricks, 0, 2);
		world.setBlock(i + 26, j + 0, k + 3, NovaCraftBlocks.basal_bricks, 0, 2);
		world.setBlock(i + 27, j + 0, k + 3, NovaCraftBlocks.cracked_basal_bricks, 0, 2);
		world.setBlock(i + 0, j + 0, k + 4, NovaCraftBlocks.basal_bricks, 0, 2);
		world.setBlock(i + 1, j + 0, k + 4, NovaCraftBlocks.basal_bricks, 0, 2);
		world.setBlock(i + 2, j + 0, k + 4, NovaCraftBlocks.basal_bricks, 0, 2);
		world.setBlock(i + 3, j + 0, k + 4, NovaCraftBlocks.basal_bricks, 0, 2);
		world.setBlock(i + 4, j + 0, k + 4, NovaCraftBlocks.cracked_basal_bricks, 0, 2);
		world.setBlock(i + 5, j + 0, k + 4, NovaCraftBlocks.basal_bricks, 0, 2);
		world.setBlock(i + 6, j + 0, k + 4, NovaCraftBlocks.basal_bricks, 0, 2);
		world.setBlock(i + 7, j + 0, k + 4, NovaCraftBlocks.cracked_basal_bricks, 0, 2);
		world.setBlock(i + 8, j + 0, k + 4, NovaCraftBlocks.basal_bricks, 0, 2);
		world.setBlock(i + 9, j + 0, k + 4, NovaCraftBlocks.basal_bricks, 0, 2);
		world.setBlock(i + 10, j + 0, k + 4, NovaCraftBlocks.basal_bricks, 0, 2);
		world.setBlock(i + 11, j + 0, k + 4, NovaCraftBlocks.cracked_basal_bricks, 0, 2);
		world.setBlock(i + 12, j + 0, k + 4, NovaCraftBlocks.basal_bricks, 0, 2);
		world.setBlock(i + 13, j + 0, k + 4, NovaCraftBlocks.cracked_basal_bricks, 0, 2);
		world.setBlock(i + 14, j + 0, k + 4, NovaCraftBlocks.basal_bricks, 0, 2);
		world.setBlock(i + 15, j + 0, k + 4, NovaCraftBlocks.basal_bricks, 0, 2);
		world.setBlock(i + 16, j + 0, k + 4, NovaCraftBlocks.basal_bricks, 0, 2);
		world.setBlock(i + 17, j + 0, k + 4, NovaCraftBlocks.basal_bricks, 0, 2);
		world.setBlock(i + 18, j + 0, k + 4, NovaCraftBlocks.cracked_basal_bricks, 0, 2);
		world.setBlock(i + 19, j + 0, k + 4, NovaCraftBlocks.basal_bricks, 0, 2);
		world.setBlock(i + 20, j + 0, k + 4, NovaCraftBlocks.basal_bricks, 0, 2);
		world.setBlock(i + 21, j + 0, k + 4, NovaCraftBlocks.basal_bricks, 0, 2);
		world.setBlock(i + 22, j + 0, k + 4, NovaCraftBlocks.basal_bricks, 0, 2);
		world.setBlock(i + 23, j + 0, k + 4, NovaCraftBlocks.basal_bricks, 0, 2);
		world.setBlock(i + 24, j + 0, k + 4, NovaCraftBlocks.basal_bricks, 0, 2);
		world.setBlock(i + 25, j + 0, k + 4, NovaCraftBlocks.basal_bricks, 0, 2);
		world.setBlock(i + 26, j + 0, k + 4, NovaCraftBlocks.basal_bricks, 0, 2);
		world.setBlock(i + 27, j + 0, k + 4, NovaCraftBlocks.cracked_basal_bricks, 0, 2);
		world.setBlock(i + 0, j + 0, k + 5, NovaCraftBlocks.cracked_basal_bricks, 0, 2);
		world.setBlock(i + 1, j + 0, k + 5, NovaCraftBlocks.basal_bricks, 0, 2);
		world.setBlock(i + 2, j + 0, k + 5, NovaCraftBlocks.basal_bricks, 0, 2);
		world.setBlock(i + 3, j + 0, k + 5, NovaCraftBlocks.basal_bricks, 0, 2);
		world.setBlock(i + 4, j + 0, k + 5, NovaCraftBlocks.basal_bricks, 0, 2);
		world.setBlock(i + 5, j + 0, k + 5, NovaCraftBlocks.basal_bricks, 0, 2);
		world.setBlock(i + 6, j + 0, k + 5, NovaCraftBlocks.cracked_basal_bricks, 0, 2);
		world.setBlock(i + 7, j + 0, k + 5, NovaCraftBlocks.basal_bricks, 0, 2);
		world.setBlock(i + 8, j + 0, k + 5, NovaCraftBlocks.cracked_basal_bricks, 0, 2);
		world.setBlock(i + 9, j + 0, k + 5, NovaCraftBlocks.basal_bricks, 0, 2);
		world.setBlock(i + 10, j + 0, k + 5, NovaCraftBlocks.basal_bricks, 0, 2);
		world.setBlock(i + 11, j + 0, k + 5, NovaCraftBlocks.basal_bricks, 0, 2);
		world.setBlock(i + 12, j + 0, k + 5, NovaCraftBlocks.cracked_basal_bricks, 0, 2);
		world.setBlock(i + 13, j + 0, k + 5, NovaCraftBlocks.cracked_basal_bricks, 0, 2);
		world.setBlock(i + 14, j + 0, k + 5, NovaCraftBlocks.basal_bricks, 0, 2);
		world.setBlock(i + 15, j + 0, k + 5, NovaCraftBlocks.basal_bricks, 0, 2);
		world.setBlock(i + 16, j + 0, k + 5, NovaCraftBlocks.basal_bricks, 0, 2);
		world.setBlock(i + 17, j + 0, k + 5, NovaCraftBlocks.cracked_basal_bricks, 0, 2);
		world.setBlock(i + 18, j + 0, k + 5, NovaCraftBlocks.basal_bricks, 0, 2);
		world.setBlock(i + 19, j + 0, k + 5, NovaCraftBlocks.basal_bricks, 0, 2);
		world.setBlock(i + 20, j + 0, k + 5, NovaCraftBlocks.cracked_basal_bricks, 0, 2);
		world.setBlock(i + 21, j + 0, k + 5, NovaCraftBlocks.basal_bricks, 0, 2);
		world.setBlock(i + 22, j + 0, k + 5, NovaCraftBlocks.cracked_basal_bricks, 0, 2);
		world.setBlock(i + 23, j + 0, k + 5, NovaCraftBlocks.cracked_basal_bricks, 0, 2);
		world.setBlock(i + 24, j + 0, k + 5, NovaCraftBlocks.cracked_basal_bricks, 0, 2);
		world.setBlock(i + 25, j + 0, k + 5, NovaCraftBlocks.cracked_basal_bricks, 0, 2);
		world.setBlock(i + 26, j + 0, k + 5, NovaCraftBlocks.cracked_basal_bricks, 0, 2);
		world.setBlock(i + 27, j + 0, k + 5, NovaCraftBlocks.cracked_basal_bricks, 0, 2);
		world.setBlock(i + 0, j + 0, k + 6, NovaCraftBlocks.basal_bricks, 0, 2);
		world.setBlock(i + 1, j + 0, k + 6, NovaCraftBlocks.basal_bricks, 0, 2);
		world.setBlock(i + 2, j + 0, k + 6, NovaCraftBlocks.cracked_basal_bricks, 0, 2);
		world.setBlock(i + 3, j + 0, k + 6, NovaCraftBlocks.cracked_basal_bricks, 0, 2);
		world.setBlock(i + 4, j + 0, k + 6, NovaCraftBlocks.cracked_basal_bricks, 0, 2);
		world.setBlock(i + 5, j + 0, k + 6, NovaCraftBlocks.basal_bricks, 0, 2);
		world.setBlock(i + 6, j + 0, k + 6, NovaCraftBlocks.basal_bricks, 0, 2);
		world.setBlock(i + 7, j + 0, k + 6, NovaCraftBlocks.basal_bricks, 0, 2);
		world.setBlock(i + 8, j + 0, k + 6, NovaCraftBlocks.basal_bricks, 0, 2);
		world.setBlock(i + 9, j + 0, k + 6, NovaCraftBlocks.basal_bricks, 0, 2);
		world.setBlock(i + 10, j + 0, k + 6, NovaCraftBlocks.cracked_basal_bricks, 0, 2);
		world.setBlock(i + 11, j + 0, k + 6, NovaCraftBlocks.basal_bricks, 0, 2);
		world.setBlock(i + 12, j + 0, k + 6, NovaCraftBlocks.basal_bricks, 0, 2);
		world.setBlock(i + 13, j + 0, k + 6, NovaCraftBlocks.basal_bricks, 0, 2);
		world.setBlock(i + 14, j + 0, k + 6, NovaCraftBlocks.basal_bricks, 0, 2);
		world.setBlock(i + 15, j + 0, k + 6, NovaCraftBlocks.basal_bricks, 0, 2);
		world.setBlock(i + 16, j + 0, k + 6, NovaCraftBlocks.cracked_basal_bricks, 0, 2);
		world.setBlock(i + 17, j + 0, k + 6, NovaCraftBlocks.basal_bricks, 0, 2);
		world.setBlock(i + 18, j + 0, k + 6, NovaCraftBlocks.basal_bricks, 0, 2);
		world.setBlock(i + 19, j + 0, k + 6, NovaCraftBlocks.cracked_basal_bricks, 0, 2);
		world.setBlock(i + 20, j + 0, k + 6, NovaCraftBlocks.cracked_basal_bricks, 0, 2);
		world.setBlock(i + 21, j + 0, k + 6, NovaCraftBlocks.cracked_basal_bricks, 0, 2);
		world.setBlock(i + 22, j + 0, k + 6, NovaCraftBlocks.basal_bricks, 0, 2);
		world.setBlock(i + 23, j + 0, k + 6, NovaCraftBlocks.basal_bricks, 0, 2);
		world.setBlock(i + 24, j + 0, k + 6, NovaCraftBlocks.cracked_basal_bricks, 0, 2);
		world.setBlock(i + 25, j + 0, k + 6, NovaCraftBlocks.cracked_basal_bricks, 0, 2);
		world.setBlock(i + 26, j + 0, k + 6, NovaCraftBlocks.basal_bricks, 0, 2);
		world.setBlock(i + 27, j + 0, k + 6, NovaCraftBlocks.basal_bricks, 0, 2);
		world.setBlock(i + 0, j + 0, k + 7, NovaCraftBlocks.cracked_basal_bricks, 0, 2);
		world.setBlock(i + 1, j + 0, k + 7, NovaCraftBlocks.basal_bricks, 0, 2);
		world.setBlock(i + 2, j + 0, k + 7, NovaCraftBlocks.basal_bricks, 0, 2);
		world.setBlock(i + 3, j + 0, k + 7, NovaCraftBlocks.cracked_basal_bricks, 0, 2);
		world.setBlock(i + 4, j + 0, k + 7, NovaCraftBlocks.basal_bricks, 0, 2);
		world.setBlock(i + 5, j + 0, k + 7, NovaCraftBlocks.cracked_basal_bricks, 0, 2);
		world.setBlock(i + 6, j + 0, k + 7, NovaCraftBlocks.basal_bricks, 0, 2);
		world.setBlock(i + 7, j + 0, k + 7, NovaCraftBlocks.basal_bricks, 0, 2);
		world.setBlock(i + 8, j + 0, k + 7, NovaCraftBlocks.basal_bricks, 0, 2);
		world.setBlock(i + 9, j + 0, k + 7, NovaCraftBlocks.basal_bricks, 0, 2);
		world.setBlock(i + 10, j + 0, k + 7, NovaCraftBlocks.basal_bricks, 0, 2);
		world.setBlock(i + 11, j + 0, k + 7, NovaCraftBlocks.cracked_basal_bricks, 0, 2);
		world.setBlock(i + 12, j + 0, k + 7, NovaCraftBlocks.cracked_basal_bricks, 0, 2);
		world.setBlock(i + 13, j + 0, k + 7, NovaCraftBlocks.basal_bricks, 0, 2);
		world.setBlock(i + 14, j + 0, k + 7, NovaCraftBlocks.basal_bricks, 0, 2);
		world.setBlock(i + 15, j + 0, k + 7, NovaCraftBlocks.cracked_basal_bricks, 0, 2);
		world.setBlock(i + 16, j + 0, k + 7, NovaCraftBlocks.cracked_basal_bricks, 0, 2);
		world.setBlock(i + 17, j + 0, k + 7, NovaCraftBlocks.basal_bricks, 0, 2);
		world.setBlock(i + 18, j + 0, k + 7, NovaCraftBlocks.basal_bricks, 0, 2);
		world.setBlock(i + 19, j + 0, k + 7, NovaCraftBlocks.cracked_basal_bricks, 0, 2);
		world.setBlock(i + 20, j + 0, k + 7, NovaCraftBlocks.basal_bricks, 0, 2);
		world.setBlock(i + 21, j + 0, k + 7, NovaCraftBlocks.basal_bricks, 0, 2);
		world.setBlock(i + 22, j + 0, k + 7, NovaCraftBlocks.cracked_basal_bricks, 0, 2);
		world.setBlock(i + 23, j + 0, k + 7, NovaCraftBlocks.basal_bricks, 0, 2);
		world.setBlock(i + 24, j + 0, k + 7, NovaCraftBlocks.basal_bricks, 0, 2);
		world.setBlock(i + 25, j + 0, k + 7, NovaCraftBlocks.cracked_basal_bricks, 0, 2);
		world.setBlock(i + 26, j + 0, k + 7, NovaCraftBlocks.cracked_basal_bricks, 0, 2);
		world.setBlock(i + 27, j + 0, k + 7, NovaCraftBlocks.basal_bricks, 0, 2);
		world.setBlock(i + 0, j + 0, k + 8, NovaCraftBlocks.basal_bricks, 0, 2);
		world.setBlock(i + 1, j + 0, k + 8, NovaCraftBlocks.basal_bricks, 0, 2);
		world.setBlock(i + 2, j + 0, k + 8, NovaCraftBlocks.cracked_basal_bricks, 0, 2);
		world.setBlock(i + 3, j + 0, k + 8, NovaCraftBlocks.basal_bricks, 0, 2);
		world.setBlock(i + 4, j + 0, k + 8, NovaCraftBlocks.basal_bricks, 0, 2);
		world.setBlock(i + 5, j + 0, k + 8, NovaCraftBlocks.basal_bricks, 0, 2);
		world.setBlock(i + 6, j + 0, k + 8, NovaCraftBlocks.basal_bricks, 0, 2);
		world.setBlock(i + 7, j + 0, k + 8, NovaCraftBlocks.cracked_basal_bricks, 0, 2);
		world.setBlock(i + 8, j + 0, k + 8, NovaCraftBlocks.cracked_basal_bricks, 0, 2);
		world.setBlock(i + 9, j + 0, k + 8, NovaCraftBlocks.cracked_basal_bricks, 0, 2);
		world.setBlock(i + 10, j + 0, k + 8, NovaCraftBlocks.basal_bricks, 0, 2);
		world.setBlock(i + 11, j + 0, k + 8, NovaCraftBlocks.basal_bricks, 0, 2);
		world.setBlock(i + 12, j + 0, k + 8, NovaCraftBlocks.basal_bricks, 0, 2);
		world.setBlock(i + 13, j + 0, k + 8, NovaCraftBlocks.cracked_basal_bricks, 0, 2);
		world.setBlock(i + 14, j + 0, k + 8, NovaCraftBlocks.cracked_basal_bricks, 0, 2);
		world.setBlock(i + 15, j + 0, k + 8, NovaCraftBlocks.basal_bricks, 0, 2);
		world.setBlock(i + 16, j + 0, k + 8, NovaCraftBlocks.cracked_basal_bricks, 0, 2);
		world.setBlock(i + 17, j + 0, k + 8, NovaCraftBlocks.basal_bricks, 0, 2);
		world.setBlock(i + 18, j + 0, k + 8, NovaCraftBlocks.basal_bricks, 0, 2);
		world.setBlock(i + 19, j + 0, k + 8, NovaCraftBlocks.basal_bricks, 0, 2);
		world.setBlock(i + 20, j + 0, k + 8, NovaCraftBlocks.basal_bricks, 0, 2);
		world.setBlock(i + 21, j + 0, k + 8, NovaCraftBlocks.basal_bricks, 0, 2);
		world.setBlock(i + 22, j + 0, k + 8, NovaCraftBlocks.cracked_basal_bricks, 0, 2);
		world.setBlock(i + 23, j + 0, k + 8, NovaCraftBlocks.cracked_basal_bricks, 0, 2);
		world.setBlock(i + 24, j + 0, k + 8, NovaCraftBlocks.cracked_basal_bricks, 0, 2);
		world.setBlock(i + 25, j + 0, k + 8, NovaCraftBlocks.cracked_basal_bricks, 0, 2);
		world.setBlock(i + 26, j + 0, k + 8, NovaCraftBlocks.basal_bricks, 0, 2);
		world.setBlock(i + 27, j + 0, k + 8, NovaCraftBlocks.basal_bricks, 0, 2);
		world.setBlock(i + 0, j + 0, k + 9, NovaCraftBlocks.basal_bricks, 0, 2);
		world.setBlock(i + 1, j + 0, k + 9, NovaCraftBlocks.basal_bricks, 0, 2);
		world.setBlock(i + 2, j + 0, k + 9, NovaCraftBlocks.cracked_basal_bricks, 0, 2);
		world.setBlock(i + 3, j + 0, k + 9, NovaCraftBlocks.cracked_basal_bricks, 0, 2);
		world.setBlock(i + 4, j + 0, k + 9, NovaCraftBlocks.basal_bricks, 0, 2);
		world.setBlock(i + 5, j + 0, k + 9, NovaCraftBlocks.basal_bricks, 0, 2);
		world.setBlock(i + 6, j + 0, k + 9, NovaCraftBlocks.basal_bricks, 0, 2);
		world.setBlock(i + 7, j + 0, k + 9, NovaCraftBlocks.basal_bricks, 0, 2);
		world.setBlock(i + 8, j + 0, k + 9, NovaCraftBlocks.basal_bricks, 0, 2);
		world.setBlock(i + 9, j + 0, k + 9, NovaCraftBlocks.basal_bricks, 0, 2);
		world.setBlock(i + 10, j + 0, k + 9, NovaCraftBlocks.basal_bricks, 0, 2);
		world.setBlock(i + 11, j + 0, k + 9, NovaCraftBlocks.basal_bricks, 0, 2);
		world.setBlock(i + 12, j + 0, k + 9, NovaCraftBlocks.basal_bricks, 0, 2);
		world.setBlock(i + 13, j + 0, k + 9, NovaCraftBlocks.basal_bricks, 0, 2);
		world.setBlock(i + 14, j + 0, k + 9, NovaCraftBlocks.basal_bricks, 0, 2);
		world.setBlock(i + 15, j + 0, k + 9, NovaCraftBlocks.basal_bricks, 0, 2);
		world.setBlock(i + 16, j + 0, k + 9, NovaCraftBlocks.basal_bricks, 0, 2);
		world.setBlock(i + 17, j + 0, k + 9, NovaCraftBlocks.basal_bricks, 0, 2);
		world.setBlock(i + 18, j + 0, k + 9, NovaCraftBlocks.basal_bricks, 0, 2);
		world.setBlock(i + 19, j + 0, k + 9, NovaCraftBlocks.cracked_basal_bricks, 0, 2);
		world.setBlock(i + 20, j + 0, k + 9, NovaCraftBlocks.basal_bricks, 0, 2);
		world.setBlock(i + 21, j + 0, k + 9, NovaCraftBlocks.basal_bricks, 0, 2);
		world.setBlock(i + 22, j + 0, k + 9, NovaCraftBlocks.basal_bricks, 0, 2);
		world.setBlock(i + 23, j + 0, k + 9, NovaCraftBlocks.cracked_basal_bricks, 0, 2);
		world.setBlock(i + 24, j + 0, k + 9, NovaCraftBlocks.basal_bricks, 0, 2);
		world.setBlock(i + 25, j + 0, k + 9, NovaCraftBlocks.basal_bricks, 0, 2);
		world.setBlock(i + 26, j + 0, k + 9, NovaCraftBlocks.basal_bricks, 0, 2);
		world.setBlock(i + 27, j + 0, k + 9, NovaCraftBlocks.cracked_basal_bricks, 0, 2);
		world.setBlock(i + 0, j + 0, k + 10, NovaCraftBlocks.basal_bricks, 0, 2);
		world.setBlock(i + 1, j + 0, k + 10, NovaCraftBlocks.basal_bricks, 0, 2);
		world.setBlock(i + 2, j + 0, k + 10, NovaCraftBlocks.basal_bricks, 0, 2);
		world.setBlock(i + 3, j + 0, k + 10, NovaCraftBlocks.cracked_basal_bricks, 0, 2);
		world.setBlock(i + 4, j + 0, k + 10, NovaCraftBlocks.basal_bricks, 0, 2);
		world.setBlock(i + 5, j + 0, k + 10, NovaCraftBlocks.basal_bricks, 0, 2);
		world.setBlock(i + 6, j + 0, k + 10, NovaCraftBlocks.basal_bricks, 0, 2);
		world.setBlock(i + 7, j + 0, k + 10, NovaCraftBlocks.cracked_basal_bricks, 0, 2);
		world.setBlock(i + 8, j + 0, k + 10, NovaCraftBlocks.basal_bricks, 0, 2);
		world.setBlock(i + 9, j + 0, k + 10, NovaCraftBlocks.basal_bricks, 0, 2);
		world.setBlock(i + 10, j + 0, k + 10, NovaCraftBlocks.basal_bricks, 0, 2);
		world.setBlock(i + 11, j + 0, k + 10, NovaCraftBlocks.basal_bricks, 0, 2);
		world.setBlock(i + 12, j + 0, k + 10, NovaCraftBlocks.basal_bricks, 0, 2);
		world.setBlock(i + 13, j + 0, k + 10, NovaCraftBlocks.basal_bricks, 0, 2);
		world.setBlock(i + 14, j + 0, k + 10, NovaCraftBlocks.basal_bricks, 0, 2);
		world.setBlock(i + 15, j + 0, k + 10, NovaCraftBlocks.basal_bricks, 0, 2);
		world.setBlock(i + 16, j + 0, k + 10, NovaCraftBlocks.basal_bricks, 0, 2);
		world.setBlock(i + 17, j + 0, k + 10, NovaCraftBlocks.cracked_basal_bricks, 0, 2);
		world.setBlock(i + 18, j + 0, k + 10, NovaCraftBlocks.basal_bricks, 0, 2);
		world.setBlock(i + 19, j + 0, k + 10, NovaCraftBlocks.cracked_basal_bricks, 0, 2);
		world.setBlock(i + 20, j + 0, k + 10, NovaCraftBlocks.cracked_basal_bricks, 0, 2);
		world.setBlock(i + 21, j + 0, k + 10, NovaCraftBlocks.basal_bricks, 0, 2);
		world.setBlock(i + 22, j + 0, k + 10, NovaCraftBlocks.basal_bricks, 0, 2);
		world.setBlock(i + 23, j + 0, k + 10, NovaCraftBlocks.basal_bricks, 0, 2);
		world.setBlock(i + 24, j + 0, k + 10, NovaCraftBlocks.basal_bricks, 0, 2);
		world.setBlock(i + 25, j + 0, k + 10, NovaCraftBlocks.basal_bricks, 0, 2);
		world.setBlock(i + 26, j + 0, k + 10, NovaCraftBlocks.basal_bricks, 0, 2);
		world.setBlock(i + 27, j + 0, k + 10, NovaCraftBlocks.cracked_basal_bricks, 0, 2);
		world.setBlock(i + 0, j + 0, k + 11, NovaCraftBlocks.basal_bricks, 0, 2);
		world.setBlock(i + 1, j + 0, k + 11, NovaCraftBlocks.basal_bricks, 0, 2);
		world.setBlock(i + 2, j + 0, k + 11, NovaCraftBlocks.basal_bricks, 0, 2);
		world.setBlock(i + 3, j + 0, k + 11, NovaCraftBlocks.cracked_basal_bricks, 0, 2);
		world.setBlock(i + 4, j + 0, k + 11, NovaCraftBlocks.basal_bricks, 0, 2);
		world.setBlock(i + 5, j + 0, k + 11, NovaCraftBlocks.cracked_basal_bricks, 0, 2);
		world.setBlock(i + 6, j + 0, k + 11, NovaCraftBlocks.basal_bricks, 0, 2);
		world.setBlock(i + 7, j + 0, k + 11, NovaCraftBlocks.basal_bricks, 0, 2);
		world.setBlock(i + 8, j + 0, k + 11, NovaCraftBlocks.basal_bricks, 0, 2);
		world.setBlock(i + 9, j + 0, k + 11, NovaCraftBlocks.basal_bricks, 0, 2);
		world.setBlock(i + 10, j + 0, k + 11, NovaCraftBlocks.cracked_basal_bricks, 0, 2);
		world.setBlock(i + 11, j + 0, k + 11, NovaCraftBlocks.basal_bricks, 0, 2);
		world.setBlock(i + 12, j + 0, k + 11, NovaCraftBlocks.basal_bricks, 0, 2);
		world.setBlock(i + 13, j + 0, k + 11, NovaCraftBlocks.cracked_basal_bricks, 0, 2);
		world.setBlock(i + 14, j + 0, k + 11, NovaCraftBlocks.cracked_basal_bricks, 0, 2);
		world.setBlock(i + 15, j + 0, k + 11, NovaCraftBlocks.cracked_basal_bricks, 0, 2);
		world.setBlock(i + 16, j + 0, k + 11, NovaCraftBlocks.cracked_basal_bricks, 0, 2);
		world.setBlock(i + 17, j + 0, k + 11, NovaCraftBlocks.cracked_basal_bricks, 0, 2);
		world.setBlock(i + 18, j + 0, k + 11, NovaCraftBlocks.basal_bricks, 0, 2);
		world.setBlock(i + 19, j + 0, k + 11, NovaCraftBlocks.cracked_basal_bricks, 0, 2);
		world.setBlock(i + 20, j + 0, k + 11, NovaCraftBlocks.cracked_basal_bricks, 0, 2);
		world.setBlock(i + 21, j + 0, k + 11, NovaCraftBlocks.basal_bricks, 0, 2);
		world.setBlock(i + 22, j + 0, k + 11, NovaCraftBlocks.cracked_basal_bricks, 0, 2);
		world.setBlock(i + 23, j + 0, k + 11, NovaCraftBlocks.cracked_basal_bricks, 0, 2);
		world.setBlock(i + 24, j + 0, k + 11, NovaCraftBlocks.basal_bricks, 0, 2);
		world.setBlock(i + 25, j + 0, k + 11, NovaCraftBlocks.basal_bricks, 0, 2);
		world.setBlock(i + 26, j + 0, k + 11, NovaCraftBlocks.basal_bricks, 0, 2);
		world.setBlock(i + 27, j + 0, k + 11, NovaCraftBlocks.basal_bricks, 0, 2);
		world.setBlock(i + 0, j + 0, k + 12, NovaCraftBlocks.basal_bricks, 0, 2);
		world.setBlock(i + 1, j + 0, k + 12, NovaCraftBlocks.cracked_basal_bricks, 0, 2);
		world.setBlock(i + 2, j + 0, k + 12, NovaCraftBlocks.basal_bricks, 0, 2);
		world.setBlock(i + 3, j + 0, k + 12, NovaCraftBlocks.cracked_basal_bricks, 0, 2);
		world.setBlock(i + 4, j + 0, k + 12, NovaCraftBlocks.cracked_basal_bricks, 0, 2);
		world.setBlock(i + 5, j + 0, k + 12, NovaCraftBlocks.basal_bricks, 0, 2);
		world.setBlock(i + 6, j + 0, k + 12, NovaCraftBlocks.cracked_basal_bricks, 0, 2);
		world.setBlock(i + 7, j + 0, k + 12, NovaCraftBlocks.cracked_basal_bricks, 0, 2);
		world.setBlock(i + 8, j + 0, k + 12, NovaCraftBlocks.basal_bricks, 0, 2);
		world.setBlock(i + 9, j + 0, k + 12, NovaCraftBlocks.basal_bricks, 0, 2);
		world.setBlock(i + 10, j + 0, k + 12, NovaCraftBlocks.cracked_basal_bricks, 0, 2);
		world.setBlock(i + 11, j + 0, k + 12, NovaCraftBlocks.cracked_basal_bricks, 0, 2);
		world.setBlock(i + 12, j + 0, k + 12, NovaCraftBlocks.cracked_basal_bricks, 0, 2);
		world.setBlock(i + 13, j + 0, k + 12, NovaCraftBlocks.basal_bricks, 0, 2);
		world.setBlock(i + 14, j + 0, k + 12, NovaCraftBlocks.basal_bricks, 0, 2);
		world.setBlock(i + 15, j + 0, k + 12, NovaCraftBlocks.basal_bricks, 0, 2);
		world.setBlock(i + 16, j + 0, k + 12, NovaCraftBlocks.basal_bricks, 0, 2);
		world.setBlock(i + 17, j + 0, k + 12, NovaCraftBlocks.cracked_basal_bricks, 0, 2);
		world.setBlock(i + 18, j + 0, k + 12, NovaCraftBlocks.cracked_basal_bricks, 0, 2);
		world.setBlock(i + 19, j + 0, k + 12, NovaCraftBlocks.basal_bricks, 0, 2);
		world.setBlock(i + 20, j + 0, k + 12, NovaCraftBlocks.cracked_basal_bricks, 0, 2);
		world.setBlock(i + 21, j + 0, k + 12, NovaCraftBlocks.cracked_basal_bricks, 0, 2);
		world.setBlock(i + 22, j + 0, k + 12, NovaCraftBlocks.cracked_basal_bricks, 0, 2);
		world.setBlock(i + 23, j + 0, k + 12, NovaCraftBlocks.basal_bricks, 0, 2);
		world.setBlock(i + 24, j + 0, k + 12, NovaCraftBlocks.cracked_basal_bricks, 0, 2);
		world.setBlock(i + 25, j + 0, k + 12, NovaCraftBlocks.cracked_basal_bricks, 0, 2);
		world.setBlock(i + 26, j + 0, k + 12, NovaCraftBlocks.basal_bricks, 0, 2);
		world.setBlock(i + 27, j + 0, k + 12, NovaCraftBlocks.basal_bricks, 0, 2);
		world.setBlock(i + 0, j + 0, k + 13, NovaCraftBlocks.basal_bricks, 0, 2);
		world.setBlock(i + 1, j + 0, k + 13, NovaCraftBlocks.basal_bricks, 0, 2);
		world.setBlock(i + 2, j + 0, k + 13, NovaCraftBlocks.basal_bricks, 0, 2);
		world.setBlock(i + 3, j + 0, k + 13, NovaCraftBlocks.cracked_basal_bricks, 0, 2);
		world.setBlock(i + 4, j + 0, k + 13, NovaCraftBlocks.basal_bricks, 0, 2);
		world.setBlock(i + 5, j + 0, k + 13, NovaCraftBlocks.basal_bricks, 0, 2);
		world.setBlock(i + 6, j + 0, k + 13, NovaCraftBlocks.cracked_basal_bricks, 0, 2);
		world.setBlock(i + 7, j + 0, k + 13, NovaCraftBlocks.basal_bricks, 0, 2);
		world.setBlock(i + 8, j + 0, k + 13, NovaCraftBlocks.basal_bricks, 0, 2);
		world.setBlock(i + 9, j + 0, k + 13, NovaCraftBlocks.basal_bricks, 0, 2);
		world.setBlock(i + 10, j + 0, k + 13, NovaCraftBlocks.basal_bricks, 0, 2);
		world.setBlock(i + 11, j + 0, k + 13, NovaCraftBlocks.cracked_basal_bricks, 0, 2);
		world.setBlock(i + 12, j + 0, k + 13, NovaCraftBlocks.basal_bricks, 0, 2);
		world.setBlock(i + 13, j + 0, k + 13, NovaCraftBlocks.basal_bricks, 0, 2);
		world.setBlock(i + 14, j + 0, k + 13, NovaCraftBlocks.basal_bricks, 0, 2);
		world.setBlock(i + 15, j + 0, k + 13, NovaCraftBlocks.cracked_basal_bricks, 0, 2);
		world.setBlock(i + 16, j + 0, k + 13, NovaCraftBlocks.basal_bricks, 0, 2);
		world.setBlock(i + 17, j + 0, k + 13, NovaCraftBlocks.basal_bricks, 0, 2);
		world.setBlock(i + 18, j + 0, k + 13, NovaCraftBlocks.cracked_basal_bricks, 0, 2);
		world.setBlock(i + 19, j + 0, k + 13, NovaCraftBlocks.cracked_basal_bricks, 0, 2);
		world.setBlock(i + 20, j + 0, k + 13, NovaCraftBlocks.basal_bricks, 0, 2);
		world.setBlock(i + 21, j + 0, k + 13, NovaCraftBlocks.cracked_basal_bricks, 0, 2);
		world.setBlock(i + 22, j + 0, k + 13, NovaCraftBlocks.cracked_basal_bricks, 0, 2);
		world.setBlock(i + 23, j + 0, k + 13, NovaCraftBlocks.cracked_basal_bricks, 0, 2);
		world.setBlock(i + 24, j + 0, k + 13, NovaCraftBlocks.basal_bricks, 0, 2);
		world.setBlock(i + 25, j + 0, k + 13, NovaCraftBlocks.cracked_basal_bricks, 0, 2);
		world.setBlock(i + 26, j + 0, k + 13, NovaCraftBlocks.cracked_basal_bricks, 0, 2);
		world.setBlock(i + 27, j + 0, k + 13, NovaCraftBlocks.basal_bricks, 0, 2);
		world.setBlock(i + 0, j + 0, k + 14, NovaCraftBlocks.basal_bricks, 0, 2);
		world.setBlock(i + 1, j + 0, k + 14, NovaCraftBlocks.cracked_basal_bricks, 0, 2);
		world.setBlock(i + 2, j + 0, k + 14, NovaCraftBlocks.basal_bricks, 0, 2);
		world.setBlock(i + 3, j + 0, k + 14, NovaCraftBlocks.basal_bricks, 0, 2);
		world.setBlock(i + 4, j + 0, k + 14, NovaCraftBlocks.cracked_basal_bricks, 0, 2);
		world.setBlock(i + 5, j + 0, k + 14, NovaCraftBlocks.cracked_basal_bricks, 0, 2);
		world.setBlock(i + 6, j + 0, k + 14, NovaCraftBlocks.basal_bricks, 0, 2);
		world.setBlock(i + 7, j + 0, k + 14, NovaCraftBlocks.basal_bricks, 0, 2);
		world.setBlock(i + 8, j + 0, k + 14, NovaCraftBlocks.cracked_basal_bricks, 0, 2);
		world.setBlock(i + 9, j + 0, k + 14, NovaCraftBlocks.cracked_basal_bricks, 0, 2);
		world.setBlock(i + 10, j + 0, k + 14, NovaCraftBlocks.basal_bricks, 0, 2);
		world.setBlock(i + 11, j + 0, k + 14, NovaCraftBlocks.basal_bricks, 0, 2);
		world.setBlock(i + 12, j + 0, k + 14, NovaCraftBlocks.basal_bricks, 0, 2);
		world.setBlock(i + 13, j + 0, k + 14, NovaCraftBlocks.cracked_basal_bricks, 0, 2);
		world.setBlock(i + 14, j + 0, k + 14, NovaCraftBlocks.basal_bricks, 0, 2);
		world.setBlock(i + 15, j + 0, k + 14, NovaCraftBlocks.basal_bricks, 0, 2);
		world.setBlock(i + 16, j + 0, k + 14, NovaCraftBlocks.basal_bricks, 0, 2);
		world.setBlock(i + 17, j + 0, k + 14, NovaCraftBlocks.cracked_basal_bricks, 0, 2);
		world.setBlock(i + 18, j + 0, k + 14, NovaCraftBlocks.basal_bricks, 0, 2);
		world.setBlock(i + 19, j + 0, k + 14, NovaCraftBlocks.basal_bricks, 0, 2);
		world.setBlock(i + 20, j + 0, k + 14, NovaCraftBlocks.basal_bricks, 0, 2);
		world.setBlock(i + 21, j + 0, k + 14, NovaCraftBlocks.basal_bricks, 0, 2);
		world.setBlock(i + 22, j + 0, k + 14, NovaCraftBlocks.basal_bricks, 0, 2);
		world.setBlock(i + 23, j + 0, k + 14, NovaCraftBlocks.cracked_basal_bricks, 0, 2);
		world.setBlock(i + 24, j + 0, k + 14, NovaCraftBlocks.cracked_basal_bricks, 0, 2);
		world.setBlock(i + 25, j + 0, k + 14, NovaCraftBlocks.cracked_basal_bricks, 0, 2);
		world.setBlock(i + 26, j + 0, k + 14, NovaCraftBlocks.basal_bricks, 0, 2);
		world.setBlock(i + 27, j + 0, k + 14, NovaCraftBlocks.basal_bricks, 0, 2);
		world.setBlock(i + 0, j + 0, k + 15, NovaCraftBlocks.basal_bricks, 0, 2);
		world.setBlock(i + 1, j + 0, k + 15, NovaCraftBlocks.basal_bricks, 0, 2);
		world.setBlock(i + 2, j + 0, k + 15, NovaCraftBlocks.basal_bricks, 0, 2);
		world.setBlock(i + 3, j + 0, k + 15, NovaCraftBlocks.cracked_basal_bricks, 0, 2);
		world.setBlock(i + 4, j + 0, k + 15, NovaCraftBlocks.cracked_basal_bricks, 0, 2);
		world.setBlock(i + 5, j + 0, k + 15, NovaCraftBlocks.basal_bricks, 0, 2);
		world.setBlock(i + 6, j + 0, k + 15, NovaCraftBlocks.cracked_basal_bricks, 0, 2);
		world.setBlock(i + 7, j + 0, k + 15, NovaCraftBlocks.cracked_basal_bricks, 0, 2);
		world.setBlock(i + 8, j + 0, k + 15, NovaCraftBlocks.basal_bricks, 0, 2);
		world.setBlock(i + 9, j + 0, k + 15, NovaCraftBlocks.cracked_basal_bricks, 0, 2);
		world.setBlock(i + 10, j + 0, k + 15, NovaCraftBlocks.basal_bricks, 0, 2);
		world.setBlock(i + 11, j + 0, k + 15, NovaCraftBlocks.cracked_basal_bricks, 0, 2);
		world.setBlock(i + 12, j + 0, k + 15, NovaCraftBlocks.basal_bricks, 0, 2);
		world.setBlock(i + 13, j + 0, k + 15, NovaCraftBlocks.basal_bricks, 0, 2);
		world.setBlock(i + 14, j + 0, k + 15, NovaCraftBlocks.cracked_basal_bricks, 0, 2);
		world.setBlock(i + 15, j + 0, k + 15, NovaCraftBlocks.cracked_basal_bricks, 0, 2);
		world.setBlock(i + 16, j + 0, k + 15, NovaCraftBlocks.cracked_basal_bricks, 0, 2);
		world.setBlock(i + 17, j + 0, k + 15, NovaCraftBlocks.cracked_basal_bricks, 0, 2);
		world.setBlock(i + 18, j + 0, k + 15, NovaCraftBlocks.basal_bricks, 0, 2);
		world.setBlock(i + 19, j + 0, k + 15, NovaCraftBlocks.basal_bricks, 0, 2);
		world.setBlock(i + 20, j + 0, k + 15, NovaCraftBlocks.basal_bricks, 0, 2);
		world.setBlock(i + 21, j + 0, k + 15, NovaCraftBlocks.basal_bricks, 0, 2);
		world.setBlock(i + 22, j + 0, k + 15, NovaCraftBlocks.basal_bricks, 0, 2);
		world.setBlock(i + 23, j + 0, k + 15, NovaCraftBlocks.basal_bricks, 0, 2);
		world.setBlock(i + 24, j + 0, k + 15, NovaCraftBlocks.basal_bricks, 0, 2);
		world.setBlock(i + 25, j + 0, k + 15, NovaCraftBlocks.basal_bricks, 0, 2);
		world.setBlock(i + 26, j + 0, k + 15, NovaCraftBlocks.basal_bricks, 0, 2);
		world.setBlock(i + 27, j + 0, k + 15, NovaCraftBlocks.basal_bricks, 0, 2);
		world.setBlock(i + 0, j + 0, k + 16, NovaCraftBlocks.cracked_basal_bricks, 0, 2);
		world.setBlock(i + 1, j + 0, k + 16, NovaCraftBlocks.basal_bricks, 0, 2);
		world.setBlock(i + 2, j + 0, k + 16, NovaCraftBlocks.basal_bricks, 0, 2);
		world.setBlock(i + 3, j + 0, k + 16, NovaCraftBlocks.basal_bricks, 0, 2);
		world.setBlock(i + 4, j + 0, k + 16, NovaCraftBlocks.cracked_basal_bricks, 0, 2);
		world.setBlock(i + 5, j + 0, k + 16, NovaCraftBlocks.basal_bricks, 0, 2);
		world.setBlock(i + 6, j + 0, k + 16, NovaCraftBlocks.cracked_basal_bricks, 0, 2);
		world.setBlock(i + 7, j + 0, k + 16, NovaCraftBlocks.basal_bricks, 0, 2);
		world.setBlock(i + 8, j + 0, k + 16, NovaCraftBlocks.basal_bricks, 0, 2);
		world.setBlock(i + 9, j + 0, k + 16, NovaCraftBlocks.basal_bricks, 0, 2);
		world.setBlock(i + 10, j + 0, k + 16, NovaCraftBlocks.cracked_basal_bricks, 0, 2);
		world.setBlock(i + 11, j + 0, k + 16, NovaCraftBlocks.basal_bricks, 0, 2);
		world.setBlock(i + 12, j + 0, k + 16, NovaCraftBlocks.basal_bricks, 0, 2);
		world.setBlock(i + 13, j + 0, k + 16, NovaCraftBlocks.basal_bricks, 0, 2);
		world.setBlock(i + 14, j + 0, k + 16, NovaCraftBlocks.basal_bricks, 0, 2);
		world.setBlock(i + 15, j + 0, k + 16, NovaCraftBlocks.basal_bricks, 0, 2);
		world.setBlock(i + 16, j + 0, k + 16, NovaCraftBlocks.basal_bricks, 0, 2);
		world.setBlock(i + 17, j + 0, k + 16, NovaCraftBlocks.cracked_basal_bricks, 0, 2);
		world.setBlock(i + 18, j + 0, k + 16, NovaCraftBlocks.basal_bricks, 0, 2);
		world.setBlock(i + 19, j + 0, k + 16, NovaCraftBlocks.cracked_basal_bricks, 0, 2);
		world.setBlock(i + 20, j + 0, k + 16, NovaCraftBlocks.cracked_basal_bricks, 0, 2);
		world.setBlock(i + 21, j + 0, k + 16, NovaCraftBlocks.basal_bricks, 0, 2);
		world.setBlock(i + 22, j + 0, k + 16, NovaCraftBlocks.basal_bricks, 0, 2);
		world.setBlock(i + 23, j + 0, k + 16, NovaCraftBlocks.cracked_basal_bricks, 0, 2);
		world.setBlock(i + 24, j + 0, k + 16, NovaCraftBlocks.basal_bricks, 0, 2);
		world.setBlock(i + 25, j + 0, k + 16, NovaCraftBlocks.basal_bricks, 0, 2);
		world.setBlock(i + 26, j + 0, k + 16, NovaCraftBlocks.basal_bricks, 0, 2);
		world.setBlock(i + 27, j + 0, k + 16, NovaCraftBlocks.basal_bricks, 0, 2);
		world.setBlock(i + 0, j + 0, k + 17, NovaCraftBlocks.basal_bricks, 0, 2);
		world.setBlock(i + 1, j + 0, k + 17, NovaCraftBlocks.basal_bricks, 0, 2);
		world.setBlock(i + 2, j + 0, k + 17, NovaCraftBlocks.basal_bricks, 0, 2);
		world.setBlock(i + 3, j + 0, k + 17, NovaCraftBlocks.basal_bricks, 0, 2);
		world.setBlock(i + 4, j + 0, k + 17, NovaCraftBlocks.cracked_basal_bricks, 0, 2);
		world.setBlock(i + 5, j + 0, k + 17, NovaCraftBlocks.basal_bricks, 0, 2);
		world.setBlock(i + 6, j + 0, k + 17, NovaCraftBlocks.basal_bricks, 0, 2);
		world.setBlock(i + 7, j + 0, k + 17, NovaCraftBlocks.basal_bricks, 0, 2);
		world.setBlock(i + 8, j + 0, k + 17, NovaCraftBlocks.cracked_basal_bricks, 0, 2);
		world.setBlock(i + 9, j + 0, k + 17, NovaCraftBlocks.basal_bricks, 0, 2);
		world.setBlock(i + 10, j + 0, k + 17, NovaCraftBlocks.basal_bricks, 0, 2);
		world.setBlock(i + 11, j + 0, k + 17, NovaCraftBlocks.basal_bricks, 0, 2);
		world.setBlock(i + 12, j + 0, k + 17, NovaCraftBlocks.cracked_basal_bricks, 0, 2);
		world.setBlock(i + 13, j + 0, k + 17, NovaCraftBlocks.cracked_basal_bricks, 0, 2);
		world.setBlock(i + 14, j + 0, k + 17, NovaCraftBlocks.basal_bricks, 0, 2);
		world.setBlock(i + 15, j + 0, k + 17, NovaCraftBlocks.basal_bricks, 0, 2);
		world.setBlock(i + 16, j + 0, k + 17, NovaCraftBlocks.basal_bricks, 0, 2);
		world.setBlock(i + 17, j + 0, k + 17, NovaCraftBlocks.basal_bricks, 0, 2);
		world.setBlock(i + 18, j + 0, k + 17, NovaCraftBlocks.basal_bricks, 0, 2);
		world.setBlock(i + 19, j + 0, k + 17, NovaCraftBlocks.basal_bricks, 0, 2);
		world.setBlock(i + 20, j + 0, k + 17, NovaCraftBlocks.cracked_basal_bricks, 0, 2);
		world.setBlock(i + 21, j + 0, k + 17, NovaCraftBlocks.basal_bricks, 0, 2);
		world.setBlock(i + 22, j + 0, k + 17, NovaCraftBlocks.basal_bricks, 0, 2);
		world.setBlock(i + 23, j + 0, k + 17, NovaCraftBlocks.basal_bricks, 0, 2);
		world.setBlock(i + 24, j + 0, k + 17, NovaCraftBlocks.basal_bricks, 0, 2);
		world.setBlock(i + 25, j + 0, k + 17, NovaCraftBlocks.basal_bricks, 0, 2);
		world.setBlock(i + 26, j + 0, k + 17, NovaCraftBlocks.cracked_basal_bricks, 0, 2);
		world.setBlock(i + 27, j + 0, k + 17, NovaCraftBlocks.basal_bricks, 0, 2);
		world.setBlock(i + 0, j + 0, k + 18, NovaCraftBlocks.basal_bricks, 0, 2);
		world.setBlock(i + 1, j + 0, k + 18, NovaCraftBlocks.basal_bricks, 0, 2);
		world.setBlock(i + 2, j + 0, k + 18, NovaCraftBlocks.cracked_basal_bricks, 0, 2);
		world.setBlock(i + 3, j + 0, k + 18, NovaCraftBlocks.basal_bricks, 0, 2);
		world.setBlock(i + 4, j + 0, k + 18, NovaCraftBlocks.basal_bricks, 0, 2);
		world.setBlock(i + 5, j + 0, k + 18, NovaCraftBlocks.basal_bricks, 0, 2);
		world.setBlock(i + 6, j + 0, k + 18, NovaCraftBlocks.cracked_basal_bricks, 0, 2);
		world.setBlock(i + 7, j + 0, k + 18, NovaCraftBlocks.cracked_basal_bricks, 0, 2);
		world.setBlock(i + 8, j + 0, k + 18, NovaCraftBlocks.basal_bricks, 0, 2);
		world.setBlock(i + 9, j + 0, k + 18, NovaCraftBlocks.basal_bricks, 0, 2);
		world.setBlock(i + 10, j + 0, k + 18, NovaCraftBlocks.cracked_basal_bricks, 0, 2);
		world.setBlock(i + 11, j + 0, k + 18, NovaCraftBlocks.cracked_basal_bricks, 0, 2);
		world.setBlock(i + 12, j + 0, k + 18, NovaCraftBlocks.cracked_basal_bricks, 0, 2);
		world.setBlock(i + 13, j + 0, k + 18, NovaCraftBlocks.basal_bricks, 0, 2);
		world.setBlock(i + 14, j + 0, k + 18, NovaCraftBlocks.cracked_basal_bricks, 0, 2);
		world.setBlock(i + 15, j + 0, k + 18, NovaCraftBlocks.basal_bricks, 0, 2);
		world.setBlock(i + 16, j + 0, k + 18, NovaCraftBlocks.basal_bricks, 0, 2);
		world.setBlock(i + 17, j + 0, k + 18, NovaCraftBlocks.cracked_basal_bricks, 0, 2);
		world.setBlock(i + 18, j + 0, k + 18, NovaCraftBlocks.basal_bricks, 0, 2);
		world.setBlock(i + 19, j + 0, k + 18, NovaCraftBlocks.basal_bricks, 0, 2);
		world.setBlock(i + 20, j + 0, k + 18, NovaCraftBlocks.basal_bricks, 0, 2);
		world.setBlock(i + 21, j + 0, k + 18, NovaCraftBlocks.cracked_basal_bricks, 0, 2);
		world.setBlock(i + 22, j + 0, k + 18, NovaCraftBlocks.basal_bricks, 0, 2);
		world.setBlock(i + 23, j + 0, k + 18, NovaCraftBlocks.cracked_basal_bricks, 0, 2);
		world.setBlock(i + 24, j + 0, k + 18, NovaCraftBlocks.basal_bricks, 0, 2);
		world.setBlock(i + 25, j + 0, k + 18, NovaCraftBlocks.cracked_basal_bricks, 0, 2);
		world.setBlock(i + 26, j + 0, k + 18, NovaCraftBlocks.cracked_basal_bricks, 0, 2);
		world.setBlock(i + 27, j + 0, k + 18, NovaCraftBlocks.basal_bricks, 0, 2);
		world.setBlock(i + 0, j + 1, k + 0, NovaCraftBlocks.cracked_basal_bricks, 0, 2);
		world.setBlock(i + 1, j + 1, k + 0, NovaCraftBlocks.cracked_basal_bricks, 0, 2);
		world.setBlock(i + 2, j + 1, k + 0, NovaCraftBlocks.basal_bricks, 0, 2);
		world.setBlock(i + 3, j + 1, k + 0, NovaCraftBlocks.cracked_basal_bricks, 0, 2);
		world.setBlock(i + 4, j + 1, k + 0, NovaCraftBlocks.basal_bricks, 0, 2);
		world.setBlock(i + 5, j + 1, k + 0, NovaCraftBlocks.basal_bricks, 0, 2);
		world.setBlock(i + 6, j + 1, k + 0, NovaCraftBlocks.cracked_basal_bricks, 0, 2);
		world.setBlock(i + 7, j + 1, k + 0, NovaCraftBlocks.basal_bricks, 0, 2);
		world.setBlock(i + 8, j + 1, k + 0, NovaCraftBlocks.basal_bricks, 0, 2);
		world.setBlock(i + 9, j + 1, k + 0, NovaCraftBlocks.basal_bricks, 0, 2);
		world.setBlock(i + 10, j + 1, k + 0, NovaCraftBlocks.basal_bricks, 0, 2);
		world.setBlock(i + 11, j + 1, k + 0, NovaCraftBlocks.basal_bricks, 0, 2);
		world.setBlock(i + 12, j + 1, k + 0, NovaCraftBlocks.cracked_basal_bricks, 0, 2);
		world.setBlock(i + 13, j + 1, k + 0, NovaCraftBlocks.basal_bricks, 0, 2);
		world.setBlock(i + 14, j + 1, k + 0, NovaCraftBlocks.cracked_basal_bricks, 0, 2);
		world.setBlock(i + 15, j + 1, k + 0, NovaCraftBlocks.cracked_basal_bricks, 0, 2);
		world.setBlock(i + 16, j + 1, k + 0, NovaCraftBlocks.basal_bricks, 0, 2);
		world.setBlock(i + 17, j + 1, k + 0, NovaCraftBlocks.basal_bricks, 0, 2);
		world.setBlock(i + 18, j + 1, k + 0, NovaCraftBlocks.cracked_basal_bricks, 0, 2);
		world.setBlock(i + 19, j + 1, k + 0, NovaCraftBlocks.basal_bricks, 0, 2);
		world.setBlock(i + 20, j + 1, k + 0, NovaCraftBlocks.basal_bricks, 0, 2);
		world.setBlock(i + 21, j + 1, k + 0, NovaCraftBlocks.cracked_basal_bricks, 0, 2);
		world.setBlock(i + 22, j + 1, k + 0, NovaCraftBlocks.basal_bricks, 0, 2);
		world.setBlock(i + 23, j + 1, k + 0, NovaCraftBlocks.basal_bricks, 0, 2);
		world.setBlock(i + 24, j + 1, k + 0, NovaCraftBlocks.basal_bricks, 0, 2);
		world.setBlock(i + 25, j + 1, k + 0, NovaCraftBlocks.basal_bricks, 0, 2);
		world.setBlock(i + 26, j + 1, k + 0, NovaCraftBlocks.basal_bricks, 0, 2);
		world.setBlock(i + 27, j + 1, k + 0, NovaCraftBlocks.basal_bricks, 0, 2);
		world.setBlock(i + 0, j + 1, k + 1, NovaCraftBlocks.basal_bricks, 0, 2);
		world.setBlock(i + 1, j + 1, k + 1, NovaCraftBlocks.basal_bricks, 0, 2);
		world.setBlock(i + 2, j + 1, k + 1, NovaCraftBlocks.cracked_basal_bricks, 0, 2);
		world.setBlock(i + 3, j + 1, k + 1, NovaCraftBlocks.basal_bricks, 0, 2);
		world.setBlock(i + 4, j + 1, k + 1, NovaCraftBlocks.basal_bricks, 0, 2);
		world.setBlock(i + 5, j + 1, k + 1, NovaCraftBlocks.cracked_basal_bricks, 0, 2);
		world.setBlock(i + 6, j + 1, k + 1, NovaCraftBlocks.cracked_basal_bricks, 0, 2);
		world.setBlock(i + 7, j + 1, k + 1, NovaCraftBlocks.cracked_basal_bricks, 0, 2);
		world.setBlock(i + 8, j + 1, k + 1, NovaCraftBlocks.cracked_basal_bricks, 0, 2);
		world.setBlock(i + 9, j + 1, k + 1, NovaCraftBlocks.cracked_basal_bricks, 0, 2);
		world.setBlock(i + 10, j + 1, k + 1, NovaCraftBlocks.basal_bricks, 0, 2);
		world.setBlock(i + 11, j + 1, k + 1, NovaCraftBlocks.cracked_basal_bricks, 0, 2);
		world.setBlock(i + 12, j + 1, k + 1, NovaCraftBlocks.basal_bricks, 0, 2);
		world.setBlock(i + 13, j + 1, k + 1, NovaCraftBlocks.basal_bricks, 0, 2);
		world.setBlock(i + 14, j + 1, k + 1, NovaCraftBlocks.basal_bricks, 0, 2);
		world.setBlock(i + 15, j + 1, k + 1, NovaCraftBlocks.basal_bricks, 0, 2);
		world.setBlock(i + 16, j + 1, k + 1, NovaCraftBlocks.basal_bricks, 0, 2);
		world.setBlock(i + 17, j + 1, k + 1, NovaCraftBlocks.basal_bricks, 0, 2);
		world.setBlock(i + 18, j + 1, k + 1, NovaCraftBlocks.basal_bricks, 0, 2);
		world.setBlock(i + 19, j + 1, k + 1, NovaCraftBlocks.cracked_basal_bricks, 0, 2);
		world.setBlock(i + 20, j + 1, k + 1, NovaCraftBlocks.cracked_basal_bricks, 0, 2);
		world.setBlock(i + 21, j + 1, k + 1, NovaCraftBlocks.basal_bricks, 0, 2);
		world.setBlock(i + 22, j + 1, k + 1, NovaCraftBlocks.cracked_basal_bricks, 0, 2);
		world.setBlock(i + 23, j + 1, k + 1, NovaCraftBlocks.cracked_basal_bricks, 0, 2);
		world.setBlock(i + 24, j + 1, k + 1, NovaCraftBlocks.basal_bricks, 0, 2);
		world.setBlock(i + 25, j + 1, k + 1, NovaCraftBlocks.cracked_basal_bricks, 0, 2);
		world.setBlock(i + 26, j + 1, k + 1, NovaCraftBlocks.basal_bricks, 0, 2);
		world.setBlock(i + 27, j + 1, k + 1, NovaCraftBlocks.basal_bricks, 0, 2);
		world.setBlock(i + 0, j + 1, k + 2, NovaCraftBlocks.basal_bricks, 0, 2);
		world.setBlock(i + 1, j + 1, k + 2, NovaCraftBlocks.cracked_basal_bricks, 0, 2);
		world.setBlock(i + 2, j + 1, k + 2, NovaCraftBlocks.cracked_basal_bricks, 0, 2);
		world.setBlock(i + 3, j + 1, k + 2, NovaCraftBlocks.basal_bricks, 0, 2);
		world.setBlock(i + 4, j + 1, k + 2, NovaCraftBlocks.cracked_basal_bricks, 0, 2);
		world.setBlock(i + 5, j + 1, k + 2, NovaCraftBlocks.basal_bricks, 0, 2);
		world.setBlock(i + 6, j + 1, k + 2, NovaCraftBlocks.cracked_basal_bricks, 0, 2);
		world.setBlock(i + 7, j + 1, k + 2, NovaCraftBlocks.cracked_basal_bricks, 0, 2);
		world.setBlock(i + 8, j + 1, k + 2, NovaCraftBlocks.basal_bricks, 0, 2);
		world.setBlock(i + 9, j + 1, k + 2, NovaCraftBlocks.cracked_basal_bricks, 0, 2);
		world.setBlock(i + 10, j + 1, k + 2, NovaCraftBlocks.basal_bricks, 0, 2);
		world.setBlock(i + 11, j + 1, k + 2, NovaCraftBlocks.basal_bricks, 0, 2);
		world.setBlock(i + 12, j + 1, k + 2, NovaCraftBlocks.cracked_basal_bricks, 0, 2);
		world.setBlock(i + 13, j + 1, k + 2, NovaCraftBlocks.basal_bricks, 0, 2);
		world.setBlock(i + 14, j + 1, k + 2, NovaCraftBlocks.cracked_basal_bricks, 0, 2);
		world.setBlock(i + 15, j + 1, k + 2, NovaCraftBlocks.cracked_basal_bricks, 0, 2);
		world.setBlock(i + 16, j + 1, k + 2, NovaCraftBlocks.basal_bricks, 0, 2);
		world.setBlock(i + 17, j + 1, k + 2, NovaCraftBlocks.basal_bricks, 0, 2);
		world.setBlock(i + 18, j + 1, k + 2, NovaCraftBlocks.basal_bricks, 0, 2);
		world.setBlock(i + 19, j + 1, k + 2, NovaCraftBlocks.cracked_basal_bricks, 0, 2);
		world.setBlock(i + 20, j + 1, k + 2, NovaCraftBlocks.basal_bricks, 0, 2);
		world.setBlock(i + 21, j + 1, k + 2, NovaCraftBlocks.basal_bricks, 0, 2);
		world.setBlock(i + 22, j + 1, k + 2, NovaCraftBlocks.basal_bricks, 0, 2);
		world.setBlock(i + 23, j + 1, k + 2, NovaCraftBlocks.basal_bricks, 0, 2);
		world.setBlock(i + 24, j + 1, k + 2, NovaCraftBlocks.basal_bricks, 0, 2);
		world.setBlock(i + 25, j + 1, k + 2, NovaCraftBlocks.basal_bricks, 0, 2);
		world.setBlock(i + 26, j + 1, k + 2, NovaCraftBlocks.basal_bricks, 0, 2);
		world.setBlock(i + 27, j + 1, k + 2, NovaCraftBlocks.basal_bricks, 0, 2);
		world.setBlock(i + 0, j + 1, k + 3, NovaCraftBlocks.basal_bricks, 0, 2);
		world.setBlock(i + 1, j + 1, k + 3, NovaCraftBlocks.cracked_basal_bricks, 0, 2);
		world.setBlock(i + 2, j + 1, k + 3, NovaCraftBlocks.basal_bricks, 0, 2);
		world.setBlock(i + 3, j + 1, k + 3, NovaCraftBlocks.basal_bricks, 0, 2);
		world.setBlock(i + 4, j + 1, k + 3, NovaCraftBlocks.basal_bricks, 0, 2);
		world.setBlock(i + 5, j + 1, k + 3, NovaCraftBlocks.basal_bricks, 0, 2);
		world.setBlock(i + 6, j + 1, k + 3, NovaCraftBlocks.basal_bricks, 0, 2);
		world.setBlock(i + 7, j + 1, k + 3, NovaCraftBlocks.cracked_basal_bricks, 0, 2);
		world.setBlock(i + 8, j + 1, k + 3, NovaCraftBlocks.cracked_basal_bricks, 0, 2);
		world.setBlock(i + 9, j + 1, k + 3, NovaCraftBlocks.basal_bricks, 0, 2);
		world.setBlock(i + 10, j + 1, k + 3, NovaCraftBlocks.basal_bricks, 0, 2);
		world.setBlock(i + 11, j + 1, k + 3, NovaCraftBlocks.basal_bricks, 0, 2);
		world.setBlock(i + 12, j + 1, k + 3, NovaCraftBlocks.cracked_basal_bricks, 0, 2);
		world.setBlock(i + 13, j + 1, k + 3, NovaCraftBlocks.basal_bricks, 0, 2);
		world.setBlock(i + 14, j + 1, k + 3, NovaCraftBlocks.cracked_basal_bricks, 0, 2);
		world.setBlock(i + 15, j + 1, k + 3, NovaCraftBlocks.cracked_basal_bricks, 0, 2);
		world.setBlock(i + 16, j + 1, k + 3, NovaCraftBlocks.basal_bricks, 0, 2);
		world.setBlock(i + 17, j + 1, k + 3, NovaCraftBlocks.cracked_basal_bricks, 0, 2);
		world.setBlock(i + 18, j + 1, k + 3, NovaCraftBlocks.basal_bricks, 0, 2);
		world.setBlock(i + 19, j + 1, k + 3, NovaCraftBlocks.basal_bricks, 0, 2);
		world.setBlock(i + 20, j + 1, k + 3, NovaCraftBlocks.cracked_basal_bricks, 0, 2);
		world.setBlock(i + 21, j + 1, k + 3, NovaCraftBlocks.basal_bricks, 0, 2);
		world.setBlock(i + 22, j + 1, k + 3, NovaCraftBlocks.basal_bricks, 0, 2);
		world.setBlock(i + 23, j + 1, k + 3, NovaCraftBlocks.basal_bricks, 0, 2);
		world.setBlock(i + 24, j + 1, k + 3, NovaCraftBlocks.basal_bricks, 0, 2);
		world.setBlock(i + 25, j + 1, k + 3, NovaCraftBlocks.cracked_basal_bricks, 0, 2);
		world.setBlock(i + 26, j + 1, k + 3, NovaCraftBlocks.basal_bricks, 0, 2);
		world.setBlock(i + 27, j + 1, k + 3, NovaCraftBlocks.basal_bricks, 0, 2);
		world.setBlock(i + 0, j + 1, k + 4, NovaCraftBlocks.basal_bricks, 0, 2);
		world.setBlock(i + 1, j + 1, k + 4, NovaCraftBlocks.basal_bricks, 0, 2);
		world.setBlock(i + 2, j + 1, k + 4, NovaCraftBlocks.basal_bricks, 0, 2);
		world.setBlock(i + 3, j + 1, k + 4, NovaCraftBlocks.cracked_basal_bricks, 0, 2);
		world.setBlock(i + 4, j + 1, k + 4, NovaCraftBlocks.basal_bricks, 0, 2);
		world.setBlock(i + 5, j + 1, k + 4, NovaCraftBlocks.basal_bricks, 0, 2);
		world.setBlock(i + 6, j + 1, k + 4, NovaCraftBlocks.basal_bricks, 0, 2);
		world.setBlock(i + 7, j + 1, k + 4, NovaCraftBlocks.basal_bricks, 0, 2);
		world.setBlock(i + 8, j + 1, k + 4, NovaCraftBlocks.basal_bricks, 0, 2);
		world.setBlock(i + 9, j + 1, k + 4, NovaCraftBlocks.basal_bricks, 0, 2);
		world.setBlock(i + 10, j + 1, k + 4, NovaCraftBlocks.basal_bricks, 0, 2);
		world.setBlock(i + 11, j + 1, k + 4, NovaCraftBlocks.cracked_basal_bricks, 0, 2);
		world.setBlock(i + 12, j + 1, k + 4, NovaCraftBlocks.basal_bricks, 0, 2);
		world.setBlock(i + 13, j + 1, k + 4, NovaCraftBlocks.basal_bricks, 0, 2);
		world.setBlock(i + 14, j + 1, k + 4, NovaCraftBlocks.cracked_basal_bricks, 0, 2);
		world.setBlock(i + 15, j + 1, k + 4, NovaCraftBlocks.basal_bricks, 0, 2);
		world.setBlock(i + 16, j + 1, k + 4, NovaCraftBlocks.basal_bricks, 0, 2);
		world.setBlock(i + 17, j + 1, k + 4, NovaCraftBlocks.basal_bricks, 0, 2);
		world.setBlock(i + 18, j + 1, k + 4, NovaCraftBlocks.cracked_basal_bricks, 0, 2);
		world.setBlock(i + 19, j + 1, k + 4, NovaCraftBlocks.cracked_basal_bricks, 0, 2);
		world.setBlock(i + 20, j + 1, k + 4, NovaCraftBlocks.basal_bricks, 0, 2);
		world.setBlock(i + 21, j + 1, k + 4, NovaCraftBlocks.cracked_basal_bricks, 0, 2);
		world.setBlock(i + 22, j + 1, k + 4, NovaCraftBlocks.basal_bricks, 0, 2);
		world.setBlock(i + 23, j + 1, k + 4, NovaCraftBlocks.cracked_basal_bricks, 0, 2);
		world.setBlock(i + 24, j + 1, k + 4, NovaCraftBlocks.basal_bricks, 0, 2);
		world.setBlock(i + 25, j + 1, k + 4, NovaCraftBlocks.basal_bricks, 0, 2);
		world.setBlock(i + 26, j + 1, k + 4, NovaCraftBlocks.basal_bricks, 0, 2);
		world.setBlock(i + 27, j + 1, k + 4, NovaCraftBlocks.cracked_basal_bricks, 0, 2);
		world.setBlock(i + 0, j + 1, k + 5, NovaCraftBlocks.basal_bricks, 0, 2);
		world.setBlock(i + 1, j + 1, k + 5, NovaCraftBlocks.basal_bricks, 0, 2);
		world.setBlock(i + 2, j + 1, k + 5, NovaCraftBlocks.cracked_basal_bricks, 0, 2);
		world.setBlock(i + 3, j + 1, k + 5, NovaCraftBlocks.basal_bricks, 0, 2);
		world.setBlock(i + 4, j + 1, k + 5, NovaCraftBlocks.cracked_basal_bricks, 0, 2);
		world.setBlock(i + 5, j + 1, k + 5, NovaCraftBlocks.basal_bricks, 0, 2);
		world.setBlock(i + 6, j + 1, k + 5, NovaCraftBlocks.basal_bricks, 0, 2);
		world.setBlock(i + 7, j + 1, k + 5, NovaCraftBlocks.basal_bricks, 0, 2);
		world.setBlock(i + 8, j + 1, k + 5, NovaCraftBlocks.basal_bricks, 0, 2);
		world.setBlock(i + 9, j + 1, k + 5, NovaCraftBlocks.cracked_basal_bricks, 0, 2);
		world.setBlock(i + 10, j + 1, k + 5, NovaCraftBlocks.basal_bricks, 0, 2);
		world.setBlock(i + 11, j + 1, k + 5, NovaCraftBlocks.basal_bricks, 0, 2);
		world.setBlock(i + 12, j + 1, k + 5, NovaCraftBlocks.cracked_basal_bricks, 0, 2);
		world.setBlock(i + 13, j + 1, k + 5, NovaCraftBlocks.basal_bricks, 0, 2);
		world.setBlock(i + 14, j + 1, k + 5, NovaCraftBlocks.basal_bricks, 0, 2);
		world.setBlock(i + 15, j + 1, k + 5, NovaCraftBlocks.basal_bricks, 0, 2);
		world.setBlock(i + 16, j + 1, k + 5, NovaCraftBlocks.basal_bricks, 0, 2);
		world.setBlock(i + 17, j + 1, k + 5, NovaCraftBlocks.basal_bricks, 0, 2);
		world.setBlock(i + 18, j + 1, k + 5, NovaCraftBlocks.basal_bricks, 0, 2);
		world.setBlock(i + 19, j + 1, k + 5, NovaCraftBlocks.basal_bricks, 0, 2);
		world.setBlock(i + 20, j + 1, k + 5, NovaCraftBlocks.cracked_basal_bricks, 0, 2);
		world.setBlock(i + 21, j + 1, k + 5, NovaCraftBlocks.basal_bricks, 0, 2);
		world.setBlock(i + 22, j + 1, k + 5, NovaCraftBlocks.basal_bricks, 0, 2);
		world.setBlock(i + 23, j + 1, k + 5, NovaCraftBlocks.cracked_basal_bricks, 0, 2);
		world.setBlock(i + 24, j + 1, k + 5, NovaCraftBlocks.basal_bricks, 0, 2);
		world.setBlock(i + 25, j + 1, k + 5, NovaCraftBlocks.basal_bricks, 0, 2);
		world.setBlock(i + 26, j + 1, k + 5, NovaCraftBlocks.basal_bricks, 0, 2);
		world.setBlock(i + 27, j + 1, k + 5, NovaCraftBlocks.basal_bricks, 0, 2);
		world.setBlock(i + 0, j + 1, k + 6, NovaCraftBlocks.basal_bricks, 0, 2);
		world.setBlock(i + 1, j + 1, k + 6, NovaCraftBlocks.cracked_basal_bricks, 0, 2);
		world.setBlock(i + 2, j + 1, k + 6, NovaCraftBlocks.basal_bricks, 0, 2);
		world.setBlock(i + 3, j + 1, k + 6, NovaCraftBlocks.basal_bricks, 0, 2);
		world.setBlock(i + 4, j + 1, k + 6, NovaCraftBlocks.basal_bricks, 0, 2);
		world.setBlock(i + 5, j + 1, k + 6, NovaCraftBlocks.basal_bricks, 0, 2);
		world.setBlock(i + 6, j + 1, k + 6, NovaCraftBlocks.basal_bricks, 0, 2);
		world.setBlock(i + 7, j + 1, k + 6, NovaCraftBlocks.cracked_basal_bricks, 0, 2);
		world.setBlock(i + 8, j + 1, k + 6, NovaCraftBlocks.basal_bricks, 0, 2);
		world.setBlock(i + 9, j + 1, k + 6, NovaCraftBlocks.basal_bricks, 0, 2);
		world.setBlock(i + 10, j + 1, k + 6, NovaCraftBlocks.basal_bricks, 0, 2);
		world.setBlock(i + 11, j + 1, k + 6, NovaCraftBlocks.cracked_basal_bricks, 0, 2);
		world.setBlock(i + 12, j + 1, k + 6, NovaCraftBlocks.basal_bricks, 0, 2);
		world.setBlock(i + 13, j + 1, k + 6, NovaCraftBlocks.cracked_basal_bricks, 0, 2);
		world.setBlock(i + 14, j + 1, k + 6, NovaCraftBlocks.cracked_basal_bricks, 0, 2);
		world.setBlock(i + 15, j + 1, k + 6, NovaCraftBlocks.basal_bricks, 0, 2);
		world.setBlock(i + 16, j + 1, k + 6, NovaCraftBlocks.basal_bricks, 0, 2);
		world.setBlock(i + 17, j + 1, k + 6, NovaCraftBlocks.basal_bricks, 0, 2);
		world.setBlock(i + 18, j + 1, k + 6, NovaCraftBlocks.basal_bricks, 0, 2);
		world.setBlock(i + 19, j + 1, k + 6, NovaCraftBlocks.cracked_basal_bricks, 0, 2);
		world.setBlock(i + 20, j + 1, k + 6, NovaCraftBlocks.cracked_basal_bricks, 0, 2);
		world.setBlock(i + 21, j + 1, k + 6, NovaCraftBlocks.basal_bricks, 0, 2);
		world.setBlock(i + 22, j + 1, k + 6, NovaCraftBlocks.cracked_basal_bricks, 0, 2);
		world.setBlock(i + 23, j + 1, k + 6, NovaCraftBlocks.cracked_basal_bricks, 0, 2);
		world.setBlock(i + 24, j + 1, k + 6, NovaCraftBlocks.basal_bricks, 0, 2);
		world.setBlock(i + 25, j + 1, k + 6, NovaCraftBlocks.basal_bricks, 0, 2);
		world.setBlock(i + 26, j + 1, k + 6, NovaCraftBlocks.basal_bricks, 0, 2);
		world.setBlock(i + 27, j + 1, k + 6, NovaCraftBlocks.cracked_basal_bricks, 0, 2);
		world.setBlock(i + 0, j + 1, k + 7, NovaCraftBlocks.cracked_basal_bricks, 0, 2);
		world.setBlock(i + 1, j + 1, k + 7, NovaCraftBlocks.basal_bricks, 0, 2);
		world.setBlock(i + 2, j + 1, k + 7, NovaCraftBlocks.basal_bricks, 0, 2);
		world.setBlock(i + 3, j + 1, k + 7, NovaCraftBlocks.cracked_basal_bricks, 0, 2);
		world.setBlock(i + 4, j + 1, k + 7, NovaCraftBlocks.cracked_basal_bricks, 0, 2);
		world.setBlock(i + 5, j + 1, k + 7, NovaCraftBlocks.basal_bricks, 0, 2);
		world.setBlock(i + 6, j + 1, k + 7, NovaCraftBlocks.basal_bricks, 0, 2);
		world.setBlock(i + 7, j + 1, k + 7, NovaCraftBlocks.cracked_basal_bricks, 0, 2);
		world.setBlock(i + 8, j + 1, k + 7, NovaCraftBlocks.cracked_basal_bricks, 0, 2);
		world.setBlock(i + 9, j + 1, k + 7, NovaCraftBlocks.cracked_basal_bricks, 0, 2);
		world.setBlock(i + 10, j + 1, k + 7, NovaCraftBlocks.basal_bricks, 0, 2);
		world.setBlock(i + 11, j + 1, k + 7, NovaCraftBlocks.basal_bricks, 0, 2);
		world.setBlock(i + 12, j + 1, k + 7, NovaCraftBlocks.cracked_basal_bricks, 0, 2);
		world.setBlock(i + 13, j + 1, k + 7, NovaCraftBlocks.basal_bricks, 0, 2);
		world.setBlock(i + 14, j + 1, k + 7, NovaCraftBlocks.basal_bricks, 0, 2);
		world.setBlock(i + 15, j + 1, k + 7, NovaCraftBlocks.basal_bricks, 0, 2);
		world.setBlock(i + 16, j + 1, k + 7, NovaCraftBlocks.basal_bricks, 0, 2);
		world.setBlock(i + 17, j + 1, k + 7, NovaCraftBlocks.cracked_basal_bricks, 0, 2);
		world.setBlock(i + 18, j + 1, k + 7, NovaCraftBlocks.basal_bricks, 0, 2);
		world.setBlock(i + 19, j + 1, k + 7, NovaCraftBlocks.basal_bricks, 0, 2);
		world.setBlock(i + 20, j + 1, k + 7, NovaCraftBlocks.basal_bricks, 0, 2);
		world.setBlock(i + 21, j + 1, k + 7, NovaCraftBlocks.cracked_basal_bricks, 0, 2);
		world.setBlock(i + 22, j + 1, k + 7, NovaCraftBlocks.basal_bricks, 0, 2);
		world.setBlock(i + 23, j + 1, k + 7, NovaCraftBlocks.basal_bricks, 0, 2);
		world.setBlock(i + 24, j + 1, k + 7, NovaCraftBlocks.cracked_basal_bricks, 0, 2);
		world.setBlock(i + 25, j + 1, k + 7, NovaCraftBlocks.basal_bricks, 0, 2);
		world.setBlock(i + 26, j + 1, k + 7, NovaCraftBlocks.basal_bricks, 0, 2);
		world.setBlock(i + 27, j + 1, k + 7, NovaCraftBlocks.basal_bricks, 0, 2);
		world.setBlock(i + 0, j + 1, k + 8, NovaCraftBlocks.basal_bricks, 0, 2);
		world.setBlock(i + 1, j + 1, k + 8, NovaCraftBlocks.basal_bricks, 0, 2);
		world.setBlock(i + 2, j + 1, k + 8, NovaCraftBlocks.cracked_basal_bricks, 0, 2);
		world.setBlock(i + 3, j + 1, k + 8, NovaCraftBlocks.cracked_basal_bricks, 0, 2);
		world.setBlock(i + 4, j + 1, k + 8, NovaCraftBlocks.basal_bricks, 0, 2);
		world.setBlock(i + 5, j + 1, k + 8, NovaCraftBlocks.cracked_basal_bricks, 0, 2);
		world.setBlock(i + 6, j + 1, k + 8, NovaCraftBlocks.cracked_basal_bricks, 0, 2);
		world.setBlock(i + 7, j + 1, k + 8, NovaCraftBlocks.basal_bricks, 0, 2);
		world.setBlock(i + 8, j + 1, k + 8, NovaCraftBlocks.cracked_basal_bricks, 0, 2);
		world.setBlock(i + 9, j + 1, k + 8, NovaCraftBlocks.basal_bricks, 0, 2);
		world.setBlock(i + 10, j + 1, k + 8, NovaCraftBlocks.basal_bricks, 0, 2);
		world.setBlock(i + 11, j + 1, k + 8, NovaCraftBlocks.cracked_basal_bricks, 0, 2);
		world.setBlock(i + 12, j + 1, k + 8, NovaCraftBlocks.basal_bricks, 0, 2);
		world.setBlock(i + 13, j + 1, k + 8, NovaCraftBlocks.cracked_basal_bricks, 0, 2);
		world.setBlock(i + 14, j + 1, k + 8, NovaCraftBlocks.basal_bricks, 0, 2);
		world.setBlock(i + 15, j + 1, k + 8, NovaCraftBlocks.basal_bricks, 0, 2);
		world.setBlock(i + 16, j + 1, k + 8, NovaCraftBlocks.basal_bricks, 0, 2);
		world.setBlock(i + 17, j + 1, k + 8, NovaCraftBlocks.basal_bricks, 0, 2);
		world.setBlock(i + 18, j + 1, k + 8, NovaCraftBlocks.basal_bricks, 0, 2);
		world.setBlock(i + 19, j + 1, k + 8, NovaCraftBlocks.basal_bricks, 0, 2);
		world.setBlock(i + 20, j + 1, k + 8, NovaCraftBlocks.basal_bricks, 0, 2);
		world.setBlock(i + 21, j + 1, k + 8, NovaCraftBlocks.cracked_basal_bricks, 0, 2);
		world.setBlock(i + 22, j + 1, k + 8, NovaCraftBlocks.basal_bricks, 0, 2);
		world.setBlock(i + 23, j + 1, k + 8, NovaCraftBlocks.cracked_basal_bricks, 0, 2);
		world.setBlock(i + 24, j + 1, k + 8, NovaCraftBlocks.basal_bricks, 0, 2);
		world.setBlock(i + 25, j + 1, k + 8, NovaCraftBlocks.cracked_basal_bricks, 0, 2);
		world.setBlock(i + 26, j + 1, k + 8, NovaCraftBlocks.basal_bricks, 0, 2);
		world.setBlock(i + 27, j + 1, k + 8, NovaCraftBlocks.basal_bricks, 0, 2);
		world.setBlock(i + 0, j + 1, k + 9, NovaCraftBlocks.cracked_basal_bricks, 0, 2);
		world.setBlock(i + 1, j + 1, k + 9, NovaCraftBlocks.cracked_basal_bricks, 0, 2);
		world.setBlock(i + 2, j + 1, k + 9, NovaCraftBlocks.cracked_basal_bricks, 0, 2);
		world.setBlock(i + 3, j + 1, k + 9, NovaCraftBlocks.cracked_basal_bricks, 0, 2);
		world.setBlock(i + 4, j + 1, k + 9, NovaCraftBlocks.basal_bricks, 0, 2);
		world.setBlock(i + 5, j + 1, k + 9, NovaCraftBlocks.cracked_basal_bricks, 0, 2);
		world.setBlock(i + 6, j + 1, k + 9, NovaCraftBlocks.basal_bricks, 0, 2);
		world.setBlock(i + 7, j + 1, k + 9, NovaCraftBlocks.basal_bricks, 0, 2);
		world.setBlock(i + 8, j + 1, k + 9, NovaCraftBlocks.basal_bricks, 0, 2);
		world.setBlock(i + 9, j + 1, k + 9, NovaCraftBlocks.cracked_basal_bricks, 0, 2);
		world.setBlock(i + 10, j + 1, k + 9, NovaCraftBlocks.basal_bricks, 0, 2);
		world.setBlock(i + 11, j + 1, k + 9, NovaCraftBlocks.basal_bricks, 0, 2);
		world.setBlock(i + 12, j + 1, k + 9, NovaCraftBlocks.basal_bricks, 0, 2);
		world.setBlock(i + 13, j + 1, k + 9, NovaCraftBlocks.basal_bricks, 0, 2);
		world.setBlock(i + 14, j + 1, k + 9, NovaCraftBlocks.cracked_basal_bricks, 0, 2);
		world.setBlock(i + 15, j + 1, k + 9, NovaCraftBlocks.cracked_basal_bricks, 0, 2);
		world.setBlock(i + 16, j + 1, k + 9, NovaCraftBlocks.basal_bricks, 0, 2);
		world.setBlock(i + 17, j + 1, k + 9, NovaCraftBlocks.basal_bricks, 0, 2);
		world.setBlock(i + 18, j + 1, k + 9, NovaCraftBlocks.basal_bricks, 0, 2);
		world.setBlock(i + 19, j + 1, k + 9, NovaCraftBlocks.cracked_basal_bricks, 0, 2);
		world.setBlock(i + 20, j + 1, k + 9, NovaCraftBlocks.basal_bricks, 0, 2);
		world.setBlock(i + 21, j + 1, k + 9, NovaCraftBlocks.basal_bricks, 0, 2);
		world.setBlock(i + 22, j + 1, k + 9, NovaCraftBlocks.basal_bricks, 0, 2);
		world.setBlock(i + 23, j + 1, k + 9, NovaCraftBlocks.basal_bricks, 0, 2);
		world.setBlock(i + 24, j + 1, k + 9, NovaCraftBlocks.basal_bricks, 0, 2);
		world.setBlock(i + 25, j + 1, k + 9, NovaCraftBlocks.cracked_basal_bricks, 0, 2);
		world.setBlock(i + 26, j + 1, k + 9, NovaCraftBlocks.basal_bricks, 0, 2);
		world.setBlock(i + 27, j + 1, k + 9, NovaCraftBlocks.basal_bricks, 0, 2);
		world.setBlock(i + 0, j + 1, k + 10, NovaCraftBlocks.basal_bricks, 0, 2);
		world.setBlock(i + 1, j + 1, k + 10, NovaCraftBlocks.cracked_basal_bricks, 0, 2);
		world.setBlock(i + 2, j + 1, k + 10, NovaCraftBlocks.basal_bricks, 0, 2);
		world.setBlock(i + 3, j + 1, k + 10, NovaCraftBlocks.basal_bricks, 0, 2);
		world.setBlock(i + 4, j + 1, k + 10, NovaCraftBlocks.basal_bricks, 0, 2);
		world.setBlock(i + 5, j + 1, k + 10, NovaCraftBlocks.cracked_basal_bricks, 0, 2);
		world.setBlock(i + 6, j + 1, k + 10, NovaCraftBlocks.cracked_basal_bricks, 0, 2);
		world.setBlock(i + 7, j + 1, k + 10, NovaCraftBlocks.cracked_basal_bricks, 0, 2);
		world.setBlock(i + 8, j + 1, k + 10, NovaCraftBlocks.basal_bricks, 0, 2);
		world.setBlock(i + 9, j + 1, k + 10, NovaCraftBlocks.basal_bricks, 0, 2);
		world.setBlock(i + 10, j + 1, k + 10, NovaCraftBlocks.cracked_basal_bricks, 0, 2);
		world.setBlock(i + 11, j + 1, k + 10, NovaCraftBlocks.cracked_basal_bricks, 0, 2);
		world.setBlock(i + 12, j + 1, k + 10, NovaCraftBlocks.basal_bricks, 0, 2);
		world.setBlock(i + 13, j + 1, k + 10, NovaCraftBlocks.basal_bricks, 0, 2);
		world.setBlock(i + 14, j + 1, k + 10, NovaCraftBlocks.cracked_basal_bricks, 0, 2);
		world.setBlock(i + 15, j + 1, k + 10, NovaCraftBlocks.cracked_basal_bricks, 0, 2);
		world.setBlock(i + 16, j + 1, k + 10, NovaCraftBlocks.basal_bricks, 0, 2);
		world.setBlock(i + 17, j + 1, k + 10, NovaCraftBlocks.basal_bricks, 0, 2);
		world.setBlock(i + 18, j + 1, k + 10, NovaCraftBlocks.basal_bricks, 0, 2);
		world.setBlock(i + 19, j + 1, k + 10, NovaCraftBlocks.basal_bricks, 0, 2);
		world.setBlock(i + 20, j + 1, k + 10, NovaCraftBlocks.cracked_basal_bricks, 0, 2);
		world.setBlock(i + 21, j + 1, k + 10, NovaCraftBlocks.cracked_basal_bricks, 0, 2);
		world.setBlock(i + 22, j + 1, k + 10, NovaCraftBlocks.basal_bricks, 0, 2);
		world.setBlock(i + 23, j + 1, k + 10, NovaCraftBlocks.cracked_basal_bricks, 0, 2);
		world.setBlock(i + 24, j + 1, k + 10, NovaCraftBlocks.cracked_basal_bricks, 0, 2);
		world.setBlock(i + 25, j + 1, k + 10, NovaCraftBlocks.basal_bricks, 0, 2);
		world.setBlock(i + 26, j + 1, k + 10, NovaCraftBlocks.basal_bricks, 0, 2);
		world.setBlock(i + 27, j + 1, k + 10, NovaCraftBlocks.basal_bricks, 0, 2);
		world.setBlock(i + 0, j + 1, k + 11, NovaCraftBlocks.cracked_basal_bricks, 0, 2);
		world.setBlock(i + 1, j + 1, k + 11, NovaCraftBlocks.basal_bricks, 0, 2);
		world.setBlock(i + 2, j + 1, k + 11, NovaCraftBlocks.cracked_basal_bricks, 0, 2);
		world.setBlock(i + 3, j + 1, k + 11, NovaCraftBlocks.basal_bricks, 0, 2);
		world.setBlock(i + 4, j + 1, k + 11, NovaCraftBlocks.basal_bricks, 0, 2);
		world.setBlock(i + 5, j + 1, k + 11, NovaCraftBlocks.cracked_basal_bricks, 0, 2);
		world.setBlock(i + 6, j + 1, k + 11, NovaCraftBlocks.basal_bricks, 0, 2);
		world.setBlock(i + 7, j + 1, k + 11, NovaCraftBlocks.cracked_basal_bricks, 0, 2);
		world.setBlock(i + 8, j + 1, k + 11, NovaCraftBlocks.basal_bricks, 0, 2);
		world.setBlock(i + 9, j + 1, k + 11, NovaCraftBlocks.cracked_basal_bricks, 0, 2);
		world.setBlock(i + 10, j + 1, k + 11, NovaCraftBlocks.cracked_basal_bricks, 0, 2);
		world.setBlock(i + 11, j + 1, k + 11, NovaCraftBlocks.cracked_basal_bricks, 0, 2);
		world.setBlock(i + 12, j + 1, k + 11, NovaCraftBlocks.basal_bricks, 0, 2);
		world.setBlock(i + 13, j + 1, k + 11, NovaCraftBlocks.basal_bricks, 0, 2);
		world.setBlock(i + 14, j + 1, k + 11, NovaCraftBlocks.cracked_basal_bricks, 0, 2);
		world.setBlock(i + 15, j + 1, k + 11, NovaCraftBlocks.basal_bricks, 0, 2);
		world.setBlock(i + 16, j + 1, k + 11, NovaCraftBlocks.basal_bricks, 0, 2);
		world.setBlock(i + 17, j + 1, k + 11, NovaCraftBlocks.basal_bricks, 0, 2);
		world.setBlock(i + 18, j + 1, k + 11, NovaCraftBlocks.basal_bricks, 0, 2);
		world.setBlock(i + 19, j + 1, k + 11, NovaCraftBlocks.basal_bricks, 0, 2);
		world.setBlock(i + 20, j + 1, k + 11, NovaCraftBlocks.basal_bricks, 0, 2);
		world.setBlock(i + 21, j + 1, k + 11, NovaCraftBlocks.basal_bricks, 0, 2);
		world.setBlock(i + 22, j + 1, k + 11, NovaCraftBlocks.basal_bricks, 0, 2);
		world.setBlock(i + 23, j + 1, k + 11, NovaCraftBlocks.basal_bricks, 0, 2);
		world.setBlock(i + 24, j + 1, k + 11, NovaCraftBlocks.basal_bricks, 0, 2);
		world.setBlock(i + 25, j + 1, k + 11, NovaCraftBlocks.cracked_basal_bricks, 0, 2);
		world.setBlock(i + 26, j + 1, k + 11, NovaCraftBlocks.basal_bricks, 0, 2);
		world.setBlock(i + 27, j + 1, k + 11, NovaCraftBlocks.cracked_basal_bricks, 0, 2);
		world.setBlock(i + 0, j + 1, k + 12, NovaCraftBlocks.basal_bricks, 0, 2);
		world.setBlock(i + 1, j + 1, k + 12, NovaCraftBlocks.cracked_basal_bricks, 0, 2);
		world.setBlock(i + 2, j + 1, k + 12, NovaCraftBlocks.cracked_basal_bricks, 0, 2);
		world.setBlock(i + 3, j + 1, k + 12, NovaCraftBlocks.cracked_basal_bricks, 0, 2);
		world.setBlock(i + 4, j + 1, k + 12, NovaCraftBlocks.cracked_basal_bricks, 0, 2);
		world.setBlock(i + 5, j + 1, k + 12, NovaCraftBlocks.cracked_basal_bricks, 0, 2);
		world.setBlock(i + 6, j + 1, k + 12, NovaCraftBlocks.basal_bricks, 0, 2);
		world.setBlock(i + 7, j + 1, k + 12, NovaCraftBlocks.cracked_basal_bricks, 0, 2);
		world.setBlock(i + 8, j + 1, k + 12, NovaCraftBlocks.basal_bricks, 0, 2);
		world.setBlock(i + 9, j + 1, k + 12, NovaCraftBlocks.basal_bricks, 0, 2);
		world.setBlock(i + 10, j + 1, k + 12, NovaCraftBlocks.cracked_basal_bricks, 0, 2);
		world.setBlock(i + 11, j + 1, k + 12, NovaCraftBlocks.cracked_basal_bricks, 0, 2);
		world.setBlock(i + 12, j + 1, k + 12, NovaCraftBlocks.basal_bricks, 0, 2);
		world.setBlock(i + 13, j + 1, k + 12, NovaCraftBlocks.basal_bricks, 0, 2);
		world.setBlock(i + 14, j + 1, k + 12, NovaCraftBlocks.basal_bricks, 0, 2);
		world.setBlock(i + 15, j + 1, k + 12, NovaCraftBlocks.cracked_basal_bricks, 0, 2);
		world.setBlock(i + 16, j + 1, k + 12, NovaCraftBlocks.cracked_basal_bricks, 0, 2);
		world.setBlock(i + 17, j + 1, k + 12, NovaCraftBlocks.cracked_basal_bricks, 0, 2);
		world.setBlock(i + 18, j + 1, k + 12, NovaCraftBlocks.basal_bricks, 0, 2);
		world.setBlock(i + 19, j + 1, k + 12, NovaCraftBlocks.cracked_basal_bricks, 0, 2);
		world.setBlock(i + 20, j + 1, k + 12, NovaCraftBlocks.cracked_basal_bricks, 0, 2);
		world.setBlock(i + 21, j + 1, k + 12, NovaCraftBlocks.basal_bricks, 0, 2);
		world.setBlock(i + 22, j + 1, k + 12, NovaCraftBlocks.cracked_basal_bricks, 0, 2);
		world.setBlock(i + 23, j + 1, k + 12, NovaCraftBlocks.cracked_basal_bricks, 0, 2);
		world.setBlock(i + 24, j + 1, k + 12, NovaCraftBlocks.cracked_basal_bricks, 0, 2);
		world.setBlock(i + 25, j + 1, k + 12, NovaCraftBlocks.cracked_basal_bricks, 0, 2);
		world.setBlock(i + 26, j + 1, k + 12, NovaCraftBlocks.cracked_basal_bricks, 0, 2);
		world.setBlock(i + 27, j + 1, k + 12, NovaCraftBlocks.basal_bricks, 0, 2);
		world.setBlock(i + 0, j + 1, k + 13, NovaCraftBlocks.basal_bricks, 0, 2);
		world.setBlock(i + 1, j + 1, k + 13, NovaCraftBlocks.cracked_basal_bricks, 0, 2);
		world.setBlock(i + 2, j + 1, k + 13, NovaCraftBlocks.basal_bricks, 0, 2);
		world.setBlock(i + 3, j + 1, k + 13, NovaCraftBlocks.basal_bricks, 0, 2);
		world.setBlock(i + 4, j + 1, k + 13, NovaCraftBlocks.cracked_basal_bricks, 0, 2);
		world.setBlock(i + 5, j + 1, k + 13, NovaCraftBlocks.basal_bricks, 0, 2);
		world.setBlock(i + 6, j + 1, k + 13, NovaCraftBlocks.basal_bricks, 0, 2);
		world.setBlock(i + 7, j + 1, k + 13, NovaCraftBlocks.basal_bricks, 0, 2);
		world.setBlock(i + 8, j + 1, k + 13, NovaCraftBlocks.basal_bricks, 0, 2);
		world.setBlock(i + 9, j + 1, k + 13, NovaCraftBlocks.basal_bricks, 0, 2);
		world.setBlock(i + 10, j + 1, k + 13, NovaCraftBlocks.basal_bricks, 0, 2);
		world.setBlock(i + 11, j + 1, k + 13, NovaCraftBlocks.basal_bricks, 0, 2);
		world.setBlock(i + 12, j + 1, k + 13, NovaCraftBlocks.cracked_basal_bricks, 0, 2);
		world.setBlock(i + 13, j + 1, k + 13, NovaCraftBlocks.basal_bricks, 0, 2);
		world.setBlock(i + 14, j + 1, k + 13, NovaCraftBlocks.basal_bricks, 0, 2);
		world.setBlock(i + 15, j + 1, k + 13, NovaCraftBlocks.basal_bricks, 0, 2);
		world.setBlock(i + 16, j + 1, k + 13, NovaCraftBlocks.basal_bricks, 0, 2);
		world.setBlock(i + 17, j + 1, k + 13, NovaCraftBlocks.cracked_basal_bricks, 0, 2);
		world.setBlock(i + 18, j + 1, k + 13, NovaCraftBlocks.basal_bricks, 0, 2);
		world.setBlock(i + 19, j + 1, k + 13, NovaCraftBlocks.cracked_basal_bricks, 0, 2);
		world.setBlock(i + 20, j + 1, k + 13, NovaCraftBlocks.basal_bricks, 0, 2);
		world.setBlock(i + 21, j + 1, k + 13, NovaCraftBlocks.basal_bricks, 0, 2);
		world.setBlock(i + 22, j + 1, k + 13, NovaCraftBlocks.basal_bricks, 0, 2);
		world.setBlock(i + 23, j + 1, k + 13, NovaCraftBlocks.cracked_basal_bricks, 0, 2);
		world.setBlock(i + 24, j + 1, k + 13, NovaCraftBlocks.cracked_basal_bricks, 0, 2);
		world.setBlock(i + 25, j + 1, k + 13, NovaCraftBlocks.cracked_basal_bricks, 0, 2);
		world.setBlock(i + 26, j + 1, k + 13, NovaCraftBlocks.basal_bricks, 0, 2);
		world.setBlock(i + 27, j + 1, k + 13, NovaCraftBlocks.basal_bricks, 0, 2);
		world.setBlock(i + 0, j + 1, k + 14, NovaCraftBlocks.cracked_basal_bricks, 0, 2);
		world.setBlock(i + 1, j + 1, k + 14, NovaCraftBlocks.basal_bricks, 0, 2);
		world.setBlock(i + 2, j + 1, k + 14, NovaCraftBlocks.basal_bricks, 0, 2);
		world.setBlock(i + 3, j + 1, k + 14, NovaCraftBlocks.basal_bricks, 0, 2);
		world.setBlock(i + 4, j + 1, k + 14, NovaCraftBlocks.basal_bricks, 0, 2);
		world.setBlock(i + 5, j + 1, k + 14, NovaCraftBlocks.basal_bricks, 0, 2);
		world.setBlock(i + 6, j + 1, k + 14, NovaCraftBlocks.basal_bricks, 0, 2);
		world.setBlock(i + 7, j + 1, k + 14, NovaCraftBlocks.cracked_basal_bricks, 0, 2);
		world.setBlock(i + 8, j + 1, k + 14, NovaCraftBlocks.cracked_basal_bricks, 0, 2);
		world.setBlock(i + 9, j + 1, k + 14, NovaCraftBlocks.basal_bricks, 0, 2);
		world.setBlock(i + 10, j + 1, k + 14, NovaCraftBlocks.basal_bricks, 0, 2);
		world.setBlock(i + 11, j + 1, k + 14, NovaCraftBlocks.basal_bricks, 0, 2);
		world.setBlock(i + 12, j + 1, k + 14, NovaCraftBlocks.basal_bricks, 0, 2);
		world.setBlock(i + 13, j + 1, k + 14, NovaCraftBlocks.cracked_basal_bricks, 0, 2);
		world.setBlock(i + 14, j + 1, k + 14, NovaCraftBlocks.basal_bricks, 0, 2);
		world.setBlock(i + 15, j + 1, k + 14, NovaCraftBlocks.basal_bricks, 0, 2);
		world.setBlock(i + 16, j + 1, k + 14, NovaCraftBlocks.basal_bricks, 0, 2);
		world.setBlock(i + 17, j + 1, k + 14, NovaCraftBlocks.basal_bricks, 0, 2);
		world.setBlock(i + 18, j + 1, k + 14, NovaCraftBlocks.cracked_basal_bricks, 0, 2);
		world.setBlock(i + 19, j + 1, k + 14, NovaCraftBlocks.basal_bricks, 0, 2);
		world.setBlock(i + 20, j + 1, k + 14, NovaCraftBlocks.cracked_basal_bricks, 0, 2);
		world.setBlock(i + 21, j + 1, k + 14, NovaCraftBlocks.cracked_basal_bricks, 0, 2);
		world.setBlock(i + 22, j + 1, k + 14, NovaCraftBlocks.cracked_basal_bricks, 0, 2);
		world.setBlock(i + 23, j + 1, k + 14, NovaCraftBlocks.cracked_basal_bricks, 0, 2);
		world.setBlock(i + 24, j + 1, k + 14, NovaCraftBlocks.basal_bricks, 0, 2);
		world.setBlock(i + 25, j + 1, k + 14, NovaCraftBlocks.cracked_basal_bricks, 0, 2);
		world.setBlock(i + 26, j + 1, k + 14, NovaCraftBlocks.basal_bricks, 0, 2);
		world.setBlock(i + 27, j + 1, k + 14, NovaCraftBlocks.cracked_basal_bricks, 0, 2);
		world.setBlock(i + 0, j + 1, k + 15, NovaCraftBlocks.cracked_basal_bricks, 0, 2);
		world.setBlock(i + 1, j + 1, k + 15, NovaCraftBlocks.cracked_basal_bricks, 0, 2);
		world.setBlock(i + 2, j + 1, k + 15, NovaCraftBlocks.cracked_basal_bricks, 0, 2);
		world.setBlock(i + 3, j + 1, k + 15, NovaCraftBlocks.basal_bricks, 0, 2);
		world.setBlock(i + 4, j + 1, k + 15, NovaCraftBlocks.cracked_basal_bricks, 0, 2);
		world.setBlock(i + 5, j + 1, k + 15, NovaCraftBlocks.basal_bricks, 0, 2);
		world.setBlock(i + 6, j + 1, k + 15, NovaCraftBlocks.cracked_basal_bricks, 0, 2);
		world.setBlock(i + 7, j + 1, k + 15, NovaCraftBlocks.basal_bricks, 0, 2);
		world.setBlock(i + 8, j + 1, k + 15, NovaCraftBlocks.basal_bricks, 0, 2);
		world.setBlock(i + 9, j + 1, k + 15, NovaCraftBlocks.cracked_basal_bricks, 0, 2);
		world.setBlock(i + 10, j + 1, k + 15, NovaCraftBlocks.cracked_basal_bricks, 0, 2);
		world.setBlock(i + 11, j + 1, k + 15, NovaCraftBlocks.basal_bricks, 0, 2);
		world.setBlock(i + 12, j + 1, k + 15, NovaCraftBlocks.basal_bricks, 0, 2);
		world.setBlock(i + 13, j + 1, k + 15, NovaCraftBlocks.basal_bricks, 0, 2);
		world.setBlock(i + 14, j + 1, k + 15, NovaCraftBlocks.basal_bricks, 0, 2);
		world.setBlock(i + 15, j + 1, k + 15, NovaCraftBlocks.basal_bricks, 0, 2);
		world.setBlock(i + 16, j + 1, k + 15, NovaCraftBlocks.basal_bricks, 0, 2);
		world.setBlock(i + 17, j + 1, k + 15, NovaCraftBlocks.basal_bricks, 0, 2);
		world.setBlock(i + 18, j + 1, k + 15, NovaCraftBlocks.basal_bricks, 0, 2);
		world.setBlock(i + 19, j + 1, k + 15, NovaCraftBlocks.cracked_basal_bricks, 0, 2);
		world.setBlock(i + 20, j + 1, k + 15, NovaCraftBlocks.basal_bricks, 0, 2);
		world.setBlock(i + 21, j + 1, k + 15, NovaCraftBlocks.basal_bricks, 0, 2);
		world.setBlock(i + 22, j + 1, k + 15, NovaCraftBlocks.basal_bricks, 0, 2);
		world.setBlock(i + 23, j + 1, k + 15, NovaCraftBlocks.basal_bricks, 0, 2);
		world.setBlock(i + 24, j + 1, k + 15, NovaCraftBlocks.cracked_basal_bricks, 0, 2);
		world.setBlock(i + 25, j + 1, k + 15, NovaCraftBlocks.basal_bricks, 0, 2);
		world.setBlock(i + 26, j + 1, k + 15, NovaCraftBlocks.basal_bricks, 0, 2);
		world.setBlock(i + 27, j + 1, k + 15, NovaCraftBlocks.basal_bricks, 0, 2);
		world.setBlock(i + 0, j + 1, k + 16, NovaCraftBlocks.basal_bricks, 0, 2);
		world.setBlock(i + 1, j + 1, k + 16, NovaCraftBlocks.cracked_basal_bricks, 0, 2);
		world.setBlock(i + 2, j + 1, k + 16, NovaCraftBlocks.basal_bricks, 0, 2);
		world.setBlock(i + 3, j + 1, k + 16, NovaCraftBlocks.basal_bricks, 0, 2);
		world.setBlock(i + 4, j + 1, k + 16, NovaCraftBlocks.basal_bricks, 0, 2);
		world.setBlock(i + 5, j + 1, k + 16, NovaCraftBlocks.cracked_basal_bricks, 0, 2);
		world.setBlock(i + 6, j + 1, k + 16, NovaCraftBlocks.basal_bricks, 0, 2);
		world.setBlock(i + 7, j + 1, k + 16, NovaCraftBlocks.basal_bricks, 0, 2);
		world.setBlock(i + 8, j + 1, k + 16, NovaCraftBlocks.cracked_basal_bricks, 0, 2);
		world.setBlock(i + 9, j + 1, k + 16, NovaCraftBlocks.basal_bricks, 0, 2);
		world.setBlock(i + 10, j + 1, k + 16, NovaCraftBlocks.basal_bricks, 0, 2);
		world.setBlock(i + 11, j + 1, k + 16, NovaCraftBlocks.basal_bricks, 0, 2);
		world.setBlock(i + 12, j + 1, k + 16, NovaCraftBlocks.basal_bricks, 0, 2);
		world.setBlock(i + 13, j + 1, k + 16, NovaCraftBlocks.basal_bricks, 0, 2);
		world.setBlock(i + 14, j + 1, k + 16, NovaCraftBlocks.basal_bricks, 0, 2);
		world.setBlock(i + 15, j + 1, k + 16, NovaCraftBlocks.basal_bricks, 0, 2);
		world.setBlock(i + 16, j + 1, k + 16, NovaCraftBlocks.basal_bricks, 0, 2);
		world.setBlock(i + 17, j + 1, k + 16, NovaCraftBlocks.basal_bricks, 0, 2);
		world.setBlock(i + 18, j + 1, k + 16, NovaCraftBlocks.basal_bricks, 0, 2);
		world.setBlock(i + 19, j + 1, k + 16, NovaCraftBlocks.basal_bricks, 0, 2);
		world.setBlock(i + 20, j + 1, k + 16, NovaCraftBlocks.basal_bricks, 0, 2);
		world.setBlock(i + 21, j + 1, k + 16, NovaCraftBlocks.cracked_basal_bricks, 0, 2);
		world.setBlock(i + 22, j + 1, k + 16, NovaCraftBlocks.basal_bricks, 0, 2);
		world.setBlock(i + 23, j + 1, k + 16, NovaCraftBlocks.basal_bricks, 0, 2);
		world.setBlock(i + 24, j + 1, k + 16, NovaCraftBlocks.basal_bricks, 0, 2);
		world.setBlock(i + 25, j + 1, k + 16, NovaCraftBlocks.basal_bricks, 0, 2);
		world.setBlock(i + 26, j + 1, k + 16, NovaCraftBlocks.basal_bricks, 0, 2);
		world.setBlock(i + 27, j + 1, k + 16, NovaCraftBlocks.basal_bricks, 0, 2);
		world.setBlock(i + 0, j + 1, k + 17, NovaCraftBlocks.basal_bricks, 0, 2);
		world.setBlock(i + 1, j + 1, k + 17, NovaCraftBlocks.basal_bricks, 0, 2);
		world.setBlock(i + 2, j + 1, k + 17, NovaCraftBlocks.basal_bricks, 0, 2);
		world.setBlock(i + 3, j + 1, k + 17, NovaCraftBlocks.cracked_basal_bricks, 0, 2);
		world.setBlock(i + 4, j + 1, k + 17, NovaCraftBlocks.basal_bricks, 0, 2);
		world.setBlock(i + 5, j + 1, k + 17, NovaCraftBlocks.cracked_basal_bricks, 0, 2);
		world.setBlock(i + 6, j + 1, k + 17, NovaCraftBlocks.basal_bricks, 0, 2);
		world.setBlock(i + 7, j + 1, k + 17, NovaCraftBlocks.basal_bricks, 0, 2);
		world.setBlock(i + 8, j + 1, k + 17, NovaCraftBlocks.cracked_basal_bricks, 0, 2);
		world.setBlock(i + 9, j + 1, k + 17, NovaCraftBlocks.basal_bricks, 0, 2);
		world.setBlock(i + 10, j + 1, k + 17, NovaCraftBlocks.basal_bricks, 0, 2);
		world.setBlock(i + 11, j + 1, k + 17, NovaCraftBlocks.cracked_basal_bricks, 0, 2);
		world.setBlock(i + 12, j + 1, k + 17, NovaCraftBlocks.basal_bricks, 0, 2);
		world.setBlock(i + 13, j + 1, k + 17, NovaCraftBlocks.cracked_basal_bricks, 0, 2);
		world.setBlock(i + 14, j + 1, k + 17, NovaCraftBlocks.basal_bricks, 0, 2);
		world.setBlock(i + 15, j + 1, k + 17, NovaCraftBlocks.basal_bricks, 0, 2);
		world.setBlock(i + 16, j + 1, k + 17, NovaCraftBlocks.basal_bricks, 0, 2);
		world.setBlock(i + 17, j + 1, k + 17, NovaCraftBlocks.cracked_basal_bricks, 0, 2);
		world.setBlock(i + 18, j + 1, k + 17, NovaCraftBlocks.basal_bricks, 0, 2);
		world.setBlock(i + 19, j + 1, k + 17, NovaCraftBlocks.basal_bricks, 0, 2);
		world.setBlock(i + 20, j + 1, k + 17, NovaCraftBlocks.basal_bricks, 0, 2);
		world.setBlock(i + 21, j + 1, k + 17, NovaCraftBlocks.basal_bricks, 0, 2);
		world.setBlock(i + 22, j + 1, k + 17, NovaCraftBlocks.basal_bricks, 0, 2);
		world.setBlock(i + 23, j + 1, k + 17, NovaCraftBlocks.basal_bricks, 0, 2);
		world.setBlock(i + 24, j + 1, k + 17, NovaCraftBlocks.cracked_basal_bricks, 0, 2);
		world.setBlock(i + 25, j + 1, k + 17, NovaCraftBlocks.cracked_basal_bricks, 0, 2);
		world.setBlock(i + 26, j + 1, k + 17, NovaCraftBlocks.cracked_basal_bricks, 0, 2);
		world.setBlock(i + 27, j + 1, k + 17, NovaCraftBlocks.basal_bricks, 0, 2);
		world.setBlock(i + 0, j + 1, k + 18, NovaCraftBlocks.basal_bricks, 0, 2);
		world.setBlock(i + 1, j + 1, k + 18, NovaCraftBlocks.basal_bricks, 0, 2);
		world.setBlock(i + 2, j + 1, k + 18, NovaCraftBlocks.basal_bricks, 0, 2);
		world.setBlock(i + 3, j + 1, k + 18, NovaCraftBlocks.cracked_basal_bricks, 0, 2);
		world.setBlock(i + 4, j + 1, k + 18, NovaCraftBlocks.cracked_basal_bricks, 0, 2);
		world.setBlock(i + 5, j + 1, k + 18, NovaCraftBlocks.cracked_basal_bricks, 0, 2);
		world.setBlock(i + 6, j + 1, k + 18, NovaCraftBlocks.basal_bricks, 0, 2);
		world.setBlock(i + 7, j + 1, k + 18, NovaCraftBlocks.basal_bricks, 0, 2);
		world.setBlock(i + 8, j + 1, k + 18, NovaCraftBlocks.cracked_basal_bricks, 0, 2);
		world.setBlock(i + 9, j + 1, k + 18, NovaCraftBlocks.basal_bricks, 0, 2);
		world.setBlock(i + 10, j + 1, k + 18, NovaCraftBlocks.basal_bricks, 0, 2);
		world.setBlock(i + 11, j + 1, k + 18, NovaCraftBlocks.basal_bricks, 0, 2);
		world.setBlock(i + 12, j + 1, k + 18, NovaCraftBlocks.basal_bricks, 0, 2);
		world.setBlock(i + 13, j + 1, k + 18, NovaCraftBlocks.cracked_basal_bricks, 0, 2);
		world.setBlock(i + 14, j + 1, k + 18, NovaCraftBlocks.basal_bricks, 0, 2);
		world.setBlock(i + 15, j + 1, k + 18, NovaCraftBlocks.basal_bricks, 0, 2);
		world.setBlock(i + 16, j + 1, k + 18, NovaCraftBlocks.basal_bricks, 0, 2);
		world.setBlock(i + 17, j + 1, k + 18, NovaCraftBlocks.cracked_basal_bricks, 0, 2);
		world.setBlock(i + 18, j + 1, k + 18, NovaCraftBlocks.cracked_basal_bricks, 0, 2);
		world.setBlock(i + 19, j + 1, k + 18, NovaCraftBlocks.cracked_basal_bricks, 0, 2);
		world.setBlock(i + 20, j + 1, k + 18, NovaCraftBlocks.basal_bricks, 0, 2);
		world.setBlock(i + 21, j + 1, k + 18, NovaCraftBlocks.cracked_basal_bricks, 0, 2);
		world.setBlock(i + 22, j + 1, k + 18, NovaCraftBlocks.basal_bricks, 0, 2);
		world.setBlock(i + 23, j + 1, k + 18, NovaCraftBlocks.cracked_basal_bricks, 0, 2);
		world.setBlock(i + 24, j + 1, k + 18, NovaCraftBlocks.basal_bricks, 0, 2);
		world.setBlock(i + 25, j + 1, k + 18, NovaCraftBlocks.basal_bricks, 0, 2);
		world.setBlock(i + 26, j + 1, k + 18, NovaCraftBlocks.basal_bricks, 0, 2);
		world.setBlock(i + 27, j + 1, k + 18, NovaCraftBlocks.cracked_basal_bricks, 0, 2);
		world.setBlock(i + 0, j + 2, k + 0, NovaCraftBlocks.basal_bricks, 0, 2);
		world.setBlock(i + 1, j + 2, k + 0, NovaCraftBlocks.basal_bricks, 0, 2);
		world.setBlock(i + 2, j + 2, k + 0, NovaCraftBlocks.cracked_basal_bricks, 0, 2);
		world.setBlock(i + 3, j + 2, k + 0, NovaCraftBlocks.cracked_basal_bricks, 0, 2);
		world.setBlock(i + 4, j + 2, k + 0, NovaCraftBlocks.cracked_basal_bricks, 0, 2);
		world.setBlock(i + 5, j + 2, k + 0, NovaCraftBlocks.basal_bricks, 0, 2);
		world.setBlock(i + 6, j + 2, k + 0, NovaCraftBlocks.cracked_basal_bricks, 0, 2);
		world.setBlock(i + 7, j + 2, k + 0, NovaCraftBlocks.basal_bricks, 0, 2);
		world.setBlock(i + 8, j + 2, k + 0, NovaCraftBlocks.basal_bricks, 0, 2);
		world.setBlock(i + 9, j + 2, k + 0, NovaCraftBlocks.cracked_basal_bricks, 0, 2);
		world.setBlock(i + 10, j + 2, k + 0, NovaCraftBlocks.basal_bricks, 0, 2);
		world.setBlock(i + 11, j + 2, k + 0, NovaCraftBlocks.basal_bricks, 0, 2);
		world.setBlock(i + 12, j + 2, k + 0, NovaCraftBlocks.basal_bricks, 0, 2);
		world.setBlock(i + 13, j + 2, k + 0, NovaCraftBlocks.cracked_basal_bricks, 0, 2);
		world.setBlock(i + 14, j + 2, k + 0, NovaCraftBlocks.basal_bricks, 0, 2);
		world.setBlock(i + 15, j + 2, k + 0, NovaCraftBlocks.basal_bricks, 0, 2);
		world.setBlock(i + 16, j + 2, k + 0, NovaCraftBlocks.cracked_basal_bricks, 0, 2);
		world.setBlock(i + 17, j + 2, k + 0, NovaCraftBlocks.basal_bricks, 0, 2);
		world.setBlock(i + 18, j + 2, k + 0, NovaCraftBlocks.cracked_basal_bricks, 0, 2);
		world.setBlock(i + 19, j + 2, k + 0, NovaCraftBlocks.cracked_basal_bricks, 0, 2);
		world.setBlock(i + 20, j + 2, k + 0, NovaCraftBlocks.basal_bricks, 0, 2);
		world.setBlock(i + 21, j + 2, k + 0, NovaCraftBlocks.basal_bricks, 0, 2);
		world.setBlock(i + 22, j + 2, k + 0, NovaCraftBlocks.basal_bricks, 0, 2);
		world.setBlock(i + 23, j + 2, k + 0, NovaCraftBlocks.basal_bricks, 0, 2);
		world.setBlock(i + 24, j + 2, k + 0, NovaCraftBlocks.basal_bricks, 0, 2);
		world.setBlock(i + 25, j + 2, k + 0, NovaCraftBlocks.cracked_basal_bricks, 0, 2);
		world.setBlock(i + 26, j + 2, k + 0, NovaCraftBlocks.basal_bricks, 0, 2);
		world.setBlock(i + 27, j + 2, k + 0, Blocks.air, 0, 2);
		world.setBlock(i + 0, j + 2, k + 1, NovaCraftBlocks.cracked_basal_bricks, 0, 2);
		world.setBlock(i + 1, j + 2, k + 1, NovaCraftBlocks.cracked_basal_bricks, 0, 2);
		world.setBlock(i + 2, j + 2, k + 1, NovaCraftBlocks.basal_bricks, 0, 2);
		world.setBlock(i + 3, j + 2, k + 1, NovaCraftBlocks.basal_bricks, 0, 2);
		world.setBlock(i + 4, j + 2, k + 1, NovaCraftBlocks.basal_bricks, 0, 2);
		world.setBlock(i + 5, j + 2, k + 1, NovaCraftBlocks.basal_bricks, 0, 2);
		world.setBlock(i + 6, j + 2, k + 1, NovaCraftBlocks.basal_bricks, 0, 2);
		world.setBlock(i + 7, j + 2, k + 1, NovaCraftBlocks.basal_bricks, 0, 2);
		world.setBlock(i + 8, j + 2, k + 1, NovaCraftBlocks.basal_bricks, 0, 2);
		world.setBlock(i + 9, j + 2, k + 1, NovaCraftBlocks.basal_bricks, 0, 2);
		world.setBlock(i + 10, j + 2, k + 1, NovaCraftBlocks.basal_bricks, 0, 2);
		world.setBlock(i + 11, j + 2, k + 1, NovaCraftBlocks.basal_bricks, 0, 2);
		world.setBlock(i + 12, j + 2, k + 1, NovaCraftBlocks.basal_bricks, 0, 2);
		world.setBlock(i + 13, j + 2, k + 1, NovaCraftBlocks.cracked_basal_bricks, 0, 2);
		world.setBlock(i + 14, j + 2, k + 1, NovaCraftBlocks.cracked_basal_bricks, 0, 2);
		world.setBlock(i + 15, j + 2, k + 1, NovaCraftBlocks.basal_bricks, 0, 2);
		world.setBlock(i + 16, j + 2, k + 1, NovaCraftBlocks.basal_bricks, 0, 2);
		world.setBlock(i + 17, j + 2, k + 1, NovaCraftBlocks.basal_bricks, 0, 2);
		world.setBlock(i + 18, j + 2, k + 1, NovaCraftBlocks.basal_bricks, 0, 2);
		world.setBlock(i + 19, j + 2, k + 1, NovaCraftBlocks.basal_bricks, 0, 2);
		world.setBlock(i + 20, j + 2, k + 1, NovaCraftBlocks.basal_bricks, 0, 2);
		world.setBlock(i + 21, j + 2, k + 1, NovaCraftBlocks.cracked_basal_bricks, 0, 2);
		world.setBlock(i + 22, j + 2, k + 1, NovaCraftBlocks.basal_bricks, 0, 2);
		world.setBlock(i + 23, j + 2, k + 1, NovaCraftBlocks.cracked_basal_bricks, 0, 2);
		world.setBlock(i + 24, j + 2, k + 1, NovaCraftBlocks.basal_bricks, 0, 2);
		world.setBlock(i + 25, j + 2, k + 1, NovaCraftBlocks.basal_bricks, 0, 2);
		world.setBlock(i + 26, j + 2, k + 1, NovaCraftBlocks.basal_bricks, 0, 2);
		world.setBlock(i + 27, j + 2, k + 1, Blocks.air, 0, 2);
		world.setBlock(i + 0, j + 2, k + 2, NovaCraftBlocks.basal_bricks, 0, 2);
		world.setBlock(i + 1, j + 2, k + 2, NovaCraftBlocks.basal_bricks, 0, 2);
		world.setBlock(i + 2, j + 2, k + 2, NovaCraftBlocks.basal_bricks, 0, 2);
		world.setBlock(i + 3, j + 2, k + 2, NovaCraftBlocks.basal_bricks, 0, 2);
		world.setBlock(i + 4, j + 2, k + 2, NovaCraftBlocks.basal_bricks, 0, 2);
		world.setBlock(i + 5, j + 2, k + 2, NovaCraftBlocks.basal_bricks, 0, 2);
		world.setBlock(i + 6, j + 2, k + 2, NovaCraftBlocks.basal_bricks, 0, 2);
		world.setBlock(i + 7, j + 2, k + 2, NovaCraftBlocks.cracked_basal_bricks, 0, 2);
		world.setBlock(i + 8, j + 2, k + 2, NovaCraftBlocks.cracked_basal_bricks, 0, 2);
		world.setBlock(i + 9, j + 2, k + 2, NovaCraftBlocks.basal_bricks, 0, 2);
		world.setBlock(i + 10, j + 2, k + 2, NovaCraftBlocks.basal_bricks, 0, 2);
		world.setBlock(i + 11, j + 2, k + 2, NovaCraftBlocks.cracked_basal_bricks, 0, 2);
		world.setBlock(i + 12, j + 2, k + 2, NovaCraftBlocks.cracked_basal_bricks, 0, 2);
		world.setBlock(i + 13, j + 2, k + 2, NovaCraftBlocks.basal_bricks, 0, 2);
		world.setBlock(i + 14, j + 2, k + 2, NovaCraftBlocks.cracked_basal_bricks, 0, 2);
		world.setBlock(i + 15, j + 2, k + 2, NovaCraftBlocks.basal_bricks, 0, 2);
		world.setBlock(i + 16, j + 2, k + 2, NovaCraftBlocks.cracked_basal_bricks, 0, 2);
		world.setBlock(i + 17, j + 2, k + 2, NovaCraftBlocks.cracked_basal_bricks, 0, 2);
		world.setBlock(i + 18, j + 2, k + 2, NovaCraftBlocks.cracked_basal_bricks, 0, 2);
		world.setBlock(i + 19, j + 2, k + 2, NovaCraftBlocks.basal_bricks, 0, 2);
		world.setBlock(i + 20, j + 2, k + 2, NovaCraftBlocks.basal_bricks, 0, 2);
		world.setBlock(i + 21, j + 2, k + 2, NovaCraftBlocks.cracked_basal_bricks, 0, 2);
		world.setBlock(i + 22, j + 2, k + 2, NovaCraftBlocks.basal_bricks, 0, 2);
		world.setBlock(i + 23, j + 2, k + 2, NovaCraftBlocks.basal_bricks, 0, 2);
		world.setBlock(i + 24, j + 2, k + 2, NovaCraftBlocks.basal_bricks, 0, 2);
		world.setBlock(i + 25, j + 2, k + 2, NovaCraftBlocks.cracked_basal_bricks, 0, 2);
		world.setBlock(i + 26, j + 2, k + 2, NovaCraftBlocks.basal_bricks, 0, 2);
		world.setBlock(i + 27, j + 2, k + 2, NovaCraftBlocks.basal_bricks, 0, 2);
		world.setBlock(i + 0, j + 2, k + 3, NovaCraftBlocks.basal_bricks, 0, 2);
		world.setBlock(i + 1, j + 2, k + 3, NovaCraftBlocks.basal_bricks, 0, 2);
		world.setBlock(i + 2, j + 2, k + 3, NovaCraftBlocks.cracked_basal_bricks, 0, 2);
		world.setBlock(i + 3, j + 2, k + 3, NovaCraftBlocks.basal_bricks, 0, 2);
		world.setBlock(i + 4, j + 2, k + 3, NovaCraftBlocks.basal_bricks, 0, 2);
		world.setBlock(i + 5, j + 2, k + 3, NovaCraftBlocks.basal_bricks, 0, 2);
		world.setBlock(i + 6, j + 2, k + 3, NovaCraftBlocks.basal_bricks, 0, 2);
		world.setBlock(i + 7, j + 2, k + 3, NovaCraftBlocks.basal_bricks, 0, 2);
		world.setBlock(i + 8, j + 2, k + 3, NovaCraftBlocks.cracked_basal_bricks, 0, 2);
		world.setBlock(i + 9, j + 2, k + 3, NovaCraftBlocks.cracked_basal_bricks, 0, 2);
		world.setBlock(i + 10, j + 2, k + 3, NovaCraftBlocks.basal_bricks, 0, 2);
		world.setBlock(i + 11, j + 2, k + 3, NovaCraftBlocks.cracked_basal_bricks, 0, 2);
		world.setBlock(i + 12, j + 2, k + 3, NovaCraftBlocks.cracked_basal_bricks, 0, 2);
		world.setBlock(i + 13, j + 2, k + 3, NovaCraftBlocks.cracked_basal_bricks, 0, 2);
		world.setBlock(i + 14, j + 2, k + 3, NovaCraftBlocks.cracked_basal_bricks, 0, 2);
		world.setBlock(i + 15, j + 2, k + 3, NovaCraftBlocks.basal_bricks, 0, 2);
		world.setBlock(i + 16, j + 2, k + 3, NovaCraftBlocks.basal_bricks, 0, 2);
		world.setBlock(i + 17, j + 2, k + 3, NovaCraftBlocks.cracked_basal_bricks, 0, 2);
		world.setBlock(i + 18, j + 2, k + 3, NovaCraftBlocks.cracked_basal_bricks, 0, 2);
		world.setBlock(i + 19, j + 2, k + 3, NovaCraftBlocks.basal_bricks, 0, 2);
		world.setBlock(i + 20, j + 2, k + 3, NovaCraftBlocks.basal_bricks, 0, 2);
		world.setBlock(i + 21, j + 2, k + 3, NovaCraftBlocks.basal_bricks, 0, 2);
		world.setBlock(i + 22, j + 2, k + 3, NovaCraftBlocks.basal_bricks, 0, 2);
		world.setBlock(i + 23, j + 2, k + 3, NovaCraftBlocks.cracked_basal_bricks, 0, 2);
		world.setBlock(i + 24, j + 2, k + 3, NovaCraftBlocks.cracked_basal_bricks, 0, 2);
		world.setBlock(i + 25, j + 2, k + 3, NovaCraftBlocks.basal_bricks, 0, 2);
		world.setBlock(i + 26, j + 2, k + 3, NovaCraftBlocks.cracked_basal_bricks, 0, 2);
		world.setBlock(i + 27, j + 2, k + 3, NovaCraftBlocks.basal_bricks, 0, 2);
		world.setBlock(i + 0, j + 2, k + 4, NovaCraftBlocks.basal_bricks, 0, 2);
		world.setBlock(i + 1, j + 2, k + 4, NovaCraftBlocks.basal_bricks, 0, 2);
		world.setBlock(i + 2, j + 2, k + 4, NovaCraftBlocks.basal_bricks, 0, 2);
		world.setBlock(i + 3, j + 2, k + 4, NovaCraftBlocks.basal_bricks, 0, 2);
		world.setBlock(i + 4, j + 2, k + 4, NovaCraftBlocks.cracked_basal_bricks, 0, 2);
		world.setBlock(i + 5, j + 2, k + 4, NovaCraftBlocks.basal_bricks, 0, 2);
		world.setBlock(i + 6, j + 2, k + 4, NovaCraftBlocks.cracked_basal_bricks, 0, 2);
		world.setBlock(i + 7, j + 2, k + 4, NovaCraftBlocks.basal_bricks, 0, 2);
		world.setBlock(i + 8, j + 2, k + 4, NovaCraftBlocks.basal_bricks, 0, 2);
		world.setBlock(i + 9, j + 2, k + 4, NovaCraftBlocks.basal_bricks, 0, 2);
		world.setBlock(i + 10, j + 2, k + 4, NovaCraftBlocks.cracked_basal_bricks, 0, 2);
		world.setBlock(i + 11, j + 2, k + 4, NovaCraftBlocks.cracked_basal_bricks, 0, 2);
		world.setBlock(i + 12, j + 2, k + 4, NovaCraftBlocks.basal_bricks, 0, 2);
		world.setBlock(i + 13, j + 2, k + 4, NovaCraftBlocks.cracked_basal_bricks, 0, 2);
		world.setBlock(i + 14, j + 2, k + 4, NovaCraftBlocks.basal_bricks, 0, 2);
		world.setBlock(i + 15, j + 2, k + 4, NovaCraftBlocks.basal_bricks, 0, 2);
		world.setBlock(i + 16, j + 2, k + 4, NovaCraftBlocks.cracked_basal_bricks, 0, 2);
		world.setBlock(i + 17, j + 2, k + 4, NovaCraftBlocks.cracked_basal_bricks, 0, 2);
		world.setBlock(i + 18, j + 2, k + 4, NovaCraftBlocks.basal_bricks, 0, 2);
		world.setBlock(i + 19, j + 2, k + 4, NovaCraftBlocks.basal_bricks, 0, 2);
		world.setBlock(i + 20, j + 2, k + 4, NovaCraftBlocks.basal_bricks, 0, 2);
		world.setBlock(i + 21, j + 2, k + 4, NovaCraftBlocks.cracked_basal_bricks, 0, 2);
		world.setBlock(i + 22, j + 2, k + 4, NovaCraftBlocks.basal_bricks, 0, 2);
		world.setBlock(i + 23, j + 2, k + 4, NovaCraftBlocks.basal_bricks, 0, 2);
		world.setBlock(i + 24, j + 2, k + 4, NovaCraftBlocks.cracked_basal_bricks, 0, 2);
		world.setBlock(i + 25, j + 2, k + 4, NovaCraftBlocks.basal_bricks, 0, 2);
		world.setBlock(i + 26, j + 2, k + 4, NovaCraftBlocks.cracked_basal_bricks, 0, 2);
		world.setBlock(i + 27, j + 2, k + 4, NovaCraftBlocks.cracked_basal_bricks, 0, 2);
		world.setBlock(i + 0, j + 2, k + 5, NovaCraftBlocks.basal_bricks, 0, 2);
		world.setBlock(i + 1, j + 2, k + 5, NovaCraftBlocks.basal_bricks, 0, 2);
		world.setBlock(i + 2, j + 2, k + 5, NovaCraftBlocks.basal_bricks, 0, 2);
		world.setBlock(i + 3, j + 2, k + 5, NovaCraftBlocks.basal_bricks, 0, 2);
		world.setBlock(i + 4, j + 2, k + 5, NovaCraftBlocks.basal_bricks, 0, 2);
		world.setBlock(i + 5, j + 2, k + 5, NovaCraftBlocks.basal_bricks, 0, 2);
		world.setBlock(i + 6, j + 2, k + 5, NovaCraftBlocks.cracked_basal_bricks, 0, 2);
		world.setBlock(i + 7, j + 2, k + 5, NovaCraftBlocks.basal_bricks, 0, 2);
		world.setBlock(i + 8, j + 2, k + 5, NovaCraftBlocks.basal_bricks, 0, 2);
		world.setBlock(i + 9, j + 2, k + 5, NovaCraftBlocks.cracked_basal_bricks, 0, 2);
		world.setBlock(i + 10, j + 2, k + 5, NovaCraftBlocks.basal_bricks, 0, 2);
		world.setBlock(i + 11, j + 2, k + 5, NovaCraftBlocks.basal_bricks, 0, 2);
		world.setBlock(i + 12, j + 2, k + 5, NovaCraftBlocks.basal_bricks, 0, 2);
		world.setBlock(i + 13, j + 2, k + 5, NovaCraftBlocks.basal_bricks, 0, 2);
		world.setBlock(i + 14, j + 2, k + 5, NovaCraftBlocks.cracked_basal_bricks, 0, 2);
		world.setBlock(i + 15, j + 2, k + 5, NovaCraftBlocks.basal_bricks, 0, 2);
		world.setBlock(i + 16, j + 2, k + 5, NovaCraftBlocks.cracked_basal_bricks, 0, 2);
		world.setBlock(i + 17, j + 2, k + 5, NovaCraftBlocks.cracked_basal_bricks, 0, 2);
		world.setBlock(i + 18, j + 2, k + 5, NovaCraftBlocks.basal_bricks, 0, 2);
		world.setBlock(i + 19, j + 2, k + 5, NovaCraftBlocks.cracked_basal_bricks, 0, 2);
		world.setBlock(i + 20, j + 2, k + 5, NovaCraftBlocks.cracked_basal_bricks, 0, 2);
		world.setBlock(i + 21, j + 2, k + 5, NovaCraftBlocks.basal_bricks, 0, 2);
		world.setBlock(i + 22, j + 2, k + 5, NovaCraftBlocks.cracked_basal_bricks, 0, 2);
		world.setBlock(i + 23, j + 2, k + 5, NovaCraftBlocks.basal_bricks, 0, 2);
		world.setBlock(i + 24, j + 2, k + 5, NovaCraftBlocks.cracked_basal_bricks, 0, 2);
		world.setBlock(i + 25, j + 2, k + 5, NovaCraftBlocks.basal_bricks, 0, 2);
		world.setBlock(i + 26, j + 2, k + 5, NovaCraftBlocks.basal_bricks, 0, 2);
		world.setBlock(i + 27, j + 2, k + 5, NovaCraftBlocks.cracked_basal_bricks, 0, 2);
		world.setBlock(i + 0, j + 2, k + 6, NovaCraftBlocks.basal_bricks, 0, 2);
		world.setBlock(i + 1, j + 2, k + 6, NovaCraftBlocks.cracked_basal_bricks, 0, 2);
		world.setBlock(i + 2, j + 2, k + 6, NovaCraftBlocks.basal_bricks, 0, 2);
		world.setBlock(i + 3, j + 2, k + 6, NovaCraftBlocks.cracked_basal_bricks, 0, 2);
		world.setBlock(i + 4, j + 2, k + 6, NovaCraftBlocks.basal_bricks, 0, 2);
		world.setBlock(i + 5, j + 2, k + 6, NovaCraftBlocks.basal_bricks, 0, 2);
		world.setBlock(i + 6, j + 2, k + 6, NovaCraftBlocks.basal_bricks, 0, 2);
		world.setBlock(i + 7, j + 2, k + 6, NovaCraftBlocks.basal_bricks, 0, 2);
		world.setBlock(i + 8, j + 2, k + 6, NovaCraftBlocks.cracked_basal_bricks, 0, 2);
		world.setBlock(i + 9, j + 2, k + 6, NovaCraftBlocks.basal_bricks, 0, 2);
		world.setBlock(i + 10, j + 2, k + 6, NovaCraftBlocks.basal_bricks, 0, 2);
		world.setBlock(i + 11, j + 2, k + 6, NovaCraftBlocks.basal_bricks, 0, 2);
		world.setBlock(i + 12, j + 2, k + 6, NovaCraftBlocks.basal_bricks, 0, 2);
		world.setBlock(i + 13, j + 2, k + 6, NovaCraftBlocks.cracked_basal_bricks, 0, 2);
		world.setBlock(i + 14, j + 2, k + 6, NovaCraftBlocks.basal_bricks, 0, 2);
		world.setBlock(i + 15, j + 2, k + 6, NovaCraftBlocks.cracked_basal_bricks, 0, 2);
		world.setBlock(i + 16, j + 2, k + 6, NovaCraftBlocks.cracked_basal_bricks, 0, 2);
		world.setBlock(i + 17, j + 2, k + 6, NovaCraftBlocks.basal_bricks, 0, 2);
		world.setBlock(i + 18, j + 2, k + 6, NovaCraftBlocks.cracked_basal_bricks, 0, 2);
		world.setBlock(i + 19, j + 2, k + 6, NovaCraftBlocks.basal_bricks, 0, 2);
		world.setBlock(i + 20, j + 2, k + 6, NovaCraftBlocks.basal_bricks, 0, 2);
		world.setBlock(i + 21, j + 2, k + 6, NovaCraftBlocks.cracked_basal_bricks, 0, 2);
		world.setBlock(i + 22, j + 2, k + 6, NovaCraftBlocks.basal_bricks, 0, 2);
		world.setBlock(i + 23, j + 2, k + 6, NovaCraftBlocks.basal_bricks, 0, 2);
		world.setBlock(i + 24, j + 2, k + 6, NovaCraftBlocks.basal_bricks, 0, 2);
		world.setBlock(i + 25, j + 2, k + 6, NovaCraftBlocks.basal_bricks, 0, 2);
		world.setBlock(i + 26, j + 2, k + 6, NovaCraftBlocks.basal_bricks, 0, 2);
		world.setBlock(i + 27, j + 2, k + 6, NovaCraftBlocks.cracked_basal_bricks, 0, 2);
		world.setBlock(i + 0, j + 2, k + 7, NovaCraftBlocks.basal_bricks, 0, 2);
		world.setBlock(i + 1, j + 2, k + 7, NovaCraftBlocks.cracked_basal_bricks, 0, 2);
