package com.NovaCraft.world.bastion.treasure;

import cpw.mods.fml.common.registry.GameRegistry;
import net.minecraft.world.gen.feature.*;
import net.minecraft.block.*;
import net.minecraft.world.*;
import java.util.*;

import com.NovaCraft.config.Configs;
import com.NovaCraft.registry.OtherModBlocks;
import com.NovaCraftBlocks.NovaCraftBlocks;

import cpw.mods.fml.common.Loader;
import net.minecraft.init.*;

public class BastionTreasureBarracksGen1 extends WorldGenerator
{
	public BastionTreasureBarracksGen1() {

	}
	
	private Block PlaceMagma;
	
	private Block determineIfMagmaExists(World world, int x, int y, int z) {
		Block existingBlock = world.getBlock(x, y, z);
		if (!(Configs.disableMagmaBlock) && Loader.isModLoaded("etfuturum")) {
			try {
				Block magma = GameRegistry.findBlock("etfuturum", "magma");
				if (magma != null && (existingBlock == null || existingBlock != magma)) {
					return magma;
				}
			} catch (Exception ex) {
				if (Configs.enableDebugMode) {
					System.out.println("Missing Magma from Et Futurum Requiem, using Gravel instead...");
				}
				return Blocks.gravel;
			}
		}

		return Blocks.gravel;
    }
    
    public boolean generate(final World world, final Random random, final int i, final int j, final int k) {
    	PlaceMagma = determineIfMagmaExists(world, i + 1, j + 0, k + 1);
    	
    	world.setBlock(i + 0, j + 0, k + 0, Blocks.lava, 0, 2);
		world.setBlock(i + 1, j + 0, k + 0, Blocks.lava, 0, 2);
		world.setBlock(i + 2, j + 0, k + 0, Blocks.lava, 0, 2);
		world.setBlock(i + 3, j + 0, k + 0, Blocks.lava, 0, 2);
		world.setBlock(i + 4, j + 0, k + 0, Blocks.lava, 0, 2);
		world.setBlock(i + 5, j + 0, k + 0, Blocks.lava, 0, 2);
		world.setBlock(i + 6, j + 0, k + 0, Blocks.lava, 0, 2);
		world.setBlock(i + 7, j + 0, k + 0, Blocks.lava, 0, 2);
		world.setBlock(i + 8, j + 0, k + 0, Blocks.lava, 0, 2);
		world.setBlock(i + 9, j + 0, k + 0, Blocks.lava, 0, 2);
		world.setBlock(i + 10, j + 0, k + 0, Blocks.lava, 0, 2);
		world.setBlock(i + 11, j + 0, k + 0, Blocks.lava, 0, 2);
		world.setBlock(i + 12, j + 0, k + 0, Blocks.lava, 0, 2);
		world.setBlock(i + 13, j + 0, k + 0, Blocks.lava, 0, 2);
		world.setBlock(i + 14, j + 0, k + 0, Blocks.lava, 0, 2);
		world.setBlock(i + 15, j + 0, k + 0, Blocks.lava, 0, 2);
		world.setBlock(i + 16, j + 0, k + 0, Blocks.lava, 0, 2);
		world.setBlock(i + 17, j + 0, k + 0, Blocks.lava, 0, 2);
		world.setBlock(i + 18, j + 0, k + 0, Blocks.lava, 0, 2);
		world.setBlock(i + 19, j + 0, k + 0, Blocks.lava, 0, 2);
		world.setBlock(i + 20, j + 0, k + 0, Blocks.lava, 0, 2);
		world.setBlock(i + 21, j + 0, k + 0, Blocks.lava, 0, 2);
		world.setBlock(i + 22, j + 0, k + 0, Blocks.lava, 0, 2);
		world.setBlock(i + 23, j + 0, k + 0, Blocks.lava, 0, 2);
		world.setBlock(i + 24, j + 0, k + 0, Blocks.lava, 0, 2);
		world.setBlock(i + 25, j + 0, k + 0, Blocks.lava, 0, 2);
		world.setBlock(i + 26, j + 0, k + 0, Blocks.lava, 0, 2);
		world.setBlock(i + 27, j + 0, k + 0, Blocks.lava, 0, 2);
		world.setBlock(i + 0, j + 0, k + 1, NovaCraftBlocks.cracked_basal_bricks, 0, 2);
		world.setBlock(i + 1, j + 0, k + 1, PlaceMagma, 0, 2);
		world.setBlock(i + 2, j + 0, k + 1, Blocks.lava, 0, 2);
		world.setBlock(i + 3, j + 0, k + 1, Blocks.lava, 0, 2);
		world.setBlock(i + 4, j + 0, k + 1, NovaCraftBlocks.cracked_basal_bricks, 0, 2);
		world.setBlock(i + 5, j + 0, k + 1, NovaCraftBlocks.cracked_basal_bricks, 0, 2);
		world.setBlock(i + 6, j + 0, k + 1, Blocks.lava, 0, 2);
		world.setBlock(i + 7, j + 0, k + 1, Blocks.lava, 0, 2);
		world.setBlock(i + 8, j + 0, k + 1, NovaCraftBlocks.basal, 0, 2);
		world.setBlock(i + 9, j + 0, k + 1, NovaCraftBlocks.basal, 0, 2);
		world.setBlock(i + 10, j + 0, k + 1, Blocks.lava, 0, 2);
		world.setBlock(i + 11, j + 0, k + 1, Blocks.lava, 0, 2);
		world.setBlock(i + 12, j + 0, k + 1, NovaCraftBlocks.basal, 0, 2);
		world.setBlock(i + 13, j + 0, k + 1, NovaCraftBlocks.basal, 0, 2);
		world.setBlock(i + 14, j + 0, k + 1, Blocks.lava, 0, 2);
		world.setBlock(i + 15, j + 0, k + 1, Blocks.lava, 0, 2);
		world.setBlock(i + 16, j + 0, k + 1, Blocks.lava, 0, 2);
		world.setBlock(i + 17, j + 0, k + 1, Blocks.lava, 0, 2);
		world.setBlock(i + 18, j + 0, k + 1, Blocks.lava, 0, 2);
		world.setBlock(i + 19, j + 0, k + 1, Blocks.lava, 0, 2);
		world.setBlock(i + 20, j + 0, k + 1, Blocks.lava, 0, 2);
		world.setBlock(i + 21, j + 0, k + 1, Blocks.lava, 0, 2);
		world.setBlock(i + 22, j + 0, k + 1, Blocks.lava, 0, 2);
		world.setBlock(i + 23, j + 0, k + 1, Blocks.lava, 0, 2);
		world.setBlock(i + 24, j + 0, k + 1, Blocks.lava, 0, 2);
		world.setBlock(i + 25, j + 0, k + 1, Blocks.lava, 0, 2);
		world.setBlock(i + 26, j + 0, k + 1, Blocks.lava, 0, 2);
		world.setBlock(i + 27, j + 0, k + 1, Blocks.lava, 0, 2);
		world.setBlock(i + 0, j + 0, k + 2, NovaCraftBlocks.basal, 0, 2);
		world.setBlock(i + 1, j + 0, k + 2, NovaCraftBlocks.basal, 0, 2);
		world.setBlock(i + 2, j + 0, k + 2, NovaCraftBlocks.basal, 0, 2);
		world.setBlock(i + 3, j + 0, k + 2, NovaCraftBlocks.basal, 0, 2);
		world.setBlock(i + 4, j + 0, k + 2, NovaCraftBlocks.basal, 0, 2);
		world.setBlock(i + 5, j + 0, k + 2, NovaCraftBlocks.basal, 0, 2);
		world.setBlock(i + 6, j + 0, k + 2, NovaCraftBlocks.basal, 0, 2);
		world.setBlock(i + 7, j + 0, k + 2, NovaCraftBlocks.basal, 0, 2);
		world.setBlock(i + 8, j + 0, k + 2, NovaCraftBlocks.basal, 0, 2);
		world.setBlock(i + 9, j + 0, k + 2, NovaCraftBlocks.basal, 0, 2);
		world.setBlock(i + 10, j + 0, k + 2, NovaCraftBlocks.basal, 0, 2);
		world.setBlock(i + 11, j + 0, k + 2, NovaCraftBlocks.basal, 0, 2);
		world.setBlock(i + 12, j + 0, k + 2, NovaCraftBlocks.basal, 0, 2);
		world.setBlock(i + 13, j + 0, k + 2, NovaCraftBlocks.basal, 0, 2);
		world.setBlock(i + 14, j + 0, k + 2, Blocks.lava, 0, 2);
		world.setBlock(i + 15, j + 0, k + 2, Blocks.lava, 0, 2);
		world.setBlock(i + 16, j + 0, k + 2, Blocks.lava, 0, 2);
		world.setBlock(i + 17, j + 0, k + 2, Blocks.lava, 0, 2);
		world.setBlock(i + 18, j + 0, k + 2, Blocks.lava, 0, 2);
		world.setBlock(i + 19, j + 0, k + 2, Blocks.lava, 0, 2);
		world.setBlock(i + 20, j + 0, k + 2, Blocks.lava, 0, 2);
		world.setBlock(i + 21, j + 0, k + 2, Blocks.lava, 0, 2);
		world.setBlock(i + 22, j + 0, k + 2, Blocks.lava, 0, 2);
		world.setBlock(i + 23, j + 0, k + 2, Blocks.lava, 0, 2);
		world.setBlock(i + 24, j + 0, k + 2, Blocks.lava, 0, 2);
		world.setBlock(i + 25, j + 0, k + 2, Blocks.lava, 0, 2);
		world.setBlock(i + 26, j + 0, k + 2, Blocks.lava, 0, 2);
		world.setBlock(i + 27, j + 0, k + 2, Blocks.lava, 0, 2);
		world.setBlock(i + 0, j + 0, k + 3, NovaCraftBlocks.basal, 0, 2);
		world.setBlock(i + 1, j + 0, k + 3, NovaCraftBlocks.basal, 0, 2);
		world.setBlock(i + 2, j + 0, k + 3, NovaCraftBlocks.basal, 0, 2);
		world.setBlock(i + 3, j + 0, k + 3, NovaCraftBlocks.basal, 0, 2);
		world.setBlock(i + 4, j + 0, k + 3, NovaCraftBlocks.basal, 0, 2);
		world.setBlock(i + 5, j + 0, k + 3, NovaCraftBlocks.basal, 0, 2);
		world.setBlock(i + 6, j + 0, k + 3, NovaCraftBlocks.basal, 0, 2);
		world.setBlock(i + 7, j + 0, k + 3, NovaCraftBlocks.glowing_basal, 0, 2);
		world.setBlock(i + 8, j + 0, k + 3, NovaCraftBlocks.basal, 0, 2);
		world.setBlock(i + 9, j + 0, k + 3, NovaCraftBlocks.basal, 0, 2);
		world.setBlock(i + 10, j + 0, k + 3, NovaCraftBlocks.basal, 0, 2);
		world.setBlock(i + 11, j + 0, k + 3, NovaCraftBlocks.basal, 0, 2);
		world.setBlock(i + 12, j + 0, k + 3, NovaCraftBlocks.basal, 0, 2);
		world.setBlock(i + 13, j + 0, k + 3, NovaCraftBlocks.basal, 0, 2);
		world.setBlock(i + 14, j + 0, k + 3, NovaCraftBlocks.cracked_basal_bricks, 0, 2);
		world.setBlock(i + 15, j + 0, k + 3, NovaCraftBlocks.cracked_basal_bricks, 0, 2);
		world.setBlock(i + 16, j + 0, k + 3, Blocks.lava, 0, 2);
		world.setBlock(i + 17, j + 0, k + 3, Blocks.lava, 0, 2);
		world.setBlock(i + 18, j + 0, k + 3, PlaceMagma, 0, 2);
		world.setBlock(i + 19, j + 0, k + 3, NovaCraftBlocks.cracked_basal_bricks, 0, 2);
		world.setBlock(i + 20, j + 0, k + 3, Blocks.lava, 0, 2);
		world.setBlock(i + 21, j + 0, k + 3, Blocks.lava, 0, 2);
		world.setBlock(i + 22, j + 0, k + 3, NovaCraftBlocks.basal, 0, 2);
		world.setBlock(i + 23, j + 0, k + 3, NovaCraftBlocks.basal, 0, 2);
		world.setBlock(i + 24, j + 0, k + 3, Blocks.lava, 0, 2);
		world.setBlock(i + 25, j + 0, k + 3, Blocks.lava, 0, 2);
		world.setBlock(i + 26, j + 0, k + 3, NovaCraftBlocks.basal, 0, 2);
		world.setBlock(i + 27, j + 0, k + 3, NovaCraftBlocks.basal, 0, 2);
		world.setBlock(i + 0, j + 0, k + 4, NovaCraftBlocks.basal, 0, 2);
		world.setBlock(i + 1, j + 0, k + 4, NovaCraftBlocks.basal, 0, 2);
		world.setBlock(i + 2, j + 0, k + 4, NovaCraftBlocks.basal, 0, 2);
		world.setBlock(i + 3, j + 0, k + 4, NovaCraftBlocks.glowing_basal, 0, 2);
		world.setBlock(i + 4, j + 0, k + 4, NovaCraftBlocks.basal, 0, 2);
		world.setBlock(i + 5, j + 0, k + 4, NovaCraftBlocks.basal, 0, 2);
		world.setBlock(i + 6, j + 0, k + 4, NovaCraftBlocks.basal, 0, 2);
		world.setBlock(i + 7, j + 0, k + 4, NovaCraftBlocks.basal, 0, 2);
		world.setBlock(i + 8, j + 0, k + 4, NovaCraftBlocks.basal, 0, 2);
		world.setBlock(i + 9, j + 0, k + 4, NovaCraftBlocks.basal, 0, 2);
		world.setBlock(i + 10, j + 0, k + 4, NovaCraftBlocks.basal, 0, 2);
		world.setBlock(i + 11, j + 0, k + 4, NovaCraftBlocks.basal, 0, 2);
		world.setBlock(i + 12, j + 0, k + 4, NovaCraftBlocks.basal, 0, 2);
		world.setBlock(i + 13, j + 0, k + 4, NovaCraftBlocks.basal, 0, 2);
		world.setBlock(i + 14, j + 0, k + 4, NovaCraftBlocks.basal, 0, 2);
		world.setBlock(i + 15, j + 0, k + 4, NovaCraftBlocks.basal, 0, 2);
		world.setBlock(i + 16, j + 0, k + 4, NovaCraftBlocks.basal, 0, 2);
		world.setBlock(i + 17, j + 0, k + 4, NovaCraftBlocks.basal, 0, 2);
		world.setBlock(i + 18, j + 0, k + 4, NovaCraftBlocks.basal, 0, 2);
		world.setBlock(i + 19, j + 0, k + 4, NovaCraftBlocks.basal, 0, 2);
		world.setBlock(i + 20, j + 0, k + 4, NovaCraftBlocks.basal, 0, 2);
		world.setBlock(i + 21, j + 0, k + 4, NovaCraftBlocks.basal, 0, 2);
		world.setBlock(i + 22, j + 0, k + 4, NovaCraftBlocks.basal, 0, 2);
		world.setBlock(i + 23, j + 0, k + 4, NovaCraftBlocks.basal, 0, 2);
		world.setBlock(i + 24, j + 0, k + 4, NovaCraftBlocks.basal, 0, 2);
		world.setBlock(i + 25, j + 0, k + 4, NovaCraftBlocks.basal, 0, 2);
		world.setBlock(i + 26, j + 0, k + 4, NovaCraftBlocks.basal, 0, 2);
		world.setBlock(i + 27, j + 0, k + 4, NovaCraftBlocks.basal, 0, 2);
		world.setBlock(i + 0, j + 0, k + 5, NovaCraftBlocks.basal, 0, 2);
		world.setBlock(i + 1, j + 0, k + 5, NovaCraftBlocks.basal, 0, 2);
		world.setBlock(i + 2, j + 0, k + 5, NovaCraftBlocks.basal, 0, 2);
		world.setBlock(i + 3, j + 0, k + 5, NovaCraftBlocks.basal, 0, 2);
		world.setBlock(i + 4, j + 0, k + 5, NovaCraftBlocks.basal, 0, 2);
		world.setBlock(i + 5, j + 0, k + 5, NovaCraftBlocks.basal, 0, 2);
		world.setBlock(i + 6, j + 0, k + 5, NovaCraftBlocks.basal, 0, 2);
		world.setBlock(i + 7, j + 0, k + 5, NovaCraftBlocks.basal, 0, 2);
		world.setBlock(i + 8, j + 0, k + 5, NovaCraftBlocks.basal, 0, 2);
		world.setBlock(i + 9, j + 0, k + 5, NovaCraftBlocks.basal, 0, 2);
		world.setBlock(i + 10, j + 0, k + 5, NovaCraftBlocks.basal, 0, 2);
		world.setBlock(i + 11, j + 0, k + 5, NovaCraftBlocks.basal, 0, 2);
		world.setBlock(i + 12, j + 0, k + 5, NovaCraftBlocks.basal, 0, 2);
		world.setBlock(i + 13, j + 0, k + 5, NovaCraftBlocks.basal, 0, 2);
		world.setBlock(i + 14, j + 0, k + 5, NovaCraftBlocks.basal, 0, 2);
		world.setBlock(i + 15, j + 0, k + 5, NovaCraftBlocks.basal, 0, 2);
		world.setBlock(i + 16, j + 0, k + 5, NovaCraftBlocks.basal, 0, 2);
		world.setBlock(i + 17, j + 0, k + 5, NovaCraftBlocks.basal, 0, 2);
		world.setBlock(i + 18, j + 0, k + 5, NovaCraftBlocks.basal, 0, 2);
		world.setBlock(i + 19, j + 0, k + 5, NovaCraftBlocks.basal, 0, 2);
		world.setBlock(i + 20, j + 0, k + 5, NovaCraftBlocks.basal, 0, 2);
		world.setBlock(i + 21, j + 0, k + 5, NovaCraftBlocks.basal, 0, 2);
		world.setBlock(i + 22, j + 0, k + 5, NovaCraftBlocks.basal, 0, 2);
		world.setBlock(i + 23, j + 0, k + 5, NovaCraftBlocks.basal, 0, 2);
		world.setBlock(i + 24, j + 0, k + 5, NovaCraftBlocks.basal, 0, 2);
		world.setBlock(i + 25, j + 0, k + 5, NovaCraftBlocks.basal, 0, 2);
		world.setBlock(i + 26, j + 0, k + 5, NovaCraftBlocks.basal, 0, 2);
		world.setBlock(i + 27, j + 0, k + 5, NovaCraftBlocks.basal, 0, 2);
		world.setBlock(i + 0, j + 0, k + 6, NovaCraftBlocks.basal, 0, 2);
		world.setBlock(i + 1, j + 0, k + 6, NovaCraftBlocks.basal, 0, 2);
		world.setBlock(i + 2, j + 0, k + 6, NovaCraftBlocks.basal, 0, 2);
		world.setBlock(i + 3, j + 0, k + 6, NovaCraftBlocks.basal, 0, 2);
		world.setBlock(i + 4, j + 0, k + 6, NovaCraftBlocks.basal, 0, 2);
		world.setBlock(i + 5, j + 0, k + 6, NovaCraftBlocks.basal, 0, 2);
		world.setBlock(i + 6, j + 0, k + 6, NovaCraftBlocks.basal, 0, 2);
		world.setBlock(i + 7, j + 0, k + 6, NovaCraftBlocks.basal, 0, 2);
		world.setBlock(i + 8, j + 0, k + 6, NovaCraftBlocks.basal, 0, 2);
		world.setBlock(i + 9, j + 0, k + 6, NovaCraftBlocks.basal, 0, 2);
		world.setBlock(i + 10, j + 0, k + 6, NovaCraftBlocks.basal, 0, 2);
		world.setBlock(i + 11, j + 0, k + 6, NovaCraftBlocks.basal, 0, 2);
		world.setBlock(i + 12, j + 0, k + 6, NovaCraftBlocks.basal, 0, 2);
		world.setBlock(i + 13, j + 0, k + 6, NovaCraftBlocks.basal, 0, 2);
		world.setBlock(i + 14, j + 0, k + 6, NovaCraftBlocks.basal, 0, 2);
		world.setBlock(i + 15, j + 0, k + 6, NovaCraftBlocks.basal, 0, 2);
		world.setBlock(i + 16, j + 0, k + 6, NovaCraftBlocks.basal, 0, 2);
		world.setBlock(i + 17, j + 0, k + 6, NovaCraftBlocks.basal, 0, 2);
		world.setBlock(i + 18, j + 0, k + 6, NovaCraftBlocks.basal, 0, 2);
		world.setBlock(i + 19, j + 0, k + 6, NovaCraftBlocks.basal, 0, 2);
		world.setBlock(i + 20, j + 0, k + 6, NovaCraftBlocks.basal, 0, 2);
		world.setBlock(i + 21, j + 0, k + 6, NovaCraftBlocks.basal, 0, 2);
		world.setBlock(i + 22, j + 0, k + 6, NovaCraftBlocks.basal, 0, 2);
		world.setBlock(i + 23, j + 0, k + 6, NovaCraftBlocks.basal, 0, 2);
		world.setBlock(i + 24, j + 0, k + 6, NovaCraftBlocks.basal, 0, 2);
		world.setBlock(i + 25, j + 0, k + 6, NovaCraftBlocks.basal, 0, 2);
		world.setBlock(i + 26, j + 0, k + 6, NovaCraftBlocks.basal, 0, 2);
		world.setBlock(i + 27, j + 0, k + 6, NovaCraftBlocks.basal, 0, 2);
		world.setBlock(i + 0, j + 0, k + 7, NovaCraftBlocks.basal, 0, 2);
		world.setBlock(i + 1, j + 0, k + 7, NovaCraftBlocks.basal, 0, 2);
		world.setBlock(i + 2, j + 0, k + 7, NovaCraftBlocks.basal, 0, 2);
		world.setBlock(i + 3, j + 0, k + 7, NovaCraftBlocks.basal, 0, 2);
		world.setBlock(i + 4, j + 0, k + 7, NovaCraftBlocks.basal, 0, 2);
		world.setBlock(i + 5, j + 0, k + 7, NovaCraftBlocks.basal, 0, 2);
		world.setBlock(i + 6, j + 0, k + 7, NovaCraftBlocks.basal, 0, 2);
		world.setBlock(i + 7, j + 0, k + 7, NovaCraftBlocks.basal, 0, 2);
		world.setBlock(i + 8, j + 0, k + 7, NovaCraftBlocks.basal, 0, 2);
		world.setBlock(i + 9, j + 0, k + 7, NovaCraftBlocks.basal, 0, 2);
		world.setBlock(i + 10, j + 0, k + 7, NovaCraftBlocks.basal, 0, 2);
		world.setBlock(i + 11, j + 0, k + 7, NovaCraftBlocks.basal, 0, 2);
		world.setBlock(i + 12, j + 0, k + 7, NovaCraftBlocks.basal, 0, 2);
		world.setBlock(i + 13, j + 0, k + 7, NovaCraftBlocks.basal, 0, 2);
		world.setBlock(i + 14, j + 0, k + 7, NovaCraftBlocks.basal, 0, 2);
		world.setBlock(i + 15, j + 0, k + 7, NovaCraftBlocks.basal, 0, 2);
		world.setBlock(i + 16, j + 0, k + 7, NovaCraftBlocks.basal, 0, 2);
		world.setBlock(i + 17, j + 0, k + 7, NovaCraftBlocks.basal, 0, 2);
		world.setBlock(i + 18, j + 0, k + 7, NovaCraftBlocks.basal, 0, 2);
		world.setBlock(i + 19, j + 0, k + 7, NovaCraftBlocks.basal, 0, 2);
		world.setBlock(i + 20, j + 0, k + 7, NovaCraftBlocks.basal, 0, 2);
		world.setBlock(i + 21, j + 0, k + 7, NovaCraftBlocks.basal, 0, 2);
		world.setBlock(i + 22, j + 0, k + 7, NovaCraftBlocks.basal, 0, 2);
		world.setBlock(i + 23, j + 0, k + 7, NovaCraftBlocks.basal, 0, 2);
		world.setBlock(i + 24, j + 0, k + 7, NovaCraftBlocks.basal, 0, 2);
		world.setBlock(i + 25, j + 0, k + 7, NovaCraftBlocks.basal, 0, 2);
		world.setBlock(i + 26, j + 0, k + 7, NovaCraftBlocks.basal, 0, 2);
		world.setBlock(i + 27, j + 0, k + 7, NovaCraftBlocks.basal, 0, 2);
		world.setBlock(i + 0, j + 0, k + 8, NovaCraftBlocks.basal, 0, 2);
		world.setBlock(i + 1, j + 0, k + 8, NovaCraftBlocks.basal, 0, 2);
		world.setBlock(i + 2, j + 0, k + 8, NovaCraftBlocks.basal, 0, 2);
		world.setBlock(i + 3, j + 0, k + 8, NovaCraftBlocks.basal, 0, 2);
		world.setBlock(i + 4, j + 0, k + 8, NovaCraftBlocks.basal, 0, 2);
		world.setBlock(i + 5, j + 0, k + 8, NovaCraftBlocks.basal, 0, 2);
		world.setBlock(i + 6, j + 0, k + 8, NovaCraftBlocks.basal, 0, 2);
		world.setBlock(i + 7, j + 0, k + 8, NovaCraftBlocks.basal, 0, 2);
		world.setBlock(i + 8, j + 0, k + 8, NovaCraftBlocks.basal, 0, 2);
		world.setBlock(i + 9, j + 0, k + 8, NovaCraftBlocks.basal, 0, 2);
		world.setBlock(i + 10, j + 0, k + 8, NovaCraftBlocks.basal, 0, 2);
		world.setBlock(i + 11, j + 0, k + 8, NovaCraftBlocks.basal, 0, 2);
		world.setBlock(i + 12, j + 0, k + 8, NovaCraftBlocks.basal, 0, 2);
		world.setBlock(i + 13, j + 0, k + 8, NovaCraftBlocks.basal, 0, 2);
		world.setBlock(i + 14, j + 0, k + 8, NovaCraftBlocks.basal, 0, 2);
		world.setBlock(i + 15, j + 0, k + 8, NovaCraftBlocks.basal, 0, 2);
		world.setBlock(i + 16, j + 0, k + 8, NovaCraftBlocks.basal, 0, 2);
		world.setBlock(i + 17, j + 0, k + 8, NovaCraftBlocks.basal, 0, 2);
		world.setBlock(i + 18, j + 0, k + 8, NovaCraftBlocks.basal, 0, 2);
		world.setBlock(i + 19, j + 0, k + 8, NovaCraftBlocks.basal, 0, 2);
		world.setBlock(i + 20, j + 0, k + 8, NovaCraftBlocks.basal, 0, 2);
		world.setBlock(i + 21, j + 0, k + 8, NovaCraftBlocks.basal, 0, 2);
		world.setBlock(i + 22, j + 0, k + 8, NovaCraftBlocks.basal, 0, 2);
		world.setBlock(i + 23, j + 0, k + 8, NovaCraftBlocks.basal, 0, 2);
		world.setBlock(i + 24, j + 0, k + 8, NovaCraftBlocks.glowing_basal, 0, 2);
		world.setBlock(i + 25, j + 0, k + 8, NovaCraftBlocks.glowing_basal, 0, 2);
		world.setBlock(i + 26, j + 0, k + 8, NovaCraftBlocks.basal, 0, 2);
		world.setBlock(i + 27, j + 0, k + 8, NovaCraftBlocks.basal, 0, 2);
		world.setBlock(i + 0, j + 0, k + 9, NovaCraftBlocks.basal, 0, 2);
		world.setBlock(i + 1, j + 0, k + 9, NovaCraftBlocks.basal, 0, 2);
		world.setBlock(i + 2, j + 0, k + 9, NovaCraftBlocks.basal, 0, 2);
		world.setBlock(i + 3, j + 0, k + 9, NovaCraftBlocks.basal, 0, 2);
		world.setBlock(i + 4, j + 0, k + 9, NovaCraftBlocks.basal, 0, 2);
		world.setBlock(i + 5, j + 0, k + 9, NovaCraftBlocks.basal, 0, 2);
		world.setBlock(i + 6, j + 0, k + 9, NovaCraftBlocks.basal, 0, 2);
		world.setBlock(i + 7, j + 0, k + 9, NovaCraftBlocks.basal, 0, 2);
		world.setBlock(i + 8, j + 0, k + 9, NovaCraftBlocks.basal, 0, 2);
		world.setBlock(i + 9, j + 0, k + 9, NovaCraftBlocks.basal, 0, 2);
		world.setBlock(i + 10, j + 0, k + 9, NovaCraftBlocks.basal, 0, 2);
		world.setBlock(i + 11, j + 0, k + 9, NovaCraftBlocks.basal, 0, 2);
		world.setBlock(i + 12, j + 0, k + 9, NovaCraftBlocks.basal, 0, 2);
		world.setBlock(i + 13, j + 0, k + 9, NovaCraftBlocks.basal, 0, 2);
		world.setBlock(i + 14, j + 0, k + 9, NovaCraftBlocks.basal, 0, 2);
		world.setBlock(i + 15, j + 0, k + 9, NovaCraftBlocks.basal, 0, 2);
		world.setBlock(i + 16, j + 0, k + 9, NovaCraftBlocks.basal, 0, 2);
		world.setBlock(i + 17, j + 0, k + 9, NovaCraftBlocks.basal, 0, 2);
		world.setBlock(i + 18, j + 0, k + 9, NovaCraftBlocks.basal, 0, 2);
		world.setBlock(i + 19, j + 0, k + 9, NovaCraftBlocks.basal, 0, 2);
		world.setBlock(i + 20, j + 0, k + 9, NovaCraftBlocks.basal, 0, 2);
		world.setBlock(i + 21, j + 0, k + 9, NovaCraftBlocks.basal, 0, 2);
		world.setBlock(i + 22, j + 0, k + 9, NovaCraftBlocks.basal, 0, 2);
		world.setBlock(i + 23, j + 0, k + 9, NovaCraftBlocks.basal, 0, 2);
		world.setBlock(i + 24, j + 0, k + 9, NovaCraftBlocks.basal, 0, 2);
		world.setBlock(i + 25, j + 0, k + 9, NovaCraftBlocks.basal, 0, 2);
		world.setBlock(i + 26, j + 0, k + 9, NovaCraftBlocks.basal, 0, 2);
		world.setBlock(i + 27, j + 0, k + 9, NovaCraftBlocks.basal, 0, 2);
		world.setBlock(i + 0, j + 0, k + 10, Blocks.lava, 0, 2);
		world.setBlock(i + 1, j + 0, k + 10, NovaCraftBlocks.basal, 0, 2);
		world.setBlock(i + 2, j + 0, k + 10, NovaCraftBlocks.basal, 0, 2);
		world.setBlock(i + 3, j + 0, k + 10, NovaCraftBlocks.basal, 0, 2);
		world.setBlock(i + 4, j + 0, k + 10, NovaCraftBlocks.basal, 0, 2);
		world.setBlock(i + 5, j + 0, k + 10, NovaCraftBlocks.basal, 0, 2);
		world.setBlock(i + 6, j + 0, k + 10, NovaCraftBlocks.basal, 0, 2);
		world.setBlock(i + 7, j + 0, k + 10, NovaCraftBlocks.basal, 0, 2);
		world.setBlock(i + 8, j + 0, k + 10, NovaCraftBlocks.basal, 0, 2);
		world.setBlock(i + 9, j + 0, k + 10, NovaCraftBlocks.basal, 0, 2);
		world.setBlock(i + 10, j + 0, k + 10, NovaCraftBlocks.basal, 0, 2);
		world.setBlock(i + 11, j + 0, k + 10, NovaCraftBlocks.basal, 0, 2);
		world.setBlock(i + 12, j + 0, k + 10, NovaCraftBlocks.basal, 0, 2);
		world.setBlock(i + 13, j + 0, k + 10, NovaCraftBlocks.basal, 0, 2);
		world.setBlock(i + 14, j + 0, k + 10, NovaCraftBlocks.basal, 0, 2);
		world.setBlock(i + 15, j + 0, k + 10, NovaCraftBlocks.basal, 0, 2);
		world.setBlock(i + 16, j + 0, k + 10, NovaCraftBlocks.basal, 0, 2);
		world.setBlock(i + 17, j + 0, k + 10, NovaCraftBlocks.basal, 0, 2);
		world.setBlock(i + 18, j + 0, k + 10, NovaCraftBlocks.basal, 0, 2);
		world.setBlock(i + 19, j + 0, k + 10, NovaCraftBlocks.basal, 0, 2);
		world.setBlock(i + 20, j + 0, k + 10, NovaCraftBlocks.basal, 0, 2);
		world.setBlock(i + 21, j + 0, k + 10, NovaCraftBlocks.basal, 0, 2);
		world.setBlock(i + 22, j + 0, k + 10, NovaCraftBlocks.basal, 0, 2);
		world.setBlock(i + 23, j + 0, k + 10, NovaCraftBlocks.basal, 0, 2);
		world.setBlock(i + 24, j + 0, k + 10, NovaCraftBlocks.basal, 0, 2);
		world.setBlock(i + 25, j + 0, k + 10, NovaCraftBlocks.glowing_basal, 0, 2);
		world.setBlock(i + 26, j + 0, k + 10, NovaCraftBlocks.basal, 0, 2);
		world.setBlock(i + 27, j + 0, k + 10, NovaCraftBlocks.basal, 0, 2);
		world.setBlock(i + 0, j + 0, k + 11, NovaCraftBlocks.basal_bricks, 0, 2);
		world.setBlock(i + 1, j + 0, k + 11, NovaCraftBlocks.basal_bricks, 0, 2);
		world.setBlock(i + 2, j + 0, k + 11, NovaCraftBlocks.basal_bricks, 0, 2);
		world.setBlock(i + 3, j + 0, k + 11, NovaCraftBlocks.cracked_basal_bricks, 0, 2);
		world.setBlock(i + 4, j + 0, k + 11, NovaCraftBlocks.basal_bricks, 0, 2);
		world.setBlock(i + 5, j + 0, k + 11, NovaCraftBlocks.cracked_basal_bricks, 0, 2);
		world.setBlock(i + 6, j + 0, k + 11, NovaCraftBlocks.basal_bricks, 0, 2);
		world.setBlock(i + 7, j + 0, k + 11, NovaCraftBlocks.basal_bricks, 0, 2);
		world.setBlock(i + 8, j + 0, k + 11, NovaCraftBlocks.basal_bricks, 0, 2);
		world.setBlock(i + 9, j + 0, k + 11, NovaCraftBlocks.cracked_basal_bricks, 0, 2);
		world.setBlock(i + 10, j + 0, k + 11, NovaCraftBlocks.basal_bricks, 0, 2);
		world.setBlock(i + 11, j + 0, k + 11, NovaCraftBlocks.basal_bricks, 0, 2);
		world.setBlock(i + 12, j + 0, k + 11, NovaCraftBlocks.basal_bricks, 0, 2);
		world.setBlock(i + 13, j + 0, k + 11, NovaCraftBlocks.basal_bricks, 0, 2);
		world.setBlock(i + 14, j + 0, k + 11, NovaCraftBlocks.basal, 0, 2);
		world.setBlock(i + 15, j + 0, k + 11, NovaCraftBlocks.basal, 0, 2);
		world.setBlock(i + 16, j + 0, k + 11, NovaCraftBlocks.basal, 0, 2);
		world.setBlock(i + 17, j + 0, k + 11, NovaCraftBlocks.basal, 0, 2);
		world.setBlock(i + 18, j + 0, k + 11, NovaCraftBlocks.basal, 0, 2);
		world.setBlock(i + 19, j + 0, k + 11, NovaCraftBlocks.glowing_basal, 0, 2);
		world.setBlock(i + 20, j + 0, k + 11, NovaCraftBlocks.basal, 0, 2);
		world.setBlock(i + 21, j + 0, k + 11, NovaCraftBlocks.basal, 0, 2);
		world.setBlock(i + 22, j + 0, k + 11, NovaCraftBlocks.basal, 0, 2);
		world.setBlock(i + 23, j + 0, k + 11, NovaCraftBlocks.basal, 0, 2);
		world.setBlock(i + 24, j + 0, k + 11, NovaCraftBlocks.basal, 0, 2);
		world.setBlock(i + 25, j + 0, k + 11, NovaCraftBlocks.basal, 0, 2);
		world.setBlock(i + 26, j + 0, k + 11, NovaCraftBlocks.basal, 0, 2);
		world.setBlock(i + 27, j + 0, k + 11, NovaCraftBlocks.basal, 0, 2);
		world.setBlock(i + 0, j + 0, k + 12, NovaCraftBlocks.cracked_basal_bricks, 0, 2);
		world.setBlock(i + 1, j + 0, k + 12, NovaCraftBlocks.cracked_basal_bricks, 0, 2);
		world.setBlock(i + 2, j + 0, k + 12, NovaCraftBlocks.basal_bricks, 0, 2);
		world.setBlock(i + 3, j + 0, k + 12, NovaCraftBlocks.basal_bricks, 0, 2);
		world.setBlock(i + 4, j + 0, k + 12, NovaCraftBlocks.basal_bricks, 0, 2);
		world.setBlock(i + 5, j + 0, k + 12, NovaCraftBlocks.basal_bricks, 0, 2);
		world.setBlock(i + 6, j + 0, k + 12, NovaCraftBlocks.basal_bricks, 0, 2);
		world.setBlock(i + 7, j + 0, k + 12, NovaCraftBlocks.cracked_basal_bricks, 0, 2);
		world.setBlock(i + 8, j + 0, k + 12, NovaCraftBlocks.basal_bricks, 0, 2);
		world.setBlock(i + 9, j + 0, k + 12, NovaCraftBlocks.basal_bricks, 0, 2);
		world.setBlock(i + 10, j + 0, k + 12, NovaCraftBlocks.basal_bricks, 0, 2);
		world.setBlock(i + 11, j + 0, k + 12, NovaCraftBlocks.cracked_basal_bricks, 0, 2);
		world.setBlock(i + 12, j + 0, k + 12, NovaCraftBlocks.basal_bricks, 0, 2);
		world.setBlock(i + 13, j + 0, k + 12, NovaCraftBlocks.cracked_basal_bricks, 0, 2);
		world.setBlock(i + 14, j + 0, k + 12, Blocks.lava, 0, 2);
		world.setBlock(i + 15, j + 0, k + 12, NovaCraftBlocks.basal, 0, 2);
		world.setBlock(i + 16, j + 0, k + 12, NovaCraftBlocks.basal, 0, 2);
		world.setBlock(i + 17, j + 0, k + 12, NovaCraftBlocks.basal, 0, 2);
		world.setBlock(i + 18, j + 0, k + 12, NovaCraftBlocks.basal, 0, 2);
		world.setBlock(i + 19, j + 0, k + 12, NovaCraftBlocks.basal, 0, 2);
		world.setBlock(i + 20, j + 0, k + 12, NovaCraftBlocks.basal, 0, 2);
		world.setBlock(i + 21, j + 0, k + 12, NovaCraftBlocks.basal, 0, 2);
		world.setBlock(i + 22, j + 0, k + 12, NovaCraftBlocks.basal, 0, 2);
		world.setBlock(i + 23, j + 0, k + 12, NovaCraftBlocks.basal, 0, 2);
		world.setBlock(i + 24, j + 0, k + 12, NovaCraftBlocks.basal, 0, 2);
		world.setBlock(i + 25, j + 0, k + 12, NovaCraftBlocks.basal, 0, 2);
		world.setBlock(i + 26, j + 0, k + 12, NovaCraftBlocks.basal, 0, 2);
		world.setBlock(i + 27, j + 0, k + 12, NovaCraftBlocks.basal, 0, 2);
		world.setBlock(i + 0, j + 1, k + 0, Blocks.lava, 0, 2);
		world.setBlock(i + 1, j + 1, k + 0, Blocks.lava, 0, 2);
		world.setBlock(i + 2, j + 1, k + 0, Blocks.lava, 0, 2);
		world.setBlock(i + 3, j + 1, k + 0, Blocks.lava, 0, 2);
		world.setBlock(i + 4, j + 1, k + 0, Blocks.lava, 0, 2);
		world.setBlock(i + 5, j + 1, k + 0, Blocks.lava, 0, 2);
		world.setBlock(i + 6, j + 1, k + 0, Blocks.lava, 0, 2);
		world.setBlock(i + 7, j + 1, k + 0, Blocks.lava, 0, 2);
		world.setBlock(i + 8, j + 1, k + 0, Blocks.lava, 0, 2);
		world.setBlock(i + 9, j + 1, k + 0, Blocks.lava, 0, 2);
		world.setBlock(i + 10, j + 1, k + 0, Blocks.lava, 0, 2);
		world.setBlock(i + 11, j + 1, k + 0, Blocks.lava, 0, 2);
		world.setBlock(i + 12, j + 1, k + 0, Blocks.lava, 0, 2);
		world.setBlock(i + 13, j + 1, k + 0, Blocks.lava, 0, 2);
		world.setBlock(i + 14, j + 1, k + 0, Blocks.lava, 0, 2);
		world.setBlock(i + 15, j + 1, k + 0, Blocks.lava, 0, 2);
		world.setBlock(i + 16, j + 1, k + 0, Blocks.lava, 0, 2);
		world.setBlock(i + 17, j + 1, k + 0, Blocks.lava, 0, 2);
		world.setBlock(i + 18, j + 1, k + 0, Blocks.lava, 0, 2);
		world.setBlock(i + 19, j + 1, k + 0, Blocks.lava, 0, 2);
		world.setBlock(i + 20, j + 1, k + 0, Blocks.lava, 0, 2);
		world.setBlock(i + 21, j + 1, k + 0, Blocks.lava, 0, 2);
		world.setBlock(i + 22, j + 1, k + 0, Blocks.lava, 0, 2);
		world.setBlock(i + 23, j + 1, k + 0, Blocks.lava, 0, 2);
		world.setBlock(i + 24, j + 1, k + 0, Blocks.lava, 0, 2);
		world.setBlock(i + 25, j + 1, k + 0, Blocks.lava, 0, 2);
		world.setBlock(i + 26, j + 1, k + 0, Blocks.lava, 0, 2);
		world.setBlock(i + 27, j + 1, k + 0, Blocks.lava, 0, 2);
		world.setBlock(i + 0, j + 1, k + 1, PlaceMagma, 0, 2);
		world.setBlock(i + 1, j + 1, k + 1, NovaCraftBlocks.cracked_basal_bricks, 0, 2);
		world.setBlock(i + 2, j + 1, k + 1, Blocks.lava, 0, 2);
		world.setBlock(i + 3, j + 1, k + 1, Blocks.lava, 0, 2);
		world.setBlock(i + 4, j + 1, k + 1, NovaCraftBlocks.cracked_basal_bricks, 0, 2);
		world.setBlock(i + 5, j + 1, k + 1, NovaCraftBlocks.cracked_basal_bricks, 0, 2);
		world.setBlock(i + 6, j + 1, k + 1, Blocks.lava, 0, 2);
		world.setBlock(i + 7, j + 1, k + 1, Blocks.lava, 0, 2);
		world.setBlock(i + 8, j + 1, k + 1, NovaCraftBlocks.basal, 0, 2);
		world.setBlock(i + 9, j + 1, k + 1, NovaCraftBlocks.basal, 0, 2);
		world.setBlock(i + 10, j + 1, k + 1, Blocks.lava, 0, 2);
		world.setBlock(i + 11, j + 1, k + 1, Blocks.lava, 0, 2);
		world.setBlock(i + 12, j + 1, k + 1, NovaCraftBlocks.basal, 0, 2);
		world.setBlock(i + 13, j + 1, k + 1, NovaCraftBlocks.basal, 0, 2);
		world.setBlock(i + 14, j + 1, k + 1, Blocks.lava, 0, 2);
		world.setBlock(i + 15, j + 1, k + 1, Blocks.lava, 0, 2);
		world.setBlock(i + 16, j + 1, k + 1, Blocks.lava, 0, 2);
		world.setBlock(i + 17, j + 1, k + 1, Blocks.lava, 0, 2);
		world.setBlock(i + 18, j + 1, k + 1, Blocks.lava, 0, 2);
		world.setBlock(i + 19, j + 1, k + 1, Blocks.lava, 0, 2);
		world.setBlock(i + 20, j + 1, k + 1, Blocks.lava, 0, 2);
		world.setBlock(i + 21, j + 1, k + 1, Blocks.lava, 0, 2);
		world.setBlock(i + 22, j + 1, k + 1, Blocks.lava, 0, 2);
		world.setBlock(i + 23, j + 1, k + 1, Blocks.lava, 0, 2);
		world.setBlock(i + 24, j + 1, k + 1, Blocks.lava, 0, 2);
		world.setBlock(i + 25, j + 1, k + 1, Blocks.lava, 0, 2);
		world.setBlock(i + 26, j + 1, k + 1, Blocks.lava, 0, 2);
		world.setBlock(i + 27, j + 1, k + 1, Blocks.lava, 0, 2);
		world.setBlock(i + 0, j + 1, k + 2, NovaCraftBlocks.basal, 0, 2);
		world.setBlock(i + 1, j + 1, k + 2, NovaCraftBlocks.basal, 0, 2);
		world.setBlock(i + 2, j + 1, k + 2, NovaCraftBlocks.basal, 0, 2);
		world.setBlock(i + 3, j + 1, k + 2, NovaCraftBlocks.basal, 0, 2);
		world.setBlock(i + 4, j + 1, k + 2, NovaCraftBlocks.basal, 0, 2);
		world.setBlock(i + 5, j + 1, k + 2, NovaCraftBlocks.basal, 0, 2);
		world.setBlock(i + 6, j + 1, k + 2, NovaCraftBlocks.basal, 0, 2);
		world.setBlock(i + 7, j + 1, k + 2, NovaCraftBlocks.basal, 0, 2);
		world.setBlock(i + 8, j + 1, k + 2, NovaCraftBlocks.basal, 0, 2);
		world.setBlock(i + 9, j + 1, k + 2, NovaCraftBlocks.basal, 0, 2);
		world.setBlock(i + 10, j + 1, k + 2, NovaCraftBlocks.basal, 0, 2);
		world.setBlock(i + 11, j + 1, k + 2, NovaCraftBlocks.basal, 0, 2);
		world.setBlock(i + 12, j + 1, k + 2, NovaCraftBlocks.basal, 0, 2);
		world.setBlock(i + 13, j + 1, k + 2, NovaCraftBlocks.basal, 0, 2);
		world.setBlock(i + 14, j + 1, k + 2, Blocks.lava, 0, 2);
		world.setBlock(i + 15, j + 1, k + 2, Blocks.lava, 0, 2);
		world.setBlock(i + 16, j + 1, k + 2, Blocks.lava, 0, 2);
		world.setBlock(i + 17, j + 1, k + 2, Blocks.lava, 0, 2);
		world.setBlock(i + 18, j + 1, k + 2, Blocks.lava, 0, 2);
		world.setBlock(i + 19, j + 1, k + 2, Blocks.lava, 0, 2);
		world.setBlock(i + 20, j + 1, k + 2, Blocks.lava, 0, 2);
		world.setBlock(i + 21, j + 1, k + 2, Blocks.lava, 0, 2);
		world.setBlock(i + 22, j + 1, k + 2, Blocks.lava, 0, 2);
		world.setBlock(i + 23, j + 1, k + 2, Blocks.lava, 0, 2);
		world.setBlock(i + 24, j + 1, k + 2, Blocks.lava, 0, 2);
		world.setBlock(i + 25, j + 1, k + 2, Blocks.lava, 0, 2);
		world.setBlock(i + 26, j + 1, k + 2, Blocks.lava, 0, 2);
		world.setBlock(i + 27, j + 1, k + 2, Blocks.lava, 0, 2);
		world.setBlock(i + 0, j + 1, k + 3, NovaCraftBlocks.basal, 0, 2);
		world.setBlock(i + 1, j + 1, k + 3, NovaCraftBlocks.basal, 0, 2);
		world.setBlock(i + 2, j + 1, k + 3, NovaCraftBlocks.basal, 0, 2);
		world.setBlock(i + 3, j + 1, k + 3, NovaCraftBlocks.basal, 0, 2);
		world.setBlock(i + 4, j + 1, k + 3, NovaCraftBlocks.basal, 0, 2);
		world.setBlock(i + 5, j + 1, k + 3, NovaCraftBlocks.basal, 0, 2);
		world.setBlock(i + 6, j + 1, k + 3, NovaCraftBlocks.basal, 0, 2);
		world.setBlock(i + 7, j + 1, k + 3, NovaCraftBlocks.basal, 0, 2);
		world.setBlock(i + 8, j + 1, k + 3, NovaCraftBlocks.basal, 0, 2);
		world.setBlock(i + 9, j + 1, k + 3, NovaCraftBlocks.basal, 0, 2);
		world.setBlock(i + 10, j + 1, k + 3, NovaCraftBlocks.basal, 0, 2);
		world.setBlock(i + 11, j + 1, k + 3, NovaCraftBlocks.basal, 0, 2);
		world.setBlock(i + 12, j + 1, k + 3, NovaCraftBlocks.basal, 0, 2);
		world.setBlock(i + 13, j + 1, k + 3, NovaCraftBlocks.basal, 0, 2);
		world.setBlock(i + 14, j + 1, k + 3, NovaCraftBlocks.cracked_basal_bricks, 0, 2);
		world.setBlock(i + 15, j + 1, k + 3, NovaCraftBlocks.cracked_basal_bricks, 0, 2);
		world.setBlock(i + 16, j + 1, k + 3, Blocks.lava, 0, 2);
		world.setBlock(i + 17, j + 1, k + 3, Blocks.lava, 0, 2);
		world.setBlock(i + 18, j + 1, k + 3, NovaCraftBlocks.cracked_basal_bricks, 0, 2);
		world.setBlock(i + 19, j + 1, k + 3, NovaCraftBlocks.cracked_basal_bricks, 0, 2);
		world.setBlock(i + 20, j + 1, k + 3, Blocks.lava, 0, 2);
		world.setBlock(i + 21, j + 1, k + 3, Blocks.lava, 0, 2);
		world.setBlock(i + 22, j + 1, k + 3, NovaCraftBlocks.basal, 0, 2);
		world.setBlock(i + 23, j + 1, k + 3, NovaCraftBlocks.basal, 0, 2);
		world.setBlock(i + 24, j + 1, k + 3, Blocks.lava, 0, 2);
		world.setBlock(i + 25, j + 1, k + 3, Blocks.lava, 0, 2);
		world.setBlock(i + 26, j + 1, k + 3, NovaCraftBlocks.basal, 0, 2);
		world.setBlock(i + 27, j + 1, k + 3, NovaCraftBlocks.basal, 0, 2);
		world.setBlock(i + 0, j + 1, k + 4, NovaCraftBlocks.basal, 0, 2);
		world.setBlock(i + 1, j + 1, k + 4, NovaCraftBlocks.basal, 0, 2);
		world.setBlock(i + 2, j + 1, k + 4, NovaCraftBlocks.basal, 0, 2);
		world.setBlock(i + 3, j + 1, k + 4, NovaCraftBlocks.basal, 0, 2);
		world.setBlock(i + 4, j + 1, k + 4, NovaCraftBlocks.basal, 0, 2);
		world.setBlock(i + 5, j + 1, k + 4, NovaCraftBlocks.basal, 0, 2);
		world.setBlock(i + 6, j + 1, k + 4, NovaCraftBlocks.basal, 0, 2);
		world.setBlock(i + 7, j + 1, k + 4, NovaCraftBlocks.basal, 0, 2);
		world.setBlock(i + 8, j + 1, k + 4, NovaCraftBlocks.basal, 0, 2);
		world.setBlock(i + 9, j + 1, k + 4, NovaCraftBlocks.basal, 0, 2);
		world.setBlock(i + 10, j + 1, k + 4, NovaCraftBlocks.basal, 0, 2);
		world.setBlock(i + 11, j + 1, k + 4, NovaCraftBlocks.basal, 0, 2);
		world.setBlock(i + 12, j + 1, k + 4, NovaCraftBlocks.basal, 0, 2);
		world.setBlock(i + 13, j + 1, k + 4, NovaCraftBlocks.basal, 0, 2);
		world.setBlock(i + 14, j + 1, k + 4, NovaCraftBlocks.basal, 0, 2);
		world.setBlock(i + 15, j + 1, k + 4, NovaCraftBlocks.basal, 0, 2);
		world.setBlock(i + 16, j + 1, k + 4, NovaCraftBlocks.basal, 0, 2);
		world.setBlock(i + 17, j + 1, k + 4, NovaCraftBlocks.basal, 0, 2);
		world.setBlock(i + 18, j + 1, k + 4, NovaCraftBlocks.basal, 0, 2);
		world.setBlock(i + 19, j + 1, k + 4, NovaCraftBlocks.basal, 0, 2);
		world.setBlock(i + 20, j + 1, k + 4, NovaCraftBlocks.basal, 0, 2);
		world.setBlock(i + 21, j + 1, k + 4, NovaCraftBlocks.basal, 0, 2);
		world.setBlock(i + 22, j + 1, k + 4, NovaCraftBlocks.basal, 0, 2);
		world.setBlock(i + 23, j + 1, k + 4, NovaCraftBlocks.basal, 0, 2);
		world.setBlock(i + 24, j + 1, k + 4, NovaCraftBlocks.basal, 0, 2);
		world.setBlock(i + 25, j + 1, k + 4, NovaCraftBlocks.basal, 0, 2);
		world.setBlock(i + 26, j + 1, k + 4, NovaCraftBlocks.basal, 0, 2);
		world.setBlock(i + 27, j + 1, k + 4, NovaCraftBlocks.basal, 0, 2);
		world.setBlock(i + 0, j + 1, k + 5, NovaCraftBlocks.basal, 0, 2);
		world.setBlock(i + 1, j + 1, k + 5, NovaCraftBlocks.basal, 0, 2);
		world.setBlock(i + 2, j + 1, k + 5, NovaCraftBlocks.basal, 0, 2);
		world.setBlock(i + 3, j + 1, k + 5, NovaCraftBlocks.basal, 0, 2);
		world.setBlock(i + 4, j + 1, k + 5, NovaCraftBlocks.basal, 0, 2);
		world.setBlock(i + 5, j + 1, k + 5, NovaCraftBlocks.basal, 0, 2);
		world.setBlock(i + 6, j + 1, k + 5, NovaCraftBlocks.basal, 0, 2);
		world.setBlock(i + 7, j + 1, k + 5, NovaCraftBlocks.basal, 0, 2);
		world.setBlock(i + 8, j + 1, k + 5, NovaCraftBlocks.basal, 0, 2);
		world.setBlock(i + 9, j + 1, k + 5, NovaCraftBlocks.basal, 0, 2);
		world.setBlock(i + 10, j + 1, k + 5, NovaCraftBlocks.basal, 0, 2);
		world.setBlock(i + 11, j + 1, k + 5, NovaCraftBlocks.basal, 0, 2);
		world.setBlock(i + 12, j + 1, k + 5, NovaCraftBlocks.basal, 0, 2);
		world.setBlock(i + 13, j + 1, k + 5, NovaCraftBlocks.basal, 0, 2);
		world.setBlock(i + 14, j + 1, k + 5, NovaCraftBlocks.basal, 0, 2);
		world.setBlock(i + 15, j + 1, k + 5, NovaCraftBlocks.basal, 0, 2);
		world.setBlock(i + 16, j + 1, k + 5, NovaCraftBlocks.basal, 0, 2);
		world.setBlock(i + 17, j + 1, k + 5, NovaCraftBlocks.basal, 0, 2);
		world.setBlock(i + 18, j + 1, k + 5, NovaCraftBlocks.basal, 0, 2);
		world.setBlock(i + 19, j + 1, k + 5, NovaCraftBlocks.basal, 0, 2);
		world.setBlock(i + 20, j + 1, k + 5, NovaCraftBlocks.basal, 0, 2);
		world.setBlock(i + 21, j + 1, k + 5, NovaCraftBlocks.basal, 0, 2);
		world.setBlock(i + 22, j + 1, k + 5, NovaCraftBlocks.basal, 0, 2);
		world.setBlock(i + 23, j + 1, k + 5, NovaCraftBlocks.basal, 0, 2);
		world.setBlock(i + 24, j + 1, k + 5, NovaCraftBlocks.basal, 0, 2);
		world.setBlock(i + 25, j + 1, k + 5, NovaCraftBlocks.basal, 0, 2);
		world.setBlock(i + 26, j + 1, k + 5, NovaCraftBlocks.basal, 0, 2);
		world.setBlock(i + 27, j + 1, k + 5, NovaCraftBlocks.basal, 0, 2);
		world.setBlock(i + 0, j + 1, k + 6, NovaCraftBlocks.basal, 0, 2);
		world.setBlock(i + 1, j + 1, k + 6, NovaCraftBlocks.basal, 0, 2);
		world.setBlock(i + 2, j + 1, k + 6, NovaCraftBlocks.basal, 0, 2);
		world.setBlock(i + 3, j + 1, k + 6, NovaCraftBlocks.basal, 0, 2);
		world.setBlock(i + 4, j + 1, k + 6, NovaCraftBlocks.basal, 0, 2);
		world.setBlock(i + 5, j + 1, k + 6, NovaCraftBlocks.basal, 0, 2);
		world.setBlock(i + 6, j + 1, k + 6, NovaCraftBlocks.basal, 0, 2);
		world.setBlock(i + 7, j + 1, k + 6, NovaCraftBlocks.basal, 0, 2);
		world.setBlock(i + 8, j + 1, k + 6, NovaCraftBlocks.basal, 0, 2);
		world.setBlock(i + 9, j + 1, k + 6, NovaCraftBlocks.basal, 0, 2);
		world.setBlock(i + 10, j + 1, k + 6, NovaCraftBlocks.basal, 0, 2);
		world.setBlock(i + 11, j + 1, k + 6, NovaCraftBlocks.basal, 0, 2);
		world.setBlock(i + 12, j + 1, k + 6, NovaCraftBlocks.basal, 0, 2);
		world.setBlock(i + 13, j + 1, k + 6, NovaCraftBlocks.basal, 0, 2);
		world.setBlock(i + 14, j + 1, k + 6, NovaCraftBlocks.basal, 0, 2);
		world.setBlock(i + 15, j + 1, k + 6, NovaCraftBlocks.basal, 0, 2);
		world.setBlock(i + 16, j + 1, k + 6, NovaCraftBlocks.basal, 0, 2);
		world.setBlock(i + 17, j + 1, k + 6, NovaCraftBlocks.basal, 0, 2);
		world.setBlock(i + 18, j + 1, k + 6, NovaCraftBlocks.basal, 0, 2);
		world.setBlock(i + 19, j + 1, k + 6, NovaCraftBlocks.basal, 0, 2);
		world.setBlock(i + 20, j + 1, k + 6, NovaCraftBlocks.basal, 0, 2);
		world.setBlock(i + 21, j + 1, k + 6, NovaCraftBlocks.basal, 0, 2);
		world.setBlock(i + 22, j + 1, k + 6, NovaCraftBlocks.basal, 0, 2);
		world.setBlock(i + 23, j + 1, k + 6, NovaCraftBlocks.basal, 0, 2);
		world.setBlock(i + 24, j + 1, k + 6, NovaCraftBlocks.basal, 0, 2);
		world.setBlock(i + 25, j + 1, k + 6, NovaCraftBlocks.basal, 0, 2);
		world.setBlock(i + 26, j + 1, k + 6, NovaCraftBlocks.basal, 0, 2);
		world.setBlock(i + 27, j + 1, k + 6, NovaCraftBlocks.basal, 0, 2);
		world.setBlock(i + 0, j + 1, k + 7, NovaCraftBlocks.basal, 0, 2);
		world.setBlock(i + 1, j + 1, k + 7, NovaCraftBlocks.basal, 0, 2);
		world.setBlock(i + 2, j + 1, k + 7, NovaCraftBlocks.basal, 0, 2);
		world.setBlock(i + 3, j + 1, k + 7, NovaCraftBlocks.basal, 0, 2);
		world.setBlock(i + 4, j + 1, k + 7, NovaCraftBlocks.basal, 0, 2);
		world.setBlock(i + 5, j + 1, k + 7, NovaCraftBlocks.basal, 0, 2);
		world.setBlock(i + 6, j + 1, k + 7, NovaCraftBlocks.basal, 0, 2);
		world.setBlock(i + 7, j + 1, k + 7, NovaCraftBlocks.basal, 0, 2);
		world.setBlock(i + 8, j + 1, k + 7, NovaCraftBlocks.basal, 0, 2);
		world.setBlock(i + 9, j + 1, k + 7, NovaCraftBlocks.basal, 0, 2);
		world.setBlock(i + 10, j + 1, k + 7, NovaCraftBlocks.basal, 0, 2);
		world.setBlock(i + 11, j + 1, k + 7, NovaCraftBlocks.basal, 0, 2);
		world.setBlock(i + 12, j + 1, k + 7, NovaCraftBlocks.basal, 0, 2);
		world.setBlock(i + 13, j + 1, k + 7, NovaCraftBlocks.basal, 0, 2);
		world.setBlock(i + 14, j + 1, k + 7, NovaCraftBlocks.basal, 0, 2);
		world.setBlock(i + 15, j + 1, k + 7, NovaCraftBlocks.basal, 0, 2);
		world.setBlock(i + 16, j + 1, k + 7, NovaCraftBlocks.basal, 0, 2);
		world.setBlock(i + 17, j + 1, k + 7, NovaCraftBlocks.basal, 0, 2);
		world.setBlock(i + 18, j + 1, k + 7, NovaCraftBlocks.basal, 0, 2);
		world.setBlock(i + 19, j + 1, k + 7, NovaCraftBlocks.basal, 0, 2);
		world.setBlock(i + 20, j + 1, k + 7, NovaCraftBlocks.basal, 0, 2);
		world.setBlock(i + 21, j + 1, k + 7, NovaCraftBlocks.basal, 0, 2);
		world.setBlock(i + 22, j + 1, k + 7, NovaCraftBlocks.basal, 0, 2);
		world.setBlock(i + 23, j + 1, k + 7, NovaCraftBlocks.basal, 0, 2);
		world.setBlock(i + 24, j + 1, k + 7, NovaCraftBlocks.basal, 0, 2);
		world.setBlock(i + 25, j + 1, k + 7, NovaCraftBlocks.basal, 0, 2);
		world.setBlock(i + 26, j + 1, k + 7, NovaCraftBlocks.basal, 0, 2);
		world.setBlock(i + 27, j + 1, k + 7, NovaCraftBlocks.basal, 0, 2);
		world.setBlock(i + 0, j + 1, k + 8, NovaCraftBlocks.basal, 0, 2);
		world.setBlock(i + 1, j + 1, k + 8, NovaCraftBlocks.basal, 0, 2);
		world.setBlock(i + 2, j + 1, k + 8, NovaCraftBlocks.basal, 0, 2);
		world.setBlock(i + 3, j + 1, k + 8, NovaCraftBlocks.basal, 0, 2);
		world.setBlock(i + 4, j + 1, k + 8, NovaCraftBlocks.basal, 0, 2);
		world.setBlock(i + 5, j + 1, k + 8, NovaCraftBlocks.basal, 0, 2);
		world.setBlock(i + 6, j + 1, k + 8, NovaCraftBlocks.basal, 0, 2);
		world.setBlock(i + 7, j + 1, k + 8, NovaCraftBlocks.basal, 0, 2);
		world.setBlock(i + 8, j + 1, k + 8, NovaCraftBlocks.basal, 0, 2);
		world.setBlock(i + 9, j + 1, k + 8, NovaCraftBlocks.basal, 0, 2);
		world.setBlock(i + 10, j + 1, k + 8, NovaCraftBlocks.basal, 0, 2);
		world.setBlock(i + 11, j + 1, k + 8, NovaCraftBlocks.basal, 0, 2);
		world.setBlock(i + 12, j + 1, k + 8, NovaCraftBlocks.basal, 0, 2);
		world.setBlock(i + 13, j + 1, k + 8, NovaCraftBlocks.basal, 0, 2);
		world.setBlock(i + 14, j + 1, k + 8, NovaCraftBlocks.basal, 0, 2);
		world.setBlock(i + 15, j + 1, k + 8, NovaCraftBlocks.basal, 0, 2);
		world.setBlock(i + 16, j + 1, k + 8, NovaCraftBlocks.basal, 0, 2);
		world.setBlock(i + 17, j + 1, k + 8, NovaCraftBlocks.basal, 0, 2);
		world.setBlock(i + 18, j + 1, k + 8, NovaCraftBlocks.basal, 0, 2);
		world.setBlock(i + 19, j + 1, k + 8, NovaCraftBlocks.basal, 0, 2);
		world.setBlock(i + 20, j + 1, k + 8, NovaCraftBlocks.basal, 0, 2);
		world.setBlock(i + 21, j + 1, k + 8, NovaCraftBlocks.basal, 0, 2);
		world.setBlock(i + 22, j + 1, k + 8, NovaCraftBlocks.basal, 0, 2);
		world.setBlock(i + 23, j + 1, k + 8, NovaCraftBlocks.basal, 0, 2);
		world.setBlock(i + 24, j + 1, k + 8, NovaCraftBlocks.basal, 0, 2);
		world.setBlock(i + 25, j + 1, k + 8, NovaCraftBlocks.basal, 0, 2);
		world.setBlock(i + 26, j + 1, k + 8, NovaCraftBlocks.basal, 0, 2);
		world.setBlock(i + 27, j + 1, k + 8, NovaCraftBlocks.basal, 0, 2);
		world.setBlock(i + 0, j + 1, k + 9, Blocks.lava, 0, 2);
		world.setBlock(i + 1, j + 1, k + 9, NovaCraftBlocks.basal, 0, 2);
		world.setBlock(i + 2, j + 1, k + 9, NovaCraftBlocks.basal, 0, 2);
		world.setBlock(i + 3, j + 1, k + 9, NovaCraftBlocks.basal, 0, 2);
		world.setBlock(i + 4, j + 1, k + 9, NovaCraftBlocks.basal, 0, 2);
		world.setBlock(i + 5, j + 1, k + 9, NovaCraftBlocks.basal, 0, 2);
		world.setBlock(i + 6, j + 1, k + 9, NovaCraftBlocks.basal, 0, 2);
		world.setBlock(i + 7, j + 1, k + 9, NovaCraftBlocks.basal, 0, 2);
		world.setBlock(i + 8, j + 1, k + 9, NovaCraftBlocks.basal, 0, 2);
		world.setBlock(i + 9, j + 1, k + 9, NovaCraftBlocks.basal, 0, 2);
		world.setBlock(i + 10, j + 1, k + 9, NovaCraftBlocks.basal, 0, 2);
		world.setBlock(i + 11, j + 1, k + 9, NovaCraftBlocks.basal, 0, 2);
		world.setBlock(i + 12, j + 1, k + 9, NovaCraftBlocks.basal, 0, 2);
		world.setBlock(i + 13, j + 1, k + 9, NovaCraftBlocks.basal, 0, 2);
		world.setBlock(i + 14, j + 1, k + 9, NovaCraftBlocks.basal, 0, 2);
		world.setBlock(i + 15, j + 1, k + 9, NovaCraftBlocks.basal, 0, 2);
		world.setBlock(i + 16, j + 1, k + 9, NovaCraftBlocks.basal, 0, 2);
		world.setBlock(i + 17, j + 1, k + 9, NovaCraftBlocks.basal, 0, 2);
		world.setBlock(i + 18, j + 1, k + 9, NovaCraftBlocks.basal, 0, 2);
		world.setBlock(i + 19, j + 1, k + 9, NovaCraftBlocks.basal, 0, 2);
		world.setBlock(i + 20, j + 1, k + 9, NovaCraftBlocks.basal, 0, 2);
		world.setBlock(i + 21, j + 1, k + 9, NovaCraftBlocks.basal, 0, 2);
		world.setBlock(i + 22, j + 1, k + 9, NovaCraftBlocks.basal, 0, 2);
		world.setBlock(i + 23, j + 1, k + 9, NovaCraftBlocks.basal, 0, 2);
		world.setBlock(i + 24, j + 1, k + 9, NovaCraftBlocks.basal, 0, 2);
		world.setBlock(i + 25, j + 1, k + 9, NovaCraftBlocks.basal, 0, 2);
		world.setBlock(i + 26, j + 1, k + 9, NovaCraftBlocks.basal, 0, 2);
		world.setBlock(i + 27, j + 1, k + 9, NovaCraftBlocks.basal, 0, 2);
		world.setBlock(i + 0, j + 1, k + 10, Blocks.lava, 0, 2);
		world.setBlock(i + 1, j + 1, k + 10, Blocks.lava, 0, 2);
		world.setBlock(i + 2, j + 1, k + 10, Blocks.lava, 0, 2);
		world.setBlock(i + 3, j + 1, k + 10, NovaCraftBlocks.basal, 0, 2);
		world.setBlock(i + 4, j + 1, k + 10, NovaCraftBlocks.basal, 0, 2);
		world.setBlock(i + 5, j + 1, k + 10, NovaCraftBlocks.basal, 0, 2);
		world.setBlock(i + 6, j + 1, k + 10, NovaCraftBlocks.basal, 0, 2);
		world.setBlock(i + 7, j + 1, k + 10, NovaCraftBlocks.basal, 0, 2);
		world.setBlock(i + 8, j + 1, k + 10, NovaCraftBlocks.basal, 0, 2);
		world.setBlock(i + 9, j + 1, k + 10, NovaCraftBlocks.glowing_basal, 0, 2);
		world.setBlock(i + 10, j + 1, k + 10, NovaCraftBlocks.basal, 0, 2);
		world.setBlock(i + 11, j + 1, k + 10, NovaCraftBlocks.basal, 0, 2);
		world.setBlock(i + 12, j + 1, k + 10, NovaCraftBlocks.basal, 0, 2);
		world.setBlock(i + 13, j + 1, k + 10, NovaCraftBlocks.basal, 0, 2);
		world.setBlock(i + 14, j + 1, k + 10, NovaCraftBlocks.basal, 0, 2);
		world.setBlock(i + 15, j + 1, k + 10, NovaCraftBlocks.basal, 0, 2);
		world.setBlock(i + 16, j + 1, k + 10, NovaCraftBlocks.basal, 0, 2);
		world.setBlock(i + 17, j + 1, k + 10, NovaCraftBlocks.basal, 0, 2);
		world.setBlock(i + 18, j + 1, k + 10, NovaCraftBlocks.basal, 0, 2);
		world.setBlock(i + 19, j + 1, k + 10, NovaCraftBlocks.basal, 0, 2);
		world.setBlock(i + 20, j + 1, k + 10, NovaCraftBlocks.glowing_basal, 0, 2);
		world.setBlock(i + 21, j + 1, k + 10, NovaCraftBlocks.basal, 0, 2);
		world.setBlock(i + 22, j + 1, k + 10, NovaCraftBlocks.basal, 0, 2);
		world.setBlock(i + 23, j + 1, k + 10, NovaCraftBlocks.basal, 0, 2);
		world.setBlock(i + 24, j + 1, k + 10, NovaCraftBlocks.basal, 0, 2);
		world.setBlock(i + 25, j + 1, k + 10, NovaCraftBlocks.basal, 0, 2);
		world.setBlock(i + 26, j + 1, k + 10, NovaCraftBlocks.basal, 0, 2);
		world.setBlock(i + 27, j + 1, k + 10, NovaCraftBlocks.basal, 0, 2);
		world.setBlock(i + 0, j + 1, k + 11, NovaCraftBlocks.basal_bricks, 0, 2);
		world.setBlock(i + 1, j + 1, k + 11, NovaCraftBlocks.basal_bricks, 0, 2);
		world.setBlock(i + 2, j + 1, k + 11, NovaCraftBlocks.basal_bricks, 0, 2);
		world.setBlock(i + 3, j + 1, k + 11, NovaCraftBlocks.basal_bricks, 0, 2);
		world.setBlock(i + 4, j + 1, k + 11, NovaCraftBlocks.cracked_basal_bricks, 0, 2);
		world.setBlock(i + 5, j + 1, k + 11, NovaCraftBlocks.basal_bricks, 0, 2);
		world.setBlock(i + 6, j + 1, k + 11, NovaCraftBlocks.basal_bricks, 0, 2);
		world.setBlock(i + 7, j + 1, k + 11, NovaCraftBlocks.basal_bricks, 0, 2);
		world.setBlock(i + 8, j + 1, k + 11, NovaCraftBlocks.basal_bricks, 0, 2);
		world.setBlock(i + 9, j + 1, k + 11, NovaCraftBlocks.basal_bricks, 0, 2);
		world.setBlock(i + 10, j + 1, k + 11, NovaCraftBlocks.basal_bricks, 0, 2);
		world.setBlock(i + 11, j + 1, k + 11, NovaCraftBlocks.basal_bricks, 0, 2);
		world.setBlock(i + 12, j + 1, k + 11, NovaCraftBlocks.cracked_basal_bricks, 0, 2);
		world.setBlock(i + 13, j + 1, k + 11, NovaCraftBlocks.basal_bricks, 0, 2);
		world.setBlock(i + 14, j + 1, k + 11, Blocks.lava, 0, 2);
		world.setBlock(i + 15, j + 1, k + 11, NovaCraftBlocks.basal, 0, 2);
		world.setBlock(i + 16, j + 1, k + 11, NovaCraftBlocks.basal, 0, 2);
		world.setBlock(i + 17, j + 1, k + 11, NovaCraftBlocks.basal, 0, 2);
		world.setBlock(i + 18, j + 1, k + 11, NovaCraftBlocks.basal, 0, 2);
		world.setBlock(i + 19, j + 1, k + 11, NovaCraftBlocks.basal, 0, 2);
		world.setBlock(i + 20, j + 1, k + 11, NovaCraftBlocks.basal, 0, 2);
		world.setBlock(i + 21, j + 1, k + 11, NovaCraftBlocks.basal, 0, 2);
		world.setBlock(i + 22, j + 1, k + 11, NovaCraftBlocks.basal, 0, 2);
		world.setBlock(i + 23, j + 1, k + 11, NovaCraftBlocks.basal, 0, 2);
		world.setBlock(i + 24, j + 1, k + 11, NovaCraftBlocks.basal, 0, 2);
		world.setBlock(i + 25, j + 1, k + 11, NovaCraftBlocks.basal, 0, 2);
		world.setBlock(i + 26, j + 1, k + 11, NovaCraftBlocks.basal, 0, 2);
		world.setBlock(i + 27, j + 1, k + 11, NovaCraftBlocks.basal, 0, 2);
		world.setBlock(i + 0, j + 1, k + 12, NovaCraftBlocks.cracked_basal_bricks, 0, 2);
		world.setBlock(i + 1, j + 1, k + 12, NovaCraftBlocks.basal_bricks, 0, 2);
		world.setBlock(i + 2, j + 1, k + 12, NovaCraftBlocks.basal_bricks, 0, 2);
		world.setBlock(i + 3, j + 1, k + 12, NovaCraftBlocks.basal_bricks, 0, 2);
		world.setBlock(i + 4, j + 1, k + 12, NovaCraftBlocks.basal_bricks, 0, 2);
		world.setBlock(i + 5, j + 1, k + 12, NovaCraftBlocks.basal_bricks, 0, 2);
		world.setBlock(i + 6, j + 1, k + 12, NovaCraftBlocks.cracked_basal_bricks, 0, 2);
		world.setBlock(i + 7, j + 1, k + 12, NovaCraftBlocks.cracked_basal_bricks, 0, 2);
		world.setBlock(i + 8, j + 1, k + 12, NovaCraftBlocks.basal_bricks, 0, 2);
		world.setBlock(i + 9, j + 1, k + 12, NovaCraftBlocks.basal_bricks, 0, 2);
		world.setBlock(i + 10, j + 1, k + 12, NovaCraftBlocks.basal_bricks, 0, 2);
		world.setBlock(i + 11, j + 1, k + 12, NovaCraftBlocks.cracked_basal_bricks, 0, 2);
		world.setBlock(i + 12, j + 1, k + 12, NovaCraftBlocks.cracked_basal_bricks, 0, 2);
		world.setBlock(i + 13, j + 1, k + 12, NovaCraftBlocks.basal_bricks, 0, 2);
		world.setBlock(i + 14, j + 1, k + 12, Blocks.lava, 0, 2);
		world.setBlock(i + 15, j + 1, k + 12, Blocks.lava, 0, 2);
		world.setBlock(i + 16, j + 1, k + 12, Blocks.lava, 0, 2);
		world.setBlock(i + 17, j + 1, k + 12, NovaCraftBlocks.basal, 0, 2);
		world.setBlock(i + 18, j + 1, k + 12, NovaCraftBlocks.basal, 0, 2);
		world.setBlock(i + 19, j + 1, k + 12, NovaCraftBlocks.basal, 0, 2);
		world.setBlock(i + 20, j + 1, k + 12, NovaCraftBlocks.basal, 0, 2);
		world.setBlock(i + 21, j + 1, k + 12, NovaCraftBlocks.basal, 0, 2);
		world.setBlock(i + 22, j + 1, k + 12, NovaCraftBlocks.basal, 0, 2);
		world.setBlock(i + 23, j + 1, k + 12, NovaCraftBlocks.basal, 0, 2);
		world.setBlock(i + 24, j + 1, k + 12, NovaCraftBlocks.basal, 0, 2);
		world.setBlock(i + 25, j + 1, k + 12, NovaCraftBlocks.basal, 0, 2);
		world.setBlock(i + 26, j + 1, k + 12, NovaCraftBlocks.basal, 0, 2);
		world.setBlock(i + 27, j + 1, k + 12, NovaCraftBlocks.basal, 0, 2);
		world.setBlock(i + 0, j + 2, k + 0, Blocks.lava, 0, 2);
		world.setBlock(i + 1, j + 2, k + 0, Blocks.lava, 0, 2);
		world.setBlock(i + 2, j + 2, k + 0, Blocks.lava, 0, 2);
		world.setBlock(i + 3, j + 2, k + 0, Blocks.lava, 0, 2);
		world.setBlock(i + 4, j + 2, k + 0, Blocks.lava, 0, 2);
		world.setBlock(i + 5, j + 2, k + 0, Blocks.lava, 0, 2);
		world.setBlock(i + 6, j + 2, k + 0, Blocks.lava, 0, 2);
		world.setBlock(i + 7, j + 2, k + 0, Blocks.lava, 0, 2);
		world.setBlock(i + 8, j + 2, k + 0, Blocks.lava, 0, 2);
		world.setBlock(i + 9, j + 2, k + 0, Blocks.lava, 0, 2);
		world.setBlock(i + 10, j + 2, k + 0, Blocks.lava, 0, 2);
		world.setBlock(i + 11, j + 2, k + 0, Blocks.lava, 0, 2);
		world.setBlock(i + 12, j + 2, k + 0, Blocks.lava, 0, 2);
		world.setBlock(i + 13, j + 2, k + 0, Blocks.lava, 0, 2);
		world.setBlock(i + 14, j + 2, k + 0, Blocks.lava, 0, 2);
		world.setBlock(i + 15, j + 2, k + 0, Blocks.lava, 0, 2);
		world.setBlock(i + 16, j + 2, k + 0, Blocks.lava, 0, 2);
		world.setBlock(i + 17, j + 2, k + 0, Blocks.lava, 0, 2);
		world.setBlock(i + 18, j + 2, k + 0, Blocks.lava, 0, 2);
		world.setBlock(i + 19, j + 2, k + 0, Blocks.lava, 0, 2);
		world.setBlock(i + 20, j + 2, k + 0, Blocks.lava, 0, 2);
		world.setBlock(i + 21, j + 2, k + 0, Blocks.lava, 0, 2);
		world.setBlock(i + 22, j + 2, k + 0, Blocks.lava, 0, 2);
		world.setBlock(i + 23, j + 2, k + 0, Blocks.lava, 0, 2);
		world.setBlock(i + 24, j + 2, k + 0, Blocks.lava, 0, 2);
		world.setBlock(i + 25, j + 2, k + 0, Blocks.lava, 0, 2);
		world.setBlock(i + 26, j + 2, k + 0, Blocks.lava, 0, 2);
		world.setBlock(i + 27, j + 2, k + 0, Blocks.lava, 0, 2);
		world.setBlock(i + 0, j + 2, k + 1, Blocks.lava, 0, 2);
		world.setBlock(i + 1, j + 2, k + 1, NovaCraftBlocks.cracked_basal_bricks, 0, 2);
		world.setBlock(i + 2, j + 2, k + 1, Blocks.lava, 0, 2);
		world.setBlock(i + 3, j + 2, k + 1, Blocks.lava, 0, 2);
		world.setBlock(i + 4, j + 2, k + 1, PlaceMagma, 0, 2);
		world.setBlock(i + 5, j + 2, k + 1, NovaCraftBlocks.cracked_basal_bricks, 0, 2);
		world.setBlock(i + 6, j + 2, k + 1, Blocks.lava, 0, 2);
		world.setBlock(i + 7, j + 2, k + 1, Blocks.lava, 0, 2);
		world.setBlock(i + 8, j + 2, k + 1, NovaCraftBlocks.cracked_basal_bricks, 0, 2);
		world.setBlock(i + 9, j + 2, k + 1, NovaCraftBlocks.basal, 0, 2);
		world.setBlock(i + 10, j + 2, k + 1, Blocks.lava, 0, 2);
		world.setBlock(i + 11, j + 2, k + 1, Blocks.lava, 0, 2);
		world.setBlock(i + 12, j + 2, k + 1, Blocks.lava, 0, 2);
		world.setBlock(i + 13, j + 2, k + 1, Blocks.lava, 0, 2);
		world.setBlock(i + 14, j + 2, k + 1, Blocks.lava, 0, 2);
		world.setBlock(i + 15, j + 2, k + 1, Blocks.lava, 0, 2);
		world.setBlock(i + 16, j + 2, k + 1, Blocks.lava, 0, 2);
		world.setBlock(i + 17, j + 2, k + 1, Blocks.lava, 0, 2);
		world.setBlock(i + 18, j + 2, k + 1, Blocks.lava, 0, 2);
		world.setBlock(i + 19, j + 2, k + 1, Blocks.lava, 0, 2);
		world.setBlock(i + 20, j + 2, k + 1, Blocks.lava, 0, 2);
		world.setBlock(i + 21, j + 2, k + 1, Blocks.lava, 0, 2);
		world.setBlock(i + 22, j + 2, k + 1, Blocks.lava, 0, 2);
		world.setBlock(i + 23, j + 2, k + 1, Blocks.lava, 0, 2);
		world.setBlock(i + 24, j + 2, k + 1, Blocks.lava, 0, 2);
		world.setBlock(i + 25, j + 2, k + 1, Blocks.lava, 0, 2);
		world.setBlock(i + 26, j + 2, k + 1, Blocks.lava, 0, 2);
		world.setBlock(i + 27, j + 2, k + 1, Blocks.lava, 0, 2);
		world.setBlock(i + 0, j + 2, k + 2, NovaCraftBlocks.basal, 0, 2);
		world.setBlock(i + 1, j + 2, k + 2, NovaCraftBlocks.basal, 0, 2);
		world.setBlock(i + 2, j + 2, k + 2, NovaCraftBlocks.basal, 0, 2);
		world.setBlock(i + 3, j + 2, k + 2, NovaCraftBlocks.basal, 0, 2);
		world.setBlock(i + 4, j + 2, k + 2, NovaCraftBlocks.basal, 0, 2);
		world.setBlock(i + 5, j + 2, k + 2, NovaCraftBlocks.basal, 0, 2);
		world.setBlock(i + 6, j + 2, k + 2, NovaCraftBlocks.basal, 0, 2);
		world.setBlock(i + 7, j + 2, k + 2, NovaCraftBlocks.basal, 0, 2);
		world.setBlock(i + 8, j + 2, k + 2, NovaCraftBlocks.basal, 0, 2);
		world.setBlock(i + 9, j + 2, k + 2, NovaCraftBlocks.basal, 0, 2);
		world.setBlock(i + 10, j + 2, k + 2, NovaCraftBlocks.basal, 0, 2);
		world.setBlock(i + 11, j + 2, k + 2, NovaCraftBlocks.basal, 0, 2);
		world.setBlock(i + 12, j + 2, k + 2, NovaCraftBlocks.basal, 0, 2);
		world.setBlock(i + 13, j + 2, k + 2, NovaCraftBlocks.basal, 0, 2);
		world.setBlock(i + 14, j + 2, k + 2, Blocks.lava, 0, 2);
		world.setBlock(i + 15, j + 2, k + 2, Blocks.lava, 0, 2);
		world.setBlock(i + 16, j + 2, k + 2, Blocks.lava, 0, 2);
		world.setBlock(i + 17, j + 2, k + 2, Blocks.lava, 0, 2);
		world.setBlock(i + 18, j + 2, k + 2, Blocks.lava, 0, 2);
		world.setBlock(i + 19, j + 2, k + 2, Blocks.lava, 0, 2);
		world.setBlock(i + 20, j + 2, k + 2, Blocks.lava, 0, 2);
		world.setBlock(i + 21, j + 2, k + 2, Blocks.lava, 0, 2);
		world.setBlock(i + 22, j + 2, k + 2, Blocks.lava, 0, 2);
		world.setBlock(i + 23, j + 2, k + 2, Blocks.lava, 0, 2);
		world.setBlock(i + 24, j + 2, k + 2, Blocks.lava, 0, 2);
		world.setBlock(i + 25, j + 2, k + 2, Blocks.lava, 0, 2);
		world.setBlock(i + 26, j + 2, k + 2, Blocks.lava, 0, 2);
		world.setBlock(i + 27, j + 2, k + 2, Blocks.lava, 0, 2);
		world.setBlock(i + 0, j + 2, k + 3, NovaCraftBlocks.basal, 0, 2);
		world.setBlock(i + 1, j + 2, k + 3, NovaCraftBlocks.basal, 0, 2);
		world.setBlock(i + 2, j + 2, k + 3, NovaCraftBlocks.basal, 0, 2);
		world.setBlock(i + 3, j + 2, k + 3, NovaCraftBlocks.basal, 0, 2);
		world.setBlock(i + 4, j + 2, k + 3, NovaCraftBlocks.basal, 0, 2);
		world.setBlock(i + 5, j + 2, k + 3, NovaCraftBlocks.basal, 0, 2);
		world.setBlock(i + 6, j + 2, k + 3, NovaCraftBlocks.basal, 0, 2);
		world.setBlock(i + 7, j + 2, k + 3, NovaCraftBlocks.basal, 0, 2);
		world.setBlock(i + 8, j + 2, k + 3, NovaCraftBlocks.basal, 0, 2);
		world.setBlock(i + 9, j + 2, k + 3, NovaCraftBlocks.basal, 0, 2);
		world.setBlock(i + 10, j + 2, k + 3, NovaCraftBlocks.basal, 0, 2);
		world.setBlock(i + 11, j + 2, k + 3, NovaCraftBlocks.basal, 0, 2);
		world.setBlock(i + 12, j + 2, k + 3, NovaCraftBlocks.basal, 0, 2);
		world.setBlock(i + 13, j + 2, k + 3, NovaCraftBlocks.basal, 0, 2);
		world.setBlock(i + 14, j + 2, k + 3, Blocks.lava, 0, 2);
		world.setBlock(i + 15, j + 2, k + 3, NovaCraftBlocks.cracked_basal_bricks, 0, 2);
		world.setBlock(i + 16, j + 2, k + 3, Blocks.lava, 0, 2);
		world.setBlock(i + 17, j + 2, k + 3, Blocks.lava, 0, 2);
		world.setBlock(i + 18, j + 2, k + 3, NovaCraftBlocks.cracked_basal_bricks, 0, 2);
		world.setBlock(i + 19, j + 2, k + 3, PlaceMagma, 0, 2);
		world.setBlock(i + 20, j + 2, k + 3, Blocks.lava, 0, 2);
		world.setBlock(i + 21, j + 2, k + 3, Blocks.lava, 0, 2);
		world.setBlock(i + 22, j + 2, k + 3, NovaCraftBlocks.cracked_basal_bricks, 0, 2);
		world.setBlock(i + 23, j + 2, k + 3, NovaCraftBlocks.basal, 0, 2);
		world.setBlock(i + 24, j + 2, k + 3, Blocks.lava, 0, 2);
		world.setBlock(i + 25, j + 2, k + 3, Blocks.lava, 0, 2);
		world.setBlock(i + 26, j + 2, k + 3, Blocks.lava, 0, 2);
		world.setBlock(i + 27, j + 2, k + 3, Blocks.lava, 0, 2);
		world.setBlock(i + 0, j + 2, k + 4, NovaCraftBlocks.basal, 0, 2);
		world.setBlock(i + 1, j + 2, k + 4, NovaCraftBlocks.basal, 0, 2);
		world.setBlock(i + 2, j + 2, k + 4, NovaCraftBlocks.basal, 0, 2);
		world.setBlock(i + 3, j + 2, k + 4, NovaCraftBlocks.basal, 0, 2);
		world.setBlock(i + 4, j + 2, k + 4, NovaCraftBlocks.basal, 0, 2);
		world.setBlock(i + 5, j + 2, k + 4, NovaCraftBlocks.basal, 0, 2);
		world.setBlock(i + 6, j + 2, k + 4, NovaCraftBlocks.basal, 0, 2);
		world.setBlock(i + 7, j + 2, k + 4, NovaCraftBlocks.basal, 0, 2);
		world.setBlock(i + 8, j + 2, k + 4, NovaCraftBlocks.basal, 0, 2);
		world.setBlock(i + 9, j + 2, k + 4, NovaCraftBlocks.basal, 0, 2);
		world.setBlock(i + 10, j + 2, k + 4, NovaCraftBlocks.basal, 0, 2);
		world.setBlock(i + 11, j + 2, k + 4, NovaCraftBlocks.basal, 0, 2);
		world.setBlock(i + 12, j + 2, k + 4, NovaCraftBlocks.basal, 0, 2);
		world.setBlock(i + 13, j + 2, k + 4, NovaCraftBlocks.basal, 0, 2);
		world.setBlock(i + 14, j + 2, k + 4, NovaCraftBlocks.basal, 0, 2);
		world.setBlock(i + 15, j + 2, k + 4, NovaCraftBlocks.basal, 0, 2);
		world.setBlock(i + 16, j + 2, k + 4, NovaCraftBlocks.basal, 0, 2);
		world.setBlock(i + 17, j + 2, k + 4, NovaCraftBlocks.basal, 0, 2);
		world.setBlock(i + 18, j + 2, k + 4, NovaCraftBlocks.basal, 0, 2);
		world.setBlock(i + 19, j + 2, k + 4, NovaCraftBlocks.basal, 0, 2);
		world.setBlock(i + 20, j + 2, k + 4, NovaCraftBlocks.basal, 0, 2);
		world.setBlock(i + 21, j + 2, k + 4, NovaCraftBlocks.basal, 0, 2);
		world.setBlock(i + 22, j + 2, k + 4, NovaCraftBlocks.basal, 0, 2);
		world.setBlock(i + 23, j + 2, k + 4, NovaCraftBlocks.basal, 0, 2);
		world.setBlock(i + 24, j + 2, k + 4, NovaCraftBlocks.basal, 0, 2);
		world.setBlock(i + 25, j + 2, k + 4, NovaCraftBlocks.basal, 0, 2);
		world.setBlock(i + 26, j + 2, k + 4, NovaCraftBlocks.basal, 0, 2);
		world.setBlock(i + 27, j + 2, k + 4, NovaCraftBlocks.glowing_basal, 0, 2);
		world.setBlock(i + 0, j + 2, k + 5, NovaCraftBlocks.basal, 0, 2);
		world.setBlock(i + 1, j + 2, k + 5, NovaCraftBlocks.basal, 0, 2);
		world.setBlock(i + 2, j + 2, k + 5, NovaCraftBlocks.basal, 0, 2);
		world.setBlock(i + 3, j + 2, k + 5, NovaCraftBlocks.basal, 0, 2);
		world.setBlock(i + 4, j + 2, k + 5, NovaCraftBlocks.basal, 0, 2);
		world.setBlock(i + 5, j + 2, k + 5, NovaCraftBlocks.basal, 0, 2);
		world.setBlock(i + 6, j + 2, k + 5, NovaCraftBlocks.basal, 0, 2);
		world.setBlock(i + 7, j + 2, k + 5, NovaCraftBlocks.basal, 0, 2);
		world.setBlock(i + 8, j + 2, k + 5, NovaCraftBlocks.glowing_basal, 0, 2);
		world.setBlock(i + 9, j + 2, k + 5, NovaCraftBlocks.basal, 0, 2);
		world.setBlock(i + 10, j + 2, k + 5, NovaCraftBlocks.basal, 0, 2);
		world.setBlock(i + 11, j + 2, k + 5, NovaCraftBlocks.basal, 0, 2);
		world.setBlock(i + 12, j + 2, k + 5, NovaCraftBlocks.basal, 0, 2);
		world.setBlock(i + 13, j + 2, k + 5, NovaCraftBlocks.basal, 0, 2);
		world.setBlock(i + 14, j + 2, k + 5, NovaCraftBlocks.basal, 0, 2);
		world.setBlock(i + 15, j + 2, k + 5, NovaCraftBlocks.basal, 0, 2);
		world.setBlock(i + 16, j + 2, k + 5, NovaCraftBlocks.basal, 0, 2);
		world.setBlock(i + 17, j + 2, k + 5, NovaCraftBlocks.basal, 0, 2);
		world.setBlock(i + 18, j + 2, k + 5, NovaCraftBlocks.basal, 0, 2);
		world.setBlock(i + 19, j + 2, k + 5, NovaCraftBlocks.basal, 0, 2);
		world.setBlock(i + 20, j + 2, k + 5, NovaCraftBlocks.basal, 0, 2);
		world.setBlock(i + 21, j + 2, k + 5, NovaCraftBlocks.basal, 0, 2);
		world.setBlock(i + 22, j + 2, k + 5, NovaCraftBlocks.basal, 0, 2);
		world.setBlock(i + 23, j + 2, k + 5, NovaCraftBlocks.basal, 0, 2);
		world.setBlock(i + 24, j + 2, k + 5, NovaCraftBlocks.basal, 0, 2);
		world.setBlock(i + 25, j + 2, k + 5, NovaCraftBlocks.basal, 0, 2);
		world.setBlock(i + 26, j + 2, k + 5, NovaCraftBlocks.basal, 0, 2);
		world.setBlock(i + 27, j + 2, k + 5, NovaCraftBlocks.basal, 0, 2);
		world.setBlock(i + 0, j + 2, k + 6, NovaCraftBlocks.basal, 0, 2);
		world.setBlock(i + 1, j + 2, k + 6, NovaCraftBlocks.basal, 0, 2);
		world.setBlock(i + 2, j + 2, k + 6, NovaCraftBlocks.basal, 0, 2);
		world.setBlock(i + 3, j + 2, k + 6, NovaCraftBlocks.basal, 0, 2);
		world.setBlock(i + 4, j + 2, k + 6, NovaCraftBlocks.basal, 0, 2);
		world.setBlock(i + 5, j + 2, k + 6, NovaCraftBlocks.basal, 0, 2);
		world.setBlock(i + 6, j + 2, k + 6, NovaCraftBlocks.basal, 0, 2);
		world.setBlock(i + 7, j + 2, k + 6, NovaCraftBlocks.basal, 0, 2);
		world.setBlock(i + 8, j + 2, k + 6, NovaCraftBlocks.basal, 0, 2);
		world.setBlock(i + 9, j + 2, k + 6, NovaCraftBlocks.basal, 0, 2);
		world.setBlock(i + 10, j + 2, k + 6, NovaCraftBlocks.basal, 0, 2);
		world.setBlock(i + 11, j + 2, k + 6, NovaCraftBlocks.basal, 0, 2);
		world.setBlock(i + 12, j + 2, k + 6, NovaCraftBlocks.basal, 0, 2);
		world.setBlock(i + 13, j + 2, k + 6, NovaCraftBlocks.basal, 0, 2);
		world.setBlock(i + 14, j + 2, k + 6, NovaCraftBlocks.basal, 0, 2);
		world.setBlock(i + 15, j + 2, k + 6, NovaCraftBlocks.basal, 0, 2);
		world.setBlock(i + 16, j + 2, k + 6, NovaCraftBlocks.basal, 0, 2);
		world.setBlock(i + 17, j + 2, k + 6, NovaCraftBlocks.basal, 0, 2);
		world.setBlock(i + 18, j + 2, k + 6, NovaCraftBlocks.basal, 0, 2);
		world.setBlock(i + 19, j + 2, k + 6, NovaCraftBlocks.basal, 0, 2);
		world.setBlock(i + 20, j + 2, k + 6, NovaCraftBlocks.basal, 0, 2);
		world.setBlock(i + 21, j + 2, k + 6, NovaCraftBlocks.basal, 0, 2);
		world.setBlock(i + 22, j + 2, k + 6, NovaCraftBlocks.basal, 0, 2);
		world.setBlock(i + 23, j + 2, k + 6, NovaCraftBlocks.basal, 0, 2);
		world.setBlock(i + 24, j + 2, k + 6, NovaCraftBlocks.basal, 0, 2);
		world.setBlock(i + 25, j + 2, k + 6, NovaCraftBlocks.basal, 0, 2);
		world.setBlock(i + 26, j + 2, k + 6, NovaCraftBlocks.basal, 0, 2);
		world.setBlock(i + 27, j + 2, k + 6, NovaCraftBlocks.basal, 0, 2);
		world.setBlock(i + 0, j + 2, k + 7, NovaCraftBlocks.basal, 0, 2);
		world.setBlock(i + 1, j + 2, k + 7, NovaCraftBlocks.basal, 0, 2);
		world.setBlock(i + 2, j + 2, k + 7, NovaCraftBlocks.basal, 0, 2);
		world.setBlock(i + 3, j + 2, k + 7, NovaCraftBlocks.basal, 0, 2);
		world.setBlock(i + 4, j + 2, k + 7, NovaCraftBlocks.basal, 0, 2);
		world.setBlock(i + 5, j + 2, k + 7, NovaCraftBlocks.basal, 0, 2);
		world.setBlock(i + 6, j + 2, k + 7, NovaCraftBlocks.basal, 0, 2);
		world.setBlock(i + 7, j + 2, k + 7, NovaCraftBlocks.basal, 0, 2);
		world.setBlock(i + 8, j + 2, k + 7, NovaCraftBlocks.basal, 0, 2);
		world.setBlock(i + 9, j + 2, k + 7, NovaCraftBlocks.basal, 0, 2);
		world.setBlock(i + 10, j + 2, k + 7, NovaCraftBlocks.basal, 0, 2);
		world.setBlock(i + 11, j + 2, k + 7, NovaCraftBlocks.basal, 0, 2);
		world.setBlock(i + 12, j + 2, k + 7, NovaCraftBlocks.basal, 0, 2);
		world.setBlock(i + 13, j + 2, k + 7, NovaCraftBlocks.basal, 0, 2);
		world.setBlock(i + 14, j + 2, k + 7, NovaCraftBlocks.basal, 0, 2);
		world.setBlock(i + 15, j + 2, k + 7, NovaCraftBlocks.basal, 0, 2);
		world.setBlock(i + 16, j + 2, k + 7, NovaCraftBlocks.basal, 0, 2);
		world.setBlock(i + 17, j + 2, k + 7, NovaCraftBlocks.basal, 0, 2);
		world.setBlock(i + 18, j + 2, k + 7, NovaCraftBlocks.basal, 0, 2);
		world.setBlock(i + 19, j + 2, k + 7, NovaCraftBlocks.basal, 0, 2);
		world.setBlock(i + 20, j + 2, k + 7, NovaCraftBlocks.basal, 0, 2);
		world.setBlock(i + 21, j + 2, k + 7, NovaCraftBlocks.basal, 0, 2);
		world.setBlock(i + 22, j + 2, k + 7, NovaCraftBlocks.basal, 0, 2);
		world.setBlock(i + 23, j + 2, k + 7, NovaCraftBlocks.basal, 0, 2);
		world.setBlock(i + 24, j + 2, k + 7, NovaCraftBlocks.basal, 0, 2);
		world.setBlock(i + 25, j + 2, k + 7, NovaCraftBlocks.basal, 0, 2);
		world.setBlock(i + 26, j + 2, k + 7, NovaCraftBlocks.basal, 0, 2);
		world.setBlock(i + 27, j + 2, k + 7, NovaCraftBlocks.basal, 0, 2);
		world.setBlock(i + 0, j + 2, k + 8, NovaCraftBlocks.basal, 0, 2);
		world.setBlock(i + 1, j + 2, k + 8, NovaCraftBlocks.basal, 0, 2);
		world.setBlock(i + 2, j + 2, k + 8, NovaCraftBlocks.basal, 0, 2);
		world.setBlock(i + 3, j + 2, k + 8, NovaCraftBlocks.basal, 0, 2);
		world.setBlock(i + 4, j + 2, k + 8, NovaCraftBlocks.basal, 0, 2);
		world.setBlock(i + 5, j + 2, k + 8, NovaCraftBlocks.basal, 0, 2);
		world.setBlock(i + 6, j + 2, k + 8, NovaCraftBlocks.basal, 0, 2);
		world.setBlock(i + 7, j + 2, k + 8, NovaCraftBlocks.basal, 0, 2);
		world.setBlock(i + 8, j + 2, k + 8, NovaCraftBlocks.basal, 0, 2);
		world.setBlock(i + 9, j + 2, k + 8, NovaCraftBlocks.basal, 0, 2);
		world.setBlock(i + 10, j + 2, k + 8, NovaCraftBlocks.basal, 0, 2);
		world.setBlock(i + 11, j + 2, k + 8, NovaCraftBlocks.basal, 0, 2);
		world.setBlock(i + 12, j + 2, k + 8, NovaCraftBlocks.basal, 0, 2);
		world.setBlock(i + 13, j + 2, k + 8, NovaCraftBlocks.basal, 0, 2);
		world.setBlock(i + 14, j + 2, k + 8, NovaCraftBlocks.basal, 0, 2);
		world.setBlock(i + 15, j + 2, k + 8, NovaCraftBlocks.basal, 0, 2);
		world.setBlock(i + 16, j + 2, k + 8, NovaCraftBlocks.basal, 0, 2);
		world.setBlock(i + 17, j + 2, k + 8, NovaCraftBlocks.basal, 0, 2);
		world.setBlock(i + 18, j + 2, k + 8, NovaCraftBlocks.basal, 0, 2);
		world.setBlock(i + 19, j + 2, k + 8, NovaCraftBlocks.basal, 0, 2);
		world.setBlock(i + 20, j + 2, k + 8, NovaCraftBlocks.basal, 0, 2);
		world.setBlock(i + 21, j + 2, k + 8, NovaCraftBlocks.basal, 0, 2);
		world.setBlock(i + 22, j + 2, k + 8, NovaCraftBlocks.basal, 0, 2);
		world.setBlock(i + 23, j + 2, k + 8, NovaCraftBlocks.basal, 0, 2);
		world.setBlock(i + 24, j + 2, k + 8, NovaCraftBlocks.basal, 0, 2);
		world.setBlock(i + 25, j + 2, k + 8, NovaCraftBlocks.basal, 0, 2);
		world.setBlock(i + 26, j + 2, k + 8, NovaCraftBlocks.basal, 0, 2);
		world.setBlock(i + 27, j + 2, k + 8, NovaCraftBlocks.basal, 0, 2);
		world.setBlock(i + 0, j + 2, k + 9, Blocks.lava, 0, 2);
		world.setBlock(i + 1, j + 2, k + 9, NovaCraftBlocks.basal, 0, 2);
		world.setBlock(i + 2, j + 2, k + 9, NovaCraftBlocks.basal, 0, 2);
		world.setBlock(i + 3, j + 2, k + 9, NovaCraftBlocks.basal, 0, 2);
		world.setBlock(i + 4, j + 2, k + 9, NovaCraftBlocks.basal, 0, 2);
		world.setBlock(i + 5, j + 2, k + 9, NovaCraftBlocks.basal, 0, 2);
		world.setBlock(i + 6, j + 2, k + 9, NovaCraftBlocks.basal, 0, 2);
		world.setBlock(i + 7, j + 2, k + 9, NovaCraftBlocks.basal, 0, 2);
		world.setBlock(i + 8, j + 2, k + 9, NovaCraftBlocks.basal, 0, 2);
		world.setBlock(i + 9, j + 2, k + 9, NovaCraftBlocks.basal, 0, 2);
		world.setBlock(i + 10, j + 2, k + 9, NovaCraftBlocks.basal, 0, 2);
		world.setBlock(i + 11, j + 2, k + 9, NovaCraftBlocks.basal, 0, 2);
		world.setBlock(i + 12, j + 2, k + 9, NovaCraftBlocks.basal, 0, 2);
		world.setBlock(i + 13, j + 2, k + 9, Blocks.lava, 0, 2);
		world.setBlock(i + 14, j + 2, k + 9, NovaCraftBlocks.basal, 0, 2);
		world.setBlock(i + 15, j + 2, k + 9, NovaCraftBlocks.basal, 0, 2);
		world.setBlock(i + 16, j + 2, k + 9, NovaCraftBlocks.basal, 0, 2);
		world.setBlock(i + 17, j + 2, k + 9, NovaCraftBlocks.basal, 0, 2);
		world.setBlock(i + 18, j + 2, k + 9, NovaCraftBlocks.basal, 0, 2);
		world.setBlock(i + 19, j + 2, k + 9, NovaCraftBlocks.basal, 0, 2);
		world.setBlock(i + 20, j + 2, k + 9, NovaCraftBlocks.basal, 0, 2);
		world.setBlock(i + 21, j + 2, k + 9, NovaCraftBlocks.basal, 0, 2);
		world.setBlock(i + 22, j + 2, k + 9, NovaCraftBlocks.basal, 0, 2);
		world.setBlock(i + 23, j + 2, k + 9, NovaCraftBlocks.basal, 0, 2);
		world.setBlock(i + 24, j + 2, k + 9, NovaCraftBlocks.basal, 0, 2);
		world.setBlock(i + 25, j + 2, k + 9, NovaCraftBlocks.basal, 0, 2);
		world.setBlock(i + 26, j + 2, k + 9, NovaCraftBlocks.basal, 0, 2);
		world.setBlock(i + 27, j + 2, k + 9, NovaCraftBlocks.basal, 0, 2);
		world.setBlock(i + 0, j + 2, k + 10, Blocks.lava, 0, 2);
		world.setBlock(i + 1, j + 2, k + 10, Blocks.lava, 0, 2);
		world.setBlock(i + 2, j + 2, k + 10, NovaCraftBlocks.basal, 0, 2);
		world.setBlock(i + 3, j + 2, k + 10, NovaCraftBlocks.basal, 0, 2);
		world.setBlock(i + 4, j + 2, k + 10, NovaCraftBlocks.basal, 0, 2);
		world.setBlock(i + 5, j + 2, k + 10, NovaCraftBlocks.basal, 0, 2);
		world.setBlock(i + 6, j + 2, k + 10, NovaCraftBlocks.basal, 0, 2);
		world.setBlock(i + 7, j + 2, k + 10, NovaCraftBlocks.basal, 0, 2);
		world.setBlock(i + 8, j + 2, k + 10, NovaCraftBlocks.basal, 0, 2);
		world.setBlock(i + 9, j + 2, k + 10, NovaCraftBlocks.basal, 0, 2);
		world.setBlock(i + 10, j + 2, k + 10, NovaCraftBlocks.basal, 0, 2);
		world.setBlock(i + 11, j + 2, k + 10, NovaCraftBlocks.basal, 0, 2);
		world.setBlock(i + 12, j + 2, k + 10, NovaCraftBlocks.basal, 0, 2);
		world.setBlock(i + 13, j + 2, k + 10, Blocks.lava, 0, 2);
		world.setBlock(i + 14, j + 2, k + 10, NovaCraftBlocks.basal, 0, 2);
		world.setBlock(i + 15, j + 2, k + 10, NovaCraftBlocks.basal, 0, 2);
		world.setBlock(i + 16, j + 2, k + 10, NovaCraftBlocks.basal, 0, 2);
		world.setBlock(i + 17, j + 2, k + 10, NovaCraftBlocks.basal, 0, 2);
		world.setBlock(i + 18, j + 2, k + 10, NovaCraftBlocks.basal, 0, 2);
		world.setBlock(i + 19, j + 2, k + 10, NovaCraftBlocks.basal, 0, 2);
		world.setBlock(i + 20, j + 2, k + 10, NovaCraftBlocks.basal, 0, 2);
		world.setBlock(i + 21, j + 2, k + 10, NovaCraftBlocks.basal, 0, 2);
		world.setBlock(i + 22, j + 2, k + 10, NovaCraftBlocks.basal, 0, 2);
		world.setBlock(i + 23, j + 2, k + 10, NovaCraftBlocks.basal, 0, 2);
		world.setBlock(i + 24, j + 2, k + 10, NovaCraftBlocks.basal, 0, 2);
		world.setBlock(i + 25, j + 2, k + 10, NovaCraftBlocks.basal, 0, 2);
		world.setBlock(i + 26, j + 2, k + 10, NovaCraftBlocks.basal, 0, 2);
		world.setBlock(i + 27, j + 2, k + 10, NovaCraftBlocks.basal, 0, 2);
		world.setBlock(i + 0, j + 2, k + 11, NovaCraftBlocks.basal_bricks, 0, 2);
		world.setBlock(i + 1, j + 2, k + 11, NovaCraftBlocks.basal_bricks, 0, 2);
		world.setBlock(i + 2, j + 2, k + 11, NovaCraftBlocks.basal_bricks, 0, 2);
		world.setBlock(i + 3, j + 2, k + 11, NovaCraftBlocks.cracked_basal_bricks, 0, 2);
		world.setBlock(i + 4, j + 2, k + 11, NovaCraftBlocks.basal_bricks, 0, 2);
		world.setBlock(i + 5, j + 2, k + 11, NovaCraftBlocks.basal_bricks, 0, 2);
		world.setBlock(i + 6, j + 2, k + 11, NovaCraftBlocks.basal_bricks, 0, 2);
		world.setBlock(i + 7, j + 2, k + 11, NovaCraftBlocks.basal_bricks, 0, 2);
		world.setBlock(i + 8, j + 2, k + 11, NovaCraftBlocks.basal_bricks, 0, 2);
		world.setBlock(i + 9, j + 2, k + 11, NovaCraftBlocks.basal_bricks, 0, 2);
		world.setBlock(i + 10, j + 2, k + 11, NovaCraftBlocks.cracked_basal_bricks, 0, 2);
		world.setBlock(i + 11, j + 2, k + 11, NovaCraftBlocks.basal_bricks, 0, 2);
		world.setBlock(i + 12, j + 2, k + 11, NovaCraftBlocks.cracked_basal_bricks, 0, 2);
		world.setBlock(i + 13, j + 2, k + 11, Blocks.lava, 0, 2);
		world.setBlock(i + 14, j + 2, k + 11, Blocks.lava, 0, 2);
		world.setBlock(i + 15, j + 2, k + 11, NovaCraftBlocks.basal, 0, 2);
		world.setBlock(i + 16, j + 2, k + 11, NovaCraftBlocks.basal, 0, 2);
		world.setBlock(i + 17, j + 2, k + 11, NovaCraftBlocks.basal, 0, 2);
		world.setBlock(i + 18, j + 2, k + 11, NovaCraftBlocks.basal, 0, 2);
		world.setBlock(i + 19, j + 2, k + 11, NovaCraftBlocks.basal, 0, 2);
		world.setBlock(i + 20, j + 2, k + 11, NovaCraftBlocks.basal, 0, 2);
		world.setBlock(i + 21, j + 2, k + 11, NovaCraftBlocks.basal, 0, 2);
		world.setBlock(i + 22, j + 2, k + 11, NovaCraftBlocks.basal, 0, 2);
		world.setBlock(i + 23, j + 2, k + 11, NovaCraftBlocks.basal, 0, 2);
		world.setBlock(i + 24, j + 2, k + 11, NovaCraftBlocks.basal, 0, 2);
		world.setBlock(i + 25, j + 2, k + 11, NovaCraftBlocks.basal, 0, 2);
		world.setBlock(i + 26, j + 2, k + 11, NovaCraftBlocks.basal, 0, 2);
		world.setBlock(i + 27, j + 2, k + 11, Blocks.lava, 0, 2);
		world.setBlock(i + 0, j + 2, k + 12, NovaCraftBlocks.cracked_basal_bricks, 0, 2);
		world.setBlock(i + 1, j + 2, k + 12, NovaCraftBlocks.cracked_basal_bricks, 0, 2);
		world.setBlock(i + 2, j + 2, k + 12, NovaCraftBlocks.basal_bricks, 0, 2);
		world.setBlock(i + 3, j + 2, k + 12, NovaCraftBlocks.basal_bricks, 0, 2);
		world.setBlock(i + 4, j + 2, k + 12, NovaCraftBlocks.cracked_basal_bricks, 0, 2);
		world.setBlock(i + 5, j + 2, k + 12, NovaCraftBlocks.basal_bricks, 0, 2);
		world.setBlock(i + 6, j + 2, k + 12, NovaCraftBlocks.basal_bricks, 0, 2);
		world.setBlock(i + 7, j + 2, k + 12, NovaCraftBlocks.basal_bricks, 0, 2);
		world.setBlock(i + 8, j + 2, k + 12, NovaCraftBlocks.cracked_basal_bricks, 0, 2);
		world.setBlock(i + 9, j + 2, k + 12, NovaCraftBlocks.cracked_basal_bricks, 0, 2);
		world.setBlock(i + 10, j + 2, k + 12, NovaCraftBlocks.basal_bricks, 0, 2);
		world.setBlock(i + 11, j + 2, k + 12, NovaCraftBlocks.basal_bricks, 0, 2);
		world.setBlock(i + 12, j + 2, k + 12, NovaCraftBlocks.basal_bricks, 0, 2);
		world.setBlock(i + 13, j + 2, k + 12, Blocks.lava, 0, 2);
		world.setBlock(i + 14, j + 2, k + 12, Blocks.lava, 0, 2);
		world.setBlock(i + 15, j + 2, k + 12, Blocks.lava, 0, 2);
		world.setBlock(i + 16, j + 2, k + 12, NovaCraftBlocks.basal, 0, 2);
		world.setBlock(i + 17, j + 2, k + 12, NovaCraftBlocks.basal, 0, 2);
		world.setBlock(i + 18, j + 2, k + 12, NovaCraftBlocks.basal, 0, 2);
		world.setBlock(i + 19, j + 2, k + 12, NovaCraftBlocks.basal, 0, 2);
		world.setBlock(i + 20, j + 2, k + 12, NovaCraftBlocks.basal, 0, 2);
		world.setBlock(i + 21, j + 2, k + 12, NovaCraftBlocks.basal, 0, 2);
		world.setBlock(i + 22, j + 2, k + 12, NovaCraftBlocks.basal, 0, 2);
		world.setBlock(i + 23, j + 2, k + 12, NovaCraftBlocks.basal, 0, 2);
		world.setBlock(i + 24, j + 2, k + 12, NovaCraftBlocks.basal, 0, 2);
		world.setBlock(i + 25, j + 2, k + 12, NovaCraftBlocks.basal, 0, 2);
		world.setBlock(i + 26, j + 2, k + 12, NovaCraftBlocks.basal, 0, 2);
		world.setBlock(i + 27, j + 2, k + 12, Blocks.lava, 0, 2);		
		world.setBlock(i + 0, j + 3, k + 1, NovaCraftBlocks.basal, 0, 2);
		world.setBlock(i + 1, j + 3, k + 1, NovaCraftBlocks.basal, 0, 2);
		world.setBlock(i + 4, j + 3, k + 1, NovaCraftBlocks.cracked_basal_bricks, 0, 2);
		world.setBlock(i + 5, j + 3, k + 1, PlaceMagma, 0, 2);
		world.setBlock(i + 8, j + 3, k + 1, NovaCraftBlocks.cracked_basal_bricks, 0, 2);
		world.setBlock(i + 9, j + 3, k + 1, NovaCraftBlocks.cracked_basal_bricks, 0, 2);
		world.setBlock(i + 12, j + 3, k + 1, NovaCraftBlocks.basal, 0, 2);
		world.setBlock(i + 0, j + 3, k + 2, NovaCraftBlocks.basal, 0, 2);
		world.setBlock(i + 1, j + 3, k + 2, NovaCraftBlocks.basal, 0, 2);
		world.setBlock(i + 2, j + 3, k + 2, NovaCraftBlocks.basal, 0, 2);
		world.setBlock(i + 3, j + 3, k + 2, NovaCraftBlocks.basal, 0, 2);
		world.setBlock(i + 4, j + 3, k + 2, NovaCraftBlocks.basal, 0, 2);
		world.setBlock(i + 5, j + 3, k + 2, NovaCraftBlocks.basal, 0, 2);
		world.setBlock(i + 6, j + 3, k + 2, NovaCraftBlocks.basal, 0, 2);
		world.setBlock(i + 7, j + 3, k + 2, NovaCraftBlocks.basal, 0, 2);
		world.setBlock(i + 8, j + 3, k + 2, NovaCraftBlocks.basal, 0, 2);
		world.setBlock(i + 9, j + 3, k + 2, NovaCraftBlocks.basal, 0, 2);
		world.setBlock(i + 10, j + 3, k + 2, NovaCraftBlocks.basal, 0, 2);
		world.setBlock(i + 11, j + 3, k + 2, NovaCraftBlocks.basal, 0, 2);
		world.setBlock(i + 12, j + 3, k + 2, NovaCraftBlocks.basal, 0, 2);
		world.setBlock(i + 13, j + 3, k + 2, NovaCraftBlocks.basal, 0, 2);
		world.setBlock(i + 0, j + 3, k + 3, NovaCraftBlocks.basal, 0, 2);
		world.setBlock(i + 1, j + 3, k + 3, NovaCraftBlocks.basal, 0, 2);
		world.setBlock(i + 2, j + 3, k + 3, NovaCraftBlocks.basal, 0, 2);
		world.setBlock(i + 3, j + 3, k + 3, NovaCraftBlocks.basal, 0, 2);
		world.setBlock(i + 4, j + 3, k + 3, NovaCraftBlocks.basal, 0, 2);
		world.setBlock(i + 5, j + 3, k + 3, NovaCraftBlocks.basal, 0, 2);
		world.setBlock(i + 6, j + 3, k + 3, NovaCraftBlocks.basal, 0, 2);
		world.setBlock(i + 7, j + 3, k + 3, NovaCraftBlocks.basal, 0, 2);
		world.setBlock(i + 8, j + 3, k + 3, NovaCraftBlocks.basal, 0, 2);
		world.setBlock(i + 9, j + 3, k + 3, NovaCraftBlocks.basal, 0, 2);
		world.setBlock(i + 10, j + 3, k + 3, NovaCraftBlocks.basal, 0, 2);
		world.setBlock(i + 11, j + 3, k + 3, NovaCraftBlocks.basal, 0, 2);
		world.setBlock(i + 12, j + 3, k + 3, NovaCraftBlocks.basal, 0, 2);
		world.setBlock(i + 13, j + 3, k + 3, NovaCraftBlocks.basal, 0, 2);
		world.setBlock(i + 14, j + 3, k + 3, NovaCraftBlocks.basal, 0, 2);
		world.setBlock(i + 15, j + 3, k + 3, NovaCraftBlocks.basal, 0, 2);
		world.setBlock(i + 18, j + 3, k + 3, NovaCraftBlocks.cracked_basal_bricks, 0, 2);
		world.setBlock(i + 19, j + 3, k + 3, NovaCraftBlocks.cracked_basal_bricks, 0, 2);
		world.setBlock(i + 22, j + 3, k + 3, NovaCraftBlocks.cracked_basal_bricks, 0, 2);
		world.setBlock(i + 23, j + 3, k + 3, NovaCraftBlocks.cracked_basal_bricks, 0, 2);
		world.setBlock(i + 26, j + 3, k + 3, NovaCraftBlocks.basal, 0, 2);
		world.setBlock(i + 0, j + 3, k + 4, NovaCraftBlocks.basal, 0, 2);
		world.setBlock(i + 1, j + 3, k + 4, NovaCraftBlocks.basal, 0, 2);
		world.setBlock(i + 2, j + 3, k + 4, NovaCraftBlocks.basal, 0, 2);
		world.setBlock(i + 3, j + 3, k + 4, NovaCraftBlocks.basal, 0, 2);
		world.setBlock(i + 4, j + 3, k + 4, NovaCraftBlocks.basal, 0, 2);
		world.setBlock(i + 5, j + 3, k + 4, NovaCraftBlocks.basal, 0, 2);
		world.setBlock(i + 6, j + 3, k + 4, NovaCraftBlocks.basal, 0, 2);
		world.setBlock(i + 7, j + 3, k + 4, NovaCraftBlocks.basal, 0, 2);
		world.setBlock(i + 8, j + 3, k + 4, NovaCraftBlocks.basal, 0, 2);
		world.setBlock(i + 9, j + 3, k + 4, NovaCraftBlocks.basal, 0, 2);
		world.setBlock(i + 10, j + 3, k + 4, NovaCraftBlocks.basal, 0, 2);
		world.setBlock(i + 11, j + 3, k + 4, NovaCraftBlocks.basal, 0, 2);
		world.setBlock(i + 12, j + 3, k + 4, NovaCraftBlocks.basal, 0, 2);
		world.setBlock(i + 13, j + 3, k + 4, NovaCraftBlocks.cracked_basal_bricks, 0, 2);
		world.setBlock(i + 14, j + 3, k + 4, NovaCraftBlocks.basal, 0, 2);
		world.setBlock(i + 15, j + 3, k + 4, NovaCraftBlocks.basal, 0, 2);
		world.setBlock(i + 16, j + 3, k + 4, NovaCraftBlocks.basal, 0, 2);
		world.setBlock(i + 17, j + 3, k + 4, NovaCraftBlocks.basal, 0, 2);
		world.setBlock(i + 18, j + 3, k + 4, NovaCraftBlocks.basal, 0, 2);
		world.setBlock(i + 19, j + 3, k + 4, NovaCraftBlocks.basal, 0, 2);
		world.setBlock(i + 20, j + 3, k + 4, NovaCraftBlocks.basal, 0, 2);
		world.setBlock(i + 21, j + 3, k + 4, NovaCraftBlocks.basal, 0, 2);
		world.setBlock(i + 22, j + 3, k + 4, NovaCraftBlocks.basal, 0, 2);
		world.setBlock(i + 23, j + 3, k + 4, NovaCraftBlocks.basal, 0, 2);
		world.setBlock(i + 24, j + 3, k + 4, NovaCraftBlocks.basal, 0, 2);
		world.setBlock(i + 25, j + 3, k + 4, NovaCraftBlocks.basal, 0, 2);
		world.setBlock(i + 26, j + 3, k + 4, NovaCraftBlocks.basal, 0, 2);
		world.setBlock(i + 27, j + 3, k + 4, NovaCraftBlocks.glowing_basal, 0, 2);
		world.setBlock(i + 0, j + 3, k + 5, NovaCraftBlocks.basal, 0, 2);
		world.setBlock(i + 1, j + 3, k + 5, NovaCraftBlocks.basal, 0, 2);
		world.setBlock(i + 2, j + 3, k + 5, NovaCraftBlocks.basal, 0, 2);
		world.setBlock(i + 3, j + 3, k + 5, NovaCraftBlocks.basal, 0, 2);
		world.setBlock(i + 4, j + 3, k + 5, NovaCraftBlocks.basal, 0, 2);
		world.setBlock(i + 5, j + 3, k + 5, NovaCraftBlocks.basal, 0, 2);
		world.setBlock(i + 6, j + 3, k + 5, NovaCraftBlocks.basal, 0, 2);
		world.setBlock(i + 7, j + 3, k + 5, NovaCraftBlocks.basal, 0, 2);
		world.setBlock(i + 8, j + 3, k + 5, NovaCraftBlocks.basal, 0, 2);
		world.setBlock(i + 9, j + 3, k + 5, NovaCraftBlocks.basal, 0, 2);
		world.setBlock(i + 10, j + 3, k + 5, NovaCraftBlocks.basal, 0, 2);
		world.setBlock(i + 11, j + 3, k + 5, NovaCraftBlocks.basal, 0, 2);
		world.setBlock(i + 12, j + 3, k + 5, NovaCraftBlocks.basal, 0, 2);
		world.setBlock(i + 13, j + 3, k + 5, NovaCraftBlocks.cracked_basal_bricks, 0, 2);
		world.setBlock(i + 14, j + 3, k + 5, NovaCraftBlocks.basal, 0, 2);
		world.setBlock(i + 15, j + 3, k + 5, NovaCraftBlocks.basal, 0, 2);
		world.setBlock(i + 16, j + 3, k + 5, NovaCraftBlocks.basal, 0, 2);
		world.setBlock(i + 17, j + 3, k + 5, NovaCraftBlocks.basal, 0, 2);
		world.setBlock(i + 18, j + 3, k + 5, NovaCraftBlocks.basal, 0, 2);
		world.setBlock(i + 19, j + 3, k + 5, NovaCraftBlocks.basal, 0, 2);
		world.setBlock(i + 20, j + 3, k + 5, NovaCraftBlocks.basal, 0, 2);
		world.setBlock(i + 21, j + 3, k + 5, NovaCraftBlocks.basal, 0, 2);
		world.setBlock(i + 22, j + 3, k + 5, NovaCraftBlocks.basal, 0, 2);
		world.setBlock(i + 23, j + 3, k + 5, NovaCraftBlocks.basal, 0, 2);
		world.setBlock(i + 24, j + 3, k + 5, NovaCraftBlocks.basal, 0, 2);
		world.setBlock(i + 25, j + 3, k + 5, NovaCraftBlocks.basal, 0, 2);
		world.setBlock(i + 26, j + 3, k + 5, NovaCraftBlocks.basal, 0, 2);
		world.setBlock(i + 27, j + 3, k + 5, NovaCraftBlocks.basal, 0, 2);
		world.setBlock(i + 0, j + 3, k + 6, NovaCraftBlocks.basal, 0, 2);
		world.setBlock(i + 1, j + 3, k + 6, NovaCraftBlocks.basal, 0, 2);
		world.setBlock(i + 2, j + 3, k + 6, NovaCraftBlocks.basal, 0, 2);
		world.setBlock(i + 3, j + 3, k + 6, NovaCraftBlocks.basal, 0, 2);
		world.setBlock(i + 4, j + 3, k + 6, NovaCraftBlocks.basal, 0, 2);
		world.setBlock(i + 5, j + 3, k + 6, NovaCraftBlocks.basal, 0, 2);
		world.setBlock(i + 6, j + 3, k + 6, NovaCraftBlocks.basal, 0, 2);
		world.setBlock(i + 7, j + 3, k + 6, NovaCraftBlocks.basal, 0, 2);
		world.setBlock(i + 8, j + 3, k + 6, NovaCraftBlocks.basal, 0, 2);
		world.setBlock(i + 9, j + 3, k + 6, NovaCraftBlocks.basal, 0, 2);
		world.setBlock(i + 10, j + 3, k + 6, NovaCraftBlocks.basal, 0, 2);
		world.setBlock(i + 11, j + 3, k + 6, NovaCraftBlocks.basal, 0, 2);
		world.setBlock(i + 12, j + 3, k + 6, NovaCraftBlocks.basal, 0, 2);
		world.setBlock(i + 13, j + 3, k + 6, NovaCraftBlocks.basal, 0, 2);
		world.setBlock(i + 14, j + 3, k + 6, NovaCraftBlocks.basal, 0, 2);
		world.setBlock(i + 15, j + 3, k + 6, NovaCraftBlocks.basal, 0, 2);
		world.setBlock(i + 16, j + 3, k + 6, NovaCraftBlocks.basal, 0, 2);
		world.setBlock(i + 17, j + 3, k + 6, NovaCraftBlocks.basal, 0, 2);
		world.setBlock(i + 18, j + 3, k + 6, NovaCraftBlocks.basal, 0, 2);
		world.setBlock(i + 19, j + 3, k + 6, NovaCraftBlocks.basal, 0, 2);
		world.setBlock(i + 20, j + 3, k + 6, NovaCraftBlocks.basal, 0, 2);
		world.setBlock(i + 21, j + 3, k + 6, NovaCraftBlocks.basal, 0, 2);
		world.setBlock(i + 22, j + 3, k + 6, NovaCraftBlocks.basal, 0, 2);
		world.setBlock(i + 23, j + 3, k + 6, NovaCraftBlocks.basal, 0, 2);
		world.setBlock(i + 24, j + 3, k + 6, NovaCraftBlocks.basal, 0, 2);
		world.setBlock(i + 25, j + 3, k + 6, NovaCraftBlocks.basal, 0, 2);
		world.setBlock(i + 26, j + 3, k + 6, NovaCraftBlocks.basal, 0, 2);
		world.setBlock(i + 27, j + 3, k + 6, NovaCraftBlocks.cracked_basal_bricks, 0, 2);
		world.setBlock(i + 0, j + 3, k + 7, NovaCraftBlocks.basal, 0, 2);
		world.setBlock(i + 1, j + 3, k + 7, NovaCraftBlocks.basal, 0, 2);
		world.setBlock(i + 2, j + 3, k + 7, NovaCraftBlocks.basal, 0, 2);
		world.setBlock(i + 3, j + 3, k + 7, NovaCraftBlocks.basal, 0, 2);
		world.setBlock(i + 4, j + 3, k + 7, NovaCraftBlocks.basal, 0, 2);
		world.setBlock(i + 5, j + 3, k + 7, NovaCraftBlocks.basal, 0, 2);
		world.setBlock(i + 6, j + 3, k + 7, NovaCraftBlocks.basal, 0, 2);
		world.setBlock(i + 7, j + 3, k + 7, NovaCraftBlocks.basal, 0, 2);
		world.setBlock(i + 8, j + 3, k + 7, NovaCraftBlocks.basal, 0, 2);
		world.setBlock(i + 9, j + 3, k + 7, NovaCraftBlocks.basal, 0, 2);
		world.setBlock(i + 10, j + 3, k + 7, NovaCraftBlocks.basal, 0, 2);
		world.setBlock(i + 11, j + 3, k + 7, NovaCraftBlocks.basal, 0, 2);
		world.setBlock(i + 12, j + 3, k + 7, Blocks.air, 0, 2);
		world.setBlock(i + 13, j + 3, k + 7, NovaCraftBlocks.basal, 0, 2);
		world.setBlock(i + 14, j + 3, k + 7, NovaCraftBlocks.basal, 0, 2);
		world.setBlock(i + 15, j + 3, k + 7, NovaCraftBlocks.basal, 0, 2);
		world.setBlock(i + 16, j + 3, k + 7, NovaCraftBlocks.basal, 0, 2);
		world.setBlock(i + 17, j + 3, k + 7, NovaCraftBlocks.basal, 0, 2);
		world.setBlock(i + 18, j + 3, k + 7, NovaCraftBlocks.basal, 0, 2);
		world.setBlock(i + 19, j + 3, k + 7, NovaCraftBlocks.basal, 0, 2);
		world.setBlock(i + 20, j + 3, k + 7, NovaCraftBlocks.basal, 0, 2);
		world.setBlock(i + 21, j + 3, k + 7, NovaCraftBlocks.basal, 0, 2);
		world.setBlock(i + 22, j + 3, k + 7, NovaCraftBlocks.basal, 0, 2);
		world.setBlock(i + 23, j + 3, k + 7, NovaCraftBlocks.basal, 0, 2);
		world.setBlock(i + 24, j + 3, k + 7, NovaCraftBlocks.basal, 0, 2);
		world.setBlock(i + 25, j + 3, k + 7, NovaCraftBlocks.basal, 0, 2);
		world.setBlock(i + 26, j + 3, k + 7, NovaCraftBlocks.basal, 0, 2);
		world.setBlock(i + 27, j + 3, k + 7, NovaCraftBlocks.cracked_basal_bricks, 0, 2);
		world.setBlock(i + 0, j + 3, k + 8, NovaCraftBlocks.basal, 0, 2);
		world.setBlock(i + 1, j + 3, k + 8, NovaCraftBlocks.basal, 0, 2);
		world.setBlock(i + 2, j + 3, k + 8, NovaCraftBlocks.basal, 0, 2);
		world.setBlock(i + 3, j + 3, k + 8, NovaCraftBlocks.basal, 0, 2);
		world.setBlock(i + 4, j + 3, k + 8, NovaCraftBlocks.basal, 0, 2);
		world.setBlock(i + 5, j + 3, k + 8, NovaCraftBlocks.basal, 0, 2);
		world.setBlock(i + 6, j + 3, k + 8, NovaCraftBlocks.basal, 0, 2);
		world.setBlock(i + 7, j + 3, k + 8, NovaCraftBlocks.basal, 0, 2);
		world.setBlock(i + 8, j + 3, k + 8, NovaCraftBlocks.basal, 0, 2);
		world.setBlock(i + 9, j + 3, k + 8, NovaCraftBlocks.basal, 0, 2);
		world.setBlock(i + 10, j + 3, k + 8, NovaCraftBlocks.basal, 0, 2);
		world.setBlock(i + 11, j + 3, k + 8, NovaCraftBlocks.basal, 0, 2);
		world.setBlock(i + 12, j + 3, k + 8, NovaCraftBlocks.basal, 0, 2);
		world.setBlock(i + 13, j + 3, k + 8, NovaCraftBlocks.basal, 0, 2);
		world.setBlock(i + 14, j + 3, k + 8, NovaCraftBlocks.basal, 0, 2);
		world.setBlock(i + 15, j + 3, k + 8, NovaCraftBlocks.basal, 0, 2);
		world.setBlock(i + 16, j + 3, k + 8, NovaCraftBlocks.basal, 0, 2);
		world.setBlock(i + 17, j + 3, k + 8, NovaCraftBlocks.basal, 0, 2);
		world.setBlock(i + 18, j + 3, k + 8, NovaCraftBlocks.basal, 0, 2);
		world.setBlock(i + 19, j + 3, k + 8, NovaCraftBlocks.basal, 0, 2);
		world.setBlock(i + 20, j + 3, k + 8, NovaCraftBlocks.basal, 0, 2);
		world.setBlock(i + 21, j + 3, k + 8, NovaCraftBlocks.basal, 0, 2);
		world.setBlock(i + 22, j + 3, k + 8, NovaCraftBlocks.basal, 0, 2);
		world.setBlock(i + 23, j + 3, k + 8, NovaCraftBlocks.basal, 0, 2);
		world.setBlock(i + 24, j + 3, k + 8, NovaCraftBlocks.basal, 0, 2);
		world.setBlock(i + 25, j + 3, k + 8, NovaCraftBlocks.basal, 0, 2);
		world.setBlock(i + 26, j + 3, k + 8, NovaCraftBlocks.basal, 0, 2);
		world.setBlock(i + 27, j + 3, k + 8, NovaCraftBlocks.basal, 0, 2);
		world.setBlock(i + 0, j + 3, k + 9, Blocks.air, 0, 2);
		world.setBlock(i + 1, j + 3, k + 9, NovaCraftBlocks.basal, 0, 2);
		world.setBlock(i + 2, j + 3, k + 9, NovaCraftBlocks.basal, 0, 2);
		world.setBlock(i + 3, j + 3, k + 9, NovaCraftBlocks.basal, 0, 2);
		world.setBlock(i + 4, j + 3, k + 9, NovaCraftBlocks.basal, 0, 2);
		world.setBlock(i + 5, j + 3, k + 9, NovaCraftBlocks.basal, 0, 2);
		world.setBlock(i + 6, j + 3, k + 9, NovaCraftBlocks.basal, 0, 2);
		world.setBlock(i + 7, j + 3, k + 9, NovaCraftBlocks.basal, 0, 2);
		world.setBlock(i + 8, j + 3, k + 9, NovaCraftBlocks.basal, 0, 2);
		world.setBlock(i + 9, j + 3, k + 9, NovaCraftBlocks.basal, 0, 2);
		world.setBlock(i + 10, j + 3, k + 9, NovaCraftBlocks.basal, 0, 2);
		world.setBlock(i + 11, j + 3, k + 9, NovaCraftBlocks.basal, 0, 2);
		world.setBlock(i + 12, j + 3, k + 9, NovaCraftBlocks.basal, 0, 2);
		world.setBlock(i + 13, j + 3, k + 9, Blocks.air, 0, 2);
		world.setBlock(i + 14, j + 3, k + 9, NovaCraftBlocks.basal, 0, 2);
		world.setBlock(i + 15, j + 3, k + 9, NovaCraftBlocks.basal, 0, 2);
		world.setBlock(i + 16, j + 3, k + 9, NovaCraftBlocks.basal, 0, 2);
		world.setBlock(i + 17, j + 3, k + 9, NovaCraftBlocks.basal, 0, 2);
		world.setBlock(i + 18, j + 3, k + 9, NovaCraftBlocks.basal, 0, 2);
		world.setBlock(i + 19, j + 3, k + 9, NovaCraftBlocks.basal, 0, 2);
		world.setBlock(i + 20, j + 3, k + 9, NovaCraftBlocks.basal, 0, 2);
		world.setBlock(i + 21, j + 3, k + 9, NovaCraftBlocks.basal, 0, 2);
		world.setBlock(i + 22, j + 3, k + 9, NovaCraftBlocks.basal, 0, 2);
		world.setBlock(i + 23, j + 3, k + 9, NovaCraftBlocks.basal, 0, 2);
		world.setBlock(i + 24, j + 3, k + 9, NovaCraftBlocks.basal, 0, 2);
		world.setBlock(i + 25, j + 3, k + 9, NovaCraftBlocks.basal, 0, 2);
		world.setBlock(i + 26, j + 3, k + 9, Blocks.air, 0, 2);
		world.setBlock(i + 27, j + 3, k + 9, NovaCraftBlocks.basal, 0, 2);
		world.setBlock(i + 0, j + 3, k + 10, Blocks.air, 0, 2);
		world.setBlock(i + 1, j + 3, k + 10, NovaCraftBlocks.basal, 0, 2);
		world.setBlock(i + 2, j + 3, k + 10, NovaCraftBlocks.basal, 0, 2);
		world.setBlock(i + 3, j + 3, k + 10, NovaCraftBlocks.basal, 0, 2);
		world.setBlock(i + 4, j + 3, k + 10, NovaCraftBlocks.basal, 0, 2);
		world.setBlock(i + 5, j + 3, k + 10, NovaCraftBlocks.basal, 0, 2);
		world.setBlock(i + 6, j + 3, k + 10, NovaCraftBlocks.basal, 0, 2);
		world.setBlock(i + 7, j + 3, k + 10, NovaCraftBlocks.basal, 0, 2);
		world.setBlock(i + 8, j + 3, k + 10, NovaCraftBlocks.basal, 0, 2);
		world.setBlock(i + 9, j + 3, k + 10, NovaCraftBlocks.basal, 0, 2);
		world.setBlock(i + 10, j + 3, k + 10, NovaCraftBlocks.basal, 0, 2);
		world.setBlock(i + 11, j + 3, k + 10, Blocks.air, 0, 2);
		world.setBlock(i + 12, j + 3, k + 10, Blocks.air, 0, 2);
		world.setBlock(i + 13, j + 3, k + 10, Blocks.air, 0, 2);
		world.setBlock(i + 14, j + 3, k + 10, NovaCraftBlocks.basal, 0, 2);
		world.setBlock(i + 15, j + 3, k + 10, NovaCraftBlocks.basal, 0, 2);
		world.setBlock(i + 16, j + 3, k + 10, NovaCraftBlocks.basal, 0, 2);
		world.setBlock(i + 17, j + 3, k + 10, NovaCraftBlocks.basal, 0, 2);
		world.setBlock(i + 18, j + 3, k + 10, NovaCraftBlocks.basal, 0, 2);
		world.setBlock(i + 19, j + 3, k + 10, NovaCraftBlocks.basal, 0, 2);
		world.setBlock(i + 20, j + 3, k + 10, NovaCraftBlocks.basal, 0, 2);
		world.setBlock(i + 21, j + 3, k + 10, NovaCraftBlocks.basal, 0, 2);
		world.setBlock(i + 22, j + 3, k + 10, NovaCraftBlocks.basal, 0, 2);
		world.setBlock(i + 23, j + 3, k + 10, NovaCraftBlocks.basal, 0, 2);
		world.setBlock(i + 24, j + 3, k + 10, NovaCraftBlocks.basal, 0, 2);
		world.setBlock(i + 25, j + 3, k + 10, NovaCraftBlocks.basal, 0, 2);
		world.setBlock(i + 26, j + 3, k + 10, NovaCraftBlocks.basal, 0, 2);
		world.setBlock(i + 27, j + 3, k + 10, NovaCraftBlocks.basal, 0, 2);
		world.setBlock(i + 0, j + 3, k + 11, NovaCraftBlocks.basal_bricks, 0, 2);
		world.setBlock(i + 1, j + 3, k + 11, NovaCraftBlocks.basal_bricks, 0, 2);
		world.setBlock(i + 2, j + 3, k + 11, NovaCraftBlocks.basal_bricks, 0, 2);
		world.setBlock(i + 3, j + 3, k + 11, NovaCraftBlocks.basal_bricks, 0, 2);
		world.setBlock(i + 4, j + 3, k + 11, NovaCraftBlocks.basal_bricks, 0, 2);
		world.setBlock(i + 5, j + 3, k + 11, NovaCraftBlocks.basal_bricks, 0, 2);
		world.setBlock(i + 6, j + 3, k + 11, NovaCraftBlocks.basal_bricks, 0, 2);
		world.setBlock(i + 7, j + 3, k + 11, NovaCraftBlocks.cracked_basal_bricks, 0, 2);
		world.setBlock(i + 8, j + 3, k + 11, NovaCraftBlocks.basal_bricks, 0, 2);
		world.setBlock(i + 9, j + 3, k + 11, NovaCraftBlocks.basal_bricks, 0, 2);
		world.setBlock(i + 10, j + 3, k + 11, NovaCraftBlocks.cracked_basal_bricks, 0, 2);
		world.setBlock(i + 11, j + 3, k + 11, NovaCraftBlocks.basal_bricks, 0, 2);
		world.setBlock(i + 12, j + 3, k + 11, Blocks.air, 0, 2);
		world.setBlock(i + 13, j + 3, k + 11, Blocks.air, 0, 2);
		world.setBlock(i + 14, j + 3, k + 11, Blocks.air, 0, 2);
		world.setBlock(i + 15, j + 3, k + 11, NovaCraftBlocks.basal, 0, 2);
		world.setBlock(i + 16, j + 3, k + 11, NovaCraftBlocks.basal, 0, 2);
		world.setBlock(i + 17, j + 3, k + 11, NovaCraftBlocks.basal, 0, 2);
		world.setBlock(i + 18, j + 3, k + 11, NovaCraftBlocks.basal, 0, 2);
		world.setBlock(i + 19, j + 3, k + 11, NovaCraftBlocks.basal, 0, 2);
		world.setBlock(i + 20, j + 3, k + 11, NovaCraftBlocks.basal, 0, 2);
		world.setBlock(i + 21, j + 3, k + 11, NovaCraftBlocks.basal, 0, 2);
		world.setBlock(i + 22, j + 3, k + 11, NovaCraftBlocks.basal, 0, 2);
		world.setBlock(i + 23, j + 3, k + 11, NovaCraftBlocks.basal, 0, 2);
		world.setBlock(i + 24, j + 3, k + 11, NovaCraftBlocks.basal, 0, 2);
		world.setBlock(i + 25, j + 3, k + 11, NovaCraftBlocks.basal, 0, 2);
		world.setBlock(i + 26, j + 3, k + 11, NovaCraftBlocks.basal, 0, 2);
		world.setBlock(i + 27, j + 3, k + 11, Blocks.air, 0, 2);
		world.setBlock(i + 0, j + 3, k + 12, NovaCraftBlocks.cracked_basal_bricks, 0, 2);
		world.setBlock(i + 1, j + 3, k + 12, NovaCraftBlocks.basal_bricks, 0, 2);
		world.setBlock(i + 2, j + 3, k + 12, NovaCraftBlocks.basal_bricks, 0, 2);
		world.setBlock(i + 3, j + 3, k + 12, NovaCraftBlocks.cracked_basal_bricks, 0, 2);
		world.setBlock(i + 4, j + 3, k + 12, NovaCraftBlocks.basal_bricks, 0, 2);
		world.setBlock(i + 5, j + 3, k + 12, NovaCraftBlocks.basal_bricks, 0, 2);
		world.setBlock(i + 6, j + 3, k + 12, NovaCraftBlocks.basal_bricks, 0, 2);
		world.setBlock(i + 7, j + 3, k + 12, NovaCraftBlocks.basal_bricks, 0, 2);
		world.setBlock(i + 8, j + 3, k + 12, NovaCraftBlocks.cracked_basal_bricks, 0, 2);
		world.setBlock(i + 9, j + 3, k + 12, NovaCraftBlocks.cracked_basal_bricks, 0, 2);
		world.setBlock(i + 10, j + 3, k + 12, NovaCraftBlocks.cracked_basal_bricks, 0, 2);
		world.setBlock(i + 11, j + 3, k + 12, NovaCraftBlocks.cracked_basal_bricks, 0, 2);
		world.setBlock(i + 12, j + 3, k + 12, NovaCraftBlocks.basal_bricks, 0, 2);
		world.setBlock(i + 13, j + 3, k + 12, NovaCraftBlocks.basal_bricks, 0, 2);
		world.setBlock(i + 14, j + 3, k + 12, Blocks.air, 0, 2);
		world.setBlock(i + 15, j + 3, k + 12, NovaCraftBlocks.basal, 0, 2);
		world.setBlock(i + 16, j + 3, k + 12, NovaCraftBlocks.basal, 0, 2);
		world.setBlock(i + 17, j + 3, k + 12, NovaCraftBlocks.basal, 0, 2);
		world.setBlock(i + 18, j + 3, k + 12, NovaCraftBlocks.basal, 0, 2);
		world.setBlock(i + 19, j + 3, k + 12, NovaCraftBlocks.basal, 0, 2);
		world.setBlock(i + 20, j + 3, k + 12, NovaCraftBlocks.basal, 0, 2);
		world.setBlock(i + 21, j + 3, k + 12, NovaCraftBlocks.basal, 0, 2);
		world.setBlock(i + 22, j + 3, k + 12, NovaCraftBlocks.basal, 0, 2);
		world.setBlock(i + 23, j + 3, k + 12, NovaCraftBlocks.basal, 0, 2);
		world.setBlock(i + 24, j + 3, k + 12, NovaCraftBlocks.basal, 0, 2);
		world.setBlock(i + 25, j + 3, k + 12, Blocks.air, 0, 2);
		world.setBlock(i + 26, j + 3, k + 12, Blocks.air, 0, 2);
		world.setBlock(i + 27, j + 3, k + 12, Blocks.air, 0, 2);
		world.setBlock(i + 0, j + 4, k + 1, NovaCraftBlocks.basal, 0, 2);
		world.setBlock(i + 1, j + 4, k + 1, NovaCraftBlocks.basal, 0, 2);
		world.setBlock(i + 4, j + 4, k + 1, PlaceMagma, 0, 2);
		world.setBlock(i + 5, j + 4, k + 1, NovaCraftBlocks.cracked_basal_bricks, 0, 2);
		world.setBlock(i + 8, j + 4, k + 1, NovaCraftBlocks.cracked_basal_bricks, 0, 2);
		world.setBlock(i + 9, j + 4, k + 1, NovaCraftBlocks.cracked_basal_bricks, 0, 2);
		world.setBlock(i + 0, j + 4, k + 2, NovaCraftBlocks.glowing_basal, 0, 2);
		world.setBlock(i + 1, j + 4, k + 2, NovaCraftBlocks.basal, 0, 2);
		world.setBlock(i + 2, j + 4, k + 2, NovaCraftBlocks.basal, 0, 2);
		world.setBlock(i + 3, j + 4, k + 2, NovaCraftBlocks.basal, 0, 2);
		world.setBlock(i + 4, j + 4, k + 2, NovaCraftBlocks.basal, 0, 2);
		world.setBlock(i + 5, j + 4, k + 2, NovaCraftBlocks.basal, 0, 2);
		world.setBlock(i + 6, j + 4, k + 2, NovaCraftBlocks.basal, 0, 2);
		world.setBlock(i + 7, j + 4, k + 2, NovaCraftBlocks.basal, 0, 2);
		world.setBlock(i + 8, j + 4, k + 2, NovaCraftBlocks.basal, 0, 2);
		world.setBlock(i + 9, j + 4, k + 2, NovaCraftBlocks.basal, 0, 2);
		world.setBlock(i + 10, j + 4, k + 2, NovaCraftBlocks.basal, 0, 2);
		world.setBlock(i + 11, j + 4, k + 2, NovaCraftBlocks.basal, 0, 2);
		world.setBlock(i + 12, j + 4, k + 2, NovaCraftBlocks.basal, 0, 2);
		world.setBlock(i + 13, j + 4, k + 2, NovaCraftBlocks.basal, 0, 2);
		world.setBlock(i + 0, j + 4, k + 3, NovaCraftBlocks.basal, 0, 2);
		world.setBlock(i + 1, j + 4, k + 3, NovaCraftBlocks.basal, 0, 2);
		world.setBlock(i + 2, j + 4, k + 3, NovaCraftBlocks.basal, 0, 2);
		world.setBlock(i + 3, j + 4, k + 3, NovaCraftBlocks.basal, 0, 2);
		world.setBlock(i + 4, j + 4, k + 3, NovaCraftBlocks.basal, 0, 2);
		world.setBlock(i + 5, j + 4, k + 3, NovaCraftBlocks.basal, 0, 2);
		world.setBlock(i + 6, j + 4, k + 3, NovaCraftBlocks.basal, 0, 2);
		world.setBlock(i + 7, j + 4, k + 3, NovaCraftBlocks.basal, 0, 2);
		world.setBlock(i + 8, j + 4, k + 3, NovaCraftBlocks.basal, 0, 2);
		world.setBlock(i + 9, j + 4, k + 3, NovaCraftBlocks.basal, 0, 2);
		world.setBlock(i + 10, j + 4, k + 3, NovaCraftBlocks.basal, 0, 2);
		world.setBlock(i + 11, j + 4, k + 3, NovaCraftBlocks.basal, 0, 2);
		world.setBlock(i + 12, j + 4, k + 3, NovaCraftBlocks.basal, 0, 2);
		world.setBlock(i + 13, j + 4, k + 3, NovaCraftBlocks.basal, 0, 2);
		world.setBlock(i + 14, j + 4, k + 3, NovaCraftBlocks.basal, 0, 2);
		world.setBlock(i + 15, j + 4, k + 3, NovaCraftBlocks.basal, 0, 2);
		world.setBlock(i + 18, j + 4, k + 3, PlaceMagma, 0, 2);
		world.setBlock(i + 19, j + 4, k + 3, NovaCraftBlocks.cracked_basal_bricks, 0, 2);
		world.setBlock(i + 22, j + 4, k + 3, NovaCraftBlocks.cracked_basal_bricks, 0, 2);
		world.setBlock(i + 23, j + 4, k + 3, NovaCraftBlocks.cracked_basal_bricks, 0, 2);
		world.setBlock(i + 0, j + 4, k + 4, NovaCraftBlocks.basal, 0, 2);
		world.setBlock(i + 1, j + 4, k + 4, NovaCraftBlocks.basal, 0, 2);
		world.setBlock(i + 2, j + 4, k + 4, NovaCraftBlocks.basal, 0, 2);
		world.setBlock(i + 3, j + 4, k + 4, NovaCraftBlocks.basal, 0, 2);
		world.setBlock(i + 4, j + 4, k + 4, NovaCraftBlocks.basal, 0, 2);
		world.setBlock(i + 5, j + 4, k + 4, NovaCraftBlocks.basal, 0, 2);
		world.setBlock(i + 6, j + 4, k + 4, NovaCraftBlocks.basal, 0, 2);
		world.setBlock(i + 7, j + 4, k + 4, NovaCraftBlocks.basal, 0, 2);
		world.setBlock(i + 8, j + 4, k + 4, NovaCraftBlocks.basal, 0, 2);
		world.setBlock(i + 9, j + 4, k + 4, NovaCraftBlocks.basal, 0, 2);
		world.setBlock(i + 10, j + 4, k + 4, NovaCraftBlocks.basal, 0, 2);
		world.setBlock(i + 11, j + 4, k + 4, NovaCraftBlocks.basal, 0, 2);
		world.setBlock(i + 12, j + 4, k + 4, NovaCraftBlocks.cracked_basal_bricks, 0, 2);
		world.setBlock(i + 13, j + 4, k + 4, NovaCraftBlocks.cracked_basal_bricks, 0, 2);
		world.setBlock(i + 14, j + 4, k + 4, NovaCraftBlocks.basal, 0, 2);
		world.setBlock(i + 15, j + 4, k + 4, NovaCraftBlocks.basal, 0, 2);
		world.setBlock(i + 16, j + 4, k + 4, NovaCraftBlocks.basal, 0, 2);
		world.setBlock(i + 17, j + 4, k + 4, NovaCraftBlocks.basal, 0, 2);
		world.setBlock(i + 18, j + 4, k + 4, NovaCraftBlocks.basal, 0, 2);
