package com.NovaCraft.world.bastion.treasure;

import net.minecraft.world.gen.feature.*;
import net.minecraft.world.*;
import java.util.*;
import com.NovaCraftBlocks.NovaCraftBlocks;
import net.minecraft.init.*;

public class BastionTreasureBridgeGen3 extends WorldGenerator
{
	public BastionTreasureBridgeGen3() {

	}
	
	public boolean generate(final World world, final Random random, final int i, final int j, final int k) {
		
		world.setBlock(i + 3, j + 10, k + 4, NovaCraftBlocks.cracked_basal_bricks, 0, 2);
		world.setBlock(i + 4, j + 10, k + 4, NovaCraftBlocks.cracked_basal_bricks, 0, 2);
		world.setBlock(i + 5, j + 10, k + 4, NovaCraftBlocks.cracked_basal_bricks, 0, 2);
		world.setBlock(i + 6, j + 10, k + 4, NovaCraftBlocks.basal_bricks, 0, 2);
		world.setBlock(i + 7, j + 10, k + 4, NovaCraftBlocks.basal_bricks, 0, 2);
		world.setBlock(i + 8, j + 10, k + 4, NovaCraftBlocks.basal_bricks, 0, 2);
		world.setBlock(i + 9, j + 10, k + 4, NovaCraftBlocks.basal_bricks, 0, 2);
		world.setBlock(i + 10, j + 10, k + 4, NovaCraftBlocks.basal_bricks, 0, 2);
		world.setBlock(i + 11, j + 10, k + 4, NovaCraftBlocks.basal_bricks, 0, 2);
		world.setBlock(i + 12, j + 10, k + 4, NovaCraftBlocks.basal_bricks, 0, 2);
		world.setBlock(i + 13, j + 10, k + 4, NovaCraftBlocks.basal_bricks, 0, 2);
		world.setBlock(i + 14, j + 10, k + 4, NovaCraftBlocks.cracked_basal_bricks, 0, 2);
		world.setBlock(i + 15, j + 10, k + 4, NovaCraftBlocks.cracked_basal_bricks, 0, 2);
		world.setBlock(i + 16, j + 10, k + 4, NovaCraftBlocks.cracked_basal_bricks, 0, 2);
		world.setBlock(i + 17, j + 10, k + 4, NovaCraftBlocks.basal_bricks, 0, 2);
		world.setBlock(i + 18, j + 10, k + 4, NovaCraftBlocks.basal_bricks, 0, 2);
		world.setBlock(i + 19, j + 10, k + 4, NovaCraftBlocks.basal_bricks, 0, 2);
		world.setBlock(i + 20, j + 10, k + 4, NovaCraftBlocks.cracked_basal_bricks, 0, 2);
		world.setBlock(i + 21, j + 10, k + 4, NovaCraftBlocks.cracked_basal_bricks, 0, 2);
		world.setBlock(i + 22, j + 10, k + 4, NovaCraftBlocks.cracked_basal_bricks, 0, 2);
		world.setBlock(i + 23, j + 10, k + 4, NovaCraftBlocks.basal_bricks, 0, 2);
		world.setBlock(i + 24, j + 10, k + 4, NovaCraftBlocks.cracked_basal_bricks, 0, 2);
		world.setBlock(i + 25, j + 10, k + 4, NovaCraftBlocks.basal_bricks, 0, 2);
		world.setBlock(i + 26, j + 10, k + 4, NovaCraftBlocks.cracked_basal_bricks, 0, 2);
		world.setBlock(i + 27, j + 10, k + 4, NovaCraftBlocks.basal_bricks, 0, 2);
		world.setBlock(i, j + 10, k + 5, NovaCraftBlocks.basal_bricks, 0, 2);
		world.setBlock(i + 1, j + 10, k + 5, NovaCraftBlocks.basal_bricks, 0, 2);
		world.setBlock(i + 2, j + 10, k + 5, NovaCraftBlocks.cracked_basal_bricks, 0, 2);
		world.setBlock(i + 3, j + 10, k + 5, NovaCraftBlocks.basal_bricks, 0, 2);
		world.setBlock(i + 4, j + 10, k + 5, NovaCraftBlocks.cracked_basal_bricks, 0, 2);
		world.setBlock(i + 5, j + 10, k + 5, NovaCraftBlocks.basal_bricks, 0, 2);
		world.setBlock(i + 6, j + 10, k + 5, NovaCraftBlocks.basal_bricks, 0, 2);
		world.setBlock(i + 7, j + 10, k + 5, NovaCraftBlocks.basal_bricks, 0, 2);
		world.setBlock(i + 8, j + 10, k + 5, NovaCraftBlocks.basal_bricks, 0, 2);
		world.setBlock(i + 9, j + 10, k + 5, NovaCraftBlocks.basal_bricks, 0, 2);
		world.setBlock(i + 10, j + 10, k + 5, NovaCraftBlocks.basal_bricks, 0, 2);
		world.setBlock(i + 11, j + 10, k + 5, NovaCraftBlocks.basal_bricks, 0, 2);
		world.setBlock(i + 12, j + 10, k + 5, NovaCraftBlocks.basal_bricks, 0, 2);
		world.setBlock(i + 13, j + 10, k + 5, NovaCraftBlocks.basal_bricks, 0, 2);
		world.setBlock(i + 14, j + 10, k + 5, NovaCraftBlocks.basal_bricks, 0, 2);
		world.setBlock(i + 15, j + 10, k + 5, NovaCraftBlocks.basal_bricks, 0, 2);
		world.setBlock(i + 16, j + 10, k + 5, NovaCraftBlocks.cracked_basal_bricks, 0, 2);
		world.setBlock(i + 17, j + 10, k + 5, NovaCraftBlocks.cracked_basal_bricks, 0, 2);
		world.setBlock(i + 18, j + 10, k + 5, NovaCraftBlocks.cracked_basal_bricks, 0, 2);
		world.setBlock(i + 19, j + 10, k + 5, NovaCraftBlocks.basal_bricks, 0, 2);
		world.setBlock(i + 20, j + 10, k + 5, NovaCraftBlocks.cracked_basal_bricks, 0, 2);
		world.setBlock(i + 21, j + 10, k + 5, NovaCraftBlocks.cracked_basal_bricks, 0, 2);
		world.setBlock(i + 22, j + 10, k + 5, NovaCraftBlocks.cracked_basal_bricks, 0, 2);
		world.setBlock(i + 23, j + 10, k + 5, NovaCraftBlocks.basal_bricks, 0, 2);
		world.setBlock(i + 24, j + 10, k + 5, NovaCraftBlocks.basal_bricks, 0, 2);
		world.setBlock(i + 25, j + 10, k + 5, NovaCraftBlocks.basal_bricks, 0, 2);
		world.setBlock(i + 26, j + 10, k + 5, NovaCraftBlocks.cracked_basal_bricks, 0, 2);
		world.setBlock(i + 27, j + 10, k + 5, NovaCraftBlocks.basal_bricks, 0, 2);
		world.setBlock(i, j + 10, k + 6, NovaCraftBlocks.basal_bricks, 0, 2);
		world.setBlock(i + 1, j + 10, k + 6, NovaCraftBlocks.basal_bricks, 0, 2);
		world.setBlock(i + 2, j + 10, k + 6, NovaCraftBlocks.basal_bricks, 0, 2);
		world.setBlock(i + 3, j + 10, k + 6, NovaCraftBlocks.cracked_basal_bricks, 0, 2);
		world.setBlock(i + 4, j + 10, k + 6, NovaCraftBlocks.basal_bricks, 0, 2);
		world.setBlock(i + 5, j + 10, k + 6, NovaCraftBlocks.basal_bricks, 0, 2);
		world.setBlock(i + 6, j + 10, k + 6, NovaCraftBlocks.basal_bricks, 0, 2);
		world.setBlock(i + 7, j + 10, k + 6, NovaCraftBlocks.basal_bricks, 0, 2);
		world.setBlock(i + 8, j + 10, k + 6, NovaCraftBlocks.basal_bricks, 0, 2);
		world.setBlock(i + 9, j + 10, k + 6, NovaCraftBlocks.basal_bricks, 0, 2);
		world.setBlock(i + 10, j + 10, k + 6, NovaCraftBlocks.basal_bricks, 0, 2);
		world.setBlock(i + 11, j + 10, k + 6, NovaCraftBlocks.basal_bricks, 0, 2);
		world.setBlock(i + 12, j + 10, k + 6, NovaCraftBlocks.cracked_basal_bricks, 0, 2);
		world.setBlock(i + 13, j + 10, k + 6, NovaCraftBlocks.basal_bricks, 0, 2);
		world.setBlock(i + 14, j + 10, k + 6, NovaCraftBlocks.cracked_basal_bricks, 0, 2);
		world.setBlock(i + 15, j + 10, k + 6, NovaCraftBlocks.basal_bricks, 0, 2);
		world.setBlock(i + 16, j + 10, k + 6, NovaCraftBlocks.cracked_basal_bricks, 0, 2);
		world.setBlock(i + 17, j + 10, k + 6, NovaCraftBlocks.cracked_basal_bricks, 0, 2);
		world.setBlock(i + 18, j + 10, k + 6, NovaCraftBlocks.cracked_basal_bricks, 0, 2);
		world.setBlock(i + 19, j + 10, k + 6, NovaCraftBlocks.basal_bricks, 0, 2);
		world.setBlock(i + 20, j + 10, k + 6, NovaCraftBlocks.basal_bricks, 0, 2);
		world.setBlock(i + 21, j + 10, k + 6, NovaCraftBlocks.cracked_basal_bricks, 0, 2);
		world.setBlock(i + 22, j + 10, k + 6, NovaCraftBlocks.basal_bricks, 0, 2);
		world.setBlock(i + 23, j + 10, k + 6, NovaCraftBlocks.basal_bricks, 0, 2);
		world.setBlock(i + 24, j + 10, k + 6, NovaCraftBlocks.cracked_basal_bricks, 0, 2);
		world.setBlock(i + 25, j + 10, k + 6, NovaCraftBlocks.cracked_basal_bricks, 0, 2);
		world.setBlock(i + 26, j + 10, k + 6, NovaCraftBlocks.basal_bricks, 0, 2);
		world.setBlock(i + 27, j + 10, k + 6, NovaCraftBlocks.basal_bricks, 0, 2);
		world.setBlock(i, j + 10, k + 7, NovaCraftBlocks.cracked_basal_bricks, 0, 2);
		world.setBlock(i + 1, j + 10, k + 7, NovaCraftBlocks.basal_bricks, 0, 2);
		world.setBlock(i + 2, j + 10, k + 7, NovaCraftBlocks.cracked_basal_bricks, 0, 2);
		world.setBlock(i + 3, j + 10, k + 7, NovaCraftBlocks.basal_bricks, 0, 2);
		world.setBlock(i + 4, j + 10, k + 7, NovaCraftBlocks.cracked_basal_bricks, 0, 2);
		world.setBlock(i + 5, j + 10, k + 7, NovaCraftBlocks.basal_bricks, 0, 2);
		world.setBlock(i + 6, j + 10, k + 7, NovaCraftBlocks.basal_bricks, 0, 2);
		world.setBlock(i + 7, j + 10, k + 7, NovaCraftBlocks.basal_bricks, 0, 2);
		world.setBlock(i + 8, j + 10, k + 7, NovaCraftBlocks.cracked_basal_bricks, 0, 2);
		world.setBlock(i + 9, j + 10, k + 7, NovaCraftBlocks.basal_bricks, 0, 2);
		world.setBlock(i + 10, j + 10, k + 7, NovaCraftBlocks.basal_bricks, 0, 2);
		world.setBlock(i + 11, j + 10, k + 7, NovaCraftBlocks.basal_bricks, 0, 2);
		world.setBlock(i + 12, j + 10, k + 7, NovaCraftBlocks.cracked_basal_bricks, 0, 2);
		world.setBlock(i + 13, j + 10, k + 7, NovaCraftBlocks.basal_bricks, 0, 2);
		world.setBlock(i + 14, j + 10, k + 7, NovaCraftBlocks.basal_bricks, 0, 2);
		world.setBlock(i + 15, j + 10, k + 7, NovaCraftBlocks.basal_bricks, 0, 2);
		world.setBlock(i + 16, j + 10, k + 7, NovaCraftBlocks.cracked_basal_bricks, 0, 2);
		world.setBlock(i + 17, j + 10, k + 7, NovaCraftBlocks.basal_bricks, 0, 2);
		world.setBlock(i + 18, j + 10, k + 7, NovaCraftBlocks.cracked_basal_bricks, 0, 2);
		world.setBlock(i + 19, j + 10, k + 7, NovaCraftBlocks.cracked_basal_bricks, 0, 2);
		world.setBlock(i + 20, j + 10, k + 7, NovaCraftBlocks.basal_bricks, 0, 2);
		world.setBlock(i + 21, j + 10, k + 7, NovaCraftBlocks.basal_bricks, 0, 2);
		world.setBlock(i + 22, j + 10, k + 7, NovaCraftBlocks.basal_bricks, 0, 2);
		world.setBlock(i + 23, j + 10, k + 7, NovaCraftBlocks.basal_bricks, 0, 2);
		world.setBlock(i + 24, j + 10, k + 7, NovaCraftBlocks.cracked_basal_bricks, 0, 2);
		world.setBlock(i + 25, j + 10, k + 7, NovaCraftBlocks.basal_bricks, 0, 2);
		world.setBlock(i + 26, j + 10, k + 7, NovaCraftBlocks.basal_bricks, 0, 2);
		world.setBlock(i + 27, j + 10, k + 7, NovaCraftBlocks.basal_bricks, 0, 2);
		world.setBlock(i, j + 10, k + 8, NovaCraftBlocks.basal_bricks, 0, 2);
		world.setBlock(i + 1, j + 10, k + 8, NovaCraftBlocks.basal_bricks, 0, 2);
		world.setBlock(i + 2, j + 10, k + 8, NovaCraftBlocks.basal_bricks, 0, 2);
		world.setBlock(i + 3, j + 10, k + 8, NovaCraftBlocks.basal_bricks, 0, 2);
		world.setBlock(i + 4, j + 10, k + 8, NovaCraftBlocks.cracked_basal_bricks, 0, 2);
		world.setBlock(i + 5, j + 10, k + 8, NovaCraftBlocks.basal_bricks, 0, 2);
		world.setBlock(i + 6, j + 10, k + 8, NovaCraftBlocks.basal_bricks, 0, 2);
		world.setBlock(i + 7, j + 10, k + 8, NovaCraftBlocks.basal_bricks, 0, 2);
		world.setBlock(i + 8, j + 10, k + 8, NovaCraftBlocks.basal_bricks, 0, 2);
		world.setBlock(i + 9, j + 10, k + 8, NovaCraftBlocks.basal_bricks, 0, 2);
		world.setBlock(i + 10, j + 10, k + 8, NovaCraftBlocks.basal_bricks, 0, 2);
		world.setBlock(i + 11, j + 10, k + 8, NovaCraftBlocks.basal_bricks, 0, 2);
		world.setBlock(i + 12, j + 10, k + 8, NovaCraftBlocks.cracked_basal_bricks, 0, 2);
		world.setBlock(i + 13, j + 10, k + 8, NovaCraftBlocks.cracked_basal_bricks, 0, 2);
		world.setBlock(i + 14, j + 10, k + 8, NovaCraftBlocks.cracked_basal_bricks, 0, 2);
		world.setBlock(i + 15, j + 10, k + 8, NovaCraftBlocks.basal_bricks, 0, 2);
		world.setBlock(i + 16, j + 10, k + 8, NovaCraftBlocks.basal_bricks, 0, 2);
		world.setBlock(i + 17, j + 10, k + 8, NovaCraftBlocks.basal_bricks, 0, 2);
		world.setBlock(i + 18, j + 10, k + 8, NovaCraftBlocks.cracked_basal_bricks, 0, 2);
		world.setBlock(i + 19, j + 10, k + 8, NovaCraftBlocks.basal_bricks, 0, 2);
		world.setBlock(i + 20, j + 10, k + 8, NovaCraftBlocks.cracked_basal_bricks, 0, 2);
		world.setBlock(i + 21, j + 10, k + 8, NovaCraftBlocks.basal_bricks, 0, 2);
		world.setBlock(i + 22, j + 10, k + 8, NovaCraftBlocks.cracked_basal_bricks, 0, 2);
		world.setBlock(i + 23, j + 10, k + 8, NovaCraftBlocks.basal_bricks, 0, 2);
		world.setBlock(i + 24, j + 10, k + 8, NovaCraftBlocks.basal_bricks, 0, 2);
		world.setBlock(i + 25, j + 10, k + 8, NovaCraftBlocks.basal_bricks, 0, 2);
		world.setBlock(i + 26, j + 10, k + 8, NovaCraftBlocks.basal_bricks, 0, 2);
		world.setBlock(i + 27, j + 10, k + 8, NovaCraftBlocks.basal_bricks, 0, 2);
		world.setBlock(i, j + 10, k + 9, NovaCraftBlocks.basal_bricks, 0, 2);
		world.setBlock(i + 1, j + 10, k + 9, NovaCraftBlocks.cracked_basal_bricks, 0, 2);
		world.setBlock(i + 2, j + 10, k + 9, NovaCraftBlocks.cracked_basal_bricks, 0, 2);
		world.setBlock(i + 3, j + 10, k + 9, NovaCraftBlocks.basal_bricks, 0, 2);
		world.setBlock(i + 4, j + 10, k + 9, NovaCraftBlocks.basal_bricks, 0, 2);
		world.setBlock(i + 5, j + 10, k + 9, NovaCraftBlocks.cracked_basal_bricks, 0, 2);
		world.setBlock(i + 6, j + 10, k + 9, NovaCraftBlocks.cracked_basal_bricks, 0, 2);
		world.setBlock(i + 7, j + 10, k + 9, NovaCraftBlocks.cracked_basal_bricks, 0, 2);
		world.setBlock(i + 8, j + 10, k + 9, NovaCraftBlocks.cracked_basal_bricks, 0, 2);
		world.setBlock(i + 9, j + 10, k + 9, NovaCraftBlocks.basal_bricks, 0, 2);
		world.setBlock(i + 10, j + 10, k + 9, NovaCraftBlocks.basal_bricks, 0, 2);
		world.setBlock(i + 11, j + 10, k + 9, NovaCraftBlocks.basal_bricks, 0, 2);
		world.setBlock(i + 12, j + 10, k + 9, NovaCraftBlocks.basal_bricks, 0, 2);
		world.setBlock(i + 13, j + 10, k + 9, NovaCraftBlocks.basal_bricks, 0, 2);
		world.setBlock(i + 14, j + 10, k + 9, NovaCraftBlocks.cracked_basal_bricks, 0, 2);
		world.setBlock(i + 15, j + 10, k + 9, NovaCraftBlocks.basal_bricks, 0, 2);
		world.setBlock(i + 16, j + 10, k + 9, NovaCraftBlocks.basal_bricks, 0, 2);
		world.setBlock(i + 17, j + 10, k + 9, NovaCraftBlocks.basal_bricks, 0, 2);
		world.setBlock(i + 18, j + 10, k + 9, NovaCraftBlocks.cracked_basal_bricks, 0, 2);
		world.setBlock(i + 19, j + 10, k + 9, NovaCraftBlocks.basal_bricks, 0, 2);
		world.setBlock(i + 20, j + 10, k + 9, NovaCraftBlocks.basal_bricks, 0, 2);
		world.setBlock(i + 21, j + 10, k + 9, NovaCraftBlocks.basal_bricks, 0, 2);
		world.setBlock(i + 22, j + 10, k + 9, NovaCraftBlocks.basal_bricks, 0, 2);
		world.setBlock(i + 23, j + 10, k + 9, NovaCraftBlocks.basal_bricks, 0, 2);
		world.setBlock(i + 24, j + 10, k + 9, NovaCraftBlocks.basal_bricks, 0, 2);
		world.setBlock(i + 25, j + 10, k + 9, NovaCraftBlocks.basal_bricks, 0, 2);
		world.setBlock(i + 26, j + 10, k + 9, NovaCraftBlocks.cracked_basal_bricks, 0, 2);
		world.setBlock(i + 27, j + 10, k + 9, NovaCraftBlocks.basal_bricks, 0, 2);
		world.setBlock(i, j + 10, k + 10, NovaCraftBlocks.cracked_basal_bricks, 0, 2);
		world.setBlock(i + 1, j + 10, k + 10, NovaCraftBlocks.basal_bricks, 0, 2);
		world.setBlock(i + 2, j + 10, k + 10, NovaCraftBlocks.basal_bricks, 0, 2);
		world.setBlock(i + 3, j + 10, k + 10, NovaCraftBlocks.cracked_basal_bricks, 0, 2);
		world.setBlock(i + 4, j + 10, k + 10, NovaCraftBlocks.cracked_basal_bricks, 0, 2);
		world.setBlock(i + 5, j + 10, k + 10, NovaCraftBlocks.cracked_basal_bricks, 0, 2);
		world.setBlock(i + 6, j + 10, k + 10, NovaCraftBlocks.cracked_basal_bricks, 0, 2);
		world.setBlock(i + 7, j + 10, k + 10, NovaCraftBlocks.basal_bricks, 0, 2);
		world.setBlock(i + 8, j + 10, k + 10, NovaCraftBlocks.cracked_basal_bricks, 0, 2);
		world.setBlock(i + 9, j + 10, k + 10, NovaCraftBlocks.basal_bricks, 0, 2);
		world.setBlock(i + 10, j + 10, k + 10, NovaCraftBlocks.basal_bricks, 0, 2);
		world.setBlock(i + 11, j + 10, k + 10, NovaCraftBlocks.basal_bricks, 0, 2);
		world.setBlock(i + 12, j + 10, k + 10, NovaCraftBlocks.basal_bricks, 0, 2);
		world.setBlock(i + 13, j + 10, k + 10, NovaCraftBlocks.cracked_basal_bricks, 0, 2);
		world.setBlock(i + 14, j + 10, k + 10, NovaCraftBlocks.cracked_basal_bricks, 0, 2);
		world.setBlock(i + 15, j + 10, k + 10, NovaCraftBlocks.basal_bricks, 0, 2);
		world.setBlock(i + 16, j + 10, k + 10, NovaCraftBlocks.basal_bricks, 0, 2);
		world.setBlock(i + 17, j + 10, k + 10, NovaCraftBlocks.basal_bricks, 0, 2);
		world.setBlock(i + 18, j + 10, k + 10, NovaCraftBlocks.basal_bricks, 0, 2);
		world.setBlock(i + 19, j + 10, k + 10, NovaCraftBlocks.cracked_basal_bricks, 0, 2);
		world.setBlock(i + 20, j + 10, k + 10, NovaCraftBlocks.basal_bricks, 0, 2);
		world.setBlock(i + 21, j + 10, k + 10, NovaCraftBlocks.cracked_basal_bricks, 0, 2);
		world.setBlock(i + 22, j + 10, k + 10, NovaCraftBlocks.basal_bricks, 0, 2);
		world.setBlock(i + 23, j + 10, k + 10, NovaCraftBlocks.cracked_basal_bricks, 0, 2);
		world.setBlock(i + 24, j + 10, k + 10, NovaCraftBlocks.basal_bricks, 0, 2);
		world.setBlock(i + 25, j + 10, k + 10, NovaCraftBlocks.basal_bricks, 0, 2);
		world.setBlock(i + 26, j + 10, k + 10, NovaCraftBlocks.cracked_basal_bricks, 0, 2);
		world.setBlock(i + 27, j + 10, k + 10, NovaCraftBlocks.basal_bricks, 0, 2);
		world.setBlock(i, j + 10, k + 11, NovaCraftBlocks.basal_bricks, 0, 2);
		world.setBlock(i + 1, j + 10, k + 11, NovaCraftBlocks.cracked_basal_bricks, 0, 2);
		world.setBlock(i + 2, j + 10, k + 11, NovaCraftBlocks.cracked_basal_bricks, 0, 2);
		world.setBlock(i + 3, j + 10, k + 11, NovaCraftBlocks.basal_bricks, 0, 2);
		world.setBlock(i + 4, j + 10, k + 11, NovaCraftBlocks.basal_bricks, 0, 2);
		world.setBlock(i + 5, j + 10, k + 11, NovaCraftBlocks.cracked_basal_bricks, 0, 2);
		world.setBlock(i + 6, j + 10, k + 11, NovaCraftBlocks.cracked_basal_bricks, 0, 2);
		world.setBlock(i + 7, j + 10, k + 11, NovaCraftBlocks.basal_bricks, 0, 2);
		world.setBlock(i + 8, j + 10, k + 11, NovaCraftBlocks.basal_bricks, 0, 2);
		world.setBlock(i + 9, j + 10, k + 11, NovaCraftBlocks.cracked_basal_bricks, 0, 2);
		world.setBlock(i + 10, j + 10, k + 11, NovaCraftBlocks.basal_bricks, 0, 2);
		world.setBlock(i + 11, j + 10, k + 11, NovaCraftBlocks.basal_bricks, 0, 2);
		world.setBlock(i + 12, j + 10, k + 11, NovaCraftBlocks.basal_bricks, 0, 2);
		world.setBlock(i + 13, j + 10, k + 11, NovaCraftBlocks.basal_bricks, 0, 2);
		world.setBlock(i + 14, j + 10, k + 11, NovaCraftBlocks.basal_bricks, 0, 2);
		world.setBlock(i + 15, j + 10, k + 11, NovaCraftBlocks.basal_bricks, 0, 2);
		world.setBlock(i + 16, j + 10, k + 11, NovaCraftBlocks.cracked_basal_bricks, 0, 2);
		world.setBlock(i + 17, j + 10, k + 11, NovaCraftBlocks.basal_bricks, 0, 2);
		world.setBlock(i + 18, j + 10, k + 11, NovaCraftBlocks.cracked_basal_bricks, 0, 2);
		world.setBlock(i + 19, j + 10, k + 11, NovaCraftBlocks.cracked_basal_bricks, 0, 2);
		world.setBlock(i + 20, j + 10, k + 11, NovaCraftBlocks.cracked_basal_bricks, 0, 2);
		world.setBlock(i + 21, j + 10, k + 11, NovaCraftBlocks.cracked_basal_bricks, 0, 2);
		world.setBlock(i + 22, j + 10, k + 11, NovaCraftBlocks.cracked_basal_bricks, 0, 2);
		world.setBlock(i + 23, j + 10, k + 11, NovaCraftBlocks.basal_bricks, 0, 2);
		world.setBlock(i + 24, j + 10, k + 11, NovaCraftBlocks.basal_bricks, 0, 2);
		world.setBlock(i + 25, j + 10, k + 11, NovaCraftBlocks.basal_bricks, 0, 2);
		world.setBlock(i + 26, j + 10, k + 11, NovaCraftBlocks.cracked_basal_bricks, 0, 2);
		world.setBlock(i + 27, j + 10, k + 11, NovaCraftBlocks.cracked_basal_bricks, 0, 2);
		world.setBlock(i, j + 10, k + 12, NovaCraftBlocks.cracked_basal_bricks, 0, 2);
		world.setBlock(i + 1, j + 10, k + 12, NovaCraftBlocks.cracked_basal_bricks, 0, 2);
		world.setBlock(i + 2, j + 10, k + 12, NovaCraftBlocks.cracked_basal_bricks, 0, 2);
		world.setBlock(i + 3, j + 10, k + 12, NovaCraftBlocks.basal_bricks, 0, 2);
		world.setBlock(i + 4, j + 10, k + 12, NovaCraftBlocks.basal_bricks, 0, 2);
		world.setBlock(i + 5, j + 10, k + 12, NovaCraftBlocks.basal_bricks, 0, 2);
		world.setBlock(i + 6, j + 10, k + 12, NovaCraftBlocks.basal_bricks, 0, 2);
		world.setBlock(i + 7, j + 10, k + 12, NovaCraftBlocks.basal_bricks, 0, 2);
		world.setBlock(i + 8, j + 10, k + 12, NovaCraftBlocks.basal_bricks, 0, 2);
		world.setBlock(i + 9, j + 10, k + 12, NovaCraftBlocks.cracked_basal_bricks, 0, 2);
		world.setBlock(i + 10, j + 10, k + 12, NovaCraftBlocks.basal_bricks, 0, 2);
		world.setBlock(i + 11, j + 10, k + 12, NovaCraftBlocks.cracked_basal_bricks, 0, 2);
		world.setBlock(i + 12, j + 10, k + 12, NovaCraftBlocks.cracked_basal_bricks, 0, 2);
		world.setBlock(i + 13, j + 10, k + 12, NovaCraftBlocks.basal_bricks, 0, 2);
		world.setBlock(i + 14, j + 10, k + 12, NovaCraftBlocks.cracked_basal_bricks, 0, 2);
		world.setBlock(i + 15, j + 10, k + 12, NovaCraftBlocks.cracked_basal_bricks, 0, 2);
		world.setBlock(i + 16, j + 10, k + 12, NovaCraftBlocks.basal_bricks, 0, 2);
		world.setBlock(i + 17, j + 10, k + 12, NovaCraftBlocks.cracked_basal_bricks, 0, 2);
		world.setBlock(i + 18, j + 10, k + 12, NovaCraftBlocks.cracked_basal_bricks, 0, 2);
		world.setBlock(i + 19, j + 10, k + 12, NovaCraftBlocks.basal_bricks, 0, 2);
		world.setBlock(i + 20, j + 10, k + 12, NovaCraftBlocks.cracked_basal_bricks, 0, 2);
		world.setBlock(i + 21, j + 10, k + 12, NovaCraftBlocks.cracked_basal_bricks, 0, 2);
		world.setBlock(i + 22, j + 10, k + 12, NovaCraftBlocks.cracked_basal_bricks, 0, 2);
		world.setBlock(i + 23, j + 10, k + 12, NovaCraftBlocks.cracked_basal_bricks, 0, 2);
		world.setBlock(i + 24, j + 10, k + 12, NovaCraftBlocks.basal_bricks, 0, 2);
		world.setBlock(i + 25, j + 10, k + 12, NovaCraftBlocks.basal_bricks, 0, 2);
		world.setBlock(i + 26, j + 10, k + 12, NovaCraftBlocks.basal_bricks, 0, 2);
		world.setBlock(i + 27, j + 10, k + 12, NovaCraftBlocks.cracked_basal_bricks, 0, 2);
		world.setBlock(i, j + 10, k + 13, NovaCraftBlocks.cracked_basal_bricks, 0, 2);
		world.setBlock(i + 1, j + 10, k + 13, NovaCraftBlocks.cracked_basal_bricks, 0, 2);
		world.setBlock(i + 2, j + 10, k + 13, NovaCraftBlocks.cracked_basal_bricks, 0, 2);
		world.setBlock(i + 3, j + 10, k + 13, NovaCraftBlocks.basal_bricks, 0, 2);
		world.setBlock(i + 4, j + 10, k + 13, NovaCraftBlocks.cracked_basal_bricks, 0, 2);
		world.setBlock(i + 5, j + 10, k + 13, NovaCraftBlocks.basal_bricks, 0, 2);
		world.setBlock(i + 6, j + 10, k + 13, NovaCraftBlocks.basal_bricks, 0, 2);
		world.setBlock(i + 7, j + 10, k + 13, NovaCraftBlocks.basal_bricks, 0, 2);
		world.setBlock(i + 8, j + 10, k + 13, NovaCraftBlocks.cracked_basal_bricks, 0, 2);
		world.setBlock(i + 9, j + 10, k + 13, NovaCraftBlocks.cracked_basal_bricks, 0, 2);
		world.setBlock(i + 10, j + 10, k + 13, NovaCraftBlocks.cracked_basal_bricks, 0, 2);
		world.setBlock(i + 11, j + 10, k + 13, NovaCraftBlocks.basal_bricks, 0, 2);
		world.setBlock(i + 12, j + 10, k + 13, NovaCraftBlocks.basal_bricks, 0, 2);
		world.setBlock(i + 13, j + 10, k + 13, NovaCraftBlocks.basal_bricks, 0, 2);
		world.setBlock(i + 14, j + 10, k + 13, NovaCraftBlocks.cracked_basal_bricks, 0, 2);
		world.setBlock(i + 15, j + 10, k + 13, NovaCraftBlocks.basal_bricks, 0, 2);
		world.setBlock(i + 16, j + 10, k + 13, NovaCraftBlocks.cracked_basal_bricks, 0, 2);
		world.setBlock(i + 17, j + 10, k + 13, NovaCraftBlocks.basal_bricks, 0, 2);
		world.setBlock(i + 18, j + 10, k + 13, NovaCraftBlocks.cracked_basal_bricks, 0, 2);
		world.setBlock(i + 19, j + 10, k + 13, NovaCraftBlocks.basal_bricks, 0, 2);
		world.setBlock(i + 20, j + 10, k + 13, NovaCraftBlocks.cracked_basal_bricks, 0, 2);
		world.setBlock(i + 21, j + 10, k + 13, NovaCraftBlocks.cracked_basal_bricks, 0, 2);
		world.setBlock(i + 22, j + 10, k + 13, NovaCraftBlocks.cracked_basal_bricks, 0, 2);
		world.setBlock(i + 23, j + 10, k + 13, NovaCraftBlocks.basal_bricks, 0, 2);
		world.setBlock(i + 24, j + 10, k + 13, NovaCraftBlocks.basal_bricks, 0, 2);
		world.setBlock(i + 25, j + 10, k + 13, NovaCraftBlocks.basal_bricks, 0, 2);
		world.setBlock(i + 26, j + 10, k + 13, NovaCraftBlocks.cracked_basal_bricks, 0, 2);
		world.setBlock(i + 27, j + 10, k + 13, NovaCraftBlocks.basal_bricks, 0, 2);
		world.setBlock(i, j + 10, k + 14, NovaCraftBlocks.basal_bricks, 0, 2);
		world.setBlock(i + 1, j + 10, k + 14, NovaCraftBlocks.cracked_basal_bricks, 0, 2);
		world.setBlock(i + 2, j + 10, k + 14, NovaCraftBlocks.basal_bricks, 0, 2);
		world.setBlock(i + 3, j + 10, k + 14, NovaCraftBlocks.basal_bricks, 0, 2);
		world.setBlock(i + 4, j + 10, k + 14, NovaCraftBlocks.basal_bricks, 0, 2);
		world.setBlock(i + 5, j + 10, k + 14, NovaCraftBlocks.basal_bricks, 0, 2);
		world.setBlock(i + 6, j + 10, k + 14, NovaCraftBlocks.cracked_basal_bricks, 0, 2);
		world.setBlock(i + 7, j + 10, k + 14, NovaCraftBlocks.basal_bricks, 0, 2);
		world.setBlock(i + 8, j + 10, k + 14, NovaCraftBlocks.basal_bricks, 0, 2);
		world.setBlock(i + 9, j + 10, k + 14, NovaCraftBlocks.cracked_basal_bricks, 0, 2);
		world.setBlock(i + 10, j + 10, k + 14, NovaCraftBlocks.basal_bricks, 0, 2);
		world.setBlock(i + 11, j + 10, k + 14, NovaCraftBlocks.basal_bricks, 0, 2);
		world.setBlock(i + 12, j + 10, k + 14, NovaCraftBlocks.cracked_basal_bricks, 0, 2);
		world.setBlock(i + 13, j + 10, k + 14, NovaCraftBlocks.basal_bricks, 0, 2);
		world.setBlock(i + 14, j + 10, k + 14, NovaCraftBlocks.basal_bricks, 0, 2);
		world.setBlock(i + 15, j + 10, k + 14, NovaCraftBlocks.basal_bricks, 0, 2);
		world.setBlock(i + 16, j + 10, k + 14, NovaCraftBlocks.basal_bricks, 0, 2);
		world.setBlock(i + 17, j + 10, k + 14, NovaCraftBlocks.basal_bricks, 0, 2);
		world.setBlock(i + 18, j + 10, k + 14, NovaCraftBlocks.basal_bricks, 0, 2);
		world.setBlock(i + 19, j + 10, k + 14, NovaCraftBlocks.basal_bricks, 0, 2);
		world.setBlock(i + 20, j + 10, k + 14, NovaCraftBlocks.basal_bricks, 0, 2);
		world.setBlock(i + 21, j + 10, k + 14, NovaCraftBlocks.cracked_basal_bricks, 0, 2);
		world.setBlock(i + 22, j + 10, k + 14, NovaCraftBlocks.cracked_basal_bricks, 0, 2);
		world.setBlock(i + 23, j + 10, k + 14, NovaCraftBlocks.basal_bricks, 0, 2);
		world.setBlock(i + 24, j + 10, k + 14, NovaCraftBlocks.basal_bricks, 0, 2);
		world.setBlock(i + 25, j + 10, k + 14, NovaCraftBlocks.basal_bricks, 0, 2);
		world.setBlock(i + 26, j + 10, k + 14, NovaCraftBlocks.basal_bricks, 0, 2);
		world.setBlock(i + 27, j + 10, k + 14, NovaCraftBlocks.cracked_basal_bricks, 0, 2);
		world.setBlock(i, j + 10, k + 15, NovaCraftBlocks.cracked_basal_bricks, 0, 2);
		world.setBlock(i + 1, j + 10, k + 15, NovaCraftBlocks.basal_bricks, 0, 2);
		world.setBlock(i + 2, j + 10, k + 15, NovaCraftBlocks.cracked_basal_bricks, 0, 2);
		world.setBlock(i + 3, j + 10, k + 15, NovaCraftBlocks.cracked_basal_bricks, 0, 2);
		world.setBlock(i + 4, j + 10, k + 15, NovaCraftBlocks.cracked_basal_bricks, 0, 2);
		world.setBlock(i + 5, j + 10, k + 15, NovaCraftBlocks.basal_bricks, 0, 2);
		world.setBlock(i + 6, j + 10, k + 15, NovaCraftBlocks.basal_bricks, 0, 2);
		world.setBlock(i + 7, j + 10, k + 15, NovaCraftBlocks.cracked_basal_bricks, 0, 2);
		world.setBlock(i + 8, j + 10, k + 15, NovaCraftBlocks.cracked_basal_bricks, 0, 2);
		world.setBlock(i + 9, j + 10, k + 15, NovaCraftBlocks.basal_bricks, 0, 2);
		world.setBlock(i + 10, j + 10, k + 15, NovaCraftBlocks.cracked_basal_bricks, 0, 2);
		world.setBlock(i + 11, j + 10, k + 15, NovaCraftBlocks.basal_bricks, 0, 2);
		world.setBlock(i + 12, j + 10, k + 15, NovaCraftBlocks.basal_bricks, 0, 2);
		world.setBlock(i + 13, j + 10, k + 15, NovaCraftBlocks.cracked_basal_bricks, 0, 2);
		world.setBlock(i + 14, j + 10, k + 15, NovaCraftBlocks.basal_bricks, 0, 2);
		world.setBlock(i + 15, j + 10, k + 15, NovaCraftBlocks.basal_bricks, 0, 2);
		world.setBlock(i + 16, j + 10, k + 15, NovaCraftBlocks.cracked_basal_bricks, 0, 2);
		world.setBlock(i + 17, j + 10, k + 15, NovaCraftBlocks.cracked_basal_bricks, 0, 2);
		world.setBlock(i + 18, j + 10, k + 15, NovaCraftBlocks.basal_bricks, 0, 2);
		world.setBlock(i + 19, j + 10, k + 15, NovaCraftBlocks.basal_bricks, 0, 2);
		world.setBlock(i + 20, j + 10, k + 15, NovaCraftBlocks.basal_bricks, 0, 2);
		world.setBlock(i + 21, j + 10, k + 15, NovaCraftBlocks.cracked_basal_bricks, 0, 2);
		world.setBlock(i + 22, j + 10, k + 15, NovaCraftBlocks.basal_bricks, 0, 2);
		world.setBlock(i + 23, j + 10, k + 15, NovaCraftBlocks.basal_bricks, 0, 2);
		world.setBlock(i + 24, j + 10, k + 15, NovaCraftBlocks.basal_bricks, 0, 2);
		world.setBlock(i + 25, j + 10, k + 15, NovaCraftBlocks.basal_bricks, 0, 2);
		world.setBlock(i + 26, j + 10, k + 15, NovaCraftBlocks.basal_bricks, 0, 2);
		world.setBlock(i + 27, j + 10, k + 15, NovaCraftBlocks.cracked_basal_bricks, 0, 2);
		world.setBlock(i, j + 10, k + 16, NovaCraftBlocks.cracked_basal_bricks, 0, 2);
		world.setBlock(i + 1, j + 10, k + 16, NovaCraftBlocks.basal_bricks, 0, 2);
		world.setBlock(i + 2, j + 10, k + 16, NovaCraftBlocks.basal_bricks, 0, 2);
		world.setBlock(i + 3, j + 10, k + 16, NovaCraftBlocks.cracked_basal_bricks, 0, 2);
		world.setBlock(i + 4, j + 10, k + 16, NovaCraftBlocks.basal_bricks, 0, 2);
		world.setBlock(i + 5, j + 10, k + 16, NovaCraftBlocks.basal_bricks, 0, 2);
		world.setBlock(i + 6, j + 10, k + 16, NovaCraftBlocks.basal_bricks, 0, 2);
		world.setBlock(i + 7, j + 10, k + 16, NovaCraftBlocks.basal_bricks, 0, 2);
		world.setBlock(i + 8, j + 10, k + 16, NovaCraftBlocks.cracked_basal_bricks, 0, 2);
		world.setBlock(i + 9, j + 10, k + 16, NovaCraftBlocks.cracked_basal_bricks, 0, 2);
		world.setBlock(i + 10, j + 10, k + 16, NovaCraftBlocks.basal_bricks, 0, 2);
		world.setBlock(i + 11, j + 10, k + 16, NovaCraftBlocks.basal_bricks, 0, 2);
		world.setBlock(i + 12, j + 10, k + 16, NovaCraftBlocks.cracked_basal_bricks, 0, 2);
		world.setBlock(i + 13, j + 10, k + 16, NovaCraftBlocks.cracked_basal_bricks, 0, 2);
		world.setBlock(i + 14, j + 10, k + 16, NovaCraftBlocks.basal_bricks, 0, 2);
		world.setBlock(i + 15, j + 10, k + 16, NovaCraftBlocks.basal_bricks, 0, 2);
		world.setBlock(i + 16, j + 10, k + 16, NovaCraftBlocks.cracked_basal_bricks, 0, 2);
		world.setBlock(i + 17, j + 10, k + 16, NovaCraftBlocks.basal_bricks, 0, 2);
		world.setBlock(i + 18, j + 10, k + 16, NovaCraftBlocks.basal_bricks, 0, 2);
		world.setBlock(i + 19, j + 10, k + 16, NovaCraftBlocks.cracked_basal_bricks, 0, 2);
		world.setBlock(i + 20, j + 10, k + 16, NovaCraftBlocks.basal_bricks, 0, 2);
		world.setBlock(i + 21, j + 10, k + 16, NovaCraftBlocks.basal_bricks, 0, 2);
		world.setBlock(i + 22, j + 10, k + 16, NovaCraftBlocks.cracked_basal_bricks, 0, 2);
		world.setBlock(i + 23, j + 10, k + 16, NovaCraftBlocks.cracked_basal_bricks, 0, 2);
		world.setBlock(i + 24, j + 10, k + 16, NovaCraftBlocks.basal_bricks, 0, 2);
		world.setBlock(i + 25, j + 10, k + 16, NovaCraftBlocks.basal_bricks, 0, 2);
		world.setBlock(i + 26, j + 10, k + 16, NovaCraftBlocks.basal_bricks, 0, 2);
		world.setBlock(i + 27, j + 10, k + 16, NovaCraftBlocks.basal_bricks, 0, 2);
		world.setBlock(i, j + 10, k + 17, NovaCraftBlocks.cracked_basal_bricks, 0, 2);
		world.setBlock(i + 1, j + 10, k + 17, NovaCraftBlocks.basal_bricks, 0, 2);
		world.setBlock(i + 2, j + 10, k + 17, NovaCraftBlocks.basal_bricks, 0, 2);
		world.setBlock(i + 3, j + 10, k + 17, NovaCraftBlocks.cracked_basal_bricks, 0, 2);
		world.setBlock(i + 4, j + 10, k + 17, NovaCraftBlocks.cracked_basal_bricks, 0, 2);
		world.setBlock(i + 5, j + 10, k + 17, NovaCraftBlocks.cracked_basal_bricks, 0, 2);
		world.setBlock(i + 6, j + 10, k + 17, NovaCraftBlocks.basal_bricks, 0, 2);
		world.setBlock(i + 7, j + 10, k + 17, NovaCraftBlocks.cracked_basal_bricks, 0, 2);
		world.setBlock(i + 8, j + 10, k + 17, NovaCraftBlocks.basal_bricks, 0, 2);
		world.setBlock(i + 9, j + 10, k + 17, NovaCraftBlocks.basal_bricks, 0, 2);
		world.setBlock(i + 10, j + 10, k + 17, NovaCraftBlocks.cracked_basal_bricks, 0, 2);
		world.setBlock(i + 11, j + 10, k + 17, NovaCraftBlocks.basal_bricks, 0, 2);
		world.setBlock(i + 12, j + 10, k + 17, NovaCraftBlocks.basal_bricks, 0, 2);
		world.setBlock(i + 13, j + 10, k + 17, NovaCraftBlocks.basal_bricks, 0, 2);
		world.setBlock(i + 14, j + 10, k + 17, NovaCraftBlocks.cracked_basal_bricks, 0, 2);
		world.setBlock(i + 15, j + 10, k + 17, NovaCraftBlocks.cracked_basal_bricks, 0, 2);
		world.setBlock(i + 16, j + 10, k + 17, NovaCraftBlocks.basal_bricks, 0, 2);
		world.setBlock(i + 17, j + 10, k + 17, NovaCraftBlocks.basal_bricks, 0, 2);
		world.setBlock(i + 18, j + 10, k + 17, NovaCraftBlocks.cracked_basal_bricks, 0, 2);
		world.setBlock(i + 19, j + 10, k + 17, NovaCraftBlocks.basal_bricks, 0, 2);
		world.setBlock(i + 20, j + 10, k + 17, NovaCraftBlocks.basal_bricks, 0, 2);
		world.setBlock(i + 21, j + 10, k + 17, NovaCraftBlocks.basal_bricks, 0, 2);
		world.setBlock(i + 22, j + 10, k + 17, NovaCraftBlocks.basal_bricks, 0, 2);
		world.setBlock(i + 23, j + 10, k + 17, NovaCraftBlocks.cracked_basal_bricks, 0, 2);
		world.setBlock(i + 24, j + 10, k + 17, NovaCraftBlocks.cracked_basal_bricks, 0, 2);
		world.setBlock(i + 25, j + 10, k + 17, NovaCraftBlocks.basal_bricks, 0, 2);
		world.setBlock(i + 26, j + 10, k + 17, NovaCraftBlocks.basal_bricks, 0, 2);
		world.setBlock(i + 27, j + 10, k + 17, NovaCraftBlocks.cracked_basal_bricks, 0, 2);
		world.setBlock(i, j + 10, k + 18, NovaCraftBlocks.basal_bricks, 0, 2);
		world.setBlock(i + 1, j + 10, k + 18, NovaCraftBlocks.cracked_basal_bricks, 0, 2);
		world.setBlock(i + 2, j + 10, k + 18, NovaCraftBlocks.basal_bricks, 0, 2);
		world.setBlock(i + 3, j + 10, k + 18, NovaCraftBlocks.basal_bricks, 0, 2);
		world.setBlock(i + 4, j + 10, k + 18, NovaCraftBlocks.basal_bricks, 0, 2);
		world.setBlock(i + 5, j + 10, k + 18, NovaCraftBlocks.basal_bricks, 0, 2);
		world.setBlock(i + 6, j + 10, k + 18, NovaCraftBlocks.basal_bricks, 0, 2);
		world.setBlock(i + 7, j + 10, k + 18, NovaCraftBlocks.basal_bricks, 0, 2);
		world.setBlock(i + 8, j + 10, k + 18, NovaCraftBlocks.basal_bricks, 0, 2);
		world.setBlock(i + 9, j + 10, k + 18, NovaCraftBlocks.basal_bricks, 0, 2);
		world.setBlock(i + 10, j + 10, k + 18, NovaCraftBlocks.cracked_basal_bricks, 0, 2);
		world.setBlock(i + 11, j + 10, k + 18, NovaCraftBlocks.basal_bricks, 0, 2);
		world.setBlock(i + 12, j + 10, k + 18, NovaCraftBlocks.basal_bricks, 0, 2);
		world.setBlock(i + 13, j + 10, k + 18, NovaCraftBlocks.cracked_basal_bricks, 0, 2);
		world.setBlock(i + 14, j + 10, k + 18, NovaCraftBlocks.basal_bricks, 0, 2);
		world.setBlock(i + 15, j + 10, k + 18, NovaCraftBlocks.cracked_basal_bricks, 0, 2);
		world.setBlock(i + 16, j + 10, k + 18, NovaCraftBlocks.cracked_basal_bricks, 0, 2);
		world.setBlock(i + 17, j + 10, k + 18, NovaCraftBlocks.basal_bricks, 0, 2);
		world.setBlock(i + 18, j + 10, k + 18, NovaCraftBlocks.basal_bricks, 0, 2);
		world.setBlock(i + 19, j + 10, k + 18, NovaCraftBlocks.basal_bricks, 0, 2);
		world.setBlock(i + 20, j + 10, k + 18, NovaCraftBlocks.basal_bricks, 0, 2);
		world.setBlock(i + 21, j + 10, k + 18, NovaCraftBlocks.cracked_basal_bricks, 0, 2);
		world.setBlock(i + 22, j + 10, k + 18, NovaCraftBlocks.basal_bricks, 0, 2);
		world.setBlock(i + 23, j + 10, k + 18, NovaCraftBlocks.basal_bricks, 0, 2);
		world.setBlock(i + 24, j + 10, k + 18, NovaCraftBlocks.basal_bricks, 0, 2);
		world.setBlock(i + 25, j + 10, k + 18, NovaCraftBlocks.basal_bricks, 0, 2);
		world.setBlock(i + 26, j + 10, k + 18, NovaCraftBlocks.basal_bricks, 0, 2);
		world.setBlock(i + 27, j + 10, k + 18, NovaCraftBlocks.cracked_basal_bricks, 0, 2);
		world.setBlock(i, j + 11, k, NovaCraftBlocks.basal_bricks, 0, 2);
		world.setBlock(i + 1, j + 11, k, NovaCraftBlocks.basal_bricks, 0, 2);
		world.setBlock(i + 2, j + 11, k, NovaCraftBlocks.cracked_basal_bricks, 0, 2);
		world.setBlock(i + 3, j + 11, k, NovaCraftBlocks.basal_bricks, 0, 2);
		world.setBlock(i + 4, j + 11, k, NovaCraftBlocks.cracked_basal_bricks, 0, 2);
		world.setBlock(i + 5, j + 11, k, NovaCraftBlocks.basal_bricks, 0, 2);
		world.setBlock(i + 6, j + 11, k, NovaCraftBlocks.basal_bricks, 0, 2);
		world.setBlock(i + 7, j + 11, k, NovaCraftBlocks.cracked_basal_bricks, 0, 2);
		world.setBlock(i + 8, j + 11, k, NovaCraftBlocks.basal_bricks, 0, 2);
		world.setBlock(i + 9, j + 11, k, NovaCraftBlocks.basal_bricks, 0, 2);
		world.setBlock(i + 10, j + 11, k, NovaCraftBlocks.basal_bricks, 0, 2);
		world.setBlock(i + 11, j + 11, k, NovaCraftBlocks.basal_bricks, 0, 2);
		world.setBlock(i + 12, j + 11, k, NovaCraftBlocks.cracked_basal_bricks, 0, 2);
		world.setBlock(i + 13, j + 11, k, NovaCraftBlocks.basal_bricks, 0, 2);
		world.setBlock(i + 14, j + 11, k, NovaCraftBlocks.basal_bricks, 0, 2);
		world.setBlock(i + 15, j + 11, k, NovaCraftBlocks.basal_bricks, 0, 2);
		world.setBlock(i + 16, j + 11, k, NovaCraftBlocks.basal_bricks, 0, 2);
		world.setBlock(i + 17, j + 11, k, NovaCraftBlocks.cracked_basal_bricks, 0, 2);
		world.setBlock(i + 18, j + 11, k, NovaCraftBlocks.basal_bricks, 0, 2);
		world.setBlock(i + 19, j + 11, k, NovaCraftBlocks.basal_bricks, 0, 2);
		world.setBlock(i + 20, j + 11, k, NovaCraftBlocks.basal_bricks, 0, 2);
		world.setBlock(i + 21, j + 11, k, NovaCraftBlocks.basal_bricks, 0, 2);
		world.setBlock(i + 22, j + 11, k, NovaCraftBlocks.cracked_basal_bricks, 0, 2);
		world.setBlock(i + 23, j + 11, k, NovaCraftBlocks.basal_bricks, 0, 2);
		world.setBlock(i + 24, j + 11, k, NovaCraftBlocks.basal_bricks, 0, 2);
		world.setBlock(i + 25, j + 11, k, Blocks.air, 0, 2);
		world.setBlock(i + 26, j + 11, k, Blocks.air, 0, 2);
		world.setBlock(i + 27, j + 11, k, Blocks.air, 0, 2);
		world.setBlock(i, j + 11, k + 1, NovaCraftBlocks.cracked_basal_bricks, 0, 2);
		world.setBlock(i + 1, j + 11, k + 1, NovaCraftBlocks.cracked_basal_bricks, 0, 2);
		world.setBlock(i + 2, j + 11, k + 1, NovaCraftBlocks.basal_bricks, 0, 2);
		world.setBlock(i + 3, j + 11, k + 1, NovaCraftBlocks.basal_bricks, 0, 2);
		world.setBlock(i + 4, j + 11, k + 1, NovaCraftBlocks.cracked_basal_bricks, 0, 2);
		world.setBlock(i + 5, j + 11, k + 1, NovaCraftBlocks.basal_bricks, 0, 2);
		world.setBlock(i + 6, j + 11, k + 1, NovaCraftBlocks.basal_bricks, 0, 2);
		world.setBlock(i + 7, j + 11, k + 1, NovaCraftBlocks.basal_bricks, 0, 2);
		world.setBlock(i + 8, j + 11, k + 1, NovaCraftBlocks.basal_bricks, 0, 2);
		world.setBlock(i + 9, j + 11, k + 1, NovaCraftBlocks.basal_bricks, 0, 2);
		world.setBlock(i + 10, j + 11, k + 1, NovaCraftBlocks.basal_bricks, 0, 2);
		world.setBlock(i + 11, j + 11, k + 1, NovaCraftBlocks.basal_bricks, 0, 2);
		world.setBlock(i + 12, j + 11, k + 1, NovaCraftBlocks.cracked_basal_bricks, 0, 2);
		world.setBlock(i + 13, j + 11, k + 1, NovaCraftBlocks.cracked_basal_bricks, 0, 2);
		world.setBlock(i + 14, j + 11, k + 1, NovaCraftBlocks.basal_bricks, 0, 2);
		world.setBlock(i + 15, j + 11, k + 1, NovaCraftBlocks.basal_bricks, 0, 2);
		world.setBlock(i + 16, j + 11, k + 1, NovaCraftBlocks.basal_bricks, 0, 2);
		world.setBlock(i + 17, j + 11, k + 1, NovaCraftBlocks.basal_bricks, 0, 2);
		world.setBlock(i + 18, j + 11, k + 1, NovaCraftBlocks.basal_bricks, 0, 2);
		world.setBlock(i + 19, j + 11, k + 1, NovaCraftBlocks.cracked_basal_bricks, 0, 2);
		world.setBlock(i + 20, j + 11, k + 1, NovaCraftBlocks.basal_bricks, 0, 2);
		world.setBlock(i + 21, j + 11, k + 1, NovaCraftBlocks.basal_bricks, 0, 2);
		world.setBlock(i + 22, j + 11, k + 1, NovaCraftBlocks.basal_bricks, 0, 2);
		world.setBlock(i + 23, j + 11, k + 1, NovaCraftBlocks.basal_bricks, 0, 2);
		world.setBlock(i + 24, j + 11, k + 1, NovaCraftBlocks.basal_bricks, 0, 2);
		world.setBlock(i + 25, j + 11, k + 1, NovaCraftBlocks.cracked_basal_bricks, 0, 2);
		world.setBlock(i + 26, j + 11, k + 1, NovaCraftBlocks.basal_bricks, 0, 2);
		world.setBlock(i + 27, j + 11, k + 1, NovaCraftBlocks.cracked_basal_bricks, 0, 2);
		world.setBlock(i, j + 11, k + 2, NovaCraftBlocks.basal_bricks, 0, 2);
		world.setBlock(i + 1, j + 11, k + 2, NovaCraftBlocks.basal_bricks, 0, 2);
		world.setBlock(i + 2, j + 11, k + 2, NovaCraftBlocks.basal_bricks, 0, 2);
		world.setBlock(i + 3, j + 11, k + 2, NovaCraftBlocks.cracked_basal_bricks, 0, 2);
		world.setBlock(i + 4, j + 11, k + 2, NovaCraftBlocks.basal_bricks, 0, 2);
		world.setBlock(i + 5, j + 11, k + 2, NovaCraftBlocks.basal_bricks, 0, 2);
		world.setBlock(i + 6, j + 11, k + 2, NovaCraftBlocks.cracked_basal_bricks, 0, 2);
		world.setBlock(i + 7, j + 11, k + 2, NovaCraftBlocks.cracked_basal_bricks, 0, 2);
		world.setBlock(i + 8, j + 11, k + 2, NovaCraftBlocks.basal_bricks, 0, 2);
		world.setBlock(i + 9, j + 11, k + 2, NovaCraftBlocks.cracked_basal_bricks, 0, 2);
		world.setBlock(i + 10, j + 11, k + 2, NovaCraftBlocks.basal_bricks, 0, 2);
		world.setBlock(i + 11, j + 11, k + 2, NovaCraftBlocks.basal_bricks, 0, 2);
		world.setBlock(i + 12, j + 11, k + 2, NovaCraftBlocks.basal_bricks, 0, 2);
		world.setBlock(i + 13, j + 11, k + 2, NovaCraftBlocks.basal_bricks, 0, 2);
		world.setBlock(i + 14, j + 11, k + 2, NovaCraftBlocks.basal_bricks, 0, 2);
		world.setBlock(i + 15, j + 11, k + 2, NovaCraftBlocks.basal_bricks, 0, 2);
		world.setBlock(i + 16, j + 11, k + 2, NovaCraftBlocks.basal_bricks, 0, 2);
		world.setBlock(i + 17, j + 11, k + 2, NovaCraftBlocks.basal_bricks, 0, 2);
		world.setBlock(i + 18, j + 11, k + 2, NovaCraftBlocks.cracked_basal_bricks, 0, 2);
		world.setBlock(i + 19, j + 11, k + 2, NovaCraftBlocks.basal_bricks, 0, 2);
		world.setBlock(i + 20, j + 11, k + 2, NovaCraftBlocks.basal_bricks, 0, 2);
		world.setBlock(i + 21, j + 11, k + 2, NovaCraftBlocks.basal_bricks, 0, 2);
		world.setBlock(i + 22, j + 11, k + 2, NovaCraftBlocks.basal_bricks, 0, 2);
		world.setBlock(i + 23, j + 11, k + 2, NovaCraftBlocks.basal_bricks, 0, 2);
		world.setBlock(i + 24, j + 11, k + 2, NovaCraftBlocks.basal_bricks, 0, 2);
		world.setBlock(i + 25, j + 11, k + 2, NovaCraftBlocks.cracked_basal_bricks, 0, 2);
		world.setBlock(i + 26, j + 11, k + 2, NovaCraftBlocks.basal_bricks, 0, 2);
		world.setBlock(i + 27, j + 11, k + 2, NovaCraftBlocks.basal_bricks, 0, 2);
		world.setBlock(i, j + 11, k + 3, NovaCraftBlocks.basal_bricks, 0, 2);
		world.setBlock(i + 1, j + 11, k + 3, NovaCraftBlocks.basal_bricks, 0, 2);
		world.setBlock(i + 2, j + 11, k + 3, NovaCraftBlocks.basal_bricks, 0, 2);
		world.setBlock(i + 3, j + 11, k + 3, NovaCraftBlocks.cracked_basal_bricks, 0, 2);
		world.setBlock(i + 4, j + 11, k + 3, NovaCraftBlocks.basal_bricks, 0, 2);
		world.setBlock(i + 5, j + 11, k + 3, NovaCraftBlocks.cracked_basal_bricks, 0, 2);
		world.setBlock(i + 6, j + 11, k + 3, NovaCraftBlocks.basal_bricks, 0, 2);
		world.setBlock(i + 7, j + 11, k + 3, NovaCraftBlocks.cracked_basal_bricks, 0, 2);
		world.setBlock(i + 8, j + 11, k + 3, NovaCraftBlocks.basal_bricks, 0, 2);
		world.setBlock(i + 9, j + 11, k + 3, NovaCraftBlocks.cracked_basal_bricks, 0, 2);
		world.setBlock(i + 10, j + 11, k + 3, NovaCraftBlocks.basal_bricks, 0, 2);
		world.setBlock(i + 11, j + 11, k + 3, NovaCraftBlocks.basal_bricks, 0, 2);
		world.setBlock(i + 12, j + 11, k + 3, NovaCraftBlocks.basal_bricks, 0, 2);
		world.setBlock(i + 13, j + 11, k + 3, NovaCraftBlocks.basal_bricks, 0, 2);
		world.setBlock(i + 14, j + 11, k + 3, NovaCraftBlocks.basal_bricks, 0, 2);
		world.setBlock(i + 15, j + 11, k + 3, NovaCraftBlocks.cracked_basal_bricks, 0, 2);
		world.setBlock(i + 16, j + 11, k + 3, NovaCraftBlocks.basal_bricks, 0, 2);
		world.setBlock(i + 17, j + 11, k + 3, NovaCraftBlocks.basal_bricks, 0, 2);
		world.setBlock(i + 18, j + 11, k + 3, NovaCraftBlocks.basal_bricks, 0, 2);
		world.setBlock(i + 19, j + 11, k + 3, NovaCraftBlocks.basal_bricks, 0, 2);
		world.setBlock(i + 20, j + 11, k + 3, NovaCraftBlocks.basal_bricks, 0, 2);
		world.setBlock(i + 21, j + 11, k + 3, NovaCraftBlocks.cracked_basal_bricks, 0, 2);
		world.setBlock(i + 22, j + 11, k + 3, NovaCraftBlocks.basal_bricks, 0, 2);
		world.setBlock(i + 23, j + 11, k + 3, NovaCraftBlocks.basal_bricks, 0, 2);
		world.setBlock(i + 24, j + 11, k + 3, NovaCraftBlocks.basal_bricks, 0, 2);
		world.setBlock(i + 25, j + 11, k + 3, NovaCraftBlocks.cracked_basal_bricks, 0, 2);
		world.setBlock(i + 26, j + 11, k + 3, NovaCraftBlocks.basal_bricks, 0, 2);
		world.setBlock(i + 27, j + 11, k + 3, NovaCraftBlocks.cracked_basal_bricks, 0, 2);
		world.setBlock(i, j + 11, k + 4, NovaCraftBlocks.cracked_basal_bricks, 0, 2);
		world.setBlock(i + 1, j + 11, k + 4, NovaCraftBlocks.cracked_basal_bricks, 0, 2);
		world.setBlock(i + 2, j + 11, k + 4, NovaCraftBlocks.cracked_basal_bricks, 0, 2);
		world.setBlock(i + 3, j + 11, k + 4, NovaCraftBlocks.basal_bricks, 0, 2);
		world.setBlock(i + 4, j + 11, k + 4, NovaCraftBlocks.basal_bricks, 0, 2);
		world.setBlock(i + 5, j + 11, k + 4, NovaCraftBlocks.cracked_basal_bricks, 0, 2);
		world.setBlock(i + 6, j + 11, k + 4, NovaCraftBlocks.basal_bricks, 0, 2);
		world.setBlock(i + 7, j + 11, k + 4, NovaCraftBlocks.basal_bricks, 0, 2);
		world.setBlock(i + 8, j + 11, k + 4, NovaCraftBlocks.basal_bricks, 0, 2);
		world.setBlock(i + 9, j + 11, k + 4, NovaCraftBlocks.cracked_basal_bricks, 0, 2);
		world.setBlock(i + 10, j + 11, k + 4, NovaCraftBlocks.cracked_basal_bricks, 0, 2);
		world.setBlock(i + 11, j + 11, k + 4, NovaCraftBlocks.cracked_basal_bricks, 0, 2);
		world.setBlock(i + 12, j + 11, k + 4, NovaCraftBlocks.basal_bricks, 0, 2);
		world.setBlock(i + 13, j + 11, k + 4, NovaCraftBlocks.basal_bricks, 0, 2);
		world.setBlock(i + 14, j + 11, k + 4, NovaCraftBlocks.cracked_basal_bricks, 0, 2);
		world.setBlock(i + 15, j + 11, k + 4, NovaCraftBlocks.basal_bricks, 0, 2);
		world.setBlock(i + 16, j + 11, k + 4, NovaCraftBlocks.cracked_basal_bricks, 0, 2);
		world.setBlock(i + 17, j + 11, k + 4, NovaCraftBlocks.basal_bricks, 0, 2);
		world.setBlock(i + 18, j + 11, k + 4, NovaCraftBlocks.cracked_basal_bricks, 0, 2);
		world.setBlock(i + 19, j + 11, k + 4, NovaCraftBlocks.cracked_basal_bricks, 0, 2);
		world.setBlock(i + 20, j + 11, k + 4, NovaCraftBlocks.cracked_basal_bricks, 0, 2);
		world.setBlock(i + 21, j + 11, k + 4, NovaCraftBlocks.cracked_basal_bricks, 0, 2);
		world.setBlock(i + 22, j + 11, k + 4, NovaCraftBlocks.basal_bricks, 0, 2);
		world.setBlock(i + 23, j + 11, k + 4, NovaCraftBlocks.basal_bricks, 0, 2);
		world.setBlock(i + 24, j + 11, k + 4, NovaCraftBlocks.cracked_basal_bricks, 0, 2);
		world.setBlock(i + 25, j + 11, k + 4, NovaCraftBlocks.basal_bricks, 0, 2);
		world.setBlock(i + 26, j + 11, k + 4, NovaCraftBlocks.cracked_basal_bricks, 0, 2);
		world.setBlock(i + 27, j + 11, k + 4, NovaCraftBlocks.basal_bricks, 0, 2);
		world.setBlock(i, j + 11, k + 5, NovaCraftBlocks.cracked_basal_bricks, 0, 2);
		world.setBlock(i + 1, j + 11, k + 5, NovaCraftBlocks.basal_bricks, 0, 2);
		world.setBlock(i + 2, j + 11, k + 5, NovaCraftBlocks.basal_bricks, 0, 2);
		world.setBlock(i + 3, j + 11, k + 5, NovaCraftBlocks.basal_bricks, 0, 2);
		world.setBlock(i + 4, j + 11, k + 5, NovaCraftBlocks.basal_bricks, 0, 2);
		world.setBlock(i + 5, j + 11, k + 5, NovaCraftBlocks.basal_bricks, 0, 2);
		world.setBlock(i + 6, j + 11, k + 5, NovaCraftBlocks.basal_bricks, 0, 2);
		world.setBlock(i + 7, j + 11, k + 5, NovaCraftBlocks.basal_bricks, 0, 2);
		world.setBlock(i + 8, j + 11, k + 5, NovaCraftBlocks.basal_bricks, 0, 2);
		world.setBlock(i + 9, j + 11, k + 5, NovaCraftBlocks.basal_bricks, 0, 2);
		world.setBlock(i + 10, j + 11, k + 5, NovaCraftBlocks.basal_bricks, 0, 2);
		world.setBlock(i + 11, j + 11, k + 5, NovaCraftBlocks.basal_bricks, 0, 2);
		world.setBlock(i + 12, j + 11, k + 5, NovaCraftBlocks.basal_bricks, 0, 2);
		world.setBlock(i + 13, j + 11, k + 5, NovaCraftBlocks.cracked_basal_bricks, 0, 2);
		world.setBlock(i + 14, j + 11, k + 5, NovaCraftBlocks.basal_bricks, 0, 2);
		world.setBlock(i + 15, j + 11, k + 5, NovaCraftBlocks.basal_bricks, 0, 2);
		world.setBlock(i + 16, j + 11, k + 5, NovaCraftBlocks.cracked_basal_bricks, 0, 2);
		world.setBlock(i + 17, j + 11, k + 5, NovaCraftBlocks.basal_bricks, 0, 2);
		world.setBlock(i + 18, j + 11, k + 5, NovaCraftBlocks.cracked_basal_bricks, 0, 2);
		world.setBlock(i + 19, j + 11, k + 5, NovaCraftBlocks.basal_bricks, 0, 2);
		world.setBlock(i + 20, j + 11, k + 5, NovaCraftBlocks.basal_bricks, 0, 2);
		world.setBlock(i + 21, j + 11, k + 5, NovaCraftBlocks.basal_bricks, 0, 2);
		world.setBlock(i + 22, j + 11, k + 5, NovaCraftBlocks.cracked_basal_bricks, 0, 2);
		world.setBlock(i + 23, j + 11, k + 5, NovaCraftBlocks.cracked_basal_bricks, 0, 2);
		world.setBlock(i + 24, j + 11, k + 5, NovaCraftBlocks.basal_bricks, 0, 2);
		world.setBlock(i + 25, j + 11, k + 5, NovaCraftBlocks.cracked_basal_bricks, 0, 2);
		world.setBlock(i + 26, j + 11, k + 5, NovaCraftBlocks.cracked_basal_bricks, 0, 2);
		world.setBlock(i + 27, j + 11, k + 5, NovaCraftBlocks.basal_bricks, 0, 2);
		world.setBlock(i, j + 11, k + 6, NovaCraftBlocks.cracked_basal_bricks, 0, 2);
		world.setBlock(i + 1, j + 11, k + 6, NovaCraftBlocks.cracked_basal_bricks, 0, 2);
		world.setBlock(i + 2, j + 11, k + 6, NovaCraftBlocks.cracked_basal_bricks, 0, 2);
		world.setBlock(i + 3, j + 11, k + 6, NovaCraftBlocks.cracked_basal_bricks, 0, 2);
		world.setBlock(i + 4, j + 11, k + 6, NovaCraftBlocks.basal_bricks, 0, 2);
		world.setBlock(i + 5, j + 11, k + 6, NovaCraftBlocks.cracked_basal_bricks, 0, 2);
		world.setBlock(i + 6, j + 11, k + 6, NovaCraftBlocks.basal_bricks, 0, 2);
		world.setBlock(i + 7, j + 11, k + 6, NovaCraftBlocks.basal_bricks, 0, 2);
		world.setBlock(i + 8, j + 11, k + 6, NovaCraftBlocks.cracked_basal_bricks, 0, 2);
		world.setBlock(i + 9, j + 11, k + 6, NovaCraftBlocks.basal_bricks, 0, 2);
		world.setBlock(i + 10, j + 11, k + 6, NovaCraftBlocks.basal_bricks, 0, 2);
		world.setBlock(i + 11, j + 11, k + 6, NovaCraftBlocks.cracked_basal_bricks, 0, 2);
		world.setBlock(i + 12, j + 11, k + 6, NovaCraftBlocks.cracked_basal_bricks, 0, 2);
		world.setBlock(i + 13, j + 11, k + 6, NovaCraftBlocks.cracked_basal_bricks, 0, 2);
		world.setBlock(i + 14, j + 11, k + 6, NovaCraftBlocks.cracked_basal_bricks, 0, 2);
		world.setBlock(i + 15, j + 11, k + 6, NovaCraftBlocks.basal_bricks, 0, 2);
		world.setBlock(i + 16, j + 11, k + 6, NovaCraftBlocks.cracked_basal_bricks, 0, 2);
		world.setBlock(i + 17, j + 11, k + 6, NovaCraftBlocks.basal_bricks, 0, 2);
		world.setBlock(i + 18, j + 11, k + 6, NovaCraftBlocks.cracked_basal_bricks, 0, 2);
		world.setBlock(i + 19, j + 11, k + 6, NovaCraftBlocks.cracked_basal_bricks, 0, 2);
		world.setBlock(i + 20, j + 11, k + 6, NovaCraftBlocks.basal_bricks, 0, 2);
		world.setBlock(i + 21, j + 11, k + 6, NovaCraftBlocks.basal_bricks, 0, 2);
		world.setBlock(i + 22, j + 11, k + 6, NovaCraftBlocks.basal_bricks, 0, 2);
		world.setBlock(i + 23, j + 11, k + 6, NovaCraftBlocks.basal_bricks, 0, 2);
		world.setBlock(i + 24, j + 11, k + 6, NovaCraftBlocks.basal_bricks, 0, 2);
		world.setBlock(i + 25, j + 11, k + 6, NovaCraftBlocks.cracked_basal_bricks, 0, 2);
		world.setBlock(i + 26, j + 11, k + 6, NovaCraftBlocks.cracked_basal_bricks, 0, 2);
		world.setBlock(i + 27, j + 11, k + 6, NovaCraftBlocks.basal_bricks, 0, 2);
		world.setBlock(i, j + 11, k + 7, NovaCraftBlocks.cracked_basal_bricks, 0, 2);
		world.setBlock(i + 1, j + 11, k + 7, NovaCraftBlocks.basal_bricks, 0, 2);
		world.setBlock(i + 2, j + 11, k + 7, NovaCraftBlocks.basal_bricks, 0, 2);
		world.setBlock(i + 3, j + 11, k + 7, NovaCraftBlocks.basal_bricks, 0, 2);
		world.setBlock(i + 4, j + 11, k + 7, NovaCraftBlocks.basal_bricks, 0, 2);
		world.setBlock(i + 5, j + 11, k + 7, NovaCraftBlocks.cracked_basal_bricks, 0, 2);
		world.setBlock(i + 6, j + 11, k + 7, NovaCraftBlocks.basal_bricks, 0, 2);
		world.setBlock(i + 7, j + 11, k + 7, NovaCraftBlocks.basal_bricks, 0, 2);
		world.setBlock(i + 8, j + 11, k + 7, NovaCraftBlocks.basal_bricks, 0, 2);
		world.setBlock(i + 9, j + 11, k + 7, NovaCraftBlocks.basal_bricks, 0, 2);
		world.setBlock(i + 10, j + 11, k + 7, NovaCraftBlocks.cracked_basal_bricks, 0, 2);
		world.setBlock(i + 11, j + 11, k + 7, NovaCraftBlocks.basal_bricks, 0, 2);
		world.setBlock(i + 12, j + 11, k + 7, NovaCraftBlocks.basal_bricks, 0, 2);
		world.setBlock(i + 13, j + 11, k + 7, NovaCraftBlocks.cracked_basal_bricks, 0, 2);
		world.setBlock(i + 14, j + 11, k + 7, NovaCraftBlocks.basal_bricks, 0, 2);
		world.setBlock(i + 15, j + 11, k + 7, NovaCraftBlocks.basal_bricks, 0, 2);
		world.setBlock(i + 16, j + 11, k + 7, NovaCraftBlocks.cracked_basal_bricks, 0, 2);
		world.setBlock(i + 17, j + 11, k + 7, NovaCraftBlocks.basal_bricks, 0, 2);
		world.setBlock(i + 18, j + 11, k + 7, NovaCraftBlocks.basal_bricks, 0, 2);
		world.setBlock(i + 19, j + 11, k + 7, NovaCraftBlocks.cracked_basal_bricks, 0, 2);
		world.setBlock(i + 20, j + 11, k + 7, NovaCraftBlocks.cracked_basal_bricks, 0, 2);
		world.setBlock(i + 21, j + 11, k + 7, NovaCraftBlocks.cracked_basal_bricks, 0, 2);
		world.setBlock(i + 22, j + 11, k + 7, NovaCraftBlocks.cracked_basal_bricks, 0, 2);
		world.setBlock(i + 23, j + 11, k + 7, NovaCraftBlocks.basal_bricks, 0, 2);
		world.setBlock(i + 24, j + 11, k + 7, NovaCraftBlocks.basal_bricks, 0, 2);
		world.setBlock(i + 25, j + 11, k + 7, NovaCraftBlocks.basal_bricks, 0, 2);
		world.setBlock(i + 26, j + 11, k + 7, NovaCraftBlocks.basal_bricks, 0, 2);
		world.setBlock(i + 27, j + 11, k + 7, NovaCraftBlocks.basal_bricks, 0, 2);
		world.setBlock(i, j + 11, k + 8, NovaCraftBlocks.basal_bricks, 0, 2);
		world.setBlock(i + 1, j + 11, k + 8, NovaCraftBlocks.basal_bricks, 0, 2);
		world.setBlock(i + 2, j + 11, k + 8, NovaCraftBlocks.basal_bricks, 0, 2);
		world.setBlock(i + 3, j + 11, k + 8, NovaCraftBlocks.cracked_basal_bricks, 0, 2);
		world.setBlock(i + 4, j + 11, k + 8, NovaCraftBlocks.cracked_basal_bricks, 0, 2);
		world.setBlock(i + 5, j + 11, k + 8, NovaCraftBlocks.basal_bricks, 0, 2);
		world.setBlock(i + 6, j + 11, k + 8, NovaCraftBlocks.basal_bricks, 0, 2);
		world.setBlock(i + 7, j + 11, k + 8, NovaCraftBlocks.basal_bricks, 0, 2);
		world.setBlock(i + 8, j + 11, k + 8, NovaCraftBlocks.basal_bricks, 0, 2);
		world.setBlock(i + 9, j + 11, k + 8, NovaCraftBlocks.cracked_basal_bricks, 0, 2);
		world.setBlock(i + 10, j + 11, k + 8, NovaCraftBlocks.basal_bricks, 0, 2);
		world.setBlock(i + 11, j + 11, k + 8, NovaCraftBlocks.basal_bricks, 0, 2);
		world.setBlock(i + 12, j + 11, k + 8, NovaCraftBlocks.cracked_basal_bricks, 0, 2);
		world.setBlock(i + 13, j + 11, k + 8, NovaCraftBlocks.basal_bricks, 0, 2);
		world.setBlock(i + 14, j + 11, k + 8, NovaCraftBlocks.basal_bricks, 0, 2);
		world.setBlock(i + 15, j + 11, k + 8, NovaCraftBlocks.cracked_basal_bricks, 0, 2);
		world.setBlock(i + 16, j + 11, k + 8, NovaCraftBlocks.basal_bricks, 0, 2);
		world.setBlock(i + 17, j + 11, k + 8, NovaCraftBlocks.basal_bricks, 0, 2);
		world.setBlock(i + 18, j + 11, k + 8, NovaCraftBlocks.basal_bricks, 0, 2);
		world.setBlock(i + 19, j + 11, k + 8, NovaCraftBlocks.basal_bricks, 0, 2);
		world.setBlock(i + 20, j + 11, k + 8, NovaCraftBlocks.basal_bricks, 0, 2);
		world.setBlock(i + 21, j + 11, k + 8, NovaCraftBlocks.basal_bricks, 0, 2);
		world.setBlock(i + 22, j + 11, k + 8, NovaCraftBlocks.basal_bricks, 0, 2);
		world.setBlock(i + 23, j + 11, k + 8, NovaCraftBlocks.basal_bricks, 0, 2);
		world.setBlock(i + 24, j + 11, k + 8, NovaCraftBlocks.basal_bricks, 0, 2);
		world.setBlock(i + 25, j + 11, k + 8, NovaCraftBlocks.basal_bricks, 0, 2);
		world.setBlock(i + 26, j + 11, k + 8, NovaCraftBlocks.cracked_basal_bricks, 0, 2);
		world.setBlock(i + 27, j + 11, k + 8, NovaCraftBlocks.cracked_basal_bricks, 0, 2);
		world.setBlock(i, j + 11, k + 9, NovaCraftBlocks.cracked_basal_bricks, 0, 2);
		world.setBlock(i + 1, j + 11, k + 9, NovaCraftBlocks.basal_bricks, 0, 2);
		world.setBlock(i + 2, j + 11, k + 9, NovaCraftBlocks.basal_bricks, 0, 2);
		world.setBlock(i + 3, j + 11, k + 9, NovaCraftBlocks.basal_bricks, 0, 2);
		world.setBlock(i + 4, j + 11, k + 9, NovaCraftBlocks.basal_bricks, 0, 2);
		world.setBlock(i + 5, j + 11, k + 9, NovaCraftBlocks.basal_bricks, 0, 2);
		world.setBlock(i + 6, j + 11, k + 9, NovaCraftBlocks.basal_bricks, 0, 2);
		world.setBlock(i + 7, j + 11, k + 9, NovaCraftBlocks.basal_bricks, 0, 2);
		world.setBlock(i + 8, j + 11, k + 9, NovaCraftBlocks.cracked_basal_bricks, 0, 2);
		world.setBlock(i + 9, j + 11, k + 9, NovaCraftBlocks.basal_bricks, 0, 2);
		world.setBlock(i + 10, j + 11, k + 9, NovaCraftBlocks.cracked_basal_bricks, 0, 2);
		world.setBlock(i + 11, j + 11, k + 9, NovaCraftBlocks.cracked_basal_bricks, 0, 2);
		world.setBlock(i + 12, j + 11, k + 9, NovaCraftBlocks.basal_bricks, 0, 2);
		world.setBlock(i + 13, j + 11, k + 9, NovaCraftBlocks.cracked_basal_bricks, 0, 2);
		world.setBlock(i + 14, j + 11, k + 9, NovaCraftBlocks.cracked_basal_bricks, 0, 2);
		world.setBlock(i + 15, j + 11, k + 9, NovaCraftBlocks.basal_bricks, 0, 2);
		world.setBlock(i + 16, j + 11, k + 9, NovaCraftBlocks.basal_bricks, 0, 2);
		world.setBlock(i + 17, j + 11, k + 9, NovaCraftBlocks.cracked_basal_bricks, 0, 2);
		world.setBlock(i + 18, j + 11, k + 9, NovaCraftBlocks.basal_bricks, 0, 2);
		world.setBlock(i + 19, j + 11, k + 9, NovaCraftBlocks.basal_bricks, 0, 2);
		world.setBlock(i + 20, j + 11, k + 9, NovaCraftBlocks.cracked_basal_bricks, 0, 2);
		world.setBlock(i + 21, j + 11, k + 9, NovaCraftBlocks.basal_bricks, 0, 2);
		world.setBlock(i + 22, j + 11, k + 9, NovaCraftBlocks.basal_bricks, 0, 2);
		world.setBlock(i + 23, j + 11, k + 9, NovaCraftBlocks.basal_bricks, 0, 2);
		world.setBlock(i + 24, j + 11, k + 9, NovaCraftBlocks.basal_bricks, 0, 2);
		world.setBlock(i + 25, j + 11, k + 9, NovaCraftBlocks.basal_bricks, 0, 2);
		world.setBlock(i + 26, j + 11, k + 9, NovaCraftBlocks.basal_bricks, 0, 2);
		world.setBlock(i + 27, j + 11, k + 9, NovaCraftBlocks.basal_bricks, 0, 2);
		world.setBlock(i, j + 11, k + 10, NovaCraftBlocks.cracked_basal_bricks, 0, 2);
		world.setBlock(i + 1, j + 11, k + 10, NovaCraftBlocks.basal_bricks, 0, 2);
		world.setBlock(i + 2, j + 11, k + 10, NovaCraftBlocks.basal_bricks, 0, 2);
		world.setBlock(i + 3, j + 11, k + 10, NovaCraftBlocks.basal_bricks, 0, 2);
		world.setBlock(i + 4, j + 11, k + 10, NovaCraftBlocks.basal_bricks, 0, 2);
		world.setBlock(i + 5, j + 11, k + 10, NovaCraftBlocks.basal_bricks, 0, 2);
		world.setBlock(i + 6, j + 11, k + 10, NovaCraftBlocks.cracked_basal_bricks, 0, 2);
		world.setBlock(i + 7, j + 11, k + 10, NovaCraftBlocks.basal_bricks, 0, 2);
		world.setBlock(i + 8, j + 11, k + 10, NovaCraftBlocks.basal_bricks, 0, 2);
		world.setBlock(i + 9, j + 11, k + 10, NovaCraftBlocks.cracked_basal_bricks, 0, 2);
		world.setBlock(i + 10, j + 11, k + 10, NovaCraftBlocks.cracked_basal_bricks, 0, 2);
		world.setBlock(i + 11, j + 11, k + 10, NovaCraftBlocks.basal_bricks, 0, 2);
		world.setBlock(i + 12, j + 11, k + 10, NovaCraftBlocks.basal_bricks, 0, 2);
		world.setBlock(i + 13, j + 11, k + 10, NovaCraftBlocks.cracked_basal_bricks, 0, 2);
		world.setBlock(i + 14, j + 11, k + 10, NovaCraftBlocks.basal_bricks, 0, 2);
		world.setBlock(i + 15, j + 11, k + 10, NovaCraftBlocks.basal_bricks, 0, 2);
		world.setBlock(i + 16, j + 11, k + 10, NovaCraftBlocks.cracked_basal_bricks, 0, 2);
		world.setBlock(i + 17, j + 11, k + 10, NovaCraftBlocks.cracked_basal_bricks, 0, 2);
		world.setBlock(i + 18, j + 11, k + 10, NovaCraftBlocks.basal_bricks, 0, 2);
		world.setBlock(i + 19, j + 11, k + 10, NovaCraftBlocks.cracked_basal_bricks, 0, 2);
		world.setBlock(i + 20, j + 11, k + 10, NovaCraftBlocks.basal_bricks, 0, 2);
		world.setBlock(i + 21, j + 11, k + 10, NovaCraftBlocks.basal_bricks, 0, 2);
		world.setBlock(i + 22, j + 11, k + 10, NovaCraftBlocks.cracked_basal_bricks, 0, 2);
		world.setBlock(i + 23, j + 11, k + 10, NovaCraftBlocks.basal_bricks, 0, 2);
		world.setBlock(i + 24, j + 11, k + 10, NovaCraftBlocks.cracked_basal_bricks, 0, 2);
		world.setBlock(i + 25, j + 11, k + 10, NovaCraftBlocks.basal_bricks, 0, 2);
		world.setBlock(i + 26, j + 11, k + 10, NovaCraftBlocks.basal_bricks, 0, 2);
		world.setBlock(i + 27, j + 11, k + 10, NovaCraftBlocks.cracked_basal_bricks, 0, 2);
		world.setBlock(i, j + 11, k + 11, NovaCraftBlocks.basal_bricks, 0, 2);
		world.setBlock(i + 1, j + 11, k + 11, NovaCraftBlocks.basal_bricks, 0, 2);
		world.setBlock(i + 2, j + 11, k + 11, NovaCraftBlocks.basal_bricks, 0, 2);
		world.setBlock(i + 3, j + 11, k + 11, NovaCraftBlocks.basal_bricks, 0, 2);
		world.setBlock(i + 4, j + 11, k + 11, NovaCraftBlocks.basal_bricks, 0, 2);
		world.setBlock(i + 5, j + 11, k + 11, NovaCraftBlocks.cracked_basal_bricks, 0, 2);
		world.setBlock(i + 6, j + 11, k + 11, NovaCraftBlocks.basal_bricks, 0, 2);
		world.setBlock(i + 7, j + 11, k + 11, NovaCraftBlocks.basal_bricks, 0, 2);
		world.setBlock(i + 8, j + 11, k + 11, NovaCraftBlocks.basal_bricks, 0, 2);
		world.setBlock(i + 9, j + 11, k + 11, NovaCraftBlocks.basal_bricks, 0, 2);
		world.setBlock(i + 10, j + 11, k + 11, NovaCraftBlocks.basal_bricks, 0, 2);
		world.setBlock(i + 11, j + 11, k + 11, NovaCraftBlocks.cracked_basal_bricks, 0, 2);
		world.setBlock(i + 12, j + 11, k + 11, NovaCraftBlocks.basal_bricks, 0, 2);
		world.setBlock(i + 13, j + 11, k + 11, NovaCraftBlocks.basal_bricks, 0, 2);
		world.setBlock(i + 14, j + 11, k + 11, NovaCraftBlocks.basal_bricks, 0, 2);
		world.setBlock(i + 15, j + 11, k + 11, NovaCraftBlocks.cracked_basal_bricks, 0, 2);
		world.setBlock(i + 16, j + 11, k + 11, NovaCraftBlocks.basal_bricks, 0, 2);
		world.setBlock(i + 17, j + 11, k + 11, NovaCraftBlocks.basal_bricks, 0, 2);
		world.setBlock(i + 18, j + 11, k + 11, NovaCraftBlocks.basal_bricks, 0, 2);
		world.setBlock(i + 19, j + 11, k + 11, NovaCraftBlocks.basal_bricks, 0, 2);
		world.setBlock(i + 20, j + 11, k + 11, NovaCraftBlocks.cracked_basal_bricks, 0, 2);
		world.setBlock(i + 21, j + 11, k + 11, NovaCraftBlocks.cracked_basal_bricks, 0, 2);
		world.setBlock(i + 22, j + 11, k + 11, NovaCraftBlocks.cracked_basal_bricks, 0, 2);
		world.setBlock(i + 23, j + 11, k + 11, NovaCraftBlocks.cracked_basal_bricks, 0, 2);
		world.setBlock(i + 24, j + 11, k + 11, NovaCraftBlocks.basal_bricks, 0, 2);
		world.setBlock(i + 25, j + 11, k + 11, NovaCraftBlocks.basal_bricks, 0, 2);
		world.setBlock(i + 26, j + 11, k + 11, NovaCraftBlocks.basal_bricks, 0, 2);
		world.setBlock(i + 27, j + 11, k + 11, NovaCraftBlocks.basal_bricks, 0, 2);
		world.setBlock(i, j + 11, k + 12, NovaCraftBlocks.basal_bricks, 0, 2);
		world.setBlock(i + 1, j + 11, k + 12, NovaCraftBlocks.basal_bricks, 0, 2);
		world.setBlock(i + 2, j + 11, k + 12, NovaCraftBlocks.basal_bricks, 0, 2);
		world.setBlock(i + 3, j + 11, k + 12, NovaCraftBlocks.cracked_basal_bricks, 0, 2);
		world.setBlock(i + 4, j + 11, k + 12, NovaCraftBlocks.cracked_basal_bricks, 0, 2);
		world.setBlock(i + 5, j + 11, k + 12, NovaCraftBlocks.cracked_basal_bricks, 0, 2);
		world.setBlock(i + 6, j + 11, k + 12, NovaCraftBlocks.cracked_basal_bricks, 0, 2);
		world.setBlock(i + 7, j + 11, k + 12, NovaCraftBlocks.cracked_basal_bricks, 0, 2);
		world.setBlock(i + 8, j + 11, k + 12, NovaCraftBlocks.cracked_basal_bricks, 0, 2);
		world.setBlock(i + 9, j + 11, k + 12, NovaCraftBlocks.cracked_basal_bricks, 0, 2);
		world.setBlock(i + 10, j + 11, k + 12, NovaCraftBlocks.basal_bricks, 0, 2);
		world.setBlock(i + 11, j + 11, k + 12, NovaCraftBlocks.basal_bricks, 0, 2);
		world.setBlock(i + 12, j + 11, k + 12, NovaCraftBlocks.basal_bricks, 0, 2);
		world.setBlock(i + 13, j + 11, k + 12, NovaCraftBlocks.basal_bricks, 0, 2);
		world.setBlock(i + 14, j + 11, k + 12, NovaCraftBlocks.basal_bricks, 0, 2);
		world.setBlock(i + 15, j + 11, k + 12, NovaCraftBlocks.cracked_basal_bricks, 0, 2);
		world.setBlock(i + 16, j + 11, k + 12, NovaCraftBlocks.cracked_basal_bricks, 0, 2);
		world.setBlock(i + 17, j + 11, k + 12, NovaCraftBlocks.basal_bricks, 0, 2);
		world.setBlock(i + 18, j + 11, k + 12, NovaCraftBlocks.basal_bricks, 0, 2);
		world.setBlock(i + 19, j + 11, k + 12, NovaCraftBlocks.basal_bricks, 0, 2);
		world.setBlock(i + 20, j + 11, k + 12, NovaCraftBlocks.basal_bricks, 0, 2);
		world.setBlock(i + 21, j + 11, k + 12, NovaCraftBlocks.basal_bricks, 0, 2);
		world.setBlock(i + 22, j + 11, k + 12, NovaCraftBlocks.basal_bricks, 0, 2);
		world.setBlock(i + 23, j + 11, k + 12, NovaCraftBlocks.cracked_basal_bricks, 0, 2);
		world.setBlock(i + 24, j + 11, k + 12, NovaCraftBlocks.basal_bricks, 0, 2);
		world.setBlock(i + 25, j + 11, k + 12, NovaCraftBlocks.cracked_basal_bricks, 0, 2);
		world.setBlock(i + 26, j + 11, k + 12, NovaCraftBlocks.basal_bricks, 0, 2);
		world.setBlock(i + 27, j + 11, k + 12, NovaCraftBlocks.cracked_basal_bricks, 0, 2);
		world.setBlock(i, j + 11, k + 13, NovaCraftBlocks.cracked_basal_bricks, 0, 2);
		world.setBlock(i + 1, j + 11, k + 13, NovaCraftBlocks.basal_bricks, 0, 2);
		world.setBlock(i + 2, j + 11, k + 13, NovaCraftBlocks.basal_bricks, 0, 2);
		world.setBlock(i + 3, j + 11, k + 13, NovaCraftBlocks.basal_bricks, 0, 2);
		world.setBlock(i + 4, j + 11, k + 13, NovaCraftBlocks.basal_bricks, 0, 2);
		world.setBlock(i + 5, j + 11, k + 13, NovaCraftBlocks.cracked_basal_bricks, 0, 2);
		world.setBlock(i + 6, j + 11, k + 13, NovaCraftBlocks.basal_bricks, 0, 2);
		world.setBlock(i + 7, j + 11, k + 13, NovaCraftBlocks.basal_bricks, 0, 2);
		world.setBlock(i + 8, j + 11, k + 13, NovaCraftBlocks.cracked_basal_bricks, 0, 2);
		world.setBlock(i + 9, j + 11, k + 13, NovaCraftBlocks.basal_bricks, 0, 2);
		world.setBlock(i + 10, j + 11, k + 13, NovaCraftBlocks.basal_bricks, 0, 2);
		world.setBlock(i + 11, j + 11, k + 13, NovaCraftBlocks.cracked_basal_bricks, 0, 2);
		world.setBlock(i + 12, j + 11, k + 13, NovaCraftBlocks.basal_bricks, 0, 2);
		world.setBlock(i + 13, j + 11, k + 13, NovaCraftBlocks.basal_bricks, 0, 2);
		world.setBlock(i + 14, j + 11, k + 13, NovaCraftBlocks.basal_bricks, 0, 2);
		world.setBlock(i + 15, j + 11, k + 13, NovaCraftBlocks.basal_bricks, 0, 2);
		world.setBlock(i + 16, j + 11, k + 13, NovaCraftBlocks.basal_bricks, 0, 2);
		world.setBlock(i + 17, j + 11, k + 13, NovaCraftBlocks.cracked_basal_bricks, 0, 2);
		world.setBlock(i + 18, j + 11, k + 13, NovaCraftBlocks.basal_bricks, 0, 2);
		world.setBlock(i + 19, j + 11, k + 13, NovaCraftBlocks.basal_bricks, 0, 2);
		world.setBlock(i + 20, j + 11, k + 13, NovaCraftBlocks.cracked_basal_bricks, 0, 2);
		world.setBlock(i + 21, j + 11, k + 13, NovaCraftBlocks.basal_bricks, 0, 2);
		world.setBlock(i + 22, j + 11, k + 13, NovaCraftBlocks.basal_bricks, 0, 2);
		world.setBlock(i + 23, j + 11, k + 13, NovaCraftBlocks.cracked_basal_bricks, 0, 2);
		world.setBlock(i + 24, j + 11, k + 13, NovaCraftBlocks.basal_bricks, 0, 2);
		world.setBlock(i + 25, j + 11, k + 13, NovaCraftBlocks.basal_bricks, 0, 2);
		world.setBlock(i + 26, j + 11, k + 13, NovaCraftBlocks.basal_bricks, 0, 2);
		world.setBlock(i + 27, j + 11, k + 13, NovaCraftBlocks.basal_bricks, 0, 2);
		world.setBlock(i, j + 11, k + 14, NovaCraftBlocks.basal_bricks, 0, 2);
		world.setBlock(i + 1, j + 11, k + 14, NovaCraftBlocks.cracked_basal_bricks, 0, 2);
		world.setBlock(i + 2, j + 11, k + 14, NovaCraftBlocks.basal_bricks, 0, 2);
		world.setBlock(i + 3, j + 11, k + 14, NovaCraftBlocks.cracked_basal_bricks, 0, 2);
		world.setBlock(i + 4, j + 11, k + 14, NovaCraftBlocks.basal_bricks, 0, 2);
		world.setBlock(i + 5, j + 11, k + 14, NovaCraftBlocks.cracked_basal_bricks, 0, 2);
		world.setBlock(i + 6, j + 11, k + 14, NovaCraftBlocks.basal_bricks, 0, 2);
		world.setBlock(i + 7, j + 11, k + 14, NovaCraftBlocks.basal_bricks, 0, 2);
		world.setBlock(i + 8, j + 11, k + 14, NovaCraftBlocks.cracked_basal_bricks, 0, 2);
		world.setBlock(i + 9, j + 11, k + 14, NovaCraftBlocks.cracked_basal_bricks, 0, 2);
		world.setBlock(i + 10, j + 11, k + 14, NovaCraftBlocks.cracked_basal_bricks, 0, 2);
		world.setBlock(i + 11, j + 11, k + 14, NovaCraftBlocks.basal_bricks, 0, 2);
		world.setBlock(i + 12, j + 11, k + 14, NovaCraftBlocks.cracked_basal_bricks, 0, 2);
		world.setBlock(i + 13, j + 11, k + 14, NovaCraftBlocks.basal_bricks, 0, 2);
		world.setBlock(i + 14, j + 11, k + 14, NovaCraftBlocks.basal_bricks, 0, 2);
		world.setBlock(i + 15, j + 11, k + 14, NovaCraftBlocks.basal_bricks, 0, 2);
		world.setBlock(i + 16, j + 11, k + 14, NovaCraftBlocks.basal_bricks, 0, 2);
		world.setBlock(i + 17, j + 11, k + 14, NovaCraftBlocks.basal_bricks, 0, 2);
		world.setBlock(i + 18, j + 11, k + 14, NovaCraftBlocks.basal_bricks, 0, 2);
		world.setBlock(i + 19, j + 11, k + 14, NovaCraftBlocks.basal_bricks, 0, 2);
		world.setBlock(i + 20, j + 11, k + 14, NovaCraftBlocks.basal_bricks, 0, 2);
		world.setBlock(i + 21, j + 11, k + 14, NovaCraftBlocks.basal_bricks, 0, 2);
		world.setBlock(i + 22, j + 11, k + 14, NovaCraftBlocks.cracked_basal_bricks, 0, 2);
		world.setBlock(i + 23, j + 11, k + 14, NovaCraftBlocks.basal_bricks, 0, 2);
		world.setBlock(i + 24, j + 11, k + 14, NovaCraftBlocks.basal_bricks, 0, 2);
		world.setBlock(i + 25, j + 11, k + 14, NovaCraftBlocks.basal_bricks, 0, 2);
		world.setBlock(i + 26, j + 11, k + 14, NovaCraftBlocks.cracked_basal_bricks, 0, 2);
		world.setBlock(i + 27, j + 11, k + 14, NovaCraftBlocks.basal_bricks, 0, 2);
		world.setBlock(i, j + 11, k + 15, NovaCraftBlocks.basal_bricks, 0, 2);
		world.setBlock(i + 1, j + 11, k + 15, NovaCraftBlocks.basal_bricks, 0, 2);
		world.setBlock(i + 2, j + 11, k + 15, NovaCraftBlocks.basal_bricks, 0, 2);
		world.setBlock(i + 3, j + 11, k + 15, NovaCraftBlocks.cracked_basal_bricks, 0, 2);
		world.setBlock(i + 4, j + 11, k + 15, NovaCraftBlocks.cracked_basal_bricks, 0, 2);
		world.setBlock(i + 5, j + 11, k + 15, NovaCraftBlocks.cracked_basal_bricks, 0, 2);
		world.setBlock(i + 6, j + 11, k + 15, NovaCraftBlocks.basal_bricks, 0, 2);
		world.setBlock(i + 7, j + 11, k + 15, NovaCraftBlocks.basal_bricks, 0, 2);
		world.setBlock(i + 8, j + 11, k + 15, NovaCraftBlocks.cracked_basal_bricks, 0, 2);
		world.setBlock(i + 9, j + 11, k + 15, NovaCraftBlocks.basal_bricks, 0, 2);
		world.setBlock(i + 10, j + 11, k + 15, NovaCraftBlocks.basal_bricks, 0, 2);
		world.setBlock(i + 11, j + 11, k + 15, NovaCraftBlocks.basal_bricks, 0, 2);
		world.setBlock(i + 12, j + 11, k + 15, NovaCraftBlocks.cracked_basal_bricks, 0, 2);
		world.setBlock(i + 13, j + 11, k + 15, NovaCraftBlocks.cracked_basal_bricks, 0, 2);
		world.setBlock(i + 14, j + 11, k + 15, NovaCraftBlocks.basal_bricks, 0, 2);
		world.setBlock(i + 15, j + 11, k + 15, NovaCraftBlocks.cracked_basal_bricks, 0, 2);
		world.setBlock(i + 16, j + 11, k + 15, NovaCraftBlocks.basal_bricks, 0, 2);
		world.setBlock(i + 17, j + 11, k + 15, NovaCraftBlocks.basal_bricks, 0, 2);
		world.setBlock(i + 18, j + 11, k + 15, NovaCraftBlocks.cracked_basal_bricks, 0, 2);
		world.setBlock(i + 19, j + 11, k + 15, NovaCraftBlocks.basal_bricks, 0, 2);
		world.setBlock(i + 20, j + 11, k + 15, NovaCraftBlocks.basal_bricks, 0, 2);
		world.setBlock(i + 21, j + 11, k + 15, NovaCraftBlocks.basal_bricks, 0, 2);
		world.setBlock(i + 22, j + 11, k + 15, NovaCraftBlocks.basal_bricks, 0, 2);
		world.setBlock(i + 23, j + 11, k + 15, NovaCraftBlocks.cracked_basal_bricks, 0, 2);
		world.setBlock(i + 24, j + 11, k + 15, NovaCraftBlocks.cracked_basal_bricks, 0, 2);
		world.setBlock(i + 25, j + 11, k + 15, NovaCraftBlocks.basal_bricks, 0, 2);
		world.setBlock(i + 26, j + 11, k + 15, NovaCraftBlocks.basal_bricks, 0, 2);
		world.setBlock(i + 27, j + 11, k + 15, NovaCraftBlocks.basal_bricks, 0, 2);
		world.setBlock(i, j + 11, k + 16, NovaCraftBlocks.cracked_basal_bricks, 0, 2);
		world.setBlock(i + 1, j + 11, k + 16, NovaCraftBlocks.basal_bricks, 0, 2);
		world.setBlock(i + 2, j + 11, k + 16, NovaCraftBlocks.basal_bricks, 0, 2);
		world.setBlock(i + 3, j + 11, k + 16, NovaCraftBlocks.cracked_basal_bricks, 0, 2);
		world.setBlock(i + 4, j + 11, k + 16, NovaCraftBlocks.cracked_basal_bricks, 0, 2);
		world.setBlock(i + 5, j + 11, k + 16, NovaCraftBlocks.basal_bricks, 0, 2);
		world.setBlock(i + 6, j + 11, k + 16, NovaCraftBlocks.cracked_basal_bricks, 0, 2);
		world.setBlock(i + 7, j + 11, k + 16, NovaCraftBlocks.basal_bricks, 0, 2);
		world.setBlock(i + 8, j + 11, k + 16, NovaCraftBlocks.basal_bricks, 0, 2);
		world.setBlock(i + 9, j + 11, k + 16, NovaCraftBlocks.cracked_basal_bricks, 0, 2);
		world.setBlock(i + 10, j + 11, k + 16, NovaCraftBlocks.basal_bricks, 0, 2);
		world.setBlock(i + 11, j + 11, k + 16, NovaCraftBlocks.cracked_basal_bricks, 0, 2);
		world.setBlock(i + 12, j + 11, k + 16, NovaCraftBlocks.basal_bricks, 0, 2);
		world.setBlock(i + 13, j + 11, k + 16, NovaCraftBlocks.cracked_basal_bricks, 0, 2);
		world.setBlock(i + 14, j + 11, k + 16, NovaCraftBlocks.basal_bricks, 0, 2);
		world.setBlock(i + 15, j + 11, k + 16, NovaCraftBlocks.basal_bricks, 0, 2);
		world.setBlock(i + 16, j + 11, k + 16, NovaCraftBlocks.basal_bricks, 0, 2);
		world.setBlock(i + 17, j + 11, k + 16, NovaCraftBlocks.basal_bricks, 0, 2);
		world.setBlock(i + 18, j + 11, k + 16, NovaCraftBlocks.cracked_basal_bricks, 0, 2);
		world.setBlock(i + 19, j + 11, k + 16, NovaCraftBlocks.basal_bricks, 0, 2);
		world.setBlock(i + 20, j + 11, k + 16, NovaCraftBlocks.cracked_basal_bricks, 0, 2);
		world.setBlock(i + 21, j + 11, k + 16, NovaCraftBlocks.basal_bricks, 0, 2);
		world.setBlock(i + 22, j + 11, k + 16, NovaCraftBlocks.basal_bricks, 0, 2);
		world.setBlock(i + 23, j + 11, k + 16, NovaCraftBlocks.basal_bricks, 0, 2);
		world.setBlock(i + 24, j + 11, k + 16, NovaCraftBlocks.basal_bricks, 0, 2);
		world.setBlock(i + 25, j + 11, k + 16, NovaCraftBlocks.basal_bricks, 0, 2);
		world.setBlock(i + 26, j + 11, k + 16, NovaCraftBlocks.basal_bricks, 0, 2);
		world.setBlock(i + 27, j + 11, k + 16, NovaCraftBlocks.cracked_basal_bricks, 0, 2);
		world.setBlock(i, j + 11, k + 17, NovaCraftBlocks.cracked_basal_bricks, 0, 2);
		world.setBlock(i + 1, j + 11, k + 17, NovaCraftBlocks.cracked_basal_bricks, 0, 2);
		world.setBlock(i + 2, j + 11, k + 17, NovaCraftBlocks.basal_bricks, 0, 2);
		world.setBlock(i + 3, j + 11, k + 17, NovaCraftBlocks.basal_bricks, 0, 2);
		world.setBlock(i + 4, j + 11, k + 17, NovaCraftBlocks.basal_bricks, 0, 2);
		world.setBlock(i + 5, j + 11, k + 17, NovaCraftBlocks.basal_bricks, 0, 2);
		world.setBlock(i + 6, j + 11, k + 17, NovaCraftBlocks.basal_bricks, 0, 2);
		world.setBlock(i + 7, j + 11, k + 17, NovaCraftBlocks.cracked_basal_bricks, 0, 2);
		world.setBlock(i + 8, j + 11, k + 17, NovaCraftBlocks.basal_bricks, 0, 2);
		world.setBlock(i + 9, j + 11, k + 17, NovaCraftBlocks.basal_bricks, 0, 2);
		world.setBlock(i + 10, j + 11, k + 17, NovaCraftBlocks.cracked_basal_bricks, 0, 2);
		world.setBlock(i + 11, j + 11, k + 17, NovaCraftBlocks.basal_bricks, 0, 2);
		world.setBlock(i + 12, j + 11, k + 17, NovaCraftBlocks.cracked_basal_bricks, 0, 2);
		world.setBlock(i + 13, j + 11, k + 17, NovaCraftBlocks.basal_bricks, 0, 2);
		world.setBlock(i + 14, j + 11, k + 17, NovaCraftBlocks.basal_bricks, 0, 2);
		world.setBlock(i + 15, j + 11, k + 17, NovaCraftBlocks.basal_bricks, 0, 2);
		world.setBlock(i + 16, j + 11, k + 17, NovaCraftBlocks.basal_bricks, 0, 2);
		world.setBlock(i + 17, j + 11, k + 17, NovaCraftBlocks.cracked_basal_bricks, 0, 2);
		world.setBlock(i + 18, j + 11, k + 17, NovaCraftBlocks.cracked_basal_bricks, 0, 2);
		world.setBlock(i + 19, j + 11, k + 17, NovaCraftBlocks.cracked_basal_bricks, 0, 2);
		world.setBlock(i + 20, j + 11, k + 17, NovaCraftBlocks.cracked_basal_bricks, 0, 2);
		world.setBlock(i + 21, j + 11, k + 17, NovaCraftBlocks.basal_bricks, 0, 2);
		world.setBlock(i + 22, j + 11, k + 17, NovaCraftBlocks.cracked_basal_bricks, 0, 2);
		world.setBlock(i + 23, j + 11, k + 17, NovaCraftBlocks.basal_bricks, 0, 2);
		world.setBlock(i + 24, j + 11, k + 17, NovaCraftBlocks.cracked_basal_bricks, 0, 2);
		world.setBlock(i + 25, j + 11, k + 17, NovaCraftBlocks.cracked_basal_bricks, 0, 2);
		world.setBlock(i + 26, j + 11, k + 17, NovaCraftBlocks.basal_bricks, 0, 2);
		world.setBlock(i + 27, j + 11, k + 17, NovaCraftBlocks.basal_bricks, 0, 2);
		world.setBlock(i, j + 11, k + 18, NovaCraftBlocks.cracked_basal_bricks, 0, 2);
		world.setBlock(i + 1, j + 11, k + 18, NovaCraftBlocks.basal_bricks, 0, 2);
		world.setBlock(i + 2, j + 11, k + 18, NovaCraftBlocks.basal_bricks, 0, 2);
		world.setBlock(i + 3, j + 11, k + 18, NovaCraftBlocks.basal_bricks, 0, 2);
		world.setBlock(i + 4, j + 11, k + 18, NovaCraftBlocks.cracked_basal_bricks, 0, 2);
		world.setBlock(i + 5, j + 11, k + 18, NovaCraftBlocks.basal_bricks, 0, 2);
		world.setBlock(i + 6, j + 11, k + 18, NovaCraftBlocks.basal_bricks, 0, 2);
		world.setBlock(i + 7, j + 11, k + 18, NovaCraftBlocks.basal_bricks, 0, 2);
		world.setBlock(i + 8, j + 11, k + 18, NovaCraftBlocks.basal_bricks, 0, 2);
		world.setBlock(i + 9, j + 11, k + 18, NovaCraftBlocks.cracked_basal_bricks, 0, 2);
		world.setBlock(i + 10, j + 11, k + 18, NovaCraftBlocks.basal_bricks, 0, 2);
		world.setBlock(i + 11, j + 11, k + 18, NovaCraftBlocks.basal_bricks, 0, 2);
		world.setBlock(i + 12, j + 11, k + 18, NovaCraftBlocks.basal_bricks, 0, 2);
		world.setBlock(i + 13, j + 11, k + 18, NovaCraftBlocks.basal_bricks, 0, 2);
		world.setBlock(i + 14, j + 11, k + 18, NovaCraftBlocks.basal_bricks, 0, 2);
		world.setBlock(i + 15, j + 11, k + 18, NovaCraftBlocks.basal_bricks, 0, 2);
		world.setBlock(i + 16, j + 11, k + 18, NovaCraftBlocks.cracked_basal_bricks, 0, 2);
		world.setBlock(i + 17, j + 11, k + 18, NovaCraftBlocks.basal_bricks, 0, 2);
		world.setBlock(i + 18, j + 11, k + 18, NovaCraftBlocks.basal_bricks, 0, 2);
		world.setBlock(i + 19, j + 11, k + 18, NovaCraftBlocks.cracked_basal_bricks, 0, 2);
		world.setBlock(i + 20, j + 11, k + 18, NovaCraftBlocks.basal_bricks, 0, 2);
		world.setBlock(i + 21, j + 11, k + 18, NovaCraftBlocks.basal_bricks, 0, 2);
		world.setBlock(i + 22, j + 11, k + 18, NovaCraftBlocks.basal_bricks, 0, 2);
		world.setBlock(i + 23, j + 11, k + 18, NovaCraftBlocks.basal_bricks, 0, 2);
		world.setBlock(i + 24, j + 11, k + 18, NovaCraftBlocks.basal_bricks, 0, 2);
		world.setBlock(i + 25, j + 11, k + 18, NovaCraftBlocks.cracked_basal_bricks, 0, 2);
		world.setBlock(i + 26, j + 11, k + 18, NovaCraftBlocks.cracked_basal_bricks, 0, 2);
		world.setBlock(i + 27, j + 11, k + 18, NovaCraftBlocks.basal_bricks, 0, 2);
		world.setBlock(i, j + 12, k, NovaCraftBlocks.basal_bricks, 0, 2);
		world.setBlock(i + 1, j + 12, k, NovaCraftBlocks.cracked_basal_bricks, 0, 2);
		world.setBlock(i + 2, j + 12, k, NovaCraftBlocks.basal_bricks, 0, 2);
		world.setBlock(i + 3, j + 12, k, NovaCraftBlocks.basal_bricks, 0, 2);
		world.setBlock(i + 4, j + 12, k, NovaCraftBlocks.cracked_basal_bricks, 0, 2);
		world.setBlock(i + 5, j + 12, k, NovaCraftBlocks.cracked_basal_bricks, 0, 2);
		world.setBlock(i + 6, j + 12, k, NovaCraftBlocks.basal_bricks, 0, 2);
		world.setBlock(i + 7, j + 12, k, NovaCraftBlocks.cracked_basal_bricks, 0, 2);
		world.setBlock(i + 8, j + 12, k, NovaCraftBlocks.basal_bricks, 0, 2);
		world.setBlock(i + 9, j + 12, k, NovaCraftBlocks.cracked_basal_bricks, 0, 2);
		world.setBlock(i + 10, j + 12, k, NovaCraftBlocks.basal_bricks, 0, 2);
		world.setBlock(i + 11, j + 12, k, NovaCraftBlocks.cracked_basal_bricks, 0, 2);
		world.setBlock(i + 12, j + 12, k, NovaCraftBlocks.cracked_basal_bricks, 0, 2);
		world.setBlock(i + 13, j + 12, k, NovaCraftBlocks.cracked_basal_bricks, 0, 2);
		world.setBlock(i + 14, j + 12, k, NovaCraftBlocks.basal_bricks, 0, 2);
		world.setBlock(i + 15, j + 12, k, NovaCraftBlocks.basal_bricks, 0, 2);
		world.setBlock(i + 16, j + 12, k, NovaCraftBlocks.basal_bricks, 0, 2);
		world.setBlock(i + 17, j + 12, k, NovaCraftBlocks.cracked_basal_bricks, 0, 2);
		world.setBlock(i + 18, j + 12, k, NovaCraftBlocks.basal_bricks, 0, 2);
		world.setBlock(i + 19, j + 12, k, NovaCraftBlocks.basal_bricks, 0, 2);
		world.setBlock(i + 20, j + 12, k, NovaCraftBlocks.cracked_basal_bricks, 0, 2);
		world.setBlock(i + 21, j + 12, k, NovaCraftBlocks.basal_bricks, 0, 2);
		world.setBlock(i + 22, j + 12, k, NovaCraftBlocks.basal_bricks, 0, 2);
		world.setBlock(i + 23, j + 12, k, NovaCraftBlocks.basal_bricks, 0, 2);
		world.setBlock(i + 24, j + 12, k, NovaCraftBlocks.basal_bricks, 0, 2);
		world.setBlock(i + 25, j + 12, k, NovaCraftBlocks.basal_bricks, 0, 2);
		world.setBlock(i + 26, j + 12, k, NovaCraftBlocks.cracked_basal_bricks, 0, 2);
		world.setBlock(i + 27, j + 12, k, Blocks.air, 0, 2);
		world.setBlock(i, j + 12, k + 1, NovaCraftBlocks.basal_bricks, 0, 2);
		world.setBlock(i + 1, j + 12, k + 1, NovaCraftBlocks.basal_bricks, 0, 2);
		world.setBlock(i + 2, j + 12, k + 1, NovaCraftBlocks.cracked_basal_bricks, 0, 2);
		world.setBlock(i + 3, j + 12, k + 1, NovaCraftBlocks.basal_bricks, 0, 2);
		world.setBlock(i + 4, j + 12, k + 1, NovaCraftBlocks.cracked_basal_bricks, 0, 2);
		world.setBlock(i + 5, j + 12, k + 1, NovaCraftBlocks.basal_bricks, 0, 2);
		world.setBlock(i + 6, j + 12, k + 1, NovaCraftBlocks.basal_bricks, 0, 2);
		world.setBlock(i + 7, j + 12, k + 1, NovaCraftBlocks.cracked_basal_bricks, 0, 2);
		world.setBlock(i + 8, j + 12, k + 1, NovaCraftBlocks.basal_bricks, 0, 2);
		world.setBlock(i + 9, j + 12, k + 1, NovaCraftBlocks.basal_bricks, 0, 2);
		world.setBlock(i + 10, j + 12, k + 1, NovaCraftBlocks.cracked_basal_bricks, 0, 2);
		world.setBlock(i + 11, j + 12, k + 1, NovaCraftBlocks.cracked_basal_bricks, 0, 2);
		world.setBlock(i + 12, j + 12, k + 1, NovaCraftBlocks.cracked_basal_bricks, 0, 2);
		world.setBlock(i + 13, j + 12, k + 1, NovaCraftBlocks.cracked_basal_bricks, 0, 2);
		world.setBlock(i + 14, j + 12, k + 1, NovaCraftBlocks.basal_bricks, 0, 2);
		world.setBlock(i + 15, j + 12, k + 1, NovaCraftBlocks.basal_bricks, 0, 2);
		world.setBlock(i + 16, j + 12, k + 1, NovaCraftBlocks.basal_bricks, 0, 2);
		world.setBlock(i + 17, j + 12, k + 1, NovaCraftBlocks.basal_bricks, 0, 2);
		world.setBlock(i + 18, j + 12, k + 1, NovaCraftBlocks.cracked_basal_bricks, 0, 2);
		world.setBlock(i + 19, j + 12, k + 1, NovaCraftBlocks.basal_bricks, 0, 2);
		world.setBlock(i + 20, j + 12, k + 1, NovaCraftBlocks.basal_bricks, 0, 2);
		world.setBlock(i + 21, j + 12, k + 1, NovaCraftBlocks.cracked_basal_bricks, 0, 2);
		world.setBlock(i + 22, j + 12, k + 1, NovaCraftBlocks.basal_bricks, 0, 2);
		world.setBlock(i + 23, j + 12, k + 1, NovaCraftBlocks.basal_bricks, 0, 2);
		world.setBlock(i + 24, j + 12, k + 1, NovaCraftBlocks.basal_bricks, 0, 2);
		world.setBlock(i + 25, j + 12, k + 1, NovaCraftBlocks.cracked_basal_bricks, 0, 2);
		world.setBlock(i + 26, j + 12, k + 1, NovaCraftBlocks.cracked_basal_bricks, 0, 2);
		world.setBlock(i + 27, j + 12, k + 1, Blocks.air, 0, 2);
		world.setBlock(i, j + 12, k + 2, NovaCraftBlocks.basal_bricks, 0, 2);
		world.setBlock(i + 1, j + 12, k + 2, NovaCraftBlocks.basal_bricks, 0, 2);
		world.setBlock(i + 2, j + 12, k + 2, NovaCraftBlocks.cracked_basal_bricks, 0, 2);
		world.setBlock(i + 3, j + 12, k + 2, NovaCraftBlocks.basal_bricks, 0, 2);
		world.setBlock(i + 4, j + 12, k + 2, NovaCraftBlocks.basal_bricks, 0, 2);
		world.setBlock(i + 5, j + 12, k + 2, NovaCraftBlocks.basal_bricks, 0, 2);
		world.setBlock(i + 6, j + 12, k + 2, NovaCraftBlocks.basal_bricks, 0, 2);
		world.setBlock(i + 7, j + 12, k + 2, NovaCraftBlocks.cracked_basal_bricks, 0, 2);
		world.setBlock(i + 8, j + 12, k + 2, NovaCraftBlocks.cracked_basal_bricks, 0, 2);
		world.setBlock(i + 9, j + 12, k + 2, NovaCraftBlocks.cracked_basal_bricks, 0, 2);
		world.setBlock(i + 10, j + 12, k + 2, NovaCraftBlocks.cracked_basal_bricks, 0, 2);
		world.setBlock(i + 11, j + 12, k + 2, NovaCraftBlocks.basal_bricks, 0, 2);
		world.setBlock(i + 12, j + 12, k + 2, NovaCraftBlocks.basal_bricks, 0, 2);
		world.setBlock(i + 13, j + 12, k + 2, NovaCraftBlocks.basal_bricks, 0, 2);
		world.setBlock(i + 14, j + 12, k + 2, NovaCraftBlocks.cracked_basal_bricks, 0, 2);
		world.setBlock(i + 15, j + 12, k + 2, NovaCraftBlocks.cracked_basal_bricks, 0, 2);
		world.setBlock(i + 16, j + 12, k + 2, NovaCraftBlocks.basal_bricks, 0, 2);
		world.setBlock(i + 17, j + 12, k + 2, NovaCraftBlocks.cracked_basal_bricks, 0, 2);
		world.setBlock(i + 18, j + 12, k + 2, NovaCraftBlocks.basal_bricks, 0, 2);
		world.setBlock(i + 19, j + 12, k + 2, NovaCraftBlocks.cracked_basal_bricks, 0, 2);
		world.setBlock(i + 20, j + 12, k + 2, NovaCraftBlocks.cracked_basal_bricks, 0, 2);
		world.setBlock(i + 21, j + 12, k + 2, NovaCraftBlocks.basal_bricks, 0, 2);
		world.setBlock(i + 22, j + 12, k + 2, NovaCraftBlocks.cracked_basal_bricks, 0, 2);
		world.setBlock(i + 23, j + 12, k + 2, NovaCraftBlocks.basal_bricks, 0, 2);
		world.setBlock(i + 24, j + 12, k + 2, NovaCraftBlocks.basal_bricks, 0, 2);
		world.setBlock(i + 25, j + 12, k + 2, NovaCraftBlocks.basal_bricks, 0, 2);
		world.setBlock(i + 26, j + 12, k + 2, NovaCraftBlocks.cracked_basal_bricks, 0, 2);
		world.setBlock(i + 27, j + 12, k + 2, NovaCraftBlocks.basal_bricks, 0, 2);
		world.setBlock(i, j + 12, k + 3, NovaCraftBlocks.cracked_basal_bricks, 0, 2);
		world.setBlock(i + 1, j + 12, k + 3, NovaCraftBlocks.basal_bricks, 0, 2);
		world.setBlock(i + 2, j + 12, k + 3, NovaCraftBlocks.basal_bricks, 0, 2);
		world.setBlock(i + 3, j + 12, k + 3, NovaCraftBlocks.basal_bricks, 0, 2);
		world.setBlock(i + 4, j + 12, k + 3, NovaCraftBlocks.basal_bricks, 0, 2);
		world.setBlock(i + 5, j + 12, k + 3, NovaCraftBlocks.cracked_basal_bricks, 0, 2);
		world.setBlock(i + 6, j + 12, k + 3, NovaCraftBlocks.basal_bricks, 0, 2);
		world.setBlock(i + 7, j + 12, k + 3, NovaCraftBlocks.basal_bricks, 0, 2);
		world.setBlock(i + 8, j + 12, k + 3, NovaCraftBlocks.cracked_basal_bricks, 0, 2);
		world.setBlock(i + 9, j + 12, k + 3, NovaCraftBlocks.cracked_basal_bricks, 0, 2);
		world.setBlock(i + 10, j + 12, k + 3, NovaCraftBlocks.cracked_basal_bricks, 0, 2);
		world.setBlock(i + 11, j + 12, k + 3, NovaCraftBlocks.cracked_basal_bricks, 0, 2);
		world.setBlock(i + 12, j + 12, k + 3, NovaCraftBlocks.basal_bricks, 0, 2);
		world.setBlock(i + 13, j + 12, k + 3, NovaCraftBlocks.cracked_basal_bricks, 0, 2);
		world.setBlock(i + 14, j + 12, k + 3, NovaCraftBlocks.basal_bricks, 0, 2);
		world.setBlock(i + 15, j + 12, k + 3, NovaCraftBlocks.cracked_basal_bricks, 0, 2);
		world.setBlock(i + 16, j + 12, k + 3, NovaCraftBlocks.basal_bricks, 0, 2);
		world.setBlock(i + 17, j + 12, k + 3, NovaCraftBlocks.cracked_basal_bricks, 0, 2);
		world.setBlock(i + 18, j + 12, k + 3, NovaCraftBlocks.basal_bricks, 0, 2);
		world.setBlock(i + 19, j + 12, k + 3, NovaCraftBlocks.basal_bricks, 0, 2);
		world.setBlock(i + 20, j + 12, k + 3, NovaCraftBlocks.basal_bricks, 0, 2);
		world.setBlock(i + 21, j + 12, k + 3, NovaCraftBlocks.basal_bricks, 0, 2);
		world.setBlock(i + 22, j + 12, k + 3, NovaCraftBlocks.cracked_basal_bricks, 0, 2);
		world.setBlock(i + 23, j + 12, k + 3, NovaCraftBlocks.basal_bricks, 0, 2);
		world.setBlock(i + 24, j + 12, k + 3, NovaCraftBlocks.basal_bricks, 0, 2);
		world.setBlock(i + 25, j + 12, k + 3, NovaCraftBlocks.cracked_basal_bricks, 0, 2);
		world.setBlock(i + 26, j + 12, k + 3, NovaCraftBlocks.basal_bricks, 0, 2);
		world.setBlock(i + 27, j + 12, k + 3, NovaCraftBlocks.basal_bricks, 0, 2);
		world.setBlock(i, j + 12, k + 4, NovaCraftBlocks.cracked_basal_bricks, 0, 2);
		world.setBlock(i + 1, j + 12, k + 4, NovaCraftBlocks.basal_bricks, 0, 2);
		world.setBlock(i + 2, j + 12, k + 4, NovaCraftBlocks.basal_bricks, 0, 2);
		world.setBlock(i + 3, j + 12, k + 4, NovaCraftBlocks.basal_bricks, 0, 2);
		world.setBlock(i + 4, j + 12, k + 4, NovaCraftBlocks.basal_bricks, 0, 2);
		world.setBlock(i + 5, j + 12, k + 4, NovaCraftBlocks.basal_bricks, 0, 2);
		world.setBlock(i + 6, j + 12, k + 4, NovaCraftBlocks.basal_bricks, 0, 2);
		world.setBlock(i + 7, j + 12, k + 4, NovaCraftBlocks.cracked_basal_bricks, 0, 2);
		world.setBlock(i + 8, j + 12, k + 4, NovaCraftBlocks.basal_bricks, 0, 2);
		world.setBlock(i + 9, j + 12, k + 4, NovaCraftBlocks.basal_bricks, 0, 2);
		world.setBlock(i + 10, j + 12, k + 4, NovaCraftBlocks.cracked_basal_bricks, 0, 2);
		world.setBlock(i + 11, j + 12, k + 4, NovaCraftBlocks.cracked_basal_bricks, 0, 2);
		world.setBlock(i + 12, j + 12, k + 4, NovaCraftBlocks.cracked_basal_bricks, 0, 2);
		world.setBlock(i + 13, j + 12, k + 4, NovaCraftBlocks.cracked_basal_bricks, 0, 2);
		world.setBlock(i + 14, j + 12, k + 4, NovaCraftBlocks.basal_bricks, 0, 2);
		world.setBlock(i + 15, j + 12, k + 4, NovaCraftBlocks.cracked_basal_bricks, 0, 2);
		world.setBlock(i + 16, j + 12, k + 4, NovaCraftBlocks.basal_bricks, 0, 2);
		world.setBlock(i + 17, j + 12, k + 4, NovaCraftBlocks.basal_bricks, 0, 2);
		world.setBlock(i + 18, j + 12, k + 4, NovaCraftBlocks.basal_bricks, 0, 2);
		world.setBlock(i + 19, j + 12, k + 4, NovaCraftBlocks.basal_bricks, 0, 2);
		world.setBlock(i + 20, j + 12, k + 4, NovaCraftBlocks.basal_bricks, 0, 2);
		world.setBlock(i + 21, j + 12, k + 4, NovaCraftBlocks.cracked_basal_bricks, 0, 2);
		world.setBlock(i + 22, j + 12, k + 4, NovaCraftBlocks.basal_bricks, 0, 2);
		world.setBlock(i + 23, j + 12, k + 4, NovaCraftBlocks.cracked_basal_bricks, 0, 2);
		world.setBlock(i + 24, j + 12, k + 4, NovaCraftBlocks.basal_bricks, 0, 2);
		world.setBlock(i + 25, j + 12, k + 4, NovaCraftBlocks.basal_bricks, 0, 2);
		world.setBlock(i + 26, j + 12, k + 4, NovaCraftBlocks.basal_bricks, 0, 2);
		world.setBlock(i + 27, j + 12, k + 4, NovaCraftBlocks.basal_bricks, 0, 2);
		world.setBlock(i, j + 12, k + 5, NovaCraftBlocks.cracked_basal_bricks, 0, 2);
		world.setBlock(i + 1, j + 12, k + 5, NovaCraftBlocks.basal_bricks, 0, 2);
		world.setBlock(i + 2, j + 12, k + 5, NovaCraftBlocks.cracked_basal_bricks, 0, 2);
		world.setBlock(i + 3, j + 12, k + 5, NovaCraftBlocks.basal_bricks, 0, 2);
		world.setBlock(i + 4, j + 12, k + 5, NovaCraftBlocks.cracked_basal_bricks, 0, 2);
		world.setBlock(i + 5, j + 12, k + 5, NovaCraftBlocks.basal_bricks, 0, 2);
		world.setBlock(i + 6, j + 12, k + 5, NovaCraftBlocks.basal_bricks, 0, 2);
		world.setBlock(i + 7, j + 12, k + 5, NovaCraftBlocks.basal_bricks, 0, 2);
		world.setBlock(i + 8, j + 12, k + 5, NovaCraftBlocks.cracked_basal_bricks, 0, 2);
		world.setBlock(i + 9, j + 12, k + 5, NovaCraftBlocks.basal_bricks, 0, 2);
		world.setBlock(i + 10, j + 12, k + 5, NovaCraftBlocks.basal_bricks, 0, 2);
		world.setBlock(i + 11, j + 12, k + 5, NovaCraftBlocks.basal_bricks, 0, 2);
		world.setBlock(i + 12, j + 12, k + 5, NovaCraftBlocks.cracked_basal_bricks, 0, 2);
		world.setBlock(i + 13, j + 12, k + 5, NovaCraftBlocks.cracked_basal_bricks, 0, 2);
		world.setBlock(i + 14, j + 12, k + 5, NovaCraftBlocks.cracked_basal_bricks, 0, 2);
		world.setBlock(i + 15, j + 12, k + 5, NovaCraftBlocks.cracked_basal_bricks, 0, 2);
		world.setBlock(i + 16, j + 12, k + 5, NovaCraftBlocks.cracked_basal_bricks, 0, 2);
		world.setBlock(i + 17, j + 12, k + 5, NovaCraftBlocks.basal_bricks, 0, 2);
		world.setBlock(i + 18, j + 12, k + 5, NovaCraftBlocks.basal_bricks, 0, 2);
		world.setBlock(i + 19, j + 12, k + 5, NovaCraftBlocks.basal_bricks, 0, 2);
		world.setBlock(i + 20, j + 12, k + 5, NovaCraftBlocks.basal_bricks, 0, 2);
		world.setBlock(i + 21, j + 12, k + 5, NovaCraftBlocks.basal_bricks, 0, 2);
		world.setBlock(i + 22, j + 12, k + 5, NovaCraftBlocks.basal_bricks, 0, 2);
		world.setBlock(i + 23, j + 12, k + 5, NovaCraftBlocks.basal_bricks, 0, 2);
		world.setBlock(i + 24, j + 12, k + 5, NovaCraftBlocks.basal_bricks, 0, 2);
		world.setBlock(i + 25, j + 12, k + 5, NovaCraftBlocks.cracked_basal_bricks, 0, 2);
		world.setBlock(i + 26, j + 12, k + 5, NovaCraftBlocks.cracked_basal_bricks, 0, 2);
		world.setBlock(i + 27, j + 12, k + 5, NovaCraftBlocks.cracked_basal_bricks, 0, 2);
		world.setBlock(i, j + 12, k + 6, NovaCraftBlocks.cracked_basal_bricks, 0, 2);
		world.setBlock(i + 1, j + 12, k + 6, NovaCraftBlocks.basal_bricks, 0, 2);
		world.setBlock(i + 2, j + 12, k + 6, NovaCraftBlocks.basal_bricks, 0, 2);
		world.setBlock(i + 3, j + 12, k + 6, NovaCraftBlocks.basal_bricks, 0, 2);
		world.setBlock(i + 4, j + 12, k + 6, NovaCraftBlocks.basal_bricks, 0, 2);
		world.setBlock(i + 5, j + 12, k + 6, NovaCraftBlocks.basal_bricks, 0, 2);
		world.setBlock(i + 6, j + 12, k + 6, NovaCraftBlocks.basal_bricks, 0, 2);
		world.setBlock(i + 7, j + 12, k + 6, NovaCraftBlocks.cracked_basal_bricks, 0, 2);
		world.setBlock(i + 8, j + 12, k + 6, NovaCraftBlocks.cracked_basal_bricks, 0, 2);
		world.setBlock(i + 9, j + 12, k + 6, NovaCraftBlocks.basal_bricks, 0, 2);
		world.setBlock(i + 10, j + 12, k + 6, NovaCraftBlocks.basal_bricks, 0, 2);
		world.setBlock(i + 11, j + 12, k + 6, NovaCraftBlocks.cracked_basal_bricks, 0, 2);
		world.setBlock(i + 12, j + 12, k + 6, NovaCraftBlocks.cracked_basal_bricks, 0, 2);
		world.setBlock(i + 13, j + 12, k + 6, NovaCraftBlocks.cracked_basal_bricks, 0, 2);
		world.setBlock(i + 14, j + 12, k + 6, NovaCraftBlocks.cracked_basal_bricks, 0, 2);
		world.setBlock(i + 15, j + 12, k + 6, NovaCraftBlocks.basal_bricks, 0, 2);
		world.setBlock(i + 16, j + 12, k + 6, NovaCraftBlocks.basal_bricks, 0, 2);
		world.setBlock(i + 17, j + 12, k + 6, NovaCraftBlocks.cracked_basal_bricks, 0, 2);
		world.setBlock(i + 18, j + 12, k + 6, NovaCraftBlocks.basal_bricks, 0, 2);
		world.setBlock(i + 19, j + 12, k + 6, NovaCraftBlocks.basal_bricks, 0, 2);
		world.setBlock(i + 20, j + 12, k + 6, NovaCraftBlocks.cracked_basal_bricks, 0, 2);
		world.setBlock(i + 21, j + 12, k + 6, NovaCraftBlocks.cracked_basal_bricks, 0, 2);
		world.setBlock(i + 22, j + 12, k + 6, NovaCraftBlocks.cracked_basal_bricks, 0, 2);
		world.setBlock(i + 23, j + 12, k + 6, NovaCraftBlocks.cracked_basal_bricks, 0, 2);
		world.setBlock(i + 24, j + 12, k + 6, NovaCraftBlocks.basal_bricks, 0, 2);
		world.setBlock(i + 25, j + 12, k + 6, NovaCraftBlocks.cracked_basal_bricks, 0, 2);
		world.setBlock(i + 26, j + 12, k + 6, NovaCraftBlocks.basal_bricks, 0, 2);
		world.setBlock(i + 27, j + 12, k + 6, NovaCraftBlocks.cracked_basal_bricks, 0, 2);
		world.setBlock(i, j + 12, k + 7, NovaCraftBlocks.cracked_basal_bricks, 0, 2);
		world.setBlock(i + 1, j + 12, k + 7, NovaCraftBlocks.basal_bricks, 0, 2);
		world.setBlock(i + 2, j + 12, k + 7, NovaCraftBlocks.cracked_basal_bricks, 0, 2);
		world.setBlock(i + 3, j + 12, k + 7, NovaCraftBlocks.basal_bricks, 0, 2);
		world.setBlock(i + 4, j + 12, k + 7, NovaCraftBlocks.cracked_basal_bricks, 0, 2);
		world.setBlock(i + 5, j + 12, k + 7, NovaCraftBlocks.basal_bricks, 0, 2);
		world.setBlock(i + 6, j + 12, k + 7, NovaCraftBlocks.cracked_basal_bricks, 0, 2);
		world.setBlock(i + 7, j + 12, k + 7, NovaCraftBlocks.cracked_basal_bricks, 0, 2);
		world.setBlock(i + 8, j + 12, k + 7, NovaCraftBlocks.cracked_basal_bricks, 0, 2);
		world.setBlock(i + 9, j + 12, k + 7, NovaCraftBlocks.basal_bricks, 0, 2);
		world.setBlock(i + 10, j + 12, k + 7, NovaCraftBlocks.basal_bricks, 0, 2);
		world.setBlock(i + 11, j + 12, k + 7, NovaCraftBlocks.basal_bricks, 0, 2);
		world.setBlock(i + 12, j + 12, k + 7, NovaCraftBlocks.basal_bricks, 0, 2);
		world.setBlock(i + 13, j + 12, k + 7, NovaCraftBlocks.cracked_basal_bricks, 0, 2);
		world.setBlock(i + 14, j + 12, k + 7, NovaCraftBlocks.cracked_basal_bricks, 0, 2);
		world.setBlock(i + 15, j + 12, k + 7, NovaCraftBlocks.basal_bricks, 0, 2);
		world.setBlock(i + 16, j + 12, k + 7, NovaCraftBlocks.basal_bricks, 0, 2);
		world.setBlock(i + 17, j + 12, k + 7, NovaCraftBlocks.basal_bricks, 0, 2);
		world.setBlock(i + 18, j + 12, k + 7, NovaCraftBlocks.basal_bricks, 0, 2);
		world.setBlock(i + 19, j + 12, k + 7, NovaCraftBlocks.basal_bricks, 0, 2);
		world.setBlock(i + 20, j + 12, k + 7, NovaCraftBlocks.cracked_basal_bricks, 0, 2);
		world.setBlock(i + 21, j + 12, k + 7, NovaCraftBlocks.basal_bricks, 0, 2);
		world.setBlock(i + 22, j + 12, k + 7, NovaCraftBlocks.basal_bricks, 0, 2);
		world.setBlock(i + 23, j + 12, k + 7, NovaCraftBlocks.cracked_basal_bricks, 0, 2);
		world.setBlock(i + 24, j + 12, k + 7, NovaCraftBlocks.basal_bricks, 0, 2);
		world.setBlock(i + 25, j + 12, k + 7, NovaCraftBlocks.basal_bricks, 0, 2);
		world.setBlock(i + 26, j + 12, k + 7, NovaCraftBlocks.cracked_basal_bricks, 0, 2);
		world.setBlock(i + 27, j + 12, k + 7, NovaCraftBlocks.cracked_basal_bricks, 0, 2);
		world.setBlock(i, j + 12, k + 8, Blocks.air, 0, 2);
		world.setBlock(i + 1, j + 12, k + 8, NovaCraftBlocks.cracked_basal_bricks, 0, 2);
		world.setBlock(i + 2, j + 12, k + 8, NovaCraftBlocks.cracked_basal_bricks, 0, 2);
		world.setBlock(i + 3, j + 12, k + 8, NovaCraftBlocks.basal_bricks, 0, 2);
		world.setBlock(i + 4, j + 12, k + 8, NovaCraftBlocks.basal_bricks, 0, 2);
		world.setBlock(i + 5, j + 12, k + 8, NovaCraftBlocks.basal_bricks, 0, 2);
		world.setBlock(i + 6, j + 12, k + 8, NovaCraftBlocks.cracked_basal_bricks, 0, 2);
		world.setBlock(i + 7, j + 12, k + 8, NovaCraftBlocks.basal_bricks, 0, 2);
		world.setBlock(i + 8, j + 12, k + 8, NovaCraftBlocks.basal_bricks, 0, 2);
		world.setBlock(i + 9, j + 12, k + 8, NovaCraftBlocks.basal_bricks, 0, 2);
		world.setBlock(i + 10, j + 12, k + 8, NovaCraftBlocks.basal_bricks, 0, 2);
		world.setBlock(i + 11, j + 12, k + 8, NovaCraftBlocks.cracked_basal_bricks, 0, 2);
		world.setBlock(i + 12, j + 12, k + 8, NovaCraftBlocks.basal_bricks, 0, 2);
		world.setBlock(i + 13, j + 12, k + 8, NovaCraftBlocks.basal_bricks, 0, 2);
		world.setBlock(i + 14, j + 12, k + 8, NovaCraftBlocks.cracked_basal_bricks, 0, 2);
		world.setBlock(i + 15, j + 12, k + 8, NovaCraftBlocks.basal_bricks, 0, 2);
		world.setBlock(i + 16, j + 12, k + 8, NovaCraftBlocks.basal_bricks, 0, 2);
		world.setBlock(i + 17, j + 12, k + 8, NovaCraftBlocks.cracked_basal_bricks, 0, 2);
		world.setBlock(i + 18, j + 12, k + 8, NovaCraftBlocks.cracked_basal_bricks, 0, 2);
		world.setBlock(i + 19, j + 12, k + 8, NovaCraftBlocks.basal_bricks, 0, 2);
		world.setBlock(i + 20, j + 12, k + 8, NovaCraftBlocks.cracked_basal_bricks, 0, 2);
		world.setBlock(i + 21, j + 12, k + 8, NovaCraftBlocks.basal_bricks, 0, 2);
		world.setBlock(i + 22, j + 12, k + 8, NovaCraftBlocks.basal_bricks, 0, 2);
		world.setBlock(i + 23, j + 12, k + 8, NovaCraftBlocks.basal_bricks, 0, 2);
		world.setBlock(i + 24, j + 12, k + 8, NovaCraftBlocks.cracked_basal_bricks, 0, 2);
		world.setBlock(i + 25, j + 12, k + 8, NovaCraftBlocks.basal_bricks, 0, 2);
		world.setBlock(i + 26, j + 12, k + 8, NovaCraftBlocks.basal_bricks, 0, 2);
		world.setBlock(i + 27, j + 12, k + 8, NovaCraftBlocks.basal_bricks, 0, 2);
		world.setBlock(i, j + 12, k + 9, Blocks.air, 0, 2);
		world.setBlock(i + 1, j + 12, k + 9, NovaCraftBlocks.cracked_basal_bricks, 0, 2);
		world.setBlock(i + 2, j + 12, k + 9, NovaCraftBlocks.cracked_basal_bricks, 0, 2);
		world.setBlock(i + 3, j + 12, k + 9, NovaCraftBlocks.basal_bricks, 0, 2);
		world.setBlock(i + 4, j + 12, k + 9, NovaCraftBlocks.cracked_basal_bricks, 0, 2);
		world.setBlock(i + 5, j + 12, k + 9, NovaCraftBlocks.cracked_basal_bricks, 0, 2);
		world.setBlock(i + 6, j + 12, k + 9, NovaCraftBlocks.basal_bricks, 0, 2);
		world.setBlock(i + 7, j + 12, k + 9, NovaCraftBlocks.basal_bricks, 0, 2);
		world.setBlock(i + 8, j + 12, k + 9, NovaCraftBlocks.basal_bricks, 0, 2);
		world.setBlock(i + 9, j + 12, k + 9, NovaCraftBlocks.cracked_basal_bricks, 0, 2);
		world.setBlock(i + 10, j + 12, k + 9, NovaCraftBlocks.basal_bricks, 0, 2);
		world.setBlock(i + 11, j + 12, k + 9, NovaCraftBlocks.basal_bricks, 0, 2);
		world.setBlock(i + 12, j + 12, k + 9, NovaCraftBlocks.basal_bricks, 0, 2);
		world.setBlock(i + 13, j + 12, k + 9, NovaCraftBlocks.cracked_basal_bricks, 0, 2);
		world.setBlock(i + 14, j + 12, k + 9, NovaCraftBlocks.basal_bricks, 0, 2);
		world.setBlock(i + 15, j + 12, k + 9, NovaCraftBlocks.basal_bricks, 0, 2);
		world.setBlock(i + 16, j + 12, k + 9, NovaCraftBlocks.basal_bricks, 0, 2);
		world.setBlock(i + 17, j + 12, k + 9, NovaCraftBlocks.basal_bricks, 0, 2);
		world.setBlock(i + 18, j + 12, k + 9, NovaCraftBlocks.basal_bricks, 0, 2);
		world.setBlock(i + 19, j + 12, k + 9, NovaCraftBlocks.basal_bricks, 0, 2);
		world.setBlock(i + 20, j + 12, k + 9, NovaCraftBlocks.basal_bricks, 0, 2);
		world.setBlock(i + 21, j + 12, k + 9, NovaCraftBlocks.basal_bricks, 0, 2);
		world.setBlock(i + 22, j + 12, k + 9, NovaCraftBlocks.basal_bricks, 0, 2);
		world.setBlock(i + 23, j + 12, k + 9, NovaCraftBlocks.basal_bricks, 0, 2);
		world.setBlock(i + 24, j + 12, k + 9, NovaCraftBlocks.basal_bricks, 0, 2);
		world.setBlock(i + 25, j + 12, k + 9, NovaCraftBlocks.basal_bricks, 0, 2);
		world.setBlock(i + 26, j + 12, k + 9, NovaCraftBlocks.basal_bricks, 0, 2);
		world.setBlock(i + 27, j + 12, k + 9, NovaCraftBlocks.basal_bricks, 0, 2);
		world.setBlock(i, j + 12, k + 10, NovaCraftBlocks.cracked_basal_bricks, 0, 2);
		world.setBlock(i + 1, j + 12, k + 10, NovaCraftBlocks.cracked_basal_bricks, 0, 2);
		world.setBlock(i + 2, j + 12, k + 10, NovaCraftBlocks.basal_bricks, 0, 2);
		world.setBlock(i + 3, j + 12, k + 10, NovaCraftBlocks.basal_bricks, 0, 2);
		world.setBlock(i + 4, j + 12, k + 10, NovaCraftBlocks.cracked_basal_bricks, 0, 2);
		world.setBlock(i + 5, j + 12, k + 10, NovaCraftBlocks.cracked_basal_bricks, 0, 2);
		world.setBlock(i + 6, j + 12, k + 10, NovaCraftBlocks.basal_bricks, 0, 2);
		world.setBlock(i + 7, j + 12, k + 10, NovaCraftBlocks.cracked_basal_bricks, 0, 2);
		world.setBlock(i + 8, j + 12, k + 10, NovaCraftBlocks.basal_bricks, 0, 2);
		world.setBlock(i + 9, j + 12, k + 10, NovaCraftBlocks.cracked_basal_bricks, 0, 2);
		world.setBlock(i + 10, j + 12, k + 10, NovaCraftBlocks.cracked_basal_bricks, 0, 2);
		world.setBlock(i + 11, j + 12, k + 10, NovaCraftBlocks.cracked_basal_bricks, 0, 2);
		world.setBlock(i + 12, j + 12, k + 10, NovaCraftBlocks.cracked_basal_bricks, 0, 2);
		world.setBlock(i + 13, j + 12, k + 10, NovaCraftBlocks.cracked_basal_bricks, 0, 2);
		world.setBlock(i + 14, j + 12, k + 10, Blocks.air, 0, 2);
		world.setBlock(i + 15, j + 12, k + 10, NovaCraftBlocks.cracked_basal_bricks, 0, 2);
		world.setBlock(i + 16, j + 12, k + 10, NovaCraftBlocks.cracked_basal_bricks, 0, 2);
		world.setBlock(i + 17, j + 12, k + 10, NovaCraftBlocks.cracked_basal_bricks, 0, 2);
		world.setBlock(i + 18, j + 12, k + 10, NovaCraftBlocks.cracked_basal_bricks, 0, 2);
		world.setBlock(i + 19, j + 12, k + 10, NovaCraftBlocks.basal_bricks, 0, 2);
		world.setBlock(i + 20, j + 12, k + 10, NovaCraftBlocks.basal_bricks, 0, 2);
		world.setBlock(i + 21, j + 12, k + 10, NovaCraftBlocks.basal_bricks, 0, 2);
		world.setBlock(i + 22, j + 12, k + 10, NovaCraftBlocks.basal_bricks, 0, 2);
