package com.NovaCraft.world.bastion.treasure;

import net.minecraft.world.gen.feature.*;
import net.minecraft.world.*;
import java.util.*;
import com.NovaCraft.entity.EntitySavageSerpent;
import com.NovaCraftBlocks.NovaCraftBlocks;
import net.minecraft.init.*;

public class BastionTreasureBarracksGen10 extends WorldGenerator
{
	public BastionTreasureBarracksGen10() {

	}
    
    public boolean generate(final World world, final Random random, final int i, final int j, final int k) {
    	
    	world.setBlock(i + 10, j + 62, k + 4, NovaCraftBlocks.basal_bricks, 0, 2);
		world.setBlock(i + 11, j + 62, k + 4, NovaCraftBlocks.basal_bricks, 0, 2);
		world.setBlock(i + 12, j + 62, k + 4, NovaCraftBlocks.basal_bricks, 0, 2);
		world.setBlock(i + 13, j + 62, k + 4, NovaCraftBlocks.basal_bricks, 0, 2);
		world.setBlock(i + 14, j + 62, k + 4, NovaCraftBlocks.basal_bricks, 0, 2);
		world.setBlock(i + 15, j + 62, k + 4, NovaCraftBlocks.basal_bricks, 0, 2);
		world.setBlock(i + 16, j + 62, k + 4, NovaCraftBlocks.basal_bricks, 0, 2);
		world.setBlock(i + 17, j + 62, k + 4, Blocks.air, 0, 2);
		world.setBlock(i + 18, j + 62, k + 4, NovaCraftBlocks.basal_bricks, 0, 2);
		world.setBlock(i + 19, j + 62, k + 4, NovaCraftBlocks.basal_bricks, 0, 2);
		world.setBlock(i + 20, j + 62, k + 4, NovaCraftBlocks.basal_bricks, 0, 2);
		world.setBlock(i + 21, j + 62, k + 4, NovaCraftBlocks.basal_bricks, 0, 2);
		world.setBlock(i + 22, j + 62, k + 4, NovaCraftBlocks.basal_bricks, 0, 2);
		world.setBlock(i + 23, j + 62, k + 4, NovaCraftBlocks.basal_bricks, 0, 2);
		world.setBlock(i + 24, j + 62, k + 4, Blocks.air, 0, 2);
		world.setBlock(i + 25, j + 62, k + 4, NovaCraftBlocks.basal_bricks, 0, 2);
		world.setBlock(i + 26, j + 62, k + 4, NovaCraftBlocks.basal_bricks, 0, 2);
		world.setBlock(i + 27, j + 62, k + 4, NovaCraftBlocks.basal_bricks, 0, 2);
		world.setBlock(i, j + 62, k + 5, NovaCraftBlocks.basal_bricks, 0, 2);
		world.setBlock(i + 1, j + 62, k + 5, NovaCraftBlocks.basal_bricks, 0, 2);
		world.setBlock(i + 2, j + 62, k + 5, NovaCraftBlocks.basal_bricks, 0, 2);
		world.setBlock(i + 3, j + 62, k + 5, NovaCraftBlocks.basal_bricks, 0, 2);
		world.setBlock(i + 4, j + 62, k + 5, Blocks.air, 0, 2);
		world.setBlock(i + 5, j + 62, k + 5, Blocks.air, 0, 2);
		world.setBlock(i + 6, j + 62, k + 5, Blocks.air, 0, 2);
		world.setBlock(i + 7, j + 62, k + 5, Blocks.air, 0, 2);
		world.setBlock(i + 8, j + 62, k + 5, Blocks.air, 0, 2);
		world.setBlock(i + 9, j + 62, k + 5, Blocks.air, 0, 2);
		world.setBlock(i + 10, j + 62, k + 5, Blocks.air, 0, 2);
		world.setBlock(i + 11, j + 62, k + 5, NovaCraftBlocks.basal_bricks, 0, 2);
		world.setBlock(i + 12, j + 62, k + 5, NovaCraftBlocks.basal_bricks, 0, 2);
		world.setBlock(i + 13, j + 62, k + 5, NovaCraftBlocks.basal_bricks, 0, 2);
		world.setBlock(i + 14, j + 62, k + 5, NovaCraftBlocks.basal_bricks, 0, 2);
		world.setBlock(i + 15, j + 62, k + 5, NovaCraftBlocks.basal_bricks, 0, 2);
		world.setBlock(i + 16, j + 62, k + 5, NovaCraftBlocks.basal_bricks, 0, 2);
		world.setBlock(i + 17, j + 62, k + 5, NovaCraftBlocks.basal_bricks, 0, 2);
		world.setBlock(i + 18, j + 62, k + 5, NovaCraftBlocks.basal_bricks, 0, 2);
		world.setBlock(i + 19, j + 62, k + 5, NovaCraftBlocks.basal_bricks, 0, 2);
		world.setBlock(i + 20, j + 62, k + 5, NovaCraftBlocks.basal_bricks, 0, 2);
		world.setBlock(i + 21, j + 62, k + 5, NovaCraftBlocks.basal_bricks, 0, 2);
		world.setBlock(i + 22, j + 62, k + 5, NovaCraftBlocks.basal_bricks, 0, 2);
		world.setBlock(i + 23, j + 62, k + 5, NovaCraftBlocks.basal_bricks, 0, 2);
		world.setBlock(i + 24, j + 62, k + 5, NovaCraftBlocks.basal_bricks, 0, 2);
		world.setBlock(i + 25, j + 62, k + 5, NovaCraftBlocks.basal_bricks, 0, 2);
		world.setBlock(i + 26, j + 62, k + 5, NovaCraftBlocks.basal_bricks, 0, 2);
		world.setBlock(i + 27, j + 62, k + 5, NovaCraftBlocks.basal_bricks, 0, 2);
		world.setBlock(i, j + 62, k + 6, NovaCraftBlocks.basal_bricks, 0, 2);
		world.setBlock(i + 1, j + 62, k + 6, NovaCraftBlocks.basal_bricks, 0, 2);
		world.setBlock(i + 2, j + 62, k + 6, NovaCraftBlocks.basal_bricks, 0, 2);
		world.setBlock(i + 3, j + 62, k + 6, NovaCraftBlocks.basal_bricks, 0, 2);
		world.setBlock(i + 4, j + 62, k + 6, Blocks.air, 0, 2);
		world.setBlock(i + 5, j + 62, k + 6, Blocks.air, 0, 2);
		world.setBlock(i + 6, j + 62, k + 6, Blocks.air, 0, 2);
		world.setBlock(i + 7, j + 62, k + 6, Blocks.air, 0, 2);
		world.setBlock(i + 8, j + 62, k + 6, Blocks.air, 0, 2);
		world.setBlock(i + 9, j + 62, k + 6, Blocks.air, 0, 2);
		world.setBlock(i + 10, j + 62, k + 6, NovaCraftBlocks.basal_bricks, 0, 2);
		world.setBlock(i + 11, j + 62, k + 6, NovaCraftBlocks.basal_bricks, 0, 2);
		world.setBlock(i + 12, j + 62, k + 6, NovaCraftBlocks.basal_bricks, 0, 2);
		world.setBlock(i + 13, j + 62, k + 6, NovaCraftBlocks.basal_scrap, 0, 2);
		world.setBlock(i + 14, j + 62, k + 6, NovaCraftBlocks.basal_bricks, 0, 2);
		world.setBlock(i + 15, j + 62, k + 6, NovaCraftBlocks.basal_bricks, 0, 2);
		world.setBlock(i + 16, j + 62, k + 6, NovaCraftBlocks.basal_bricks, 0, 2);
		world.setBlock(i + 17, j + 62, k + 6, NovaCraftBlocks.basal_bricks, 0, 2);
		world.setBlock(i + 18, j + 62, k + 6, Blocks.air, 0, 2);
		world.setBlock(i + 19, j + 62, k + 6, Blocks.air, 0, 2);
		world.setBlock(i + 20, j + 62, k + 6, Blocks.air, 0, 2);
		world.setBlock(i + 21, j + 62, k + 6, Blocks.air, 0, 2);
		world.setBlock(i + 22, j + 62, k + 6, Blocks.air, 0, 2);
		world.setBlock(i + 23, j + 62, k + 6, Blocks.air, 0, 2);
		world.setBlock(i + 24, j + 62, k + 6, NovaCraftBlocks.basal_bricks, 0, 2);
		world.setBlock(i + 25, j + 62, k + 6, NovaCraftBlocks.basal_bricks, 0, 2);
		world.setBlock(i + 26, j + 62, k + 6, NovaCraftBlocks.basal_bricks, 0, 2);
		world.setBlock(i + 27, j + 62, k + 6, NovaCraftBlocks.basal_bricks, 0, 2);
		world.setBlock(i, j + 62, k + 7, Blocks.air, 0, 2);
		world.setBlock(i + 1, j + 62, k + 7, NovaCraftBlocks.basal_bricks, 0, 2);
		world.setBlock(i + 2, j + 62, k + 7, NovaCraftBlocks.basal_bricks, 0, 2);
		world.setBlock(i + 3, j + 62, k + 7, NovaCraftBlocks.basal_bricks, 0, 2);
		world.setBlock(i + 4, j + 62, k + 7, NovaCraftBlocks.basal_brick_stairs, 2, 2);
		world.setBlock(i + 5, j + 62, k + 7, NovaCraftBlocks.basal_brick_stairs, 2, 2);
		world.setBlock(i + 6, j + 62, k + 7, Blocks.air, 0, 2);
		world.setBlock(i + 7, j + 62, k + 7, Blocks.air, 0, 2);
		world.setBlock(i + 8, j + 62, k + 7, NovaCraftBlocks.basal_brick_stairs, 2, 2);
		world.setBlock(i + 9, j + 62, k + 7, NovaCraftBlocks.basal_brick_stairs, 2, 2);
		world.setBlock(i + 10, j + 62, k + 7, NovaCraftBlocks.basal_bricks, 0, 2);
		world.setBlock(i + 11, j + 62, k + 7, NovaCraftBlocks.basal_bricks, 0, 2);
		world.setBlock(i + 12, j + 62, k + 7, NovaCraftBlocks.basal_bricks, 0, 2);
		world.setBlock(i + 13, j + 62, k + 7, NovaCraftBlocks.basal_scrap, 0, 2);
		world.setBlock(i + 14, j + 62, k + 7, NovaCraftBlocks.basal_bricks, 0, 2);
		world.setBlock(i + 15, j + 62, k + 7, NovaCraftBlocks.basal_bricks, 0, 2);
		world.setBlock(i + 16, j + 62, k + 7, NovaCraftBlocks.basal_bricks, 0, 2);
		world.setBlock(i + 17, j + 62, k + 7, NovaCraftBlocks.basal_bricks, 0, 2);
		world.setBlock(i + 18, j + 62, k + 7, Blocks.air, 0, 2);
		world.setBlock(i + 19, j + 62, k + 7, Blocks.air, 0, 2);
		world.setBlock(i + 20, j + 62, k + 7, Blocks.air, 0, 2);
		world.setBlock(i + 21, j + 62, k + 7, Blocks.air, 0, 2);
		world.setBlock(i + 22, j + 62, k + 7, Blocks.air, 0, 2);
		world.setBlock(i + 23, j + 62, k + 7, Blocks.air, 0, 2);
		world.setBlock(i + 24, j + 62, k + 7, NovaCraftBlocks.basal_bricks, 0, 2);
		world.setBlock(i + 25, j + 62, k + 7, NovaCraftBlocks.basal_bricks, 0, 2);
		world.setBlock(i + 26, j + 62, k + 7, NovaCraftBlocks.basal_bricks, 0, 2);
		world.setBlock(i + 27, j + 62, k + 7, NovaCraftBlocks.basal, 0, 2);
		world.setBlock(i, j + 62, k + 8, NovaCraftBlocks.basal_bricks, 0, 2);
		world.setBlock(i + 1, j + 62, k + 8, NovaCraftBlocks.basal_bricks, 0, 2);
		world.setBlock(i + 2, j + 62, k + 8, NovaCraftBlocks.basal_bricks, 0, 2);
		world.setBlock(i + 3, j + 62, k + 8, NovaCraftBlocks.basal_bricks, 0, 2);
		world.setBlock(i + 4, j + 62, k + 8, NovaCraftBlocks.basal_bricks, 0, 2);
		world.setBlock(i + 5, j + 62, k + 8, NovaCraftBlocks.basal_bricks, 0, 2);
		world.setBlock(i + 6, j + 62, k + 8, NovaCraftBlocks.basal_bricks, 0, 2);
		world.setBlock(i + 7, j + 62, k + 8, NovaCraftBlocks.basal_bricks, 0, 2);
		world.setBlock(i + 8, j + 62, k + 8, NovaCraftBlocks.basal_bricks, 0, 2);
		world.setBlock(i + 9, j + 62, k + 8, NovaCraftBlocks.basal_bricks, 0, 2);
		world.setBlock(i + 10, j + 62, k + 8, Blocks.air, 0, 2);
		world.setBlock(i + 11, j + 62, k + 8, NovaCraftBlocks.basal_bricks, 0, 2);
		world.setBlock(i + 12, j + 62, k + 8, Blocks.air, 0, 2);
		world.setBlock(i + 13, j + 62, k + 8, NovaCraftBlocks.basal_scrap, 0, 2);
		world.setBlock(i + 14, j + 62, k + 8, NovaCraftBlocks.basal_bricks, 0, 2);
		world.setBlock(i + 15, j + 62, k + 8, NovaCraftBlocks.basal_bricks, 0, 2);
		world.setBlock(i + 16, j + 62, k + 8, NovaCraftBlocks.basal_bricks, 0, 2);
		world.setBlock(i + 17, j + 62, k + 8, NovaCraftBlocks.basal_bricks, 0, 2);
		world.setBlock(i + 18, j + 62, k + 8, NovaCraftBlocks.basal_brick_stairs, 2, 2);
		world.setBlock(i + 19, j + 62, k + 8, NovaCraftBlocks.basal_brick_stairs, 2, 2);
		world.setBlock(i + 20, j + 62, k + 8, Blocks.air, 0, 2);
		world.setBlock(i + 21, j + 62, k + 8, Blocks.air, 0, 2);
		world.setBlock(i + 22, j + 62, k + 8, Blocks.air, 0, 2);
		world.setBlock(i + 23, j + 62, k + 8, NovaCraftBlocks.basal_brick_stairs, 2, 2);
		world.setBlock(i + 24, j + 62, k + 8, NovaCraftBlocks.basal_bricks, 0, 2);
		world.setBlock(i + 25, j + 62, k + 8, NovaCraftBlocks.basal_bricks, 0, 2);
		world.setBlock(i + 26, j + 62, k + 8, NovaCraftBlocks.basal_bricks, 0, 2);
		world.setBlock(i + 27, j + 62, k + 8, Blocks.air, 0, 2);
		world.setBlock(i, j + 62, k + 9, NovaCraftBlocks.basal_bricks, 0, 2);
		world.setBlock(i + 1, j + 62, k + 9, NovaCraftBlocks.basal_bricks, 0, 2);
		world.setBlock(i + 2, j + 62, k + 9, NovaCraftBlocks.basal_bricks, 0, 2);
		world.setBlock(i + 3, j + 62, k + 9, NovaCraftBlocks.basal_bricks, 0, 2);
		world.setBlock(i + 4, j + 62, k + 9, NovaCraftBlocks.basal_bricks, 0, 2);
		world.setBlock(i + 5, j + 62, k + 9, Blocks.air, 0, 2);
		world.setBlock(i + 6, j + 62, k + 9, NovaCraftBlocks.basal_bricks, 0, 2);
		world.setBlock(i + 7, j + 62, k + 9, NovaCraftBlocks.basal_bricks, 0, 2);
		world.setBlock(i + 8, j + 62, k + 9, NovaCraftBlocks.basal_bricks, 0, 2);
		world.setBlock(i + 9, j + 62, k + 9, NovaCraftBlocks.basal_bricks, 0, 2);
		world.setBlock(i + 10, j + 62, k + 9, NovaCraftBlocks.basal_bricks, 0, 2);
		world.setBlock(i + 11, j + 62, k + 9, NovaCraftBlocks.basal_bricks, 0, 2);
		world.setBlock(i + 12, j + 62, k + 9, NovaCraftBlocks.basal_bricks, 0, 2);
		world.setBlock(i + 13, j + 62, k + 9, NovaCraftBlocks.basal_bricks, 0, 2);
		world.setBlock(i + 14, j + 62, k + 9, NovaCraftBlocks.basal_bricks, 0, 2);
		world.setBlock(i + 15, j + 62, k + 9, NovaCraftBlocks.basal_bricks, 0, 2);
		world.setBlock(i + 16, j + 62, k + 9, NovaCraftBlocks.basal_bricks, 0, 2);
		world.setBlock(i + 17, j + 62, k + 9, NovaCraftBlocks.basal_bricks, 0, 2);
		world.setBlock(i + 18, j + 62, k + 9, NovaCraftBlocks.basal_bricks, 0, 2);
		world.setBlock(i + 19, j + 62, k + 9, NovaCraftBlocks.basal_bricks, 0, 2);
		world.setBlock(i + 20, j + 62, k + 9, Blocks.air, 0, 2);
		world.setBlock(i + 21, j + 62, k + 9, Blocks.air, 0, 2);
		world.setBlock(i + 22, j + 62, k + 9, NovaCraftBlocks.basal_bricks, 0, 2);
		world.setBlock(i + 23, j + 62, k + 9, NovaCraftBlocks.basal_bricks, 0, 2);
		world.setBlock(i + 24, j + 62, k + 9, NovaCraftBlocks.basal_bricks, 0, 2);
		world.setBlock(i + 25, j + 62, k + 9, NovaCraftBlocks.basal_bricks, 0, 2);
		world.setBlock(i + 26, j + 62, k + 9, NovaCraftBlocks.basal_bricks, 0, 2);
		world.setBlock(i + 27, j + 62, k + 9, NovaCraftBlocks.basal_scrap, 0, 2);
		world.setBlock(i, j + 62, k + 10, NovaCraftBlocks.basal_bricks, 0, 2);
		world.setBlock(i + 1, j + 62, k + 10, NovaCraftBlocks.basal_bricks, 0, 2);
		world.setBlock(i + 2, j + 62, k + 10, NovaCraftBlocks.basal_bricks, 0, 2);
		world.setBlock(i + 3, j + 62, k + 10, NovaCraftBlocks.basal_bricks, 0, 2);
		world.setBlock(i + 4, j + 62, k + 10, NovaCraftBlocks.basal_bricks, 0, 2);
		world.setBlock(i + 5, j + 62, k + 10, NovaCraftBlocks.basal_bricks, 0, 2);
		world.setBlock(i + 6, j + 62, k + 10, NovaCraftBlocks.basal_bricks, 0, 2);
		world.setBlock(i + 7, j + 62, k + 10, NovaCraftBlocks.basal_bricks, 0, 2);
		world.setBlock(i + 8, j + 62, k + 10, NovaCraftBlocks.basal_bricks, 0, 2);
		world.setBlock(i + 9, j + 62, k + 10, NovaCraftBlocks.basal_bricks, 0, 2);
		world.setBlock(i + 10, j + 62, k + 10, NovaCraftBlocks.basal_bricks, 0, 2);
		world.setBlock(i + 11, j + 62, k + 10, Blocks.air, 0, 2);
		world.setBlock(i + 12, j + 62, k + 10, NovaCraftBlocks.basal_bricks, 0, 2);
		world.setBlock(i + 13, j + 62, k + 10, NovaCraftBlocks.basal_bricks, 0, 2);
		world.setBlock(i + 14, j + 62, k + 10, NovaCraftBlocks.basal_bricks, 0, 2);
		world.setBlock(i + 15, j + 62, k + 10, NovaCraftBlocks.basal_bricks, 0, 2);
		world.setBlock(i + 16, j + 62, k + 10, NovaCraftBlocks.basal_bricks, 0, 2);
		world.setBlock(i + 17, j + 62, k + 10, NovaCraftBlocks.basal_bricks, 0, 2);
		world.setBlock(i + 18, j + 62, k + 10, NovaCraftBlocks.basal_bricks, 0, 2);
		world.setBlock(i + 19, j + 62, k + 10, NovaCraftBlocks.basal_bricks, 0, 2);
		world.setBlock(i + 20, j + 62, k + 10, Blocks.air, 0, 2);
		world.setBlock(i + 21, j + 62, k + 10, Blocks.air, 0, 2);
		world.setBlock(i + 22, j + 62, k + 10, NovaCraftBlocks.basal_bricks, 0, 2);
		world.setBlock(i + 23, j + 62, k + 10, NovaCraftBlocks.basal_bricks, 0, 2);
		world.setBlock(i + 24, j + 62, k + 10, NovaCraftBlocks.basal_bricks, 0, 2);
		world.setBlock(i + 25, j + 62, k + 10, NovaCraftBlocks.basal_bricks, 0, 2);
		world.setBlock(i + 26, j + 62, k + 10, NovaCraftBlocks.basal_bricks, 0, 2);
		world.setBlock(i + 27, j + 62, k + 10, NovaCraftBlocks.basal_scrap, 0, 2);
		world.setBlock(i, j + 62, k + 11, Blocks.air, 0, 2);
		world.setBlock(i + 1, j + 62, k + 11, Blocks.air, 0, 2);
		world.setBlock(i + 2, j + 62, k + 11, Blocks.air, 0, 2);
		world.setBlock(i + 3, j + 62, k + 11, Blocks.air, 0, 2);
		world.setBlock(i + 4, j + 62, k + 11, Blocks.air, 0, 2);
		world.setBlock(i + 5, j + 62, k + 11, Blocks.air, 0, 2);
		world.setBlock(i + 6, j + 62, k + 11, Blocks.air, 0, 2);
		world.setBlock(i + 7, j + 62, k + 11, Blocks.air, 0, 2);
		world.setBlock(i + 8, j + 62, k + 11, Blocks.air, 0, 2);
		world.setBlock(i + 9, j + 62, k + 11, Blocks.air, 0, 2);
		world.setBlock(i + 10, j + 62, k + 11, Blocks.air, 0, 2);
		world.setBlock(i + 11, j + 62, k + 11, Blocks.air, 0, 2);
		world.setBlock(i + 12, j + 62, k + 11, Blocks.air, 0, 2);
		world.setBlock(i + 13, j + 62, k + 11, Blocks.air, 0, 2);
		world.setBlock(i + 14, j + 62, k + 11, NovaCraftBlocks.basal_bricks, 0, 2);
		world.setBlock(i + 15, j + 62, k + 11, NovaCraftBlocks.basal_bricks, 0, 2);
		world.setBlock(i + 16, j + 62, k + 11, NovaCraftBlocks.basal_bricks, 0, 2);
		world.setBlock(i + 17, j + 62, k + 11, NovaCraftBlocks.basal_bricks, 0, 2);
		world.setBlock(i + 18, j + 62, k + 11, NovaCraftBlocks.basal_bricks, 0, 2);
		world.setBlock(i + 19, j + 62, k + 11, NovaCraftBlocks.basal_bricks, 0, 2);
		world.setBlock(i + 20, j + 62, k + 11, Blocks.air, 0, 2);
		world.setBlock(i + 21, j + 62, k + 11, Blocks.air, 0, 2);
		world.setBlock(i + 22, j + 62, k + 11, NovaCraftBlocks.basal_bricks, 0, 2);
		world.setBlock(i + 23, j + 62, k + 11, NovaCraftBlocks.basal_bricks, 0, 2);
		world.setBlock(i + 24, j + 62, k + 11, NovaCraftBlocks.basal_bricks, 0, 2);
		world.setBlock(i + 25, j + 62, k + 11, NovaCraftBlocks.basal_bricks, 0, 2);
		world.setBlock(i + 26, j + 62, k + 11, NovaCraftBlocks.basal_bricks, 0, 2);
		world.setBlock(i + 27, j + 62, k + 11, NovaCraftBlocks.basal_bricks, 0, 2);
		world.setBlock(i, j + 62, k + 12, Blocks.air, 0, 2);
		world.setBlock(i + 1, j + 62, k + 12, Blocks.air, 0, 2);
		world.setBlock(i + 2, j + 62, k + 12, Blocks.air, 0, 2);
		world.setBlock(i + 3, j + 62, k + 12, Blocks.air, 0, 2);
		world.setBlock(i + 4, j + 62, k + 12, Blocks.air, 0, 2);
		world.setBlock(i + 5, j + 62, k + 12, Blocks.air, 0, 2);
		world.setBlock(i + 6, j + 62, k + 12, Blocks.air, 0, 2);
		world.setBlock(i + 7, j + 62, k + 12, Blocks.air, 0, 2);
		world.setBlock(i + 8, j + 62, k + 12, Blocks.air, 0, 2);
		world.setBlock(i + 9, j + 62, k + 12, Blocks.air, 0, 2);
		world.setBlock(i + 10, j + 62, k + 12, Blocks.air, 0, 2);
		world.setBlock(i + 11, j + 62, k + 12, Blocks.air, 0, 2);
		world.setBlock(i + 12, j + 62, k + 12, Blocks.air, 0, 2);
		world.setBlock(i + 13, j + 62, k + 12, Blocks.air, 0, 2);
		world.setBlock(i + 14, j + 62, k + 12, NovaCraftBlocks.basal_bricks, 0, 2);
		world.setBlock(i + 15, j + 62, k + 12, NovaCraftBlocks.basal_bricks, 0, 2);
		world.setBlock(i + 16, j + 62, k + 12, NovaCraftBlocks.basal_bricks, 0, 2);
		world.setBlock(i + 17, j + 62, k + 12, NovaCraftBlocks.basal_bricks, 0, 2);
		world.setBlock(i + 18, j + 62, k + 12, NovaCraftBlocks.basal_bricks, 0, 2);
		world.setBlock(i + 19, j + 62, k + 12, Blocks.air, 0, 2);
		world.setBlock(i + 20, j + 62, k + 12, Blocks.air, 0, 2);
		world.setBlock(i + 21, j + 62, k + 12, Blocks.air, 0, 2);
		world.setBlock(i + 22, j + 62, k + 12, NovaCraftBlocks.basal_bricks, 0, 2);
		world.setBlock(i + 23, j + 62, k + 12, NovaCraftBlocks.basal_bricks, 0, 2);
		world.setBlock(i + 24, j + 62, k + 12, NovaCraftBlocks.basal_bricks, 0, 2);
		world.setBlock(i + 25, j + 62, k + 12, NovaCraftBlocks.basal_bricks, 0, 2);
		world.setBlock(i + 26, j + 62, k + 12, NovaCraftBlocks.basal_bricks, 0, 2);
		world.setBlock(i + 27, j + 62, k + 12, NovaCraftBlocks.basal_bricks, 0, 2);
		world.setBlock(i, j + 63, k, NovaCraftBlocks.basal_scrap, 0, 2);
		world.setBlock(i + 1, j + 63, k, NovaCraftBlocks.basal_scrap, 0, 2);
		world.setBlock(i + 4, j + 63, k, NovaCraftBlocks.basal_bricks, 0, 2);
		world.setBlock(i + 5, j + 63, k, NovaCraftBlocks.basal_bricks, 0, 2);
		world.setBlock(i + 8, j + 63, k, NovaCraftBlocks.basal_bricks, 0, 2);
		world.setBlock(i + 1, j + 63, k + 1, NovaCraftBlocks.basal_bricks, 0, 2);
		world.setBlock(i + 4, j + 63, k + 1, NovaCraftBlocks.basal_bricks, 0, 2);
		world.setBlock(i + 5, j + 63, k + 1, NovaCraftBlocks.basal_bricks, 0, 2);
		world.setBlock(i + 8, j + 63, k + 1, NovaCraftBlocks.basal_bricks, 0, 2);
		world.setBlock(i + 9, j + 63, k + 1, NovaCraftBlocks.basal_bricks, 0, 2);
		world.setBlock(i, j + 63, k + 2, NovaCraftBlocks.basal_bricks, 0, 2);
		world.setBlock(i + 1, j + 63, k + 2, NovaCraftBlocks.basal_bricks, 0, 2);
		world.setBlock(i + 4, j + 63, k + 2, NovaCraftBlocks.basal_bricks, 0, 2);
		world.setBlock(i + 5, j + 63, k + 2, NovaCraftBlocks.basal_bricks, 0, 2);
		world.setBlock(i + 8, j + 63, k + 2, NovaCraftBlocks.basal_bricks, 0, 2);
		world.setBlock(i + 9, j + 63, k + 2, NovaCraftBlocks.basal_bricks, 0, 2);
		world.setBlock(i + 13, j + 63, k + 2, NovaCraftBlocks.basal_bricks, 0, 2);
		world.setBlock(i + 14, j + 63, k + 2, NovaCraftBlocks.basal_bricks, 0, 2);
		world.setBlock(i + 15, j + 63, k + 2, NovaCraftBlocks.basal_bricks, 0, 2);
		world.setBlock(i + 19, j + 63, k + 2, NovaCraftBlocks.basal_bricks, 0, 2);
		world.setBlock(i, j + 63, k + 3, NovaCraftBlocks.basal_bricks, 0, 2);
		world.setBlock(i + 1, j + 63, k + 3, NovaCraftBlocks.basal_bricks, 0, 2);
		world.setBlock(i + 3, j + 63, k + 3, NovaCraftBlocks.block_of_vanite, 0, 2);
		world.setBlock(i + 4, j + 63, k + 3, NovaCraftBlocks.basal_bricks, 0, 2);
		world.setBlock(i + 5, j + 63, k + 3, NovaCraftBlocks.basal_bricks, 0, 2);
		world.setBlock(i + 6, j + 63, k + 3, NovaCraftBlocks.block_of_vanite, 0, 2);
		world.setBlock(i + 7, j + 63, k + 3, NovaCraftBlocks.cracked_basal_bricks, 0, 2);
		world.setBlock(i + 8, j + 63, k + 3, NovaCraftBlocks.basal_bricks, 0, 2);
		world.setBlock(i + 9, j + 63, k + 3, NovaCraftBlocks.basal_bricks, 0, 2);
		world.setBlock(i + 12, j + 63, k + 3, NovaCraftBlocks.basal_bricks, 0, 2);
		world.setBlock(i + 13, j + 63, k + 3, NovaCraftBlocks.basal_bricks, 0, 2);
		world.setBlock(i + 14, j + 63, k + 3, NovaCraftBlocks.basal_bricks, 0, 2);
		world.setBlock(i + 15, j + 63, k + 3, NovaCraftBlocks.basal_bricks, 0, 2);
		world.setBlock(i + 18, j + 63, k + 3, NovaCraftBlocks.basal_bricks, 0, 2);
		world.setBlock(i + 19, j + 63, k + 3, NovaCraftBlocks.basal_bricks, 0, 2);
		world.setBlock(i + 23, j + 63, k + 3, NovaCraftBlocks.basal_bricks, 0, 2);
		world.setBlock(i, j + 63, k + 4, NovaCraftBlocks.basal_bricks, 0, 2);
		world.setBlock(i + 1, j + 63, k + 4, NovaCraftBlocks.basal_bricks, 0, 2);
		world.setBlock(i + 2, j + 63, k + 4, NovaCraftBlocks.basal_bricks, 0, 2);
		world.setBlock(i + 3, j + 63, k + 4, NovaCraftBlocks.basal_bricks, 0, 2);
		world.setBlock(i + 4, j + 63, k + 4, NovaCraftBlocks.basal_bricks, 0, 2);
		world.setBlock(i + 5, j + 63, k + 4, NovaCraftBlocks.basal_bricks, 0, 2);
		world.setBlock(i + 6, j + 63, k + 4, NovaCraftBlocks.basal_bricks, 0, 2);
		world.setBlock(i + 7, j + 63, k + 4, NovaCraftBlocks.basal_bricks, 0, 2);
		world.setBlock(i + 8, j + 63, k + 4, NovaCraftBlocks.basal_bricks, 0, 2);
		world.setBlock(i + 9, j + 63, k + 4, NovaCraftBlocks.basal_bricks, 0, 2);
		world.setBlock(i + 10, j + 63, k + 4, NovaCraftBlocks.basal_bricks, 0, 2);
		world.setBlock(i + 11, j + 63, k + 4, NovaCraftBlocks.basal_bricks, 0, 2);
		world.setBlock(i + 12, j + 63, k + 4, NovaCraftBlocks.basal_bricks, 0, 2);
		world.setBlock(i + 13, j + 63, k + 4, NovaCraftBlocks.basal_bricks, 0, 2);
		world.setBlock(i + 14, j + 63, k + 4, NovaCraftBlocks.basal_bricks, 0, 2);
		world.setBlock(i + 15, j + 63, k + 4, NovaCraftBlocks.basal_bricks, 0, 2);
		world.setBlock(i + 16, j + 63, k + 4, NovaCraftBlocks.basal_bricks, 0, 2);
		world.setBlock(i + 17, j + 63, k + 4, NovaCraftBlocks.basal_bricks, 0, 2);
		world.setBlock(i + 18, j + 63, k + 4, Blocks.air, 0, 2);
		world.setBlock(i + 19, j + 63, k + 4, NovaCraftBlocks.basal_bricks, 0, 2);
		world.setBlock(i + 20, j + 63, k + 4, NovaCraftBlocks.basal_bricks, 0, 2);
		world.setBlock(i + 21, j + 63, k + 4, NovaCraftBlocks.basal_bricks, 0, 2);
		world.setBlock(i + 22, j + 63, k + 4, NovaCraftBlocks.basal_bricks, 0, 2);
		world.setBlock(i + 23, j + 63, k + 4, NovaCraftBlocks.basal_bricks, 0, 2);
		world.setBlock(i + 24, j + 63, k + 4, Blocks.air, 0, 2);
		world.setBlock(i + 25, j + 63, k + 4, Blocks.air, 0, 2);
		world.setBlock(i + 26, j + 63, k + 4, Blocks.air, 0, 2);
		world.setBlock(i + 27, j + 63, k + 4, NovaCraftBlocks.basal_bricks, 0, 2);
		world.setBlock(i, j + 63, k + 5, NovaCraftBlocks.basal_bricks, 0, 2);
		world.setBlock(i + 1, j + 63, k + 5, NovaCraftBlocks.basal_bricks, 0, 2);
		world.setBlock(i + 2, j + 63, k + 5, NovaCraftBlocks.basal_bricks, 0, 2);
		world.setBlock(i + 3, j + 63, k + 5, NovaCraftBlocks.basal_bricks, 0, 2);
		world.setBlock(i + 4, j + 63, k + 5, Blocks.air, 0, 2);
		world.setBlock(i + 5, j + 63, k + 5, Blocks.air, 0, 2);
		world.setBlock(i + 6, j + 63, k + 5, NovaCraftBlocks.basal_bricks, 0, 2);
		world.setBlock(i + 7, j + 63, k + 5, NovaCraftBlocks.basal_bricks, 0, 2);
		world.setBlock(i + 8, j + 63, k + 5, Blocks.air, 0, 2);
		world.setBlock(i + 9, j + 63, k + 5, Blocks.air, 0, 2);
		world.setBlock(i + 10, j + 63, k + 5, NovaCraftBlocks.basal_bricks, 0, 2);
		world.setBlock(i + 11, j + 63, k + 5, NovaCraftBlocks.basal_bricks, 0, 2);
		world.setBlock(i + 12, j + 63, k + 5, NovaCraftBlocks.basal_bricks, 0, 2);
		world.setBlock(i + 13, j + 63, k + 5, NovaCraftBlocks.basal_scrap, 0, 2);
		world.setBlock(i + 14, j + 63, k + 5, NovaCraftBlocks.basal_bricks, 0, 2);
		world.setBlock(i + 15, j + 63, k + 5, NovaCraftBlocks.basal_bricks, 0, 2);
		world.setBlock(i + 16, j + 63, k + 5, NovaCraftBlocks.basal_bricks, 0, 2);
		world.setBlock(i + 17, j + 63, k + 5, NovaCraftBlocks.basal_bricks, 0, 2);
		world.setBlock(i + 18, j + 63, k + 5, NovaCraftBlocks.basal_bricks, 0, 2);
		world.setBlock(i + 19, j + 63, k + 5, NovaCraftBlocks.basal_bricks, 0, 2);
		world.setBlock(i + 20, j + 63, k + 5, NovaCraftBlocks.basal_bricks, 0, 2);
		world.setBlock(i + 21, j + 63, k + 5, NovaCraftBlocks.basal_bricks, 0, 2);
		world.setBlock(i + 22, j + 63, k + 5, NovaCraftBlocks.basal_bricks, 0, 2);
		world.setBlock(i + 23, j + 63, k + 5, NovaCraftBlocks.basal_bricks, 0, 2);
		world.setBlock(i + 24, j + 63, k + 5, Blocks.air, 0, 2);
		world.setBlock(i + 25, j + 63, k + 5, NovaCraftBlocks.basal_bricks, 0, 2);
		world.setBlock(i + 26, j + 63, k + 5, Blocks.air, 0, 2);
		world.setBlock(i + 27, j + 63, k + 5, NovaCraftBlocks.basal_bricks, 0, 2);
		world.setBlock(i, j + 63, k + 6, NovaCraftBlocks.basal_bricks, 0, 2);
		world.setBlock(i + 1, j + 63, k + 6, NovaCraftBlocks.basal_bricks, 0, 2);
		world.setBlock(i + 2, j + 63, k + 6, NovaCraftBlocks.basal_bricks, 0, 2);
		world.setBlock(i + 3, j + 63, k + 6, NovaCraftBlocks.basal_bricks, 0, 2);
		world.setBlock(i + 4, j + 63, k + 6, Blocks.air, 0, 2);
		world.setBlock(i + 5, j + 63, k + 6, Blocks.air, 0, 2);
		world.setBlock(i + 6, j + 63, k + 6, NovaCraftBlocks.basal_bricks, 0, 2);
		world.setBlock(i + 7, j + 63, k + 6, NovaCraftBlocks.basal_bricks, 0, 2);
		world.setBlock(i + 8, j + 63, k + 6, Blocks.air, 0, 2);
		world.setBlock(i + 9, j + 63, k + 6, Blocks.air, 0, 2);
		world.setBlock(i + 10, j + 63, k + 6, NovaCraftBlocks.basal_bricks, 0, 2);
		world.setBlock(i + 11, j + 63, k + 6, NovaCraftBlocks.basal, 0, 2);
		world.setBlock(i + 12, j + 63, k + 6, NovaCraftBlocks.basal, 0, 2);
		world.setBlock(i + 13, j + 63, k + 6, Blocks.air, 0, 2);
		world.setBlock(i + 14, j + 63, k + 6, NovaCraftBlocks.basal_bricks, 0, 2);
		world.setBlock(i + 15, j + 63, k + 6, NovaCraftBlocks.basal_bricks, 0, 2);
		world.setBlock(i + 16, j + 63, k + 6, NovaCraftBlocks.basal_bricks, 0, 2);
		world.setBlock(i + 17, j + 63, k + 6, NovaCraftBlocks.basal_bricks, 0, 2);
		world.setBlock(i + 18, j + 63, k + 6, Blocks.air, 0, 2);
		world.setBlock(i + 19, j + 63, k + 6, Blocks.air, 0, 2);
		world.setBlock(i + 20, j + 63, k + 6, Blocks.air, 0, 2);
		world.setBlock(i + 21, j + 63, k + 6, Blocks.air, 0, 2);
		world.setBlock(i + 22, j + 63, k + 6, Blocks.air, 0, 2);
		world.setBlock(i + 23, j + 63, k + 6, Blocks.air, 0, 2);
		world.setBlock(i + 24, j + 63, k + 6, NovaCraftBlocks.basal_bricks, 0, 2);
		world.setBlock(i + 25, j + 63, k + 6, NovaCraftBlocks.basal_bricks, 0, 2);
		world.setBlock(i + 26, j + 63, k + 6, NovaCraftBlocks.basal_bricks, 0, 2);
		world.setBlock(i + 27, j + 63, k + 6, NovaCraftBlocks.basal_bricks, 0, 2);
		world.setBlock(i, j + 63, k + 7, NovaCraftBlocks.basal_bricks, 0, 2);
		world.setBlock(i + 1, j + 63, k + 7, NovaCraftBlocks.basal_bricks, 0, 2);
		world.setBlock(i + 2, j + 63, k + 7, NovaCraftBlocks.basal_bricks, 0, 2);
		world.setBlock(i + 3, j + 63, k + 7, NovaCraftBlocks.basal_bricks, 0, 2);
		world.setBlock(i + 4, j + 63, k + 7, Blocks.air, 0, 2);
		world.setBlock(i + 5, j + 63, k + 7, Blocks.air, 0, 2);
		world.setBlock(i + 6, j + 63, k + 7, NovaCraftBlocks.basal_bricks, 0, 2);
		world.setBlock(i + 7, j + 63, k + 7, NovaCraftBlocks.basal_bricks, 0, 2);
		world.setBlock(i + 8, j + 63, k + 7, Blocks.air, 0, 2);
		world.setBlock(i + 9, j + 63, k + 7, Blocks.air, 0, 2);
		world.setBlock(i + 10, j + 63, k + 7, NovaCraftBlocks.basal_bricks, 0, 2);
		world.setBlock(i + 11, j + 63, k + 7, NovaCraftBlocks.basal_scrap, 0, 2);
		world.setBlock(i + 12, j + 63, k + 7, NovaCraftBlocks.basal_scrap, 0, 2);
		world.setBlock(i + 13, j + 63, k + 7, Blocks.air, 0, 2);
		world.setBlock(i + 14, j + 63, k + 7, NovaCraftBlocks.basal_bricks, 0, 2);
		world.setBlock(i + 15, j + 63, k + 7, NovaCraftBlocks.basal_bricks, 0, 2);
		world.setBlock(i + 16, j + 63, k + 7, NovaCraftBlocks.basal_bricks, 0, 2);
		world.setBlock(i + 17, j + 63, k + 7, NovaCraftBlocks.basal_bricks, 0, 2);
		world.setBlock(i + 18, j + 63, k + 7, Blocks.air, 0, 2);
		world.setBlock(i + 19, j + 63, k + 7, Blocks.air, 0, 2);
		world.setBlock(i + 20, j + 63, k + 7, Blocks.air, 0, 2);
		world.setBlock(i + 21, j + 63, k + 7, Blocks.air, 0, 2);
		world.setBlock(i + 22, j + 63, k + 7, Blocks.air, 0, 2);
		world.setBlock(i + 23, j + 63, k + 7, Blocks.air, 0, 2);
		world.setBlock(i + 24, j + 63, k + 7, NovaCraftBlocks.basal_bricks, 0, 2);
		world.setBlock(i + 25, j + 63, k + 7, NovaCraftBlocks.basal_bricks, 0, 2);
		world.setBlock(i + 26, j + 63, k + 7, NovaCraftBlocks.basal_bricks, 0, 2);
		world.setBlock(i + 27, j + 63, k + 7, Blocks.air, 0, 2);
		world.setBlock(i, j + 63, k + 8, NovaCraftBlocks.basal_bricks, 0, 2);
		world.setBlock(i + 1, j + 63, k + 8, NovaCraftBlocks.basal_bricks, 0, 2);
		world.setBlock(i + 2, j + 63, k + 8, NovaCraftBlocks.basal_bricks, 0, 2);
		world.setBlock(i + 3, j + 63, k + 8, NovaCraftBlocks.basal_bricks, 0, 2);
		world.setBlock(i + 4, j + 63, k + 8, NovaCraftBlocks.basal_brick_stairs, 2, 2);
		world.setBlock(i + 5, j + 63, k + 8, NovaCraftBlocks.basal_brick_stairs, 2, 2);
		world.setBlock(i + 6, j + 63, k + 8, NovaCraftBlocks.basal_bricks, 0, 2);
		world.setBlock(i + 7, j + 63, k + 8, NovaCraftBlocks.basal_bricks, 0, 2);
		world.setBlock(i + 8, j + 63, k + 8, NovaCraftBlocks.basal, 0, 2);
		world.setBlock(i + 9, j + 63, k + 8, NovaCraftBlocks.basal, 0, 2);
		world.setBlock(i + 10, j + 63, k + 8, NovaCraftBlocks.basal, 0, 2);
		world.setBlock(i + 11, j + 63, k + 8, NovaCraftBlocks.basal_bricks, 0, 2);
		world.setBlock(i + 12, j + 63, k + 8, NovaCraftBlocks.basal_scrap, 0, 2);
		world.setBlock(i + 13, j + 63, k + 8, Blocks.air, 0, 2);
		world.setBlock(i + 14, j + 63, k + 8, NovaCraftBlocks.basal_bricks, 0, 2);
		world.setBlock(i + 15, j + 63, k + 8, NovaCraftBlocks.basal_bricks, 0, 2);
		world.setBlock(i + 16, j + 63, k + 8, NovaCraftBlocks.basal_bricks, 0, 2);
		world.setBlock(i + 17, j + 63, k + 8, NovaCraftBlocks.basal_bricks, 0, 2);
		world.setBlock(i + 18, j + 63, k + 8, Blocks.air, 0, 2);
		world.setBlock(i + 19, j + 63, k + 8, Blocks.air, 0, 2);
		world.setBlock(i + 20, j + 63, k + 8, Blocks.air, 0, 2);
		world.setBlock(i + 21, j + 63, k + 8, Blocks.air, 0, 2);
		world.setBlock(i + 22, j + 63, k + 8, Blocks.air, 0, 2);
		world.setBlock(i + 23, j + 63, k + 8, Blocks.air, 0, 2);
		world.setBlock(i + 24, j + 63, k + 8, NovaCraftBlocks.basal_bricks, 0, 2);
		world.setBlock(i + 25, j + 63, k + 8, NovaCraftBlocks.basal_bricks, 0, 2);
		world.setBlock(i + 26, j + 63, k + 8, NovaCraftBlocks.basal_bricks, 0, 2);
		world.setBlock(i + 27, j + 63, k + 8, NovaCraftBlocks.basal_scrap, 0, 2);
		world.setBlock(i, j + 63, k + 9, NovaCraftBlocks.basal_bricks, 0, 2);
		world.setBlock(i + 1, j + 63, k + 9, NovaCraftBlocks.basal_bricks, 0, 2);
		world.setBlock(i + 2, j + 63, k + 9, NovaCraftBlocks.basal_bricks, 0, 2);
		world.setBlock(i + 3, j + 63, k + 9, Blocks.air, 0, 2);
		world.setBlock(i + 4, j + 63, k + 9, NovaCraftBlocks.basal_bricks, 0, 2);
		world.setBlock(i + 5, j + 63, k + 9, NovaCraftBlocks.basal_bricks, 0, 2);
		world.setBlock(i + 6, j + 63, k + 9, NovaCraftBlocks.basal_bricks, 0, 2);
		world.setBlock(i + 7, j + 63, k + 9, NovaCraftBlocks.basal_bricks, 0, 2);
		world.setBlock(i + 8, j + 63, k + 9, NovaCraftBlocks.basal_bricks, 0, 2);
		world.setBlock(i + 9, j + 63, k + 9, NovaCraftBlocks.basal_bricks, 0, 2);
		world.setBlock(i + 10, j + 63, k + 9, NovaCraftBlocks.basal_bricks, 0, 2);
		world.setBlock(i + 11, j + 63, k + 9, NovaCraftBlocks.basal_bricks, 0, 2);
		world.setBlock(i + 12, j + 63, k + 9, NovaCraftBlocks.basal_bricks, 0, 2);
		world.setBlock(i + 13, j + 63, k + 9, NovaCraftBlocks.basal_bricks, 0, 2);
		world.setBlock(i + 14, j + 63, k + 9, NovaCraftBlocks.basal_bricks, 0, 2);
		world.setBlock(i + 15, j + 63, k + 9, NovaCraftBlocks.basal_bricks, 0, 2);
		world.setBlock(i + 16, j + 63, k + 9, NovaCraftBlocks.basal_bricks, 0, 2);
		world.setBlock(i + 17, j + 63, k + 9, NovaCraftBlocks.basal_bricks, 0, 2);
		world.setBlock(i + 18, j + 63, k + 9, NovaCraftBlocks.basal_brick_stairs, 2, 2);
		world.setBlock(i + 19, j + 63, k + 9, NovaCraftBlocks.basal_brick_stairs, 2, 2);
		world.setBlock(i + 20, j + 63, k + 9, Blocks.air, 0, 2);
		world.setBlock(i + 21, j + 63, k + 9, Blocks.air, 0, 2);
		world.setBlock(i + 22, j + 63, k + 9, NovaCraftBlocks.basal_brick_stairs, 2, 2);
		world.setBlock(i + 23, j + 63, k + 9, NovaCraftBlocks.basal_brick_stairs, 2, 2);
		world.setBlock(i + 24, j + 63, k + 9, NovaCraftBlocks.basal_bricks, 0, 2);
		world.setBlock(i + 25, j + 63, k + 9, NovaCraftBlocks.basal_bricks, 0, 2);
		world.setBlock(i + 26, j + 63, k + 9, NovaCraftBlocks.basal_bricks, 0, 2);
		world.setBlock(i + 27, j + 63, k + 9, NovaCraftBlocks.basal_scrap, 0, 2);
		world.setBlock(i, j + 63, k + 10, NovaCraftBlocks.basal_bricks, 0, 2);
		world.setBlock(i + 1, j + 63, k + 10, NovaCraftBlocks.basal_bricks, 0, 2);
		world.setBlock(i + 2, j + 63, k + 10, NovaCraftBlocks.basal_bricks, 0, 2);
		world.setBlock(i + 3, j + 63, k + 10, NovaCraftBlocks.basal_bricks, 0, 2);
		world.setBlock(i + 4, j + 63, k + 10, NovaCraftBlocks.basal_bricks, 0, 2);
		world.setBlock(i + 5, j + 63, k + 10, NovaCraftBlocks.basal_bricks, 0, 2);
		world.setBlock(i + 6, j + 63, k + 10, NovaCraftBlocks.basal_bricks, 0, 2);
		world.setBlock(i + 7, j + 63, k + 10, NovaCraftBlocks.basal_bricks, 0, 2);
		world.setBlock(i + 8, j + 63, k + 10, NovaCraftBlocks.basal_bricks, 0, 2);
		world.setBlock(i + 9, j + 63, k + 10, NovaCraftBlocks.basal_bricks, 0, 2);
		world.setBlock(i + 10, j + 63, k + 10, NovaCraftBlocks.basal_bricks, 0, 2);
		world.setBlock(i + 11, j + 63, k + 10, NovaCraftBlocks.basal_bricks, 0, 2);
		world.setBlock(i + 12, j + 63, k + 10, NovaCraftBlocks.basal_bricks, 0, 2);
		world.setBlock(i + 13, j + 63, k + 10, NovaCraftBlocks.basal_bricks, 0, 2);
		world.setBlock(i + 14, j + 63, k + 10, NovaCraftBlocks.basal_bricks, 0, 2);
		world.setBlock(i + 15, j + 63, k + 10, NovaCraftBlocks.basal_bricks, 0, 2);
		world.setBlock(i + 16, j + 63, k + 10, NovaCraftBlocks.basal_bricks, 0, 2);
		world.setBlock(i + 17, j + 63, k + 10, NovaCraftBlocks.basal_bricks, 0, 2);
		world.setBlock(i + 18, j + 63, k + 10, NovaCraftBlocks.basal_bricks, 0, 2);
		world.setBlock(i + 19, j + 63, k + 10, NovaCraftBlocks.basal_bricks, 0, 2);
		world.setBlock(i + 20, j + 63, k + 10, NovaCraftBlocks.basal_bricks, 0, 2);
		world.setBlock(i + 21, j + 63, k + 10, NovaCraftBlocks.basal_bricks, 0, 2);
		world.setBlock(i + 22, j + 63, k + 10, NovaCraftBlocks.basal_bricks, 0, 2);
		world.setBlock(i + 23, j + 63, k + 10, NovaCraftBlocks.basal_bricks, 0, 2);
		world.setBlock(i + 24, j + 63, k + 10, NovaCraftBlocks.basal_bricks, 0, 2);
		world.setBlock(i + 25, j + 63, k + 10, NovaCraftBlocks.basal_bricks, 0, 2);
		world.setBlock(i + 26, j + 63, k + 10, Blocks.air, 0, 2);
		world.setBlock(i + 27, j + 63, k + 10, NovaCraftBlocks.basal_scrap, 0, 2);
		world.setBlock(i, j + 63, k + 11, Blocks.air, 0, 2);
		world.setBlock(i + 1, j + 63, k + 11, Blocks.air, 0, 2);
		world.setBlock(i + 2, j + 63, k + 11, Blocks.air, 0, 2);
		world.setBlock(i + 3, j + 63, k + 11, Blocks.air, 0, 2);
		world.setBlock(i + 4, j + 63, k + 11, Blocks.air, 0, 2);
		world.setBlock(i + 5, j + 63, k + 11, Blocks.air, 0, 2);
		world.setBlock(i + 6, j + 63, k + 11, Blocks.air, 0, 2);
		world.setBlock(i + 7, j + 63, k + 11, Blocks.air, 0, 2);
		world.setBlock(i + 8, j + 63, k + 11, Blocks.air, 0, 2);
		world.setBlock(i + 9, j + 63, k + 11, Blocks.air, 0, 2);
		world.setBlock(i + 10, j + 63, k + 11, Blocks.air, 0, 2);
		world.setBlock(i + 11, j + 63, k + 11, Blocks.air, 0, 2);
		world.setBlock(i + 12, j + 63, k + 11, Blocks.air, 0, 2);
		world.setBlock(i + 13, j + 63, k + 11, Blocks.air, 0, 2);
		world.setBlock(i + 14, j + 63, k + 11, NovaCraftBlocks.basal_bricks, 0, 2);
		world.setBlock(i + 15, j + 63, k + 11, NovaCraftBlocks.basal_bricks, 0, 2);
		world.setBlock(i + 16, j + 63, k + 11, NovaCraftBlocks.basal_bricks, 0, 2);
		world.setBlock(i + 17, j + 63, k + 11, NovaCraftBlocks.basal_bricks, 0, 2);
		world.setBlock(i + 18, j + 63, k + 11, NovaCraftBlocks.basal_bricks, 0, 2);
		world.setBlock(i + 19, j + 63, k + 11, NovaCraftBlocks.basal_bricks, 0, 2);
		world.setBlock(i + 20, j + 63, k + 11, NovaCraftBlocks.basal_bricks, 0, 2);
		world.setBlock(i + 21, j + 63, k + 11, NovaCraftBlocks.basal_bricks, 0, 2);
		world.setBlock(i + 22, j + 63, k + 11, NovaCraftBlocks.basal_bricks, 0, 2);
		world.setBlock(i + 23, j + 63, k + 11, NovaCraftBlocks.basal_bricks, 0, 2);
		world.setBlock(i + 24, j + 63, k + 11, NovaCraftBlocks.basal_bricks, 0, 2);
		world.setBlock(i + 25, j + 63, k + 11, NovaCraftBlocks.basal_bricks, 0, 2);
		world.setBlock(i + 26, j + 63, k + 11, Blocks.air, 0, 2);
		world.setBlock(i + 27, j + 63, k + 11, NovaCraftBlocks.basal_bricks, 0, 2);
		world.setBlock(i, j + 63, k + 12, Blocks.air, 0, 2);
		world.setBlock(i + 1, j + 63, k + 12, Blocks.air, 0, 2);
		world.setBlock(i + 2, j + 63, k + 12, Blocks.air, 0, 2);
		world.setBlock(i + 3, j + 63, k + 12, Blocks.air, 0, 2);
		world.setBlock(i + 4, j + 63, k + 12, Blocks.air, 0, 2);
		world.setBlock(i + 5, j + 63, k + 12, Blocks.air, 0, 2);
		world.setBlock(i + 6, j + 63, k + 12, Blocks.air, 0, 2);
		world.setBlock(i + 7, j + 63, k + 12, Blocks.air, 0, 2);
		world.setBlock(i + 8, j + 63, k + 12, Blocks.air, 0, 2);
		world.setBlock(i + 9, j + 63, k + 12, Blocks.air, 0, 2);
		world.setBlock(i + 10, j + 63, k + 12, Blocks.air, 0, 2);
		world.setBlock(i + 11, j + 63, k + 12, Blocks.air, 0, 2);
		world.setBlock(i + 12, j + 63, k + 12, Blocks.air, 0, 2);
		world.setBlock(i + 13, j + 63, k + 12, Blocks.air, 0, 2);
		world.setBlock(i + 14, j + 63, k + 12, NovaCraftBlocks.basal_bricks, 0, 2);
		world.setBlock(i + 15, j + 63, k + 12, NovaCraftBlocks.basal_bricks, 0, 2);
		world.setBlock(i + 16, j + 63, k + 12, NovaCraftBlocks.basal_bricks, 0, 2);
		world.setBlock(i + 17, j + 63, k + 12, NovaCraftBlocks.basal_bricks, 0, 2);
		world.setBlock(i + 18, j + 63, k + 12, NovaCraftBlocks.basal_bricks, 0, 2);
		world.setBlock(i + 19, j + 63, k + 12, NovaCraftBlocks.basal_bricks, 0, 2);
		world.setBlock(i + 20, j + 63, k + 12, NovaCraftBlocks.basal_bricks, 0, 2);
		world.setBlock(i + 21, j + 63, k + 12, NovaCraftBlocks.basal_bricks, 0, 2);
		world.setBlock(i + 22, j + 63, k + 12, NovaCraftBlocks.basal_bricks, 0, 2);
		world.setBlock(i + 23, j + 63, k + 12, NovaCraftBlocks.basal_bricks, 0, 2);
		world.setBlock(i + 24, j + 63, k + 12, NovaCraftBlocks.basal_bricks, 0, 2);
		world.setBlock(i + 25, j + 63, k + 12, NovaCraftBlocks.basal_bricks, 0, 2);
		world.setBlock(i + 26, j + 63, k + 12, NovaCraftBlocks.basal_bricks, 0, 2);
		world.setBlock(i + 27, j + 63, k + 12, NovaCraftBlocks.basal_bricks, 0, 2);
		world.setBlock(i, j + 64, k, NovaCraftBlocks.basal_scrap, 0, 2);
		world.setBlock(i + 1, j + 64, k, NovaCraftBlocks.basal_scrap, 0, 2);
		world.setBlock(i + 2, j + 64, k, NovaCraftBlocks.basal_bricks, 0, 2);
		world.setBlock(i + 3, j + 64, k, NovaCraftBlocks.basal_bricks, 0, 2);
		world.setBlock(i + 4, j + 64, k, NovaCraftBlocks.basal_bricks, 0, 2);
		world.setBlock(i + 5, j + 64, k, NovaCraftBlocks.basal_bricks, 0, 2);
		world.setBlock(i + 6, j + 64, k, NovaCraftBlocks.basal_bricks, 0, 2);
		world.setBlock(i + 7, j + 64, k, NovaCraftBlocks.basal_bricks, 0, 2);
		world.setBlock(i + 8, j + 64, k, NovaCraftBlocks.basal_bricks, 0, 2);
		world.setBlock(i + 9, j + 64, k, NovaCraftBlocks.basal_bricks, 0, 2);
		world.setBlock(i + 10, j + 64, k, NovaCraftBlocks.basal_bricks, 0, 2);
		world.setBlock(i, j + 64, k + 1, NovaCraftBlocks.basal_scrap, 0, 2);
		world.setBlock(i + 1, j + 64, k + 1, NovaCraftBlocks.basal_bricks, 0, 2);
		world.setBlock(i + 2, j + 64, k + 1, NovaCraftBlocks.basal_bricks, 0, 2);
		world.setBlock(i + 3, j + 64, k + 1, NovaCraftBlocks.basal_bricks, 0, 2);
		world.setBlock(i + 4, j + 64, k + 1, NovaCraftBlocks.basal_bricks, 0, 2);
		world.setBlock(i + 5, j + 64, k + 1, NovaCraftBlocks.basal_bricks, 0, 2);
		world.setBlock(i + 6, j + 64, k + 1, NovaCraftBlocks.basal_bricks, 0, 2);
		world.setBlock(i + 7, j + 64, k + 1, NovaCraftBlocks.basal_bricks, 0, 2);
		world.setBlock(i + 8, j + 64, k + 1, NovaCraftBlocks.basal_bricks, 0, 2);
		world.setBlock(i + 9, j + 64, k + 1, NovaCraftBlocks.basal_bricks, 0, 2);
		world.setBlock(i + 10, j + 64, k + 1, NovaCraftBlocks.basal_bricks, 0, 2);
		world.setBlock(i, j + 64, k + 2, NovaCraftBlocks.basal_bricks, 0, 2);
		world.setBlock(i + 1, j + 64, k + 2, NovaCraftBlocks.basal_bricks, 0, 2);
		world.setBlock(i + 2, j + 64, k + 2, NovaCraftBlocks.basal_bricks, 0, 2);
		world.setBlock(i + 3, j + 64, k + 2, NovaCraftBlocks.basal_bricks, 0, 2);
		world.setBlock(i + 4, j + 64, k + 2, NovaCraftBlocks.basal_bricks, 0, 2);
		world.setBlock(i + 5, j + 64, k + 2, NovaCraftBlocks.basal_bricks, 0, 2);
		world.setBlock(i + 6, j + 64, k + 2, NovaCraftBlocks.basal_bricks, 0, 2);
		world.setBlock(i + 7, j + 64, k + 2, NovaCraftBlocks.basal_bricks, 0, 2);
		world.setBlock(i + 8, j + 64, k + 2, NovaCraftBlocks.basal_bricks, 0, 2);
		world.setBlock(i + 9, j + 64, k + 2, NovaCraftBlocks.basal_bricks, 0, 2);
		world.setBlock(i + 10, j + 64, k + 2, NovaCraftBlocks.basal_bricks, 0, 2);
		world.setBlock(i + 12, j + 64, k + 2, NovaCraftBlocks.basal_bricks, 0, 2);
		world.setBlock(i + 13, j + 64, k + 2, NovaCraftBlocks.basal_bricks, 0, 2);
		world.setBlock(i + 15, j + 64, k + 2, NovaCraftBlocks.basal_scrap, 0, 2);
		world.setBlock(i + 19, j + 64, k + 2, NovaCraftBlocks.basal_bricks, 0, 2);
		world.setBlock(i + 22, j + 64, k + 2, NovaCraftBlocks.basal_bricks, 0, 2);
		world.setBlock(i + 23, j + 64, k + 2, NovaCraftBlocks.basal_bricks, 0, 2);
		world.setBlock(i, j + 64, k + 3, NovaCraftBlocks.basal_bricks, 0, 2);
		world.setBlock(i + 1, j + 64, k + 3, NovaCraftBlocks.basal_bricks, 0, 2);
		world.setBlock(i + 2, j + 64, k + 3, NovaCraftBlocks.basal_bricks, 0, 2);
		world.setBlock(i + 3, j + 64, k + 3, NovaCraftBlocks.basal_bricks, 0, 2);
		world.setBlock(i + 4, j + 64, k + 3, NovaCraftBlocks.basal_bricks, 0, 2);
		world.setBlock(i + 5, j + 64, k + 3, NovaCraftBlocks.basal_bricks, 0, 2);
		world.setBlock(i + 6, j + 64, k + 3, NovaCraftBlocks.basal_bricks, 0, 2);
		world.setBlock(i + 7, j + 64, k + 3, NovaCraftBlocks.basal_bricks, 0, 2);
		world.setBlock(i + 8, j + 64, k + 3, NovaCraftBlocks.basal_bricks, 0, 2);
		world.setBlock(i + 9, j + 64, k + 3, NovaCraftBlocks.basal_bricks, 0, 2);
		world.setBlock(i + 10, j + 64, k + 3, NovaCraftBlocks.basal_bricks, 0, 2);
		world.setBlock(i + 11, j + 64, k + 3, NovaCraftBlocks.basal_bricks, 0, 2);
		world.setBlock(i + 12, j + 64, k + 3, NovaCraftBlocks.basal_bricks, 0, 2);
		world.setBlock(i + 13, j + 64, k + 3, NovaCraftBlocks.basal_bricks, 0, 2);
		world.setBlock(i + 14, j + 64, k + 3, NovaCraftBlocks.basal_bricks, 0, 2);
		world.setBlock(i + 15, j + 64, k + 3, NovaCraftBlocks.basal_bricks, 0, 2);
		world.setBlock(i + 18, j + 64, k + 3, NovaCraftBlocks.basal_bricks, 0, 2);
		world.setBlock(i + 19, j + 64, k + 3, NovaCraftBlocks.basal_bricks, 0, 2);
		world.setBlock(i + 22, j + 64, k + 3, NovaCraftBlocks.basal_bricks, 0, 2);
		world.setBlock(i + 23, j + 64, k + 3, NovaCraftBlocks.basal_bricks, 0, 2);
		world.setBlock(i, j + 64, k + 4, NovaCraftBlocks.basal_bricks, 0, 2);
		world.setBlock(i + 1, j + 64, k + 4, NovaCraftBlocks.basal_bricks, 0, 2);
		world.setBlock(i + 2, j + 64, k + 4, NovaCraftBlocks.basal_bricks, 0, 2);
		world.setBlock(i + 3, j + 64, k + 4, NovaCraftBlocks.basal_bricks, 0, 2);
		world.setBlock(i + 4, j + 64, k + 4, NovaCraftBlocks.basal_bricks, 0, 2);
		world.setBlock(i + 5, j + 64, k + 4, NovaCraftBlocks.basal_bricks, 0, 2);
		world.setBlock(i + 6, j + 64, k + 4, NovaCraftBlocks.basal_bricks, 0, 2);
		world.setBlock(i + 7, j + 64, k + 4, NovaCraftBlocks.basal_bricks, 0, 2);
		world.setBlock(i + 8, j + 64, k + 4, NovaCraftBlocks.basal_bricks, 0, 2);
		world.setBlock(i + 9, j + 64, k + 4, NovaCraftBlocks.basal_bricks, 0, 2);
		world.setBlock(i + 10, j + 64, k + 4, NovaCraftBlocks.basal_bricks, 0, 2);
		world.setBlock(i + 11, j + 64, k + 4, Blocks.air, 0, 2);
		world.setBlock(i + 12, j + 64, k + 4, NovaCraftBlocks.basal_bricks, 0, 2);
		world.setBlock(i + 13, j + 64, k + 4, NovaCraftBlocks.basal_bricks, 0, 2);
		world.setBlock(i + 14, j + 64, k + 4, NovaCraftBlocks.basal_bricks, 0, 2);
		world.setBlock(i + 15, j + 64, k + 4, NovaCraftBlocks.basal_bricks, 0, 2);
		world.setBlock(i + 16, j + 64, k + 4, Blocks.air, 0, 2);
		world.setBlock(i + 17, j + 64, k + 4, Blocks.air, 0, 2);
		world.setBlock(i + 18, j + 64, k + 4, NovaCraftBlocks.basal_bricks, 0, 2);
		world.setBlock(i + 19, j + 64, k + 4, NovaCraftBlocks.basal_bricks, 0, 2);
		world.setBlock(i + 20, j + 64, k + 4, Blocks.air, 0, 2);
		world.setBlock(i + 21, j + 64, k + 4, Blocks.air, 0, 2);
		world.setBlock(i + 22, j + 64, k + 4, NovaCraftBlocks.basal_bricks, 0, 2);
		world.setBlock(i + 23, j + 64, k + 4, NovaCraftBlocks.basal_bricks, 0, 2);
		world.setBlock(i + 24, j + 64, k + 4, Blocks.air, 0, 2);
		world.setBlock(i + 25, j + 64, k + 4, Blocks.air, 0, 2);
		world.setBlock(i + 26, j + 64, k + 4, Blocks.air, 0, 2);
		world.setBlock(i + 27, j + 64, k + 4, NovaCraftBlocks.basal_bricks, 0, 2);
		world.setBlock(i, j + 64, k + 5, NovaCraftBlocks.basal_bricks, 0, 2);
		world.setBlock(i + 1, j + 64, k + 5, NovaCraftBlocks.basal_bricks, 0, 2);
		world.setBlock(i + 2, j + 64, k + 5, NovaCraftBlocks.basal_bricks, 0, 2);
		world.setBlock(i + 3, j + 64, k + 5, NovaCraftBlocks.basal_bricks, 0, 2);
		world.setBlock(i + 4, j + 64, k + 5, NovaCraftBlocks.basal_bricks, 0, 2);
		world.setBlock(i + 5, j + 64, k + 5, NovaCraftBlocks.basal_bricks, 0, 2);
		world.setBlock(i + 6, j + 64, k + 5, NovaCraftBlocks.basal_bricks, 0, 2);
		world.setBlock(i + 7, j + 64, k + 5, NovaCraftBlocks.basal_bricks, 0, 2);
		world.setBlock(i + 8, j + 64, k + 5, NovaCraftBlocks.basal_bricks, 0, 2);
		world.setBlock(i + 9, j + 64, k + 5, NovaCraftBlocks.basal_bricks, 0, 2);
		world.setBlock(i + 10, j + 64, k + 5, NovaCraftBlocks.basal_bricks, 0, 2);
		world.setBlock(i + 11, j + 64, k + 5, NovaCraftBlocks.basal, 0, 2);
		world.setBlock(i + 12, j + 64, k + 5, NovaCraftBlocks.basal_bricks, 0, 2);
		world.setBlock(i + 13, j + 64, k + 5, NovaCraftBlocks.basal_bricks, 0, 2);
		world.setBlock(i + 14, j + 64, k + 5, NovaCraftBlocks.basal_bricks, 0, 2);
		world.setBlock(i + 15, j + 64, k + 5, NovaCraftBlocks.basal_bricks, 0, 2);
		world.setBlock(i + 16, j + 64, k + 5, Blocks.air, 0, 2);
		world.setBlock(i + 17, j + 64, k + 5, NovaCraftBlocks.block_of_vanite, 0, 2);
		world.setBlock(i + 18, j + 64, k + 5, NovaCraftBlocks.basal_bricks, 0, 2);
		world.setBlock(i + 19, j + 64, k + 5, NovaCraftBlocks.basal_bricks, 0, 2);
		world.setBlock(i + 20, j + 64, k + 5, NovaCraftBlocks.block_of_vanite, 0, 2);
		world.setBlock(i + 21, j + 64, k + 5, NovaCraftBlocks.block_of_vanite, 0, 2);
		world.setBlock(i + 22, j + 64, k + 5, NovaCraftBlocks.basal_bricks, 0, 2);
		world.setBlock(i + 23, j + 64, k + 5, NovaCraftBlocks.basal_bricks, 0, 2);
		world.setBlock(i + 24, j + 64, k + 5, Blocks.air, 0, 2);
		world.setBlock(i + 25, j + 64, k + 5, Blocks.air, 0, 2);
		world.setBlock(i + 26, j + 64, k + 5, NovaCraftBlocks.basal_bricks, 0, 2);
		world.setBlock(i + 27, j + 64, k + 5, NovaCraftBlocks.basal_bricks, 0, 2);
		world.setBlock(i, j + 64, k + 6, Blocks.air, 0, 2);
		world.setBlock(i + 1, j + 64, k + 6, Blocks.air, 0, 2);
		world.setBlock(i + 2, j + 64, k + 6, Blocks.air, 0, 2);
		world.setBlock(i + 3, j + 64, k + 6, NovaCraftBlocks.basal_brick_stairs, 3, 2);
		world.setBlock(i + 4, j + 64, k + 6, Blocks.air, 0, 2);
		world.setBlock(i + 5, j + 64, k + 6, Blocks.air, 0, 2);
		world.setBlock(i + 6, j + 64, k + 6, NovaCraftBlocks.basal_brick_stairs, 3, 2);
		world.setBlock(i + 7, j + 64, k + 6, NovaCraftBlocks.basal_brick_stairs, 3, 2);
		world.setBlock(i + 8, j + 64, k + 6, Blocks.air, 0, 2);
		world.setBlock(i + 9, j + 64, k + 6, Blocks.air, 0, 2);
		world.setBlock(i + 10, j + 64, k + 6, Blocks.air, 0, 2);
		world.setBlock(i + 11, j + 64, k + 6, Blocks.air, 0, 2);
		world.setBlock(i + 12, j + 64, k + 6, Blocks.air, 0, 2);
		world.setBlock(i + 13, j + 64, k + 6, Blocks.air, 0, 2);
		world.setBlock(i + 14, j + 64, k + 6, NovaCraftBlocks.basal_bricks, 0, 2);
		world.setBlock(i + 15, j + 64, k + 6, NovaCraftBlocks.basal_bricks, 0, 2);
		world.setBlock(i + 16, j + 64, k + 6, NovaCraftBlocks.basal_bricks, 0, 2);
		world.setBlock(i + 17, j + 64, k + 6, NovaCraftBlocks.basal_bricks, 0, 2);
		world.setBlock(i + 18, j + 64, k + 6, NovaCraftBlocks.basal_bricks, 0, 2);
		world.setBlock(i + 19, j + 64, k + 6, NovaCraftBlocks.basal_bricks, 0, 2);
		world.setBlock(i + 20, j + 64, k + 6, NovaCraftBlocks.basal_bricks, 0, 2);
		world.setBlock(i + 21, j + 64, k + 6, NovaCraftBlocks.basal_bricks, 0, 2);
		world.setBlock(i + 22, j + 64, k + 6, NovaCraftBlocks.basal_bricks, 0, 2);
		world.setBlock(i + 23, j + 64, k + 6, NovaCraftBlocks.basal_bricks, 0, 2);
		world.setBlock(i + 24, j + 64, k + 6, NovaCraftBlocks.basal_bricks, 0, 2);
		world.setBlock(i + 25, j + 64, k + 6, NovaCraftBlocks.basal_bricks, 0, 2);
		world.setBlock(i + 26, j + 64, k + 6, NovaCraftBlocks.basal_bricks, 0, 2);
		world.setBlock(i + 27, j + 64, k + 6, NovaCraftBlocks.basal_bricks, 0, 2);
		world.setBlock(i, j + 64, k + 7, Blocks.air, 0, 2);
		world.setBlock(i + 1, j + 64, k + 7, Blocks.air, 0, 2);
		world.setBlock(i + 3, j + 64, k + 7, Blocks.air, 0, 2);
		world.setBlock(i + 4, j + 64, k + 7, Blocks.air, 0, 2);
		world.setBlock(i + 5, j + 64, k + 7, Blocks.air, 0, 2);
		world.setBlock(i + 6, j + 64, k + 7, Blocks.air, 0, 2);
		world.setBlock(i + 7, j + 64, k + 7, Blocks.air, 0, 2);
		world.setBlock(i + 8, j + 64, k + 7, Blocks.air, 0, 2);
		world.setBlock(i + 9, j + 64, k + 7, Blocks.air, 0, 2);
		world.setBlock(i + 10, j + 64, k + 7, Blocks.air, 0, 2);
		world.setBlock(i + 11, j + 64, k + 7, Blocks.air, 0, 2);
		world.setBlock(i + 12, j + 64, k + 7, Blocks.air, 0, 2);
		world.setBlock(i + 13, j + 64, k + 7, Blocks.air, 0, 2);
		world.setBlock(i + 14, j + 64, k + 7, NovaCraftBlocks.basal_bricks, 0, 2);
		world.setBlock(i + 15, j + 64, k + 7, NovaCraftBlocks.basal_bricks, 0, 2);
		world.setBlock(i + 16, j + 64, k + 7, NovaCraftBlocks.basal_bricks, 0, 2);
		world.setBlock(i + 17, j + 64, k + 7, NovaCraftBlocks.basal_bricks, 0, 2);
		world.setBlock(i + 18, j + 64, k + 7, Blocks.air, 0, 2);
		world.setBlock(i + 19, j + 64, k + 7, Blocks.air, 0, 2);
		world.setBlock(i + 20, j + 64, k + 7, NovaCraftBlocks.basal_bricks, 0, 2);
		world.setBlock(i + 21, j + 64, k + 7, NovaCraftBlocks.basal_bricks, 0, 2);
		world.setBlock(i + 22, j + 64, k + 7, Blocks.air, 0, 2);
		world.setBlock(i + 23, j + 64, k + 7, Blocks.air, 0, 2);
		world.setBlock(i + 24, j + 64, k + 7, NovaCraftBlocks.basal_bricks, 0, 2);
		world.setBlock(i + 25, j + 64, k + 7, NovaCraftBlocks.basal_bricks, 0, 2);
		world.setBlock(i + 26, j + 64, k + 7, NovaCraftBlocks.basal_bricks, 0, 2);
		world.setBlock(i + 27, j + 64, k + 7, NovaCraftBlocks.basal_scrap, 0, 2);
		world.setBlock(i, j + 64, k + 8, Blocks.air, 0, 2);
		world.setBlock(i + 1, j + 64, k + 8, Blocks.air, 0, 2);
		world.setBlock(i + 2, j + 64, k + 8, Blocks.air, 0, 2);
		world.setBlock(i + 3, j + 64, k + 8, Blocks.air, 0, 2);
		world.setBlock(i + 4, j + 64, k + 8, Blocks.air, 0, 2);
		world.setBlock(i + 5, j + 64, k + 8, Blocks.air, 0, 2);
		world.setBlock(i + 6, j + 64, k + 8, Blocks.air, 0, 2);
		world.setBlock(i + 7, j + 64, k + 8, Blocks.air, 0, 2);
		world.setBlock(i + 8, j + 64, k + 8, Blocks.air, 0, 2);
		world.setBlock(i + 9, j + 64, k + 8, Blocks.air, 0, 2);
		world.setBlock(i + 10, j + 64, k + 8, Blocks.air, 0, 2);
		world.setBlock(i + 11, j + 64, k + 8, Blocks.air, 0, 2);
		world.setBlock(i + 12, j + 64, k + 8, Blocks.air, 0, 2);
		world.setBlock(i + 13, j + 64, k + 8, Blocks.air, 0, 2);
		world.setBlock(i + 14, j + 64, k + 8, NovaCraftBlocks.basal_bricks, 0, 2);
		world.setBlock(i + 15, j + 64, k + 8, Blocks.air, 0, 2);
		world.setBlock(i + 16, j + 64, k + 8, NovaCraftBlocks.basal_bricks, 0, 2);
		world.setBlock(i + 17, j + 64, k + 8, NovaCraftBlocks.basal_bricks, 0, 2);
		world.setBlock(i + 18, j + 64, k + 8, Blocks.air, 0, 2);
		world.setBlock(i + 19, j + 64, k + 8, Blocks.air, 0, 2);
		world.setBlock(i + 20, j + 64, k + 8, NovaCraftBlocks.basal_bricks, 0, 2);
		world.setBlock(i + 21, j + 64, k + 8, NovaCraftBlocks.basal_bricks, 0, 2);
		world.setBlock(i + 22, j + 64, k + 8, Blocks.air, 0, 2);
		world.setBlock(i + 23, j + 64, k + 8, Blocks.air, 0, 2);
		world.setBlock(i + 24, j + 64, k + 8, NovaCraftBlocks.basal_bricks, 0, 2);
		world.setBlock(i + 25, j + 64, k + 8, NovaCraftBlocks.basal, 0, 2);
		world.setBlock(i + 26, j + 64, k + 8, NovaCraftBlocks.basal, 0, 2);
		world.setBlock(i + 27, j + 64, k + 8, Blocks.air, 0, 2);
		world.setBlock(i, j + 64, k + 9, NovaCraftBlocks.basal_bricks, 0, 2);
		world.setBlock(i + 1, j + 64, k + 9, NovaCraftBlocks.basal_bricks, 0, 2);
		world.setBlock(i + 2, j + 64, k + 9, NovaCraftBlocks.basal_bricks, 0, 2);
		world.setBlock(i + 3, j + 64, k + 9, NovaCraftBlocks.basal_bricks, 0, 2);
		world.setBlock(i + 4, j + 64, k + 9, NovaCraftBlocks.basal_bricks, 0, 2);
		world.setBlock(i + 5, j + 64, k + 9, NovaCraftBlocks.basal_bricks, 0, 2);
		world.setBlock(i + 6, j + 64, k + 9, NovaCraftBlocks.basal_bricks, 0, 2);
		world.setBlock(i + 7, j + 64, k + 9, NovaCraftBlocks.basal_bricks, 0, 2);
		world.setBlock(i + 8, j + 64, k + 9, NovaCraftBlocks.basal, 0, 2);
		world.setBlock(i + 9, j + 64, k + 9, NovaCraftBlocks.basal, 0, 2);
		world.setBlock(i + 10, j + 64, k + 9, Blocks.air, 0, 2);
		world.setBlock(i + 11, j + 64, k + 9, NovaCraftBlocks.basal, 0, 2);
		world.setBlock(i + 12, j + 64, k + 9, NovaCraftBlocks.basal_bricks, 0, 2);
		world.setBlock(i + 13, j + 64, k + 9, NovaCraftBlocks.basal, 0, 2);
		world.setBlock(i + 14, j + 64, k + 9, NovaCraftBlocks.basal_bricks, 0, 2);
		world.setBlock(i + 15, j + 64, k + 9, NovaCraftBlocks.basal_bricks, 0, 2);
		world.setBlock(i + 16, j + 64, k + 9, NovaCraftBlocks.basal_bricks, 0, 2);
		world.setBlock(i + 17, j + 64, k + 9, NovaCraftBlocks.basal_bricks, 0, 2);
		world.setBlock(i + 18, j + 64, k + 9, Blocks.air, 0, 2);
		world.setBlock(i + 19, j + 64, k + 9, Blocks.air, 0, 2);
		world.setBlock(i + 20, j + 64, k + 9, NovaCraftBlocks.basal_bricks, 0, 2);
		world.setBlock(i + 21, j + 64, k + 9, NovaCraftBlocks.basal_bricks, 0, 2);
		world.setBlock(i + 22, j + 64, k + 9, Blocks.air, 0, 2);
		world.setBlock(i + 23, j + 64, k + 9, Blocks.air, 0, 2);
		world.setBlock(i + 24, j + 64, k + 9, NovaCraftBlocks.basal_bricks, 0, 2);
		world.setBlock(i + 25, j + 64, k + 9, NovaCraftBlocks.basal_scrap, 0, 2);
		world.setBlock(i + 26, j + 64, k + 9, NovaCraftBlocks.basal_scrap, 0, 2);
		world.setBlock(i + 27, j + 64, k + 9, Blocks.air, 0, 2);
		world.setBlock(i, j + 64, k + 10, NovaCraftBlocks.basal_bricks, 0, 2);
		world.setBlock(i + 1, j + 64, k + 10, NovaCraftBlocks.basal_bricks, 0, 2);
		world.setBlock(i + 2, j + 64, k + 10, NovaCraftBlocks.basal_bricks, 0, 2);
		world.setBlock(i + 3, j + 64, k + 10, NovaCraftBlocks.basal_bricks, 0, 2);
		world.setBlock(i + 4, j + 64, k + 10, NovaCraftBlocks.basal_bricks, 0, 2);
		world.setBlock(i + 5, j + 64, k + 10, NovaCraftBlocks.basal_bricks, 0, 2);
		world.setBlock(i + 6, j + 64, k + 10, NovaCraftBlocks.basal_bricks, 0, 2);
		world.setBlock(i + 7, j + 64, k + 10, NovaCraftBlocks.basal_bricks, 0, 2);
		world.setBlock(i + 8, j + 64, k + 10, NovaCraftBlocks.basal_bricks, 0, 2);
		world.setBlock(i + 9, j + 64, k + 10, NovaCraftBlocks.basal_bricks, 0, 2);
		world.setBlock(i + 10, j + 64, k + 10, NovaCraftBlocks.basal_bricks, 0, 2);
		world.setBlock(i + 11, j + 64, k + 10, NovaCraftBlocks.basal_bricks, 0, 2);
		world.setBlock(i + 12, j + 64, k + 10, NovaCraftBlocks.basal_bricks, 0, 2);
		world.setBlock(i + 13, j + 64, k + 10, NovaCraftBlocks.basal_bricks, 0, 2);
		world.setBlock(i + 14, j + 64, k + 10, NovaCraftBlocks.basal_bricks, 0, 2);
		world.setBlock(i + 15, j + 64, k + 10, NovaCraftBlocks.basal_bricks, 0, 2);
		world.setBlock(i + 16, j + 64, k + 10, NovaCraftBlocks.basal_bricks, 0, 2);
		world.setBlock(i + 17, j + 64, k + 10, NovaCraftBlocks.basal_bricks, 0, 2);
		world.setBlock(i + 18, j + 64, k + 10, NovaCraftBlocks.basal_brick_stairs, 2, 2);
		world.setBlock(i + 19, j + 64, k + 10, NovaCraftBlocks.basal_brick_stairs, 2, 2);
		world.setBlock(i + 20, j + 64, k + 10, NovaCraftBlocks.basal_bricks, 0, 2);
		world.setBlock(i + 21, j + 64, k + 10, NovaCraftBlocks.basal_bricks, 0, 2);
		world.setBlock(i + 22, j + 64, k + 10, NovaCraftBlocks.basal, 0, 2);
		world.setBlock(i + 23, j + 64, k + 10, NovaCraftBlocks.basal, 0, 2);
		world.setBlock(i + 24, j + 64, k + 10, NovaCraftBlocks.basal, 0, 2);
		world.setBlock(i + 25, j + 64, k + 10, NovaCraftBlocks.basal_bricks, 0, 2);
		world.setBlock(i + 26, j + 64, k + 10, NovaCraftBlocks.basal_scrap, 0, 2);
		world.setBlock(i + 27, j + 64, k + 10, Blocks.air, 0, 2);
		world.setBlock(i, j + 64, k + 11, Blocks.air, 0, 2);
		world.setBlock(i + 1, j + 64, k + 11, Blocks.air, 0, 2);
		world.setBlock(i + 2, j + 64, k + 11, Blocks.air, 0, 2);
		world.setBlock(i + 3, j + 64, k + 11, Blocks.air, 0, 2);
		world.setBlock(i + 4, j + 64, k + 11, Blocks.air, 0, 2);
		world.setBlock(i + 5, j + 64, k + 11, Blocks.air, 0, 2);
		world.setBlock(i + 6, j + 64, k + 11, Blocks.air, 0, 2);
		world.setBlock(i + 7, j + 64, k + 11, Blocks.air, 0, 2);
		world.setBlock(i + 8, j + 64, k + 11, Blocks.air, 0, 2);
		world.setBlock(i + 9, j + 64, k + 11, Blocks.air, 0, 2);
		world.setBlock(i + 10, j + 64, k + 11, Blocks.air, 0, 2);
		world.setBlock(i + 11, j + 64, k + 11, Blocks.air, 0, 2);
		world.setBlock(i + 12, j + 64, k + 11, Blocks.air, 0, 2);
		world.setBlock(i + 13, j + 64, k + 11, Blocks.air, 0, 2);
		world.setBlock(i + 14, j + 64, k + 11, NovaCraftBlocks.basal_bricks, 0, 2);
		world.setBlock(i + 15, j + 64, k + 11, NovaCraftBlocks.basal_bricks, 0, 2);
		world.setBlock(i + 16, j + 64, k + 11, NovaCraftBlocks.basal_bricks, 0, 2);
		world.setBlock(i + 17, j + 64, k + 11, NovaCraftBlocks.basal_bricks, 0, 2);
		world.setBlock(i + 18, j + 64, k + 11, NovaCraftBlocks.basal_bricks, 0, 2);
		world.setBlock(i + 19, j + 64, k + 11, NovaCraftBlocks.basal_bricks, 0, 2);
		world.setBlock(i + 20, j + 64, k + 11, NovaCraftBlocks.basal_bricks, 0, 2);
		world.setBlock(i + 21, j + 64, k + 11, NovaCraftBlocks.basal_bricks, 0, 2);
		world.setBlock(i + 22, j + 64, k + 11, NovaCraftBlocks.basal_bricks, 0, 2);
		world.setBlock(i + 23, j + 64, k + 11, NovaCraftBlocks.basal_bricks, 0, 2);
		world.setBlock(i + 24, j + 64, k + 11, NovaCraftBlocks.basal_bricks, 0, 2);
		world.setBlock(i + 25, j + 64, k + 11, NovaCraftBlocks.basal_bricks, 0, 2);
		world.setBlock(i + 26, j + 64, k + 11, NovaCraftBlocks.basal_bricks, 0, 2);
		world.setBlock(i + 27, j + 64, k + 11, NovaCraftBlocks.basal_bricks, 0, 2);
		world.setBlock(i, j + 64, k + 12, Blocks.air, 0, 2);
		world.setBlock(i + 1, j + 64, k + 12, Blocks.air, 0, 2);
		world.setBlock(i + 2, j + 64, k + 12, Blocks.air, 0, 2);
		world.setBlock(i + 3, j + 64, k + 12, Blocks.air, 0, 2);
		world.setBlock(i + 4, j + 64, k + 12, Blocks.air, 0, 2);
		world.setBlock(i + 5, j + 64, k + 12, Blocks.air, 0, 2);
		world.setBlock(i + 6, j + 64, k + 12, Blocks.air, 0, 2);
		world.setBlock(i + 7, j + 64, k + 12, Blocks.air, 0, 2);
		world.setBlock(i + 8, j + 64, k + 12, Blocks.air, 0, 2);
		world.setBlock(i + 9, j + 64, k + 12, Blocks.air, 0, 2);
		world.setBlock(i + 10, j + 64, k + 12, Blocks.air, 0, 2);
		world.setBlock(i + 11, j + 64, k + 12, Blocks.air, 0, 2);
		world.setBlock(i + 12, j + 64, k + 12, Blocks.air, 0, 2);
		world.setBlock(i + 13, j + 64, k + 12, Blocks.air, 0, 2);
		world.setBlock(i + 14, j + 64, k + 12, NovaCraftBlocks.basal_bricks, 0, 2);
		world.setBlock(i + 15, j + 64, k + 12, Blocks.air, 0, 2);
		world.setBlock(i + 16, j + 64, k + 12, NovaCraftBlocks.basal_bricks, 0, 2);
		world.setBlock(i + 17, j + 64, k + 12, NovaCraftBlocks.basal_bricks, 0, 2);
		world.setBlock(i + 18, j + 64, k + 12, Blocks.air, 0, 2);
		world.setBlock(i + 19, j + 64, k + 12, NovaCraftBlocks.basal_bricks, 0, 2);
		world.setBlock(i + 20, j + 64, k + 12, NovaCraftBlocks.basal_bricks, 0, 2);
		world.setBlock(i + 21, j + 64, k + 12, NovaCraftBlocks.basal_bricks, 0, 2);
		world.setBlock(i + 22, j + 64, k + 12, NovaCraftBlocks.basal_bricks, 0, 2);
		world.setBlock(i + 23, j + 64, k + 12, NovaCraftBlocks.basal_bricks, 0, 2);
		world.setBlock(i + 24, j + 64, k + 12, NovaCraftBlocks.basal_bricks, 0, 2);
		world.setBlock(i + 25, j + 64, k + 12, NovaCraftBlocks.basal_bricks, 0, 2);
		world.setBlock(i + 26, j + 64, k + 12, NovaCraftBlocks.basal_bricks, 0, 2);
		world.setBlock(i + 27, j + 64, k + 12, NovaCraftBlocks.basal_bricks, 0, 2);
		world.setBlock(i, j + 65, k, NovaCraftBlocks.basal_scrap, 0, 2);
		world.setBlock(i + 3, j + 65, k, NovaCraftBlocks.basal_scrap, 0, 2);
		world.setBlock(i + 4, j + 65, k, NovaCraftBlocks.basal_bricks, 0, 2);
		world.setBlock(i + 5, j + 65, k, NovaCraftBlocks.basal_bricks, 0, 2);
		world.setBlock(i + 6, j + 65, k, NovaCraftBlocks.basal_bricks, 0, 2);
		world.setBlock(i + 7, j + 65, k, NovaCraftBlocks.basal_bricks, 0, 2);
		world.setBlock(i + 8, j + 65, k, NovaCraftBlocks.basal_bricks, 0, 2);
		world.setBlock(i, j + 65, k + 1, NovaCraftBlocks.basal_scrap, 0, 2);
		world.setBlock(i + 1, j + 65, k + 1, NovaCraftBlocks.basal_bricks, 0, 2);
		world.setBlock(i + 3, j + 65, k + 1, NovaCraftBlocks.basal_bricks, 0, 2);
		world.setBlock(i + 4, j + 65, k + 1, NovaCraftBlocks.basal_bricks, 0, 2);
		world.setBlock(i + 5, j + 65, k + 1, NovaCraftBlocks.basal_bricks, 0, 2);
		world.setBlock(i + 6, j + 65, k + 1, NovaCraftBlocks.basal_bricks, 0, 2);
		world.setBlock(i + 7, j + 65, k + 1, NovaCraftBlocks.basal_bricks, 0, 2);
		world.setBlock(i + 8, j + 65, k + 1, NovaCraftBlocks.basal_bricks, 0, 2);
		world.setBlock(i + 9, j + 65, k + 1, NovaCraftBlocks.basal_bricks, 0, 2);
		world.setBlock(i, j + 65, k + 2, NovaCraftBlocks.basal_bricks, 0, 2);
		world.setBlock(i + 1, j + 65, k + 2, NovaCraftBlocks.basal_bricks, 0, 2);
		world.setBlock(i + 2, j + 65, k + 2, NovaCraftBlocks.basal_bricks, 0, 2);
		world.setBlock(i + 3, j + 65, k + 2, NovaCraftBlocks.basal_bricks, 0, 2);
		world.setBlock(i + 4, j + 65, k + 2, NovaCraftBlocks.basal_bricks, 0, 2);
		world.setBlock(i + 5, j + 65, k + 2, NovaCraftBlocks.basal_bricks, 0, 2);
		world.setBlock(i + 6, j + 65, k + 2, NovaCraftBlocks.basal, 0, 2);
		world.setBlock(i + 7, j + 65, k + 2, NovaCraftBlocks.basal_bricks, 0, 2);
		world.setBlock(i + 8, j + 65, k + 2, NovaCraftBlocks.basal_bricks, 0, 2);
		world.setBlock(i + 9, j + 65, k + 2, NovaCraftBlocks.basal_bricks, 0, 2);
		world.setBlock(i + 10, j + 65, k + 2, NovaCraftBlocks.basal_bricks, 0, 2);
		world.setBlock(i + 11, j + 65, k + 2, NovaCraftBlocks.basal_bricks, 0, 2);
		world.setBlock(i + 13, j + 65, k + 2, NovaCraftBlocks.basal_bricks, 0, 2);
		world.setBlock(i + 14, j + 65, k + 2, NovaCraftBlocks.basal_scrap, 0, 2);
		world.setBlock(i + 15, j + 65, k + 2, NovaCraftBlocks.basal_scrap, 0, 2);
		world.setBlock(i + 16, j + 65, k + 2, NovaCraftBlocks.basal_bricks, 0, 2);
		world.setBlock(i + 17, j + 65, k + 2, NovaCraftBlocks.basal_bricks, 0, 2);
		world.setBlock(i + 18, j + 65, k + 2, NovaCraftBlocks.basal_bricks, 0, 2);
		world.setBlock(i + 19, j + 65, k + 2, NovaCraftBlocks.basal_bricks, 0, 2);
		world.setBlock(i + 20, j + 65, k + 2, NovaCraftBlocks.basal_bricks, 0, 2);
		world.setBlock(i + 21, j + 65, k + 2, NovaCraftBlocks.basal_bricks, 0, 2);
		world.setBlock(i + 22, j + 65, k + 2, NovaCraftBlocks.basal_bricks, 0, 2);
		world.setBlock(i + 23, j + 65, k + 2, NovaCraftBlocks.basal_bricks, 0, 2);
		world.setBlock(i + 24, j + 65, k + 2, NovaCraftBlocks.basal_bricks, 0, 2);
		world.setBlock(i, j + 65, k + 3, NovaCraftBlocks.basal_bricks, 0, 2);
		world.setBlock(i + 1, j + 65, k + 3, NovaCraftBlocks.basal_bricks, 0, 2);
		world.setBlock(i + 2, j + 65, k + 3, NovaCraftBlocks.basal_bricks, 0, 2);
		world.setBlock(i + 3, j + 65, k + 3, NovaCraftBlocks.basal, 0, 2);
		world.setBlock(i + 4, j + 65, k + 3, NovaCraftBlocks.basal_bricks, 0, 2);
		world.setBlock(i + 5, j + 65, k + 3, NovaCraftBlocks.basal_bricks, 0, 2);
		world.setBlock(i + 6, j + 65, k + 3, NovaCraftBlocks.basal, 0, 2);
		world.setBlock(i + 7, j + 65, k + 3, NovaCraftBlocks.basal_bricks, 0, 2);
		world.setBlock(i + 8, j + 65, k + 3, NovaCraftBlocks.basal_bricks, 0, 2);
		world.setBlock(i + 9, j + 65, k + 3, NovaCraftBlocks.basal_bricks, 0, 2);
		world.setBlock(i + 10, j + 65, k + 3, NovaCraftBlocks.basal_bricks, 0, 2);
		world.setBlock(i + 11, j + 65, k + 3, NovaCraftBlocks.basal_bricks, 0, 2);
		world.setBlock(i + 12, j + 65, k + 3, NovaCraftBlocks.basal_bricks, 0, 2);
		world.setBlock(i + 13, j + 65, k + 3, NovaCraftBlocks.basal_bricks, 0, 2);
		world.setBlock(i + 14, j + 65, k + 3, NovaCraftBlocks.basal_scrap, 0, 2);
		world.setBlock(i + 15, j + 65, k + 3, NovaCraftBlocks.basal_bricks, 0, 2);
		world.setBlock(i + 16, j + 65, k + 3, NovaCraftBlocks.basal_bricks, 0, 2);
		world.setBlock(i + 17, j + 65, k + 3, NovaCraftBlocks.basal_bricks, 0, 2);
		world.setBlock(i + 18, j + 65, k + 3, NovaCraftBlocks.basal_bricks, 0, 2);
		world.setBlock(i + 19, j + 65, k + 3, NovaCraftBlocks.basal_bricks, 0, 2);
		world.setBlock(i + 20, j + 65, k + 3, NovaCraftBlocks.basal_bricks, 0, 2);
		world.setBlock(i + 21, j + 65, k + 3, NovaCraftBlocks.basal_bricks, 0, 2);
		world.setBlock(i + 22, j + 65, k + 3, NovaCraftBlocks.basal_bricks, 0, 2);
		world.setBlock(i + 23, j + 65, k + 3, NovaCraftBlocks.basal_bricks, 0, 2);
		world.setBlock(i + 24, j + 65, k + 3, NovaCraftBlocks.basal_bricks, 0, 2);
		world.setBlock(i, j + 65, k + 4, NovaCraftBlocks.basal_bricks, 0, 2);
		world.setBlock(i + 1, j + 65, k + 4, NovaCraftBlocks.basal_bricks, 0, 2);
		world.setBlock(i + 2, j + 65, k + 4, NovaCraftBlocks.basal, 0, 2);
		world.setBlock(i + 3, j + 65, k + 4, NovaCraftBlocks.basal, 0, 2);
		world.setBlock(i + 4, j + 65, k + 4, NovaCraftBlocks.basal_bricks, 0, 2);
		world.setBlock(i + 5, j + 65, k + 4, NovaCraftBlocks.basal_bricks, 0, 2);
		world.setBlock(i + 6, j + 65, k + 4, NovaCraftBlocks.basal_bricks, 0, 2);
		world.setBlock(i + 7, j + 65, k + 4, NovaCraftBlocks.basal_bricks, 0, 2);
		world.setBlock(i + 8, j + 65, k + 4, NovaCraftBlocks.basal_bricks, 0, 2);
		world.setBlock(i + 9, j + 65, k + 4, NovaCraftBlocks.basal_bricks, 0, 2);
		world.setBlock(i + 10, j + 65, k + 4, NovaCraftBlocks.basal_bricks, 0, 2);
		world.setBlock(i + 11, j + 65, k + 4, NovaCraftBlocks.basal_bricks, 0, 2);
		world.setBlock(i + 12, j + 65, k + 4, NovaCraftBlocks.basal_bricks, 0, 2);
		world.setBlock(i + 13, j + 65, k + 4, NovaCraftBlocks.basal_bricks, 0, 2);
		world.setBlock(i + 14, j + 65, k + 4, NovaCraftBlocks.basal_bricks, 0, 2);
		world.setBlock(i + 15, j + 65, k + 4, NovaCraftBlocks.basal_bricks, 0, 2);
		world.setBlock(i + 16, j + 65, k + 4, NovaCraftBlocks.basal_bricks, 0, 2);
		world.setBlock(i + 17, j + 65, k + 4, NovaCraftBlocks.basal_bricks, 0, 2);
		world.setBlock(i + 18, j + 65, k + 4, NovaCraftBlocks.basal_bricks, 0, 2);
		world.setBlock(i + 19, j + 65, k + 4, NovaCraftBlocks.basal_bricks, 0, 2);
		world.setBlock(i + 20, j + 65, k + 4, NovaCraftBlocks.basal_bricks, 0, 2);
		world.setBlock(i + 21, j + 65, k + 4, NovaCraftBlocks.basal_bricks, 0, 2);
		world.setBlock(i + 22, j + 65, k + 4, NovaCraftBlocks.basal_bricks, 0, 2);
		world.setBlock(i + 23, j + 65, k + 4, NovaCraftBlocks.basal_bricks, 0, 2);
		world.setBlock(i + 24, j + 65, k + 4, NovaCraftBlocks.basal_bricks, 0, 2);
		world.setBlock(i + 25, j + 65, k + 4, Blocks.air, 0, 2);
		world.setBlock(i + 26, j + 65, k + 4, NovaCraftBlocks.basal_bricks, 0, 2);
		world.setBlock(i + 27, j + 65, k + 4, NovaCraftBlocks.basal_bricks, 0, 2);
		world.setBlock(i, j + 65, k + 5, NovaCraftBlocks.basal_bricks, 0, 2);
		world.setBlock(i + 1, j + 65, k + 5, NovaCraftBlocks.basal_bricks, 0, 2);
		world.setBlock(i + 2, j + 65, k + 5, NovaCraftBlocks.basal_brick_stairs, 3, 2);
		world.setBlock(i + 3, j + 65, k + 5, NovaCraftBlocks.basal_brick_stairs, 3, 2);
		world.setBlock(i + 4, j + 65, k + 5, NovaCraftBlocks.basal_bricks, 0, 2);
		world.setBlock(i + 5, j + 65, k + 5, NovaCraftBlocks.basal_bricks, 0, 2);
		world.setBlock(i + 6, j + 65, k + 5, NovaCraftBlocks.basal_brick_stairs, 3, 2);
		world.setBlock(i + 7, j + 65, k + 5, NovaCraftBlocks.basal_brick_stairs, 3, 2);
		world.setBlock(i + 8, j + 65, k + 5, NovaCraftBlocks.basal_bricks, 0, 2);
		world.setBlock(i + 9, j + 65, k + 5, NovaCraftBlocks.basal_bricks, 0, 2);
		world.setBlock(i + 10, j + 65, k + 5, NovaCraftBlocks.basal_brick_stairs, 3, 2);
		world.setBlock(i + 11, j + 65, k + 5, Blocks.air, 0, 2);
		world.setBlock(i + 12, j + 65, k + 5, NovaCraftBlocks.basal_bricks, 0, 2);
		world.setBlock(i + 13, j + 65, k + 5, Blocks.air, 0, 2);
		world.setBlock(i + 14, j + 65, k + 5, NovaCraftBlocks.basal_bricks, 0, 2);
		world.setBlock(i + 15, j + 65, k + 5, NovaCraftBlocks.basal_bricks, 0, 2);
		world.setBlock(i + 16, j + 65, k + 5, NovaCraftBlocks.basal_bricks, 0, 2);
		world.setBlock(i + 17, j + 65, k + 5, NovaCraftBlocks.basal_bricks, 0, 2);
		world.setBlock(i + 18, j + 65, k + 5, NovaCraftBlocks.basal_bricks, 0, 2);
		world.setBlock(i + 19, j + 65, k + 5, NovaCraftBlocks.basal_bricks, 0, 2);
		world.setBlock(i + 20, j + 65, k + 5, NovaCraftBlocks.basal_bricks, 0, 2);
		world.setBlock(i + 21, j + 65, k + 5, NovaCraftBlocks.basal_bricks, 0, 2);
		world.setBlock(i + 22, j + 65, k + 5, NovaCraftBlocks.basal_bricks, 0, 2);
		world.setBlock(i + 23, j + 65, k + 5, NovaCraftBlocks.basal_bricks, 0, 2);
		world.setBlock(i + 24, j + 65, k + 5, NovaCraftBlocks.basal_bricks, 0, 2);
		world.setBlock(i + 25, j + 65, k + 5, NovaCraftBlocks.basal_bricks, 0, 2);
		world.setBlock(i + 26, j + 65, k + 5, NovaCraftBlocks.basal_bricks, 0, 2);
		world.setBlock(i + 27, j + 65, k + 5, Blocks.air, 0, 2);
		world.setBlock(i, j + 65, k + 6, Blocks.air, 0, 2);
		world.setBlock(i + 1, j + 65, k + 6, Blocks.air, 0, 2);
		world.setBlock(i + 2, j + 65, k + 6, Blocks.air, 0, 2);
		world.setBlock(i + 3, j + 65, k + 6, Blocks.air, 0, 2);
		world.setBlock(i + 4, j + 65, k + 6, Blocks.air, 0, 2);
		world.setBlock(i + 5, j + 65, k + 6, Blocks.air, 0, 2);
		world.setBlock(i + 6, j + 65, k + 6, Blocks.air, 0, 2);
		world.setBlock(i + 7, j + 65, k + 6, Blocks.air, 0, 2);
		world.setBlock(i + 8, j + 65, k + 6, Blocks.air, 0, 2);
		world.setBlock(i + 9, j + 65, k + 6, Blocks.air, 0, 2);
		world.setBlock(i + 10, j + 65, k + 6, Blocks.air, 0, 2);
		world.setBlock(i + 11, j + 65, k + 6, Blocks.air, 0, 2);
		world.setBlock(i + 12, j + 65, k + 6, Blocks.air, 0, 2);
		world.setBlock(i + 13, j + 65, k + 6, Blocks.air, 0, 2);
		world.setBlock(i + 14, j + 65, k + 6, NovaCraftBlocks.basal_bricks, 0, 2);
		world.setBlock(i + 15, j + 65, k + 6, NovaCraftBlocks.basal_bricks, 0, 2);
		world.setBlock(i + 16, j + 65, k + 6, NovaCraftBlocks.basal_bricks, 0, 2);
		world.setBlock(i + 17, j + 65, k + 6, NovaCraftBlocks.basal_bricks, 0, 2);
		world.setBlock(i + 18, j + 65, k + 6, NovaCraftBlocks.basal_bricks, 0, 2);
		world.setBlock(i + 19, j + 65, k + 6, NovaCraftBlocks.basal_bricks, 0, 2);
		world.setBlock(i + 20, j + 65, k + 6, NovaCraftBlocks.basal_bricks, 0, 2);
		world.setBlock(i + 21, j + 65, k + 6, NovaCraftBlocks.basal_bricks, 0, 2);
		world.setBlock(i + 22, j + 65, k + 6, NovaCraftBlocks.basal_bricks, 0, 2);
		world.setBlock(i + 23, j + 65, k + 6, NovaCraftBlocks.basal_bricks, 0, 2);
		world.setBlock(i + 24, j + 65, k + 6, NovaCraftBlocks.basal_bricks, 0, 2);
		world.setBlock(i + 25, j + 65, k + 6, NovaCraftBlocks.basal_bricks, 0, 2);
		world.setBlock(i + 26, j + 65, k + 6, NovaCraftBlocks.basal_bricks, 0, 2);
		world.setBlock(i + 27, j + 65, k + 6, NovaCraftBlocks.basal_bricks, 0, 2);
		world.setBlock(i, j + 65, k + 7, Blocks.air, 0, 2);
		world.setBlock(i + 1, j + 65, k + 7, Blocks.air, 0, 2);
		world.setBlock(i + 2, j + 65, k + 7, Blocks.air, 0, 2);
		world.setBlock(i + 3, j + 65, k + 7, Blocks.air, 0, 2);
		world.setBlock(i + 4, j + 65, k + 7, Blocks.air, 0, 2);
		world.setBlock(i + 5, j + 65, k + 7, Blocks.air, 0, 2);
		world.setBlock(i + 6, j + 65, k + 7, Blocks.air, 0, 2);
		world.setBlock(i + 7, j + 65, k + 7, Blocks.air, 0, 2);
		world.setBlock(i + 8, j + 65, k + 7, Blocks.air, 0, 2);
		world.setBlock(i + 9, j + 65, k + 7, Blocks.air, 0, 2);
		world.setBlock(i + 10, j + 65, k + 7, Blocks.air, 0, 2);
		world.setBlock(i + 11, j + 65, k + 7, Blocks.air, 0, 2);
		world.setBlock(i + 12, j + 65, k + 7, Blocks.air, 0, 2);
		world.setBlock(i + 13, j + 65, k + 7, Blocks.air, 0, 2);
		world.setBlock(i + 14, j + 65, k + 7, NovaCraftBlocks.basal_bricks, 0, 2);
		world.setBlock(i + 15, j + 65, k + 7, NovaCraftBlocks.basal_bricks, 0, 2);
		world.setBlock(i + 16, j + 65, k + 7, NovaCraftBlocks.basal_bricks, 0, 2);
		world.setBlock(i + 17, j + 65, k + 7, NovaCraftBlocks.basal_bricks, 0, 2);
		world.setBlock(i + 18, j + 65, k + 7, NovaCraftBlocks.basal_bricks, 0, 2);
		world.setBlock(i + 19, j + 65, k + 7, NovaCraftBlocks.basal_bricks, 0, 2);
		world.setBlock(i + 20, j + 65, k + 7, NovaCraftBlocks.basal_bricks, 0, 2);
		world.setBlock(i + 21, j + 65, k + 7, NovaCraftBlocks.basal_bricks, 0, 2);
		world.setBlock(i + 22, j + 65, k + 7, NovaCraftBlocks.basal_bricks, 0, 2);
		world.setBlock(i + 23, j + 65, k + 7, NovaCraftBlocks.basal_bricks, 0, 2);
		world.setBlock(i + 24, j + 65, k + 7, NovaCraftBlocks.basal_bricks, 0, 2);
		world.setBlock(i + 25, j + 65, k + 7, NovaCraftBlocks.basal, 0, 2);
		world.setBlock(i + 26, j + 65, k + 7, NovaCraftBlocks.basal_bricks, 0, 2);
		world.setBlock(i + 27, j + 65, k + 7, NovaCraftBlocks.basal_bricks, 0, 2);
		world.setBlock(i, j + 65, k + 8, Blocks.air, 0, 2);
		world.setBlock(i + 1, j + 65, k + 8, Blocks.air, 0, 2);
		world.setBlock(i + 2, j + 65, k + 8, Blocks.air, 0, 2);
		world.setBlock(i + 3, j + 65, k + 8, Blocks.air, 0, 2);
		world.setBlock(i + 4, j + 65, k + 8, Blocks.air, 0, 2);
		world.setBlock(i + 5, j + 65, k + 8, Blocks.air, 0, 2);
		world.setBlock(i + 6, j + 65, k + 8, Blocks.air, 0, 2);
		world.setBlock(i + 7, j + 65, k + 8, Blocks.air, 0, 2);
		world.setBlock(i + 8, j + 65, k + 8, Blocks.air, 0, 2);
		world.setBlock(i + 9, j + 65, k + 8, Blocks.air, 0, 2);
		world.setBlock(i + 10, j + 65, k + 8, Blocks.air, 0, 2);
		world.setBlock(i + 11, j + 65, k + 8, Blocks.air, 0, 2);
		world.setBlock(i + 12, j + 65, k + 8, Blocks.air, 0, 2);
		world.setBlock(i + 13, j + 65, k + 8, Blocks.air, 0, 2);
		world.setBlock(i + 14, j + 65, k + 8, Blocks.air, 0, 2);
		world.setBlock(i + 15, j + 65, k + 8, Blocks.air, 0, 2);
		world.setBlock(i + 16, j + 65, k + 8, NovaCraftBlocks.basal_brick_stairs, 3, 2);
		world.setBlock(i + 17, j + 65, k + 8, NovaCraftBlocks.basal_brick_stairs, 3, 2);
		world.setBlock(i + 18, j + 65, k + 8, Blocks.air, 0, 2);
		world.setBlock(i + 19, j + 65, k + 8, Blocks.air, 0, 2);
		world.setBlock(i + 20, j + 65, k + 8, NovaCraftBlocks.basal_brick_stairs, 3, 2);
		world.setBlock(i + 21, j + 65, k + 8, NovaCraftBlocks.basal_brick_stairs, 3, 2);
		world.setBlock(i + 22, j + 65, k + 8, Blocks.air, 0, 2);
		world.setBlock(i + 23, j + 65, k + 8, Blocks.air, 0, 2);
		world.setBlock(i + 24, j + 65, k + 8, Blocks.air, 0, 2);
		world.setBlock(i + 25, j + 65, k + 8, Blocks.air, 0, 2);
		world.setBlock(i + 26, j + 65, k + 8, Blocks.air, 0, 2);
		world.setBlock(i + 27, j + 65, k + 8, Blocks.air, 0, 2);
		world.setBlock(i, j + 65, k + 9, NovaCraftBlocks.basal_bricks, 0, 2);
		world.setBlock(i + 1, j + 65, k + 9, NovaCraftBlocks.basal_bricks, 0, 2);
		world.setBlock(i + 2, j + 65, k + 9, Blocks.air, 0, 2);
		world.setBlock(i + 3, j + 65, k + 9, Blocks.air, 0, 2);
		world.setBlock(i + 4, j + 65, k + 9, NovaCraftBlocks.basal_bricks, 0, 2);
		world.setBlock(i + 5, j + 65, k + 9, Blocks.air, 0, 2);
		world.setBlock(i + 6, j + 65, k + 9, Blocks.air, 0, 2);
		world.setBlock(i + 7, j + 65, k + 9, Blocks.air, 0, 2);
		world.setBlock(i + 8, j + 65, k + 9, Blocks.air, 0, 2);
		world.setBlock(i + 9, j + 65, k + 9, Blocks.air, 0, 2);
		world.setBlock(i + 10, j + 65, k + 9, Blocks.air, 0, 2);
		world.setBlock(i + 11, j + 65, k + 9, Blocks.air, 0, 2);
		world.setBlock(i + 12, j + 65, k + 9, NovaCraftBlocks.basal_bricks, 0, 2);
		world.setBlock(i + 13, j + 65, k + 9, NovaCraftBlocks.basal_bricks, 0, 2);
		world.setBlock(i + 14, j + 65, k + 9, Blocks.air, 0, 2);
		world.setBlock(i + 16, j + 65, k + 9, Blocks.air, 0, 2);
		world.setBlock(i + 17, j + 65, k + 9, Blocks.air, 0, 2);
		world.setBlock(i + 18, j + 65, k + 9, Blocks.air, 0, 2);
		world.setBlock(i + 19, j + 65, k + 9, Blocks.air, 0, 2);
		world.setBlock(i + 20, j + 65, k + 9, Blocks.air, 0, 2);
		world.setBlock(i + 21, j + 65, k + 9, Blocks.air, 0, 2);
		world.setBlock(i + 22, j + 65, k + 9, Blocks.air, 0, 2);
		world.setBlock(i + 23, j + 65, k + 9, Blocks.air, 0, 2);
		world.setBlock(i + 24, j + 65, k + 9, Blocks.air, 0, 2);
		world.setBlock(i + 25, j + 65, k + 9, Blocks.air, 0, 2);
		world.setBlock(i + 26, j + 65, k + 9, Blocks.air, 0, 2);
		world.setBlock(i + 27, j + 65, k + 9, Blocks.air, 0, 2);
		world.setBlock(i, j + 65, k + 10, NovaCraftBlocks.basal_bricks, 0, 2);
		world.setBlock(i + 1, j + 65, k + 10, NovaCraftBlocks.basal_bricks, 0, 2);
		world.setBlock(i + 2, j + 65, k + 10, Blocks.air, 0, 2);
		world.setBlock(i + 3, j + 65, k + 10, Blocks.air, 0, 2);
		world.setBlock(i + 4, j + 65, k + 10, NovaCraftBlocks.basal_bricks, 0, 2);
		world.setBlock(i + 5, j + 65, k + 10, NovaCraftBlocks.basal_bricks, 0, 2);
		world.setBlock(i + 6, j + 65, k + 10, Blocks.air, 0, 2);
		world.setBlock(i + 7, j + 65, k + 10, Blocks.air, 0, 2);
		world.setBlock(i + 8, j + 65, k + 10, NovaCraftBlocks.basal_bricks, 0, 2);
		world.setBlock(i + 9, j + 65, k + 10, NovaCraftBlocks.basal_bricks, 0, 2);
		world.setBlock(i + 10, j + 65, k + 10, Blocks.air, 0, 2);
		world.setBlock(i + 11, j + 65, k + 10, Blocks.air, 0, 2);
		world.setBlock(i + 12, j + 65, k + 10, Blocks.air, 0, 2);
		world.setBlock(i + 13, j + 65, k + 10, NovaCraftBlocks.basal_bricks, 0, 2);
		world.setBlock(i + 14, j + 65, k + 10, Blocks.air, 0, 2);
		world.setBlock(i + 15, j + 65, k + 10, Blocks.air, 0, 2);
		world.setBlock(i + 16, j + 65, k + 10, Blocks.air, 0, 2);
		world.setBlock(i + 17, j + 65, k + 10, Blocks.air, 0, 2);
		world.setBlock(i + 18, j + 65, k + 10, Blocks.air, 0, 2);
		world.setBlock(i + 19, j + 65, k + 10, Blocks.air, 0, 2);
		world.setBlock(i + 20, j + 65, k + 10, Blocks.air, 0, 2);
		world.setBlock(i + 21, j + 65, k + 10, Blocks.air, 0, 2);
		world.setBlock(i + 22, j + 65, k + 10, Blocks.air, 0, 2);
		world.setBlock(i + 23, j + 65, k + 10, Blocks.air, 0, 2);
		world.setBlock(i + 24, j + 65, k + 10, Blocks.air, 0, 2);
		world.setBlock(i + 25, j + 65, k + 10, Blocks.air, 0, 2);
		world.setBlock(i + 26, j + 65, k + 10, Blocks.air, 0, 2);
		world.setBlock(i + 27, j + 65, k + 10, Blocks.air, 0, 2);
		world.setBlock(i, j + 65, k + 11, Blocks.air, 0, 2);
		world.setBlock(i + 1, j + 65, k + 11, Blocks.air, 0, 2);
		world.setBlock(i + 2, j + 65, k + 11, Blocks.air, 0, 2);
		world.setBlock(i + 3, j + 65, k + 11, Blocks.air, 0, 2);
		world.setBlock(i + 4, j + 65, k + 11, Blocks.air, 0, 2);
		world.setBlock(i + 5, j + 65, k + 11, Blocks.air, 0, 2);
		world.setBlock(i + 6, j + 65, k + 11, Blocks.air, 0, 2);
		world.setBlock(i + 7, j + 65, k + 11, Blocks.air, 0, 2);
		world.setBlock(i + 8, j + 65, k + 11, Blocks.air, 0, 2);
		world.setBlock(i + 9, j + 65, k + 11, Blocks.air, 0, 2);
		world.setBlock(i + 10, j + 65, k + 11, Blocks.air, 0, 2);
		world.setBlock(i + 11, j + 65, k + 11, Blocks.air, 0, 2);
		world.setBlock(i + 12, j + 65, k + 11, Blocks.air, 0, 2);
		world.setBlock(i + 13, j + 65, k + 11, Blocks.air, 0, 2);
		world.setBlock(i + 14, j + 65, k + 11, NovaCraftBlocks.basal_bricks, 0, 2);
		world.setBlock(i + 15, j + 65, k + 11, NovaCraftBlocks.basal_bricks, 0, 2);
		world.setBlock(i + 16, j + 65, k + 11, NovaCraftBlocks.basal_bricks, 0, 2);
		world.setBlock(i + 17, j + 65, k + 11, NovaCraftBlocks.basal_bricks, 0, 2);
		world.setBlock(i + 18, j + 65, k + 11, NovaCraftBlocks.basal_bricks, 0, 2);
		world.setBlock(i + 19, j + 65, k + 11, NovaCraftBlocks.basal_bricks, 0, 2);
		world.setBlock(i + 20, j + 65, k + 11, NovaCraftBlocks.basal_bricks, 0, 2);
		world.setBlock(i + 21, j + 65, k + 11, NovaCraftBlocks.basal_bricks, 0, 2);
		world.setBlock(i + 22, j + 65, k + 11, NovaCraftBlocks.basal, 0, 2);
		world.setBlock(i + 23, j + 65, k + 11, NovaCraftBlocks.basal, 0, 2);
		world.setBlock(i + 24, j + 65, k + 11, NovaCraftBlocks.basal_bricks, 0, 2);
		world.setBlock(i + 25, j + 65, k + 11, NovaCraftBlocks.basal, 0, 2);
		world.setBlock(i + 26, j + 65, k + 11, NovaCraftBlocks.basal_bricks, 0, 2);
		world.setBlock(i + 27, j + 65, k + 11, NovaCraftBlocks.basal, 0, 2);
		world.setBlock(i, j + 65, k + 12, Blocks.air, 0, 2);
		world.setBlock(i + 1, j + 65, k + 12, Blocks.air, 0, 2);
		world.setBlock(i + 2, j + 65, k + 12, Blocks.air, 0, 2);
		world.setBlock(i + 3, j + 65, k + 12, Blocks.air, 0, 2);
		world.setBlock(i + 4, j + 65, k + 12, Blocks.air, 0, 2);
		world.setBlock(i + 5, j + 65, k + 12, Blocks.air, 0, 2);
		world.setBlock(i + 6, j + 65, k + 12, Blocks.air, 0, 2);
		world.setBlock(i + 7, j + 65, k + 12, Blocks.air, 0, 2);
		world.setBlock(i + 8, j + 65, k + 12, Blocks.air, 0, 2);
		world.setBlock(i + 9, j + 65, k + 12, Blocks.air, 0, 2);
		world.setBlock(i + 10, j + 65, k + 12, Blocks.air, 0, 2);
		world.setBlock(i + 11, j + 65, k + 12, Blocks.air, 0, 2);
		world.setBlock(i + 12, j + 65, k + 12, Blocks.air, 0, 2);
		world.setBlock(i + 13, j + 65, k + 12, Blocks.air, 0, 2);
		world.setBlock(i + 14, j + 65, k + 12, NovaCraftBlocks.basal_bricks, 0, 2);
		world.setBlock(i + 15, j + 65, k + 12, NovaCraftBlocks.basal_bricks, 0, 2);
		world.setBlock(i + 16, j + 65, k + 12, NovaCraftBlocks.basal_bricks, 0, 2);
		world.setBlock(i + 17, j + 65, k + 12, NovaCraftBlocks.basal_bricks, 0, 2);
		world.setBlock(i + 18, j + 65, k + 12, NovaCraftBlocks.basal_bricks, 0, 2);
		world.setBlock(i + 19, j + 65, k + 12, NovaCraftBlocks.basal_bricks, 0, 2);
		world.setBlock(i + 20, j + 65, k + 12, NovaCraftBlocks.basal_bricks, 0, 2);
		world.setBlock(i + 21, j + 65, k + 12, NovaCraftBlocks.basal_bricks, 0, 2);
		world.setBlock(i + 22, j + 65, k + 12, NovaCraftBlocks.basal_bricks, 0, 2);
		world.setBlock(i + 23, j + 65, k + 12, NovaCraftBlocks.basal_bricks, 0, 2);
		world.setBlock(i + 24, j + 65, k + 12, NovaCraftBlocks.basal_bricks, 0, 2);
		world.setBlock(i + 25, j + 65, k + 12, NovaCraftBlocks.basal_bricks, 0, 2);
		world.setBlock(i + 26, j + 65, k + 12, NovaCraftBlocks.basal_bricks, 0, 2);
		world.setBlock(i + 27, j + 65, k + 12, NovaCraftBlocks.basal_bricks, 0, 2);
		world.setBlock(i, j + 66, k, NovaCraftBlocks.basal_scrap, 0, 2);
		world.setBlock(i + 5, j + 66, k, NovaCraftBlocks.basal_bricks, 0, 2);
		world.setBlock(i, j + 66, k + 1, NovaCraftBlocks.basal_scrap, 0, 2);
		world.setBlock(i + 1, j + 66, k + 1, NovaCraftBlocks.basal_bricks, 0, 2);
		world.setBlock(i + 4, j + 66, k + 1, NovaCraftBlocks.basal, 0, 2);
		world.setBlock(i + 5, j + 66, k + 1, NovaCraftBlocks.basal_bricks, 0, 2);
		world.setBlock(i + 7, j + 66, k + 1, NovaCraftBlocks.basal, 0, 2);
		world.setBlock(i + 8, j + 66, k + 1, NovaCraftBlocks.basal_bricks, 0, 2);
		world.setBlock(i, j + 66, k + 2, NovaCraftBlocks.basal_scrap, 0, 2);
		world.setBlock(i + 1, j + 66, k + 2, NovaCraftBlocks.basal_scrap, 0, 2);
		world.setBlock(i + 4, j + 66, k + 2, NovaCraftBlocks.basal_bricks, 0, 2);
		world.setBlock(i + 8, j + 66, k + 2, NovaCraftBlocks.basal_bricks, 0, 2);
		world.setBlock(i + 9, j + 66, k + 2, NovaCraftBlocks.basal_bricks, 0, 2);
		world.setBlock(i + 17, j + 66, k + 2, NovaCraftBlocks.basal_scrap, 0, 2);
		world.setBlock(i + 18, j + 66, k + 2, NovaCraftBlocks.basal_bricks, 0, 2);
		world.setBlock(i + 19, j + 66, k + 2, NovaCraftBlocks.basal_bricks, 0, 2);
		world.setBlock(i + 20, j + 66, k + 2, NovaCraftBlocks.basal_bricks, 0, 2);
		world.setBlock(i + 21, j + 66, k + 2, NovaCraftBlocks.basal_bricks, 0, 2);
		world.setBlock(i + 22, j + 66, k + 2, NovaCraftBlocks.basal_bricks, 0, 2);
		world.setBlock(i, j + 66, k + 3, NovaCraftBlocks.basal_bricks, 0, 2);
		world.setBlock(i + 1, j + 66, k + 3, NovaCraftBlocks.basal_scrap, 0, 2);
		world.setBlock(i + 4, j + 66, k + 3, NovaCraftBlocks.basal_bricks, 0, 2);
		world.setBlock(i + 5, j + 66, k + 3, NovaCraftBlocks.basal_bricks, 0, 2);
		world.setBlock(i + 8, j + 66, k + 3, NovaCraftBlocks.basal_bricks, 0, 2);
		world.setBlock(i + 9, j + 66, k + 3, NovaCraftBlocks.basal_bricks, 0, 2);
		world.setBlock(i + 12, j + 66, k + 3, NovaCraftBlocks.basal_bricks, 0, 2);
		world.setBlock(i + 13, j + 66, k + 3, NovaCraftBlocks.basal_bricks, 0, 2);
		world.setBlock(i + 14, j + 66, k + 3, NovaCraftBlocks.basal_scrap, 0, 2);
		world.setBlock(i + 15, j + 66, k + 3, NovaCraftBlocks.basal_bricks, 0, 2);
		world.setBlock(i + 17, j + 66, k + 3, NovaCraftBlocks.basal_bricks, 0, 2);
		world.setBlock(i + 18, j + 66, k + 3, NovaCraftBlocks.basal_bricks, 0, 2);
		world.setBlock(i + 19, j + 66, k + 3, NovaCraftBlocks.basal_bricks, 0, 2);
		world.setBlock(i + 20, j + 66, k + 3, NovaCraftBlocks.basal_bricks, 0, 2);
		world.setBlock(i + 21, j + 66, k + 3, NovaCraftBlocks.basal_bricks, 0, 2);
		world.setBlock(i + 22, j + 66, k + 3, NovaCraftBlocks.basal_bricks, 0, 2);
		world.setBlock(i + 23, j + 66, k + 3, NovaCraftBlocks.basal_bricks, 0, 2);
		world.setBlock(i, j + 66, k + 4, NovaCraftBlocks.basal_bricks, 0, 2);
		world.setBlock(i + 1, j + 66, k + 4, NovaCraftBlocks.basal_bricks, 0, 2);
		world.setBlock(i + 2, j + 66, k + 4, Blocks.air, 0, 2);
		world.setBlock(i + 3, j + 66, k + 4, Blocks.air, 0, 2);
		world.setBlock(i + 4, j + 66, k + 4, NovaCraftBlocks.basal_bricks, 0, 2);
		world.setBlock(i + 5, j + 66, k + 4, NovaCraftBlocks.basal_bricks, 0, 2);
		world.setBlock(i + 7, j + 66, k + 4, Blocks.air, 0, 2);
		world.setBlock(i + 8, j + 66, k + 4, NovaCraftBlocks.basal_bricks, 0, 2);
		world.setBlock(i + 9, j + 66, k + 4, NovaCraftBlocks.basal, 0, 2);
		world.setBlock(i + 10, j + 66, k + 4, Blocks.air, 0, 2);
		world.setBlock(i + 11, j + 66, k + 4, Blocks.air, 0, 2);
		world.setBlock(i + 12, j + 66, k + 4, Blocks.air, 0, 2);
		world.setBlock(i + 13, j + 66, k + 4, NovaCraftBlocks.basal_bricks, 0, 2);
		world.setBlock(i + 14, j + 66, k + 4, NovaCraftBlocks.basal_bricks, 0, 2);
		world.setBlock(i + 15, j + 66, k + 4, NovaCraftBlocks.basal_bricks, 0, 2);
		world.setBlock(i + 16, j + 66, k + 4, NovaCraftBlocks.basal_bricks, 0, 2);
		world.setBlock(i + 17, j + 66, k + 4, NovaCraftBlocks.basal_bricks, 0, 2);
		world.setBlock(i + 18, j + 66, k + 4, NovaCraftBlocks.basal_bricks, 0, 2);
		world.setBlock(i + 19, j + 66, k + 4, NovaCraftBlocks.basal_bricks, 0, 2);
		world.setBlock(i + 20, j + 66, k + 4, NovaCraftBlocks.basal, 0, 2);
		world.setBlock(i + 21, j + 66, k + 4, NovaCraftBlocks.basal_bricks, 0, 2);
		world.setBlock(i + 22, j + 66, k + 4, NovaCraftBlocks.basal_bricks, 0, 2);
		world.setBlock(i + 23, j + 66, k + 4, NovaCraftBlocks.basal_bricks, 0, 2);
		world.setBlock(i + 24, j + 66, k + 4, NovaCraftBlocks.basal_bricks, 0, 2);
		world.setBlock(i + 25, j + 66, k + 4, NovaCraftBlocks.basal_bricks, 0, 2);
		world.setBlock(i + 26, j + 66, k + 4, Blocks.air, 0, 2);
		world.setBlock(i + 27, j + 66, k + 4, NovaCraftBlocks.basal_bricks, 0, 2);
		world.setBlock(i, j + 66, k + 5, NovaCraftBlocks.basal_bricks, 0, 2);
		world.setBlock(i + 1, j + 66, k + 5, NovaCraftBlocks.basal_bricks, 0, 2);
		world.setBlock(i + 2, j + 66, k + 5, Blocks.air, 0, 2);
		world.setBlock(i + 3, j + 66, k + 5, Blocks.air, 0, 2);
		world.setBlock(i + 4, j + 66, k + 5, NovaCraftBlocks.basal_bricks, 0, 2);
		world.setBlock(i + 5, j + 66, k + 5, NovaCraftBlocks.basal_bricks, 0, 2);
		world.setBlock(i + 6, j + 66, k + 5, Blocks.air, 0, 2);
		world.setBlock(i + 7, j + 66, k + 5, Blocks.air, 0, 2);
		world.setBlock(i + 8, j + 66, k + 5, NovaCraftBlocks.basal_bricks, 0, 2);
		world.setBlock(i + 9, j + 66, k + 5, NovaCraftBlocks.basal, 0, 2);
		world.setBlock(i + 10, j + 66, k + 5, Blocks.air, 0, 2);
		world.setBlock(i + 11, j + 66, k + 5, Blocks.air, 0, 2);
		world.setBlock(i + 12, j + 66, k + 5, Blocks.air, 0, 2);
		world.setBlock(i + 13, j + 66, k + 5, Blocks.air, 0, 2);
		world.setBlock(i + 14, j + 66, k + 5, NovaCraftBlocks.basal_bricks, 0, 2);
		world.setBlock(i + 15, j + 66, k + 5, NovaCraftBlocks.basal_bricks, 0, 2);
		world.setBlock(i + 16, j + 66, k + 5, NovaCraftBlocks.basal_bricks, 0, 2);
		world.setBlock(i + 17, j + 66, k + 5, NovaCraftBlocks.basal, 0, 2);
		world.setBlock(i + 18, j + 66, k + 5, NovaCraftBlocks.basal_bricks, 0, 2);
		world.setBlock(i + 19, j + 66, k + 5, NovaCraftBlocks.basal_bricks, 0, 2);
		world.setBlock(i + 20, j + 66, k + 5, NovaCraftBlocks.basal, 0, 2);
		world.setBlock(i + 21, j + 66, k + 5, NovaCraftBlocks.basal_bricks, 0, 2);
		world.setBlock(i + 22, j + 66, k + 5, NovaCraftBlocks.basal_bricks, 0, 2);
		world.setBlock(i + 23, j + 66, k + 5, NovaCraftBlocks.basal_bricks, 0, 2);
		world.setBlock(i + 24, j + 66, k + 5, NovaCraftBlocks.basal_bricks, 0, 2);
		world.setBlock(i + 25, j + 66, k + 5, NovaCraftBlocks.basal_bricks, 0, 2);
		world.setBlock(i + 26, j + 66, k + 5, NovaCraftBlocks.basal_bricks, 0, 2);
		world.setBlock(i + 27, j + 66, k + 5, NovaCraftBlocks.basal_bricks, 0, 2);
		world.setBlock(i, j + 66, k + 6, Blocks.air, 0, 2);
		world.setBlock(i + 1, j + 66, k + 6, Blocks.air, 0, 2);
		world.setBlock(i + 2, j + 66, k + 6, Blocks.air, 0, 2);
		world.setBlock(i + 3, j + 66, k + 6, Blocks.air, 0, 2);
		world.setBlock(i + 4, j + 66, k + 6, Blocks.air, 0, 2);
		world.setBlock(i + 5, j + 66, k + 6, Blocks.air, 0, 2);
		world.setBlock(i + 6, j + 66, k + 6, Blocks.air, 0, 2);
		world.setBlock(i + 7, j + 66, k + 6, Blocks.air, 0, 2);
		world.setBlock(i + 8, j + 66, k + 6, Blocks.air, 0, 2);
		world.setBlock(i + 9, j + 66, k + 6, Blocks.air, 0, 2);
		world.setBlock(i + 10, j + 66, k + 6, Blocks.air, 0, 2);
		world.setBlock(i + 11, j + 66, k + 6, Blocks.air, 0, 2);
		world.setBlock(i + 12, j + 66, k + 6, Blocks.air, 0, 2);
		world.setBlock(i + 13, j + 66, k + 6, Blocks.air, 0, 2);
		world.setBlock(i + 14, j + 66, k + 6, NovaCraftBlocks.basal_bricks, 0, 2);
		world.setBlock(i + 15, j + 66, k + 6, NovaCraftBlocks.basal_bricks, 0, 2);
		world.setBlock(i + 16, j + 66, k + 6, NovaCraftBlocks.basal, 0, 2);
		world.setBlock(i + 17, j + 66, k + 6, NovaCraftBlocks.basal, 0, 2);
		world.setBlock(i + 18, j + 66, k + 6, NovaCraftBlocks.basal_bricks, 0, 2);
		world.setBlock(i + 19, j + 66, k + 6, NovaCraftBlocks.basal_bricks, 0, 2);
		world.setBlock(i + 20, j + 66, k + 6, NovaCraftBlocks.basal_bricks, 0, 2);
		world.setBlock(i + 21, j + 66, k + 6, NovaCraftBlocks.basal_bricks, 0, 2);
		world.setBlock(i + 22, j + 66, k + 6, NovaCraftBlocks.basal_bricks, 0, 2);
		world.setBlock(i + 23, j + 66, k + 6, NovaCraftBlocks.basal_bricks, 0, 2);
		world.setBlock(i + 24, j + 66, k + 6, NovaCraftBlocks.basal_bricks, 0, 2);
		world.setBlock(i + 25, j + 66, k + 6, NovaCraftBlocks.basal_bricks, 0, 2);
		world.setBlock(i + 26, j + 66, k + 6, NovaCraftBlocks.basal_bricks, 0, 2);
		world.setBlock(i + 27, j + 66, k + 6, NovaCraftBlocks.basal_bricks, 0, 2);
		world.setBlock(i, j + 66, k + 7, Blocks.air, 0, 2);
		world.setBlock(i + 1, j + 66, k + 7, Blocks.air, 0, 2);
		world.setBlock(i + 2, j + 66, k + 7, Blocks.air, 0, 2);
		world.setBlock(i + 3, j + 66, k + 7, Blocks.air, 0, 2);
		world.setBlock(i + 4, j + 66, k + 7, Blocks.air, 0, 2);
		world.setBlock(i + 5, j + 66, k + 7, Blocks.air, 0, 2);
		world.setBlock(i + 6, j + 66, k + 7, Blocks.air, 0, 2);
		world.setBlock(i + 7, j + 66, k + 7, Blocks.air, 0, 2);
		world.setBlock(i + 8, j + 66, k + 7, Blocks.air, 0, 2);
		world.setBlock(i + 9, j + 66, k + 7, Blocks.air, 0, 2);
		world.setBlock(i + 10, j + 66, k + 7, Blocks.air, 0, 2);
		world.setBlock(i + 11, j + 66, k + 7, Blocks.air, 0, 2);
		world.setBlock(i + 12, j + 66, k + 7, Blocks.air, 0, 2);
		world.setBlock(i + 13, j + 66, k + 7, Blocks.air, 0, 2);
		world.setBlock(i + 14, j + 66, k + 7, NovaCraftBlocks.basal_bricks, 0, 2);
		world.setBlock(i + 15, j + 66, k + 7, Blocks.air, 0, 2);
		world.setBlock(i + 16, j + 66, k + 7, NovaCraftBlocks.basal_brick_stairs, 3, 2);
		world.setBlock(i + 17, j + 66, k + 7, NovaCraftBlocks.basal_brick_stairs, 3, 2);
		world.setBlock(i + 18, j + 66, k + 7, NovaCraftBlocks.basal_bricks, 0, 2);
		world.setBlock(i + 19, j + 66, k + 7, NovaCraftBlocks.basal_bricks, 0, 2);
		world.setBlock(i + 20, j + 66, k + 7, NovaCraftBlocks.basal_brick_stairs, 3, 2);
		world.setBlock(i + 21, j + 66, k + 7, NovaCraftBlocks.basal_brick_stairs, 3, 2);
		world.setBlock(i + 22, j + 66, k + 7, NovaCraftBlocks.basal_bricks, 0, 2);
		world.setBlock(i + 23, j + 66, k + 7, NovaCraftBlocks.basal_bricks, 0, 2);
		world.setBlock(i + 24, j + 66, k + 7, NovaCraftBlocks.basal_brick_stairs, 3, 2);
		world.setBlock(i + 25, j + 66, k + 7, Blocks.air, 0, 2);
		world.setBlock(i + 26, j + 66, k + 7, NovaCraftBlocks.basal_bricks, 0, 2);
		world.setBlock(i + 27, j + 66, k + 7, Blocks.air, 0, 2);
		world.setBlock(i, j + 66, k + 8, Blocks.air, 0, 2);
		world.setBlock(i + 1, j + 66, k + 8, Blocks.air, 0, 2);
		world.setBlock(i + 2, j + 66, k + 8, Blocks.air, 0, 2);
		world.setBlock(i + 3, j + 66, k + 8, Blocks.air, 0, 2);
		world.setBlock(i + 4, j + 66, k + 8, Blocks.air, 0, 2);
		world.setBlock(i + 5, j + 66, k + 8, Blocks.air, 0, 2);
		world.setBlock(i + 6, j + 66, k + 8, Blocks.air, 0, 2);
		world.setBlock(i + 7, j + 66, k + 8, Blocks.air, 0, 2);
		world.setBlock(i + 8, j + 66, k + 8, Blocks.air, 0, 2);
		world.setBlock(i + 9, j + 66, k + 8, Blocks.air, 0, 2);
		world.setBlock(i + 10, j + 66, k + 8, Blocks.air, 0, 2);
		world.setBlock(i + 11, j + 66, k + 8, Blocks.air, 0, 2);
		world.setBlock(i + 12, j + 66, k + 8, Blocks.air, 0, 2);
		world.setBlock(i + 13, j + 66, k + 8, Blocks.air, 0, 2);
		world.setBlock(i + 14, j + 66, k + 8, Blocks.air, 0, 2);
		world.setBlock(i + 15, j + 66, k + 8, Blocks.air, 0, 2);
		world.setBlock(i + 16, j + 66, k + 8, Blocks.air, 0, 2);
		world.setBlock(i + 17, j + 66, k + 8, Blocks.air, 0, 2);
		world.setBlock(i + 18, j + 66, k + 8, Blocks.air, 0, 2);
		world.setBlock(i + 19, j + 66, k + 8, Blocks.air, 0, 2);
		world.setBlock(i + 20, j + 66, k + 8, Blocks.air, 0, 2);
		world.setBlock(i + 21, j + 66, k + 8, Blocks.air, 0, 2);
		world.setBlock(i + 22, j + 66, k + 8, Blocks.air, 0, 2);
		world.setBlock(i + 23, j + 66, k + 8, Blocks.air, 0, 2);
		world.setBlock(i + 24, j + 66, k + 8, Blocks.air, 0, 2);
		world.setBlock(i + 25, j + 66, k + 8, Blocks.air, 0, 2);
		world.setBlock(i + 26, j + 66, k + 8, Blocks.air, 0, 2);
		world.setBlock(i + 27, j + 66, k + 8, Blocks.air, 0, 2);
		world.setBlock(i, j + 66, k + 9, NovaCraftBlocks.basal_bricks, 0, 2);
		world.setBlock(i + 1, j + 66, k + 9, NovaCraftBlocks.basal_bricks, 0, 2);
		world.setBlock(i + 2, j + 66, k + 9, Blocks.air, 0, 2);
		world.setBlock(i + 3, j + 66, k + 9, Blocks.air, 0, 2);
		world.setBlock(i + 4, j + 66, k + 9, Blocks.air, 0, 2);
		world.setBlock(i + 5, j + 66, k + 9, Blocks.air, 0, 2);
		world.setBlock(i + 6, j + 66, k + 9, Blocks.air, 0, 2);
		world.setBlock(i + 7, j + 66, k + 9, Blocks.air, 0, 2);
		world.setBlock(i + 8, j + 66, k + 9, Blocks.air, 0, 2);
		world.setBlock(i + 9, j + 66, k + 9, Blocks.air, 0, 2);
		world.setBlock(i + 10, j + 66, k + 9, Blocks.air, 0, 2);
		world.setBlock(i + 11, j + 66, k + 9, Blocks.air, 0, 2);
		world.setBlock(i + 12, j + 66, k + 9, NovaCraftBlocks.basal_bricks, 0, 2);
		world.setBlock(i + 13, j + 66, k + 9, NovaCraftBlocks.basal, 0, 2);
		world.setBlock(i + 14, j + 66, k + 9, Blocks.air, 0, 2);
		world.setBlock(i + 15, j + 66, k + 9, Blocks.air, 0, 2);
		world.setBlock(i + 16, j + 66, k + 9, Blocks.air, 0, 2);
		world.setBlock(i + 17, j + 66, k + 9, Blocks.air, 0, 2);
		world.setBlock(i + 18, j + 66, k + 9, Blocks.air, 0, 2);
		world.setBlock(i + 19, j + 66, k + 9, Blocks.air, 0, 2);
		world.setBlock(i + 20, j + 66, k + 9, Blocks.air, 0, 2);
		world.setBlock(i + 21, j + 66, k + 9, Blocks.air, 0, 2);
		world.setBlock(i + 22, j + 66, k + 9, Blocks.air, 0, 2);
		world.setBlock(i + 23, j + 66, k + 9, Blocks.air, 0, 2);
		world.setBlock(i + 24, j + 66, k + 9, Blocks.air, 0, 2);
		world.setBlock(i + 25, j + 66, k + 9, Blocks.air, 0, 2);
		world.setBlock(i + 26, j + 66, k + 9, Blocks.air, 0, 2);
		world.setBlock(i + 27, j + 66, k + 9, Blocks.air, 0, 2);
		world.setBlock(i, j + 66, k + 10, NovaCraftBlocks.basal_bricks, 0, 2);
		world.setBlock(i + 1, j + 66, k + 10, NovaCraftBlocks.basal_bricks, 0, 2);
		world.setBlock(i + 2, j + 66, k + 10, Blocks.air, 0, 2);
		world.setBlock(i + 3, j + 66, k + 10, Blocks.air, 0, 2);
		world.setBlock(i + 4, j + 66, k + 10, NovaCraftBlocks.basal, 0, 2);
		world.setBlock(i + 5, j + 66, k + 10, NovaCraftBlocks.basal_bricks, 0, 2);
		world.setBlock(i + 6, j + 66, k + 10, Blocks.air, 0, 2);
		world.setBlock(i + 7, j + 66, k + 10, Blocks.air, 0, 2);
		world.setBlock(i + 8, j + 66, k + 10, Blocks.air, 0, 2);
		world.setBlock(i + 9, j + 66, k + 10, Blocks.air, 0, 2);
		world.setBlock(i + 10, j + 66, k + 10, Blocks.air, 0, 2);
		world.setBlock(i + 11, j + 66, k + 10, Blocks.air, 0, 2);
		world.setBlock(i + 12, j + 66, k + 10, Blocks.air, 0, 2);
		world.setBlock(i + 13, j + 66, k + 10, NovaCraftBlocks.basal_bricks, 0, 2);
		world.setBlock(i + 14, j + 66, k + 10, Blocks.air, 0, 2);
		world.setBlock(i + 15, j + 66, k + 10, Blocks.air, 0, 2);
		world.setBlock(i + 16, j + 66, k + 10, Blocks.air, 0, 2);
		world.setBlock(i + 17, j + 66, k + 10, Blocks.air, 0, 2);
		world.setBlock(i + 18, j + 66, k + 10, Blocks.air, 0, 2);
		world.setBlock(i + 19, j + 66, k + 10, Blocks.air, 0, 2);
		world.setBlock(i + 20, j + 66, k + 10, Blocks.air, 0, 2);
		world.setBlock(i + 21, j + 66, k + 10, Blocks.air, 0, 2);
		world.setBlock(i + 22, j + 66, k + 10, Blocks.air, 0, 2);
		world.setBlock(i + 23, j + 66, k + 10, Blocks.air, 0, 2);
		world.setBlock(i + 24, j + 66, k + 10, Blocks.air, 0, 2);
		world.setBlock(i + 25, j + 66, k + 10, Blocks.air, 0, 2);
		world.setBlock(i + 26, j + 66, k + 10, Blocks.air, 0, 2);
		world.setBlock(i + 27, j + 66, k + 10, Blocks.air, 0, 2);
		world.setBlock(i, j + 66, k + 11, Blocks.air, 0, 2);
		world.setBlock(i + 1, j + 66, k + 11, Blocks.air, 0, 2);
		world.setBlock(i + 2, j + 66, k + 11, Blocks.air, 0, 2);
		world.setBlock(i + 3, j + 66, k + 11, Blocks.air, 0, 2);
		world.setBlock(i + 4, j + 66, k + 11, Blocks.air, 0, 2);
		world.setBlock(i + 5, j + 66, k + 11, Blocks.air, 0, 2);
		world.setBlock(i + 6, j + 66, k + 11, Blocks.air, 0, 2);
		world.setBlock(i + 7, j + 66, k + 11, Blocks.air, 0, 2);
		world.setBlock(i + 8, j + 66, k + 11, Blocks.air, 0, 2);
		world.setBlock(i + 9, j + 66, k + 11, Blocks.air, 0, 2);
		world.setBlock(i + 10, j + 66, k + 11, Blocks.air, 0, 2);
		world.setBlock(i + 11, j + 66, k + 11, Blocks.air, 0, 2);
		world.setBlock(i + 12, j + 66, k + 11, Blocks.air, 0, 2);
		world.setBlock(i + 13, j + 66, k + 11, Blocks.air, 0, 2);
		world.setBlock(i + 14, j + 66, k + 11, NovaCraftBlocks.basal_bricks, 0, 2);
		world.setBlock(i + 15, j + 66, k + 11, NovaCraftBlocks.basal_bricks, 0, 2);
		world.setBlock(i + 16, j + 66, k + 11, Blocks.air, 0, 2);
		world.setBlock(i + 17, j + 66, k + 11, Blocks.air, 0, 2);
		world.setBlock(i + 18, j + 66, k + 11, NovaCraftBlocks.basal_bricks, 0, 2);
		world.setBlock(i + 19, j + 66, k + 11, NovaCraftBlocks.basal_bricks, 0, 2);
		world.setBlock(i + 20, j + 66, k + 11, Blocks.air, 0, 2);
		world.setBlock(i + 21, j + 66, k + 11, Blocks.air, 0, 2);
		world.setBlock(i + 22, j + 66, k + 11, Blocks.air, 0, 2);
		world.setBlock(i + 23, j + 66, k + 11, Blocks.air, 0, 2);
		world.setBlock(i + 24, j + 66, k + 11, Blocks.air, 0, 2);
		world.setBlock(i + 25, j + 66, k + 11, Blocks.air, 0, 2);
		world.setBlock(i + 26, j + 66, k + 11, NovaCraftBlocks.basal_bricks, 0, 2);
		world.setBlock(i + 27, j + 66, k + 11, NovaCraftBlocks.basal_bricks, 0, 2);
		world.setBlock(i, j + 66, k + 12, Blocks.air, 0, 2);
		world.setBlock(i + 1, j + 66, k + 12, Blocks.air, 0, 2);
		world.setBlock(i + 2, j + 66, k + 12, Blocks.air, 0, 2);
		world.setBlock(i + 3, j + 66, k + 12, Blocks.air, 0, 2);
		world.setBlock(i + 4, j + 66, k + 12, Blocks.air, 0, 2);
		world.setBlock(i + 5, j + 66, k + 12, Blocks.air, 0, 2);
