package com.NovaCraft.world.bastion.treasure;

import net.minecraft.world.gen.feature.*;
import net.minecraft.block.*;
import net.minecraft.world.*;
import java.util.*;

import com.NovaCraft.config.Configs;
import com.NovaCraft.registry.OtherModBlocks;
import com.NovaCraftBlocks.NovaCraftBlocks;

import cpw.mods.fml.common.Loader;
import net.minecraft.init.*;

public class BastionTreasureBarracksGen5 extends WorldGenerator
{
	public BastionTreasureBarracksGen5() {

	}
    
    public boolean generate(final World world, final Random random, final int i, final int j, final int k) {
    	
    	world.setBlock(i + 12, j + 27, k + 1, NovaCraftBlocks.basal_bricks, 0, 2);
		world.setBlock(i + 13, j + 27, k + 1, NovaCraftBlocks.basal_bricks, 0, 2);
		world.setBlock(i + 14, j + 27, k + 1, Blocks.air, 0, 2);
		world.setBlock(i + 15, j + 27, k + 1, Blocks.air, 0, 2);
		world.setBlock(i + 16, j + 27, k + 1, Blocks.air, 0, 2);
		world.setBlock(i + 17, j + 27, k + 1, Blocks.air, 0, 2);
		world.setBlock(i + 18, j + 27, k + 1, Blocks.air, 0, 2);
		world.setBlock(i + 19, j + 27, k + 1, Blocks.air, 0, 2);
		world.setBlock(i + 20, j + 27, k + 1, Blocks.air, 0, 2);
		world.setBlock(i + 21, j + 27, k + 1, Blocks.air, 0, 2);
		world.setBlock(i + 22, j + 27, k + 1, Blocks.air, 0, 2);
		world.setBlock(i + 23, j + 27, k + 1, Blocks.air, 0, 2);
		world.setBlock(i + 24, j + 27, k + 1, Blocks.air, 0, 2);
		world.setBlock(i + 25, j + 27, k + 1, Blocks.air, 0, 2);
		world.setBlock(i + 26, j + 27, k + 1, Blocks.air, 0, 2);
		world.setBlock(i + 27, j + 27, k + 1, Blocks.air, 0, 2);
		world.setBlock(i + 0, j + 27, k + 2, NovaCraftBlocks.cracked_basal_bricks, 0, 2);
		world.setBlock(i + 1, j + 27, k + 2, NovaCraftBlocks.basal_bricks, 0, 2);
		world.setBlock(i + 2, j + 27, k + 2, Blocks.air, 0, 2);
		world.setBlock(i + 3, j + 27, k + 2, Blocks.air, 0, 2);
		world.setBlock(i + 4, j + 27, k + 2, NovaCraftBlocks.cracked_basal_bricks, 0, 2);
		world.setBlock(i + 5, j + 27, k + 2, NovaCraftBlocks.cracked_basal_bricks, 0, 2);
		world.setBlock(i + 6, j + 27, k + 2, Blocks.air, 0, 2);
		world.setBlock(i + 7, j + 27, k + 2, Blocks.air, 0, 2);
		world.setBlock(i + 8, j + 27, k + 2, NovaCraftBlocks.basal_bricks, 0, 2);
		world.setBlock(i + 9, j + 27, k + 2, NovaCraftBlocks.basal_bricks, 0, 2);
		world.setBlock(i + 10, j + 27, k + 2, Blocks.air, 0, 2);
		world.setBlock(i + 11, j + 27, k + 2, Blocks.air, 0, 2);
		world.setBlock(i + 12, j + 27, k + 2, NovaCraftBlocks.basal_bricks, 0, 2);
		world.setBlock(i + 13, j + 27, k + 2, NovaCraftBlocks.basal_bricks, 0, 2);
		world.setBlock(i + 14, j + 27, k + 2, Blocks.air, 0, 2);
		world.setBlock(i + 15, j + 27, k + 2, Blocks.air, 0, 2);
		world.setBlock(i + 16, j + 27, k + 2, Blocks.air, 0, 2);
		world.setBlock(i + 17, j + 27, k + 2, Blocks.air, 0, 2);
		world.setBlock(i + 18, j + 27, k + 2, Blocks.air, 0, 2);
		world.setBlock(i + 19, j + 27, k + 2, Blocks.air, 0, 2);
		world.setBlock(i + 20, j + 27, k + 2, Blocks.air, 0, 2);
		world.setBlock(i + 21, j + 27, k + 2, Blocks.air, 0, 2);
		world.setBlock(i + 22, j + 27, k + 2, Blocks.air, 0, 2);
		world.setBlock(i + 23, j + 27, k + 2, Blocks.air, 0, 2);
		world.setBlock(i + 24, j + 27, k + 2, Blocks.air, 0, 2);
		world.setBlock(i + 25, j + 27, k + 2, Blocks.air, 0, 2);
		world.setBlock(i + 26, j + 27, k + 2, Blocks.air, 0, 2);
		world.setBlock(i + 27, j + 27, k + 2, Blocks.air, 0, 2);
		world.setBlock(i + 0, j + 27, k + 3, NovaCraftBlocks.cracked_basal_bricks, 0, 2);
		world.setBlock(i + 1, j + 27, k + 3, NovaCraftBlocks.cracked_basal_bricks, 0, 2);
		world.setBlock(i + 2, j + 27, k + 3, NovaCraftBlocks.basal_bricks, 0, 2);
		world.setBlock(i + 3, j + 27, k + 3, NovaCraftBlocks.cracked_basal_bricks, 0, 2);
		world.setBlock(i + 4, j + 27, k + 3, NovaCraftBlocks.basal_bricks, 0, 2);
		world.setBlock(i + 5, j + 27, k + 3, NovaCraftBlocks.basal_bricks, 0, 2);
		world.setBlock(i + 6, j + 27, k + 3, NovaCraftBlocks.cracked_basal_bricks, 0, 2);
		world.setBlock(i + 7, j + 27, k + 3, NovaCraftBlocks.basal_bricks, 0, 2);
		world.setBlock(i + 8, j + 27, k + 3, NovaCraftBlocks.cracked_basal_bricks, 0, 2);
		world.setBlock(i + 10, j + 27, k + 3, NovaCraftBlocks.basal_bricks, 0, 2);
		world.setBlock(i + 11, j + 27, k + 3, NovaCraftBlocks.cracked_basal_bricks, 0, 2);
		world.setBlock(i + 13, j + 27, k + 3, NovaCraftBlocks.cracked_basal_bricks, 0, 2);
		world.setBlock(i + 14, j + 27, k + 3, NovaCraftBlocks.basal_scrap, 0, 2);
		world.setBlock(i + 15, j + 27, k + 3, NovaCraftBlocks.basal_scrap, 0, 2);
		world.setBlock(i + 16, j + 27, k + 3, Blocks.air, 0, 2);
		world.setBlock(i + 17, j + 27, k + 3, Blocks.air, 0, 2);
		world.setBlock(i + 18, j + 27, k + 3, NovaCraftBlocks.basal_scrap, 0, 2);
		world.setBlock(i + 19, j + 27, k + 3, NovaCraftBlocks.cracked_basal_bricks, 0, 2);
		world.setBlock(i + 20, j + 27, k + 3, Blocks.air, 0, 2);
		world.setBlock(i + 21, j + 27, k + 3, Blocks.air, 0, 2);
		world.setBlock(i + 22, j + 27, k + 3, NovaCraftBlocks.cracked_basal_bricks, 0, 2);
		world.setBlock(i + 23, j + 27, k + 3, NovaCraftBlocks.cracked_basal_bricks, 0, 2);
		world.setBlock(i + 24, j + 27, k + 3, Blocks.air, 0, 2);
		world.setBlock(i + 25, j + 27, k + 3, Blocks.air, 0, 2);
		world.setBlock(i + 26, j + 27, k + 3, NovaCraftBlocks.basal_bricks, 0, 2);
		world.setBlock(i + 27, j + 27, k + 3, NovaCraftBlocks.basal_bricks, 0, 2);
		world.setBlock(i + 0, j + 27, k + 4, NovaCraftBlocks.basal_bricks, 0, 2);
		world.setBlock(i + 1, j + 27, k + 4, Blocks.air, 0, 2);
		world.setBlock(i + 2, j + 27, k + 4, Blocks.air, 0, 2);
		world.setBlock(i + 3, j + 27, k + 4, Blocks.air, 0, 2);
		world.setBlock(i + 4, j + 27, k + 4, Blocks.air, 0, 2);
		world.setBlock(i + 5, j + 27, k + 4, NovaCraftBlocks.basal_bricks, 0, 2);
		world.setBlock(i + 6, j + 27, k + 4, NovaCraftBlocks.basal_bricks, 0, 2);
		world.setBlock(i + 7, j + 27, k + 4, NovaCraftBlocks.cracked_basal_bricks, 0, 2);
		world.setBlock(i + 8, j + 27, k + 4, NovaCraftBlocks.basal_bricks, 0, 2);
		world.setBlock(i + 9, j + 27, k + 4, Blocks.air, 0, 2);
		world.setBlock(i + 10, j + 27, k + 4, Blocks.air, 0, 2);
		world.setBlock(i + 11, j + 27, k + 4, Blocks.air, 0, 2);
		world.setBlock(i + 12, j + 27, k + 4, Blocks.air, 0, 2);
		world.setBlock(i + 13, j + 27, k + 4, NovaCraftBlocks.basal_bricks, 0, 2);
		world.setBlock(i + 14, j + 27, k + 4, NovaCraftBlocks.cracked_basal_bricks, 0, 2);
		world.setBlock(i + 15, j + 27, k + 4, NovaCraftBlocks.basal_bricks, 0, 2);
		world.setBlock(i + 16, j + 27, k + 4, Blocks.air, 0, 2);
		world.setBlock(i + 17, j + 27, k + 4, Blocks.air, 0, 2);
		world.setBlock(i + 18, j + 27, k + 4, NovaCraftBlocks.basal_bricks, 0, 2);
		world.setBlock(i + 19, j + 27, k + 4, NovaCraftBlocks.cracked_basal_bricks, 0, 2);
		world.setBlock(i + 20, j + 27, k + 4, Blocks.air, 0, 2);
		world.setBlock(i + 21, j + 27, k + 4, Blocks.air, 0, 2);
		world.setBlock(i + 22, j + 27, k + 4, NovaCraftBlocks.basal_bricks, 0, 2);
		world.setBlock(i + 23, j + 27, k + 4, NovaCraftBlocks.basal_bricks, 0, 2);
		world.setBlock(i + 24, j + 27, k + 4, Blocks.air, 0, 2);
		world.setBlock(i + 25, j + 27, k + 4, Blocks.air, 0, 2);
		world.setBlock(i + 26, j + 27, k + 4, NovaCraftBlocks.basal_bricks, 0, 2);
		world.setBlock(i + 27, j + 27, k + 4, NovaCraftBlocks.cracked_basal_bricks, 0, 2);
		world.setBlock(i + 0, j + 27, k + 5, NovaCraftBlocks.cracked_basal_bricks, 0, 2);
		world.setBlock(i + 1, j + 27, k + 5, Blocks.air, 0, 2);
		world.setBlock(i + 2, j + 27, k + 5, Blocks.air, 0, 2);
		world.setBlock(i + 3, j + 27, k + 5, Blocks.air, 0, 2);
		world.setBlock(i + 4, j + 27, k + 5, Blocks.air, 0, 2);
		world.setBlock(i + 5, j + 27, k + 5, NovaCraftBlocks.basal_bricks, 0, 2);
		world.setBlock(i + 6, j + 27, k + 5, NovaCraftBlocks.cracked_basal_bricks, 0, 2);
		world.setBlock(i + 7, j + 27, k + 5, NovaCraftBlocks.cracked_basal_bricks, 0, 2);
		world.setBlock(i + 8, j + 27, k + 5, NovaCraftBlocks.basal_bricks, 0, 2);
		world.setBlock(i + 9, j + 27, k + 5, Blocks.air, 0, 2);
		world.setBlock(i + 10, j + 27, k + 5, Blocks.air, 0, 2);
		world.setBlock(i + 11, j + 27, k + 5, Blocks.air, 0, 2);
		world.setBlock(i + 12, j + 27, k + 5, Blocks.air, 0, 2);
		world.setBlock(i + 13, j + 27, k + 5, NovaCraftBlocks.basal_bricks, 0, 2);
		world.setBlock(i + 14, j + 27, k + 5, NovaCraftBlocks.basal_bricks, 0, 2);
		world.setBlock(i + 15, j + 27, k + 5, NovaCraftBlocks.cracked_basal_bricks, 0, 2);
		world.setBlock(i + 16, j + 27, k + 5, NovaCraftBlocks.basal_bricks, 0, 2);
		world.setBlock(i + 17, j + 27, k + 5, NovaCraftBlocks.basal_bricks, 0, 2);
		world.setBlock(i + 18, j + 27, k + 5, NovaCraftBlocks.basal_bricks, 0, 2);
		world.setBlock(i + 19, j + 27, k + 5, NovaCraftBlocks.cracked_basal_bricks, 0, 2);
		world.setBlock(i + 20, j + 27, k + 5, NovaCraftBlocks.cracked_basal_bricks, 0, 2);
		world.setBlock(i + 21, j + 27, k + 5, NovaCraftBlocks.basal_bricks, 0, 2);
		world.setBlock(i + 22, j + 27, k + 5, NovaCraftBlocks.basal_bricks, 0, 2);
		world.setBlock(i + 23, j + 27, k + 5, NovaCraftBlocks.cracked_basal_bricks, 0, 2);
		world.setBlock(i + 24, j + 27, k + 5, NovaCraftBlocks.cracked_basal_bricks, 0, 2);
		world.setBlock(i + 25, j + 27, k + 5, NovaCraftBlocks.basal_bricks, 0, 2);
		world.setBlock(i + 26, j + 27, k + 5, NovaCraftBlocks.basal_bricks, 0, 2);
		world.setBlock(i + 27, j + 27, k + 5, NovaCraftBlocks.cracked_basal_bricks, 0, 2);
		world.setBlock(i + 0, j + 27, k + 6, NovaCraftBlocks.cracked_basal_bricks, 0, 2);
		world.setBlock(i + 1, j + 27, k + 6, Blocks.air, 0, 2);
		world.setBlock(i + 2, j + 27, k + 6, Blocks.air, 0, 2);
		world.setBlock(i + 3, j + 27, k + 6, Blocks.air, 0, 2);
		world.setBlock(i + 4, j + 27, k + 6, Blocks.air, 0, 2);
		world.setBlock(i + 5, j + 27, k + 6, NovaCraftBlocks.basal_bricks, 0, 2);
		world.setBlock(i + 6, j + 27, k + 6, NovaCraftBlocks.basal_bricks, 0, 2);
		world.setBlock(i + 7, j + 27, k + 6, NovaCraftBlocks.cracked_basal_bricks, 0, 2);
		world.setBlock(i + 8, j + 27, k + 6, Blocks.air, 0, 2);
		world.setBlock(i + 9, j + 27, k + 6, Blocks.air, 0, 2);
		world.setBlock(i + 10, j + 27, k + 6, Blocks.air, 0, 2);
		world.setBlock(i + 11, j + 27, k + 6, Blocks.air, 0, 2);
		world.setBlock(i + 12, j + 27, k + 6, Blocks.air, 0, 2);
		world.setBlock(i + 13, j + 27, k + 6, NovaCraftBlocks.cracked_basal_bricks, 0, 2);
		world.setBlock(i + 14, j + 27, k + 6, NovaCraftBlocks.basal_bricks, 0, 2);
		world.setBlock(i + 15, j + 27, k + 6, Blocks.air, 0, 2);
		world.setBlock(i + 16, j + 27, k + 6, Blocks.air, 0, 2);
		world.setBlock(i + 17, j + 27, k + 6, Blocks.air, 0, 2);
		world.setBlock(i + 18, j + 27, k + 6, Blocks.air, 0, 2);
		world.setBlock(i + 19, j + 27, k + 6, NovaCraftBlocks.basal_bricks, 0, 2);
		world.setBlock(i + 20, j + 27, k + 6, NovaCraftBlocks.basal_bricks, 0, 2);
		world.setBlock(i + 21, j + 27, k + 6, NovaCraftBlocks.cracked_basal_bricks, 0, 2);
		world.setBlock(i + 22, j + 27, k + 6, NovaCraftBlocks.basal_bricks, 0, 2);
		world.setBlock(i + 23, j + 27, k + 6, NovaCraftBlocks.cracked_basal_bricks, 0, 2);
		world.setBlock(i + 24, j + 27, k + 6, Blocks.air, 0, 2);
		world.setBlock(i + 25, j + 27, k + 6, Blocks.air, 0, 2);
		world.setBlock(i + 26, j + 27, k + 6, Blocks.air, 0, 2);
		world.setBlock(i + 27, j + 27, k + 6, NovaCraftBlocks.cracked_basal_bricks, 0, 2);
		world.setBlock(i + 0, j + 27, k + 7, NovaCraftBlocks.cracked_basal_bricks, 0, 2);
		world.setBlock(i + 1, j + 27, k + 7, Blocks.air, 0, 2);
		world.setBlock(i + 2, j + 27, k + 7, Blocks.air, 0, 2);
		world.setBlock(i + 3, j + 27, k + 7, Blocks.air, 0, 2);
		world.setBlock(i + 4, j + 27, k + 7, Blocks.air, 0, 2);
		world.setBlock(i + 5, j + 27, k + 7, NovaCraftBlocks.cracked_basal_bricks, 0, 2);
		world.setBlock(i + 6, j + 27, k + 7, NovaCraftBlocks.cracked_basal_bricks, 0, 2);
		world.setBlock(i + 7, j + 27, k + 7, NovaCraftBlocks.basal_bricks, 0, 2);
		world.setBlock(i + 8, j + 27, k + 7, Blocks.air, 0, 2);
		world.setBlock(i + 9, j + 27, k + 7, Blocks.air, 0, 2);
		world.setBlock(i + 10, j + 27, k + 7, Blocks.air, 0, 2);
		world.setBlock(i + 11, j + 27, k + 7, Blocks.air, 0, 2);
		world.setBlock(i + 12, j + 27, k + 7, Blocks.air, 0, 2);
		world.setBlock(i + 13, j + 27, k + 7, NovaCraftBlocks.cracked_basal_bricks, 0, 2);
		world.setBlock(i + 14, j + 27, k + 7, NovaCraftBlocks.cracked_basal_bricks, 0, 2);
		world.setBlock(i + 15, j + 27, k + 7, Blocks.air, 0, 2);
		world.setBlock(i + 16, j + 27, k + 7, Blocks.air, 0, 2);
		world.setBlock(i + 17, j + 27, k + 7, Blocks.air, 0, 2);
		world.setBlock(i + 18, j + 27, k + 7, Blocks.air, 0, 2);
		world.setBlock(i + 19, j + 27, k + 7, NovaCraftBlocks.cracked_basal_bricks, 0, 2);
		world.setBlock(i + 20, j + 27, k + 7, NovaCraftBlocks.basal_bricks, 0, 2);
		world.setBlock(i + 21, j + 27, k + 7, NovaCraftBlocks.basal_bricks, 0, 2);
		world.setBlock(i + 22, j + 27, k + 7, NovaCraftBlocks.basal_bricks, 0, 2);
		world.setBlock(i + 23, j + 27, k + 7, Blocks.air, 0, 2);
		world.setBlock(i + 24, j + 27, k + 7, Blocks.air, 0, 2);
		world.setBlock(i + 25, j + 27, k + 7, Blocks.air, 0, 2);
		world.setBlock(i + 26, j + 27, k + 7, Blocks.air, 0, 2);
		world.setBlock(i + 27, j + 27, k + 7, NovaCraftBlocks.cracked_basal_bricks, 0, 2);
		world.setBlock(i + 0, j + 27, k + 8, NovaCraftBlocks.basal_bricks, 0, 2);
		world.setBlock(i + 1, j + 27, k + 8, NovaCraftBlocks.basal_bricks, 0, 2);
		world.setBlock(i + 2, j + 27, k + 8, NovaCraftBlocks.basal_bricks, 0, 2);
		world.setBlock(i + 3, j + 27, k + 8, NovaCraftBlocks.basal_bricks, 0, 2);
		world.setBlock(i + 4, j + 27, k + 8, NovaCraftBlocks.basal_bricks, 0, 2);
		world.setBlock(i + 5, j + 27, k + 8, NovaCraftBlocks.basal_bricks, 0, 2);
		world.setBlock(i + 6, j + 27, k + 8, NovaCraftBlocks.basal_bricks, 0, 2);
		world.setBlock(i + 7, j + 27, k + 8, NovaCraftBlocks.basal_bricks, 0, 2);
		world.setBlock(i + 8, j + 27, k + 8, Blocks.air, 0, 2);
		world.setBlock(i + 9, j + 27, k + 8, Blocks.air, 0, 2);
		world.setBlock(i + 10, j + 27, k + 8, Blocks.air, 0, 2);
		world.setBlock(i + 11, j + 27, k + 8, NovaCraftBlocks.basal_bricks, 0, 2);
		world.setBlock(i + 12, j + 27, k + 8, NovaCraftBlocks.cracked_basal_bricks, 0, 2);
		world.setBlock(i + 13, j + 27, k + 8, NovaCraftBlocks.basal_bricks, 0, 2);
		world.setBlock(i + 14, j + 27, k + 8, NovaCraftBlocks.cracked_basal_bricks, 0, 2);
		world.setBlock(i + 15, j + 27, k + 8, Blocks.air, 0, 2);
		world.setBlock(i + 16, j + 27, k + 8, Blocks.air, 0, 2);
		world.setBlock(i + 17, j + 27, k + 8, Blocks.air, 0, 2);
		world.setBlock(i + 18, j + 27, k + 8, NovaCraftBlocks.basal_bricks, 0, 2);
		world.setBlock(i + 19, j + 27, k + 8, NovaCraftBlocks.cracked_basal_bricks, 0, 2);
		world.setBlock(i + 20, j + 27, k + 8, NovaCraftBlocks.basal_bricks, 0, 2);
		world.setBlock(i + 21, j + 27, k + 8, NovaCraftBlocks.cracked_basal_bricks, 0, 2);
		world.setBlock(i + 22, j + 27, k + 8, Blocks.air, 0, 2);
		world.setBlock(i + 23, j + 27, k + 8, Blocks.air, 0, 2);
		world.setBlock(i + 24, j + 27, k + 8, Blocks.air, 0, 2);
		world.setBlock(i + 25, j + 27, k + 8, Blocks.air, 0, 2);
		world.setBlock(i + 26, j + 27, k + 8, Blocks.air, 0, 2);
		world.setBlock(i + 27, j + 27, k + 8, NovaCraftBlocks.basal_bricks, 0, 2);
		world.setBlock(i + 0, j + 27, k + 9, NovaCraftBlocks.basal_bricks, 0, 2);
		world.setBlock(i + 1, j + 27, k + 9, NovaCraftBlocks.basal_bricks, 0, 2);
		world.setBlock(i + 2, j + 27, k + 9, NovaCraftBlocks.basal_bricks, 0, 2);
		world.setBlock(i + 3, j + 27, k + 9, NovaCraftBlocks.basal_bricks, 0, 2);
		world.setBlock(i + 4, j + 27, k + 9, NovaCraftBlocks.cracked_basal_bricks, 0, 2);
		world.setBlock(i + 5, j + 27, k + 9, NovaCraftBlocks.cracked_basal_bricks, 0, 2);
		world.setBlock(i + 6, j + 27, k + 9, NovaCraftBlocks.basal_bricks, 0, 2);
		world.setBlock(i + 7, j + 27, k + 9, NovaCraftBlocks.basal_bricks, 0, 2);
		world.setBlock(i + 8, j + 27, k + 9, NovaCraftBlocks.basal_bricks, 0, 2);
		world.setBlock(i + 9, j + 27, k + 9, NovaCraftBlocks.basal_bricks, 0, 2);
		world.setBlock(i + 10, j + 27, k + 9, NovaCraftBlocks.cracked_basal_bricks, 0, 2);
		world.setBlock(i + 11, j + 27, k + 9, NovaCraftBlocks.basal_bricks, 0, 2);
		world.setBlock(i + 12, j + 27, k + 9, NovaCraftBlocks.basal_bricks, 0, 2);
		world.setBlock(i + 13, j + 27, k + 9, NovaCraftBlocks.cracked_basal_bricks, 0, 2);
		world.setBlock(i + 14, j + 27, k + 9, NovaCraftBlocks.cracked_basal_bricks, 0, 2);
		world.setBlock(i + 15, j + 27, k + 9, Blocks.air, 0, 2);
		world.setBlock(i + 16, j + 27, k + 9, Blocks.air, 0, 2);
		world.setBlock(i + 17, j + 27, k + 9, Blocks.air, 0, 2);
		world.setBlock(i + 18, j + 27, k + 9, Blocks.air, 0, 2);
		world.setBlock(i + 19, j + 27, k + 9, Blocks.air, 0, 2);
		world.setBlock(i + 20, j + 27, k + 9, Blocks.air, 0, 2);
		world.setBlock(i + 21, j + 27, k + 9, Blocks.air, 0, 2);
		world.setBlock(i + 22, j + 27, k + 9, Blocks.air, 0, 2);
		world.setBlock(i + 23, j + 27, k + 9, Blocks.air, 0, 2);
		world.setBlock(i + 24, j + 27, k + 9, NovaCraftBlocks.cracked_basal_bricks, 0, 2);
		world.setBlock(i + 25, j + 27, k + 9, Blocks.air, 0, 2);
		world.setBlock(i + 26, j + 27, k + 9, Blocks.air, 0, 2);
		world.setBlock(i + 27, j + 27, k + 9, NovaCraftBlocks.basal_bricks, 0, 2);
		world.setBlock(i + 0, j + 27, k + 10, Blocks.air, 0, 2);
		world.setBlock(i + 1, j + 27, k + 10, NovaCraftBlocks.basal_bricks, 0, 2);
		world.setBlock(i + 2, j + 27, k + 10, NovaCraftBlocks.basal_bricks, 0, 2);
		world.setBlock(i + 3, j + 27, k + 10, NovaCraftBlocks.basal_bricks, 0, 2);
		world.setBlock(i + 4, j + 27, k + 10, NovaCraftBlocks.basal_bricks, 0, 2);
		world.setBlock(i + 5, j + 27, k + 10, NovaCraftBlocks.basal_bricks, 0, 2);
		world.setBlock(i + 6, j + 27, k + 10, NovaCraftBlocks.basal_bricks, 0, 2);
		world.setBlock(i + 7, j + 27, k + 10, NovaCraftBlocks.basal_bricks, 0, 2);
		world.setBlock(i + 8, j + 27, k + 10, NovaCraftBlocks.cracked_basal_bricks, 0, 2);
		world.setBlock(i + 9, j + 27, k + 10, NovaCraftBlocks.basal_bricks, 0, 2);
		world.setBlock(i + 10, j + 27, k + 10, NovaCraftBlocks.basal_bricks, 0, 2);
		world.setBlock(i + 11, j + 27, k + 10, NovaCraftBlocks.cracked_basal_bricks, 0, 2);
		world.setBlock(i + 12, j + 27, k + 10, NovaCraftBlocks.cracked_basal_bricks, 0, 2);
		world.setBlock(i + 13, j + 27, k + 10, NovaCraftBlocks.basal_bricks, 0, 2);
		world.setBlock(i + 14, j + 27, k + 10, NovaCraftBlocks.basal_bricks, 0, 2);
		world.setBlock(i + 15, j + 27, k + 10, NovaCraftBlocks.basal_bricks, 0, 2);
		world.setBlock(i + 16, j + 27, k + 10, NovaCraftBlocks.cracked_basal_bricks, 0, 2);
		world.setBlock(i + 17, j + 27, k + 10, Blocks.air, 0, 2);
		world.setBlock(i + 18, j + 27, k + 10, Blocks.air, 0, 2);
		world.setBlock(i + 19, j + 27, k + 10, Blocks.air, 0, 2);
		world.setBlock(i + 20, j + 27, k + 10, Blocks.air, 0, 2);
		world.setBlock(i + 21, j + 27, k + 10, Blocks.air, 0, 2);
		world.setBlock(i + 22, j + 27, k + 10, Blocks.air, 0, 2);
		world.setBlock(i + 23, j + 27, k + 10, NovaCraftBlocks.basal_bricks, 0, 2);
		world.setBlock(i + 24, j + 27, k + 10, NovaCraftBlocks.basal_bricks, 0, 2);
		world.setBlock(i + 25, j + 27, k + 10, NovaCraftBlocks.cracked_basal_bricks, 0, 2);
		world.setBlock(i + 26, j + 27, k + 10, NovaCraftBlocks.cracked_basal_bricks, 0, 2);
		world.setBlock(i + 27, j + 27, k + 10, NovaCraftBlocks.cracked_basal_bricks, 0, 2);
		world.setBlock(i + 0, j + 27, k + 11, NovaCraftBlocks.cracked_basal_bricks, 0, 2);
		world.setBlock(i + 1, j + 27, k + 11, NovaCraftBlocks.basal_bricks, 0, 2);
		world.setBlock(i + 2, j + 27, k + 11, NovaCraftBlocks.cracked_basal_bricks, 0, 2);
		world.setBlock(i + 3, j + 27, k + 11, NovaCraftBlocks.basal_bricks, 0, 2);
		world.setBlock(i + 4, j + 27, k + 11, NovaCraftBlocks.cracked_basal_bricks, 0, 2);
		world.setBlock(i + 5, j + 27, k + 11, NovaCraftBlocks.basal_bricks, 0, 2);
		world.setBlock(i + 6, j + 27, k + 11, NovaCraftBlocks.basal_bricks, 0, 2);
		world.setBlock(i + 7, j + 27, k + 11, NovaCraftBlocks.cracked_basal_bricks, 0, 2);
		world.setBlock(i + 8, j + 27, k + 11, NovaCraftBlocks.cracked_basal_bricks, 0, 2);
		world.setBlock(i + 9, j + 27, k + 11, NovaCraftBlocks.basal_bricks, 0, 2);
		world.setBlock(i + 10, j + 27, k + 11, NovaCraftBlocks.basal_bricks, 0, 2);
		world.setBlock(i + 11, j + 27, k + 11, NovaCraftBlocks.basal_bricks, 0, 2);
		world.setBlock(i + 12, j + 27, k + 11, NovaCraftBlocks.basal_bricks, 0, 2);
		world.setBlock(i + 13, j + 27, k + 11, NovaCraftBlocks.cracked_basal_bricks, 0, 2);
		world.setBlock(i + 14, j + 27, k + 11, NovaCraftBlocks.cracked_basal_bricks, 0, 2);
		world.setBlock(i + 15, j + 27, k + 11, NovaCraftBlocks.basal_bricks, 0, 2);
		world.setBlock(i + 16, j + 27, k + 11, NovaCraftBlocks.basal_bricks, 0, 2);
		world.setBlock(i + 17, j + 27, k + 11, NovaCraftBlocks.basal_bricks, 0, 2);
		world.setBlock(i + 18, j + 27, k + 11, NovaCraftBlocks.cracked_basal_bricks, 0, 2);
		world.setBlock(i + 19, j + 27, k + 11, NovaCraftBlocks.basal_bricks, 0, 2);
		world.setBlock(i + 20, j + 27, k + 11, NovaCraftBlocks.basal_bricks, 0, 2);
		world.setBlock(i + 21, j + 27, k + 11, NovaCraftBlocks.basal_bricks, 0, 2);
		world.setBlock(i + 22, j + 27, k + 11, NovaCraftBlocks.cracked_basal_bricks, 0, 2);
		world.setBlock(i + 23, j + 27, k + 11, NovaCraftBlocks.basal_bricks, 0, 2);
		world.setBlock(i + 24, j + 27, k + 11, NovaCraftBlocks.cracked_basal_bricks, 0, 2);
		world.setBlock(i + 25, j + 27, k + 11, NovaCraftBlocks.basal_bricks, 0, 2);
		world.setBlock(i + 26, j + 27, k + 11, NovaCraftBlocks.cracked_basal_bricks, 0, 2);
		world.setBlock(i + 27, j + 27, k + 11, NovaCraftBlocks.basal_bricks, 0, 2);
		world.setBlock(i + 0, j + 27, k + 12, NovaCraftBlocks.cracked_basal_bricks, 0, 2);
		world.setBlock(i + 1, j + 27, k + 12, NovaCraftBlocks.basal_bricks, 0, 2);
		world.setBlock(i + 2, j + 27, k + 12, NovaCraftBlocks.basal_bricks, 0, 2);
		world.setBlock(i + 3, j + 27, k + 12, NovaCraftBlocks.basal_bricks, 0, 2);
		world.setBlock(i + 4, j + 27, k + 12, NovaCraftBlocks.basal_bricks, 0, 2);
		world.setBlock(i + 5, j + 27, k + 12, NovaCraftBlocks.cracked_basal_bricks, 0, 2);
		world.setBlock(i + 6, j + 27, k + 12, NovaCraftBlocks.cracked_basal_bricks, 0, 2);
		world.setBlock(i + 7, j + 27, k + 12, NovaCraftBlocks.cracked_basal_bricks, 0, 2);
		world.setBlock(i + 8, j + 27, k + 12, NovaCraftBlocks.cracked_basal_bricks, 0, 2);
		world.setBlock(i + 9, j + 27, k + 12, NovaCraftBlocks.basal_bricks, 0, 2);
		world.setBlock(i + 10, j + 27, k + 12, NovaCraftBlocks.basal_bricks, 0, 2);
		world.setBlock(i + 11, j + 27, k + 12, NovaCraftBlocks.basal_bricks, 0, 2);
		world.setBlock(i + 12, j + 27, k + 12, NovaCraftBlocks.cracked_basal_bricks, 0, 2);
		world.setBlock(i + 13, j + 27, k + 12, NovaCraftBlocks.basal_bricks, 0, 2);
		world.setBlock(i + 14, j + 27, k + 12, NovaCraftBlocks.basal_bricks, 0, 2);
		world.setBlock(i + 15, j + 27, k + 12, NovaCraftBlocks.cracked_basal_bricks, 0, 2);
		world.setBlock(i + 16, j + 27, k + 12, NovaCraftBlocks.basal_bricks, 0, 2);
		world.setBlock(i + 17, j + 27, k + 12, NovaCraftBlocks.cracked_basal_bricks, 0, 2);
		world.setBlock(i + 18, j + 27, k + 12, NovaCraftBlocks.basal_bricks, 0, 2);
		world.setBlock(i + 19, j + 27, k + 12, NovaCraftBlocks.basal_bricks, 0, 2);
		world.setBlock(i + 20, j + 27, k + 12, NovaCraftBlocks.basal_bricks, 0, 2);
		world.setBlock(i + 21, j + 27, k + 12, NovaCraftBlocks.cracked_basal_bricks, 0, 2);
		world.setBlock(i + 22, j + 27, k + 12, NovaCraftBlocks.cracked_basal_bricks, 0, 2);
		world.setBlock(i + 23, j + 27, k + 12, NovaCraftBlocks.basal_bricks, 0, 2);
		world.setBlock(i + 24, j + 27, k + 12, NovaCraftBlocks.basal_bricks, 0, 2);
		world.setBlock(i + 25, j + 27, k + 12, NovaCraftBlocks.basal_bricks, 0, 2);
		world.setBlock(i + 26, j + 27, k + 12, NovaCraftBlocks.basal_bricks, 0, 2);
		world.setBlock(i + 27, j + 27, k + 12, NovaCraftBlocks.basal_bricks, 0, 2);
		world.setBlock(i + 0, j + 28, k + 0, Blocks.air, 0, 2);
		world.setBlock(i + 1, j + 28, k + 0, Blocks.air, 0, 2);
		world.setBlock(i + 2, j + 28, k + 0, Blocks.air, 0, 2);
		world.setBlock(i + 3, j + 28, k + 0, Blocks.air, 0, 2);
		world.setBlock(i + 4, j + 28, k + 0, Blocks.air, 0, 2);
		world.setBlock(i + 5, j + 28, k + 0, Blocks.air, 0, 2);
		world.setBlock(i + 6, j + 28, k + 0, Blocks.air, 0, 2);
		world.setBlock(i + 7, j + 28, k + 0, Blocks.air, 0, 2);
		world.setBlock(i + 8, j + 28, k + 0, Blocks.air, 0, 2);
		world.setBlock(i + 9, j + 28, k + 0, Blocks.air, 0, 2);
		world.setBlock(i + 10, j + 28, k + 0, Blocks.air, 0, 2);
		world.setBlock(i + 11, j + 28, k + 0, Blocks.air, 0, 2);
		world.setBlock(i + 12, j + 28, k + 0, Blocks.air, 0, 2);
		world.setBlock(i + 13, j + 28, k + 0, Blocks.air, 0, 2);
		world.setBlock(i + 14, j + 28, k + 0, Blocks.air, 0, 2);
		world.setBlock(i + 15, j + 28, k + 0, Blocks.air, 0, 2);
		world.setBlock(i + 16, j + 28, k + 0, Blocks.air, 0, 2);
		world.setBlock(i + 17, j + 28, k + 0, Blocks.air, 0, 2);
		world.setBlock(i + 18, j + 28, k + 0, Blocks.air, 0, 2);
		world.setBlock(i + 19, j + 28, k + 0, Blocks.air, 0, 2);
		world.setBlock(i + 20, j + 28, k + 0, Blocks.air, 0, 2);
		world.setBlock(i + 21, j + 28, k + 0, Blocks.air, 0, 2);
		world.setBlock(i + 22, j + 28, k + 0, Blocks.air, 0, 2);
		world.setBlock(i + 23, j + 28, k + 0, Blocks.air, 0, 2);
		world.setBlock(i + 24, j + 28, k + 0, Blocks.air, 0, 2);
		world.setBlock(i + 25, j + 28, k + 0, Blocks.air, 0, 2);
		world.setBlock(i + 26, j + 28, k + 0, Blocks.air, 0, 2);
		world.setBlock(i + 27, j + 28, k + 0, Blocks.air, 0, 2);
		world.setBlock(i + 0, j + 28, k + 1, NovaCraftBlocks.basal_scrap, 0, 2);
		world.setBlock(i + 1, j + 28, k + 1, NovaCraftBlocks.basal_scrap, 0, 2);
		world.setBlock(i + 2, j + 28, k + 1, Blocks.air, 0, 2);
		world.setBlock(i + 3, j + 28, k + 1, Blocks.air, 0, 2);
		world.setBlock(i + 4, j + 28, k + 1, NovaCraftBlocks.basal_scrap, 0, 2);
		world.setBlock(i + 5, j + 28, k + 1, NovaCraftBlocks.basal_scrap, 0, 2);
		world.setBlock(i + 6, j + 28, k + 1, Blocks.air, 0, 2);
		world.setBlock(i + 7, j + 28, k + 1, Blocks.air, 0, 2);
		world.setBlock(i + 8, j + 28, k + 1, NovaCraftBlocks.basal_bricks, 0, 2);
		world.setBlock(i + 9, j + 28, k + 1, NovaCraftBlocks.basal_bricks, 0, 2);
		world.setBlock(i + 10, j + 28, k + 1, Blocks.air, 0, 2);
		world.setBlock(i + 11, j + 28, k + 1, Blocks.air, 0, 2);
		world.setBlock(i + 12, j + 28, k + 1, NovaCraftBlocks.basal_bricks, 0, 2);
		world.setBlock(i + 13, j + 28, k + 1, NovaCraftBlocks.basal_bricks, 0, 2);
		world.setBlock(i + 14, j + 28, k + 1, Blocks.air, 0, 2);
		world.setBlock(i + 15, j + 28, k + 1, Blocks.air, 0, 2);
		world.setBlock(i + 16, j + 28, k + 1, Blocks.air, 0, 2);
		world.setBlock(i + 17, j + 28, k + 1, Blocks.air, 0, 2);
		world.setBlock(i + 18, j + 28, k + 1, Blocks.air, 0, 2);
		world.setBlock(i + 19, j + 28, k + 1, Blocks.air, 0, 2);
		world.setBlock(i + 20, j + 28, k + 1, Blocks.air, 0, 2);
		world.setBlock(i + 21, j + 28, k + 1, Blocks.air, 0, 2);
		world.setBlock(i + 22, j + 28, k + 1, Blocks.air, 0, 2);
		world.setBlock(i + 23, j + 28, k + 1, Blocks.air, 0, 2);
		world.setBlock(i + 24, j + 28, k + 1, Blocks.air, 0, 2);
		world.setBlock(i + 25, j + 28, k + 1, Blocks.air, 0, 2);
		world.setBlock(i + 26, j + 28, k + 1, Blocks.air, 0, 2);
		world.setBlock(i + 27, j + 28, k + 1, Blocks.air, 0, 2);
		world.setBlock(i + 0, j + 28, k + 2, NovaCraftBlocks.cracked_basal_bricks, 0, 2);
		world.setBlock(i + 1, j + 28, k + 2, NovaCraftBlocks.basal_bricks, 0, 2);
		world.setBlock(i + 2, j + 28, k + 2, Blocks.air, 0, 2);
		world.setBlock(i + 3, j + 28, k + 2, Blocks.air, 0, 2);
		world.setBlock(i + 4, j + 28, k + 2, NovaCraftBlocks.basal_bricks, 0, 2);
		world.setBlock(i + 5, j + 28, k + 2, NovaCraftBlocks.basal_bricks, 0, 2);
		world.setBlock(i + 6, j + 28, k + 2, Blocks.air, 0, 2);
		world.setBlock(i + 7, j + 28, k + 2, Blocks.air, 0, 2);
		world.setBlock(i + 8, j + 28, k + 2, NovaCraftBlocks.basal_bricks, 0, 2);
		world.setBlock(i + 9, j + 28, k + 2, NovaCraftBlocks.basal_bricks, 0, 2);
		world.setBlock(i + 10, j + 28, k + 2, Blocks.air, 0, 2);
		world.setBlock(i + 11, j + 28, k + 2, Blocks.air, 0, 2);
		world.setBlock(i + 12, j + 28, k + 2, NovaCraftBlocks.basal_bricks, 0, 2);
		world.setBlock(i + 13, j + 28, k + 2, NovaCraftBlocks.basal_bricks, 0, 2);
		world.setBlock(i + 14, j + 28, k + 2, Blocks.air, 0, 2);
		world.setBlock(i + 15, j + 28, k + 2, Blocks.air, 0, 2);
		world.setBlock(i + 16, j + 28, k + 2, Blocks.air, 0, 2);
		world.setBlock(i + 17, j + 28, k + 2, Blocks.air, 0, 2);
		world.setBlock(i + 18, j + 28, k + 2, Blocks.air, 0, 2);
		world.setBlock(i + 19, j + 28, k + 2, Blocks.air, 0, 2);
		world.setBlock(i + 20, j + 28, k + 2, Blocks.air, 0, 2);
		world.setBlock(i + 21, j + 28, k + 2, Blocks.air, 0, 2);
		world.setBlock(i + 22, j + 28, k + 2, Blocks.air, 0, 2);
		world.setBlock(i + 23, j + 28, k + 2, Blocks.air, 0, 2);
		world.setBlock(i + 24, j + 28, k + 2, Blocks.air, 0, 2);
		world.setBlock(i + 25, j + 28, k + 2, Blocks.air, 0, 2);
		world.setBlock(i + 26, j + 28, k + 2, Blocks.air, 0, 2);
		world.setBlock(i + 27, j + 28, k + 2, Blocks.air, 0, 2);
		world.setBlock(i + 0, j + 28, k + 3, NovaCraftBlocks.basal_bricks, 0, 2);
		world.setBlock(i + 1, j + 28, k + 3, NovaCraftBlocks.basal_bricks, 0, 2);
		world.setBlock(i + 2, j + 28, k + 3, NovaCraftBlocks.cracked_basal_bricks, 0, 2);
		world.setBlock(i + 3, j + 28, k + 3, NovaCraftBlocks.basal_bricks, 0, 2);
		world.setBlock(i + 4, j + 28, k + 3, NovaCraftBlocks.cracked_basal_bricks, 0, 2);
		world.setBlock(i + 5, j + 28, k + 3, NovaCraftBlocks.basal_bricks, 0, 2);
		world.setBlock(i + 6, j + 28, k + 3, NovaCraftBlocks.cracked_basal_bricks, 0, 2);
		world.setBlock(i + 7, j + 28, k + 3, NovaCraftBlocks.basal_bricks, 0, 2);
		world.setBlock(i + 8, j + 28, k + 3, NovaCraftBlocks.cracked_basal_bricks, 0, 2);
		world.setBlock(i + 9, j + 28, k + 3, NovaCraftBlocks.cracked_basal_bricks, 0, 2);
		world.setBlock(i + 10, j + 28, k + 3, NovaCraftBlocks.basal_bricks, 0, 2);
		world.setBlock(i + 11, j + 28, k + 3, NovaCraftBlocks.cracked_basal_bricks, 0, 2);
		world.setBlock(i + 12, j + 28, k + 3, NovaCraftBlocks.cracked_basal_bricks, 0, 2);
		world.setBlock(i + 13, j + 28, k + 3, NovaCraftBlocks.cracked_basal_bricks, 0, 2);
		world.setBlock(i + 14, j + 28, k + 3, NovaCraftBlocks.basal_scrap, 0, 2);
		world.setBlock(i + 15, j + 28, k + 3, NovaCraftBlocks.basal_scrap, 0, 2);
		world.setBlock(i + 16, j + 28, k + 3, Blocks.air, 0, 2);
		world.setBlock(i + 17, j + 28, k + 3, Blocks.air, 0, 2);
		world.setBlock(i + 18, j + 28, k + 3, NovaCraftBlocks.basal_scrap, 0, 2);
		world.setBlock(i + 19, j + 28, k + 3, NovaCraftBlocks.basal_scrap, 0, 2);
		world.setBlock(i + 20, j + 28, k + 3, Blocks.air, 0, 2);
		world.setBlock(i + 21, j + 28, k + 3, Blocks.air, 0, 2);
		world.setBlock(i + 22, j + 28, k + 3, NovaCraftBlocks.basal_bricks, 0, 2);
		world.setBlock(i + 23, j + 28, k + 3, NovaCraftBlocks.cracked_basal_bricks, 0, 2);
		world.setBlock(i + 24, j + 28, k + 3, Blocks.air, 0, 2);
		world.setBlock(i + 25, j + 28, k + 3, Blocks.air, 0, 2);
		world.setBlock(i + 26, j + 28, k + 3, NovaCraftBlocks.basal_bricks, 0, 2);
		world.setBlock(i + 27, j + 28, k + 3, NovaCraftBlocks.basal_bricks, 0, 2);
		world.setBlock(i + 0, j + 28, k + 4, NovaCraftBlocks.cracked_basal_bricks, 0, 2);
		world.setBlock(i + 1, j + 28, k + 4, Blocks.air, 0, 2);
		world.setBlock(i + 2, j + 28, k + 4, Blocks.air, 0, 2);
		world.setBlock(i + 3, j + 28, k + 4, Blocks.air, 0, 2);
		world.setBlock(i + 4, j + 28, k + 4, NovaCraftBlocks.basal_bricks, 0, 2);
		world.setBlock(i + 5, j + 28, k + 4, NovaCraftBlocks.basal_bricks, 0, 2);
		world.setBlock(i + 6, j + 28, k + 4, NovaCraftBlocks.cracked_basal_bricks, 0, 2);
		world.setBlock(i + 7, j + 28, k + 4, NovaCraftBlocks.basal_bricks, 0, 2);
		world.setBlock(i + 8, j + 28, k + 4, NovaCraftBlocks.basal_bricks, 0, 2);
		world.setBlock(i + 9, j + 28, k + 4, NovaCraftBlocks.cracked_basal_bricks, 0, 2);
		world.setBlock(i + 10, j + 28, k + 4, NovaCraftBlocks.basal_bricks, 0, 2);
		world.setBlock(i + 11, j + 28, k + 4, NovaCraftBlocks.basal_bricks, 0, 2);
		world.setBlock(i + 12, j + 28, k + 4, NovaCraftBlocks.cracked_basal_bricks, 0, 2);
		world.setBlock(i + 13, j + 28, k + 4, NovaCraftBlocks.basal_bricks, 0, 2);
		world.setBlock(i + 14, j + 28, k + 4, NovaCraftBlocks.cracked_basal_bricks, 0, 2);
		world.setBlock(i + 15, j + 28, k + 4, NovaCraftBlocks.cracked_basal_bricks, 0, 2);
		world.setBlock(i + 16, j + 28, k + 4, Blocks.air, 0, 2);
		world.setBlock(i + 17, j + 28, k + 4, Blocks.air, 0, 2);
		world.setBlock(i + 18, j + 28, k + 4, NovaCraftBlocks.basal_bricks, 0, 2);
		world.setBlock(i + 19, j + 28, k + 4, NovaCraftBlocks.basal_bricks, 0, 2);
		world.setBlock(i + 20, j + 28, k + 4, Blocks.air, 0, 2);
		world.setBlock(i + 21, j + 28, k + 4, Blocks.air, 0, 2);
		world.setBlock(i + 22, j + 28, k + 4, NovaCraftBlocks.cracked_basal_bricks, 0, 2);
		world.setBlock(i + 23, j + 28, k + 4, NovaCraftBlocks.basal_bricks, 0, 2);
		world.setBlock(i + 24, j + 28, k + 4, Blocks.air, 0, 2);
		world.setBlock(i + 25, j + 28, k + 4, Blocks.air, 0, 2);
		world.setBlock(i + 26, j + 28, k + 4, NovaCraftBlocks.cracked_basal_bricks, 0, 2);
		world.setBlock(i + 27, j + 28, k + 4, NovaCraftBlocks.basal_bricks, 0, 2);
		world.setBlock(i + 0, j + 28, k + 5, NovaCraftBlocks.basal_bricks, 0, 2);
		world.setBlock(i + 1, j + 28, k + 5, Blocks.air, 0, 2);
		world.setBlock(i + 2, j + 28, k + 5, Blocks.air, 0, 2);
		world.setBlock(i + 3, j + 28, k + 5, NovaCraftBlocks.basal_bricks, 0, 2);
		world.setBlock(i + 4, j + 28, k + 5, Blocks.air, 0, 2);
		world.setBlock(i + 5, j + 28, k + 5, NovaCraftBlocks.basal_bricks, 0, 2);
		world.setBlock(i + 6, j + 28, k + 5, NovaCraftBlocks.basal_bricks, 0, 2);
		world.setBlock(i + 7, j + 28, k + 5, NovaCraftBlocks.basal_bricks, 0, 2);
		world.setBlock(i + 8, j + 28, k + 5, NovaCraftBlocks.basal_bricks, 0, 2);
		world.setBlock(i + 9, j + 28, k + 5, NovaCraftBlocks.basal_bricks, 0, 2);
		world.setBlock(i + 10, j + 28, k + 5, NovaCraftBlocks.basal_bricks, 0, 2);
		world.setBlock(i + 11, j + 28, k + 5, Blocks.air, 0, 2);
		world.setBlock(i + 12, j + 28, k + 5, Blocks.air, 0, 2);
		world.setBlock(i + 13, j + 28, k + 5, NovaCraftBlocks.basal_bricks, 0, 2);
		world.setBlock(i + 14, j + 28, k + 5, NovaCraftBlocks.basal_bricks, 0, 2);
		world.setBlock(i + 15, j + 28, k + 5, NovaCraftBlocks.basal_bricks, 0, 2);
		world.setBlock(i + 16, j + 28, k + 5, NovaCraftBlocks.basal_bricks, 0, 2);
		world.setBlock(i + 17, j + 28, k + 5, NovaCraftBlocks.basal_bricks, 0, 2);
		world.setBlock(i + 18, j + 28, k + 5, NovaCraftBlocks.basal_bricks, 0, 2);
		world.setBlock(i + 19, j + 28, k + 5, NovaCraftBlocks.basal_bricks, 0, 2);
		world.setBlock(i + 20, j + 28, k + 5, NovaCraftBlocks.basal_bricks, 0, 2);
		world.setBlock(i + 21, j + 28, k + 5, NovaCraftBlocks.basal_bricks, 0, 2);
		world.setBlock(i + 22, j + 28, k + 5, NovaCraftBlocks.basal_bricks, 0, 2);
		world.setBlock(i + 23, j + 28, k + 5, NovaCraftBlocks.basal_bricks, 0, 2);
		world.setBlock(i + 24, j + 28, k + 5, NovaCraftBlocks.basal_bricks, 0, 2);
		world.setBlock(i + 25, j + 28, k + 5, NovaCraftBlocks.basal_bricks, 0, 2);
		world.setBlock(i + 26, j + 28, k + 5, NovaCraftBlocks.basal_bricks, 0, 2);
		world.setBlock(i + 27, j + 28, k + 5, NovaCraftBlocks.cracked_basal_bricks, 0, 2);
		world.setBlock(i + 0, j + 28, k + 6, NovaCraftBlocks.basal_bricks, 0, 2);
		world.setBlock(i + 1, j + 28, k + 6, Blocks.air, 0, 2);
		world.setBlock(i + 2, j + 28, k + 6, Blocks.air, 0, 2);
		world.setBlock(i + 3, j + 28, k + 6, NovaCraftBlocks.basal_bricks, 0, 2);
		world.setBlock(i + 4, j + 28, k + 6, NovaCraftBlocks.cracked_basal_bricks, 0, 2);
		world.setBlock(i + 5, j + 28, k + 6, NovaCraftBlocks.cracked_basal_bricks, 0, 2);
		world.setBlock(i + 6, j + 28, k + 6, NovaCraftBlocks.basal_bricks, 0, 2);
		world.setBlock(i + 7, j + 28, k + 6, NovaCraftBlocks.basal_bricks, 0, 2);
		world.setBlock(i + 8, j + 28, k + 6, NovaCraftBlocks.basal_bricks, 0, 2);
		world.setBlock(i + 9, j + 28, k + 6, NovaCraftBlocks.basal_bricks, 0, 2);
		world.setBlock(i + 10, j + 28, k + 6, NovaCraftBlocks.basal_bricks, 0, 2);
		world.setBlock(i + 11, j + 28, k + 6, Blocks.air, 0, 2);
		world.setBlock(i + 12, j + 28, k + 6, Blocks.air, 0, 2);
		world.setBlock(i + 13, j + 28, k + 6, NovaCraftBlocks.cracked_basal_bricks, 0, 2);
		world.setBlock(i + 14, j + 28, k + 6, NovaCraftBlocks.basal_bricks, 0, 2);
		world.setBlock(i + 15, j + 28, k + 6, NovaCraftBlocks.basal_bricks, 0, 2);
		world.setBlock(i + 16, j + 28, k + 6, NovaCraftBlocks.cracked_basal_bricks, 0, 2);
		world.setBlock(i + 17, j + 28, k + 6, NovaCraftBlocks.cracked_basal_bricks, 0, 2);
		world.setBlock(i + 18, j + 28, k + 6, NovaCraftBlocks.cracked_basal_bricks, 0, 2);
		world.setBlock(i + 19, j + 28, k + 6, NovaCraftBlocks.cracked_basal_bricks, 0, 2);
		world.setBlock(i + 20, j + 28, k + 6, NovaCraftBlocks.cracked_basal_bricks, 0, 2);
		world.setBlock(i + 21, j + 28, k + 6, NovaCraftBlocks.basal_bricks, 0, 2);
		world.setBlock(i + 22, j + 28, k + 6, NovaCraftBlocks.cracked_basal_bricks, 0, 2);
		world.setBlock(i + 23, j + 28, k + 6, NovaCraftBlocks.basal_bricks, 0, 2);
		world.setBlock(i + 24, j + 28, k + 6, NovaCraftBlocks.cracked_basal_bricks, 0, 2);
		world.setBlock(i + 25, j + 28, k + 6, NovaCraftBlocks.basal_bricks, 0, 2);
		world.setBlock(i + 26, j + 28, k + 6, NovaCraftBlocks.basal_bricks, 0, 2);
		world.setBlock(i + 27, j + 28, k + 6, NovaCraftBlocks.cracked_basal_bricks, 0, 2);
		world.setBlock(i + 0, j + 28, k + 7, NovaCraftBlocks.basal_bricks, 0, 2);
		world.setBlock(i + 1, j + 28, k + 7, Blocks.air, 0, 2);
		world.setBlock(i + 2, j + 28, k + 7, Blocks.air, 0, 2);
		world.setBlock(i + 3, j + 28, k + 7, NovaCraftBlocks.basal_bricks, 0, 2);
		world.setBlock(i + 4, j + 28, k + 7, NovaCraftBlocks.basal_bricks, 0, 2);
		world.setBlock(i + 5, j + 28, k + 7, NovaCraftBlocks.cracked_basal_bricks, 0, 2);
		world.setBlock(i + 6, j + 28, k + 7, NovaCraftBlocks.cracked_basal_bricks, 0, 2);
		world.setBlock(i + 7, j + 28, k + 7, NovaCraftBlocks.basal_bricks, 0, 2);
		world.setBlock(i + 8, j + 28, k + 7, NovaCraftBlocks.cracked_basal_bricks, 0, 2);
		world.setBlock(i + 9, j + 28, k + 7, NovaCraftBlocks.cracked_basal_bricks, 0, 2);
		world.setBlock(i + 10, j + 28, k + 7, NovaCraftBlocks.basal_bricks, 0, 2);
		world.setBlock(i + 11, j + 28, k + 7, Blocks.air, 0, 2);
		world.setBlock(i + 12, j + 28, k + 7, Blocks.air, 0, 2);
		world.setBlock(i + 13, j + 28, k + 7, NovaCraftBlocks.basal_bricks, 0, 2);
		world.setBlock(i + 14, j + 28, k + 7, NovaCraftBlocks.cracked_basal_bricks, 0, 2);
		world.setBlock(i + 15, j + 28, k + 7, Blocks.air, 0, 2);
		world.setBlock(i + 16, j + 28, k + 7, Blocks.air, 0, 2);
		world.setBlock(i + 17, j + 28, k + 7, NovaCraftBlocks.basal_bricks, 0, 2);
		world.setBlock(i + 18, j + 28, k + 7, NovaCraftBlocks.basal_bricks, 0, 2);
		world.setBlock(i + 19, j + 28, k + 7, NovaCraftBlocks.basal_bricks, 0, 2);
		world.setBlock(i + 20, j + 28, k + 7, NovaCraftBlocks.basal_bricks, 0, 2);
		world.setBlock(i + 21, j + 28, k + 7, NovaCraftBlocks.basal_bricks, 0, 2);
		world.setBlock(i + 22, j + 28, k + 7, NovaCraftBlocks.cracked_basal_bricks, 0, 2);
		world.setBlock(i + 23, j + 28, k + 7, NovaCraftBlocks.basal_bricks, 0, 2);
		world.setBlock(i + 24, j + 28, k + 7, NovaCraftBlocks.basal_bricks, 0, 2);
		world.setBlock(i + 25, j + 28, k + 7, NovaCraftBlocks.cracked_basal_bricks, 0, 2);
		world.setBlock(i + 26, j + 28, k + 7, NovaCraftBlocks.cracked_basal_bricks, 0, 2);
		world.setBlock(i + 27, j + 28, k + 7, NovaCraftBlocks.cracked_basal_bricks, 0, 2);
		world.setBlock(i + 0, j + 28, k + 8, NovaCraftBlocks.cracked_basal_bricks, 0, 2);
		world.setBlock(i + 1, j + 28, k + 8, Blocks.air, 0, 2);
		world.setBlock(i + 2, j + 28, k + 8, Blocks.air, 0, 2);
		world.setBlock(i + 3, j + 28, k + 8, NovaCraftBlocks.cracked_basal_bricks, 0, 2);
		world.setBlock(i + 4, j + 28, k + 8, NovaCraftBlocks.basal_bricks, 0, 2);
		world.setBlock(i + 5, j + 28, k + 8, NovaCraftBlocks.cracked_basal_bricks, 0, 2);
		world.setBlock(i + 6, j + 28, k + 8, NovaCraftBlocks.basal_bricks, 0, 2);
		world.setBlock(i + 7, j + 28, k + 8, NovaCraftBlocks.basal_bricks, 0, 2);
		world.setBlock(i + 8, j + 28, k + 8, NovaCraftBlocks.basal_bricks, 0, 2);
		world.setBlock(i + 9, j + 28, k + 8, NovaCraftBlocks.cracked_basal_bricks, 0, 2);
		world.setBlock(i + 10, j + 28, k + 8, NovaCraftBlocks.basal_bricks, 0, 2);
		world.setBlock(i + 11, j + 28, k + 8, Blocks.air, 0, 2);
		world.setBlock(i + 12, j + 28, k + 8, Blocks.air, 0, 2);
		world.setBlock(i + 13, j + 28, k + 8, NovaCraftBlocks.basal_bricks, 0, 2);
		world.setBlock(i + 14, j + 28, k + 8, NovaCraftBlocks.cracked_basal_bricks, 0, 2);
		world.setBlock(i + 15, j + 28, k + 8, Blocks.air, 0, 2);
		world.setBlock(i + 16, j + 28, k + 8, Blocks.air, 0, 2);
		world.setBlock(i + 17, j + 28, k + 8, Blocks.air, 0, 2);
		world.setBlock(i + 18, j + 28, k + 8, NovaCraftBlocks.cracked_basal_bricks, 0, 2);
		world.setBlock(i + 19, j + 28, k + 8, NovaCraftBlocks.cracked_basal_bricks, 0, 2);
		world.setBlock(i + 20, j + 28, k + 8, NovaCraftBlocks.cracked_basal_bricks, 0, 2);
		world.setBlock(i + 21, j + 28, k + 8, NovaCraftBlocks.basal_bricks, 0, 2);
		world.setBlock(i + 22, j + 28, k + 8, NovaCraftBlocks.basal_bricks, 0, 2);
		world.setBlock(i + 23, j + 28, k + 8, NovaCraftBlocks.cracked_basal_bricks, 0, 2);
		world.setBlock(i + 24, j + 28, k + 8, NovaCraftBlocks.basal_bricks, 0, 2);
		world.setBlock(i + 25, j + 28, k + 8, Blocks.air, 0, 2);
		world.setBlock(i + 26, j + 28, k + 8, Blocks.air, 0, 2);
		world.setBlock(i + 27, j + 28, k + 8, NovaCraftBlocks.basal_bricks, 0, 2);
		world.setBlock(i + 0, j + 28, k + 9, NovaCraftBlocks.basal_bricks, 0, 2);
		world.setBlock(i + 1, j + 28, k + 9, NovaCraftBlocks.basal_bricks, 0, 2);
		world.setBlock(i + 2, j + 28, k + 9, NovaCraftBlocks.basal_bricks, 0, 2);
		world.setBlock(i + 3, j + 28, k + 9, NovaCraftBlocks.cracked_basal_bricks, 0, 2);
		world.setBlock(i + 4, j + 28, k + 9, NovaCraftBlocks.cracked_basal_bricks, 0, 2);
		world.setBlock(i + 5, j + 28, k + 9, NovaCraftBlocks.basal_bricks, 0, 2);
		world.setBlock(i + 6, j + 28, k + 9, NovaCraftBlocks.basal_bricks, 0, 2);
		world.setBlock(i + 7, j + 28, k + 9, NovaCraftBlocks.cracked_basal_bricks, 0, 2);
		world.setBlock(i + 8, j + 28, k + 9, NovaCraftBlocks.basal_bricks, 0, 2);
		world.setBlock(i + 9, j + 28, k + 9, NovaCraftBlocks.cracked_basal_bricks, 0, 2);
		world.setBlock(i + 10, j + 28, k + 9, NovaCraftBlocks.basal_bricks, 0, 2);
		world.setBlock(i + 11, j + 28, k + 9, NovaCraftBlocks.basal_bricks, 0, 2);
		world.setBlock(i + 12, j + 28, k + 9, NovaCraftBlocks.basal_bricks, 0, 2);
		world.setBlock(i + 13, j + 28, k + 9, NovaCraftBlocks.cracked_basal_bricks, 0, 2);
		world.setBlock(i + 14, j + 28, k + 9, NovaCraftBlocks.cracked_basal_bricks, 0, 2);
		world.setBlock(i + 15, j + 28, k + 9, Blocks.air, 0, 2);
		world.setBlock(i + 16, j + 28, k + 9, Blocks.air, 0, 2);
		world.setBlock(i + 17, j + 28, k + 9, Blocks.air, 0, 2);
		world.setBlock(i + 18, j + 28, k + 9, NovaCraftBlocks.basal_bricks, 0, 2);
		world.setBlock(i + 19, j + 28, k + 9, NovaCraftBlocks.basal_bricks, 0, 2);
		world.setBlock(i + 20, j + 28, k + 9, NovaCraftBlocks.basal_bricks, 0, 2);
		world.setBlock(i + 21, j + 28, k + 9, NovaCraftBlocks.basal_bricks, 0, 2);
		world.setBlock(i + 22, j + 28, k + 9, NovaCraftBlocks.cracked_basal_bricks, 0, 2);
		world.setBlock(i + 23, j + 28, k + 9, NovaCraftBlocks.basal_bricks, 0, 2);
		world.setBlock(i + 24, j + 28, k + 9, NovaCraftBlocks.cracked_basal_bricks, 0, 2);
		world.setBlock(i + 25, j + 28, k + 9, Blocks.air, 0, 2);
		world.setBlock(i + 26, j + 28, k + 9, Blocks.air, 0, 2);
		world.setBlock(i + 27, j + 28, k + 9, NovaCraftBlocks.basal_bricks, 0, 2);
		world.setBlock(i + 0, j + 28, k + 10, NovaCraftBlocks.cracked_basal_bricks, 0, 2);
		world.setBlock(i + 1, j + 28, k + 10, NovaCraftBlocks.basal_bricks, 0, 2);
		world.setBlock(i + 2, j + 28, k + 10, NovaCraftBlocks.basal_bricks, 0, 2);
		world.setBlock(i + 3, j + 28, k + 10, NovaCraftBlocks.basal_bricks, 0, 2);
		world.setBlock(i + 4, j + 28, k + 10, NovaCraftBlocks.cracked_basal_bricks, 0, 2);
		world.setBlock(i + 5, j + 28, k + 10, NovaCraftBlocks.basal_bricks, 0, 2);
		world.setBlock(i + 6, j + 28, k + 10, NovaCraftBlocks.cracked_basal_bricks, 0, 2);
		world.setBlock(i + 7, j + 28, k + 10, NovaCraftBlocks.basal_bricks, 0, 2);
		world.setBlock(i + 8, j + 28, k + 10, NovaCraftBlocks.basal_bricks, 0, 2);
		world.setBlock(i + 9, j + 28, k + 10, NovaCraftBlocks.basal_bricks, 0, 2);
		world.setBlock(i + 10, j + 28, k + 10, NovaCraftBlocks.cracked_basal_bricks, 0, 2);
		world.setBlock(i + 11, j + 28, k + 10, NovaCraftBlocks.basal_bricks, 0, 2);
		world.setBlock(i + 12, j + 28, k + 10, NovaCraftBlocks.basal_bricks, 0, 2);
		world.setBlock(i + 13, j + 28, k + 10, NovaCraftBlocks.basal_bricks, 0, 2);
		world.setBlock(i + 14, j + 28, k + 10, NovaCraftBlocks.basal_bricks, 0, 2);
		world.setBlock(i + 15, j + 28, k + 10, Blocks.air, 0, 2);
		world.setBlock(i + 16, j + 28, k + 10, Blocks.air, 0, 2);
		world.setBlock(i + 17, j + 28, k + 10, NovaCraftBlocks.cracked_basal_bricks, 0, 2);
		world.setBlock(i + 18, j + 28, k + 10, NovaCraftBlocks.basal_bricks, 0, 2);
		world.setBlock(i + 19, j + 28, k + 10, NovaCraftBlocks.basal_bricks, 0, 2);
		world.setBlock(i + 20, j + 28, k + 10, NovaCraftBlocks.basal_bricks, 0, 2);
		world.setBlock(i + 21, j + 28, k + 10, NovaCraftBlocks.basal_bricks, 0, 2);
		world.setBlock(i + 22, j + 28, k + 10, NovaCraftBlocks.cracked_basal_bricks, 0, 2);
		world.setBlock(i + 23, j + 28, k + 10, NovaCraftBlocks.basal_bricks, 0, 2);
		world.setBlock(i + 24, j + 28, k + 10, NovaCraftBlocks.basal_bricks, 0, 2);
		world.setBlock(i + 25, j + 28, k + 10, Blocks.air, 0, 2);
		world.setBlock(i + 26, j + 28, k + 10, Blocks.air, 0, 2);
		world.setBlock(i + 27, j + 28, k + 10, NovaCraftBlocks.basal_bricks, 0, 2);
		world.setBlock(i + 0, j + 28, k + 11, NovaCraftBlocks.cracked_basal_bricks, 0, 2);
		world.setBlock(i + 1, j + 28, k + 11, Blocks.lava, 0, 2);
		world.setBlock(i + 2, j + 28, k + 11, Blocks.lava, 0, 2);
		world.setBlock(i + 3, j + 28, k + 11, Blocks.lava, 0, 2);
		world.setBlock(i + 4, j + 28, k + 11, Blocks.lava, 0, 2);
		world.setBlock(i + 5, j + 28, k + 11, Blocks.lava, 0, 2);
		world.setBlock(i + 6, j + 28, k + 11, Blocks.lava, 0, 2);
		world.setBlock(i + 7, j + 28, k + 11, Blocks.lava, 0, 2);
		world.setBlock(i + 8, j + 28, k + 11, Blocks.lava, 0, 2);
		world.setBlock(i + 9, j + 28, k + 11, Blocks.lava, 0, 2);
		world.setBlock(i + 10, j + 28, k + 11, Blocks.lava, 0, 2);
		world.setBlock(i + 11, j + 28, k + 11, Blocks.lava, 0, 2);
		world.setBlock(i + 12, j + 28, k + 11, Blocks.lava, 0, 2);
		world.setBlock(i + 13, j + 28, k + 11, NovaCraftBlocks.basal_bricks, 0, 2);
		world.setBlock(i + 14, j + 28, k + 11, NovaCraftBlocks.basal_bricks, 0, 2);
		world.setBlock(i + 15, j + 28, k + 11, NovaCraftBlocks.basal_bricks, 0, 2);
		world.setBlock(i + 16, j + 28, k + 11, NovaCraftBlocks.basal_bricks, 0, 2);
		world.setBlock(i + 17, j + 28, k + 11, NovaCraftBlocks.basal_bricks, 0, 2);
		world.setBlock(i + 18, j + 28, k + 11, NovaCraftBlocks.cracked_basal_bricks, 0, 2);
		world.setBlock(i + 19, j + 28, k + 11, NovaCraftBlocks.basal_bricks, 0, 2);
		world.setBlock(i + 20, j + 28, k + 11, NovaCraftBlocks.basal_bricks, 0, 2);
		world.setBlock(i + 21, j + 28, k + 11, NovaCraftBlocks.basal_bricks, 0, 2);
		world.setBlock(i + 22, j + 28, k + 11, NovaCraftBlocks.cracked_basal_bricks, 0, 2);
		world.setBlock(i + 23, j + 28, k + 11, NovaCraftBlocks.basal_bricks, 0, 2);
		world.setBlock(i + 24, j + 28, k + 11, NovaCraftBlocks.cracked_basal_bricks, 0, 2);
		world.setBlock(i + 25, j + 28, k + 11, Blocks.air, 0, 2);
		world.setBlock(i + 26, j + 28, k + 11, Blocks.air, 0, 2);
		world.setBlock(i + 27, j + 28, k + 11, NovaCraftBlocks.cracked_basal_bricks, 0, 2);
		world.setBlock(i + 0, j + 28, k + 12, NovaCraftBlocks.basal_bricks, 0, 2);
		world.setBlock(i + 1, j + 28, k + 12, Blocks.lava, 0, 2);
		world.setBlock(i + 2, j + 28, k + 12, Blocks.lava, 0, 2);
		world.setBlock(i + 3, j + 28, k + 12, Blocks.lava, 0, 2);
		world.setBlock(i + 4, j + 28, k + 12, Blocks.lava, 0, 2);
		world.setBlock(i + 5, j + 28, k + 12, Blocks.lava, 0, 2);
		world.setBlock(i + 6, j + 28, k + 12, Blocks.lava, 0, 2);
		world.setBlock(i + 7, j + 28, k + 12, Blocks.lava, 0, 2);
		world.setBlock(i + 8, j + 28, k + 12, Blocks.lava, 0, 2);
		world.setBlock(i + 9, j + 28, k + 12, Blocks.lava, 0, 2);
		world.setBlock(i + 10, j + 28, k + 12, Blocks.lava, 0, 2);
		world.setBlock(i + 11, j + 28, k + 12, Blocks.lava, 0, 2);
		world.setBlock(i + 12, j + 28, k + 12, Blocks.lava, 0, 2);
		world.setBlock(i + 13, j + 28, k + 12, NovaCraftBlocks.basal_bricks, 0, 2);
		world.setBlock(i + 14, j + 28, k + 12, NovaCraftBlocks.cracked_basal_bricks, 0, 2);
		world.setBlock(i + 15, j + 28, k + 12, NovaCraftBlocks.cracked_basal_bricks, 0, 2);
		world.setBlock(i + 16, j + 28, k + 12, NovaCraftBlocks.cracked_basal_bricks, 0, 2);
		world.setBlock(i + 17, j + 28, k + 12, NovaCraftBlocks.basal_bricks, 0, 2);
		world.setBlock(i + 18, j + 28, k + 12, NovaCraftBlocks.basal_bricks, 0, 2);
		world.setBlock(i + 19, j + 28, k + 12, NovaCraftBlocks.basal_bricks, 0, 2);
		world.setBlock(i + 20, j + 28, k + 12, NovaCraftBlocks.cracked_basal_bricks, 0, 2);
		world.setBlock(i + 21, j + 28, k + 12, NovaCraftBlocks.cracked_basal_bricks, 0, 2);
		world.setBlock(i + 22, j + 28, k + 12, NovaCraftBlocks.basal_bricks, 0, 2);
		world.setBlock(i + 23, j + 28, k + 12, NovaCraftBlocks.basal_bricks, 0, 2);
		world.setBlock(i + 24, j + 28, k + 12, NovaCraftBlocks.cracked_basal_bricks, 0, 2);
		world.setBlock(i + 25, j + 28, k + 12, NovaCraftBlocks.basal_bricks, 0, 2);
		world.setBlock(i + 26, j + 28, k + 12, NovaCraftBlocks.cracked_basal_bricks, 0, 2);
		world.setBlock(i + 27, j + 28, k + 12, NovaCraftBlocks.basal_bricks, 0, 2);
		world.setBlock(i + 0, j + 29, k + 0, Blocks.air, 0, 2);
		world.setBlock(i + 1, j + 29, k + 0, Blocks.air, 0, 2);
		world.setBlock(i + 2, j + 29, k + 0, Blocks.air, 0, 2);
		world.setBlock(i + 3, j + 29, k + 0, Blocks.air, 0, 2);
		world.setBlock(i + 4, j + 29, k + 0, Blocks.air, 0, 2);
		world.setBlock(i + 5, j + 29, k + 0, Blocks.air, 0, 2);
		world.setBlock(i + 6, j + 29, k + 0, Blocks.air, 0, 2);
		world.setBlock(i + 7, j + 29, k + 0, Blocks.air, 0, 2);
		world.setBlock(i + 8, j + 29, k + 0, Blocks.air, 0, 2);
		world.setBlock(i + 9, j + 29, k + 0, Blocks.air, 0, 2);
		world.setBlock(i + 10, j + 29, k + 0, Blocks.air, 0, 2);
		world.setBlock(i + 11, j + 29, k + 0, Blocks.air, 0, 2);
		world.setBlock(i + 12, j + 29, k + 0, Blocks.air, 0, 2);
		world.setBlock(i + 13, j + 29, k + 0, Blocks.air, 0, 2);
		world.setBlock(i + 14, j + 29, k + 0, Blocks.air, 0, 2);
		world.setBlock(i + 15, j + 29, k + 0, Blocks.air, 0, 2);
		world.setBlock(i + 16, j + 29, k + 0, Blocks.air, 0, 2);
		world.setBlock(i + 17, j + 29, k + 0, Blocks.air, 0, 2);
		world.setBlock(i + 18, j + 29, k + 0, Blocks.air, 0, 2);
		world.setBlock(i + 19, j + 29, k + 0, Blocks.air, 0, 2);
		world.setBlock(i + 20, j + 29, k + 0, Blocks.air, 0, 2);
		world.setBlock(i + 21, j + 29, k + 0, Blocks.air, 0, 2);
		world.setBlock(i + 22, j + 29, k + 0, Blocks.air, 0, 2);
		world.setBlock(i + 23, j + 29, k + 0, Blocks.air, 0, 2);
		world.setBlock(i + 24, j + 29, k + 0, Blocks.air, 0, 2);
		world.setBlock(i + 25, j + 29, k + 0, Blocks.air, 0, 2);
		world.setBlock(i + 26, j + 29, k + 0, Blocks.air, 0, 2);
		world.setBlock(i + 27, j + 29, k + 0, Blocks.air, 0, 2);
		world.setBlock(i + 0, j + 29, k + 1, Blocks.air, 0, 2);
		world.setBlock(i + 1, j + 29, k + 1, NovaCraftBlocks.basal_scrap, 0, 2);
		world.setBlock(i + 2, j + 29, k + 1, Blocks.air, 0, 2);
		world.setBlock(i + 3, j + 29, k + 1, Blocks.air, 0, 2);
		world.setBlock(i + 4, j + 29, k + 1, NovaCraftBlocks.basal_scrap, 0, 2);
		world.setBlock(i + 5, j + 29, k + 1, NovaCraftBlocks.basal_scrap, 0, 2);
		world.setBlock(i + 6, j + 29, k + 1, Blocks.air, 0, 2);
		world.setBlock(i + 7, j + 29, k + 1, Blocks.air, 0, 2);
		world.setBlock(i + 8, j + 29, k + 1, Blocks.air, 0, 2);
		world.setBlock(i + 9, j + 29, k + 1, Blocks.air, 0, 2);
		world.setBlock(i + 10, j + 29, k + 1, Blocks.air, 0, 2);
		world.setBlock(i + 11, j + 29, k + 1, Blocks.air, 0, 2);
		world.setBlock(i + 12, j + 29, k + 1, Blocks.air, 0, 2);
		world.setBlock(i + 13, j + 29, k + 1, Blocks.air, 0, 2);
		world.setBlock(i + 14, j + 29, k + 1, Blocks.air, 0, 2);
		world.setBlock(i + 15, j + 29, k + 1, Blocks.air, 0, 2);
		world.setBlock(i + 16, j + 29, k + 1, Blocks.air, 0, 2);
		world.setBlock(i + 17, j + 29, k + 1, Blocks.air, 0, 2);
		world.setBlock(i + 18, j + 29, k + 1, Blocks.air, 0, 2);
		world.setBlock(i + 19, j + 29, k + 1, Blocks.air, 0, 2);
		world.setBlock(i + 20, j + 29, k + 1, Blocks.air, 0, 2);
		world.setBlock(i + 21, j + 29, k + 1, Blocks.air, 0, 2);
		world.setBlock(i + 22, j + 29, k + 1, Blocks.air, 0, 2);
		world.setBlock(i + 23, j + 29, k + 1, Blocks.air, 0, 2);
		world.setBlock(i + 24, j + 29, k + 1, Blocks.air, 0, 2);
		world.setBlock(i + 25, j + 29, k + 1, Blocks.air, 0, 2);
		world.setBlock(i + 26, j + 29, k + 1, Blocks.air, 0, 2);
		world.setBlock(i + 27, j + 29, k + 1, Blocks.air, 0, 2);
		world.setBlock(i + 0, j + 29, k + 2, NovaCraftBlocks.basal_bricks, 0, 2);
		world.setBlock(i + 1, j + 29, k + 2, NovaCraftBlocks.basal_bricks, 0, 2);
		world.setBlock(i + 2, j + 29, k + 2, Blocks.air, 0, 2);
		world.setBlock(i + 3, j + 29, k + 2, Blocks.air, 0, 2);
		world.setBlock(i + 4, j + 29, k + 2, NovaCraftBlocks.basal_scrap, 0, 2);
		world.setBlock(i + 5, j + 29, k + 2, NovaCraftBlocks.basal_bricks, 0, 2);
		world.setBlock(i + 6, j + 29, k + 2, Blocks.air, 0, 2);
		world.setBlock(i + 7, j + 29, k + 2, Blocks.air, 0, 2);
		world.setBlock(i + 8, j + 29, k + 2, NovaCraftBlocks.cracked_basal_bricks, 0, 2);
		world.setBlock(i + 9, j + 29, k + 2, NovaCraftBlocks.basal_bricks, 0, 2);
		world.setBlock(i + 10, j + 29, k + 2, Blocks.air, 0, 2);
		world.setBlock(i + 11, j + 29, k + 2, Blocks.air, 0, 2);
		world.setBlock(i + 12, j + 29, k + 2, NovaCraftBlocks.basal_bricks, 0, 2);
		world.setBlock(i + 13, j + 29, k + 2, NovaCraftBlocks.basal_bricks, 0, 2);
		world.setBlock(i + 14, j + 29, k + 2, Blocks.air, 0, 2);
		world.setBlock(i + 15, j + 29, k + 2, Blocks.air, 0, 2);
		world.setBlock(i + 16, j + 29, k + 2, Blocks.air, 0, 2);
		world.setBlock(i + 17, j + 29, k + 2, Blocks.air, 0, 2);
		world.setBlock(i + 18, j + 29, k + 2, Blocks.air, 0, 2);
		world.setBlock(i + 19, j + 29, k + 2, Blocks.air, 0, 2);
		world.setBlock(i + 20, j + 29, k + 2, Blocks.air, 0, 2);
		world.setBlock(i + 21, j + 29, k + 2, Blocks.air, 0, 2);
		world.setBlock(i + 22, j + 29, k + 2, Blocks.air, 0, 2);
		world.setBlock(i + 23, j + 29, k + 2, Blocks.air, 0, 2);
		world.setBlock(i + 24, j + 29, k + 2, Blocks.air, 0, 2);
		world.setBlock(i + 25, j + 29, k + 2, Blocks.air, 0, 2);
		world.setBlock(i + 26, j + 29, k + 2, Blocks.air, 0, 2);
		world.setBlock(i + 27, j + 29, k + 2, Blocks.air, 0, 2);
		world.setBlock(i + 0, j + 29, k + 3, NovaCraftBlocks.basal_bricks, 0, 2);
		world.setBlock(i + 1, j + 29, k + 3, NovaCraftBlocks.cracked_basal_bricks, 0, 2);
		world.setBlock(i + 2, j + 29, k + 3, NovaCraftBlocks.basal_bricks, 0, 2);
		world.setBlock(i + 3, j + 29, k + 3, NovaCraftBlocks.cracked_basal_bricks, 0, 2);
		world.setBlock(i + 4, j + 29, k + 3, NovaCraftBlocks.basal_bricks, 0, 2);
		world.setBlock(i + 5, j + 29, k + 3, NovaCraftBlocks.cracked_basal_bricks, 0, 2);
		world.setBlock(i + 6, j + 29, k + 3, Blocks.air, 0, 2);
		world.setBlock(i + 7, j + 29, k + 3, NovaCraftBlocks.basal_bricks, 0, 2);
		world.setBlock(i + 8, j + 29, k + 3, NovaCraftBlocks.basal_bricks, 0, 2);
		world.setBlock(i + 9, j + 29, k + 3, NovaCraftBlocks.basal_bricks, 0, 2);
		world.setBlock(i + 10, j + 29, k + 3, NovaCraftBlocks.basal_bricks, 0, 2);
		world.setBlock(i + 11, j + 29, k + 3, NovaCraftBlocks.basal_bricks, 0, 2);
		world.setBlock(i + 12, j + 29, k + 3, NovaCraftBlocks.basal_bricks, 0, 2);
		world.setBlock(i + 13, j + 29, k + 3, NovaCraftBlocks.basal_bricks, 0, 2);
		world.setBlock(i + 14, j + 29, k + 3, Blocks.air, 0, 2);
		world.setBlock(i + 15, j + 29, k + 3, Blocks.air, 0, 2);
		world.setBlock(i + 16, j + 29, k + 3, Blocks.air, 0, 2);
		world.setBlock(i + 17, j + 29, k + 3, Blocks.air, 0, 2);
		world.setBlock(i + 18, j + 29, k + 3, Blocks.air, 0, 2);
		world.setBlock(i + 19, j + 29, k + 3, Blocks.air, 0, 2);
		world.setBlock(i + 20, j + 29, k + 3, Blocks.air, 0, 2);
		world.setBlock(i + 21, j + 29, k + 3, Blocks.air, 0, 2);
		world.setBlock(i + 22, j + 29, k + 3, Blocks.air, 0, 2);
		world.setBlock(i + 23, j + 29, k + 3, Blocks.air, 0, 2);
		world.setBlock(i + 24, j + 29, k + 3, Blocks.air, 0, 2);
		world.setBlock(i + 25, j + 29, k + 3, Blocks.air, 0, 2);
		world.setBlock(i + 26, j + 29, k + 3, Blocks.air, 0, 2);
		world.setBlock(i + 27, j + 29, k + 3, Blocks.air, 0, 2);
		world.setBlock(i + 0, j + 29, k + 4, Blocks.air, 0, 2);
		world.setBlock(i + 1, j + 29, k + 4, NovaCraftBlocks.cracked_basal_bricks, 0, 2);
		world.setBlock(i + 2, j + 29, k + 4, NovaCraftBlocks.basal_bricks, 0, 2);
		world.setBlock(i + 3, j + 29, k + 4, NovaCraftBlocks.basal_bricks, 0, 2);
		world.setBlock(i + 4, j + 29, k + 4, NovaCraftBlocks.basal_bricks, 0, 2);
		world.setBlock(i + 5, j + 29, k + 4, NovaCraftBlocks.basal_bricks, 0, 2);
		world.setBlock(i + 6, j + 29, k + 4, NovaCraftBlocks.basal_bricks, 0, 2);
		world.setBlock(i + 7, j + 29, k + 4, NovaCraftBlocks.cracked_basal_bricks, 0, 2);
		world.setBlock(i + 8, j + 29, k + 4, NovaCraftBlocks.basal_bricks, 0, 2);
		world.setBlock(i + 9, j + 29, k + 4, NovaCraftBlocks.cracked_basal_bricks, 0, 2);
		world.setBlock(i + 10, j + 29, k + 4, NovaCraftBlocks.basal_bricks, 0, 2);
		world.setBlock(i + 11, j + 29, k + 4, NovaCraftBlocks.cracked_basal_bricks, 0, 2);
		world.setBlock(i + 12, j + 29, k + 4, NovaCraftBlocks.basal_bricks, 0, 2);
		world.setBlock(i + 13, j + 29, k + 4, NovaCraftBlocks.basal_bricks, 0, 2);
		world.setBlock(i + 14, j + 29, k + 4, NovaCraftBlocks.cracked_basal_bricks, 0, 2);
		world.setBlock(i + 15, j + 29, k + 4, NovaCraftBlocks.cracked_basal_bricks, 0, 2);
		world.setBlock(i + 16, j + 29, k + 4, Blocks.air, 0, 2);
		world.setBlock(i + 17, j + 29, k + 4, Blocks.air, 0, 2);
		world.setBlock(i + 18, j + 29, k + 4, NovaCraftBlocks.basal_scrap, 0, 2);
		world.setBlock(i + 19, j + 29, k + 4, NovaCraftBlocks.cracked_basal_bricks, 0, 2);
		world.setBlock(i + 20, j + 29, k + 4, Blocks.air, 0, 2);
		world.setBlock(i + 21, j + 29, k + 4, Blocks.air, 0, 2);
		world.setBlock(i + 22, j + 29, k + 4, NovaCraftBlocks.cracked_basal_bricks, 0, 2);
		world.setBlock(i + 23, j + 29, k + 4, NovaCraftBlocks.basal_bricks, 0, 2);
		world.setBlock(i + 24, j + 29, k + 4, Blocks.air, 0, 2);
		world.setBlock(i + 25, j + 29, k + 4, Blocks.air, 0, 2);
		world.setBlock(i + 26, j + 29, k + 4, NovaCraftBlocks.basal_bricks, 0, 2);
		world.setBlock(i + 27, j + 29, k + 4, NovaCraftBlocks.basal_bricks, 0, 2);
		world.setBlock(i + 0, j + 29, k + 5, Blocks.air, 0, 2);
		world.setBlock(i + 1, j + 29, k + 5, NovaCraftBlocks.basal_bricks, 0, 2);
		world.setBlock(i + 2, j + 29, k + 5, NovaCraftBlocks.basal_bricks, 0, 2);
		world.setBlock(i + 3, j + 29, k + 5, NovaCraftBlocks.basal_bricks, 0, 2);
		world.setBlock(i + 4, j + 29, k + 5, Blocks.air, 0, 2);
		world.setBlock(i + 5, j + 29, k + 5, NovaCraftBlocks.basal_bricks, 0, 2);
		world.setBlock(i + 6, j + 29, k + 5, NovaCraftBlocks.basal_bricks, 0, 2);
		world.setBlock(i + 7, j + 29, k + 5, NovaCraftBlocks.basal_bricks, 0, 2);
		world.setBlock(i + 8, j + 29, k + 5, NovaCraftBlocks.basal_bricks, 0, 2);
		world.setBlock(i + 9, j + 29, k + 5, NovaCraftBlocks.basal_bricks, 0, 2);
		world.setBlock(i + 10, j + 29, k + 5, NovaCraftBlocks.cracked_basal_bricks, 0, 2);
		world.setBlock(i + 11, j + 29, k + 5, NovaCraftBlocks.basal_bricks, 0, 2);
		world.setBlock(i + 12, j + 29, k + 5, NovaCraftBlocks.basal_bricks, 0, 2);
		world.setBlock(i + 13, j + 29, k + 5, NovaCraftBlocks.basal_bricks, 0, 2);
		world.setBlock(i + 14, j + 29, k + 5, NovaCraftBlocks.cracked_basal_bricks, 0, 2);
		world.setBlock(i + 15, j + 29, k + 5, NovaCraftBlocks.basal_bricks, 0, 2);
		world.setBlock(i + 16, j + 29, k + 5, NovaCraftBlocks.basal_bricks, 0, 2);
		world.setBlock(i + 17, j + 29, k + 5, NovaCraftBlocks.basal_bricks, 0, 2);
		world.setBlock(i + 18, j + 29, k + 5, NovaCraftBlocks.basal_bricks, 0, 2);
		world.setBlock(i + 19, j + 29, k + 5, NovaCraftBlocks.basal_bricks, 0, 2);
		world.setBlock(i + 20, j + 29, k + 5, Blocks.air, 0, 2);
		world.setBlock(i + 21, j + 29, k + 5, NovaCraftBlocks.basal_bricks, 0, 2);
		world.setBlock(i + 22, j + 29, k + 5, NovaCraftBlocks.basal_bricks, 0, 2);
		world.setBlock(i + 23, j + 29, k + 5, NovaCraftBlocks.cracked_basal_bricks, 0, 2);
		world.setBlock(i + 24, j + 29, k + 5, NovaCraftBlocks.basal_bricks, 0, 2);
		world.setBlock(i + 25, j + 29, k + 5, NovaCraftBlocks.basal_bricks, 0, 2);
		world.setBlock(i + 26, j + 29, k + 5, NovaCraftBlocks.cracked_basal_bricks, 0, 2);
		world.setBlock(i + 27, j + 29, k + 5, NovaCraftBlocks.basal_bricks, 0, 2);
		world.setBlock(i + 0, j + 29, k + 6, NovaCraftBlocks.basal_bricks, 0, 2);
		world.setBlock(i + 1, j + 29, k + 6, Blocks.air, 0, 2);
		world.setBlock(i + 2, j + 29, k + 6, Blocks.air, 0, 2);
		world.setBlock(i + 3, j + 29, k + 6, NovaCraftBlocks.cracked_basal_bricks, 0, 2);
		world.setBlock(i + 4, j + 29, k + 6, NovaCraftBlocks.basal_bricks, 0, 2);
		world.setBlock(i + 5, j + 29, k + 6, NovaCraftBlocks.basal_bricks, 0, 2);
		world.setBlock(i + 6, j + 29, k + 6, NovaCraftBlocks.basal_bricks, 0, 2);
		world.setBlock(i + 7, j + 29, k + 6, NovaCraftBlocks.cracked_basal_bricks, 0, 2);
		world.setBlock(i + 8, j + 29, k + 6, NovaCraftBlocks.basal_bricks, 0, 2);
		world.setBlock(i + 9, j + 29, k + 6, NovaCraftBlocks.basal_bricks, 0, 2);
		world.setBlock(i + 10, j + 29, k + 6, NovaCraftBlocks.basal_bricks, 0, 2);
		world.setBlock(i + 11, j + 29, k + 6, Blocks.air, 0, 2);
		world.setBlock(i + 12, j + 29, k + 6, Blocks.air, 0, 2);
		world.setBlock(i + 13, j + 29, k + 6, NovaCraftBlocks.basal_bricks, 0, 2);
		world.setBlock(i + 14, j + 29, k + 6, NovaCraftBlocks.cracked_basal_bricks, 0, 2);
		world.setBlock(i + 15, j + 29, k + 6, NovaCraftBlocks.basal_bricks, 0, 2);
		world.setBlock(i + 16, j + 29, k + 6, NovaCraftBlocks.basal_bricks, 0, 2);
		world.setBlock(i + 17, j + 29, k + 6, NovaCraftBlocks.cracked_basal_bricks, 0, 2);
		world.setBlock(i + 18, j + 29, k + 6, NovaCraftBlocks.cracked_basal_bricks, 0, 2);
		world.setBlock(i + 19, j + 29, k + 6, NovaCraftBlocks.cracked_basal_bricks, 0, 2);
		world.setBlock(i + 20, j + 29, k + 6, NovaCraftBlocks.basal_bricks, 0, 2);
		world.setBlock(i + 21, j + 29, k + 6, NovaCraftBlocks.basal_bricks, 0, 2);
		world.setBlock(i + 22, j + 29, k + 6, NovaCraftBlocks.basal_bricks, 0, 2);
		world.setBlock(i + 23, j + 29, k + 6, NovaCraftBlocks.cracked_basal_bricks, 0, 2);
		world.setBlock(i + 24, j + 29, k + 6, NovaCraftBlocks.cracked_basal_bricks, 0, 2);
		world.setBlock(i + 25, j + 29, k + 6, NovaCraftBlocks.cracked_basal_bricks, 0, 2);
		world.setBlock(i + 26, j + 29, k + 6, NovaCraftBlocks.basal_bricks, 0, 2);
		world.setBlock(i + 27, j + 29, k + 6, NovaCraftBlocks.cracked_basal_bricks, 0, 2);
		world.setBlock(i + 0, j + 29, k + 7, NovaCraftBlocks.cracked_basal_bricks, 0, 2);
		world.setBlock(i + 1, j + 29, k + 7, Blocks.air, 0, 2);
		world.setBlock(i + 2, j + 29, k + 7, Blocks.air, 0, 2);
		world.setBlock(i + 3, j + 29, k + 7, NovaCraftBlocks.basal_bricks, 0, 2);
		world.setBlock(i + 4, j + 29, k + 7, NovaCraftBlocks.basal_bricks, 0, 2);
		world.setBlock(i + 5, j + 29, k + 7, NovaCraftBlocks.cracked_basal_bricks, 0, 2);
		world.setBlock(i + 6, j + 29, k + 7, NovaCraftBlocks.basal_bricks, 0, 2);
		world.setBlock(i + 7, j + 29, k + 7, NovaCraftBlocks.basal_bricks, 0, 2);
		world.setBlock(i + 8, j + 29, k + 7, NovaCraftBlocks.basal_bricks, 0, 2);
		world.setBlock(i + 9, j + 29, k + 7, NovaCraftBlocks.cracked_basal_bricks, 0, 2);
		world.setBlock(i + 10, j + 29, k + 7, NovaCraftBlocks.basal_bricks, 0, 2);
		world.setBlock(i + 11, j + 29, k + 7, Blocks.air, 0, 2);
		world.setBlock(i + 12, j + 29, k + 7, Blocks.air, 0, 2);
		world.setBlock(i + 13, j + 29, k + 7, NovaCraftBlocks.basal_bricks, 0, 2);
		world.setBlock(i + 14, j + 29, k + 7, NovaCraftBlocks.cracked_basal_bricks, 0, 2);
		world.setBlock(i + 15, j + 29, k + 7, NovaCraftBlocks.cracked_basal_bricks, 0, 2);
		world.setBlock(i + 16, j + 29, k + 7, NovaCraftBlocks.basal_bricks, 0, 2);
		world.setBlock(i + 17, j + 29, k + 7, NovaCraftBlocks.basal_bricks, 0, 2);
		world.setBlock(i + 18, j + 29, k + 7, NovaCraftBlocks.basal_bricks, 0, 2);
		world.setBlock(i + 19, j + 29, k + 7, NovaCraftBlocks.cracked_basal_bricks, 0, 2);
		world.setBlock(i + 20, j + 29, k + 7, NovaCraftBlocks.cracked_basal_bricks, 0, 2);
		world.setBlock(i + 21, j + 29, k + 7, NovaCraftBlocks.cracked_basal_bricks, 0, 2);
		world.setBlock(i + 22, j + 29, k + 7, NovaCraftBlocks.basal_bricks, 0, 2);
		world.setBlock(i + 23, j + 29, k + 7, NovaCraftBlocks.basal_bricks, 0, 2);
		world.setBlock(i + 24, j + 29, k + 7, NovaCraftBlocks.basal_bricks, 0, 2);
		world.setBlock(i + 25, j + 29, k + 7, NovaCraftBlocks.basal_bricks, 0, 2);
		world.setBlock(i + 26, j + 29, k + 7, NovaCraftBlocks.basal_bricks, 0, 2);
		world.setBlock(i + 27, j + 29, k + 7, NovaCraftBlocks.basal_bricks, 0, 2);
		world.setBlock(i + 0, j + 29, k + 8, NovaCraftBlocks.basal_bricks, 0, 2);
		world.setBlock(i + 1, j + 29, k + 8, Blocks.air, 0, 2);
		world.setBlock(i + 2, j + 29, k + 8, Blocks.air, 0, 2);
		world.setBlock(i + 3, j + 29, k + 8, NovaCraftBlocks.cracked_basal_bricks, 0, 2);
		world.setBlock(i + 4, j + 29, k + 8, NovaCraftBlocks.basal_bricks, 0, 2);
		world.setBlock(i + 5, j + 29, k + 8, NovaCraftBlocks.basal_bricks, 0, 2);
		world.setBlock(i + 6, j + 29, k + 8, NovaCraftBlocks.basal_bricks, 0, 2);
		world.setBlock(i + 7, j + 29, k + 8, NovaCraftBlocks.basal_bricks, 0, 2);
		world.setBlock(i + 8, j + 29, k + 8, NovaCraftBlocks.basal_bricks, 0, 2);
		world.setBlock(i + 9, j + 29, k + 8, NovaCraftBlocks.basal_bricks, 0, 2);
		world.setBlock(i + 10, j + 29, k + 8, NovaCraftBlocks.basal_bricks, 0, 2);
		world.setBlock(i + 11, j + 29, k + 8, Blocks.air, 0, 2);
		world.setBlock(i + 12, j + 29, k + 8, Blocks.air, 0, 2);
		world.setBlock(i + 13, j + 29, k + 8, NovaCraftBlocks.cracked_basal_bricks, 0, 2);
		world.setBlock(i + 14, j + 29, k + 8, NovaCraftBlocks.cracked_basal_bricks, 0, 2);
		world.setBlock(i + 15, j + 29, k + 8, Blocks.air, 0, 2);
		world.setBlock(i + 16, j + 29, k + 8, Blocks.air, 0, 2);
		world.setBlock(i + 17, j + 29, k + 8, NovaCraftBlocks.basal_bricks, 0, 2);
		world.setBlock(i + 18, j + 29, k + 8, NovaCraftBlocks.basal_bricks, 0, 2);
		world.setBlock(i + 19, j + 29, k + 8, NovaCraftBlocks.cracked_basal_bricks, 0, 2);
		world.setBlock(i + 20, j + 29, k + 8, NovaCraftBlocks.cracked_basal_bricks, 0, 2);
		world.setBlock(i + 21, j + 29, k + 8, NovaCraftBlocks.basal_bricks, 0, 2);
		world.setBlock(i + 22, j + 29, k + 8, NovaCraftBlocks.basal_bricks, 0, 2);
		world.setBlock(i + 23, j + 29, k + 8, NovaCraftBlocks.cracked_basal_bricks, 0, 2);
		world.setBlock(i + 24, j + 29, k + 8, NovaCraftBlocks.cracked_basal_bricks, 0, 2);
		world.setBlock(i + 25, j + 29, k + 8, NovaCraftBlocks.basal_bricks, 0, 2);
		world.setBlock(i + 26, j + 29, k + 8, NovaCraftBlocks.basal_bricks, 0, 2);
		world.setBlock(i + 27, j + 29, k + 8, NovaCraftBlocks.cracked_basal_bricks, 0, 2);
		world.setBlock(i + 0, j + 29, k + 9, NovaCraftBlocks.cracked_basal_bricks, 0, 2);
		world.setBlock(i + 1, j + 29, k + 9, Blocks.air, 0, 2);
		world.setBlock(i + 2, j + 29, k + 9, Blocks.air, 0, 2);
		world.setBlock(i + 3, j + 29, k + 9, NovaCraftBlocks.cracked_basal_bricks, 0, 2);
		world.setBlock(i + 4, j + 29, k + 9, NovaCraftBlocks.cracked_basal_bricks, 0, 2);
		world.setBlock(i + 5, j + 29, k + 9, NovaCraftBlocks.basal_bricks, 0, 2);
		world.setBlock(i + 6, j + 29, k + 9, NovaCraftBlocks.basal_bricks, 0, 2);
		world.setBlock(i + 7, j + 29, k + 9, NovaCraftBlocks.basal_bricks, 0, 2);
		world.setBlock(i + 8, j + 29, k + 9, NovaCraftBlocks.basal_bricks, 0, 2);
		world.setBlock(i + 9, j + 29, k + 9, NovaCraftBlocks.cracked_basal_bricks, 0, 2);
		world.setBlock(i + 10, j + 29, k + 9, NovaCraftBlocks.cracked_basal_bricks, 0, 2);
		world.setBlock(i + 11, j + 29, k + 9, Blocks.air, 0, 2);
		world.setBlock(i + 12, j + 29, k + 9, Blocks.air, 0, 2);
		world.setBlock(i + 13, j + 29, k + 9, NovaCraftBlocks.cracked_basal_bricks, 0, 2);
		world.setBlock(i + 14, j + 29, k + 9, NovaCraftBlocks.cracked_basal_bricks, 0, 2);
		world.setBlock(i + 15, j + 29, k + 9, Blocks.air, 0, 2);
		world.setBlock(i + 16, j + 29, k + 9, Blocks.air, 0, 2);
		world.setBlock(i + 17, j + 29, k + 9, NovaCraftBlocks.cracked_basal_bricks, 0, 2);
		world.setBlock(i + 18, j + 29, k + 9, NovaCraftBlocks.cracked_basal_bricks, 0, 2);
		world.setBlock(i + 19, j + 29, k + 9, NovaCraftBlocks.basal_bricks, 0, 2);
		world.setBlock(i + 20, j + 29, k + 9, NovaCraftBlocks.basal_bricks, 0, 2);
		world.setBlock(i + 21, j + 29, k + 9, NovaCraftBlocks.basal_bricks, 0, 2);
		world.setBlock(i + 22, j + 29, k + 9, NovaCraftBlocks.basal_bricks, 0, 2);
		world.setBlock(i + 23, j + 29, k + 9, NovaCraftBlocks.basal_bricks, 0, 2);
		world.setBlock(i + 24, j + 29, k + 9, NovaCraftBlocks.basal_bricks, 0, 2);
		world.setBlock(i + 25, j + 29, k + 9, Blocks.air, 0, 2);
		world.setBlock(i + 26, j + 29, k + 9, Blocks.air, 0, 2);
		world.setBlock(i + 27, j + 29, k + 9, NovaCraftBlocks.cracked_basal_bricks, 0, 2);
		world.setBlock(i + 0, j + 29, k + 10, NovaCraftBlocks.basal_bricks, 0, 2);
		world.setBlock(i + 1, j + 29, k + 10, NovaCraftBlocks.cracked_basal_bricks, 0, 2);
		world.setBlock(i + 2, j + 29, k + 10, NovaCraftBlocks.cracked_basal_bricks, 0, 2);
		world.setBlock(i + 3, j + 29, k + 10, NovaCraftBlocks.cracked_basal_bricks, 0, 2);
		world.setBlock(i + 4, j + 29, k + 10, NovaCraftBlocks.cracked_basal_bricks, 0, 2);
		world.setBlock(i + 5, j + 29, k + 10, NovaCraftBlocks.basal_bricks, 0, 2);
		world.setBlock(i + 6, j + 29, k + 10, NovaCraftBlocks.cracked_basal_bricks, 0, 2);
		world.setBlock(i + 7, j + 29, k + 10, NovaCraftBlocks.basal_bricks, 0, 2);
		world.setBlock(i + 8, j + 29, k + 10, NovaCraftBlocks.basal_bricks, 0, 2);
		world.setBlock(i + 9, j + 29, k + 10, NovaCraftBlocks.basal_bricks, 0, 2);
		world.setBlock(i + 10, j + 29, k + 10, NovaCraftBlocks.basal_bricks, 0, 2);
		world.setBlock(i + 11, j + 29, k + 10, NovaCraftBlocks.cracked_basal_bricks, 0, 2);
		world.setBlock(i + 12, j + 29, k + 10, NovaCraftBlocks.cracked_basal_bricks, 0, 2);
		world.setBlock(i + 13, j + 29, k + 10, NovaCraftBlocks.basal_bricks, 0, 2);
		world.setBlock(i + 14, j + 29, k + 10, NovaCraftBlocks.cracked_basal_bricks, 0, 2);
		world.setBlock(i + 15, j + 29, k + 10, Blocks.air, 0, 2);
		world.setBlock(i + 16, j + 29, k + 10, Blocks.air, 0, 2);
		world.setBlock(i + 17, j + 29, k + 10, Blocks.air, 0, 2);
		world.setBlock(i + 18, j + 29, k + 10, NovaCraftBlocks.basal_bricks, 0, 2);
		world.setBlock(i + 19, j + 29, k + 10, NovaCraftBlocks.basal_bricks, 0, 2);
		world.setBlock(i + 20, j + 29, k + 10, NovaCraftBlocks.basal_bricks, 0, 2);
		world.setBlock(i + 21, j + 29, k + 10, NovaCraftBlocks.basal_bricks, 0, 2);
		world.setBlock(i + 22, j + 29, k + 10, NovaCraftBlocks.cracked_basal_bricks, 0, 2);
		world.setBlock(i + 23, j + 29, k + 10, NovaCraftBlocks.cracked_basal_bricks, 0, 2);
		world.setBlock(i + 24, j + 29, k + 10, Blocks.air, 0, 2);
		world.setBlock(i + 25, j + 29, k + 10, Blocks.air, 0, 2);
		world.setBlock(i + 26, j + 29, k + 10, Blocks.air, 0, 2);
		world.setBlock(i + 27, j + 29, k + 10, NovaCraftBlocks.cracked_basal_bricks, 0, 2);
		world.setBlock(i + 0, j + 29, k + 11, NovaCraftBlocks.basal_bricks, 0, 2);
		world.setBlock(i + 1, j + 29, k + 11, Blocks.lava, 0, 2);
		world.setBlock(i + 2, j + 29, k + 11, Blocks.lava, 0, 2);
		world.setBlock(i + 3, j + 29, k + 11, Blocks.lava, 0, 2);
		world.setBlock(i + 4, j + 29, k + 11, Blocks.lava, 0, 2);
		world.setBlock(i + 5, j + 29, k + 11, Blocks.lava, 0, 2);
		world.setBlock(i + 6, j + 29, k + 11, Blocks.lava, 0, 2);
		world.setBlock(i + 7, j + 29, k + 11, Blocks.lava, 0, 2);
		world.setBlock(i + 8, j + 29, k + 11, Blocks.lava, 0, 2);
		world.setBlock(i + 9, j + 29, k + 11, Blocks.lava, 0, 2);
		world.setBlock(i + 10, j + 29, k + 11, Blocks.lava, 0, 2);
		world.setBlock(i + 11, j + 29, k + 11, Blocks.lava, 0, 2);
		world.setBlock(i + 12, j + 29, k + 11, Blocks.lava, 0, 2);
		world.setBlock(i + 13, j + 29, k + 11, NovaCraftBlocks.cracked_basal_bricks, 0, 2);
		world.setBlock(i + 14, j + 29, k + 11, NovaCraftBlocks.cracked_basal_bricks, 0, 2);
		world.setBlock(i + 15, j + 29, k + 11, Blocks.air, 0, 2);
		world.setBlock(i + 16, j + 29, k + 11, Blocks.air, 0, 2);
		world.setBlock(i + 17, j + 29, k + 11, Blocks.air, 0, 2);
		world.setBlock(i + 18, j + 29, k + 11, NovaCraftBlocks.cracked_basal_bricks, 0, 2);
		world.setBlock(i + 19, j + 29, k + 11, NovaCraftBlocks.cracked_basal_bricks, 0, 2);
		world.setBlock(i + 20, j + 29, k + 11, NovaCraftBlocks.basal_bricks, 0, 2);
		world.setBlock(i + 21, j + 29, k + 11, NovaCraftBlocks.basal_bricks, 0, 2);
		world.setBlock(i + 22, j + 29, k + 11, NovaCraftBlocks.basal_bricks, 0, 2);
		world.setBlock(i + 23, j + 29, k + 11, NovaCraftBlocks.cracked_basal_bricks, 0, 2);
		world.setBlock(i + 24, j + 29, k + 11, Blocks.air, 0, 2);
		world.setBlock(i + 25, j + 29, k + 11, Blocks.air, 0, 2);
		world.setBlock(i + 26, j + 29, k + 11, Blocks.air, 0, 2);
		world.setBlock(i + 27, j + 29, k + 11, NovaCraftBlocks.basal_bricks, 0, 2);
		world.setBlock(i + 0, j + 29, k + 12, NovaCraftBlocks.basal_bricks, 0, 2);
		world.setBlock(i + 1, j + 29, k + 12, Blocks.lava, 0, 2);
		world.setBlock(i + 2, j + 29, k + 12, Blocks.lava, 0, 2);
		world.setBlock(i + 3, j + 29, k + 12, Blocks.lava, 0, 2);
		world.setBlock(i + 4, j + 29, k + 12, Blocks.lava, 0, 2);
		world.setBlock(i + 5, j + 29, k + 12, Blocks.lava, 0, 2);
		world.setBlock(i + 6, j + 29, k + 12, Blocks.lava, 0, 2);
		world.setBlock(i + 7, j + 29, k + 12, Blocks.lava, 0, 2);
		world.setBlock(i + 8, j + 29, k + 12, Blocks.lava, 0, 2);
		world.setBlock(i + 9, j + 29, k + 12, Blocks.lava, 0, 2);
		world.setBlock(i + 10, j + 29, k + 12, Blocks.lava, 0, 2);
		world.setBlock(i + 11, j + 29, k + 12, Blocks.lava, 0, 2);
		world.setBlock(i + 12, j + 29, k + 12, Blocks.lava, 0, 2);
		world.setBlock(i + 13, j + 29, k + 12, NovaCraftBlocks.basal_bricks, 0, 2);
		world.setBlock(i + 14, j + 29, k + 12, NovaCraftBlocks.basal_bricks, 0, 2);
		world.setBlock(i + 15, j + 29, k + 12, NovaCraftBlocks.basal_bricks, 0, 2);
		world.setBlock(i + 16, j + 29, k + 12, NovaCraftBlocks.basal_bricks, 0, 2);
		world.setBlock(i + 17, j + 29, k + 12, NovaCraftBlocks.cracked_basal_bricks, 0, 2);
		world.setBlock(i + 18, j + 29, k + 12, NovaCraftBlocks.basal_bricks, 0, 2);
		world.setBlock(i + 19, j + 29, k + 12, NovaCraftBlocks.basal_bricks, 0, 2);
		world.setBlock(i + 20, j + 29, k + 12, NovaCraftBlocks.cracked_basal_bricks, 0, 2);
		world.setBlock(i + 21, j + 29, k + 12, NovaCraftBlocks.basal_bricks, 0, 2);
		world.setBlock(i + 22, j + 29, k + 12, NovaCraftBlocks.basal_bricks, 0, 2);
		world.setBlock(i + 23, j + 29, k + 12, NovaCraftBlocks.basal_bricks, 0, 2);
		world.setBlock(i + 24, j + 29, k + 12, NovaCraftBlocks.basal_bricks, 0, 2);
		world.setBlock(i + 25, j + 29, k + 12, NovaCraftBlocks.basal_bricks, 0, 2);
		world.setBlock(i + 26, j + 29, k + 12, NovaCraftBlocks.cracked_basal_bricks, 0, 2);
		world.setBlock(i + 27, j + 29, k + 12, NovaCraftBlocks.basal_bricks, 0, 2);
		world.setBlock(i + 0, j + 30, k + 0, Blocks.air, 0, 2);
		world.setBlock(i + 1, j + 30, k + 0, Blocks.air, 0, 2);
		world.setBlock(i + 2, j + 30, k + 0, Blocks.air, 0, 2);
		world.setBlock(i + 3, j + 30, k + 0, Blocks.air, 0, 2);
		world.setBlock(i + 4, j + 30, k + 0, Blocks.air, 0, 2);
		world.setBlock(i + 5, j + 30, k + 0, Blocks.air, 0, 2);
		world.setBlock(i + 6, j + 30, k + 0, Blocks.air, 0, 2);
		world.setBlock(i + 7, j + 30, k + 0, Blocks.air, 0, 2);
		world.setBlock(i + 8, j + 30, k + 0, Blocks.air, 0, 2);
		world.setBlock(i + 9, j + 30, k + 0, Blocks.air, 0, 2);
		world.setBlock(i + 10, j + 30, k + 0, Blocks.air, 0, 2);
		world.setBlock(i + 11, j + 30, k + 0, Blocks.air, 0, 2);
		world.setBlock(i + 12, j + 30, k + 0, Blocks.air, 0, 2);
		world.setBlock(i + 13, j + 30, k + 0, Blocks.air, 0, 2);
		world.setBlock(i + 14, j + 30, k + 0, Blocks.air, 0, 2);
		world.setBlock(i + 15, j + 30, k + 0, Blocks.air, 0, 2);
		world.setBlock(i + 16, j + 30, k + 0, Blocks.air, 0, 2);
		world.setBlock(i + 17, j + 30, k + 0, Blocks.air, 0, 2);
		world.setBlock(i + 18, j + 30, k + 0, Blocks.air, 0, 2);
		world.setBlock(i + 19, j + 30, k + 0, Blocks.air, 0, 2);
		world.setBlock(i + 20, j + 30, k + 0, Blocks.air, 0, 2);
		world.setBlock(i + 21, j + 30, k + 0, Blocks.air, 0, 2);
		world.setBlock(i + 22, j + 30, k + 0, Blocks.air, 0, 2);
		world.setBlock(i + 23, j + 30, k + 0, Blocks.air, 0, 2);
		world.setBlock(i + 24, j + 30, k + 0, Blocks.air, 0, 2);
		world.setBlock(i + 25, j + 30, k + 0, Blocks.air, 0, 2);
		world.setBlock(i + 26, j + 30, k + 0, Blocks.air, 0, 2);
		world.setBlock(i + 27, j + 30, k + 0, Blocks.air, 0, 2);
		world.setBlock(i + 0, j + 30, k + 1, Blocks.air, 0, 2);
		world.setBlock(i + 1, j + 30, k + 1, Blocks.air, 0, 2);
		world.setBlock(i + 2, j + 30, k + 1, Blocks.air, 0, 2);
		world.setBlock(i + 3, j + 30, k + 1, Blocks.air, 0, 2);
		world.setBlock(i + 4, j + 30, k + 1, NovaCraftBlocks.basal_scrap, 0, 2);
		world.setBlock(i + 5, j + 30, k + 1, NovaCraftBlocks.basal_scrap, 0, 2);
		world.setBlock(i + 6, j + 30, k + 1, Blocks.air, 0, 2);
		world.setBlock(i + 7, j + 30, k + 1, Blocks.air, 0, 2);
		world.setBlock(i + 8, j + 30, k + 1, Blocks.air, 0, 2);
		world.setBlock(i + 9, j + 30, k + 1, Blocks.air, 0, 2);
		world.setBlock(i + 10, j + 30, k + 1, Blocks.air, 0, 2);
		world.setBlock(i + 11, j + 30, k + 1, Blocks.air, 0, 2);
		world.setBlock(i + 12, j + 30, k + 1, Blocks.air, 0, 2);
		world.setBlock(i + 13, j + 30, k + 1, Blocks.air, 0, 2);
		world.setBlock(i + 14, j + 30, k + 1, Blocks.air, 0, 2);
		world.setBlock(i + 15, j + 30, k + 1, Blocks.air, 0, 2);
		world.setBlock(i + 16, j + 30, k + 1, Blocks.air, 0, 2);
		world.setBlock(i + 17, j + 30, k + 1, Blocks.air, 0, 2);
		world.setBlock(i + 18, j + 30, k + 1, Blocks.air, 0, 2);
		world.setBlock(i + 19, j + 30, k + 1, Blocks.air, 0, 2);
		world.setBlock(i + 20, j + 30, k + 1, Blocks.air, 0, 2);
		world.setBlock(i + 21, j + 30, k + 1, Blocks.air, 0, 2);
		world.setBlock(i + 22, j + 30, k + 1, Blocks.air, 0, 2);
		world.setBlock(i + 23, j + 30, k + 1, Blocks.air, 0, 2);
		world.setBlock(i + 24, j + 30, k + 1, Blocks.air, 0, 2);
		world.setBlock(i + 25, j + 30, k + 1, Blocks.air, 0, 2);
		world.setBlock(i + 26, j + 30, k + 1, Blocks.air, 0, 2);
		world.setBlock(i + 27, j + 30, k + 1, Blocks.air, 0, 2);
		world.setBlock(i + 0, j + 30, k + 2, NovaCraftBlocks.cracked_basal_bricks, 0, 2);
		world.setBlock(i + 1, j + 30, k + 2, NovaCraftBlocks.basal_bricks, 0, 2);
		world.setBlock(i + 2, j + 30, k + 2, Blocks.air, 0, 2);
		world.setBlock(i + 3, j + 30, k + 2, Blocks.air, 0, 2);
		world.setBlock(i + 4, j + 30, k + 2, NovaCraftBlocks.basal_scrap, 0, 2);
		world.setBlock(i + 5, j + 30, k + 2, NovaCraftBlocks.basal_bricks, 0, 2);
		world.setBlock(i + 6, j + 30, k + 2, Blocks.air, 0, 2);
		world.setBlock(i + 7, j + 30, k + 2, Blocks.air, 0, 2);
		world.setBlock(i + 8, j + 30, k + 2, NovaCraftBlocks.basal_bricks, 0, 2);
		world.setBlock(i + 9, j + 30, k + 2, NovaCraftBlocks.basal_bricks, 0, 2);
		world.setBlock(i + 10, j + 30, k + 2, Blocks.air, 0, 2);
		world.setBlock(i + 11, j + 30, k + 2, Blocks.air, 0, 2);
		world.setBlock(i + 12, j + 30, k + 2, NovaCraftBlocks.basal_bricks, 0, 2);
		world.setBlock(i + 13, j + 30, k + 2, NovaCraftBlocks.basal_bricks, 0, 2);
		world.setBlock(i + 14, j + 30, k + 2, Blocks.air, 0, 2);
		world.setBlock(i + 15, j + 30, k + 2, Blocks.air, 0, 2);
		world.setBlock(i + 16, j + 30, k + 2, Blocks.air, 0, 2);
		world.setBlock(i + 17, j + 30, k + 2, Blocks.air, 0, 2);
		world.setBlock(i + 18, j + 30, k + 2, Blocks.air, 0, 2);
		world.setBlock(i + 19, j + 30, k + 2, Blocks.air, 0, 2);
		world.setBlock(i + 20, j + 30, k + 2, Blocks.air, 0, 2);
		world.setBlock(i + 21, j + 30, k + 2, Blocks.air, 0, 2);
		world.setBlock(i + 22, j + 30, k + 2, Blocks.air, 0, 2);
		world.setBlock(i + 23, j + 30, k + 2, Blocks.air, 0, 2);
		world.setBlock(i + 24, j + 30, k + 2, Blocks.air, 0, 2);
		world.setBlock(i + 25, j + 30, k + 2, Blocks.air, 0, 2);
		world.setBlock(i + 26, j + 30, k + 2, Blocks.air, 0, 2);
		world.setBlock(i + 27, j + 30, k + 2, Blocks.air, 0, 2);
		world.setBlock(i + 0, j + 30, k + 3, Blocks.air, 0, 2);
		world.setBlock(i + 1, j + 30, k + 3, NovaCraftBlocks.basal_bricks, 0, 2);
		world.setBlock(i + 2, j + 30, k + 3, NovaCraftBlocks.basal_bricks, 0, 2);
		world.setBlock(i + 3, j + 30, k + 3, NovaCraftBlocks.basal_bricks, 0, 2);
		world.setBlock(i + 4, j + 30, k + 3, NovaCraftBlocks.basal_bricks, 0, 2);
		world.setBlock(i + 5, j + 30, k + 3, NovaCraftBlocks.basal_bricks, 0, 2);
		world.setBlock(i + 6, j + 30, k + 3, NovaCraftBlocks.cracked_basal_bricks, 0, 2);
		world.setBlock(i + 7, j + 30, k + 3, NovaCraftBlocks.basal_bricks, 0, 2);
		world.setBlock(i + 8, j + 30, k + 3, NovaCraftBlocks.basal_bricks, 0, 2);
		world.setBlock(i + 9, j + 30, k + 3, NovaCraftBlocks.basal_bricks, 0, 2);
		world.setBlock(i + 10, j + 30, k + 3, NovaCraftBlocks.cracked_basal_bricks, 0, 2);
		world.setBlock(i + 11, j + 30, k + 3, NovaCraftBlocks.basal_bricks, 0, 2);
		world.setBlock(i + 12, j + 30, k + 3, NovaCraftBlocks.cracked_basal_bricks, 0, 2);
		world.setBlock(i + 13, j + 30, k + 3, NovaCraftBlocks.cracked_basal_bricks, 0, 2);
		world.setBlock(i + 14, j + 30, k + 3, Blocks.air, 0, 2);
		world.setBlock(i + 15, j + 30, k + 3, Blocks.air, 0, 2);
		world.setBlock(i + 16, j + 30, k + 3, Blocks.air, 0, 2);
		world.setBlock(i + 17, j + 30, k + 3, Blocks.air, 0, 2);
		world.setBlock(i + 18, j + 30, k + 3, Blocks.air, 0, 2);
		world.setBlock(i + 19, j + 30, k + 3, Blocks.air, 0, 2);
		world.setBlock(i + 20, j + 30, k + 3, Blocks.air, 0, 2);
		world.setBlock(i + 21, j + 30, k + 3, Blocks.air, 0, 2);
		world.setBlock(i + 22, j + 30, k + 3, Blocks.air, 0, 2);
		world.setBlock(i + 23, j + 30, k + 3, Blocks.air, 0, 2);
		world.setBlock(i + 24, j + 30, k + 3, Blocks.air, 0, 2);
		world.setBlock(i + 25, j + 30, k + 3, Blocks.air, 0, 2);
		world.setBlock(i + 26, j + 30, k + 3, Blocks.air, 0, 2);
		world.setBlock(i + 27, j + 30, k + 3, Blocks.air, 0, 2);
		world.setBlock(i + 0, j + 30, k + 4, Blocks.air, 0, 2);
		world.setBlock(i + 1, j + 30, k + 4, Blocks.air, 0, 2);
		world.setBlock(i + 2, j + 30, k + 4, NovaCraftBlocks.cracked_basal_bricks, 0, 2);
		world.setBlock(i + 3, j + 30, k + 4, NovaCraftBlocks.cracked_basal_bricks, 0, 2);
		world.setBlock(i + 4, j + 30, k + 4, NovaCraftBlocks.basal_bricks, 0, 2);
		world.setBlock(i + 5, j + 30, k + 4, NovaCraftBlocks.cracked_basal_bricks, 0, 2);
		world.setBlock(i + 6, j + 30, k + 4, NovaCraftBlocks.basal_bricks, 0, 2);
		world.setBlock(i + 7, j + 30, k + 4, NovaCraftBlocks.basal_bricks, 0, 2);
		world.setBlock(i + 8, j + 30, k + 4, NovaCraftBlocks.basal_bricks, 0, 2);
		world.setBlock(i + 9, j + 30, k + 4, NovaCraftBlocks.basal_bricks, 0, 2);
		world.setBlock(i + 10, j + 30, k + 4, NovaCraftBlocks.basal_bricks, 0, 2);
		world.setBlock(i + 11, j + 30, k + 4, NovaCraftBlocks.basal_bricks, 0, 2);
		world.setBlock(i + 12, j + 30, k + 4, NovaCraftBlocks.basal_bricks, 0, 2);
		world.setBlock(i + 13, j + 30, k + 4, NovaCraftBlocks.basal_bricks, 0, 2);
		world.setBlock(i + 14, j + 30, k + 4, NovaCraftBlocks.cracked_basal_bricks, 0, 2);
		world.setBlock(i + 15, j + 30, k + 4, NovaCraftBlocks.cracked_basal_bricks, 0, 2);
		world.setBlock(i + 16, j + 30, k + 4, Blocks.air, 0, 2);
		world.setBlock(i + 17, j + 30, k + 4, Blocks.air, 0, 2);
		world.setBlock(i + 18, j + 30, k + 4, NovaCraftBlocks.basal_scrap, 0, 2);
		world.setBlock(i + 19, j + 30, k + 4, NovaCraftBlocks.cracked_basal_bricks, 0, 2);
		world.setBlock(i + 20, j + 30, k + 4, Blocks.air, 0, 2);
		world.setBlock(i + 21, j + 30, k + 4, Blocks.air, 0, 2);
		world.setBlock(i + 22, j + 30, k + 4, NovaCraftBlocks.cracked_basal_bricks, 0, 2);
		world.setBlock(i + 23, j + 30, k + 4, NovaCraftBlocks.basal_bricks, 0, 2);
		world.setBlock(i + 24, j + 30, k + 4, Blocks.air, 0, 2);
		world.setBlock(i + 25, j + 30, k + 4, Blocks.air, 0, 2);
		world.setBlock(i + 26, j + 30, k + 4, NovaCraftBlocks.cracked_basal_bricks, 0, 2);
		world.setBlock(i + 27, j + 30, k + 4, NovaCraftBlocks.cracked_basal_bricks, 0, 2);
		world.setBlock(i + 0, j + 30, k + 5, Blocks.air, 0, 2);
		world.setBlock(i + 1, j + 30, k + 5, Blocks.air, 0, 2);
		world.setBlock(i + 2, j + 30, k + 5, NovaCraftBlocks.basal_bricks, 0, 2);
		world.setBlock(i + 3, j + 30, k + 5, NovaCraftBlocks.cracked_basal_bricks, 0, 2);
		world.setBlock(i + 4, j + 30, k + 5, NovaCraftBlocks.basal_bricks, 0, 2);
		world.setBlock(i + 5, j + 30, k + 5, NovaCraftBlocks.basal_bricks, 0, 2);
		world.setBlock(i + 6, j + 30, k + 5, NovaCraftBlocks.basal_bricks, 0, 2);
		world.setBlock(i + 7, j + 30, k + 5, NovaCraftBlocks.basal_bricks, 0, 2);
		world.setBlock(i + 8, j + 30, k + 5, NovaCraftBlocks.basal_bricks, 0, 2);
		world.setBlock(i + 9, j + 30, k + 5, NovaCraftBlocks.cracked_basal_bricks, 0, 2);
		world.setBlock(i + 10, j + 30, k + 5, NovaCraftBlocks.basal_bricks, 0, 2);
		world.setBlock(i + 11, j + 30, k + 5, NovaCraftBlocks.cracked_basal_bricks, 0, 2);
		world.setBlock(i + 12, j + 30, k + 5, NovaCraftBlocks.cracked_basal_bricks, 0, 2);
		world.setBlock(i + 13, j + 30, k + 5, NovaCraftBlocks.basal_bricks, 0, 2);
		world.setBlock(i + 14, j + 30, k + 5, NovaCraftBlocks.basal_bricks, 0, 2);
		world.setBlock(i + 15, j + 30, k + 5, NovaCraftBlocks.basal_bricks, 0, 2);
		world.setBlock(i + 16, j + 30, k + 5, NovaCraftBlocks.basal_bricks, 0, 2);
		world.setBlock(i + 17, j + 30, k + 5, NovaCraftBlocks.basal_bricks, 0, 2);
		world.setBlock(i + 18, j + 30, k + 5, NovaCraftBlocks.cracked_basal_bricks, 0, 2);
		world.setBlock(i + 19, j + 30, k + 5, NovaCraftBlocks.basal_bricks, 0, 2);
		world.setBlock(i + 20, j + 30, k + 5, NovaCraftBlocks.cracked_basal_bricks, 0, 2);
		world.setBlock(i + 21, j + 30, k + 5, NovaCraftBlocks.basal_bricks, 0, 2);
		world.setBlock(i + 22, j + 30, k + 5, NovaCraftBlocks.cracked_basal_bricks, 0, 2);
		world.setBlock(i + 23, j + 30, k + 5, NovaCraftBlocks.basal_bricks, 0, 2);
		world.setBlock(i + 24, j + 30, k + 5, NovaCraftBlocks.cracked_basal_bricks, 0, 2);
		world.setBlock(i + 25, j + 30, k + 5, NovaCraftBlocks.basal_bricks, 0, 2);
		world.setBlock(i + 26, j + 30, k + 5, NovaCraftBlocks.basal_bricks, 0, 2);
		world.setBlock(i + 27, j + 30, k + 5, NovaCraftBlocks.basal_bricks, 0, 2);
		world.setBlock(i + 0, j + 30, k + 6, Blocks.air, 0, 2);
		world.setBlock(i + 1, j + 30, k + 6, NovaCraftBlocks.basal_bricks, 0, 2);
		world.setBlock(i + 2, j + 30, k + 6, NovaCraftBlocks.basal_bricks, 0, 2);
		world.setBlock(i + 3, j + 30, k + 6, NovaCraftBlocks.basal_bricks, 0, 2);
		world.setBlock(i + 4, j + 30, k + 6, NovaCraftBlocks.basal_bricks, 0, 2);
		world.setBlock(i + 5, j + 30, k + 6, NovaCraftBlocks.basal_bricks, 0, 2);
		world.setBlock(i + 6, j + 30, k + 6, NovaCraftBlocks.basal_bricks, 0, 2);
		world.setBlock(i + 7, j + 30, k + 6, NovaCraftBlocks.cracked_basal_bricks, 0, 2);
		world.setBlock(i + 8, j + 30, k + 6, NovaCraftBlocks.cracked_basal_bricks, 0, 2);
		world.setBlock(i + 9, j + 30, k + 6, NovaCraftBlocks.basal_bricks, 0, 2);
		world.setBlock(i + 10, j + 30, k + 6, NovaCraftBlocks.basal_bricks, 0, 2);
		world.setBlock(i + 11, j + 30, k + 6, NovaCraftBlocks.basal_bricks, 0, 2);
		world.setBlock(i + 12, j + 30, k + 6, NovaCraftBlocks.cracked_basal_bricks, 0, 2);
		world.setBlock(i + 13, j + 30, k + 6, NovaCraftBlocks.basal_bricks, 0, 2);
		world.setBlock(i + 14, j + 30, k + 6, NovaCraftBlocks.cracked_basal_bricks, 0, 2);
		world.setBlock(i + 15, j + 30, k + 6, NovaCraftBlocks.basal_bricks, 0, 2);
		world.setBlock(i + 16, j + 30, k + 6, NovaCraftBlocks.basal_bricks, 0, 2);
		world.setBlock(i + 17, j + 30, k + 6, NovaCraftBlocks.cracked_basal_bricks, 0, 2);
		world.setBlock(i + 18, j + 30, k + 6, NovaCraftBlocks.cracked_basal_bricks, 0, 2);
		world.setBlock(i + 19, j + 30, k + 6, NovaCraftBlocks.cracked_basal_bricks, 0, 2);
		world.setBlock(i + 20, j + 30, k + 6, NovaCraftBlocks.cracked_basal_bricks, 0, 2);
		world.setBlock(i + 21, j + 30, k + 6, NovaCraftBlocks.basal_bricks, 0, 2);
		world.setBlock(i + 22, j + 30, k + 6, NovaCraftBlocks.basal_bricks, 0, 2);
		world.setBlock(i + 23, j + 30, k + 6, NovaCraftBlocks.cracked_basal_bricks, 0, 2);
		world.setBlock(i + 24, j + 30, k + 6, NovaCraftBlocks.basal_bricks, 0, 2);
		world.setBlock(i + 25, j + 30, k + 6, NovaCraftBlocks.basal_bricks, 0, 2);
		world.setBlock(i + 26, j + 30, k + 6, NovaCraftBlocks.cracked_basal_bricks, 0, 2);
		world.setBlock(i + 27, j + 30, k + 6, NovaCraftBlocks.cracked_basal_bricks, 0, 2);
		world.setBlock(i + 0, j + 30, k + 7, NovaCraftBlocks.cracked_basal_bricks, 0, 2);
		world.setBlock(i + 1, j + 30, k + 7, Blocks.air, 0, 2);
		world.setBlock(i + 2, j + 30, k + 7, Blocks.air, 0, 2);
		world.setBlock(i + 3, j + 30, k + 7, NovaCraftBlocks.cracked_basal_bricks, 0, 2);
		world.setBlock(i + 4, j + 30, k + 7, NovaCraftBlocks.basal_bricks, 0, 2);
		world.setBlock(i + 5, j + 30, k + 7, NovaCraftBlocks.cracked_basal_bricks, 0, 2);
		world.setBlock(i + 6, j + 30, k + 7, NovaCraftBlocks.basal_bricks, 0, 2);
		world.setBlock(i + 7, j + 30, k + 7, NovaCraftBlocks.basal_bricks, 0, 2);
		world.setBlock(i + 8, j + 30, k + 7, NovaCraftBlocks.basal_bricks, 0, 2);
		world.setBlock(i + 9, j + 30, k + 7, NovaCraftBlocks.basal_bricks, 0, 2);
		world.setBlock(i + 10, j + 30, k + 7, NovaCraftBlocks.cracked_basal_bricks, 0, 2);
		world.setBlock(i + 11, j + 30, k + 7, Blocks.air, 0, 2);
		world.setBlock(i + 12, j + 30, k + 7, Blocks.air, 0, 2);
		world.setBlock(i + 13, j + 30, k + 7, NovaCraftBlocks.basal_bricks, 0, 2);
		world.setBlock(i + 14, j + 30, k + 7, NovaCraftBlocks.cracked_basal_bricks, 0, 2);
		world.setBlock(i + 15, j + 30, k + 7, NovaCraftBlocks.basal_bricks, 0, 2);
		world.setBlock(i + 16, j + 30, k + 7, NovaCraftBlocks.basal_bricks, 0, 2);
		world.setBlock(i + 17, j + 30, k + 7, NovaCraftBlocks.cracked_basal_bricks, 0, 2);
		world.setBlock(i + 18, j + 30, k + 7, NovaCraftBlocks.cracked_basal_bricks, 0, 2);
		world.setBlock(i + 19, j + 30, k + 7, NovaCraftBlocks.cracked_basal_bricks, 0, 2);
		world.setBlock(i + 20, j + 30, k + 7, NovaCraftBlocks.basal_bricks, 0, 2);
		world.setBlock(i + 21, j + 30, k + 7, NovaCraftBlocks.cracked_basal_bricks, 0, 2);
		world.setBlock(i + 22, j + 30, k + 7, NovaCraftBlocks.cracked_basal_bricks, 0, 2);
		world.setBlock(i + 23, j + 30, k + 7, NovaCraftBlocks.cracked_basal_bricks, 0, 2);
		world.setBlock(i + 24, j + 30, k + 7, NovaCraftBlocks.basal_bricks, 0, 2);
		world.setBlock(i + 25, j + 30, k + 7, NovaCraftBlocks.basal_bricks, 0, 2);
		world.setBlock(i + 26, j + 30, k + 7, NovaCraftBlocks.cracked_basal_bricks, 0, 2);
		world.setBlock(i + 27, j + 30, k + 7, NovaCraftBlocks.basal_bricks, 0, 2);
		world.setBlock(i + 0, j + 30, k + 8, NovaCraftBlocks.basal_bricks, 0, 2);
		world.setBlock(i + 1, j + 30, k + 8, Blocks.air, 0, 2);
		world.setBlock(i + 2, j + 30, k + 8, Blocks.air, 0, 2);
		world.setBlock(i + 3, j + 30, k + 8, Blocks.air, 0, 2);
		world.setBlock(i + 4, j + 30, k + 8, NovaCraftBlocks.basal_bricks, 0, 2);
		world.setBlock(i + 5, j + 30, k + 8, NovaCraftBlocks.basal_bricks, 0, 2);
		world.setBlock(i + 6, j + 30, k + 8, NovaCraftBlocks.basal_bricks, 0, 2);
		world.setBlock(i + 7, j + 30, k + 8, NovaCraftBlocks.basal_bricks, 0, 2);
		world.setBlock(i + 8, j + 30, k + 8, NovaCraftBlocks.cracked_basal_bricks, 0, 2);
		world.setBlock(i + 9, j + 30, k + 8, NovaCraftBlocks.cracked_basal_bricks, 0, 2);
		world.setBlock(i + 10, j + 30, k + 8, Blocks.air, 0, 2);
		world.setBlock(i + 11, j + 30, k + 8, Blocks.air, 0, 2);
		world.setBlock(i + 12, j + 30, k + 8, Blocks.air, 0, 2);
		world.setBlock(i + 13, j + 30, k + 8, NovaCraftBlocks.cracked_basal_bricks, 0, 2);
		world.setBlock(i + 14, j + 30, k + 8, NovaCraftBlocks.basal_bricks, 0, 2);
		world.setBlock(i + 15, j + 30, k + 8, NovaCraftBlocks.basal_bricks, 0, 2);
		world.setBlock(i + 16, j + 30, k + 8, NovaCraftBlocks.basal_bricks, 0, 2);
		world.setBlock(i + 17, j + 30, k + 8, NovaCraftBlocks.basal_bricks, 0, 2);
		world.setBlock(i + 18, j + 30, k + 8, NovaCraftBlocks.cracked_basal_bricks, 0, 2);
		world.setBlock(i + 19, j + 30, k + 8, NovaCraftBlocks.basal_bricks, 0, 2);
		world.setBlock(i + 20, j + 30, k + 8, NovaCraftBlocks.basal_bricks, 0, 2);
		world.setBlock(i + 21, j + 30, k + 8, NovaCraftBlocks.cracked_basal_bricks, 0, 2);
		world.setBlock(i + 22, j + 30, k + 8, NovaCraftBlocks.basal_bricks, 0, 2);
		world.setBlock(i + 23, j + 30, k + 8, NovaCraftBlocks.cracked_basal_bricks, 0, 2);
		world.setBlock(i + 24, j + 30, k + 8, NovaCraftBlocks.cracked_basal_bricks, 0, 2);
		world.setBlock(i + 25, j + 30, k + 8, NovaCraftBlocks.basal_bricks, 0, 2);
		world.setBlock(i + 26, j + 30, k + 8, NovaCraftBlocks.cracked_basal_bricks, 0, 2);
		world.setBlock(i + 27, j + 30, k + 8, NovaCraftBlocks.basal_bricks, 0, 2);
		world.setBlock(i + 0, j + 30, k + 9, NovaCraftBlocks.cracked_basal_bricks, 0, 2);
		world.setBlock(i + 1, j + 30, k + 9, Blocks.air, 0, 2);
		world.setBlock(i + 2, j + 30, k + 9, Blocks.air, 0, 2);
		world.setBlock(i + 3, j + 30, k + 9, Blocks.air, 0, 2);
		world.setBlock(i + 4, j + 30, k + 9, NovaCraftBlocks.basal_bricks, 0, 2);
		world.setBlock(i + 5, j + 30, k + 9, NovaCraftBlocks.cracked_basal_bricks, 0, 2);
		world.setBlock(i + 6, j + 30, k + 9, NovaCraftBlocks.basal_bricks, 0, 2);
		world.setBlock(i + 7, j + 30, k + 9, NovaCraftBlocks.basal_bricks, 0, 2);
		world.setBlock(i + 8, j + 30, k + 9, NovaCraftBlocks.basal_bricks, 0, 2);
		world.setBlock(i + 9, j + 30, k + 9, NovaCraftBlocks.basal_bricks, 0, 2);
		world.setBlock(i + 10, j + 30, k + 9, Blocks.air, 0, 2);
		world.setBlock(i + 11, j + 30, k + 9, Blocks.air, 0, 2);
		world.setBlock(i + 12, j + 30, k + 9, Blocks.air, 0, 2);
		world.setBlock(i + 13, j + 30, k + 9, NovaCraftBlocks.basal_bricks, 0, 2);
		world.setBlock(i + 14, j + 30, k + 9, NovaCraftBlocks.cracked_basal_bricks, 0, 2);
		world.setBlock(i + 15, j + 30, k + 9, NovaCraftBlocks.basal_bricks, 0, 2);
		world.setBlock(i + 16, j + 30, k + 9, NovaCraftBlocks.basal_bricks, 0, 2);
		world.setBlock(i + 17, j + 30, k + 9, NovaCraftBlocks.cracked_basal_bricks, 0, 2);
		world.setBlock(i + 18, j + 30, k + 9, NovaCraftBlocks.basal_bricks, 0, 2);
		world.setBlock(i + 19, j + 30, k + 9, NovaCraftBlocks.basal_bricks, 0, 2);
		world.setBlock(i + 20, j + 30, k + 9, NovaCraftBlocks.cracked_basal_bricks, 0, 2);
		world.setBlock(i + 21, j + 30, k + 9, NovaCraftBlocks.cracked_basal_bricks, 0, 2);
		world.setBlock(i + 22, j + 30, k + 9, NovaCraftBlocks.basal_bricks, 0, 2);
		world.setBlock(i + 23, j + 30, k + 9, NovaCraftBlocks.cracked_basal_bricks, 0, 2);
		world.setBlock(i + 24, j + 30, k + 9, NovaCraftBlocks.basal_bricks, 0, 2);
		world.setBlock(i + 25, j + 30, k + 9, NovaCraftBlocks.basal_bricks, 0, 2);
		world.setBlock(i + 26, j + 30, k + 9, NovaCraftBlocks.cracked_basal_bricks, 0, 2);
		world.setBlock(i + 27, j + 30, k + 9, NovaCraftBlocks.basal_bricks, 0, 2);
		world.setBlock(i + 0, j + 30, k + 10, NovaCraftBlocks.basal_bricks, 0, 2);
		world.setBlock(i + 1, j + 30, k + 10, NovaCraftBlocks.basal_bricks, 0, 2);
		world.setBlock(i + 2, j + 30, k + 10, NovaCraftBlocks.basal_bricks, 0, 2);
		world.setBlock(i + 3, j + 30, k + 10, NovaCraftBlocks.basal_bricks, 0, 2);
		world.setBlock(i + 4, j + 30, k + 10, NovaCraftBlocks.basal_bricks, 0, 2);
		world.setBlock(i + 5, j + 30, k + 10, NovaCraftBlocks.cracked_basal_bricks, 0, 2);
		world.setBlock(i + 6, j + 30, k + 10, NovaCraftBlocks.cracked_basal_bricks, 0, 2);
		world.setBlock(i + 7, j + 30, k + 10, NovaCraftBlocks.basal_bricks, 0, 2);
		world.setBlock(i + 8, j + 30, k + 10, NovaCraftBlocks.cracked_basal_bricks, 0, 2);
		world.setBlock(i + 9, j + 30, k + 10, NovaCraftBlocks.cracked_basal_bricks, 0, 2);
		world.setBlock(i + 10, j + 30, k + 10, NovaCraftBlocks.cracked_basal_bricks, 0, 2);
		world.setBlock(i + 11, j + 30, k + 10, NovaCraftBlocks.cracked_basal_bricks, 0, 2);
		world.setBlock(i + 12, j + 30, k + 10, NovaCraftBlocks.basal_bricks, 0, 2);
		world.setBlock(i + 13, j + 30, k + 10, NovaCraftBlocks.basal_bricks, 0, 2);
		world.setBlock(i + 14, j + 30, k + 10, NovaCraftBlocks.cracked_basal_bricks, 0, 2);
		world.setBlock(i + 15, j + 30, k + 10, Blocks.air, 0, 2);
		world.setBlock(i + 16, j + 30, k + 10, Blocks.air, 0, 2);
		world.setBlock(i + 17, j + 30, k + 10, Blocks.air, 0, 2);
		world.setBlock(i + 18, j + 30, k + 10, Blocks.air, 0, 2);
		world.setBlock(i + 19, j + 30, k + 10, NovaCraftBlocks.cracked_basal_bricks, 0, 2);
		world.setBlock(i + 20, j + 30, k + 10, NovaCraftBlocks.basal_bricks, 0, 2);
		world.setBlock(i + 21, j + 30, k + 10, NovaCraftBlocks.basal_bricks, 0, 2);
		world.setBlock(i + 22, j + 30, k + 10, NovaCraftBlocks.basal_bricks, 0, 2);
		world.setBlock(i + 23, j + 30, k + 10, Blocks.air, 0, 2);
		world.setBlock(i + 24, j + 30, k + 10, Blocks.air, 0, 2);
		world.setBlock(i + 25, j + 30, k + 10, Blocks.air, 0, 2);
		world.setBlock(i + 26, j + 30, k + 10, Blocks.air, 0, 2);
		world.setBlock(i + 27, j + 30, k + 10, NovaCraftBlocks.cracked_basal_bricks, 0, 2);
		world.setBlock(i + 0, j + 30, k + 11, Blocks.air, 0, 2);
		world.setBlock(i + 1, j + 30, k + 11, Blocks.air, 0, 2);
		world.setBlock(i + 2, j + 30, k + 11, Blocks.air, 0, 2);
		world.setBlock(i + 3, j + 30, k + 11, Blocks.air, 0, 2);
		world.setBlock(i + 4, j + 30, k + 11, Blocks.air, 0, 2);
		world.setBlock(i + 5, j + 30, k + 11, Blocks.air, 0, 2);
		world.setBlock(i + 6, j + 30, k + 11, Blocks.air, 0, 2);
		world.setBlock(i + 7, j + 30, k + 11, Blocks.air, 0, 2);
		world.setBlock(i + 8, j + 30, k + 11, Blocks.air, 0, 2);
		world.setBlock(i + 9, j + 30, k + 11, Blocks.air, 0, 2);
		world.setBlock(i + 10, j + 30, k + 11, Blocks.air, 0, 2);
		world.setBlock(i + 11, j + 30, k + 11, Blocks.air, 0, 2);
		world.setBlock(i + 12, j + 30, k + 11, Blocks.air, 0, 2);
		world.setBlock(i + 13, j + 30, k + 11, Blocks.air, 0, 2);
		world.setBlock(i + 14, j + 30, k + 11, NovaCraftBlocks.cracked_basal_bricks, 0, 2);
		world.setBlock(i + 15, j + 30, k + 11, Blocks.air, 0, 2);
		world.setBlock(i + 16, j + 30, k + 11, Blocks.air, 0, 2);
		world.setBlock(i + 17, j + 30, k + 11, Blocks.air, 0, 2);
		world.setBlock(i + 18, j + 30, k + 11, Blocks.air, 0, 2);
		world.setBlock(i + 19, j + 30, k + 11, NovaCraftBlocks.cracked_basal_bricks, 0, 2);
		world.setBlock(i + 20, j + 30, k + 11, NovaCraftBlocks.basal_bricks, 0, 2);
		world.setBlock(i + 21, j + 30, k + 11, NovaCraftBlocks.cracked_basal_bricks, 0, 2);
		world.setBlock(i + 22, j + 30, k + 11, NovaCraftBlocks.basal_bricks, 0, 2);
		world.setBlock(i + 23, j + 30, k + 11, Blocks.air, 0, 2);
		world.setBlock(i + 24, j + 30, k + 11, Blocks.air, 0, 2);
		world.setBlock(i + 25, j + 30, k + 11, Blocks.air, 0, 2);
		world.setBlock(i + 27, j + 30, k + 11, NovaCraftBlocks.basal_bricks, 0, 2);
		world.setBlock(i + 0, j + 30, k + 12, Blocks.air, 0, 2);
		world.setBlock(i + 1, j + 30, k + 12, Blocks.air, 0, 2);
		world.setBlock(i + 2, j + 30, k + 12, Blocks.air, 0, 2);
		world.setBlock(i + 3, j + 30, k + 12, Blocks.air, 0, 2);
		world.setBlock(i + 4, j + 30, k + 12, Blocks.air, 0, 2);
		world.setBlock(i + 5, j + 30, k + 12, Blocks.air, 0, 2);
		world.setBlock(i + 6, j + 30, k + 12, Blocks.air, 0, 2);
		world.setBlock(i + 7, j + 30, k + 12, Blocks.air, 0, 2);
		world.setBlock(i + 8, j + 30, k + 12, Blocks.air, 0, 2);
		world.setBlock(i + 9, j + 30, k + 12, Blocks.air, 0, 2);
		world.setBlock(i + 10, j + 30, k + 12, Blocks.air, 0, 2);
		world.setBlock(i + 11, j + 30, k + 12, Blocks.air, 0, 2);
