package com.NovaCraft.world.bastion.treasure;

import net.minecraft.world.gen.feature.*;
import net.minecraft.block.*;
import net.minecraft.world.*;
import java.util.*;

import com.NovaCraft.config.Configs;
import com.NovaCraft.registry.OtherModBlocks;
import com.NovaCraftBlocks.NovaCraftBlocks;

import cpw.mods.fml.common.Loader;
import net.minecraft.init.*;

public class BastionTreasureBarracksGen2 extends WorldGenerator
{
	public BastionTreasureBarracksGen2() {

	}
    
    public boolean generate(final World world, final Random random, final int i, final int j, final int k) {
    	
    	world.setBlock(i + 15, j + 6, k + 0, Blocks.air, 0, 2);
		world.setBlock(i + 16, j + 6, k + 0, Blocks.air, 0, 2);
		world.setBlock(i + 17, j + 6, k + 0, Blocks.air, 0, 2);
		world.setBlock(i + 18, j + 6, k + 0, Blocks.air, 0, 2);
		world.setBlock(i + 19, j + 6, k + 0, Blocks.air, 0, 2);
		world.setBlock(i + 20, j + 6, k + 0, Blocks.air, 0, 2);
		world.setBlock(i + 21, j + 6, k + 0, Blocks.air, 0, 2);
		world.setBlock(i + 22, j + 6, k + 0, Blocks.air, 0, 2);
		world.setBlock(i + 23, j + 6, k + 0, Blocks.air, 0, 2);
		world.setBlock(i + 24, j + 6, k + 0, Blocks.air, 0, 2);
		world.setBlock(i + 25, j + 6, k + 0, Blocks.air, 0, 2);
		world.setBlock(i + 26, j + 6, k + 0, Blocks.air, 0, 2);
		world.setBlock(i + 27, j + 6, k + 0, Blocks.air, 0, 2);
		world.setBlock(i + 0, j + 6, k + 1, Blocks.air, 0, 2);
		world.setBlock(i + 1, j + 6, k + 1, Blocks.air, 0, 2);
		world.setBlock(i + 2, j + 6, k + 1, Blocks.air, 0, 2);
		world.setBlock(i + 3, j + 6, k + 1, Blocks.air, 0, 2);
		world.setBlock(i + 4, j + 6, k + 1, NovaCraftBlocks.basal, 0, 2);
		world.setBlock(i + 5, j + 6, k + 1, NovaCraftBlocks.basal, 0, 2);
		world.setBlock(i + 6, j + 6, k + 1, Blocks.air, 0, 2);
		world.setBlock(i + 7, j + 6, k + 1, Blocks.air, 0, 2);
		world.setBlock(i + 8, j + 6, k + 1, NovaCraftBlocks.basal, 0, 2);
		world.setBlock(i + 9, j + 6, k + 1, Blocks.air, 0, 2);
		world.setBlock(i + 10, j + 6, k + 1, Blocks.air, 0, 2);
		world.setBlock(i + 11, j + 6, k + 1, Blocks.air, 0, 2);
		world.setBlock(i + 12, j + 6, k + 1, Blocks.air, 0, 2);
		world.setBlock(i + 13, j + 6, k + 1, Blocks.air, 0, 2);
		world.setBlock(i + 14, j + 6, k + 1, Blocks.air, 0, 2);
		world.setBlock(i + 15, j + 6, k + 1, Blocks.air, 0, 2);
		world.setBlock(i + 16, j + 6, k + 1, Blocks.air, 0, 2);
		world.setBlock(i + 17, j + 6, k + 1, Blocks.air, 0, 2);
		world.setBlock(i + 18, j + 6, k + 1, Blocks.air, 0, 2);
		world.setBlock(i + 19, j + 6, k + 1, Blocks.air, 0, 2);
		world.setBlock(i + 20, j + 6, k + 1, Blocks.air, 0, 2);
		world.setBlock(i + 21, j + 6, k + 1, Blocks.air, 0, 2);
		world.setBlock(i + 22, j + 6, k + 1, Blocks.air, 0, 2);
		world.setBlock(i + 23, j + 6, k + 1, Blocks.air, 0, 2);
		world.setBlock(i + 24, j + 6, k + 1, Blocks.air, 0, 2);
		world.setBlock(i + 25, j + 6, k + 1, Blocks.air, 0, 2);
		world.setBlock(i + 26, j + 6, k + 1, Blocks.air, 0, 2);
		world.setBlock(i + 27, j + 6, k + 1, Blocks.air, 0, 2);
		world.setBlock(i + 0, j + 6, k + 2, NovaCraftBlocks.basal, 0, 2);
		world.setBlock(i + 1, j + 6, k + 2, NovaCraftBlocks.basal, 0, 2);
		world.setBlock(i + 2, j + 6, k + 2, NovaCraftBlocks.basal, 0, 2);
		world.setBlock(i + 3, j + 6, k + 2, NovaCraftBlocks.basal, 0, 2);
		world.setBlock(i + 4, j + 6, k + 2, NovaCraftBlocks.basal, 0, 2);
		world.setBlock(i + 5, j + 6, k + 2, NovaCraftBlocks.basal, 0, 2);
		world.setBlock(i + 6, j + 6, k + 2, NovaCraftBlocks.basal, 0, 2);
		world.setBlock(i + 7, j + 6, k + 2, NovaCraftBlocks.basal, 0, 2);
		world.setBlock(i + 8, j + 6, k + 2, NovaCraftBlocks.basal, 0, 2);
		world.setBlock(i + 9, j + 6, k + 2, NovaCraftBlocks.basal, 0, 2);
		world.setBlock(i + 10, j + 6, k + 2, NovaCraftBlocks.basal, 0, 2);
		world.setBlock(i + 11, j + 6, k + 2, Blocks.air, 0, 2);
		world.setBlock(i + 12, j + 6, k + 2, NovaCraftBlocks.basal, 0, 2);
		world.setBlock(i + 13, j + 6, k + 2, Blocks.air, 0, 2);
		world.setBlock(i + 14, j + 6, k + 2, Blocks.air, 0, 2);
		world.setBlock(i + 15, j + 6, k + 2, Blocks.air, 0, 2);
		world.setBlock(i + 16, j + 6, k + 2, Blocks.air, 0, 2);
		world.setBlock(i + 17, j + 6, k + 2, Blocks.air, 0, 2);
		world.setBlock(i + 18, j + 6, k + 2, Blocks.air, 0, 2);
		world.setBlock(i + 19, j + 6, k + 2, Blocks.air, 0, 2);
		world.setBlock(i + 20, j + 6, k + 2, Blocks.air, 0, 2);
		world.setBlock(i + 21, j + 6, k + 2, Blocks.air, 0, 2);
		world.setBlock(i + 22, j + 6, k + 2, Blocks.air, 0, 2);
		world.setBlock(i + 23, j + 6, k + 2, Blocks.air, 0, 2);
		world.setBlock(i + 24, j + 6, k + 2, Blocks.air, 0, 2);
		world.setBlock(i + 25, j + 6, k + 2, Blocks.air, 0, 2);
		world.setBlock(i + 26, j + 6, k + 2, Blocks.air, 0, 2);
		world.setBlock(i + 27, j + 6, k + 2, Blocks.air, 0, 2);
		world.setBlock(i + 0, j + 6, k + 3, NovaCraftBlocks.basal_bricks, 0, 2);
		world.setBlock(i + 1, j + 6, k + 3, NovaCraftBlocks.basal, 0, 2);
		world.setBlock(i + 2, j + 6, k + 3, NovaCraftBlocks.basal, 0, 2);
		world.setBlock(i + 3, j + 6, k + 3, NovaCraftBlocks.basal, 0, 2);
		world.setBlock(i + 4, j + 6, k + 3, NovaCraftBlocks.basal, 0, 2);
		world.setBlock(i + 5, j + 6, k + 3, NovaCraftBlocks.basal, 0, 2);
		world.setBlock(i + 6, j + 6, k + 3, NovaCraftBlocks.basal, 0, 2);
		world.setBlock(i + 7, j + 6, k + 3, NovaCraftBlocks.basal, 0, 2);
		world.setBlock(i + 8, j + 6, k + 3, NovaCraftBlocks.basal, 0, 2);
		world.setBlock(i + 9, j + 6, k + 3, NovaCraftBlocks.basal, 0, 2);
		world.setBlock(i + 10, j + 6, k + 3, NovaCraftBlocks.basal, 0, 2);
		world.setBlock(i + 11, j + 6, k + 3, NovaCraftBlocks.basal, 0, 2);
		world.setBlock(i + 12, j + 6, k + 3, NovaCraftBlocks.basal, 0, 2);
		world.setBlock(i + 13, j + 6, k + 3, NovaCraftBlocks.basal, 0, 2);
		world.setBlock(i + 14, j + 6, k + 3, Blocks.air, 0, 2);
		world.setBlock(i + 15, j + 6, k + 3, Blocks.air, 0, 2);
		world.setBlock(i + 16, j + 6, k + 3, Blocks.air, 0, 2);
		world.setBlock(i + 17, j + 6, k + 3, Blocks.air, 0, 2);
		world.setBlock(i + 18, j + 6, k + 3, NovaCraftBlocks.basal, 0, 2);
		world.setBlock(i + 19, j + 6, k + 3, NovaCraftBlocks.basal, 0, 2);
		world.setBlock(i + 20, j + 6, k + 3, Blocks.air, 0, 2);
		world.setBlock(i + 21, j + 6, k + 3, Blocks.air, 0, 2);
		world.setBlock(i + 22, j + 6, k + 3, NovaCraftBlocks.basal, 0, 2);
		world.setBlock(i + 23, j + 6, k + 3, Blocks.air, 0, 2);
		world.setBlock(i + 24, j + 6, k + 3, Blocks.air, 0, 2);
		world.setBlock(i + 25, j + 6, k + 3, Blocks.air, 0, 2);
		world.setBlock(i + 26, j + 6, k + 3, Blocks.air, 0, 2);
		world.setBlock(i + 27, j + 6, k + 3, Blocks.air, 0, 2);
		world.setBlock(i + 0, j + 6, k + 4, Blocks.air, 0, 2);
		world.setBlock(i + 1, j + 6, k + 4, NovaCraftBlocks.cracked_basal_bricks, 0, 2);
		world.setBlock(i + 2, j + 6, k + 4, NovaCraftBlocks.basal, 0, 2);
		world.setBlock(i + 3, j + 6, k + 4, NovaCraftBlocks.basal, 0, 2);
		world.setBlock(i + 4, j + 6, k + 4, Blocks.air, 0, 2);
		world.setBlock(i + 5, j + 6, k + 4, Blocks.air, 0, 2);
		world.setBlock(i + 6, j + 6, k + 4, NovaCraftBlocks.basal, 0, 2);
		world.setBlock(i + 7, j + 6, k + 4, NovaCraftBlocks.basal, 0, 2);
		world.setBlock(i + 8, j + 6, k + 4, NovaCraftBlocks.basal, 0, 2);
		world.setBlock(i + 9, j + 6, k + 4, NovaCraftBlocks.basal, 0, 2);
		world.setBlock(i + 10, j + 6, k + 4, NovaCraftBlocks.basal, 0, 2);
		world.setBlock(i + 11, j + 6, k + 4, NovaCraftBlocks.basal, 0, 2);
		world.setBlock(i + 12, j + 6, k + 4, NovaCraftBlocks.basal, 0, 2);
		world.setBlock(i + 13, j + 6, k + 4, NovaCraftBlocks.basal, 0, 2);
		world.setBlock(i + 14, j + 6, k + 4, NovaCraftBlocks.basal, 0, 2);
		world.setBlock(i + 15, j + 6, k + 4, NovaCraftBlocks.basal, 0, 2);
		world.setBlock(i + 16, j + 6, k + 4, NovaCraftBlocks.basal, 0, 2);
		world.setBlock(i + 17, j + 6, k + 4, NovaCraftBlocks.basal, 0, 2);
		world.setBlock(i + 18, j + 6, k + 4, NovaCraftBlocks.basal, 0, 2);
		world.setBlock(i + 19, j + 6, k + 4, NovaCraftBlocks.basal, 0, 2);
		world.setBlock(i + 20, j + 6, k + 4, NovaCraftBlocks.basal, 0, 2);
		world.setBlock(i + 21, j + 6, k + 4, NovaCraftBlocks.basal, 0, 2);
		world.setBlock(i + 22, j + 6, k + 4, NovaCraftBlocks.basal, 0, 2);
		world.setBlock(i + 23, j + 6, k + 4, NovaCraftBlocks.basal, 0, 2);
		world.setBlock(i + 24, j + 6, k + 4, NovaCraftBlocks.basal, 0, 2);
		world.setBlock(i + 25, j + 6, k + 4, Blocks.air, 0, 2);
		world.setBlock(i + 26, j + 6, k + 4, NovaCraftBlocks.basal, 0, 2);
		world.setBlock(i + 27, j + 6, k + 4, Blocks.air, 0, 2);
		world.setBlock(i + 0, j + 6, k + 5, Blocks.air, 0, 2);
		world.setBlock(i + 1, j + 6, k + 5, NovaCraftBlocks.chiseled_basal, 0, 2);
		world.setBlock(i + 2, j + 6, k + 5, Blocks.air, 0, 2);
		world.setBlock(i + 3, j + 6, k + 5, Blocks.air, 0, 2);
		world.setBlock(i + 4, j + 6, k + 5, Blocks.air, 0, 2);
		world.setBlock(i + 5, j + 6, k + 5, Blocks.air, 0, 2);
		world.setBlock(i + 6, j + 6, k + 5, NovaCraftBlocks.basal, 0, 2);
		world.setBlock(i + 7, j + 6, k + 5, NovaCraftBlocks.basal, 0, 2);
		world.setBlock(i + 8, j + 6, k + 5, NovaCraftBlocks.basal, 0, 2);
		world.setBlock(i + 9, j + 6, k + 5, NovaCraftBlocks.basal, 0, 2);
		world.setBlock(i + 10, j + 6, k + 5, NovaCraftBlocks.basal, 0, 2);
		world.setBlock(i + 11, j + 6, k + 5, NovaCraftBlocks.basal, 0, 2);
		world.setBlock(i + 12, j + 6, k + 5, NovaCraftBlocks.basal, 0, 2);
		world.setBlock(i + 13, j + 6, k + 5, NovaCraftBlocks.basal, 0, 2);
		world.setBlock(i + 14, j + 6, k + 5, NovaCraftBlocks.cracked_basal_bricks, 0, 2);
		world.setBlock(i + 15, j + 6, k + 5, NovaCraftBlocks.basal, 0, 2);
		world.setBlock(i + 16, j + 6, k + 5, NovaCraftBlocks.basal, 0, 2);
		world.setBlock(i + 17, j + 6, k + 5, NovaCraftBlocks.basal, 0, 2);
		world.setBlock(i + 18, j + 6, k + 5, NovaCraftBlocks.basal, 0, 2);
		world.setBlock(i + 19, j + 6, k + 5, NovaCraftBlocks.basal, 0, 2);
		world.setBlock(i + 20, j + 6, k + 5, NovaCraftBlocks.basal, 0, 2);
		world.setBlock(i + 21, j + 6, k + 5, NovaCraftBlocks.basal, 0, 2);
		world.setBlock(i + 22, j + 6, k + 5, NovaCraftBlocks.basal, 0, 2);
		world.setBlock(i + 23, j + 6, k + 5, NovaCraftBlocks.basal, 0, 2);
		world.setBlock(i + 24, j + 6, k + 5, NovaCraftBlocks.basal, 0, 2);
		world.setBlock(i + 25, j + 6, k + 5, NovaCraftBlocks.basal, 0, 2);
		world.setBlock(i + 26, j + 6, k + 5, NovaCraftBlocks.basal, 0, 2);
		world.setBlock(i + 27, j + 6, k + 5, NovaCraftBlocks.basal, 0, 2);
		world.setBlock(i + 0, j + 6, k + 6, Blocks.air, 0, 2);
		world.setBlock(i + 1, j + 6, k + 6, Blocks.air, 0, 2);
		world.setBlock(i + 2, j + 6, k + 6, Blocks.air, 0, 2);
		world.setBlock(i + 3, j + 6, k + 6, Blocks.air, 0, 2);
		world.setBlock(i + 4, j + 6, k + 6, Blocks.air, 0, 2);
		world.setBlock(i + 5, j + 6, k + 6, NovaCraftBlocks.basal, 0, 2);
		world.setBlock(i + 6, j + 6, k + 6, NovaCraftBlocks.basal, 0, 2);
		world.setBlock(i + 7, j + 6, k + 6, NovaCraftBlocks.basal, 0, 2);
		world.setBlock(i + 8, j + 6, k + 6, Blocks.air, 0, 2);
		world.setBlock(i + 9, j + 6, k + 6, Blocks.air, 0, 2);
		world.setBlock(i + 10, j + 6, k + 6, NovaCraftBlocks.basal, 0, 2);
		world.setBlock(i + 11, j + 6, k + 6, NovaCraftBlocks.basal, 0, 2);
		world.setBlock(i + 12, j + 6, k + 6, NovaCraftBlocks.basal, 0, 2);
		world.setBlock(i + 13, j + 6, k + 6, NovaCraftBlocks.basal, 0, 2);
		world.setBlock(i + 14, j + 6, k + 6, Blocks.air, 0, 2);
		world.setBlock(i + 15, j + 6, k + 6, NovaCraftBlocks.cracked_basal_bricks, 0, 2);
		world.setBlock(i + 16, j + 6, k + 6, NovaCraftBlocks.basal, 0, 2);
		world.setBlock(i + 17, j + 6, k + 6, NovaCraftBlocks.basal, 0, 2);
		world.setBlock(i + 18, j + 6, k + 6, Blocks.air, 0, 2);
		world.setBlock(i + 19, j + 6, k + 6, Blocks.air, 0, 2);
		world.setBlock(i + 20, j + 6, k + 6, NovaCraftBlocks.basal, 0, 2);
		world.setBlock(i + 21, j + 6, k + 6, NovaCraftBlocks.basal, 0, 2);
		world.setBlock(i + 22, j + 6, k + 6, NovaCraftBlocks.basal, 0, 2);
		world.setBlock(i + 23, j + 6, k + 6, NovaCraftBlocks.basal, 0, 2);
		world.setBlock(i + 24, j + 6, k + 6, NovaCraftBlocks.basal, 0, 2);
		world.setBlock(i + 25, j + 6, k + 6, NovaCraftBlocks.basal, 0, 2);
		world.setBlock(i + 26, j + 6, k + 6, NovaCraftBlocks.basal, 0, 2);
		world.setBlock(i + 27, j + 6, k + 6, NovaCraftBlocks.basal, 0, 2);
		world.setBlock(i + 0, j + 6, k + 7, NovaCraftBlocks.basal_bricks, 0, 2);
		world.setBlock(i + 1, j + 6, k + 7, NovaCraftBlocks.cracked_basal_bricks, 0, 2);
		world.setBlock(i + 2, j + 6, k + 7, NovaCraftBlocks.basal, 0, 2);
		world.setBlock(i + 3, j + 6, k + 7, NovaCraftBlocks.basal, 0, 2);
		world.setBlock(i + 4, j + 6, k + 7, NovaCraftBlocks.basal, 0, 2);
		world.setBlock(i + 5, j + 6, k + 7, NovaCraftBlocks.basal, 0, 2);
		world.setBlock(i + 6, j + 6, k + 7, NovaCraftBlocks.basal, 0, 2);
		world.setBlock(i + 7, j + 6, k + 7, Blocks.lava, 8, 2);
		world.setBlock(i + 8, j + 6, k + 7, NovaCraftBlocks.cracked_basal_bricks, 0, 2);
		world.setBlock(i + 9, j + 6, k + 7, Blocks.air, 0, 2);
		world.setBlock(i + 10, j + 6, k + 7, Blocks.air, 0, 2);
		world.setBlock(i + 11, j + 6, k + 7, NovaCraftBlocks.basal, 0, 2);
		world.setBlock(i + 12, j + 6, k + 7, NovaCraftBlocks.basal, 0, 2);
		world.setBlock(i + 13, j + 6, k + 7, NovaCraftBlocks.basal, 0, 2);
		world.setBlock(i + 14, j + 6, k + 7, Blocks.air, 0, 2);
		world.setBlock(i + 15, j + 6, k + 7, NovaCraftBlocks.chiseled_basal, 0, 2);
		world.setBlock(i + 16, j + 6, k + 7, Blocks.air, 0, 2);
		world.setBlock(i + 17, j + 6, k + 7, Blocks.air, 0, 2);
		world.setBlock(i + 18, j + 6, k + 7, Blocks.air, 0, 2);
		world.setBlock(i + 19, j + 6, k + 7, Blocks.air, 0, 2);
		world.setBlock(i + 20, j + 6, k + 7, NovaCraftBlocks.basal, 0, 2);
		world.setBlock(i + 21, j + 6, k + 7, NovaCraftBlocks.basal, 0, 2);
		world.setBlock(i + 22, j + 6, k + 7, NovaCraftBlocks.basal, 0, 2);
		world.setBlock(i + 23, j + 6, k + 7, NovaCraftBlocks.basal, 0, 2);
		world.setBlock(i + 24, j + 6, k + 7, NovaCraftBlocks.basal, 0, 2);
		world.setBlock(i + 25, j + 6, k + 7, NovaCraftBlocks.basal, 0, 2);
		world.setBlock(i + 26, j + 6, k + 7, NovaCraftBlocks.basal, 0, 2);
		world.setBlock(i + 27, j + 6, k + 7, NovaCraftBlocks.basal, 0, 2);
		world.setBlock(i + 0, j + 6, k + 8, NovaCraftBlocks.basal, 0, 2);
		world.setBlock(i + 1, j + 6, k + 8, NovaCraftBlocks.basal, 0, 2);
		world.setBlock(i + 2, j + 6, k + 8, NovaCraftBlocks.basal, 0, 2);
		world.setBlock(i + 3, j + 6, k + 8, NovaCraftBlocks.basal, 0, 2);
		world.setBlock(i + 4, j + 6, k + 8, NovaCraftBlocks.basal, 0, 2);
		world.setBlock(i + 5, j + 6, k + 8, NovaCraftBlocks.basal, 0, 2);
		world.setBlock(i + 6, j + 6, k + 8, NovaCraftBlocks.basal, 0, 2);
		world.setBlock(i + 7, j + 6, k + 8, Blocks.air, 0, 2);
		world.setBlock(i + 8, j + 6, k + 8, Blocks.air, 0, 2);
		world.setBlock(i + 9, j + 6, k + 8, Blocks.air, 0, 2);
		world.setBlock(i + 10, j + 6, k + 8, Blocks.air, 0, 2);
		world.setBlock(i + 11, j + 6, k + 8, Blocks.air, 0, 2);
		world.setBlock(i + 12, j + 6, k + 8, NovaCraftBlocks.basal, 0, 2);
		world.setBlock(i + 13, j + 6, k + 8, NovaCraftBlocks.basal, 0, 2);
		world.setBlock(i + 14, j + 6, k + 8, Blocks.air, 0, 2);
		world.setBlock(i + 15, j + 6, k + 8, Blocks.air, 0, 2);
		world.setBlock(i + 16, j + 6, k + 8, Blocks.air, 0, 2);
		world.setBlock(i + 17, j + 6, k + 8, Blocks.air, 0, 2);
		world.setBlock(i + 18, j + 6, k + 8, Blocks.air, 0, 2);
		world.setBlock(i + 19, j + 6, k + 8, NovaCraftBlocks.basal, 0, 2);
		world.setBlock(i + 20, j + 6, k + 8, NovaCraftBlocks.basal, 0, 2);
		world.setBlock(i + 21, j + 6, k + 8, NovaCraftBlocks.basal, 0, 2);
		world.setBlock(i + 22, j + 6, k + 8, Blocks.air, 0, 2);
		world.setBlock(i + 23, j + 6, k + 8, Blocks.air, 0, 2);
		world.setBlock(i + 24, j + 6, k + 8, NovaCraftBlocks.basal, 0, 2);
		world.setBlock(i + 25, j + 6, k + 8, NovaCraftBlocks.basal, 0, 2);
		world.setBlock(i + 26, j + 6, k + 8, NovaCraftBlocks.basal, 0, 2);
		world.setBlock(i + 27, j + 6, k + 8, NovaCraftBlocks.basal, 0, 2);
		world.setBlock(i + 0, j + 6, k + 9, NovaCraftBlocks.basal, 0, 2);
		world.setBlock(i + 1, j + 6, k + 9, NovaCraftBlocks.basal, 0, 2);
		world.setBlock(i + 2, j + 6, k + 9, NovaCraftBlocks.basal, 0, 2);
		world.setBlock(i + 3, j + 6, k + 9, NovaCraftBlocks.basal, 0, 2);
		world.setBlock(i + 4, j + 6, k + 9, NovaCraftBlocks.basal, 0, 2);
		world.setBlock(i + 5, j + 6, k + 9, NovaCraftBlocks.basal, 0, 2);
		world.setBlock(i + 6, j + 6, k + 9, NovaCraftBlocks.basal, 0, 2);
		world.setBlock(i + 7, j + 6, k + 9, NovaCraftBlocks.basal, 0, 2);
		world.setBlock(i + 8, j + 6, k + 9, NovaCraftBlocks.basal, 0, 2);
		world.setBlock(i + 9, j + 6, k + 9, NovaCraftBlocks.glowing_basal, 0, 2);
		world.setBlock(i + 10, j + 6, k + 9, Blocks.air, 0, 2);
		world.setBlock(i + 11, j + 6, k + 9, Blocks.air, 0, 2);
		world.setBlock(i + 12, j + 6, k + 9, NovaCraftBlocks.basal, 0, 2);
		world.setBlock(i + 13, j + 6, k + 9, Blocks.air, 0, 2);
		world.setBlock(i + 14, j + 6, k + 9, NovaCraftBlocks.cracked_basal_bricks, 0, 2);
		world.setBlock(i + 15, j + 6, k + 9, NovaCraftBlocks.cracked_basal_bricks, 0, 2);
		world.setBlock(i + 16, j + 6, k + 9, NovaCraftBlocks.basal, 0, 2);
		world.setBlock(i + 17, j + 6, k + 9, NovaCraftBlocks.basal, 0, 2);
		world.setBlock(i + 18, j + 6, k + 9, NovaCraftBlocks.basal, 0, 2);
		world.setBlock(i + 19, j + 6, k + 9, NovaCraftBlocks.basal, 0, 2);
		world.setBlock(i + 20, j + 6, k + 9, NovaCraftBlocks.basal, 0, 2);
		world.setBlock(i + 21, j + 6, k + 9, Blocks.lava, 8, 2);
		world.setBlock(i + 22, j + 6, k + 9, NovaCraftBlocks.cracked_basal_bricks, 0, 2);
		world.setBlock(i + 23, j + 6, k + 9, Blocks.air, 0, 2);
		world.setBlock(i + 24, j + 6, k + 9, Blocks.air, 0, 2);
		world.setBlock(i + 25, j + 6, k + 9, NovaCraftBlocks.basal, 0, 2);
		world.setBlock(i + 26, j + 6, k + 9, NovaCraftBlocks.basal, 0, 2);
		world.setBlock(i + 27, j + 6, k + 9, NovaCraftBlocks.basal, 0, 2);
		world.setBlock(i + 0, j + 6, k + 10, NovaCraftBlocks.basal, 0, 2);
		world.setBlock(i + 1, j + 6, k + 10, NovaCraftBlocks.basal, 0, 2);
		world.setBlock(i + 2, j + 6, k + 10, NovaCraftBlocks.basal, 0, 2);
		world.setBlock(i + 3, j + 6, k + 10, NovaCraftBlocks.basal, 0, 2);
		world.setBlock(i + 4, j + 6, k + 10, NovaCraftBlocks.basal, 0, 2);
		world.setBlock(i + 5, j + 6, k + 10, NovaCraftBlocks.basal, 0, 2);
		world.setBlock(i + 6, j + 6, k + 10, NovaCraftBlocks.basal, 0, 2);
		world.setBlock(i + 7, j + 6, k + 10, NovaCraftBlocks.basal, 0, 2);
		world.setBlock(i + 8, j + 6, k + 10, NovaCraftBlocks.basal, 0, 2);
		world.setBlock(i + 9, j + 6, k + 10, NovaCraftBlocks.basal, 0, 2);
		world.setBlock(i + 10, j + 6, k + 10, NovaCraftBlocks.basal, 0, 2);
		world.setBlock(i + 11, j + 6, k + 10, NovaCraftBlocks.basal, 0, 2);
		world.setBlock(i + 12, j + 6, k + 10, Blocks.air, 0, 2);
		world.setBlock(i + 13, j + 6, k + 10, Blocks.air, 0, 2);
		world.setBlock(i + 14, j + 6, k + 10, NovaCraftBlocks.basal, 0, 2);
		world.setBlock(i + 15, j + 6, k + 10, NovaCraftBlocks.basal, 0, 2);
		world.setBlock(i + 16, j + 6, k + 10, NovaCraftBlocks.basal, 0, 2);
		world.setBlock(i + 17, j + 6, k + 10, NovaCraftBlocks.basal, 0, 2);
		world.setBlock(i + 18, j + 6, k + 10, NovaCraftBlocks.basal, 0, 2);
		world.setBlock(i + 19, j + 6, k + 10, NovaCraftBlocks.basal, 0, 2);
		world.setBlock(i + 20, j + 6, k + 10, NovaCraftBlocks.basal, 0, 2);
		world.setBlock(i + 21, j + 6, k + 10, Blocks.air, 0, 2);
		world.setBlock(i + 22, j + 6, k + 10, Blocks.air, 0, 2);
		world.setBlock(i + 23, j + 6, k + 10, Blocks.air, 0, 2);
		world.setBlock(i + 24, j + 6, k + 10, Blocks.air, 0, 2);
		world.setBlock(i + 25, j + 6, k + 10, Blocks.air, 0, 2);
		world.setBlock(i + 26, j + 6, k + 10, NovaCraftBlocks.basal, 0, 2);
		world.setBlock(i + 27, j + 6, k + 10, NovaCraftBlocks.basal, 0, 2);
		world.setBlock(i + 0, j + 6, k + 11, NovaCraftBlocks.basal_bricks, 0, 2);
		world.setBlock(i + 1, j + 6, k + 11, NovaCraftBlocks.cracked_basal_bricks, 0, 2);
		world.setBlock(i + 2, j + 6, k + 11, NovaCraftBlocks.basal_bricks, 0, 2);
		world.setBlock(i + 3, j + 6, k + 11, NovaCraftBlocks.basal_bricks, 0, 2);
		world.setBlock(i + 4, j + 6, k + 11, NovaCraftBlocks.basal_bricks, 0, 2);
		world.setBlock(i + 5, j + 6, k + 11, NovaCraftBlocks.basal_bricks, 0, 2);
		world.setBlock(i + 6, j + 6, k + 11, NovaCraftBlocks.basal_bricks, 0, 2);
		world.setBlock(i + 7, j + 6, k + 11, NovaCraftBlocks.basal_bricks, 0, 2);
		world.setBlock(i + 8, j + 6, k + 11, NovaCraftBlocks.cracked_basal_bricks, 0, 2);
		world.setBlock(i + 9, j + 6, k + 11, NovaCraftBlocks.basal_bricks, 0, 2);
		world.setBlock(i + 10, j + 6, k + 11, NovaCraftBlocks.basal_bricks, 0, 2);
		world.setBlock(i + 11, j + 6, k + 11, NovaCraftBlocks.cracked_basal_bricks, 0, 2);
		world.setBlock(i + 12, j + 6, k + 11, Blocks.air, 0, 2);
		world.setBlock(i + 13, j + 6, k + 11, Blocks.air, 0, 2);
		world.setBlock(i + 14, j + 6, k + 11, NovaCraftBlocks.basal, 0, 2);
		world.setBlock(i + 15, j + 6, k + 11, NovaCraftBlocks.basal, 0, 2);
		world.setBlock(i + 16, j + 6, k + 11, NovaCraftBlocks.basal, 0, 2);
		world.setBlock(i + 17, j + 6, k + 11, NovaCraftBlocks.basal, 0, 2);
		world.setBlock(i + 18, j + 6, k + 11, NovaCraftBlocks.basal, 0, 2);
		world.setBlock(i + 19, j + 6, k + 11, NovaCraftBlocks.basal, 0, 2);
		world.setBlock(i + 20, j + 6, k + 11, NovaCraftBlocks.basal, 0, 2);
		world.setBlock(i + 21, j + 6, k + 11, NovaCraftBlocks.basal, 0, 2);
		world.setBlock(i + 22, j + 6, k + 11, NovaCraftBlocks.basal, 0, 2);
		world.setBlock(i + 23, j + 6, k + 11, NovaCraftBlocks.basal, 0, 2);
		world.setBlock(i + 24, j + 6, k + 11, Blocks.air, 0, 2);
		world.setBlock(i + 25, j + 6, k + 11, Blocks.air, 0, 2);
		world.setBlock(i + 26, j + 6, k + 11, NovaCraftBlocks.basal, 0, 2);
		world.setBlock(i + 27, j + 6, k + 11, Blocks.air, 0, 2);
		world.setBlock(i + 0, j + 6, k + 12, NovaCraftBlocks.basal_bricks, 0, 2);
		world.setBlock(i + 1, j + 6, k + 12, NovaCraftBlocks.cracked_basal_bricks, 0, 2);
		world.setBlock(i + 2, j + 6, k + 12, NovaCraftBlocks.basal_bricks, 0, 2);
		world.setBlock(i + 3, j + 6, k + 12, NovaCraftBlocks.basal_bricks, 0, 2);
		world.setBlock(i + 4, j + 6, k + 12, NovaCraftBlocks.cracked_basal_bricks, 0, 2);
		world.setBlock(i + 5, j + 6, k + 12, NovaCraftBlocks.cracked_basal_bricks, 0, 2);
		world.setBlock(i + 6, j + 6, k + 12, NovaCraftBlocks.basal_bricks, 0, 2);
		world.setBlock(i + 7, j + 6, k + 12, NovaCraftBlocks.basal_bricks, 0, 2);
		world.setBlock(i + 8, j + 6, k + 12, NovaCraftBlocks.basal_bricks, 0, 2);
		world.setBlock(i + 9, j + 6, k + 12, NovaCraftBlocks.basal_bricks, 0, 2);
		world.setBlock(i + 10, j + 6, k + 12, NovaCraftBlocks.basal_bricks, 0, 2);
		world.setBlock(i + 11, j + 6, k + 12, NovaCraftBlocks.cracked_basal_bricks, 0, 2);
		world.setBlock(i + 12, j + 6, k + 12, Blocks.air, 0, 2);
		world.setBlock(i + 13, j + 6, k + 12, Blocks.air, 0, 2);
		world.setBlock(i + 14, j + 6, k + 12, NovaCraftBlocks.basal, 0, 2);
		world.setBlock(i + 15, j + 6, k + 12, NovaCraftBlocks.basal, 0, 2);
		world.setBlock(i + 16, j + 6, k + 12, NovaCraftBlocks.basal, 0, 2);
		world.setBlock(i + 17, j + 6, k + 12, NovaCraftBlocks.basal, 0, 2);
		world.setBlock(i + 18, j + 6, k + 12, NovaCraftBlocks.basal, 0, 2);
		world.setBlock(i + 19, j + 6, k + 12, NovaCraftBlocks.basal, 0, 2);
		world.setBlock(i + 20, j + 6, k + 12, NovaCraftBlocks.basal, 0, 2);
		world.setBlock(i + 21, j + 6, k + 12, NovaCraftBlocks.basal, 0, 2);
		world.setBlock(i + 22, j + 6, k + 12, NovaCraftBlocks.basal, 0, 2);
		world.setBlock(i + 23, j + 6, k + 12, NovaCraftBlocks.basal, 0, 2);
		world.setBlock(i + 24, j + 6, k + 12, NovaCraftBlocks.basal, 0, 2);
		world.setBlock(i + 25, j + 6, k + 12, NovaCraftBlocks.basal, 0, 2);
		world.setBlock(i + 26, j + 6, k + 12, Blocks.air, 0, 2);
		world.setBlock(i + 27, j + 6, k + 12, Blocks.air, 0, 2);
		world.setBlock(i + 0, j + 7, k + 0, Blocks.air, 0, 2);
		world.setBlock(i + 1, j + 7, k + 0, Blocks.air, 0, 2);
		world.setBlock(i + 2, j + 7, k + 0, Blocks.air, 0, 2);
		world.setBlock(i + 3, j + 7, k + 0, Blocks.air, 0, 2);
		world.setBlock(i + 4, j + 7, k + 0, Blocks.air, 0, 2);
		world.setBlock(i + 5, j + 7, k + 0, Blocks.air, 0, 2);
		world.setBlock(i + 6, j + 7, k + 0, Blocks.air, 0, 2);
		world.setBlock(i + 7, j + 7, k + 0, Blocks.air, 0, 2);
		world.setBlock(i + 8, j + 7, k + 0, Blocks.air, 0, 2);
		world.setBlock(i + 9, j + 7, k + 0, Blocks.air, 0, 2);
		world.setBlock(i + 10, j + 7, k + 0, Blocks.air, 0, 2);
		world.setBlock(i + 11, j + 7, k + 0, Blocks.air, 0, 2);
		world.setBlock(i + 12, j + 7, k + 0, Blocks.air, 0, 2);
		world.setBlock(i + 13, j + 7, k + 0, Blocks.air, 0, 2);
		world.setBlock(i + 14, j + 7, k + 0, Blocks.air, 0, 2);
		world.setBlock(i + 15, j + 7, k + 0, Blocks.air, 0, 2);
		world.setBlock(i + 16, j + 7, k + 0, Blocks.air, 0, 2);
		world.setBlock(i + 17, j + 7, k + 0, Blocks.air, 0, 2);
		world.setBlock(i + 18, j + 7, k + 0, Blocks.air, 0, 2);
		world.setBlock(i + 19, j + 7, k + 0, Blocks.air, 0, 2);
		world.setBlock(i + 20, j + 7, k + 0, Blocks.air, 0, 2);
		world.setBlock(i + 21, j + 7, k + 0, Blocks.air, 0, 2);
		world.setBlock(i + 22, j + 7, k + 0, Blocks.air, 0, 2);
		world.setBlock(i + 23, j + 7, k + 0, Blocks.air, 0, 2);
		world.setBlock(i + 24, j + 7, k + 0, Blocks.air, 0, 2);
		world.setBlock(i + 25, j + 7, k + 0, Blocks.air, 0, 2);
		world.setBlock(i + 26, j + 7, k + 0, Blocks.air, 0, 2);
		world.setBlock(i + 27, j + 7, k + 0, Blocks.air, 0, 2);
		world.setBlock(i + 0, j + 7, k + 1, NovaCraftBlocks.basal, 0, 2);
		world.setBlock(i + 1, j + 7, k + 1, NovaCraftBlocks.basal, 0, 2);
		world.setBlock(i + 2, j + 7, k + 1, Blocks.air, 0, 2);
		world.setBlock(i + 3, j + 7, k + 1, Blocks.air, 0, 2);
		world.setBlock(i + 4, j + 7, k + 1, NovaCraftBlocks.basal, 0, 2);
		world.setBlock(i + 5, j + 7, k + 1, Blocks.air, 0, 2);
		world.setBlock(i + 6, j + 7, k + 1, Blocks.air, 0, 2);
		world.setBlock(i + 7, j + 7, k + 1, Blocks.air, 0, 2);
		world.setBlock(i + 8, j + 7, k + 1, Blocks.air, 0, 2);
		world.setBlock(i + 9, j + 7, k + 1, NovaCraftBlocks.basal, 0, 2);
		world.setBlock(i + 10, j + 7, k + 1, Blocks.air, 0, 2);
		world.setBlock(i + 11, j + 7, k + 1, Blocks.air, 0, 2);
		world.setBlock(i + 12, j + 7, k + 1, Blocks.air, 0, 2);
		world.setBlock(i + 13, j + 7, k + 1, Blocks.air, 0, 2);
		world.setBlock(i + 14, j + 7, k + 1, Blocks.air, 0, 2);
		world.setBlock(i + 15, j + 7, k + 1, Blocks.air, 0, 2);
		world.setBlock(i + 16, j + 7, k + 1, Blocks.air, 0, 2);
		world.setBlock(i + 17, j + 7, k + 1, Blocks.air, 0, 2);
		world.setBlock(i + 18, j + 7, k + 1, Blocks.air, 0, 2);
		world.setBlock(i + 19, j + 7, k + 1, Blocks.air, 0, 2);
		world.setBlock(i + 20, j + 7, k + 1, Blocks.air, 0, 2);
		world.setBlock(i + 21, j + 7, k + 1, Blocks.air, 0, 2);
		world.setBlock(i + 22, j + 7, k + 1, Blocks.air, 0, 2);
		world.setBlock(i + 23, j + 7, k + 1, Blocks.air, 0, 2);
		world.setBlock(i + 24, j + 7, k + 1, Blocks.air, 0, 2);
		world.setBlock(i + 25, j + 7, k + 1, Blocks.air, 0, 2);
		world.setBlock(i + 26, j + 7, k + 1, Blocks.air, 0, 2);
		world.setBlock(i + 27, j + 7, k + 1, Blocks.air, 0, 2);
		world.setBlock(i + 0, j + 7, k + 2, NovaCraftBlocks.basal, 0, 2);
		world.setBlock(i + 1, j + 7, k + 2, NovaCraftBlocks.basal, 0, 2);
		world.setBlock(i + 2, j + 7, k + 2, NovaCraftBlocks.basal, 0, 2);
		world.setBlock(i + 3, j + 7, k + 2, NovaCraftBlocks.basal, 0, 2);
		world.setBlock(i + 4, j + 7, k + 2, NovaCraftBlocks.basal, 0, 2);
		world.setBlock(i + 5, j + 7, k + 2, NovaCraftBlocks.basal, 0, 2);
		world.setBlock(i + 6, j + 7, k + 2, NovaCraftBlocks.basal, 0, 2);
		world.setBlock(i + 7, j + 7, k + 2, NovaCraftBlocks.basal, 0, 2);
		world.setBlock(i + 8, j + 7, k + 2, NovaCraftBlocks.basal, 0, 2);
		world.setBlock(i + 9, j + 7, k + 2, NovaCraftBlocks.basal, 0, 2);
		world.setBlock(i + 10, j + 7, k + 2, NovaCraftBlocks.basal, 0, 2);
		world.setBlock(i + 11, j + 7, k + 2, Blocks.air, 0, 2);
		world.setBlock(i + 12, j + 7, k + 2, Blocks.air, 0, 2);
		world.setBlock(i + 13, j + 7, k + 2, Blocks.air, 0, 2);
		world.setBlock(i + 14, j + 7, k + 2, Blocks.air, 0, 2);
		world.setBlock(i + 15, j + 7, k + 2, Blocks.air, 0, 2);
		world.setBlock(i + 16, j + 7, k + 2, Blocks.air, 0, 2);
		world.setBlock(i + 17, j + 7, k + 2, Blocks.air, 0, 2);
		world.setBlock(i + 18, j + 7, k + 2, Blocks.air, 0, 2);
		world.setBlock(i + 19, j + 7, k + 2, Blocks.air, 0, 2);
		world.setBlock(i + 20, j + 7, k + 2, Blocks.air, 0, 2);
		world.setBlock(i + 21, j + 7, k + 2, Blocks.air, 0, 2);
		world.setBlock(i + 22, j + 7, k + 2, Blocks.air, 0, 2);
		world.setBlock(i + 23, j + 7, k + 2, Blocks.air, 0, 2);
		world.setBlock(i + 24, j + 7, k + 2, Blocks.air, 0, 2);
		world.setBlock(i + 25, j + 7, k + 2, Blocks.air, 0, 2);
		world.setBlock(i + 26, j + 7, k + 2, Blocks.air, 0, 2);
		world.setBlock(i + 27, j + 7, k + 2, Blocks.air, 0, 2);
		world.setBlock(i + 0, j + 7, k + 3, NovaCraftBlocks.basal, 0, 2);
		world.setBlock(i + 1, j + 7, k + 3, NovaCraftBlocks.basal, 0, 2);
		world.setBlock(i + 2, j + 7, k + 3, NovaCraftBlocks.basal, 0, 2);
		world.setBlock(i + 3, j + 7, k + 3, NovaCraftBlocks.basal, 0, 2);
		world.setBlock(i + 4, j + 7, k + 3, Blocks.air, 0, 2);
		world.setBlock(i + 5, j + 7, k + 3, Blocks.air, 0, 2);
		world.setBlock(i + 6, j + 7, k + 3, NovaCraftBlocks.basal, 0, 2);
		world.setBlock(i + 7, j + 7, k + 3, NovaCraftBlocks.basal, 0, 2);
		world.setBlock(i + 8, j + 7, k + 3, NovaCraftBlocks.basal, 0, 2);
		world.setBlock(i + 9, j + 7, k + 3, NovaCraftBlocks.basal, 0, 2);
		world.setBlock(i + 10, j + 7, k + 3, NovaCraftBlocks.basal, 0, 2);
		world.setBlock(i + 11, j + 7, k + 3, NovaCraftBlocks.basal, 0, 2);
		world.setBlock(i + 12, j + 7, k + 3, NovaCraftBlocks.basal, 0, 2);
		world.setBlock(i + 13, j + 7, k + 3, Blocks.air, 0, 2);
		world.setBlock(i + 14, j + 7, k + 3, NovaCraftBlocks.basal, 0, 2);
		world.setBlock(i + 15, j + 7, k + 3, NovaCraftBlocks.basal, 0, 2);
		world.setBlock(i + 16, j + 7, k + 3, Blocks.air, 0, 2);
		world.setBlock(i + 17, j + 7, k + 3, Blocks.air, 0, 2);
		world.setBlock(i + 18, j + 7, k + 3, NovaCraftBlocks.basal, 0, 2);
		world.setBlock(i + 19, j + 7, k + 3, Blocks.air, 0, 2);
		world.setBlock(i + 20, j + 7, k + 3, Blocks.air, 0, 2);
		world.setBlock(i + 21, j + 7, k + 3, Blocks.air, 0, 2);
		world.setBlock(i + 22, j + 7, k + 3, Blocks.air, 0, 2);
		world.setBlock(i + 23, j + 7, k + 3, NovaCraftBlocks.basal, 0, 2);
		world.setBlock(i + 24, j + 7, k + 3, Blocks.air, 0, 2);
		world.setBlock(i + 25, j + 7, k + 3, Blocks.air, 0, 2);
		world.setBlock(i + 26, j + 7, k + 3, Blocks.air, 0, 2);
		world.setBlock(i + 27, j + 7, k + 3, Blocks.air, 0, 2);
		world.setBlock(i + 0, j + 7, k + 4, NovaCraftBlocks.cracked_basal_bricks, 0, 2);
		world.setBlock(i + 1, j + 7, k + 4, NovaCraftBlocks.basal, 0, 2);
		world.setBlock(i + 2, j + 7, k + 4, NovaCraftBlocks.basal, 0, 2);
		world.setBlock(i + 3, j + 7, k + 4, Blocks.air, 0, 2);
		world.setBlock(i + 4, j + 7, k + 4, Blocks.air, 0, 2);
		world.setBlock(i + 5, j + 7, k + 4, Blocks.air, 0, 2);
		world.setBlock(i + 6, j + 7, k + 4, NovaCraftBlocks.basal, 0, 2);
		world.setBlock(i + 7, j + 7, k + 4, NovaCraftBlocks.basal, 0, 2);
		world.setBlock(i + 8, j + 7, k + 4, NovaCraftBlocks.basal, 0, 2);
		world.setBlock(i + 9, j + 7, k + 4, NovaCraftBlocks.basal, 0, 2);
		world.setBlock(i + 10, j + 7, k + 4, NovaCraftBlocks.basal, 0, 2);
		world.setBlock(i + 11, j + 7, k + 4, NovaCraftBlocks.basal, 0, 2);
		world.setBlock(i + 12, j + 7, k + 4, NovaCraftBlocks.basal, 0, 2);
		world.setBlock(i + 13, j + 7, k + 4, NovaCraftBlocks.basal, 0, 2);
		world.setBlock(i + 14, j + 7, k + 4, NovaCraftBlocks.basal, 0, 2);
		world.setBlock(i + 15, j + 7, k + 4, NovaCraftBlocks.basal, 0, 2);
		world.setBlock(i + 16, j + 7, k + 4, NovaCraftBlocks.basal, 0, 2);
		world.setBlock(i + 17, j + 7, k + 4, NovaCraftBlocks.basal, 0, 2);
		world.setBlock(i + 18, j + 7, k + 4, NovaCraftBlocks.basal, 0, 2);
		world.setBlock(i + 19, j + 7, k + 4, NovaCraftBlocks.basal, 0, 2);
		world.setBlock(i + 20, j + 7, k + 4, NovaCraftBlocks.basal, 0, 2);
		world.setBlock(i + 21, j + 7, k + 4, NovaCraftBlocks.basal, 0, 2);
		world.setBlock(i + 22, j + 7, k + 4, NovaCraftBlocks.basal, 0, 2);
		world.setBlock(i + 23, j + 7, k + 4, NovaCraftBlocks.basal, 0, 2);
		world.setBlock(i + 24, j + 7, k + 4, NovaCraftBlocks.basal, 0, 2);
		world.setBlock(i + 25, j + 7, k + 4, Blocks.air, 0, 2);
		world.setBlock(i + 26, j + 7, k + 4, Blocks.air, 0, 2);
		world.setBlock(i + 27, j + 7, k + 4, Blocks.air, 0, 2);
		world.setBlock(i + 0, j + 7, k + 5, NovaCraftBlocks.cracked_basal_bricks, 0, 2);
		world.setBlock(i + 1, j + 7, k + 5, NovaCraftBlocks.cracked_basal_bricks, 0, 2);
		world.setBlock(i + 2, j + 7, k + 5, NovaCraftBlocks.basal, 0, 2);
		world.setBlock(i + 3, j + 7, k + 5, Blocks.air, 0, 2);
		world.setBlock(i + 4, j + 7, k + 5, Blocks.air, 0, 2);
		world.setBlock(i + 5, j + 7, k + 5, Blocks.air, 0, 2);
		world.setBlock(i + 6, j + 7, k + 5, NovaCraftBlocks.basal, 0, 2);
		world.setBlock(i + 7, j + 7, k + 5, Blocks.air, 0, 2);
		world.setBlock(i + 8, j + 7, k + 5, Blocks.air, 0, 2);
		world.setBlock(i + 9, j + 7, k + 5, Blocks.air, 0, 2);
		world.setBlock(i + 10, j + 7, k + 5, NovaCraftBlocks.basal, 0, 2);
		world.setBlock(i + 11, j + 7, k + 5, NovaCraftBlocks.basal, 0, 2);
		world.setBlock(i + 12, j + 7, k + 5, NovaCraftBlocks.basal, 0, 2);
		world.setBlock(i + 13, j + 7, k + 5, NovaCraftBlocks.basal, 0, 2);
		world.setBlock(i + 14, j + 7, k + 5, NovaCraftBlocks.basal, 0, 2);
		world.setBlock(i + 15, j + 7, k + 5, NovaCraftBlocks.basal, 0, 2);
		world.setBlock(i + 16, j + 7, k + 5, NovaCraftBlocks.basal, 0, 2);
		world.setBlock(i + 17, j + 7, k + 5, NovaCraftBlocks.basal, 0, 2);
		world.setBlock(i + 18, j + 7, k + 5, Blocks.air, 0, 2);
		world.setBlock(i + 19, j + 7, k + 5, Blocks.air, 0, 2);
		world.setBlock(i + 20, j + 7, k + 5, NovaCraftBlocks.basal, 0, 2);
		world.setBlock(i + 21, j + 7, k + 5, NovaCraftBlocks.basal, 0, 2);
		world.setBlock(i + 22, j + 7, k + 5, NovaCraftBlocks.basal, 0, 2);
		world.setBlock(i + 23, j + 7, k + 5, NovaCraftBlocks.basal, 0, 2);
		world.setBlock(i + 24, j + 7, k + 5, NovaCraftBlocks.basal, 0, 2);
		world.setBlock(i + 25, j + 7, k + 5, NovaCraftBlocks.basal, 0, 2);
		world.setBlock(i + 26, j + 7, k + 5, NovaCraftBlocks.basal, 0, 2);
		world.setBlock(i + 27, j + 7, k + 5, Blocks.air, 0, 2);
		world.setBlock(i + 0, j + 7, k + 6, NovaCraftBlocks.basal_bricks, 0, 2);
		world.setBlock(i + 1, j + 7, k + 6, NovaCraftBlocks.basal_bricks, 0, 2);
		world.setBlock(i + 2, j + 7, k + 6, NovaCraftBlocks.basal, 0, 2);
		world.setBlock(i + 3, j + 7, k + 6, NovaCraftBlocks.basal, 0, 2);
		world.setBlock(i + 4, j + 7, k + 6, NovaCraftBlocks.basal, 0, 2);
		world.setBlock(i + 5, j + 7, k + 6, NovaCraftBlocks.basal, 0, 2);
		world.setBlock(i + 6, j + 7, k + 6, NovaCraftBlocks.basal, 0, 2);
		world.setBlock(i + 7, j + 7, k + 6, Blocks.air, 0, 2);
		world.setBlock(i + 8, j + 7, k + 6, Blocks.air, 0, 2);
		world.setBlock(i + 9, j + 7, k + 6, Blocks.air, 0, 2);
		world.setBlock(i + 10, j + 7, k + 6, NovaCraftBlocks.basal, 0, 2);
		world.setBlock(i + 11, j + 7, k + 6, NovaCraftBlocks.basal, 0, 2);
		world.setBlock(i + 12, j + 7, k + 6, NovaCraftBlocks.basal, 0, 2);
		world.setBlock(i + 13, j + 7, k + 6, NovaCraftBlocks.basal, 0, 2);
		world.setBlock(i + 14, j + 7, k + 6, NovaCraftBlocks.cracked_basal_bricks, 0, 2);
		world.setBlock(i + 15, j + 7, k + 6, NovaCraftBlocks.basal, 0, 2);
		world.setBlock(i + 16, j + 7, k + 6, NovaCraftBlocks.basal, 0, 2);
		world.setBlock(i + 17, j + 7, k + 6, Blocks.air, 0, 2);
		world.setBlock(i + 18, j + 7, k + 6, Blocks.air, 0, 2);
		world.setBlock(i + 19, j + 7, k + 6, Blocks.air, 0, 2);
		world.setBlock(i + 20, j + 7, k + 6, NovaCraftBlocks.glowing_basal, 0, 2);
		world.setBlock(i + 21, j + 7, k + 6, NovaCraftBlocks.basal, 0, 2);
		world.setBlock(i + 22, j + 7, k + 6, NovaCraftBlocks.basal, 0, 2);
		world.setBlock(i + 23, j + 7, k + 6, NovaCraftBlocks.basal, 0, 2);
		world.setBlock(i + 24, j + 7, k + 6, NovaCraftBlocks.basal, 0, 2);
		world.setBlock(i + 25, j + 7, k + 6, NovaCraftBlocks.basal, 0, 2);
		world.setBlock(i + 26, j + 7, k + 6, NovaCraftBlocks.basal, 0, 2);
		world.setBlock(i + 27, j + 7, k + 6, NovaCraftBlocks.basal, 0, 2);
		world.setBlock(i + 0, j + 7, k + 7, NovaCraftBlocks.cracked_basal_bricks, 0, 2);
		world.setBlock(i + 1, j + 7, k + 7, NovaCraftBlocks.basal, 0, 2);
		world.setBlock(i + 2, j + 7, k + 7, NovaCraftBlocks.basal, 0, 2);
		world.setBlock(i + 3, j + 7, k + 7, NovaCraftBlocks.basal, 0, 2);
		world.setBlock(i + 4, j + 7, k + 7, NovaCraftBlocks.basal, 0, 2);
		world.setBlock(i + 5, j + 7, k + 7, NovaCraftBlocks.basal, 0, 2);
		world.setBlock(i + 6, j + 7, k + 7, NovaCraftBlocks.basal, 0, 2);
		world.setBlock(i + 7, j + 7, k + 7, Blocks.lava, 8, 2);
		world.setBlock(i + 8, j + 7, k + 7, NovaCraftBlocks.cracked_basal_bricks, 0, 2);
		world.setBlock(i + 9, j + 7, k + 7, Blocks.air, 0, 2);
		world.setBlock(i + 10, j + 7, k + 7, Blocks.air, 0, 2);
		world.setBlock(i + 11, j + 7, k + 7, NovaCraftBlocks.basal, 0, 2);
		world.setBlock(i + 12, j + 7, k + 7, NovaCraftBlocks.basal, 0, 2);
		world.setBlock(i + 13, j + 7, k + 7, NovaCraftBlocks.basal, 0, 2);
		world.setBlock(i + 14, j + 7, k + 7, NovaCraftBlocks.cracked_basal_bricks, 0, 2);
		world.setBlock(i + 15, j + 7, k + 7, NovaCraftBlocks.cracked_basal_bricks, 0, 2);
		world.setBlock(i + 16, j + 7, k + 7, NovaCraftBlocks.basal, 0, 2);
		world.setBlock(i + 17, j + 7, k + 7, Blocks.air, 0, 2);
		world.setBlock(i + 18, j + 7, k + 7, Blocks.air, 0, 2);
		world.setBlock(i + 19, j + 7, k + 7, Blocks.air, 0, 2);
		world.setBlock(i + 20, j + 7, k + 7, NovaCraftBlocks.basal, 0, 2);
		world.setBlock(i + 21, j + 7, k + 7, Blocks.air, 0, 2);
		world.setBlock(i + 22, j + 7, k + 7, Blocks.air, 0, 2);
		world.setBlock(i + 23, j + 7, k + 7, Blocks.air, 0, 2);
		world.setBlock(i + 24, j + 7, k + 7, NovaCraftBlocks.basal, 0, 2);
		world.setBlock(i + 25, j + 7, k + 7, NovaCraftBlocks.basal, 0, 2);
		world.setBlock(i + 26, j + 7, k + 7, NovaCraftBlocks.basal, 0, 2);
		world.setBlock(i + 27, j + 7, k + 7, NovaCraftBlocks.basal, 0, 2);
		world.setBlock(i + 0, j + 7, k + 8, NovaCraftBlocks.basal, 0, 2);
		world.setBlock(i + 1, j + 7, k + 8, NovaCraftBlocks.basal, 0, 2);
		world.setBlock(i + 2, j + 7, k + 8, NovaCraftBlocks.basal, 0, 2);
		world.setBlock(i + 3, j + 7, k + 8, NovaCraftBlocks.basal, 0, 2);
		world.setBlock(i + 4, j + 7, k + 8, NovaCraftBlocks.basal, 0, 2);
		world.setBlock(i + 5, j + 7, k + 8, NovaCraftBlocks.basal, 0, 2);
		world.setBlock(i + 6, j + 7, k + 8, NovaCraftBlocks.basal, 0, 2);
		world.setBlock(i + 7, j + 7, k + 8, NovaCraftBlocks.basal, 0, 2);
		world.setBlock(i + 8, j + 7, k + 8, NovaCraftBlocks.basal, 0, 2);
		world.setBlock(i + 9, j + 7, k + 8, Blocks.air, 0, 2);
		world.setBlock(i + 10, j + 7, k + 8, Blocks.air, 0, 2);
		world.setBlock(i + 11, j + 7, k + 8, NovaCraftBlocks.basal, 0, 2);
		world.setBlock(i + 12, j + 7, k + 8, NovaCraftBlocks.basal, 0, 2);
		world.setBlock(i + 13, j + 7, k + 8, NovaCraftBlocks.basal, 0, 2);
		world.setBlock(i + 14, j + 7, k + 8, NovaCraftBlocks.cracked_basal_bricks, 0, 2);
		world.setBlock(i + 15, j + 7, k + 8, NovaCraftBlocks.basal_bricks, 0, 2);
		world.setBlock(i + 16, j + 7, k + 8, NovaCraftBlocks.basal, 0, 2);
		world.setBlock(i + 17, j + 7, k + 8, NovaCraftBlocks.basal, 0, 2);
		world.setBlock(i + 18, j + 7, k + 8, NovaCraftBlocks.basal, 0, 2);
		world.setBlock(i + 19, j + 7, k + 8, NovaCraftBlocks.basal, 0, 2);
		world.setBlock(i + 20, j + 7, k + 8, NovaCraftBlocks.basal, 0, 2);
		world.setBlock(i + 21, j + 7, k + 8, Blocks.air, 0, 2);
		world.setBlock(i + 22, j + 7, k + 8, Blocks.air, 0, 2);
		world.setBlock(i + 23, j + 7, k + 8, Blocks.air, 0, 2);
		world.setBlock(i + 24, j + 7, k + 8, NovaCraftBlocks.basal, 0, 2);
		world.setBlock(i + 25, j + 7, k + 8, NovaCraftBlocks.basal, 0, 2);
		world.setBlock(i + 26, j + 7, k + 8, NovaCraftBlocks.basal, 0, 2);
		world.setBlock(i + 27, j + 7, k + 8, NovaCraftBlocks.basal, 0, 2);
		world.setBlock(i + 0, j + 7, k + 9, NovaCraftBlocks.basal, 0, 2);
		world.setBlock(i + 1, j + 7, k + 9, NovaCraftBlocks.basal, 0, 2);
		world.setBlock(i + 2, j + 7, k + 9, NovaCraftBlocks.basal, 0, 2);
		world.setBlock(i + 3, j + 7, k + 9, NovaCraftBlocks.basal, 0, 2);
		world.setBlock(i + 4, j + 7, k + 9, NovaCraftBlocks.basal, 0, 2);
		world.setBlock(i + 5, j + 7, k + 9, NovaCraftBlocks.basal, 0, 2);
		world.setBlock(i + 6, j + 7, k + 9, NovaCraftBlocks.basal, 0, 2);
		world.setBlock(i + 7, j + 7, k + 9, NovaCraftBlocks.basal, 0, 2);
		world.setBlock(i + 8, j + 7, k + 9, NovaCraftBlocks.basal, 0, 2);
		world.setBlock(i + 9, j + 7, k + 9, NovaCraftBlocks.basal, 0, 2);
		world.setBlock(i + 10, j + 7, k + 9, NovaCraftBlocks.basal, 0, 2);
		world.setBlock(i + 11, j + 7, k + 9, NovaCraftBlocks.basal, 0, 2);
		world.setBlock(i + 12, j + 7, k + 9, Blocks.air, 0, 2);
		world.setBlock(i + 13, j + 7, k + 9, Blocks.air, 0, 2);
		world.setBlock(i + 14, j + 7, k + 9, NovaCraftBlocks.cracked_basal_bricks, 0, 2);
		world.setBlock(i + 15, j + 7, k + 9, NovaCraftBlocks.basal, 0, 2);
		world.setBlock(i + 16, j + 7, k + 9, NovaCraftBlocks.basal, 0, 2);
		world.setBlock(i + 17, j + 7, k + 9, NovaCraftBlocks.basal, 0, 2);
		world.setBlock(i + 18, j + 7, k + 9, NovaCraftBlocks.basal, 0, 2);
		world.setBlock(i + 19, j + 7, k + 9, NovaCraftBlocks.basal, 0, 2);
		world.setBlock(i + 20, j + 7, k + 9, NovaCraftBlocks.basal, 0, 2);
		world.setBlock(i + 21, j + 7, k + 9, Blocks.lava, 8, 2);
		world.setBlock(i + 22, j + 7, k + 9, NovaCraftBlocks.cracked_basal_bricks, 0, 2);
		world.setBlock(i + 23, j + 7, k + 9, Blocks.air, 0, 2);
		world.setBlock(i + 24, j + 7, k + 9, Blocks.air, 0, 2);
		world.setBlock(i + 25, j + 7, k + 9, NovaCraftBlocks.basal, 0, 2);
		world.setBlock(i + 26, j + 7, k + 9, NovaCraftBlocks.basal, 0, 2);
		world.setBlock(i + 27, j + 7, k + 9, NovaCraftBlocks.basal, 0, 2);
		world.setBlock(i + 0, j + 7, k + 10, NovaCraftBlocks.basal, 0, 2);
		world.setBlock(i + 1, j + 7, k + 10, NovaCraftBlocks.basal, 0, 2);
		world.setBlock(i + 2, j + 7, k + 10, NovaCraftBlocks.basal, 0, 2);
		world.setBlock(i + 3, j + 7, k + 10, NovaCraftBlocks.basal, 0, 2);
		world.setBlock(i + 4, j + 7, k + 10, NovaCraftBlocks.basal, 0, 2);
		world.setBlock(i + 5, j + 7, k + 10, NovaCraftBlocks.basal, 0, 2);
		world.setBlock(i + 6, j + 7, k + 10, NovaCraftBlocks.basal, 0, 2);
		world.setBlock(i + 7, j + 7, k + 10, NovaCraftBlocks.basal, 0, 2);
		world.setBlock(i + 8, j + 7, k + 10, NovaCraftBlocks.basal, 0, 2);
		world.setBlock(i + 9, j + 7, k + 10, NovaCraftBlocks.basal, 0, 2);
		world.setBlock(i + 10, j + 7, k + 10, NovaCraftBlocks.basal, 0, 2);
		world.setBlock(i + 11, j + 7, k + 10, Blocks.air, 0, 2);
		world.setBlock(i + 12, j + 7, k + 10, Blocks.air, 0, 2);
		world.setBlock(i + 13, j + 7, k + 10, Blocks.air, 0, 2);
		world.setBlock(i + 14, j + 7, k + 10, NovaCraftBlocks.basal, 0, 2);
		world.setBlock(i + 15, j + 7, k + 10, NovaCraftBlocks.basal, 0, 2);
		world.setBlock(i + 16, j + 7, k + 10, NovaCraftBlocks.basal, 0, 2);
		world.setBlock(i + 17, j + 7, k + 10, NovaCraftBlocks.basal, 0, 2);
		world.setBlock(i + 18, j + 7, k + 10, NovaCraftBlocks.basal, 0, 2);
		world.setBlock(i + 19, j + 7, k + 10, NovaCraftBlocks.basal, 0, 2);
		world.setBlock(i + 20, j + 7, k + 10, NovaCraftBlocks.basal, 0, 2);
		world.setBlock(i + 21, j + 7, k + 10, NovaCraftBlocks.basal, 0, 2);
		world.setBlock(i + 22, j + 7, k + 10, NovaCraftBlocks.basal, 0, 2);
		world.setBlock(i + 23, j + 7, k + 10, Blocks.air, 0, 2);
		world.setBlock(i + 24, j + 7, k + 10, Blocks.air, 0, 2);
		world.setBlock(i + 25, j + 7, k + 10, NovaCraftBlocks.basal, 0, 2);
		world.setBlock(i + 26, j + 7, k + 10, NovaCraftBlocks.basal, 0, 2);
		world.setBlock(i + 27, j + 7, k + 10, NovaCraftBlocks.basal, 0, 2);
		world.setBlock(i + 0, j + 7, k + 11, NovaCraftBlocks.basal_bricks, 0, 2);
		world.setBlock(i + 1, j + 7, k + 11, NovaCraftBlocks.basal_bricks, 0, 2);
		world.setBlock(i + 2, j + 7, k + 11, NovaCraftBlocks.basal_bricks, 0, 2);
		world.setBlock(i + 3, j + 7, k + 11, NovaCraftBlocks.basal_bricks, 0, 2);
		world.setBlock(i + 4, j + 7, k + 11, NovaCraftBlocks.basal_bricks, 0, 2);
		world.setBlock(i + 5, j + 7, k + 11, NovaCraftBlocks.basal_bricks, 0, 2);
		world.setBlock(i + 6, j + 7, k + 11, NovaCraftBlocks.basal_bricks, 0, 2);
		world.setBlock(i + 7, j + 7, k + 11, NovaCraftBlocks.basal_bricks, 0, 2);
		world.setBlock(i + 8, j + 7, k + 11, NovaCraftBlocks.basal_bricks, 0, 2);
		world.setBlock(i + 9, j + 7, k + 11, NovaCraftBlocks.basal_bricks, 0, 2);
		world.setBlock(i + 10, j + 7, k + 11, NovaCraftBlocks.cracked_basal_bricks, 0, 2);
		world.setBlock(i + 11, j + 7, k + 11, Blocks.air, 0, 2);
		world.setBlock(i + 12, j + 7, k + 11, Blocks.air, 0, 2);
		world.setBlock(i + 13, j + 7, k + 11, Blocks.air, 0, 2);
		world.setBlock(i + 14, j + 7, k + 11, NovaCraftBlocks.basal, 0, 2);
		world.setBlock(i + 15, j + 7, k + 11, NovaCraftBlocks.basal, 0, 2);
		world.setBlock(i + 16, j + 7, k + 11, NovaCraftBlocks.basal, 0, 2);
		world.setBlock(i + 17, j + 7, k + 11, NovaCraftBlocks.basal, 0, 2);
		world.setBlock(i + 18, j + 7, k + 11, NovaCraftBlocks.basal, 0, 2);
		world.setBlock(i + 19, j + 7, k + 11, NovaCraftBlocks.basal, 0, 2);
		world.setBlock(i + 20, j + 7, k + 11, NovaCraftBlocks.basal, 0, 2);
		world.setBlock(i + 21, j + 7, k + 11, NovaCraftBlocks.basal, 0, 2);
		world.setBlock(i + 22, j + 7, k + 11, NovaCraftBlocks.basal, 0, 2);
		world.setBlock(i + 23, j + 7, k + 11, NovaCraftBlocks.basal, 0, 2);
		world.setBlock(i + 24, j + 7, k + 11, NovaCraftBlocks.basal, 0, 2);
		world.setBlock(i + 25, j + 7, k + 11, NovaCraftBlocks.basal, 0, 2);
		world.setBlock(i + 26, j + 7, k + 11, Blocks.air, 0, 2);
		world.setBlock(i + 27, j + 7, k + 11, Blocks.air, 0, 2);
		world.setBlock(i + 0, j + 7, k + 12, NovaCraftBlocks.basal_bricks, 0, 2);
		world.setBlock(i + 1, j + 7, k + 12, NovaCraftBlocks.basal_bricks, 0, 2);
		world.setBlock(i + 2, j + 7, k + 12, NovaCraftBlocks.basal_bricks, 0, 2);
		world.setBlock(i + 3, j + 7, k + 12, NovaCraftBlocks.basal_bricks, 0, 2);
		world.setBlock(i + 4, j + 7, k + 12, NovaCraftBlocks.basal_bricks, 0, 2);
		world.setBlock(i + 5, j + 7, k + 12, NovaCraftBlocks.basal_bricks, 0, 2);
		world.setBlock(i + 6, j + 7, k + 12, NovaCraftBlocks.cracked_basal_bricks, 0, 2);
		world.setBlock(i + 7, j + 7, k + 12, NovaCraftBlocks.cracked_basal_bricks, 0, 2);
		world.setBlock(i + 8, j + 7, k + 12, NovaCraftBlocks.basal_bricks, 0, 2);
		world.setBlock(i + 9, j + 7, k + 12, NovaCraftBlocks.cracked_basal_bricks, 0, 2);
		world.setBlock(i + 10, j + 7, k + 12, NovaCraftBlocks.cracked_basal_bricks, 0, 2);
		world.setBlock(i + 11, j + 7, k + 12, NovaCraftBlocks.basal_bricks, 0, 2);
		world.setBlock(i + 12, j + 7, k + 12, NovaCraftBlocks.cracked_basal_bricks, 0, 2);
		world.setBlock(i + 13, j + 7, k + 12, Blocks.air, 0, 2);
		world.setBlock(i + 14, j + 7, k + 12, NovaCraftBlocks.basal, 0, 2);
		world.setBlock(i + 15, j + 7, k + 12, NovaCraftBlocks.basal, 0, 2);
		world.setBlock(i + 16, j + 7, k + 12, NovaCraftBlocks.basal, 0, 2);
		world.setBlock(i + 17, j + 7, k + 12, NovaCraftBlocks.basal, 0, 2);
		world.setBlock(i + 18, j + 7, k + 12, NovaCraftBlocks.basal, 0, 2);
		world.setBlock(i + 19, j + 7, k + 12, NovaCraftBlocks.basal, 0, 2);
		world.setBlock(i + 20, j + 7, k + 12, NovaCraftBlocks.basal, 0, 2);
		world.setBlock(i + 21, j + 7, k + 12, NovaCraftBlocks.basal, 0, 2);
		world.setBlock(i + 22, j + 7, k + 12, NovaCraftBlocks.basal, 0, 2);
		world.setBlock(i + 23, j + 7, k + 12, NovaCraftBlocks.basal, 0, 2);
		world.setBlock(i + 24, j + 7, k + 12, NovaCraftBlocks.basal, 0, 2);
		world.setBlock(i + 25, j + 7, k + 12, Blocks.air, 0, 2);
		world.setBlock(i + 26, j + 7, k + 12, Blocks.air, 0, 2);
		world.setBlock(i + 27, j + 7, k + 12, Blocks.air, 0, 2);
		world.setBlock(i + 0, j + 8, k + 0, Blocks.air, 0, 2);
		world.setBlock(i + 1, j + 8, k + 0, Blocks.air, 0, 2);
		world.setBlock(i + 2, j + 8, k + 0, Blocks.air, 0, 2);
		world.setBlock(i + 3, j + 8, k + 0, Blocks.air, 0, 2);
		world.setBlock(i + 4, j + 8, k + 0, Blocks.air, 0, 2);
		world.setBlock(i + 5, j + 8, k + 0, Blocks.air, 0, 2);
		world.setBlock(i + 6, j + 8, k + 0, Blocks.air, 0, 2);
		world.setBlock(i + 7, j + 8, k + 0, Blocks.air, 0, 2);
		world.setBlock(i + 8, j + 8, k + 0, Blocks.air, 0, 2);
		world.setBlock(i + 9, j + 8, k + 0, Blocks.air, 0, 2);
		world.setBlock(i + 10, j + 8, k + 0, Blocks.air, 0, 2);
		world.setBlock(i + 11, j + 8, k + 0, Blocks.air, 0, 2);
		world.setBlock(i + 12, j + 8, k + 0, Blocks.air, 0, 2);
		world.setBlock(i + 13, j + 8, k + 0, Blocks.air, 0, 2);
		world.setBlock(i + 14, j + 8, k + 0, Blocks.air, 0, 2);
		world.setBlock(i + 15, j + 8, k + 0, Blocks.air, 0, 2);
		world.setBlock(i + 16, j + 8, k + 0, Blocks.air, 0, 2);
		world.setBlock(i + 17, j + 8, k + 0, Blocks.air, 0, 2);
		world.setBlock(i + 18, j + 8, k + 0, Blocks.air, 0, 2);
		world.setBlock(i + 19, j + 8, k + 0, Blocks.air, 0, 2);
		world.setBlock(i + 20, j + 8, k + 0, Blocks.air, 0, 2);
		world.setBlock(i + 21, j + 8, k + 0, Blocks.air, 0, 2);
		world.setBlock(i + 22, j + 8, k + 0, Blocks.air, 0, 2);
		world.setBlock(i + 23, j + 8, k + 0, Blocks.air, 0, 2);
		world.setBlock(i + 24, j + 8, k + 0, Blocks.air, 0, 2);
		world.setBlock(i + 25, j + 8, k + 0, Blocks.air, 0, 2);
		world.setBlock(i + 26, j + 8, k + 0, Blocks.air, 0, 2);
		world.setBlock(i + 27, j + 8, k + 0, Blocks.air, 0, 2);
		world.setBlock(i + 0, j + 8, k + 1, NovaCraftBlocks.basal, 0, 2);
		world.setBlock(i + 1, j + 8, k + 1, NovaCraftBlocks.basal, 0, 2);
		world.setBlock(i + 2, j + 8, k + 1, Blocks.air, 0, 2);
		world.setBlock(i + 3, j + 8, k + 1, Blocks.air, 0, 2);
		world.setBlock(i + 4, j + 8, k + 1, NovaCraftBlocks.basal, 0, 2);
		world.setBlock(i + 5, j + 8, k + 1, NovaCraftBlocks.basal, 0, 2);
		world.setBlock(i + 6, j + 8, k + 1, Blocks.air, 0, 2);
		world.setBlock(i + 7, j + 8, k + 1, Blocks.air, 0, 2);
		world.setBlock(i + 8, j + 8, k + 1, Blocks.air, 0, 2);
		world.setBlock(i + 9, j + 8, k + 1, NovaCraftBlocks.basal, 0, 2);
		world.setBlock(i + 10, j + 8, k + 1, Blocks.air, 0, 2);
		world.setBlock(i + 11, j + 8, k + 1, Blocks.air, 0, 2);
		world.setBlock(i + 12, j + 8, k + 1, Blocks.air, 0, 2);
		world.setBlock(i + 13, j + 8, k + 1, Blocks.air, 0, 2);
		world.setBlock(i + 14, j + 8, k + 1, Blocks.air, 0, 2);
		world.setBlock(i + 15, j + 8, k + 1, Blocks.air, 0, 2);
		world.setBlock(i + 16, j + 8, k + 1, Blocks.air, 0, 2);
		world.setBlock(i + 17, j + 8, k + 1, Blocks.air, 0, 2);
		world.setBlock(i + 18, j + 8, k + 1, Blocks.air, 0, 2);
		world.setBlock(i + 19, j + 8, k + 1, Blocks.air, 0, 2);
		world.setBlock(i + 20, j + 8, k + 1, Blocks.air, 0, 2);
		world.setBlock(i + 21, j + 8, k + 1, Blocks.air, 0, 2);
		world.setBlock(i + 22, j + 8, k + 1, Blocks.air, 0, 2);
		world.setBlock(i + 23, j + 8, k + 1, Blocks.air, 0, 2);
		world.setBlock(i + 24, j + 8, k + 1, Blocks.air, 0, 2);
		world.setBlock(i + 25, j + 8, k + 1, Blocks.air, 0, 2);
		world.setBlock(i + 26, j + 8, k + 1, Blocks.air, 0, 2);
		world.setBlock(i + 27, j + 8, k + 1, Blocks.air, 0, 2);
		world.setBlock(i + 0, j + 8, k + 2, NovaCraftBlocks.basal, 0, 2);
		world.setBlock(i + 1, j + 8, k + 2, NovaCraftBlocks.basal, 0, 2);
		world.setBlock(i + 2, j + 8, k + 2, NovaCraftBlocks.basal, 0, 2);
		world.setBlock(i + 3, j + 8, k + 2, NovaCraftBlocks.basal, 0, 2);
		world.setBlock(i + 4, j + 8, k + 2, Blocks.air, 0, 2);
		world.setBlock(i + 5, j + 8, k + 2, Blocks.air, 0, 2);
		world.setBlock(i + 6, j + 8, k + 2, NovaCraftBlocks.basal, 0, 2);
		world.setBlock(i + 7, j + 8, k + 2, NovaCraftBlocks.basal, 0, 2);
		world.setBlock(i + 8, j + 8, k + 2, Blocks.air, 0, 2);
		world.setBlock(i + 9, j + 8, k + 2, NovaCraftBlocks.basal, 0, 2);
		world.setBlock(i + 10, j + 8, k + 2, NovaCraftBlocks.basal, 0, 2);
		world.setBlock(i + 11, j + 8, k + 2, Blocks.air, 0, 2);
		world.setBlock(i + 12, j + 8, k + 2, Blocks.air, 0, 2);
		world.setBlock(i + 13, j + 8, k + 2, Blocks.air, 0, 2);
		world.setBlock(i + 14, j + 8, k + 2, Blocks.air, 0, 2);
		world.setBlock(i + 15, j + 8, k + 2, Blocks.air, 0, 2);
		world.setBlock(i + 16, j + 8, k + 2, Blocks.air, 0, 2);
		world.setBlock(i + 17, j + 8, k + 2, Blocks.air, 0, 2);
		world.setBlock(i + 18, j + 8, k + 2, Blocks.air, 0, 2);
		world.setBlock(i + 19, j + 8, k + 2, Blocks.air, 0, 2);
		world.setBlock(i + 20, j + 8, k + 2, Blocks.air, 0, 2);
		world.setBlock(i + 21, j + 8, k + 2, Blocks.air, 0, 2);
		world.setBlock(i + 22, j + 8, k + 2, Blocks.air, 0, 2);
		world.setBlock(i + 23, j + 8, k + 2, Blocks.air, 0, 2);
		world.setBlock(i + 24, j + 8, k + 2, Blocks.air, 0, 2);
		world.setBlock(i + 25, j + 8, k + 2, Blocks.air, 0, 2);
		world.setBlock(i + 26, j + 8, k + 2, Blocks.air, 0, 2);
		world.setBlock(i + 27, j + 8, k + 2, Blocks.air, 0, 2);
		world.setBlock(i + 0, j + 8, k + 3, NovaCraftBlocks.basal, 0, 2);
		world.setBlock(i + 1, j + 8, k + 3, NovaCraftBlocks.basal, 0, 2);
		world.setBlock(i + 2, j + 8, k + 3, NovaCraftBlocks.basal, 0, 2);
		world.setBlock(i + 3, j + 8, k + 3, Blocks.air, 0, 2);
		world.setBlock(i + 4, j + 8, k + 3, Blocks.air, 0, 2);
		world.setBlock(i + 5, j + 8, k + 3, Blocks.air, 0, 2);
		world.setBlock(i + 6, j + 8, k + 3, NovaCraftBlocks.basal, 0, 2);
		world.setBlock(i + 7, j + 8, k + 3, NovaCraftBlocks.basal, 0, 2);
		world.setBlock(i + 8, j + 8, k + 3, NovaCraftBlocks.basal, 0, 2);
		world.setBlock(i + 9, j + 8, k + 3, NovaCraftBlocks.basal, 0, 2);
		world.setBlock(i + 10, j + 8, k + 3, NovaCraftBlocks.basal, 0, 2);
		world.setBlock(i + 11, j + 8, k + 3, NovaCraftBlocks.basal, 0, 2);
		world.setBlock(i + 12, j + 8, k + 3, NovaCraftBlocks.basal, 0, 2);
		world.setBlock(i + 13, j + 8, k + 3, Blocks.air, 0, 2);
		world.setBlock(i + 14, j + 8, k + 3, NovaCraftBlocks.basal, 0, 2);
		world.setBlock(i + 15, j + 8, k + 3, NovaCraftBlocks.basal, 0, 2);
		world.setBlock(i + 16, j + 8, k + 3, Blocks.air, 0, 2);
		world.setBlock(i + 17, j + 8, k + 3, Blocks.air, 0, 2);
		world.setBlock(i + 18, j + 8, k + 3, NovaCraftBlocks.basal, 0, 2);
		world.setBlock(i + 19, j + 8, k + 3, NovaCraftBlocks.basal, 0, 2);
		world.setBlock(i + 20, j + 8, k + 3, Blocks.air, 0, 2);
		world.setBlock(i + 21, j + 8, k + 3, Blocks.air, 0, 2);
		world.setBlock(i + 22, j + 8, k + 3, Blocks.air, 0, 2);
		world.setBlock(i + 23, j + 8, k + 3, NovaCraftBlocks.basal, 0, 2);
		world.setBlock(i + 24, j + 8, k + 3, Blocks.air, 0, 2);
		world.setBlock(i + 25, j + 8, k + 3, Blocks.air, 0, 2);
		world.setBlock(i + 26, j + 8, k + 3, Blocks.air, 0, 2);
		world.setBlock(i + 27, j + 8, k + 3, Blocks.air, 0, 2);
		world.setBlock(i + 0, j + 8, k + 4, NovaCraftBlocks.cracked_basal_bricks, 0, 2);
		world.setBlock(i + 1, j + 8, k + 4, NovaCraftBlocks.basal, 0, 2);
		world.setBlock(i + 2, j + 8, k + 4, NovaCraftBlocks.basal, 0, 2);
		world.setBlock(i + 3, j + 8, k + 4, Blocks.air, 0, 2);
		world.setBlock(i + 4, j + 8, k + 4, Blocks.air, 0, 2);
		world.setBlock(i + 5, j + 8, k + 4, Blocks.air, 0, 2);
		world.setBlock(i + 6, j + 8, k + 4, NovaCraftBlocks.basal, 0, 2);
		world.setBlock(i + 7, j + 8, k + 4, Blocks.air, 0, 2);
		world.setBlock(i + 8, j + 8, k + 4, Blocks.air, 0, 2);
		world.setBlock(i + 9, j + 8, k + 4, NovaCraftBlocks.basal, 0, 2);
		world.setBlock(i + 10, j + 8, k + 4, NovaCraftBlocks.basal, 0, 2);
		world.setBlock(i + 11, j + 8, k + 4, NovaCraftBlocks.basal, 0, 2);
		world.setBlock(i + 12, j + 8, k + 4, NovaCraftBlocks.basal, 0, 2);
		world.setBlock(i + 13, j + 8, k + 4, NovaCraftBlocks.basal, 0, 2);
		world.setBlock(i + 14, j + 8, k + 4, NovaCraftBlocks.basal, 0, 2);
		world.setBlock(i + 15, j + 8, k + 4, NovaCraftBlocks.basal, 0, 2);
		world.setBlock(i + 16, j + 8, k + 4, NovaCraftBlocks.basal, 0, 2);
		world.setBlock(i + 17, j + 8, k + 4, NovaCraftBlocks.basal, 0, 2);
		world.setBlock(i + 18, j + 8, k + 4, Blocks.air, 0, 2);
		world.setBlock(i + 19, j + 8, k + 4, Blocks.air, 0, 2);
		world.setBlock(i + 20, j + 8, k + 4, NovaCraftBlocks.basal, 0, 2);
		world.setBlock(i + 21, j + 8, k + 4, NovaCraftBlocks.basal, 0, 2);
		world.setBlock(i + 22, j + 8, k + 4, Blocks.air, 0, 2);
		world.setBlock(i + 23, j + 8, k + 4, NovaCraftBlocks.basal, 0, 2);
		world.setBlock(i + 24, j + 8, k + 4, NovaCraftBlocks.basal, 0, 2);
		world.setBlock(i + 25, j + 8, k + 4, Blocks.air, 0, 2);
		world.setBlock(i + 26, j + 8, k + 4, Blocks.air, 0, 2);
		world.setBlock(i + 27, j + 8, k + 4, Blocks.air, 0, 2);
		world.setBlock(i + 0, j + 8, k + 5, NovaCraftBlocks.cracked_basal_bricks, 0, 2);
		world.setBlock(i + 1, j + 8, k + 5, NovaCraftBlocks.cracked_basal_bricks, 0, 2);
		world.setBlock(i + 2, j + 8, k + 5, NovaCraftBlocks.basal, 0, 2);
		world.setBlock(i + 3, j + 8, k + 5, NovaCraftBlocks.basal, 0, 2);
		world.setBlock(i + 4, j + 8, k + 5, NovaCraftBlocks.basal, 0, 2);
		world.setBlock(i + 5, j + 8, k + 5, NovaCraftBlocks.basal, 0, 2);
		world.setBlock(i + 6, j + 8, k + 5, NovaCraftBlocks.basal, 0, 2);
		world.setBlock(i + 7, j + 8, k + 5, Blocks.air, 0, 2);
		world.setBlock(i + 8, j + 8, k + 5, Blocks.air, 0, 2);
		world.setBlock(i + 9, j + 8, k + 5, Blocks.air, 0, 2);
		world.setBlock(i + 10, j + 8, k + 5, NovaCraftBlocks.basal, 0, 2);
		world.setBlock(i + 11, j + 8, k + 5, NovaCraftBlocks.basal, 0, 2);
		world.setBlock(i + 12, j + 8, k + 5, NovaCraftBlocks.basal, 0, 2);
		world.setBlock(i + 13, j + 8, k + 5, NovaCraftBlocks.basal, 0, 2);
		world.setBlock(i + 14, j + 8, k + 5, NovaCraftBlocks.basal, 0, 2);
		world.setBlock(i + 15, j + 8, k + 5, NovaCraftBlocks.basal, 0, 2);
		world.setBlock(i + 16, j + 8, k + 5, NovaCraftBlocks.basal, 0, 2);
		world.setBlock(i + 17, j + 8, k + 5, Blocks.air, 0, 2);
		world.setBlock(i + 18, j + 8, k + 5, Blocks.air, 0, 2);
		world.setBlock(i + 19, j + 8, k + 5, Blocks.air, 0, 2);
		world.setBlock(i + 20, j + 8, k + 5, NovaCraftBlocks.basal, 0, 2);
		world.setBlock(i + 21, j + 8, k + 5, NovaCraftBlocks.basal, 0, 2);
		world.setBlock(i + 22, j + 8, k + 5, NovaCraftBlocks.basal, 0, 2);
		world.setBlock(i + 23, j + 8, k + 5, NovaCraftBlocks.basal, 0, 2);
		world.setBlock(i + 24, j + 8, k + 5, NovaCraftBlocks.basal, 0, 2);
		world.setBlock(i + 25, j + 8, k + 5, NovaCraftBlocks.basal, 0, 2);
		world.setBlock(i + 26, j + 8, k + 5, NovaCraftBlocks.basal, 0, 2);
		world.setBlock(i + 27, j + 8, k + 5, Blocks.air, 0, 2);
		world.setBlock(i + 0, j + 8, k + 6, NovaCraftBlocks.basal, 0, 2);
		world.setBlock(i + 1, j + 8, k + 6, NovaCraftBlocks.basal, 0, 2);
		world.setBlock(i + 2, j + 8, k + 6, NovaCraftBlocks.basal, 0, 2);
		world.setBlock(i + 3, j + 8, k + 6, NovaCraftBlocks.basal, 0, 2);
		world.setBlock(i + 4, j + 8, k + 6, NovaCraftBlocks.basal, 0, 2);
		world.setBlock(i + 5, j + 8, k + 6, NovaCraftBlocks.basal, 0, 2);
		world.setBlock(i + 6, j + 8, k + 6, NovaCraftBlocks.basal, 0, 2);
		world.setBlock(i + 7, j + 8, k + 6, Blocks.air, 0, 2);
		world.setBlock(i + 8, j + 8, k + 6, Blocks.air, 0, 2);
		world.setBlock(i + 9, j + 8, k + 6, Blocks.air, 0, 2);
		world.setBlock(i + 10, j + 8, k + 6, NovaCraftBlocks.basal, 0, 2);
		world.setBlock(i + 11, j + 8, k + 6, NovaCraftBlocks.basal, 0, 2);
		world.setBlock(i + 12, j + 8, k + 6, NovaCraftBlocks.basal, 0, 2);
		world.setBlock(i + 13, j + 8, k + 6, NovaCraftBlocks.basal, 0, 2);
		world.setBlock(i + 14, j + 8, k + 6, NovaCraftBlocks.cracked_basal_bricks, 0, 2);
		world.setBlock(i + 15, j + 8, k + 6, NovaCraftBlocks.basal, 0, 2);
		world.setBlock(i + 16, j + 8, k + 6, NovaCraftBlocks.basal, 0, 2);
		world.setBlock(i + 17, j + 8, k + 6, Blocks.air, 0, 2);
		world.setBlock(i + 18, j + 8, k + 6, Blocks.air, 0, 2);
		world.setBlock(i + 19, j + 8, k + 6, Blocks.air, 0, 2);
		world.setBlock(i + 20, j + 8, k + 6, NovaCraftBlocks.basal, 0, 2);
		world.setBlock(i + 21, j + 8, k + 6, Blocks.air, 0, 2);
		world.setBlock(i + 22, j + 8, k + 6, Blocks.air, 0, 2);
		world.setBlock(i + 23, j + 8, k + 6, NovaCraftBlocks.basal, 0, 2);
		world.setBlock(i + 24, j + 8, k + 6, NovaCraftBlocks.basal, 0, 2);
		world.setBlock(i + 25, j + 8, k + 6, NovaCraftBlocks.basal, 0, 2);
		world.setBlock(i + 26, j + 8, k + 6, NovaCraftBlocks.basal, 0, 2);
		world.setBlock(i + 27, j + 8, k + 6, NovaCraftBlocks.basal, 0, 2);
		world.setBlock(i + 0, j + 8, k + 7, NovaCraftBlocks.basal, 0, 2);
		world.setBlock(i + 1, j + 8, k + 7, NovaCraftBlocks.basal, 0, 2);
		world.setBlock(i + 2, j + 8, k + 7, NovaCraftBlocks.basal, 0, 2);
		world.setBlock(i + 3, j + 8, k + 7, NovaCraftBlocks.basal, 0, 2);
		world.setBlock(i + 4, j + 8, k + 7, NovaCraftBlocks.basal, 0, 2);
		world.setBlock(i + 5, j + 8, k + 7, NovaCraftBlocks.basal, 0, 2);
		world.setBlock(i + 6, j + 8, k + 7, NovaCraftBlocks.basal, 0, 2);
		world.setBlock(i + 7, j + 8, k + 7, Blocks.lava, 8, 2);
		world.setBlock(i + 8, j + 8, k + 7, NovaCraftBlocks.basal, 0, 2);
		world.setBlock(i + 9, j + 8, k + 7, NovaCraftBlocks.glowing_basal, 0, 2);
		world.setBlock(i + 10, j + 8, k + 7, NovaCraftBlocks.basal, 0, 2);
		world.setBlock(i + 11, j + 8, k + 7, NovaCraftBlocks.basal, 0, 2);
		world.setBlock(i + 12, j + 8, k + 7, NovaCraftBlocks.basal, 0, 2);
		world.setBlock(i + 13, j + 8, k + 7, NovaCraftBlocks.basal, 0, 2);
		world.setBlock(i + 14, j + 8, k + 7, NovaCraftBlocks.cracked_basal_bricks, 0, 2);
		world.setBlock(i + 15, j + 8, k + 7, NovaCraftBlocks.cracked_basal_bricks, 0, 2);
		world.setBlock(i + 16, j + 8, k + 7, NovaCraftBlocks.basal, 0, 2);
		world.setBlock(i + 17, j + 8, k + 7, NovaCraftBlocks.basal, 0, 2);
		world.setBlock(i + 18, j + 8, k + 7, NovaCraftBlocks.basal, 0, 2);
		world.setBlock(i + 19, j + 8, k + 7, NovaCraftBlocks.basal, 0, 2);
		world.setBlock(i + 20, j + 8, k + 7, NovaCraftBlocks.basal, 0, 2);
		world.setBlock(i + 21, j + 8, k + 7, Blocks.air, 0, 2);
		world.setBlock(i + 22, j + 8, k + 7, Blocks.air, 0, 2);
		world.setBlock(i + 23, j + 8, k + 7, Blocks.air, 0, 2);
		world.setBlock(i + 24, j + 8, k + 7, NovaCraftBlocks.basal, 0, 2);
		world.setBlock(i + 25, j + 8, k + 7, NovaCraftBlocks.basal, 0, 2);
		world.setBlock(i + 26, j + 8, k + 7, NovaCraftBlocks.basal, 0, 2);
		world.setBlock(i + 27, j + 8, k + 7, NovaCraftBlocks.basal, 0, 2);
		world.setBlock(i + 0, j + 8, k + 8, NovaCraftBlocks.basal, 0, 2);
		world.setBlock(i + 1, j + 8, k + 8, NovaCraftBlocks.basal, 0, 2);
		world.setBlock(i + 2, j + 8, k + 8, NovaCraftBlocks.basal, 0, 2);
		world.setBlock(i + 3, j + 8, k + 8, NovaCraftBlocks.basal, 0, 2);
		world.setBlock(i + 4, j + 8, k + 8, NovaCraftBlocks.basal, 0, 2);
		world.setBlock(i + 5, j + 8, k + 8, NovaCraftBlocks.basal, 0, 2);
		world.setBlock(i + 6, j + 8, k + 8, NovaCraftBlocks.basal, 0, 2);
		world.setBlock(i + 7, j + 8, k + 8, NovaCraftBlocks.basal, 0, 2);
		world.setBlock(i + 8, j + 8, k + 8, NovaCraftBlocks.basal, 0, 2);
		world.setBlock(i + 9, j + 8, k + 8, NovaCraftBlocks.basal, 0, 2);
		world.setBlock(i + 10, j + 8, k + 8, NovaCraftBlocks.basal, 0, 2);
		world.setBlock(i + 11, j + 8, k + 8, NovaCraftBlocks.basal, 0, 2);
		world.setBlock(i + 12, j + 8, k + 8, NovaCraftBlocks.basal, 0, 2);
		world.setBlock(i + 13, j + 8, k + 8, NovaCraftBlocks.basal, 0, 2);
		world.setBlock(i + 14, j + 8, k + 8, NovaCraftBlocks.basal, 0, 2);
		world.setBlock(i + 15, j + 8, k + 8, NovaCraftBlocks.basal, 0, 2);
		world.setBlock(i + 16, j + 8, k + 8, NovaCraftBlocks.basal, 0, 2);
		world.setBlock(i + 17, j + 8, k + 8, NovaCraftBlocks.basal, 0, 2);
		world.setBlock(i + 18, j + 8, k + 8, NovaCraftBlocks.basal, 0, 2);
		world.setBlock(i + 19, j + 8, k + 8, NovaCraftBlocks.basal, 0, 2);
		world.setBlock(i + 20, j + 8, k + 8, NovaCraftBlocks.basal, 0, 2);
		world.setBlock(i + 21, j + 8, k + 8, Blocks.air, 0, 2);
		world.setBlock(i + 22, j + 8, k + 8, Blocks.air, 0, 2);
		world.setBlock(i + 23, j + 8, k + 8, Blocks.air, 0, 2);
		world.setBlock(i + 24, j + 8, k + 8, NovaCraftBlocks.basal, 0, 2);
		world.setBlock(i + 25, j + 8, k + 8, NovaCraftBlocks.basal, 0, 2);
		world.setBlock(i + 26, j + 8, k + 8, NovaCraftBlocks.basal, 0, 2);
		world.setBlock(i + 27, j + 8, k + 8, NovaCraftBlocks.basal, 0, 2);
		world.setBlock(i + 0, j + 8, k + 9, NovaCraftBlocks.basal, 0, 2);
		world.setBlock(i + 1, j + 8, k + 9, NovaCraftBlocks.basal, 0, 2);
		world.setBlock(i + 2, j + 8, k + 9, NovaCraftBlocks.basal, 0, 2);
		world.setBlock(i + 3, j + 8, k + 9, NovaCraftBlocks.basal, 0, 2);
		world.setBlock(i + 4, j + 8, k + 9, NovaCraftBlocks.basal, 0, 2);
		world.setBlock(i + 5, j + 8, k + 9, NovaCraftBlocks.basal, 0, 2);
		world.setBlock(i + 6, j + 8, k + 9, NovaCraftBlocks.basal, 0, 2);
		world.setBlock(i + 7, j + 8, k + 9, NovaCraftBlocks.basal, 0, 2);
		world.setBlock(i + 8, j + 8, k + 9, NovaCraftBlocks.basal, 0, 2);
		world.setBlock(i + 9, j + 8, k + 9, NovaCraftBlocks.basal, 0, 2);
		world.setBlock(i + 10, j + 8, k + 9, NovaCraftBlocks.basal, 0, 2);
		world.setBlock(i + 11, j + 8, k + 9, NovaCraftBlocks.basal, 0, 2);
		world.setBlock(i + 12, j + 8, k + 9, Blocks.air, 0, 2);
		world.setBlock(i + 13, j + 8, k + 9, Blocks.air, 0, 2);
		world.setBlock(i + 14, j + 8, k + 9, NovaCraftBlocks.basal, 0, 2);
		world.setBlock(i + 15, j + 8, k + 9, NovaCraftBlocks.basal, 0, 2);
		world.setBlock(i + 16, j + 8, k + 9, NovaCraftBlocks.basal, 0, 2);
		world.setBlock(i + 17, j + 8, k + 9, NovaCraftBlocks.basal, 0, 2);
		world.setBlock(i + 18, j + 8, k + 9, NovaCraftBlocks.glowing_basal, 0, 2);
		world.setBlock(i + 19, j + 8, k + 9, NovaCraftBlocks.basal, 0, 2);
		world.setBlock(i + 20, j + 8, k + 9, NovaCraftBlocks.basal, 0, 2);
		world.setBlock(i + 21, j + 8, k + 9, Blocks.lava, 8, 2);
		world.setBlock(i + 22, j + 8, k + 9, NovaCraftBlocks.basal, 0, 2);
		world.setBlock(i + 23, j + 8, k + 9, NovaCraftBlocks.basal, 0, 2);
		world.setBlock(i + 24, j + 8, k + 9, NovaCraftBlocks.basal, 0, 2);
		world.setBlock(i + 25, j + 8, k + 9, NovaCraftBlocks.basal, 0, 2);
		world.setBlock(i + 26, j + 8, k + 9, NovaCraftBlocks.basal, 0, 2);
		world.setBlock(i + 27, j + 8, k + 9, NovaCraftBlocks.basal, 0, 2);
		world.setBlock(i + 0, j + 8, k + 10, NovaCraftBlocks.basal, 0, 2);
		world.setBlock(i + 1, j + 8, k + 10, NovaCraftBlocks.basal, 0, 2);
		world.setBlock(i + 2, j + 8, k + 10, NovaCraftBlocks.basal, 0, 2);
		world.setBlock(i + 3, j + 8, k + 10, NovaCraftBlocks.basal, 0, 2);
		world.setBlock(i + 4, j + 8, k + 10, NovaCraftBlocks.basal, 0, 2);
		world.setBlock(i + 5, j + 8, k + 10, NovaCraftBlocks.basal, 0, 2);
		world.setBlock(i + 6, j + 8, k + 10, NovaCraftBlocks.glowing_basal, 0, 2);
		world.setBlock(i + 7, j + 8, k + 10, NovaCraftBlocks.basal, 0, 2);
		world.setBlock(i + 8, j + 8, k + 10, NovaCraftBlocks.basal, 0, 2);
		world.setBlock(i + 9, j + 8, k + 10, NovaCraftBlocks.basal, 0, 2);
		world.setBlock(i + 10, j + 8, k + 10, NovaCraftBlocks.basal, 0, 2);
		world.setBlock(i + 11, j + 8, k + 10, NovaCraftBlocks.basal, 0, 2);
		world.setBlock(i + 12, j + 8, k + 10, Blocks.air, 0, 2);
		world.setBlock(i + 13, j + 8, k + 10, Blocks.air, 0, 2);
		world.setBlock(i + 14, j + 8, k + 10, NovaCraftBlocks.basal, 0, 2);
		world.setBlock(i + 15, j + 8, k + 10, NovaCraftBlocks.basal, 0, 2);
		world.setBlock(i + 16, j + 8, k + 10, NovaCraftBlocks.basal, 0, 2);
		world.setBlock(i + 17, j + 8, k + 10, NovaCraftBlocks.basal, 0, 2);
		world.setBlock(i + 18, j + 8, k + 10, NovaCraftBlocks.basal, 0, 2);
		world.setBlock(i + 19, j + 8, k + 10, NovaCraftBlocks.basal, 0, 2);
		world.setBlock(i + 20, j + 8, k + 10, NovaCraftBlocks.basal, 0, 2);
		world.setBlock(i + 21, j + 8, k + 10, NovaCraftBlocks.glowing_basal, 0, 2);
		world.setBlock(i + 22, j + 8, k + 10, NovaCraftBlocks.basal, 0, 2);
		world.setBlock(i + 23, j + 8, k + 10, NovaCraftBlocks.basal, 0, 2);
		world.setBlock(i + 24, j + 8, k + 10, NovaCraftBlocks.basal, 0, 2);
		world.setBlock(i + 25, j + 8, k + 10, NovaCraftBlocks.basal, 0, 2);
		world.setBlock(i + 26, j + 8, k + 10, NovaCraftBlocks.basal, 0, 2);
		world.setBlock(i + 27, j + 8, k + 10, NovaCraftBlocks.basal, 0, 2);
		world.setBlock(i + 0, j + 8, k + 11, NovaCraftBlocks.cracked_basal_bricks, 0, 2);
		world.setBlock(i + 1, j + 8, k + 11, NovaCraftBlocks.basal_bricks, 0, 2);
		world.setBlock(i + 2, j + 8, k + 11, NovaCraftBlocks.basal_bricks, 0, 2);
		world.setBlock(i + 3, j + 8, k + 11, NovaCraftBlocks.cracked_basal_bricks, 0, 2);
		world.setBlock(i + 4, j + 8, k + 11, NovaCraftBlocks.basal_bricks, 0, 2);
		world.setBlock(i + 5, j + 8, k + 11, NovaCraftBlocks.basal_bricks, 0, 2);
		world.setBlock(i + 6, j + 8, k + 11, NovaCraftBlocks.cracked_basal_bricks, 0, 2);
		world.setBlock(i + 7, j + 8, k + 11, NovaCraftBlocks.basal_bricks, 0, 2);
		world.setBlock(i + 8, j + 8, k + 11, NovaCraftBlocks.basal_bricks, 0, 2);
		world.setBlock(i + 9, j + 8, k + 11, NovaCraftBlocks.basal_bricks, 0, 2);
		world.setBlock(i + 10, j + 8, k + 11, NovaCraftBlocks.basal_bricks, 0, 2);
		world.setBlock(i + 11, j + 8, k + 11, Blocks.air, 0, 2);
		world.setBlock(i + 12, j + 8, k + 11, Blocks.air, 0, 2);
		world.setBlock(i + 13, j + 8, k + 11, Blocks.air, 0, 2);
		world.setBlock(i + 14, j + 8, k + 11, NovaCraftBlocks.basal, 0, 2);
		world.setBlock(i + 15, j + 8, k + 11, NovaCraftBlocks.basal, 0, 2);
		world.setBlock(i + 16, j + 8, k + 11, NovaCraftBlocks.basal, 0, 2);
		world.setBlock(i + 17, j + 8, k + 11, NovaCraftBlocks.basal, 0, 2);
		world.setBlock(i + 18, j + 8, k + 11, NovaCraftBlocks.basal, 0, 2);
		world.setBlock(i + 19, j + 8, k + 11, NovaCraftBlocks.basal, 0, 2);
		world.setBlock(i + 20, j + 8, k + 11, NovaCraftBlocks.basal, 0, 2);
		world.setBlock(i + 21, j + 8, k + 11, NovaCraftBlocks.basal, 0, 2);
		world.setBlock(i + 22, j + 8, k + 11, NovaCraftBlocks.basal, 0, 2);
		world.setBlock(i + 23, j + 8, k + 11, NovaCraftBlocks.basal, 0, 2);
		world.setBlock(i + 24, j + 8, k + 11, NovaCraftBlocks.basal, 0, 2);
		world.setBlock(i + 25, j + 8, k + 11, NovaCraftBlocks.basal, 0, 2);
		world.setBlock(i + 26, j + 8, k + 11, Blocks.air, 0, 2);
		world.setBlock(i + 27, j + 8, k + 11, Blocks.air, 0, 2);
		world.setBlock(i + 0, j + 8, k + 12, NovaCraftBlocks.basal_bricks, 0, 2);
		world.setBlock(i + 1, j + 8, k + 12, NovaCraftBlocks.basal_bricks, 0, 2);
		world.setBlock(i + 2, j + 8, k + 12, NovaCraftBlocks.cracked_basal_bricks, 0, 2);
		world.setBlock(i + 3, j + 8, k + 12, NovaCraftBlocks.basal_bricks, 0, 2);
		world.setBlock(i + 4, j + 8, k + 12, NovaCraftBlocks.cracked_basal_bricks, 0, 2);
		world.setBlock(i + 5, j + 8, k + 12, NovaCraftBlocks.cracked_basal_bricks, 0, 2);
		world.setBlock(i + 6, j + 8, k + 12, NovaCraftBlocks.cracked_basal_bricks, 0, 2);
		world.setBlock(i + 7, j + 8, k + 12, NovaCraftBlocks.basal_bricks, 0, 2);
		world.setBlock(i + 8, j + 8, k + 12, NovaCraftBlocks.basal_bricks, 0, 2);
		world.setBlock(i + 9, j + 8, k + 12, NovaCraftBlocks.cracked_basal_bricks, 0, 2);
		world.setBlock(i + 10, j + 8, k + 12, NovaCraftBlocks.basal_bricks, 0, 2);
		world.setBlock(i + 11, j + 8, k + 12, Blocks.air, 0, 2);
		world.setBlock(i + 12, j + 8, k + 12, Blocks.air, 0, 2);
		world.setBlock(i + 13, j + 8, k + 12, Blocks.air, 0, 2);
		world.setBlock(i + 14, j + 8, k + 12, NovaCraftBlocks.basal, 0, 2);
		world.setBlock(i + 15, j + 8, k + 12, NovaCraftBlocks.basal, 0, 2);
		world.setBlock(i + 16, j + 8, k + 12, NovaCraftBlocks.basal, 0, 2);
		world.setBlock(i + 17, j + 8, k + 12, NovaCraftBlocks.basal, 0, 2);
		world.setBlock(i + 18, j + 8, k + 12, NovaCraftBlocks.basal, 0, 2);
		world.setBlock(i + 19, j + 8, k + 12, NovaCraftBlocks.basal, 0, 2);
		world.setBlock(i + 20, j + 8, k + 12, NovaCraftBlocks.basal, 0, 2);
		world.setBlock(i + 21, j + 8, k + 12, NovaCraftBlocks.basal, 0, 2);
		world.setBlock(i + 22, j + 8, k + 12, NovaCraftBlocks.basal, 0, 2);
		world.setBlock(i + 23, j + 8, k + 12, NovaCraftBlocks.basal, 0, 2);
		world.setBlock(i + 24, j + 8, k + 12, NovaCraftBlocks.basal, 0, 2);
		world.setBlock(i + 25, j + 8, k + 12, NovaCraftBlocks.basal, 0, 2);
		world.setBlock(i + 26, j + 8, k + 12, Blocks.air, 0, 2);
		world.setBlock(i + 27, j + 8, k + 12, Blocks.air, 0, 2);
		world.setBlock(i + 0, j + 9, k + 0, Blocks.air, 0, 2);
		world.setBlock(i + 1, j + 9, k + 0, Blocks.air, 0, 2);
		world.setBlock(i + 2, j + 9, k + 0, Blocks.air, 0, 2);
		world.setBlock(i + 3, j + 9, k + 0, Blocks.air, 0, 2);
		world.setBlock(i + 4, j + 9, k + 0, Blocks.air, 0, 2);
		world.setBlock(i + 5, j + 9, k + 0, Blocks.air, 0, 2);
		world.setBlock(i + 6, j + 9, k + 0, Blocks.air, 0, 2);
		world.setBlock(i + 7, j + 9, k + 0, Blocks.air, 0, 2);
		world.setBlock(i + 8, j + 9, k + 0, Blocks.air, 0, 2);
		world.setBlock(i + 9, j + 9, k + 0, Blocks.air, 0, 2);
		world.setBlock(i + 10, j + 9, k + 0, Blocks.air, 0, 2);
		world.setBlock(i + 11, j + 9, k + 0, Blocks.air, 0, 2);
		world.setBlock(i + 12, j + 9, k + 0, Blocks.air, 0, 2);
		world.setBlock(i + 13, j + 9, k + 0, Blocks.air, 0, 2);
		world.setBlock(i + 14, j + 9, k + 0, Blocks.air, 0, 2);
		world.setBlock(i + 15, j + 9, k + 0, Blocks.air, 0, 2);
		world.setBlock(i + 16, j + 9, k + 0, Blocks.air, 0, 2);
		world.setBlock(i + 17, j + 9, k + 0, Blocks.air, 0, 2);
		world.setBlock(i + 18, j + 9, k + 0, Blocks.air, 0, 2);
		world.setBlock(i + 19, j + 9, k + 0, Blocks.air, 0, 2);
		world.setBlock(i + 20, j + 9, k + 0, Blocks.air, 0, 2);
		world.setBlock(i + 21, j + 9, k + 0, Blocks.air, 0, 2);
		world.setBlock(i + 22, j + 9, k + 0, Blocks.air, 0, 2);
		world.setBlock(i + 23, j + 9, k + 0, Blocks.air, 0, 2);
		world.setBlock(i + 24, j + 9, k + 0, Blocks.air, 0, 2);
		world.setBlock(i + 25, j + 9, k + 0, Blocks.air, 0, 2);
		world.setBlock(i + 26, j + 9, k + 0, Blocks.air, 0, 2);
		world.setBlock(i + 27, j + 9, k + 0, Blocks.air, 0, 2);
		world.setBlock(i + 0, j + 9, k + 1, Blocks.air, 0, 2);
		world.setBlock(i + 1, j + 9, k + 1, Blocks.air, 0, 2);
		world.setBlock(i + 2, j + 9, k + 1, Blocks.air, 0, 2);
		world.setBlock(i + 3, j + 9, k + 1, Blocks.air, 0, 2);
		world.setBlock(i + 4, j + 9, k + 1, NovaCraftBlocks.basal, 0, 2);
		world.setBlock(i + 5, j + 9, k + 1, NovaCraftBlocks.basal, 0, 2);
		world.setBlock(i + 6, j + 9, k + 1, Blocks.air, 0, 2);
		world.setBlock(i + 7, j + 9, k + 1, Blocks.air, 0, 2);
		world.setBlock(i + 8, j + 9, k + 1, Blocks.air, 0, 2);
		world.setBlock(i + 9, j + 9, k + 1, NovaCraftBlocks.basal, 0, 2);
		world.setBlock(i + 10, j + 9, k + 1, Blocks.air, 0, 2);
		world.setBlock(i + 11, j + 9, k + 1, Blocks.air, 0, 2);
		world.setBlock(i + 12, j + 9, k + 1, Blocks.air, 0, 2);
		world.setBlock(i + 13, j + 9, k + 1, Blocks.air, 0, 2);
		world.setBlock(i + 14, j + 9, k + 1, Blocks.air, 0, 2);
		world.setBlock(i + 15, j + 9, k + 1, Blocks.air, 0, 2);
		world.setBlock(i + 16, j + 9, k + 1, Blocks.air, 0, 2);
		world.setBlock(i + 17, j + 9, k + 1, Blocks.air, 0, 2);
		world.setBlock(i + 18, j + 9, k + 1, Blocks.air, 0, 2);
		world.setBlock(i + 19, j + 9, k + 1, Blocks.air, 0, 2);
		world.setBlock(i + 20, j + 9, k + 1, Blocks.air, 0, 2);
		world.setBlock(i + 21, j + 9, k + 1, Blocks.air, 0, 2);
		world.setBlock(i + 22, j + 9, k + 1, Blocks.air, 0, 2);
		world.setBlock(i + 23, j + 9, k + 1, Blocks.air, 0, 2);
		world.setBlock(i + 24, j + 9, k + 1, Blocks.air, 0, 2);
		world.setBlock(i + 25, j + 9, k + 1, Blocks.air, 0, 2);
		world.setBlock(i + 26, j + 9, k + 1, Blocks.air, 0, 2);
		world.setBlock(i + 27, j + 9, k + 1, Blocks.air, 0, 2);
		world.setBlock(i + 0, j + 9, k + 2, NovaCraftBlocks.basal, 0, 2);
		world.setBlock(i + 1, j + 9, k + 2, NovaCraftBlocks.basal, 0, 2);
		world.setBlock(i + 2, j + 9, k + 2, NovaCraftBlocks.basal, 0, 2);
		world.setBlock(i + 3, j + 9, k + 2, NovaCraftBlocks.basal, 0, 2);
		world.setBlock(i + 4, j + 9, k + 2, Blocks.air, 0, 2);
		world.setBlock(i + 5, j + 9, k + 2, Blocks.air, 0, 2);
		world.setBlock(i + 6, j + 9, k + 2, NovaCraftBlocks.cracked_basal_bricks, 0, 2);
		world.setBlock(i + 7, j + 9, k + 2, NovaCraftBlocks.cracked_basal_bricks, 0, 2);
		world.setBlock(i + 8, j + 9, k + 2, NovaCraftBlocks.basal, 0, 2);
		world.setBlock(i + 9, j + 9, k + 2, NovaCraftBlocks.basal, 0, 2);
		world.setBlock(i + 10, j + 9, k + 2, Blocks.air, 0, 2);
		world.setBlock(i + 11, j + 9, k + 2, Blocks.air, 0, 2);
		world.setBlock(i + 12, j + 9, k + 2, Blocks.air, 0, 2);
		world.setBlock(i + 13, j + 9, k + 2, Blocks.air, 0, 2);
		world.setBlock(i + 14, j + 9, k + 2, Blocks.air, 0, 2);
		world.setBlock(i + 15, j + 9, k + 2, Blocks.air, 0, 2);
		world.setBlock(i + 16, j + 9, k + 2, Blocks.air, 0, 2);
		world.setBlock(i + 17, j + 9, k + 2, Blocks.air, 0, 2);
		world.setBlock(i + 18, j + 9, k + 2, Blocks.air, 0, 2);
		world.setBlock(i + 19, j + 9, k + 2, Blocks.air, 0, 2);
		world.setBlock(i + 20, j + 9, k + 2, Blocks.air, 0, 2);
		world.setBlock(i + 21, j + 9, k + 2, Blocks.air, 0, 2);
		world.setBlock(i + 22, j + 9, k + 2, Blocks.air, 0, 2);
		world.setBlock(i + 23, j + 9, k + 2, Blocks.air, 0, 2);
		world.setBlock(i + 24, j + 9, k + 2, Blocks.air, 0, 2);
		world.setBlock(i + 25, j + 9, k + 2, Blocks.air, 0, 2);
		world.setBlock(i + 26, j + 9, k + 2, Blocks.air, 0, 2);
		world.setBlock(i + 27, j + 9, k + 2, Blocks.air, 0, 2);
		world.setBlock(i + 0, j + 9, k + 3, NovaCraftBlocks.basal, 0, 2);
		world.setBlock(i + 1, j + 9, k + 3, NovaCraftBlocks.basal, 0, 2);
		world.setBlock(i + 2, j + 9, k + 3, Blocks.air, 0, 2);
		world.setBlock(i + 3, j + 9, k + 3, Blocks.air, 0, 2);
		world.setBlock(i + 4, j + 9, k + 3, Blocks.air, 0, 2);
		world.setBlock(i + 5, j + 9, k + 3, Blocks.air, 0, 2);
		world.setBlock(i + 6, j + 9, k + 3, NovaCraftBlocks.basal, 0, 2);
		world.setBlock(i + 7, j + 9, k + 3, Blocks.air, 0, 2);
		world.setBlock(i + 8, j + 9, k + 3, Blocks.air, 0, 2);
		world.setBlock(i + 9, j + 9, k + 3, NovaCraftBlocks.glowing_basal, 0, 2);
		world.setBlock(i + 10, j + 9, k + 3, NovaCraftBlocks.glowing_basal, 0, 2);
		world.setBlock(i + 11, j + 9, k + 3, NovaCraftBlocks.basal_bricks, 0, 2);
		world.setBlock(i + 12, j + 9, k + 3, Blocks.air, 0, 2);
		world.setBlock(i + 13, j + 9, k + 3, Blocks.air, 0, 2);
		world.setBlock(i + 14, j + 9, k + 3, Blocks.air, 0, 2);
		world.setBlock(i + 15, j + 9, k + 3, Blocks.air, 0, 2);
		world.setBlock(i + 16, j + 9, k + 3, Blocks.air, 0, 2);
		world.setBlock(i + 17, j + 9, k + 3, Blocks.air, 0, 2);
		world.setBlock(i + 18, j + 9, k + 3, NovaCraftBlocks.basal, 0, 2);
		world.setBlock(i + 19, j + 9, k + 3, NovaCraftBlocks.basal, 0, 2);
		world.setBlock(i + 20, j + 9, k + 3, Blocks.air, 0, 2);
		world.setBlock(i + 21, j + 9, k + 3, Blocks.air, 0, 2);
		world.setBlock(i + 22, j + 9, k + 3, Blocks.air, 0, 2);
		world.setBlock(i + 23, j + 9, k + 3, NovaCraftBlocks.basal, 0, 2);
		world.setBlock(i + 24, j + 9, k + 3, Blocks.air, 0, 2);
		world.setBlock(i + 25, j + 9, k + 3, Blocks.air, 0, 2);
		world.setBlock(i + 26, j + 9, k + 3, Blocks.air, 0, 2);
		world.setBlock(i + 27, j + 9, k + 3, Blocks.air, 0, 2);
		world.setBlock(i + 0, j + 9, k + 4, NovaCraftBlocks.basal, 0, 2);
		world.setBlock(i + 1, j + 9, k + 4, NovaCraftBlocks.basal, 0, 2);
		world.setBlock(i + 2, j + 9, k + 4, Blocks.air, 0, 2);
		world.setBlock(i + 3, j + 9, k + 4, Blocks.air, 0, 2);
		world.setBlock(i + 4, j + 9, k + 4, Blocks.air, 0, 2);
		world.setBlock(i + 5, j + 9, k + 4, NovaCraftBlocks.basal, 0, 2);
		world.setBlock(i + 6, j + 9, k + 4, NovaCraftBlocks.basal, 0, 2);
		world.setBlock(i + 7, j + 9, k + 4, Blocks.air, 0, 2);
		world.setBlock(i + 8, j + 9, k + 4, Blocks.air, 0, 2);
		world.setBlock(i + 9, j + 9, k + 4, NovaCraftBlocks.basal, 0, 2);
		world.setBlock(i + 10, j + 9, k + 4, NovaCraftBlocks.basal, 0, 2);
		world.setBlock(i + 11, j + 9, k + 4, NovaCraftBlocks.basal, 0, 2);
		world.setBlock(i + 12, j + 9, k + 4, NovaCraftBlocks.basal, 0, 2);
		world.setBlock(i + 13, j + 9, k + 4, NovaCraftBlocks.basal, 0, 2);
		world.setBlock(i + 14, j + 9, k + 4, NovaCraftBlocks.basal, 0, 2);
		world.setBlock(i + 15, j + 9, k + 4, NovaCraftBlocks.basal, 0, 2);
		world.setBlock(i + 16, j + 9, k + 4, NovaCraftBlocks.basal, 0, 2);
		world.setBlock(i + 17, j + 9, k + 4, NovaCraftBlocks.basal, 0, 2);
		world.setBlock(i + 18, j + 9, k + 4, Blocks.air, 0, 2);
		world.setBlock(i + 19, j + 9, k + 4, Blocks.air, 0, 2);
		world.setBlock(i + 20, j + 9, k + 4, NovaCraftBlocks.basal_bricks, 0, 2);
		world.setBlock(i + 21, j + 9, k + 4, NovaCraftBlocks.cracked_basal_bricks, 0, 2);
		world.setBlock(i + 22, j + 9, k + 4, NovaCraftBlocks.basal, 0, 2);
		world.setBlock(i + 23, j + 9, k + 4, NovaCraftBlocks.basal, 0, 2);
		world.setBlock(i + 24, j + 9, k + 4, Blocks.air, 0, 2);
		world.setBlock(i + 25, j + 9, k + 4, Blocks.air, 0, 2);
		world.setBlock(i + 26, j + 9, k + 4, Blocks.air, 0, 2);
		world.setBlock(i + 27, j + 9, k + 4, Blocks.air, 0, 2);
		world.setBlock(i + 0, j + 9, k + 5, NovaCraftBlocks.basal, 0, 2);
		world.setBlock(i + 1, j + 9, k + 5, NovaCraftBlocks.basal, 0, 2);
		world.setBlock(i + 2, j + 9, k + 5, NovaCraftBlocks.basal, 0, 2);
		world.setBlock(i + 3, j + 9, k + 5, NovaCraftBlocks.basal, 0, 2);
		world.setBlock(i + 4, j + 9, k + 5, NovaCraftBlocks.basal, 0, 2);
		world.setBlock(i + 5, j + 9, k + 5, NovaCraftBlocks.basal, 0, 2);
		world.setBlock(i + 6, j + 9, k + 5, NovaCraftBlocks.basal, 0, 2);
		world.setBlock(i + 7, j + 9, k + 5, Blocks.air, 0, 2);
		world.setBlock(i + 8, j + 9, k + 5, Blocks.air, 0, 2);
		world.setBlock(i + 9, j + 9, k + 5, NovaCraftBlocks.basal, 0, 2);
		world.setBlock(i + 10, j + 9, k + 5, NovaCraftBlocks.basal, 0, 2);
		world.setBlock(i + 11, j + 9, k + 5, NovaCraftBlocks.basal, 0, 2);
		world.setBlock(i + 12, j + 9, k + 5, NovaCraftBlocks.basal, 0, 2);
		world.setBlock(i + 13, j + 9, k + 5, NovaCraftBlocks.basal, 0, 2);
		world.setBlock(i + 14, j + 9, k + 5, NovaCraftBlocks.basal, 0, 2);
		world.setBlock(i + 15, j + 9, k + 5, NovaCraftBlocks.basal, 0, 2);
		world.setBlock(i + 16, j + 9, k + 5, Blocks.air, 0, 2);
		world.setBlock(i + 17, j + 9, k + 5, Blocks.air, 0, 2);
		world.setBlock(i + 18, j + 9, k + 5, Blocks.air, 0, 2);
		world.setBlock(i + 19, j + 9, k + 5, Blocks.air, 0, 2);
		world.setBlock(i + 20, j + 9, k + 5, NovaCraftBlocks.basal, 0, 2);
		world.setBlock(i + 21, j + 9, k + 5, Blocks.air, 0, 2);
		world.setBlock(i + 22, j + 9, k + 5, Blocks.air, 0, 2);
		world.setBlock(i + 23, j + 9, k + 5, NovaCraftBlocks.basal, 0, 2);
		world.setBlock(i + 24, j + 9, k + 5, NovaCraftBlocks.basal, 0, 2);
		world.setBlock(i + 25, j + 9, k + 5, NovaCraftBlocks.basal_bricks, 0, 2);
		world.setBlock(i + 26, j + 9, k + 5, Blocks.air, 0, 2);
		world.setBlock(i + 27, j + 9, k + 5, Blocks.air, 0, 2);
		world.setBlock(i + 0, j + 9, k + 6, NovaCraftBlocks.basal, 0, 2);
		world.setBlock(i + 1, j + 9, k + 6, NovaCraftBlocks.basal, 0, 2);
		world.setBlock(i + 2, j + 9, k + 6, NovaCraftBlocks.basal, 0, 2);
		world.setBlock(i + 3, j + 9, k + 6, NovaCraftBlocks.basal, 0, 2);
		world.setBlock(i + 4, j + 9, k + 6, NovaCraftBlocks.basal, 0, 2);
		world.setBlock(i + 5, j + 9, k + 6, NovaCraftBlocks.basal, 0, 2);
		world.setBlock(i + 6, j + 9, k + 6, NovaCraftBlocks.glowing_basal, 0, 2);
		world.setBlock(i + 7, j + 9, k + 6, Blocks.air, 0, 2);
		world.setBlock(i + 8, j + 9, k + 6, Blocks.air, 0, 2);
		world.setBlock(i + 9, j + 9, k + 6, NovaCraftBlocks.basal, 0, 2);
		world.setBlock(i + 10, j + 9, k + 6, NovaCraftBlocks.basal, 0, 2);
		world.setBlock(i + 11, j + 9, k + 6, NovaCraftBlocks.basal, 0, 2);
		world.setBlock(i + 12, j + 9, k + 6, NovaCraftBlocks.basal, 0, 2);
		world.setBlock(i + 13, j + 9, k + 6, NovaCraftBlocks.basal, 0, 2);
		world.setBlock(i + 14, j + 9, k + 6, NovaCraftBlocks.basal, 0, 2);
		world.setBlock(i + 15, j + 9, k + 6, NovaCraftBlocks.basal, 0, 2);
		world.setBlock(i + 16, j + 9, k + 6, Blocks.air, 0, 2);
		world.setBlock(i + 17, j + 9, k + 6, Blocks.air, 0, 2);
		world.setBlock(i + 18, j + 9, k + 6, Blocks.air, 0, 2);
		world.setBlock(i + 19, j + 9, k + 6, NovaCraftBlocks.basal, 0, 2);
		world.setBlock(i + 20, j + 9, k + 6, NovaCraftBlocks.basal, 0, 2);
		world.setBlock(i + 21, j + 9, k + 6, Blocks.air, 0, 2);
		world.setBlock(i + 22, j + 9, k + 6, Blocks.air, 0, 2);
		world.setBlock(i + 23, j + 9, k + 6, NovaCraftBlocks.basal, 0, 2);
		world.setBlock(i + 24, j + 9, k + 6, NovaCraftBlocks.basal, 0, 2);
		world.setBlock(i + 25, j + 9, k + 6, NovaCraftBlocks.basal, 0, 2);
		world.setBlock(i + 26, j + 9, k + 6, NovaCraftBlocks.basal, 0, 2);
		world.setBlock(i + 27, j + 9, k + 6, NovaCraftBlocks.basal, 0, 2);
		world.setBlock(i + 0, j + 9, k + 7, NovaCraftBlocks.basal, 0, 2);
		world.setBlock(i + 1, j + 9, k + 7, NovaCraftBlocks.basal, 0, 2);
		world.setBlock(i + 2, j + 9, k + 7, NovaCraftBlocks.basal, 0, 2);
		world.setBlock(i + 3, j + 9, k + 7, NovaCraftBlocks.basal, 0, 2);
		world.setBlock(i + 4, j + 9, k + 7, NovaCraftBlocks.basal, 0, 2);
		world.setBlock(i + 5, j + 9, k + 7, NovaCraftBlocks.basal, 0, 2);
		world.setBlock(i + 6, j + 9, k + 7, NovaCraftBlocks.basal, 0, 2);
		world.setBlock(i + 7, j + 9, k + 7, Blocks.lava, 8, 2);
		world.setBlock(i + 8, j + 9, k + 7, NovaCraftBlocks.basal, 0, 2);
		world.setBlock(i + 9, j + 9, k + 7, NovaCraftBlocks.basal, 0, 2);
		world.setBlock(i + 10, j + 9, k + 7, NovaCraftBlocks.basal, 0, 2);
		world.setBlock(i + 11, j + 9, k + 7, NovaCraftBlocks.basal, 0, 2);
		world.setBlock(i + 12, j + 9, k + 7, NovaCraftBlocks.basal, 0, 2);
		world.setBlock(i + 13, j + 9, k + 7, NovaCraftBlocks.basal, 0, 2);
		world.setBlock(i + 14, j + 9, k + 7, NovaCraftBlocks.basal, 0, 2);
		world.setBlock(i + 15, j + 9, k + 7, NovaCraftBlocks.basal, 0, 2);
		world.setBlock(i + 16, j + 9, k + 7, NovaCraftBlocks.basal, 0, 2);
		world.setBlock(i + 17, j + 9, k + 7, NovaCraftBlocks.basal, 0, 2);
		world.setBlock(i + 18, j + 9, k + 7, NovaCraftBlocks.basal, 0, 2);
		world.setBlock(i + 19, j + 9, k + 7, NovaCraftBlocks.basal, 0, 2);
		world.setBlock(i + 20, j + 9, k + 7, NovaCraftBlocks.basal, 0, 2);
		world.setBlock(i + 21, j + 9, k + 7, Blocks.air, 0, 2);
		world.setBlock(i + 22, j + 9, k + 7, Blocks.air, 0, 2);
		world.setBlock(i + 23, j + 9, k + 7, NovaCraftBlocks.basal, 0, 2);
		world.setBlock(i + 24, j + 9, k + 7, NovaCraftBlocks.basal, 0, 2);
		world.setBlock(i + 25, j + 9, k + 7, NovaCraftBlocks.basal, 0, 2);
		world.setBlock(i + 26, j + 9, k + 7, NovaCraftBlocks.basal, 0, 2);
		world.setBlock(i + 27, j + 9, k + 7, NovaCraftBlocks.basal, 0, 2);
		world.setBlock(i + 0, j + 9, k + 8, NovaCraftBlocks.basal, 0, 2);
		world.setBlock(i + 1, j + 9, k + 8, NovaCraftBlocks.basal, 0, 2);
		world.setBlock(i + 2, j + 9, k + 8, NovaCraftBlocks.basal, 0, 2);
		world.setBlock(i + 3, j + 9, k + 8, NovaCraftBlocks.basal, 0, 2);
		world.setBlock(i + 4, j + 9, k + 8, NovaCraftBlocks.basal, 0, 2);
		world.setBlock(i + 5, j + 9, k + 8, NovaCraftBlocks.basal, 0, 2);
		world.setBlock(i + 6, j + 9, k + 8, NovaCraftBlocks.basal, 0, 2);
		world.setBlock(i + 7, j + 9, k + 8, NovaCraftBlocks.basal, 0, 2);
		world.setBlock(i + 8, j + 9, k + 8, NovaCraftBlocks.basal, 0, 2);
		world.setBlock(i + 9, j + 9, k + 8, NovaCraftBlocks.basal, 0, 2);
		world.setBlock(i + 10, j + 9, k + 8, NovaCraftBlocks.basal, 0, 2);
		world.setBlock(i + 11, j + 9, k + 8, NovaCraftBlocks.basal, 0, 2);
		world.setBlock(i + 12, j + 9, k + 8, NovaCraftBlocks.basal, 0, 2);
		world.setBlock(i + 13, j + 9, k + 8, NovaCraftBlocks.basal, 0, 2);
		world.setBlock(i + 14, j + 9, k + 8, NovaCraftBlocks.basal, 0, 2);
		world.setBlock(i + 15, j + 9, k + 8, NovaCraftBlocks.basal, 0, 2);
		world.setBlock(i + 16, j + 9, k + 8, NovaCraftBlocks.basal, 0, 2);
		world.setBlock(i + 17, j + 9, k + 8, NovaCraftBlocks.basal, 0, 2);
		world.setBlock(i + 18, j + 9, k + 8, NovaCraftBlocks.basal, 0, 2);
		world.setBlock(i + 19, j + 9, k + 8, NovaCraftBlocks.basal, 0, 2);
		world.setBlock(i + 20, j + 9, k + 8, NovaCraftBlocks.basal, 0, 2);
		world.setBlock(i + 21, j + 9, k + 8, Blocks.air, 0, 2);
		world.setBlock(i + 22, j + 9, k + 8, Blocks.air, 0, 2);
		world.setBlock(i + 23, j + 9, k + 8, NovaCraftBlocks.basal, 0, 2);
		world.setBlock(i + 24, j + 9, k + 8, NovaCraftBlocks.basal, 0, 2);
		world.setBlock(i + 25, j + 9, k + 8, NovaCraftBlocks.basal, 0, 2);
		world.setBlock(i + 26, j + 9, k + 8, NovaCraftBlocks.basal, 0, 2);
		world.setBlock(i + 27, j + 9, k + 8, NovaCraftBlocks.basal, 0, 2);
		world.setBlock(i + 0, j + 9, k + 9, NovaCraftBlocks.basal, 0, 2);
		world.setBlock(i + 1, j + 9, k + 9, NovaCraftBlocks.basal, 0, 2);
		world.setBlock(i + 2, j + 9, k + 9, NovaCraftBlocks.basal, 0, 2);
		world.setBlock(i + 3, j + 9, k + 9, NovaCraftBlocks.basal, 0, 2);
		world.setBlock(i + 4, j + 9, k + 9, NovaCraftBlocks.basal, 0, 2);
		world.setBlock(i + 5, j + 9, k + 9, NovaCraftBlocks.basal, 0, 2);
		world.setBlock(i + 6, j + 9, k + 9, NovaCraftBlocks.basal, 0, 2);
		world.setBlock(i + 7, j + 9, k + 9, NovaCraftBlocks.basal, 0, 2);
		world.setBlock(i + 8, j + 9, k + 9, NovaCraftBlocks.basal, 0, 2);
		world.setBlock(i + 9, j + 9, k + 9, NovaCraftBlocks.basal, 0, 2);
		world.setBlock(i + 10, j + 9, k + 9, NovaCraftBlocks.basal, 0, 2);
		world.setBlock(i + 11, j + 9, k + 9, NovaCraftBlocks.basal, 0, 2);
		world.setBlock(i + 12, j + 9, k + 9, Blocks.air, 0, 2);
		world.setBlock(i + 13, j + 9, k + 9, Blocks.air, 0, 2);
		world.setBlock(i + 14, j + 9, k + 9, NovaCraftBlocks.basal, 0, 2);
		world.setBlock(i + 15, j + 9, k + 9, NovaCraftBlocks.basal, 0, 2);
		world.setBlock(i + 16, j + 9, k + 9, NovaCraftBlocks.basal, 0, 2);
		world.setBlock(i + 17, j + 9, k + 9, NovaCraftBlocks.basal, 0, 2);
		world.setBlock(i + 18, j + 9, k + 9, NovaCraftBlocks.basal, 0, 2);
		world.setBlock(i + 19, j + 9, k + 9, NovaCraftBlocks.basal, 0, 2);
		world.setBlock(i + 20, j + 9, k + 9, NovaCraftBlocks.basal, 0, 2);
		world.setBlock(i + 21, j + 9, k + 9, Blocks.lava, 8, 2);
		world.setBlock(i + 22, j + 9, k + 9, NovaCraftBlocks.basal, 0, 2);
		world.setBlock(i + 23, j + 9, k + 9, NovaCraftBlocks.basal, 0, 2);
		world.setBlock(i + 24, j + 9, k + 9, NovaCraftBlocks.basal, 0, 2);
		world.setBlock(i + 25, j + 9, k + 9, NovaCraftBlocks.basal, 0, 2);
		world.setBlock(i + 26, j + 9, k + 9, NovaCraftBlocks.basal, 0, 2);
		world.setBlock(i + 27, j + 9, k + 9, NovaCraftBlocks.basal, 0, 2);
		world.setBlock(i + 0, j + 9, k + 10, NovaCraftBlocks.basal, 0, 2);
		world.setBlock(i + 1, j + 9, k + 10, NovaCraftBlocks.basal, 0, 2);
		world.setBlock(i + 2, j + 9, k + 10, NovaCraftBlocks.basal, 0, 2);
		world.setBlock(i + 3, j + 9, k + 10, NovaCraftBlocks.basal, 0, 2);
		world.setBlock(i + 4, j + 9, k + 10, NovaCraftBlocks.basal, 0, 2);
		world.setBlock(i + 5, j + 9, k + 10, NovaCraftBlocks.basal, 0, 2);
		world.setBlock(i + 6, j + 9, k + 10, NovaCraftBlocks.basal, 0, 2);
		world.setBlock(i + 7, j + 9, k + 10, NovaCraftBlocks.basal, 0, 2);
		world.setBlock(i + 8, j + 9, k + 10, NovaCraftBlocks.basal, 0, 2);
		world.setBlock(i + 9, j + 9, k + 10, NovaCraftBlocks.basal, 0, 2);
		world.setBlock(i + 10, j + 9, k + 10, NovaCraftBlocks.basal, 0, 2);
		world.setBlock(i + 11, j + 9, k + 10, NovaCraftBlocks.basal, 0, 2);
		world.setBlock(i + 12, j + 9, k + 10, Blocks.air, 0, 2);
		world.setBlock(i + 13, j + 9, k + 10, Blocks.air, 0, 2);
		world.setBlock(i + 14, j + 9, k + 10, NovaCraftBlocks.basal, 0, 2);
		world.setBlock(i + 15, j + 9, k + 10, NovaCraftBlocks.basal, 0, 2);
		world.setBlock(i + 16, j + 9, k + 10, NovaCraftBlocks.basal, 0, 2);
		world.setBlock(i + 17, j + 9, k + 10, NovaCraftBlocks.basal, 0, 2);
		world.setBlock(i + 18, j + 9, k + 10, NovaCraftBlocks.basal, 0, 2);
		world.setBlock(i + 19, j + 9, k + 10, NovaCraftBlocks.basal, 0, 2);
		world.setBlock(i + 20, j + 9, k + 10, NovaCraftBlocks.basal, 0, 2);
		world.setBlock(i + 21, j + 9, k + 10, NovaCraftBlocks.basal, 0, 2);
		world.setBlock(i + 22, j + 9, k + 10, NovaCraftBlocks.basal, 0, 2);
		world.setBlock(i + 23, j + 9, k + 10, NovaCraftBlocks.basal, 0, 2);
		world.setBlock(i + 24, j + 9, k + 10, NovaCraftBlocks.basal, 0, 2);
		world.setBlock(i + 25, j + 9, k + 10, NovaCraftBlocks.basal, 0, 2);
		world.setBlock(i + 26, j + 9, k + 10, NovaCraftBlocks.basal, 0, 2);
		world.setBlock(i + 27, j + 9, k + 10, NovaCraftBlocks.basal, 0, 2);
		world.setBlock(i + 0, j + 9, k + 11, NovaCraftBlocks.cracked_basal_bricks, 0, 2);
		world.setBlock(i + 1, j + 9, k + 11, NovaCraftBlocks.basal_bricks, 0, 2);
		world.setBlock(i + 2, j + 9, k + 11, NovaCraftBlocks.basal_bricks, 0, 2);
		world.setBlock(i + 3, j + 9, k + 11, NovaCraftBlocks.cracked_basal_bricks, 0, 2);
		world.setBlock(i + 4, j + 9, k + 11, NovaCraftBlocks.basal_bricks, 0, 2);
		world.setBlock(i + 5, j + 9, k + 11, NovaCraftBlocks.cracked_basal_bricks, 0, 2);
		world.setBlock(i + 6, j + 9, k + 11, NovaCraftBlocks.cracked_basal_bricks, 0, 2);
		world.setBlock(i + 7, j + 9, k + 11, NovaCraftBlocks.cracked_basal_bricks, 0, 2);
		world.setBlock(i + 8, j + 9, k + 11, NovaCraftBlocks.cracked_basal_bricks, 0, 2);
		world.setBlock(i + 9, j + 9, k + 11, NovaCraftBlocks.basal_bricks, 0, 2);
		world.setBlock(i + 10, j + 9, k + 11, NovaCraftBlocks.cracked_basal_bricks, 0, 2);
		world.setBlock(i + 11, j + 9, k + 11, Blocks.air, 0, 2);
		world.setBlock(i + 12, j + 9, k + 11, Blocks.air, 0, 2);
		world.setBlock(i + 13, j + 9, k + 11, Blocks.air, 0, 2);
		world.setBlock(i + 14, j + 9, k + 11, NovaCraftBlocks.basal, 0, 2);
		world.setBlock(i + 15, j + 9, k + 11, NovaCraftBlocks.basal, 0, 2);
		world.setBlock(i + 16, j + 9, k + 11, NovaCraftBlocks.basal, 0, 2);
		world.setBlock(i + 17, j + 9, k + 11, NovaCraftBlocks.basal, 0, 2);
		world.setBlock(i + 18, j + 9, k + 11, NovaCraftBlocks.basal, 0, 2);
		world.setBlock(i + 19, j + 9, k + 11, NovaCraftBlocks.basal, 0, 2);
		world.setBlock(i + 20, j + 9, k + 11, NovaCraftBlocks.basal, 0, 2);
		world.setBlock(i + 21, j + 9, k + 11, NovaCraftBlocks.basal, 0, 2);
		world.setBlock(i + 22, j + 9, k + 11, NovaCraftBlocks.basal, 0, 2);
		world.setBlock(i + 23, j + 9, k + 11, NovaCraftBlocks.basal, 0, 2);
		world.setBlock(i + 24, j + 9, k + 11, NovaCraftBlocks.basal, 0, 2);
		world.setBlock(i + 25, j + 9, k + 11, NovaCraftBlocks.basal, 0, 2);
		world.setBlock(i + 26, j + 9, k + 11, Blocks.air, 0, 2);
		world.setBlock(i + 27, j + 9, k + 11, Blocks.air, 0, 2);
		world.setBlock(i + 0, j + 9, k + 12, NovaCraftBlocks.cracked_basal_bricks, 0, 2);
		world.setBlock(i + 1, j + 9, k + 12, NovaCraftBlocks.basal_bricks, 0, 2);
		world.setBlock(i + 2, j + 9, k + 12, NovaCraftBlocks.basal_bricks, 0, 2);
		world.setBlock(i + 3, j + 9, k + 12, NovaCraftBlocks.cracked_basal_bricks, 0, 2);
		world.setBlock(i + 4, j + 9, k + 12, NovaCraftBlocks.basal_bricks, 0, 2);
		world.setBlock(i + 5, j + 9, k + 12, NovaCraftBlocks.cracked_basal_bricks, 0, 2);
		world.setBlock(i + 6, j + 9, k + 12, NovaCraftBlocks.basal_bricks, 0, 2);
		world.setBlock(i + 7, j + 9, k + 12, NovaCraftBlocks.basal_bricks, 0, 2);
		world.setBlock(i + 8, j + 9, k + 12, NovaCraftBlocks.basal_bricks, 0, 2);
		world.setBlock(i + 9, j + 9, k + 12, NovaCraftBlocks.basal_bricks, 0, 2);
		world.setBlock(i + 10, j + 9, k + 12, NovaCraftBlocks.basal_bricks, 0, 2);
		world.setBlock(i + 11, j + 9, k + 12, NovaCraftBlocks.cracked_basal_bricks, 0, 2);
		world.setBlock(i + 12, j + 9, k + 12, Blocks.air, 0, 2);
		world.setBlock(i + 13, j + 9, k + 12, Blocks.air, 0, 2);
		world.setBlock(i + 14, j + 9, k + 12, NovaCraftBlocks.basal, 0, 2);
		world.setBlock(i + 15, j + 9, k + 12, NovaCraftBlocks.basal, 0, 2);
		world.setBlock(i + 16, j + 9, k + 12, NovaCraftBlocks.basal, 0, 2);
		world.setBlock(i + 17, j + 9, k + 12, NovaCraftBlocks.basal, 0, 2);
		world.setBlock(i + 18, j + 9, k + 12, NovaCraftBlocks.basal, 0, 2);
		world.setBlock(i + 19, j + 9, k + 12, NovaCraftBlocks.basal, 0, 2);
		world.setBlock(i + 20, j + 9, k + 12, NovaCraftBlocks.basal, 0, 2);
		world.setBlock(i + 21, j + 9, k + 12, NovaCraftBlocks.basal, 0, 2);
		world.setBlock(i + 22, j + 9, k + 12, NovaCraftBlocks.basal, 0, 2);
		world.setBlock(i + 23, j + 9, k + 12, NovaCraftBlocks.basal, 0, 2);
		world.setBlock(i + 24, j + 9, k + 12, NovaCraftBlocks.basal, 0, 2);
		world.setBlock(i + 25, j + 9, k + 12, NovaCraftBlocks.basal, 0, 2);
		world.setBlock(i + 26, j + 9, k + 12, Blocks.air, 0, 2);
		world.setBlock(i + 27, j + 9, k + 12, Blocks.air, 0, 2);
		world.setBlock(i + 0, j + 10, k + 0, Blocks.air, 0, 2);
		world.setBlock(i + 1, j + 10, k + 0, Blocks.air, 0, 2);
		world.setBlock(i + 2, j + 10, k + 0, Blocks.air, 0, 2);
		world.setBlock(i + 3, j + 10, k + 0, Blocks.air, 0, 2);
		world.setBlock(i + 4, j + 10, k + 0, Blocks.air, 0, 2);
		world.setBlock(i + 5, j + 10, k + 0, Blocks.air, 0, 2);
		world.setBlock(i + 6, j + 10, k + 0, Blocks.air, 0, 2);
		world.setBlock(i + 7, j + 10, k + 0, Blocks.air, 0, 2);
		world.setBlock(i + 8, j + 10, k + 0, Blocks.air, 0, 2);
		world.setBlock(i + 9, j + 10, k + 0, Blocks.air, 0, 2);
		world.setBlock(i + 10, j + 10, k + 0, Blocks.air, 0, 2);
		world.setBlock(i + 11, j + 10, k + 0, Blocks.air, 0, 2);
		world.setBlock(i + 12, j + 10, k + 0, Blocks.air, 0, 2);
		world.setBlock(i + 13, j + 10, k + 0, Blocks.air, 0, 2);
		world.setBlock(i + 14, j + 10, k + 0, Blocks.air, 0, 2);
		world.setBlock(i + 15, j + 10, k + 0, Blocks.air, 0, 2);
		world.setBlock(i + 16, j + 10, k + 0, Blocks.air, 0, 2);
		world.setBlock(i + 17, j + 10, k + 0, Blocks.air, 0, 2);
		world.setBlock(i + 18, j + 10, k + 0, Blocks.air, 0, 2);
		world.setBlock(i + 19, j + 10, k + 0, Blocks.air, 0, 2);
		world.setBlock(i + 20, j + 10, k + 0, Blocks.air, 0, 2);
		world.setBlock(i + 21, j + 10, k + 0, Blocks.air, 0, 2);
		world.setBlock(i + 22, j + 10, k + 0, Blocks.air, 0, 2);
		world.setBlock(i + 23, j + 10, k + 0, Blocks.air, 0, 2);
		world.setBlock(i + 24, j + 10, k + 0, Blocks.air, 0, 2);
		world.setBlock(i + 25, j + 10, k + 0, Blocks.air, 0, 2);
		world.setBlock(i + 26, j + 10, k + 0, Blocks.air, 0, 2);
		world.setBlock(i + 27, j + 10, k + 0, Blocks.air, 0, 2);
		world.setBlock(i + 0, j + 10, k + 1, Blocks.air, 0, 2);
		world.setBlock(i + 1, j + 10, k + 1, NovaCraftBlocks.basal, 0, 2);
		world.setBlock(i + 2, j + 10, k + 1, Blocks.air, 0, 2);
		world.setBlock(i + 3, j + 10, k + 1, Blocks.air, 0, 2);
		world.setBlock(i + 4, j + 10, k + 1, NovaCraftBlocks.basal, 0, 2);
		world.setBlock(i + 5, j + 10, k + 1, NovaCraftBlocks.basal, 0, 2);
		world.setBlock(i + 6, j + 10, k + 1, Blocks.air, 0, 2);
		world.setBlock(i + 7, j + 10, k + 1, Blocks.air, 0, 2);
		world.setBlock(i + 8, j + 10, k + 1, Blocks.air, 0, 2);
		world.setBlock(i + 9, j + 10, k + 1, NovaCraftBlocks.basal, 0, 2);
		world.setBlock(i + 10, j + 10, k + 1, Blocks.air, 0, 2);
		world.setBlock(i + 11, j + 10, k + 1, Blocks.air, 0, 2);
		world.setBlock(i + 12, j + 10, k + 1, NovaCraftBlocks.basal, 0, 2);
		world.setBlock(i + 13, j + 10, k + 1, Blocks.air, 0, 2);
		world.setBlock(i + 14, j + 10, k + 1, Blocks.air, 0, 2);
		world.setBlock(i + 15, j + 10, k + 1, Blocks.air, 0, 2);
		world.setBlock(i + 16, j + 10, k + 1, Blocks.air, 0, 2);
		world.setBlock(i + 17, j + 10, k + 1, Blocks.air, 0, 2);
		world.setBlock(i + 18, j + 10, k + 1, Blocks.air, 0, 2);
		world.setBlock(i + 19, j + 10, k + 1, Blocks.air, 0, 2);
		world.setBlock(i + 20, j + 10, k + 1, Blocks.air, 0, 2);
		world.setBlock(i + 21, j + 10, k + 1, Blocks.air, 0, 2);
		world.setBlock(i + 22, j + 10, k + 1, Blocks.air, 0, 2);
		world.setBlock(i + 23, j + 10, k + 1, Blocks.air, 0, 2);
		world.setBlock(i + 24, j + 10, k + 1, Blocks.air, 0, 2);
		world.setBlock(i + 25, j + 10, k + 1, Blocks.air, 0, 2);
		world.setBlock(i + 26, j + 10, k + 1, Blocks.air, 0, 2);
		world.setBlock(i + 27, j + 10, k + 1, Blocks.air, 0, 2);
		world.setBlock(i + 0, j + 10, k + 2, NovaCraftBlocks.basal, 0, 2);
		world.setBlock(i + 1, j + 10, k + 2, NovaCraftBlocks.basal, 0, 2);
		world.setBlock(i + 2, j + 10, k + 2, NovaCraftBlocks.cracked_basal_bricks, 0, 2);
		world.setBlock(i + 3, j + 10, k + 2, NovaCraftBlocks.basal, 0, 2);
		world.setBlock(i + 4, j + 10, k + 2, Blocks.air, 0, 2);
		world.setBlock(i + 5, j + 10, k + 2, Blocks.air, 0, 2);
		world.setBlock(i + 6, j + 10, k + 2, NovaCraftBlocks.cracked_basal_bricks, 0, 2);
		world.setBlock(i + 7, j + 10, k + 2, NovaCraftBlocks.basal_bricks, 0, 2);
		world.setBlock(i + 8, j + 10, k + 2, NovaCraftBlocks.basal, 0, 2);
		world.setBlock(i + 9, j + 10, k + 2, NovaCraftBlocks.basal, 0, 2);
		world.setBlock(i + 10, j + 10, k + 2, NovaCraftBlocks.basal, 0, 2);
		world.setBlock(i + 11, j + 10, k + 2, Blocks.air, 0, 2);
		world.setBlock(i + 12, j + 10, k + 2, NovaCraftBlocks.basal, 0, 2);
		world.setBlock(i + 13, j + 10, k + 2, Blocks.air, 0, 2);
		world.setBlock(i + 14, j + 10, k + 2, Blocks.air, 0, 2);
		world.setBlock(i + 15, j + 10, k + 2, Blocks.air, 0, 2);
		world.setBlock(i + 16, j + 10, k + 2, Blocks.air, 0, 2);
		world.setBlock(i + 17, j + 10, k + 2, Blocks.air, 0, 2);
